File: Files_organized_for_plots/Centroid_changing_NaOH/XRDb_Centroid08Dec21_Act14Feb22_B4_0538M_NaOH_LS0146_1.csv
[Measurement conditions]
Sample identification,XRD_Centroid08Dec21_Act14Feb22_B4_0538M_NaOH_LS0146_1
Comment - 1,"Configuration=Stage for Flat Samples/Holders, Owner=User-1, Creation date=7/1/2020 9:53:24 AM"
Comment - 2,"Goniometer=Theta/Theta; Minimum step size 2Theta:0.0001; Minimum step size Omega:0.0001"
Comment - 3,"Sample stage=Stage for flat samples/holders"
Comment - 4,"Diffractometer system=EMPYREAN"
Comment - 5,"Measurement program=C:\Users\ibo5034\OneDrive - The Pennsylvania State University\NEUP - Reed, Titus's files\XRD\Cement\Zerobackground scan.xrdmp, Identifier={98A3B11C-88F9-4AA6-982C-73314A311EF5}"
Anode material,Cu
K-Alpha1 wavelength,1.5405980
K-Alpha2 wavelength,1.5444260
Ratio K-Alpha2/K-Alpha1,0.500
Divergence slit,Fixed,0.25
Monochromator used,NO
Generator voltage, 45
Tube current, 40
File date and time,17/Feb/2022 13:09
Unit cell,
h k l, 0 0 0
Scan axis,Gonio
Scan range,4.994599997,64.999991833
Scan step size,0.0262606
No. of points, 2285
Scan type,CONTINUOUS
Time per step,96.390
[Scan points]
Angle, TimePerStep, Intensity, ESD
5.007730280, 96.390, 5210.0, 72.1803
5.060251411, 96.390, 5250.0, 72.4569
5.112772541, 96.390, 4957.0, 70.4060
5.165293672, 96.390, 5088.0, 71.3302
5.217814803, 96.390, 5006.0, 70.7531
5.270335934, 96.390, 4890.0, 69.9285
5.322857064, 96.390, 5014.0, 70.8096
5.375378195, 96.390, 4956.0, 70.3989
5.427899326, 96.390, 4789.0, 69.2026
5.480420456, 96.390, 4758.0, 68.9783
5.532941587, 96.390, 4954.0, 70.3847
5.585462718, 96.390, 4768.0, 69.0507
5.637983849, 96.390, 4780.0, 69.1375
5.690504979, 96.390, 4689.0, 68.4763
5.743026110, 96.390, 4822.0, 69.4406
5.795547241, 96.390, 4639.0, 68.1102
5.848068371, 96.390, 4650.0, 68.1909
5.900589502, 96.390, 4668.0, 68.3228
5.953110633, 96.390, 4716.0, 68.6731
6.005631763, 96.390, 4610.0, 67.8970
6.058152894, 96.390, 4706.0, 68.6003
6.110674025, 96.390, 4514.0, 67.1863
6.163195156, 96.390, 4732.0, 68.7895
6.215716286, 96.390, 4606.0, 67.8675
6.268237417, 96.390, 4434.0, 66.5883
6.320758548, 96.390, 4592.0, 67.7643
6.373279678, 96.390, 4612.0, 67.9117
6.425800809, 96.390, 4454.0, 66.7383
6.478321940, 96.390, 4631.0, 68.0515
6.530843071, 96.390, 4511.0, 67.1640
6.583364201, 96.390, 4519.0, 67.2235
6.635885332, 96.390, 4504.0, 67.1118
6.688406463, 96.390, 4530.0, 67.3053
6.740927593, 96.390, 4358.0, 66.0151
6.793448724, 96.390, 4509.0, 67.1491
6.845969855, 96.390, 4451.0, 66.7158
6.898490986, 96.390, 4408.0, 66.3928
6.951012116, 96.390, 4399.0, 66.3250
7.003533247, 96.390, 4325.0, 65.7647
7.056054378, 96.390, 4281.0, 65.4294
7.108575508, 96.390, 4361.0, 66.0379
7.161096639, 96.390, 4369.0, 66.0984
7.213617770, 96.390, 4446.0, 66.6783
7.266138900, 96.390, 4351.0, 65.9621
7.318660031, 96.390, 4293.0, 65.5210
7.371181162, 96.390, 4419.0, 66.4756
7.423702293, 96.390, 4259.0, 65.2610
7.476223423, 96.390, 4233.0, 65.0615
7.528744554, 96.390, 4141.0, 64.3506
7.581265685, 96.390, 4317.0, 65.7039
7.633786815, 96.390, 4320.0, 65.7267
7.686307946, 96.390, 4258.0, 65.2534
7.738829077, 96.390, 4280.0, 65.4217
7.791350208, 96.390, 4304.0, 65.6049
7.843871338, 96.390, 4242.0, 65.1306
7.896392469, 96.390, 4174.0, 64.6065
7.948913600, 96.390, 4243.0, 65.1383
8.001434730, 96.390, 4046.0, 63.6082
8.053955861, 96.390, 4107.0, 64.0859
8.106476992, 96.390, 4117.0, 64.1639
8.158998123, 96.390, 4168.0, 64.5600
8.211519253, 96.390, 4120.0, 64.1872
8.264040384, 96.390, 4067.0, 63.7730
8.316561515, 96.390, 3988.0, 63.1506
8.369082645, 96.390, 3973.0, 63.0317
8.421603776, 96.390, 3972.0, 63.0238
8.474124907, 96.390, 3836.0, 61.9355
8.526646038, 96.390, 3936.0, 62.7375
8.579167168, 96.390, 3904.0, 62.4820
8.631688299, 96.390, 3960.0, 62.9285
8.684209430, 96.390, 3892.0, 62.3859
8.736730560, 96.390, 3911.0, 62.5380
8.789251691, 96.390, 3965.0, 62.9682
8.841772822, 96.390, 4000.0, 63.2456
8.894293952, 96.390, 4003.0, 63.2693
8.946815083, 96.390, 3922.0, 62.6259
8.999336214, 96.390, 3949.0, 62.8411
9.051857345, 96.390, 3811.0, 61.7333
9.104378475, 96.390, 3774.0, 61.4329
9.156899606, 96.390, 3812.0, 61.7414
9.209420737, 96.390, 3878.0, 62.2736
9.261941867, 96.390, 3732.0, 61.0901
9.314462998, 96.390, 3688.0, 60.7289
9.366984129, 96.390, 3753.0, 61.2617
9.419505260, 96.390, 3714.0, 60.9426
9.472026390, 96.390, 3615.0, 60.1249
9.524547521, 96.390, 3680.0, 60.6630
9.577068652, 96.390, 3679.0, 60.6548
9.629589782, 96.390, 3669.0, 60.5723
9.682110913, 96.390, 3671.0, 60.5888
9.734632044, 96.390, 3620.0, 60.1664
9.787153175, 96.390, 3678.0, 60.6465
9.839674305, 96.390, 3523.0, 59.3549
9.892195436, 96.390, 3539.0, 59.4895
9.944716567, 96.390, 3558.0, 59.6490
9.997237697, 96.390, 3571.0, 59.7578
10.049758828, 96.390, 3584.0, 59.8665
10.102279959, 96.390, 3562.0, 59.6825
10.154801090, 96.390, 3519.0, 59.3212
10.207322220, 96.390, 3537.0, 59.4727
10.259843351, 96.390, 3509.0, 59.2368
10.312364482, 96.390, 3597.0, 59.9750
10.364885612, 96.390, 3436.0, 58.6174
10.417406743, 96.390, 3445.0, 58.6941
10.469927874, 96.390, 3520.0, 59.3296
10.522449004, 96.390, 3479.0, 58.9830
10.574970135, 96.390, 3381.0, 58.1464
10.627491266, 96.390, 3366.0, 58.0172
10.680012397, 96.390, 3362.0, 57.9828
10.732533527, 96.390, 3358.0, 57.9483
10.785054658, 96.390, 3357.0, 57.9396
10.837575789, 96.390, 3439.0, 58.6430
10.890096919, 96.390, 3361.0, 57.9741
10.942618050, 96.390, 3340.0, 57.7927
10.995139181, 96.390, 3337.0, 57.7668
11.047660312, 96.390, 3295.0, 57.4021
11.100181442, 96.390, 3245.0, 56.9649
11.152702573, 96.390, 3308.0, 57.5152
11.205223704, 96.390, 3299.0, 57.4369
11.257744834, 96.390, 3235.0, 56.8771
11.310265965, 96.390, 3277.0, 57.2451
11.362787096, 96.390, 3132.0, 55.9643
11.415308227, 96.390, 3214.0, 56.6922
11.467829357, 96.390, 3119.0, 55.8480
11.520350488, 96.390, 3095.0, 55.6327
11.572871619, 96.390, 3157.0, 56.1872
11.625392749, 96.390, 3087.0, 55.5608
11.677913880, 96.390, 2968.0, 54.4794
11.730435011, 96.390, 3075.0, 55.4527
11.782956141, 96.390, 3127.0, 55.9196
11.835477272, 96.390, 3055.0, 55.2721
11.887998403, 96.390, 2898.0, 53.8331
11.940519534, 96.390, 3100.0, 55.6776
11.993040664, 96.390, 2958.0, 54.3875
12.045561795, 96.390, 2952.0, 54.3323
12.098082926, 96.390, 2887.0, 53.7308
12.150604056, 96.390, 2975.0, 54.5436
12.203125187, 96.390, 2900.0, 53.8516
12.255646318, 96.390, 2895.0, 53.8052
12.308167449, 96.390, 2927.0, 54.1018
12.360688579, 96.390, 2880.0, 53.6656
12.413209710, 96.390, 2943.0, 54.2494
12.465730841, 96.390, 2914.0, 53.9815
12.518251971, 96.390, 2872.0, 53.5910
12.570773102, 96.390, 2849.0, 53.3760
12.623294233, 96.390, 2926.0, 54.0925
12.675815364, 96.390, 2806.0, 52.9717
12.728336494, 96.390, 2920.0, 54.0370
12.780857625, 96.390, 2823.0, 53.1319
12.833378756, 96.390, 2805.0, 52.9623
12.885899886, 96.390, 2752.0, 52.4595
12.938421017, 96.390, 2803.0, 52.9434
12.990942148, 96.390, 2750.0, 52.4404
13.043463279, 96.390, 2620.0, 51.1859
13.095984409, 96.390, 2748.0, 52.4214
13.148505540, 96.390, 2676.0, 51.7301
13.201026671, 96.390, 2599.0, 50.9804
13.253547801, 96.390, 2721.0, 52.1632
13.306068932, 96.390, 2542.0, 50.4183
13.358590063, 96.390, 2604.0, 51.0294
13.411111193, 96.390, 2543.0, 50.4282
13.463632324, 96.390, 2518.0, 50.1797
13.516153455, 96.390, 2515.0, 50.1498
13.568674586, 96.390, 2539.0, 50.3885
13.621195716, 96.390, 2625.0, 51.2348
13.673716847, 96.390, 2547.0, 50.4678
13.726237978, 96.390, 2532.0, 50.3190
13.778759108, 96.390, 2471.0, 49.7092
13.831280239, 96.390, 2567.0, 50.6656
13.883801370, 96.390, 2533.0, 50.3289
13.936322501, 96.390, 2562.0, 50.6162
13.988843631, 96.390, 2550.0, 50.4975
14.041364762, 96.390, 2540.0, 50.3984
14.093885893, 96.390, 2542.0, 50.4183
14.146407023, 96.390, 2487.0, 49.8698
14.198928154, 96.390, 2500.0, 50.0000
14.251449285, 96.390, 2422.0, 49.2138
14.303970416, 96.390, 2432.0, 49.3153
14.356491546, 96.390, 2505.0, 50.0500
14.409012677, 96.390, 2546.0, 50.4579
14.461533808, 96.390, 2385.0, 48.8365
14.514054938, 96.390, 2498.0, 49.9800
14.566576069, 96.390, 2414.0, 49.1325
14.619097200, 96.390, 2363.0, 48.6107
14.671618331, 96.390, 2498.0, 49.9800
14.724139461, 96.390, 2406.0, 49.0510
14.776660592, 96.390, 2457.0, 49.5681
14.829181723, 96.390, 2411.0, 49.1019
14.881702853, 96.390, 2424.0, 49.2341
14.934223984, 96.390, 2450.0, 49.4975
14.986745115, 96.390, 2341.0, 48.3839
15.039266245, 96.390, 2352.0, 48.4974
15.091787376, 96.390, 2357.0, 48.5489
15.144308507, 96.390, 2564.0, 50.6360
15.196829638, 96.390, 2500.0, 50.0000
15.249350768, 96.390, 2388.0, 48.8672
15.301871899, 96.390, 2353.0, 48.5077
15.354393030, 96.390, 2443.0, 49.4267
15.406914160, 96.390, 2448.0, 49.4773
15.459435291, 96.390, 2369.0, 48.6724
15.511956422, 96.390, 2352.0, 48.4974
15.564477553, 96.390, 2315.0, 48.1144
15.616998683, 96.390, 2387.0, 48.8569
15.669519814, 96.390, 2377.0, 48.7545
15.722040945, 96.390, 2376.0, 48.7442
15.774562075, 96.390, 2378.0, 48.7647
15.827083206, 96.390, 2307.0, 48.0312
15.879604337, 96.390, 2354.0, 48.5180
15.932125468, 96.390, 2345.0, 48.4252
15.984646598, 96.390, 2402.0, 49.0102
16.037167729, 96.390, 2318.0, 48.1456
16.089688860, 96.390, 2336.0, 48.3322
16.142209990, 96.390, 2343.0, 48.4045
16.194731121, 96.390, 2357.0, 48.5489
16.247252252, 96.390, 2306.0, 48.0208
16.299773382, 96.390, 2361.0, 48.5901
16.352294513, 96.390, 2408.0, 49.0714
16.404815644, 96.390, 2405.0, 49.0408
16.457336775, 96.390, 2380.0, 48.7852
16.509857905, 96.390, 2380.0, 48.7852
16.562379036, 96.390, 2385.0, 48.8365
16.614900167, 96.390, 2436.0, 49.3559
16.667421297, 96.390, 2365.0, 48.6313
16.719942428, 96.390, 2443.0, 49.4267
16.772463559, 96.390, 2399.0, 48.9796
16.824984690, 96.390, 2416.0, 49.1528
16.877505820, 96.390, 2412.0, 49.1121
16.930026951, 96.390, 2420.0, 49.1935
16.982548082, 96.390, 2383.0, 48.8160
17.035069212, 96.390, 2407.0, 49.0612
17.087590343, 96.390, 2426.0, 49.2544
17.140111474, 96.390, 2391.0, 48.8979
17.192632605, 96.390, 2485.0, 49.8498
17.245153735, 96.390, 2350.0, 48.4768
17.297674866, 96.390, 2495.0, 49.9500
17.350195997, 96.390, 2532.0, 50.3190
17.402717127, 96.390, 2397.0, 48.9592
17.455238258, 96.390, 2423.0, 49.2240
17.507759389, 96.390, 2490.0, 49.8999
17.560280520, 96.390, 2487.0, 49.8698
17.612801650, 96.390, 2386.0, 48.8467
17.665322781, 96.390, 2437.0, 49.3660
17.717843912, 96.390, 2435.0, 49.3457
17.770365042, 96.390, 2526.0, 50.2593
17.822886173, 96.390, 2395.0, 48.9387
17.875407304, 96.390, 2552.0, 50.5173
17.927928434, 96.390, 2427.0, 49.2646
17.980449565, 96.390, 2455.0, 49.5480
18.032970696, 96.390, 2388.0, 48.8672
18.085491827, 96.390, 2495.0, 49.9500
18.138012957, 96.390, 2553.0, 50.5272
18.190534088, 96.390, 2478.0, 49.7795
18.243055219, 96.390, 2490.0, 49.8999
18.295576349, 96.390, 2463.0, 49.6286
18.348097480, 96.390, 2577.0, 50.7642
18.400618611, 96.390, 2575.0, 50.7445
18.453139742, 96.390, 2510.0, 50.0999
18.505660872, 96.390, 2543.0, 50.4282
18.558182003, 96.390, 2629.0, 51.2738
18.610703134, 96.390, 2516.0, 50.1597
18.663224264, 96.390, 2544.0, 50.4381
18.715745395, 96.390, 2555.0, 50.5470
18.768266526, 96.390, 2632.0, 51.3030
18.820787657, 96.390, 2515.0, 50.1498
18.873308787, 96.390, 2614.0, 51.1273
18.925829918, 96.390, 2608.0, 51.0686
18.978351049, 96.390, 2626.0, 51.2445
19.030872179, 96.390, 2588.0, 50.8724
19.083393310, 96.390, 2600.0, 50.9902
19.135914441, 96.390, 2698.0, 51.9423
19.188435572, 96.390, 2653.0, 51.5073
19.240956702, 96.390, 2655.0, 51.5267
19.293477833, 96.390, 2661.0, 51.5849
19.345998964, 96.390, 2567.0, 50.6656
19.398520094, 96.390, 2680.0, 51.7687
19.451041225, 96.390, 2648.0, 51.4587
19.503562356, 96.390, 2613.0, 51.1175
19.556083486, 96.390, 2630.0, 51.2835
19.608604617, 96.390, 2613.0, 51.1175
19.661125748, 96.390, 2720.0, 52.1536
19.713646879, 96.390, 2708.0, 52.0384
19.766168009, 96.390, 2737.0, 52.3163
19.818689140, 96.390, 2647.0, 51.4490
19.871210271, 96.390, 2623.0, 51.2152
19.923731401, 96.390, 2712.0, 52.0769
19.976252532, 96.390, 2711.0, 52.0673
20.028773663, 96.390, 2691.0, 51.8748
20.081294794, 96.390, 2643.0, 51.4101
20.133815924, 96.390, 2723.0, 52.1824
20.186337055, 96.390, 2847.0, 53.3573
20.238858186, 96.390, 2828.0, 53.1789
20.291379316, 96.390, 2750.0, 52.4404
20.343900447, 96.390, 2846.0, 53.3479
20.396421578, 96.390, 2916.0, 54.0000
20.448942709, 96.390, 2710.0, 52.0577
20.501463839, 96.390, 2716.0, 52.1153
20.553984970, 96.390, 2796.0, 52.8772
20.606506101, 96.390, 2690.0, 51.8652
20.659027231, 96.390, 2700.0, 51.9615
20.711548362, 96.390, 2799.0, 52.9056
20.764069493, 96.390, 2849.0, 53.3760
20.816590623, 96.390, 2761.0, 52.5452
20.869111754, 96.390, 2728.0, 52.2303
20.921632885, 96.390, 2821.0, 53.1131
20.974154016, 96.390, 2762.0, 52.5547
21.026675146, 96.390, 2888.0, 53.7401
21.079196277, 96.390, 2852.0, 53.4041
21.131717408, 96.390, 2836.0, 53.2541
21.184238538, 96.390, 2812.0, 53.0283
21.236759669, 96.390, 2790.0, 52.8205
21.289280800, 96.390, 2868.0, 53.5537
21.341801931, 96.390, 2727.0, 52.2207
21.394323061, 96.390, 2858.0, 53.4603
21.446844192, 96.390, 2826.0, 53.1601
21.499365323, 96.390, 2872.0, 53.5910
21.551886453, 96.390, 2851.0, 53.3948
21.604407584, 96.390, 2795.0, 52.8678
21.656928715, 96.390, 2773.0, 52.6593
21.709449846, 96.390, 2865.0, 53.5257
21.761970976, 96.390, 2837.0, 53.2635
21.814492107, 96.390, 2842.0, 53.3104
21.867013238, 96.390, 2857.0, 53.4509
21.919534368, 96.390, 2788.0, 52.8015
21.972055499, 96.390, 2805.0, 52.9623
22.024576630, 96.390, 2854.0, 53.4228
22.077097761, 96.390, 2827.0, 53.1695
22.129618891, 96.390, 2880.0, 53.6656
22.182140022, 96.390, 2771.0, 52.6403
22.234661153, 96.390, 2838.0, 53.2729
22.287182283, 96.390, 2782.0, 52.7447
22.339703414, 96.390, 2805.0, 52.9623
22.392224545, 96.390, 2804.0, 52.9528
22.444745675, 96.390, 2834.0, 53.2353
22.497266806, 96.390, 2803.0, 52.9434
22.549787937, 96.390, 2815.0, 53.0566
22.602309068, 96.390, 2846.0, 53.3479
22.654830198, 96.390, 2813.0, 53.0377
22.707351329, 96.390, 2704.0, 52.0000
22.759872460, 96.390, 2812.0, 53.0283
22.812393590, 96.390, 2707.0, 52.0288
22.864914721, 96.390, 2837.0, 53.2635
22.917435852, 96.390, 2751.0, 52.4500
22.969956983, 96.390, 2714.0, 52.0961
23.022478113, 96.390, 2737.0, 52.3163
23.074999244, 96.390, 2794.0, 52.8583
23.127520375, 96.390, 2799.0, 52.9056
23.180041505, 96.390, 2657.0, 51.5461
23.232562636, 96.390, 2751.0, 52.4500
23.285083767, 96.390, 2794.0, 52.8583
23.337604898, 96.390, 2797.0, 52.8867
23.390126028, 96.390, 2777.0, 52.6972
23.442647159, 96.390, 2842.0, 53.3104
23.495168290, 96.390, 2750.0, 52.4404
23.547689420, 96.390, 2622.0, 51.2055
23.600210551, 96.390, 2724.0, 52.1920
23.652731682, 96.390, 2709.0, 52.0481
23.705252813, 96.390, 2678.0, 51.7494
23.757773943, 96.390, 2626.0, 51.2445
23.810295074, 96.390, 2628.0, 51.2640
23.862816205, 96.390, 2621.0, 51.1957
23.915337335, 96.390, 2589.0, 50.8822
23.967858466, 96.390, 2584.0, 50.8331
24.020379597, 96.390, 2634.0, 51.3225
24.072900727, 96.390, 2670.0, 51.6720
24.125421858, 96.390, 2532.0, 50.3190
24.177942989, 96.390, 2569.0, 50.6853
24.230464120, 96.390, 2517.0, 50.1697
24.282985250, 96.390, 2586.0, 50.8527
24.335506381, 96.390, 2558.0, 50.5767
24.388027512, 96.390, 2516.0, 50.1597
24.440548642, 96.390, 2501.0, 50.0100
24.493069773, 96.390, 2357.0, 48.5489
24.545590904, 96.390, 2513.0, 50.1298
24.598112035, 96.390, 2488.0, 49.8799
24.650633165, 96.390, 2462.0, 49.6185
24.703154296, 96.390, 2451.0, 49.5076
24.755675427, 96.390, 2393.0, 48.9183
24.808196557, 96.390, 2455.0, 49.5480
24.860717688, 96.390, 2321.0, 48.1768
24.913238819, 96.390, 2372.0, 48.7032
24.965759950, 96.390, 2363.0, 48.6107
25.018281080, 96.390, 2484.0, 49.8397
25.070802211, 96.390, 2392.0, 48.9081
25.123323342, 96.390, 2370.0, 48.6826
25.175844472, 96.390, 2305.0, 48.0104
25.228365603, 96.390, 2325.0, 48.2183
25.280886734, 96.390, 2335.0, 48.3218
25.333407864, 96.390, 2295.0, 47.9062
25.385928995, 96.390, 2377.0, 48.7545
25.438450126, 96.390, 2319.0, 48.1560
25.490971257, 96.390, 2372.0, 48.7032
25.543492387, 96.390, 2269.0, 47.6340
25.596013518, 96.390, 2202.0, 46.9255
25.648534649, 96.390, 2296.0, 47.9166
25.701055779, 96.390, 2305.0, 48.0104
25.753576910, 96.390, 2367.0, 48.6518
25.806098041, 96.390, 2318.0, 48.1456
25.858619172, 96.390, 2257.0, 47.5079
25.911140302, 96.390, 2208.0, 46.9894
25.963661433, 96.390, 2258.0, 47.5184
26.016182564, 96.390, 2316.0, 48.1248
26.068703694, 96.390, 2254.0, 47.4763
26.121224825, 96.390, 2189.0, 46.7868
26.173745956, 96.390, 2193.0, 46.8295
26.226267087, 96.390, 2241.0, 47.3392
26.278788217, 96.390, 2224.0, 47.1593
26.331309348, 96.390, 2314.0, 48.1041
26.383830479, 96.390, 2243.0, 47.3603
26.436351609, 96.390, 2130.0, 46.1519
26.488872740, 96.390, 2222.0, 47.1381
26.541393871, 96.390, 2097.0, 45.7930
26.593915002, 96.390, 2176.0, 46.6476
26.646436132, 96.390, 2147.0, 46.3357
26.698957263, 96.390, 2173.0, 46.6154
26.751478394, 96.390, 2201.0, 46.9148
26.803999524, 96.390, 2076.0, 45.5631
26.856520655, 96.390, 2093.0, 45.7493
26.909041786, 96.390, 2178.0, 46.6690
26.961562916, 96.390, 2167.0, 46.5510
27.014084047, 96.390, 2120.0, 46.0435
27.066605178, 96.390, 2125.0, 46.0977
27.119126309, 96.390, 2103.0, 45.8585
27.171647439, 96.390, 2077.0, 45.5741
27.224168570, 96.390, 2182.0, 46.7119
27.276689701, 96.390, 2098.0, 45.8039
27.329210831, 96.390, 2143.0, 46.2925
27.381731962, 96.390, 2092.0, 45.7384
27.434253093, 96.390, 2109.0, 45.9239
27.486774224, 96.390, 2061.0, 45.3982
27.539295354, 96.390, 2125.0, 46.0977
27.591816485, 96.390, 2093.0, 45.7493
27.644337616, 96.390, 2001.0, 44.7325
27.696858746, 96.390, 2118.0, 46.0217
27.749379877, 96.390, 2131.0, 46.1628
27.801901008, 96.390, 2152.0, 46.3897
27.854422139, 96.390, 2127.0, 46.1194
27.906943269, 96.390, 2124.0, 46.0869
27.959464400, 96.390, 2092.0, 45.7384
28.011985531, 96.390, 2179.0, 46.6798
28.064506661, 96.390, 2179.0, 46.6798
28.117027792, 96.390, 2059.0, 45.3762
28.169548923, 96.390, 2060.0, 45.3872
28.222070054, 96.390, 2129.0, 46.1411
28.274591184, 96.390, 2102.0, 45.8476
28.327112315, 96.390, 2180.0, 46.6905
28.379633446, 96.390, 2070.0, 45.4973
28.432154576, 96.390, 2079.0, 45.5961
28.484675707, 96.390, 2165.0, 46.5296
28.537196838, 96.390, 2080.0, 45.6070
28.589717968, 96.390, 2107.0, 45.9021
28.642239099, 96.390, 2099.0, 45.8148
28.694760230, 96.390, 2208.0, 46.9894
28.747281361, 96.390, 2027.0, 45.0222
28.799802491, 96.390, 2056.0, 45.3431
28.852323622, 96.390, 2136.0, 46.2169
28.904844753, 96.390, 2048.0, 45.2548
28.957365883, 96.390, 2083.0, 45.6399
29.009887014, 96.390, 2029.0, 45.0444
29.062408145, 96.390, 2099.0, 45.8148
29.114929276, 96.390, 2079.0, 45.5961
29.167450406, 96.390, 2120.0, 46.0435
29.219971537, 96.390, 2133.0, 46.1844
29.272492668, 96.390, 2180.0, 46.6905
29.325013798, 96.390, 2115.0, 45.9891
29.377534929, 96.390, 2051.0, 45.2880
29.430056060, 96.390, 2068.0, 45.4753
29.482577191, 96.390, 2121.0, 46.0543
29.535098321, 96.390, 2139.0, 46.2493
29.587619452, 96.390, 2158.0, 46.4543
29.640140583, 96.390, 2102.0, 45.8476
29.692661713, 96.390, 1970.0, 44.3847
29.745182844, 96.390, 2134.0, 46.1952
29.797703975, 96.390, 2132.0, 46.1736
29.850225105, 96.390, 2145.0, 46.3141
29.902746236, 96.390, 2157.0, 46.4435
29.955267367, 96.390, 2120.0, 46.0435
30.007788498, 96.390, 2112.0, 45.9565
30.060309628, 96.390, 2134.0, 46.1952
30.112830759, 96.390, 2147.0, 46.3357
30.165351890, 96.390, 2019.0, 44.9333
30.217873020, 96.390, 2103.0, 45.8585
30.270394151, 96.390, 2119.0, 46.0326
30.322915282, 96.390, 2097.0, 45.7930
30.375436413, 96.390, 2076.0, 45.5631
30.427957543, 96.390, 2144.0, 46.3033
30.480478674, 96.390, 2072.0, 45.5192
30.532999805, 96.390, 2131.0, 46.1628
30.585520935, 96.390, 2061.0, 45.3982
30.638042066, 96.390, 2154.0, 46.4112
30.690563197, 96.390, 2142.0, 46.2817
30.743084328, 96.390, 2135.0, 46.2061
30.795605458, 96.390, 2164.0, 46.5188
30.848126589, 96.390, 2129.0, 46.1411
30.900647720, 96.390, 2186.0, 46.7547
30.953168850, 96.390, 2084.0, 45.6508
31.005689981, 96.390, 2146.0, 46.3249
31.058211112, 96.390, 2103.0, 45.8585
31.110732243, 96.390, 2148.0, 46.3465
31.163253373, 96.390, 2118.0, 46.0217
31.215774504, 96.390, 2080.0, 45.6070
31.268295635, 96.390, 2052.0, 45.2990
31.320816765, 96.390, 2123.0, 46.0760
31.373337896, 96.390, 2060.0, 45.3872
31.425859027, 96.390, 2099.0, 45.8148
31.478380157, 96.390, 2040.0, 45.1664
31.530901288, 96.390, 2114.0, 45.9783
31.583422419, 96.390, 2097.0, 45.7930
31.635943550, 96.390, 2045.0, 45.2217
31.688464680, 96.390, 2031.0, 45.0666
31.740985811, 96.390, 2017.0, 44.9110
31.793506942, 96.390, 2080.0, 45.6070
31.846028072, 96.390, 2002.0, 44.7437
31.898549203, 96.390, 2076.0, 45.5631
31.951070334, 96.390, 2011.0, 44.8442
32.003591465, 96.390, 2003.0, 44.7549
32.056112595, 96.390, 2108.0, 45.9130
32.108633726, 96.390, 2075.0, 45.5522
32.161154857, 96.390, 1962.0, 44.2945
32.213675987, 96.390, 1988.0, 44.5870
32.266197118, 96.390, 2068.0, 45.4753
32.318718249, 96.390, 2067.0, 45.4643
32.371239380, 96.390, 2000.0, 44.7214
32.423760510, 96.390, 2016.0, 44.8999
32.476281641, 96.390, 1966.0, 44.3396
32.528802772, 96.390, 2021.0, 44.9555
32.581323902, 96.390, 2039.0, 45.1553
32.633845033, 96.390, 2087.0, 45.6837
32.686366164, 96.390, 1998.0, 44.6990
32.738887295, 96.390, 2069.0, 45.4863
32.791408425, 96.390, 1943.0, 44.0795
32.843929556, 96.390, 1982.0, 44.5197
32.896450687, 96.390, 2025.0, 45.0000
32.948971817, 96.390, 2070.0, 45.4973
33.001492948, 96.390, 2083.0, 45.6399
33.054014079, 96.390, 2002.0, 44.7437
33.106535209, 96.390, 1963.0, 44.3058
33.159056340, 96.390, 1962.0, 44.2945
33.211577471, 96.390, 2058.0, 45.3652
33.264098602, 96.390, 2076.0, 45.5631
33.316619732, 96.390, 1907.0, 43.6692
33.369140863, 96.390, 2042.0, 45.1885
33.421661994, 96.390, 1992.0, 44.6318
33.474183124, 96.390, 2026.0, 45.0111
33.526704255, 96.390, 2039.0, 45.1553
33.579225386, 96.390, 2037.0, 45.1331
33.631746517, 96.390, 1964.0, 44.3170
33.684267647, 96.390, 2054.0, 45.3211
33.736788778, 96.390, 1983.0, 44.5309
33.789309909, 96.390, 1980.0, 44.4972
33.841831039, 96.390, 1990.0, 44.6094
33.894352170, 96.390, 2077.0, 45.5741
33.946873301, 96.390, 2106.0, 45.8912
33.999394432, 96.390, 1990.0, 44.6094
34.051915562, 96.390, 2065.0, 45.4423
34.104436693, 96.390, 1997.0, 44.6878
34.156957824, 96.390, 2121.0, 46.0543
34.209478954, 96.390, 2112.0, 45.9565
34.262000085, 96.390, 2130.0, 46.1519
34.314521216, 96.390, 2147.0, 46.3357
34.367042346, 96.390, 2154.0, 46.4112
34.419563477, 96.390, 2171.0, 46.5940
34.472084608, 96.390, 2068.0, 45.4753
34.524605739, 96.390, 2174.0, 46.6262
34.577126869, 96.390, 2217.0, 47.0850
34.629648000, 96.390, 2166.0, 46.5403
34.682169131, 96.390, 2177.0, 46.6583
34.734690261, 96.390, 2222.0, 47.1381
34.787211392, 96.390, 2282.0, 47.7703
34.839732523, 96.390, 2309.0, 48.0521
34.892253654, 96.390, 2230.0, 47.2229
34.944774784, 96.390, 2296.0, 47.9166
34.997295915, 96.390, 2252.0, 47.4552
35.049817046, 96.390, 2212.0, 47.0319
35.102338176, 96.390, 2130.0, 46.1519
35.154859307, 96.390, 2188.0, 46.7761
35.207380438, 96.390, 2248.0, 47.4131
35.259901569, 96.390, 2123.0, 46.0760
35.312422699, 96.390, 2139.0, 46.2493
35.364943830, 96.390, 2144.0, 46.3033
35.417464961, 96.390, 2160.0, 46.4758
35.469986091, 96.390, 2152.0, 46.3897
35.522507222, 96.390, 2194.0, 46.8402
35.575028353, 96.390, 2155.0, 46.4220
35.627549484, 96.390, 2141.0, 46.2709
35.680070614, 96.390, 2043.0, 45.1996
35.732591745, 96.390, 2015.0, 44.8888
35.785112876, 96.390, 2120.0, 46.0435
35.837634006, 96.390, 2015.0, 44.8888
35.890155137, 96.390, 2023.0, 44.9778
35.942676268, 96.390, 2059.0, 45.3762
35.995197398, 96.390, 2010.0, 44.8330
36.047718529, 96.390, 1935.0, 43.9886
36.100239660, 96.390, 2031.0, 45.0666
36.152760791, 96.390, 2004.0, 44.7661
36.205281921, 96.390, 1979.0, 44.4860
36.257803052, 96.390, 2038.0, 45.1442
36.310324183, 96.390, 2020.0, 44.9444
36.362845313, 96.390, 1914.0, 43.7493
36.415366444, 96.390, 2061.0, 45.3982
36.467887575, 96.390, 1943.0, 44.0795
36.520408706, 96.390, 1961.0, 44.2832
36.572929836, 96.390, 1887.0, 43.4396
36.625450967, 96.390, 1946.0, 44.1135
36.677972098, 96.390, 1989.0, 44.5982
36.730493228, 96.390, 1941.0, 44.0568
36.783014359, 96.390, 1857.0, 43.0929
36.835535490, 96.390, 1862.0, 43.1509
36.888056621, 96.390, 1857.0, 43.0929
36.940577751, 96.390, 1874.0, 43.2897
36.993098882, 96.390, 1786.0, 42.2611
37.045620013, 96.390, 1800.0, 42.4264
37.098141143, 96.390, 1774.0, 42.1189
37.150662274, 96.390, 1790.0, 42.3084
37.203183405, 96.390, 1767.0, 42.0357
37.255704535, 96.390, 1874.0, 43.2897
37.308225666, 96.390, 1789.0, 42.2966
37.360746797, 96.390, 1776.0, 42.1426
37.413267928, 96.390, 1755.0, 41.8927
37.465789058, 96.390, 1685.0, 41.0488
37.518310189, 96.390, 1809.0, 42.5323
37.570831320, 96.390, 1764.0, 42.0000
37.623352450, 96.390, 1667.0, 40.8289
37.675873581, 96.390, 1718.0, 41.4488
37.728394712, 96.390, 1710.0, 41.3521
37.780915843, 96.390, 1661.0, 40.7554
37.833436973, 96.390, 1725.0, 41.5331
37.885958104, 96.390, 1697.0, 41.1947
37.938479235, 96.390, 1717.0, 41.4367
37.991000365, 96.390, 1642.0, 40.5216
38.043521496, 96.390, 1643.0, 40.5339
38.096042627, 96.390, 1702.0, 41.2553
38.148563758, 96.390, 1664.0, 40.7922
38.201084888, 96.390, 1583.0, 39.7869
38.253606019, 96.390, 1577.0, 39.7115
38.306127150, 96.390, 1624.0, 40.2989
38.358648280, 96.390, 1623.0, 40.2865
38.411169411, 96.390, 1626.0, 40.3237
38.463690542, 96.390, 1624.0, 40.2989
38.516211673, 96.390, 1598.0, 39.9750
38.568732803, 96.390, 1657.0, 40.7063
38.621253934, 96.390, 1587.0, 39.8372
38.673775065, 96.390, 1580.0, 39.7492
38.726296195, 96.390, 1456.0, 38.1576
38.778817326, 96.390, 1596.0, 39.9500
38.831338457, 96.390, 1581.0, 39.7618
38.883859587, 96.390, 1559.0, 39.4842
38.936380718, 96.390, 1583.0, 39.7869
38.988901849, 96.390, 1597.0, 39.9625
39.041422980, 96.390, 1507.0, 38.8201
39.093944110, 96.390, 1528.0, 39.0896
39.146465241, 96.390, 1508.0, 38.8330
39.198986372, 96.390, 1490.0, 38.6005
39.251507502, 96.390, 1519.0, 38.9744
39.304028633, 96.390, 1424.0, 37.7359
39.356549764, 96.390, 1450.0, 38.0789
39.409070895, 96.390, 1524.0, 39.0384
39.461592025, 96.390, 1483.0, 38.5097
39.514113156, 96.390, 1528.0, 39.0896
39.566634287, 96.390, 1455.0, 38.1445
39.619155417, 96.390, 1409.0, 37.5366
39.671676548, 96.390, 1423.0, 37.7227
39.724197679, 96.390, 1456.0, 38.1576
39.776718810, 96.390, 1427.0, 37.7757
39.829239940, 96.390, 1418.0, 37.6563
39.881761071, 96.390, 1360.0, 36.8782
39.934282202, 96.390, 1467.0, 38.3014
39.986803332, 96.390, 1345.0, 36.6742
40.039324463, 96.390, 1392.0, 37.3095
40.091845594, 96.390, 1386.0, 37.2290
40.144366725, 96.390, 1371.0, 37.0270
40.196887855, 96.390, 1436.0, 37.8946
40.249408986, 96.390, 1408.0, 37.5233
40.301930117, 96.390, 1409.0, 37.5366
40.354451247, 96.390, 1392.0, 37.3095
40.406972378, 96.390, 1331.0, 36.4829
40.459493509, 96.390, 1370.0, 37.0135
40.512014639, 96.390, 1342.0, 36.6333
40.564535770, 96.390, 1331.0, 36.4829
40.617056901, 96.390, 1381.0, 37.1618
40.669578032, 96.390, 1373.0, 37.0540
40.722099162, 96.390, 1390.0, 37.2827
40.774620293, 96.390, 1319.0, 36.3180
40.827141424, 96.390, 1329.0, 36.4555
40.879662554, 96.390, 1357.0, 36.8375
40.932183685, 96.390, 1340.0, 36.6060
40.984704816, 96.390, 1442.0, 37.9737
41.037225947, 96.390, 1327.0, 36.4280
41.089747077, 96.390, 1319.0, 36.3180
41.142268208, 96.390, 1296.0, 36.0000
41.194789339, 96.390, 1330.0, 36.4692
41.247310469, 96.390, 1288.0, 35.8887
41.299831600, 96.390, 1276.0, 35.7211
41.352352731, 96.390, 1269.0, 35.6230
41.404873862, 96.390, 1285.0, 35.8469
41.457394992, 96.390, 1260.0, 35.4965
41.509916123, 96.390, 1305.0, 36.1248
41.562437254, 96.390, 1314.0, 36.2491
41.614958384, 96.390, 1255.0, 35.4260
41.667479515, 96.390, 1271.0, 35.6511
41.720000646, 96.390, 1297.0, 36.0139
41.772521776, 96.390, 1326.0, 36.4143
41.825042907, 96.390, 1247.0, 35.3129
41.877564038, 96.390, 1259.0, 35.4824
41.930085169, 96.390, 1303.0, 36.0971
41.982606299, 96.390, 1256.0, 35.4401
42.035127430, 96.390, 1249.0, 35.3412
42.087648561, 96.390, 1265.0, 35.5668
42.140169691, 96.390, 1256.0, 35.4401
42.192690822, 96.390, 1237.0, 35.1710
42.245211953, 96.390, 1315.0, 36.2629
42.297733084, 96.390, 1221.0, 34.9428
42.350254214, 96.390, 1232.0, 35.0999
42.402775345, 96.390, 1290.0, 35.9166
42.455296476, 96.390, 1280.0, 35.7771
42.507817606, 96.390, 1277.0, 35.7351
42.560338737, 96.390, 1253.0, 35.3977
42.612859868, 96.390, 1248.0, 35.3270
42.665380999, 96.390, 1316.0, 36.2767
42.717902129, 96.390, 1225.0, 35.0000
42.770423260, 96.390, 1288.0, 35.8887
42.822944391, 96.390, 1230.0, 35.0714
42.875465521, 96.390, 1286.0, 35.8608
42.927986652, 96.390, 1197.0, 34.5977
42.980507783, 96.390, 1336.0, 36.5513
43.033028914, 96.390, 1261.0, 35.5106
43.085550044, 96.390, 1299.0, 36.0416
43.138071175, 96.390, 1263.0, 35.5387
43.190592306, 96.390, 1287.0, 35.8748
43.243113436, 96.390, 1266.0, 35.5809
43.295634567, 96.390, 1259.0, 35.4824
43.348155698, 96.390, 1251.0, 35.3695
43.400676828, 96.390, 1266.0, 35.5809
43.453197959, 96.390, 1239.0, 35.1994
43.505719090, 96.390, 1241.0, 35.2278
43.558240221, 96.390, 1201.0, 34.6554
43.610761351, 96.390, 1284.0, 35.8329
43.663282482, 96.390, 1198.0, 34.6121
43.715803613, 96.390, 1251.0, 35.3695
43.768324743, 96.390, 1319.0, 36.3180
43.820845874, 96.390, 1278.0, 35.7491
43.873367005, 96.390, 1207.0, 34.7419
43.925888136, 96.390, 1243.0, 35.2562
43.978409266, 96.390, 1237.0, 35.1710
44.030930397, 96.390, 1274.0, 35.6931
44.083451528, 96.390, 1273.0, 35.6791
44.135972658, 96.390, 1269.0, 35.6230
44.188493789, 96.390, 1252.0, 35.3836
44.241014920, 96.390, 1202.0, 34.6699
44.293536051, 96.390, 1265.0, 35.5668
44.346057181, 96.390, 1281.0, 35.7911
44.398578312, 96.390, 1224.0, 34.9857
44.451099443, 96.390, 1226.0, 35.0143
44.503620573, 96.390, 1247.0, 35.3129
44.556141704, 96.390, 1311.0, 36.2077
44.608662835, 96.390, 1218.0, 34.8999
44.661183966, 96.390, 1274.0, 35.6931
44.713705096, 96.390, 1250.0, 35.3553
44.766226227, 96.390, 1250.0, 35.3553
44.818747358, 96.390, 1220.0, 34.9285
44.871268488, 96.390, 1239.0, 35.1994
44.923789619, 96.390, 1224.0, 34.9857
44.976310750, 96.390, 1222.0, 34.9571
45.028831880, 96.390, 1243.0, 35.2562
45.081353011, 96.390, 1262.0, 35.5246
45.133874142, 96.390, 1259.0, 35.4824
45.186395273, 96.390, 1298.0, 36.0278
45.238916403, 96.390, 1264.0, 35.5528
45.291437534, 96.390, 1267.0, 35.5949
45.343958665, 96.390, 1239.0, 35.1994
45.396479795, 96.390, 1276.0, 35.7211
45.449000926, 96.390, 1298.0, 36.0278
45.501522057, 96.390, 1199.0, 34.6266
45.554043188, 96.390, 1249.0, 35.3412
45.606564318, 96.390, 1243.0, 35.2562
45.659085449, 96.390, 1198.0, 34.6121
45.711606580, 96.390, 1197.0, 34.5977
45.764127710, 96.390, 1293.0, 35.9583
45.816648841, 96.390, 1258.0, 35.4683
45.869169972, 96.390, 1231.0, 35.0856
45.921691103, 96.390, 1323.0, 36.3731
45.974212233, 96.390, 1241.0, 35.2278
46.026733364, 96.390, 1201.0, 34.6554
46.079254495, 96.390, 1198.0, 34.6121
46.131775625, 96.390, 1205.0, 34.7131
46.184296756, 96.390, 1305.0, 36.1248
46.236817887, 96.390, 1278.0, 35.7491
46.289339017, 96.390, 1211.0, 34.7994
46.341860148, 96.390, 1254.0, 35.4119
46.394381279, 96.390, 1258.0, 35.4683
46.446902410, 96.390, 1303.0, 36.0971
46.499423540, 96.390, 1211.0, 34.7994
46.551944671, 96.390, 1294.0, 35.9722
46.604465802, 96.390, 1237.0, 35.1710
46.656986932, 96.390, 1262.0, 35.5246
46.709508063, 96.390, 1250.0, 35.3553
46.762029194, 96.390, 1192.0, 34.5254
46.814550325, 96.390, 1221.0, 34.9428
46.867071455, 96.390, 1259.0, 35.4824
46.919592586, 96.390, 1220.0, 34.9285
46.972113717, 96.390, 1215.0, 34.8569
47.024634847, 96.390, 1259.0, 35.4824
47.077155978, 96.390, 1226.0, 35.0143
47.129677109, 96.390, 1137.0, 33.7194
47.182198240, 96.390, 1175.0, 34.2783
47.234719370, 96.390, 1212.0, 34.8138
47.287240501, 96.390, 1149.0, 33.8969
47.339761632, 96.390, 1202.0, 34.6699
47.392282762, 96.390, 1159.0, 34.0441
47.444803893, 96.390, 1140.0, 33.7639
47.497325024, 96.390, 1192.0, 34.5254
47.549846155, 96.390, 1213.0, 34.8281
47.602367285, 96.390, 1247.0, 35.3129
47.654888416, 96.390, 1185.0, 34.4238
47.707409547, 96.390, 1139.0, 33.7491
47.759930677, 96.390, 1197.0, 34.5977
47.812451808, 96.390, 1146.0, 33.8526
47.864972939, 96.390, 1122.0, 33.4963
47.917494069, 96.390, 1155.0, 33.9853
47.970015200, 96.390, 1155.0, 33.9853
48.022536331, 96.390, 1142.0, 33.7935
48.075057462, 96.390, 1120.0, 33.4664
48.127578592, 96.390, 1145.0, 33.8378
48.180099723, 96.390, 1231.0, 35.0856
48.232620854, 96.390, 1125.0, 33.5410
48.285141984, 96.390, 1196.0, 34.5832
48.337663115, 96.390, 1110.0, 33.3167
48.390184246, 96.390, 1116.0, 33.4066
48.442705377, 96.390, 1125.0, 33.5410
48.495226507, 96.390, 1102.0, 33.1964
48.547747638, 96.390, 1116.0, 33.4066
48.600268769, 96.390, 1104.0, 33.2265
48.652789899, 96.390, 1082.0, 32.8938
48.705311030, 96.390, 1064.0, 32.6190
48.757832161, 96.390, 1113.0, 33.3617
48.810353292, 96.390, 1064.0, 32.6190
48.862874422, 96.390, 1078.0, 32.8329
48.915395553, 96.390, 1110.0, 33.3167
48.967916684, 96.390, 1119.0, 33.4515
49.020437814, 96.390, 1070.0, 32.7109
49.072958945, 96.390, 1055.0, 32.4808
49.125480076, 96.390, 1055.0, 32.4808
49.178001207, 96.390, 1101.0, 33.1813
49.230522337, 96.390, 1000.0, 31.6228
49.283043468, 96.390, 1075.0, 32.7872
49.335564599, 96.390, 1088.0, 32.9848
49.388085729, 96.390, 1066.0, 32.6497
49.440606860, 96.390, 1073.0, 32.7567
49.493127991, 96.390, 1056.0, 32.4962
49.545649121, 96.390, 1044.0, 32.3110
49.598170252, 96.390, 1070.0, 32.7109
49.650691383, 96.390, 1007.0, 31.7333
49.703212514, 96.390, 1030.0, 32.0936
49.755733644, 96.390, 1006.0, 31.7175
49.808254775, 96.390, 1059.0, 32.5423
49.860775906, 96.390, 1027.0, 32.0468
49.913297036, 96.390, 1034.0, 32.1559
49.965818167, 96.390, 982.0, 31.3369
50.018339298, 96.390, 1034.0, 32.1559
50.070860429, 96.390, 996.0, 31.5595
50.123381559, 96.390, 1029.0, 32.0780
50.175902690, 96.390, 1074.0, 32.7719
50.228423821, 96.390, 1039.0, 32.2335
50.280944951, 96.390, 992.0, 31.4960
50.333466082, 96.390, 1033.0, 32.1403
50.385987213, 96.390, 1043.0, 32.2955
50.438508344, 96.390, 985.0, 31.3847
50.491029474, 96.390, 997.0, 31.5753
50.543550605, 96.390, 996.0, 31.5595
50.596071736, 96.390, 1021.0, 31.9531
50.648592866, 96.390, 1029.0, 32.0780
50.701113997, 96.390, 1020.0, 31.9374
50.753635128, 96.390, 989.0, 31.4484
50.806156258, 96.390, 987.0, 31.4166
50.858677389, 96.390, 962.0, 31.0161
50.911198520, 96.390, 979.0, 31.2890
50.963719651, 96.390, 948.0, 30.7896
51.016240781, 96.390, 1011.0, 31.7962
51.068761912, 96.390, 957.0, 30.9354
51.121283043, 96.390, 905.0, 30.0832
51.173804173, 96.390, 951.0, 30.8383
51.226325304, 96.390, 982.0, 31.3369
51.278846435, 96.390, 944.0, 30.7246
51.331367566, 96.390, 961.0, 31.0000
51.383888696, 96.390, 1040.0, 32.2490
51.436409827, 96.390, 991.0, 31.4802
51.488930958, 96.390, 918.0, 30.2985
51.541452088, 96.390, 967.0, 31.0966
51.593973219, 96.390, 942.0, 30.6920
51.646494350, 96.390, 930.0, 30.4959
51.699015481, 96.390, 967.0, 31.0966
51.751536611, 96.390, 971.0, 31.1609
51.804057742, 96.390, 864.0, 29.3939
51.856578873, 96.390, 937.0, 30.6105
51.909100003, 96.390, 943.0, 30.7083
51.961621134, 96.390, 939.0, 30.6431
52.014142265, 96.390, 934.0, 30.5614
52.066663396, 96.390, 970.0, 31.1448
52.119184526, 96.390, 963.0, 31.0322
52.171705657, 96.390, 922.0, 30.3645
52.224226788, 96.390, 962.0, 31.0161
52.276747918, 96.390, 933.0, 30.5450
52.329269049, 96.390, 918.0, 30.2985
52.381790180, 96.390, 940.0, 30.6594
52.434311310, 96.390, 938.0, 30.6268
52.486832441, 96.390, 924.0, 30.3974
52.539353572, 96.390, 885.0, 29.7489
52.591874703, 96.390, 970.0, 31.1448
52.644395833, 96.390, 923.0, 30.3809
52.696916964, 96.390, 947.0, 30.7734
52.749438095, 96.390, 946.0, 30.7571
52.801959225, 96.390, 874.0, 29.5635
52.854480356, 96.390, 899.0, 29.9833
52.907001487, 96.390, 948.0, 30.7896
52.959522618, 96.390, 885.0, 29.7489
53.012043748, 96.390, 920.0, 30.3315
53.064564879, 96.390, 923.0, 30.3809
53.117086010, 96.390, 893.0, 29.8831
53.169607140, 96.390, 899.0, 29.9833
53.222128271, 96.390, 904.0, 30.0666
53.274649402, 96.390, 918.0, 30.2985
53.327170533, 96.390, 937.0, 30.6105
53.379691663, 96.390, 895.0, 29.9166
53.432212794, 96.390, 910.0, 30.1662
53.484733925, 96.390, 850.0, 29.1548
53.537255055, 96.390, 906.0, 30.0998
53.589776186, 96.390, 878.0, 29.6311
53.642297317, 96.390, 879.0, 29.6479
53.694818448, 96.390, 894.0, 29.8998
53.747339578, 96.390, 901.0, 30.0167
53.799860709, 96.390, 814.0, 28.5307
53.852381840, 96.390, 859.0, 29.3087
53.904902970, 96.390, 922.0, 30.3645
53.957424101, 96.390, 885.0, 29.7489
54.009945232, 96.390, 912.0, 30.1993
54.062466362, 96.390, 887.0, 29.7825
54.114987493, 96.390, 862.0, 29.3598
54.167508624, 96.390, 904.0, 30.0666
54.220029755, 96.390, 881.0, 29.6816
54.272550885, 96.390, 875.0, 29.5804
54.325072016, 96.390, 857.0, 29.2746
54.377593147, 96.390, 906.0, 30.0998
54.430114277, 96.390, 877.0, 29.6142
54.482635408, 96.390, 864.0, 29.3939
54.535156539, 96.390, 855.0, 29.2404
54.587677670, 96.390, 858.0, 29.2916
54.640198800, 96.390, 849.0, 29.1376
54.692719931, 96.390, 863.0, 29.3769
54.745241062, 96.390, 932.0, 30.5287
54.797762192, 96.390, 826.0, 28.7402
54.850283323, 96.390, 870.0, 29.4958
54.902804454, 96.390, 861.0, 29.3428
54.955325585, 96.390, 836.0, 28.9137
55.007846715, 96.390, 814.0, 28.5307
55.060367846, 96.390, 850.0, 29.1548
55.112888977, 96.390, 807.0, 28.4077
55.165410107, 96.390, 812.0, 28.4956
55.217931238, 96.390, 845.0, 29.0689
55.270452369, 96.390, 882.0, 29.6985
55.322973499, 96.390, 888.0, 29.7993
55.375494630, 96.390, 861.0, 29.3428
55.428015761, 96.390, 832.0, 28.8444
55.480536892, 96.390, 888.0, 29.7993
55.533058022, 96.390, 790.0, 28.1069
55.585579153, 96.390, 825.0, 28.7228
55.638100284, 96.390, 898.0, 29.9666
55.690621414, 96.390, 860.0, 29.3258
55.743142545, 96.390, 845.0, 29.0689
55.795663676, 96.390, 843.0, 29.0345
55.848184807, 96.390, 812.0, 28.4956
55.900705937, 96.390, 801.0, 28.3019
55.953227068, 96.390, 861.0, 29.3428
56.005748199, 96.390, 845.0, 29.0689
56.058269329, 96.390, 788.0, 28.0713
56.110790460, 96.390, 812.0, 28.4956
56.163311591, 96.390, 832.0, 28.8444
56.215832722, 96.390, 870.0, 29.4958
56.268353852, 96.390, 813.0, 28.5132
56.320874983, 96.390, 847.0, 29.1033
56.373396114, 96.390, 784.0, 28.0000
56.425917244, 96.390, 852.0, 29.1890
56.478438375, 96.390, 839.0, 28.9655
56.530959506, 96.390, 840.0, 28.9828
56.583480637, 96.390, 852.0, 29.1890
56.636001767, 96.390, 817.0, 28.5832
56.688522898, 96.390, 812.0, 28.4956
56.741044029, 96.390, 827.0, 28.7576
56.793565159, 96.390, 858.0, 29.2916
56.846086290, 96.390, 815.0, 28.5482
56.898607421, 96.390, 810.0, 28.4605
56.951128551, 96.390, 829.0, 28.7924
57.003649682, 96.390, 884.0, 29.7321
57.056170813, 96.390, 775.0, 27.8388
57.108691944, 96.390, 833.0, 28.8617
57.161213074, 96.390, 748.0, 27.3496
57.213734205, 96.390, 815.0, 28.5482
57.266255336, 96.390, 758.0, 27.5318
57.318776466, 96.390, 821.0, 28.6531
57.371297597, 96.390, 850.0, 29.1548
57.423818728, 96.390, 851.0, 29.1719
57.476339859, 96.390, 816.0, 28.5657
57.528860989, 96.390, 848.0, 29.1204
57.581382120, 96.390, 835.0, 28.8964
57.633903251, 96.390, 762.0, 27.6043
57.686424381, 96.390, 784.0, 28.0000
57.738945512, 96.390, 840.0, 28.9828
57.791466643, 96.390, 826.0, 28.7402
57.843987774, 96.390, 802.0, 28.3196
57.896508904, 96.390, 789.0, 28.0891
57.949030035, 96.390, 831.0, 28.8271
58.001551166, 96.390, 792.0, 28.1425
58.054072296, 96.390, 803.0, 28.3373
58.106593427, 96.390, 859.0, 29.3087
58.159114558, 96.390, 830.0, 28.8097
58.211635689, 96.390, 842.0, 29.0172
58.264156819, 96.390, 839.0, 28.9655
58.316677950, 96.390, 786.0, 28.0357
58.369199081, 96.390, 816.0, 28.5657
58.421720211, 96.390, 818.0, 28.6007
58.474241342, 96.390, 816.0, 28.5657
58.526762473, 96.390, 814.0, 28.5307
58.579283603, 96.390, 805.0, 28.3725
58.631804734, 96.390, 840.0, 28.9828
58.684325865, 96.390, 833.0, 28.8617
58.736846996, 96.390, 763.0, 27.6225
58.789368126, 96.390, 775.0, 27.8388
58.841889257, 96.390, 795.0, 28.1957
58.894410388, 96.390, 809.0, 28.4429
58.946931518, 96.390, 798.0, 28.2489
58.999452649, 96.390, 808.0, 28.4253
59.051973780, 96.390, 849.0, 29.1376
59.104494911, 96.390, 784.0, 28.0000
59.157016041, 96.390, 833.0, 28.8617
59.209537172, 96.390, 782.0, 27.9643
59.262058303, 96.390, 802.0, 28.3196
59.314579433, 96.390, 806.0, 28.3901
59.367100564, 96.390, 811.0, 28.4781
59.419621695, 96.390, 846.0, 29.0861
59.472142826, 96.390, 825.0, 28.7228
59.524663956, 96.390, 849.0, 29.1376
59.577185087, 96.390, 805.0, 28.3725
59.629706218, 96.390, 805.0, 28.3725
59.682227348, 96.390, 823.0, 28.6880
59.734748479, 96.390, 878.0, 29.6311
59.787269610, 96.390, 851.0, 29.1719
59.839790740, 96.390, 881.0, 29.6816
59.892311871, 96.390, 857.0, 29.2746
59.944833002, 96.390, 852.0, 29.1890
59.997354133, 96.390, 833.0, 28.8617
60.049875263, 96.390, 880.0, 29.6648
60.102396394, 96.390, 873.0, 29.5466
60.154917525, 96.390, 899.0, 29.9833
60.207438655, 96.390, 866.0, 29.4279
60.259959786, 96.390, 873.0, 29.5466
60.312480917, 96.390, 925.0, 30.4138
60.365002048, 96.390, 965.0, 31.0644
60.417523178, 96.390, 969.0, 31.1288
60.470044309, 96.390, 978.0, 31.2730
60.522565440, 96.390, 939.0, 30.6431
60.575086570, 96.390, 953.0, 30.8707
60.627607701, 96.390, 959.0, 30.9677
60.680128832, 96.390, 919.0, 30.3150
60.732649963, 96.390, 965.0, 31.0644
60.785171093, 96.390, 1049.0, 32.3883
60.837692224, 96.390, 992.0, 31.4960
60.890213355, 96.390, 972.0, 31.1769
60.942734485, 96.390, 1001.0, 31.6386
60.995255616, 96.390, 1098.0, 33.1361
61.047776747, 96.390, 1045.0, 32.3265
61.100297878, 96.390, 984.0, 31.3688
61.152819008, 96.390, 1058.0, 32.5269
61.205340139, 96.390, 1127.0, 33.5708
61.257861270, 96.390, 1025.0, 32.0156
61.310382400, 96.390, 1132.0, 33.6452
61.362903531, 96.390, 1112.0, 33.3467
61.415424662, 96.390, 1089.0, 33.0000
61.467945792, 96.390, 1096.0, 33.1059
61.520466923, 96.390, 1066.0, 32.6497
61.572988054, 96.390, 1022.0, 31.9687
61.625509185, 96.390, 1059.0, 32.5423
61.678030315, 96.390, 1107.0, 33.2716
61.730551446, 96.390, 1068.0, 32.6803
61.783072577, 96.390, 981.0, 31.3209
61.835593707, 96.390, 1075.0, 32.7872
61.888114838, 96.390, 1024.0, 32.0000
61.940635969, 96.390, 1018.0, 31.9061
61.993157100, 96.390, 1044.0, 32.3110
62.045678230, 96.390, 1006.0, 31.7175
62.098199361, 96.390, 983.0, 31.3528
62.150720492, 96.390, 1022.0, 31.9687
62.203241622, 96.390, 995.0, 31.5436
62.255762753, 96.390, 989.0, 31.4484
62.308283884, 96.390, 949.0, 30.8058
62.360805015, 96.390, 951.0, 30.8383
62.413326145, 96.390, 991.0, 31.4802
62.465847276, 96.390, 958.0, 30.9516
62.518368407, 96.390, 997.0, 31.5753
62.570889537, 96.390, 1002.0, 31.6544
62.623410668, 96.390, 917.0, 30.2820
62.675931799, 96.390, 930.0, 30.4959
62.728452930, 96.390, 920.0, 30.3315
62.780974060, 96.390, 886.0, 29.7658
62.833495191, 96.390, 951.0, 30.8383
62.886016322, 96.390, 905.0, 30.0832
62.938537452, 96.390, 834.0, 28.8791
62.991058583, 96.390, 858.0, 29.2916
63.043579714, 96.390, 869.0, 29.4788
63.096100844, 96.390, 862.0, 29.3598
63.148621975, 96.390, 844.0, 29.0517
63.201143106, 96.390, 916.0, 30.2655
63.253664237, 96.390, 894.0, 29.8998
63.306185367, 96.390, 875.0, 29.5804
63.358706498, 96.390, 817.0, 28.5832
63.411227629, 96.390, 873.0, 29.5466
63.463748759, 96.390, 863.0, 29.3769
63.516269890, 96.390, 845.0, 29.0689
63.568791021, 96.390, 781.0, 27.9464
63.621312152, 96.390, 780.0, 27.9285
63.673833282, 96.390, 797.0, 28.2312
63.726354413, 96.390, 777.0, 27.8747
63.778875544, 96.390, 819.0, 28.6182
63.831396674, 96.390, 831.0, 28.8271
63.883917805, 96.390, 741.0, 27.2213
63.936438936, 96.390, 766.0, 27.6767
63.988960067, 96.390, 793.0, 28.1603
64.041481197, 96.390, 786.0, 28.0357
64.094002328, 96.390, 765.0, 27.6586
64.146523459, 96.390, 760.0, 27.5681
64.199044589, 96.390, 769.0, 27.7308
64.251565720, 96.390, 731.0, 27.0370
64.304086851, 96.390, 726.0, 26.9444
64.356607981, 96.390, 752.0, 27.4226
64.409129112, 96.390, 774.0, 27.8209
64.461650243, 96.390, 762.0, 27.6043
64.514171374, 96.390, 719.0, 26.8142
64.566692504, 96.390, 737.0, 27.1477
64.619213635, 96.390, 725.0, 26.9258
64.671734766, 96.390, 744.0, 27.2764
64.724255896, 96.390, 801.0, 28.3019
64.776777027, 96.390, 740.0, 27.2029
64.829298158, 96.390, 741.0, 27.2213
64.881819289, 96.390, 729.0, 27.0000
64.934340419, 96.390, 765.0, 27.6586
64.986861550, 96.390, 748.0, 27.3496