File: Files_organized_for_plots/Centroid_changing_NaOH/XRDc_Centroid16Mar22_Act21Mar22_B1_0593M_NaOH_LS0153_1.csv
[Measurement conditions]
Sample identification,XRD_Centroid16Mar22_Act21Mar22_B1_0593M_NaOH_LS0153_1
Comment - 1,"Configuration=Stage for Flat Samples/Holders, Owner=User-1, Creation date=7/1/2020 9:53:24 AM"
Comment - 2,"Goniometer=Theta/Theta; Minimum step size 2Theta:0.0001; Minimum step size Omega:0.0001"
Comment - 3,"Sample stage=Stage for flat samples/holders"
Comment - 4,"Diffractometer system=EMPYREAN"
Comment - 5,"Measurement program=C:\Users\ibo5034\OneDrive - The Pennsylvania State University\NEUP\Zerobackground scan.xrdmp, Identifier={98A3B11C-88F9-4AA6-982C-73314A311EF5}"
Anode material,Cu
K-Alpha1 wavelength,1.5405980
K-Alpha2 wavelength,1.5444260
Ratio K-Alpha2/K-Alpha1,0.500
Divergence slit,Fixed,0.25
Monochromator used,NO
Generator voltage, 45
Tube current, 40
File date and time,24/Mar/2022 18:01
Unit cell,
h k l, 0 0 0
Scan axis,Gonio
Scan range,4.994599997,64.999991833
Scan step size,0.0262606
No. of points, 2285
Scan type,CONTINUOUS
Time per step,96.390
[Scan points]
Angle, TimePerStep, Intensity, ESD
5.007730280, 96.390, 4639.0, 68.1102
5.060251411, 96.390, 4514.0, 67.1863
5.112772541, 96.390, 4610.0, 67.8970
5.165293672, 96.390, 4542.0, 67.3944
5.217814803, 96.390, 4577.0, 67.6535
5.270335934, 96.390, 4379.0, 66.1740
5.322857064, 96.390, 4457.0, 66.7608
5.375378195, 96.390, 4458.0, 66.7683
5.427899326, 96.390, 4231.0, 65.0461
5.480420456, 96.390, 4315.0, 65.6887
5.532941587, 96.390, 4226.0, 65.0077
5.585462718, 96.390, 4311.0, 65.6582
5.637983849, 96.390, 4222.0, 64.9769
5.690504979, 96.390, 4250.0, 65.1920
5.743026110, 96.390, 4177.0, 64.6297
5.795547241, 96.390, 4155.0, 64.4593
5.848068371, 96.390, 4225.0, 65.0000
5.900589502, 96.390, 4082.0, 63.8905
5.953110633, 96.390, 4250.0, 65.1920
6.005631763, 96.390, 4113.0, 64.1327
6.058152894, 96.390, 4126.0, 64.2339
6.110674025, 96.390, 4126.0, 64.2339
6.163195156, 96.390, 4105.0, 64.0703
6.215716286, 96.390, 4154.0, 64.4515
6.268237417, 96.390, 4137.0, 64.3195
6.320758548, 96.390, 4146.0, 64.3894
6.373279678, 96.390, 4075.0, 63.8357
6.425800809, 96.390, 4105.0, 64.0703
6.478321940, 96.390, 4056.0, 63.6867
6.530843071, 96.390, 4043.0, 63.5846
6.583364201, 96.390, 3964.0, 62.9603
6.635885332, 96.390, 4071.0, 63.8044
6.688406463, 96.390, 4127.0, 64.2417
6.740927593, 96.390, 3999.0, 63.2376
6.793448724, 96.390, 3898.0, 62.4340
6.845969855, 96.390, 3982.0, 63.1031
6.898490986, 96.390, 3995.0, 63.2060
6.951012116, 96.390, 3999.0, 63.2376
7.003533247, 96.390, 4090.0, 63.9531
7.056054378, 96.390, 3960.0, 62.9285
7.108575508, 96.390, 3964.0, 62.9603
7.161096639, 96.390, 3933.0, 62.7136
7.213617770, 96.390, 3812.0, 61.7414
7.266138900, 96.390, 3909.0, 62.5220
7.318660031, 96.390, 3897.0, 62.4260
7.371181162, 96.390, 3836.0, 61.9355
7.423702293, 96.390, 3945.0, 62.8092
7.476223423, 96.390, 4004.0, 63.2772
7.528744554, 96.390, 3864.0, 62.1611
7.581265685, 96.390, 3781.0, 61.4898
7.633786815, 96.390, 3842.0, 61.9839
7.686307946, 96.390, 3766.0, 61.3677
7.738829077, 96.390, 3758.0, 61.3025
7.791350208, 96.390, 3920.0, 62.6099
7.843871338, 96.390, 3786.0, 61.5305
7.896392469, 96.390, 3807.0, 61.7009
7.948913600, 96.390, 3708.0, 60.8933
8.001434730, 96.390, 3709.0, 60.9016
8.053955861, 96.390, 3841.0, 61.9758
8.106476992, 96.390, 3708.0, 60.8933
8.158998123, 96.390, 3761.0, 61.3270
8.211519253, 96.390, 3774.0, 61.4329
8.264040384, 96.390, 3681.0, 60.6712
8.316561515, 96.390, 3871.0, 62.2174
8.369082645, 96.390, 3723.0, 61.0164
8.421603776, 96.390, 3669.0, 60.5723
8.474124907, 96.390, 3540.0, 59.4979
8.526646038, 96.390, 3612.0, 60.0999
8.579167168, 96.390, 3707.0, 60.8851
8.631688299, 96.390, 3653.0, 60.4401
8.684209430, 96.390, 3676.0, 60.6300
8.736730560, 96.390, 3656.0, 60.4649
8.789251691, 96.390, 3672.0, 60.5970
8.841772822, 96.390, 3484.0, 59.0254
8.894293952, 96.390, 3593.0, 59.9416
8.946815083, 96.390, 3474.0, 58.9406
8.999336214, 96.390, 3546.0, 59.5483
9.051857345, 96.390, 3535.0, 59.4559
9.104378475, 96.390, 3426.0, 58.5320
9.156899606, 96.390, 3515.0, 59.2874
9.209420737, 96.390, 3532.0, 59.4306
9.261941867, 96.390, 3455.0, 58.7792
9.314462998, 96.390, 3543.0, 59.5231
9.366984129, 96.390, 3564.0, 59.6992
9.419505260, 96.390, 3510.0, 59.2453
9.472026390, 96.390, 3579.0, 59.8247
9.524547521, 96.390, 3420.0, 58.4808
9.577068652, 96.390, 3339.0, 57.7841
9.629589782, 96.390, 3365.0, 58.0086
9.682110913, 96.390, 3437.0, 58.6259
9.734632044, 96.390, 3365.0, 58.0086
9.787153175, 96.390, 3259.0, 57.0877
9.839674305, 96.390, 3495.0, 59.1185
9.892195436, 96.390, 3432.0, 58.5833
9.944716567, 96.390, 3341.0, 57.8014
9.997237697, 96.390, 3325.0, 57.6628
10.049758828, 96.390, 3313.0, 57.5587
10.102279959, 96.390, 3329.0, 57.6975
10.154801090, 96.390, 3396.0, 58.2752
10.207322220, 96.390, 3307.0, 57.5065
10.259843351, 96.390, 3378.0, 58.1206
10.312364482, 96.390, 3162.0, 56.2317
10.364885612, 96.390, 3327.0, 57.6802
10.417406743, 96.390, 3265.0, 57.1402
10.469927874, 96.390, 3226.0, 56.7979
10.522449004, 96.390, 3215.0, 56.7010
10.574970135, 96.390, 3258.0, 57.0789
10.627491266, 96.390, 3182.0, 56.4092
10.680012397, 96.390, 3240.0, 56.9210
10.732533527, 96.390, 3215.0, 56.7010
10.785054658, 96.390, 3226.0, 56.7979
10.837575789, 96.390, 3194.0, 56.5155
10.890096919, 96.390, 3083.0, 55.5248
10.942618050, 96.390, 3258.0, 57.0789
10.995139181, 96.390, 3196.0, 56.5332
11.047660312, 96.390, 3128.0, 55.9285
11.100181442, 96.390, 3103.0, 55.7046
11.152702573, 96.390, 3154.0, 56.1605
11.205223704, 96.390, 3100.0, 55.6776
11.257744834, 96.390, 3142.0, 56.0535
11.310265965, 96.390, 3011.0, 54.8726
11.362787096, 96.390, 3089.0, 55.5788
11.415308227, 96.390, 2952.0, 54.3323
11.467829357, 96.390, 2992.0, 54.6992
11.520350488, 96.390, 3018.0, 54.9363
11.572871619, 96.390, 3005.0, 54.8179
11.625392749, 96.390, 3004.0, 54.8088
11.677913880, 96.390, 2965.0, 54.4518
11.730435011, 96.390, 2890.0, 53.7587
11.782956141, 96.390, 2925.0, 54.0833
11.835477272, 96.390, 2880.0, 53.6656
11.887998403, 96.390, 2900.0, 53.8516
11.940519534, 96.390, 2994.0, 54.7175
11.993040664, 96.390, 2919.0, 54.0278
12.045561795, 96.390, 2873.0, 53.6004
12.098082926, 96.390, 2874.0, 53.6097
12.150604056, 96.390, 2804.0, 52.9528
12.203125187, 96.390, 2856.0, 53.4416
12.255646318, 96.390, 2866.0, 53.5350
12.308167449, 96.390, 2707.0, 52.0288
12.360688579, 96.390, 2776.0, 52.6878
12.413209710, 96.390, 2858.0, 53.4603
12.465730841, 96.390, 2789.0, 52.8110
12.518251971, 96.390, 2675.0, 51.7204
12.570773102, 96.390, 2764.0, 52.5738
12.623294233, 96.390, 2665.0, 51.6236
12.675815364, 96.390, 2633.0, 51.3128
12.728336494, 96.390, 2737.0, 52.3163
12.780857625, 96.390, 2700.0, 51.9615
12.833378756, 96.390, 2642.0, 51.4004
12.885899886, 96.390, 2666.0, 51.6333
12.938421017, 96.390, 2604.0, 51.0294
12.990942148, 96.390, 2723.0, 52.1824
13.043463279, 96.390, 2633.0, 51.3128
13.095984409, 96.390, 2550.0, 50.4975
13.148505540, 96.390, 2540.0, 50.3984
13.201026671, 96.390, 2552.0, 50.5173
13.253547801, 96.390, 2667.0, 51.6430
13.306068932, 96.390, 2619.0, 51.1762
13.358590063, 96.390, 2493.0, 49.9300
13.411111193, 96.390, 2658.0, 51.5558
13.463632324, 96.390, 2548.0, 50.4777
13.516153455, 96.390, 2569.0, 50.6853
13.568674586, 96.390, 2556.0, 50.5569
13.621195716, 96.390, 2566.0, 50.6557
13.673716847, 96.390, 2604.0, 51.0294
13.726237978, 96.390, 2359.0, 48.5695
13.778759108, 96.390, 2493.0, 49.9300
13.831280239, 96.390, 2520.0, 50.1996
13.883801370, 96.390, 2424.0, 49.2341
13.936322501, 96.390, 2489.0, 49.8899
13.988843631, 96.390, 2484.0, 49.8397
14.041364762, 96.390, 2446.0, 49.4571
14.093885893, 96.390, 2473.0, 49.7293
14.146407023, 96.390, 2484.0, 49.8397
14.198928154, 96.390, 2464.0, 49.6387
14.251449285, 96.390, 2441.0, 49.4065
14.303970416, 96.390, 2476.0, 49.7594
14.356491546, 96.390, 2388.0, 48.8672
14.409012677, 96.390, 2374.0, 48.7237
14.461533808, 96.390, 2375.0, 48.7340
14.514054938, 96.390, 2397.0, 48.9592
14.566576069, 96.390, 2496.0, 49.9600
14.619097200, 96.390, 2441.0, 49.4065
14.671618331, 96.390, 2340.0, 48.3735
14.724139461, 96.390, 2318.0, 48.1456
14.776660592, 96.390, 2375.0, 48.7340
14.829181723, 96.390, 2398.0, 48.9694
14.881702853, 96.390, 2424.0, 49.2341
14.934223984, 96.390, 2302.0, 47.9792
14.986745115, 96.390, 2376.0, 48.7442
15.039266245, 96.390, 2348.0, 48.4562
15.091787376, 96.390, 2340.0, 48.3735
15.144308507, 96.390, 2363.0, 48.6107
15.196829638, 96.390, 2309.0, 48.0521
15.249350768, 96.390, 2328.0, 48.2494
15.301871899, 96.390, 2437.0, 49.3660
15.354393030, 96.390, 2380.0, 48.7852
15.406914160, 96.390, 2279.0, 47.7389
15.459435291, 96.390, 2269.0, 47.6340
15.511956422, 96.390, 2351.0, 48.4871
15.564477553, 96.390, 2318.0, 48.1456
15.616998683, 96.390, 2340.0, 48.3735
15.669519814, 96.390, 2276.0, 47.7074
15.722040945, 96.390, 2328.0, 48.2494
15.774562075, 96.390, 2283.0, 47.7807
15.827083206, 96.390, 2260.0, 47.5395
15.879604337, 96.390, 2329.0, 48.2597
15.932125468, 96.390, 2257.0, 47.5079
15.984646598, 96.390, 2419.0, 49.1833
16.037167729, 96.390, 2234.0, 47.2652
16.089688860, 96.390, 2282.0, 47.7703
16.142209990, 96.390, 2244.0, 47.3709
16.194731121, 96.390, 2289.0, 47.8435
16.247252252, 96.390, 2321.0, 48.1768
16.299773382, 96.390, 2292.0, 47.8748
16.352294513, 96.390, 2345.0, 48.4252
16.404815644, 96.390, 2335.0, 48.3218
16.457336775, 96.390, 2274.0, 47.6865
16.509857905, 96.390, 2355.0, 48.5283
16.562379036, 96.390, 2323.0, 48.1975
16.614900167, 96.390, 2294.0, 47.8957
16.667421297, 96.390, 2337.0, 48.3425
16.719942428, 96.390, 2239.0, 47.3181
16.772463559, 96.390, 2368.0, 48.6621
16.824984690, 96.390, 2303.0, 47.9896
16.877505820, 96.390, 2365.0, 48.6313
16.930026951, 96.390, 2421.0, 49.2037
16.982548082, 96.390, 2333.0, 48.3011
17.035069212, 96.390, 2376.0, 48.7442
17.087590343, 96.390, 2373.0, 48.7134
17.140111474, 96.390, 2437.0, 49.3660
17.192632605, 96.390, 2356.0, 48.5386
17.245153735, 96.390, 2374.0, 48.7237
17.297674866, 96.390, 2347.0, 48.4458
17.350195997, 96.390, 2410.0, 49.0918
17.402717127, 96.390, 2364.0, 48.6210
17.455238258, 96.390, 2469.0, 49.6890
17.507759389, 96.390, 2327.0, 48.2390
17.560280520, 96.390, 2342.0, 48.3942
17.612801650, 96.390, 2417.0, 49.1630
17.665322781, 96.390, 2401.0, 49.0000
17.717843912, 96.390, 2377.0, 48.7545
17.770365042, 96.390, 2439.0, 49.3862
17.822886173, 96.390, 2465.0, 49.6488
17.875407304, 96.390, 2329.0, 48.2597
17.927928434, 96.390, 2481.0, 49.8096
17.980449565, 96.390, 2428.0, 49.2747
18.032970696, 96.390, 2458.0, 49.5782
18.085491827, 96.390, 2522.0, 50.2195
18.138012957, 96.390, 2477.0, 49.7695
18.190534088, 96.390, 2527.0, 50.2693
18.243055219, 96.390, 2429.0, 49.2849
18.295576349, 96.390, 2370.0, 48.6826
18.348097480, 96.390, 2462.0, 49.6185
18.400618611, 96.390, 2517.0, 50.1697
18.453139742, 96.390, 2485.0, 49.8498
18.505660872, 96.390, 2509.0, 50.0899
18.558182003, 96.390, 2537.0, 50.3686
18.610703134, 96.390, 2549.0, 50.4876
18.663224264, 96.390, 2537.0, 50.3686
18.715745395, 96.390, 2497.0, 49.9700
18.768266526, 96.390, 2519.0, 50.1896
18.820787657, 96.390, 2473.0, 49.7293
18.873308787, 96.390, 2569.0, 50.6853
18.925829918, 96.390, 2602.0, 51.0098
18.978351049, 96.390, 2568.0, 50.6754
19.030872179, 96.390, 2568.0, 50.6754
19.083393310, 96.390, 2569.0, 50.6853
19.135914441, 96.390, 2513.0, 50.1298
19.188435572, 96.390, 2601.0, 51.0000
19.240956702, 96.390, 2553.0, 50.5272
19.293477833, 96.390, 2558.0, 50.5767
19.345998964, 96.390, 2670.0, 51.6720
19.398520094, 96.390, 2700.0, 51.9615
19.451041225, 96.390, 2616.0, 51.1468
19.503562356, 96.390, 2670.0, 51.6720
19.556083486, 96.390, 2574.0, 50.7346
19.608604617, 96.390, 2629.0, 51.2738
19.661125748, 96.390, 2759.0, 52.5262
19.713646879, 96.390, 2717.0, 52.1249
19.766168009, 96.390, 2709.0, 52.0481
19.818689140, 96.390, 2752.0, 52.4595
19.871210271, 96.390, 2714.0, 52.0961
19.923731401, 96.390, 2746.0, 52.4023
19.976252532, 96.390, 2737.0, 52.3163
20.028773663, 96.390, 2686.0, 51.8266
20.081294794, 96.390, 2677.0, 51.7397
20.133815924, 96.390, 2758.0, 52.5167
20.186337055, 96.390, 2805.0, 52.9623
20.238858186, 96.390, 2692.0, 51.8845
20.291379316, 96.390, 2760.0, 52.5357
20.343900447, 96.390, 2745.0, 52.3927
20.396421578, 96.390, 2753.0, 52.4690
20.448942709, 96.390, 2692.0, 51.8845
20.501463839, 96.390, 2742.0, 52.3641
20.553984970, 96.390, 2766.0, 52.5928
20.606506101, 96.390, 2849.0, 53.3760
20.659027231, 96.390, 2827.0, 53.1695
20.711548362, 96.390, 2821.0, 53.1131
20.764069493, 96.390, 2862.0, 53.4977
20.816590623, 96.390, 2804.0, 52.9528
20.869111754, 96.390, 2821.0, 53.1131
20.921632885, 96.390, 2793.0, 52.8488
20.974154016, 96.390, 2820.0, 53.1037
21.026675146, 96.390, 2819.0, 53.0943
21.079196277, 96.390, 2796.0, 52.8772
21.131717408, 96.390, 2722.0, 52.1728
21.184238538, 96.390, 2900.0, 53.8516
21.236759669, 96.390, 2852.0, 53.4041
21.289280800, 96.390, 2890.0, 53.7587
21.341801931, 96.390, 2796.0, 52.8772
21.394323061, 96.390, 2867.0, 53.5444
21.446844192, 96.390, 2767.0, 52.6023
21.499365323, 96.390, 2651.0, 51.4879
21.551886453, 96.390, 2785.0, 52.7731
21.604407584, 96.390, 2810.0, 53.0094
21.656928715, 96.390, 2735.0, 52.2972
21.709449846, 96.390, 2868.0, 53.5537
21.761970976, 96.390, 2721.0, 52.1632
21.814492107, 96.390, 2818.0, 53.0848
21.867013238, 96.390, 2760.0, 52.5357
21.919534368, 96.390, 2828.0, 53.1789
21.972055499, 96.390, 2866.0, 53.5350
22.024576630, 96.390, 2780.0, 52.7257
22.077097761, 96.390, 2816.0, 53.0660
22.129618891, 96.390, 2811.0, 53.0189
22.182140022, 96.390, 2765.0, 52.5833
22.234661153, 96.390, 2764.0, 52.5738
22.287182283, 96.390, 2867.0, 53.5444
22.339703414, 96.390, 2739.0, 52.3355
22.392224545, 96.390, 2797.0, 52.8867
22.444745675, 96.390, 2800.0, 52.9150
22.497266806, 96.390, 2710.0, 52.0577
22.549787937, 96.390, 2878.0, 53.6470
22.602309068, 96.390, 2794.0, 52.8583
22.654830198, 96.390, 2666.0, 51.6333
22.707351329, 96.390, 2898.0, 53.8331
22.759872460, 96.390, 2882.0, 53.6843
22.812393590, 96.390, 2859.0, 53.4696
22.864914721, 96.390, 2802.0, 52.9339
22.917435852, 96.390, 2809.0, 53.0000
22.969956983, 96.390, 2918.0, 54.0185
23.022478113, 96.390, 2807.0, 52.9811
23.074999244, 96.390, 2591.0, 50.9019
23.127520375, 96.390, 2686.0, 51.8266
23.180041505, 96.390, 2766.0, 52.5928
23.232562636, 96.390, 2732.0, 52.2685
23.285083767, 96.390, 2789.0, 52.8110
23.337604898, 96.390, 2767.0, 52.6023
23.390126028, 96.390, 2741.0, 52.3546
23.442647159, 96.390, 2659.0, 51.5655
23.495168290, 96.390, 2729.0, 52.2398
23.547689420, 96.390, 2649.0, 51.4684
23.600210551, 96.390, 2755.0, 52.4881
23.652731682, 96.390, 2676.0, 51.7301
23.705252813, 96.390, 2647.0, 51.4490
23.757773943, 96.390, 2699.0, 51.9519
23.810295074, 96.390, 2695.0, 51.9134
23.862816205, 96.390, 2676.0, 51.7301
23.915337335, 96.390, 2610.0, 51.0882
23.967858466, 96.390, 2665.0, 51.6236
24.020379597, 96.390, 2660.0, 51.5752
24.072900727, 96.390, 2495.0, 49.9500
24.125421858, 96.390, 2582.0, 50.8134
24.177942989, 96.390, 2557.0, 50.5668
24.230464120, 96.390, 2531.0, 50.3090
24.282985250, 96.390, 2502.0, 50.0200
24.335506381, 96.390, 2417.0, 49.1630
24.388027512, 96.390, 2536.0, 50.3587
24.440548642, 96.390, 2438.0, 49.3761
24.493069773, 96.390, 2458.0, 49.5782
24.545590904, 96.390, 2418.0, 49.1732
24.598112035, 96.390, 2496.0, 49.9600
24.650633165, 96.390, 2412.0, 49.1121
24.703154296, 96.390, 2461.0, 49.6085
24.755675427, 96.390, 2439.0, 49.3862
24.808196557, 96.390, 2411.0, 49.1019
24.860717688, 96.390, 2411.0, 49.1019
24.913238819, 96.390, 2388.0, 48.8672
24.965759950, 96.390, 2402.0, 49.0102
25.018281080, 96.390, 2358.0, 48.5592
25.070802211, 96.390, 2419.0, 49.1833
25.123323342, 96.390, 2450.0, 49.4975
25.175844472, 96.390, 2307.0, 48.0312
25.228365603, 96.390, 2371.0, 48.6929
25.280886734, 96.390, 2331.0, 48.2804
25.333407864, 96.390, 2454.0, 49.5379
25.385928995, 96.390, 2272.0, 47.6655
25.438450126, 96.390, 2310.0, 48.0625
25.490971257, 96.390, 2301.0, 47.9687
25.543492387, 96.390, 2302.0, 47.9792
25.596013518, 96.390, 2317.0, 48.1352
25.648534649, 96.390, 2305.0, 48.0104
25.701055779, 96.390, 2305.0, 48.0104
25.753576910, 96.390, 2237.0, 47.2969
25.806098041, 96.390, 2159.0, 46.4650
25.858619172, 96.390, 2210.0, 47.0106
25.911140302, 96.390, 2237.0, 47.2969
25.963661433, 96.390, 2301.0, 47.9687
26.016182564, 96.390, 2151.0, 46.3789
26.068703694, 96.390, 2152.0, 46.3897
26.121224825, 96.390, 2173.0, 46.6154
26.173745956, 96.390, 2242.0, 47.3498
26.226267087, 96.390, 2184.0, 46.7333
26.278788217, 96.390, 2234.0, 47.2652
26.331309348, 96.390, 2210.0, 47.0106
26.383830479, 96.390, 2218.0, 47.0956
26.436351609, 96.390, 2096.0, 45.7821
26.488872740, 96.390, 2200.0, 46.9042
26.541393871, 96.390, 2233.0, 47.2546
26.593915002, 96.390, 2193.0, 46.8295
26.646436132, 96.390, 2153.0, 46.4004
26.698957263, 96.390, 2073.0, 45.5302
26.751478394, 96.390, 2154.0, 46.4112
26.803999524, 96.390, 2190.0, 46.7974
26.856520655, 96.390, 2125.0, 46.0977
26.909041786, 96.390, 2183.0, 46.7226
26.961562916, 96.390, 2102.0, 45.8476
27.014084047, 96.390, 2091.0, 45.7275
27.066605178, 96.390, 2120.0, 46.0435
27.119126309, 96.390, 2121.0, 46.0543
27.171647439, 96.390, 2182.0, 46.7119
27.224168570, 96.390, 2159.0, 46.4650
27.276689701, 96.390, 2095.0, 45.7712
27.329210831, 96.390, 2117.0, 46.0109
27.381731962, 96.390, 2079.0, 45.5961
27.434253093, 96.390, 2062.0, 45.4093
27.486774224, 96.390, 2070.0, 45.4973
27.539295354, 96.390, 2158.0, 46.4543
27.591816485, 96.390, 2088.0, 45.6946
27.644337616, 96.390, 2183.0, 46.7226
27.696858746, 96.390, 2193.0, 46.8295
27.749379877, 96.390, 2124.0, 46.0869
27.801901008, 96.390, 2063.0, 45.4203
27.854422139, 96.390, 2110.0, 45.9347
27.906943269, 96.390, 2107.0, 45.9021
27.959464400, 96.390, 2176.0, 46.6476
28.011985531, 96.390, 2179.0, 46.6798
28.064506661, 96.390, 2107.0, 45.9021
28.117027792, 96.390, 2139.0, 46.2493
28.169548923, 96.390, 2112.0, 45.9565
28.222070054, 96.390, 2073.0, 45.5302
28.274591184, 96.390, 2133.0, 46.1844
28.327112315, 96.390, 2140.0, 46.2601
28.379633446, 96.390, 2147.0, 46.3357
28.432154576, 96.390, 2088.0, 45.6946
28.484675707, 96.390, 2065.0, 45.4423
28.537196838, 96.390, 2170.0, 46.5833
28.589717968, 96.390, 2128.0, 46.1303
28.642239099, 96.390, 2165.0, 46.5296
28.694760230, 96.390, 2133.0, 46.1844
28.747281361, 96.390, 2095.0, 45.7712
28.799802491, 96.390, 2159.0, 46.4650
28.852323622, 96.390, 2164.0, 46.5188
28.904844753, 96.390, 2060.0, 45.3872
28.957365883, 96.390, 2193.0, 46.8295
29.009887014, 96.390, 2147.0, 46.3357
29.062408145, 96.390, 2164.0, 46.5188
29.114929276, 96.390, 2130.0, 46.1519
29.167450406, 96.390, 2076.0, 45.5631
29.219971537, 96.390, 2155.0, 46.4220
29.272492668, 96.390, 2159.0, 46.4650
29.325013798, 96.390, 2180.0, 46.6905
29.377534929, 96.390, 2117.0, 46.0109
29.430056060, 96.390, 2169.0, 46.5725
29.482577191, 96.390, 2069.0, 45.4863
29.535098321, 96.390, 2136.0, 46.2169
29.587619452, 96.390, 2131.0, 46.1628
29.640140583, 96.390, 2191.0, 46.8081
29.692661713, 96.390, 2097.0, 45.7930
29.745182844, 96.390, 2030.0, 45.0555
29.797703975, 96.390, 2096.0, 45.7821
29.850225105, 96.390, 2167.0, 46.5510
29.902746236, 96.390, 2191.0, 46.8081
29.955267367, 96.390, 2096.0, 45.7821
30.007788498, 96.390, 2103.0, 45.8585
30.060309628, 96.390, 2133.0, 46.1844
30.112830759, 96.390, 2145.0, 46.3141
30.165351890, 96.390, 2171.0, 46.5940
30.217873020, 96.390, 2160.0, 46.4758
30.270394151, 96.390, 2112.0, 45.9565
30.322915282, 96.390, 2114.0, 45.9783
30.375436413, 96.390, 2258.0, 47.5184
30.427957543, 96.390, 2108.0, 45.9130
30.480478674, 96.390, 2287.0, 47.8226
30.532999805, 96.390, 2116.0, 46.0000
30.585520935, 96.390, 2032.0, 45.0777
30.638042066, 96.390, 2162.0, 46.4973
30.690563197, 96.390, 2292.0, 47.8748
30.743084328, 96.390, 2211.0, 47.0213
30.795605458, 96.390, 2111.0, 45.9456
30.848126589, 96.390, 2228.0, 47.2017
30.900647720, 96.390, 2152.0, 46.3897
30.953168850, 96.390, 2125.0, 46.0977
31.005689981, 96.390, 2186.0, 46.7547
31.058211112, 96.390, 2184.0, 46.7333
31.110732243, 96.390, 2194.0, 46.8402
31.163253373, 96.390, 2119.0, 46.0326
31.215774504, 96.390, 2147.0, 46.3357
31.268295635, 96.390, 2166.0, 46.5403
31.320816765, 96.390, 2138.0, 46.2385
31.373337896, 96.390, 2192.0, 46.8188
31.425859027, 96.390, 2135.0, 46.2061
31.478380157, 96.390, 2148.0, 46.3465
31.530901288, 96.390, 2202.0, 46.9255
31.583422419, 96.390, 2197.0, 46.8722
31.635943550, 96.390, 2106.0, 45.8912
31.688464680, 96.390, 2070.0, 45.4973
31.740985811, 96.390, 2270.0, 47.6445
31.793506942, 96.390, 2112.0, 45.9565
31.846028072, 96.390, 2181.0, 46.7012
31.898549203, 96.390, 2115.0, 45.9891
31.951070334, 96.390, 2192.0, 46.8188
32.003591465, 96.390, 2103.0, 45.8585
32.056112595, 96.390, 2235.0, 47.2758
32.108633726, 96.390, 2283.0, 47.7807
32.161154857, 96.390, 2217.0, 47.0850
32.213675987, 96.390, 2137.0, 46.2277
32.266197118, 96.390, 2094.0, 45.7602
32.318718249, 96.390, 2066.0, 45.4533
32.371239380, 96.390, 2048.0, 45.2548
32.423760510, 96.390, 2124.0, 46.0869
32.476281641, 96.390, 2155.0, 46.4220
32.528802772, 96.390, 2206.0, 46.9681
32.581323902, 96.390, 2081.0, 45.6180
32.633845033, 96.390, 2105.0, 45.8803
32.686366164, 96.390, 2085.0, 45.6618
32.738887295, 96.390, 2119.0, 46.0326
32.791408425, 96.390, 2144.0, 46.3033
32.843929556, 96.390, 2032.0, 45.0777
32.896450687, 96.390, 2110.0, 45.9347
32.948971817, 96.390, 2162.0, 46.4973
33.001492948, 96.390, 2136.0, 46.2169
33.054014079, 96.390, 2097.0, 45.7930
33.106535209, 96.390, 2093.0, 45.7493
33.159056340, 96.390, 2080.0, 45.6070
33.211577471, 96.390, 2128.0, 46.1303
33.264098602, 96.390, 2034.0, 45.0999
33.316619732, 96.390, 2086.0, 45.6727
33.369140863, 96.390, 2092.0, 45.7384
33.421661994, 96.390, 2178.0, 46.6690
33.474183124, 96.390, 2057.0, 45.3542
33.526704255, 96.390, 2026.0, 45.0111
33.579225386, 96.390, 2061.0, 45.3982
33.631746517, 96.390, 2128.0, 46.1303
33.684267647, 96.390, 2159.0, 46.4650
33.736788778, 96.390, 2113.0, 45.9674
33.789309909, 96.390, 2146.0, 46.3249
33.841831039, 96.390, 2160.0, 46.4758
33.894352170, 96.390, 2054.0, 45.3211
33.946873301, 96.390, 2214.0, 47.0532
33.999394432, 96.390, 2264.0, 47.5815
34.051915562, 96.390, 2243.0, 47.3603
34.104436693, 96.390, 2283.0, 47.7807
34.156957824, 96.390, 2290.0, 47.8539
34.209478954, 96.390, 2203.0, 46.9361
34.262000085, 96.390, 2341.0, 48.3839
34.314521216, 96.390, 2274.0, 47.6865
34.367042346, 96.390, 2297.0, 47.9270
34.419563477, 96.390, 2321.0, 48.1768
34.472084608, 96.390, 2371.0, 48.6929
34.524605739, 96.390, 2417.0, 49.1630
34.577126869, 96.390, 2373.0, 48.7134
34.629648000, 96.390, 2358.0, 48.5592
34.682169131, 96.390, 2358.0, 48.5592
34.734690261, 96.390, 2333.0, 48.3011
34.787211392, 96.390, 2302.0, 47.9792
34.839732523, 96.390, 2399.0, 48.9796
34.892253654, 96.390, 2343.0, 48.4045
34.944774784, 96.390, 2454.0, 49.5379
34.997295915, 96.390, 2379.0, 48.7750
35.049817046, 96.390, 2278.0, 47.7284
35.102338176, 96.390, 2356.0, 48.5386
35.154859307, 96.390, 2344.0, 48.4149
35.207380438, 96.390, 2323.0, 48.1975
35.259901569, 96.390, 2256.0, 47.4974
35.312422699, 96.390, 2273.0, 47.6760
35.364943830, 96.390, 2313.0, 48.0937
35.417464961, 96.390, 2302.0, 47.9792
35.469986091, 96.390, 2237.0, 47.2969
35.522507222, 96.390, 2261.0, 47.5500
35.575028353, 96.390, 2248.0, 47.4131
35.627549484, 96.390, 2273.0, 47.6760
35.680070614, 96.390, 2209.0, 47.0000
35.732591745, 96.390, 2274.0, 47.6865
35.785112876, 96.390, 2242.0, 47.3498
35.837634006, 96.390, 2188.0, 46.7761
35.890155137, 96.390, 2202.0, 46.9255
35.942676268, 96.390, 2259.0, 47.5289
35.995197398, 96.390, 2146.0, 46.3249
36.047718529, 96.390, 2136.0, 46.2169
36.100239660, 96.390, 2127.0, 46.1194
36.152760791, 96.390, 2087.0, 45.6837
36.205281921, 96.390, 2073.0, 45.5302
36.257803052, 96.390, 2155.0, 46.4220
36.310324183, 96.390, 2109.0, 45.9239
36.362845313, 96.390, 2108.0, 45.9130
36.415366444, 96.390, 2005.0, 44.7772
36.467887575, 96.390, 2005.0, 44.7772
36.520408706, 96.390, 2037.0, 45.1331
36.572929836, 96.390, 1912.0, 43.7264
36.625450967, 96.390, 2065.0, 45.4423
36.677972098, 96.390, 1967.0, 44.3509
36.730493228, 96.390, 1943.0, 44.0795
36.783014359, 96.390, 2028.0, 45.0333
36.835535490, 96.390, 1909.0, 43.6921
36.888056621, 96.390, 1953.0, 44.1928
36.940577751, 96.390, 1975.0, 44.4410
36.993098882, 96.390, 1959.0, 44.2606
37.045620013, 96.390, 1903.0, 43.6234
37.098141143, 96.390, 1833.0, 42.8135
37.150662274, 96.390, 1859.0, 43.1161
37.203183405, 96.390, 1883.0, 43.3935
37.255704535, 96.390, 1900.0, 43.5890
37.308225666, 96.390, 1851.0, 43.0232
37.360746797, 96.390, 1896.0, 43.5431
37.413267928, 96.390, 1803.0, 42.4617
37.465789058, 96.390, 1830.0, 42.7785
37.518310189, 96.390, 1907.0, 43.6692
37.570831320, 96.390, 1872.0, 43.2666
37.623352450, 96.390, 1762.0, 41.9762
37.675873581, 96.390, 1863.0, 43.1625
37.728394712, 96.390, 1812.0, 42.5676
37.780915843, 96.390, 1833.0, 42.8135
37.833436973, 96.390, 1827.0, 42.7434
37.885958104, 96.390, 1772.0, 42.0951
37.938479235, 96.390, 1765.0, 42.0119
37.991000365, 96.390, 1690.0, 41.1096
38.043521496, 96.390, 1798.0, 42.4028
38.096042627, 96.390, 1757.0, 41.9166
38.148563758, 96.390, 1753.0, 41.8688
38.201084888, 96.390, 1617.0, 40.2119
38.253606019, 96.390, 1740.0, 41.7133
38.306127150, 96.390, 1817.0, 42.6263
38.358648280, 96.390, 1745.0, 41.7732
38.411169411, 96.390, 1680.0, 40.9878
38.463690542, 96.390, 1762.0, 41.9762
38.516211673, 96.390, 1724.0, 41.5211
38.568732803, 96.390, 1672.0, 40.8901
38.621253934, 96.390, 1690.0, 41.1096
38.673775065, 96.390, 1695.0, 41.1704
38.726296195, 96.390, 1634.0, 40.4228
38.778817326, 96.390, 1687.0, 41.0731
38.831338457, 96.390, 1620.0, 40.2492
38.883859587, 96.390, 1754.0, 41.8808
38.936380718, 96.390, 1641.0, 40.5093
38.988901849, 96.390, 1658.0, 40.7185
39.041422980, 96.390, 1642.0, 40.5216
39.093944110, 96.390, 1570.0, 39.6232
39.146465241, 96.390, 1616.0, 40.1995
39.198986372, 96.390, 1583.0, 39.7869
39.251507502, 96.390, 1587.0, 39.8372
39.304028633, 96.390, 1629.0, 40.3609
39.356549764, 96.390, 1610.0, 40.1248
39.409070895, 96.390, 1651.0, 40.6325
39.461592025, 96.390, 1597.0, 39.9625
39.514113156, 96.390, 1584.0, 39.7995
39.566634287, 96.390, 1571.0, 39.6358
39.619155417, 96.390, 1616.0, 40.1995
39.671676548, 96.390, 1525.0, 39.0512
39.724197679, 96.390, 1556.0, 39.4462
39.776718810, 96.390, 1451.0, 38.0920
39.829239940, 96.390, 1548.0, 39.3446
39.881761071, 96.390, 1536.0, 39.1918
39.934282202, 96.390, 1483.0, 38.5097
39.986803332, 96.390, 1563.0, 39.5348
40.039324463, 96.390, 1504.0, 38.7814
40.091845594, 96.390, 1452.0, 38.1051
40.144366725, 96.390, 1526.0, 39.0640
40.196887855, 96.390, 1575.0, 39.6863
40.249408986, 96.390, 1517.0, 38.9487
40.301930117, 96.390, 1453.0, 38.1182
40.354451247, 96.390, 1459.0, 38.1969
40.406972378, 96.390, 1462.0, 38.2361
40.459493509, 96.390, 1436.0, 37.8946
40.512014639, 96.390, 1474.0, 38.3927
40.564535770, 96.390, 1411.0, 37.5633
40.617056901, 96.390, 1404.0, 37.4700
40.669578032, 96.390, 1424.0, 37.7359
40.722099162, 96.390, 1472.0, 38.3667
40.774620293, 96.390, 1409.0, 37.5366
40.827141424, 96.390, 1425.0, 37.7492
40.879662554, 96.390, 1441.0, 37.9605
40.932183685, 96.390, 1463.0, 38.2492
40.984704816, 96.390, 1397.0, 37.3765
41.037225947, 96.390, 1341.0, 36.6197
41.089747077, 96.390, 1370.0, 37.0135
41.142268208, 96.390, 1363.0, 36.9188
41.194789339, 96.390, 1448.0, 38.0526
41.247310469, 96.390, 1404.0, 37.4700
41.299831600, 96.390, 1408.0, 37.5233
41.352352731, 96.390, 1322.0, 36.3593
41.404873862, 96.390, 1428.0, 37.7889
41.457394992, 96.390, 1430.0, 37.8153
41.509916123, 96.390, 1403.0, 37.4566
41.562437254, 96.390, 1362.0, 36.9053
41.614958384, 96.390, 1379.0, 37.1349
41.667479515, 96.390, 1402.0, 37.4433
41.720000646, 96.390, 1388.0, 37.2559
41.772521776, 96.390, 1383.0, 37.1887
41.825042907, 96.390, 1367.0, 36.9730
41.877564038, 96.390, 1359.0, 36.8646
41.930085169, 96.390, 1338.0, 36.5787
41.982606299, 96.390, 1360.0, 36.8782
42.035127430, 96.390, 1404.0, 37.4700
42.087648561, 96.390, 1341.0, 36.6197
42.140169691, 96.390, 1441.0, 37.9605
42.192690822, 96.390, 1396.0, 37.3631
42.245211953, 96.390, 1384.0, 37.2022
42.297733084, 96.390, 1354.0, 36.7967
42.350254214, 96.390, 1415.0, 37.6165
42.402775345, 96.390, 1373.0, 37.0540
42.455296476, 96.390, 1381.0, 37.1618
42.507817606, 96.390, 1309.0, 36.1801
42.560338737, 96.390, 1313.0, 36.2353
42.612859868, 96.390, 1416.0, 37.6298
42.665380999, 96.390, 1382.0, 37.1753
42.717902129, 96.390, 1369.0, 37.0000
42.770423260, 96.390, 1345.0, 36.6742
42.822944391, 96.390, 1358.0, 36.8511
42.875465521, 96.390, 1351.0, 36.7560
42.927986652, 96.390, 1354.0, 36.7967
42.980507783, 96.390, 1441.0, 37.9605
43.033028914, 96.390, 1381.0, 37.1618
43.085550044, 96.390, 1293.0, 35.9583
43.138071175, 96.390, 1310.0, 36.1939
43.190592306, 96.390, 1375.0, 37.0810
43.243113436, 96.390, 1356.0, 36.8239
43.295634567, 96.390, 1343.0, 36.6470
43.348155698, 96.390, 1357.0, 36.8375
43.400676828, 96.390, 1369.0, 37.0000
43.453197959, 96.390, 1341.0, 36.6197
43.505719090, 96.390, 1380.0, 37.1484
43.558240221, 96.390, 1336.0, 36.5513
43.610761351, 96.390, 1280.0, 35.7771
43.663282482, 96.390, 1386.0, 37.2290
43.715803613, 96.390, 1421.0, 37.6962
43.768324743, 96.390, 1357.0, 36.8375
43.820845874, 96.390, 1338.0, 36.5787
43.873367005, 96.390, 1362.0, 36.9053
43.925888136, 96.390, 1346.0, 36.6879
43.978409266, 96.390, 1417.0, 37.6431
44.030930397, 96.390, 1362.0, 36.9053
44.083451528, 96.390, 1372.0, 37.0405
44.135972658, 96.390, 1362.0, 36.9053
44.188493789, 96.390, 1364.0, 36.9324
44.241014920, 96.390, 1387.0, 37.2424
44.293536051, 96.390, 1361.0, 36.8917
44.346057181, 96.390, 1374.0, 37.0675
44.398578312, 96.390, 1419.0, 37.6696
44.451099443, 96.390, 1441.0, 37.9605
44.503620573, 96.390, 1414.0, 37.6032
44.556141704, 96.390, 1357.0, 36.8375
44.608662835, 96.390, 1410.0, 37.5500
44.661183966, 96.390, 1330.0, 36.4692
44.713705096, 96.390, 1434.0, 37.8682
44.766226227, 96.390, 1367.0, 36.9730
44.818747358, 96.390, 1387.0, 37.2424
44.871268488, 96.390, 1418.0, 37.6563
44.923789619, 96.390, 1386.0, 37.2290
44.976310750, 96.390, 1405.0, 37.4833
45.028831880, 96.390, 1375.0, 37.0810
45.081353011, 96.390, 1405.0, 37.4833
45.133874142, 96.390, 1342.0, 36.6333
45.186395273, 96.390, 1411.0, 37.5633
45.238916403, 96.390, 1341.0, 36.6197
45.291437534, 96.390, 1338.0, 36.5787
45.343958665, 96.390, 1426.0, 37.7624
45.396479795, 96.390, 1456.0, 38.1576
45.449000926, 96.390, 1453.0, 38.1182
45.501522057, 96.390, 1426.0, 37.7624
45.554043188, 96.390, 1384.0, 37.2022
45.606564318, 96.390, 1354.0, 36.7967
45.659085449, 96.390, 1421.0, 37.6962
45.711606580, 96.390, 1354.0, 36.7967
45.764127710, 96.390, 1332.0, 36.4966
45.816648841, 96.390, 1421.0, 37.6962
45.869169972, 96.390, 1411.0, 37.5633
45.921691103, 96.390, 1407.0, 37.5100
45.974212233, 96.390, 1442.0, 37.9737
46.026733364, 96.390, 1386.0, 37.2290
46.079254495, 96.390, 1333.0, 36.5103
46.131775625, 96.390, 1365.0, 36.9459
46.184296756, 96.390, 1410.0, 37.5500
46.236817887, 96.390, 1337.0, 36.5650
46.289339017, 96.390, 1360.0, 36.8782
46.341860148, 96.390, 1312.0, 36.2215
46.394381279, 96.390, 1403.0, 37.4566
46.446902410, 96.390, 1365.0, 36.9459
46.499423540, 96.390, 1367.0, 36.9730
46.551944671, 96.390, 1333.0, 36.5103
46.604465802, 96.390, 1317.0, 36.2905
46.656986932, 96.390, 1302.0, 36.0832
46.709508063, 96.390, 1361.0, 36.8917
46.762029194, 96.390, 1282.0, 35.8050
46.814550325, 96.390, 1367.0, 36.9730
46.867071455, 96.390, 1367.0, 36.9730
46.919592586, 96.390, 1330.0, 36.4692
46.972113717, 96.390, 1429.0, 37.8021
47.024634847, 96.390, 1379.0, 37.1349
47.077155978, 96.390, 1396.0, 37.3631
47.129677109, 96.390, 1292.0, 35.9444
47.182198240, 96.390, 1342.0, 36.6333
47.234719370, 96.390, 1336.0, 36.5513
47.287240501, 96.390, 1334.0, 36.5240
47.339761632, 96.390, 1351.0, 36.7560
47.392282762, 96.390, 1344.0, 36.6606
47.444803893, 96.390, 1331.0, 36.4829
47.497325024, 96.390, 1268.0, 35.6090
47.549846155, 96.390, 1272.0, 35.6651
47.602367285, 96.390, 1339.0, 36.5923
47.654888416, 96.390, 1276.0, 35.7211
47.707409547, 96.390, 1248.0, 35.3270
47.759930677, 96.390, 1253.0, 35.3977
47.812451808, 96.390, 1342.0, 36.6333
47.864972939, 96.390, 1234.0, 35.1283
47.917494069, 96.390, 1244.0, 35.2704
47.970015200, 96.390, 1283.0, 35.8190
48.022536331, 96.390, 1303.0, 36.0971
48.075057462, 96.390, 1254.0, 35.4119
48.127578592, 96.390, 1304.0, 36.1109
48.180099723, 96.390, 1269.0, 35.6230
48.232620854, 96.390, 1269.0, 35.6230
48.285141984, 96.390, 1308.0, 36.1663
48.337663115, 96.390, 1222.0, 34.9571
48.390184246, 96.390, 1301.0, 36.0694
48.442705377, 96.390, 1267.0, 35.5949
48.495226507, 96.390, 1259.0, 35.4824
48.547747638, 96.390, 1250.0, 35.3553
48.600268769, 96.390, 1263.0, 35.5387
48.652789899, 96.390, 1214.0, 34.8425
48.705311030, 96.390, 1206.0, 34.7275
48.757832161, 96.390, 1243.0, 35.2562
48.810353292, 96.390, 1271.0, 35.6511
48.862874422, 96.390, 1235.0, 35.1426
48.915395553, 96.390, 1229.0, 35.0571
48.967916684, 96.390, 1224.0, 34.9857
49.020437814, 96.390, 1184.0, 34.4093
49.072958945, 96.390, 1226.0, 35.0143
49.125480076, 96.390, 1279.0, 35.7631
49.178001207, 96.390, 1223.0, 34.9714
49.230522337, 96.390, 1214.0, 34.8425
49.283043468, 96.390, 1194.0, 34.5543
49.335564599, 96.390, 1203.0, 34.6843
49.388085729, 96.390, 1313.0, 36.2353
49.440606860, 96.390, 1218.0, 34.8999
49.493127991, 96.390, 1197.0, 34.5977
49.545649121, 96.390, 1219.0, 34.9142
49.598170252, 96.390, 1233.0, 35.1141
49.650691383, 96.390, 1194.0, 34.5543
49.703212514, 96.390, 1164.0, 34.1174
49.755733644, 96.390, 1160.0, 34.0588
49.808254775, 96.390, 1147.0, 33.8674
49.860775906, 96.390, 1202.0, 34.6699
49.913297036, 96.390, 1152.0, 33.9411
49.965818167, 96.390, 1160.0, 34.0588
50.018339298, 96.390, 1189.0, 34.4819
50.070860429, 96.390, 1129.0, 33.6006
50.123381559, 96.390, 1164.0, 34.1174
50.175902690, 96.390, 1102.0, 33.1964
50.228423821, 96.390, 1125.0, 33.5410
50.280944951, 96.390, 1156.0, 34.0000
50.333466082, 96.390, 1075.0, 32.7872
50.385987213, 96.390, 1191.0, 34.5109
50.438508344, 96.390, 1053.0, 32.4500
50.491029474, 96.390, 1136.0, 33.7046
50.543550605, 96.390, 1077.0, 32.8177
50.596071736, 96.390, 1189.0, 34.4819
50.648592866, 96.390, 1198.0, 34.6121
50.701113997, 96.390, 1096.0, 33.1059
50.753635128, 96.390, 1127.0, 33.5708
50.806156258, 96.390, 1116.0, 33.4066
50.858677389, 96.390, 1070.0, 32.7109
50.911198520, 96.390, 1108.0, 33.2866
50.963719651, 96.390, 1072.0, 32.7414
51.016240781, 96.390, 1071.0, 32.7261
51.068761912, 96.390, 1124.0, 33.5261
51.121283043, 96.390, 1095.0, 33.0908
51.173804173, 96.390, 1090.0, 33.0151
51.226325304, 96.390, 1040.0, 32.2490
51.278846435, 96.390, 1134.0, 33.6749
51.331367566, 96.390, 1066.0, 32.6497
51.383888696, 96.390, 1110.0, 33.3167
51.436409827, 96.390, 1114.0, 33.3766
51.488930958, 96.390, 1106.0, 33.2566
51.541452088, 96.390, 1066.0, 32.6497
51.593973219, 96.390, 1090.0, 33.0151
51.646494350, 96.390, 1043.0, 32.2955
51.699015481, 96.390, 1059.0, 32.5423
51.751536611, 96.390, 1014.0, 31.8434
51.804057742, 96.390, 1111.0, 33.3317
51.856578873, 96.390, 1075.0, 32.7872
51.909100003, 96.390, 1087.0, 32.9697
51.961621134, 96.390, 1064.0, 32.6190
52.014142265, 96.390, 1072.0, 32.7414
52.066663396, 96.390, 1059.0, 32.5423
52.119184526, 96.390, 1091.0, 33.0303
52.171705657, 96.390, 1058.0, 32.5269
52.224226788, 96.390, 1108.0, 33.2866
52.276747918, 96.390, 1035.0, 32.1714
52.329269049, 96.390, 1065.0, 32.6343
52.381790180, 96.390, 993.0, 31.5119
52.434311310, 96.390, 1023.0, 31.9844
52.486832441, 96.390, 1030.0, 32.0936
52.539353572, 96.390, 1028.0, 32.0624
52.591874703, 96.390, 1054.0, 32.4654
52.644395833, 96.390, 1049.0, 32.3883
52.696916964, 96.390, 987.0, 31.4166
52.749438095, 96.390, 1082.0, 32.8938
52.801959225, 96.390, 1076.0, 32.8024
52.854480356, 96.390, 1064.0, 32.6190
52.907001487, 96.390, 1023.0, 31.9844
52.959522618, 96.390, 999.0, 31.6070
53.012043748, 96.390, 1049.0, 32.3883
53.064564879, 96.390, 1048.0, 32.3728
53.117086010, 96.390, 973.0, 31.1929
53.169607140, 96.390, 977.0, 31.2570
53.222128271, 96.390, 1021.0, 31.9531
53.274649402, 96.390, 1059.0, 32.5423
53.327170533, 96.390, 1101.0, 33.1813
53.379691663, 96.390, 1039.0, 32.2335
53.432212794, 96.390, 1046.0, 32.3419
53.484733925, 96.390, 1001.0, 31.6386
53.537255055, 96.390, 1008.0, 31.7490
53.589776186, 96.390, 988.0, 31.4325
53.642297317, 96.390, 1056.0, 32.4962
53.694818448, 96.390, 981.0, 31.3209
53.747339578, 96.390, 994.0, 31.5278
53.799860709, 96.390, 1032.0, 32.1248
53.852381840, 96.390, 1009.0, 31.7648
53.904902970, 96.390, 1004.0, 31.6860
53.957424101, 96.390, 990.0, 31.4643
54.009945232, 96.390, 961.0, 31.0000
54.062466362, 96.390, 1001.0, 31.6386
54.114987493, 96.390, 1008.0, 31.7490
54.167508624, 96.390, 1024.0, 32.0000
54.220029755, 96.390, 1022.0, 31.9687
54.272550885, 96.390, 1027.0, 32.0468
54.325072016, 96.390, 997.0, 31.5753
54.377593147, 96.390, 957.0, 30.9354
54.430114277, 96.390, 959.0, 30.9677
54.482635408, 96.390, 1015.0, 31.8591
54.535156539, 96.390, 1034.0, 32.1559
54.587677670, 96.390, 949.0, 30.8058
54.640198800, 96.390, 979.0, 31.2890
54.692719931, 96.390, 975.0, 31.2250
54.745241062, 96.390, 969.0, 31.1288
54.797762192, 96.390, 1004.0, 31.6860
54.850283323, 96.390, 984.0, 31.3688
54.902804454, 96.390, 966.0, 31.0805
54.955325585, 96.390, 1012.0, 31.8119
55.007846715, 96.390, 962.0, 31.0161
55.060367846, 96.390, 950.0, 30.8221
55.112888977, 96.390, 1014.0, 31.8434
55.165410107, 96.390, 994.0, 31.5278
55.217931238, 96.390, 937.0, 30.6105
55.270452369, 96.390, 996.0, 31.5595
55.322973499, 96.390, 947.0, 30.7734
55.375494630, 96.390, 989.0, 31.4484
55.428015761, 96.390, 995.0, 31.5436
55.480536892, 96.390, 916.0, 30.2655
55.533058022, 96.390, 960.0, 30.9839
55.585579153, 96.390, 908.0, 30.1330
55.638100284, 96.390, 983.0, 31.3528
55.690621414, 96.390, 966.0, 31.0805
55.743142545, 96.390, 958.0, 30.9516
55.795663676, 96.390, 917.0, 30.2820
55.848184807, 96.390, 927.0, 30.4467
55.900705937, 96.390, 968.0, 31.1127
55.953227068, 96.390, 955.0, 30.9031
56.005748199, 96.390, 910.0, 30.1662
56.058269329, 96.390, 934.0, 30.5614
56.110790460, 96.390, 936.0, 30.5941
56.163311591, 96.390, 960.0, 30.9839
56.215832722, 96.390, 969.0, 31.1288
56.268353852, 96.390, 954.0, 30.8869
56.320874983, 96.390, 934.0, 30.5614
56.373396114, 96.390, 933.0, 30.5450
56.425917244, 96.390, 908.0, 30.1330
56.478438375, 96.390, 924.0, 30.3974
56.530959506, 96.390, 927.0, 30.4467
56.583480637, 96.390, 900.0, 30.0000
56.636001767, 96.390, 922.0, 30.3645
56.688522898, 96.390, 955.0, 30.9031
56.741044029, 96.390, 880.0, 29.6648
56.793565159, 96.390, 943.0, 30.7083
56.846086290, 96.390, 905.0, 30.0832
56.898607421, 96.390, 910.0, 30.1662
56.951128551, 96.390, 963.0, 31.0322
57.003649682, 96.390, 885.0, 29.7489
57.056170813, 96.390, 993.0, 31.5119
57.108691944, 96.390, 887.0, 29.7825
57.161213074, 96.390, 890.0, 29.8329
57.213734205, 96.390, 948.0, 30.7896
57.266255336, 96.390, 905.0, 30.0832
57.318776466, 96.390, 905.0, 30.0832
57.371297597, 96.390, 937.0, 30.6105
57.423818728, 96.390, 940.0, 30.6594
57.476339859, 96.390, 913.0, 30.2159
57.528860989, 96.390, 923.0, 30.3809
57.581382120, 96.390, 907.0, 30.1164
57.633903251, 96.390, 925.0, 30.4138
57.686424381, 96.390, 893.0, 29.8831
57.738945512, 96.390, 899.0, 29.9833
57.791466643, 96.390, 925.0, 30.4138
57.843987774, 96.390, 886.0, 29.7658
57.896508904, 96.390, 918.0, 30.2985
57.949030035, 96.390, 950.0, 30.8221
58.001551166, 96.390, 902.0, 30.0333
58.054072296, 96.390, 983.0, 31.3528
58.106593427, 96.390, 906.0, 30.0998
58.159114558, 96.390, 938.0, 30.6268
58.211635689, 96.390, 910.0, 30.1662
58.264156819, 96.390, 894.0, 29.8998
58.316677950, 96.390, 969.0, 31.1288
58.369199081, 96.390, 927.0, 30.4467
58.421720211, 96.390, 846.0, 29.0861
58.474241342, 96.390, 919.0, 30.3150
58.526762473, 96.390, 970.0, 31.1448
58.579283603, 96.390, 881.0, 29.6816
58.631804734, 96.390, 885.0, 29.7489
58.684325865, 96.390, 935.0, 30.5778
58.736846996, 96.390, 884.0, 29.7321
58.789368126, 96.390, 923.0, 30.3809
58.841889257, 96.390, 891.0, 29.8496
58.894410388, 96.390, 933.0, 30.5450
58.946931518, 96.390, 942.0, 30.6920
58.999452649, 96.390, 903.0, 30.0500
59.051973780, 96.390, 944.0, 30.7246
59.104494911, 96.390, 956.0, 30.9192
59.157016041, 96.390, 854.0, 29.2233
59.209537172, 96.390, 928.0, 30.4631
59.262058303, 96.390, 920.0, 30.3315
59.314579433, 96.390, 906.0, 30.0998
59.367100564, 96.390, 939.0, 30.6431
59.419621695, 96.390, 900.0, 30.0000
59.472142826, 96.390, 970.0, 31.1448
59.524663956, 96.390, 956.0, 30.9192
59.577185087, 96.390, 931.0, 30.5123
59.629706218, 96.390, 942.0, 30.6920
59.682227348, 96.390, 924.0, 30.3974
59.734748479, 96.390, 955.0, 30.9031
59.787269610, 96.390, 977.0, 31.2570
59.839790740, 96.390, 903.0, 30.0500
59.892311871, 96.390, 972.0, 31.1769
59.944833002, 96.390, 977.0, 31.2570
59.997354133, 96.390, 1017.0, 31.8904
60.049875263, 96.390, 1016.0, 31.8748
60.102396394, 96.390, 967.0, 31.0966
60.154917525, 96.390, 1029.0, 32.0780
60.207438655, 96.390, 1069.0, 32.6956
60.259959786, 96.390, 1025.0, 32.0156
60.312480917, 96.390, 1052.0, 32.4345
60.365002048, 96.390, 1062.0, 32.5883
60.417523178, 96.390, 1095.0, 33.0908
60.470044309, 96.390, 1075.0, 32.7872
60.522565440, 96.390, 1093.0, 33.0606
60.575086570, 96.390, 1064.0, 32.6190
60.627607701, 96.390, 1115.0, 33.3916
60.680128832, 96.390, 1198.0, 34.6121
60.732649963, 96.390, 1207.0, 34.7419
60.785171093, 96.390, 1199.0, 34.6266
60.837692224, 96.390, 1180.0, 34.3511
60.890213355, 96.390, 1252.0, 35.3836
60.942734485, 96.390, 1229.0, 35.0571
60.995255616, 96.390, 1240.0, 35.2136
61.047776747, 96.390, 1280.0, 35.7771
61.100297878, 96.390, 1311.0, 36.2077
61.152819008, 96.390, 1314.0, 36.2491
61.205340139, 96.390, 1273.0, 35.6791
61.257861270, 96.390, 1359.0, 36.8646
61.310382400, 96.390, 1373.0, 37.0540
61.362903531, 96.390, 1288.0, 35.8887
61.415424662, 96.390, 1262.0, 35.5246
61.467945792, 96.390, 1263.0, 35.5387
61.520466923, 96.390, 1272.0, 35.6651
61.572988054, 96.390, 1262.0, 35.5246
61.625509185, 96.390, 1232.0, 35.0999
61.678030315, 96.390, 1287.0, 35.8748
61.730551446, 96.390, 1267.0, 35.5949
61.783072577, 96.390, 1296.0, 36.0000
61.835593707, 96.390, 1254.0, 35.4119
61.888114838, 96.390, 1207.0, 34.7419
61.940635969, 96.390, 1189.0, 34.4819
61.993157100, 96.390, 1187.0, 34.4529
62.045678230, 96.390, 1255.0, 35.4260
62.098199361, 96.390, 1169.0, 34.1906
62.150720492, 96.390, 1178.0, 34.3220
62.203241622, 96.390, 1216.0, 34.8712
62.255762753, 96.390, 1122.0, 33.4963
62.308283884, 96.390, 1129.0, 33.6006
62.360805015, 96.390, 1126.0, 33.5559
62.413326145, 96.390, 1170.0, 34.2053
62.465847276, 96.390, 1143.0, 33.8083
62.518368407, 96.390, 1140.0, 33.7639
62.570889537, 96.390, 1038.0, 32.2180
62.623410668, 96.390, 1056.0, 32.4962
62.675931799, 96.390, 1050.0, 32.4037
62.728452930, 96.390, 1034.0, 32.1559
62.780974060, 96.390, 1057.0, 32.5115
62.833495191, 96.390, 1078.0, 32.8329
62.886016322, 96.390, 1053.0, 32.4500
62.938537452, 96.390, 991.0, 31.4802
62.991058583, 96.390, 993.0, 31.5119
63.043579714, 96.390, 1051.0, 32.4191
63.096100844, 96.390, 926.0, 30.4302
63.148621975, 96.390, 1009.0, 31.7648
63.201143106, 96.390, 952.0, 30.8545
63.253664237, 96.390, 932.0, 30.5287
63.306185367, 96.390, 960.0, 30.9839
63.358706498, 96.390, 967.0, 31.0966
63.411227629, 96.390, 951.0, 30.8383
63.463748759, 96.390, 942.0, 30.6920
63.516269890, 96.390, 886.0, 29.7658
63.568791021, 96.390, 918.0, 30.2985
63.621312152, 96.390, 898.0, 29.9666
63.673833282, 96.390, 925.0, 30.4138
63.726354413, 96.390, 893.0, 29.8831
63.778875544, 96.390, 885.0, 29.7489
63.831396674, 96.390, 910.0, 30.1662
63.883917805, 96.390, 902.0, 30.0333
63.936438936, 96.390, 857.0, 29.2746
63.988960067, 96.390, 911.0, 30.1828
64.041481197, 96.390, 894.0, 29.8998
64.094002328, 96.390, 883.0, 29.7153
64.146523459, 96.390, 839.0, 28.9655
64.199044589, 96.390, 856.0, 29.2575
64.251565720, 96.390, 838.0, 28.9482
64.304086851, 96.390, 814.0, 28.5307
64.356607981, 96.390, 814.0, 28.5307
64.409129112, 96.390, 835.0, 28.8964
64.461650243, 96.390, 828.0, 28.7750
64.514171374, 96.390, 879.0, 29.6479
64.566692504, 96.390, 821.0, 28.6531
64.619213635, 96.390, 847.0, 29.1033
64.671734766, 96.390, 897.0, 29.9500
64.724255896, 96.390, 861.0, 29.3428
64.776777027, 96.390, 847.0, 29.1033
64.829298158, 96.390, 875.0, 29.5804
64.881819289, 96.390, 787.0, 28.0535
64.934340419, 96.390, 860.0, 29.3258
64.986861550, 96.390, 849.0, 29.1376