File: Files_organized_for_plots/Centroid_changing_NaOH/XRDd_Centroid16Mar22_Act21Mar22_B2_0655M_NaOH_LS0157_1.csv
[Measurement conditions]
Sample identification,XRD_Centroid16Mar22_Act21Mar22_B2_0655M_NaOH_LS0157_1
Comment - 1,"Configuration=Stage for Flat Samples/Holders, Owner=User-1, Creation date=7/1/2020 9:53:24 AM"
Comment - 2,"Goniometer=Theta/Theta; Minimum step size 2Theta:0.0001; Minimum step size Omega:0.0001"
Comment - 3,"Sample stage=Stage for flat samples/holders"
Comment - 4,"Diffractometer system=EMPYREAN"
Comment - 5,"Measurement program=C:\Users\ibo5034\OneDrive - The Pennsylvania State University\NEUP\Zerobackground scan.xrdmp, Identifier={98A3B11C-88F9-4AA6-982C-73314A311EF5}"
Anode material,Cu
K-Alpha1 wavelength,1.5405980
K-Alpha2 wavelength,1.5444260
Ratio K-Alpha2/K-Alpha1,0.500
Divergence slit,Fixed,0.25
Monochromator used,NO
Generator voltage, 45
Tube current, 40
File date and time,24/Mar/2022 18:21
Unit cell,
h k l, 0 0 0
Scan axis,Gonio
Scan range,4.994599997,64.999991833
Scan step size,0.0262606
No. of points, 2285
Scan type,CONTINUOUS
Time per step,96.390
[Scan points]
Angle, TimePerStep, Intensity, ESD
5.007730280, 96.390, 4460.0, 66.7832
5.060251411, 96.390, 4375.0, 66.1438
5.112772541, 96.390, 4316.0, 65.6963
5.165293672, 96.390, 4424.0, 66.5132
5.217814803, 96.390, 4283.0, 65.4446
5.270335934, 96.390, 4397.0, 66.3099
5.322857064, 96.390, 4049.0, 63.6318
5.375378195, 96.390, 4322.0, 65.7419
5.427899326, 96.390, 4247.0, 65.1690
5.480420456, 96.390, 4231.0, 65.0461
5.532941587, 96.390, 4256.0, 65.2380
5.585462718, 96.390, 4066.0, 63.7652
5.637983849, 96.390, 4212.0, 64.8999
5.690504979, 96.390, 4147.0, 64.3972
5.743026110, 96.390, 4078.0, 63.8592
5.795547241, 96.390, 4206.0, 64.8537
5.848068371, 96.390, 4149.0, 64.4127
5.900589502, 96.390, 4099.0, 64.0234
5.953110633, 96.390, 4117.0, 64.1639
6.005631763, 96.390, 4088.0, 63.9375
6.058152894, 96.390, 3975.0, 63.0476
6.110674025, 96.390, 4098.0, 64.0156
6.163195156, 96.390, 3919.0, 62.6019
6.215716286, 96.390, 3904.0, 62.4820
6.268237417, 96.390, 3950.0, 62.8490
6.320758548, 96.390, 4053.0, 63.6632
6.373279678, 96.390, 3945.0, 62.8092
6.425800809, 96.390, 4019.0, 63.3956
6.478321940, 96.390, 4002.0, 63.2614
6.530843071, 96.390, 4041.0, 63.5689
6.583364201, 96.390, 3933.0, 62.7136
6.635885332, 96.390, 4030.0, 63.4823
6.688406463, 96.390, 3978.0, 63.0714
6.740927593, 96.390, 3965.0, 62.9682
6.793448724, 96.390, 4057.0, 63.6946
6.845969855, 96.390, 3869.0, 62.2013
6.898490986, 96.390, 3934.0, 62.7216
6.951012116, 96.390, 3949.0, 62.8411
7.003533247, 96.390, 3943.0, 62.7933
7.056054378, 96.390, 3949.0, 62.8411
7.108575508, 96.390, 3787.0, 61.5386
7.161096639, 96.390, 3874.0, 62.2415
7.213617770, 96.390, 3917.0, 62.5859
7.266138900, 96.390, 3772.0, 61.4166
7.318660031, 96.390, 3971.0, 63.0159
7.371181162, 96.390, 3740.0, 61.1555
7.423702293, 96.390, 3863.0, 62.1530
7.476223423, 96.390, 3961.0, 62.9365
7.528744554, 96.390, 3828.0, 61.8708
7.581265685, 96.390, 3874.0, 62.2415
7.633786815, 96.390, 3844.0, 62.0000
7.686307946, 96.390, 3778.0, 61.4654
7.738829077, 96.390, 3899.0, 62.4420
7.791350208, 96.390, 3795.0, 61.6036
7.843871338, 96.390, 3786.0, 61.5305
7.896392469, 96.390, 3893.0, 62.3939
7.948913600, 96.390, 3817.0, 61.7819
8.001434730, 96.390, 3826.0, 61.8547
8.053955861, 96.390, 3789.0, 61.5549
8.106476992, 96.390, 3850.0, 62.0484
8.158998123, 96.390, 3921.0, 62.6179
8.211519253, 96.390, 3857.0, 62.1048
8.264040384, 96.390, 3759.0, 61.3107
8.316561515, 96.390, 3695.0, 60.7865
8.369082645, 96.390, 3708.0, 60.8933
8.421603776, 96.390, 3678.0, 60.6465
8.474124907, 96.390, 3775.0, 61.4410
8.526646038, 96.390, 3618.0, 60.1498
8.579167168, 96.390, 3660.0, 60.4979
8.631688299, 96.390, 3655.0, 60.4566
8.684209430, 96.390, 3658.0, 60.4814
8.736730560, 96.390, 3650.0, 60.4152
8.789251691, 96.390, 3578.0, 59.8164
8.841772822, 96.390, 3579.0, 59.8247
8.894293952, 96.390, 3556.0, 59.6322
8.946815083, 96.390, 3557.0, 59.6406
8.999336214, 96.390, 3585.0, 59.8749
9.051857345, 96.390, 3507.0, 59.2199
9.104378475, 96.390, 3569.0, 59.7411
9.156899606, 96.390, 3505.0, 59.2030
9.209420737, 96.390, 3559.0, 59.6574
9.261941867, 96.390, 3587.0, 59.8916
9.314462998, 96.390, 3587.0, 59.8916
9.366984129, 96.390, 3548.0, 59.5651
9.419505260, 96.390, 3584.0, 59.8665
9.472026390, 96.390, 3548.0, 59.5651
9.524547521, 96.390, 3562.0, 59.6825
9.577068652, 96.390, 3443.0, 58.6771
9.629589782, 96.390, 3398.0, 58.2924
9.682110913, 96.390, 3622.0, 60.1831
9.734632044, 96.390, 3540.0, 59.4979
9.787153175, 96.390, 3449.0, 58.7282
9.839674305, 96.390, 3459.0, 58.8133
9.892195436, 96.390, 3497.0, 59.1354
9.944716567, 96.390, 3456.0, 58.7878
9.997237697, 96.390, 3388.0, 58.2065
10.049758828, 96.390, 3387.0, 58.1979
10.102279959, 96.390, 3378.0, 58.1206
10.154801090, 96.390, 3503.0, 59.1861
10.207322220, 96.390, 3458.0, 58.8048
10.259843351, 96.390, 3341.0, 57.8014
10.312364482, 96.390, 3348.0, 57.8619
10.364885612, 96.390, 3456.0, 58.7878
10.417406743, 96.390, 3324.0, 57.6541
10.469927874, 96.390, 3369.0, 58.0431
10.522449004, 96.390, 3264.0, 57.1314
10.574970135, 96.390, 3259.0, 57.0877
10.627491266, 96.390, 3343.0, 57.8187
10.680012397, 96.390, 3421.0, 58.4893
10.732533527, 96.390, 3347.0, 57.8533
10.785054658, 96.390, 3412.0, 58.4123
10.837575789, 96.390, 3338.0, 57.7754
10.890096919, 96.390, 3355.0, 57.9224
10.942618050, 96.390, 3177.0, 56.3649
10.995139181, 96.390, 3441.0, 58.6600
11.047660312, 96.390, 3315.0, 57.5760
11.100181442, 96.390, 3248.0, 56.9912
11.152702573, 96.390, 3184.0, 56.4269
11.205223704, 96.390, 3274.0, 57.2189
11.257744834, 96.390, 3092.0, 55.6058
11.310265965, 96.390, 3199.0, 56.5597
11.362787096, 96.390, 3197.0, 56.5420
11.415308227, 96.390, 3118.0, 55.8391
11.467829357, 96.390, 3190.0, 56.4801
11.520350488, 96.390, 3161.0, 56.2228
11.572871619, 96.390, 3065.0, 55.3624
11.625392749, 96.390, 3072.0, 55.4256
11.677913880, 96.390, 3063.0, 55.3444
11.730435011, 96.390, 3033.0, 55.0727
11.782956141, 96.390, 2957.0, 54.3783
11.835477272, 96.390, 3146.0, 56.0892
11.887998403, 96.390, 3029.0, 55.0364
11.940519534, 96.390, 3001.0, 54.7814
11.993040664, 96.390, 3043.0, 55.1634
12.045561795, 96.390, 2881.0, 53.6749
12.098082926, 96.390, 3006.0, 54.8270
12.150604056, 96.390, 2835.0, 53.2447
12.203125187, 96.390, 2895.0, 53.8052
12.255646318, 96.390, 2873.0, 53.6004
12.308167449, 96.390, 2863.0, 53.5070
12.360688579, 96.390, 2836.0, 53.2541
12.413209710, 96.390, 2862.0, 53.4977
12.465730841, 96.390, 2857.0, 53.4509
12.518251971, 96.390, 2832.0, 53.2165
12.570773102, 96.390, 2755.0, 52.4881
12.623294233, 96.390, 2777.0, 52.6972
12.675815364, 96.390, 2882.0, 53.6843
12.728336494, 96.390, 2764.0, 52.5738
12.780857625, 96.390, 2689.0, 51.8556
12.833378756, 96.390, 2688.0, 51.8459
12.885899886, 96.390, 2708.0, 52.0384
12.938421017, 96.390, 2687.0, 51.8363
12.990942148, 96.390, 2677.0, 51.7397
13.043463279, 96.390, 2750.0, 52.4404
13.095984409, 96.390, 2607.0, 51.0588
13.148505540, 96.390, 2600.0, 50.9902
13.201026671, 96.390, 2671.0, 51.6817
13.253547801, 96.390, 2699.0, 51.9519
13.306068932, 96.390, 2551.0, 50.5074
13.358590063, 96.390, 2611.0, 51.0979
13.411111193, 96.390, 2649.0, 51.4684
13.463632324, 96.390, 2650.0, 51.4782
13.516153455, 96.390, 2755.0, 52.4881
13.568674586, 96.390, 2543.0, 50.4282
13.621195716, 96.390, 2652.0, 51.4976
13.673716847, 96.390, 2565.0, 50.6458
13.726237978, 96.390, 2651.0, 51.4879
13.778759108, 96.390, 2440.0, 49.3964
13.831280239, 96.390, 2566.0, 50.6557
13.883801370, 96.390, 2539.0, 50.3885
13.936322501, 96.390, 2559.0, 50.5866
13.988843631, 96.390, 2524.0, 50.2394
14.041364762, 96.390, 2443.0, 49.4267
14.093885893, 96.390, 2450.0, 49.4975
14.146407023, 96.390, 2465.0, 49.6488
14.198928154, 96.390, 2493.0, 49.9300
14.251449285, 96.390, 2606.0, 51.0490
14.303970416, 96.390, 2628.0, 51.2640
14.356491546, 96.390, 2509.0, 50.0899
14.409012677, 96.390, 2496.0, 49.9600
14.461533808, 96.390, 2626.0, 51.2445
14.514054938, 96.390, 2863.0, 53.5070
14.566576069, 96.390, 2816.0, 53.0660
14.619097200, 96.390, 2533.0, 50.3289
14.671618331, 96.390, 2442.0, 49.4166
14.724139461, 96.390, 2342.0, 48.3942
14.776660592, 96.390, 2358.0, 48.5592
14.829181723, 96.390, 2355.0, 48.5283
14.881702853, 96.390, 2324.0, 48.2079
14.934223984, 96.390, 2344.0, 48.4149
14.986745115, 96.390, 2320.0, 48.1664
15.039266245, 96.390, 2391.0, 48.8979
15.091787376, 96.390, 2411.0, 49.1019
15.144308507, 96.390, 2514.0, 50.1398
15.196829638, 96.390, 2472.0, 49.7192
15.249350768, 96.390, 2571.0, 50.7050
15.301871899, 96.390, 2712.0, 52.0769
15.354393030, 96.390, 2532.0, 50.3190
15.406914160, 96.390, 2337.0, 48.3425
15.459435291, 96.390, 2262.0, 47.5605
15.511956422, 96.390, 2353.0, 48.5077
15.564477553, 96.390, 2294.0, 47.8957
15.616998683, 96.390, 2364.0, 48.6210
15.669519814, 96.390, 2288.0, 47.8330
15.722040945, 96.390, 2339.0, 48.3632
15.774562075, 96.390, 2342.0, 48.3942
15.827083206, 96.390, 2199.0, 46.8935
15.879604337, 96.390, 2199.0, 46.8935
15.932125468, 96.390, 2301.0, 47.9687
15.984646598, 96.390, 2295.0, 47.9062
16.037167729, 96.390, 2296.0, 47.9166
16.089688860, 96.390, 2349.0, 48.4665
16.142209990, 96.390, 2310.0, 48.0625
16.194731121, 96.390, 2373.0, 48.7134
16.247252252, 96.390, 2354.0, 48.5180
16.299773382, 96.390, 2562.0, 50.6162
16.352294513, 96.390, 2786.0, 52.7826
16.404815644, 96.390, 2410.0, 49.0918
16.457336775, 96.390, 2249.0, 47.4236
16.509857905, 96.390, 2340.0, 48.3735
16.562379036, 96.390, 2331.0, 48.2804
16.614900167, 96.390, 2321.0, 48.1768
16.667421297, 96.390, 2236.0, 47.2864
16.719942428, 96.390, 2334.0, 48.3115
16.772463559, 96.390, 2295.0, 47.9062
16.824984690, 96.390, 2356.0, 48.5386
16.877505820, 96.390, 2337.0, 48.3425
16.930026951, 96.390, 2318.0, 48.1456
16.982548082, 96.390, 2341.0, 48.3839
17.035069212, 96.390, 2272.0, 47.6655
17.087590343, 96.390, 2343.0, 48.4045
17.140111474, 96.390, 2231.0, 47.2335
17.192632605, 96.390, 2380.0, 48.7852
17.245153735, 96.390, 2343.0, 48.4045
17.297674866, 96.390, 2444.0, 49.4368
17.350195997, 96.390, 2345.0, 48.4252
17.402717127, 96.390, 2326.0, 48.2286
17.455238258, 96.390, 2344.0, 48.4149
17.507759389, 96.390, 2279.0, 47.7389
17.560280520, 96.390, 2300.0, 47.9583
17.612801650, 96.390, 2306.0, 48.0208
17.665322781, 96.390, 2308.0, 48.0416
17.717843912, 96.390, 2295.0, 47.9062
17.770365042, 96.390, 2424.0, 49.2341
17.822886173, 96.390, 2288.0, 47.8330
17.875407304, 96.390, 2394.0, 48.9285
17.927928434, 96.390, 2421.0, 49.2037
17.980449565, 96.390, 2375.0, 48.7340
18.032970696, 96.390, 2348.0, 48.4562
18.085491827, 96.390, 2405.0, 49.0408
18.138012957, 96.390, 2362.0, 48.6004
18.190534088, 96.390, 2400.0, 48.9898
18.243055219, 96.390, 2430.0, 49.2950
18.295576349, 96.390, 2440.0, 49.3964
18.348097480, 96.390, 2563.0, 50.6261
18.400618611, 96.390, 2496.0, 49.9600
18.453139742, 96.390, 2467.0, 49.6689
18.505660872, 96.390, 2428.0, 49.2747
18.558182003, 96.390, 2434.0, 49.3356
18.610703134, 96.390, 2528.0, 50.2792
18.663224264, 96.390, 2476.0, 49.7594
18.715745395, 96.390, 2491.0, 49.9099
18.768266526, 96.390, 2628.0, 51.2640
18.820787657, 96.390, 2603.0, 51.0196
18.873308787, 96.390, 2852.0, 53.4041
18.925829918, 96.390, 2920.0, 54.0370
18.978351049, 96.390, 2965.0, 54.4518
19.030872179, 96.390, 2740.0, 52.3450
19.083393310, 96.390, 2695.0, 51.9134
19.135914441, 96.390, 2683.0, 51.7977
19.188435572, 96.390, 2571.0, 50.7050
19.240956702, 96.390, 2552.0, 50.5173
19.293477833, 96.390, 2487.0, 49.8698
19.345998964, 96.390, 2704.0, 52.0000
19.398520094, 96.390, 2702.0, 51.9808
19.451041225, 96.390, 2667.0, 51.6430
19.503562356, 96.390, 2688.0, 51.8459
19.556083486, 96.390, 2622.0, 51.2055
19.608604617, 96.390, 2638.0, 51.3615
19.661125748, 96.390, 2620.0, 51.1859
19.713646879, 96.390, 2736.0, 52.3068
19.766168009, 96.390, 2738.0, 52.3259
19.818689140, 96.390, 2792.0, 52.8394
19.871210271, 96.390, 2785.0, 52.7731
19.923731401, 96.390, 2827.0, 53.1695
19.976252532, 96.390, 3027.0, 55.0182
20.028773663, 96.390, 2964.0, 54.4426
20.081294794, 96.390, 2749.0, 52.4309
20.133815924, 96.390, 2718.0, 52.1344
20.186337055, 96.390, 2731.0, 52.2590
20.238858186, 96.390, 2732.0, 52.2685
20.291379316, 96.390, 2662.0, 51.5946
20.343900447, 96.390, 2705.0, 52.0096
20.396421578, 96.390, 2709.0, 52.0481
20.448942709, 96.390, 2812.0, 53.0283
20.501463839, 96.390, 2768.0, 52.6118
20.553984970, 96.390, 2954.0, 54.3507
20.606506101, 96.390, 3115.0, 55.8122
20.659027231, 96.390, 3266.0, 57.1489
20.711548362, 96.390, 3750.0, 61.2372
20.764069493, 96.390, 3529.0, 59.4054
20.816590623, 96.390, 2963.0, 54.4334
20.869111754, 96.390, 2834.0, 53.2353
20.921632885, 96.390, 2740.0, 52.3450
20.974154016, 96.390, 2809.0, 53.0000
21.026675146, 96.390, 2862.0, 53.4977
21.079196277, 96.390, 2792.0, 52.8394
21.131717408, 96.390, 2849.0, 53.3760
21.184238538, 96.390, 2726.0, 52.2111
21.236759669, 96.390, 2887.0, 53.7308
21.289280800, 96.390, 2892.0, 53.7773
21.341801931, 96.390, 2965.0, 54.4518
21.394323061, 96.390, 2873.0, 53.6004
21.446844192, 96.390, 2853.0, 53.4135
21.499365323, 96.390, 2698.0, 51.9423
21.551886453, 96.390, 2819.0, 53.0943
21.604407584, 96.390, 3045.0, 55.1815
21.656928715, 96.390, 3156.0, 56.1783
21.709449846, 96.390, 2946.0, 54.2771
21.761970976, 96.390, 2842.0, 53.3104
21.814492107, 96.390, 2673.0, 51.7011
21.867013238, 96.390, 2762.0, 52.5547
21.919534368, 96.390, 2792.0, 52.8394
21.972055499, 96.390, 2763.0, 52.5642
22.024576630, 96.390, 2776.0, 52.6878
22.077097761, 96.390, 2771.0, 52.6403
22.129618891, 96.390, 2697.0, 51.9326
22.182140022, 96.390, 2810.0, 53.0094
22.234661153, 96.390, 2825.0, 53.1507
22.287182283, 96.390, 2920.0, 54.0370
22.339703414, 96.390, 2785.0, 52.7731
22.392224545, 96.390, 2820.0, 53.1037
22.444745675, 96.390, 2761.0, 52.5452
22.497266806, 96.390, 2836.0, 53.2541
22.549787937, 96.390, 2840.0, 53.2917
22.602309068, 96.390, 2835.0, 53.2447
22.654830198, 96.390, 2904.0, 53.8888
22.707351329, 96.390, 2893.0, 53.7866
22.759872460, 96.390, 3006.0, 54.8270
22.812393590, 96.390, 3112.0, 55.7853
22.864914721, 96.390, 2978.0, 54.5711
22.917435852, 96.390, 3042.0, 55.1543
22.969956983, 96.390, 3003.0, 54.7996
23.022478113, 96.390, 2851.0, 53.3948
23.074999244, 96.390, 2947.0, 54.2863
23.127520375, 96.390, 2870.0, 53.5724
23.180041505, 96.390, 3043.0, 55.1634
23.232562636, 96.390, 3062.0, 55.3353
23.285083767, 96.390, 2835.0, 53.2447
23.337604898, 96.390, 2908.0, 53.9259
23.390126028, 96.390, 2976.0, 54.5527
23.442647159, 96.390, 2865.0, 53.5257
23.495168290, 96.390, 2816.0, 53.0660
23.547689420, 96.390, 2872.0, 53.5910
23.600210551, 96.390, 2965.0, 54.4518
23.652731682, 96.390, 2778.0, 52.7067
23.705252813, 96.390, 2692.0, 51.8845
23.757773943, 96.390, 2599.0, 50.9804
23.810295074, 96.390, 2694.0, 51.9038
23.862816205, 96.390, 2802.0, 52.9339
23.915337335, 96.390, 2621.0, 51.1957
23.967858466, 96.390, 2561.0, 50.6063
24.020379597, 96.390, 2532.0, 50.3190
24.072900727, 96.390, 2585.0, 50.8429
24.125421858, 96.390, 2634.0, 51.3225
24.177942989, 96.390, 2629.0, 51.2738
24.230464120, 96.390, 2648.0, 51.4587
24.282985250, 96.390, 2611.0, 51.0979
24.335506381, 96.390, 2539.0, 50.3885
24.388027512, 96.390, 2545.0, 50.4480
24.440548642, 96.390, 2455.0, 49.5480
24.493069773, 96.390, 2559.0, 50.5866
24.545590904, 96.390, 2424.0, 49.2341
24.598112035, 96.390, 2451.0, 49.5076
24.650633165, 96.390, 2426.0, 49.2544
24.703154296, 96.390, 2476.0, 49.7594
24.755675427, 96.390, 2384.0, 48.8262
24.808196557, 96.390, 2370.0, 48.6826
24.860717688, 96.390, 2405.0, 49.0408
24.913238819, 96.390, 2335.0, 48.3218
24.965759950, 96.390, 2439.0, 49.3862
25.018281080, 96.390, 2303.0, 47.9896
25.070802211, 96.390, 2293.0, 47.8853
25.123323342, 96.390, 2355.0, 48.5283
25.175844472, 96.390, 2269.0, 47.6340
25.228365603, 96.390, 2288.0, 47.8330
25.280886734, 96.390, 2316.0, 48.1248
25.333407864, 96.390, 2222.0, 47.1381
25.385928995, 96.390, 2305.0, 48.0104
25.438450126, 96.390, 2389.0, 48.8774
25.490971257, 96.390, 2409.0, 49.0816
25.543492387, 96.390, 2289.0, 47.8435
25.596013518, 96.390, 2271.0, 47.6550
25.648534649, 96.390, 2289.0, 47.8435
25.701055779, 96.390, 2254.0, 47.4763
25.753576910, 96.390, 2113.0, 45.9674
25.806098041, 96.390, 2107.0, 45.9021
25.858619172, 96.390, 2179.0, 46.6798
25.911140302, 96.390, 2168.0, 46.5618
25.963661433, 96.390, 2134.0, 46.1952
26.016182564, 96.390, 2107.0, 45.9021
26.068703694, 96.390, 2185.0, 46.7440
26.121224825, 96.390, 2103.0, 45.8585
26.173745956, 96.390, 2084.0, 45.6508
26.226267087, 96.390, 2107.0, 45.9021
26.278788217, 96.390, 2155.0, 46.4220
26.331309348, 96.390, 2195.0, 46.8508
26.383830479, 96.390, 2055.0, 45.3321
26.436351609, 96.390, 2114.0, 45.9783
26.488872740, 96.390, 2131.0, 46.1628
26.541393871, 96.390, 2050.0, 45.2769
26.593915002, 96.390, 1998.0, 44.6990
26.646436132, 96.390, 2202.0, 46.9255
26.698957263, 96.390, 2141.0, 46.2709
26.751478394, 96.390, 2270.0, 47.6445
26.803999524, 96.390, 2569.0, 50.6853
26.856520655, 96.390, 2401.0, 49.0000
26.909041786, 96.390, 2379.0, 48.7750
26.961562916, 96.390, 2236.0, 47.2864
27.014084047, 96.390, 2354.0, 48.5180
27.066605178, 96.390, 2441.0, 49.4065
27.119126309, 96.390, 2524.0, 50.2394
27.171647439, 96.390, 2743.0, 52.3737
27.224168570, 96.390, 2847.0, 53.3573
27.276689701, 96.390, 2557.0, 50.5668
27.329210831, 96.390, 2266.0, 47.6025
27.381731962, 96.390, 2158.0, 46.4543
27.434253093, 96.390, 2137.0, 46.2277
27.486774224, 96.390, 1954.0, 44.2041
27.539295354, 96.390, 2076.0, 45.5631
27.591816485, 96.390, 2027.0, 45.0222
27.644337616, 96.390, 2029.0, 45.0444
27.696858746, 96.390, 2021.0, 44.9555
27.749379877, 96.390, 2046.0, 45.2327
27.801901008, 96.390, 1922.0, 43.8406
27.854422139, 96.390, 2086.0, 45.6727
27.906943269, 96.390, 2046.0, 45.2327
27.959464400, 96.390, 1996.0, 44.6766
28.011985531, 96.390, 1995.0, 44.6654
28.064506661, 96.390, 2002.0, 44.7437
28.117027792, 96.390, 2075.0, 45.5522
28.169548923, 96.390, 2040.0, 45.1664
28.222070054, 96.390, 2059.0, 45.3762
28.274591184, 96.390, 2023.0, 44.9778
28.327112315, 96.390, 2039.0, 45.1553
28.379633446, 96.390, 2207.0, 46.9787
28.432154576, 96.390, 2194.0, 46.8402
28.484675707, 96.390, 2108.0, 45.9130
28.537196838, 96.390, 2154.0, 46.4112
28.589717968, 96.390, 1981.0, 44.5084
28.642239099, 96.390, 1981.0, 44.5084
28.694760230, 96.390, 1979.0, 44.4860
28.747281361, 96.390, 2070.0, 45.4973
28.799802491, 96.390, 2108.0, 45.9130
28.852323622, 96.390, 2126.0, 46.1086
28.904844753, 96.390, 2089.0, 45.7056
28.957365883, 96.390, 2000.0, 44.7214
29.009887014, 96.390, 2123.0, 46.0760
29.062408145, 96.390, 2165.0, 46.5296
29.114929276, 96.390, 2230.0, 47.2229
29.167450406, 96.390, 2234.0, 47.2652
29.219971537, 96.390, 2256.0, 47.4974
29.272492668, 96.390, 2368.0, 48.6621
29.325013798, 96.390, 2662.0, 51.5946
29.377534929, 96.390, 2501.0, 50.0100
29.430056060, 96.390, 2349.0, 48.4665
29.482577191, 96.390, 2451.0, 49.5076
29.535098321, 96.390, 2425.0, 49.2443
29.587619452, 96.390, 2217.0, 47.0850
29.640140583, 96.390, 2152.0, 46.3897
29.692661713, 96.390, 2075.0, 45.5522
29.745182844, 96.390, 2123.0, 46.0760
29.797703975, 96.390, 2172.0, 46.6047
29.850225105, 96.390, 2042.0, 45.1885
29.902746236, 96.390, 2008.0, 44.8107
29.955267367, 96.390, 2058.0, 45.3652
30.007788498, 96.390, 2065.0, 45.4423
30.060309628, 96.390, 2014.0, 44.8776
30.112830759, 96.390, 2083.0, 45.6399
30.165351890, 96.390, 1959.0, 44.2606
30.217873020, 96.390, 2012.0, 44.8553
30.270394151, 96.390, 1974.0, 44.4297
30.322915282, 96.390, 2030.0, 45.0555
30.375436413, 96.390, 2093.0, 45.7493
30.427957543, 96.390, 2037.0, 45.1331
30.480478674, 96.390, 2067.0, 45.4643
30.532999805, 96.390, 2113.0, 45.9674
30.585520935, 96.390, 2117.0, 46.0109
30.638042066, 96.390, 2149.0, 46.3573
30.690563197, 96.390, 2285.0, 47.8017
30.743084328, 96.390, 2273.0, 47.6760
30.795605458, 96.390, 2173.0, 46.6154
30.848126589, 96.390, 2215.0, 47.0638
30.900647720, 96.390, 2141.0, 46.2709
30.953168850, 96.390, 2072.0, 45.5192
31.005689981, 96.390, 2023.0, 44.9778
31.058211112, 96.390, 1977.0, 44.4635
31.110732243, 96.390, 2081.0, 45.6180
31.163253373, 96.390, 2237.0, 47.2969
31.215774504, 96.390, 2491.0, 49.9099
31.268295635, 96.390, 2503.0, 50.0300
31.320816765, 96.390, 2505.0, 50.0500
31.373337896, 96.390, 2479.0, 49.7896
31.425859027, 96.390, 2382.0, 48.8057
31.478380157, 96.390, 2272.0, 47.6655
31.530901288, 96.390, 2156.0, 46.4327
31.583422419, 96.390, 2127.0, 46.1194
31.635943550, 96.390, 2155.0, 46.4220
31.688464680, 96.390, 2150.0, 46.3681
31.740985811, 96.390, 2119.0, 46.0326
31.793506942, 96.390, 1999.0, 44.7102
31.846028072, 96.390, 2003.0, 44.7549
31.898549203, 96.390, 2060.0, 45.3872
31.951070334, 96.390, 2086.0, 45.6727
32.003591465, 96.390, 2356.0, 48.5386
32.056112595, 96.390, 2746.0, 52.4023
32.108633726, 96.390, 2840.0, 53.2917
32.161154857, 96.390, 2577.0, 50.7642
32.213675987, 96.390, 2265.0, 47.5920
32.266197118, 96.390, 2314.0, 48.1041
32.318718249, 96.390, 2301.0, 47.9687
32.371239380, 96.390, 2128.0, 46.1303
32.423760510, 96.390, 2033.0, 45.0888
32.476281641, 96.390, 1954.0, 44.2041
32.528802772, 96.390, 1942.0, 44.0681
32.581323902, 96.390, 1965.0, 44.3283
32.633845033, 96.390, 2036.0, 45.1221
32.686366164, 96.390, 2088.0, 45.6946
32.738887295, 96.390, 1984.0, 44.5421
32.791408425, 96.390, 2007.0, 44.7996
32.843929556, 96.390, 1974.0, 44.4297
32.896450687, 96.390, 1937.0, 44.0114
32.948971817, 96.390, 1935.0, 43.9886
33.001492948, 96.390, 1997.0, 44.6878
33.054014079, 96.390, 1979.0, 44.4860
33.106535209, 96.390, 1996.0, 44.6766
33.159056340, 96.390, 2058.0, 45.3652
33.211577471, 96.390, 2053.0, 45.3100
33.264098602, 96.390, 2061.0, 45.3982
33.316619732, 96.390, 2010.0, 44.8330
33.369140863, 96.390, 1959.0, 44.2606
33.421661994, 96.390, 2032.0, 45.0777
33.474183124, 96.390, 1977.0, 44.4635
33.526704255, 96.390, 1973.0, 44.4185
33.579225386, 96.390, 1933.0, 43.9659
33.631746517, 96.390, 2034.0, 45.0999
33.684267647, 96.390, 2009.0, 44.8219
33.736788778, 96.390, 2014.0, 44.8776
33.789309909, 96.390, 2036.0, 45.1221
33.841831039, 96.390, 2055.0, 45.3321
33.894352170, 96.390, 2031.0, 45.0666
33.946873301, 96.390, 2253.0, 47.4658
33.999394432, 96.390, 2230.0, 47.2229
34.051915562, 96.390, 2239.0, 47.3181
34.104436693, 96.390, 2181.0, 46.7012
34.156957824, 96.390, 2046.0, 45.2327
34.209478954, 96.390, 2143.0, 46.2925
34.262000085, 96.390, 2135.0, 46.2061
34.314521216, 96.390, 2262.0, 47.5605
34.367042346, 96.390, 2194.0, 46.8402
34.419563477, 96.390, 2242.0, 47.3498
34.472084608, 96.390, 2477.0, 49.7695
34.524605739, 96.390, 2677.0, 51.7397
34.577126869, 96.390, 2707.0, 52.0288
34.629648000, 96.390, 2709.0, 52.0481
34.682169131, 96.390, 2533.0, 50.3289
34.734690261, 96.390, 2342.0, 48.3942
34.787211392, 96.390, 2355.0, 48.5283
34.839732523, 96.390, 2354.0, 48.5180
34.892253654, 96.390, 2400.0, 48.9898
34.944774784, 96.390, 2526.0, 50.2593
34.997295915, 96.390, 2505.0, 50.0500
35.049817046, 96.390, 2408.0, 49.0714
35.102338176, 96.390, 2331.0, 48.2804
35.154859307, 96.390, 2355.0, 48.5283
35.207380438, 96.390, 2466.0, 49.6588
35.259901569, 96.390, 2251.0, 47.4447
35.312422699, 96.390, 2297.0, 47.9270
35.364943830, 96.390, 2291.0, 47.8644
35.417464961, 96.390, 2126.0, 46.1086
35.469986091, 96.390, 2182.0, 46.7119
35.522507222, 96.390, 2138.0, 46.2385
35.575028353, 96.390, 2125.0, 46.0977
35.627549484, 96.390, 2097.0, 45.7930
35.680070614, 96.390, 2176.0, 46.6476
35.732591745, 96.390, 2111.0, 45.9456
35.785112876, 96.390, 2088.0, 45.6946
35.837634006, 96.390, 2159.0, 46.4650
35.890155137, 96.390, 2236.0, 47.2864
35.942676268, 96.390, 2420.0, 49.1935
35.995197398, 96.390, 2159.0, 46.4650
36.047718529, 96.390, 2222.0, 47.1381
36.100239660, 96.390, 2149.0, 46.3573
36.152760791, 96.390, 2340.0, 48.3735
36.205281921, 96.390, 2452.0, 49.5177
36.257803052, 96.390, 2344.0, 48.4149
36.310324183, 96.390, 2292.0, 47.8748
36.362845313, 96.390, 2002.0, 44.7437
36.415366444, 96.390, 1930.0, 43.9318
36.467887575, 96.390, 1875.0, 43.3013
36.520408706, 96.390, 1954.0, 44.2041
36.572929836, 96.390, 1855.0, 43.0697
36.625450967, 96.390, 1791.0, 42.3202
36.677972098, 96.390, 1899.0, 43.5775
36.730493228, 96.390, 1827.0, 42.7434
36.783014359, 96.390, 1793.0, 42.3438
36.835535490, 96.390, 1888.0, 43.4511
36.888056621, 96.390, 1757.0, 41.9166
36.940577751, 96.390, 1785.0, 42.2493
36.993098882, 96.390, 1824.0, 42.7083
37.045620013, 96.390, 1780.0, 42.1900
37.098141143, 96.390, 1825.0, 42.7200
37.150662274, 96.390, 1764.0, 42.0000
37.203183405, 96.390, 1751.0, 41.8450
37.255704535, 96.390, 1824.0, 42.7083
37.308225666, 96.390, 1779.0, 42.1782
37.360746797, 96.390, 1716.0, 41.4246
37.413267928, 96.390, 1791.0, 42.3202
37.465789058, 96.390, 1816.0, 42.6146
37.518310189, 96.390, 1875.0, 43.3013
37.570831320, 96.390, 1874.0, 43.2897
37.623352450, 96.390, 1808.0, 42.5206
37.675873581, 96.390, 1714.0, 41.4005
37.728394712, 96.390, 1927.0, 43.8976
37.780915843, 96.390, 1878.0, 43.3359
37.833436973, 96.390, 1846.0, 42.9651
37.885958104, 96.390, 1858.0, 43.1045
37.938479235, 96.390, 1812.0, 42.5676
37.991000365, 96.390, 1834.0, 42.8252
38.043521496, 96.390, 1749.0, 41.8210
38.096042627, 96.390, 1721.0, 41.4849
38.148563758, 96.390, 1774.0, 42.1189
38.201084888, 96.390, 1760.0, 41.9524
38.253606019, 96.390, 1719.0, 41.4608
38.306127150, 96.390, 1670.0, 40.8656
38.358648280, 96.390, 1603.0, 40.0375
38.411169411, 96.390, 1620.0, 40.2492
38.463690542, 96.390, 1615.0, 40.1871
38.516211673, 96.390, 1606.0, 40.0749
38.568732803, 96.390, 1652.0, 40.6448
38.621253934, 96.390, 1615.0, 40.1871
38.673775065, 96.390, 1569.0, 39.6106
38.726296195, 96.390, 1608.0, 40.0999
38.778817326, 96.390, 1707.0, 41.3159
38.831338457, 96.390, 1607.0, 40.0874
38.883859587, 96.390, 1623.0, 40.2865
38.936380718, 96.390, 1520.0, 38.9872
38.988901849, 96.390, 1493.0, 38.6394
39.041422980, 96.390, 1554.0, 39.4208
39.093944110, 96.390, 1542.0, 39.2683
39.146465241, 96.390, 1483.0, 38.5097
39.198986372, 96.390, 1566.0, 39.5727
39.251507502, 96.390, 1568.0, 39.5980
39.304028633, 96.390, 1530.0, 39.1152
39.356549764, 96.390, 1573.0, 39.6611
39.409070895, 96.390, 1609.0, 40.1123
39.461592025, 96.390, 1620.0, 40.2492
39.514113156, 96.390, 1559.0, 39.4842
39.566634287, 96.390, 1564.0, 39.5474
39.619155417, 96.390, 1499.0, 38.7169
39.671676548, 96.390, 1447.0, 38.0395
39.724197679, 96.390, 1497.0, 38.6911
39.776718810, 96.390, 1496.0, 38.6782
39.829239940, 96.390, 1553.0, 39.4081
39.881761071, 96.390, 1461.0, 38.2230
39.934282202, 96.390, 1520.0, 38.9872
39.986803332, 96.390, 1481.0, 38.4838
40.039324463, 96.390, 1560.0, 39.4968
40.091845594, 96.390, 1477.0, 38.4318
40.144366725, 96.390, 1523.0, 39.0256
40.196887855, 96.390, 1504.0, 38.7814
40.249408986, 96.390, 1402.0, 37.4433
40.301930117, 96.390, 1368.0, 36.9865
40.354451247, 96.390, 1290.0, 35.9166
40.406972378, 96.390, 1410.0, 37.5500
40.459493509, 96.390, 1407.0, 37.5100
40.512014639, 96.390, 1495.0, 38.6652
40.564535770, 96.390, 1400.0, 37.4166
40.617056901, 96.390, 1479.0, 38.4578
40.669578032, 96.390, 1427.0, 37.7757
40.722099162, 96.390, 1387.0, 37.2424
40.774620293, 96.390, 1325.0, 36.4005
40.827141424, 96.390, 1380.0, 37.1484
40.879662554, 96.390, 1351.0, 36.7560
40.932183685, 96.390, 1367.0, 36.9730
40.984704816, 96.390, 1260.0, 35.4965
41.037225947, 96.390, 1380.0, 37.1484
41.089747077, 96.390, 1307.0, 36.1525
41.142268208, 96.390, 1320.0, 36.3318
41.194789339, 96.390, 1313.0, 36.2353
41.247310469, 96.390, 1337.0, 36.5650
41.299831600, 96.390, 1317.0, 36.2905
41.352352731, 96.390, 1409.0, 37.5366
41.404873862, 96.390, 1432.0, 37.8418
41.457394992, 96.390, 1329.0, 36.4555
41.509916123, 96.390, 1396.0, 37.3631
41.562437254, 96.390, 1337.0, 36.5650
41.614958384, 96.390, 1388.0, 37.2559
41.667479515, 96.390, 1234.0, 35.1283
41.720000646, 96.390, 1325.0, 36.4005
41.772521776, 96.390, 1322.0, 36.3593
41.825042907, 96.390, 1304.0, 36.1109
41.877564038, 96.390, 1291.0, 35.9305
41.930085169, 96.390, 1278.0, 35.7491
41.982606299, 96.390, 1327.0, 36.4280
42.035127430, 96.390, 1337.0, 36.5650
42.087648561, 96.390, 1387.0, 37.2424
42.140169691, 96.390, 1495.0, 38.6652
42.192690822, 96.390, 1510.0, 38.8587
42.245211953, 96.390, 1407.0, 37.5100
42.297733084, 96.390, 1375.0, 37.0810
42.350254214, 96.390, 1268.0, 35.6090
42.402775345, 96.390, 1361.0, 36.8917
42.455296476, 96.390, 1308.0, 36.1663
42.507817606, 96.390, 1340.0, 36.6060
42.560338737, 96.390, 1253.0, 35.3977
42.612859868, 96.390, 1266.0, 35.5809
42.665380999, 96.390, 1306.0, 36.1386
42.717902129, 96.390, 1338.0, 36.5787
42.770423260, 96.390, 1306.0, 36.1386
42.822944391, 96.390, 1284.0, 35.8329
42.875465521, 96.390, 1307.0, 36.1525
42.927986652, 96.390, 1283.0, 35.8190
42.980507783, 96.390, 1214.0, 34.8425
43.033028914, 96.390, 1229.0, 35.0571
43.085550044, 96.390, 1227.0, 35.0286
43.138071175, 96.390, 1293.0, 35.9583
43.190592306, 96.390, 1262.0, 35.5246
43.243113436, 96.390, 1263.0, 35.5387
43.295634567, 96.390, 1237.0, 35.1710
43.348155698, 96.390, 1343.0, 36.6470
43.400676828, 96.390, 1172.0, 34.2345
43.453197959, 96.390, 1240.0, 35.2136
43.505719090, 96.390, 1210.0, 34.7851
43.558240221, 96.390, 1182.0, 34.3802
43.610761351, 96.390, 1251.0, 35.3695
43.663282482, 96.390, 1240.0, 35.2136
43.715803613, 96.390, 1289.0, 35.9026
43.768324743, 96.390, 1325.0, 36.4005
43.820845874, 96.390, 1350.0, 36.7423
43.873367005, 96.390, 1320.0, 36.3318
43.925888136, 96.390, 1351.0, 36.7560
43.978409266, 96.390, 1290.0, 35.9166
44.030930397, 96.390, 1284.0, 35.8329
44.083451528, 96.390, 1275.0, 35.7071
44.135972658, 96.390, 1256.0, 35.4401
44.188493789, 96.390, 1280.0, 35.7771
44.241014920, 96.390, 1264.0, 35.5528
44.293536051, 96.390, 1361.0, 36.8917
44.346057181, 96.390, 1406.0, 37.4967
44.398578312, 96.390, 1296.0, 36.0000
44.451099443, 96.390, 1346.0, 36.6879
44.503620573, 96.390, 1385.0, 37.2156
44.556141704, 96.390, 1317.0, 36.2905
44.608662835, 96.390, 1334.0, 36.5240
44.661183966, 96.390, 1281.0, 35.7911
44.713705096, 96.390, 1285.0, 35.8469
44.766226227, 96.390, 1308.0, 36.1663
44.818747358, 96.390, 1377.0, 37.1080
44.871268488, 96.390, 1325.0, 36.4005
44.923789619, 96.390, 1281.0, 35.7911
44.976310750, 96.390, 1300.0, 36.0555
45.028831880, 96.390, 1309.0, 36.1801
45.081353011, 96.390, 1325.0, 36.4005
45.133874142, 96.390, 1387.0, 37.2424
45.186395273, 96.390, 1373.0, 37.0540
45.238916403, 96.390, 1374.0, 37.0675
45.291437534, 96.390, 1339.0, 36.5923
45.343958665, 96.390, 1362.0, 36.9053
45.396479795, 96.390, 1284.0, 35.8329
45.449000926, 96.390, 1339.0, 36.5923
45.501522057, 96.390, 1326.0, 36.4143
45.554043188, 96.390, 1364.0, 36.9324
45.606564318, 96.390, 1270.0, 35.6371
45.659085449, 96.390, 1213.0, 34.8281
45.711606580, 96.390, 1371.0, 37.0270
45.764127710, 96.390, 1334.0, 36.5240
45.816648841, 96.390, 1258.0, 35.4683
45.869169972, 96.390, 1353.0, 36.7831
45.921691103, 96.390, 1304.0, 36.1109
45.974212233, 96.390, 1351.0, 36.7560
46.026733364, 96.390, 1306.0, 36.1386
46.079254495, 96.390, 1323.0, 36.3731
46.131775625, 96.390, 1329.0, 36.4555
46.184296756, 96.390, 1416.0, 37.6298
46.236817887, 96.390, 1443.0, 37.9868
46.289339017, 96.390, 1445.0, 38.0132
46.341860148, 96.390, 1446.0, 38.0263
46.394381279, 96.390, 1334.0, 36.5240
46.446902410, 96.390, 1331.0, 36.4829
46.499423540, 96.390, 1306.0, 36.1386
46.551944671, 96.390, 1288.0, 35.8887
46.604465802, 96.390, 1330.0, 36.4692
46.656986932, 96.390, 1294.0, 35.9722
46.709508063, 96.390, 1306.0, 36.1386
46.762029194, 96.390, 1328.0, 36.4417
46.814550325, 96.390, 1308.0, 36.1663
46.867071455, 96.390, 1292.0, 35.9444
46.919592586, 96.390, 1241.0, 35.2278
46.972113717, 96.390, 1312.0, 36.2215
47.024634847, 96.390, 1293.0, 35.9583
47.077155978, 96.390, 1319.0, 36.3180
47.129677109, 96.390, 1254.0, 35.4119
47.182198240, 96.390, 1311.0, 36.2077
47.234719370, 96.390, 1209.0, 34.7707
47.287240501, 96.390, 1208.0, 34.7563
47.339761632, 96.390, 1258.0, 35.4683
47.392282762, 96.390, 1214.0, 34.8425
47.444803893, 96.390, 1177.0, 34.3074
47.497325024, 96.390, 1330.0, 36.4692
47.549846155, 96.390, 1210.0, 34.7851
47.602367285, 96.390, 1300.0, 36.0555
47.654888416, 96.390, 1293.0, 35.9583
47.707409547, 96.390, 1221.0, 34.9428
47.759930677, 96.390, 1243.0, 35.2562
47.812451808, 96.390, 1265.0, 35.5668
47.864972939, 96.390, 1284.0, 35.8329
47.917494069, 96.390, 1205.0, 34.7131
47.970015200, 96.390, 1255.0, 35.4260
48.022536331, 96.390, 1193.0, 34.5398
48.075057462, 96.390, 1275.0, 35.7071
48.127578592, 96.390, 1153.0, 33.9559
48.180099723, 96.390, 1184.0, 34.4093
48.232620854, 96.390, 1308.0, 36.1663
48.285141984, 96.390, 1134.0, 33.6749
48.337663115, 96.390, 1239.0, 35.1994
48.390184246, 96.390, 1222.0, 34.9571
48.442705377, 96.390, 1341.0, 36.6197
48.495226507, 96.390, 1354.0, 36.7967
48.547747638, 96.390, 1273.0, 35.6791
48.600268769, 96.390, 1196.0, 34.5832
48.652789899, 96.390, 1260.0, 35.4965
48.705311030, 96.390, 1196.0, 34.5832
48.757832161, 96.390, 1151.0, 33.9264
48.810353292, 96.390, 1104.0, 33.2265
48.862874422, 96.390, 1156.0, 34.0000
48.915395553, 96.390, 1127.0, 33.5708
48.967916684, 96.390, 1099.0, 33.1512
49.020437814, 96.390, 1155.0, 33.9853
49.072958945, 96.390, 1102.0, 33.1964
49.125480076, 96.390, 1154.0, 33.9706
49.178001207, 96.390, 1216.0, 34.8712
49.230522337, 96.390, 1059.0, 32.5423
49.283043468, 96.390, 1169.0, 34.1906
49.335564599, 96.390, 1217.0, 34.8855
49.388085729, 96.390, 1128.0, 33.5857
49.440606860, 96.390, 1066.0, 32.6497
49.493127991, 96.390, 1063.0, 32.6037
49.545649121, 96.390, 1072.0, 32.7414
49.598170252, 96.390, 1142.0, 33.7935
49.650691383, 96.390, 1072.0, 32.7414
49.703212514, 96.390, 1095.0, 33.0908
49.755733644, 96.390, 1092.0, 33.0454
49.808254775, 96.390, 1106.0, 33.2566
49.860775906, 96.390, 1082.0, 32.8938
49.913297036, 96.390, 1097.0, 33.1210
49.965818167, 96.390, 1068.0, 32.6803
50.018339298, 96.390, 1067.0, 32.6650
50.070860429, 96.390, 1029.0, 32.0780
50.123381559, 96.390, 1088.0, 32.9848
50.175902690, 96.390, 1095.0, 33.0908
50.228423821, 96.390, 1105.0, 33.2415
50.280944951, 96.390, 1115.0, 33.3916
50.333466082, 96.390, 1087.0, 32.9697
50.385987213, 96.390, 1173.0, 34.2491
50.438508344, 96.390, 1110.0, 33.3167
50.491029474, 96.390, 1142.0, 33.7935
50.543550605, 96.390, 1109.0, 33.3017
50.596071736, 96.390, 1128.0, 33.5857
50.648592866, 96.390, 1108.0, 33.2866
50.701113997, 96.390, 1017.0, 31.8904
50.753635128, 96.390, 1026.0, 32.0312
50.806156258, 96.390, 1009.0, 31.7648
50.858677389, 96.390, 988.0, 31.4325
50.911198520, 96.390, 989.0, 31.4484
50.963719651, 96.390, 1014.0, 31.8434
51.016240781, 96.390, 1113.0, 33.3617
51.068761912, 96.390, 1123.0, 33.5112
51.121283043, 96.390, 1099.0, 33.1512
51.173804173, 96.390, 1028.0, 32.0624
51.226325304, 96.390, 1020.0, 31.9374
51.278846435, 96.390, 987.0, 31.4166
51.331367566, 96.390, 1004.0, 31.6860
51.383888696, 96.390, 1025.0, 32.0156
51.436409827, 96.390, 981.0, 31.3209
51.488930958, 96.390, 945.0, 30.7409
51.541452088, 96.390, 993.0, 31.5119
51.593973219, 96.390, 993.0, 31.5119
51.646494350, 96.390, 1024.0, 32.0000
51.699015481, 96.390, 967.0, 31.0966
51.751536611, 96.390, 985.0, 31.3847
51.804057742, 96.390, 993.0, 31.5119
51.856578873, 96.390, 1007.0, 31.7333
51.909100003, 96.390, 1049.0, 32.3883
51.961621134, 96.390, 1007.0, 31.7333
52.014142265, 96.390, 995.0, 31.5436
52.066663396, 96.390, 986.0, 31.4006
52.119184526, 96.390, 1012.0, 31.8119
52.171705657, 96.390, 970.0, 31.1448
52.224226788, 96.390, 915.0, 30.2490
52.276747918, 96.390, 986.0, 31.4006
52.329269049, 96.390, 1017.0, 31.8904
52.381790180, 96.390, 969.0, 31.1288
52.434311310, 96.390, 983.0, 31.3528
52.486832441, 96.390, 949.0, 30.8058
52.539353572, 96.390, 924.0, 30.3974
52.591874703, 96.390, 968.0, 31.1127
52.644395833, 96.390, 980.0, 31.3050
52.696916964, 96.390, 948.0, 30.7896
52.749438095, 96.390, 940.0, 30.6594
52.801959225, 96.390, 929.0, 30.4795
52.854480356, 96.390, 974.0, 31.2090
52.907001487, 96.390, 951.0, 30.8383
52.959522618, 96.390, 901.0, 30.0167
53.012043748, 96.390, 895.0, 29.9166
53.064564879, 96.390, 975.0, 31.2250
53.117086010, 96.390, 902.0, 30.0333
53.169607140, 96.390, 990.0, 31.4643
53.222128271, 96.390, 914.0, 30.2324
53.274649402, 96.390, 982.0, 31.3369
53.327170533, 96.390, 943.0, 30.7083
53.379691663, 96.390, 966.0, 31.0805
53.432212794, 96.390, 927.0, 30.4467
53.484733925, 96.390, 914.0, 30.2324
53.537255055, 96.390, 934.0, 30.5614
53.589776186, 96.390, 947.0, 30.7734
53.642297317, 96.390, 947.0, 30.7734
53.694818448, 96.390, 895.0, 29.9166
53.747339578, 96.390, 901.0, 30.0167
53.799860709, 96.390, 897.0, 29.9500
53.852381840, 96.390, 911.0, 30.1828
53.904902970, 96.390, 1001.0, 31.6386
53.957424101, 96.390, 956.0, 30.9192
54.009945232, 96.390, 1024.0, 32.0000
54.062466362, 96.390, 999.0, 31.6070
54.114987493, 96.390, 942.0, 30.6920
54.167508624, 96.390, 958.0, 30.9516
54.220029755, 96.390, 977.0, 31.2570
54.272550885, 96.390, 872.0, 29.5296
54.325072016, 96.390, 999.0, 31.6070
54.377593147, 96.390, 927.0, 30.4467
54.430114277, 96.390, 940.0, 30.6594
54.482635408, 96.390, 938.0, 30.6268
54.535156539, 96.390, 947.0, 30.7734
54.587677670, 96.390, 864.0, 29.3939
54.640198800, 96.390, 891.0, 29.8496
54.692719931, 96.390, 893.0, 29.8831
54.745241062, 96.390, 854.0, 29.2233
54.797762192, 96.390, 842.0, 29.0172
54.850283323, 96.390, 867.0, 29.4449
54.902804454, 96.390, 899.0, 29.9833
54.955325585, 96.390, 861.0, 29.3428
55.007846715, 96.390, 844.0, 29.0517
55.060367846, 96.390, 898.0, 29.9666
55.112888977, 96.390, 830.0, 28.8097
55.165410107, 96.390, 844.0, 29.0517
55.217931238, 96.390, 826.0, 28.7402
55.270452369, 96.390, 849.0, 29.1376
55.322973499, 96.390, 867.0, 29.4449
55.375494630, 96.390, 900.0, 30.0000
55.428015761, 96.390, 858.0, 29.2916
55.480536892, 96.390, 846.0, 29.0861
55.533058022, 96.390, 886.0, 29.7658
55.585579153, 96.390, 872.0, 29.5296
55.638100284, 96.390, 864.0, 29.3939
55.690621414, 96.390, 814.0, 28.5307
55.743142545, 96.390, 844.0, 29.0517
55.795663676, 96.390, 868.0, 29.4618
55.848184807, 96.390, 853.0, 29.2062
55.900705937, 96.390, 852.0, 29.1890
55.953227068, 96.390, 833.0, 28.8617
56.005748199, 96.390, 858.0, 29.2916
56.058269329, 96.390, 851.0, 29.1719
56.110790460, 96.390, 918.0, 30.2985
56.163311591, 96.390, 873.0, 29.5466
56.215832722, 96.390, 911.0, 30.1828
56.268353852, 96.390, 856.0, 29.2575
56.320874983, 96.390, 929.0, 30.4795
56.373396114, 96.390, 887.0, 29.7825
56.425917244, 96.390, 875.0, 29.5804
56.478438375, 96.390, 873.0, 29.5466
56.530959506, 96.390, 840.0, 28.9828
56.583480637, 96.390, 877.0, 29.6142
56.636001767, 96.390, 823.0, 28.6880
56.688522898, 96.390, 796.0, 28.2135
56.741044029, 96.390, 858.0, 29.2916
56.793565159, 96.390, 845.0, 29.0689
56.846086290, 96.390, 780.0, 27.9285
56.898607421, 96.390, 798.0, 28.2489
56.951128551, 96.390, 768.0, 27.7128
57.003649682, 96.390, 784.0, 28.0000
57.056170813, 96.390, 774.0, 27.8209
57.108691944, 96.390, 870.0, 29.4958
57.161213074, 96.390, 852.0, 29.1890
57.213734205, 96.390, 891.0, 29.8496
57.266255336, 96.390, 822.0, 28.6705
57.318776466, 96.390, 886.0, 29.7658
57.371297597, 96.390, 897.0, 29.9500
57.423818728, 96.390, 813.0, 28.5132
57.476339859, 96.390, 814.0, 28.5307
57.528860989, 96.390, 816.0, 28.5657
57.581382120, 96.390, 869.0, 29.4788
57.633903251, 96.390, 869.0, 29.4788
57.686424381, 96.390, 819.0, 28.6182
57.738945512, 96.390, 824.0, 28.7054
57.791466643, 96.390, 825.0, 28.7228
57.843987774, 96.390, 803.0, 28.3373
57.896508904, 96.390, 849.0, 29.1376
57.949030035, 96.390, 889.0, 29.8161
58.001551166, 96.390, 865.0, 29.4109
58.054072296, 96.390, 886.0, 29.7658
58.106593427, 96.390, 867.0, 29.4449
58.159114558, 96.390, 820.0, 28.6356
58.211635689, 96.390, 815.0, 28.5482
58.264156819, 96.390, 818.0, 28.6007
58.316677950, 96.390, 881.0, 29.6816
58.369199081, 96.390, 802.0, 28.3196
58.421720211, 96.390, 847.0, 29.1033
58.474241342, 96.390, 834.0, 28.8791
58.526762473, 96.390, 759.0, 27.5500
58.579283603, 96.390, 802.0, 28.3196
58.631804734, 96.390, 881.0, 29.6816
58.684325865, 96.390, 792.0, 28.1425
58.736846996, 96.390, 861.0, 29.3428
58.789368126, 96.390, 791.0, 28.1247
58.841889257, 96.390, 790.0, 28.1069
58.894410388, 96.390, 821.0, 28.6531
58.946931518, 96.390, 811.0, 28.4781
58.999452649, 96.390, 827.0, 28.7576
59.051973780, 96.390, 849.0, 29.1376
59.104494911, 96.390, 790.0, 28.1069
59.157016041, 96.390, 819.0, 28.6182
59.209537172, 96.390, 796.0, 28.2135
59.262058303, 96.390, 808.0, 28.4253
59.314579433, 96.390, 862.0, 29.3598
59.367100564, 96.390, 798.0, 28.2489
59.419621695, 96.390, 913.0, 30.2159
59.472142826, 96.390, 852.0, 29.1890
59.524663956, 96.390, 862.0, 29.3598
59.577185087, 96.390, 840.0, 28.9828
59.629706218, 96.390, 817.0, 28.5832
59.682227348, 96.390, 800.0, 28.2843
59.734748479, 96.390, 845.0, 29.0689
59.787269610, 96.390, 868.0, 29.4618
59.839790740, 96.390, 861.0, 29.3428
59.892311871, 96.390, 912.0, 30.1993
59.944833002, 96.390, 863.0, 29.3769
59.997354133, 96.390, 915.0, 30.2490
60.049875263, 96.390, 887.0, 29.7825
60.102396394, 96.390, 956.0, 30.9192
60.154917525, 96.390, 879.0, 29.6479
60.207438655, 96.390, 966.0, 31.0805
60.259959786, 96.390, 901.0, 30.0167
60.312480917, 96.390, 957.0, 30.9354
60.365002048, 96.390, 970.0, 31.1448
60.417523178, 96.390, 976.0, 31.2410
60.470044309, 96.390, 992.0, 31.4960
60.522565440, 96.390, 1029.0, 32.0780
60.575086570, 96.390, 1067.0, 32.6650
60.627607701, 96.390, 1060.0, 32.5576
60.680128832, 96.390, 1068.0, 32.6803
60.732649963, 96.390, 1098.0, 33.1361
60.785171093, 96.390, 1166.0, 34.1467
60.837692224, 96.390, 1121.0, 33.4813
60.890213355, 96.390, 1172.0, 34.2345
60.942734485, 96.390, 1187.0, 34.4529
60.995255616, 96.390, 1151.0, 33.9264
61.047776747, 96.390, 1171.0, 34.2199
61.100297878, 96.390, 1165.0, 34.1321
61.152819008, 96.390, 1225.0, 35.0000
61.205340139, 96.390, 1115.0, 33.3916
61.257861270, 96.390, 1148.0, 33.8821
61.310382400, 96.390, 1181.0, 34.3657
61.362903531, 96.390, 1146.0, 33.8526
61.415424662, 96.390, 1107.0, 33.2716
61.467945792, 96.390, 1202.0, 34.6699
61.520466923, 96.390, 1176.0, 34.2929
61.572988054, 96.390, 1171.0, 34.2199
61.625509185, 96.390, 1122.0, 33.4963
61.678030315, 96.390, 1232.0, 35.0999
61.730551446, 96.390, 1091.0, 33.0303
61.783072577, 96.390, 1199.0, 34.6266
61.835593707, 96.390, 1084.0, 32.9242
61.888114838, 96.390, 1150.0, 33.9116
61.940635969, 96.390, 1123.0, 33.5112
61.993157100, 96.390, 1022.0, 31.9687
62.045678230, 96.390, 1131.0, 33.6303
62.098199361, 96.390, 1114.0, 33.3766
62.150720492, 96.390, 1085.0, 32.9393
62.203241622, 96.390, 1073.0, 32.7567
62.255762753, 96.390, 1073.0, 32.7567
62.308283884, 96.390, 1009.0, 31.7648
62.360805015, 96.390, 1100.0, 33.1662
62.413326145, 96.390, 1001.0, 31.6386
62.465847276, 96.390, 1020.0, 31.9374
62.518368407, 96.390, 970.0, 31.1448
62.570889537, 96.390, 999.0, 31.6070
62.623410668, 96.390, 1000.0, 31.6228
62.675931799, 96.390, 946.0, 30.7571
62.728452930, 96.390, 947.0, 30.7734
62.780974060, 96.390, 972.0, 31.1769
62.833495191, 96.390, 920.0, 30.3315
62.886016322, 96.390, 913.0, 30.2159
62.938537452, 96.390, 911.0, 30.1828
62.991058583, 96.390, 875.0, 29.5804
63.043579714, 96.390, 836.0, 28.9137
63.096100844, 96.390, 840.0, 28.9828
63.148621975, 96.390, 809.0, 28.4429
63.201143106, 96.390, 857.0, 29.2746
63.253664237, 96.390, 837.0, 28.9310
63.306185367, 96.390, 815.0, 28.5482
63.358706498, 96.390, 836.0, 28.9137
63.411227629, 96.390, 810.0, 28.4605
63.463748759, 96.390, 838.0, 28.9482
63.516269890, 96.390, 826.0, 28.7402
63.568791021, 96.390, 777.0, 27.8747
63.621312152, 96.390, 846.0, 29.0861
63.673833282, 96.390, 815.0, 28.5482
63.726354413, 96.390, 766.0, 27.6767
63.778875544, 96.390, 826.0, 28.7402
63.831396674, 96.390, 811.0, 28.4781
63.883917805, 96.390, 824.0, 28.7054
63.936438936, 96.390, 761.0, 27.5862
63.988960067, 96.390, 797.0, 28.2312
64.041481197, 96.390, 779.0, 27.9106
64.094002328, 96.390, 769.0, 27.7308
64.146523459, 96.390, 806.0, 28.3901
64.199044589, 96.390, 791.0, 28.1247
64.251565720, 96.390, 809.0, 28.4429
64.304086851, 96.390, 825.0, 28.7228
64.356607981, 96.390, 751.0, 27.4044
64.409129112, 96.390, 762.0, 27.6043
64.461650243, 96.390, 742.0, 27.2397
64.514171374, 96.390, 753.0, 27.4408
64.566692504, 96.390, 706.0, 26.5707
64.619213635, 96.390, 689.0, 26.2488
64.671734766, 96.390, 703.0, 26.5141
64.724255896, 96.390, 745.0, 27.2947
64.776777027, 96.390, 734.0, 27.0924
64.829298158, 96.390, 730.0, 27.0185
64.881819289, 96.390, 725.0, 26.9258
64.934340419, 96.390, 767.0, 27.6948
64.986861550, 96.390, 701.0, 26.4764