File: Files_organized_for_plots/Centroid_age/bXRD_Centroid16Mar22_Act23Mar22_B1_0714M_NaOH_LS0172_new7day.csv
[Measurement conditions]
Sample identification,XRD_Centroid16Mar22_Act23Mar22_B1_0714M_NaOH_LS0172_1
Comment - 1,"Configuration=Stage for Flat Samples/Holders, Owner=User-1, Creation date=7/1/2020 9:53:24 AM"
Comment - 2,"Goniometer=Theta/Theta; Minimum step size 2Theta:0.0001; Minimum step size Omega:0.0001"
Comment - 3,"Sample stage=Stage for flat samples/holders"
Comment - 4,"Diffractometer system=EMPYREAN"
Comment - 5,"Measurement program=C:\Users\ibo5034\OneDrive - The Pennsylvania State University\NEUP\Zerobackground scan.xrdmp, Identifier={98A3B11C-88F9-4AA6-982C-73314A311EF5}"
Anode material,Cu
K-Alpha1 wavelength,1.5405980
K-Alpha2 wavelength,1.5444260
Ratio K-Alpha2/K-Alpha1,0.500
Divergence slit,Fixed,0.25
Monochromator used,NO
Generator voltage, 45
Tube current, 40
File date and time,01/Apr/2022 16:14
Unit cell,
h k l, 0 0 0
Scan axis,Gonio
Scan range,4.994599997,64.999991833
Scan step size,0.0262606
No. of points, 2285
Scan type,CONTINUOUS
Time per step,96.390
[Scan points]
Angle, TimePerStep, Intensity, ESD
5.007730280, 96.390, 4439.0, 66.6258
5.060251411, 96.390, 4238.0, 65.0999
5.112772541, 96.390, 4355.0, 65.9924
5.165293672, 96.390, 4226.0, 65.0077
5.217814803, 96.390, 4220.0, 64.9615
5.270335934, 96.390, 4108.0, 64.0937
5.322857064, 96.390, 4119.0, 64.1794
5.375378195, 96.390, 4119.0, 64.1794
5.427899326, 96.390, 4083.0, 63.8984
5.480420456, 96.390, 4028.0, 63.4665
5.532941587, 96.390, 3964.0, 62.9603
5.585462718, 96.390, 4071.0, 63.8044
5.637983849, 96.390, 3905.0, 62.4900
5.690504979, 96.390, 3990.0, 63.1664
5.743026110, 96.390, 3834.0, 61.9193
5.795547241, 96.390, 3890.0, 62.3699
5.848068371, 96.390, 3941.0, 62.7774
5.900589502, 96.390, 3915.0, 62.5700
5.953110633, 96.390, 3847.0, 62.0242
6.005631763, 96.390, 3839.0, 61.9597
6.058152894, 96.390, 3943.0, 62.7933
6.110674025, 96.390, 3870.0, 62.2093
6.163195156, 96.390, 3856.0, 62.0967
6.215716286, 96.390, 3852.0, 62.0645
6.268237417, 96.390, 3834.0, 61.9193
6.320758548, 96.390, 3715.0, 60.9508
6.373279678, 96.390, 3819.0, 61.7981
6.425800809, 96.390, 3682.0, 60.6795
6.478321940, 96.390, 3792.0, 61.5792
6.530843071, 96.390, 3759.0, 61.3107
6.583364201, 96.390, 3746.0, 61.2046
6.635885332, 96.390, 3769.0, 61.3922
6.688406463, 96.390, 3739.0, 61.1474
6.740927593, 96.390, 3708.0, 60.8933
6.793448724, 96.390, 3635.0, 60.2910
6.845969855, 96.390, 3627.0, 60.2246
6.898490986, 96.390, 3675.0, 60.6218
6.951012116, 96.390, 3685.0, 60.7042
7.003533247, 96.390, 3660.0, 60.4979
7.056054378, 96.390, 3702.0, 60.8441
7.108575508, 96.390, 3501.0, 59.1692
7.161096639, 96.390, 3586.0, 59.8832
7.213617770, 96.390, 3616.0, 60.1332
7.266138900, 96.390, 3584.0, 59.8665
7.318660031, 96.390, 3563.0, 59.6909
7.371181162, 96.390, 3571.0, 59.7578
7.423702293, 96.390, 3721.0, 61.0000
7.476223423, 96.390, 3673.0, 60.6053
7.528744554, 96.390, 3709.0, 60.9016
7.581265685, 96.390, 3577.0, 59.8080
7.633786815, 96.390, 3615.0, 60.1249
7.686307946, 96.390, 3568.0, 59.7327
7.738829077, 96.390, 3549.0, 59.5735
7.791350208, 96.390, 3514.0, 59.2790
7.843871338, 96.390, 3614.0, 60.1166
7.896392469, 96.390, 3595.0, 59.9583
7.948913600, 96.390, 3522.0, 59.3464
8.001434730, 96.390, 3574.0, 59.7829
8.053955861, 96.390, 3591.0, 59.9250
8.106476992, 96.390, 3549.0, 59.5735
8.158998123, 96.390, 3633.0, 60.2744
8.211519253, 96.390, 3545.0, 59.5399
8.264040384, 96.390, 3451.0, 58.7452
8.316561515, 96.390, 3488.0, 59.0593
8.369082645, 96.390, 3574.0, 59.7829
8.421603776, 96.390, 3554.0, 59.6154
8.474124907, 96.390, 3415.0, 58.4380
8.526646038, 96.390, 3442.0, 58.6686
8.579167168, 96.390, 3499.0, 59.1523
8.631688299, 96.390, 3539.0, 59.4895
8.684209430, 96.390, 3485.0, 59.0339
8.736730560, 96.390, 3465.0, 58.8643
8.789251691, 96.390, 3406.0, 58.3609
8.841772822, 96.390, 3459.0, 58.8133
8.894293952, 96.390, 3347.0, 57.8533
8.946815083, 96.390, 3505.0, 59.2030
8.999336214, 96.390, 3360.0, 57.9655
9.051857345, 96.390, 3420.0, 58.4808
9.104378475, 96.390, 3353.0, 57.9051
9.156899606, 96.390, 3386.0, 58.1893
9.209420737, 96.390, 3510.0, 59.2453
9.261941867, 96.390, 3361.0, 57.9741
9.314462998, 96.390, 3466.0, 58.8727
9.366984129, 96.390, 3410.0, 58.3952
9.419505260, 96.390, 3381.0, 58.1464
9.472026390, 96.390, 3446.0, 58.7026
9.524547521, 96.390, 3342.0, 57.8100
9.577068652, 96.390, 3375.0, 58.0948
9.629589782, 96.390, 3360.0, 57.9655
9.682110913, 96.390, 3377.0, 58.1120
9.734632044, 96.390, 3333.0, 57.7321
9.787153175, 96.390, 3406.0, 58.3609
9.839674305, 96.390, 3325.0, 57.6628
9.892195436, 96.390, 3380.0, 58.1378
9.944716567, 96.390, 3344.0, 57.8273
9.997237697, 96.390, 3363.0, 57.9914
10.049758828, 96.390, 3289.0, 57.3498
10.102279959, 96.390, 3435.0, 58.6089
10.154801090, 96.390, 3287.0, 57.3324
10.207322220, 96.390, 3273.0, 57.2101
10.259843351, 96.390, 3292.0, 57.3760
10.312364482, 96.390, 3377.0, 58.1120
10.364885612, 96.390, 3381.0, 58.1464
10.417406743, 96.390, 3689.0, 60.7371
10.469927874, 96.390, 3855.0, 62.0886
10.522449004, 96.390, 3342.0, 57.8100
10.574970135, 96.390, 3237.0, 56.8946
10.627491266, 96.390, 3251.0, 57.0175
10.680012397, 96.390, 3215.0, 56.7010
10.732533527, 96.390, 3292.0, 57.3760
10.785054658, 96.390, 3279.0, 57.2626
10.837575789, 96.390, 3326.0, 57.6715
10.890096919, 96.390, 3249.0, 57.0000
10.942618050, 96.390, 3379.0, 58.1292
10.995139181, 96.390, 3394.0, 58.2580
11.047660312, 96.390, 3387.0, 58.1979
11.100181442, 96.390, 3197.0, 56.5420
11.152702573, 96.390, 3217.0, 56.7186
11.205223704, 96.390, 3179.0, 56.3826
11.257744834, 96.390, 3154.0, 56.1605
11.310265965, 96.390, 3114.0, 55.8032
11.362787096, 96.390, 3103.0, 55.7046
11.415308227, 96.390, 3053.0, 55.2540
11.467829357, 96.390, 3111.0, 55.7763
11.520350488, 96.390, 3104.0, 55.7136
11.572871619, 96.390, 2960.0, 54.4059
11.625392749, 96.390, 2996.0, 54.7357
11.677913880, 96.390, 3080.0, 55.4977
11.730435011, 96.390, 2939.0, 54.2125
11.782956141, 96.390, 3141.0, 56.0446
11.835477272, 96.390, 3016.0, 54.9181
11.887998403, 96.390, 2875.0, 53.6190
11.940519534, 96.390, 2962.0, 54.4243
11.993040664, 96.390, 2898.0, 53.8331
12.045561795, 96.390, 2888.0, 53.7401
12.098082926, 96.390, 2908.0, 53.9259
12.150604056, 96.390, 2913.0, 53.9722
12.203125187, 96.390, 2843.0, 53.3198
12.255646318, 96.390, 2902.0, 53.8702
12.308167449, 96.390, 2799.0, 52.9056
12.360688579, 96.390, 2837.0, 53.2635
12.413209710, 96.390, 2830.0, 53.1977
12.465730841, 96.390, 2708.0, 52.0384
12.518251971, 96.390, 2864.0, 53.5164
12.570773102, 96.390, 2789.0, 52.8110
12.623294233, 96.390, 2823.0, 53.1319
12.675815364, 96.390, 2948.0, 54.2955
12.728336494, 96.390, 2957.0, 54.3783
12.780857625, 96.390, 2768.0, 52.6118
12.833378756, 96.390, 2717.0, 52.1249
12.885899886, 96.390, 2681.0, 51.7784
12.938421017, 96.390, 2651.0, 51.4879
12.990942148, 96.390, 2625.0, 51.2348
13.043463279, 96.390, 2627.0, 51.2543
13.095984409, 96.390, 2590.0, 50.8920
13.148505540, 96.390, 2512.0, 50.1199
13.201026671, 96.390, 2520.0, 50.1996
13.253547801, 96.390, 2620.0, 51.1859
13.306068932, 96.390, 2549.0, 50.4876
13.358590063, 96.390, 2667.0, 51.6430
13.411111193, 96.390, 2632.0, 51.3030
13.463632324, 96.390, 2845.0, 53.3385
13.516153455, 96.390, 2986.0, 54.6443
13.568674586, 96.390, 2791.0, 52.8299
13.621195716, 96.390, 2778.0, 52.7067
13.673716847, 96.390, 2696.0, 51.9230
13.726237978, 96.390, 2621.0, 51.1957
13.778759108, 96.390, 2867.0, 53.5444
13.831280239, 96.390, 2912.0, 53.9630
13.883801370, 96.390, 2680.0, 51.7687
13.936322501, 96.390, 2612.0, 51.1077
13.988843631, 96.390, 2497.0, 49.9700
14.041364762, 96.390, 2620.0, 51.1859
14.093885893, 96.390, 2514.0, 50.1398
14.146407023, 96.390, 2780.0, 52.7257
14.198928154, 96.390, 3195.0, 56.5243
14.251449285, 96.390, 4017.0, 63.3798
14.303970416, 96.390, 5782.0, 76.0395
14.356491546, 96.390, 3371.0, 58.0603
14.409012677, 96.390, 2498.0, 49.9800
14.461533808, 96.390, 2469.0, 49.6890
14.514054938, 96.390, 2643.0, 51.4101
14.566576069, 96.390, 2674.0, 51.7107
14.619097200, 96.390, 2412.0, 49.1121
14.671618331, 96.390, 2230.0, 47.2229
14.724139461, 96.390, 2322.0, 48.1871
14.776660592, 96.390, 2268.0, 47.6235
14.829181723, 96.390, 2309.0, 48.0521
14.881702853, 96.390, 2272.0, 47.6655
14.934223984, 96.390, 2344.0, 48.4149
14.986745115, 96.390, 2290.0, 47.8539
15.039266245, 96.390, 2334.0, 48.3115
15.091787376, 96.390, 2300.0, 47.9583
15.144308507, 96.390, 2497.0, 49.9700
15.196829638, 96.390, 2718.0, 52.1344
15.249350768, 96.390, 3048.0, 55.2087
15.301871899, 96.390, 3269.0, 57.1752
15.354393030, 96.390, 2740.0, 52.3450
15.406914160, 96.390, 2442.0, 49.4166
15.459435291, 96.390, 2419.0, 49.1833
15.511956422, 96.390, 2322.0, 48.1871
15.564477553, 96.390, 2247.0, 47.4025
15.616998683, 96.390, 2301.0, 47.9687
15.669519814, 96.390, 2316.0, 48.1248
15.722040945, 96.390, 2166.0, 46.5403
15.774562075, 96.390, 2177.0, 46.6583
15.827083206, 96.390, 2162.0, 46.4973
15.879604337, 96.390, 2226.0, 47.1805
15.932125468, 96.390, 2298.0, 47.9375
15.984646598, 96.390, 2208.0, 46.9894
16.037167729, 96.390, 2279.0, 47.7389
16.089688860, 96.390, 2282.0, 47.7703
16.142209990, 96.390, 2185.0, 46.7440
16.194731121, 96.390, 2087.0, 45.6837
16.247252252, 96.390, 2320.0, 48.1664
16.299773382, 96.390, 2300.0, 47.9583
16.352294513, 96.390, 2393.0, 48.9183
16.404815644, 96.390, 2267.0, 47.6130
16.457336775, 96.390, 2171.0, 46.5940
16.509857905, 96.390, 2245.0, 47.3814
16.562379036, 96.390, 2239.0, 47.3181
16.614900167, 96.390, 2238.0, 47.3075
16.667421297, 96.390, 2150.0, 46.3681
16.719942428, 96.390, 2142.0, 46.2817
16.772463559, 96.390, 2201.0, 46.9148
16.824984690, 96.390, 2217.0, 47.0850
16.877505820, 96.390, 2255.0, 47.4868
16.930026951, 96.390, 2322.0, 48.1871
16.982548082, 96.390, 2192.0, 46.8188
17.035069212, 96.390, 2147.0, 46.3357
17.087590343, 96.390, 2128.0, 46.1303
17.140111474, 96.390, 2042.0, 45.1885
17.192632605, 96.390, 2183.0, 46.7226
17.245153735, 96.390, 2218.0, 47.0956
17.297674866, 96.390, 2184.0, 46.7333
17.350195997, 96.390, 2372.0, 48.7032
17.402717127, 96.390, 2350.0, 48.4768
17.455238258, 96.390, 2272.0, 47.6655
17.507759389, 96.390, 2251.0, 47.4447
17.560280520, 96.390, 2161.0, 46.4866
17.612801650, 96.390, 2187.0, 46.7654
17.665322781, 96.390, 2176.0, 46.6476
17.717843912, 96.390, 2217.0, 47.0850
17.770365042, 96.390, 2182.0, 46.7119
17.822886173, 96.390, 2227.0, 47.1911
17.875407304, 96.390, 2193.0, 46.8295
17.927928434, 96.390, 2168.0, 46.5618
17.980449565, 96.390, 2175.0, 46.6369
18.032970696, 96.390, 2252.0, 47.4552
18.085491827, 96.390, 2269.0, 47.6340
18.138012957, 96.390, 2351.0, 48.4871
18.190534088, 96.390, 2223.0, 47.1487
18.243055219, 96.390, 2248.0, 47.4131
18.295576349, 96.390, 2673.0, 51.7011
18.348097480, 96.390, 2543.0, 50.4282
18.400618611, 96.390, 2443.0, 49.4267
18.453139742, 96.390, 2539.0, 50.3885
18.505660872, 96.390, 2401.0, 49.0000
18.558182003, 96.390, 2294.0, 47.8957
18.610703134, 96.390, 2238.0, 47.3075
18.663224264, 96.390, 2220.0, 47.1169
18.715745395, 96.390, 2257.0, 47.5079
18.768266526, 96.390, 2429.0, 49.2849
18.820787657, 96.390, 2382.0, 48.8057
18.873308787, 96.390, 2486.0, 49.8598
18.925829918, 96.390, 2650.0, 51.4782
18.978351049, 96.390, 2661.0, 51.5849
19.030872179, 96.390, 2713.0, 52.0865
19.083393310, 96.390, 2613.0, 51.1175
19.135914441, 96.390, 2599.0, 50.9804
19.188435572, 96.390, 2433.0, 49.3254
19.240956702, 96.390, 2402.0, 49.0102
19.293477833, 96.390, 2509.0, 50.0899
19.345998964, 96.390, 2546.0, 50.4579
19.398520094, 96.390, 2912.0, 53.9630
19.451041225, 96.390, 2974.0, 54.5344
19.503562356, 96.390, 2855.0, 53.4322
19.556083486, 96.390, 2660.0, 51.5752
19.608604617, 96.390, 2601.0, 51.0000
19.661125748, 96.390, 2528.0, 50.2792
19.713646879, 96.390, 2764.0, 52.5738
19.766168009, 96.390, 3014.0, 54.8999
19.818689140, 96.390, 3033.0, 55.0727
19.871210271, 96.390, 2971.0, 54.5069
19.923731401, 96.390, 3263.0, 57.1227
19.976252532, 96.390, 3918.0, 62.5939
20.028773663, 96.390, 3506.0, 59.2115
20.081294794, 96.390, 2817.0, 53.0754
20.133815924, 96.390, 2552.0, 50.5173
20.186337055, 96.390, 2561.0, 50.6063
20.238858186, 96.390, 2566.0, 50.6557
20.291379316, 96.390, 2594.0, 50.9313
20.343900447, 96.390, 2719.0, 52.1440
20.396421578, 96.390, 3026.0, 55.0091
20.448942709, 96.390, 3992.0, 63.1823
20.501463839, 96.390, 3522.0, 59.3464
20.553984970, 96.390, 3343.0, 57.8187
20.606506101, 96.390, 3936.0, 62.7375
20.659027231, 96.390, 4956.0, 70.3989
20.711548362, 96.390, 6280.0, 79.2465
20.764069493, 96.390, 5180.0, 71.9722
20.816590623, 96.390, 3548.0, 59.5651
20.869111754, 96.390, 2805.0, 52.9623
20.921632885, 96.390, 2605.0, 51.0392
20.974154016, 96.390, 2790.0, 52.8205
21.026675146, 96.390, 2745.0, 52.3927
21.079196277, 96.390, 2629.0, 51.2738
21.131717408, 96.390, 2532.0, 50.3190
21.184238538, 96.390, 2641.0, 51.3907
21.236759669, 96.390, 2631.0, 51.2933
21.289280800, 96.390, 2673.0, 51.7011
21.341801931, 96.390, 2767.0, 52.6023
21.394323061, 96.390, 2663.0, 51.6043
21.446844192, 96.390, 2609.0, 51.0784
21.499365323, 96.390, 2614.0, 51.1273
21.551886453, 96.390, 2735.0, 52.2972
21.604407584, 96.390, 2869.0, 53.5630
21.656928715, 96.390, 2846.0, 53.3479
21.709449846, 96.390, 2663.0, 51.6043
21.761970976, 96.390, 2677.0, 51.7397
21.814492107, 96.390, 2710.0, 52.0577
21.867013238, 96.390, 2645.0, 51.4296
21.919534368, 96.390, 2635.0, 51.3323
21.972055499, 96.390, 2603.0, 51.0196
22.024576630, 96.390, 2619.0, 51.1762
22.077097761, 96.390, 2712.0, 52.0769
22.129618891, 96.390, 2855.0, 53.4322
22.182140022, 96.390, 2693.0, 51.8941
22.234661153, 96.390, 2687.0, 51.8363
22.287182283, 96.390, 2696.0, 51.9230
22.339703414, 96.390, 2653.0, 51.5073
22.392224545, 96.390, 2660.0, 51.5752
22.444745675, 96.390, 2683.0, 51.7977
22.497266806, 96.390, 2600.0, 50.9902
22.549787937, 96.390, 2859.0, 53.4696
22.602309068, 96.390, 2820.0, 53.1037
22.654830198, 96.390, 2684.0, 51.8073
22.707351329, 96.390, 2722.0, 52.1728
22.759872460, 96.390, 2669.0, 51.6624
22.812393590, 96.390, 2846.0, 53.3479
22.864914721, 96.390, 2795.0, 52.8678
22.917435852, 96.390, 2968.0, 54.4794
22.969956983, 96.390, 2790.0, 52.8205
23.022478113, 96.390, 2750.0, 52.4404
23.074999244, 96.390, 2792.0, 52.8394
23.127520375, 96.390, 2808.0, 52.9906
23.180041505, 96.390, 2841.0, 53.3010
23.232562636, 96.390, 2875.0, 53.6190
23.285083767, 96.390, 2725.0, 52.2015
23.337604898, 96.390, 2686.0, 51.8266
23.390126028, 96.390, 2672.0, 51.6914
23.442647159, 96.390, 2714.0, 52.0961
23.495168290, 96.390, 2772.0, 52.6498
23.547689420, 96.390, 3540.0, 59.4979
23.600210551, 96.390, 3131.0, 55.9553
23.652731682, 96.390, 2683.0, 51.7977
23.705252813, 96.390, 2515.0, 50.1498
23.757773943, 96.390, 2557.0, 50.5668
23.810295074, 96.390, 2493.0, 49.9300
23.862816205, 96.390, 2375.0, 48.7340
23.915337335, 96.390, 2476.0, 49.7594
23.967858466, 96.390, 2517.0, 50.1697
24.020379597, 96.390, 2469.0, 49.6890
24.072900727, 96.390, 2625.0, 51.2348
24.125421858, 96.390, 2599.0, 50.9804
24.177942989, 96.390, 2753.0, 52.4690
24.230464120, 96.390, 3034.0, 55.0818
24.282985250, 96.390, 2799.0, 52.9056
24.335506381, 96.390, 2866.0, 53.5350
24.388027512, 96.390, 2473.0, 49.7293
24.440548642, 96.390, 2417.0, 49.1630
24.493069773, 96.390, 2557.0, 50.5668
24.545590904, 96.390, 3428.0, 58.5491
24.598112035, 96.390, 4516.0, 67.2012
24.650633165, 96.390, 3532.0, 59.4306
24.703154296, 96.390, 2404.0, 49.0306
24.755675427, 96.390, 2253.0, 47.4658
24.808196557, 96.390, 2291.0, 47.8644
24.860717688, 96.390, 2302.0, 47.9792
24.913238819, 96.390, 2233.0, 47.2546
24.965759950, 96.390, 2210.0, 47.0106
25.018281080, 96.390, 2328.0, 48.2494
25.070802211, 96.390, 2318.0, 48.1456
25.123323342, 96.390, 2229.0, 47.2123
25.175844472, 96.390, 2274.0, 47.6865
25.228365603, 96.390, 2112.0, 45.9565
25.280886734, 96.390, 2169.0, 46.5725
25.333407864, 96.390, 2258.0, 47.5184
25.385928995, 96.390, 2596.0, 50.9510
25.438450126, 96.390, 2990.0, 54.6809
25.490971257, 96.390, 2825.0, 53.1507
25.543492387, 96.390, 2416.0, 49.1528
25.596013518, 96.390, 2188.0, 46.7761
25.648534649, 96.390, 2152.0, 46.3897
25.701055779, 96.390, 2126.0, 46.1086
25.753576910, 96.390, 2036.0, 45.1221
25.806098041, 96.390, 2062.0, 45.4093
25.858619172, 96.390, 2122.0, 46.0652
25.911140302, 96.390, 2111.0, 45.9456
25.963661433, 96.390, 2055.0, 45.3321
26.016182564, 96.390, 1988.0, 44.5870
26.068703694, 96.390, 2026.0, 45.0111
26.121224825, 96.390, 1964.0, 44.3170
26.173745956, 96.390, 2009.0, 44.8219
26.226267087, 96.390, 2014.0, 44.8776
26.278788217, 96.390, 2019.0, 44.9333
26.331309348, 96.390, 2028.0, 45.0333
26.383830479, 96.390, 2058.0, 45.3652
26.436351609, 96.390, 1987.0, 44.5758
26.488872740, 96.390, 2110.0, 45.9347
26.541393871, 96.390, 2044.0, 45.2106
26.593915002, 96.390, 1956.0, 44.2267
26.646436132, 96.390, 2173.0, 46.6154
26.698957263, 96.390, 2055.0, 45.3321
26.751478394, 96.390, 2085.0, 45.6618
26.803999524, 96.390, 2199.0, 46.8935
26.856520655, 96.390, 2133.0, 46.1844
26.909041786, 96.390, 2125.0, 46.0977
26.961562916, 96.390, 2133.0, 46.1844
27.014084047, 96.390, 2282.0, 47.7703
27.066605178, 96.390, 2352.0, 48.4974
27.119126309, 96.390, 2733.0, 52.2781
27.171647439, 96.390, 3070.0, 55.4076
27.224168570, 96.390, 3227.0, 56.8067
27.276689701, 96.390, 2656.0, 51.5364
27.329210831, 96.390, 2485.0, 49.8498
27.381731962, 96.390, 2228.0, 47.2017
27.434253093, 96.390, 2054.0, 45.3211
27.486774224, 96.390, 1850.0, 43.0116
27.539295354, 96.390, 1831.0, 42.7902
27.591816485, 96.390, 1886.0, 43.4281
27.644337616, 96.390, 2022.0, 44.9667
27.696858746, 96.390, 1946.0, 44.1135
27.749379877, 96.390, 1962.0, 44.2945
27.801901008, 96.390, 1958.0, 44.2493
27.854422139, 96.390, 1971.0, 44.3959
27.906943269, 96.390, 1909.0, 43.6921
27.959464400, 96.390, 1818.0, 42.6380
28.011985531, 96.390, 1959.0, 44.2606
28.064506661, 96.390, 1946.0, 44.1135
28.117027792, 96.390, 1960.0, 44.2719
28.169548923, 96.390, 1889.0, 43.4626
28.222070054, 96.390, 2026.0, 45.0111
28.274591184, 96.390, 1980.0, 44.4972
28.327112315, 96.390, 1918.0, 43.7950
28.379633446, 96.390, 1936.0, 44.0000
28.432154576, 96.390, 1838.0, 42.8719
28.484675707, 96.390, 1936.0, 44.0000
28.537196838, 96.390, 1910.0, 43.7035
28.589717968, 96.390, 1897.0, 43.5546
28.642239099, 96.390, 1790.0, 42.3084
28.694760230, 96.390, 1942.0, 44.0681
28.747281361, 96.390, 1932.0, 43.9545
28.799802491, 96.390, 2117.0, 46.0109
28.852323622, 96.390, 2072.0, 45.5192
28.904844753, 96.390, 1993.0, 44.6430
28.957365883, 96.390, 1912.0, 43.7264
29.009887014, 96.390, 1945.0, 44.1022
29.062408145, 96.390, 2201.0, 46.9148
29.114929276, 96.390, 2297.0, 47.9270
29.167450406, 96.390, 2329.0, 48.2597
29.219971537, 96.390, 2156.0, 46.4327
29.272492668, 96.390, 2187.0, 46.7654
29.325013798, 96.390, 2253.0, 47.4658
29.377534929, 96.390, 2139.0, 46.2493
29.430056060, 96.390, 2081.0, 45.6180
29.482577191, 96.390, 2108.0, 45.9130
29.535098321, 96.390, 2063.0, 45.4203
29.587619452, 96.390, 2051.0, 45.2880
29.640140583, 96.390, 2038.0, 45.1442
29.692661713, 96.390, 1911.0, 43.7150
29.745182844, 96.390, 1846.0, 42.9651
29.797703975, 96.390, 1895.0, 43.5316
29.850225105, 96.390, 1812.0, 42.5676
29.902746236, 96.390, 1814.0, 42.5911
29.955267367, 96.390, 1816.0, 42.6146
30.007788498, 96.390, 1890.0, 43.4741
30.060309628, 96.390, 1791.0, 42.3202
30.112830759, 96.390, 1864.0, 43.1741
30.165351890, 96.390, 1824.0, 42.7083
30.217873020, 96.390, 1901.0, 43.6005
30.270394151, 96.390, 1955.0, 44.2154
30.322915282, 96.390, 1865.0, 43.1856
30.375436413, 96.390, 1882.0, 43.3820
30.427957543, 96.390, 1947.0, 44.1248
30.480478674, 96.390, 2180.0, 46.6905
30.532999805, 96.390, 2148.0, 46.3465
30.585520935, 96.390, 2132.0, 46.1736
30.638042066, 96.390, 2326.0, 48.2286
30.690563197, 96.390, 2763.0, 52.5642
30.743084328, 96.390, 2904.0, 53.8888
30.795605458, 96.390, 2624.0, 51.2250
30.848126589, 96.390, 2330.0, 48.2701
30.900647720, 96.390, 2120.0, 46.0435
30.953168850, 96.390, 2071.0, 45.5082
31.005689981, 96.390, 1911.0, 43.7150
31.058211112, 96.390, 1969.0, 44.3734
31.110732243, 96.390, 2111.0, 45.9456
31.163253373, 96.390, 2449.0, 49.4874
31.215774504, 96.390, 2956.0, 54.3691
31.268295635, 96.390, 2763.0, 52.5642
31.320816765, 96.390, 2609.0, 51.0784
31.373337896, 96.390, 2409.0, 49.0816
31.425859027, 96.390, 2372.0, 48.7032
31.478380157, 96.390, 2400.0, 48.9898
31.530901288, 96.390, 2480.0, 49.7996
31.583422419, 96.390, 2368.0, 48.6621
31.635943550, 96.390, 2736.0, 52.3068
31.688464680, 96.390, 2824.0, 53.1413
31.740985811, 96.390, 3383.0, 58.1636
31.793506942, 96.390, 2939.0, 54.2125
31.846028072, 96.390, 2255.0, 47.4868
31.898549203, 96.390, 2283.0, 47.7807
31.951070334, 96.390, 2516.0, 50.1597
32.003591465, 96.390, 3292.0, 57.3760
32.056112595, 96.390, 4723.0, 68.7241
32.108633726, 96.390, 4702.0, 68.5711
32.161154857, 96.390, 3689.0, 60.7371
32.213675987, 96.390, 2690.0, 51.8652
32.266197118, 96.390, 2326.0, 48.2286
32.318718249, 96.390, 2067.0, 45.4643
32.371239380, 96.390, 1968.0, 44.3621
32.423760510, 96.390, 1901.0, 43.6005
32.476281641, 96.390, 1795.0, 42.3674
32.528802772, 96.390, 1786.0, 42.2611
32.581323902, 96.390, 1820.0, 42.6615
32.633845033, 96.390, 1845.0, 42.9535
32.686366164, 96.390, 1914.0, 43.7493
32.738887295, 96.390, 2004.0, 44.7661
32.791408425, 96.390, 1923.0, 43.8520
32.843929556, 96.390, 1788.0, 42.2847
32.896450687, 96.390, 1920.0, 43.8178
32.948971817, 96.390, 2055.0, 45.3321
33.001492948, 96.390, 2012.0, 44.8553
33.054014079, 96.390, 2152.0, 46.3897
33.106535209, 96.390, 2222.0, 47.1381
33.159056340, 96.390, 2134.0, 46.1952
33.211577471, 96.390, 2146.0, 46.3249
33.264098602, 96.390, 2061.0, 45.3982
33.316619732, 96.390, 1976.0, 44.4522
33.369140863, 96.390, 2047.0, 45.2438
33.421661994, 96.390, 2346.0, 48.4355
33.474183124, 96.390, 2524.0, 50.2394
33.526704255, 96.390, 2353.0, 48.5077
33.579225386, 96.390, 2049.0, 45.2659
33.631746517, 96.390, 1851.0, 43.0232
33.684267647, 96.390, 1819.0, 42.6497
33.736788778, 96.390, 1853.0, 43.0465
33.789309909, 96.390, 1826.0, 42.7317
33.841831039, 96.390, 1951.0, 44.1701
33.894352170, 96.390, 2341.0, 48.3839
33.946873301, 96.390, 2867.0, 53.5444
33.999394432, 96.390, 3003.0, 54.7996
34.051915562, 96.390, 2555.0, 50.5470
34.104436693, 96.390, 2191.0, 46.8081
34.156957824, 96.390, 2049.0, 45.2659
34.209478954, 96.390, 2002.0, 44.7437
34.262000085, 96.390, 2120.0, 46.0435
34.314521216, 96.390, 2152.0, 46.3897
34.367042346, 96.390, 2260.0, 47.5395
34.419563477, 96.390, 2349.0, 48.4665
34.472084608, 96.390, 2589.0, 50.8822
34.524605739, 96.390, 2635.0, 51.3323
34.577126869, 96.390, 2712.0, 52.0769
34.629648000, 96.390, 2705.0, 52.0096
34.682169131, 96.390, 2681.0, 51.7784
34.734690261, 96.390, 2501.0, 50.0100
34.787211392, 96.390, 2475.0, 49.7494
34.839732523, 96.390, 2589.0, 50.8822
34.892253654, 96.390, 2932.0, 54.1479
34.944774784, 96.390, 3239.0, 56.9122
34.997295915, 96.390, 3215.0, 56.7010
35.049817046, 96.390, 3023.0, 54.9818
35.102338176, 96.390, 2697.0, 51.9326
35.154859307, 96.390, 2402.0, 49.0102
35.207380438, 96.390, 2521.0, 50.2096
35.259901569, 96.390, 2402.0, 49.0102
35.312422699, 96.390, 2377.0, 48.7545
35.364943830, 96.390, 2177.0, 46.6583
35.417464961, 96.390, 2096.0, 45.7821
35.469986091, 96.390, 2089.0, 45.7056
35.522507222, 96.390, 2156.0, 46.4327
35.575028353, 96.390, 2114.0, 45.9783
35.627549484, 96.390, 2148.0, 46.3465
35.680070614, 96.390, 2166.0, 46.5403
35.732591745, 96.390, 2177.0, 46.6583
35.785112876, 96.390, 2078.0, 45.5851
35.837634006, 96.390, 2094.0, 45.7602
35.890155137, 96.390, 2245.0, 47.3814
35.942676268, 96.390, 2345.0, 48.4252
35.995197398, 96.390, 2173.0, 46.6154
36.047718529, 96.390, 2405.0, 49.0408
36.100239660, 96.390, 2125.0, 46.0977
36.152760791, 96.390, 2077.0, 45.5741
36.205281921, 96.390, 2126.0, 46.1086
36.257803052, 96.390, 2141.0, 46.2709
36.310324183, 96.390, 2036.0, 45.1221
36.362845313, 96.390, 2131.0, 46.1628
36.415366444, 96.390, 1964.0, 44.3170
36.467887575, 96.390, 1967.0, 44.3509
36.520408706, 96.390, 1839.0, 42.8836
36.572929836, 96.390, 1767.0, 42.0357
36.625450967, 96.390, 1681.0, 41.0000
36.677972098, 96.390, 1833.0, 42.8135
36.730493228, 96.390, 1793.0, 42.3438
36.783014359, 96.390, 1756.0, 41.9047
36.835535490, 96.390, 1666.0, 40.8167
36.888056621, 96.390, 1656.0, 40.6940
36.940577751, 96.390, 1662.0, 40.7676
36.993098882, 96.390, 1703.0, 41.2674
37.045620013, 96.390, 1739.0, 41.7013
37.098141143, 96.390, 1604.0, 40.0500
37.150662274, 96.390, 1653.0, 40.6571
37.203183405, 96.390, 1612.0, 40.1497
37.255704535, 96.390, 1649.0, 40.6079
37.308225666, 96.390, 1656.0, 40.6940
37.360746797, 96.390, 1709.0, 41.3401
37.413267928, 96.390, 1662.0, 40.7676
37.465789058, 96.390, 1708.0, 41.3280
37.518310189, 96.390, 1724.0, 41.5211
37.570831320, 96.390, 1793.0, 42.3438
37.623352450, 96.390, 1899.0, 43.5775
37.675873581, 96.390, 1888.0, 43.4511
37.728394712, 96.390, 2098.0, 45.8039
37.780915843, 96.390, 2033.0, 45.0888
37.833436973, 96.390, 2051.0, 45.2880
37.885958104, 96.390, 1940.0, 44.0454
37.938479235, 96.390, 1778.0, 42.1663
37.991000365, 96.390, 1765.0, 42.0119
38.043521496, 96.390, 1690.0, 41.1096
38.096042627, 96.390, 1704.0, 41.2795
38.148563758, 96.390, 1779.0, 42.1782
38.201084888, 96.390, 1870.0, 43.2435
38.253606019, 96.390, 1833.0, 42.8135
38.306127150, 96.390, 1824.0, 42.7083
38.358648280, 96.390, 1693.0, 41.1461
38.411169411, 96.390, 1611.0, 40.1373
38.463690542, 96.390, 1684.0, 41.0366
38.516211673, 96.390, 1609.0, 40.1123
38.568732803, 96.390, 1680.0, 40.9878
38.621253934, 96.390, 1632.0, 40.3980
38.673775065, 96.390, 1707.0, 41.3159
38.726296195, 96.390, 1728.0, 41.5692
38.778817326, 96.390, 1889.0, 43.4626
38.831338457, 96.390, 1839.0, 42.8836
38.883859587, 96.390, 1709.0, 41.3401
38.936380718, 96.390, 1589.0, 39.8623
38.988901849, 96.390, 1513.0, 38.8973
39.041422980, 96.390, 1425.0, 37.7492
39.093944110, 96.390, 1475.0, 38.4057
39.146465241, 96.390, 1468.0, 38.3145
39.198986372, 96.390, 1585.0, 39.8121
39.251507502, 96.390, 1627.0, 40.3361
39.304028633, 96.390, 1662.0, 40.7676
39.356549764, 96.390, 1681.0, 41.0000
39.409070895, 96.390, 1876.0, 43.3128
39.461592025, 96.390, 1934.0, 43.9773
39.514113156, 96.390, 1764.0, 42.0000
39.566634287, 96.390, 1654.0, 40.6694
39.619155417, 96.390, 1592.0, 39.8999
39.671676548, 96.390, 1480.0, 38.4708
39.724197679, 96.390, 1552.0, 39.3954
39.776718810, 96.390, 1581.0, 39.7618
39.829239940, 96.390, 1575.0, 39.6863
39.881761071, 96.390, 1575.0, 39.6863
39.934282202, 96.390, 1511.0, 38.8716
39.986803332, 96.390, 1454.0, 38.1314
40.039324463, 96.390, 1536.0, 39.1918
40.091845594, 96.390, 1507.0, 38.8201
40.144366725, 96.390, 1593.0, 39.9124
40.196887855, 96.390, 1483.0, 38.5097
40.249408986, 96.390, 1369.0, 37.0000
40.301930117, 96.390, 1364.0, 36.9324
40.354451247, 96.390, 1381.0, 37.1618
40.406972378, 96.390, 1333.0, 36.5103
40.459493509, 96.390, 1277.0, 35.7351
40.512014639, 96.390, 1388.0, 37.2559
40.564535770, 96.390, 1429.0, 37.8021
40.617056901, 96.390, 1509.0, 38.8458
40.669578032, 96.390, 1480.0, 38.4708
40.722099162, 96.390, 1461.0, 38.2230
40.774620293, 96.390, 1348.0, 36.7151
40.827141424, 96.390, 1190.0, 34.4964
40.879662554, 96.390, 1293.0, 35.9583
40.932183685, 96.390, 1304.0, 36.1109
40.984704816, 96.390, 1324.0, 36.3868
41.037225947, 96.390, 1315.0, 36.2629
41.089747077, 96.390, 1422.0, 37.7094
41.142268208, 96.390, 1305.0, 36.1248
41.194789339, 96.390, 1340.0, 36.6060
41.247310469, 96.390, 1296.0, 36.0000
41.299831600, 96.390, 1369.0, 37.0000
41.352352731, 96.390, 1634.0, 40.4228
41.404873862, 96.390, 1863.0, 43.1625
41.457394992, 96.390, 1658.0, 40.7185
41.509916123, 96.390, 1620.0, 40.2492
41.562437254, 96.390, 1419.0, 37.6696
41.614958384, 96.390, 1278.0, 35.7491
41.667479515, 96.390, 1302.0, 36.0832
41.720000646, 96.390, 1294.0, 35.9722
41.772521776, 96.390, 1226.0, 35.0143
41.825042907, 96.390, 1271.0, 35.6511
41.877564038, 96.390, 1286.0, 35.8608
41.930085169, 96.390, 1229.0, 35.0571
41.982606299, 96.390, 1352.0, 36.7696
42.035127430, 96.390, 1295.0, 35.9861
42.087648561, 96.390, 1506.0, 38.8072
42.140169691, 96.390, 1910.0, 43.7035
42.192690822, 96.390, 1648.0, 40.5956
42.245211953, 96.390, 1643.0, 40.5339
42.297733084, 96.390, 1426.0, 37.7624
42.350254214, 96.390, 1353.0, 36.7831
42.402775345, 96.390, 1249.0, 35.3412
42.455296476, 96.390, 1270.0, 35.6371
42.507817606, 96.390, 1373.0, 37.0540
42.560338737, 96.390, 1374.0, 37.0675
42.612859868, 96.390, 1449.0, 38.0657
42.665380999, 96.390, 1380.0, 37.1484
42.717902129, 96.390, 1426.0, 37.7624
42.770423260, 96.390, 1359.0, 36.8646
42.822944391, 96.390, 1320.0, 36.3318
42.875465521, 96.390, 1265.0, 35.5668
42.927986652, 96.390, 1160.0, 34.0588
42.980507783, 96.390, 1219.0, 34.9142
43.033028914, 96.390, 1188.0, 34.4674
43.085550044, 96.390, 1284.0, 35.8329
43.138071175, 96.390, 1198.0, 34.6121
43.190592306, 96.390, 1141.0, 33.7787
43.243113436, 96.390, 1147.0, 33.8674
43.295634567, 96.390, 1232.0, 35.0999
43.348155698, 96.390, 1240.0, 35.2136
43.400676828, 96.390, 1109.0, 33.3017
43.453197959, 96.390, 1171.0, 34.2199
43.505719090, 96.390, 1168.0, 34.1760
43.558240221, 96.390, 1203.0, 34.6843
43.610761351, 96.390, 1264.0, 35.5528
43.663282482, 96.390, 1210.0, 34.7851
43.715803613, 96.390, 1439.0, 37.9342
43.768324743, 96.390, 1663.0, 40.7799
43.820845874, 96.390, 1612.0, 40.1497
43.873367005, 96.390, 1507.0, 38.8201
43.925888136, 96.390, 1426.0, 37.7624
43.978409266, 96.390, 1339.0, 36.5923
44.030930397, 96.390, 1294.0, 35.9722
44.083451528, 96.390, 1253.0, 35.3977
44.135972658, 96.390, 1222.0, 34.9571
44.188493789, 96.390, 1269.0, 35.6230
44.241014920, 96.390, 1409.0, 37.5366
44.293536051, 96.390, 1358.0, 36.8511
44.346057181, 96.390, 1505.0, 38.7943
44.398578312, 96.390, 1575.0, 39.6863
44.451099443, 96.390, 1523.0, 39.0256
44.503620573, 96.390, 1396.0, 37.3631
44.556141704, 96.390, 1362.0, 36.9053
44.608662835, 96.390, 1295.0, 35.9861
44.661183966, 96.390, 1321.0, 36.3456
44.713705096, 96.390, 1345.0, 36.6742
44.766226227, 96.390, 1447.0, 38.0395
44.818747358, 96.390, 1354.0, 36.7967
44.871268488, 96.390, 1415.0, 37.6165
44.923789619, 96.390, 1369.0, 37.0000
44.976310750, 96.390, 1319.0, 36.3180
45.028831880, 96.390, 1338.0, 36.5787
45.081353011, 96.390, 1476.0, 38.4187
45.133874142, 96.390, 1633.0, 40.4104
45.186395273, 96.390, 1557.0, 39.4588
45.238916403, 96.390, 1523.0, 39.0256
45.291437534, 96.390, 1561.0, 39.5095
45.343958665, 96.390, 1573.0, 39.6611
45.396479795, 96.390, 1484.0, 38.5227
45.449000926, 96.390, 1568.0, 39.5980
45.501522057, 96.390, 1604.0, 40.0500
45.554043188, 96.390, 1526.0, 39.0640
45.606564318, 96.390, 1371.0, 37.0270
45.659085449, 96.390, 1451.0, 38.0920
45.711606580, 96.390, 1351.0, 36.7560
45.764127710, 96.390, 1372.0, 37.0405
45.816648841, 96.390, 1266.0, 35.5809
45.869169972, 96.390, 1323.0, 36.3731
45.921691103, 96.390, 1272.0, 35.6651
45.974212233, 96.390, 1310.0, 36.1939
46.026733364, 96.390, 1312.0, 36.2215
46.079254495, 96.390, 1343.0, 36.6470
46.131775625, 96.390, 1399.0, 37.4032
46.184296756, 96.390, 1449.0, 38.0657
46.236817887, 96.390, 1583.0, 39.7869
46.289339017, 96.390, 1677.0, 40.9512
46.341860148, 96.390, 1680.0, 40.9878
46.394381279, 96.390, 1906.0, 43.6578
46.446902410, 96.390, 1628.0, 40.3485
46.499423540, 96.390, 1511.0, 38.8716
46.551944671, 96.390, 1557.0, 39.4588
46.604465802, 96.390, 1347.0, 36.7015
46.656986932, 96.390, 1372.0, 37.0405
46.709508063, 96.390, 1362.0, 36.9053
46.762029194, 96.390, 1344.0, 36.6606
46.814550325, 96.390, 1323.0, 36.3731
46.867071455, 96.390, 1296.0, 36.0000
46.919592586, 96.390, 1332.0, 36.4966
46.972113717, 96.390, 1434.0, 37.8682
47.024634847, 96.390, 1407.0, 37.5100
47.077155978, 96.390, 1341.0, 36.6197
47.129677109, 96.390, 1287.0, 35.8748
47.182198240, 96.390, 1217.0, 34.8855
47.234719370, 96.390, 1210.0, 34.7851
47.287240501, 96.390, 1229.0, 35.0571
47.339761632, 96.390, 1262.0, 35.5246
47.392282762, 96.390, 1300.0, 36.0555
47.444803893, 96.390, 1267.0, 35.5949
47.497325024, 96.390, 1267.0, 35.5949
47.549846155, 96.390, 1266.0, 35.5809
47.602367285, 96.390, 1275.0, 35.7071
47.654888416, 96.390, 1213.0, 34.8281
47.707409547, 96.390, 1284.0, 35.8329
47.759930677, 96.390, 1214.0, 34.8425
47.812451808, 96.390, 1266.0, 35.5809
47.864972939, 96.390, 1250.0, 35.3553
47.917494069, 96.390, 1227.0, 35.0286
47.970015200, 96.390, 1155.0, 33.9853
48.022536331, 96.390, 1188.0, 34.4674
48.075057462, 96.390, 1350.0, 36.7423
48.127578592, 96.390, 1333.0, 36.5103
48.180099723, 96.390, 1262.0, 35.5246
48.232620854, 96.390, 1333.0, 36.5103
48.285141984, 96.390, 1243.0, 35.2562
48.337663115, 96.390, 1230.0, 35.0714
48.390184246, 96.390, 1282.0, 35.8050
48.442705377, 96.390, 1331.0, 36.4829
48.495226507, 96.390, 1414.0, 37.6032
48.547747638, 96.390, 1439.0, 37.9342
48.600268769, 96.390, 1317.0, 36.2905
48.652789899, 96.390, 1228.0, 35.0428
48.705311030, 96.390, 1165.0, 34.1321
48.757832161, 96.390, 1091.0, 33.0303
48.810353292, 96.390, 1253.0, 35.3977
48.862874422, 96.390, 1083.0, 32.9090
48.915395553, 96.390, 1191.0, 34.5109
48.967916684, 96.390, 1082.0, 32.8938
49.020437814, 96.390, 1150.0, 33.9116
49.072958945, 96.390, 1150.0, 33.9116
49.125480076, 96.390, 1192.0, 34.5254
49.178001207, 96.390, 1174.0, 34.2637
49.230522337, 96.390, 1120.0, 33.4664
49.283043468, 96.390, 1119.0, 33.4515
49.335564599, 96.390, 1060.0, 32.5576
49.388085729, 96.390, 1177.0, 34.3074
49.440606860, 96.390, 1163.0, 34.1028
49.493127991, 96.390, 1066.0, 32.6497
49.545649121, 96.390, 1200.0, 34.6410
49.598170252, 96.390, 1129.0, 33.6006
49.650691383, 96.390, 1114.0, 33.3766
49.703212514, 96.390, 1218.0, 34.8999
49.755733644, 96.390, 1092.0, 33.0454
49.808254775, 96.390, 1148.0, 33.8821
49.860775906, 96.390, 1046.0, 32.3419
49.913297036, 96.390, 1030.0, 32.0936
49.965818167, 96.390, 1005.0, 31.7017
50.018339298, 96.390, 1050.0, 32.4037
50.070860429, 96.390, 1034.0, 32.1559
50.123381559, 96.390, 1001.0, 31.6386
50.175902690, 96.390, 1074.0, 32.7719
50.228423821, 96.390, 1194.0, 34.5543
50.280944951, 96.390, 1287.0, 35.8748
50.333466082, 96.390, 1204.0, 34.6987
50.385987213, 96.390, 1230.0, 35.0714
50.438508344, 96.390, 1161.0, 34.0735
50.491029474, 96.390, 1126.0, 33.5559
50.543550605, 96.390, 1108.0, 33.2866
50.596071736, 96.390, 1066.0, 32.6497
50.648592866, 96.390, 1073.0, 32.7567
50.701113997, 96.390, 1014.0, 31.8434
50.753635128, 96.390, 1052.0, 32.4345
50.806156258, 96.390, 999.0, 31.6070
50.858677389, 96.390, 1005.0, 31.7017
50.911198520, 96.390, 1027.0, 32.0468
50.963719651, 96.390, 1018.0, 31.9061
51.016240781, 96.390, 1188.0, 34.4674
51.068761912, 96.390, 1204.0, 34.6987
51.121283043, 96.390, 1136.0, 33.7046
51.173804173, 96.390, 1184.0, 34.4093
51.226325304, 96.390, 1121.0, 33.4813
51.278846435, 96.390, 1106.0, 33.2566
51.331367566, 96.390, 1016.0, 31.8748
51.383888696, 96.390, 1073.0, 32.7567
51.436409827, 96.390, 1037.0, 32.2025
51.488930958, 96.390, 1007.0, 31.7333
51.541452088, 96.390, 969.0, 31.1288
51.593973219, 96.390, 966.0, 31.0805
51.646494350, 96.390, 937.0, 30.6105
51.699015481, 96.390, 962.0, 31.0161
51.751536611, 96.390, 983.0, 31.3528
51.804057742, 96.390, 978.0, 31.2730
51.856578873, 96.390, 988.0, 31.4325
51.909100003, 96.390, 974.0, 31.2090
51.961621134, 96.390, 968.0, 31.1127
52.014142265, 96.390, 1068.0, 32.6803
52.066663396, 96.390, 1063.0, 32.6037
52.119184526, 96.390, 1064.0, 32.6190
52.171705657, 96.390, 1060.0, 32.5576
52.224226788, 96.390, 1106.0, 33.2566
52.276747918, 96.390, 1236.0, 35.1568
52.329269049, 96.390, 1299.0, 36.0416
52.381790180, 96.390, 1176.0, 34.2929
52.434311310, 96.390, 1117.0, 33.4215
52.486832441, 96.390, 1114.0, 33.3766
52.539353572, 96.390, 997.0, 31.5753
52.591874703, 96.390, 952.0, 30.8545
52.644395833, 96.390, 928.0, 30.4631
52.696916964, 96.390, 1006.0, 31.7175
52.749438095, 96.390, 936.0, 30.5941
52.801959225, 96.390, 954.0, 30.8869
52.854480356, 96.390, 989.0, 31.4484
52.907001487, 96.390, 1045.0, 32.3265
52.959522618, 96.390, 989.0, 31.4484
53.012043748, 96.390, 928.0, 30.4631
53.064564879, 96.390, 1017.0, 31.8904
53.117086010, 96.390, 994.0, 31.5278
53.169607140, 96.390, 1025.0, 32.0156
53.222128271, 96.390, 1019.0, 31.9218
53.274649402, 96.390, 1005.0, 31.7017
53.327170533, 96.390, 936.0, 30.5941
53.379691663, 96.390, 1007.0, 31.7333
53.432212794, 96.390, 872.0, 29.5296
53.484733925, 96.390, 931.0, 30.5123
53.537255055, 96.390, 915.0, 30.2490
53.589776186, 96.390, 931.0, 30.5123
53.642297317, 96.390, 913.0, 30.2159
53.694818448, 96.390, 889.0, 29.8161
53.747339578, 96.390, 856.0, 29.2575
53.799860709, 96.390, 885.0, 29.7489
53.852381840, 96.390, 987.0, 31.4166
53.904902970, 96.390, 1072.0, 32.7414
53.957424101, 96.390, 896.0, 29.9333
54.009945232, 96.390, 992.0, 31.4960
54.062466362, 96.390, 1017.0, 31.8904
54.114987493, 96.390, 1070.0, 32.7109
54.167508624, 96.390, 1109.0, 33.3017
54.220029755, 96.390, 1034.0, 32.1559
54.272550885, 96.390, 1105.0, 33.2415
54.325072016, 96.390, 1053.0, 32.4500
54.377593147, 96.390, 1035.0, 32.1714
54.430114277, 96.390, 985.0, 31.3847
54.482635408, 96.390, 954.0, 30.8869
54.535156539, 96.390, 938.0, 30.6268
54.587677670, 96.390, 974.0, 31.2090
54.640198800, 96.390, 992.0, 31.4960
54.692719931, 96.390, 879.0, 29.6479
54.745241062, 96.390, 841.0, 29.0000
54.797762192, 96.390, 901.0, 30.0167
54.850283323, 96.390, 932.0, 30.5287
54.902804454, 96.390, 879.0, 29.6479
54.955325585, 96.390, 1080.0, 32.8634
55.007846715, 96.390, 883.0, 29.7153
55.060367846, 96.390, 892.0, 29.8664
55.112888977, 96.390, 957.0, 30.9354
55.165410107, 96.390, 846.0, 29.0861
55.217931238, 96.390, 831.0, 28.8271
55.270452369, 96.390, 819.0, 28.6182
55.322973499, 96.390, 855.0, 29.2404
55.375494630, 96.390, 806.0, 28.3901
55.428015761, 96.390, 869.0, 29.4788
55.480536892, 96.390, 871.0, 29.5127
55.533058022, 96.390, 851.0, 29.1719
55.585579153, 96.390, 866.0, 29.4279
55.638100284, 96.390, 852.0, 29.1890
55.690621414, 96.390, 888.0, 29.7993
55.743142545, 96.390, 883.0, 29.7153
55.795663676, 96.390, 930.0, 30.4959
55.848184807, 96.390, 851.0, 29.1719
55.900705937, 96.390, 760.0, 27.5681
55.953227068, 96.390, 857.0, 29.2746
56.005748199, 96.390, 825.0, 28.7228
56.058269329, 96.390, 898.0, 29.9666
56.110790460, 96.390, 884.0, 29.7321
56.163311591, 96.390, 884.0, 29.7321
56.215832722, 96.390, 889.0, 29.8161
56.268353852, 96.390, 963.0, 31.0322
56.320874983, 96.390, 836.0, 28.9137
56.373396114, 96.390, 886.0, 29.7658
56.425917244, 96.390, 846.0, 29.0861
56.478438375, 96.390, 818.0, 28.6007
56.530959506, 96.390, 834.0, 28.8791
56.583480637, 96.390, 811.0, 28.4781
56.636001767, 96.390, 812.0, 28.4956
56.688522898, 96.390, 804.0, 28.3549
56.741044029, 96.390, 799.0, 28.2666
56.793565159, 96.390, 820.0, 28.6356
56.846086290, 96.390, 820.0, 28.6356
56.898607421, 96.390, 811.0, 28.4781
56.951128551, 96.390, 785.0, 28.0179
57.003649682, 96.390, 825.0, 28.7228
57.056170813, 96.390, 772.0, 27.7849
57.108691944, 96.390, 803.0, 28.3373
57.161213074, 96.390, 863.0, 29.3769
57.213734205, 96.390, 829.0, 28.7924
57.266255336, 96.390, 814.0, 28.5307
57.318776466, 96.390, 843.0, 29.0345
57.371297597, 96.390, 865.0, 29.4109
57.423818728, 96.390, 835.0, 28.8964
57.476339859, 96.390, 839.0, 28.9655
57.528860989, 96.390, 903.0, 30.0500
57.581382120, 96.390, 808.0, 28.4253
57.633903251, 96.390, 841.0, 29.0000
57.686424381, 96.390, 933.0, 30.5450
57.738945512, 96.390, 901.0, 30.0167
57.791466643, 96.390, 836.0, 28.9137
57.843987774, 96.390, 818.0, 28.6007
57.896508904, 96.390, 817.0, 28.5832
57.949030035, 96.390, 864.0, 29.3939
58.001551166, 96.390, 928.0, 30.4631
58.054072296, 96.390, 1020.0, 31.9374
58.106593427, 96.390, 943.0, 30.7083
58.159114558, 96.390, 889.0, 29.8161
58.211635689, 96.390, 903.0, 30.0500
58.264156819, 96.390, 838.0, 28.9482
58.316677950, 96.390, 855.0, 29.2404
58.369199081, 96.390, 794.0, 28.1780
58.421720211, 96.390, 791.0, 28.1247
58.474241342, 96.390, 817.0, 28.5832
58.526762473, 96.390, 788.0, 28.0713
58.579283603, 96.390, 854.0, 29.2233
58.631804734, 96.390, 808.0, 28.4253
58.684325865, 96.390, 825.0, 28.7228
58.736846996, 96.390, 751.0, 27.4044
58.789368126, 96.390, 825.0, 28.7228
58.841889257, 96.390, 811.0, 28.4781
58.894410388, 96.390, 734.0, 27.0924
58.946931518, 96.390, 791.0, 28.1247
58.999452649, 96.390, 774.0, 27.8209
59.051973780, 96.390, 875.0, 29.5804
59.104494911, 96.390, 748.0, 27.3496
59.157016041, 96.390, 810.0, 28.4605
59.209537172, 96.390, 815.0, 28.5482
59.262058303, 96.390, 870.0, 29.4958
59.314579433, 96.390, 882.0, 29.6985
59.367100564, 96.390, 924.0, 30.3974
59.419621695, 96.390, 837.0, 28.9310
59.472142826, 96.390, 874.0, 29.5635
59.524663956, 96.390, 843.0, 29.0345
59.577185087, 96.390, 855.0, 29.2404
59.629706218, 96.390, 893.0, 29.8831
59.682227348, 96.390, 870.0, 29.4958
59.734748479, 96.390, 860.0, 29.3258
59.787269610, 96.390, 905.0, 30.0832
59.839790740, 96.390, 910.0, 30.1662
59.892311871, 96.390, 860.0, 29.3258
59.944833002, 96.390, 918.0, 30.2985
59.997354133, 96.390, 979.0, 31.2890
60.049875263, 96.390, 919.0, 30.3150
60.102396394, 96.390, 926.0, 30.4302
60.154917525, 96.390, 930.0, 30.4959
60.207438655, 96.390, 934.0, 30.5614
60.259959786, 96.390, 948.0, 30.7896
60.312480917, 96.390, 945.0, 30.7409
60.365002048, 96.390, 987.0, 31.4166
60.417523178, 96.390, 1007.0, 31.7333
60.470044309, 96.390, 1076.0, 32.8024
60.522565440, 96.390, 988.0, 31.4325
60.575086570, 96.390, 1008.0, 31.7490
60.627607701, 96.390, 1049.0, 32.3883
60.680128832, 96.390, 1139.0, 33.7491
60.732649963, 96.390, 1109.0, 33.3017
60.785171093, 96.390, 1092.0, 33.0454
60.837692224, 96.390, 1153.0, 33.9559
60.890213355, 96.390, 1125.0, 33.5410
60.942734485, 96.390, 1125.0, 33.5410
60.995255616, 96.390, 1227.0, 35.0286
61.047776747, 96.390, 1129.0, 33.6006
61.100297878, 96.390, 1136.0, 33.7046
61.152819008, 96.390, 1273.0, 35.6791
61.205340139, 96.390, 1335.0, 36.5377
61.257861270, 96.390, 1235.0, 35.1426
61.310382400, 96.390, 1263.0, 35.5387
61.362903531, 96.390, 1262.0, 35.5246
61.415424662, 96.390, 1166.0, 34.1467
61.467945792, 96.390, 1261.0, 35.5106
61.520466923, 96.390, 1258.0, 35.4683
61.572988054, 96.390, 1246.0, 35.2987
61.625509185, 96.390, 1175.0, 34.2783
61.678030315, 96.390, 1171.0, 34.2199
61.730551446, 96.390, 1102.0, 33.1964
61.783072577, 96.390, 1136.0, 33.7046
61.835593707, 96.390, 1135.0, 33.6898
61.888114838, 96.390, 1095.0, 33.0908
61.940635969, 96.390, 1154.0, 33.9706
61.993157100, 96.390, 1102.0, 33.1964
62.045678230, 96.390, 1076.0, 32.8024
62.098199361, 96.390, 1073.0, 32.7567
62.150720492, 96.390, 1137.0, 33.7194
62.203241622, 96.390, 1132.0, 33.6452
62.255762753, 96.390, 1146.0, 33.8526
62.308283884, 96.390, 1045.0, 32.3265
62.360805015, 96.390, 1063.0, 32.6037
62.413326145, 96.390, 1016.0, 31.8748
62.465847276, 96.390, 998.0, 31.5911
62.518368407, 96.390, 990.0, 31.4643
62.570889537, 96.390, 1024.0, 32.0000
62.623410668, 96.390, 1036.0, 32.1870
62.675931799, 96.390, 1043.0, 32.2955
62.728452930, 96.390, 966.0, 31.0805
62.780974060, 96.390, 1037.0, 32.2025
62.833495191, 96.390, 926.0, 30.4302
62.886016322, 96.390, 970.0, 31.1448
62.938537452, 96.390, 880.0, 29.6648
62.991058583, 96.390, 850.0, 29.1548
63.043579714, 96.390, 849.0, 29.1376
63.096100844, 96.390, 865.0, 29.4109
63.148621975, 96.390, 816.0, 28.5657
63.201143106, 96.390, 832.0, 28.8444
63.253664237, 96.390, 814.0, 28.5307
63.306185367, 96.390, 819.0, 28.6182
63.358706498, 96.390, 840.0, 28.9828
63.411227629, 96.390, 816.0, 28.5657
63.463748759, 96.390, 813.0, 28.5132
63.516269890, 96.390, 790.0, 28.1069
63.568791021, 96.390, 805.0, 28.3725
63.621312152, 96.390, 774.0, 27.8209
63.673833282, 96.390, 777.0, 27.8747
63.726354413, 96.390, 816.0, 28.5657
63.778875544, 96.390, 819.0, 28.6182
63.831396674, 96.390, 803.0, 28.3373
63.883917805, 96.390, 806.0, 28.3901
63.936438936, 96.390, 824.0, 28.7054
63.988960067, 96.390, 779.0, 27.9106
64.041481197, 96.390, 807.0, 28.4077
64.094002328, 96.390, 806.0, 28.3901
64.146523459, 96.390, 782.0, 27.9643
64.199044589, 96.390, 793.0, 28.1603
64.251565720, 96.390, 778.0, 27.8927
64.304086851, 96.390, 797.0, 28.2312
64.356607981, 96.390, 751.0, 27.4044
64.409129112, 96.390, 731.0, 27.0370
64.461650243, 96.390, 852.0, 29.1890
64.514171374, 96.390, 797.0, 28.2312
64.566692504, 96.390, 736.0, 27.1293
64.619213635, 96.390, 742.0, 27.2397
64.671734766, 96.390, 736.0, 27.1293
64.724255896, 96.390, 741.0, 27.2213
64.776777027, 96.390, 739.0, 27.1846
64.829298158, 96.390, 704.0, 26.5330
64.881819289, 96.390, 708.0, 26.6083
64.934340419, 96.390, 707.0, 26.5895
64.986861550, 96.390, 724.0, 26.9072