File: Files_organized_for_plots/Centroid_age/XRD_Centroid08Dec21_Act08Mar22_B2_0714M_NaOH_LS0163_14day.csv
[Measurement conditions]
Sample identification,XRD_Centroid08Dec21_Act08Mar22_B2_0714M_NaOH_LS0163_1
Comment - 1,"Configuration=Stage for Flat Samples/Holders, Owner=User-1, Creation date=7/1/2020 9:53:24 AM"
Comment - 2,"Goniometer=Theta/Theta; Minimum step size 2Theta:0.0001; Minimum step size Omega:0.0001"
Comment - 3,"Sample stage=Stage for flat samples/holders"
Comment - 4,"Diffractometer system=EMPYREAN"
Comment - 5,"Measurement program=C:\Users\ibo5034\OneDrive - The Pennsylvania State University\NEUP\Zerobackground scan.xrdmp, Identifier={98A3B11C-88F9-4AA6-982C-73314A311EF5}"
Anode material,Cu
K-Alpha1 wavelength,1.5405980
K-Alpha2 wavelength,1.5444260
Ratio K-Alpha2/K-Alpha1,0.500
Divergence slit,Fixed,0.25
Monochromator used,NO
Generator voltage, 45
Tube current, 40
File date and time,24/Mar/2022 17:20
Unit cell,
h k l, 0 0 0
Scan axis,Gonio
Scan range,4.994599997,64.999991833
Scan step size,0.0262606
No. of points, 2285
Scan type,CONTINUOUS
Time per step,96.390
[Scan points]
Angle, TimePerStep, Intensity, ESD
5.007730280, 96.390, 4335.0, 65.8407
5.060251411, 96.390, 4274.0, 65.3758
5.112772541, 96.390, 4292.0, 65.5134
5.165293672, 96.390, 4349.0, 65.9469
5.217814803, 96.390, 4279.0, 65.4141
5.270335934, 96.390, 4201.0, 64.8151
5.322857064, 96.390, 4141.0, 64.3506
5.375378195, 96.390, 4168.0, 64.5600
5.427899326, 96.390, 4050.0, 63.6396
5.480420456, 96.390, 4019.0, 63.3956
5.532941587, 96.390, 4050.0, 63.6396
5.585462718, 96.390, 4019.0, 63.3956
5.637983849, 96.390, 4075.0, 63.8357
5.690504979, 96.390, 3988.0, 63.1506
5.743026110, 96.390, 3985.0, 63.1269
5.795547241, 96.390, 3960.0, 62.9285
5.848068371, 96.390, 3973.0, 63.0317
5.900589502, 96.390, 3913.0, 62.5540
5.953110633, 96.390, 4108.0, 64.0937
6.005631763, 96.390, 3900.0, 62.4500
6.058152894, 96.390, 3896.0, 62.4179
6.110674025, 96.390, 3959.0, 62.9206
6.163195156, 96.390, 3863.0, 62.1530
6.215716286, 96.390, 3866.0, 62.1772
6.268237417, 96.390, 3776.0, 61.4492
6.320758548, 96.390, 3847.0, 62.0242
6.373279678, 96.390, 3872.0, 62.2254
6.425800809, 96.390, 3840.0, 61.9677
6.478321940, 96.390, 3999.0, 63.2376
6.530843071, 96.390, 3896.0, 62.4179
6.583364201, 96.390, 3802.0, 61.6604
6.635885332, 96.390, 3851.0, 62.0564
6.688406463, 96.390, 3784.0, 61.5142
6.740927593, 96.390, 3904.0, 62.4820
6.793448724, 96.390, 3711.0, 60.9180
6.845969855, 96.390, 3901.0, 62.4580
6.898490986, 96.390, 3668.0, 60.5640
6.951012116, 96.390, 3790.0, 61.5630
7.003533247, 96.390, 3782.0, 61.4980
7.056054378, 96.390, 3838.0, 61.9516
7.108575508, 96.390, 3726.0, 61.0410
7.161096639, 96.390, 3800.0, 61.6441
7.213617770, 96.390, 3812.0, 61.7414
7.266138900, 96.390, 3730.0, 61.0737
7.318660031, 96.390, 3762.0, 61.3351
7.371181162, 96.390, 3882.0, 62.3057
7.423702293, 96.390, 3763.0, 61.3433
7.476223423, 96.390, 3609.0, 60.0750
7.528744554, 96.390, 3745.0, 61.1964
7.581265685, 96.390, 3552.0, 59.5987
7.633786815, 96.390, 3693.0, 60.7701
7.686307946, 96.390, 3713.0, 60.9344
7.738829077, 96.390, 3654.0, 60.4483
7.791350208, 96.390, 3652.0, 60.4318
7.843871338, 96.390, 3686.0, 60.7124
7.896392469, 96.390, 3617.0, 60.1415
7.948913600, 96.390, 3548.0, 59.5651
8.001434730, 96.390, 3678.0, 60.6465
8.053955861, 96.390, 3601.0, 60.0083
8.106476992, 96.390, 3531.0, 59.4222
8.158998123, 96.390, 3531.0, 59.4222
8.211519253, 96.390, 3474.0, 58.9406
8.264040384, 96.390, 3629.0, 60.2412
8.316561515, 96.390, 3589.0, 59.9083
8.369082645, 96.390, 3601.0, 60.0083
8.421603776, 96.390, 3515.0, 59.2874
8.474124907, 96.390, 3701.0, 60.8358
8.526646038, 96.390, 3563.0, 59.6909
8.579167168, 96.390, 3517.0, 59.3043
8.631688299, 96.390, 3531.0, 59.4222
8.684209430, 96.390, 3548.0, 59.5651
8.736730560, 96.390, 3520.0, 59.3296
8.789251691, 96.390, 3535.0, 59.4559
8.841772822, 96.390, 3524.0, 59.3633
8.894293952, 96.390, 3708.0, 60.8933
8.946815083, 96.390, 3366.0, 58.0172
8.999336214, 96.390, 3455.0, 58.7792
9.051857345, 96.390, 3463.0, 58.8473
9.104378475, 96.390, 3512.0, 59.2621
9.156899606, 96.390, 3537.0, 59.4727
9.209420737, 96.390, 3445.0, 58.6941
9.261941867, 96.390, 3414.0, 58.4294
9.314462998, 96.390, 3456.0, 58.7878
9.366984129, 96.390, 3513.0, 59.2706
9.419505260, 96.390, 3430.0, 58.5662
9.472026390, 96.390, 3481.0, 59.0000
9.524547521, 96.390, 3479.0, 58.9830
9.577068652, 96.390, 3376.0, 58.1034
9.629589782, 96.390, 3296.0, 57.4108
9.682110913, 96.390, 3324.0, 57.6541
9.734632044, 96.390, 3309.0, 57.5239
9.787153175, 96.390, 3385.0, 58.1808
9.839674305, 96.390, 3356.0, 57.9310
9.892195436, 96.390, 3407.0, 58.3695
9.944716567, 96.390, 3343.0, 57.8187
9.997237697, 96.390, 3445.0, 58.6941
10.049758828, 96.390, 3323.0, 57.6455
10.102279959, 96.390, 3352.0, 57.8965
10.154801090, 96.390, 3262.0, 57.1139
10.207322220, 96.390, 3244.0, 56.9561
10.259843351, 96.390, 3335.0, 57.7495
10.312364482, 96.390, 3394.0, 58.2580
10.364885612, 96.390, 3222.0, 56.7627
10.417406743, 96.390, 3276.0, 57.2364
10.469927874, 96.390, 3256.0, 57.0614
10.522449004, 96.390, 3232.0, 56.8507
10.574970135, 96.390, 3256.0, 57.0614
10.627491266, 96.390, 3267.0, 57.1577
10.680012397, 96.390, 3237.0, 56.8946
10.732533527, 96.390, 3245.0, 56.9649
10.785054658, 96.390, 3363.0, 57.9914
10.837575789, 96.390, 3280.0, 57.2713
10.890096919, 96.390, 3114.0, 55.8032
10.942618050, 96.390, 3375.0, 58.0948
10.995139181, 96.390, 3240.0, 56.9210
11.047660312, 96.390, 3203.0, 56.5951
11.100181442, 96.390, 3213.0, 56.6833
11.152702573, 96.390, 3123.0, 55.8838
11.205223704, 96.390, 3088.0, 55.5698
11.257744834, 96.390, 3084.0, 55.5338
11.310265965, 96.390, 3092.0, 55.6058
11.362787096, 96.390, 3229.0, 56.8243
11.415308227, 96.390, 3129.0, 55.9375
11.467829357, 96.390, 3125.0, 55.9017
11.520350488, 96.390, 3057.0, 55.2901
11.572871619, 96.390, 2941.0, 54.2310
11.625392749, 96.390, 3047.0, 55.1996
11.677913880, 96.390, 3098.0, 55.6597
11.730435011, 96.390, 3035.0, 55.0908
11.782956141, 96.390, 3082.0, 55.5158
11.835477272, 96.390, 2866.0, 53.5350
11.887998403, 96.390, 2981.0, 54.5985
11.940519534, 96.390, 2832.0, 53.2165
11.993040664, 96.390, 2828.0, 53.1789
12.045561795, 96.390, 2893.0, 53.7866
12.098082926, 96.390, 2784.0, 52.7636
12.150604056, 96.390, 2774.0, 52.6688
12.203125187, 96.390, 2891.0, 53.7680
12.255646318, 96.390, 2738.0, 52.3259
12.308167449, 96.390, 2911.0, 53.9537
12.360688579, 96.390, 2710.0, 52.0577
12.413209710, 96.390, 2788.0, 52.8015
12.465730841, 96.390, 2705.0, 52.0096
12.518251971, 96.390, 2735.0, 52.2972
12.570773102, 96.390, 2761.0, 52.5452
12.623294233, 96.390, 2733.0, 52.2781
12.675815364, 96.390, 2819.0, 53.0943
12.728336494, 96.390, 2707.0, 52.0288
12.780857625, 96.390, 2772.0, 52.6498
12.833378756, 96.390, 2583.0, 50.8232
12.885899886, 96.390, 2657.0, 51.5461
12.938421017, 96.390, 2669.0, 51.6624
12.990942148, 96.390, 2591.0, 50.9019
13.043463279, 96.390, 2658.0, 51.5558
13.095984409, 96.390, 2691.0, 51.8748
13.148505540, 96.390, 2581.0, 50.8035
13.201026671, 96.390, 2564.0, 50.6360
13.253547801, 96.390, 2589.0, 50.8822
13.306068932, 96.390, 2632.0, 51.3030
13.358590063, 96.390, 2657.0, 51.5461
13.411111193, 96.390, 2742.0, 52.3641
13.463632324, 96.390, 2883.0, 53.6936
13.516153455, 96.390, 3208.0, 56.6392
13.568674586, 96.390, 2710.0, 52.0577
13.621195716, 96.390, 2589.0, 50.8822
13.673716847, 96.390, 2504.0, 50.0400
13.726237978, 96.390, 2509.0, 50.0899
13.778759108, 96.390, 2593.0, 50.9215
13.831280239, 96.390, 2670.0, 51.6720
13.883801370, 96.390, 2791.0, 52.8299
13.936322501, 96.390, 2742.0, 52.3641
13.988843631, 96.390, 2433.0, 49.3254
14.041364762, 96.390, 2436.0, 49.3559
14.093885893, 96.390, 2538.0, 50.3786
14.146407023, 96.390, 2659.0, 51.5655
14.198928154, 96.390, 2742.0, 52.3641
14.251449285, 96.390, 3258.0, 57.0789
14.303970416, 96.390, 3207.0, 56.6304
14.356491546, 96.390, 2463.0, 49.6286
14.409012677, 96.390, 2425.0, 49.2443
14.461533808, 96.390, 2371.0, 48.6929
14.514054938, 96.390, 2415.0, 49.1426
14.566576069, 96.390, 2471.0, 49.7092
14.619097200, 96.390, 2356.0, 48.5386
14.671618331, 96.390, 2197.0, 46.8722
14.724139461, 96.390, 2310.0, 48.0625
14.776660592, 96.390, 2288.0, 47.8330
14.829181723, 96.390, 2259.0, 47.5289
14.881702853, 96.390, 2408.0, 49.0714
14.934223984, 96.390, 2311.0, 48.0729
14.986745115, 96.390, 2224.0, 47.1593
15.039266245, 96.390, 2326.0, 48.2286
15.091787376, 96.390, 2375.0, 48.7340
15.144308507, 96.390, 2548.0, 50.4777
15.196829638, 96.390, 2852.0, 53.4041
15.249350768, 96.390, 3169.0, 56.2939
15.301871899, 96.390, 3460.0, 58.8218
15.354393030, 96.390, 2671.0, 51.6817
15.406914160, 96.390, 2310.0, 48.0625
15.459435291, 96.390, 2236.0, 47.2864
15.511956422, 96.390, 2290.0, 47.8539
15.564477553, 96.390, 2191.0, 46.8081
15.616998683, 96.390, 2200.0, 46.9042
15.669519814, 96.390, 2257.0, 47.5079
15.722040945, 96.390, 2196.0, 46.8615
15.774562075, 96.390, 2159.0, 46.4650
15.827083206, 96.390, 2189.0, 46.7868
15.879604337, 96.390, 2207.0, 46.9787
15.932125468, 96.390, 2239.0, 47.3181
15.984646598, 96.390, 2137.0, 46.2277
16.037167729, 96.390, 2338.0, 48.3529
16.089688860, 96.390, 2179.0, 46.6798
16.142209990, 96.390, 2217.0, 47.0850
16.194731121, 96.390, 2094.0, 45.7602
16.247252252, 96.390, 2170.0, 46.5833
16.299773382, 96.390, 2162.0, 46.4973
16.352294513, 96.390, 2256.0, 47.4974
16.404815644, 96.390, 2175.0, 46.6369
16.457336775, 96.390, 2154.0, 46.4112
16.509857905, 96.390, 2225.0, 47.1699
16.562379036, 96.390, 2248.0, 47.4131
16.614900167, 96.390, 2153.0, 46.4004
16.667421297, 96.390, 2212.0, 47.0319
16.719942428, 96.390, 2167.0, 46.5510
16.772463559, 96.390, 2287.0, 47.8226
16.824984690, 96.390, 2211.0, 47.0213
16.877505820, 96.390, 2157.0, 46.4435
16.930026951, 96.390, 2233.0, 47.2546
16.982548082, 96.390, 2257.0, 47.5079
17.035069212, 96.390, 2213.0, 47.0425
17.087590343, 96.390, 2225.0, 47.1699
17.140111474, 96.390, 2192.0, 46.8188
17.192632605, 96.390, 2155.0, 46.4220
17.245153735, 96.390, 2235.0, 47.2758
17.297674866, 96.390, 2172.0, 46.6047
17.350195997, 96.390, 2241.0, 47.3392
17.402717127, 96.390, 2211.0, 47.0213
17.455238258, 96.390, 2313.0, 48.0937
17.507759389, 96.390, 2276.0, 47.7074
17.560280520, 96.390, 2185.0, 46.7440
17.612801650, 96.390, 2286.0, 47.8121
17.665322781, 96.390, 2193.0, 46.8295
17.717843912, 96.390, 2245.0, 47.3814
17.770365042, 96.390, 2178.0, 46.6690
17.822886173, 96.390, 2155.0, 46.4220
17.875407304, 96.390, 2275.0, 47.6970
17.927928434, 96.390, 2257.0, 47.5079
17.980449565, 96.390, 2213.0, 47.0425
18.032970696, 96.390, 2261.0, 47.5500
18.085491827, 96.390, 2202.0, 46.9255
18.138012957, 96.390, 2328.0, 48.2494
18.190534088, 96.390, 2205.0, 46.9574
18.243055219, 96.390, 2362.0, 48.6004
18.295576349, 96.390, 2385.0, 48.8365
18.348097480, 96.390, 2447.0, 49.4672
18.400618611, 96.390, 2356.0, 48.5386
18.453139742, 96.390, 2297.0, 47.9270
18.505660872, 96.390, 2361.0, 48.5901
18.558182003, 96.390, 2271.0, 47.6550
18.610703134, 96.390, 2268.0, 47.6235
18.663224264, 96.390, 2284.0, 47.7912
18.715745395, 96.390, 2276.0, 47.7074
18.768266526, 96.390, 2280.0, 47.7493
18.820787657, 96.390, 2394.0, 48.9285
18.873308787, 96.390, 2486.0, 49.8598
18.925829918, 96.390, 2362.0, 48.6004
18.978351049, 96.390, 2482.0, 49.8197
19.030872179, 96.390, 2324.0, 48.2079
19.083393310, 96.390, 2419.0, 49.1833
19.135914441, 96.390, 2369.0, 48.6724
19.188435572, 96.390, 2393.0, 48.9183
19.240956702, 96.390, 2434.0, 49.3356
19.293477833, 96.390, 2401.0, 49.0000
19.345998964, 96.390, 2618.0, 51.1664
19.398520094, 96.390, 2886.0, 53.7215
19.451041225, 96.390, 3027.0, 55.0182
19.503562356, 96.390, 2756.0, 52.4976
19.556083486, 96.390, 2544.0, 50.4381
19.608604617, 96.390, 2578.0, 50.7740
19.661125748, 96.390, 2780.0, 52.7257
19.713646879, 96.390, 2829.0, 53.1883
19.766168009, 96.390, 2897.0, 53.8238
19.818689140, 96.390, 3056.0, 55.2811
19.871210271, 96.390, 3272.0, 57.2014
19.923731401, 96.390, 3856.0, 62.0967
19.976252532, 96.390, 4832.0, 69.5126
20.028773663, 96.390, 3888.0, 62.3538
20.081294794, 96.390, 2832.0, 53.2165
20.133815924, 96.390, 2530.0, 50.2991
20.186337055, 96.390, 2508.0, 50.0799
20.238858186, 96.390, 2573.0, 50.7247
20.291379316, 96.390, 2663.0, 51.6043
20.343900447, 96.390, 2672.0, 51.6914
20.396421578, 96.390, 2813.0, 53.0377
20.448942709, 96.390, 2927.0, 54.1018
20.501463839, 96.390, 3178.0, 56.3738
20.553984970, 96.390, 3384.0, 58.1722
20.606506101, 96.390, 4245.0, 65.1537
20.659027231, 96.390, 6179.0, 78.6066
20.711548362, 96.390, 8692.0, 93.2309
20.764069493, 96.390, 6726.0, 82.0122
20.816590623, 96.390, 3743.0, 61.1801
20.869111754, 96.390, 2856.0, 53.4416
20.921632885, 96.390, 2737.0, 52.3163
20.974154016, 96.390, 2702.0, 51.9808
21.026675146, 96.390, 2656.0, 51.5364
21.079196277, 96.390, 2646.0, 51.4393
21.131717408, 96.390, 2561.0, 50.6063
21.184238538, 96.390, 2586.0, 50.8527
21.236759669, 96.390, 2647.0, 51.4490
21.289280800, 96.390, 2641.0, 51.3907
21.341801931, 96.390, 2649.0, 51.4684
21.394323061, 96.390, 2581.0, 50.8035
21.446844192, 96.390, 2531.0, 50.3090
21.499365323, 96.390, 2649.0, 51.4684
21.551886453, 96.390, 2671.0, 51.6817
21.604407584, 96.390, 2646.0, 51.4393
21.656928715, 96.390, 2706.0, 52.0192
21.709449846, 96.390, 2671.0, 51.6817
21.761970976, 96.390, 2657.0, 51.5461
21.814492107, 96.390, 2633.0, 51.3128
21.867013238, 96.390, 2695.0, 51.9134
21.919534368, 96.390, 2681.0, 51.7784
21.972055499, 96.390, 2568.0, 50.6754
22.024576630, 96.390, 2661.0, 51.5849
22.077097761, 96.390, 2681.0, 51.7784
22.129618891, 96.390, 2658.0, 51.5558
22.182140022, 96.390, 2597.0, 50.9608
22.234661153, 96.390, 2599.0, 50.9804
22.287182283, 96.390, 2555.0, 50.5470
22.339703414, 96.390, 2571.0, 50.7050
22.392224545, 96.390, 2665.0, 51.6236
22.444745675, 96.390, 2534.0, 50.3389
22.497266806, 96.390, 2679.0, 51.7591
22.549787937, 96.390, 2550.0, 50.4975
22.602309068, 96.390, 2637.0, 51.3517
22.654830198, 96.390, 2646.0, 51.4393
22.707351329, 96.390, 2601.0, 51.0000
22.759872460, 96.390, 2719.0, 52.1440
22.812393590, 96.390, 2730.0, 52.2494
22.864914721, 96.390, 2727.0, 52.2207
22.917435852, 96.390, 2701.0, 51.9711
22.969956983, 96.390, 2768.0, 52.6118
23.022478113, 96.390, 2608.0, 51.0686
23.074999244, 96.390, 2611.0, 51.0979
23.127520375, 96.390, 2650.0, 51.4782
23.180041505, 96.390, 2706.0, 52.0192
23.232562636, 96.390, 2670.0, 51.6720
23.285083767, 96.390, 2632.0, 51.3030
23.337604898, 96.390, 2614.0, 51.1273
23.390126028, 96.390, 2512.0, 50.1199
23.442647159, 96.390, 2712.0, 52.0769
23.495168290, 96.390, 2624.0, 51.2250
23.547689420, 96.390, 2692.0, 51.8845
23.600210551, 96.390, 2597.0, 50.9608
23.652731682, 96.390, 2576.0, 50.7543
23.705252813, 96.390, 2478.0, 49.7795
23.757773943, 96.390, 2563.0, 50.6261
23.810295074, 96.390, 2398.0, 48.9694
23.862816205, 96.390, 2553.0, 50.5272
23.915337335, 96.390, 2477.0, 49.7695
23.967858466, 96.390, 2574.0, 50.7346
24.020379597, 96.390, 2450.0, 49.4975
24.072900727, 96.390, 2629.0, 51.2738
24.125421858, 96.390, 2742.0, 52.3641
24.177942989, 96.390, 3015.0, 54.9090
24.230464120, 96.390, 2895.0, 53.8052
24.282985250, 96.390, 2573.0, 50.7247
24.335506381, 96.390, 2519.0, 50.1896
24.388027512, 96.390, 2383.0, 48.8160
24.440548642, 96.390, 2341.0, 48.3839
24.493069773, 96.390, 2410.0, 49.0918
24.545590904, 96.390, 2397.0, 48.9592
24.598112035, 96.390, 2363.0, 48.6107
24.650633165, 96.390, 2250.0, 47.4342
24.703154296, 96.390, 2306.0, 48.0208
24.755675427, 96.390, 2221.0, 47.1275
24.808196557, 96.390, 2243.0, 47.3603
24.860717688, 96.390, 2125.0, 46.0977
24.913238819, 96.390, 2237.0, 47.2969
24.965759950, 96.390, 2244.0, 47.3709
25.018281080, 96.390, 2273.0, 47.6760
25.070802211, 96.390, 2209.0, 47.0000
25.123323342, 96.390, 2168.0, 46.5618
25.175844472, 96.390, 2103.0, 45.8585
25.228365603, 96.390, 2252.0, 47.4552
25.280886734, 96.390, 2256.0, 47.4974
25.333407864, 96.390, 2398.0, 48.9694
25.385928995, 96.390, 2793.0, 52.8488
25.438450126, 96.390, 3368.0, 58.0345
25.490971257, 96.390, 3095.0, 55.6327
25.543492387, 96.390, 2593.0, 50.9215
25.596013518, 96.390, 2210.0, 47.0106
25.648534649, 96.390, 2111.0, 45.9456
25.701055779, 96.390, 2074.0, 45.5412
25.753576910, 96.390, 2066.0, 45.4533
25.806098041, 96.390, 2027.0, 45.0222
25.858619172, 96.390, 2059.0, 45.3762
25.911140302, 96.390, 2037.0, 45.1331
25.963661433, 96.390, 2142.0, 46.2817
26.016182564, 96.390, 2051.0, 45.2880
26.068703694, 96.390, 2028.0, 45.0333
26.121224825, 96.390, 1953.0, 44.1928
26.173745956, 96.390, 2066.0, 45.4533
26.226267087, 96.390, 1954.0, 44.2041
26.278788217, 96.390, 1962.0, 44.2945
26.331309348, 96.390, 2045.0, 45.2217
26.383830479, 96.390, 1995.0, 44.6654
26.436351609, 96.390, 2026.0, 45.0111
26.488872740, 96.390, 2072.0, 45.5192
26.541393871, 96.390, 2050.0, 45.2769
26.593915002, 96.390, 1922.0, 43.8406
26.646436132, 96.390, 1963.0, 44.3058
26.698957263, 96.390, 1919.0, 43.8064
26.751478394, 96.390, 1982.0, 44.5197
26.803999524, 96.390, 2027.0, 45.0222
26.856520655, 96.390, 1990.0, 44.6094
26.909041786, 96.390, 2063.0, 45.4203
26.961562916, 96.390, 2014.0, 44.8776
27.014084047, 96.390, 2161.0, 46.4866
27.066605178, 96.390, 2225.0, 47.1699
27.119126309, 96.390, 2705.0, 52.0096
27.171647439, 96.390, 3530.0, 59.4138
27.224168570, 96.390, 3371.0, 58.0603
27.276689701, 96.390, 2709.0, 52.0481
27.329210831, 96.390, 2090.0, 45.7165
27.381731962, 96.390, 1983.0, 44.5309
27.434253093, 96.390, 1952.0, 44.1814
27.486774224, 96.390, 1965.0, 44.3283
27.539295354, 96.390, 2004.0, 44.7661
27.591816485, 96.390, 1873.0, 43.2782
27.644337616, 96.390, 1916.0, 43.7721
27.696858746, 96.390, 1902.0, 43.6119
27.749379877, 96.390, 1892.0, 43.4971
27.801901008, 96.390, 1932.0, 43.9545
27.854422139, 96.390, 1954.0, 44.2041
27.906943269, 96.390, 1983.0, 44.5309
27.959464400, 96.390, 2012.0, 44.8553
28.011985531, 96.390, 1988.0, 44.5870
28.064506661, 96.390, 2015.0, 44.8888
28.117027792, 96.390, 2057.0, 45.3542
28.169548923, 96.390, 2060.0, 45.3872
28.222070054, 96.390, 1970.0, 44.3847
28.274591184, 96.390, 1956.0, 44.2267
28.327112315, 96.390, 1984.0, 44.5421
28.379633446, 96.390, 1855.0, 43.0697
28.432154576, 96.390, 1903.0, 43.6234
28.484675707, 96.390, 1964.0, 44.3170
28.537196838, 96.390, 1933.0, 43.9659
28.589717968, 96.390, 1933.0, 43.9659
28.642239099, 96.390, 2060.0, 45.3872
28.694760230, 96.390, 2069.0, 45.4863
28.747281361, 96.390, 2238.0, 47.3075
28.799802491, 96.390, 2271.0, 47.6550
28.852323622, 96.390, 2142.0, 46.2817
28.904844753, 96.390, 1924.0, 43.8634
28.957365883, 96.390, 1985.0, 44.5533
29.009887014, 96.390, 2091.0, 45.7275
29.062408145, 96.390, 2338.0, 48.3529
29.114929276, 96.390, 2508.0, 50.0799
29.167450406, 96.390, 2324.0, 48.2079
29.219971537, 96.390, 2118.0, 46.0217
29.272492668, 96.390, 2025.0, 45.0000
29.325013798, 96.390, 2044.0, 45.2106
29.377534929, 96.390, 1933.0, 43.9659
29.430056060, 96.390, 1959.0, 44.2606
29.482577191, 96.390, 2001.0, 44.7325
29.535098321, 96.390, 1944.0, 44.0908
29.587619452, 96.390, 1904.0, 43.6348
29.640140583, 96.390, 1938.0, 44.0227
29.692661713, 96.390, 1982.0, 44.5197
29.745182844, 96.390, 1935.0, 43.9886
29.797703975, 96.390, 1859.0, 43.1161
29.850225105, 96.390, 1827.0, 42.7434
29.902746236, 96.390, 1936.0, 44.0000
29.955267367, 96.390, 1875.0, 43.3013
30.007788498, 96.390, 1880.0, 43.3590
30.060309628, 96.390, 1813.0, 42.5793
30.112830759, 96.390, 1906.0, 43.6578
30.165351890, 96.390, 1837.0, 42.8602
30.217873020, 96.390, 1898.0, 43.5660
30.270394151, 96.390, 1894.0, 43.5201
30.322915282, 96.390, 1813.0, 42.5793
30.375436413, 96.390, 1918.0, 43.7950
30.427957543, 96.390, 2027.0, 45.0222
30.480478674, 96.390, 2032.0, 45.0777
30.532999805, 96.390, 2016.0, 44.8999
30.585520935, 96.390, 2133.0, 46.1844
30.638042066, 96.390, 2236.0, 47.2864
30.690563197, 96.390, 2457.0, 49.5681
30.743084328, 96.390, 2465.0, 49.6488
30.795605458, 96.390, 2368.0, 48.6621
30.848126589, 96.390, 2370.0, 48.6826
30.900647720, 96.390, 2143.0, 46.2925
30.953168850, 96.390, 2142.0, 46.2817
31.005689981, 96.390, 2053.0, 45.3100
31.058211112, 96.390, 2077.0, 45.5741
31.110732243, 96.390, 2301.0, 47.9687
31.163253373, 96.390, 2677.0, 51.7397
31.215774504, 96.390, 3277.0, 57.2451
31.268295635, 96.390, 2926.0, 54.0925
31.320816765, 96.390, 2543.0, 50.4282
31.373337896, 96.390, 2142.0, 46.2817
31.425859027, 96.390, 2246.0, 47.3920
31.478380157, 96.390, 2282.0, 47.7703
31.530901288, 96.390, 2340.0, 48.3735
31.583422419, 96.390, 2401.0, 49.0000
31.635943550, 96.390, 2383.0, 48.8160
31.688464680, 96.390, 2262.0, 47.5605
31.740985811, 96.390, 2201.0, 46.9148
31.793506942, 96.390, 2155.0, 46.4220
31.846028072, 96.390, 2180.0, 46.6905
31.898549203, 96.390, 2544.0, 50.4381
31.951070334, 96.390, 3233.0, 56.8595
32.003591465, 96.390, 4825.0, 69.4622
32.056112595, 96.390, 6852.0, 82.7768
32.108633726, 96.390, 6292.0, 79.3221
32.161154857, 96.390, 4645.0, 68.1542
32.213675987, 96.390, 2899.0, 53.8424
32.266197118, 96.390, 2250.0, 47.4342
32.318718249, 96.390, 2066.0, 45.4533
32.371239380, 96.390, 1943.0, 44.0795
32.423760510, 96.390, 1896.0, 43.5431
32.476281641, 96.390, 1914.0, 43.7493
32.528802772, 96.390, 1899.0, 43.5775
32.581323902, 96.390, 1820.0, 42.6615
32.633845033, 96.390, 1898.0, 43.5660
32.686366164, 96.390, 1930.0, 43.9318
32.738887295, 96.390, 1942.0, 44.0681
32.791408425, 96.390, 1877.0, 43.3244
32.843929556, 96.390, 1811.0, 42.5558
32.896450687, 96.390, 1861.0, 43.1393
32.948971817, 96.390, 1904.0, 43.6348
33.001492948, 96.390, 1900.0, 43.5890
33.054014079, 96.390, 1978.0, 44.4747
33.106535209, 96.390, 2050.0, 45.2769
33.159056340, 96.390, 2059.0, 45.3762
33.211577471, 96.390, 1997.0, 44.6878
33.264098602, 96.390, 1961.0, 44.2832
33.316619732, 96.390, 1909.0, 43.6921
33.369140863, 96.390, 1959.0, 44.2606
33.421661994, 96.390, 2097.0, 45.7930
33.474183124, 96.390, 2074.0, 45.5412
33.526704255, 96.390, 2103.0, 45.8585
33.579225386, 96.390, 1957.0, 44.2380
33.631746517, 96.390, 1933.0, 43.9659
33.684267647, 96.390, 1929.0, 43.9204
33.736788778, 96.390, 1964.0, 44.3170
33.789309909, 96.390, 2021.0, 44.9555
33.841831039, 96.390, 2212.0, 47.0319
33.894352170, 96.390, 2828.0, 53.1789
33.946873301, 96.390, 3547.0, 59.5567
33.999394432, 96.390, 3663.0, 60.5227
34.051915562, 96.390, 2925.0, 54.0833
34.104436693, 96.390, 2485.0, 49.8498
34.156957824, 96.390, 2169.0, 46.5725
34.209478954, 96.390, 2158.0, 46.4543
34.262000085, 96.390, 2104.0, 45.8694
34.314521216, 96.390, 2213.0, 47.0425
34.367042346, 96.390, 2304.0, 48.0000
34.419563477, 96.390, 2392.0, 48.9081
34.472084608, 96.390, 2645.0, 51.4296
34.524605739, 96.390, 2519.0, 50.1896
34.577126869, 96.390, 2569.0, 50.6853
34.629648000, 96.390, 2434.0, 49.3356
34.682169131, 96.390, 2368.0, 48.6621
34.734690261, 96.390, 2396.0, 48.9490
34.787211392, 96.390, 2561.0, 50.6063
34.839732523, 96.390, 2933.0, 54.1572
34.892253654, 96.390, 3614.0, 60.1166
34.944774784, 96.390, 3948.0, 62.8331
34.997295915, 96.390, 3548.0, 59.5651
35.049817046, 96.390, 3071.0, 55.4166
35.102338176, 96.390, 2614.0, 51.1273
35.154859307, 96.390, 2371.0, 48.6929
35.207380438, 96.390, 2382.0, 48.8057
35.259901569, 96.390, 2321.0, 48.1768
35.312422699, 96.390, 2334.0, 48.3115
35.364943830, 96.390, 2143.0, 46.2925
35.417464961, 96.390, 2173.0, 46.6154
35.469986091, 96.390, 2162.0, 46.4973
35.522507222, 96.390, 2190.0, 46.7974
35.575028353, 96.390, 2226.0, 47.1805
35.627549484, 96.390, 2288.0, 47.8330
35.680070614, 96.390, 2212.0, 47.0319
35.732591745, 96.390, 2205.0, 46.9574
35.785112876, 96.390, 2230.0, 47.2229
35.837634006, 96.390, 2153.0, 46.4004
35.890155137, 96.390, 2056.0, 45.3431
35.942676268, 96.390, 2070.0, 45.4973
35.995197398, 96.390, 2079.0, 45.5961
36.047718529, 96.390, 2066.0, 45.4533
36.100239660, 96.390, 1952.0, 44.1814
36.152760791, 96.390, 2087.0, 45.6837
36.205281921, 96.390, 2007.0, 44.7996
36.257803052, 96.390, 1946.0, 44.1135
36.310324183, 96.390, 1851.0, 43.0232
36.362845313, 96.390, 1922.0, 43.8406
36.415366444, 96.390, 1857.0, 43.0929
36.467887575, 96.390, 1858.0, 43.1045
36.520408706, 96.390, 1784.0, 42.2374
36.572929836, 96.390, 1792.0, 42.3320
36.625450967, 96.390, 1776.0, 42.1426
36.677972098, 96.390, 1778.0, 42.1663
36.730493228, 96.390, 1755.0, 41.8927
36.783014359, 96.390, 1781.0, 42.2019
36.835535490, 96.390, 1735.0, 41.6533
36.888056621, 96.390, 1750.0, 41.8330
36.940577751, 96.390, 1763.0, 41.9881
36.993098882, 96.390, 1658.0, 40.7185
37.045620013, 96.390, 1723.0, 41.5090
37.098141143, 96.390, 1731.0, 41.6053
37.150662274, 96.390, 1757.0, 41.9166
37.203183405, 96.390, 1770.0, 42.0714
37.255704535, 96.390, 1728.0, 41.5692
37.308225666, 96.390, 1623.0, 40.2865
37.360746797, 96.390, 1750.0, 41.8330
37.413267928, 96.390, 1734.0, 41.6413
37.465789058, 96.390, 1750.0, 41.8330
37.518310189, 96.390, 1759.0, 41.9404
37.570831320, 96.390, 1811.0, 42.5558
37.623352450, 96.390, 1904.0, 43.6348
37.675873581, 96.390, 2152.0, 46.3897
37.728394712, 96.390, 2340.0, 48.3735
37.780915843, 96.390, 2283.0, 47.7807
37.833436973, 96.390, 2144.0, 46.3033
37.885958104, 96.390, 1861.0, 43.1393
37.938479235, 96.390, 1774.0, 42.1189
37.991000365, 96.390, 1674.0, 40.9145
38.043521496, 96.390, 1760.0, 41.9524
38.096042627, 96.390, 1770.0, 42.0714
38.148563758, 96.390, 1904.0, 43.6348
38.201084888, 96.390, 1942.0, 44.0681
38.253606019, 96.390, 1775.0, 42.1307
38.306127150, 96.390, 1780.0, 42.1900
38.358648280, 96.390, 1723.0, 41.5090
38.411169411, 96.390, 1720.0, 41.4729
38.463690542, 96.390, 1675.0, 40.9268
38.516211673, 96.390, 1682.0, 41.0122
38.568732803, 96.390, 1666.0, 40.8167
38.621253934, 96.390, 1689.0, 41.0974
38.673775065, 96.390, 1810.0, 42.5441
38.726296195, 96.390, 1989.0, 44.5982
38.778817326, 96.390, 2108.0, 45.9130
38.831338457, 96.390, 1977.0, 44.4635
38.883859587, 96.390, 1979.0, 44.4860
38.936380718, 96.390, 1672.0, 40.8901
38.988901849, 96.390, 1647.0, 40.5832
39.041422980, 96.390, 1562.0, 39.5221
39.093944110, 96.390, 1561.0, 39.5095
39.146465241, 96.390, 1576.0, 39.6989
39.198986372, 96.390, 1548.0, 39.3446
39.251507502, 96.390, 1662.0, 40.7676
39.304028633, 96.390, 1795.0, 42.3674
39.356549764, 96.390, 1908.0, 43.6807
39.409070895, 96.390, 2360.0, 48.5798
39.461592025, 96.390, 2240.0, 47.3286
39.514113156, 96.390, 2054.0, 45.3211
39.566634287, 96.390, 1839.0, 42.8836
39.619155417, 96.390, 1631.0, 40.3856
39.671676548, 96.390, 1559.0, 39.4842
39.724197679, 96.390, 1570.0, 39.6232
39.776718810, 96.390, 1530.0, 39.1152
39.829239940, 96.390, 1468.0, 38.3145
39.881761071, 96.390, 1540.0, 39.2428
39.934282202, 96.390, 1487.0, 38.5616
39.986803332, 96.390, 1527.0, 39.0768
40.039324463, 96.390, 1579.0, 39.7366
40.091845594, 96.390, 1649.0, 40.6079
40.144366725, 96.390, 1661.0, 40.7554
40.196887855, 96.390, 1601.0, 40.0125
40.249408986, 96.390, 1526.0, 39.0640
40.301930117, 96.390, 1472.0, 38.3667
40.354451247, 96.390, 1496.0, 38.6782
40.406972378, 96.390, 1429.0, 37.8021
40.459493509, 96.390, 1396.0, 37.3631
40.512014639, 96.390, 1480.0, 38.4708
40.564535770, 96.390, 1575.0, 39.6863
40.617056901, 96.390, 1624.0, 40.2989
40.669578032, 96.390, 1536.0, 39.1918
40.722099162, 96.390, 1451.0, 38.0920
40.774620293, 96.390, 1429.0, 37.8021
40.827141424, 96.390, 1435.0, 37.8814
40.879662554, 96.390, 1395.0, 37.3497
40.932183685, 96.390, 1365.0, 36.9459
40.984704816, 96.390, 1372.0, 37.0405
41.037225947, 96.390, 1416.0, 37.6298
41.089747077, 96.390, 1387.0, 37.2424
41.142268208, 96.390, 1452.0, 38.1051
41.194789339, 96.390, 1382.0, 37.1753
41.247310469, 96.390, 1550.0, 39.3700
41.299831600, 96.390, 1712.0, 41.3763
41.352352731, 96.390, 1955.0, 44.2154
41.404873862, 96.390, 2192.0, 46.8188
41.457394992, 96.390, 1787.0, 42.2729
41.509916123, 96.390, 1713.0, 41.3884
41.562437254, 96.390, 1453.0, 38.1182
41.614958384, 96.390, 1357.0, 36.8375
41.667479515, 96.390, 1284.0, 35.8329
41.720000646, 96.390, 1333.0, 36.5103
41.772521776, 96.390, 1288.0, 35.8887
41.825042907, 96.390, 1297.0, 36.0139
41.877564038, 96.390, 1257.0, 35.4542
41.930085169, 96.390, 1262.0, 35.5246
41.982606299, 96.390, 1348.0, 36.7151
42.035127430, 96.390, 1405.0, 37.4833
42.087648561, 96.390, 1474.0, 38.3927
42.140169691, 96.390, 1619.0, 40.2368
42.192690822, 96.390, 1556.0, 39.4462
42.245211953, 96.390, 1550.0, 39.3700
42.297733084, 96.390, 1428.0, 37.7889
42.350254214, 96.390, 1343.0, 36.6470
42.402775345, 96.390, 1258.0, 35.4683
42.455296476, 96.390, 1401.0, 37.4299
42.507817606, 96.390, 1447.0, 38.0395
42.560338737, 96.390, 1520.0, 38.9872
42.612859868, 96.390, 1495.0, 38.6652
42.665380999, 96.390, 1479.0, 38.4578
42.717902129, 96.390, 1364.0, 36.9324
42.770423260, 96.390, 1325.0, 36.4005
42.822944391, 96.390, 1295.0, 35.9861
42.875465521, 96.390, 1343.0, 36.6470
42.927986652, 96.390, 1297.0, 36.0139
42.980507783, 96.390, 1301.0, 36.0694
43.033028914, 96.390, 1230.0, 35.0714
43.085550044, 96.390, 1243.0, 35.2562
43.138071175, 96.390, 1238.0, 35.1852
43.190592306, 96.390, 1270.0, 35.6371
43.243113436, 96.390, 1266.0, 35.5809
43.295634567, 96.390, 1160.0, 34.0588
43.348155698, 96.390, 1273.0, 35.6791
43.400676828, 96.390, 1317.0, 36.2905
43.453197959, 96.390, 1247.0, 35.3129
43.505719090, 96.390, 1264.0, 35.5528
43.558240221, 96.390, 1367.0, 36.9730
43.610761351, 96.390, 1367.0, 36.9730
43.663282482, 96.390, 1554.0, 39.4208
43.715803613, 96.390, 1892.0, 43.4971
43.768324743, 96.390, 2154.0, 46.4112
43.820845874, 96.390, 2012.0, 44.8553
43.873367005, 96.390, 1850.0, 43.0116
43.925888136, 96.390, 1686.0, 41.0609
43.978409266, 96.390, 1512.0, 38.8844
44.030930397, 96.390, 1385.0, 37.2156
44.083451528, 96.390, 1387.0, 37.2424
44.135972658, 96.390, 1342.0, 36.6333
44.188493789, 96.390, 1342.0, 36.6333
44.241014920, 96.390, 1351.0, 36.7560
44.293536051, 96.390, 1492.0, 38.6264
44.346057181, 96.390, 1637.0, 40.4599
44.398578312, 96.390, 1747.0, 41.7971
44.451099443, 96.390, 1718.0, 41.4488
44.503620573, 96.390, 1537.0, 39.2046
44.556141704, 96.390, 1460.0, 38.2099
44.608662835, 96.390, 1340.0, 36.6060
44.661183966, 96.390, 1342.0, 36.6333
44.713705096, 96.390, 1385.0, 37.2156
44.766226227, 96.390, 1392.0, 37.3095
44.818747358, 96.390, 1460.0, 38.2099
44.871268488, 96.390, 1459.0, 38.1969
44.923789619, 96.390, 1452.0, 38.1051
44.976310750, 96.390, 1432.0, 37.8418
45.028831880, 96.390, 1571.0, 39.6358
45.081353011, 96.390, 1748.0, 41.8091
45.133874142, 96.390, 1881.0, 43.3705
45.186395273, 96.390, 1782.0, 42.2137
45.238916403, 96.390, 1750.0, 41.8330
45.291437534, 96.390, 1853.0, 43.0465
45.343958665, 96.390, 1868.0, 43.2204
45.396479795, 96.390, 1816.0, 42.6146
45.449000926, 96.390, 1918.0, 43.7950
45.501522057, 96.390, 1864.0, 43.1741
45.554043188, 96.390, 1615.0, 40.1871
45.606564318, 96.390, 1653.0, 40.6571
45.659085449, 96.390, 1536.0, 39.1918
45.711606580, 96.390, 1440.0, 37.9473
45.764127710, 96.390, 1366.0, 36.9594
45.816648841, 96.390, 1456.0, 38.1576
45.869169972, 96.390, 1412.0, 37.5766
45.921691103, 96.390, 1407.0, 37.5100
45.974212233, 96.390, 1528.0, 39.0896
46.026733364, 96.390, 1418.0, 37.6563
46.079254495, 96.390, 1422.0, 37.7094
46.131775625, 96.390, 1506.0, 38.8072
46.184296756, 96.390, 1549.0, 39.3573
46.236817887, 96.390, 1724.0, 41.5211
46.289339017, 96.390, 1759.0, 41.9404
46.341860148, 96.390, 1652.0, 40.6448
46.394381279, 96.390, 1676.0, 40.9390
46.446902410, 96.390, 1520.0, 38.9872
46.499423540, 96.390, 1396.0, 37.3631
46.551944671, 96.390, 1406.0, 37.4967
46.604465802, 96.390, 1380.0, 37.1484
46.656986932, 96.390, 1396.0, 37.3631
46.709508063, 96.390, 1326.0, 36.4143
46.762029194, 96.390, 1446.0, 38.0263
46.814550325, 96.390, 1334.0, 36.5240
46.867071455, 96.390, 1416.0, 37.6298
46.919592586, 96.390, 1398.0, 37.3898
46.972113717, 96.390, 1567.0, 39.5854
47.024634847, 96.390, 1502.0, 38.7556
47.077155978, 96.390, 1512.0, 38.8844
47.129677109, 96.390, 1473.0, 38.3797
47.182198240, 96.390, 1374.0, 37.0675
47.234719370, 96.390, 1361.0, 36.8917
47.287240501, 96.390, 1403.0, 37.4566
47.339761632, 96.390, 1332.0, 36.4966
47.392282762, 96.390, 1309.0, 36.1801
47.444803893, 96.390, 1259.0, 35.4824
47.497325024, 96.390, 1330.0, 36.4692
47.549846155, 96.390, 1276.0, 35.7211
47.602367285, 96.390, 1297.0, 36.0139
47.654888416, 96.390, 1306.0, 36.1386
47.707409547, 96.390, 1230.0, 35.0714
47.759930677, 96.390, 1216.0, 34.8712
47.812451808, 96.390, 1309.0, 36.1801
47.864972939, 96.390, 1186.0, 34.4384
47.917494069, 96.390, 1289.0, 35.9026
47.970015200, 96.390, 1306.0, 36.1386
48.022536331, 96.390, 1412.0, 37.5766
48.075057462, 96.390, 1405.0, 37.4833
48.127578592, 96.390, 1470.0, 38.3406
48.180099723, 96.390, 1460.0, 38.2099
48.232620854, 96.390, 1380.0, 37.1484
48.285141984, 96.390, 1392.0, 37.3095
48.337663115, 96.390, 1315.0, 36.2629
48.390184246, 96.390, 1354.0, 36.7967
48.442705377, 96.390, 1443.0, 37.9868
48.495226507, 96.390, 1526.0, 39.0640
48.547747638, 96.390, 1492.0, 38.6264
48.600268769, 96.390, 1369.0, 37.0000
48.652789899, 96.390, 1357.0, 36.8375
48.705311030, 96.390, 1227.0, 35.0286
48.757832161, 96.390, 1217.0, 34.8855
48.810353292, 96.390, 1192.0, 34.5254
48.862874422, 96.390, 1186.0, 34.4384
48.915395553, 96.390, 1208.0, 34.7563
48.967916684, 96.390, 1211.0, 34.7994
49.020437814, 96.390, 1245.0, 35.2846
49.072958945, 96.390, 1109.0, 33.3017
49.125480076, 96.390, 1169.0, 34.1906
49.178001207, 96.390, 1217.0, 34.8855
49.230522337, 96.390, 1149.0, 33.8969
49.283043468, 96.390, 1234.0, 35.1283
49.335564599, 96.390, 1178.0, 34.3220
49.388085729, 96.390, 1119.0, 33.4515
49.440606860, 96.390, 1169.0, 34.1906
49.493127991, 96.390, 1170.0, 34.2053
49.545649121, 96.390, 1236.0, 35.1568
49.598170252, 96.390, 1134.0, 33.6749
49.650691383, 96.390, 1182.0, 34.3802
49.703212514, 96.390, 1163.0, 34.1028
49.755733644, 96.390, 1118.0, 33.4365
49.808254775, 96.390, 1171.0, 34.2199
49.860775906, 96.390, 1100.0, 33.1662
49.913297036, 96.390, 1126.0, 33.5559
49.965818167, 96.390, 1060.0, 32.5576
50.018339298, 96.390, 1067.0, 32.6650
50.070860429, 96.390, 1095.0, 33.0908
50.123381559, 96.390, 1122.0, 33.4963
50.175902690, 96.390, 1254.0, 35.4119
50.228423821, 96.390, 1458.0, 38.1838
50.280944951, 96.390, 1475.0, 38.4057
50.333466082, 96.390, 1303.0, 36.0971
50.385987213, 96.390, 1311.0, 36.2077
50.438508344, 96.390, 1161.0, 34.0735
50.491029474, 96.390, 1187.0, 34.4529
50.543550605, 96.390, 1052.0, 32.4345
50.596071736, 96.390, 1049.0, 32.3883
50.648592866, 96.390, 1079.0, 32.8481
50.701113997, 96.390, 1203.0, 34.6843
50.753635128, 96.390, 1057.0, 32.5115
50.806156258, 96.390, 1055.0, 32.4808
50.858677389, 96.390, 1045.0, 32.3265
50.911198520, 96.390, 1067.0, 32.6650
50.963719651, 96.390, 1088.0, 32.9848
51.016240781, 96.390, 1039.0, 32.2335
51.068761912, 96.390, 1099.0, 33.1512
51.121283043, 96.390, 1104.0, 33.2265
51.173804173, 96.390, 1120.0, 33.4664
51.226325304, 96.390, 1241.0, 35.2278
51.278846435, 96.390, 1182.0, 34.3802
51.331367566, 96.390, 1160.0, 34.0588
51.383888696, 96.390, 1150.0, 33.9116
51.436409827, 96.390, 1059.0, 32.5423
51.488930958, 96.390, 1003.0, 31.6702
51.541452088, 96.390, 946.0, 30.7571
51.593973219, 96.390, 999.0, 31.6070
51.646494350, 96.390, 1006.0, 31.7175
51.699015481, 96.390, 1064.0, 32.6190
51.751536611, 96.390, 1087.0, 32.9697
51.804057742, 96.390, 1062.0, 32.5883
51.856578873, 96.390, 1137.0, 33.7194
51.909100003, 96.390, 1099.0, 33.1512
51.961621134, 96.390, 1101.0, 33.1813
52.014142265, 96.390, 1087.0, 32.9697
52.066663396, 96.390, 1147.0, 33.8674
52.119184526, 96.390, 1185.0, 34.4238
52.171705657, 96.390, 1322.0, 36.3593
52.224226788, 96.390, 1435.0, 37.8814
52.276747918, 96.390, 1406.0, 37.4967
52.329269049, 96.390, 1335.0, 36.5377
52.381790180, 96.390, 1302.0, 36.0832
52.434311310, 96.390, 1113.0, 33.3617
52.486832441, 96.390, 1091.0, 33.0303
52.539353572, 96.390, 1057.0, 32.5115
52.591874703, 96.390, 1023.0, 31.9844
52.644395833, 96.390, 1027.0, 32.0468
52.696916964, 96.390, 1103.0, 33.2114
52.749438095, 96.390, 1114.0, 33.3766
52.801959225, 96.390, 1103.0, 33.2114
52.854480356, 96.390, 1081.0, 32.8786
52.907001487, 96.390, 1072.0, 32.7414
52.959522618, 96.390, 1114.0, 33.3766
53.012043748, 96.390, 1013.0, 31.8277
53.064564879, 96.390, 1000.0, 31.6228
53.117086010, 96.390, 998.0, 31.5911
53.169607140, 96.390, 1092.0, 33.0454
53.222128271, 96.390, 1076.0, 32.8024
53.274649402, 96.390, 1040.0, 32.2490
53.327170533, 96.390, 1106.0, 33.2566
53.379691663, 96.390, 1069.0, 32.6956
53.432212794, 96.390, 1039.0, 32.2335
53.484733925, 96.390, 1011.0, 31.7962
53.537255055, 96.390, 1014.0, 31.8434
53.589776186, 96.390, 1014.0, 31.8434
53.642297317, 96.390, 940.0, 30.6594
53.694818448, 96.390, 911.0, 30.1828
53.747339578, 96.390, 970.0, 31.1448
53.799860709, 96.390, 923.0, 30.3809
53.852381840, 96.390, 983.0, 31.3528
53.904902970, 96.390, 1016.0, 31.8748
53.957424101, 96.390, 958.0, 30.9516
54.009945232, 96.390, 1044.0, 32.3110
54.062466362, 96.390, 1104.0, 33.2265
54.114987493, 96.390, 1155.0, 33.9853
54.167508624, 96.390, 1184.0, 34.4093
54.220029755, 96.390, 1113.0, 33.3617
54.272550885, 96.390, 1134.0, 33.6749
54.325072016, 96.390, 1245.0, 35.2846
54.377593147, 96.390, 1110.0, 33.3167
54.430114277, 96.390, 1039.0, 32.2335
54.482635408, 96.390, 958.0, 30.9516
54.535156539, 96.390, 981.0, 31.3209
54.587677670, 96.390, 969.0, 31.1288
54.640198800, 96.390, 944.0, 30.7246
54.692719931, 96.390, 837.0, 28.9310
54.745241062, 96.390, 930.0, 30.4959
54.797762192, 96.390, 885.0, 29.7489
54.850283323, 96.390, 869.0, 29.4788
54.902804454, 96.390, 928.0, 30.4631
54.955325585, 96.390, 921.0, 30.3480
55.007846715, 96.390, 890.0, 29.8329
55.060367846, 96.390, 874.0, 29.5635
55.112888977, 96.390, 934.0, 30.5614
55.165410107, 96.390, 817.0, 28.5832
55.217931238, 96.390, 859.0, 29.3087
55.270452369, 96.390, 901.0, 30.0167
55.322973499, 96.390, 850.0, 29.1548
55.375494630, 96.390, 946.0, 30.7571
55.428015761, 96.390, 939.0, 30.6431
55.480536892, 96.390, 950.0, 30.8221
55.533058022, 96.390, 1029.0, 32.0780
55.585579153, 96.390, 1062.0, 32.5883
55.638100284, 96.390, 953.0, 30.8707
55.690621414, 96.390, 983.0, 31.3528
55.743142545, 96.390, 972.0, 31.1769
55.795663676, 96.390, 990.0, 31.4643
55.848184807, 96.390, 938.0, 30.6268
55.900705937, 96.390, 940.0, 30.6594
55.953227068, 96.390, 886.0, 29.7658
56.005748199, 96.390, 917.0, 30.2820
56.058269329, 96.390, 947.0, 30.7734
56.110790460, 96.390, 947.0, 30.7734
56.163311591, 96.390, 837.0, 28.9310
56.215832722, 96.390, 919.0, 30.3150
56.268353852, 96.390, 870.0, 29.4958
56.320874983, 96.390, 861.0, 29.3428
56.373396114, 96.390, 902.0, 30.0333
56.425917244, 96.390, 898.0, 29.9666
56.478438375, 96.390, 853.0, 29.2062
56.530959506, 96.390, 850.0, 29.1548
56.583480637, 96.390, 863.0, 29.3769
56.636001767, 96.390, 903.0, 30.0500
56.688522898, 96.390, 921.0, 30.3480
56.741044029, 96.390, 863.0, 29.3769
56.793565159, 96.390, 859.0, 29.3087
56.846086290, 96.390, 866.0, 29.4279
56.898607421, 96.390, 878.0, 29.6311
56.951128551, 96.390, 950.0, 30.8221
57.003649682, 96.390, 833.0, 28.8617
57.056170813, 96.390, 865.0, 29.4109
57.108691944, 96.390, 872.0, 29.5296
57.161213074, 96.390, 854.0, 29.2233
57.213734205, 96.390, 780.0, 27.9285
57.266255336, 96.390, 902.0, 30.0333
57.318776466, 96.390, 855.0, 29.2404
57.371297597, 96.390, 908.0, 30.1330
57.423818728, 96.390, 973.0, 31.1929
57.476339859, 96.390, 890.0, 29.8329
57.528860989, 96.390, 873.0, 29.5466
57.581382120, 96.390, 870.0, 29.4958
57.633903251, 96.390, 933.0, 30.5450
57.686424381, 96.390, 854.0, 29.2233
57.738945512, 96.390, 887.0, 29.7825
57.791466643, 96.390, 859.0, 29.3087
57.843987774, 96.390, 899.0, 29.9833
57.896508904, 96.390, 939.0, 30.6431
57.949030035, 96.390, 960.0, 30.9839
58.001551166, 96.390, 1048.0, 32.3728
58.054072296, 96.390, 1237.0, 35.1710
58.106593427, 96.390, 1165.0, 34.1321
58.159114558, 96.390, 1044.0, 32.3110
58.211635689, 96.390, 1002.0, 31.6544
58.264156819, 96.390, 969.0, 31.1288
58.316677950, 96.390, 915.0, 30.2490
58.369199081, 96.390, 936.0, 30.5941
58.421720211, 96.390, 850.0, 29.1548
58.474241342, 96.390, 874.0, 29.5635
58.526762473, 96.390, 834.0, 28.8791
58.579283603, 96.390, 866.0, 29.4279
58.631804734, 96.390, 911.0, 30.1828
58.684325865, 96.390, 914.0, 30.2324
58.736846996, 96.390, 908.0, 30.1330
58.789368126, 96.390, 906.0, 30.0998
58.841889257, 96.390, 843.0, 29.0345
58.894410388, 96.390, 865.0, 29.4109
58.946931518, 96.390, 852.0, 29.1890
58.999452649, 96.390, 882.0, 29.6985
59.051973780, 96.390, 867.0, 29.4449
59.104494911, 96.390, 866.0, 29.4279
59.157016041, 96.390, 872.0, 29.5296
59.209537172, 96.390, 991.0, 31.4802
59.262058303, 96.390, 952.0, 30.8545
59.314579433, 96.390, 962.0, 31.0161
59.367100564, 96.390, 900.0, 30.0000
59.419621695, 96.390, 994.0, 31.5278
59.472142826, 96.390, 1019.0, 31.9218
59.524663956, 96.390, 972.0, 31.1769
59.577185087, 96.390, 942.0, 30.6920
59.629706218, 96.390, 968.0, 31.1127
59.682227348, 96.390, 995.0, 31.5436
59.734748479, 96.390, 981.0, 31.3209
59.787269610, 96.390, 976.0, 31.2410
59.839790740, 96.390, 1068.0, 32.6803
59.892311871, 96.390, 978.0, 31.2730
59.944833002, 96.390, 1061.0, 32.5730
59.997354133, 96.390, 1139.0, 33.7491
60.049875263, 96.390, 1082.0, 32.8938
60.102396394, 96.390, 1114.0, 33.3766
60.154917525, 96.390, 1146.0, 33.8526
60.207438655, 96.390, 1104.0, 33.2265
60.259959786, 96.390, 1111.0, 33.3317
60.312480917, 96.390, 1129.0, 33.6006
60.365002048, 96.390, 1075.0, 32.7872
60.417523178, 96.390, 1137.0, 33.7194
60.470044309, 96.390, 1092.0, 33.0454
60.522565440, 96.390, 1183.0, 34.3948
60.575086570, 96.390, 1220.0, 34.9285
60.627607701, 96.390, 1149.0, 33.8969
60.680128832, 96.390, 1227.0, 35.0286
60.732649963, 96.390, 1221.0, 34.9428
60.785171093, 96.390, 1211.0, 34.7994
60.837692224, 96.390, 1292.0, 35.9444
60.890213355, 96.390, 1228.0, 35.0428
60.942734485, 96.390, 1283.0, 35.8190
60.995255616, 96.390, 1278.0, 35.7491
61.047776747, 96.390, 1306.0, 36.1386
61.100297878, 96.390, 1310.0, 36.1939
61.152819008, 96.390, 1372.0, 37.0405
61.205340139, 96.390, 1320.0, 36.3318
61.257861270, 96.390, 1292.0, 35.9444
61.310382400, 96.390, 1310.0, 36.1939
61.362903531, 96.390, 1289.0, 35.9026
61.415424662, 96.390, 1404.0, 37.4700
61.467945792, 96.390, 1474.0, 38.3927
61.520466923, 96.390, 1480.0, 38.4708
61.572988054, 96.390, 1379.0, 37.1349
61.625509185, 96.390, 1351.0, 36.7560
61.678030315, 96.390, 1349.0, 36.7287
61.730551446, 96.390, 1314.0, 36.2491
61.783072577, 96.390, 1320.0, 36.3318
61.835593707, 96.390, 1236.0, 35.1568
61.888114838, 96.390, 1301.0, 36.0694
61.940635969, 96.390, 1204.0, 34.6987
61.993157100, 96.390, 1193.0, 34.5398
62.045678230, 96.390, 1173.0, 34.2491
62.098199361, 96.390, 1199.0, 34.6266
62.150720492, 96.390, 1121.0, 33.4813
62.203241622, 96.390, 1216.0, 34.8712
62.255762753, 96.390, 1130.0, 33.6155
62.308283884, 96.390, 1142.0, 33.7935
62.360805015, 96.390, 1167.0, 34.1614
62.413326145, 96.390, 1080.0, 32.8634
62.465847276, 96.390, 1098.0, 33.1361
62.518368407, 96.390, 1106.0, 33.2566
62.570889537, 96.390, 1093.0, 33.0606
62.623410668, 96.390, 1154.0, 33.9706
62.675931799, 96.390, 1157.0, 34.0147
62.728452930, 96.390, 1207.0, 34.7419
62.780974060, 96.390, 1096.0, 33.1059
62.833495191, 96.390, 1142.0, 33.7935
62.886016322, 96.390, 1166.0, 34.1467
62.938537452, 96.390, 1022.0, 31.9687
62.991058583, 96.390, 961.0, 31.0000
63.043579714, 96.390, 957.0, 30.9354
63.096100844, 96.390, 893.0, 29.8831
63.148621975, 96.390, 924.0, 30.3974
63.201143106, 96.390, 885.0, 29.7489
63.253664237, 96.390, 921.0, 30.3480
63.306185367, 96.390, 878.0, 29.6311
63.358706498, 96.390, 868.0, 29.4618
63.411227629, 96.390, 895.0, 29.9166
63.463748759, 96.390, 821.0, 28.6531
63.516269890, 96.390, 898.0, 29.9666
63.568791021, 96.390, 881.0, 29.6816
63.621312152, 96.390, 887.0, 29.7825
63.673833282, 96.390, 930.0, 30.4959
63.726354413, 96.390, 888.0, 29.7993
63.778875544, 96.390, 940.0, 30.6594
63.831396674, 96.390, 963.0, 31.0322
63.883917805, 96.390, 911.0, 30.1828
63.936438936, 96.390, 903.0, 30.0500
63.988960067, 96.390, 900.0, 30.0000
64.041481197, 96.390, 861.0, 29.3428
64.094002328, 96.390, 869.0, 29.4788
64.146523459, 96.390, 882.0, 29.6985
64.199044589, 96.390, 882.0, 29.6985
64.251565720, 96.390, 876.0, 29.5973
64.304086851, 96.390, 868.0, 29.4618
64.356607981, 96.390, 887.0, 29.7825
64.409129112, 96.390, 887.0, 29.7825
64.461650243, 96.390, 844.0, 29.0517
64.514171374, 96.390, 814.0, 28.5307
64.566692504, 96.390, 748.0, 27.3496
64.619213635, 96.390, 810.0, 28.4605
64.671734766, 96.390, 794.0, 28.1780
64.724255896, 96.390, 772.0, 27.7849
64.776777027, 96.390, 838.0, 28.9482
64.829298158, 96.390, 763.0, 27.6225
64.881819289, 96.390, 788.0, 28.0713
64.934340419, 96.390, 823.0, 28.6880
64.986861550, 96.390, 821.0, 28.6531