File: Files_organized_for_plots/Constant_NaOH_1mL10M_to_1gPC/XRD_MgCorner08Nov21_Act08Jan22_B1_0714M_NaOH_LS0162_1.csv
[Measurement conditions]
Sample identification,XRD_MgCorner08Nov21_Act08Jan22_B1_0714M_NaOH_LS0162_1
Comment - 1,"Configuration=Stage for Flat Samples/Holders, Owner=User-1, Creation date=7/1/2020 9:53:24 AM"
Comment - 2,"Goniometer=Theta/Theta; Minimum step size 2Theta:0.0001; Minimum step size Omega:0.0001"
Comment - 3,"Sample stage=Stage for flat samples/holders"
Comment - 4,"Diffractometer system=EMPYREAN"
Comment - 5,"Measurement program=C:\Users\ibo5034\OneDrive - The Pennsylvania State University\NEUP - Reed, Titus's files\XRD\Cement\Zerobackground scan.xrdmp, Identifier={98A3B11C-88F9-4AA6-982C-73314A311EF5}"
Anode material,Cu
K-Alpha1 wavelength,1.5405980
K-Alpha2 wavelength,1.5444260
Ratio K-Alpha2/K-Alpha1,0.500
Divergence slit,Fixed,0.25
Monochromator used,NO
Generator voltage, 45
Tube current, 40
File date and time,11/Jan/2022 12:31
Unit cell,
h k l, 0 0 0
Scan axis,Gonio
Scan range,4.994599997,64.999991833
Scan step size,0.0262606
No. of points, 2285
Scan type,CONTINUOUS
Time per step,96.390
[Scan points]
Angle, TimePerStep, Intensity, ESD
5.007730280, 96.390, 5204.0, 72.1388
5.060251411, 96.390, 5051.0, 71.0704
5.112772541, 96.390, 4956.0, 70.3989
5.165293672, 96.390, 5031.0, 70.9295
5.217814803, 96.390, 5005.0, 70.7460
5.270335934, 96.390, 4984.0, 70.5975
5.322857064, 96.390, 5035.0, 70.9577
5.375378195, 96.390, 4767.0, 69.0435
5.427899326, 96.390, 4792.0, 69.2243
5.480420456, 96.390, 4942.0, 70.2994
5.532941587, 96.390, 4792.0, 69.2243
5.585462718, 96.390, 4680.0, 68.4105
5.637983849, 96.390, 4827.0, 69.4766
5.690504979, 96.390, 4644.0, 68.1469
5.743026110, 96.390, 4658.0, 68.2495
5.795547241, 96.390, 4709.0, 68.6222
5.848068371, 96.390, 4738.0, 68.8331
5.900589502, 96.390, 4744.0, 68.8767
5.953110633, 96.390, 4547.0, 67.4314
6.005631763, 96.390, 4589.0, 67.7422
6.058152894, 96.390, 4624.0, 68.0000
6.110674025, 96.390, 4637.0, 68.0955
6.163195156, 96.390, 4510.0, 67.1565
6.215716286, 96.390, 4598.0, 67.8086
6.268237417, 96.390, 4610.0, 67.8970
6.320758548, 96.390, 4498.0, 67.0671
6.373279678, 96.390, 4517.0, 67.2086
6.425800809, 96.390, 4572.0, 67.6166
6.478321940, 96.390, 4534.0, 67.3350
6.530843071, 96.390, 4426.0, 66.5282
6.583364201, 96.390, 4348.0, 65.9394
6.635885332, 96.390, 4340.0, 65.8787
6.688406463, 96.390, 4442.0, 66.6483
6.740927593, 96.390, 4471.0, 66.8655
6.793448724, 96.390, 4420.0, 66.4831
6.845969855, 96.390, 4318.0, 65.7115
6.898490986, 96.390, 4485.0, 66.9701
6.951012116, 96.390, 4316.0, 65.6963
7.003533247, 96.390, 4140.0, 64.3428
7.056054378, 96.390, 4253.0, 65.2150
7.108575508, 96.390, 4207.0, 64.8614
7.161096639, 96.390, 4203.0, 64.8305
7.213617770, 96.390, 4150.0, 64.4205
7.266138900, 96.390, 4045.0, 63.6003
7.318660031, 96.390, 4089.0, 63.9453
7.371181162, 96.390, 4120.0, 64.1872
7.423702293, 96.390, 4138.0, 64.3273
7.476223423, 96.390, 3964.0, 62.9603
7.528744554, 96.390, 3860.0, 62.1289
7.581265685, 96.390, 3915.0, 62.5700
7.633786815, 96.390, 3990.0, 63.1664
7.686307946, 96.390, 3821.0, 61.8142
7.738829077, 96.390, 3927.0, 62.6658
7.791350208, 96.390, 3877.0, 62.2656
7.843871338, 96.390, 3891.0, 62.3779
7.896392469, 96.390, 3811.0, 61.7333
7.948913600, 96.390, 3865.0, 62.1691
8.001434730, 96.390, 3841.0, 61.9758
8.053955861, 96.390, 3889.0, 62.3618
8.106476992, 96.390, 4035.0, 63.5216
8.158998123, 96.390, 4130.0, 64.2651
8.211519253, 96.390, 3722.0, 61.0082
8.264040384, 96.390, 3626.0, 60.2163
8.316561515, 96.390, 3591.0, 59.9250
8.369082645, 96.390, 3538.0, 59.4811
8.421603776, 96.390, 3491.0, 59.0847
8.474124907, 96.390, 3487.0, 59.0508
8.526646038, 96.390, 3600.0, 60.0000
8.579167168, 96.390, 3696.0, 60.7947
8.631688299, 96.390, 3620.0, 60.1664
8.684209430, 96.390, 3563.0, 59.6909
8.736730560, 96.390, 3516.0, 59.2959
8.789251691, 96.390, 3540.0, 59.4979
8.841772822, 96.390, 3511.0, 59.2537
8.894293952, 96.390, 3450.0, 58.7367
8.946815083, 96.390, 3559.0, 59.6574
8.999336214, 96.390, 3444.0, 58.6856
9.051857345, 96.390, 3565.0, 59.7076
9.104378475, 96.390, 3453.0, 58.7622
9.156899606, 96.390, 3470.0, 58.9067
9.209420737, 96.390, 3408.0, 58.3781
9.261941867, 96.390, 3577.0, 59.8080
9.314462998, 96.390, 3480.0, 58.9915
9.366984129, 96.390, 3522.0, 59.3464
9.419505260, 96.390, 3513.0, 59.2706
9.472026390, 96.390, 3602.0, 60.0167
9.524547521, 96.390, 3610.0, 60.0833
9.577068652, 96.390, 3625.0, 60.2080
9.629589782, 96.390, 3617.0, 60.1415
9.682110913, 96.390, 3526.0, 59.3801
9.734632044, 96.390, 3601.0, 60.0083
9.787153175, 96.390, 3716.0, 60.9590
9.839674305, 96.390, 3706.0, 60.8769
9.892195436, 96.390, 3746.0, 61.2046
9.944716567, 96.390, 3776.0, 61.4492
9.997237697, 96.390, 3915.0, 62.5700
10.049758828, 96.390, 3907.0, 62.5060
10.102279959, 96.390, 4020.0, 63.4035
10.154801090, 96.390, 4047.0, 63.6160
10.207322220, 96.390, 4043.0, 63.5846
10.259843351, 96.390, 4134.0, 64.2962
10.312364482, 96.390, 3981.0, 63.0952
10.364885612, 96.390, 4226.0, 65.0077
10.417406743, 96.390, 4331.0, 65.8103
10.469927874, 96.390, 4375.0, 66.1438
10.522449004, 96.390, 4301.0, 65.5820
10.574970135, 96.390, 4483.0, 66.9552
10.627491266, 96.390, 4602.0, 67.8380
10.680012397, 96.390, 4538.0, 67.3647
10.732533527, 96.390, 4604.0, 67.8528
10.785054658, 96.390, 4658.0, 68.2495
10.837575789, 96.390, 4710.0, 68.6294
10.890096919, 96.390, 4823.0, 69.4478
10.942618050, 96.390, 4938.0, 70.2709
10.995139181, 96.390, 4790.0, 69.2098
11.047660312, 96.390, 4887.0, 69.9071
11.100181442, 96.390, 4879.0, 69.8498
11.152702573, 96.390, 4969.0, 70.4911
11.205223704, 96.390, 4847.0, 69.6204
11.257744834, 96.390, 4828.0, 69.4838
11.310265965, 96.390, 4848.0, 69.6276
11.362787096, 96.390, 4911.0, 70.0785
11.415308227, 96.390, 4708.0, 68.6149
11.467829357, 96.390, 4740.0, 68.8477
11.520350488, 96.390, 4636.0, 68.0882
11.572871619, 96.390, 4564.0, 67.5574
11.625392749, 96.390, 4391.0, 66.2646
11.677913880, 96.390, 4442.0, 66.6483
11.730435011, 96.390, 4165.0, 64.5368
11.782956141, 96.390, 4190.0, 64.7302
11.835477272, 96.390, 4154.0, 64.4515
11.887998403, 96.390, 4025.0, 63.4429
11.940519534, 96.390, 3932.0, 62.7057
11.993040664, 96.390, 3873.0, 62.2334
12.045561795, 96.390, 3797.0, 61.6198
12.098082926, 96.390, 3600.0, 60.0000
12.150604056, 96.390, 3556.0, 59.6322
12.203125187, 96.390, 3453.0, 58.7622
12.255646318, 96.390, 3314.0, 57.5674
12.308167449, 96.390, 3266.0, 57.1489
12.360688579, 96.390, 3237.0, 56.8946
12.413209710, 96.390, 3276.0, 57.2364
12.465730841, 96.390, 3140.0, 56.0357
12.518251971, 96.390, 3040.0, 55.1362
12.570773102, 96.390, 3007.0, 54.8361
12.623294233, 96.390, 3019.0, 54.9454
12.675815364, 96.390, 2929.0, 54.1202
12.728336494, 96.390, 2811.0, 53.0189
12.780857625, 96.390, 2778.0, 52.7067
12.833378756, 96.390, 2830.0, 53.1977
12.885899886, 96.390, 2726.0, 52.2111
12.938421017, 96.390, 2696.0, 51.9230
12.990942148, 96.390, 2618.0, 51.1664
13.043463279, 96.390, 2624.0, 51.2250
13.095984409, 96.390, 2469.0, 49.6890
13.148505540, 96.390, 2499.0, 49.9900
13.201026671, 96.390, 2529.0, 50.2892
13.253547801, 96.390, 2459.0, 49.5883
13.306068932, 96.390, 2446.0, 49.4571
13.358590063, 96.390, 2478.0, 49.7795
13.411111193, 96.390, 2441.0, 49.4065
13.463632324, 96.390, 2562.0, 50.6162
13.516153455, 96.390, 2763.0, 52.5642
13.568674586, 96.390, 2594.0, 50.9313
13.621195716, 96.390, 2342.0, 48.3942
13.673716847, 96.390, 2293.0, 47.8853
13.726237978, 96.390, 2227.0, 47.1911
13.778759108, 96.390, 2274.0, 47.6865
13.831280239, 96.390, 2286.0, 47.8121
13.883801370, 96.390, 2363.0, 48.6107
13.936322501, 96.390, 2265.0, 47.5920
13.988843631, 96.390, 2216.0, 47.0744
14.041364762, 96.390, 2172.0, 46.6047
14.093885893, 96.390, 2271.0, 47.6550
14.146407023, 96.390, 2321.0, 48.1768
14.198928154, 96.390, 2369.0, 48.6724
14.251449285, 96.390, 2708.0, 52.0384
14.303970416, 96.390, 2528.0, 50.2792
14.356491546, 96.390, 2223.0, 47.1487
14.409012677, 96.390, 2324.0, 48.2079
14.461533808, 96.390, 2401.0, 49.0000
14.514054938, 96.390, 2946.0, 54.2771
14.566576069, 96.390, 2969.0, 54.4885
14.619097200, 96.390, 2152.0, 46.3897
14.671618331, 96.390, 1989.0, 44.5982
14.724139461, 96.390, 1961.0, 44.2832
14.776660592, 96.390, 1895.0, 43.5316
14.829181723, 96.390, 1952.0, 44.1814
14.881702853, 96.390, 1938.0, 44.0227
14.934223984, 96.390, 1997.0, 44.6878
14.986745115, 96.390, 1949.0, 44.1475
15.039266245, 96.390, 1945.0, 44.1022
15.091787376, 96.390, 2141.0, 46.2709
15.144308507, 96.390, 2335.0, 48.3218
15.196829638, 96.390, 2608.0, 51.0686
15.249350768, 96.390, 2899.0, 53.8424
15.301871899, 96.390, 3007.0, 54.8361
15.354393030, 96.390, 2274.0, 47.6865
15.406914160, 96.390, 1893.0, 43.5086
15.459435291, 96.390, 1903.0, 43.6234
15.511956422, 96.390, 1928.0, 43.9090
15.564477553, 96.390, 1918.0, 43.7950
15.616998683, 96.390, 1939.0, 44.0341
15.669519814, 96.390, 1865.0, 43.1856
15.722040945, 96.390, 2044.0, 45.2106
15.774562075, 96.390, 1940.0, 44.0454
15.827083206, 96.390, 1855.0, 43.0697
15.879604337, 96.390, 1834.0, 42.8252
15.932125468, 96.390, 1874.0, 43.2897
15.984646598, 96.390, 1853.0, 43.0465
16.037167729, 96.390, 1819.0, 42.6497
16.089688860, 96.390, 1807.0, 42.5088
16.142209990, 96.390, 1849.0, 43.0000
16.194731121, 96.390, 1915.0, 43.7607
16.247252252, 96.390, 2085.0, 45.6618
16.299773382, 96.390, 2324.0, 48.2079
16.352294513, 96.390, 2552.0, 50.5173
16.404815644, 96.390, 1997.0, 44.6878
16.457336775, 96.390, 1854.0, 43.0581
16.509857905, 96.390, 1955.0, 44.2154
16.562379036, 96.390, 1953.0, 44.1928
16.614900167, 96.390, 1827.0, 42.7434
16.667421297, 96.390, 1792.0, 42.3320
16.719942428, 96.390, 1752.0, 41.8569
16.772463559, 96.390, 1901.0, 43.6005
16.824984690, 96.390, 1882.0, 43.3820
16.877505820, 96.390, 1974.0, 44.4297
16.930026951, 96.390, 1936.0, 44.0000
16.982548082, 96.390, 1733.0, 41.6293
17.035069212, 96.390, 1791.0, 42.3202
17.087590343, 96.390, 1748.0, 41.8091
17.140111474, 96.390, 1712.0, 41.3763
17.192632605, 96.390, 1665.0, 40.8044
17.245153735, 96.390, 1671.0, 40.8779
17.297674866, 96.390, 1739.0, 41.7013
17.350195997, 96.390, 1698.0, 41.2068
17.402717127, 96.390, 1633.0, 40.4104
17.455238258, 96.390, 1594.0, 39.9249
17.507759389, 96.390, 1621.0, 40.2616
17.560280520, 96.390, 1681.0, 41.0000
17.612801650, 96.390, 1673.0, 40.9023
17.665322781, 96.390, 1707.0, 41.3159
17.717843912, 96.390, 1755.0, 41.8927
17.770365042, 96.390, 1660.0, 40.7431
17.822886173, 96.390, 1695.0, 41.1704
17.875407304, 96.390, 1738.0, 41.6893
17.927928434, 96.390, 1772.0, 42.0951
17.980449565, 96.390, 1720.0, 41.4729
18.032970696, 96.390, 1685.0, 41.0488
18.085491827, 96.390, 1646.0, 40.5709
18.138012957, 96.390, 1707.0, 41.3159
18.190534088, 96.390, 1733.0, 41.6293
18.243055219, 96.390, 1678.0, 40.9634
18.295576349, 96.390, 1660.0, 40.7431
18.348097480, 96.390, 1703.0, 41.2674
18.400618611, 96.390, 1598.0, 39.9750
18.453139742, 96.390, 1719.0, 41.4608
18.505660872, 96.390, 1674.0, 40.9145
18.558182003, 96.390, 1696.0, 41.1825
18.610703134, 96.390, 1710.0, 41.3521
18.663224264, 96.390, 1701.0, 41.2432
18.715745395, 96.390, 1894.0, 43.5201
18.768266526, 96.390, 1961.0, 44.2832
18.820787657, 96.390, 2181.0, 46.7012
18.873308787, 96.390, 2393.0, 48.9183
18.925829918, 96.390, 2525.0, 50.2494
18.978351049, 96.390, 2676.0, 51.7301
19.030872179, 96.390, 2316.0, 48.1248
19.083393310, 96.390, 1884.0, 43.4051
19.135914441, 96.390, 1921.0, 43.8292
19.188435572, 96.390, 1881.0, 43.3705
19.240956702, 96.390, 1716.0, 41.4246
19.293477833, 96.390, 1858.0, 43.1045
19.345998964, 96.390, 1955.0, 44.2154
19.398520094, 96.390, 2142.0, 46.2817
19.451041225, 96.390, 2169.0, 46.5725
19.503562356, 96.390, 2016.0, 44.8999
19.556083486, 96.390, 1776.0, 42.1426
19.608604617, 96.390, 1851.0, 43.0232
19.661125748, 96.390, 1975.0, 44.4410
19.713646879, 96.390, 1948.0, 44.1362
19.766168009, 96.390, 1979.0, 44.4860
19.818689140, 96.390, 2064.0, 45.4313
19.871210271, 96.390, 2216.0, 47.0744
19.923731401, 96.390, 2849.0, 53.3760
19.976252532, 96.390, 3507.0, 59.2199
20.028773663, 96.390, 2588.0, 50.8724
20.081294794, 96.390, 2009.0, 44.8219
20.133815924, 96.390, 1972.0, 44.4072
20.186337055, 96.390, 2003.0, 44.7549
20.238858186, 96.390, 1915.0, 43.7607
20.291379316, 96.390, 1963.0, 44.3058
20.343900447, 96.390, 2004.0, 44.7661
20.396421578, 96.390, 2148.0, 46.3465
20.448942709, 96.390, 2161.0, 46.4866
20.501463839, 96.390, 2268.0, 47.6235
20.553984970, 96.390, 2472.0, 49.7192
20.606506101, 96.390, 3107.0, 55.7405
20.659027231, 96.390, 4277.0, 65.3988
20.711548362, 96.390, 5849.0, 76.4788
20.764069493, 96.390, 4532.0, 67.3201
20.816590623, 96.390, 2771.0, 52.6403
20.869111754, 96.390, 2330.0, 48.2701
20.921632885, 96.390, 2248.0, 47.4131
20.974154016, 96.390, 2106.0, 45.8912
21.026675146, 96.390, 2205.0, 46.9574
21.079196277, 96.390, 2145.0, 46.3141
21.131717408, 96.390, 2087.0, 45.6837
21.184238538, 96.390, 2109.0, 45.9239
21.236759669, 96.390, 2295.0, 47.9062
21.289280800, 96.390, 2381.0, 48.7955
21.341801931, 96.390, 2696.0, 51.9230
21.394323061, 96.390, 2424.0, 49.2341
21.446844192, 96.390, 2435.0, 49.3457
21.499365323, 96.390, 2342.0, 48.3942
21.551886453, 96.390, 2489.0, 49.8899
21.604407584, 96.390, 2773.0, 52.6593
21.656928715, 96.390, 2849.0, 53.3760
21.709449846, 96.390, 2583.0, 50.8232
21.761970976, 96.390, 2353.0, 48.5077
21.814492107, 96.390, 2382.0, 48.8057
21.867013238, 96.390, 2381.0, 48.7955
21.919534368, 96.390, 2352.0, 48.4974
21.972055499, 96.390, 2379.0, 48.7750
22.024576630, 96.390, 2506.0, 50.0600
22.077097761, 96.390, 2446.0, 49.4571
22.129618891, 96.390, 2556.0, 50.5569
22.182140022, 96.390, 2576.0, 50.7543
22.234661153, 96.390, 2537.0, 50.3686
22.287182283, 96.390, 2549.0, 50.4876
22.339703414, 96.390, 2563.0, 50.6261
22.392224545, 96.390, 2624.0, 51.2250
22.444745675, 96.390, 2607.0, 51.0588
22.497266806, 96.390, 2549.0, 50.4876
22.549787937, 96.390, 2635.0, 51.3323
22.602309068, 96.390, 2739.0, 52.3355
22.654830198, 96.390, 2782.0, 52.7447
22.707351329, 96.390, 2767.0, 52.6023
22.759872460, 96.390, 2767.0, 52.6023
22.812393590, 96.390, 3055.0, 55.2721
22.864914721, 96.390, 3143.0, 56.0625
22.917435852, 96.390, 3016.0, 54.9181
22.969956983, 96.390, 2794.0, 52.8583
23.022478113, 96.390, 2855.0, 53.4322
23.074999244, 96.390, 2799.0, 52.9056
23.127520375, 96.390, 2829.0, 53.1883
23.180041505, 96.390, 3105.0, 55.7225
23.232562636, 96.390, 3025.0, 55.0000
23.285083767, 96.390, 2728.0, 52.2303
23.337604898, 96.390, 2743.0, 52.3737
23.390126028, 96.390, 2787.0, 52.7920
23.442647159, 96.390, 2536.0, 50.3587
23.495168290, 96.390, 2278.0, 47.7284
23.547689420, 96.390, 2414.0, 49.1325
23.600210551, 96.390, 2443.0, 49.4267
23.652731682, 96.390, 2295.0, 47.9062
23.705252813, 96.390, 2148.0, 46.3465
23.757773943, 96.390, 1964.0, 44.3170
23.810295074, 96.390, 2120.0, 46.0435
23.862816205, 96.390, 2075.0, 45.5522
23.915337335, 96.390, 2072.0, 45.5192
23.967858466, 96.390, 2042.0, 45.1885
24.020379597, 96.390, 1976.0, 44.4522
24.072900727, 96.390, 2038.0, 45.1442
24.125421858, 96.390, 2131.0, 46.1628
24.177942989, 96.390, 2144.0, 46.3033
24.230464120, 96.390, 1985.0, 44.5533
24.282985250, 96.390, 1820.0, 42.6615
24.335506381, 96.390, 1846.0, 42.9651
24.388027512, 96.390, 1741.0, 41.7253
24.440548642, 96.390, 1840.0, 42.8952
24.493069773, 96.390, 1757.0, 41.9166
24.545590904, 96.390, 1727.0, 41.5572
24.598112035, 96.390, 1791.0, 42.3202
24.650633165, 96.390, 1674.0, 40.9145
24.703154296, 96.390, 1655.0, 40.6817
24.755675427, 96.390, 1711.0, 41.3642
24.808196557, 96.390, 1693.0, 41.1461
24.860717688, 96.390, 1716.0, 41.4246
24.913238819, 96.390, 1668.0, 40.8412
24.965759950, 96.390, 1608.0, 40.0999
25.018281080, 96.390, 1638.0, 40.4722
25.070802211, 96.390, 1595.0, 39.9375
25.123323342, 96.390, 1570.0, 39.6232
25.175844472, 96.390, 1615.0, 40.1871
25.228365603, 96.390, 1554.0, 39.4208
25.280886734, 96.390, 1617.0, 40.2119
25.333407864, 96.390, 1654.0, 40.6694
25.385928995, 96.390, 1947.0, 44.1248
25.438450126, 96.390, 2317.0, 48.1352
25.490971257, 96.390, 2170.0, 46.5833
25.543492387, 96.390, 1736.0, 41.6653
25.596013518, 96.390, 1613.0, 40.1622
25.648534649, 96.390, 1582.0, 39.7744
25.701055779, 96.390, 1515.0, 38.9230
25.753576910, 96.390, 1468.0, 38.3145
25.806098041, 96.390, 1539.0, 39.2301
25.858619172, 96.390, 1503.0, 38.7685
25.911140302, 96.390, 1554.0, 39.4208
25.963661433, 96.390, 1610.0, 40.1248
26.016182564, 96.390, 1596.0, 39.9500
26.068703694, 96.390, 1526.0, 39.0640
26.121224825, 96.390, 1547.0, 39.3319
26.173745956, 96.390, 1583.0, 39.7869
26.226267087, 96.390, 1462.0, 38.2361
26.278788217, 96.390, 1536.0, 39.1918
26.331309348, 96.390, 1505.0, 38.7943
26.383830479, 96.390, 1543.0, 39.2810
26.436351609, 96.390, 1544.0, 39.2938
26.488872740, 96.390, 1564.0, 39.5474
26.541393871, 96.390, 1490.0, 38.6005
26.593915002, 96.390, 1531.0, 39.1280
26.646436132, 96.390, 1535.0, 39.1791
26.698957263, 96.390, 1658.0, 40.7185
26.751478394, 96.390, 1985.0, 44.5533
26.803999524, 96.390, 2371.0, 48.6929
26.856520655, 96.390, 2214.0, 47.0532
26.909041786, 96.390, 1979.0, 44.4860
26.961562916, 96.390, 1834.0, 42.8252
27.014084047, 96.390, 2147.0, 46.3357
27.066605178, 96.390, 2510.0, 50.0999
27.119126309, 96.390, 2706.0, 52.0192
27.171647439, 96.390, 3300.0, 57.4456
27.224168570, 96.390, 3708.0, 60.8933
27.276689701, 96.390, 3216.0, 56.7098
27.329210831, 96.390, 2317.0, 48.1352
27.381731962, 96.390, 1834.0, 42.8252
27.434253093, 96.390, 1745.0, 41.7732
27.486774224, 96.390, 1514.0, 38.9102
27.539295354, 96.390, 1520.0, 38.9872
27.591816485, 96.390, 1517.0, 38.9487
27.644337616, 96.390, 1548.0, 39.3446
27.696858746, 96.390, 1485.0, 38.5357
27.749379877, 96.390, 1469.0, 38.3275
27.801901008, 96.390, 1554.0, 39.4208
27.854422139, 96.390, 1480.0, 38.4708
27.906943269, 96.390, 1429.0, 37.8021
27.959464400, 96.390, 1624.0, 40.2989
28.011985531, 96.390, 1553.0, 39.4081
28.064506661, 96.390, 1648.0, 40.5956
28.117027792, 96.390, 1535.0, 39.1791
28.169548923, 96.390, 1582.0, 39.7744
28.222070054, 96.390, 1579.0, 39.7366
28.274591184, 96.390, 1548.0, 39.3446
28.327112315, 96.390, 1601.0, 40.0125
28.379633446, 96.390, 1695.0, 41.1704
28.432154576, 96.390, 1598.0, 39.9750
28.484675707, 96.390, 1612.0, 40.1497
28.537196838, 96.390, 1595.0, 39.9375
28.589717968, 96.390, 1541.0, 39.2556
28.642239099, 96.390, 1646.0, 40.5709
28.694760230, 96.390, 1643.0, 40.5339
28.747281361, 96.390, 1709.0, 41.3401
28.799802491, 96.390, 1718.0, 41.4488
28.852323622, 96.390, 1684.0, 41.0366
28.904844753, 96.390, 1519.0, 38.9744
28.957365883, 96.390, 1649.0, 40.6079
29.009887014, 96.390, 1664.0, 40.7922
29.062408145, 96.390, 1862.0, 43.1509
29.114929276, 96.390, 2087.0, 45.6837
29.167450406, 96.390, 2193.0, 46.8295
29.219971537, 96.390, 2181.0, 46.7012
29.272492668, 96.390, 2497.0, 49.9700
29.325013798, 96.390, 2839.0, 53.2823
29.377534929, 96.390, 2387.0, 48.8569
29.430056060, 96.390, 2300.0, 47.9583
29.482577191, 96.390, 2306.0, 48.0208
29.535098321, 96.390, 2285.0, 47.8017
29.587619452, 96.390, 1984.0, 44.5421
29.640140583, 96.390, 1871.0, 43.2551
29.692661713, 96.390, 1736.0, 41.6653
29.745182844, 96.390, 1787.0, 42.2729
29.797703975, 96.390, 1622.0, 40.2741
29.850225105, 96.390, 1493.0, 38.6394
29.902746236, 96.390, 1574.0, 39.6737
29.955267367, 96.390, 1585.0, 39.8121
30.007788498, 96.390, 1556.0, 39.4462
30.060309628, 96.390, 1646.0, 40.5709
30.112830759, 96.390, 1526.0, 39.0640
30.165351890, 96.390, 1550.0, 39.3700
30.217873020, 96.390, 1559.0, 39.4842
30.270394151, 96.390, 1532.0, 39.1408
30.322915282, 96.390, 1510.0, 38.8587
30.375436413, 96.390, 1517.0, 38.9487
30.427957543, 96.390, 1580.0, 39.7492
30.480478674, 96.390, 1530.0, 39.1152
30.532999805, 96.390, 1622.0, 40.2741
30.585520935, 96.390, 1624.0, 40.2989
30.638042066, 96.390, 1896.0, 43.5431
30.690563197, 96.390, 2013.0, 44.8665
30.743084328, 96.390, 1927.0, 43.8976
30.795605458, 96.390, 1945.0, 44.1022
30.848126589, 96.390, 2036.0, 45.1221
30.900647720, 96.390, 1881.0, 43.3705
30.953168850, 96.390, 1793.0, 42.3438
31.005689981, 96.390, 1668.0, 40.8412
31.058211112, 96.390, 1662.0, 40.7676
31.110732243, 96.390, 1772.0, 42.0951
31.163253373, 96.390, 2244.0, 47.3709
31.215774504, 96.390, 2700.0, 51.9615
31.268295635, 96.390, 2689.0, 51.8556
31.320816765, 96.390, 2610.0, 51.0882
31.373337896, 96.390, 2401.0, 49.0000
31.425859027, 96.390, 2178.0, 46.6690
31.478380157, 96.390, 2009.0, 44.8219
31.530901288, 96.390, 2051.0, 45.2880
31.583422419, 96.390, 1971.0, 44.3959
31.635943550, 96.390, 1784.0, 42.2374
31.688464680, 96.390, 1721.0, 41.4849
31.740985811, 96.390, 1671.0, 40.8779
31.793506942, 96.390, 1610.0, 40.1248
31.846028072, 96.390, 1671.0, 40.8779
31.898549203, 96.390, 1918.0, 43.7950
31.951070334, 96.390, 2349.0, 48.4665
32.003591465, 96.390, 3566.0, 59.7160
32.056112595, 96.390, 4797.0, 69.2604
32.108633726, 96.390, 4002.0, 63.2614
32.161154857, 96.390, 3304.0, 57.4804
32.213675987, 96.390, 2527.0, 50.2693
32.266197118, 96.390, 2918.0, 54.0185
32.318718249, 96.390, 2853.0, 53.4135
32.371239380, 96.390, 2404.0, 49.0306
32.423760510, 96.390, 2182.0, 46.7119
32.476281641, 96.390, 2203.0, 46.9361
32.528802772, 96.390, 1950.0, 44.1588
32.581323902, 96.390, 1869.0, 43.2319
32.633845033, 96.390, 1810.0, 42.5441
32.686366164, 96.390, 1716.0, 41.4246
32.738887295, 96.390, 1703.0, 41.2674
32.791408425, 96.390, 1682.0, 41.0122
32.843929556, 96.390, 1621.0, 40.2616
32.896450687, 96.390, 1583.0, 39.7869
32.948971817, 96.390, 1666.0, 40.8167
33.001492948, 96.390, 1779.0, 42.1782
33.054014079, 96.390, 1838.0, 42.8719
33.106535209, 96.390, 1831.0, 42.7902
33.159056340, 96.390, 1865.0, 43.1856
33.211577471, 96.390, 1954.0, 44.2041
33.264098602, 96.390, 2131.0, 46.1628
33.316619732, 96.390, 2185.0, 46.7440
33.369140863, 96.390, 2179.0, 46.6798
33.421661994, 96.390, 2123.0, 46.0760
33.474183124, 96.390, 2251.0, 47.4447
33.526704255, 96.390, 2292.0, 47.8748
33.579225386, 96.390, 2409.0, 49.0816
33.631746517, 96.390, 2401.0, 49.0000
33.684267647, 96.390, 2438.0, 49.3761
33.736788778, 96.390, 2302.0, 47.9792
33.789309909, 96.390, 2398.0, 48.9694
33.841831039, 96.390, 2480.0, 49.7996
33.894352170, 96.390, 3062.0, 55.3353
33.946873301, 96.390, 3547.0, 59.5567
33.999394432, 96.390, 3723.0, 61.0164
34.051915562, 96.390, 3518.0, 59.3127
34.104436693, 96.390, 3339.0, 57.7841
34.156957824, 96.390, 3107.0, 55.7405
34.209478954, 96.390, 3136.0, 56.0000
34.262000085, 96.390, 3108.0, 55.7494
34.314521216, 96.390, 2996.0, 54.7357
34.367042346, 96.390, 3140.0, 56.0357
34.419563477, 96.390, 3483.0, 59.0169
34.472084608, 96.390, 3633.0, 60.2744
34.524605739, 96.390, 3734.0, 61.1065
34.577126869, 96.390, 3882.0, 62.3057
34.629648000, 96.390, 3708.0, 60.8933
34.682169131, 96.390, 3257.0, 57.0701
34.734690261, 96.390, 3133.0, 55.9732
34.787211392, 96.390, 3148.0, 56.1070
34.839732523, 96.390, 3231.0, 56.8419
34.892253654, 96.390, 3660.0, 60.4979
34.944774784, 96.390, 4002.0, 63.2614
34.997295915, 96.390, 3509.0, 59.2368
35.049817046, 96.390, 3306.0, 57.4978
35.102338176, 96.390, 3062.0, 55.3353
35.154859307, 96.390, 2844.0, 53.3292
35.207380438, 96.390, 3022.0, 54.9727
35.259901569, 96.390, 2923.0, 54.0648
35.312422699, 96.390, 2755.0, 52.4881
35.364943830, 96.390, 2784.0, 52.7636
35.417464961, 96.390, 2576.0, 50.7543
35.469986091, 96.390, 2492.0, 49.9199
35.522507222, 96.390, 2565.0, 50.6458
35.575028353, 96.390, 2425.0, 49.2443
35.627549484, 96.390, 2612.0, 51.1077
35.680070614, 96.390, 2626.0, 51.2445
35.732591745, 96.390, 2595.0, 50.9411
35.785112876, 96.390, 2545.0, 50.4480
35.837634006, 96.390, 2596.0, 50.9510
35.890155137, 96.390, 2977.0, 54.5619
35.942676268, 96.390, 3188.0, 56.4624
35.995197398, 96.390, 2928.0, 54.1110
36.047718529, 96.390, 2935.0, 54.1756
36.100239660, 96.390, 2903.0, 53.8795
36.152760791, 96.390, 3205.0, 56.6127
36.205281921, 96.390, 3551.0, 59.5903
36.257803052, 96.390, 3221.0, 56.7539
36.310324183, 96.390, 2789.0, 52.8110
36.362845313, 96.390, 2442.0, 49.4166
36.415366444, 96.390, 2208.0, 46.9894
36.467887575, 96.390, 2206.0, 46.9681
36.520408706, 96.390, 2244.0, 47.3709
36.572929836, 96.390, 2218.0, 47.0956
36.625450967, 96.390, 2361.0, 48.5901
36.677972098, 96.390, 2225.0, 47.1699
36.730493228, 96.390, 2271.0, 47.6550
36.783014359, 96.390, 2073.0, 45.5302
36.835535490, 96.390, 2190.0, 46.7974
36.888056621, 96.390, 2133.0, 46.1844
36.940577751, 96.390, 2163.0, 46.5081
36.993098882, 96.390, 2180.0, 46.6905
37.045620013, 96.390, 2172.0, 46.6047
37.098141143, 96.390, 2222.0, 47.1381
37.150662274, 96.390, 2196.0, 46.8615
37.203183405, 96.390, 2271.0, 47.6550
37.255704535, 96.390, 2291.0, 47.8644
37.308225666, 96.390, 2345.0, 48.4252
37.360746797, 96.390, 2241.0, 47.3392
37.413267928, 96.390, 2270.0, 47.6445
37.465789058, 96.390, 2449.0, 49.4874
37.518310189, 96.390, 2475.0, 49.7494
37.570831320, 96.390, 2473.0, 49.7293
37.623352450, 96.390, 2506.0, 50.0600
37.675873581, 96.390, 2486.0, 49.8598
37.728394712, 96.390, 2712.0, 52.0769
37.780915843, 96.390, 2954.0, 54.3507
37.833436973, 96.390, 3348.0, 57.8619
37.885958104, 96.390, 3463.0, 58.8473
37.938479235, 96.390, 2944.0, 54.2586
37.991000365, 96.390, 2805.0, 52.9623
38.043521496, 96.390, 2460.0, 49.5984
38.096042627, 96.390, 2381.0, 48.7955
38.148563758, 96.390, 2379.0, 48.7750
38.201084888, 96.390, 2320.0, 48.1664
38.253606019, 96.390, 2281.0, 47.7598
38.306127150, 96.390, 2093.0, 45.7493
38.358648280, 96.390, 2108.0, 45.9130
38.411169411, 96.390, 2139.0, 46.2493
38.463690542, 96.390, 2067.0, 45.4643
38.516211673, 96.390, 2096.0, 45.7821
38.568732803, 96.390, 2192.0, 46.8188
38.621253934, 96.390, 2139.0, 46.2493
38.673775065, 96.390, 2096.0, 45.7821
38.726296195, 96.390, 2254.0, 47.4763
38.778817326, 96.390, 2274.0, 47.6865
38.831338457, 96.390, 2171.0, 46.5940
38.883859587, 96.390, 2113.0, 45.9674
38.936380718, 96.390, 2013.0, 44.8665
38.988901849, 96.390, 1957.0, 44.2380
39.041422980, 96.390, 1844.0, 42.9418
39.093944110, 96.390, 1952.0, 44.1814
39.146465241, 96.390, 2034.0, 45.0999
39.198986372, 96.390, 1927.0, 43.8976
39.251507502, 96.390, 2027.0, 45.0222
39.304028633, 96.390, 1977.0, 44.4635
39.356549764, 96.390, 2062.0, 45.4093
39.409070895, 96.390, 2336.0, 48.3322
39.461592025, 96.390, 2428.0, 49.2747
39.514113156, 96.390, 2151.0, 46.3789
39.566634287, 96.390, 2073.0, 45.5302
39.619155417, 96.390, 1881.0, 43.3705
39.671676548, 96.390, 1733.0, 41.6293
39.724197679, 96.390, 1801.0, 42.4382
39.776718810, 96.390, 1829.0, 42.7668
39.829239940, 96.390, 1817.0, 42.6263
39.881761071, 96.390, 1746.0, 41.7852
39.934282202, 96.390, 1770.0, 42.0714
39.986803332, 96.390, 1798.0, 42.4028
40.039324463, 96.390, 1921.0, 43.8292
40.091845594, 96.390, 1908.0, 43.6807
40.144366725, 96.390, 1921.0, 43.8292
40.196887855, 96.390, 1874.0, 43.2897
40.249408986, 96.390, 1817.0, 42.6263
40.301930117, 96.390, 1688.0, 41.0853
40.354451247, 96.390, 1724.0, 41.5211
40.406972378, 96.390, 1625.0, 40.3113
40.459493509, 96.390, 1673.0, 40.9023
40.512014639, 96.390, 1846.0, 42.9651
40.564535770, 96.390, 1814.0, 42.5911
40.617056901, 96.390, 1853.0, 43.0465
40.669578032, 96.390, 1926.0, 43.8862
40.722099162, 96.390, 1808.0, 42.5206
40.774620293, 96.390, 1586.0, 39.8246
40.827141424, 96.390, 1656.0, 40.6940
40.879662554, 96.390, 1539.0, 39.2301
40.932183685, 96.390, 1609.0, 40.1123
40.984704816, 96.390, 1568.0, 39.5980
41.037225947, 96.390, 1560.0, 39.4968
41.089747077, 96.390, 1585.0, 39.8121
41.142268208, 96.390, 1577.0, 39.7115
41.194789339, 96.390, 1612.0, 40.1497
41.247310469, 96.390, 1671.0, 40.8779
41.299831600, 96.390, 1961.0, 44.2832
41.352352731, 96.390, 2093.0, 45.7493
41.404873862, 96.390, 2096.0, 45.7821
41.457394992, 96.390, 1947.0, 44.1248
41.509916123, 96.390, 1708.0, 41.3280
41.562437254, 96.390, 1655.0, 40.6817
41.614958384, 96.390, 1593.0, 39.9124
41.667479515, 96.390, 1543.0, 39.2810
41.720000646, 96.390, 1609.0, 40.1123
41.772521776, 96.390, 1619.0, 40.2368
41.825042907, 96.390, 1630.0, 40.3733
41.877564038, 96.390, 1612.0, 40.1497
41.930085169, 96.390, 1591.0, 39.8873
41.982606299, 96.390, 1492.0, 38.6264
42.035127430, 96.390, 1667.0, 40.8289
42.087648561, 96.390, 1839.0, 42.8836
42.140169691, 96.390, 2123.0, 46.0760
42.192690822, 96.390, 1921.0, 43.8292
42.245211953, 96.390, 1876.0, 43.3128
42.297733084, 96.390, 1698.0, 41.2068
42.350254214, 96.390, 1684.0, 41.0366
42.402775345, 96.390, 1574.0, 39.6737
42.455296476, 96.390, 1720.0, 41.4729
42.507817606, 96.390, 1841.0, 42.9069
42.560338737, 96.390, 1811.0, 42.5558
42.612859868, 96.390, 1776.0, 42.1426
42.665380999, 96.390, 1823.0, 42.6966
42.717902129, 96.390, 1994.0, 44.6542
42.770423260, 96.390, 1995.0, 44.6654
42.822944391, 96.390, 2005.0, 44.7772
42.875465521, 96.390, 2052.0, 45.2990
42.927986652, 96.390, 1972.0, 44.4072
42.980507783, 96.390, 1951.0, 44.1701
43.033028914, 96.390, 1868.0, 43.2204
43.085550044, 96.390, 1791.0, 42.3202
43.138071175, 96.390, 1815.0, 42.6028
43.190592306, 96.390, 1697.0, 41.1947
43.243113436, 96.390, 1658.0, 40.7185
43.295634567, 96.390, 1588.0, 39.8497
43.348155698, 96.390, 1582.0, 39.7744
43.400676828, 96.390, 1508.0, 38.8330
43.453197959, 96.390, 1487.0, 38.5616
43.505719090, 96.390, 1485.0, 38.5357
43.558240221, 96.390, 1525.0, 39.0512
43.610761351, 96.390, 1526.0, 39.0640
43.663282482, 96.390, 1576.0, 39.6989
43.715803613, 96.390, 1771.0, 42.0833
43.768324743, 96.390, 1963.0, 44.3058
43.820845874, 96.390, 1929.0, 43.9204
43.873367005, 96.390, 1831.0, 42.7902
43.925888136, 96.390, 1795.0, 42.3674
43.978409266, 96.390, 1604.0, 40.0500
44.030930397, 96.390, 1556.0, 39.4462
44.083451528, 96.390, 1503.0, 38.7685
44.135972658, 96.390, 1492.0, 38.6264
44.188493789, 96.390, 1509.0, 38.8458
44.241014920, 96.390, 1484.0, 38.5227
44.293536051, 96.390, 1593.0, 39.9124
44.346057181, 96.390, 1580.0, 39.7492
44.398578312, 96.390, 1750.0, 41.8330
44.451099443, 96.390, 1742.0, 41.7373
44.503620573, 96.390, 1624.0, 40.2989
44.556141704, 96.390, 1623.0, 40.2865
44.608662835, 96.390, 1507.0, 38.8201
44.661183966, 96.390, 1417.0, 37.6431
44.713705096, 96.390, 1486.0, 38.5487
44.766226227, 96.390, 1481.0, 38.4838
44.818747358, 96.390, 1544.0, 39.2938
44.871268488, 96.390, 1525.0, 39.0512
44.923789619, 96.390, 1621.0, 40.2616
44.976310750, 96.390, 1640.0, 40.4969
45.028831880, 96.390, 1719.0, 41.4608
45.081353011, 96.390, 1743.0, 41.7493
45.133874142, 96.390, 1734.0, 41.6413
45.186395273, 96.390, 1616.0, 40.1995
45.238916403, 96.390, 1630.0, 40.3733
45.291437534, 96.390, 1636.0, 40.4475
45.343958665, 96.390, 1723.0, 41.5090
45.396479795, 96.390, 1672.0, 40.8901
45.449000926, 96.390, 1664.0, 40.7922
45.501522057, 96.390, 1572.0, 39.6485
45.554043188, 96.390, 1476.0, 38.4187
45.606564318, 96.390, 1441.0, 37.9605
45.659085449, 96.390, 1394.0, 37.3363
45.711606580, 96.390, 1274.0, 35.6931
45.764127710, 96.390, 1345.0, 36.6742
45.816648841, 96.390, 1285.0, 35.8469
45.869169972, 96.390, 1382.0, 37.1753
45.921691103, 96.390, 1383.0, 37.1887
45.974212233, 96.390, 1314.0, 36.2491
46.026733364, 96.390, 1336.0, 36.5513
46.079254495, 96.390, 1381.0, 37.1618
46.131775625, 96.390, 1411.0, 37.5633
46.184296756, 96.390, 1538.0, 39.2173
46.236817887, 96.390, 1706.0, 41.3038
46.289339017, 96.390, 1824.0, 42.7083
46.341860148, 96.390, 1689.0, 41.0974
46.394381279, 96.390, 1512.0, 38.8844
46.446902410, 96.390, 1519.0, 38.9744
46.499423540, 96.390, 1361.0, 36.8917
46.551944671, 96.390, 1317.0, 36.2905
46.604465802, 96.390, 1304.0, 36.1109
46.656986932, 96.390, 1322.0, 36.3593
46.709508063, 96.390, 1307.0, 36.1525
46.762029194, 96.390, 1281.0, 35.7911
46.814550325, 96.390, 1209.0, 34.7707
46.867071455, 96.390, 1312.0, 36.2215
46.919592586, 96.390, 1240.0, 35.2136
46.972113717, 96.390, 1311.0, 36.2077
47.024634847, 96.390, 1406.0, 37.4967
47.077155978, 96.390, 1366.0, 36.9594
47.129677109, 96.390, 1281.0, 35.7911
47.182198240, 96.390, 1274.0, 35.6931
47.234719370, 96.390, 1338.0, 36.5787
47.287240501, 96.390, 1261.0, 35.5106
47.339761632, 96.390, 1236.0, 35.1568
47.392282762, 96.390, 1248.0, 35.3270
47.444803893, 96.390, 1310.0, 36.1939
47.497325024, 96.390, 1346.0, 36.6879
47.549846155, 96.390, 1307.0, 36.1525
47.602367285, 96.390, 1285.0, 35.8469
47.654888416, 96.390, 1314.0, 36.2491
47.707409547, 96.390, 1337.0, 36.5650
47.759930677, 96.390, 1370.0, 37.0135
47.812451808, 96.390, 1401.0, 37.4299
47.864972939, 96.390, 1328.0, 36.4417
47.917494069, 96.390, 1266.0, 35.5809
47.970015200, 96.390, 1177.0, 34.3074
48.022536331, 96.390, 1248.0, 35.3270
48.075057462, 96.390, 1289.0, 35.9026
48.127578592, 96.390, 1298.0, 36.0278
48.180099723, 96.390, 1286.0, 35.8608
48.232620854, 96.390, 1280.0, 35.7771
48.285141984, 96.390, 1269.0, 35.6230
48.337663115, 96.390, 1256.0, 35.4401
48.390184246, 96.390, 1329.0, 36.4555
48.442705377, 96.390, 1524.0, 39.0384
48.495226507, 96.390, 1602.0, 40.0250
48.547747638, 96.390, 1559.0, 39.4842
48.600268769, 96.390, 1440.0, 37.9473
48.652789899, 96.390, 1291.0, 35.9305
48.705311030, 96.390, 1129.0, 33.6006
48.757832161, 96.390, 1148.0, 33.8821
48.810353292, 96.390, 1136.0, 33.7046
48.862874422, 96.390, 1142.0, 33.7935
48.915395553, 96.390, 1234.0, 35.1283
48.967916684, 96.390, 1227.0, 35.0286
49.020437814, 96.390, 1184.0, 34.4093
49.072958945, 96.390, 1143.0, 33.8083
49.125480076, 96.390, 1134.0, 33.6749
49.178001207, 96.390, 1255.0, 35.4260
49.230522337, 96.390, 1146.0, 33.8526
49.283043468, 96.390, 1220.0, 34.9285
49.335564599, 96.390, 1180.0, 34.3511
49.388085729, 96.390, 1036.0, 32.1870
49.440606860, 96.390, 1023.0, 31.9844
49.493127991, 96.390, 1048.0, 32.3728
49.545649121, 96.390, 1072.0, 32.7414
49.598170252, 96.390, 1059.0, 32.5423
49.650691383, 96.390, 1094.0, 33.0757
49.703212514, 96.390, 1117.0, 33.4215
49.755733644, 96.390, 1064.0, 32.6190
49.808254775, 96.390, 1066.0, 32.6497
49.860775906, 96.390, 1041.0, 32.2645
49.913297036, 96.390, 1025.0, 32.0156
49.965818167, 96.390, 1020.0, 31.9374
50.018339298, 96.390, 1062.0, 32.5883
50.070860429, 96.390, 1032.0, 32.1248
50.123381559, 96.390, 1080.0, 32.8634
50.175902690, 96.390, 1165.0, 34.1321
50.228423821, 96.390, 1315.0, 36.2629
50.280944951, 96.390, 1222.0, 34.9571
50.333466082, 96.390, 1144.0, 33.8231
50.385987213, 96.390, 1103.0, 33.2114
50.438508344, 96.390, 1159.0, 34.0441
50.491029474, 96.390, 1218.0, 34.8999
50.543550605, 96.390, 1211.0, 34.7994
50.596071736, 96.390, 1171.0, 34.2199
50.648592866, 96.390, 1104.0, 33.2265
50.701113997, 96.390, 1052.0, 32.4345
50.753635128, 96.390, 1052.0, 32.4345
50.806156258, 96.390, 1128.0, 33.5857
50.858677389, 96.390, 1139.0, 33.7491
50.911198520, 96.390, 1036.0, 32.1870
50.963719651, 96.390, 1142.0, 33.7935
51.016240781, 96.390, 1174.0, 34.2637
51.068761912, 96.390, 1258.0, 35.4683
51.121283043, 96.390, 1198.0, 34.6121
51.173804173, 96.390, 1202.0, 34.6699
51.226325304, 96.390, 1180.0, 34.3511
51.278846435, 96.390, 1061.0, 32.5730
51.331367566, 96.390, 1105.0, 33.2415
51.383888696, 96.390, 1008.0, 31.7490
51.436409827, 96.390, 1004.0, 31.6860
51.488930958, 96.390, 960.0, 30.9839
51.541452088, 96.390, 907.0, 30.1164
51.593973219, 96.390, 954.0, 30.8869
51.646494350, 96.390, 937.0, 30.6105
51.699015481, 96.390, 971.0, 31.1609
51.751536611, 96.390, 977.0, 31.2570
51.804057742, 96.390, 1053.0, 32.4500
51.856578873, 96.390, 1121.0, 33.4813
51.909100003, 96.390, 1041.0, 32.2645
51.961621134, 96.390, 1042.0, 32.2800
52.014142265, 96.390, 1096.0, 33.1059
52.066663396, 96.390, 1051.0, 32.4191
52.119184526, 96.390, 1136.0, 33.7046
52.171705657, 96.390, 1146.0, 33.8526
52.224226788, 96.390, 1158.0, 34.0294
52.276747918, 96.390, 1180.0, 34.3511
52.329269049, 96.390, 1096.0, 33.1059
52.381790180, 96.390, 1039.0, 32.2335
52.434311310, 96.390, 1032.0, 32.1248
52.486832441, 96.390, 932.0, 30.5287
52.539353572, 96.390, 1034.0, 32.1559
52.591874703, 96.390, 980.0, 31.3050
52.644395833, 96.390, 970.0, 31.1448
52.696916964, 96.390, 909.0, 30.1496
52.749438095, 96.390, 963.0, 31.0322
52.801959225, 96.390, 965.0, 31.0644
52.854480356, 96.390, 1001.0, 31.6386
52.907001487, 96.390, 1051.0, 32.4191
52.959522618, 96.390, 933.0, 30.5450
53.012043748, 96.390, 905.0, 30.0832
53.064564879, 96.390, 961.0, 31.0000
53.117086010, 96.390, 950.0, 30.8221
53.169607140, 96.390, 950.0, 30.8221
53.222128271, 96.390, 1010.0, 31.7805
53.274649402, 96.390, 964.0, 31.0483
53.327170533, 96.390, 972.0, 31.1769
53.379691663, 96.390, 985.0, 31.3847
53.432212794, 96.390, 970.0, 31.1448
53.484733925, 96.390, 987.0, 31.4166
53.537255055, 96.390, 953.0, 30.8707
53.589776186, 96.390, 985.0, 31.3847
53.642297317, 96.390, 916.0, 30.2655
53.694818448, 96.390, 916.0, 30.2655
53.747339578, 96.390, 917.0, 30.2820
53.799860709, 96.390, 947.0, 30.7734
53.852381840, 96.390, 966.0, 31.0805
53.904902970, 96.390, 1020.0, 31.9374
53.957424101, 96.390, 1112.0, 33.3467
54.009945232, 96.390, 1111.0, 33.3317
54.062466362, 96.390, 1072.0, 32.7414
54.114987493, 96.390, 1059.0, 32.5423
54.167508624, 96.390, 1076.0, 32.8024
54.220029755, 96.390, 1002.0, 31.6544
54.272550885, 96.390, 1101.0, 33.1813
54.325072016, 96.390, 1057.0, 32.5115
54.377593147, 96.390, 1040.0, 32.2490
54.430114277, 96.390, 1017.0, 31.8904
54.482635408, 96.390, 966.0, 31.0805
54.535156539, 96.390, 918.0, 30.2985
54.587677670, 96.390, 923.0, 30.3809
54.640198800, 96.390, 929.0, 30.4795
54.692719931, 96.390, 924.0, 30.3974
54.745241062, 96.390, 850.0, 29.1548
54.797762192, 96.390, 901.0, 30.0167
54.850283323, 96.390, 890.0, 29.8329
54.902804454, 96.390, 879.0, 29.6479
54.955325585, 96.390, 856.0, 29.2575
55.007846715, 96.390, 869.0, 29.4788
55.060367846, 96.390, 885.0, 29.7489
55.112888977, 96.390, 896.0, 29.9333
55.165410107, 96.390, 921.0, 30.3480
55.217931238, 96.390, 852.0, 29.1890
55.270452369, 96.390, 860.0, 29.3258
55.322973499, 96.390, 871.0, 29.5127
55.375494630, 96.390, 895.0, 29.9166
55.428015761, 96.390, 980.0, 31.3050
55.480536892, 96.390, 863.0, 29.3769
55.533058022, 96.390, 941.0, 30.6757
55.585579153, 96.390, 918.0, 30.2985
55.638100284, 96.390, 919.0, 30.3150
55.690621414, 96.390, 920.0, 30.3315
55.743142545, 96.390, 990.0, 31.4643
55.795663676, 96.390, 924.0, 30.3974
55.848184807, 96.390, 980.0, 31.3050
55.900705937, 96.390, 924.0, 30.3974
55.953227068, 96.390, 892.0, 29.8664
56.005748199, 96.390, 929.0, 30.4795
56.058269329, 96.390, 933.0, 30.5450
56.110790460, 96.390, 975.0, 31.2250
56.163311591, 96.390, 931.0, 30.5123
56.215832722, 96.390, 975.0, 31.2250
56.268353852, 96.390, 923.0, 30.3809
56.320874983, 96.390, 913.0, 30.2159
56.373396114, 96.390, 865.0, 29.4109
56.425917244, 96.390, 796.0, 28.2135
56.478438375, 96.390, 881.0, 29.6816
56.530959506, 96.390, 908.0, 30.1330
56.583480637, 96.390, 839.0, 28.9655
56.636001767, 96.390, 885.0, 29.7489
56.688522898, 96.390, 868.0, 29.4618
56.741044029, 96.390, 885.0, 29.7489
56.793565159, 96.390, 858.0, 29.2916
56.846086290, 96.390, 919.0, 30.3150
56.898607421, 96.390, 914.0, 30.2324
56.951128551, 96.390, 834.0, 28.8791
57.003649682, 96.390, 895.0, 29.9166
57.056170813, 96.390, 883.0, 29.7153
57.108691944, 96.390, 928.0, 30.4631
57.161213074, 96.390, 924.0, 30.3974
57.213734205, 96.390, 1002.0, 31.6544
57.266255336, 96.390, 971.0, 31.1609
57.318776466, 96.390, 951.0, 30.8383
57.371297597, 96.390, 860.0, 29.3258
57.423818728, 96.390, 898.0, 29.9666
57.476339859, 96.390, 893.0, 29.8831
57.528860989, 96.390, 883.0, 29.7153
57.581382120, 96.390, 840.0, 28.9828
57.633903251, 96.390, 804.0, 28.3549
57.686424381, 96.390, 804.0, 28.3549
57.738945512, 96.390, 915.0, 30.2490
57.791466643, 96.390, 950.0, 30.8221
57.843987774, 96.390, 880.0, 29.6648
57.896508904, 96.390, 896.0, 29.9333
57.949030035, 96.390, 912.0, 30.1993
58.001551166, 96.390, 1036.0, 32.1870
58.054072296, 96.390, 1115.0, 33.3916
58.106593427, 96.390, 1074.0, 32.7719
58.159114558, 96.390, 942.0, 30.6920
58.211635689, 96.390, 996.0, 31.5595
58.264156819, 96.390, 928.0, 30.4631
58.316677950, 96.390, 911.0, 30.1828
58.369199081, 96.390, 933.0, 30.5450
58.421720211, 96.390, 929.0, 30.4795
58.474241342, 96.390, 942.0, 30.6920
58.526762473, 96.390, 921.0, 30.3480
58.579283603, 96.390, 950.0, 30.8221
58.631804734, 96.390, 973.0, 31.1929
58.684325865, 96.390, 933.0, 30.5450
58.736846996, 96.390, 938.0, 30.6268
58.789368126, 96.390, 976.0, 31.2410
58.841889257, 96.390, 1006.0, 31.7175
58.894410388, 96.390, 989.0, 31.4484
58.946931518, 96.390, 981.0, 31.3209
58.999452649, 96.390, 1035.0, 32.1714
59.051973780, 96.390, 1039.0, 32.2335
59.104494911, 96.390, 1090.0, 33.0151
59.157016041, 96.390, 1125.0, 33.5410
59.209537172, 96.390, 1117.0, 33.4215
59.262058303, 96.390, 1116.0, 33.4066
59.314579433, 96.390, 1190.0, 34.4964
59.367100564, 96.390, 1197.0, 34.5977
59.419621695, 96.390, 1213.0, 34.8281
59.472142826, 96.390, 1361.0, 36.8917
59.524663956, 96.390, 1342.0, 36.6333
59.577185087, 96.390, 1292.0, 35.9444
59.629706218, 96.390, 1344.0, 36.6606
59.682227348, 96.390, 1433.0, 37.8550
59.734748479, 96.390, 1447.0, 38.0395
59.787269610, 96.390, 1498.0, 38.7040
59.839790740, 96.390, 1610.0, 40.1248
59.892311871, 96.390, 1630.0, 40.3733
59.944833002, 96.390, 1628.0, 40.3485
59.997354133, 96.390, 1771.0, 42.0833
60.049875263, 96.390, 1723.0, 41.5090
60.102396394, 96.390, 1748.0, 41.8091
60.154917525, 96.390, 1802.0, 42.4500
60.207438655, 96.390, 1941.0, 44.0568
60.259959786, 96.390, 1944.0, 44.0908
60.312480917, 96.390, 1875.0, 43.3013
60.365002048, 96.390, 1822.0, 42.6849
60.417523178, 96.390, 1854.0, 43.0581
60.470044309, 96.390, 1939.0, 44.0341
60.522565440, 96.390, 1895.0, 43.5316
60.575086570, 96.390, 1805.0, 42.4853
60.627607701, 96.390, 1878.0, 43.3359
60.680128832, 96.390, 1807.0, 42.5088
60.732649963, 96.390, 1725.0, 41.5331
60.785171093, 96.390, 1658.0, 40.7185
60.837692224, 96.390, 1643.0, 40.5339
60.890213355, 96.390, 1591.0, 39.8873
60.942734485, 96.390, 1548.0, 39.3446
60.995255616, 96.390, 1587.0, 39.8372
61.047776747, 96.390, 1554.0, 39.4208
61.100297878, 96.390, 1505.0, 38.7943
61.152819008, 96.390, 1568.0, 39.5980
61.205340139, 96.390, 1543.0, 39.2810
61.257861270, 96.390, 1501.0, 38.7427
61.310382400, 96.390, 1506.0, 38.8072
61.362903531, 96.390, 1543.0, 39.2810
61.415424662, 96.390, 1538.0, 39.2173
61.467945792, 96.390, 1471.0, 38.3536
61.520466923, 96.390, 1466.0, 38.2884
61.572988054, 96.390, 1408.0, 37.5233
61.625509185, 96.390, 1446.0, 38.0263
61.678030315, 96.390, 1424.0, 37.7359
61.730551446, 96.390, 1304.0, 36.1109
61.783072577, 96.390, 1332.0, 36.4966
61.835593707, 96.390, 1287.0, 35.8748
61.888114838, 96.390, 1320.0, 36.3318
61.940635969, 96.390, 1274.0, 35.6931
61.993157100, 96.390, 1261.0, 35.5106
62.045678230, 96.390, 1257.0, 35.4542
62.098199361, 96.390, 1244.0, 35.2704
62.150720492, 96.390, 1250.0, 35.3553
62.203241622, 96.390, 1310.0, 36.1939
62.255762753, 96.390, 1323.0, 36.3731
62.308283884, 96.390, 1293.0, 35.9583
62.360805015, 96.390, 1211.0, 34.7994
62.413326145, 96.390, 1189.0, 34.4819
62.465847276, 96.390, 1126.0, 33.5559
62.518368407, 96.390, 1153.0, 33.9559
62.570889537, 96.390, 1056.0, 32.4962
62.623410668, 96.390, 1041.0, 32.2645
62.675931799, 96.390, 1119.0, 33.4515
62.728452930, 96.390, 1013.0, 31.8277
62.780974060, 96.390, 981.0, 31.3209
62.833495191, 96.390, 980.0, 31.3050
62.886016322, 96.390, 921.0, 30.3480
62.938537452, 96.390, 928.0, 30.4631
62.991058583, 96.390, 863.0, 29.3769
63.043579714, 96.390, 840.0, 28.9828
63.096100844, 96.390, 841.0, 29.0000
63.148621975, 96.390, 764.0, 27.6405
63.201143106, 96.390, 786.0, 28.0357
63.253664237, 96.390, 831.0, 28.8271
63.306185367, 96.390, 860.0, 29.3258
63.358706498, 96.390, 815.0, 28.5482
63.411227629, 96.390, 801.0, 28.3019
63.463748759, 96.390, 803.0, 28.3373
63.516269890, 96.390, 762.0, 27.6043
63.568791021, 96.390, 765.0, 27.6586
63.621312152, 96.390, 841.0, 29.0000
63.673833282, 96.390, 771.0, 27.7669
63.726354413, 96.390, 801.0, 28.3019
63.778875544, 96.390, 826.0, 28.7402
63.831396674, 96.390, 823.0, 28.6880
63.883917805, 96.390, 864.0, 29.3939
63.936438936, 96.390, 752.0, 27.4226
63.988960067, 96.390, 812.0, 28.4956
64.041481197, 96.390, 753.0, 27.4408
64.094002328, 96.390, 787.0, 28.0535
64.146523459, 96.390, 801.0, 28.3019
64.199044589, 96.390, 738.0, 27.1662
64.251565720, 96.390, 778.0, 27.8927
64.304086851, 96.390, 776.0, 27.8568
64.356607981, 96.390, 750.0, 27.3861
64.409129112, 96.390, 770.0, 27.7489
64.461650243, 96.390, 763.0, 27.6225
64.514171374, 96.390, 785.0, 28.0179
64.566692504, 96.390, 666.0, 25.8070
64.619213635, 96.390, 746.0, 27.3130
64.671734766, 96.390, 684.0, 26.1534
64.724255896, 96.390, 651.0, 25.5147
64.776777027, 96.390, 738.0, 27.1662
64.829298158, 96.390, 717.0, 26.7769
64.881819289, 96.390, 748.0, 27.3496
64.934340419, 96.390, 761.0, 27.5862
64.986861550, 96.390, 708.0, 26.6083