File: Files_organized_for_plots/Constant_NaOH_1mL10M_to_1gPC/XRD_SiAxial05Nov21_Act10Jan22_B1_0714M_NaOH_LS0162_1.csv
[Measurement conditions]
Sample identification,XRD_SiAxial05Nov21_Act10Jan22_B1_0714M_NaOH_LS0162_1
Comment - 1,"Configuration=Stage for Flat Samples/Holders, Owner=User-1, Creation date=7/1/2020 9:53:24 AM"
Comment - 2,"Goniometer=Theta/Theta; Minimum step size 2Theta:0.0001; Minimum step size Omega:0.0001"
Comment - 3,"Sample stage=Stage for flat samples/holders"
Comment - 4,"Diffractometer system=EMPYREAN"
Comment - 5,"Measurement program=C:\Users\ibo5034\OneDrive - The Pennsylvania State University\NEUP - Reed, Titus's files\XRD\Cement\Zerobackground scan.xrdmp, Identifier={98A3B11C-88F9-4AA6-982C-73314A311EF5}"
Anode material,Cu
K-Alpha1 wavelength,1.5405980
K-Alpha2 wavelength,1.5444260
Ratio K-Alpha2/K-Alpha1,0.500
Divergence slit,Fixed,0.25
Monochromator used,NO
Generator voltage, 45
Tube current, 40
File date and time,13/Jan/2022 12:16
Unit cell,
h k l, 0 0 0
Scan axis,Gonio
Scan range,4.994599997,64.999991833
Scan step size,0.0262606
No. of points, 2285
Scan type,CONTINUOUS
Time per step,96.390
[Scan points]
Angle, TimePerStep, Intensity, ESD
5.007730280, 96.390, 4139.0, 64.3351
5.060251411, 96.390, 4059.0, 63.7103
5.112772541, 96.390, 3919.0, 62.6019
5.165293672, 96.390, 3835.0, 61.9274
5.217814803, 96.390, 3824.0, 61.8385
5.270335934, 96.390, 3923.0, 62.6339
5.322857064, 96.390, 3838.0, 61.9516
5.375378195, 96.390, 3763.0, 61.3433
5.427899326, 96.390, 3856.0, 62.0967
5.480420456, 96.390, 3801.0, 61.6523
5.532941587, 96.390, 3764.0, 61.3514
5.585462718, 96.390, 3694.0, 60.7783
5.637983849, 96.390, 3596.0, 59.9667
5.690504979, 96.390, 3548.0, 59.5651
5.743026110, 96.390, 3491.0, 59.0847
5.795547241, 96.390, 3598.0, 59.9833
5.848068371, 96.390, 3457.0, 58.7963
5.900589502, 96.390, 3528.0, 59.3970
5.953110633, 96.390, 3617.0, 60.1415
6.005631763, 96.390, 3564.0, 59.6992
6.058152894, 96.390, 3578.0, 59.8164
6.110674025, 96.390, 3533.0, 59.4390
6.163195156, 96.390, 3511.0, 59.2537
6.215716286, 96.390, 3544.0, 59.5315
6.268237417, 96.390, 3507.0, 59.2199
6.320758548, 96.390, 3405.0, 58.3524
6.373279678, 96.390, 3491.0, 59.0847
6.425800809, 96.390, 3517.0, 59.3043
6.478321940, 96.390, 3353.0, 57.9051
6.530843071, 96.390, 3416.0, 58.4466
6.583364201, 96.390, 3492.0, 59.0931
6.635885332, 96.390, 3493.0, 59.1016
6.688406463, 96.390, 3507.0, 59.2199
6.740927593, 96.390, 3352.0, 57.8965
6.793448724, 96.390, 3394.0, 58.2580
6.845969855, 96.390, 3413.0, 58.4209
6.898490986, 96.390, 3470.0, 58.9067
6.951012116, 96.390, 3421.0, 58.4893
7.003533247, 96.390, 3329.0, 57.6975
7.056054378, 96.390, 3549.0, 59.5735
7.108575508, 96.390, 3356.0, 57.9310
7.161096639, 96.390, 3452.0, 58.7537
7.213617770, 96.390, 3434.0, 58.6003
7.266138900, 96.390, 3389.0, 58.2151
7.318660031, 96.390, 3434.0, 58.6003
7.371181162, 96.390, 3578.0, 59.8164
7.423702293, 96.390, 3368.0, 58.0345
7.476223423, 96.390, 3475.0, 58.9491
7.528744554, 96.390, 3381.0, 58.1464
7.581265685, 96.390, 3407.0, 58.3695
7.633786815, 96.390, 3495.0, 59.1185
7.686307946, 96.390, 3411.0, 58.4038
7.738829077, 96.390, 3537.0, 59.4727
7.791350208, 96.390, 3541.0, 59.5063
7.843871338, 96.390, 3521.0, 59.3380
7.896392469, 96.390, 3458.0, 58.8048
7.948913600, 96.390, 3538.0, 59.4811
8.001434730, 96.390, 3623.0, 60.1914
8.053955861, 96.390, 3606.0, 60.0500
8.106476992, 96.390, 3579.0, 59.8247
8.158998123, 96.390, 3692.0, 60.7618
8.211519253, 96.390, 3717.0, 60.9672
8.264040384, 96.390, 3636.0, 60.2993
8.316561515, 96.390, 3526.0, 59.3801
8.369082645, 96.390, 3603.0, 60.0250
8.421603776, 96.390, 3592.0, 59.9333
8.474124907, 96.390, 3491.0, 59.0847
8.526646038, 96.390, 3413.0, 58.4209
8.579167168, 96.390, 3510.0, 59.2453
8.631688299, 96.390, 3641.0, 60.3407
8.684209430, 96.390, 3484.0, 59.0254
8.736730560, 96.390, 3537.0, 59.4727
8.789251691, 96.390, 3575.0, 59.7913
8.841772822, 96.390, 3378.0, 58.1206
8.894293952, 96.390, 3490.0, 59.0762
8.946815083, 96.390, 3516.0, 59.2959
8.999336214, 96.390, 3513.0, 59.2706
9.051857345, 96.390, 3339.0, 57.7841
9.104378475, 96.390, 3362.0, 57.9828
9.156899606, 96.390, 3543.0, 59.5231
9.209420737, 96.390, 3312.0, 57.5500
9.261941867, 96.390, 3384.0, 58.1722
9.314462998, 96.390, 3403.0, 58.3352
9.366984129, 96.390, 3427.0, 58.5406
9.419505260, 96.390, 3397.0, 58.2838
9.472026390, 96.390, 3430.0, 58.5662
9.524547521, 96.390, 3318.0, 57.6021
9.577068652, 96.390, 3296.0, 57.4108
9.629589782, 96.390, 3347.0, 57.8533
9.682110913, 96.390, 3224.0, 56.7803
9.734632044, 96.390, 3312.0, 57.5500
9.787153175, 96.390, 3197.0, 56.5420
9.839674305, 96.390, 3311.0, 57.5413
9.892195436, 96.390, 3175.0, 56.3471
9.944716567, 96.390, 3179.0, 56.3826
9.997237697, 96.390, 3265.0, 57.1402
10.049758828, 96.390, 3220.0, 56.7450
10.102279959, 96.390, 3194.0, 56.5155
10.154801090, 96.390, 3172.0, 56.3205
10.207322220, 96.390, 3099.0, 55.6687
10.259843351, 96.390, 3170.0, 56.3028
10.312364482, 96.390, 3069.0, 55.3986
10.364885612, 96.390, 3055.0, 55.2721
10.417406743, 96.390, 3125.0, 55.9017
10.469927874, 96.390, 3135.0, 55.9911
10.522449004, 96.390, 3170.0, 56.3028
10.574970135, 96.390, 2971.0, 54.5069
10.627491266, 96.390, 2982.0, 54.6077
10.680012397, 96.390, 3030.0, 55.0454
10.732533527, 96.390, 3086.0, 55.5518
10.785054658, 96.390, 2937.0, 54.1941
10.837575789, 96.390, 2970.0, 54.4977
10.890096919, 96.390, 2993.0, 54.7083
10.942618050, 96.390, 2983.0, 54.6168
10.995139181, 96.390, 3008.0, 54.8452
11.047660312, 96.390, 2921.0, 54.0463
11.100181442, 96.390, 2909.0, 53.9351
11.152702573, 96.390, 2969.0, 54.4885
11.205223704, 96.390, 2866.0, 53.5350
11.257744834, 96.390, 2762.0, 52.5547
11.310265965, 96.390, 2800.0, 52.9150
11.362787096, 96.390, 2791.0, 52.8299
11.415308227, 96.390, 2833.0, 53.2259
11.467829357, 96.390, 2871.0, 53.5817
11.520350488, 96.390, 2798.0, 52.8961
11.572871619, 96.390, 2750.0, 52.4404
11.625392749, 96.390, 2690.0, 51.8652
11.677913880, 96.390, 2727.0, 52.2207
11.730435011, 96.390, 2693.0, 51.8941
11.782956141, 96.390, 2733.0, 52.2781
11.835477272, 96.390, 2626.0, 51.2445
11.887998403, 96.390, 2675.0, 51.7204
11.940519534, 96.390, 2697.0, 51.9326
11.993040664, 96.390, 2678.0, 51.7494
12.045561795, 96.390, 2648.0, 51.4587
12.098082926, 96.390, 2589.0, 50.8822
12.150604056, 96.390, 2627.0, 51.2543
12.203125187, 96.390, 2664.0, 51.6140
12.255646318, 96.390, 2580.0, 50.7937
12.308167449, 96.390, 2568.0, 50.6754
12.360688579, 96.390, 2559.0, 50.5866
12.413209710, 96.390, 2553.0, 50.5272
12.465730841, 96.390, 2588.0, 50.8724
12.518251971, 96.390, 2479.0, 49.7896
12.570773102, 96.390, 2494.0, 49.9400
12.623294233, 96.390, 2602.0, 51.0098
12.675815364, 96.390, 2420.0, 49.1935
12.728336494, 96.390, 2493.0, 49.9300
12.780857625, 96.390, 2528.0, 50.2792
12.833378756, 96.390, 2374.0, 48.7237
12.885899886, 96.390, 2547.0, 50.4678
12.938421017, 96.390, 2458.0, 49.5782
12.990942148, 96.390, 2483.0, 49.8297
13.043463279, 96.390, 2462.0, 49.6185
13.095984409, 96.390, 2503.0, 50.0300
13.148505540, 96.390, 2421.0, 49.2037
13.201026671, 96.390, 2519.0, 50.1896
13.253547801, 96.390, 2511.0, 50.1099
13.306068932, 96.390, 2470.0, 49.6991
13.358590063, 96.390, 2475.0, 49.7494
13.411111193, 96.390, 2485.0, 49.8498
13.463632324, 96.390, 2658.0, 51.5558
13.516153455, 96.390, 2759.0, 52.5262
13.568674586, 96.390, 2783.0, 52.7541
13.621195716, 96.390, 2473.0, 49.7293
13.673716847, 96.390, 2470.0, 49.6991
13.726237978, 96.390, 2398.0, 48.9694
13.778759108, 96.390, 2494.0, 49.9400
13.831280239, 96.390, 2527.0, 50.2693
13.883801370, 96.390, 2427.0, 49.2646
13.936322501, 96.390, 2568.0, 50.6754
13.988843631, 96.390, 2424.0, 49.2341
14.041364762, 96.390, 2339.0, 48.3632
14.093885893, 96.390, 2445.0, 49.4469
14.146407023, 96.390, 2455.0, 49.5480
14.198928154, 96.390, 2567.0, 50.6656
14.251449285, 96.390, 2708.0, 52.0384
14.303970416, 96.390, 2889.0, 53.7494
14.356491546, 96.390, 2499.0, 49.9900
14.409012677, 96.390, 2439.0, 49.3862
14.461533808, 96.390, 2505.0, 50.0500
14.514054938, 96.390, 2700.0, 51.9615
14.566576069, 96.390, 2848.0, 53.3667
14.619097200, 96.390, 2611.0, 51.0979
14.671618331, 96.390, 2388.0, 48.8672
14.724139461, 96.390, 2392.0, 48.9081
14.776660592, 96.390, 2313.0, 48.0937
14.829181723, 96.390, 2262.0, 47.5605
14.881702853, 96.390, 2357.0, 48.5489
14.934223984, 96.390, 2261.0, 47.5500
14.986745115, 96.390, 2332.0, 48.2908
15.039266245, 96.390, 2398.0, 48.9694
15.091787376, 96.390, 2366.0, 48.6415
15.144308507, 96.390, 2494.0, 49.9400
15.196829638, 96.390, 2638.0, 51.3615
15.249350768, 96.390, 2909.0, 53.9351
15.301871899, 96.390, 3085.0, 55.5428
15.354393030, 96.390, 2682.0, 51.7880
15.406914160, 96.390, 2495.0, 49.9500
15.459435291, 96.390, 2320.0, 48.1664
15.511956422, 96.390, 2433.0, 49.3254
15.564477553, 96.390, 2351.0, 48.4871
15.616998683, 96.390, 2335.0, 48.3218
15.669519814, 96.390, 2341.0, 48.3839
15.722040945, 96.390, 2381.0, 48.7955
15.774562075, 96.390, 2389.0, 48.8774
15.827083206, 96.390, 2329.0, 48.2597
15.879604337, 96.390, 2362.0, 48.6004
15.932125468, 96.390, 2404.0, 49.0306
15.984646598, 96.390, 2275.0, 47.6970
16.037167729, 96.390, 2335.0, 48.3218
16.089688860, 96.390, 2463.0, 49.6286
16.142209990, 96.390, 2339.0, 48.3632
16.194731121, 96.390, 2452.0, 49.5177
16.247252252, 96.390, 2529.0, 50.2892
16.299773382, 96.390, 2640.0, 51.3809
16.352294513, 96.390, 2817.0, 53.0754
16.404815644, 96.390, 2799.0, 52.9056
16.457336775, 96.390, 2659.0, 51.5655
16.509857905, 96.390, 2610.0, 51.0882
16.562379036, 96.390, 2695.0, 51.9134
16.614900167, 96.390, 2490.0, 49.8999
16.667421297, 96.390, 2463.0, 49.6286
16.719942428, 96.390, 2438.0, 49.3761
16.772463559, 96.390, 2521.0, 50.2096
16.824984690, 96.390, 2498.0, 49.9800
16.877505820, 96.390, 2499.0, 49.9900
16.930026951, 96.390, 2527.0, 50.2693
16.982548082, 96.390, 2485.0, 49.8498
17.035069212, 96.390, 2355.0, 48.5283
17.087590343, 96.390, 2345.0, 48.4252
17.140111474, 96.390, 2324.0, 48.2079
17.192632605, 96.390, 2370.0, 48.6826
17.245153735, 96.390, 2301.0, 47.9687
17.297674866, 96.390, 2366.0, 48.6415
17.350195997, 96.390, 2367.0, 48.6518
17.402717127, 96.390, 2281.0, 47.7598
17.455238258, 96.390, 2337.0, 48.3425
17.507759389, 96.390, 2306.0, 48.0208
17.560280520, 96.390, 2304.0, 48.0000
17.612801650, 96.390, 2276.0, 47.7074
17.665322781, 96.390, 2347.0, 48.4458
17.717843912, 96.390, 2329.0, 48.2597
17.770365042, 96.390, 2239.0, 47.3181
17.822886173, 96.390, 2413.0, 49.1223
17.875407304, 96.390, 2270.0, 47.6445
17.927928434, 96.390, 2253.0, 47.4658
17.980449565, 96.390, 2246.0, 47.3920
18.032970696, 96.390, 2220.0, 47.1169
18.085491827, 96.390, 2362.0, 48.6004
18.138012957, 96.390, 2383.0, 48.8160
18.190534088, 96.390, 2232.0, 47.2440
18.243055219, 96.390, 2379.0, 48.7750
18.295576349, 96.390, 2326.0, 48.2286
18.348097480, 96.390, 2427.0, 49.2646
18.400618611, 96.390, 2405.0, 49.0408
18.453139742, 96.390, 2380.0, 48.7852
18.505660872, 96.390, 2300.0, 47.9583
18.558182003, 96.390, 2353.0, 48.5077
18.610703134, 96.390, 2300.0, 47.9583
18.663224264, 96.390, 2376.0, 48.7442
18.715745395, 96.390, 2476.0, 49.7594
18.768266526, 96.390, 2544.0, 50.4381
18.820787657, 96.390, 2751.0, 52.4500
18.873308787, 96.390, 2869.0, 53.5630
18.925829918, 96.390, 2931.0, 54.1387
18.978351049, 96.390, 2878.0, 53.6470
19.030872179, 96.390, 2911.0, 53.9537
19.083393310, 96.390, 2700.0, 51.9615
19.135914441, 96.390, 2583.0, 50.8232
19.188435572, 96.390, 2559.0, 50.5866
19.240956702, 96.390, 2479.0, 49.7896
19.293477833, 96.390, 2530.0, 50.2991
19.345998964, 96.390, 2570.0, 50.6952
19.398520094, 96.390, 2710.0, 52.0577
19.451041225, 96.390, 2720.0, 52.1536
19.503562356, 96.390, 2661.0, 51.5849
19.556083486, 96.390, 2600.0, 50.9902
19.608604617, 96.390, 2541.0, 50.4083
19.661125748, 96.390, 2587.0, 50.8626
19.713646879, 96.390, 2777.0, 52.6972
19.766168009, 96.390, 2791.0, 52.8299
19.818689140, 96.390, 2886.0, 53.7215
19.871210271, 96.390, 2815.0, 53.0566
19.923731401, 96.390, 3019.0, 54.9454
19.976252532, 96.390, 3444.0, 58.6856
20.028773663, 96.390, 3397.0, 58.2838
20.081294794, 96.390, 2786.0, 52.7826
20.133815924, 96.390, 2657.0, 51.5461
20.186337055, 96.390, 2629.0, 51.2738
20.238858186, 96.390, 2722.0, 52.1728
20.291379316, 96.390, 2748.0, 52.4214
20.343900447, 96.390, 2752.0, 52.4595
20.396421578, 96.390, 2971.0, 54.5069
20.448942709, 96.390, 3106.0, 55.7315
20.501463839, 96.390, 3189.0, 56.4712
20.553984970, 96.390, 3140.0, 56.0357
20.606506101, 96.390, 3396.0, 58.2752
20.659027231, 96.390, 4059.0, 63.7103
20.711548362, 96.390, 5134.0, 71.6519
20.764069493, 96.390, 5046.0, 71.0352
20.816590623, 96.390, 3740.0, 61.1555
20.869111754, 96.390, 3047.0, 55.1996
20.921632885, 96.390, 2938.0, 54.2033
20.974154016, 96.390, 2904.0, 53.8888
21.026675146, 96.390, 2906.0, 53.9073
21.079196277, 96.390, 2877.0, 53.6377
21.131717408, 96.390, 2779.0, 52.7162
21.184238538, 96.390, 2809.0, 53.0000
21.236759669, 96.390, 2810.0, 53.0094
21.289280800, 96.390, 2924.0, 54.0740
21.341801931, 96.390, 2880.0, 53.6656
21.394323061, 96.390, 3025.0, 55.0000
21.446844192, 96.390, 2806.0, 52.9717
21.499365323, 96.390, 2763.0, 52.5642
21.551886453, 96.390, 2838.0, 53.2729
21.604407584, 96.390, 2981.0, 54.5985
21.656928715, 96.390, 3120.0, 55.8570
21.709449846, 96.390, 3035.0, 55.0908
21.761970976, 96.390, 2945.0, 54.2679
21.814492107, 96.390, 2761.0, 52.5452
21.867013238, 96.390, 2822.0, 53.1225
21.919534368, 96.390, 2695.0, 51.9134
21.972055499, 96.390, 2819.0, 53.0943
22.024576630, 96.390, 2742.0, 52.3641
22.077097761, 96.390, 2800.0, 52.9150
22.129618891, 96.390, 2677.0, 51.7397
22.182140022, 96.390, 2744.0, 52.3832
22.234661153, 96.390, 2761.0, 52.5452
22.287182283, 96.390, 2753.0, 52.4690
22.339703414, 96.390, 2822.0, 53.1225
22.392224545, 96.390, 2812.0, 53.0283
22.444745675, 96.390, 2751.0, 52.4500
22.497266806, 96.390, 2903.0, 53.8795
22.549787937, 96.390, 2800.0, 52.9150
22.602309068, 96.390, 2925.0, 54.0833
22.654830198, 96.390, 2896.0, 53.8145
22.707351329, 96.390, 2920.0, 54.0370
22.759872460, 96.390, 2842.0, 53.3104
22.812393590, 96.390, 2974.0, 54.5344
22.864914721, 96.390, 3120.0, 55.8570
22.917435852, 96.390, 3131.0, 55.9553
22.969956983, 96.390, 3002.0, 54.7905
23.022478113, 96.390, 3039.0, 55.1271
23.074999244, 96.390, 2950.0, 54.3139
23.127520375, 96.390, 3008.0, 54.8452
23.180041505, 96.390, 3225.0, 56.7891
23.232562636, 96.390, 3199.0, 56.5597
23.285083767, 96.390, 3098.0, 55.6597
23.337604898, 96.390, 2990.0, 54.6809
23.390126028, 96.390, 3059.0, 55.3082
23.442647159, 96.390, 3125.0, 55.9017
23.495168290, 96.390, 2918.0, 54.0185
23.547689420, 96.390, 3082.0, 55.5158
23.600210551, 96.390, 2922.0, 54.0555
23.652731682, 96.390, 2966.0, 54.4610
23.705252813, 96.390, 2882.0, 53.6843
23.757773943, 96.390, 2851.0, 53.3948
23.810295074, 96.390, 2729.0, 52.2398
23.862816205, 96.390, 2928.0, 54.1110
23.915337335, 96.390, 2707.0, 52.0288
23.967858466, 96.390, 2839.0, 53.2823
24.020379597, 96.390, 2788.0, 52.8015
24.072900727, 96.390, 2768.0, 52.6118
24.125421858, 96.390, 2865.0, 53.5257
24.177942989, 96.390, 2971.0, 54.5069
24.230464120, 96.390, 3025.0, 55.0000
24.282985250, 96.390, 2939.0, 54.2125
24.335506381, 96.390, 2773.0, 52.6593
24.388027512, 96.390, 2804.0, 52.9528
24.440548642, 96.390, 2679.0, 51.7591
24.493069773, 96.390, 2734.0, 52.2877
24.545590904, 96.390, 2787.0, 52.7920
24.598112035, 96.390, 2738.0, 52.3259
24.650633165, 96.390, 2669.0, 51.6624
24.703154296, 96.390, 2686.0, 51.8266
24.755675427, 96.390, 2614.0, 51.1273
24.808196557, 96.390, 2590.0, 50.8920
24.860717688, 96.390, 2537.0, 50.3686
24.913238819, 96.390, 2560.0, 50.5964
24.965759950, 96.390, 2487.0, 49.8698
25.018281080, 96.390, 2540.0, 50.3984
25.070802211, 96.390, 2501.0, 50.0100
25.123323342, 96.390, 2493.0, 49.9300
25.175844472, 96.390, 2415.0, 49.1426
25.228365603, 96.390, 2409.0, 49.0816
25.280886734, 96.390, 2327.0, 48.2390
25.333407864, 96.390, 2546.0, 50.4579
25.385928995, 96.390, 2552.0, 50.5173
25.438450126, 96.390, 2917.0, 54.0093
25.490971257, 96.390, 2858.0, 53.4603
25.543492387, 96.390, 2591.0, 50.9019
25.596013518, 96.390, 2481.0, 49.8096
25.648534649, 96.390, 2263.0, 47.5710
25.701055779, 96.390, 2331.0, 48.2804
25.753576910, 96.390, 2229.0, 47.2123
25.806098041, 96.390, 2226.0, 47.1805
25.858619172, 96.390, 2370.0, 48.6826
25.911140302, 96.390, 2315.0, 48.1144
25.963661433, 96.390, 2218.0, 47.0956
26.016182564, 96.390, 2250.0, 47.4342
26.068703694, 96.390, 2306.0, 48.0208
26.121224825, 96.390, 2217.0, 47.0850
26.173745956, 96.390, 2164.0, 46.5188
26.226267087, 96.390, 2155.0, 46.4220
26.278788217, 96.390, 2177.0, 46.6583
26.331309348, 96.390, 2176.0, 46.6476
26.383830479, 96.390, 2199.0, 46.8935
26.436351609, 96.390, 2123.0, 46.0760
26.488872740, 96.390, 2174.0, 46.6262
26.541393871, 96.390, 2107.0, 45.9021
26.593915002, 96.390, 2056.0, 45.3431
26.646436132, 96.390, 2121.0, 46.0543
26.698957263, 96.390, 2105.0, 45.8803
26.751478394, 96.390, 2318.0, 48.1456
26.803999524, 96.390, 2475.0, 49.7494
26.856520655, 96.390, 2535.0, 50.3488
26.909041786, 96.390, 2342.0, 48.3942
26.961562916, 96.390, 2330.0, 48.2701
27.014084047, 96.390, 2453.0, 49.5278
27.066605178, 96.390, 2668.0, 51.6527
27.119126309, 96.390, 2717.0, 52.1249
27.171647439, 96.390, 3105.0, 55.7225
27.224168570, 96.390, 3329.0, 57.6975
27.276689701, 96.390, 2888.0, 53.7401
27.329210831, 96.390, 2553.0, 50.5272
27.381731962, 96.390, 2336.0, 48.3322
27.434253093, 96.390, 2145.0, 46.3141
27.486774224, 96.390, 2170.0, 46.5833
27.539295354, 96.390, 2050.0, 45.2769
27.591816485, 96.390, 2044.0, 45.2106
27.644337616, 96.390, 2062.0, 45.4093
27.696858746, 96.390, 2047.0, 45.2438
27.749379877, 96.390, 2132.0, 46.1736
27.801901008, 96.390, 2017.0, 44.9110
27.854422139, 96.390, 2105.0, 45.8803
27.906943269, 96.390, 2120.0, 46.0435
27.959464400, 96.390, 2094.0, 45.7602
28.011985531, 96.390, 2112.0, 45.9565
28.064506661, 96.390, 2092.0, 45.7384
28.117027792, 96.390, 2117.0, 46.0109
28.169548923, 96.390, 2084.0, 45.6508
28.222070054, 96.390, 2138.0, 46.2385
28.274591184, 96.390, 2102.0, 45.8476
28.327112315, 96.390, 2148.0, 46.3465
28.379633446, 96.390, 2189.0, 46.7868
28.432154576, 96.390, 2127.0, 46.1194
28.484675707, 96.390, 2104.0, 45.8694
28.537196838, 96.390, 2137.0, 46.2277
28.589717968, 96.390, 2131.0, 46.1628
28.642239099, 96.390, 1926.0, 43.8862
28.694760230, 96.390, 2006.0, 44.7884
28.747281361, 96.390, 2129.0, 46.1411
28.799802491, 96.390, 2133.0, 46.1844
28.852323622, 96.390, 2188.0, 46.7761
28.904844753, 96.390, 2108.0, 45.9130
28.957365883, 96.390, 2097.0, 45.7930
29.009887014, 96.390, 2096.0, 45.7821
29.062408145, 96.390, 2170.0, 46.5833
29.114929276, 96.390, 2290.0, 47.8539
29.167450406, 96.390, 2352.0, 48.4974
29.219971537, 96.390, 2330.0, 48.2701
29.272492668, 96.390, 2433.0, 49.3254
29.325013798, 96.390, 2522.0, 50.2195
29.377534929, 96.390, 2454.0, 49.5379
29.430056060, 96.390, 2317.0, 48.1352
29.482577191, 96.390, 2370.0, 48.6826
29.535098321, 96.390, 2315.0, 48.1144
29.587619452, 96.390, 2300.0, 47.9583
29.640140583, 96.390, 2236.0, 47.2864
29.692661713, 96.390, 2103.0, 45.8585
29.745182844, 96.390, 2001.0, 44.7325
29.797703975, 96.390, 2057.0, 45.3542
29.850225105, 96.390, 2039.0, 45.1553
29.902746236, 96.390, 1907.0, 43.6692
29.955267367, 96.390, 1969.0, 44.3734
30.007788498, 96.390, 1955.0, 44.2154
30.060309628, 96.390, 1988.0, 44.5870
30.112830759, 96.390, 1956.0, 44.2267
30.165351890, 96.390, 2029.0, 45.0444
30.217873020, 96.390, 2051.0, 45.2880
30.270394151, 96.390, 2004.0, 44.7661
30.322915282, 96.390, 2034.0, 45.0999
30.375436413, 96.390, 1986.0, 44.5646
30.427957543, 96.390, 2029.0, 45.0444
30.480478674, 96.390, 1979.0, 44.4860
30.532999805, 96.390, 2014.0, 44.8776
30.585520935, 96.390, 2166.0, 46.5403
30.638042066, 96.390, 2212.0, 47.0319
30.690563197, 96.390, 2287.0, 47.8226
30.743084328, 96.390, 2297.0, 47.9270
30.795605458, 96.390, 2264.0, 47.5815
30.848126589, 96.390, 2262.0, 47.5605
30.900647720, 96.390, 2190.0, 46.7974
30.953168850, 96.390, 2053.0, 45.3100
31.005689981, 96.390, 2018.0, 44.9222
31.058211112, 96.390, 1966.0, 44.3396
31.110732243, 96.390, 2042.0, 45.1885
31.163253373, 96.390, 2371.0, 48.6929
31.215774504, 96.390, 2596.0, 50.9510
31.268295635, 96.390, 2648.0, 51.4587
31.320816765, 96.390, 2618.0, 51.1664
31.373337896, 96.390, 2469.0, 49.6890
31.425859027, 96.390, 2405.0, 49.0408
31.478380157, 96.390, 2361.0, 48.5901
31.530901288, 96.390, 2472.0, 49.7192
31.583422419, 96.390, 2387.0, 48.8569
31.635943550, 96.390, 2438.0, 49.3761
31.688464680, 96.390, 2202.0, 46.9255
31.740985811, 96.390, 2124.0, 46.0869
31.793506942, 96.390, 2066.0, 45.4533
31.846028072, 96.390, 1957.0, 44.2380
31.898549203, 96.390, 2093.0, 45.7493
31.951070334, 96.390, 2323.0, 48.1975
32.003591465, 96.390, 2807.0, 52.9811
32.056112595, 96.390, 3699.0, 60.8194
32.108633726, 96.390, 4084.0, 63.9062
32.161154857, 96.390, 3196.0, 56.5332
32.213675987, 96.390, 2546.0, 50.4579
32.266197118, 96.390, 2224.0, 47.1593
32.318718249, 96.390, 2291.0, 47.8644
32.371239380, 96.390, 2133.0, 46.1844
32.423760510, 96.390, 1921.0, 43.8292
32.476281641, 96.390, 1784.0, 42.2374
32.528802772, 96.390, 1757.0, 41.9166
32.581323902, 96.390, 1824.0, 42.7083
32.633845033, 96.390, 1858.0, 43.1045
32.686366164, 96.390, 1897.0, 43.5546
32.738887295, 96.390, 1901.0, 43.6005
32.791408425, 96.390, 1875.0, 43.3013
32.843929556, 96.390, 1816.0, 42.6146
32.896450687, 96.390, 1833.0, 42.8135
32.948971817, 96.390, 1889.0, 43.4626
33.001492948, 96.390, 1922.0, 43.8406
33.054014079, 96.390, 1912.0, 43.7264
33.106535209, 96.390, 1889.0, 43.4626
33.159056340, 96.390, 1969.0, 44.3734
33.211577471, 96.390, 2027.0, 45.0222
33.264098602, 96.390, 2047.0, 45.2438
33.316619732, 96.390, 2010.0, 44.8330
33.369140863, 96.390, 2065.0, 45.4423
33.421661994, 96.390, 2072.0, 45.5192
33.474183124, 96.390, 2129.0, 46.1411
33.526704255, 96.390, 2095.0, 45.7712
33.579225386, 96.390, 2010.0, 44.8330
33.631746517, 96.390, 1957.0, 44.2380
33.684267647, 96.390, 2030.0, 45.0555
33.736788778, 96.390, 2123.0, 46.0760
33.789309909, 96.390, 2069.0, 45.4863
33.841831039, 96.390, 2178.0, 46.6690
33.894352170, 96.390, 2282.0, 47.7703
33.946873301, 96.390, 2619.0, 51.1762
33.999394432, 96.390, 2844.0, 53.3292
34.051915562, 96.390, 2566.0, 50.6557
34.104436693, 96.390, 2549.0, 50.4876
34.156957824, 96.390, 2364.0, 48.6210
34.209478954, 96.390, 2313.0, 48.0937
34.262000085, 96.390, 2393.0, 48.9183
34.314521216, 96.390, 2372.0, 48.7032
34.367042346, 96.390, 2412.0, 49.1121
34.419563477, 96.390, 2440.0, 49.3964
34.472084608, 96.390, 2691.0, 51.8748
34.524605739, 96.390, 2784.0, 52.7636
34.577126869, 96.390, 2891.0, 53.7680
34.629648000, 96.390, 2822.0, 53.1225
34.682169131, 96.390, 2574.0, 50.7346
34.734690261, 96.390, 2458.0, 49.5782
34.787211392, 96.390, 2463.0, 49.6286
34.839732523, 96.390, 2538.0, 50.3786
34.892253654, 96.390, 2688.0, 51.8459
34.944774784, 96.390, 2929.0, 54.1202
34.997295915, 96.390, 2845.0, 53.3385
35.049817046, 96.390, 2622.0, 51.2055
35.102338176, 96.390, 2366.0, 48.6415
35.154859307, 96.390, 2273.0, 47.6760
35.207380438, 96.390, 2269.0, 47.6340
35.259901569, 96.390, 2275.0, 47.6970
35.312422699, 96.390, 2195.0, 46.8508
35.364943830, 96.390, 2170.0, 46.5833
35.417464961, 96.390, 2002.0, 44.7437
35.469986091, 96.390, 1983.0, 44.5309
35.522507222, 96.390, 1911.0, 43.7150
35.575028353, 96.390, 1925.0, 43.8748
35.627549484, 96.390, 2024.0, 44.9889
35.680070614, 96.390, 2010.0, 44.8330
35.732591745, 96.390, 2050.0, 45.2769
35.785112876, 96.390, 2021.0, 44.9555
35.837634006, 96.390, 1855.0, 43.0697
35.890155137, 96.390, 2035.0, 45.1110
35.942676268, 96.390, 2196.0, 46.8615
35.995197398, 96.390, 2022.0, 44.9667
36.047718529, 96.390, 2150.0, 46.3681
36.100239660, 96.390, 2063.0, 45.4203
36.152760791, 96.390, 1974.0, 44.4297
36.205281921, 96.390, 2221.0, 47.1275
36.257803052, 96.390, 2204.0, 46.9468
36.310324183, 96.390, 1969.0, 44.3734
36.362845313, 96.390, 1831.0, 42.7902
36.415366444, 96.390, 1824.0, 42.7083
36.467887575, 96.390, 1729.0, 41.5812
36.520408706, 96.390, 1593.0, 39.9124
36.572929836, 96.390, 1694.0, 41.1582
36.625450967, 96.390, 1622.0, 40.2741
36.677972098, 96.390, 1532.0, 39.1408
36.730493228, 96.390, 1572.0, 39.6485
36.783014359, 96.390, 1601.0, 40.0125
36.835535490, 96.390, 1589.0, 39.8623
36.888056621, 96.390, 1504.0, 38.7814
36.940577751, 96.390, 1482.0, 38.4968
36.993098882, 96.390, 1489.0, 38.5876
37.045620013, 96.390, 1496.0, 38.6782
37.098141143, 96.390, 1577.0, 39.7115
37.150662274, 96.390, 1519.0, 38.9744
37.203183405, 96.390, 1632.0, 40.3980
37.255704535, 96.390, 1639.0, 40.4846
37.308225666, 96.390, 1576.0, 39.6989
37.360746797, 96.390, 1598.0, 39.9750
37.413267928, 96.390, 1613.0, 40.1622
37.465789058, 96.390, 1583.0, 39.7869
37.518310189, 96.390, 1695.0, 41.1704
37.570831320, 96.390, 1636.0, 40.4475
37.623352450, 96.390, 1689.0, 41.0974
37.675873581, 96.390, 1616.0, 40.1995
37.728394712, 96.390, 1838.0, 42.8719
37.780915843, 96.390, 1852.0, 43.0349
37.833436973, 96.390, 1875.0, 43.3013
37.885958104, 96.390, 1759.0, 41.9404
37.938479235, 96.390, 1710.0, 41.3521
37.991000365, 96.390, 1705.0, 41.2916
38.043521496, 96.390, 1635.0, 40.4351
38.096042627, 96.390, 1560.0, 39.4968
38.148563758, 96.390, 1689.0, 41.0974
38.201084888, 96.390, 1715.0, 41.4126
38.253606019, 96.390, 1604.0, 40.0500
38.306127150, 96.390, 1587.0, 39.8372
38.358648280, 96.390, 1524.0, 39.0384
38.411169411, 96.390, 1476.0, 38.4187
38.463690542, 96.390, 1475.0, 38.4057
38.516211673, 96.390, 1503.0, 38.7685
38.568732803, 96.390, 1520.0, 38.9872
38.621253934, 96.390, 1521.0, 39.0000
38.673775065, 96.390, 1626.0, 40.3237
38.726296195, 96.390, 1536.0, 39.1918
38.778817326, 96.390, 1602.0, 40.0250
38.831338457, 96.390, 1553.0, 39.4081
38.883859587, 96.390, 1465.0, 38.2753
38.936380718, 96.390, 1467.0, 38.3014
38.988901849, 96.390, 1338.0, 36.5787
39.041422980, 96.390, 1377.0, 37.1080
39.093944110, 96.390, 1380.0, 37.1484
39.146465241, 96.390, 1458.0, 38.1838
39.198986372, 96.390, 1461.0, 38.2230
39.251507502, 96.390, 1559.0, 39.4842
39.304028633, 96.390, 1440.0, 37.9473
39.356549764, 96.390, 1539.0, 39.2301
39.409070895, 96.390, 1651.0, 40.6325
39.461592025, 96.390, 1738.0, 41.6893
39.514113156, 96.390, 1531.0, 39.1280
39.566634287, 96.390, 1581.0, 39.7618
39.619155417, 96.390, 1463.0, 38.2492
39.671676548, 96.390, 1364.0, 36.9324
39.724197679, 96.390, 1320.0, 36.3318
39.776718810, 96.390, 1388.0, 37.2559
39.829239940, 96.390, 1449.0, 38.0657
39.881761071, 96.390, 1369.0, 37.0000
39.934282202, 96.390, 1386.0, 37.2290
39.986803332, 96.390, 1370.0, 37.0135
40.039324463, 96.390, 1356.0, 36.8239
40.091845594, 96.390, 1382.0, 37.1753
40.144366725, 96.390, 1420.0, 37.6829
40.196887855, 96.390, 1362.0, 36.9053
40.249408986, 96.390, 1318.0, 36.3043
40.301930117, 96.390, 1349.0, 36.7287
40.354451247, 96.390, 1224.0, 34.9857
40.406972378, 96.390, 1260.0, 35.4965
40.459493509, 96.390, 1219.0, 34.9142
40.512014639, 96.390, 1346.0, 36.6879
40.564535770, 96.390, 1310.0, 36.1939
40.617056901, 96.390, 1355.0, 36.8103
40.669578032, 96.390, 1409.0, 37.5366
40.722099162, 96.390, 1407.0, 37.5100
40.774620293, 96.390, 1274.0, 35.6931
40.827141424, 96.390, 1208.0, 34.7563
40.879662554, 96.390, 1317.0, 36.2905
40.932183685, 96.390, 1193.0, 34.5398
40.984704816, 96.390, 1246.0, 35.2987
41.037225947, 96.390, 1241.0, 35.2278
41.089747077, 96.390, 1257.0, 35.4542
41.142268208, 96.390, 1208.0, 34.7563
41.194789339, 96.390, 1251.0, 35.3695
41.247310469, 96.390, 1221.0, 34.9428
41.299831600, 96.390, 1277.0, 35.7351
41.352352731, 96.390, 1422.0, 37.7094
41.404873862, 96.390, 1538.0, 39.2173
41.457394992, 96.390, 1484.0, 38.5227
41.509916123, 96.390, 1436.0, 37.8946
41.562437254, 96.390, 1227.0, 35.0286
41.614958384, 96.390, 1281.0, 35.7911
41.667479515, 96.390, 1224.0, 34.9857
41.720000646, 96.390, 1256.0, 35.4401
41.772521776, 96.390, 1215.0, 34.8569
41.825042907, 96.390, 1240.0, 35.2136
41.877564038, 96.390, 1161.0, 34.0735
41.930085169, 96.390, 1253.0, 35.3977
41.982606299, 96.390, 1169.0, 34.1906
42.035127430, 96.390, 1180.0, 34.3511
42.087648561, 96.390, 1345.0, 36.6742
42.140169691, 96.390, 1458.0, 38.1838
42.192690822, 96.390, 1553.0, 39.4081
42.245211953, 96.390, 1516.0, 38.9358
42.297733084, 96.390, 1376.0, 37.0945
42.350254214, 96.390, 1292.0, 35.9444
42.402775345, 96.390, 1169.0, 34.1906
42.455296476, 96.390, 1193.0, 34.5398
42.507817606, 96.390, 1199.0, 34.6266
42.560338737, 96.390, 1271.0, 35.6511
42.612859868, 96.390, 1305.0, 36.1248
42.665380999, 96.390, 1239.0, 35.1994
42.717902129, 96.390, 1228.0, 35.0428
42.770423260, 96.390, 1173.0, 34.2491
42.822944391, 96.390, 1153.0, 33.9559
42.875465521, 96.390, 1164.0, 34.1174
42.927986652, 96.390, 1156.0, 34.0000
42.980507783, 96.390, 1063.0, 32.6037
43.033028914, 96.390, 1167.0, 34.1614
43.085550044, 96.390, 1149.0, 33.8969
43.138071175, 96.390, 1136.0, 33.7046
43.190592306, 96.390, 1121.0, 33.4813
43.243113436, 96.390, 1128.0, 33.5857
43.295634567, 96.390, 1149.0, 33.8969
43.348155698, 96.390, 1126.0, 33.5559
43.400676828, 96.390, 1134.0, 33.6749
43.453197959, 96.390, 1175.0, 34.2783
43.505719090, 96.390, 1181.0, 34.3657
43.558240221, 96.390, 1098.0, 33.1361
43.610761351, 96.390, 1147.0, 33.8674
43.663282482, 96.390, 1222.0, 34.9571
43.715803613, 96.390, 1314.0, 36.2491
43.768324743, 96.390, 1369.0, 37.0000
43.820845874, 96.390, 1356.0, 36.8239
43.873367005, 96.390, 1366.0, 36.9594
43.925888136, 96.390, 1313.0, 36.2353
43.978409266, 96.390, 1250.0, 35.3553
44.030930397, 96.390, 1170.0, 34.2053
44.083451528, 96.390, 1199.0, 34.6266
44.135972658, 96.390, 1177.0, 34.3074
44.188493789, 96.390, 1156.0, 34.0000
44.241014920, 96.390, 1197.0, 34.5977
44.293536051, 96.390, 1224.0, 34.9857
44.346057181, 96.390, 1292.0, 35.9444
44.398578312, 96.390, 1360.0, 36.8782
44.451099443, 96.390, 1248.0, 35.3270
44.503620573, 96.390, 1292.0, 35.9444
44.556141704, 96.390, 1272.0, 35.6651
44.608662835, 96.390, 1181.0, 34.3657
44.661183966, 96.390, 1156.0, 34.0000
44.713705096, 96.390, 1103.0, 33.2114
44.766226227, 96.390, 1222.0, 34.9571
44.818747358, 96.390, 1217.0, 34.8855
44.871268488, 96.390, 1147.0, 33.8674
44.923789619, 96.390, 1188.0, 34.4674
44.976310750, 96.390, 1203.0, 34.6843
45.028831880, 96.390, 1172.0, 34.2345
45.081353011, 96.390, 1332.0, 36.4966
45.133874142, 96.390, 1369.0, 37.0000
45.186395273, 96.390, 1342.0, 36.6333
45.238916403, 96.390, 1352.0, 36.7696
45.291437534, 96.390, 1267.0, 35.5949
45.343958665, 96.390, 1387.0, 37.2424
45.396479795, 96.390, 1315.0, 36.2629
45.449000926, 96.390, 1310.0, 36.1939
45.501522057, 96.390, 1416.0, 37.6298
45.554043188, 96.390, 1277.0, 35.7351
45.606564318, 96.390, 1276.0, 35.7211
45.659085449, 96.390, 1187.0, 34.4529
45.711606580, 96.390, 1164.0, 34.1174
45.764127710, 96.390, 1165.0, 34.1321
45.816648841, 96.390, 1175.0, 34.2783
45.869169972, 96.390, 1150.0, 33.9116
45.921691103, 96.390, 1128.0, 33.5857
45.974212233, 96.390, 1202.0, 34.6699
46.026733364, 96.390, 1123.0, 33.5112
46.079254495, 96.390, 1235.0, 35.1426
46.131775625, 96.390, 1278.0, 35.7491
46.184296756, 96.390, 1372.0, 37.0405
46.236817887, 96.390, 1414.0, 37.6032
46.289339017, 96.390, 1426.0, 37.7624
46.341860148, 96.390, 1361.0, 36.8917
46.394381279, 96.390, 1322.0, 36.3593
46.446902410, 96.390, 1276.0, 35.7211
46.499423540, 96.390, 1220.0, 34.9285
46.551944671, 96.390, 1204.0, 34.6987
46.604465802, 96.390, 1198.0, 34.6121
46.656986932, 96.390, 1271.0, 35.6511
46.709508063, 96.390, 1254.0, 35.4119
46.762029194, 96.390, 1240.0, 35.2136
46.814550325, 96.390, 1244.0, 35.2704
46.867071455, 96.390, 1193.0, 34.5398
46.919592586, 96.390, 1225.0, 35.0000
46.972113717, 96.390, 1187.0, 34.4529
47.024634847, 96.390, 1257.0, 35.4542
47.077155978, 96.390, 1153.0, 33.9559
47.129677109, 96.390, 1204.0, 34.6987
47.182198240, 96.390, 1202.0, 34.6699
47.234719370, 96.390, 1070.0, 32.7109
47.287240501, 96.390, 1134.0, 33.6749
47.339761632, 96.390, 1236.0, 35.1568
47.392282762, 96.390, 1197.0, 34.5977
47.444803893, 96.390, 1191.0, 34.5109
47.497325024, 96.390, 1171.0, 34.2199
47.549846155, 96.390, 1169.0, 34.1906
47.602367285, 96.390, 1201.0, 34.6554
47.654888416, 96.390, 1162.0, 34.0881
47.707409547, 96.390, 1130.0, 33.6155
47.759930677, 96.390, 1180.0, 34.3511
47.812451808, 96.390, 1142.0, 33.7935
47.864972939, 96.390, 1130.0, 33.6155
47.917494069, 96.390, 1101.0, 33.1813
47.970015200, 96.390, 1143.0, 33.8083
48.022536331, 96.390, 1132.0, 33.6452
48.075057462, 96.390, 1143.0, 33.8083
48.127578592, 96.390, 1229.0, 35.0571
48.180099723, 96.390, 1186.0, 34.4384
48.232620854, 96.390, 1165.0, 34.1321
48.285141984, 96.390, 1162.0, 34.0881
48.337663115, 96.390, 1139.0, 33.7491
48.390184246, 96.390, 1152.0, 33.9411
48.442705377, 96.390, 1269.0, 35.6230
48.495226507, 96.390, 1288.0, 35.8887
48.547747638, 96.390, 1302.0, 36.0832
48.600268769, 96.390, 1263.0, 35.5387
48.652789899, 96.390, 1169.0, 34.1906
48.705311030, 96.390, 1085.0, 32.9393
48.757832161, 96.390, 1096.0, 33.1059
48.810353292, 96.390, 1187.0, 34.4529
48.862874422, 96.390, 1125.0, 33.5410
48.915395553, 96.390, 1112.0, 33.3467
48.967916684, 96.390, 1135.0, 33.6898
49.020437814, 96.390, 1003.0, 31.6702
49.072958945, 96.390, 1125.0, 33.5410
49.125480076, 96.390, 1131.0, 33.6303
49.178001207, 96.390, 1056.0, 32.4962
49.230522337, 96.390, 1094.0, 33.0757
49.283043468, 96.390, 1106.0, 33.2566
49.335564599, 96.390, 1090.0, 33.0151
49.388085729, 96.390, 1082.0, 32.8938
49.440606860, 96.390, 1058.0, 32.5269
49.493127991, 96.390, 992.0, 31.4960
49.545649121, 96.390, 1069.0, 32.6956
49.598170252, 96.390, 1092.0, 33.0454
49.650691383, 96.390, 1008.0, 31.7490
49.703212514, 96.390, 1034.0, 32.1559
49.755733644, 96.390, 1008.0, 31.7490
49.808254775, 96.390, 1016.0, 31.8748
49.860775906, 96.390, 1035.0, 32.1714
49.913297036, 96.390, 1038.0, 32.2180
49.965818167, 96.390, 989.0, 31.4484
50.018339298, 96.390, 987.0, 31.4166
50.070860429, 96.390, 1017.0, 31.8904
50.123381559, 96.390, 975.0, 31.2250
50.175902690, 96.390, 1043.0, 32.2955
50.228423821, 96.390, 1165.0, 34.1321
50.280944951, 96.390, 1168.0, 34.1760
50.333466082, 96.390, 1082.0, 32.8938
50.385987213, 96.390, 1061.0, 32.5730
50.438508344, 96.390, 1050.0, 32.4037
50.491029474, 96.390, 1099.0, 33.1512
50.543550605, 96.390, 1115.0, 33.3916
50.596071736, 96.390, 1003.0, 31.6702
50.648592866, 96.390, 926.0, 30.4302
50.701113997, 96.390, 1053.0, 32.4500
50.753635128, 96.390, 990.0, 31.4643
50.806156258, 96.390, 953.0, 30.8707
50.858677389, 96.390, 1010.0, 31.7805
50.911198520, 96.390, 1005.0, 31.7017
50.963719651, 96.390, 1009.0, 31.7648
51.016240781, 96.390, 1103.0, 33.2114
51.068761912, 96.390, 1134.0, 33.6749
51.121283043, 96.390, 1183.0, 34.3948
51.173804173, 96.390, 1034.0, 32.1559
51.226325304, 96.390, 1050.0, 32.4037
51.278846435, 96.390, 1023.0, 31.9844
51.331367566, 96.390, 1002.0, 31.6544
51.383888696, 96.390, 941.0, 30.6757
51.436409827, 96.390, 930.0, 30.4959
51.488930958, 96.390, 929.0, 30.4795
51.541452088, 96.390, 943.0, 30.7083
51.593973219, 96.390, 928.0, 30.4631
51.646494350, 96.390, 896.0, 29.9333
51.699015481, 96.390, 890.0, 29.8329
51.751536611, 96.390, 978.0, 31.2730
51.804057742, 96.390, 890.0, 29.8329
51.856578873, 96.390, 970.0, 31.1448
51.909100003, 96.390, 993.0, 31.5119
51.961621134, 96.390, 1020.0, 31.9374
52.014142265, 96.390, 947.0, 30.7734
52.066663396, 96.390, 972.0, 31.1769
52.119184526, 96.390, 938.0, 30.6268
52.171705657, 96.390, 959.0, 30.9677
52.224226788, 96.390, 1035.0, 32.1714
52.276747918, 96.390, 1019.0, 31.9218
52.329269049, 96.390, 1002.0, 31.6544
52.381790180, 96.390, 1034.0, 32.1559
52.434311310, 96.390, 941.0, 30.6757
52.486832441, 96.390, 935.0, 30.5778
52.539353572, 96.390, 955.0, 30.9031
52.591874703, 96.390, 920.0, 30.3315
52.644395833, 96.390, 894.0, 29.8998
52.696916964, 96.390, 871.0, 29.5127
52.749438095, 96.390, 935.0, 30.5778
52.801959225, 96.390, 910.0, 30.1662
52.854480356, 96.390, 931.0, 30.5123
52.907001487, 96.390, 911.0, 30.1828
52.959522618, 96.390, 953.0, 30.8707
53.012043748, 96.390, 881.0, 29.6816
53.064564879, 96.390, 907.0, 30.1164
53.117086010, 96.390, 940.0, 30.6594
53.169607140, 96.390, 889.0, 29.8161
53.222128271, 96.390, 1006.0, 31.7175
53.274649402, 96.390, 895.0, 29.9166
53.327170533, 96.390, 877.0, 29.6142
53.379691663, 96.390, 931.0, 30.5123
53.432212794, 96.390, 919.0, 30.3150
53.484733925, 96.390, 854.0, 29.2233
53.537255055, 96.390, 903.0, 30.0500
53.589776186, 96.390, 890.0, 29.8329
53.642297317, 96.390, 855.0, 29.2404
53.694818448, 96.390, 912.0, 30.1993
53.747339578, 96.390, 817.0, 28.5832
53.799860709, 96.390, 815.0, 28.5482
53.852381840, 96.390, 916.0, 30.2655
53.904902970, 96.390, 858.0, 29.2916
53.957424101, 96.390, 940.0, 30.6594
54.009945232, 96.390, 939.0, 30.6431
54.062466362, 96.390, 965.0, 31.0644
54.114987493, 96.390, 1006.0, 31.7175
54.167508624, 96.390, 1001.0, 31.6386
54.220029755, 96.390, 973.0, 31.1929
54.272550885, 96.390, 980.0, 31.3050
54.325072016, 96.390, 885.0, 29.7489
54.377593147, 96.390, 968.0, 31.1127
54.430114277, 96.390, 887.0, 29.7825
54.482635408, 96.390, 959.0, 30.9677
54.535156539, 96.390, 856.0, 29.2575
54.587677670, 96.390, 915.0, 30.2490
54.640198800, 96.390, 844.0, 29.0517
54.692719931, 96.390, 852.0, 29.1890
54.745241062, 96.390, 831.0, 28.8271
54.797762192, 96.390, 870.0, 29.4958
54.850283323, 96.390, 836.0, 28.9137
54.902804454, 96.390, 791.0, 28.1247
54.955325585, 96.390, 800.0, 28.2843
55.007846715, 96.390, 827.0, 28.7576
55.060367846, 96.390, 829.0, 28.7924
55.112888977, 96.390, 815.0, 28.5482
55.165410107, 96.390, 797.0, 28.2312
55.217931238, 96.390, 838.0, 28.9482
55.270452369, 96.390, 800.0, 28.2843
55.322973499, 96.390, 835.0, 28.8964
55.375494630, 96.390, 823.0, 28.6880
55.428015761, 96.390, 868.0, 29.4618
55.480536892, 96.390, 855.0, 29.2404
55.533058022, 96.390, 818.0, 28.6007
55.585579153, 96.390, 850.0, 29.1548
55.638100284, 96.390, 843.0, 29.0345
55.690621414, 96.390, 771.0, 27.7669
55.743142545, 96.390, 815.0, 28.5482
55.795663676, 96.390, 770.0, 27.7489
55.848184807, 96.390, 810.0, 28.4605
55.900705937, 96.390, 731.0, 27.0370
55.953227068, 96.390, 783.0, 27.9821
56.005748199, 96.390, 813.0, 28.5132
56.058269329, 96.390, 866.0, 29.4279
56.110790460, 96.390, 865.0, 29.4109
56.163311591, 96.390, 822.0, 28.6705
56.215832722, 96.390, 881.0, 29.6816
56.268353852, 96.390, 764.0, 27.6405
56.320874983, 96.390, 857.0, 29.2746
56.373396114, 96.390, 791.0, 28.1247
56.425917244, 96.390, 828.0, 28.7750
56.478438375, 96.390, 846.0, 29.0861
56.530959506, 96.390, 807.0, 28.4077
56.583480637, 96.390, 762.0, 27.6043
56.636001767, 96.390, 796.0, 28.2135
56.688522898, 96.390, 786.0, 28.0357
56.741044029, 96.390, 816.0, 28.5657
56.793565159, 96.390, 786.0, 28.0357
56.846086290, 96.390, 779.0, 27.9106
56.898607421, 96.390, 793.0, 28.1603
56.951128551, 96.390, 722.0, 26.8701
57.003649682, 96.390, 765.0, 27.6586
57.056170813, 96.390, 816.0, 28.5657
57.108691944, 96.390, 758.0, 27.5318
57.161213074, 96.390, 838.0, 28.9482
57.213734205, 96.390, 815.0, 28.5482
57.266255336, 96.390, 823.0, 28.6880
57.318776466, 96.390, 821.0, 28.6531
57.371297597, 96.390, 820.0, 28.6356
57.423818728, 96.390, 789.0, 28.0891
57.476339859, 96.390, 758.0, 27.5318
57.528860989, 96.390, 772.0, 27.7849
57.581382120, 96.390, 738.0, 27.1662
57.633903251, 96.390, 781.0, 27.9464
57.686424381, 96.390, 811.0, 28.4781
57.738945512, 96.390, 803.0, 28.3373
57.791466643, 96.390, 858.0, 29.2916
57.843987774, 96.390, 763.0, 27.6225
57.896508904, 96.390, 784.0, 28.0000
57.949030035, 96.390, 761.0, 27.5862
58.001551166, 96.390, 821.0, 28.6531
58.054072296, 96.390, 936.0, 30.5941
58.106593427, 96.390, 942.0, 30.6920
58.159114558, 96.390, 843.0, 29.0345
58.211635689, 96.390, 810.0, 28.4605
58.264156819, 96.390, 840.0, 28.9828
58.316677950, 96.390, 821.0, 28.6531
58.369199081, 96.390, 738.0, 27.1662
58.421720211, 96.390, 790.0, 28.1069
58.474241342, 96.390, 810.0, 28.4605
58.526762473, 96.390, 815.0, 28.5482
58.579283603, 96.390, 749.0, 27.3679
58.631804734, 96.390, 762.0, 27.6043
58.684325865, 96.390, 790.0, 28.1069
58.736846996, 96.390, 799.0, 28.2666
58.789368126, 96.390, 776.0, 27.8568
58.841889257, 96.390, 779.0, 27.9106
58.894410388, 96.390, 720.0, 26.8328
58.946931518, 96.390, 753.0, 27.4408
58.999452649, 96.390, 743.0, 27.2580
59.051973780, 96.390, 757.0, 27.5136
59.104494911, 96.390, 787.0, 28.0535
59.157016041, 96.390, 730.0, 27.0185
59.209537172, 96.390, 788.0, 28.0713
59.262058303, 96.390, 788.0, 28.0713
59.314579433, 96.390, 773.0, 27.8029
59.367100564, 96.390, 794.0, 28.1780
59.419621695, 96.390, 741.0, 27.2213
59.472142826, 96.390, 808.0, 28.4253
59.524663956, 96.390, 782.0, 27.9643
59.577185087, 96.390, 766.0, 27.6767
59.629706218, 96.390, 774.0, 27.8209
59.682227348, 96.390, 822.0, 28.6705
59.734748479, 96.390, 798.0, 28.2489
59.787269610, 96.390, 821.0, 28.6531
59.839790740, 96.390, 845.0, 29.0689
59.892311871, 96.390, 836.0, 28.9137
59.944833002, 96.390, 887.0, 29.7825
59.997354133, 96.390, 869.0, 29.4788
60.049875263, 96.390, 815.0, 28.5482
60.102396394, 96.390, 824.0, 28.7054
60.154917525, 96.390, 874.0, 29.5635
60.207438655, 96.390, 876.0, 29.5973
60.259959786, 96.390, 916.0, 30.2655
60.312480917, 96.390, 914.0, 30.2324
60.365002048, 96.390, 911.0, 30.1828
60.417523178, 96.390, 887.0, 29.7825
60.470044309, 96.390, 918.0, 30.2985
60.522565440, 96.390, 964.0, 31.0483
60.575086570, 96.390, 997.0, 31.5753
60.627607701, 96.390, 1011.0, 31.7962
60.680128832, 96.390, 1046.0, 32.3419
60.732649963, 96.390, 1120.0, 33.4664
60.785171093, 96.390, 1120.0, 33.4664
60.837692224, 96.390, 1232.0, 35.0999
60.890213355, 96.390, 1185.0, 34.4238
60.942734485, 96.390, 1189.0, 34.4819
60.995255616, 96.390, 1286.0, 35.8608
61.047776747, 96.390, 1300.0, 36.0555
61.100297878, 96.390, 1276.0, 35.7211
61.152819008, 96.390, 1221.0, 34.9428
61.205340139, 96.390, 1250.0, 35.3553
61.257861270, 96.390, 1218.0, 34.8999
61.310382400, 96.390, 1228.0, 35.0428
61.362903531, 96.390, 1209.0, 34.7707
61.415424662, 96.390, 1212.0, 34.8138
61.467945792, 96.390, 1226.0, 35.0143
61.520466923, 96.390, 1196.0, 34.5832
61.572988054, 96.390, 1121.0, 33.4813
61.625509185, 96.390, 1080.0, 32.8634
61.678030315, 96.390, 1117.0, 33.4215
61.730551446, 96.390, 1026.0, 32.0312
61.783072577, 96.390, 990.0, 31.4643
61.835593707, 96.390, 1041.0, 32.2645
61.888114838, 96.390, 971.0, 31.1609
61.940635969, 96.390, 1037.0, 32.2025
61.993157100, 96.390, 1042.0, 32.2800
62.045678230, 96.390, 1039.0, 32.2335
62.098199361, 96.390, 990.0, 31.4643
62.150720492, 96.390, 958.0, 30.9516
62.203241622, 96.390, 948.0, 30.7896
62.255762753, 96.390, 960.0, 30.9839
62.308283884, 96.390, 909.0, 30.1496
62.360805015, 96.390, 940.0, 30.6594
62.413326145, 96.390, 985.0, 31.3847
62.465847276, 96.390, 908.0, 30.1330
62.518368407, 96.390, 888.0, 29.7993
62.570889537, 96.390, 870.0, 29.4958
62.623410668, 96.390, 875.0, 29.5804
62.675931799, 96.390, 928.0, 30.4631
62.728452930, 96.390, 920.0, 30.3315
62.780974060, 96.390, 841.0, 29.0000
62.833495191, 96.390, 807.0, 28.4077
62.886016322, 96.390, 899.0, 29.9833
62.938537452, 96.390, 814.0, 28.5307
62.991058583, 96.390, 692.0, 26.3059
63.043579714, 96.390, 769.0, 27.7308
63.096100844, 96.390, 756.0, 27.4955
63.148621975, 96.390, 712.0, 26.6833
63.201143106, 96.390, 725.0, 26.9258
63.253664237, 96.390, 776.0, 27.8568
63.306185367, 96.390, 760.0, 27.5681
63.358706498, 96.390, 727.0, 26.9629
63.411227629, 96.390, 721.0, 26.8514
63.463748759, 96.390, 696.0, 26.3818
63.516269890, 96.390, 705.0, 26.5518
63.568791021, 96.390, 735.0, 27.1109
63.621312152, 96.390, 753.0, 27.4408
63.673833282, 96.390, 752.0, 27.4226
63.726354413, 96.390, 725.0, 26.9258
63.778875544, 96.390, 697.0, 26.4008
63.831396674, 96.390, 735.0, 27.1109
63.883917805, 96.390, 743.0, 27.2580
63.936438936, 96.390, 769.0, 27.7308
63.988960067, 96.390, 758.0, 27.5318
64.041481197, 96.390, 707.0, 26.5895
64.094002328, 96.390, 679.0, 26.0576
64.146523459, 96.390, 713.0, 26.7021
64.199044589, 96.390, 733.0, 27.0740
64.251565720, 96.390, 781.0, 27.9464
64.304086851, 96.390, 739.0, 27.1846
64.356607981, 96.390, 713.0, 26.7021
64.409129112, 96.390, 781.0, 27.9464
64.461650243, 96.390, 716.0, 26.7582
64.514171374, 96.390, 712.0, 26.6833
64.566692504, 96.390, 714.0, 26.7208
64.619213635, 96.390, 704.0, 26.5330
64.671734766, 96.390, 670.0, 25.8844
64.724255896, 96.390, 658.0, 25.6515
64.776777027, 96.390, 700.0, 26.4575
64.829298158, 96.390, 674.0, 25.9615
64.881819289, 96.390, 698.0, 26.4197
64.934340419, 96.390, 660.0, 25.6905
64.986861550, 96.390, 720.0, 26.8328