File: Files_organized_for_plots/Constant_NaOH_1mL10M_to_1gPC/XRD_PAxial04Jan22_Act07Jan22_B1_0833M_NaOH_LS0143_1.csv
[Measurement conditions]
Sample identification,XRD_PAxial04Jan22_Act07Jan22_B1_0833M_NaOH_LS0143_1
Comment - 1,"Configuration=Stage for Flat Samples/Holders, Owner=User-1, Creation date=7/1/2020 9:53:24 AM"
Comment - 2,"Goniometer=Theta/Theta; Minimum step size 2Theta:0.0001; Minimum step size Omega:0.0001"
Comment - 3,"Sample stage=Stage for flat samples/holders"
Comment - 4,"Diffractometer system=EMPYREAN"
Comment - 5,"Measurement program=C:\Users\ibo5034\OneDrive - The Pennsylvania State University\NEUP - Reed, Titus's files\XRD\Cement\Zerobackground scan.xrdmp, Identifier={98A3B11C-88F9-4AA6-982C-73314A311EF5}"
Anode material,Cu
K-Alpha1 wavelength,1.5405980
K-Alpha2 wavelength,1.5444260
Ratio K-Alpha2/K-Alpha1,0.500
Divergence slit,Fixed,0.25
Monochromator used,NO
Generator voltage, 45
Tube current, 40
File date and time,10/Jan/2022 13:18
Unit cell,
h k l, 0 0 0
Scan axis,Gonio
Scan range,4.994599997,64.999991833
Scan step size,0.0262606
No. of points, 2285
Scan type,CONTINUOUS
Time per step,96.390
[Scan points]
Angle, TimePerStep, Intensity, ESD
5.007730280, 96.390, 5323.0, 72.9589
5.060251411, 96.390, 5235.0, 72.3533
5.112772541, 96.390, 5089.0, 71.3372
5.165293672, 96.390, 5052.0, 71.0774
5.217814803, 96.390, 5082.0, 71.2881
5.270335934, 96.390, 4974.0, 70.5266
5.322857064, 96.390, 4886.0, 69.8999
5.375378195, 96.390, 4751.0, 68.9275
5.427899326, 96.390, 4719.0, 68.6950
5.480420456, 96.390, 4844.0, 69.5989
5.532941587, 96.390, 4920.0, 70.1427
5.585462718, 96.390, 4716.0, 68.6731
5.637983849, 96.390, 4619.0, 67.9632
5.690504979, 96.390, 4656.0, 68.2349
5.743026110, 96.390, 4585.0, 67.7126
5.795547241, 96.390, 4594.0, 67.7791
5.848068371, 96.390, 4582.0, 67.6905
5.900589502, 96.390, 4494.0, 67.0373
5.953110633, 96.390, 4495.0, 67.0448
6.005631763, 96.390, 4422.0, 66.4981
6.058152894, 96.390, 4472.0, 66.8730
6.110674025, 96.390, 4440.0, 66.6333
6.163195156, 96.390, 4429.0, 66.5507
6.215716286, 96.390, 4362.0, 66.0454
6.268237417, 96.390, 4331.0, 65.8103
6.320758548, 96.390, 4360.0, 66.0303
6.373279678, 96.390, 4245.0, 65.1537
6.425800809, 96.390, 4398.0, 66.3174
6.478321940, 96.390, 4258.0, 65.2534
6.530843071, 96.390, 4315.0, 65.6887
6.583364201, 96.390, 4267.0, 65.3223
6.635885332, 96.390, 4271.0, 65.3529
6.688406463, 96.390, 4206.0, 64.8537
6.740927593, 96.390, 4200.0, 64.8074
6.793448724, 96.390, 4273.0, 65.3682
6.845969855, 96.390, 4215.0, 64.9230
6.898490986, 96.390, 4114.0, 64.1405
6.951012116, 96.390, 4143.0, 64.3661
7.003533247, 96.390, 4228.0, 65.0231
7.056054378, 96.390, 4069.0, 63.7887
7.108575508, 96.390, 4139.0, 64.3351
7.161096639, 96.390, 4006.0, 63.2930
7.213617770, 96.390, 4057.0, 63.6946
7.266138900, 96.390, 4111.0, 64.1171
7.318660031, 96.390, 4067.0, 63.7730
7.371181162, 96.390, 4129.0, 64.2573
7.423702293, 96.390, 4051.0, 63.6475
7.476223423, 96.390, 4035.0, 63.5216
7.528744554, 96.390, 4079.0, 63.8670
7.581265685, 96.390, 4091.0, 63.9609
7.633786815, 96.390, 4097.0, 64.0078
7.686307946, 96.390, 4030.0, 63.4823
7.738829077, 96.390, 4011.0, 63.3325
7.791350208, 96.390, 3953.0, 62.8729
7.843871338, 96.390, 3913.0, 62.5540
7.896392469, 96.390, 3932.0, 62.7057
7.948913600, 96.390, 4053.0, 63.6632
8.001434730, 96.390, 3847.0, 62.0242
8.053955861, 96.390, 3877.0, 62.2656
8.106476992, 96.390, 3800.0, 61.6441
8.158998123, 96.390, 3858.0, 62.1128
8.211519253, 96.390, 3839.0, 61.9597
8.264040384, 96.390, 3835.0, 61.9274
8.316561515, 96.390, 3761.0, 61.3270
8.369082645, 96.390, 3791.0, 61.5711
8.421603776, 96.390, 3754.0, 61.2699
8.474124907, 96.390, 3784.0, 61.5142
8.526646038, 96.390, 3672.0, 60.5970
8.579167168, 96.390, 3682.0, 60.6795
8.631688299, 96.390, 3732.0, 61.0901
8.684209430, 96.390, 3646.0, 60.3821
8.736730560, 96.390, 3742.0, 61.1719
8.789251691, 96.390, 3732.0, 61.0901
8.841772822, 96.390, 3649.0, 60.4070
8.894293952, 96.390, 3608.0, 60.0666
8.946815083, 96.390, 3637.0, 60.3075
8.999336214, 96.390, 3741.0, 61.1637
9.051857345, 96.390, 3709.0, 60.9016
9.104378475, 96.390, 3610.0, 60.0833
9.156899606, 96.390, 3609.0, 60.0750
9.209420737, 96.390, 3560.0, 59.6657
9.261941867, 96.390, 3597.0, 59.9750
9.314462998, 96.390, 3652.0, 60.4318
9.366984129, 96.390, 3548.0, 59.5651
9.419505260, 96.390, 3470.0, 58.9067
9.472026390, 96.390, 3544.0, 59.5315
9.524547521, 96.390, 3450.0, 58.7367
9.577068652, 96.390, 3509.0, 59.2368
9.629589782, 96.390, 3545.0, 59.5399
9.682110913, 96.390, 3473.0, 58.9322
9.734632044, 96.390, 3519.0, 59.3212
9.787153175, 96.390, 3447.0, 58.7112
9.839674305, 96.390, 3378.0, 58.1206
9.892195436, 96.390, 3363.0, 57.9914
9.944716567, 96.390, 3420.0, 58.4808
9.997237697, 96.390, 3425.0, 58.5235
10.049758828, 96.390, 3286.0, 57.3236
10.102279959, 96.390, 3429.0, 58.5577
10.154801090, 96.390, 3377.0, 58.1120
10.207322220, 96.390, 3280.0, 57.2713
10.259843351, 96.390, 3197.0, 56.5420
10.312364482, 96.390, 3349.0, 57.8705
10.364885612, 96.390, 3319.0, 57.6108
10.417406743, 96.390, 3294.0, 57.3934
10.469927874, 96.390, 3278.0, 57.2538
10.522449004, 96.390, 3407.0, 58.3695
10.574970135, 96.390, 3269.0, 57.1752
10.627491266, 96.390, 3278.0, 57.2538
10.680012397, 96.390, 3275.0, 57.2276
10.732533527, 96.390, 3229.0, 56.8243
10.785054658, 96.390, 3135.0, 55.9911
10.837575789, 96.390, 3090.0, 55.5878
10.890096919, 96.390, 3275.0, 57.2276
10.942618050, 96.390, 3174.0, 56.3383
10.995139181, 96.390, 3224.0, 56.7803
11.047660312, 96.390, 3289.0, 57.3498
11.100181442, 96.390, 3285.0, 57.3149
11.152702573, 96.390, 3435.0, 58.6089
11.205223704, 96.390, 4072.0, 63.8122
11.257744834, 96.390, 4748.0, 68.9057
11.310265965, 96.390, 3600.0, 60.0000
11.362787096, 96.390, 3084.0, 55.5338
11.415308227, 96.390, 3084.0, 55.5338
11.467829357, 96.390, 3064.0, 55.3534
11.520350488, 96.390, 3085.0, 55.5428
11.572871619, 96.390, 2992.0, 54.6992
11.625392749, 96.390, 2947.0, 54.2863
11.677913880, 96.390, 2832.0, 53.2165
11.730435011, 96.390, 2974.0, 54.5344
11.782956141, 96.390, 2915.0, 53.9907
11.835477272, 96.390, 2808.0, 52.9906
11.887998403, 96.390, 2840.0, 53.2917
11.940519534, 96.390, 2894.0, 53.7959
11.993040664, 96.390, 2786.0, 52.7826
12.045561795, 96.390, 2868.0, 53.5537
12.098082926, 96.390, 2863.0, 53.5070
12.150604056, 96.390, 2793.0, 52.8488
12.203125187, 96.390, 2704.0, 52.0000
12.255646318, 96.390, 2725.0, 52.2015
12.308167449, 96.390, 2806.0, 52.9717
12.360688579, 96.390, 2820.0, 53.1037
12.413209710, 96.390, 2840.0, 53.2917
12.465730841, 96.390, 2746.0, 52.4023
12.518251971, 96.390, 2751.0, 52.4500
12.570773102, 96.390, 2811.0, 53.0189
12.623294233, 96.390, 2764.0, 52.5738
12.675815364, 96.390, 2846.0, 53.3479
12.728336494, 96.390, 2956.0, 54.3691
12.780857625, 96.390, 3354.0, 57.9137
12.833378756, 96.390, 4419.0, 66.4756
12.885899886, 96.390, 4463.0, 66.8057
12.938421017, 96.390, 2806.0, 52.9717
12.990942148, 96.390, 2697.0, 51.9326
13.043463279, 96.390, 2614.0, 51.1273
13.095984409, 96.390, 2594.0, 50.9313
13.148505540, 96.390, 2678.0, 51.7494
13.201026671, 96.390, 2544.0, 50.4381
13.253547801, 96.390, 2689.0, 51.8556
13.306068932, 96.390, 2695.0, 51.9134
13.358590063, 96.390, 2783.0, 52.7541
13.411111193, 96.390, 2801.0, 52.9245
13.463632324, 96.390, 3256.0, 57.0614
13.516153455, 96.390, 4470.0, 66.8581
13.568674586, 96.390, 6258.0, 79.1075
13.621195716, 96.390, 4515.0, 67.1937
13.673716847, 96.390, 2652.0, 51.4976
13.726237978, 96.390, 2547.0, 50.4678
13.778759108, 96.390, 2654.0, 51.5170
13.831280239, 96.390, 2762.0, 52.5547
13.883801370, 96.390, 3065.0, 55.3624
13.936322501, 96.390, 3350.0, 57.8792
13.988843631, 96.390, 2823.0, 53.1319
14.041364762, 96.390, 2472.0, 49.7192
14.093885893, 96.390, 2430.0, 49.2950
14.146407023, 96.390, 2486.0, 49.8598
14.198928154, 96.390, 2394.0, 48.9285
14.251449285, 96.390, 2511.0, 50.1099
14.303970416, 96.390, 2633.0, 51.3128
14.356491546, 96.390, 2865.0, 53.5257
14.409012677, 96.390, 3311.0, 57.5413
14.461533808, 96.390, 3520.0, 59.3296
14.514054938, 96.390, 2698.0, 51.9423
14.566576069, 96.390, 2438.0, 49.3761
14.619097200, 96.390, 2469.0, 49.6890
14.671618331, 96.390, 2354.0, 48.5180
14.724139461, 96.390, 2320.0, 48.1664
14.776660592, 96.390, 2265.0, 47.5920
14.829181723, 96.390, 2368.0, 48.6621
14.881702853, 96.390, 2312.0, 48.0833
14.934223984, 96.390, 2284.0, 47.7912
14.986745115, 96.390, 2289.0, 47.8435
15.039266245, 96.390, 2358.0, 48.5592
15.091787376, 96.390, 2219.0, 47.1063
15.144308507, 96.390, 2220.0, 47.1169
15.196829638, 96.390, 2178.0, 46.6690
15.249350768, 96.390, 2363.0, 48.6107
15.301871899, 96.390, 2244.0, 47.3709
15.354393030, 96.390, 2300.0, 47.9583
15.406914160, 96.390, 2323.0, 48.1975
15.459435291, 96.390, 2278.0, 47.7284
15.511956422, 96.390, 2336.0, 48.3322
15.564477553, 96.390, 2389.0, 48.8774
15.616998683, 96.390, 2316.0, 48.1248
15.669519814, 96.390, 2403.0, 49.0204
15.722040945, 96.390, 2289.0, 47.8435
15.774562075, 96.390, 2313.0, 48.0937
15.827083206, 96.390, 2221.0, 47.1275
15.879604337, 96.390, 2357.0, 48.5489
15.932125468, 96.390, 2290.0, 47.8539
15.984646598, 96.390, 2313.0, 48.0937
16.037167729, 96.390, 2482.0, 49.8197
16.089688860, 96.390, 2688.0, 51.8459
16.142209990, 96.390, 3275.0, 57.2276
16.194731121, 96.390, 4632.0, 68.0588
16.247252252, 96.390, 3898.0, 62.4340
16.299773382, 96.390, 2489.0, 49.8899
16.352294513, 96.390, 2320.0, 48.1664
16.404815644, 96.390, 2300.0, 47.9583
16.457336775, 96.390, 2254.0, 47.4763
16.509857905, 96.390, 2294.0, 47.8957
16.562379036, 96.390, 2247.0, 47.4025
16.614900167, 96.390, 2219.0, 47.1063
16.667421297, 96.390, 2299.0, 47.9479
16.719942428, 96.390, 2228.0, 47.2017
16.772463559, 96.390, 2294.0, 47.8957
16.824984690, 96.390, 2247.0, 47.4025
16.877505820, 96.390, 2151.0, 46.3789
16.930026951, 96.390, 2260.0, 47.5395
16.982548082, 96.390, 2219.0, 47.1063
17.035069212, 96.390, 2250.0, 47.4342
17.087590343, 96.390, 2250.0, 47.4342
17.140111474, 96.390, 2293.0, 47.8853
17.192632605, 96.390, 2257.0, 47.5079
17.245153735, 96.390, 2184.0, 46.7333
17.297674866, 96.390, 2169.0, 46.5725
17.350195997, 96.390, 2277.0, 47.7179
17.402717127, 96.390, 2255.0, 47.4868
17.455238258, 96.390, 2212.0, 47.0319
17.507759389, 96.390, 2354.0, 48.5180
17.560280520, 96.390, 2285.0, 47.8017
17.612801650, 96.390, 2327.0, 48.2390
17.665322781, 96.390, 2270.0, 47.6445
17.717843912, 96.390, 2248.0, 47.4131
17.770365042, 96.390, 2379.0, 48.7750
17.822886173, 96.390, 2288.0, 47.8330
17.875407304, 96.390, 2158.0, 46.4543
17.927928434, 96.390, 2222.0, 47.1381
17.980449565, 96.390, 2264.0, 47.5815
18.032970696, 96.390, 2267.0, 47.6130
18.085491827, 96.390, 2285.0, 47.8017
18.138012957, 96.390, 2245.0, 47.3814
18.190534088, 96.390, 2343.0, 48.4045
18.243055219, 96.390, 2330.0, 48.2701
18.295576349, 96.390, 2336.0, 48.3322
18.348097480, 96.390, 2307.0, 48.0312
18.400618611, 96.390, 2298.0, 47.9375
18.453139742, 96.390, 2298.0, 47.9375
18.505660872, 96.390, 2314.0, 48.1041
18.558182003, 96.390, 2290.0, 47.8539
18.610703134, 96.390, 2409.0, 49.0816
18.663224264, 96.390, 2289.0, 47.8435
18.715745395, 96.390, 2284.0, 47.7912
18.768266526, 96.390, 2317.0, 48.1352
18.820787657, 96.390, 2397.0, 48.9592
18.873308787, 96.390, 2499.0, 49.9900
18.925829918, 96.390, 2552.0, 50.5173
18.978351049, 96.390, 2472.0, 49.7192
19.030872179, 96.390, 2453.0, 49.5278
19.083393310, 96.390, 2443.0, 49.4267
19.135914441, 96.390, 2309.0, 48.0521
19.188435572, 96.390, 2443.0, 49.4267
19.240956702, 96.390, 2399.0, 48.9796
19.293477833, 96.390, 2350.0, 48.4768
19.345998964, 96.390, 2317.0, 48.1352
19.398520094, 96.390, 2417.0, 49.1630
19.451041225, 96.390, 2508.0, 50.0799
19.503562356, 96.390, 2441.0, 49.4065
19.556083486, 96.390, 2418.0, 49.1732
19.608604617, 96.390, 2472.0, 49.7192
19.661125748, 96.390, 2504.0, 50.0400
19.713646879, 96.390, 2420.0, 49.1935
19.766168009, 96.390, 2478.0, 49.7795
19.818689140, 96.390, 2549.0, 50.4876
19.871210271, 96.390, 2664.0, 51.6140
19.923731401, 96.390, 2899.0, 53.8424
19.976252532, 96.390, 3412.0, 58.4123
20.028773663, 96.390, 4036.0, 63.5295
20.081294794, 96.390, 5171.0, 71.9097
20.133815924, 96.390, 5697.0, 75.4785
20.186337055, 96.390, 6191.0, 78.6829
20.238858186, 96.390, 7539.0, 86.8274
20.291379316, 96.390, 5244.0, 72.4155
20.343900447, 96.390, 3349.0, 57.8705
20.396421578, 96.390, 2944.0, 54.2586
20.448942709, 96.390, 2753.0, 52.4690
20.501463839, 96.390, 2573.0, 50.7247
20.553984970, 96.390, 2488.0, 49.8799
20.606506101, 96.390, 2487.0, 49.8698
20.659027231, 96.390, 2471.0, 49.7092
20.711548362, 96.390, 2468.0, 49.6790
20.764069493, 96.390, 2539.0, 50.3885
20.816590623, 96.390, 2436.0, 49.3559
20.869111754, 96.390, 2518.0, 50.1797
20.921632885, 96.390, 2451.0, 49.5076
20.974154016, 96.390, 2453.0, 49.5278
21.026675146, 96.390, 2475.0, 49.7494
21.079196277, 96.390, 2484.0, 49.8397
21.131717408, 96.390, 2477.0, 49.7695
21.184238538, 96.390, 2601.0, 51.0000
21.236759669, 96.390, 2526.0, 50.2593
21.289280800, 96.390, 2587.0, 50.8626
21.341801931, 96.390, 2585.0, 50.8429
21.394323061, 96.390, 2662.0, 51.5946
21.446844192, 96.390, 2724.0, 52.1920
21.499365323, 96.390, 2619.0, 51.1762
21.551886453, 96.390, 2403.0, 49.0204
21.604407584, 96.390, 2545.0, 50.4480
21.656928715, 96.390, 2461.0, 49.6085
21.709449846, 96.390, 2494.0, 49.9400
21.761970976, 96.390, 2461.0, 49.6085
21.814492107, 96.390, 2553.0, 50.5272
21.867013238, 96.390, 2431.0, 49.3052
21.919534368, 96.390, 2481.0, 49.8096
21.972055499, 96.390, 2432.0, 49.3153
22.024576630, 96.390, 2388.0, 48.8672
22.077097761, 96.390, 2512.0, 50.1199
22.129618891, 96.390, 2560.0, 50.5964
22.182140022, 96.390, 2392.0, 48.9081
22.234661153, 96.390, 2433.0, 49.3254
22.287182283, 96.390, 2515.0, 50.1498
22.339703414, 96.390, 2539.0, 50.3885
22.392224545, 96.390, 2513.0, 50.1298
22.444745675, 96.390, 2410.0, 49.0918
22.497266806, 96.390, 2574.0, 50.7346
22.549787937, 96.390, 2431.0, 49.3052
22.602309068, 96.390, 2454.0, 49.5379
22.654830198, 96.390, 2531.0, 50.3090
22.707351329, 96.390, 2463.0, 49.6286
22.759872460, 96.390, 2494.0, 49.9400
22.812393590, 96.390, 2473.0, 49.7293
22.864914721, 96.390, 2492.0, 49.9199
22.917435852, 96.390, 2472.0, 49.7192
22.969956983, 96.390, 2445.0, 49.4469
23.022478113, 96.390, 2498.0, 49.9800
23.074999244, 96.390, 2551.0, 50.5074
23.127520375, 96.390, 2400.0, 48.9898
23.180041505, 96.390, 2567.0, 50.6656
23.232562636, 96.390, 2469.0, 49.6890
23.285083767, 96.390, 2381.0, 48.7955
23.337604898, 96.390, 2476.0, 49.7594
23.390126028, 96.390, 2342.0, 48.3942
23.442647159, 96.390, 2369.0, 48.6724
23.495168290, 96.390, 2505.0, 50.0500
23.547689420, 96.390, 2348.0, 48.4562
23.600210551, 96.390, 2450.0, 49.4975
23.652731682, 96.390, 2379.0, 48.7750
23.705252813, 96.390, 2450.0, 49.4975
23.757773943, 96.390, 2422.0, 49.2138
23.810295074, 96.390, 2529.0, 50.2892
23.862816205, 96.390, 2551.0, 50.5074
23.915337335, 96.390, 3021.0, 54.9636
23.967858466, 96.390, 3695.0, 60.7865
24.020379597, 96.390, 3561.0, 59.6741
24.072900727, 96.390, 4062.0, 63.7338
24.125421858, 96.390, 4849.0, 69.6348
24.177942989, 96.390, 3743.0, 61.1801
24.230464120, 96.390, 2697.0, 51.9326
24.282985250, 96.390, 2399.0, 48.9796
24.335506381, 96.390, 2393.0, 48.9183
24.388027512, 96.390, 2268.0, 47.6235
24.440548642, 96.390, 2253.0, 47.4658
24.493069773, 96.390, 2201.0, 46.9148
24.545590904, 96.390, 2257.0, 47.5079
24.598112035, 96.390, 2227.0, 47.1911
24.650633165, 96.390, 2160.0, 46.4758
24.703154296, 96.390, 2232.0, 47.2440
24.755675427, 96.390, 2318.0, 48.1456
24.808196557, 96.390, 2254.0, 47.4763
24.860717688, 96.390, 2140.0, 46.2601
24.913238819, 96.390, 2215.0, 47.0638
24.965759950, 96.390, 2195.0, 46.8508
25.018281080, 96.390, 2212.0, 47.0319
25.070802211, 96.390, 2139.0, 46.2493
25.123323342, 96.390, 2179.0, 46.6798
25.175844472, 96.390, 2200.0, 46.9042
25.228365603, 96.390, 2196.0, 46.8615
25.280886734, 96.390, 2220.0, 47.1169
25.333407864, 96.390, 2205.0, 46.9574
25.385928995, 96.390, 2242.0, 47.3498
25.438450126, 96.390, 2276.0, 47.7074
25.490971257, 96.390, 2575.0, 50.7445
25.543492387, 96.390, 3180.0, 56.3915
25.596013518, 96.390, 3126.0, 55.9106
25.648534649, 96.390, 2799.0, 52.9056
25.701055779, 96.390, 2363.0, 48.6107
25.753576910, 96.390, 2357.0, 48.5489
25.806098041, 96.390, 2760.0, 52.5357
25.858619172, 96.390, 3319.0, 57.6108
25.911140302, 96.390, 2834.0, 53.2353
25.963661433, 96.390, 2435.0, 49.3457
26.016182564, 96.390, 2118.0, 46.0217
26.068703694, 96.390, 2175.0, 46.6369
26.121224825, 96.390, 2127.0, 46.1194
26.173745956, 96.390, 2025.0, 45.0000
26.226267087, 96.390, 2243.0, 47.3603
26.278788217, 96.390, 2245.0, 47.3814
26.331309348, 96.390, 2519.0, 50.1896
26.383830479, 96.390, 2555.0, 50.5470
26.436351609, 96.390, 2717.0, 52.1249
26.488872740, 96.390, 2576.0, 50.7543
26.541393871, 96.390, 2293.0, 47.8853
26.593915002, 96.390, 2202.0, 46.9255
26.646436132, 96.390, 2162.0, 46.4973
26.698957263, 96.390, 2098.0, 45.8039
26.751478394, 96.390, 2026.0, 45.0111
26.803999524, 96.390, 2029.0, 45.0444
26.856520655, 96.390, 2040.0, 45.1664
26.909041786, 96.390, 2131.0, 46.1628
26.961562916, 96.390, 2062.0, 45.4093
27.014084047, 96.390, 2013.0, 44.8665
27.066605178, 96.390, 2060.0, 45.3872
27.119126309, 96.390, 2116.0, 46.0000
27.171647439, 96.390, 2174.0, 46.6262
27.224168570, 96.390, 2183.0, 46.7226
27.276689701, 96.390, 2493.0, 49.9300
27.329210831, 96.390, 2578.0, 50.7740
27.381731962, 96.390, 2354.0, 48.5180
27.434253093, 96.390, 2185.0, 46.7440
27.486774224, 96.390, 2158.0, 46.4543
27.539295354, 96.390, 2204.0, 46.9468
27.591816485, 96.390, 2014.0, 44.8776
27.644337616, 96.390, 2148.0, 46.3465
27.696858746, 96.390, 2133.0, 46.1844
27.749379877, 96.390, 2082.0, 45.6289
27.801901008, 96.390, 2159.0, 46.4650
27.854422139, 96.390, 2097.0, 45.7930
27.906943269, 96.390, 2070.0, 45.4973
27.959464400, 96.390, 2110.0, 45.9347
28.011985531, 96.390, 2197.0, 46.8722
28.064506661, 96.390, 2266.0, 47.6025
28.117027792, 96.390, 2161.0, 46.4866
28.169548923, 96.390, 2210.0, 47.0106
28.222070054, 96.390, 2044.0, 45.2106
28.274591184, 96.390, 2005.0, 44.7772
28.327112315, 96.390, 2034.0, 45.0999
28.379633446, 96.390, 2106.0, 45.8912
28.432154576, 96.390, 1957.0, 44.2380
28.484675707, 96.390, 2089.0, 45.7056
28.537196838, 96.390, 1995.0, 44.6654
28.589717968, 96.390, 2072.0, 45.5192
28.642239099, 96.390, 2078.0, 45.5851
28.694760230, 96.390, 2326.0, 48.2286
28.747281361, 96.390, 2514.0, 50.1398
28.799802491, 96.390, 2378.0, 48.7647
28.852323622, 96.390, 2278.0, 47.7284
28.904844753, 96.390, 2228.0, 47.2017
28.957365883, 96.390, 2232.0, 47.2440
29.009887014, 96.390, 2434.0, 49.3356
29.062408145, 96.390, 3085.0, 55.5428
29.114929276, 96.390, 3165.0, 56.2583
29.167450406, 96.390, 2640.0, 51.3809
29.219971537, 96.390, 2316.0, 48.1248
29.272492668, 96.390, 2101.0, 45.8367
29.325013798, 96.390, 2171.0, 46.5940
29.377534929, 96.390, 2136.0, 46.2169
29.430056060, 96.390, 2201.0, 46.9148
29.482577191, 96.390, 2415.0, 49.1426
29.535098321, 96.390, 2727.0, 52.2207
29.587619452, 96.390, 2770.0, 52.6308
29.640140583, 96.390, 2574.0, 50.7346
29.692661713, 96.390, 2429.0, 49.2849
29.745182844, 96.390, 2567.0, 50.6656
29.797703975, 96.390, 2485.0, 49.8498
29.850225105, 96.390, 2346.0, 48.4355
29.902746236, 96.390, 2238.0, 47.3075
29.955267367, 96.390, 2378.0, 48.7647
30.007788498, 96.390, 2679.0, 51.7591
30.060309628, 96.390, 3005.0, 54.8179
30.112830759, 96.390, 2601.0, 51.0000
30.165351890, 96.390, 2197.0, 46.8722
30.217873020, 96.390, 2139.0, 46.2493
30.270394151, 96.390, 2103.0, 45.8585
30.322915282, 96.390, 2091.0, 45.7275
30.375436413, 96.390, 2106.0, 45.8912
30.427957543, 96.390, 2183.0, 46.7226
30.480478674, 96.390, 2120.0, 46.0435
30.532999805, 96.390, 2271.0, 47.6550
30.585520935, 96.390, 2373.0, 48.7134
30.638042066, 96.390, 2490.0, 49.8999
30.690563197, 96.390, 2245.0, 47.3814
30.743084328, 96.390, 2327.0, 48.2390
30.795605458, 96.390, 2125.0, 46.0977
30.848126589, 96.390, 2127.0, 46.1194
30.900647720, 96.390, 2116.0, 46.0000
30.953168850, 96.390, 2145.0, 46.3141
31.005689981, 96.390, 2148.0, 46.3465
31.058211112, 96.390, 2088.0, 45.6946
31.110732243, 96.390, 2174.0, 46.6262
31.163253373, 96.390, 2339.0, 48.3632
31.215774504, 96.390, 2267.0, 47.6130
31.268295635, 96.390, 2230.0, 47.2229
31.320816765, 96.390, 2171.0, 46.5940
31.373337896, 96.390, 2066.0, 45.4533
31.425859027, 96.390, 2095.0, 45.7712
31.478380157, 96.390, 2202.0, 46.9255
31.530901288, 96.390, 2325.0, 48.2183
31.583422419, 96.390, 2701.0, 51.9711
31.635943550, 96.390, 3488.0, 59.0593
31.688464680, 96.390, 3298.0, 57.4282
31.740985811, 96.390, 2983.0, 54.6168
31.793506942, 96.390, 2542.0, 50.4183
31.846028072, 96.390, 2406.0, 49.0510
31.898549203, 96.390, 2647.0, 51.4490
31.951070334, 96.390, 3519.0, 59.3212
32.003591465, 96.390, 4232.0, 65.0538
32.056112595, 96.390, 3381.0, 58.1464
32.108633726, 96.390, 2799.0, 52.9056
32.161154857, 96.390, 2500.0, 50.0000
32.213675987, 96.390, 2768.0, 52.6118
32.266197118, 96.390, 3570.0, 59.7495
32.318718249, 96.390, 3018.0, 54.9363
32.371239380, 96.390, 2679.0, 51.7591
32.423760510, 96.390, 2226.0, 47.1805
32.476281641, 96.390, 2241.0, 47.3392
32.528802772, 96.390, 2250.0, 47.4342
32.581323902, 96.390, 2449.0, 49.4874
32.633845033, 96.390, 2828.0, 53.1789
32.686366164, 96.390, 3459.0, 58.8133
32.738887295, 96.390, 3744.0, 61.1882
32.791408425, 96.390, 3364.0, 58.0000
32.843929556, 96.390, 3144.0, 56.0714
32.896450687, 96.390, 3000.0, 54.7723
32.948971817, 96.390, 3145.0, 56.0803
33.001492948, 96.390, 2899.0, 53.8424
33.054014079, 96.390, 2979.0, 54.5802
33.106535209, 96.390, 3750.0, 61.2372
33.159056340, 96.390, 4564.0, 67.5574
33.211577471, 96.390, 4349.0, 65.9469
33.264098602, 96.390, 3852.0, 62.0645
33.316619732, 96.390, 3147.0, 56.0981
33.369140863, 96.390, 2794.0, 52.8583
33.421661994, 96.390, 2522.0, 50.2195
33.474183124, 96.390, 2302.0, 47.9792
33.526704255, 96.390, 2195.0, 46.8508
33.579225386, 96.390, 2083.0, 45.6399
33.631746517, 96.390, 2267.0, 47.6130
33.684267647, 96.390, 2103.0, 45.8585
33.736788778, 96.390, 2113.0, 45.9674
33.789309909, 96.390, 2192.0, 46.8188
33.841831039, 96.390, 2192.0, 46.8188
33.894352170, 96.390, 2200.0, 46.9042
33.946873301, 96.390, 2340.0, 48.3735
33.999394432, 96.390, 2715.0, 52.1057
34.051915562, 96.390, 3031.0, 55.0545
34.104436693, 96.390, 4148.0, 64.4050
34.156957824, 96.390, 4457.0, 66.7608
34.209478954, 96.390, 3609.0, 60.0750
34.262000085, 96.390, 2909.0, 53.9351
34.314521216, 96.390, 2363.0, 48.6107
34.367042346, 96.390, 2367.0, 48.6518
34.419563477, 96.390, 2208.0, 46.9894
34.472084608, 96.390, 2176.0, 46.6476
34.524605739, 96.390, 2052.0, 45.2990
34.577126869, 96.390, 2111.0, 45.9456
34.629648000, 96.390, 2114.0, 45.9783
34.682169131, 96.390, 2067.0, 45.4643
34.734690261, 96.390, 1998.0, 44.6990
34.787211392, 96.390, 2019.0, 44.9333
34.839732523, 96.390, 2016.0, 44.8999
34.892253654, 96.390, 1995.0, 44.6654
34.944774784, 96.390, 1929.0, 43.9204
34.997295915, 96.390, 2030.0, 45.0555
35.049817046, 96.390, 1947.0, 44.1248
35.102338176, 96.390, 1997.0, 44.6878
35.154859307, 96.390, 1968.0, 44.3621
35.207380438, 96.390, 1972.0, 44.4072
35.259901569, 96.390, 2163.0, 46.5081
35.312422699, 96.390, 2564.0, 50.6360
35.364943830, 96.390, 3485.0, 59.0339
35.417464961, 96.390, 3333.0, 57.7321
35.469986091, 96.390, 2793.0, 52.8488
35.522507222, 96.390, 2327.0, 48.2390
35.575028353, 96.390, 1975.0, 44.4410
35.627549484, 96.390, 1902.0, 43.6119
35.680070614, 96.390, 1955.0, 44.2154
35.732591745, 96.390, 1912.0, 43.7264
35.785112876, 96.390, 1844.0, 42.9418
35.837634006, 96.390, 1847.0, 42.9767
35.890155137, 96.390, 1825.0, 42.7200
35.942676268, 96.390, 1761.0, 41.9643
35.995197398, 96.390, 1801.0, 42.4382
36.047718529, 96.390, 1775.0, 42.1307
36.100239660, 96.390, 1800.0, 42.4264
36.152760791, 96.390, 1769.0, 42.0595
36.205281921, 96.390, 1718.0, 41.4488
36.257803052, 96.390, 1699.0, 41.2189
36.310324183, 96.390, 1777.0, 42.1545
36.362845313, 96.390, 1994.0, 44.6542
36.415366444, 96.390, 2143.0, 46.2925
36.467887575, 96.390, 2167.0, 46.5510
36.520408706, 96.390, 1950.0, 44.1588
36.572929836, 96.390, 1998.0, 44.6990
36.625450967, 96.390, 2172.0, 46.6047
36.677972098, 96.390, 2295.0, 47.9062
36.730493228, 96.390, 2303.0, 47.9896
36.783014359, 96.390, 2115.0, 45.9891
36.835535490, 96.390, 2012.0, 44.8553
36.888056621, 96.390, 1799.0, 42.4146
36.940577751, 96.390, 1741.0, 41.7253
36.993098882, 96.390, 1648.0, 40.5956
37.045620013, 96.390, 1775.0, 42.1307
37.098141143, 96.390, 1591.0, 39.8873
37.150662274, 96.390, 1700.0, 41.2311
37.203183405, 96.390, 1769.0, 42.0595
37.255704535, 96.390, 1814.0, 42.5911
37.308225666, 96.390, 1713.0, 41.3884
37.360746797, 96.390, 1752.0, 41.8569
37.413267928, 96.390, 1738.0, 41.6893
37.465789058, 96.390, 1655.0, 40.6817
37.518310189, 96.390, 1588.0, 39.8497
37.570831320, 96.390, 1628.0, 40.3485
37.623352450, 96.390, 1623.0, 40.2865
37.675873581, 96.390, 1558.0, 39.4715
37.728394712, 96.390, 1592.0, 39.8999
37.780915843, 96.390, 1735.0, 41.6533
37.833436973, 96.390, 1750.0, 41.8330
37.885958104, 96.390, 1704.0, 41.2795
37.938479235, 96.390, 1661.0, 40.7554
37.991000365, 96.390, 1567.0, 39.5854
38.043521496, 96.390, 1503.0, 38.7685
38.096042627, 96.390, 1504.0, 38.7814
38.148563758, 96.390, 1455.0, 38.1445
38.201084888, 96.390, 1517.0, 38.9487
38.253606019, 96.390, 1522.0, 39.0128
38.306127150, 96.390, 1503.0, 38.7685
38.358648280, 96.390, 1642.0, 40.5216
38.411169411, 96.390, 1665.0, 40.8044
38.463690542, 96.390, 1901.0, 43.6005
38.516211673, 96.390, 1932.0, 43.9545
38.568732803, 96.390, 1996.0, 44.6766
38.621253934, 96.390, 2084.0, 45.6508
38.673775065, 96.390, 2254.0, 47.4763
38.726296195, 96.390, 2067.0, 45.4643
38.778817326, 96.390, 1864.0, 43.1741
38.831338457, 96.390, 1679.0, 40.9756
38.883859587, 96.390, 1552.0, 39.3954
38.936380718, 96.390, 1468.0, 38.3145
38.988901849, 96.390, 1486.0, 38.5487
39.041422980, 96.390, 1389.0, 37.2693
39.093944110, 96.390, 1476.0, 38.4187
39.146465241, 96.390, 1422.0, 37.7094
39.198986372, 96.390, 1463.0, 38.2492
39.251507502, 96.390, 1541.0, 39.2556
39.304028633, 96.390, 1580.0, 39.7492
39.356549764, 96.390, 1761.0, 41.9643
39.409070895, 96.390, 1806.0, 42.4971
39.461592025, 96.390, 1619.0, 40.2368
39.514113156, 96.390, 1620.0, 40.2492
39.566634287, 96.390, 1667.0, 40.8289
39.619155417, 96.390, 1947.0, 44.1248
39.671676548, 96.390, 1949.0, 44.1475
39.724197679, 96.390, 1727.0, 41.5572
39.776718810, 96.390, 1657.0, 40.7063
39.829239940, 96.390, 1614.0, 40.1746
39.881761071, 96.390, 1772.0, 42.0951
39.934282202, 96.390, 1690.0, 41.1096
39.986803332, 96.390, 1544.0, 39.2938
40.039324463, 96.390, 1554.0, 39.4208
40.091845594, 96.390, 1404.0, 37.4700
40.144366725, 96.390, 1463.0, 38.2492
40.196887855, 96.390, 1367.0, 36.9730
40.249408986, 96.390, 1424.0, 37.7359
40.301930117, 96.390, 1356.0, 36.8239
40.354451247, 96.390, 1242.0, 35.2420
40.406972378, 96.390, 1305.0, 36.1248
40.459493509, 96.390, 1250.0, 35.3553
40.512014639, 96.390, 1316.0, 36.2767
40.564535770, 96.390, 1262.0, 35.5246
40.617056901, 96.390, 1320.0, 36.3318
40.669578032, 96.390, 1260.0, 35.4965
40.722099162, 96.390, 1275.0, 35.7071
40.774620293, 96.390, 1269.0, 35.6230
40.827141424, 96.390, 1298.0, 36.0278
40.879662554, 96.390, 1349.0, 36.7287
40.932183685, 96.390, 1285.0, 35.8469
40.984704816, 96.390, 1306.0, 36.1386
41.037225947, 96.390, 1353.0, 36.7831
41.089747077, 96.390, 1398.0, 37.3898
41.142268208, 96.390, 1423.0, 37.7227
41.194789339, 96.390, 1324.0, 36.3868
41.247310469, 96.390, 1302.0, 36.0832
41.299831600, 96.390, 1274.0, 35.6931
41.352352731, 96.390, 1284.0, 35.8329
41.404873862, 96.390, 1270.0, 35.6371
41.457394992, 96.390, 1307.0, 36.1525
41.509916123, 96.390, 1223.0, 34.9714
41.562437254, 96.390, 1251.0, 35.3695
41.614958384, 96.390, 1184.0, 34.4093
41.667479515, 96.390, 1219.0, 34.9142
41.720000646, 96.390, 1327.0, 36.4280
41.772521776, 96.390, 1442.0, 37.9737
41.825042907, 96.390, 1380.0, 37.1484
41.877564038, 96.390, 1477.0, 38.4318
41.930085169, 96.390, 1324.0, 36.3868
41.982606299, 96.390, 1275.0, 35.7071
42.035127430, 96.390, 1278.0, 35.7491
42.087648561, 96.390, 1352.0, 36.7696
42.140169691, 96.390, 1456.0, 38.1576
42.192690822, 96.390, 1691.0, 41.1218
42.245211953, 96.390, 1484.0, 38.5227
42.297733084, 96.390, 1393.0, 37.3229
42.350254214, 96.390, 1341.0, 36.6197
42.402775345, 96.390, 1342.0, 36.6333
42.455296476, 96.390, 1242.0, 35.2420
42.507817606, 96.390, 1338.0, 36.5787
42.560338737, 96.390, 1355.0, 36.8103
42.612859868, 96.390, 1421.0, 37.6962
42.665380999, 96.390, 1430.0, 37.8153
42.717902129, 96.390, 1481.0, 38.4838
42.770423260, 96.390, 1612.0, 40.1497
42.822944391, 96.390, 1624.0, 40.2989
42.875465521, 96.390, 1419.0, 37.6696
42.927986652, 96.390, 1448.0, 38.0526
42.980507783, 96.390, 1337.0, 36.5650
43.033028914, 96.390, 1241.0, 35.2278
43.085550044, 96.390, 1212.0, 34.8138
43.138071175, 96.390, 1304.0, 36.1109
43.190592306, 96.390, 1341.0, 36.6197
43.243113436, 96.390, 1308.0, 36.1663
43.295634567, 96.390, 1339.0, 36.5923
43.348155698, 96.390, 1464.0, 38.2623
43.400676828, 96.390, 1340.0, 36.6060
43.453197959, 96.390, 1363.0, 36.9188
43.505719090, 96.390, 1352.0, 36.7696
43.558240221, 96.390, 1389.0, 37.2693
43.610761351, 96.390, 1382.0, 37.1753
43.663282482, 96.390, 1418.0, 37.6563
43.715803613, 96.390, 1391.0, 37.2961
43.768324743, 96.390, 1301.0, 36.0694
43.820845874, 96.390, 1329.0, 36.4555
43.873367005, 96.390, 1387.0, 37.2424
43.925888136, 96.390, 1366.0, 36.9594
43.978409266, 96.390, 1314.0, 36.2491
44.030930397, 96.390, 1347.0, 36.7015
44.083451528, 96.390, 1344.0, 36.6606
44.135972658, 96.390, 1321.0, 36.3456
44.188493789, 96.390, 1292.0, 35.9444
44.241014920, 96.390, 1161.0, 34.0735
44.293536051, 96.390, 1272.0, 35.6651
44.346057181, 96.390, 1251.0, 35.3695
44.398578312, 96.390, 1316.0, 36.2767
44.451099443, 96.390, 1237.0, 35.1710
44.503620573, 96.390, 1259.0, 35.4824
44.556141704, 96.390, 1204.0, 34.6987
44.608662835, 96.390, 1275.0, 35.7071
44.661183966, 96.390, 1257.0, 35.4542
44.713705096, 96.390, 1279.0, 35.7631
44.766226227, 96.390, 1235.0, 35.1426
44.818747358, 96.390, 1284.0, 35.8329
44.871268488, 96.390, 1291.0, 35.9305
44.923789619, 96.390, 1306.0, 36.1386
44.976310750, 96.390, 1376.0, 37.0945
45.028831880, 96.390, 1534.0, 39.1663
45.081353011, 96.390, 1583.0, 39.7869
45.133874142, 96.390, 1532.0, 39.1408
45.186395273, 96.390, 1523.0, 39.0256
45.238916403, 96.390, 1350.0, 36.7423
45.291437534, 96.390, 1279.0, 35.7631
45.343958665, 96.390, 1214.0, 34.8425
45.396479795, 96.390, 1154.0, 33.9706
45.449000926, 96.390, 1194.0, 34.5543
45.501522057, 96.390, 1179.0, 34.3366
45.554043188, 96.390, 1182.0, 34.3802
45.606564318, 96.390, 1169.0, 34.1906
45.659085449, 96.390, 1180.0, 34.3511
45.711606580, 96.390, 1215.0, 34.8569
45.764127710, 96.390, 1266.0, 35.5809
45.816648841, 96.390, 1216.0, 34.8712
45.869169972, 96.390, 1207.0, 34.7419
45.921691103, 96.390, 1209.0, 34.7707
45.974212233, 96.390, 1302.0, 36.0832
46.026733364, 96.390, 1253.0, 35.3977
46.079254495, 96.390, 1281.0, 35.7911
46.131775625, 96.390, 1248.0, 35.3270
46.184296756, 96.390, 1255.0, 35.4260
46.236817887, 96.390, 1274.0, 35.6931
46.289339017, 96.390, 1193.0, 34.5398
46.341860148, 96.390, 1214.0, 34.8425
46.394381279, 96.390, 1212.0, 34.8138
46.446902410, 96.390, 1172.0, 34.2345
46.499423540, 96.390, 1277.0, 35.7351
46.551944671, 96.390, 1150.0, 33.9116
46.604465802, 96.390, 1283.0, 35.8190
46.656986932, 96.390, 1395.0, 37.3497
46.709508063, 96.390, 1433.0, 37.8550
46.762029194, 96.390, 1320.0, 36.3318
46.814550325, 96.390, 1262.0, 35.5246
46.867071455, 96.390, 1266.0, 35.5809
46.919592586, 96.390, 1165.0, 34.1321
46.972113717, 96.390, 1154.0, 33.9706
47.024634847, 96.390, 1126.0, 33.5559
47.077155978, 96.390, 1198.0, 34.6121
47.129677109, 96.390, 1190.0, 34.4964
47.182198240, 96.390, 1242.0, 35.2420
47.234719370, 96.390, 1382.0, 37.1753
47.287240501, 96.390, 1456.0, 38.1576
47.339761632, 96.390, 1446.0, 38.0263
47.392282762, 96.390, 1434.0, 37.8682
47.444803893, 96.390, 1476.0, 38.4187
47.497325024, 96.390, 1494.0, 38.6523
47.549846155, 96.390, 1541.0, 39.2556
47.602367285, 96.390, 1573.0, 39.6611
47.654888416, 96.390, 1557.0, 39.4588
47.707409547, 96.390, 1405.0, 37.4833
47.759930677, 96.390, 1298.0, 36.0278
47.812451808, 96.390, 1222.0, 34.9571
47.864972939, 96.390, 1220.0, 34.9285
47.917494069, 96.390, 1127.0, 33.5708
47.970015200, 96.390, 1138.0, 33.7343
48.022536331, 96.390, 1082.0, 32.8938
48.075057462, 96.390, 1156.0, 34.0000
48.127578592, 96.390, 1151.0, 33.9264
48.180099723, 96.390, 1065.0, 32.6343
48.232620854, 96.390, 1046.0, 32.3419
48.285141984, 96.390, 1098.0, 33.1361
48.337663115, 96.390, 1021.0, 31.9531
48.390184246, 96.390, 1113.0, 33.3617
48.442705377, 96.390, 1097.0, 33.1210
48.495226507, 96.390, 1071.0, 32.7261
48.547747638, 96.390, 1095.0, 33.0908
48.600268769, 96.390, 1117.0, 33.4215
48.652789899, 96.390, 1118.0, 33.4365
48.705311030, 96.390, 1116.0, 33.4066
48.757832161, 96.390, 1158.0, 34.0294
48.810353292, 96.390, 1255.0, 35.4260
48.862874422, 96.390, 1183.0, 34.3948
48.915395553, 96.390, 1138.0, 33.7343
48.967916684, 96.390, 1171.0, 34.2199
49.020437814, 96.390, 1100.0, 33.1662
49.072958945, 96.390, 1096.0, 33.1059
49.125480076, 96.390, 1209.0, 34.7707
49.178001207, 96.390, 1249.0, 35.3412
49.230522337, 96.390, 1119.0, 33.4515
49.283043468, 96.390, 1137.0, 33.7194
49.335564599, 96.390, 1128.0, 33.5857
49.388085729, 96.390, 977.0, 31.2570
49.440606860, 96.390, 1053.0, 32.4500
49.493127991, 96.390, 964.0, 31.0483
49.545649121, 96.390, 1003.0, 31.6702
49.598170252, 96.390, 1031.0, 32.1092
49.650691383, 96.390, 1091.0, 33.0303
49.703212514, 96.390, 1076.0, 32.8024
49.755733644, 96.390, 1181.0, 34.3657
49.808254775, 96.390, 1106.0, 33.2566
49.860775906, 96.390, 1113.0, 33.3617
49.913297036, 96.390, 1075.0, 32.7872
49.965818167, 96.390, 1089.0, 33.0000
50.018339298, 96.390, 993.0, 31.5119
50.070860429, 96.390, 1034.0, 32.1559
50.123381559, 96.390, 934.0, 30.5614
50.175902690, 96.390, 1006.0, 31.7175
50.228423821, 96.390, 1010.0, 31.7805
50.280944951, 96.390, 984.0, 31.3688
50.333466082, 96.390, 1082.0, 32.8938
50.385987213, 96.390, 1029.0, 32.0780
50.438508344, 96.390, 1089.0, 33.0000
50.491029474, 96.390, 1029.0, 32.0780
50.543550605, 96.390, 1149.0, 33.8969
50.596071736, 96.390, 1212.0, 34.8138
50.648592866, 96.390, 1325.0, 36.4005
50.701113997, 96.390, 1276.0, 35.7211
50.753635128, 96.390, 1270.0, 35.6371
50.806156258, 96.390, 1171.0, 34.2199
50.858677389, 96.390, 1101.0, 33.1813
50.911198520, 96.390, 1082.0, 32.8938
50.963719651, 96.390, 1052.0, 32.4345
51.016240781, 96.390, 1054.0, 32.4654
51.068761912, 96.390, 1029.0, 32.0780
51.121283043, 96.390, 1035.0, 32.1714
51.173804173, 96.390, 1016.0, 31.8748
51.226325304, 96.390, 956.0, 30.9192
51.278846435, 96.390, 964.0, 31.0483
51.331367566, 96.390, 920.0, 30.3315
51.383888696, 96.390, 974.0, 31.2090
51.436409827, 96.390, 965.0, 31.0644
51.488930958, 96.390, 990.0, 31.4643
51.541452088, 96.390, 1013.0, 31.8277
51.593973219, 96.390, 1030.0, 32.0936
51.646494350, 96.390, 1099.0, 33.1512
51.699015481, 96.390, 1079.0, 32.8481
51.751536611, 96.390, 1132.0, 33.6452
51.804057742, 96.390, 1188.0, 34.4674
51.856578873, 96.390, 1133.0, 33.6601
51.909100003, 96.390, 1114.0, 33.3766
51.961621134, 96.390, 1169.0, 34.1906
52.014142265, 96.390, 1341.0, 36.6197
52.066663396, 96.390, 1477.0, 38.4318
52.119184526, 96.390, 1278.0, 35.7491
52.171705657, 96.390, 1182.0, 34.3802
52.224226788, 96.390, 1117.0, 33.4215
52.276747918, 96.390, 1097.0, 33.1210
52.329269049, 96.390, 974.0, 31.2090
52.381790180, 96.390, 978.0, 31.2730
52.434311310, 96.390, 999.0, 31.6070
52.486832441, 96.390, 1028.0, 32.0624
52.539353572, 96.390, 1006.0, 31.7175
52.591874703, 96.390, 998.0, 31.5911
52.644395833, 96.390, 981.0, 31.3209
52.696916964, 96.390, 1023.0, 31.9844
52.749438095, 96.390, 1029.0, 32.0780
52.801959225, 96.390, 1039.0, 32.2335
52.854480356, 96.390, 1161.0, 34.0735
52.907001487, 96.390, 1089.0, 33.0000
52.959522618, 96.390, 1130.0, 33.6155
53.012043748, 96.390, 1210.0, 34.7851
53.064564879, 96.390, 1354.0, 36.7967
53.117086010, 96.390, 1291.0, 35.9305
53.169607140, 96.390, 1183.0, 34.3948
53.222128271, 96.390, 1134.0, 33.6749
53.274649402, 96.390, 1092.0, 33.0454
53.327170533, 96.390, 1025.0, 32.0156
53.379691663, 96.390, 980.0, 31.3050
53.432212794, 96.390, 1000.0, 31.6228
53.484733925, 96.390, 1041.0, 32.2645
53.537255055, 96.390, 1035.0, 32.1714
53.589776186, 96.390, 993.0, 31.5119
53.642297317, 96.390, 951.0, 30.8383
53.694818448, 96.390, 923.0, 30.3809
53.747339578, 96.390, 968.0, 31.1127
53.799860709, 96.390, 940.0, 30.6594
53.852381840, 96.390, 907.0, 30.1164
53.904902970, 96.390, 897.0, 29.9500
53.957424101, 96.390, 968.0, 31.1127
54.009945232, 96.390, 942.0, 30.6920
54.062466362, 96.390, 935.0, 30.5778
54.114987493, 96.390, 900.0, 30.0000
54.167508624, 96.390, 905.0, 30.0832
54.220029755, 96.390, 902.0, 30.0333
54.272550885, 96.390, 928.0, 30.4631
54.325072016, 96.390, 926.0, 30.4302
54.377593147, 96.390, 890.0, 29.8329
54.430114277, 96.390, 961.0, 31.0000
54.482635408, 96.390, 1071.0, 32.7261
54.535156539, 96.390, 1074.0, 32.7719
54.587677670, 96.390, 1055.0, 32.4808
54.640198800, 96.390, 1057.0, 32.5115
54.692719931, 96.390, 1020.0, 31.9374
54.745241062, 96.390, 1011.0, 31.7962
54.797762192, 96.390, 977.0, 31.2570
54.850283323, 96.390, 972.0, 31.1769
54.902804454, 96.390, 1012.0, 31.8119
54.955325585, 96.390, 1098.0, 33.1361
55.007846715, 96.390, 1061.0, 32.5730
55.060367846, 96.390, 1013.0, 31.8277
55.112888977, 96.390, 1042.0, 32.2800
55.165410107, 96.390, 949.0, 30.8058
55.217931238, 96.390, 924.0, 30.3974
55.270452369, 96.390, 881.0, 29.6816
55.322973499, 96.390, 894.0, 29.8998
55.375494630, 96.390, 953.0, 30.8707
55.428015761, 96.390, 934.0, 30.5614
55.480536892, 96.390, 922.0, 30.3645
55.533058022, 96.390, 887.0, 29.7825
55.585579153, 96.390, 871.0, 29.5127
55.638100284, 96.390, 909.0, 30.1496
55.690621414, 96.390, 894.0, 29.8998
55.743142545, 96.390, 872.0, 29.5296
55.795663676, 96.390, 884.0, 29.7321
55.848184807, 96.390, 913.0, 30.2159
55.900705937, 96.390, 895.0, 29.9166
55.953227068, 96.390, 945.0, 30.7409
56.005748199, 96.390, 915.0, 30.2490
56.058269329, 96.390, 905.0, 30.0832
56.110790460, 96.390, 912.0, 30.1993
56.163311591, 96.390, 950.0, 30.8221
56.215832722, 96.390, 986.0, 31.4006
56.268353852, 96.390, 920.0, 30.3315
56.320874983, 96.390, 1001.0, 31.6386
56.373396114, 96.390, 949.0, 30.8058
56.425917244, 96.390, 876.0, 29.5973
56.478438375, 96.390, 824.0, 28.7054
56.530959506, 96.390, 850.0, 29.1548
56.583480637, 96.390, 916.0, 30.2655
56.636001767, 96.390, 889.0, 29.8161
56.688522898, 96.390, 889.0, 29.8161
56.741044029, 96.390, 923.0, 30.3809
56.793565159, 96.390, 916.0, 30.2655
56.846086290, 96.390, 901.0, 30.0167
56.898607421, 96.390, 840.0, 28.9828
56.951128551, 96.390, 919.0, 30.3150
57.003649682, 96.390, 870.0, 29.4958
57.056170813, 96.390, 830.0, 28.8097
57.108691944, 96.390, 902.0, 30.0333
57.161213074, 96.390, 859.0, 29.3087
57.213734205, 96.390, 893.0, 29.8831
57.266255336, 96.390, 885.0, 29.7489
57.318776466, 96.390, 889.0, 29.8161
57.371297597, 96.390, 925.0, 30.4138
57.423818728, 96.390, 901.0, 30.0167
57.476339859, 96.390, 919.0, 30.3150
57.528860989, 96.390, 964.0, 31.0483
57.581382120, 96.390, 996.0, 31.5595
57.633903251, 96.390, 932.0, 30.5287
57.686424381, 96.390, 899.0, 29.9833
57.738945512, 96.390, 862.0, 29.3598
57.791466643, 96.390, 994.0, 31.5278
57.843987774, 96.390, 1038.0, 32.2180
57.896508904, 96.390, 1096.0, 33.1059
57.949030035, 96.390, 1003.0, 31.6702
58.001551166, 96.390, 999.0, 31.6070
58.054072296, 96.390, 992.0, 31.4960
58.106593427, 96.390, 947.0, 30.7734
58.159114558, 96.390, 896.0, 29.9333
58.211635689, 96.390, 884.0, 29.7321
58.264156819, 96.390, 894.0, 29.8998
58.316677950, 96.390, 872.0, 29.5296
58.369199081, 96.390, 876.0, 29.5973
58.421720211, 96.390, 880.0, 29.6648
58.474241342, 96.390, 871.0, 29.5127
58.526762473, 96.390, 817.0, 28.5832
58.579283603, 96.390, 935.0, 30.5778
58.631804734, 96.390, 877.0, 29.6142
58.684325865, 96.390, 829.0, 28.7924
58.736846996, 96.390, 846.0, 29.0861
58.789368126, 96.390, 885.0, 29.7489
58.841889257, 96.390, 927.0, 30.4467
58.894410388, 96.390, 989.0, 31.4484
58.946931518, 96.390, 1071.0, 32.7261
58.999452649, 96.390, 1040.0, 32.2490
59.051973780, 96.390, 1029.0, 32.0780
59.104494911, 96.390, 1026.0, 32.0312
59.157016041, 96.390, 1042.0, 32.2800
59.209537172, 96.390, 1006.0, 31.7175
59.262058303, 96.390, 1006.0, 31.7175
59.314579433, 96.390, 1034.0, 32.1559
59.367100564, 96.390, 968.0, 31.1127
59.419621695, 96.390, 991.0, 31.4802
59.472142826, 96.390, 988.0, 31.4325
59.524663956, 96.390, 901.0, 30.0167
59.577185087, 96.390, 973.0, 31.1929
59.629706218, 96.390, 901.0, 30.0167
59.682227348, 96.390, 1021.0, 31.9531
59.734748479, 96.390, 966.0, 31.0805
59.787269610, 96.390, 980.0, 31.3050
59.839790740, 96.390, 988.0, 31.4325
59.892311871, 96.390, 940.0, 30.6594
59.944833002, 96.390, 988.0, 31.4325
59.997354133, 96.390, 912.0, 30.1993
60.049875263, 96.390, 884.0, 29.7321
60.102396394, 96.390, 949.0, 30.8058
60.154917525, 96.390, 969.0, 31.1288
60.207438655, 96.390, 925.0, 30.4138
60.259959786, 96.390, 920.0, 30.3315
60.312480917, 96.390, 899.0, 29.9833
60.365002048, 96.390, 924.0, 30.3974
60.417523178, 96.390, 895.0, 29.9166
60.470044309, 96.390, 950.0, 30.8221
60.522565440, 96.390, 916.0, 30.2655
60.575086570, 96.390, 907.0, 30.1164
60.627607701, 96.390, 1005.0, 31.7017
60.680128832, 96.390, 972.0, 31.1769
60.732649963, 96.390, 946.0, 30.7571
60.785171093, 96.390, 962.0, 31.0161
60.837692224, 96.390, 955.0, 30.9031
60.890213355, 96.390, 957.0, 30.9354
60.942734485, 96.390, 951.0, 30.8383
60.995255616, 96.390, 973.0, 31.1929
61.047776747, 96.390, 1014.0, 31.8434
61.100297878, 96.390, 997.0, 31.5753
61.152819008, 96.390, 1015.0, 31.8591
61.205340139, 96.390, 1004.0, 31.6860
61.257861270, 96.390, 1075.0, 32.7872
61.310382400, 96.390, 1052.0, 32.4345
61.362903531, 96.390, 1081.0, 32.8786
61.415424662, 96.390, 988.0, 31.4325
61.467945792, 96.390, 994.0, 31.5278
61.520466923, 96.390, 1082.0, 32.8938
61.572988054, 96.390, 964.0, 31.0483
61.625509185, 96.390, 1001.0, 31.6386
61.678030315, 96.390, 1035.0, 32.1714
61.730551446, 96.390, 1098.0, 33.1361
61.783072577, 96.390, 1073.0, 32.7567
61.835593707, 96.390, 997.0, 31.5753
61.888114838, 96.390, 948.0, 30.7896
61.940635969, 96.390, 989.0, 31.4484
61.993157100, 96.390, 980.0, 31.3050
62.045678230, 96.390, 984.0, 31.3688
62.098199361, 96.390, 941.0, 30.6757
62.150720492, 96.390, 951.0, 30.8383
62.203241622, 96.390, 986.0, 31.4006
62.255762753, 96.390, 943.0, 30.7083
62.308283884, 96.390, 979.0, 31.2890
62.360805015, 96.390, 996.0, 31.5595
62.413326145, 96.390, 988.0, 31.4325
62.465847276, 96.390, 980.0, 31.3050
62.518368407, 96.390, 972.0, 31.1769
62.570889537, 96.390, 884.0, 29.7321
62.623410668, 96.390, 922.0, 30.3645
62.675931799, 96.390, 917.0, 30.2820
62.728452930, 96.390, 983.0, 31.3528
62.780974060, 96.390, 964.0, 31.0483
62.833495191, 96.390, 1017.0, 31.8904
62.886016322, 96.390, 982.0, 31.3369
62.938537452, 96.390, 990.0, 31.4643
62.991058583, 96.390, 970.0, 31.1448
63.043579714, 96.390, 975.0, 31.2250
63.096100844, 96.390, 1025.0, 32.0156
63.148621975, 96.390, 950.0, 30.8221
63.201143106, 96.390, 910.0, 30.1662
63.253664237, 96.390, 922.0, 30.3645
63.306185367, 96.390, 880.0, 29.6648
63.358706498, 96.390, 880.0, 29.6648
63.411227629, 96.390, 878.0, 29.6311
63.463748759, 96.390, 795.0, 28.1957
63.516269890, 96.390, 862.0, 29.3598
63.568791021, 96.390, 782.0, 27.9643
63.621312152, 96.390, 826.0, 28.7402
63.673833282, 96.390, 812.0, 28.4956
63.726354413, 96.390, 868.0, 29.4618
63.778875544, 96.390, 812.0, 28.4956
63.831396674, 96.390, 887.0, 29.7825
63.883917805, 96.390, 887.0, 29.7825
63.936438936, 96.390, 865.0, 29.4109
63.988960067, 96.390, 861.0, 29.3428
64.041481197, 96.390, 860.0, 29.3258
64.094002328, 96.390, 874.0, 29.5635
64.146523459, 96.390, 851.0, 29.1719
64.199044589, 96.390, 849.0, 29.1376
64.251565720, 96.390, 826.0, 28.7402
64.304086851, 96.390, 814.0, 28.5307
64.356607981, 96.390, 753.0, 27.4408
64.409129112, 96.390, 802.0, 28.3196
64.461650243, 96.390, 811.0, 28.4781
64.514171374, 96.390, 736.0, 27.1293
64.566692504, 96.390, 788.0, 28.0713
64.619213635, 96.390, 798.0, 28.2489
64.671734766, 96.390, 797.0, 28.2312
64.724255896, 96.390, 832.0, 28.8444
64.776777027, 96.390, 804.0, 28.3549
64.829298158, 96.390, 840.0, 28.9828
64.881819289, 96.390, 762.0, 27.6043
64.934340419, 96.390, 831.0, 28.8271
64.986861550, 96.390, 774.0, 27.8209