File: Files_organized_for_plots/Constant_NaOH_1mL10M_to_1gPC/XRD_Centroid16Mar22_Act23Mar22_B2_0714M_NaOH_LS0172_1.csv
[Measurement conditions]
Sample identification,XRD_Centroid16Mar22_Act23Mar22_B2_0714M_NaOH_LS0172_1
Comment - 1,"Configuration=Stage for Flat Samples/Holders, Owner=User-1, Creation date=7/1/2020 9:53:24 AM"
Comment - 2,"Goniometer=Theta/Theta; Minimum step size 2Theta:0.0001; Minimum step size Omega:0.0001"
Comment - 3,"Sample stage=Stage for flat samples/holders"
Comment - 4,"Diffractometer system=EMPYREAN"
Comment - 5,"Measurement program=C:\Users\ibo5034\OneDrive - The Pennsylvania State University\NEUP\Zerobackground scan.xrdmp, Identifier={98A3B11C-88F9-4AA6-982C-73314A311EF5}"
Anode material,Cu
K-Alpha1 wavelength,1.5405980
K-Alpha2 wavelength,1.5444260
Ratio K-Alpha2/K-Alpha1,0.500
Divergence slit,Fixed,0.25
Monochromator used,NO
Generator voltage, 45
Tube current, 40
File date and time,01/Apr/2022 16:35
Unit cell,
h k l, 0 0 0
Scan axis,Gonio
Scan range,4.994599997,64.999991833
Scan step size,0.0262606
No. of points, 2285
Scan type,CONTINUOUS
Time per step,96.390
[Scan points]
Angle, TimePerStep, Intensity, ESD
5.007730280, 96.390, 3937.0, 62.7455
5.060251411, 96.390, 3948.0, 62.8331
5.112772541, 96.390, 3840.0, 61.9677
5.165293672, 96.390, 3857.0, 62.1048
5.217814803, 96.390, 3935.0, 62.7296
5.270335934, 96.390, 3923.0, 62.6339
5.322857064, 96.390, 3917.0, 62.5859
5.375378195, 96.390, 3729.0, 61.0655
5.427899326, 96.390, 3688.0, 60.7289
5.480420456, 96.390, 3682.0, 60.6795
5.532941587, 96.390, 3682.0, 60.6795
5.585462718, 96.390, 3696.0, 60.7947
5.637983849, 96.390, 3580.0, 59.8331
5.690504979, 96.390, 3635.0, 60.2910
5.743026110, 96.390, 3605.0, 60.0417
5.795547241, 96.390, 3563.0, 59.6909
5.848068371, 96.390, 3539.0, 59.4895
5.900589502, 96.390, 3565.0, 59.7076
5.953110633, 96.390, 3566.0, 59.7160
6.005631763, 96.390, 3543.0, 59.5231
6.058152894, 96.390, 3579.0, 59.8247
6.110674025, 96.390, 3412.0, 58.4123
6.163195156, 96.390, 3538.0, 59.4811
6.215716286, 96.390, 3402.0, 58.3267
6.268237417, 96.390, 3389.0, 58.2151
6.320758548, 96.390, 3410.0, 58.3952
6.373279678, 96.390, 3487.0, 59.0508
6.425800809, 96.390, 3506.0, 59.2115
6.478321940, 96.390, 3356.0, 57.9310
6.530843071, 96.390, 3458.0, 58.8048
6.583364201, 96.390, 3459.0, 58.8133
6.635885332, 96.390, 3437.0, 58.6259
6.688406463, 96.390, 3391.0, 58.2323
6.740927593, 96.390, 3355.0, 57.9224
6.793448724, 96.390, 3442.0, 58.6686
6.845969855, 96.390, 3417.0, 58.4551
6.898490986, 96.390, 3465.0, 58.8643
6.951012116, 96.390, 3424.0, 58.5150
7.003533247, 96.390, 3321.0, 57.6281
7.056054378, 96.390, 3443.0, 58.6771
7.108575508, 96.390, 3368.0, 58.0345
7.161096639, 96.390, 3399.0, 58.3009
7.213617770, 96.390, 3258.0, 57.0789
7.266138900, 96.390, 3284.0, 57.3062
7.318660031, 96.390, 3370.0, 58.0517
7.371181162, 96.390, 3353.0, 57.9051
7.423702293, 96.390, 3405.0, 58.3524
7.476223423, 96.390, 3264.0, 57.1314
7.528744554, 96.390, 3356.0, 57.9310
7.581265685, 96.390, 3338.0, 57.7754
7.633786815, 96.390, 3344.0, 57.8273
7.686307946, 96.390, 3314.0, 57.5674
7.738829077, 96.390, 3290.0, 57.3585
7.791350208, 96.390, 3307.0, 57.5065
7.843871338, 96.390, 3425.0, 58.5235
7.896392469, 96.390, 3317.0, 57.5934
7.948913600, 96.390, 3411.0, 58.4038
8.001434730, 96.390, 3296.0, 57.4108
8.053955861, 96.390, 3451.0, 58.7452
8.106476992, 96.390, 3509.0, 59.2368
8.158998123, 96.390, 3511.0, 59.2537
8.211519253, 96.390, 3363.0, 57.9914
8.264040384, 96.390, 3278.0, 57.2538
8.316561515, 96.390, 3238.0, 56.9034
8.369082645, 96.390, 3313.0, 57.5587
8.421603776, 96.390, 3360.0, 57.9655
8.474124907, 96.390, 3227.0, 56.8067
8.526646038, 96.390, 3366.0, 58.0172
8.579167168, 96.390, 3225.0, 56.7891
8.631688299, 96.390, 3320.0, 57.6194
8.684209430, 96.390, 3303.0, 57.4717
8.736730560, 96.390, 3379.0, 58.1292
8.789251691, 96.390, 3306.0, 57.4978
8.841772822, 96.390, 3291.0, 57.3672
8.894293952, 96.390, 3280.0, 57.2713
8.946815083, 96.390, 3235.0, 56.8771
8.999336214, 96.390, 3297.0, 57.4195
9.051857345, 96.390, 3229.0, 56.8243
9.104378475, 96.390, 3240.0, 56.9210
9.156899606, 96.390, 3172.0, 56.3205
9.209420737, 96.390, 3202.0, 56.5862
9.261941867, 96.390, 3188.0, 56.4624
9.314462998, 96.390, 3172.0, 56.3205
9.366984129, 96.390, 3179.0, 56.3826
9.419505260, 96.390, 3218.0, 56.7274
9.472026390, 96.390, 3298.0, 57.4282
9.524547521, 96.390, 3107.0, 55.7405
9.577068652, 96.390, 3282.0, 57.2887
9.629589782, 96.390, 3245.0, 56.9649
9.682110913, 96.390, 3178.0, 56.3738
9.734632044, 96.390, 3290.0, 57.3585
9.787153175, 96.390, 3221.0, 56.7539
9.839674305, 96.390, 3255.0, 57.0526
9.892195436, 96.390, 3177.0, 56.3649
9.944716567, 96.390, 3192.0, 56.4978
9.997237697, 96.390, 3146.0, 56.0892
10.049758828, 96.390, 3157.0, 56.1872
10.102279959, 96.390, 3196.0, 56.5332
10.154801090, 96.390, 3186.0, 56.4447
10.207322220, 96.390, 3171.0, 56.3116
10.259843351, 96.390, 3129.0, 55.9375
10.312364482, 96.390, 3194.0, 56.5155
10.364885612, 96.390, 3184.0, 56.4269
10.417406743, 96.390, 3225.0, 56.7891
10.469927874, 96.390, 3405.0, 58.3524
10.522449004, 96.390, 3051.0, 55.2359
10.574970135, 96.390, 3036.0, 55.0999
10.627491266, 96.390, 3033.0, 55.0727
10.680012397, 96.390, 3016.0, 54.9181
10.732533527, 96.390, 3111.0, 55.7763
10.785054658, 96.390, 3075.0, 55.4527
10.837575789, 96.390, 2847.0, 53.3573
10.890096919, 96.390, 3153.0, 56.1516
10.942618050, 96.390, 2973.0, 54.5252
10.995139181, 96.390, 3072.0, 55.4256
11.047660312, 96.390, 3321.0, 57.6281
11.100181442, 96.390, 2981.0, 54.5985
11.152702573, 96.390, 2893.0, 53.7866
11.205223704, 96.390, 2911.0, 53.9537
11.257744834, 96.390, 2930.0, 54.1295
11.310265965, 96.390, 2933.0, 54.1572
11.362787096, 96.390, 2964.0, 54.4426
11.415308227, 96.390, 2838.0, 53.2729
11.467829357, 96.390, 2833.0, 53.2259
11.520350488, 96.390, 2846.0, 53.3479
11.572871619, 96.390, 2799.0, 52.9056
11.625392749, 96.390, 2882.0, 53.6843
11.677913880, 96.390, 2891.0, 53.7680
11.730435011, 96.390, 2818.0, 53.0848
11.782956141, 96.390, 2783.0, 52.7541
11.835477272, 96.390, 2731.0, 52.2590
11.887998403, 96.390, 2759.0, 52.5262
11.940519534, 96.390, 2762.0, 52.5547
11.993040664, 96.390, 2816.0, 53.0660
12.045561795, 96.390, 2722.0, 52.1728
12.098082926, 96.390, 2760.0, 52.5357
12.150604056, 96.390, 2750.0, 52.4404
12.203125187, 96.390, 2705.0, 52.0096
12.255646318, 96.390, 2768.0, 52.6118
12.308167449, 96.390, 2693.0, 51.8941
12.360688579, 96.390, 2679.0, 51.7591
12.413209710, 96.390, 2623.0, 51.2152
12.465730841, 96.390, 2676.0, 51.7301
12.518251971, 96.390, 2509.0, 50.0899
12.570773102, 96.390, 2589.0, 50.8822
12.623294233, 96.390, 2466.0, 49.6588
12.675815364, 96.390, 2586.0, 50.8527
12.728336494, 96.390, 2526.0, 50.2593
12.780857625, 96.390, 2570.0, 50.6952
12.833378756, 96.390, 2417.0, 49.1630
12.885899886, 96.390, 2479.0, 49.7896
12.938421017, 96.390, 2474.0, 49.7393
12.990942148, 96.390, 2403.0, 49.0204
13.043463279, 96.390, 2393.0, 48.9183
13.095984409, 96.390, 2607.0, 51.0588
13.148505540, 96.390, 2495.0, 49.9500
13.201026671, 96.390, 2367.0, 48.6518
13.253547801, 96.390, 2504.0, 50.0400
13.306068932, 96.390, 2420.0, 49.1935
13.358590063, 96.390, 2430.0, 49.2950
13.411111193, 96.390, 2433.0, 49.3254
13.463632324, 96.390, 2360.0, 48.5798
13.516153455, 96.390, 2472.0, 49.7192
13.568674586, 96.390, 2422.0, 49.2138
13.621195716, 96.390, 2413.0, 49.1223
13.673716847, 96.390, 2420.0, 49.1935
13.726237978, 96.390, 2571.0, 50.7050
13.778759108, 96.390, 2946.0, 54.2771
13.831280239, 96.390, 3350.0, 57.8792
13.883801370, 96.390, 2561.0, 50.6063
13.936322501, 96.390, 2399.0, 48.9796
13.988843631, 96.390, 2400.0, 48.9898
14.041364762, 96.390, 2266.0, 47.6025
14.093885893, 96.390, 2298.0, 47.9375
14.146407023, 96.390, 2362.0, 48.6004
14.198928154, 96.390, 2445.0, 49.4469
14.251449285, 96.390, 2611.0, 51.0979
14.303970416, 96.390, 3496.0, 59.1270
14.356491546, 96.390, 2989.0, 54.6717
14.409012677, 96.390, 2427.0, 49.2646
14.461533808, 96.390, 2502.0, 50.0200
14.514054938, 96.390, 2736.0, 52.3068
14.566576069, 96.390, 3205.0, 56.6127
14.619097200, 96.390, 2626.0, 51.2445
14.671618331, 96.390, 2208.0, 46.9894
14.724139461, 96.390, 2165.0, 46.5296
14.776660592, 96.390, 2046.0, 45.2327
14.829181723, 96.390, 2204.0, 46.9468
14.881702853, 96.390, 2158.0, 46.4543
14.934223984, 96.390, 2192.0, 46.8188
14.986745115, 96.390, 2246.0, 47.3920
15.039266245, 96.390, 2264.0, 47.5815
15.091787376, 96.390, 2238.0, 47.3075
15.144308507, 96.390, 2355.0, 48.5283
15.196829638, 96.390, 2507.0, 50.0700
15.249350768, 96.390, 2474.0, 49.7393
15.301871899, 96.390, 2431.0, 49.3052
15.354393030, 96.390, 2323.0, 48.1975
15.406914160, 96.390, 2181.0, 46.7012
15.459435291, 96.390, 2109.0, 45.9239
15.511956422, 96.390, 2167.0, 46.5510
15.564477553, 96.390, 2219.0, 47.1063
15.616998683, 96.390, 2210.0, 47.0106
15.669519814, 96.390, 2269.0, 47.6340
15.722040945, 96.390, 2229.0, 47.2123
15.774562075, 96.390, 2255.0, 47.4868
15.827083206, 96.390, 2124.0, 46.0869
15.879604337, 96.390, 2102.0, 45.8476
15.932125468, 96.390, 2161.0, 46.4866
15.984646598, 96.390, 2173.0, 46.6154
16.037167729, 96.390, 2189.0, 46.7868
16.089688860, 96.390, 2169.0, 46.5725
16.142209990, 96.390, 2162.0, 46.4973
16.194731121, 96.390, 2261.0, 47.5500
16.247252252, 96.390, 2338.0, 48.3529
16.299773382, 96.390, 2497.0, 49.9700
16.352294513, 96.390, 2736.0, 52.3068
16.404815644, 96.390, 2413.0, 49.1223
16.457336775, 96.390, 2248.0, 47.4131
16.509857905, 96.390, 2154.0, 46.4112
16.562379036, 96.390, 2111.0, 45.9456
16.614900167, 96.390, 2184.0, 46.7333
16.667421297, 96.390, 2120.0, 46.0435
16.719942428, 96.390, 2146.0, 46.3249
16.772463559, 96.390, 2198.0, 46.8828
16.824984690, 96.390, 2138.0, 46.2385
16.877505820, 96.390, 2165.0, 46.5296
16.930026951, 96.390, 2090.0, 45.7165
16.982548082, 96.390, 2267.0, 47.6130
17.035069212, 96.390, 2221.0, 47.1275
17.087590343, 96.390, 2092.0, 45.7384
17.140111474, 96.390, 2130.0, 46.1519
17.192632605, 96.390, 2175.0, 46.6369
17.245153735, 96.390, 2141.0, 46.2709
17.297674866, 96.390, 2140.0, 46.2601
17.350195997, 96.390, 2247.0, 47.4025
17.402717127, 96.390, 2367.0, 48.6518
17.455238258, 96.390, 2380.0, 48.7852
17.507759389, 96.390, 2272.0, 47.6655
17.560280520, 96.390, 2177.0, 46.6583
17.612801650, 96.390, 2171.0, 46.5940
17.665322781, 96.390, 2190.0, 46.7974
17.717843912, 96.390, 2056.0, 45.3431
17.770365042, 96.390, 2135.0, 46.2061
17.822886173, 96.390, 2109.0, 45.9239
17.875407304, 96.390, 2149.0, 46.3573
17.927928434, 96.390, 2146.0, 46.3249
17.980449565, 96.390, 2135.0, 46.2061
18.032970696, 96.390, 2123.0, 46.0760
18.085491827, 96.390, 2297.0, 47.9270
18.138012957, 96.390, 2313.0, 48.0937
18.190534088, 96.390, 2240.0, 47.3286
18.243055219, 96.390, 2249.0, 47.4236
18.295576349, 96.390, 2418.0, 49.1732
18.348097480, 96.390, 2482.0, 49.8197
18.400618611, 96.390, 2348.0, 48.4562
18.453139742, 96.390, 2476.0, 49.7594
18.505660872, 96.390, 2636.0, 51.3420
18.558182003, 96.390, 2268.0, 47.6235
18.610703134, 96.390, 2159.0, 46.4650
18.663224264, 96.390, 2193.0, 46.8295
18.715745395, 96.390, 2121.0, 46.0543
18.768266526, 96.390, 2288.0, 47.8330
18.820787657, 96.390, 2445.0, 49.4469
18.873308787, 96.390, 2653.0, 51.5073
18.925829918, 96.390, 2787.0, 52.7920
18.978351049, 96.390, 2974.0, 54.5344
19.030872179, 96.390, 3114.0, 55.8032
19.083393310, 96.390, 2735.0, 52.2972
19.135914441, 96.390, 2531.0, 50.3090
19.188435572, 96.390, 2358.0, 48.5592
19.240956702, 96.390, 2276.0, 47.7074
19.293477833, 96.390, 2248.0, 47.4131
19.345998964, 96.390, 2389.0, 48.8774
19.398520094, 96.390, 2365.0, 48.6313
19.451041225, 96.390, 2301.0, 47.9687
19.503562356, 96.390, 2430.0, 49.2950
19.556083486, 96.390, 2397.0, 48.9592
19.608604617, 96.390, 2356.0, 48.5386
19.661125748, 96.390, 2353.0, 48.5077
19.713646879, 96.390, 2533.0, 50.3289
19.766168009, 96.390, 2640.0, 51.3809
19.818689140, 96.390, 2960.0, 54.4059
19.871210271, 96.390, 2657.0, 51.5461
19.923731401, 96.390, 2330.0, 48.2701
19.976252532, 96.390, 2276.0, 47.7074
20.028773663, 96.390, 2332.0, 48.2908
20.081294794, 96.390, 2335.0, 48.3218
20.133815924, 96.390, 2348.0, 48.4562
20.186337055, 96.390, 2250.0, 47.4342
20.238858186, 96.390, 2375.0, 48.7340
20.291379316, 96.390, 2372.0, 48.7032
20.343900447, 96.390, 2408.0, 49.0714
20.396421578, 96.390, 2661.0, 51.5849
20.448942709, 96.390, 2844.0, 53.3292
20.501463839, 96.390, 2716.0, 52.1153
20.553984970, 96.390, 2652.0, 51.4976
20.606506101, 96.390, 2922.0, 54.0555
20.659027231, 96.390, 2866.0, 53.5350
20.711548362, 96.390, 2689.0, 51.8556
20.764069493, 96.390, 2549.0, 50.4876
20.816590623, 96.390, 2498.0, 49.9800
20.869111754, 96.390, 2420.0, 49.1935
20.921632885, 96.390, 2513.0, 50.1298
20.974154016, 96.390, 2499.0, 49.9900
21.026675146, 96.390, 2494.0, 49.9400
21.079196277, 96.390, 2430.0, 49.2950
21.131717408, 96.390, 2409.0, 49.0816
21.184238538, 96.390, 2481.0, 49.8096
21.236759669, 96.390, 2505.0, 50.0500
21.289280800, 96.390, 2656.0, 51.5364
21.341801931, 96.390, 2704.0, 52.0000
21.394323061, 96.390, 2570.0, 50.6952
21.446844192, 96.390, 2570.0, 50.6952
21.499365323, 96.390, 2497.0, 49.9700
21.551886453, 96.390, 2564.0, 50.6360
21.604407584, 96.390, 2862.0, 53.4977
21.656928715, 96.390, 2961.0, 54.4151
21.709449846, 96.390, 2889.0, 53.7494
21.761970976, 96.390, 2679.0, 51.7591
21.814492107, 96.390, 2487.0, 49.8698
21.867013238, 96.390, 2415.0, 49.1426
21.919534368, 96.390, 2375.0, 48.7340
21.972055499, 96.390, 2488.0, 49.8799
22.024576630, 96.390, 2443.0, 49.4267
22.077097761, 96.390, 2455.0, 49.5480
22.129618891, 96.390, 2501.0, 50.0100
22.182140022, 96.390, 2615.0, 51.1371
22.234661153, 96.390, 2687.0, 51.8363
22.287182283, 96.390, 2791.0, 52.8299
22.339703414, 96.390, 2757.0, 52.5071
22.392224545, 96.390, 2808.0, 52.9906
22.444745675, 96.390, 2778.0, 52.7067
22.497266806, 96.390, 2718.0, 52.1344
22.549787937, 96.390, 2612.0, 51.1077
22.602309068, 96.390, 2754.0, 52.4786
22.654830198, 96.390, 2706.0, 52.0192
22.707351329, 96.390, 2712.0, 52.0769
22.759872460, 96.390, 2776.0, 52.6878
22.812393590, 96.390, 2846.0, 53.3479
22.864914721, 96.390, 2886.0, 53.7215
22.917435852, 96.390, 2896.0, 53.8145
22.969956983, 96.390, 2844.0, 53.3292
23.022478113, 96.390, 2896.0, 53.8145
23.074999244, 96.390, 3101.0, 55.6866
23.127520375, 96.390, 3344.0, 57.8273
23.180041505, 96.390, 3621.0, 60.1747
23.232562636, 96.390, 3490.0, 59.0762
23.285083767, 96.390, 3049.0, 55.2178
23.337604898, 96.390, 2799.0, 52.9056
23.390126028, 96.390, 2984.0, 54.6260
23.442647159, 96.390, 2859.0, 53.4696
23.495168290, 96.390, 2857.0, 53.4509
23.547689420, 96.390, 3521.0, 59.3380
23.600210551, 96.390, 3336.0, 57.7581
23.652731682, 96.390, 2800.0, 52.9150
23.705252813, 96.390, 2483.0, 49.8297
23.757773943, 96.390, 2389.0, 48.8774
23.810295074, 96.390, 2505.0, 50.0500
23.862816205, 96.390, 2427.0, 49.2646
23.915337335, 96.390, 2345.0, 48.4252
23.967858466, 96.390, 2359.0, 48.5695
24.020379597, 96.390, 2413.0, 49.1223
24.072900727, 96.390, 2271.0, 47.6550
24.125421858, 96.390, 2431.0, 49.3052
24.177942989, 96.390, 2390.0, 48.8876
24.230464120, 96.390, 2485.0, 49.8498
24.282985250, 96.390, 2454.0, 49.5379
24.335506381, 96.390, 2483.0, 49.8297
24.388027512, 96.390, 2348.0, 48.4562
24.440548642, 96.390, 2301.0, 47.9687
24.493069773, 96.390, 2214.0, 47.0532
24.545590904, 96.390, 2313.0, 48.0937
24.598112035, 96.390, 2489.0, 49.8899
24.650633165, 96.390, 2426.0, 49.2544
24.703154296, 96.390, 2222.0, 47.1381
24.755675427, 96.390, 2192.0, 46.8188
24.808196557, 96.390, 2346.0, 48.4355
24.860717688, 96.390, 2244.0, 47.3709
24.913238819, 96.390, 2193.0, 46.8295
24.965759950, 96.390, 2130.0, 46.1519
25.018281080, 96.390, 2419.0, 49.1833
25.070802211, 96.390, 2216.0, 47.0744
25.123323342, 96.390, 2104.0, 45.8694
25.175844472, 96.390, 1998.0, 44.6990
25.228365603, 96.390, 2065.0, 45.4423
25.280886734, 96.390, 1986.0, 44.5646
25.333407864, 96.390, 2067.0, 45.4643
25.385928995, 96.390, 2187.0, 46.7654
25.438450126, 96.390, 2265.0, 47.5920
25.490971257, 96.390, 2178.0, 46.6690
25.543492387, 96.390, 2004.0, 44.7661
25.596013518, 96.390, 1944.0, 44.0908
25.648534649, 96.390, 1923.0, 43.8520
25.701055779, 96.390, 2044.0, 45.2106
25.753576910, 96.390, 1951.0, 44.1701
25.806098041, 96.390, 1930.0, 43.9318
25.858619172, 96.390, 2193.0, 46.8295
25.911140302, 96.390, 2093.0, 45.7493
25.963661433, 96.390, 2213.0, 47.0425
26.016182564, 96.390, 2154.0, 46.4112
26.068703694, 96.390, 2149.0, 46.3573
26.121224825, 96.390, 1979.0, 44.4860
26.173745956, 96.390, 1896.0, 43.5431
26.226267087, 96.390, 1939.0, 44.0341
26.278788217, 96.390, 1923.0, 43.8520
26.331309348, 96.390, 1889.0, 43.4626
26.383830479, 96.390, 1827.0, 42.7434
26.436351609, 96.390, 1893.0, 43.5086
26.488872740, 96.390, 1726.0, 41.5452
26.541393871, 96.390, 1816.0, 42.6146
26.593915002, 96.390, 1808.0, 42.5206
26.646436132, 96.390, 1832.0, 42.8019
26.698957263, 96.390, 1970.0, 44.3847
26.751478394, 96.390, 2236.0, 47.2864
26.803999524, 96.390, 2443.0, 49.4267
26.856520655, 96.390, 2478.0, 49.7795
26.909041786, 96.390, 2267.0, 47.6130
26.961562916, 96.390, 2128.0, 46.1303
27.014084047, 96.390, 2348.0, 48.4562
27.066605178, 96.390, 2536.0, 50.3587
27.119126309, 96.390, 2442.0, 49.4166
27.171647439, 96.390, 2492.0, 49.9199
27.224168570, 96.390, 2663.0, 51.6043
27.276689701, 96.390, 2434.0, 49.3356
27.329210831, 96.390, 2138.0, 46.2385
27.381731962, 96.390, 2015.0, 44.8888
27.434253093, 96.390, 2084.0, 45.6508
27.486774224, 96.390, 1778.0, 42.1663
27.539295354, 96.390, 1832.0, 42.8019
27.591816485, 96.390, 1801.0, 42.4382
27.644337616, 96.390, 1896.0, 43.5431
27.696858746, 96.390, 2096.0, 45.7821
27.749379877, 96.390, 2014.0, 44.8776
27.801901008, 96.390, 1990.0, 44.6094
27.854422139, 96.390, 1907.0, 43.6692
27.906943269, 96.390, 1751.0, 41.8450
27.959464400, 96.390, 1752.0, 41.8569
28.011985531, 96.390, 1775.0, 42.1307
28.064506661, 96.390, 1829.0, 42.7668
28.117027792, 96.390, 1835.0, 42.8369
28.169548923, 96.390, 1814.0, 42.5911
28.222070054, 96.390, 1788.0, 42.2847
28.274591184, 96.390, 1824.0, 42.7083
28.327112315, 96.390, 1823.0, 42.6966
28.379633446, 96.390, 1816.0, 42.6146
28.432154576, 96.390, 1906.0, 43.6578
28.484675707, 96.390, 1825.0, 42.7200
28.537196838, 96.390, 1863.0, 43.1625
28.589717968, 96.390, 1872.0, 43.2666
28.642239099, 96.390, 1812.0, 42.5676
28.694760230, 96.390, 1749.0, 41.8210
28.747281361, 96.390, 1750.0, 41.8330
28.799802491, 96.390, 1766.0, 42.0238
28.852323622, 96.390, 1791.0, 42.3202
28.904844753, 96.390, 1818.0, 42.6380
28.957365883, 96.390, 1870.0, 43.2435
29.009887014, 96.390, 1863.0, 43.1625
29.062408145, 96.390, 1748.0, 41.8091
29.114929276, 96.390, 1956.0, 44.2267
29.167450406, 96.390, 2111.0, 45.9456
29.219971537, 96.390, 2156.0, 46.4327
29.272492668, 96.390, 2302.0, 47.9792
29.325013798, 96.390, 2680.0, 51.7687
29.377534929, 96.390, 2572.0, 50.7149
29.430056060, 96.390, 2326.0, 48.2286
29.482577191, 96.390, 2326.0, 48.2286
29.535098321, 96.390, 2422.0, 49.2138
29.587619452, 96.390, 2185.0, 46.7440
29.640140583, 96.390, 2065.0, 45.4423
29.692661713, 96.390, 1991.0, 44.6206
29.745182844, 96.390, 2010.0, 44.8330
29.797703975, 96.390, 1925.0, 43.8748
29.850225105, 96.390, 1825.0, 42.7200
29.902746236, 96.390, 1869.0, 43.2319
29.955267367, 96.390, 1719.0, 41.4608
30.007788498, 96.390, 1831.0, 42.7902
30.060309628, 96.390, 1896.0, 43.5431
30.112830759, 96.390, 1738.0, 41.6893
30.165351890, 96.390, 1709.0, 41.3401
30.217873020, 96.390, 1782.0, 42.2137
30.270394151, 96.390, 1719.0, 41.4608
30.322915282, 96.390, 1685.0, 41.0488
30.375436413, 96.390, 1710.0, 41.3521
30.427957543, 96.390, 1827.0, 42.7434
30.480478674, 96.390, 1797.0, 42.3910
30.532999805, 96.390, 1883.0, 43.3935
30.585520935, 96.390, 1899.0, 43.5775
30.638042066, 96.390, 2164.0, 46.5188
30.690563197, 96.390, 2422.0, 49.2138
30.743084328, 96.390, 2761.0, 52.5452
30.795605458, 96.390, 2569.0, 50.6853
30.848126589, 96.390, 2195.0, 46.8508
30.900647720, 96.390, 1971.0, 44.3959
30.953168850, 96.390, 1896.0, 43.5431
31.005689981, 96.390, 1949.0, 44.1475
31.058211112, 96.390, 1969.0, 44.3734
31.110732243, 96.390, 1897.0, 43.5546
31.163253373, 96.390, 2162.0, 46.4973
31.215774504, 96.390, 2154.0, 46.4112
31.268295635, 96.390, 2323.0, 48.1975
31.320816765, 96.390, 2538.0, 50.3786
31.373337896, 96.390, 2506.0, 50.0600
31.425859027, 96.390, 2318.0, 48.1456
31.478380157, 96.390, 2110.0, 45.9347
31.530901288, 96.390, 2001.0, 44.7325
31.583422419, 96.390, 2024.0, 44.9889
31.635943550, 96.390, 1979.0, 44.4860
31.688464680, 96.390, 2314.0, 48.1041
31.740985811, 96.390, 2498.0, 49.9800
31.793506942, 96.390, 2340.0, 48.3735
31.846028072, 96.390, 2409.0, 49.0816
31.898549203, 96.390, 2441.0, 49.4065
31.951070334, 96.390, 2580.0, 50.7937
32.003591465, 96.390, 2426.0, 49.2544
32.056112595, 96.390, 2244.0, 47.3709
32.108633726, 96.390, 2185.0, 46.7440
32.161154857, 96.390, 2180.0, 46.6905
32.213675987, 96.390, 2051.0, 45.2880
32.266197118, 96.390, 2143.0, 46.2925
32.318718249, 96.390, 2388.0, 48.8672
32.371239380, 96.390, 2075.0, 45.5522
32.423760510, 96.390, 1815.0, 42.6028
32.476281641, 96.390, 1801.0, 42.4382
32.528802772, 96.390, 1756.0, 41.9047
32.581323902, 96.390, 1759.0, 41.9404
32.633845033, 96.390, 1816.0, 42.6146
32.686366164, 96.390, 1996.0, 44.6766
32.738887295, 96.390, 2061.0, 45.3982
32.791408425, 96.390, 2033.0, 45.0888
32.843929556, 96.390, 2079.0, 45.5961
32.896450687, 96.390, 2050.0, 45.2769
32.948971817, 96.390, 2302.0, 47.9792
33.001492948, 96.390, 2261.0, 47.5500
33.054014079, 96.390, 2249.0, 47.4236
33.106535209, 96.390, 2158.0, 46.4543
33.159056340, 96.390, 2333.0, 48.3011
33.211577471, 96.390, 2138.0, 46.2385
33.264098602, 96.390, 2184.0, 46.7333
33.316619732, 96.390, 2018.0, 44.9222
33.369140863, 96.390, 2007.0, 44.7996
33.421661994, 96.390, 2290.0, 47.8539
33.474183124, 96.390, 4561.0, 67.5352
33.526704255, 96.390, 3159.0, 56.2050
33.579225386, 96.390, 3050.0, 55.2268
33.631746517, 96.390, 1974.0, 44.4297
33.684267647, 96.390, 1857.0, 43.0929
33.736788778, 96.390, 1875.0, 43.3013
33.789309909, 96.390, 1812.0, 42.5676
33.841831039, 96.390, 1746.0, 41.7852
33.894352170, 96.390, 1898.0, 43.5660
33.946873301, 96.390, 1939.0, 44.0341
33.999394432, 96.390, 1889.0, 43.4626
34.051915562, 96.390, 1914.0, 43.7493
34.104436693, 96.390, 1865.0, 43.1856
34.156957824, 96.390, 1864.0, 43.1741
34.209478954, 96.390, 1837.0, 42.8602
34.262000085, 96.390, 1928.0, 43.9090
34.314521216, 96.390, 1994.0, 44.6542
34.367042346, 96.390, 2158.0, 46.4543
34.419563477, 96.390, 2137.0, 46.2277
34.472084608, 96.390, 2262.0, 47.5605
34.524605739, 96.390, 2587.0, 50.8626
34.577126869, 96.390, 2630.0, 51.2835
34.629648000, 96.390, 2821.0, 53.1131
34.682169131, 96.390, 2560.0, 50.5964
34.734690261, 96.390, 2478.0, 49.7795
34.787211392, 96.390, 2265.0, 47.5920
34.839732523, 96.390, 2136.0, 46.2169
34.892253654, 96.390, 2201.0, 46.9148
34.944774784, 96.390, 2173.0, 46.6154
34.997295915, 96.390, 2597.0, 50.9608
35.049817046, 96.390, 2976.0, 54.5527
35.102338176, 96.390, 2741.0, 52.3546
35.154859307, 96.390, 2507.0, 50.0700
35.207380438, 96.390, 2375.0, 48.7340
35.259901569, 96.390, 2375.0, 48.7340
35.312422699, 96.390, 2187.0, 46.7654
35.364943830, 96.390, 2160.0, 46.4758
35.417464961, 96.390, 2031.0, 45.0666
35.469986091, 96.390, 1969.0, 44.3734
35.522507222, 96.390, 1988.0, 44.5870
35.575028353, 96.390, 1996.0, 44.6766
35.627549484, 96.390, 1901.0, 43.6005
35.680070614, 96.390, 1961.0, 44.2832
35.732591745, 96.390, 1966.0, 44.3396
35.785112876, 96.390, 1967.0, 44.3509
35.837634006, 96.390, 1979.0, 44.4860
35.890155137, 96.390, 2117.0, 46.0109
35.942676268, 96.390, 2247.0, 47.4025
35.995197398, 96.390, 2424.0, 49.2341
36.047718529, 96.390, 2253.0, 47.4658
36.100239660, 96.390, 2212.0, 47.0319
36.152760791, 96.390, 2274.0, 47.6865
36.205281921, 96.390, 2532.0, 50.3190
36.257803052, 96.390, 2379.0, 48.7750
36.310324183, 96.390, 2189.0, 46.7868
36.362845313, 96.390, 2054.0, 45.3211
36.415366444, 96.390, 2049.0, 45.2659
36.467887575, 96.390, 1858.0, 43.1045
36.520408706, 96.390, 1869.0, 43.2319
36.572929836, 96.390, 1685.0, 41.0488
36.625450967, 96.390, 1706.0, 41.3038
36.677972098, 96.390, 1771.0, 42.0833
36.730493228, 96.390, 1842.0, 42.9185
36.783014359, 96.390, 1620.0, 40.2492
36.835535490, 96.390, 1684.0, 41.0366
36.888056621, 96.390, 1587.0, 39.8372
36.940577751, 96.390, 1536.0, 39.1918
36.993098882, 96.390, 1527.0, 39.0768
37.045620013, 96.390, 1566.0, 39.5727
37.098141143, 96.390, 1561.0, 39.5095
37.150662274, 96.390, 1634.0, 40.4228
37.203183405, 96.390, 1616.0, 40.1995
37.255704535, 96.390, 1624.0, 40.2989
37.308225666, 96.390, 1649.0, 40.6079
37.360746797, 96.390, 1653.0, 40.6571
37.413267928, 96.390, 1688.0, 41.0853
37.465789058, 96.390, 1670.0, 40.8656
37.518310189, 96.390, 1766.0, 42.0238
37.570831320, 96.390, 1774.0, 42.1189
37.623352450, 96.390, 1710.0, 41.3521
37.675873581, 96.390, 1623.0, 40.2865
37.728394712, 96.390, 1657.0, 40.7063
37.780915843, 96.390, 1617.0, 40.2119
37.833436973, 96.390, 1887.0, 43.4396
37.885958104, 96.390, 2100.0, 45.8258
37.938479235, 96.390, 1812.0, 42.5676
37.991000365, 96.390, 1885.0, 43.4166
38.043521496, 96.390, 1771.0, 42.0833
38.096042627, 96.390, 1508.0, 38.8330
38.148563758, 96.390, 1699.0, 41.2189
38.201084888, 96.390, 1640.0, 40.4969
38.253606019, 96.390, 1854.0, 43.0581
38.306127150, 96.390, 1651.0, 40.6325
38.358648280, 96.390, 1729.0, 41.5812
38.411169411, 96.390, 1460.0, 38.2099
38.463690542, 96.390, 1506.0, 38.8072
38.516211673, 96.390, 1463.0, 38.2492
38.568732803, 96.390, 1453.0, 38.1182
38.621253934, 96.390, 1408.0, 37.5233
38.673775065, 96.390, 1452.0, 38.1051
38.726296195, 96.390, 1497.0, 38.6911
38.778817326, 96.390, 1484.0, 38.5227
38.831338457, 96.390, 1391.0, 37.2961
38.883859587, 96.390, 1421.0, 37.6962
38.936380718, 96.390, 1476.0, 38.4187
38.988901849, 96.390, 1456.0, 38.1576
39.041422980, 96.390, 1400.0, 37.4166
39.093944110, 96.390, 1418.0, 37.6563
39.146465241, 96.390, 1536.0, 39.1918
39.198986372, 96.390, 1587.0, 39.8372
39.251507502, 96.390, 1611.0, 40.1373
39.304028633, 96.390, 1547.0, 39.3319
39.356549764, 96.390, 1501.0, 38.7427
39.409070895, 96.390, 1375.0, 37.0810
39.461592025, 96.390, 1388.0, 37.2559
39.514113156, 96.390, 1433.0, 37.8550
39.566634287, 96.390, 1413.0, 37.5899
39.619155417, 96.390, 1405.0, 37.4833
39.671676548, 96.390, 1469.0, 38.3275
39.724197679, 96.390, 1440.0, 37.9473
39.776718810, 96.390, 1529.0, 39.1024
39.829239940, 96.390, 1445.0, 38.0132
39.881761071, 96.390, 1385.0, 37.2156
39.934282202, 96.390, 1508.0, 38.8330
39.986803332, 96.390, 1363.0, 36.9188
40.039324463, 96.390, 1411.0, 37.5633
40.091845594, 96.390, 1265.0, 35.5668
40.144366725, 96.390, 1304.0, 36.1109
40.196887855, 96.390, 1346.0, 36.6879
40.249408986, 96.390, 1298.0, 36.0278
40.301930117, 96.390, 1254.0, 35.4119
40.354451247, 96.390, 1270.0, 35.6371
40.406972378, 96.390, 1278.0, 35.7491
40.459493509, 96.390, 1293.0, 35.9583
40.512014639, 96.390, 1260.0, 35.4965
40.564535770, 96.390, 1278.0, 35.7491
40.617056901, 96.390, 1280.0, 35.7771
40.669578032, 96.390, 1265.0, 35.5668
40.722099162, 96.390, 1315.0, 36.2629
40.774620293, 96.390, 1271.0, 35.6511
40.827141424, 96.390, 1305.0, 36.1248
40.879662554, 96.390, 1201.0, 34.6554
40.932183685, 96.390, 1239.0, 35.1994
40.984704816, 96.390, 1265.0, 35.5668
41.037225947, 96.390, 1356.0, 36.8239
41.089747077, 96.390, 1299.0, 36.0416
41.142268208, 96.390, 1332.0, 36.4966
41.194789339, 96.390, 1335.0, 36.5377
41.247310469, 96.390, 1204.0, 34.6987
41.299831600, 96.390, 1191.0, 34.5109
41.352352731, 96.390, 1288.0, 35.8887
41.404873862, 96.390, 1196.0, 34.5832
41.457394992, 96.390, 1240.0, 35.2136
41.509916123, 96.390, 1232.0, 35.0999
41.562437254, 96.390, 1192.0, 34.5254
41.614958384, 96.390, 1237.0, 35.1710
41.667479515, 96.390, 1197.0, 34.5977
41.720000646, 96.390, 1171.0, 34.2199
41.772521776, 96.390, 1264.0, 35.5528
41.825042907, 96.390, 1246.0, 35.2987
41.877564038, 96.390, 1176.0, 34.2929
41.930085169, 96.390, 1127.0, 33.5708
41.982606299, 96.390, 1240.0, 35.2136
42.035127430, 96.390, 1160.0, 34.0588
42.087648561, 96.390, 1294.0, 35.9722
42.140169691, 96.390, 1551.0, 39.3827
42.192690822, 96.390, 1609.0, 40.1123
42.245211953, 96.390, 1393.0, 37.3229
42.297733084, 96.390, 1411.0, 37.5633
42.350254214, 96.390, 1277.0, 35.7351
42.402775345, 96.390, 1149.0, 33.8969
42.455296476, 96.390, 1068.0, 32.6803
42.507817606, 96.390, 1086.0, 32.9545
42.560338737, 96.390, 1060.0, 32.5576
42.612859868, 96.390, 1162.0, 34.0881
42.665380999, 96.390, 1215.0, 34.8569
42.717902129, 96.390, 1228.0, 35.0428
42.770423260, 96.390, 1249.0, 35.3412
42.822944391, 96.390, 1161.0, 34.0735
42.875465521, 96.390, 1115.0, 33.3916
42.927986652, 96.390, 1138.0, 33.7343
42.980507783, 96.390, 1064.0, 32.6190
43.033028914, 96.390, 1100.0, 33.1662
43.085550044, 96.390, 1118.0, 33.4365
43.138071175, 96.390, 1142.0, 33.7935
43.190592306, 96.390, 1231.0, 35.0856
43.243113436, 96.390, 1132.0, 33.6452
43.295634567, 96.390, 1170.0, 34.2053
43.348155698, 96.390, 1113.0, 33.3617
43.400676828, 96.390, 1087.0, 32.9697
43.453197959, 96.390, 1027.0, 32.0468
43.505719090, 96.390, 1134.0, 33.6749
43.558240221, 96.390, 1072.0, 32.7414
43.610761351, 96.390, 1101.0, 33.1813
43.663282482, 96.390, 1087.0, 32.9697
43.715803613, 96.390, 1087.0, 32.9697
43.768324743, 96.390, 1081.0, 32.8786
43.820845874, 96.390, 1159.0, 34.0441
43.873367005, 96.390, 1139.0, 33.7491
43.925888136, 96.390, 1147.0, 33.8674
43.978409266, 96.390, 1136.0, 33.7046
44.030930397, 96.390, 1091.0, 33.0303
44.083451528, 96.390, 1079.0, 32.8481
44.135972658, 96.390, 1218.0, 34.8999
44.188493789, 96.390, 1159.0, 34.0441
44.241014920, 96.390, 1401.0, 37.4299
44.293536051, 96.390, 1184.0, 34.4093
44.346057181, 96.390, 1324.0, 36.3868
44.398578312, 96.390, 1165.0, 34.1321
44.451099443, 96.390, 1184.0, 34.4093
44.503620573, 96.390, 1194.0, 34.5543
44.556141704, 96.390, 1154.0, 33.9706
44.608662835, 96.390, 1192.0, 34.5254
44.661183966, 96.390, 1146.0, 33.8526
44.713705096, 96.390, 1218.0, 34.8999
44.766226227, 96.390, 1166.0, 34.1467
44.818747358, 96.390, 1167.0, 34.1614
44.871268488, 96.390, 1180.0, 34.3511
44.923789619, 96.390, 1226.0, 35.0143
44.976310750, 96.390, 1191.0, 34.5109
45.028831880, 96.390, 1206.0, 34.7275
45.081353011, 96.390, 1169.0, 34.1906
45.133874142, 96.390, 1241.0, 35.2278
45.186395273, 96.390, 1366.0, 36.9594
45.238916403, 96.390, 1236.0, 35.1568
45.291437534, 96.390, 1183.0, 34.3948
45.343958665, 96.390, 1184.0, 34.4093
45.396479795, 96.390, 1151.0, 33.9264
45.449000926, 96.390, 1224.0, 34.9857
45.501522057, 96.390, 1182.0, 34.3802
45.554043188, 96.390, 1284.0, 35.8329
45.606564318, 96.390, 1327.0, 36.4280
45.659085449, 96.390, 1391.0, 37.2961
45.711606580, 96.390, 1199.0, 34.6266
45.764127710, 96.390, 1228.0, 35.0428
45.816648841, 96.390, 1253.0, 35.3977
45.869169972, 96.390, 1171.0, 34.2199
45.921691103, 96.390, 1103.0, 33.2114
45.974212233, 96.390, 1132.0, 33.6452
46.026733364, 96.390, 1192.0, 34.5254
46.079254495, 96.390, 1193.0, 34.5398
46.131775625, 96.390, 1220.0, 34.9285
46.184296756, 96.390, 1272.0, 35.6651
46.236817887, 96.390, 1454.0, 38.1314
46.289339017, 96.390, 1434.0, 37.8682
46.341860148, 96.390, 1424.0, 37.7359
46.394381279, 96.390, 1581.0, 39.7618
46.446902410, 96.390, 1600.0, 40.0000
46.499423540, 96.390, 1522.0, 39.0128
46.551944671, 96.390, 1374.0, 37.0675
46.604465802, 96.390, 1420.0, 37.6829
46.656986932, 96.390, 1311.0, 36.2077
46.709508063, 96.390, 1355.0, 36.8103
46.762029194, 96.390, 1327.0, 36.4280
46.814550325, 96.390, 1161.0, 34.0735
46.867071455, 96.390, 1185.0, 34.4238
46.919592586, 96.390, 1147.0, 33.8674
46.972113717, 96.390, 1138.0, 33.7343
47.024634847, 96.390, 1121.0, 33.4813
47.077155978, 96.390, 1127.0, 33.5708
47.129677109, 96.390, 1125.0, 33.5410
47.182198240, 96.390, 1188.0, 34.4674
47.234719370, 96.390, 1233.0, 35.1141
47.287240501, 96.390, 1288.0, 35.8887
47.339761632, 96.390, 1230.0, 35.0714
47.392282762, 96.390, 1252.0, 35.3836
47.444803893, 96.390, 1262.0, 35.5246
47.497325024, 96.390, 1210.0, 34.7851
47.549846155, 96.390, 1258.0, 35.4683
47.602367285, 96.390, 1152.0, 33.9411
47.654888416, 96.390, 1124.0, 33.5261
47.707409547, 96.390, 1173.0, 34.2491
47.759930677, 96.390, 1177.0, 34.3074
47.812451808, 96.390, 1166.0, 34.1467
47.864972939, 96.390, 1156.0, 34.0000
47.917494069, 96.390, 1146.0, 33.8526
47.970015200, 96.390, 1146.0, 33.8526
48.022536331, 96.390, 1081.0, 32.8786
48.075057462, 96.390, 1051.0, 32.4191
48.127578592, 96.390, 1130.0, 33.6155
48.180099723, 96.390, 1155.0, 33.9853
48.232620854, 96.390, 1148.0, 33.8821
48.285141984, 96.390, 1101.0, 33.1813
48.337663115, 96.390, 1081.0, 32.8786
48.390184246, 96.390, 1175.0, 34.2783
48.442705377, 96.390, 1287.0, 35.8748
48.495226507, 96.390, 1267.0, 35.5949
48.547747638, 96.390, 1217.0, 34.8855
48.600268769, 96.390, 1262.0, 35.5246
48.652789899, 96.390, 1105.0, 33.2415
48.705311030, 96.390, 1047.0, 32.3574
48.757832161, 96.390, 1131.0, 33.6303
48.810353292, 96.390, 1035.0, 32.1714
48.862874422, 96.390, 1007.0, 31.7333
48.915395553, 96.390, 1076.0, 32.8024
48.967916684, 96.390, 1025.0, 32.0156
49.020437814, 96.390, 1034.0, 32.1559
49.072958945, 96.390, 1084.0, 32.9242
49.125480076, 96.390, 1093.0, 33.0606
49.178001207, 96.390, 1034.0, 32.1559
49.230522337, 96.390, 1095.0, 33.0908
49.283043468, 96.390, 1033.0, 32.1403
49.335564599, 96.390, 994.0, 31.5278
49.388085729, 96.390, 1022.0, 31.9687
49.440606860, 96.390, 1003.0, 31.6702
49.493127991, 96.390, 1004.0, 31.6860
49.545649121, 96.390, 944.0, 30.7246
49.598170252, 96.390, 1042.0, 32.2800
49.650691383, 96.390, 1082.0, 32.8938
49.703212514, 96.390, 1094.0, 33.0757
49.755733644, 96.390, 1046.0, 32.3419
49.808254775, 96.390, 1059.0, 32.5423
49.860775906, 96.390, 1040.0, 32.2490
49.913297036, 96.390, 939.0, 30.6431
49.965818167, 96.390, 937.0, 30.6105
50.018339298, 96.390, 917.0, 30.2820
50.070860429, 96.390, 959.0, 30.9677
50.123381559, 96.390, 915.0, 30.2490
50.175902690, 96.390, 969.0, 31.1288
50.228423821, 96.390, 952.0, 30.8545
50.280944951, 96.390, 949.0, 30.8058
50.333466082, 96.390, 978.0, 31.2730
50.385987213, 96.390, 1015.0, 31.8591
50.438508344, 96.390, 1086.0, 32.9545
50.491029474, 96.390, 1067.0, 32.6650
50.543550605, 96.390, 1042.0, 32.2800
50.596071736, 96.390, 1028.0, 32.0624
50.648592866, 96.390, 997.0, 31.5753
50.701113997, 96.390, 1041.0, 32.2645
50.753635128, 96.390, 984.0, 31.3688
50.806156258, 96.390, 971.0, 31.1609
50.858677389, 96.390, 966.0, 31.0805
50.911198520, 96.390, 982.0, 31.3369
50.963719651, 96.390, 919.0, 30.3150
51.016240781, 96.390, 1043.0, 32.2955
51.068761912, 96.390, 1007.0, 31.7333
51.121283043, 96.390, 1061.0, 32.5730
51.173804173, 96.390, 975.0, 31.2250
51.226325304, 96.390, 941.0, 30.6757
51.278846435, 96.390, 915.0, 30.2490
51.331367566, 96.390, 874.0, 29.5635
51.383888696, 96.390, 877.0, 29.6142
51.436409827, 96.390, 900.0, 30.0000
51.488930958, 96.390, 892.0, 29.8664
51.541452088, 96.390, 852.0, 29.1890
51.593973219, 96.390, 854.0, 29.2233
51.646494350, 96.390, 847.0, 29.1033
51.699015481, 96.390, 844.0, 29.0517
51.751536611, 96.390, 903.0, 30.0500
51.804057742, 96.390, 917.0, 30.2820
51.856578873, 96.390, 973.0, 31.1929
51.909100003, 96.390, 908.0, 30.1330
51.961621134, 96.390, 893.0, 29.8831
52.014142265, 96.390, 948.0, 30.7896
52.066663396, 96.390, 891.0, 29.8496
52.119184526, 96.390, 887.0, 29.7825
52.171705657, 96.390, 928.0, 30.4631
52.224226788, 96.390, 948.0, 30.7896
52.276747918, 96.390, 953.0, 30.8707
52.329269049, 96.390, 997.0, 31.5753
52.381790180, 96.390, 979.0, 31.2890
52.434311310, 96.390, 1070.0, 32.7109
52.486832441, 96.390, 876.0, 29.5973
52.539353572, 96.390, 986.0, 31.4006
52.591874703, 96.390, 899.0, 29.9833
52.644395833, 96.390, 934.0, 30.5614
52.696916964, 96.390, 874.0, 29.5635
52.749438095, 96.390, 890.0, 29.8329
52.801959225, 96.390, 886.0, 29.7658
52.854480356, 96.390, 847.0, 29.1033
52.907001487, 96.390, 885.0, 29.7489
52.959522618, 96.390, 902.0, 30.0333
53.012043748, 96.390, 863.0, 29.3769
53.064564879, 96.390, 854.0, 29.2233
53.117086010, 96.390, 915.0, 30.2490
53.169607140, 96.390, 913.0, 30.2159
53.222128271, 96.390, 1053.0, 32.4500
53.274649402, 96.390, 873.0, 29.5466
53.327170533, 96.390, 898.0, 29.9666
53.379691663, 96.390, 965.0, 31.0644
53.432212794, 96.390, 920.0, 30.3315
53.484733925, 96.390, 963.0, 31.0322
53.537255055, 96.390, 930.0, 30.4959
53.589776186, 96.390, 912.0, 30.1993
53.642297317, 96.390, 881.0, 29.6816
53.694818448, 96.390, 881.0, 29.6816
53.747339578, 96.390, 838.0, 28.9482
53.799860709, 96.390, 899.0, 29.9833
53.852381840, 96.390, 862.0, 29.3598
53.904902970, 96.390, 969.0, 31.1288
53.957424101, 96.390, 934.0, 30.5614
54.009945232, 96.390, 975.0, 31.2250
54.062466362, 96.390, 967.0, 31.0966
54.114987493, 96.390, 976.0, 31.2410
54.167508624, 96.390, 886.0, 29.7658
54.220029755, 96.390, 954.0, 30.8869
54.272550885, 96.390, 918.0, 30.2985
54.325072016, 96.390, 885.0, 29.7489
54.377593147, 96.390, 932.0, 30.5287
54.430114277, 96.390, 850.0, 29.1548
54.482635408, 96.390, 823.0, 28.6880
54.535156539, 96.390, 803.0, 28.3373
54.587677670, 96.390, 883.0, 29.7153
54.640198800, 96.390, 756.0, 27.4955
54.692719931, 96.390, 795.0, 28.1957
54.745241062, 96.390, 776.0, 27.8568
54.797762192, 96.390, 814.0, 28.5307
54.850283323, 96.390, 786.0, 28.0357
54.902804454, 96.390, 786.0, 28.0357
54.955325585, 96.390, 772.0, 27.7849
55.007846715, 96.390, 865.0, 29.4109
55.060367846, 96.390, 818.0, 28.6007
55.112888977, 96.390, 818.0, 28.6007
55.165410107, 96.390, 799.0, 28.2666
55.217931238, 96.390, 729.0, 27.0000
55.270452369, 96.390, 791.0, 28.1247
55.322973499, 96.390, 842.0, 29.0172
55.375494630, 96.390, 836.0, 28.9137
55.428015761, 96.390, 892.0, 29.8664
55.480536892, 96.390, 955.0, 30.9031
55.533058022, 96.390, 814.0, 28.5307
55.585579153, 96.390, 767.0, 27.6948
55.638100284, 96.390, 806.0, 28.3901
55.690621414, 96.390, 749.0, 27.3679
55.743142545, 96.390, 729.0, 27.0000
55.795663676, 96.390, 727.0, 26.9629
55.848184807, 96.390, 786.0, 28.0357
55.900705937, 96.390, 739.0, 27.1846
55.953227068, 96.390, 763.0, 27.6225
56.005748199, 96.390, 830.0, 28.8097
56.058269329, 96.390, 872.0, 29.5296
56.110790460, 96.390, 835.0, 28.8964
56.163311591, 96.390, 816.0, 28.5657
56.215832722, 96.390, 852.0, 29.1890
56.268353852, 96.390, 796.0, 28.2135
56.320874983, 96.390, 819.0, 28.6182
56.373396114, 96.390, 818.0, 28.6007
56.425917244, 96.390, 762.0, 27.6043
56.478438375, 96.390, 846.0, 29.0861
56.530959506, 96.390, 847.0, 29.1033
56.583480637, 96.390, 829.0, 28.7924
56.636001767, 96.390, 905.0, 30.0832
56.688522898, 96.390, 824.0, 28.7054
56.741044029, 96.390, 758.0, 27.5318
56.793565159, 96.390, 797.0, 28.2312
56.846086290, 96.390, 738.0, 27.1662
56.898607421, 96.390, 736.0, 27.1293
56.951128551, 96.390, 763.0, 27.6225
57.003649682, 96.390, 742.0, 27.2397
57.056170813, 96.390, 774.0, 27.8209
57.108691944, 96.390, 722.0, 26.8701
57.161213074, 96.390, 777.0, 27.8747
57.213734205, 96.390, 814.0, 28.5307
57.266255336, 96.390, 829.0, 28.7924
57.318776466, 96.390, 793.0, 28.1603
57.371297597, 96.390, 817.0, 28.5832
57.423818728, 96.390, 795.0, 28.1957
57.476339859, 96.390, 831.0, 28.8271
57.528860989, 96.390, 869.0, 29.4788
57.581382120, 96.390, 887.0, 29.7825
57.633903251, 96.390, 831.0, 28.8271
57.686424381, 96.390, 864.0, 29.3939
57.738945512, 96.390, 898.0, 29.9666
57.791466643, 96.390, 905.0, 30.0832
57.843987774, 96.390, 830.0, 28.8097
57.896508904, 96.390, 874.0, 29.5635
57.949030035, 96.390, 791.0, 28.1247
58.001551166, 96.390, 807.0, 28.4077
58.054072296, 96.390, 811.0, 28.4781
58.106593427, 96.390, 809.0, 28.4429
58.159114558, 96.390, 794.0, 28.1780
58.211635689, 96.390, 815.0, 28.5482
58.264156819, 96.390, 735.0, 27.1109
58.316677950, 96.390, 767.0, 27.6948
58.369199081, 96.390, 730.0, 27.0185
58.421720211, 96.390, 789.0, 28.0891
58.474241342, 96.390, 755.0, 27.4773
58.526762473, 96.390, 758.0, 27.5318
58.579283603, 96.390, 732.0, 27.0555
58.631804734, 96.390, 695.0, 26.3629
58.684325865, 96.390, 734.0, 27.0924
58.736846996, 96.390, 699.0, 26.4386
58.789368126, 96.390, 685.0, 26.1725
58.841889257, 96.390, 710.0, 26.6458
58.894410388, 96.390, 683.0, 26.1343
58.946931518, 96.390, 720.0, 26.8328
58.999452649, 96.390, 772.0, 27.7849
59.051973780, 96.390, 713.0, 26.7021
59.104494911, 96.390, 718.0, 26.7955
59.157016041, 96.390, 764.0, 27.6405
59.209537172, 96.390, 776.0, 27.8568
59.262058303, 96.390, 752.0, 27.4226
59.314579433, 96.390, 747.0, 27.3313
59.367100564, 96.390, 910.0, 30.1662
59.419621695, 96.390, 781.0, 27.9464
59.472142826, 96.390, 746.0, 27.3130
59.524663956, 96.390, 789.0, 28.0891
59.577185087, 96.390, 780.0, 27.9285
59.629706218, 96.390, 787.0, 28.0535
59.682227348, 96.390, 760.0, 27.5681
59.734748479, 96.390, 801.0, 28.3019
59.787269610, 96.390, 747.0, 27.3313
59.839790740, 96.390, 801.0, 28.3019
59.892311871, 96.390, 761.0, 27.5862
59.944833002, 96.390, 758.0, 27.5318
59.997354133, 96.390, 822.0, 28.6705
60.049875263, 96.390, 754.0, 27.4591
60.102396394, 96.390, 806.0, 28.3901
60.154917525, 96.390, 819.0, 28.6182
60.207438655, 96.390, 870.0, 29.4958
60.259959786, 96.390, 827.0, 28.7576
60.312480917, 96.390, 843.0, 29.0345
60.365002048, 96.390, 864.0, 29.3939
60.417523178, 96.390, 811.0, 28.4781
60.470044309, 96.390, 916.0, 30.2655
60.522565440, 96.390, 958.0, 30.9516
60.575086570, 96.390, 892.0, 29.8664
60.627607701, 96.390, 938.0, 30.6268
60.680128832, 96.390, 916.0, 30.2655
60.732649963, 96.390, 1022.0, 31.9687
60.785171093, 96.390, 1017.0, 31.8904
60.837692224, 96.390, 1059.0, 32.5423
60.890213355, 96.390, 1088.0, 32.9848
60.942734485, 96.390, 1081.0, 32.8786
60.995255616, 96.390, 1082.0, 32.8938
61.047776747, 96.390, 1072.0, 32.7414
61.100297878, 96.390, 1131.0, 33.6303
61.152819008, 96.390, 1191.0, 34.5109
61.205340139, 96.390, 1194.0, 34.5543
61.257861270, 96.390, 1080.0, 32.8634
61.310382400, 96.390, 1094.0, 33.0757
61.362903531, 96.390, 1114.0, 33.3766
61.415424662, 96.390, 1118.0, 33.4365
61.467945792, 96.390, 1070.0, 32.7109
61.520466923, 96.390, 1066.0, 32.6497
61.572988054, 96.390, 1054.0, 32.4654
61.625509185, 96.390, 1050.0, 32.4037
61.678030315, 96.390, 1057.0, 32.5115
61.730551446, 96.390, 1046.0, 32.3419
61.783072577, 96.390, 1047.0, 32.3574
61.835593707, 96.390, 1014.0, 31.8434
61.888114838, 96.390, 1007.0, 31.7333
61.940635969, 96.390, 992.0, 31.4960
61.993157100, 96.390, 970.0, 31.1448
62.045678230, 96.390, 1006.0, 31.7175
62.098199361, 96.390, 942.0, 30.6920
62.150720492, 96.390, 910.0, 30.1662
62.203241622, 96.390, 965.0, 31.0644
62.255762753, 96.390, 991.0, 31.4802
62.308283884, 96.390, 975.0, 31.2250
62.360805015, 96.390, 957.0, 30.9354
62.413326145, 96.390, 954.0, 30.8869
62.465847276, 96.390, 942.0, 30.6920
62.518368407, 96.390, 963.0, 31.0322
62.570889537, 96.390, 908.0, 30.1330
62.623410668, 96.390, 913.0, 30.2159
62.675931799, 96.390, 788.0, 28.0713
62.728452930, 96.390, 810.0, 28.4605
62.780974060, 96.390, 839.0, 28.9655
62.833495191, 96.390, 824.0, 28.7054
62.886016322, 96.390, 838.0, 28.9482
62.938537452, 96.390, 830.0, 28.8097
62.991058583, 96.390, 756.0, 27.4955
63.043579714, 96.390, 767.0, 27.6948
63.096100844, 96.390, 750.0, 27.3861
63.148621975, 96.390, 737.0, 27.1477
63.201143106, 96.390, 776.0, 27.8568
63.253664237, 96.390, 728.0, 26.9815
63.306185367, 96.390, 775.0, 27.8388
63.358706498, 96.390, 832.0, 28.8444
63.411227629, 96.390, 749.0, 27.3679
63.463748759, 96.390, 734.0, 27.0924
63.516269890, 96.390, 740.0, 27.2029
63.568791021, 96.390, 788.0, 28.0713
63.621312152, 96.390, 695.0, 26.3629
63.673833282, 96.390, 701.0, 26.4764
63.726354413, 96.390, 684.0, 26.1534
63.778875544, 96.390, 748.0, 27.3496
63.831396674, 96.390, 721.0, 26.8514
63.883917805, 96.390, 731.0, 27.0370
63.936438936, 96.390, 740.0, 27.2029
63.988960067, 96.390, 798.0, 28.2489
64.041481197, 96.390, 711.0, 26.6646
64.094002328, 96.390, 728.0, 26.9815
64.146523459, 96.390, 802.0, 28.3196
64.199044589, 96.390, 755.0, 27.4773
64.251565720, 96.390, 735.0, 27.1109
64.304086851, 96.390, 729.0, 27.0000
64.356607981, 96.390, 712.0, 26.6833
64.409129112, 96.390, 694.0, 26.3439
64.461650243, 96.390, 684.0, 26.1534
64.514171374, 96.390, 703.0, 26.5141
64.566692504, 96.390, 626.0, 25.0200
64.619213635, 96.390, 643.0, 25.3574
64.671734766, 96.390, 643.0, 25.3574
64.724255896, 96.390, 635.0, 25.1992
64.776777027, 96.390, 666.0, 25.8070
64.829298158, 96.390, 654.0, 25.5734
64.881819289, 96.390, 592.0, 24.3311
64.934340419, 96.390, 688.0, 26.2298
64.986861550, 96.390, 632.0, 25.1396