File: Files_organized_for_plots/Constant_NaOH_1mL10M_to_1gPC/xXRD_P04Free14Apr22_Act18Apr22_B2_1000M_NaOH_LS0133_1.csv
[Measurement conditions]
Sample identification,XRD_P04Free14Apr22_Act18Apr22_B2_1000M_NaOH_LS0133_1
Comment - 1,"Configuration=Stage for Flat Samples/Holders, Owner=User-1, Creation date=7/1/2020 9:53:24 AM"
Comment - 2,"Goniometer=Theta/Theta; Minimum step size 2Theta:0.0001; Minimum step size Omega:0.0001"
Comment - 3,"Sample stage=Stage for flat samples/holders"
Comment - 4,"Diffractometer system=EMPYREAN"
Comment - 5,"Measurement program=C:\Users\ibo5034\OneDrive - The Pennsylvania State University\NEUP\Zerobackground scan.xrdmp, Identifier={98A3B11C-88F9-4AA6-982C-73314A311EF5}"
Anode material,Cu
K-Alpha1 wavelength,1.5405980
K-Alpha2 wavelength,1.5444260
Ratio K-Alpha2/K-Alpha1,0.500
Divergence slit,Fixed,0.25
Monochromator used,NO
Generator voltage, 45
Tube current, 40
File date and time,21/Apr/2022 17:13
Unit cell,
h k l, 0 0 0
Scan axis,Gonio
Scan range,4.994599997,64.999991833
Scan step size,0.0262606
No. of points, 2285
Scan type,CONTINUOUS
Time per step,96.390
[Scan points]
Angle, TimePerStep, Intensity, ESD
5.007730280, 96.390, 5070.0, 71.2039
5.060251411, 96.390, 5000.0, 70.7107
5.112772541, 96.390, 4819.0, 69.4190
5.165293672, 96.390, 4892.0, 69.9428
5.217814803, 96.390, 4963.0, 70.4486
5.270335934, 96.390, 4938.0, 70.2709
5.322857064, 96.390, 4817.0, 69.4046
5.375378195, 96.390, 4971.0, 70.5053
5.427899326, 96.390, 5129.0, 71.6170
5.480420456, 96.390, 5198.0, 72.0972
5.532941587, 96.390, 5293.0, 72.7530
5.585462718, 96.390, 5679.0, 75.3591
5.637983849, 96.390, 5770.0, 75.9605
5.690504979, 96.390, 6065.0, 77.8781
5.743026110, 96.390, 6263.0, 79.1391
5.795547241, 96.390, 6416.0, 80.0999
5.848068371, 96.390, 6364.0, 79.7747
5.900589502, 96.390, 6191.0, 78.6829
5.953110633, 96.390, 6050.0, 77.7817
6.005631763, 96.390, 6056.0, 77.8203
6.058152894, 96.390, 6124.0, 78.2560
6.110674025, 96.390, 6083.0, 77.9936
6.163195156, 96.390, 6089.0, 78.0320
6.215716286, 96.390, 5828.0, 76.3413
6.268237417, 96.390, 6080.0, 77.9744
6.320758548, 96.390, 5898.0, 76.7984
6.373279678, 96.390, 5789.0, 76.0855
6.425800809, 96.390, 5657.0, 75.2130
6.478321940, 96.390, 5651.0, 75.1731
6.530843071, 96.390, 5655.0, 75.1997
6.583364201, 96.390, 5344.0, 73.1027
6.635885332, 96.390, 5238.0, 72.3740
6.688406463, 96.390, 5199.0, 72.1041
6.740927593, 96.390, 5075.0, 71.2390
6.793448724, 96.390, 4928.0, 70.1997
6.845969855, 96.390, 4975.0, 70.5337
6.898490986, 96.390, 4727.0, 68.7532
6.951012116, 96.390, 4703.0, 68.5784
7.003533247, 96.390, 4588.0, 67.7348
7.056054378, 96.390, 4590.0, 67.7495
7.108575508, 96.390, 4529.0, 67.2978
7.161096639, 96.390, 4359.0, 66.0227
7.213617770, 96.390, 4419.0, 66.4756
7.266138900, 96.390, 4315.0, 65.6887
7.318660031, 96.390, 4193.0, 64.7534
7.371181162, 96.390, 4148.0, 64.4050
7.423702293, 96.390, 4179.0, 64.6452
7.476223423, 96.390, 3967.0, 62.9841
7.528744554, 96.390, 3936.0, 62.7375
7.581265685, 96.390, 3996.0, 63.2139
7.633786815, 96.390, 3791.0, 61.5711
7.686307946, 96.390, 3699.0, 60.8194
7.738829077, 96.390, 3645.0, 60.3738
7.791350208, 96.390, 3570.0, 59.7495
7.843871338, 96.390, 3648.0, 60.3987
7.896392469, 96.390, 3617.0, 60.1415
7.948913600, 96.390, 3495.0, 59.1185
8.001434730, 96.390, 3440.0, 58.6515
8.053955861, 96.390, 3438.0, 58.6345
8.106476992, 96.390, 3475.0, 58.9491
8.158998123, 96.390, 3393.0, 58.2495
8.211519253, 96.390, 3200.0, 56.5685
8.264040384, 96.390, 3379.0, 58.1292
8.316561515, 96.390, 3341.0, 57.8014
8.369082645, 96.390, 3320.0, 57.6194
8.421603776, 96.390, 3211.0, 56.6657
8.474124907, 96.390, 3265.0, 57.1402
8.526646038, 96.390, 3199.0, 56.5597
8.579167168, 96.390, 3041.0, 55.1453
8.631688299, 96.390, 3164.0, 56.2494
8.684209430, 96.390, 3174.0, 56.3383
8.736730560, 96.390, 3108.0, 55.7494
8.789251691, 96.390, 3187.0, 56.4535
8.841772822, 96.390, 3158.0, 56.1961
8.894293952, 96.390, 3124.0, 55.8928
8.946815083, 96.390, 3025.0, 55.0000
8.999336214, 96.390, 3037.0, 55.1090
9.051857345, 96.390, 3121.0, 55.8659
9.104378475, 96.390, 3140.0, 56.0357
9.156899606, 96.390, 3142.0, 56.0535
9.209420737, 96.390, 2922.0, 54.0555
9.261941867, 96.390, 2988.0, 54.6626
9.314462998, 96.390, 3086.0, 55.5518
9.366984129, 96.390, 3150.0, 56.1249
9.419505260, 96.390, 3123.0, 55.8838
9.472026390, 96.390, 3132.0, 55.9643
9.524547521, 96.390, 3193.0, 56.5066
9.577068652, 96.390, 3138.0, 56.0179
9.629589782, 96.390, 3166.0, 56.2672
9.682110913, 96.390, 3288.0, 57.3411
9.734632044, 96.390, 3238.0, 56.9034
9.787153175, 96.390, 3446.0, 58.7026
9.839674305, 96.390, 3637.0, 60.3075
9.892195436, 96.390, 3567.0, 59.7244
9.944716567, 96.390, 3678.0, 60.6465
9.997237697, 96.390, 3769.0, 61.3922
10.049758828, 96.390, 3646.0, 60.3821
10.102279959, 96.390, 3554.0, 59.6154
10.154801090, 96.390, 3572.0, 59.7662
10.207322220, 96.390, 3514.0, 59.2790
10.259843351, 96.390, 3429.0, 58.5577
10.312364482, 96.390, 3411.0, 58.4038
10.364885612, 96.390, 3374.0, 58.0861
10.417406743, 96.390, 3400.0, 58.3095
10.469927874, 96.390, 3449.0, 58.7282
10.522449004, 96.390, 3538.0, 59.4811
10.574970135, 96.390, 3459.0, 58.8133
10.627491266, 96.390, 3542.0, 59.5147
10.680012397, 96.390, 3624.0, 60.1997
10.732533527, 96.390, 3569.0, 59.7411
10.785054658, 96.390, 3527.0, 59.3886
10.837575789, 96.390, 3594.0, 59.9500
10.890096919, 96.390, 3665.0, 60.5392
10.942618050, 96.390, 3716.0, 60.9590
10.995139181, 96.390, 3630.0, 60.2495
11.047660312, 96.390, 3794.0, 61.5955
11.100181442, 96.390, 3754.0, 61.2699
11.152702573, 96.390, 3761.0, 61.3270
11.205223704, 96.390, 3778.0, 61.4654
11.257744834, 96.390, 3739.0, 61.1474
11.310265965, 96.390, 3774.0, 61.4329
11.362787096, 96.390, 3851.0, 62.0564
11.415308227, 96.390, 3835.0, 61.9274
11.467829357, 96.390, 3883.0, 62.3137
11.520350488, 96.390, 3797.0, 61.6198
11.572871619, 96.390, 3888.0, 62.3538
11.625392749, 96.390, 3868.0, 62.1932
11.677913880, 96.390, 3873.0, 62.2334
11.730435011, 96.390, 3930.0, 62.6897
11.782956141, 96.390, 3869.0, 62.2013
11.835477272, 96.390, 3887.0, 62.3458
11.887998403, 96.390, 3784.0, 61.5142
11.940519534, 96.390, 3746.0, 61.2046
11.993040664, 96.390, 3552.0, 59.5987
12.045561795, 96.390, 3512.0, 59.2621
12.098082926, 96.390, 3459.0, 58.8133
12.150604056, 96.390, 3358.0, 57.9483
12.203125187, 96.390, 3306.0, 57.4978
12.255646318, 96.390, 3220.0, 56.7450
12.308167449, 96.390, 3165.0, 56.2583
12.360688579, 96.390, 3083.0, 55.5248
12.413209710, 96.390, 3148.0, 56.1070
12.465730841, 96.390, 2818.0, 53.0848
12.518251971, 96.390, 2871.0, 53.5817
12.570773102, 96.390, 2862.0, 53.4977
12.623294233, 96.390, 2753.0, 52.4690
12.675815364, 96.390, 2692.0, 51.8845
12.728336494, 96.390, 2630.0, 51.2835
12.780857625, 96.390, 2729.0, 52.2398
12.833378756, 96.390, 2551.0, 50.5074
12.885899886, 96.390, 2617.0, 51.1566
12.938421017, 96.390, 2490.0, 49.8999
12.990942148, 96.390, 2360.0, 48.5798
13.043463279, 96.390, 2384.0, 48.8262
13.095984409, 96.390, 2425.0, 49.2443
13.148505540, 96.390, 2323.0, 48.1975
13.201026671, 96.390, 2293.0, 47.8853
13.253547801, 96.390, 2327.0, 48.2390
13.306068932, 96.390, 2363.0, 48.6107
13.358590063, 96.390, 2258.0, 47.5184
13.411111193, 96.390, 2232.0, 47.2440
13.463632324, 96.390, 2306.0, 48.0208
13.516153455, 96.390, 2247.0, 47.4025
13.568674586, 96.390, 2235.0, 47.2758
13.621195716, 96.390, 2156.0, 46.4327
13.673716847, 96.390, 2173.0, 46.6154
13.726237978, 96.390, 2122.0, 46.0652
13.778759108, 96.390, 2152.0, 46.3897
13.831280239, 96.390, 2191.0, 46.8081
13.883801370, 96.390, 2158.0, 46.4543
13.936322501, 96.390, 2128.0, 46.1303
13.988843631, 96.390, 2148.0, 46.3465
14.041364762, 96.390, 2185.0, 46.7440
14.093885893, 96.390, 2162.0, 46.4973
14.146407023, 96.390, 2073.0, 45.5302
14.198928154, 96.390, 2151.0, 46.3789
14.251449285, 96.390, 2058.0, 45.3652
14.303970416, 96.390, 2051.0, 45.2880
14.356491546, 96.390, 2067.0, 45.4643
14.409012677, 96.390, 2029.0, 45.0444
14.461533808, 96.390, 1968.0, 44.3621
14.514054938, 96.390, 1974.0, 44.4297
14.566576069, 96.390, 1954.0, 44.2041
14.619097200, 96.390, 1926.0, 43.8862
14.671618331, 96.390, 2043.0, 45.1996
14.724139461, 96.390, 1965.0, 44.3283
14.776660592, 96.390, 2067.0, 45.4643
14.829181723, 96.390, 2049.0, 45.2659
14.881702853, 96.390, 2094.0, 45.7602
14.934223984, 96.390, 2091.0, 45.7275
14.986745115, 96.390, 2172.0, 46.6047
15.039266245, 96.390, 2105.0, 45.8803
15.091787376, 96.390, 2201.0, 46.9148
15.144308507, 96.390, 2368.0, 48.6621
15.196829638, 96.390, 2466.0, 49.6588
15.249350768, 96.390, 2750.0, 52.4404
15.301871899, 96.390, 2759.0, 52.5262
15.354393030, 96.390, 2762.0, 52.5547
15.406914160, 96.390, 2749.0, 52.4309
15.459435291, 96.390, 2723.0, 52.1824
15.511956422, 96.390, 2629.0, 51.2738
15.564477553, 96.390, 2578.0, 50.7740
15.616998683, 96.390, 2411.0, 49.1019
15.669519814, 96.390, 2387.0, 48.8569
15.722040945, 96.390, 2228.0, 47.2017
15.774562075, 96.390, 2211.0, 47.0213
15.827083206, 96.390, 2160.0, 46.4758
15.879604337, 96.390, 2041.0, 45.1774
15.932125468, 96.390, 2041.0, 45.1774
15.984646598, 96.390, 1979.0, 44.4860
16.037167729, 96.390, 1947.0, 44.1248
16.089688860, 96.390, 1969.0, 44.3734
16.142209990, 96.390, 1941.0, 44.0568
16.194731121, 96.390, 1956.0, 44.2267
16.247252252, 96.390, 1897.0, 43.5546
16.299773382, 96.390, 1851.0, 43.0232
16.352294513, 96.390, 1863.0, 43.1625
16.404815644, 96.390, 1824.0, 42.7083
16.457336775, 96.390, 1843.0, 42.9302
16.509857905, 96.390, 1905.0, 43.6463
16.562379036, 96.390, 1820.0, 42.6615
16.614900167, 96.390, 1746.0, 41.7852
16.667421297, 96.390, 1799.0, 42.4146
16.719942428, 96.390, 1755.0, 41.8927
16.772463559, 96.390, 1782.0, 42.2137
16.824984690, 96.390, 1753.0, 41.8688
16.877505820, 96.390, 1809.0, 42.5323
16.930026951, 96.390, 1816.0, 42.6146
16.982548082, 96.390, 1768.0, 42.0476
17.035069212, 96.390, 1728.0, 41.5692
17.087590343, 96.390, 1796.0, 42.3792
17.140111474, 96.390, 1802.0, 42.4500
17.192632605, 96.390, 1750.0, 41.8330
17.245153735, 96.390, 1735.0, 41.6533
17.297674866, 96.390, 1702.0, 41.2553
17.350195997, 96.390, 1688.0, 41.0853
17.402717127, 96.390, 1807.0, 42.5088
17.455238258, 96.390, 1768.0, 42.0476
17.507759389, 96.390, 1792.0, 42.3320
17.560280520, 96.390, 1757.0, 41.9166
17.612801650, 96.390, 1667.0, 40.8289
17.665322781, 96.390, 1723.0, 41.5090
17.717843912, 96.390, 1652.0, 40.6448
17.770365042, 96.390, 1725.0, 41.5331
17.822886173, 96.390, 1727.0, 41.5572
17.875407304, 96.390, 1806.0, 42.4971
17.927928434, 96.390, 1702.0, 41.2553
17.980449565, 96.390, 1807.0, 42.5088
18.032970696, 96.390, 1814.0, 42.5911
18.085491827, 96.390, 1790.0, 42.3084
18.138012957, 96.390, 1739.0, 41.7013
18.190534088, 96.390, 1664.0, 40.7922
18.243055219, 96.390, 1777.0, 42.1545
18.295576349, 96.390, 1770.0, 42.0714
18.348097480, 96.390, 1779.0, 42.1782
18.400618611, 96.390, 1829.0, 42.7668
18.453139742, 96.390, 1820.0, 42.6615
18.505660872, 96.390, 1875.0, 43.3013
18.558182003, 96.390, 1866.0, 43.1972
18.610703134, 96.390, 1741.0, 41.7253
18.663224264, 96.390, 1807.0, 42.5088
18.715745395, 96.390, 1896.0, 43.5431
18.768266526, 96.390, 1691.0, 41.1218
18.820787657, 96.390, 1698.0, 41.2068
18.873308787, 96.390, 1783.0, 42.2256
18.925829918, 96.390, 1805.0, 42.4853
18.978351049, 96.390, 1833.0, 42.8135
19.030872179, 96.390, 1786.0, 42.2611
19.083393310, 96.390, 1747.0, 41.7971
19.135914441, 96.390, 1864.0, 43.1741
19.188435572, 96.390, 1736.0, 41.6653
19.240956702, 96.390, 1881.0, 43.3705
19.293477833, 96.390, 1870.0, 43.2435
19.345998964, 96.390, 1877.0, 43.3244
19.398520094, 96.390, 1822.0, 42.6849
19.451041225, 96.390, 1941.0, 44.0568
19.503562356, 96.390, 1791.0, 42.3202
19.556083486, 96.390, 1926.0, 43.8862
19.608604617, 96.390, 1870.0, 43.2435
19.661125748, 96.390, 1911.0, 43.7150
19.713646879, 96.390, 1944.0, 44.0908
19.766168009, 96.390, 1915.0, 43.7607
19.818689140, 96.390, 2055.0, 45.3321
19.871210271, 96.390, 2092.0, 45.7384
19.923731401, 96.390, 2061.0, 45.3982
19.976252532, 96.390, 2264.0, 47.5815
20.028773663, 96.390, 2317.0, 48.1352
20.081294794, 96.390, 2320.0, 48.1664
20.133815924, 96.390, 2221.0, 47.1275
20.186337055, 96.390, 2195.0, 46.8508
20.238858186, 96.390, 2118.0, 46.0217
20.291379316, 96.390, 1921.0, 43.8292
20.343900447, 96.390, 1941.0, 44.0568
20.396421578, 96.390, 1957.0, 44.2380
20.448942709, 96.390, 1880.0, 43.3590
20.501463839, 96.390, 1860.0, 43.1277
20.553984970, 96.390, 1895.0, 43.5316
20.606506101, 96.390, 1892.0, 43.4971
20.659027231, 96.390, 1865.0, 43.1856
20.711548362, 96.390, 1874.0, 43.2897
20.764069493, 96.390, 1888.0, 43.4511
20.816590623, 96.390, 1936.0, 44.0000
20.869111754, 96.390, 1976.0, 44.4522
20.921632885, 96.390, 1992.0, 44.6318
20.974154016, 96.390, 1938.0, 44.0227
21.026675146, 96.390, 1939.0, 44.0341
21.079196277, 96.390, 1995.0, 44.6654
21.131717408, 96.390, 1906.0, 43.6578
21.184238538, 96.390, 1993.0, 44.6430
21.236759669, 96.390, 1908.0, 43.6807
21.289280800, 96.390, 1890.0, 43.4741
21.341801931, 96.390, 1936.0, 44.0000
21.394323061, 96.390, 1990.0, 44.6094
21.446844192, 96.390, 2028.0, 45.0333
21.499365323, 96.390, 2071.0, 45.5082
21.551886453, 96.390, 1945.0, 44.1022
21.604407584, 96.390, 2078.0, 45.5851
21.656928715, 96.390, 2089.0, 45.7056
21.709449846, 96.390, 2072.0, 45.5192
21.761970976, 96.390, 2061.0, 45.3982
21.814492107, 96.390, 2109.0, 45.9239
21.867013238, 96.390, 2135.0, 46.2061
21.919534368, 96.390, 2095.0, 45.7712
21.972055499, 96.390, 2046.0, 45.2327
22.024576630, 96.390, 2196.0, 46.8615
22.077097761, 96.390, 2140.0, 46.2601
22.129618891, 96.390, 2183.0, 46.7226
22.182140022, 96.390, 2227.0, 47.1911
22.234661153, 96.390, 2252.0, 47.4552
22.287182283, 96.390, 2283.0, 47.7807
22.339703414, 96.390, 2485.0, 49.8498
22.392224545, 96.390, 2350.0, 48.4768
22.444745675, 96.390, 2368.0, 48.6621
22.497266806, 96.390, 2486.0, 49.8598
22.549787937, 96.390, 2584.0, 50.8331
22.602309068, 96.390, 2668.0, 51.6527
22.654830198, 96.390, 2589.0, 50.8822
22.707351329, 96.390, 2737.0, 52.3163
22.759872460, 96.390, 2712.0, 52.0769
22.812393590, 96.390, 2792.0, 52.8394
22.864914721, 96.390, 2847.0, 53.3573
22.917435852, 96.390, 3074.0, 55.4437
22.969956983, 96.390, 3094.0, 55.6237
23.022478113, 96.390, 3230.0, 56.8331
23.074999244, 96.390, 3367.0, 58.0259
23.127520375, 96.390, 3616.0, 60.1332
23.180041505, 96.390, 3781.0, 61.4898
23.232562636, 96.390, 3873.0, 62.2334
23.285083767, 96.390, 3933.0, 62.7136
23.337604898, 96.390, 3741.0, 61.1637
23.390126028, 96.390, 3608.0, 60.0666
23.442647159, 96.390, 3562.0, 59.6825
23.495168290, 96.390, 3294.0, 57.3934
23.547689420, 96.390, 3291.0, 57.3672
23.600210551, 96.390, 3165.0, 56.2583
23.652731682, 96.390, 3174.0, 56.3383
23.705252813, 96.390, 2957.0, 54.3783
23.757773943, 96.390, 2835.0, 53.2447
23.810295074, 96.390, 2891.0, 53.7680
23.862816205, 96.390, 2734.0, 52.2877
23.915337335, 96.390, 2599.0, 50.9804
23.967858466, 96.390, 2629.0, 51.2738
24.020379597, 96.390, 2567.0, 50.6656
24.072900727, 96.390, 2446.0, 49.4571
24.125421858, 96.390, 2406.0, 49.0510
24.177942989, 96.390, 2501.0, 50.0100
24.230464120, 96.390, 2401.0, 49.0000
24.282985250, 96.390, 2361.0, 48.5901
24.335506381, 96.390, 2341.0, 48.3839
24.388027512, 96.390, 2362.0, 48.6004
24.440548642, 96.390, 2272.0, 47.6655
24.493069773, 96.390, 2369.0, 48.6724
24.545590904, 96.390, 2240.0, 47.3286
24.598112035, 96.390, 2154.0, 46.4112
24.650633165, 96.390, 2161.0, 46.4866
24.703154296, 96.390, 2153.0, 46.4004
24.755675427, 96.390, 2114.0, 45.9783
24.808196557, 96.390, 2033.0, 45.0888
24.860717688, 96.390, 2060.0, 45.3872
24.913238819, 96.390, 2025.0, 45.0000
24.965759950, 96.390, 1922.0, 43.8406
25.018281080, 96.390, 1921.0, 43.8292
25.070802211, 96.390, 1969.0, 44.3734
25.123323342, 96.390, 1948.0, 44.1362
25.175844472, 96.390, 1982.0, 44.5197
25.228365603, 96.390, 1888.0, 43.4511
25.280886734, 96.390, 1926.0, 43.8862
25.333407864, 96.390, 1934.0, 43.9773
25.385928995, 96.390, 1868.0, 43.2204
25.438450126, 96.390, 1960.0, 44.2719
25.490971257, 96.390, 1864.0, 43.1741
25.543492387, 96.390, 1893.0, 43.5086
25.596013518, 96.390, 1905.0, 43.6463
25.648534649, 96.390, 1953.0, 44.1928
25.701055779, 96.390, 1809.0, 42.5323
25.753576910, 96.390, 1973.0, 44.4185
25.806098041, 96.390, 1905.0, 43.6463
25.858619172, 96.390, 1998.0, 44.6990
25.911140302, 96.390, 1974.0, 44.4297
25.963661433, 96.390, 2051.0, 45.2880
26.016182564, 96.390, 2043.0, 45.1996
26.068703694, 96.390, 2017.0, 44.9110
26.121224825, 96.390, 2099.0, 45.8148
26.173745956, 96.390, 2149.0, 46.3573
26.226267087, 96.390, 2206.0, 46.9681
26.278788217, 96.390, 2269.0, 47.6340
26.331309348, 96.390, 2272.0, 47.6655
26.383830479, 96.390, 2344.0, 48.4149
26.436351609, 96.390, 2488.0, 49.8799
26.488872740, 96.390, 2589.0, 50.8822
26.541393871, 96.390, 2663.0, 51.6043
26.593915002, 96.390, 2848.0, 53.3667
26.646436132, 96.390, 3074.0, 55.4437
26.698957263, 96.390, 2932.0, 54.1479
26.751478394, 96.390, 2681.0, 51.7784
26.803999524, 96.390, 2619.0, 51.1762
26.856520655, 96.390, 2434.0, 49.3356
26.909041786, 96.390, 2251.0, 47.4447
26.961562916, 96.390, 2289.0, 47.8435
27.014084047, 96.390, 2095.0, 45.7712
27.066605178, 96.390, 2069.0, 45.4863
27.119126309, 96.390, 2103.0, 45.8585
27.171647439, 96.390, 2059.0, 45.3762
27.224168570, 96.390, 2042.0, 45.1885
27.276689701, 96.390, 1941.0, 44.0568
27.329210831, 96.390, 1928.0, 43.9090
27.381731962, 96.390, 2020.0, 44.9444
27.434253093, 96.390, 1988.0, 44.5870
27.486774224, 96.390, 1987.0, 44.5758
27.539295354, 96.390, 1943.0, 44.0795
27.591816485, 96.390, 1924.0, 43.8634
27.644337616, 96.390, 1889.0, 43.4626
27.696858746, 96.390, 1917.0, 43.7836
27.749379877, 96.390, 1793.0, 42.3438
27.801901008, 96.390, 1895.0, 43.5316
27.854422139, 96.390, 1929.0, 43.9204
27.906943269, 96.390, 1849.0, 43.0000
27.959464400, 96.390, 1985.0, 44.5533
28.011985531, 96.390, 1998.0, 44.6990
28.064506661, 96.390, 1884.0, 43.4051
28.117027792, 96.390, 2041.0, 45.1774
28.169548923, 96.390, 2009.0, 44.8219
28.222070054, 96.390, 1864.0, 43.1741
28.274591184, 96.390, 1952.0, 44.1814
28.327112315, 96.390, 1922.0, 43.8406
28.379633446, 96.390, 1919.0, 43.8064
28.432154576, 96.390, 1989.0, 44.5982
28.484675707, 96.390, 1955.0, 44.2154
28.537196838, 96.390, 2007.0, 44.7996
28.589717968, 96.390, 2035.0, 45.1110
28.642239099, 96.390, 1963.0, 44.3058
28.694760230, 96.390, 2018.0, 44.9222
28.747281361, 96.390, 2136.0, 46.2169
28.799802491, 96.390, 2083.0, 45.6399
28.852323622, 96.390, 2232.0, 47.2440
28.904844753, 96.390, 2102.0, 45.8476
28.957365883, 96.390, 2200.0, 46.9042
29.009887014, 96.390, 2381.0, 48.7955
29.062408145, 96.390, 2238.0, 47.3075
29.114929276, 96.390, 2389.0, 48.8774
29.167450406, 96.390, 2415.0, 49.1426
29.219971537, 96.390, 2443.0, 49.4267
29.272492668, 96.390, 2456.0, 49.5580
29.325013798, 96.390, 2430.0, 49.2950
29.377534929, 96.390, 2519.0, 50.1896
29.430056060, 96.390, 2349.0, 48.4665
29.482577191, 96.390, 2378.0, 48.7647
29.535098321, 96.390, 2281.0, 47.7598
29.587619452, 96.390, 2296.0, 47.9166
29.640140583, 96.390, 2316.0, 48.1248
29.692661713, 96.390, 2316.0, 48.1248
29.745182844, 96.390, 2332.0, 48.2908
29.797703975, 96.390, 2219.0, 47.1063
29.850225105, 96.390, 2210.0, 47.0106
29.902746236, 96.390, 2329.0, 48.2597
29.955267367, 96.390, 2292.0, 47.8748
30.007788498, 96.390, 2434.0, 49.3356
30.060309628, 96.390, 2286.0, 47.8121
30.112830759, 96.390, 2537.0, 50.3686
30.165351890, 96.390, 2476.0, 49.7594
30.217873020, 96.390, 2460.0, 49.5984
30.270394151, 96.390, 2540.0, 50.3984
30.322915282, 96.390, 2500.0, 50.0000
30.375436413, 96.390, 2472.0, 49.7192
30.427957543, 96.390, 2696.0, 51.9230
30.480478674, 96.390, 2621.0, 51.1957
30.532999805, 96.390, 2816.0, 53.0660
30.585520935, 96.390, 2788.0, 52.8015
30.638042066, 96.390, 2882.0, 53.6843
30.690563197, 96.390, 2873.0, 53.6004
30.743084328, 96.390, 3005.0, 54.8179
30.795605458, 96.390, 3067.0, 55.3805
30.848126589, 96.390, 3070.0, 55.4076
30.900647720, 96.390, 3186.0, 56.4447
30.953168850, 96.390, 3170.0, 56.3028
31.005689981, 96.390, 2960.0, 54.4059
31.058211112, 96.390, 3014.0, 54.8999
31.110732243, 96.390, 2874.0, 53.6097
31.163253373, 96.390, 2942.0, 54.2402
31.215774504, 96.390, 2746.0, 52.4023
31.268295635, 96.390, 2738.0, 52.3259
31.320816765, 96.390, 2675.0, 51.7204
31.373337896, 96.390, 2601.0, 51.0000
31.425859027, 96.390, 2670.0, 51.6720
31.478380157, 96.390, 2568.0, 50.6754
31.530901288, 96.390, 2475.0, 49.7494
31.583422419, 96.390, 2439.0, 49.3862
31.635943550, 96.390, 2374.0, 48.7237
31.688464680, 96.390, 2381.0, 48.7955
31.740985811, 96.390, 2440.0, 49.3964
31.793506942, 96.390, 2469.0, 49.6890
31.846028072, 96.390, 2385.0, 48.8365
31.898549203, 96.390, 2452.0, 49.5177
31.951070334, 96.390, 2472.0, 49.7192
32.003591465, 96.390, 2361.0, 48.5901
32.056112595, 96.390, 2367.0, 48.6518
32.108633726, 96.390, 2271.0, 47.6550
32.161154857, 96.390, 2289.0, 47.8435
32.213675987, 96.390, 2294.0, 47.8957
32.266197118, 96.390, 2195.0, 46.8508
32.318718249, 96.390, 2249.0, 47.4236
32.371239380, 96.390, 2213.0, 47.0425
32.423760510, 96.390, 2198.0, 46.8828
32.476281641, 96.390, 2167.0, 46.5510
32.528802772, 96.390, 2163.0, 46.5081
32.581323902, 96.390, 2216.0, 47.0744
32.633845033, 96.390, 2126.0, 46.1086
32.686366164, 96.390, 2016.0, 44.8999
32.738887295, 96.390, 2109.0, 45.9239
32.791408425, 96.390, 2053.0, 45.3100
32.843929556, 96.390, 2052.0, 45.2990
32.896450687, 96.390, 2071.0, 45.5082
32.948971817, 96.390, 2061.0, 45.3982
33.001492948, 96.390, 1988.0, 44.5870
33.054014079, 96.390, 2034.0, 45.0999
33.106535209, 96.390, 2054.0, 45.3211
33.159056340, 96.390, 2032.0, 45.0777
33.211577471, 96.390, 2089.0, 45.7056
33.264098602, 96.390, 2102.0, 45.8476
33.316619732, 96.390, 2152.0, 46.3897
33.369140863, 96.390, 2150.0, 46.3681
33.421661994, 96.390, 2169.0, 46.5725
33.474183124, 96.390, 2230.0, 47.2229
33.526704255, 96.390, 2211.0, 47.0213
33.579225386, 96.390, 2241.0, 47.3392
33.631746517, 96.390, 2214.0, 47.0532
33.684267647, 96.390, 2225.0, 47.1699
33.736788778, 96.390, 2250.0, 47.4342
33.789309909, 96.390, 2191.0, 46.8081
33.841831039, 96.390, 2291.0, 47.8644
33.894352170, 96.390, 2227.0, 47.1911
33.946873301, 96.390, 2194.0, 46.8402
33.999394432, 96.390, 2262.0, 47.5605
34.051915562, 96.390, 2340.0, 48.3735
34.104436693, 96.390, 2374.0, 48.7237
34.156957824, 96.390, 2399.0, 48.9796
34.209478954, 96.390, 2426.0, 49.2544
34.262000085, 96.390, 2508.0, 50.0799
34.314521216, 96.390, 2525.0, 50.2494
34.367042346, 96.390, 2620.0, 51.1859
34.419563477, 96.390, 2531.0, 50.3090
34.472084608, 96.390, 2612.0, 51.1077
34.524605739, 96.390, 2666.0, 51.6333
34.577126869, 96.390, 2660.0, 51.5752
34.629648000, 96.390, 2693.0, 51.8941
34.682169131, 96.390, 2762.0, 52.5547
34.734690261, 96.390, 2724.0, 52.1920
34.787211392, 96.390, 2728.0, 52.2303
34.839732523, 96.390, 2615.0, 51.1371
34.892253654, 96.390, 2599.0, 50.9804
34.944774784, 96.390, 2595.0, 50.9411
34.997295915, 96.390, 2487.0, 49.8698
35.049817046, 96.390, 2567.0, 50.6656
35.102338176, 96.390, 2506.0, 50.0600
35.154859307, 96.390, 2490.0, 49.8999
35.207380438, 96.390, 2397.0, 48.9592
35.259901569, 96.390, 2521.0, 50.2096
35.312422699, 96.390, 2297.0, 47.9270
35.364943830, 96.390, 2317.0, 48.1352
35.417464961, 96.390, 2287.0, 47.8226
35.469986091, 96.390, 2233.0, 47.2546
35.522507222, 96.390, 2206.0, 46.9681
35.575028353, 96.390, 2200.0, 46.9042
35.627549484, 96.390, 2215.0, 47.0638
35.680070614, 96.390, 2150.0, 46.3681
35.732591745, 96.390, 2183.0, 46.7226
35.785112876, 96.390, 2070.0, 45.4973
35.837634006, 96.390, 2032.0, 45.0777
35.890155137, 96.390, 1968.0, 44.3621
35.942676268, 96.390, 1982.0, 44.5197
35.995197398, 96.390, 2024.0, 44.9889
36.047718529, 96.390, 2048.0, 45.2548
36.100239660, 96.390, 1936.0, 44.0000
36.152760791, 96.390, 2064.0, 45.4313
36.205281921, 96.390, 1990.0, 44.6094
36.257803052, 96.390, 2071.0, 45.5082
36.310324183, 96.390, 1953.0, 44.1928
36.362845313, 96.390, 1901.0, 43.6005
36.415366444, 96.390, 1998.0, 44.6990
36.467887575, 96.390, 2013.0, 44.8665
36.520408706, 96.390, 1888.0, 43.4511
36.572929836, 96.390, 1949.0, 44.1475
36.625450967, 96.390, 1910.0, 43.7035
36.677972098, 96.390, 1938.0, 44.0227
36.730493228, 96.390, 1861.0, 43.1393
36.783014359, 96.390, 1941.0, 44.0568
36.835535490, 96.390, 1859.0, 43.1161
36.888056621, 96.390, 1919.0, 43.8064
36.940577751, 96.390, 1913.0, 43.7379
36.993098882, 96.390, 1893.0, 43.5086
37.045620013, 96.390, 1794.0, 42.3556
37.098141143, 96.390, 1888.0, 43.4511
37.150662274, 96.390, 1885.0, 43.4166
37.203183405, 96.390, 1880.0, 43.3590
37.255704535, 96.390, 1834.0, 42.8252
37.308225666, 96.390, 1908.0, 43.6807
37.360746797, 96.390, 1906.0, 43.6578
37.413267928, 96.390, 1893.0, 43.5086
37.465789058, 96.390, 1883.0, 43.3935
37.518310189, 96.390, 1885.0, 43.4166
37.570831320, 96.390, 1893.0, 43.5086
37.623352450, 96.390, 1809.0, 42.5323
37.675873581, 96.390, 1754.0, 41.8808
37.728394712, 96.390, 1786.0, 42.2611
37.780915843, 96.390, 1886.0, 43.4281
37.833436973, 96.390, 1858.0, 43.1045
37.885958104, 96.390, 1890.0, 43.4741
37.938479235, 96.390, 1862.0, 43.1509
37.991000365, 96.390, 1867.0, 43.2088
38.043521496, 96.390, 1819.0, 42.6497
38.096042627, 96.390, 1805.0, 42.4853
38.148563758, 96.390, 1747.0, 41.7971
38.201084888, 96.390, 1751.0, 41.8450
38.253606019, 96.390, 1729.0, 41.5812
38.306127150, 96.390, 1729.0, 41.5812
38.358648280, 96.390, 1742.0, 41.7373
38.411169411, 96.390, 1652.0, 40.6448
38.463690542, 96.390, 1817.0, 42.6263
38.516211673, 96.390, 1769.0, 42.0595
38.568732803, 96.390, 1679.0, 40.9756
38.621253934, 96.390, 1637.0, 40.4599
38.673775065, 96.390, 1688.0, 41.0853
38.726296195, 96.390, 1660.0, 40.7431
38.778817326, 96.390, 1638.0, 40.4722
38.831338457, 96.390, 1596.0, 39.9500
38.883859587, 96.390, 1599.0, 39.9875
38.936380718, 96.390, 1709.0, 41.3401
38.988901849, 96.390, 1675.0, 40.9268
39.041422980, 96.390, 1722.0, 41.4970
39.093944110, 96.390, 1639.0, 40.4846
39.146465241, 96.390, 1611.0, 40.1373
39.198986372, 96.390, 1544.0, 39.2938
39.251507502, 96.390, 1644.0, 40.5463
39.304028633, 96.390, 1550.0, 39.3700
39.356549764, 96.390, 1585.0, 39.8121
39.409070895, 96.390, 1601.0, 40.0125
39.461592025, 96.390, 1616.0, 40.1995
39.514113156, 96.390, 1645.0, 40.5586
39.566634287, 96.390, 1575.0, 39.6863
39.619155417, 96.390, 1558.0, 39.4715
39.671676548, 96.390, 1593.0, 39.9124
39.724197679, 96.390, 1586.0, 39.8246
39.776718810, 96.390, 1629.0, 40.3609
39.829239940, 96.390, 1575.0, 39.6863
39.881761071, 96.390, 1515.0, 38.9230
39.934282202, 96.390, 1566.0, 39.5727
39.986803332, 96.390, 1560.0, 39.4968
40.039324463, 96.390, 1533.0, 39.1535
40.091845594, 96.390, 1560.0, 39.4968
40.144366725, 96.390, 1565.0, 39.5601
40.196887855, 96.390, 1536.0, 39.1918
40.249408986, 96.390, 1595.0, 39.9375
40.301930117, 96.390, 1536.0, 39.1918
40.354451247, 96.390, 1474.0, 38.3927
40.406972378, 96.390, 1550.0, 39.3700
40.459493509, 96.390, 1597.0, 39.9625
40.512014639, 96.390, 1571.0, 39.6358
40.564535770, 96.390, 1552.0, 39.3954
40.617056901, 96.390, 1632.0, 40.3980
40.669578032, 96.390, 1622.0, 40.2741
40.722099162, 96.390, 1715.0, 41.4126
40.774620293, 96.390, 1743.0, 41.7493
40.827141424, 96.390, 1747.0, 41.7971
40.879662554, 96.390, 1658.0, 40.7185
40.932183685, 96.390, 1670.0, 40.8656
40.984704816, 96.390, 1638.0, 40.4722
41.037225947, 96.390, 1535.0, 39.1791
41.089747077, 96.390, 1639.0, 40.4846
41.142268208, 96.390, 1661.0, 40.7554
41.194789339, 96.390, 1651.0, 40.6325
41.247310469, 96.390, 1627.0, 40.3361
41.299831600, 96.390, 1574.0, 39.6737
41.352352731, 96.390, 1646.0, 40.5709
41.404873862, 96.390, 1586.0, 39.8246
41.457394992, 96.390, 1605.0, 40.0625
41.509916123, 96.390, 1585.0, 39.8121
41.562437254, 96.390, 1474.0, 38.3927
41.614958384, 96.390, 1608.0, 40.0999
41.667479515, 96.390, 1543.0, 39.2810
41.720000646, 96.390, 1514.0, 38.9102
41.772521776, 96.390, 1455.0, 38.1445
41.825042907, 96.390, 1519.0, 38.9744
41.877564038, 96.390, 1481.0, 38.4838
41.930085169, 96.390, 1425.0, 37.7492
41.982606299, 96.390, 1418.0, 37.6563
42.035127430, 96.390, 1463.0, 38.2492
42.087648561, 96.390, 1425.0, 37.7492
42.140169691, 96.390, 1457.0, 38.1707
42.192690822, 96.390, 1506.0, 38.8072
42.245211953, 96.390, 1409.0, 37.5366
42.297733084, 96.390, 1415.0, 37.6165
42.350254214, 96.390, 1386.0, 37.2290
42.402775345, 96.390, 1422.0, 37.7094
42.455296476, 96.390, 1493.0, 38.6394
42.507817606, 96.390, 1436.0, 37.8946
42.560338737, 96.390, 1457.0, 38.1707
42.612859868, 96.390, 1458.0, 38.1838
42.665380999, 96.390, 1390.0, 37.2827
42.717902129, 96.390, 1422.0, 37.7094
42.770423260, 96.390, 1401.0, 37.4299
42.822944391, 96.390, 1419.0, 37.6696
42.875465521, 96.390, 1423.0, 37.7227
42.927986652, 96.390, 1386.0, 37.2290
42.980507783, 96.390, 1362.0, 36.9053
43.033028914, 96.390, 1354.0, 36.7967
43.085550044, 96.390, 1357.0, 36.8375
43.138071175, 96.390, 1348.0, 36.7151
43.190592306, 96.390, 1312.0, 36.2215
43.243113436, 96.390, 1351.0, 36.7560
43.295634567, 96.390, 1311.0, 36.2077
43.348155698, 96.390, 1301.0, 36.0694
43.400676828, 96.390, 1252.0, 35.3836
43.453197959, 96.390, 1228.0, 35.0428
43.505719090, 96.390, 1212.0, 34.8138
43.558240221, 96.390, 1258.0, 35.4683
43.610761351, 96.390, 1247.0, 35.3129
43.663282482, 96.390, 1195.0, 34.5688
43.715803613, 96.390, 1233.0, 35.1141
43.768324743, 96.390, 1236.0, 35.1568
43.820845874, 96.390, 1239.0, 35.1994
43.873367005, 96.390, 1292.0, 35.9444
43.925888136, 96.390, 1211.0, 34.7994
43.978409266, 96.390, 1238.0, 35.1852
44.030930397, 96.390, 1170.0, 34.2053
44.083451528, 96.390, 1159.0, 34.0441
44.135972658, 96.390, 1136.0, 33.7046
44.188493789, 96.390, 1193.0, 34.5398
44.241014920, 96.390, 1145.0, 33.8378
44.293536051, 96.390, 1162.0, 34.0881
44.346057181, 96.390, 1182.0, 34.3802
44.398578312, 96.390, 1193.0, 34.5398
44.451099443, 96.390, 1202.0, 34.6699
44.503620573, 96.390, 1216.0, 34.8712
44.556141704, 96.390, 1208.0, 34.7563
44.608662835, 96.390, 1200.0, 34.6410
44.661183966, 96.390, 1228.0, 35.0428
44.713705096, 96.390, 1219.0, 34.9142
44.766226227, 96.390, 1270.0, 35.6371
44.818747358, 96.390, 1184.0, 34.4093
44.871268488, 96.390, 1271.0, 35.6511
44.923789619, 96.390, 1277.0, 35.7351
44.976310750, 96.390, 1230.0, 35.0714
45.028831880, 96.390, 1264.0, 35.5528
45.081353011, 96.390, 1348.0, 36.7151
45.133874142, 96.390, 1284.0, 35.8329
45.186395273, 96.390, 1246.0, 35.2987
45.238916403, 96.390, 1207.0, 34.7419
45.291437534, 96.390, 1232.0, 35.0999
45.343958665, 96.390, 1275.0, 35.7071
45.396479795, 96.390, 1208.0, 34.7563
45.449000926, 96.390, 1248.0, 35.3270
45.501522057, 96.390, 1246.0, 35.2987
45.554043188, 96.390, 1246.0, 35.2987
45.606564318, 96.390, 1300.0, 36.0555
45.659085449, 96.390, 1319.0, 36.3180
45.711606580, 96.390, 1297.0, 36.0139
45.764127710, 96.390, 1277.0, 35.7351
45.816648841, 96.390, 1308.0, 36.1663
45.869169972, 96.390, 1283.0, 35.8190
45.921691103, 96.390, 1339.0, 36.5923
45.974212233, 96.390, 1243.0, 35.2562
46.026733364, 96.390, 1291.0, 35.9305
46.079254495, 96.390, 1266.0, 35.5809
46.131775625, 96.390, 1287.0, 35.8748
46.184296756, 96.390, 1317.0, 36.2905
46.236817887, 96.390, 1353.0, 36.7831
46.289339017, 96.390, 1350.0, 36.7423
46.341860148, 96.390, 1366.0, 36.9594
46.394381279, 96.390, 1325.0, 36.4005
46.446902410, 96.390, 1324.0, 36.3868
46.499423540, 96.390, 1232.0, 35.0999
46.551944671, 96.390, 1390.0, 37.2827
46.604465802, 96.390, 1298.0, 36.0278
46.656986932, 96.390, 1296.0, 36.0000
46.709508063, 96.390, 1288.0, 35.8887
46.762029194, 96.390, 1270.0, 35.6371
46.814550325, 96.390, 1317.0, 36.2905
46.867071455, 96.390, 1329.0, 36.4555
46.919592586, 96.390, 1297.0, 36.0139
46.972113717, 96.390, 1251.0, 35.3695
47.024634847, 96.390, 1258.0, 35.4683
47.077155978, 96.390, 1267.0, 35.5949
47.129677109, 96.390, 1256.0, 35.4401
47.182198240, 96.390, 1292.0, 35.9444
47.234719370, 96.390, 1387.0, 37.2424
47.287240501, 96.390, 1208.0, 34.7563
47.339761632, 96.390, 1228.0, 35.0428
47.392282762, 96.390, 1248.0, 35.3270
47.444803893, 96.390, 1226.0, 35.0143
47.497325024, 96.390, 1211.0, 34.7994
47.549846155, 96.390, 1163.0, 34.1028
47.602367285, 96.390, 1124.0, 33.5261
47.654888416, 96.390, 1112.0, 33.3467
47.707409547, 96.390, 1134.0, 33.6749
47.759930677, 96.390, 1142.0, 33.7935
47.812451808, 96.390, 1103.0, 33.2114
47.864972939, 96.390, 1104.0, 33.2265
47.917494069, 96.390, 1136.0, 33.7046
47.970015200, 96.390, 1125.0, 33.5410
48.022536331, 96.390, 1140.0, 33.7639
48.075057462, 96.390, 1080.0, 32.8634
48.127578592, 96.390, 1174.0, 34.2637
48.180099723, 96.390, 1156.0, 34.0000
48.232620854, 96.390, 1072.0, 32.7414
48.285141984, 96.390, 1091.0, 33.0303
48.337663115, 96.390, 1096.0, 33.1059
48.390184246, 96.390, 1088.0, 32.9848
48.442705377, 96.390, 1060.0, 32.5576
48.495226507, 96.390, 1105.0, 33.2415
48.547747638, 96.390, 1058.0, 32.5269
48.600268769, 96.390, 1072.0, 32.7414
48.652789899, 96.390, 1116.0, 33.4066
48.705311030, 96.390, 1081.0, 32.8786
48.757832161, 96.390, 1005.0, 31.7017
48.810353292, 96.390, 1074.0, 32.7719
48.862874422, 96.390, 1001.0, 31.6386
48.915395553, 96.390, 1015.0, 31.8591
48.967916684, 96.390, 1053.0, 32.4500
49.020437814, 96.390, 1059.0, 32.5423
49.072958945, 96.390, 1060.0, 32.5576
49.125480076, 96.390, 1058.0, 32.5269
49.178001207, 96.390, 1005.0, 31.7017
49.230522337, 96.390, 943.0, 30.7083
49.283043468, 96.390, 1018.0, 31.9061
49.335564599, 96.390, 1053.0, 32.4500
49.388085729, 96.390, 1011.0, 31.7962
49.440606860, 96.390, 1035.0, 32.1714
49.493127991, 96.390, 1058.0, 32.5269
49.545649121, 96.390, 1040.0, 32.2490
49.598170252, 96.390, 925.0, 30.4138
49.650691383, 96.390, 1052.0, 32.4345
49.703212514, 96.390, 1002.0, 31.6544
49.755733644, 96.390, 1025.0, 32.0156
49.808254775, 96.390, 1027.0, 32.0468
49.860775906, 96.390, 964.0, 31.0483
49.913297036, 96.390, 961.0, 31.0000
49.965818167, 96.390, 994.0, 31.5278
50.018339298, 96.390, 1024.0, 32.0000
50.070860429, 96.390, 942.0, 30.6920
50.123381559, 96.390, 977.0, 31.2570
50.175902690, 96.390, 1020.0, 31.9374
50.228423821, 96.390, 959.0, 30.9677
50.280944951, 96.390, 995.0, 31.5436
50.333466082, 96.390, 953.0, 30.8707
50.385987213, 96.390, 948.0, 30.7896
50.438508344, 96.390, 905.0, 30.0832
50.491029474, 96.390, 993.0, 31.5119
50.543550605, 96.390, 980.0, 31.3050
50.596071736, 96.390, 919.0, 30.3150
50.648592866, 96.390, 982.0, 31.3369
50.701113997, 96.390, 1064.0, 32.6190
50.753635128, 96.390, 993.0, 31.5119
50.806156258, 96.390, 958.0, 30.9516
50.858677389, 96.390, 998.0, 31.5911
50.911198520, 96.390, 1082.0, 32.8938
50.963719651, 96.390, 1064.0, 32.6190
51.016240781, 96.390, 1102.0, 33.1964
51.068761912, 96.390, 973.0, 31.1929
51.121283043, 96.390, 1036.0, 32.1870
51.173804173, 96.390, 992.0, 31.4960
51.226325304, 96.390, 1016.0, 31.8748
51.278846435, 96.390, 992.0, 31.4960
51.331367566, 96.390, 1015.0, 31.8591
51.383888696, 96.390, 1024.0, 32.0000
51.436409827, 96.390, 1019.0, 31.9218
51.488930958, 96.390, 983.0, 31.3528
51.541452088, 96.390, 1066.0, 32.6497
51.593973219, 96.390, 1057.0, 32.5115
51.646494350, 96.390, 1119.0, 33.4515
51.699015481, 96.390, 1098.0, 33.1361
51.751536611, 96.390, 1030.0, 32.0936
51.804057742, 96.390, 993.0, 31.5119
51.856578873, 96.390, 979.0, 31.2890
51.909100003, 96.390, 1003.0, 31.6702
51.961621134, 96.390, 1019.0, 31.9218
52.014142265, 96.390, 948.0, 30.7896
52.066663396, 96.390, 938.0, 30.6268
52.119184526, 96.390, 988.0, 31.4325
52.171705657, 96.390, 1012.0, 31.8119
52.224226788, 96.390, 956.0, 30.9192
52.276747918, 96.390, 1006.0, 31.7175
52.329269049, 96.390, 989.0, 31.4484
52.381790180, 96.390, 1007.0, 31.7333
52.434311310, 96.390, 974.0, 31.2090
52.486832441, 96.390, 970.0, 31.1448
52.539353572, 96.390, 958.0, 30.9516
52.591874703, 96.390, 1011.0, 31.7962
52.644395833, 96.390, 1048.0, 32.3728
52.696916964, 96.390, 975.0, 31.2250
52.749438095, 96.390, 993.0, 31.5119
52.801959225, 96.390, 977.0, 31.2570
52.854480356, 96.390, 1017.0, 31.8904
52.907001487, 96.390, 982.0, 31.3369
52.959522618, 96.390, 1040.0, 32.2490
53.012043748, 96.390, 1043.0, 32.2955
53.064564879, 96.390, 1038.0, 32.2180
53.117086010, 96.390, 1106.0, 33.2566
53.169607140, 96.390, 1055.0, 32.4808
53.222128271, 96.390, 1087.0, 32.9697
53.274649402, 96.390, 1069.0, 32.6956
53.327170533, 96.390, 959.0, 30.9677
53.379691663, 96.390, 959.0, 30.9677
53.432212794, 96.390, 996.0, 31.5595
53.484733925, 96.390, 976.0, 31.2410
53.537255055, 96.390, 926.0, 30.4302
53.589776186, 96.390, 929.0, 30.4795
53.642297317, 96.390, 920.0, 30.3315
53.694818448, 96.390, 959.0, 30.9677
53.747339578, 96.390, 887.0, 29.7825
53.799860709, 96.390, 881.0, 29.6816
53.852381840, 96.390, 886.0, 29.7658
53.904902970, 96.390, 838.0, 28.9482
53.957424101, 96.390, 918.0, 30.2985
54.009945232, 96.390, 908.0, 30.1330
54.062466362, 96.390, 865.0, 29.4109
54.114987493, 96.390, 876.0, 29.5973
54.167508624, 96.390, 827.0, 28.7576
54.220029755, 96.390, 868.0, 29.4618
54.272550885, 96.390, 912.0, 30.1993
54.325072016, 96.390, 895.0, 29.9166
54.377593147, 96.390, 849.0, 29.1376
54.430114277, 96.390, 896.0, 29.9333
54.482635408, 96.390, 903.0, 30.0500
54.535156539, 96.390, 897.0, 29.9500
54.587677670, 96.390, 954.0, 30.8869
54.640198800, 96.390, 877.0, 29.6142
54.692719931, 96.390, 892.0, 29.8664
54.745241062, 96.390, 864.0, 29.3939
54.797762192, 96.390, 818.0, 28.6007
54.850283323, 96.390, 860.0, 29.3258
54.902804454, 96.390, 842.0, 29.0172
54.955325585, 96.390, 851.0, 29.1719
55.007846715, 96.390, 866.0, 29.4279
55.060367846, 96.390, 923.0, 30.3809
55.112888977, 96.390, 819.0, 28.6182
55.165410107, 96.390, 864.0, 29.3939
55.217931238, 96.390, 896.0, 29.9333
55.270452369, 96.390, 838.0, 28.9482
55.322973499, 96.390, 864.0, 29.3939
55.375494630, 96.390, 846.0, 29.0861
55.428015761, 96.390, 764.0, 27.6405
55.480536892, 96.390, 833.0, 28.8617
55.533058022, 96.390, 854.0, 29.2233
55.585579153, 96.390, 902.0, 30.0333
55.638100284, 96.390, 857.0, 29.2746
55.690621414, 96.390, 820.0, 28.6356
55.743142545, 96.390, 838.0, 28.9482
55.795663676, 96.390, 786.0, 28.0357
55.848184807, 96.390, 847.0, 29.1033
55.900705937, 96.390, 848.0, 29.1204
55.953227068, 96.390, 840.0, 28.9828
56.005748199, 96.390, 886.0, 29.7658
56.058269329, 96.390, 779.0, 27.9106
56.110790460, 96.390, 827.0, 28.7576
56.163311591, 96.390, 847.0, 29.1033
56.215832722, 96.390, 873.0, 29.5466
56.268353852, 96.390, 834.0, 28.8791
56.320874983, 96.390, 822.0, 28.6705
56.373396114, 96.390, 834.0, 28.8791
56.425917244, 96.390, 845.0, 29.0689
56.478438375, 96.390, 891.0, 29.8496
56.530959506, 96.390, 824.0, 28.7054
56.583480637, 96.390, 840.0, 28.9828
56.636001767, 96.390, 897.0, 29.9500
56.688522898, 96.390, 830.0, 28.8097
56.741044029, 96.390, 886.0, 29.7658
56.793565159, 96.390, 883.0, 29.7153
56.846086290, 96.390, 926.0, 30.4302
56.898607421, 96.390, 887.0, 29.7825
56.951128551, 96.390, 873.0, 29.5466
57.003649682, 96.390, 909.0, 30.1496
57.056170813, 96.390, 820.0, 28.6356
57.108691944, 96.390, 843.0, 29.0345
57.161213074, 96.390, 917.0, 30.2820
57.213734205, 96.390, 925.0, 30.4138
57.266255336, 96.390, 966.0, 31.0805
57.318776466, 96.390, 977.0, 31.2570
57.371297597, 96.390, 1016.0, 31.8748
57.423818728, 96.390, 980.0, 31.3050
57.476339859, 96.390, 980.0, 31.3050
57.528860989, 96.390, 937.0, 30.6105
57.581382120, 96.390, 911.0, 30.1828
57.633903251, 96.390, 903.0, 30.0500
57.686424381, 96.390, 928.0, 30.4631
57.738945512, 96.390, 878.0, 29.6311
57.791466643, 96.390, 920.0, 30.3315
57.843987774, 96.390, 875.0, 29.5804
57.896508904, 96.390, 900.0, 30.0000
57.949030035, 96.390, 898.0, 29.9666
58.001551166, 96.390, 828.0, 28.7750
58.054072296, 96.390, 871.0, 29.5127
58.106593427, 96.390, 858.0, 29.2916
58.159114558, 96.390, 860.0, 29.3258
58.211635689, 96.390, 867.0, 29.4449
58.264156819, 96.390, 855.0, 29.2404
58.316677950, 96.390, 918.0, 30.2985
58.369199081, 96.390, 896.0, 29.9333
58.421720211, 96.390, 937.0, 30.6105
58.474241342, 96.390, 934.0, 30.5614
58.526762473, 96.390, 921.0, 30.3480
58.579283603, 96.390, 956.0, 30.9192
58.631804734, 96.390, 892.0, 29.8664
58.684325865, 96.390, 927.0, 30.4467
58.736846996, 96.390, 916.0, 30.2655
58.789368126, 96.390, 908.0, 30.1330
58.841889257, 96.390, 885.0, 29.7489
58.894410388, 96.390, 1025.0, 32.0156
58.946931518, 96.390, 910.0, 30.1662
58.999452649, 96.390, 950.0, 30.8221
59.051973780, 96.390, 884.0, 29.7321
59.104494911, 96.390, 937.0, 30.6105
59.157016041, 96.390, 900.0, 30.0000
59.209537172, 96.390, 995.0, 31.5436
59.262058303, 96.390, 959.0, 30.9677
59.314579433, 96.390, 903.0, 30.0500
59.367100564, 96.390, 1012.0, 31.8119
59.419621695, 96.390, 995.0, 31.5436
59.472142826, 96.390, 1042.0, 32.2800
59.524663956, 96.390, 1030.0, 32.0936
59.577185087, 96.390, 981.0, 31.3209
59.629706218, 96.390, 1042.0, 32.2800
59.682227348, 96.390, 1019.0, 31.9218
59.734748479, 96.390, 1066.0, 32.6497
59.787269610, 96.390, 1129.0, 33.6006
59.839790740, 96.390, 1128.0, 33.5857
59.892311871, 96.390, 1107.0, 33.2716
59.944833002, 96.390, 1112.0, 33.3467
59.997354133, 96.390, 1155.0, 33.9853
60.049875263, 96.390, 1198.0, 34.6121
60.102396394, 96.390, 1166.0, 34.1467
60.154917525, 96.390, 1152.0, 33.9411
60.207438655, 96.390, 1207.0, 34.7419
60.259959786, 96.390, 1250.0, 35.3553
60.312480917, 96.390, 1269.0, 35.6230
60.365002048, 96.390, 1320.0, 36.3318
60.417523178, 96.390, 1298.0, 36.0278
60.470044309, 96.390, 1387.0, 37.2424
60.522565440, 96.390, 1420.0, 37.6829
60.575086570, 96.390, 1442.0, 37.9737
60.627607701, 96.390, 1418.0, 37.6563
60.680128832, 96.390, 1413.0, 37.5899
60.732649963, 96.390, 1329.0, 36.4555
60.785171093, 96.390, 1344.0, 36.6606
60.837692224, 96.390, 1445.0, 38.0132
60.890213355, 96.390, 1295.0, 35.9861
60.942734485, 96.390, 1318.0, 36.3043
60.995255616, 96.390, 1289.0, 35.9026
61.047776747, 96.390, 1296.0, 36.0000
61.100297878, 96.390, 1253.0, 35.3977
61.152819008, 96.390, 1199.0, 34.6266
61.205340139, 96.390, 1196.0, 34.5832
61.257861270, 96.390, 1104.0, 33.2265
61.310382400, 96.390, 1149.0, 33.8969
61.362903531, 96.390, 1129.0, 33.6006
61.415424662, 96.390, 1162.0, 34.0881
61.467945792, 96.390, 1134.0, 33.6749
61.520466923, 96.390, 1130.0, 33.6155
61.572988054, 96.390, 1118.0, 33.4365
61.625509185, 96.390, 1088.0, 32.9848
61.678030315, 96.390, 1140.0, 33.7639
61.730551446, 96.390, 1109.0, 33.3017
61.783072577, 96.390, 1099.0, 33.1512
61.835593707, 96.390, 1048.0, 32.3728
61.888114838, 96.390, 1138.0, 33.7343
61.940635969, 96.390, 1142.0, 33.7935
61.993157100, 96.390, 1124.0, 33.5261
62.045678230, 96.390, 1128.0, 33.5857
62.098199361, 96.390, 1068.0, 32.6803
62.150720492, 96.390, 1066.0, 32.6497
62.203241622, 96.390, 1049.0, 32.3883
62.255762753, 96.390, 1015.0, 31.8591
62.308283884, 96.390, 1087.0, 32.9697
62.360805015, 96.390, 990.0, 31.4643
62.413326145, 96.390, 1020.0, 31.9374
62.465847276, 96.390, 976.0, 31.2410
62.518368407, 96.390, 949.0, 30.8058
62.570889537, 96.390, 921.0, 30.3480
62.623410668, 96.390, 958.0, 30.9516
62.675931799, 96.390, 913.0, 30.2159
62.728452930, 96.390, 875.0, 29.5804
62.780974060, 96.390, 938.0, 30.6268
62.833495191, 96.390, 919.0, 30.3150
62.886016322, 96.390, 983.0, 31.3528
62.938537452, 96.390, 901.0, 30.0167
62.991058583, 96.390, 927.0, 30.4467
63.043579714, 96.390, 882.0, 29.6985
63.096100844, 96.390, 891.0, 29.8496
63.148621975, 96.390, 932.0, 30.5287
63.201143106, 96.390, 898.0, 29.9666
63.253664237, 96.390, 820.0, 28.6356
63.306185367, 96.390, 860.0, 29.3258
63.358706498, 96.390, 815.0, 28.5482
63.411227629, 96.390, 775.0, 27.8388
63.463748759, 96.390, 796.0, 28.2135
63.516269890, 96.390, 812.0, 28.4956
63.568791021, 96.390, 820.0, 28.6356
63.621312152, 96.390, 808.0, 28.4253
63.673833282, 96.390, 764.0, 27.6405
63.726354413, 96.390, 740.0, 27.2029
63.778875544, 96.390, 786.0, 28.0357
63.831396674, 96.390, 818.0, 28.6007
63.883917805, 96.390, 763.0, 27.6225
63.936438936, 96.390, 752.0, 27.4226
63.988960067, 96.390, 780.0, 27.9285
64.041481197, 96.390, 771.0, 27.7669
64.094002328, 96.390, 728.0, 26.9815
64.146523459, 96.390, 793.0, 28.1603
64.199044589, 96.390, 745.0, 27.2947
64.251565720, 96.390, 741.0, 27.2213
64.304086851, 96.390, 716.0, 26.7582
64.356607981, 96.390, 673.0, 25.9422
64.409129112, 96.390, 707.0, 26.5895
64.461650243, 96.390, 740.0, 27.2029
64.514171374, 96.390, 710.0, 26.6458
64.566692504, 96.390, 673.0, 25.9422
64.619213635, 96.390, 637.0, 25.2389
64.671734766, 96.390, 722.0, 26.8701
64.724255896, 96.390, 660.0, 25.6905
64.776777027, 96.390, 669.0, 25.8650
64.829298158, 96.390, 656.0, 25.6125
64.881819289, 96.390, 642.0, 25.3377
64.934340419, 96.390, 660.0, 25.6905
64.986861550, 96.390, 658.0, 25.6515