File: Files_organized_for_plots/Constant_NaOH_1mL10M_to_1gPC/yXRD_Centroid20Oct21_Act27Oct21_B1_0714M_NaOH_LS0173_1.csv
[Measurement conditions],,,
Sample identification,MNASPH_CentroidPC25Oct21_Act27Oct21,,
Comment - 1,Exposed to air for long period,,
Comment - 2,"Configuration=Stage for Flat Samples/Holders, Owner=User-1, Creation date=7/1/2020 9:53:24 AM",,
Comment - 3,Goniometer=Theta/Theta; Minimum step size 2Theta:0.0001; Minimum step size Omega:0.0001,,
Comment - 4,Sample stage=Stage for flat samples/holders,,
Comment - 5,Diffractometer system=EMPYREAN,,
Anode material,Cu,,
K-Alpha1 wavelength,1.540598,,
K-Alpha2 wavelength,1.544426,,
Ratio K-Alpha2/K-Alpha1,0.5,,
Divergence slit,Fixed,0.25,
Monochromator used,NO,,
Generator voltage,45,,
Tube current,40,,
File date and time,11/15/2021 15:40,,
Unit cell,,,
h k l, 0 0 0,,
Scan axis,Gonio,,
Scan range,4.994599997,64.99999183,
Scan step size,0.0262606,,
No. of points,2285,,
Scan type,CONTINUOUS,,
Time per step,96.39,,
[Scan points],,,
Angle, TimePerStep, Intensity, ESD
5.00773028,96.39,4740,68.8477
5.060251411,96.39,4789,69.2026
5.112772541,96.39,4661,68.2715
5.165293672,96.39,4542,67.3944
5.217814803,96.39,4497,67.0597
5.270335934,96.39,4509,67.1491
5.322857064,96.39,4476,66.9029
5.375378195,96.39,4413,66.4304
5.427899326,96.39,4452,66.7233
5.480420456,96.39,4382,66.1967
5.532941587,96.39,4424,66.5132
5.585462718,96.39,4414,66.4379
5.637983849,96.39,4355,65.9924
5.690504979,96.39,4304,65.6049
5.74302611,96.39,4430,66.5582
5.795547241,96.39,4380,66.1816
5.848068371,96.39,4150,64.4205
5.900589502,96.39,4239,65.1076
5.953110633,96.39,4239,65.1076
6.005631763,96.39,4164,64.5291
6.058152894,96.39,4242,65.1306
6.110674025,96.39,4250,65.192
6.163195156,96.39,4201,64.8151
6.215716286,96.39,4280,65.4217
6.268237417,96.39,4189,64.7225
6.320758548,96.39,4197,64.7843
6.373279678,96.39,4106,64.0781
6.425800809,96.39,4243,65.1383
6.47832194,96.39,4222,64.9769
6.530843071,96.39,4149,64.4127
6.583364201,96.39,4106,64.0781
6.635885332,96.39,4044,63.5925
6.688406463,96.39,4193,64.7534
6.740927593,96.39,4111,64.1171
6.793448724,96.39,4087,63.9296
6.845969855,96.39,4057,63.6946
6.898490986,96.39,4087,63.9296
6.951012116,96.39,3977,63.0635
7.003533247,96.39,4064,63.7495
7.056054378,96.39,4094,63.9844
7.108575508,96.39,4169,64.5678
7.161096639,96.39,3934,62.7216
7.21361777,96.39,3964,62.9603
7.2661389,96.39,3997,63.2218
7.318660031,96.39,3916,62.578
7.371181162,96.39,4013,63.3482
7.423702293,96.39,3978,63.0714
7.476223423,96.39,3902,62.466
7.528744554,96.39,3941,62.7774
7.581265685,96.39,3914,62.562
7.633786815,96.39,3875,62.2495
7.686307946,96.39,3849,62.0403
7.738829077,96.39,3967,62.9841
7.791350208,96.39,3868,62.1932
7.843871338,96.39,3872,62.2254
7.896392469,96.39,3817,61.7819
7.9489136,96.39,3917,62.5859
8.00143473,96.39,3959,62.9206
8.053955861,96.39,3811,61.7333
8.106476992,96.39,3883,62.3137
8.158998123,96.39,3901,62.458
8.211519253,96.39,3806,61.6928
8.264040384,96.39,3842,61.9839
8.316561515,96.39,3756,61.2862
8.369082645,96.39,3781,61.4898
8.421603776,96.39,3701,60.8358
8.474124907,96.39,3804,61.6766
8.526646038,96.39,3902,62.466
8.579167168,96.39,3807,61.7009
8.631688299,96.39,3790,61.563
8.68420943,96.39,3939,62.7615
8.73673056,96.39,3963,62.9524
8.789251691,96.39,3620,60.1664
8.841772822,96.39,3681,60.6712
8.894293952,96.39,3736,61.1228
8.946815083,96.39,3707,60.8851
8.999336214,96.39,3627,60.2246
9.051857345,96.39,3598,59.9833
9.104378475,96.39,3665,60.5392
9.156899606,96.39,3668,60.564
9.209420737,96.39,3676,60.63
9.261941867,96.39,3597,59.975
9.314462998,96.39,3575,59.7913
9.366984129,96.39,3720,60.9918
9.41950526,96.39,3586,59.8832
9.47202639,96.39,3669,60.5723
9.524547521,96.39,3617,60.1415
9.577068652,96.39,3593,59.9416
9.629589782,96.39,3497,59.1354
9.682110913,96.39,3679,60.6548
9.734632044,96.39,3613,60.1082
9.787153175,96.39,3592,59.9333
9.839674305,96.39,3572,59.7662
9.892195436,96.39,3505,59.203
9.944716567,96.39,3587,59.8916
9.997237697,96.39,3557,59.6406
10.04975883,96.39,3646,60.3821
10.10227996,96.39,3619,60.1581
10.15480109,96.39,3714,60.9426
10.20732222,96.39,3602,60.0167
10.25984335,96.39,3704,60.8605
10.31236448,96.39,3839,61.9597
10.36488561,96.39,4133,64.2884
10.41740674,96.39,5743,75.7826
10.46992787,96.39,11470,107.0981
10.522449,96.39,4829,69.491
10.57497014,96.39,3631,60.2578
10.62749127,96.39,3446,58.7026
10.6800124,96.39,3499,59.1523
10.73253353,96.39,3487,59.0508
10.78505466,96.39,3461,58.8303
10.83757579,96.39,3400,58.3095
10.89009692,96.39,3619,60.1581
10.94261805,96.39,3615,60.1249
10.99513918,96.39,4052,63.6553
11.04766031,96.39,4630,68.0441
11.10018144,96.39,3424,58.515
11.15270257,96.39,3369,58.0431
11.2052237,96.39,3325,57.6628
11.25774483,96.39,3346,57.8446
11.31026597,96.39,3334,57.7408
11.3627871,96.39,3297,57.4195
11.41530823,96.39,3185,56.4358
11.46782936,96.39,3284,57.3062
11.52035049,96.39,3330,57.7062
11.57287162,96.39,3228,56.8155
11.62539275,96.39,3204,56.6039
11.67791388,96.39,3250,57.0088
11.73043501,96.39,3258,57.0789
11.78295614,96.39,3048,55.2087
11.83547727,96.39,3074,55.4437
11.8879984,96.39,3131,55.9553
11.94051953,96.39,3161,56.2228
11.99304066,96.39,3003,54.7996
12.0455618,96.39,3220,56.745
12.09808293,96.39,3059,55.3082
12.15060406,96.39,2950,54.3139
12.20312519,96.39,2945,54.2679
12.25564632,96.39,2983,54.6168
12.30816745,96.39,2915,53.9907
12.36068858,96.39,2903,53.8795
12.41320971,96.39,2886,53.7215
12.46573084,96.39,2990,54.6809
12.51825197,96.39,2832,53.2165
12.5707731,96.39,2795,52.8678
12.62329423,96.39,2838,53.2729
12.67581536,96.39,2777,52.6972
12.72833649,96.39,2732,52.2685
12.78085763,96.39,2886,53.7215
12.83337876,96.39,2806,52.9717
12.88589989,96.39,2803,52.9434
12.93842102,96.39,2694,51.9038
12.99094215,96.39,2716,52.1153
13.04346328,96.39,2736,52.3068
13.09598441,96.39,2740,52.345
13.14850554,96.39,2655,51.5267
13.20102667,96.39,2622,51.2055
13.2535478,96.39,2692,51.8845
13.30606893,96.39,2532,50.319
13.35859006,96.39,2517,50.1697
13.41111119,96.39,2592,50.9117
13.46363232,96.39,2520,50.1996
13.51615346,96.39,2583,50.8232
13.56867459,96.39,2689,51.8556
13.62119572,96.39,2899,53.8424
13.67371685,96.39,2788,52.8015
13.72623798,96.39,3244,56.9561
13.77875911,96.39,4332,65.8179
13.83128024,96.39,5163,71.854
13.88380137,96.39,2816,53.066
13.9363225,96.39,2581,50.8035
13.98884363,96.39,2665,51.6236
14.04136476,96.39,2822,53.1225
14.09388589,96.39,2970,54.4977
14.14640702,96.39,4076,63.8436
14.19892815,96.39,6470,80.4363
14.25144929,96.39,13378,115.6633
14.30397042,96.39,31117,176.4001
14.35649155,96.39,9264,96.2497
14.40901268,96.39,2840,53.2917
14.46153381,96.39,2550,50.4975
14.51405494,96.39,2480,49.7996
14.56657607,96.39,2521,50.2096
14.6190972,96.39,2373,48.7134
14.67161833,96.39,2326,48.2286
14.72413946,96.39,2337,48.3425
14.77666059,96.39,2408,49.0714
14.82918172,96.39,2383,48.816
14.88170285,96.39,2259,47.5289
14.93422398,96.39,2366,48.6415
14.98674512,96.39,2286,47.8121
15.03926625,96.39,2282,47.7703
15.09178738,96.39,2256,47.4974
15.14430851,96.39,2236,47.2864
15.19682964,96.39,2405,49.0408
15.24935077,96.39,2274,47.6865
15.3018719,96.39,2313,48.0937
15.35439303,96.39,2317,48.1352
15.40691416,96.39,2223,47.1487
15.45943529,96.39,2300,47.9583
15.51195642,96.39,2295,47.9062
15.56447755,96.39,2357,48.5489
15.61699868,96.39,2251,47.4447
15.66951981,96.39,2215,47.0638
15.72204095,96.39,2346,48.4355
15.77456208,96.39,2258,47.5184
15.82708321,96.39,2336,48.3322
15.87960434,96.39,2247,47.4025
15.93212547,96.39,2253,47.4658
15.9846466,96.39,2236,47.2864
16.03716773,96.39,2217,47.085
16.08968886,96.39,2269,47.634
16.14220999,96.39,2264,47.5815
16.19473112,96.39,2142,46.2817
16.24725225,96.39,2197,46.8722
16.29977338,96.39,2234,47.2652
16.35229451,96.39,2198,46.8828
16.40481564,96.39,2177,46.6583
16.45733678,96.39,2195,46.8508
16.50985791,96.39,2264,47.5815
16.56237904,96.39,2225,47.1699
16.61490017,96.39,2272,47.6655
16.6674213,96.39,2218,47.0956
16.71994243,96.39,2247,47.4025
16.77246356,96.39,2217,47.085
16.82498469,96.39,2298,47.9375
16.87750582,96.39,2319,48.156
16.93002695,96.39,2560,50.5964
16.98254808,96.39,2404,49.0306
17.03506921,96.39,2192,46.8188
17.08759034,96.39,2190,46.7974
17.14011147,96.39,2197,46.8722
17.19263261,96.39,2330,48.2701
17.24515374,96.39,2234,47.2652
17.29767487,96.39,2400,48.9898
17.350196,96.39,2360,48.5798
17.40271713,96.39,3035,55.0908
17.45523826,96.39,2861,53.4883
17.50775939,96.39,2468,49.679
17.56028052,96.39,2230,47.2229
17.61280165,96.39,2226,47.1805
17.66532278,96.39,2149,46.3573
17.71784391,96.39,2292,47.8748
17.77036504,96.39,2121,46.0543
17.82288617,96.39,2312,48.0833
17.8754073,96.39,2143,46.2925
17.92792843,96.39,2267,47.613
17.98044957,96.39,2349,48.4665
18.0329707,96.39,2330,48.2701
18.08549183,96.39,2402,49.0102
18.13801296,96.39,2533,50.3289
18.19053409,96.39,2500,50
18.24305522,96.39,2628,51.264
18.29557635,96.39,3135,55.9911
18.34809748,96.39,2935,54.1756
18.40061861,96.39,3031,55.0545
18.45313974,96.39,4255,65.2304
18.50566087,96.39,3246,56.9737
18.558182,96.39,2421,49.2037
18.61070313,96.39,2316,48.1248
18.66322426,96.39,2349,48.4665
18.7157454,96.39,2448,49.4773
18.76826653,96.39,2351,48.4871
18.82078766,96.39,2362,48.6004
18.87330879,96.39,2431,49.3052
18.92582992,96.39,2814,53.0471
18.97835105,96.39,3525,59.3717
19.03087218,96.39,4007,63.3009
19.08339331,96.39,2939,54.2125
19.13591444,96.39,2381,48.7955
19.18843557,96.39,2426,49.2544
19.2409567,96.39,2287,47.8226
19.29347783,96.39,2516,50.1597
19.34599896,96.39,2453,49.5278
19.39852009,96.39,2529,50.2892
19.45104123,96.39,2671,51.6817
19.50356236,96.39,2895,53.8052
19.55608349,96.39,2701,51.9711
19.60860462,96.39,2664,51.614
19.66112575,96.39,2607,51.0588
19.71364688,96.39,2805,52.9623
19.76616801,96.39,3692,60.7618
19.81868914,96.39,3723,61.0164
19.87121027,96.39,2947,54.2863
19.9237314,96.39,2624,51.225
19.97625253,96.39,2578,50.774
20.02877366,96.39,2410,49.0918
20.08129479,96.39,2503,50.03
20.13381592,96.39,2583,50.8232
20.18633706,96.39,2648,51.4587
20.23885819,96.39,2613,51.1175
20.29137932,96.39,2752,52.4595
20.34390045,96.39,3223,56.7715
20.39642158,96.39,3958,62.9126
20.44894271,96.39,3895,62.4099
20.50146384,96.39,3127,55.9196
20.55398497,96.39,3076,55.4617
20.6065061,96.39,3517,59.3043
20.65902723,96.39,3130,55.9464
20.71154836,96.39,2678,51.7494
20.76406949,96.39,2677,51.7397
20.81659062,96.39,2625,51.2348
20.86911175,96.39,2843,53.3198
20.92163289,96.39,3047,55.1996
20.97415402,96.39,4004,63.2772
21.02667515,96.39,5732,75.71
21.07919628,96.39,4111,64.1171
21.13171741,96.39,2650,51.4782
21.18423854,96.39,2624,51.225
21.23675967,96.39,2687,51.8363
21.2892808,96.39,2673,51.7011
21.34180193,96.39,2669,51.6624
21.39432306,96.39,2710,52.0577
21.44684419,96.39,2661,51.5849
21.49936532,96.39,2692,51.8845
21.55188645,96.39,2712,52.0769
21.60440758,96.39,2720,52.1536
21.65692872,96.39,2876,53.6284
21.70944985,96.39,2845,53.3385
21.76197098,96.39,2920,54.037
21.81449211,96.39,2772,52.6498
21.86701324,96.39,2732,52.2685
21.91953437,96.39,2714,52.0961
21.9720555,96.39,2646,51.4393
22.02457663,96.39,2685,51.817
22.07709776,96.39,2722,52.1728
22.12961889,96.39,2774,52.6688
22.18214002,96.39,2799,52.9056
22.23466115,96.39,2786,52.7826
22.28718228,96.39,2660,51.5752
22.33970341,96.39,2758,52.5167
22.39222455,96.39,2818,53.0848
22.44474568,96.39,2760,52.5357
22.49726681,96.39,2843,53.3198
22.54978794,96.39,2888,53.7401
22.60230907,96.39,2880,53.6656
22.6548302,96.39,2762,52.5547
22.70735133,96.39,2796,52.8772
22.75987246,96.39,2873,53.6004
22.81239359,96.39,2859,53.4696
22.86491472,96.39,2826,53.1601
22.91743585,96.39,2872,53.591
22.96995698,96.39,2723,52.1824
23.02247811,96.39,2893,53.7866
23.07499924,96.39,2839,53.2823
23.12752038,96.39,2727,52.2207
23.18004151,96.39,2923,54.0648
23.23256264,96.39,2738,52.3259
23.28508377,96.39,2694,51.9038
23.3376049,96.39,2747,52.4118
23.39012603,96.39,2806,52.9717
23.44264716,96.39,3190,56.4801
23.49516829,96.39,4645,68.1542
23.54768942,96.39,4351,65.9621
23.60021055,96.39,3435,58.6089
23.65273168,96.39,2715,52.1057
23.70525281,96.39,2763,52.5642
23.75777394,96.39,2762,52.5547
23.81029507,96.39,2557,50.5668
23.86281621,96.39,2515,50.1498
23.91533734,96.39,2515,50.1498
23.96785847,96.39,2526,50.2593
24.0203796,96.39,2646,51.4393
24.07290073,96.39,2997,54.7449
24.12542186,96.39,2933,54.1572
24.17794299,96.39,3022,54.9727
24.23046412,96.39,3750,61.2372
24.28298525,96.39,3658,60.4814
24.33550638,96.39,3491,59.0847
24.38802751,96.39,2752,52.4595
24.44054864,96.39,3010,54.8635
24.49306977,96.39,4219,64.9538
24.5455909,96.39,10491,102.4256
24.59811204,96.39,8686,93.1987
24.65063317,96.39,5843,76.4395
24.7031543,96.39,2582,50.8134
24.75567543,96.39,2399,48.9796
24.80819656,96.39,2390,48.8876
24.86071769,96.39,2309,48.0521
24.91323882,96.39,2303,47.9896
24.96575995,96.39,2330,48.2701
25.01828108,96.39,2444,49.4368
25.07080221,96.39,2385,48.8365
25.12332334,96.39,2296,47.9166
25.17584447,96.39,2206,46.9681
25.2283656,96.39,2205,46.9574
25.28088673,96.39,2317,48.1352
25.33340786,96.39,2336,48.3322
25.385929,96.39,2839,53.2823
25.43845013,96.39,2827,53.1695
25.49097126,96.39,2478,49.7795
25.54349239,96.39,2147,46.3357
25.59601352,96.39,2179,46.6798
25.64853465,96.39,2258,47.5184
25.70105578,96.39,2303,47.9896
25.75357691,96.39,2190,46.7974
25.80609804,96.39,2205,46.9574
25.85861917,96.39,2458,49.5782
25.9111403,96.39,2251,47.4447
25.96366143,96.39,2169,46.5725
26.01618256,96.39,2135,46.2061
26.06870369,96.39,2091,45.7275
26.12122483,96.39,2095,45.7712
26.17374596,96.39,2071,45.5082
26.22626709,96.39,2088,45.6946
26.27878822,96.39,2153,46.4004
26.33130935,96.39,2114,45.9783
26.38383048,96.39,2100,45.8258
26.43635161,96.39,1986,44.5646
26.48887274,96.39,2086,45.6727
26.54139387,96.39,1988,44.587
26.593915,96.39,2063,45.4203
26.64643613,96.39,2251,47.4447
26.69895726,96.39,2456,49.558
26.75147839,96.39,2265,47.592
26.80399952,96.39,2029,45.0444
26.85652066,96.39,2084,45.6508
26.90904179,96.39,2070,45.4973
26.96156292,96.39,2182,46.7119
27.01408405,96.39,2228,47.2017
27.06660518,96.39,2206,46.9681
27.11912631,96.39,2130,46.1519
27.17164744,96.39,2096,45.7821
27.22416857,96.39,2041,45.1774
27.2766897,96.39,2143,46.2925
27.32921083,96.39,2576,50.7543
27.38173196,96.39,2156,46.4327
27.43425309,96.39,2149,46.3573
27.48677422,96.39,2070,45.4973
27.53929535,96.39,2051,45.288
27.59181649,96.39,2209,47
27.64433762,96.39,2618,51.1664
27.69685875,96.39,2992,54.6992
27.74937988,96.39,2534,50.3389
27.80190101,96.39,2274,47.6865
27.85442214,96.39,2084,45.6508
27.90694327,96.39,2045,45.2217
27.9594644,96.39,1956,44.2267
28.01198553,96.39,1900,43.589
28.06450666,96.39,1939,44.0341
28.11702779,96.39,1970,44.3847
28.16954892,96.39,1972,44.4072
28.22207005,96.39,1993,44.643
28.27459118,96.39,2212,47.0319
28.32711232,96.39,2016,44.8999
28.37963345,96.39,2075,45.5522
28.43215458,96.39,1946,44.1135
28.48467571,96.39,2074,45.5412
28.53719684,96.39,1942,44.0681
28.58971797,96.39,2088,45.6946
28.6422391,96.39,1914,43.7493
28.69476023,96.39,2062,45.4093
28.74728136,96.39,2035,45.111
28.79980249,96.39,2001,44.7325
28.85232362,96.39,2021,44.9555
28.90484475,96.39,2210,47.0106
28.95736588,96.39,2796,52.8772
29.00988701,96.39,2209,47
29.06240815,96.39,2118,46.0217
29.11492928,96.39,2058,45.3652
29.16745041,96.39,2097,45.793
29.21997154,96.39,1999,44.7102
29.27249267,96.39,1983,44.5309
29.3250138,96.39,1963,44.3058
29.37753493,96.39,1927,43.8976
29.43005606,96.39,2052,45.299
29.48257719,96.39,1967,44.3509
29.53509832,96.39,1907,43.6692
29.58761945,96.39,1991,44.6206
29.64014058,96.39,2041,45.1774
29.69266171,96.39,2005,44.7772
29.74518284,96.39,2023,44.9778
29.79770398,96.39,1920,43.8178
29.85022511,96.39,1961,44.2832
29.90274624,96.39,1949,44.1475
29.95526737,96.39,1877,43.3244
30.0077885,96.39,1968,44.3621
30.06030963,96.39,1905,43.6463
30.11283076,96.39,1923,43.852
30.16535189,96.39,2005,44.7772
30.21787302,96.39,1900,43.589
30.27039415,96.39,1998,44.699
30.32291528,96.39,1903,43.6234
30.37543641,96.39,1987,44.5758
30.42795754,96.39,2059,45.3762
30.48047867,96.39,2412,49.1121
30.53299981,96.39,2425,49.2443
30.58552094,96.39,2391,48.8979
30.63804207,96.39,3104,55.7136
30.6905632,96.39,4330,65.8027
30.74308433,96.39,3886,62.3378
30.79560546,96.39,3402,58.3267
30.84812659,96.39,2341,48.3839
30.90064772,96.39,2143,46.2925
30.95316885,96.39,2195,46.8508
31.00568998,96.39,2328,48.2494
31.05821111,96.39,2455,49.548
31.11073224,96.39,2127,46.1194
31.16325337,96.39,2058,45.3652
31.2157745,96.39,2008,44.8107
31.26829564,96.39,1986,44.5646
31.32081677,96.39,2077,45.5741
31.3733379,96.39,2423,49.224
31.42585903,96.39,2354,48.518
31.47838016,96.39,2512,50.1199
31.53090129,96.39,2871,53.5817
31.58342242,96.39,2949,54.3047
31.63594355,96.39,4217,64.9384
31.68846468,96.39,11585,107.6336
31.74098581,96.39,48035,219.1689
31.79350694,96.39,16586,128.7866
31.84602807,96.39,10837,104.1009
31.8985492,96.39,2906,53.9073
31.95107033,96.39,2537,50.3686
32.00359147,96.39,2136,46.2169
32.0561126,96.39,2152,46.3897
32.10863373,96.39,2105,45.8803
32.16115486,96.39,1977,44.4635
32.21367599,96.39,2181,46.7012
32.26619712,96.39,1989,44.5982
32.31871825,96.39,2026,45.0111
32.37123938,96.39,2137,46.2277
32.42376051,96.39,2097,45.793
32.47628164,96.39,2066,45.4533
32.52880277,96.39,2018,44.9222
32.5813239,96.39,1937,44.0114
32.63384503,96.39,2041,45.1774
32.68636616,96.39,2139,46.2493
32.7388873,96.39,1945,44.1022
32.79140843,96.39,1993,44.643
32.84392956,96.39,2049,45.2659
32.89645069,96.39,2079,45.5961
32.94897182,96.39,2234,47.2652
33.00149295,96.39,2472,49.7192
33.05401408,96.39,3470,58.9067
33.10653521,96.39,3309,57.5239
33.15905634,96.39,3568,59.7327
33.21157747,96.39,2793,52.8488
33.2640986,96.39,2576,50.7543
33.31661973,96.39,2459,49.5883
33.36914086,96.39,2774,52.6688
33.42166199,96.39,4938,70.2709
33.47418312,96.39,5778,76.0132
33.52670426,96.39,5179,71.9653
33.57922539,96.39,3362,57.9828
33.63174652,96.39,2347,48.4458
33.68426765,96.39,1976,44.4522
33.73678878,96.39,1915,43.7607
33.78930991,96.39,1968,44.3621
33.84183104,96.39,2116,46
33.89435217,96.39,2311,48.0729
33.9468733,96.39,2272,47.6655
33.99939443,96.39,2298,47.9375
34.05191556,96.39,2158,46.4543
34.10443669,96.39,2043,45.1996
34.15695782,96.39,2021,44.9555
34.20947895,96.39,2048,45.2548
34.26200009,96.39,2427,49.2646
34.31452122,96.39,2658,51.5558
34.36704235,96.39,3404,58.3438
34.41956348,96.39,2573,50.7247
34.47208461,96.39,2606,51.049
34.52460574,96.39,2224,47.1593
34.57712687,96.39,2388,48.8672
34.629648,96.39,2645,51.4296
34.68216913,96.39,2944,54.2586
34.73469026,96.39,2769,52.6213
34.78721139,96.39,2564,50.636
34.83973252,96.39,2415,49.1426
34.89225365,96.39,2413,49.1223
34.94477478,96.39,2622,51.2055
34.99729592,96.39,3301,57.4543
35.04981705,96.39,2909,53.9351
35.10233818,96.39,2829,53.1883
35.15485931,96.39,2597,50.9608
35.20738044,96.39,3623,60.1914
35.25990157,96.39,3859,62.1208
35.3124227,96.39,3096,55.6417
35.36494383,96.39,2572,50.7149
35.41746496,96.39,2302,47.9792
35.46998609,96.39,2168,46.5618
35.52250722,96.39,2295,47.9062
35.57502835,96.39,2590,50.892
35.62754948,96.39,2188,46.7761
35.68007061,96.39,2297,47.927
35.73259175,96.39,2180,46.6905
35.78511288,96.39,2177,46.6583
35.83763401,96.39,2236,47.2864
35.89015514,96.39,2365,48.6313
35.94267627,96.39,2890,53.7587
35.9951974,96.39,2717,52.1249
36.04771853,96.39,2488,49.8799
36.10023966,96.39,2101,45.8367
36.15276079,96.39,2027,45.0222
36.20528192,96.39,1987,44.5758
36.25780305,96.39,2068,45.4753
36.31032418,96.39,2278,47.7284
36.36284531,96.39,3178,56.3738
36.41536644,96.39,2865,53.5257
36.46788758,96.39,2537,50.3686
36.52040871,96.39,2109,45.9239
36.57292984,96.39,1842,42.9185
36.62545097,96.39,1942,44.0681
36.6779721,96.39,1965,44.3283
36.73049323,96.39,1980,44.4972
36.78301436,96.39,1967,44.3509
36.83553549,96.39,1890,43.4741
36.88805662,96.39,1798,42.4028
36.94057775,96.39,1771,42.0833
36.99309888,96.39,1899,43.5775
37.04562001,96.39,1726,41.5452
37.09814114,96.39,1815,42.6028
37.15066227,96.39,1787,42.2729
37.20318341,96.39,1723,41.509
37.25570454,96.39,1733,41.6293
37.30822567,96.39,1744,41.7612
37.3607468,96.39,1830,42.7785
37.41326793,96.39,1943,44.0795
37.46578906,96.39,1744,41.7612
37.51831019,96.39,1852,43.0349
37.57083132,96.39,1659,40.7308
37.62335245,96.39,1748,41.8091
37.67587358,96.39,1769,42.0595
37.72839471,96.39,1853,43.0465
37.78091584,96.39,1963,44.3058
37.83343697,96.39,2355,48.5283
37.8859581,96.39,2116,46
37.93847924,96.39,2233,47.2546
37.99100037,96.39,1808,42.5206
38.0435215,96.39,1793,42.3438
38.09604263,96.39,1765,42.0119
38.14856376,96.39,2021,44.9555
38.20108489,96.39,2434,49.3356
38.25360602,96.39,2119,46.0326
38.30612715,96.39,2338,48.3529
38.35864828,96.39,1980,44.4972
38.41116941,96.39,1945,44.1022
38.46369054,96.39,1792,42.332
38.51621167,96.39,1772,42.0951
38.5687328,96.39,1723,41.509
38.62125393,96.39,1605,40.0625
38.67377507,96.39,1713,41.3884
38.7262962,96.39,1605,40.0625
38.77881733,96.39,1576,39.6989
38.83133846,96.39,1579,39.7366
38.88385959,96.39,1659,40.7308
38.93638072,96.39,1658,40.7185
38.98890185,96.39,1756,41.9047
39.04142298,96.39,1755,41.8927
39.09394411,96.39,1715,41.4126
39.14646524,96.39,1712,41.3763
39.19898637,96.39,1961,44.2832
39.2515075,96.39,2082,45.6289
39.30402863,96.39,1978,44.4747
39.35654976,96.39,1774,42.1189
39.4090709,96.39,1615,40.1871
39.46159203,96.39,1522,39.0128
39.51411316,96.39,1602,40.025
39.56663429,96.39,1609,40.1123
39.61915542,96.39,1651,40.6325
39.67167655,96.39,1631,40.3856
39.72419768,96.39,1676,40.939
39.77671881,96.39,2073,45.5302
39.82923994,96.39,1861,43.1393
39.88176107,96.39,1894,43.5201
39.9342822,96.39,1689,41.0974
39.98680333,96.39,1796,42.3792
40.03932446,96.39,1583,39.7869
40.09184559,96.39,1721,41.4849
40.14436673,96.39,1627,40.3361
40.19688786,96.39,1960,44.2719
40.24940899,96.39,1624,40.2989
40.30193012,96.39,1742,41.7373
40.35445125,96.39,1451,38.092
40.40697238,96.39,1422,37.7094
40.45949351,96.39,1441,37.9605
40.51201464,96.39,1516,38.9358
40.56453577,96.39,1444,38
40.6170569,96.39,1612,40.1497
40.66957803,96.39,1531,39.128
40.72209916,96.39,1455,38.1445
40.77462029,96.39,1443,37.9868
40.82714142,96.39,1414,37.6032
40.87966255,96.39,1403,37.4566
40.93218369,96.39,1324,36.3868
40.98470482,96.39,1416,37.6298
41.03722595,96.39,1454,38.1314
41.08974708,96.39,1579,39.7366
41.14226821,96.39,1415,37.6165
41.19478934,96.39,1358,36.8511
41.24731047,96.39,1402,37.4433
41.2998316,96.39,1513,38.8973
41.35235273,96.39,1568,39.598
41.40487386,96.39,1535,39.1791
41.45739499,96.39,1530,39.1152
41.50991612,96.39,1488,38.5746
41.56243725,96.39,1466,38.2884
41.61495838,96.39,1362,36.9053
41.66747952,96.39,1400,37.4166
41.72000065,96.39,1396,37.3631
41.77252178,96.39,1287,35.8748
41.82504291,96.39,1315,36.2629
41.87756404,96.39,1354,36.7967
41.93008517,96.39,1343,36.647
41.9826063,96.39,1375,37.081
42.03512743,96.39,1348,36.7151
42.08764856,96.39,1516,38.9358
42.14016969,96.39,2026,45.0111
42.19269082,96.39,1691,41.1218
42.24521195,96.39,1767,42.0357
42.29773308,96.39,1785,42.2493
42.35025421,96.39,1382,37.1753
42.40277535,96.39,1494,38.6523
42.45529648,96.39,1389,37.2693
42.50781761,96.39,1329,36.4555
42.56033874,96.39,1643,40.5339
42.61285987,96.39,1577,39.7115
42.665381,96.39,1821,42.6732
42.71790213,96.39,2777,52.6972
42.77042326,96.39,5514,74.2563
42.82294439,96.39,2129,46.1411
42.87546552,96.39,3596,59.9667
42.92798665,96.39,1568,39.598
42.98050778,96.39,1381,37.1618
43.03302891,96.39,1414,37.6032
43.08555004,96.39,1296,36
43.13807118,96.39,1308,36.1663
43.19059231,96.39,1265,35.5668
43.24311344,96.39,1353,36.7831
43.29563457,96.39,1384,37.2022
43.3481557,96.39,1378,37.1214
43.40067683,96.39,1393,37.3229
43.45319796,96.39,1369,37
43.50571909,96.39,1288,35.8887
43.55824022,96.39,1379,37.1349
43.61076135,96.39,1442,37.9737
43.66328248,96.39,1375,37.081
43.71580361,96.39,1372,37.0405
43.76832474,96.39,1316,36.2767
43.82084587,96.39,1352,36.7696
43.87336701,96.39,1283,35.819
43.92588814,96.39,1352,36.7696
43.97840927,96.39,1335,36.5377
44.0309304,96.39,1328,36.4417
44.08345153,96.39,1370,37.0135
44.13597266,96.39,1371,37.027
44.18849379,96.39,1532,39.1408
44.24101492,96.39,2422,49.2138
44.29353605,96.39,1562,39.5221
44.34605718,96.39,1871,43.2551
44.39857831,96.39,1585,39.8121
44.45109944,96.39,1342,36.6333
44.50362057,96.39,1324,36.3868
44.5561417,96.39,1381,37.1618
44.60866284,96.39,1271,35.6511
44.66118397,96.39,1372,37.0405
44.7137051,96.39,1437,37.9078
44.76622623,96.39,1535,39.1791
44.81874736,96.39,1533,39.1535
44.87126849,96.39,1531,39.128
44.92378962,96.39,1498,38.704
44.97631075,96.39,1448,38.0526
45.02883188,96.39,1409,37.5366
45.08135301,96.39,1615,40.1871
45.13387414,96.39,1630,40.3733
45.18639527,96.39,1555,39.4335
45.2389164,96.39,1621,40.2616
45.29143753,96.39,1516,38.9358
45.34395867,96.39,1534,39.1663
45.3964798,96.39,1510,38.8587
45.44900093,96.39,1428,37.7889
45.50152206,96.39,1424,37.7359
45.55404319,96.39,1511,38.8716
45.60656432,96.39,1860,43.1277
45.65908545,96.39,2214,47.0532
45.71160658,96.39,1661,40.7554
45.76412771,96.39,2179,46.6798
45.81664884,96.39,1494,38.6523
45.86916997,96.39,1508,38.833
45.9216911,96.39,1456,38.1576
45.97421223,96.39,1378,37.1214
46.02673336,96.39,1454,38.1314
46.0792545,96.39,1555,39.4335
46.13177563,96.39,1842,42.9185
46.18429676,96.39,2054,45.3211
46.23681789,96.39,2282,47.7703
46.28933902,96.39,3483,59.0169
46.34186015,96.39,3817,61.7819
46.39438128,96.39,2716,52.1153
46.44690241,96.39,4667,68.3154
46.49942354,96.39,2041,45.1774
46.55194467,96.39,2254,47.4763
46.6044658,96.39,1981,44.5084
46.65698693,96.39,1622,40.2741
46.70950806,96.39,2392,48.9081
46.76202919,96.39,1629,40.3609
46.81455033,96.39,1647,40.5832
46.86707146,96.39,1655,40.6817
46.91959259,96.39,1400,37.4166
46.97211372,96.39,1361,36.8917
47.02463485,96.39,1433,37.855
47.07715598,96.39,1342,36.6333
47.12967711,96.39,1364,36.9324
47.18219824,96.39,1393,37.3229
47.23471937,96.39,1411,37.5633
47.2872405,96.39,1285,35.8469
47.33976163,96.39,1332,36.4966
47.39228276,96.39,1346,36.6879
47.44480389,96.39,1314,36.2491
47.49732502,96.39,1263,35.5387
47.54984616,96.39,1331,36.4829
47.60236729,96.39,1385,37.2156
47.65488842,96.39,1353,36.7831
47.70740955,96.39,1271,35.6511
47.75993068,96.39,1320,36.3318
47.81245181,96.39,1271,35.6511
47.86497294,96.39,1355,36.8103
47.91749407,96.39,1216,34.8712
47.9700152,96.39,1329,36.4555
48.02253633,96.39,1277,35.7351
48.07505746,96.39,1388,37.2559
48.12757859,96.39,1375,37.081
48.18009972,96.39,1262,35.5246
48.23262085,96.39,1275,35.7071
48.28514198,96.39,1269,35.623
48.33766312,96.39,1231,35.0856
48.39018425,96.39,1293,35.9583
48.44270538,96.39,1397,37.3765
48.49522651,96.39,1354,36.7967
48.54774764,96.39,1458,38.1838
48.60026877,96.39,1549,39.3573
48.6527899,96.39,1358,36.8511
48.70531103,96.39,1423,37.7227
48.75783216,96.39,1382,37.1753
48.81035329,96.39,1374,37.0675
48.86287442,96.39,1245,35.2846
48.91539555,96.39,1213,34.8281
48.96791668,96.39,1193,34.5398
49.02043781,96.39,1280,35.7771
49.07295895,96.39,1279,35.7631
49.12548008,96.39,1299,36.0416
49.17800121,96.39,1273,35.6791
49.23052234,96.39,1169,34.1906
49.28304347,96.39,1270,35.6371
49.3355646,96.39,1181,34.3657
49.38808573,96.39,1225,35
49.44060686,96.39,1354,36.7967
49.49312799,96.39,1224,34.9857
49.54564912,96.39,1222,34.9571
49.59817025,96.39,1367,36.973
49.65069138,96.39,1516,38.9358
49.70321251,96.39,1484,38.5227
49.75573364,96.39,1365,36.9459
49.80825478,96.39,1356,36.8239
49.86077591,96.39,1259,35.4824
49.91329704,96.39,1188,34.4674
49.96581817,96.39,1086,32.9545
50.0183393,96.39,1111,33.3317
50.07086043,96.39,1156,34
50.12338156,96.39,1085,32.9393
50.17590269,96.39,1198,34.6121
50.22842382,96.39,1157,34.0147
50.28094495,96.39,1266,35.5809
50.33346608,96.39,1505,38.7943
50.38598721,96.39,1421,37.6962
50.43850834,96.39,1180,34.3511
50.49102947,96.39,1282,35.805
50.54355061,96.39,1142,33.7935
50.59607174,96.39,1062,32.5883
50.64859287,96.39,1060,32.5576
50.701114,96.39,1104,33.2265
50.75363513,96.39,1088,32.9848
50.80615626,96.39,1079,32.8481
50.85867739,96.39,1059,32.5423
50.91119852,96.39,1082,32.8938
50.96371965,96.39,1166,34.1467
51.01624078,96.39,1341,36.6197
51.06876191,96.39,1437,37.9078
51.12128304,96.39,1135,33.6898
51.17380417,96.39,1376,37.0945
51.2263253,96.39,1142,33.7935
51.27884644,96.39,1088,32.9848
51.33136757,96.39,1058,32.5269
51.3838887,96.39,1108,33.2866
51.43640983,96.39,1122,33.4963
51.48893096,96.39,1088,32.9848
51.54145209,96.39,1057,32.5115
51.59397322,96.39,1051,32.4191
51.64649435,96.39,1039,32.2335
51.69901548,96.39,1075,32.7872
51.75153661,96.39,1032,32.1248
51.80405774,96.39,1063,32.6037
51.85657887,96.39,1084,32.9242
51.9091,96.39,1077,32.8177
51.96162113,96.39,1044,32.311
52.01414227,96.39,1056,32.4962
52.0666634,96.39,1002,31.6544
52.11918453,96.39,1082,32.8938
52.17170566,96.39,1115,33.3916
52.22422679,96.39,1056,32.4962
52.27674792,96.39,1073,32.7567
52.32926905,96.39,1362,36.9053
52.38179018,96.39,1372,37.0405
52.43431131,96.39,1321,36.3456
52.48683244,96.39,1425,37.7492
52.53935357,96.39,1317,36.2905
52.5918747,96.39,1616,40.1995
52.64439583,96.39,1122,33.4963
52.69691696,96.39,1181,34.3657
52.7494381,96.39,1222,34.9571
52.80195923,96.39,1032,32.1248
52.85448036,96.39,1123,33.5112
52.90700149,96.39,1228,35.0428
52.95952262,96.39,1226,35.0143
53.01204375,96.39,1210,34.7851
53.06456488,96.39,1151,33.9264
53.11708601,96.39,1076,32.8024
53.16960714,96.39,1098,33.1361
53.22212827,96.39,1093,33.0606
53.2746494,96.39,1076,32.8024
53.32717053,96.39,1016,31.8748
53.37969166,96.39,1010,31.7805
53.43221279,96.39,1004,31.686
53.48473393,96.39,960,30.9839
53.53725506,96.39,986,31.4006
53.58977619,96.39,979,31.289
53.64229732,96.39,981,31.3209
53.69481845,96.39,987,31.4166
53.74733958,96.39,998,31.5911
53.79986071,96.39,1062,32.5883
53.85238184,96.39,1256,35.4401
53.90490297,96.39,1235,35.1426
53.9574241,96.39,1165,34.1321
54.00994523,96.39,1164,34.1174
54.06246636,96.39,1238,35.1852
54.11498749,96.39,1564,39.5474
54.16750862,96.39,1187,34.4529
54.22002976,96.39,1272,35.6651
54.27255089,96.39,1184,34.4093
54.32507202,96.39,1181,34.3657
54.37759315,96.39,1041,32.2645
54.43011428,96.39,1004,31.686
54.48263541,96.39,1047,32.3574
54.53515654,96.39,1004,31.686
54.58767767,96.39,1057,32.5115
54.6401988,96.39,1024,32
54.69271993,96.39,1040,32.249
54.74524106,96.39,998,31.5911
54.79776219,96.39,1169,34.1906
54.85028332,96.39,1090,33.0151
54.90280445,96.39,1157,34.0147
54.95532559,96.39,1259,35.4824
55.00784672,96.39,1274,35.6931
55.06036785,96.39,1173,34.2491
55.11288898,96.39,1420,37.6829
55.16541011,96.39,1218,34.8999
55.21793124,96.39,1004,31.686
55.27045237,96.39,1097,33.121
55.3229735,96.39,970,31.1448
55.37549463,96.39,962,31.0161
55.42801576,96.39,1081,32.8786
55.48053689,96.39,1025,32.0156
55.53305802,96.39,907,30.1164
55.58557915,96.39,959,30.9677
55.63810028,96.39,924,30.3974
55.69062141,96.39,961,31
55.74314255,96.39,949,30.8058
55.79566368,96.39,940,30.6594
55.84818481,96.39,947,30.7734
55.90070594,96.39,918,30.2985
55.95322707,96.39,907,30.1164
56.0057482,96.39,949,30.8058
56.05826933,96.39,1045,32.3265
56.11079046,96.39,1027,32.0468
56.16331159,96.39,1004,31.686
56.21583272,96.39,966,31.0805
56.26835385,96.39,904,30.0666
56.32087498,96.39,880,29.6648
56.37339611,96.39,885,29.7489
56.42591724,96.39,938,30.6268
56.47843838,96.39,875,29.5804
56.53095951,96.39,931,30.5123
56.58348064,96.39,974,31.209
56.63600177,96.39,878,29.6311
56.6885229,96.39,974,31.209
56.74104403,96.39,885,29.7489
56.79356516,96.39,876,29.5973
56.84608629,96.39,908,30.133
56.89860742,96.39,869,29.4788
56.95112855,96.39,895,29.9166
57.00364968,96.39,888,29.7993
57.05617081,96.39,924,30.3974
57.10869194,96.39,897,29.95
57.16121307,96.39,886,29.7658
57.21373421,96.39,858,29.2916
57.26625534,96.39,901,30.0167
57.31877647,96.39,967,31.0966
57.3712976,96.39,958,30.9516
57.42381873,96.39,974,31.209
57.47633986,96.39,1212,34.8138
57.52886099,96.39,1391,37.2961
57.58138212,96.39,994,31.5278
57.63390325,96.39,1142,33.7935
57.68642438,96.39,1408,37.5233
57.73894551,96.39,1344,36.6606
57.79146664,96.39,1146,33.8526
57.84398777,96.39,1156,34
57.8965089,96.39,1351,36.756
57.94903004,96.39,1066,32.6497
58.00155117,96.39,967,31.0966
58.0540723,96.39,1060,32.5576
58.10659343,96.39,939,30.6431
58.15911456,96.39,950,30.8221
58.21163569,96.39,920,30.3315
58.26415682,96.39,954,30.8869
58.31667795,96.39,908,30.133
58.36919908,96.39,909,30.1496
58.42172021,96.39,930,30.4959
58.47424134,96.39,966,31.0805
58.52676247,96.39,919,30.315
58.5792836,96.39,921,30.348
58.63180473,96.39,915,30.249
58.68432587,96.39,880,29.6648
58.736847,96.39,920,30.3315
58.78936813,96.39,869,29.4788
58.84188926,96.39,901,30.0167
58.89441039,96.39,881,29.6816
58.94693152,96.39,924,30.3974
58.99945265,96.39,907,30.1164
59.05197378,96.39,901,30.0167
59.10449491,96.39,900,30
59.15701604,96.39,941,30.6757
59.20953717,96.39,922,30.3645
59.2620583,96.39,949,30.8058
59.31457943,96.39,1011,31.7962
59.36710056,96.39,1588,39.8497
59.4196217,96.39,988,31.4325
59.47214283,96.39,1031,32.1092
59.52466396,96.39,1254,35.4119
59.57718509,96.39,1040,32.249
59.62970622,96.39,1003,31.6702
59.68222735,96.39,1033,32.1403
59.73474848,96.39,970,31.1448
59.78726961,96.39,1013,31.8277
59.83979074,96.39,1005,31.7017
59.89231187,96.39,968,31.1127
59.944833,96.39,1067,32.665
59.99735413,96.39,1184,34.4093
60.04987526,96.39,946,30.7571
60.10239639,96.39,1050,32.4037
60.15491753,96.39,1113,33.3617
60.20743866,96.39,1012,31.8119
60.25995979,96.39,1093,33.0606
60.31248092,96.39,1143,33.8083
60.36500205,96.39,1076,32.8024
60.41752318,96.39,1109,33.3017
60.47004431,96.39,1146,33.8526
60.52256544,96.39,1122,33.4963
60.57508657,96.39,1196,34.5832
60.6276077,96.39,1192,34.5254
60.68012883,96.39,1238,35.1852
60.73264996,96.39,1260,35.4965
60.78517109,96.39,1245,35.2846
60.83769222,96.39,1246,35.2987
60.89021336,96.39,1179,34.3366
60.94273449,96.39,1282,35.805
60.99525562,96.39,1373,37.054
61.04777675,96.39,1385,37.2156
61.10029788,96.39,1317,36.2905
61.15281901,96.39,1391,37.2961
61.20534014,96.39,1373,37.054
61.25786127,96.39,1327,36.428
61.3103824,96.39,1312,36.2215
61.36290353,96.39,1354,36.7967
61.41542466,96.39,1350,36.7423
61.46794579,96.39,1370,37.0135
61.52046692,96.39,1378,37.1214
61.57298805,96.39,1280,35.7771
61.62550919,96.39,1359,36.8646
61.67803032,96.39,1306,36.1386
61.73055145,96.39,1309,36.1801
61.78307258,96.39,1280,35.7771
61.83559371,96.39,1272,35.6651
61.88811484,96.39,1269,35.623
61.94063597,96.39,1296,36
61.9931571,96.39,1265,35.5668
62.04567823,96.39,1334,36.524
62.09819936,96.39,1298,36.0278
62.15072049,96.39,1253,35.3977
62.20324162,96.39,1252,35.3836
62.25576275,96.39,1307,36.1525
62.30828388,96.39,1332,36.4966
62.36080502,96.39,1405,37.4833
62.41332615,96.39,1283,35.819
62.46584728,96.39,1201,34.6554
62.51836841,96.39,1301,36.0694
62.57088954,96.39,1139,33.7491
62.62341067,96.39,1139,33.7491
62.6759318,96.39,1145,33.8378
62.72845293,96.39,1024,32
62.78097406,96.39,1112,33.3467
62.83349519,96.39,1039,32.2335
62.88601632,96.39,1089,33
62.93853745,96.39,951,30.8383
62.99105858,96.39,999,31.607
63.04357971,96.39,1032,32.1248
63.09610084,96.39,987,31.4166
63.14862198,96.39,943,30.7083
63.20114311,96.39,967,31.0966
63.25366424,96.39,987,31.4166
63.30618537,96.39,1017,31.8904
63.3587065,96.39,1059,32.5423
63.41122763,96.39,1043,32.2955
63.46374876,96.39,919,30.315
63.51626989,96.39,985,31.3847
63.56879102,96.39,1024,32
63.62131215,96.39,945,30.7409
63.67383328,96.39,890,29.8329
63.72635441,96.39,894,29.8998
63.77887554,96.39,906,30.0998
63.83139667,96.39,886,29.7658
63.88391781,96.39,956,30.9192
63.93643894,96.39,1061,32.573
63.98896007,96.39,902,30.0333
64.0414812,96.39,979,31.289
64.09400233,96.39,1004,31.686
64.14652346,96.39,948,30.7896
64.19904459,96.39,938,30.6268
64.25156572,96.39,961,31
64.30408685,96.39,880,29.6648
64.35660798,96.39,807,28.4077
64.40912911,96.39,827,28.7576
64.46165024,96.39,852,29.189
64.51417137,96.39,824,28.7054
64.5666925,96.39,826,28.7402
64.61921364,96.39,871,29.5127
64.67173477,96.39,866,29.4279
64.7242559,96.39,923,30.3809
64.77677703,96.39,897,29.95
64.82929816,96.39,865,29.4109
64.88181929,96.39,936,30.5941
64.93434042,96.39,1002,31.6544
64.98686155,96.39,1061,32.573