File: Files_organized_for_plots/Constant_NaOH_1mL10M_to_1gPC/zXRD_Centroid08Dec21_Act08Mar22_B2_0714M_NaOH_LS0160_2.csv
[Measurement conditions]
Sample identification,XRD_Centroid08Dec21_Act08Mar22_B2_0714M_NaOH_LS0160_2
Comment - 1,"Configuration=Stage for Flat Samples/Holders, Owner=User-1, Creation date=7/1/2020 9:53:24 AM"
Comment - 2,"Goniometer=Theta/Theta; Minimum step size 2Theta:0.0001; Minimum step size Omega:0.0001"
Comment - 3,"Sample stage=Stage for flat samples/holders"
Comment - 4,"Diffractometer system=EMPYREAN"
Comment - 5,"Measurement program=C:\Users\ibo5034\OneDrive - The Pennsylvania State University\NEUP\Zerobackground scan.xrdmp, Identifier={98A3B11C-88F9-4AA6-982C-73314A311EF5}"
Anode material,Cu
K-Alpha1 wavelength,1.5405980
K-Alpha2 wavelength,1.5444260
Ratio K-Alpha2/K-Alpha1,0.500
Divergence slit,Fixed,0.25
Monochromator used,NO
Generator voltage, 45
Tube current, 40
File date and time,11/Mar/2022 12:28
Unit cell,
h k l, 0 0 0
Scan axis,Gonio
Scan range,4.994599997,64.999991833
Scan step size,0.0262606
No. of points, 2285
Scan type,CONTINUOUS
Time per step,96.390
[Scan points]
Angle, TimePerStep, Intensity, ESD
5.007730280, 96.390, 4364.0, 66.0606
5.060251411, 96.390, 4499.0, 67.0746
5.112772541, 96.390, 4409.0, 66.4003
5.165293672, 96.390, 4416.0, 66.4530
5.217814803, 96.390, 4219.0, 64.9538
5.270335934, 96.390, 4325.0, 65.7647
5.322857064, 96.390, 4218.0, 64.9461
5.375378195, 96.390, 4124.0, 64.2184
5.427899326, 96.390, 4179.0, 64.6452
5.480420456, 96.390, 4109.0, 64.1015
5.532941587, 96.390, 4062.0, 63.7338
5.585462718, 96.390, 4047.0, 63.6160
5.637983849, 96.390, 4109.0, 64.1015
5.690504979, 96.390, 3993.0, 63.1902
5.743026110, 96.390, 4024.0, 63.4350
5.795547241, 96.390, 4015.0, 63.3640
5.848068371, 96.390, 3916.0, 62.5780
5.900589502, 96.390, 3790.0, 61.5630
5.953110633, 96.390, 3839.0, 61.9597
6.005631763, 96.390, 3875.0, 62.2495
6.058152894, 96.390, 3829.0, 61.8789
6.110674025, 96.390, 3921.0, 62.6179
6.163195156, 96.390, 3793.0, 61.5873
6.215716286, 96.390, 3928.0, 62.6738
6.268237417, 96.390, 3804.0, 61.6766
6.320758548, 96.390, 3840.0, 61.9677
6.373279678, 96.390, 3674.0, 60.6135
6.425800809, 96.390, 3841.0, 61.9758
6.478321940, 96.390, 3667.0, 60.5558
6.530843071, 96.390, 3712.0, 60.9262
6.583364201, 96.390, 3754.0, 61.2699
6.635885332, 96.390, 3643.0, 60.3573
6.688406463, 96.390, 3721.0, 61.0000
6.740927593, 96.390, 3737.0, 61.1310
6.793448724, 96.390, 3569.0, 59.7411
6.845969855, 96.390, 3681.0, 60.6712
6.898490986, 96.390, 3611.0, 60.0916
6.951012116, 96.390, 3595.0, 59.9583
7.003533247, 96.390, 3581.0, 59.8415
7.056054378, 96.390, 3558.0, 59.6490
7.108575508, 96.390, 3576.0, 59.7997
7.161096639, 96.390, 3639.0, 60.3241
7.213617770, 96.390, 3510.0, 59.2453
7.266138900, 96.390, 3499.0, 59.1523
7.318660031, 96.390, 3679.0, 60.6548
7.371181162, 96.390, 3635.0, 60.2910
7.423702293, 96.390, 3547.0, 59.5567
7.476223423, 96.390, 3546.0, 59.5483
7.528744554, 96.390, 3571.0, 59.7578
7.581265685, 96.390, 3414.0, 58.4294
7.633786815, 96.390, 3433.0, 58.5918
7.686307946, 96.390, 3561.0, 59.6741
7.738829077, 96.390, 3442.0, 58.6686
7.791350208, 96.390, 3346.0, 57.8446
7.843871338, 96.390, 3454.0, 58.7707
7.896392469, 96.390, 3544.0, 59.5315
7.948913600, 96.390, 3417.0, 58.4551
8.001434730, 96.390, 3462.0, 58.8388
8.053955861, 96.390, 3630.0, 60.2495
8.106476992, 96.390, 3671.0, 60.5888
8.158998123, 96.390, 3508.0, 59.2284
8.211519253, 96.390, 3449.0, 58.7282
8.264040384, 96.390, 3451.0, 58.7452
8.316561515, 96.390, 3575.0, 59.7913
8.369082645, 96.390, 3366.0, 58.0172
8.421603776, 96.390, 3351.0, 57.8878
8.474124907, 96.390, 3460.0, 58.8218
8.526646038, 96.390, 3457.0, 58.7963
8.579167168, 96.390, 3422.0, 58.4979
8.631688299, 96.390, 3459.0, 58.8133
8.684209430, 96.390, 3416.0, 58.4466
8.736730560, 96.390, 3375.0, 58.0948
8.789251691, 96.390, 3308.0, 57.5152
8.841772822, 96.390, 3308.0, 57.5152
8.894293952, 96.390, 3356.0, 57.9310
8.946815083, 96.390, 3304.0, 57.4804
8.999336214, 96.390, 3232.0, 56.8507
9.051857345, 96.390, 3324.0, 57.6541
9.104378475, 96.390, 3267.0, 57.1577
9.156899606, 96.390, 3277.0, 57.2451
9.209420737, 96.390, 3420.0, 58.4808
9.261941867, 96.390, 3235.0, 56.8771
9.314462998, 96.390, 3321.0, 57.6281
9.366984129, 96.390, 3341.0, 57.8014
9.419505260, 96.390, 3417.0, 58.4551
9.472026390, 96.390, 3287.0, 57.3324
9.524547521, 96.390, 3277.0, 57.2451
9.577068652, 96.390, 3282.0, 57.2887
9.629589782, 96.390, 3224.0, 56.7803
9.682110913, 96.390, 3278.0, 57.2538
9.734632044, 96.390, 3202.0, 56.5862
9.787153175, 96.390, 3253.0, 57.0351
9.839674305, 96.390, 3204.0, 56.6039
9.892195436, 96.390, 3231.0, 56.8419
9.944716567, 96.390, 3317.0, 57.5934
9.997237697, 96.390, 3284.0, 57.3062
10.049758828, 96.390, 3224.0, 56.7803
10.102279959, 96.390, 3246.0, 56.9737
10.154801090, 96.390, 3193.0, 56.5066
10.207322220, 96.390, 3226.0, 56.7979
10.259843351, 96.390, 3326.0, 57.6715
10.312364482, 96.390, 3162.0, 56.2317
10.364885612, 96.390, 3335.0, 57.7495
10.417406743, 96.390, 3446.0, 58.7026
10.469927874, 96.390, 3882.0, 62.3057
10.522449004, 96.390, 3157.0, 56.1872
10.574970135, 96.390, 3160.0, 56.2139
10.627491266, 96.390, 3241.0, 56.9298
10.680012397, 96.390, 3285.0, 57.3149
10.732533527, 96.390, 3201.0, 56.5774
10.785054658, 96.390, 3193.0, 56.5066
10.837575789, 96.390, 3256.0, 57.0614
10.890096919, 96.390, 3189.0, 56.4712
10.942618050, 96.390, 3349.0, 57.8705
10.995139181, 96.390, 3510.0, 59.2453
11.047660312, 96.390, 3224.0, 56.7803
11.100181442, 96.390, 3176.0, 56.3560
11.152702573, 96.390, 3121.0, 55.8659
11.205223704, 96.390, 3178.0, 56.3738
11.257744834, 96.390, 3090.0, 55.5878
11.310265965, 96.390, 2919.0, 54.0278
11.362787096, 96.390, 3004.0, 54.8088
11.415308227, 96.390, 3168.0, 56.2850
11.467829357, 96.390, 3005.0, 54.8179
11.520350488, 96.390, 2983.0, 54.6168
11.572871619, 96.390, 3027.0, 55.0182
11.625392749, 96.390, 3000.0, 54.7723
11.677913880, 96.390, 2910.0, 53.9444
11.730435011, 96.390, 3044.0, 55.1725
11.782956141, 96.390, 3014.0, 54.8999
11.835477272, 96.390, 2899.0, 53.8424
11.887998403, 96.390, 2919.0, 54.0278
11.940519534, 96.390, 2860.0, 53.4790
11.993040664, 96.390, 2906.0, 53.9073
12.045561795, 96.390, 2916.0, 54.0000
12.098082926, 96.390, 2867.0, 53.5444
12.150604056, 96.390, 2902.0, 53.8702
12.203125187, 96.390, 2905.0, 53.8981
12.255646318, 96.390, 2802.0, 52.9339
12.308167449, 96.390, 2751.0, 52.4500
12.360688579, 96.390, 2784.0, 52.7636
12.413209710, 96.390, 2918.0, 54.0185
12.465730841, 96.390, 2845.0, 53.3385
12.518251971, 96.390, 2816.0, 53.0660
12.570773102, 96.390, 2844.0, 53.3292
12.623294233, 96.390, 2960.0, 54.4059
12.675815364, 96.390, 2843.0, 53.3198
12.728336494, 96.390, 2823.0, 53.1319
12.780857625, 96.390, 2738.0, 52.3259
12.833378756, 96.390, 2726.0, 52.2111
12.885899886, 96.390, 2618.0, 51.1664
12.938421017, 96.390, 2703.0, 51.9904
12.990942148, 96.390, 2679.0, 51.7591
13.043463279, 96.390, 2586.0, 50.8527
13.095984409, 96.390, 2540.0, 50.3984
13.148505540, 96.390, 2566.0, 50.6557
13.201026671, 96.390, 2641.0, 51.3907
13.253547801, 96.390, 2608.0, 51.0686
13.306068932, 96.390, 2688.0, 51.8459
13.358590063, 96.390, 2659.0, 51.5655
13.411111193, 96.390, 2597.0, 50.9608
13.463632324, 96.390, 2767.0, 52.6023
13.516153455, 96.390, 2601.0, 51.0000
13.568674586, 96.390, 2551.0, 50.5074
13.621195716, 96.390, 2580.0, 50.7937
13.673716847, 96.390, 2556.0, 50.5569
13.726237978, 96.390, 2807.0, 52.9811
13.778759108, 96.390, 2797.0, 52.8867
13.831280239, 96.390, 2627.0, 51.2543
13.883801370, 96.390, 2548.0, 50.4777
13.936322501, 96.390, 2498.0, 49.9800
13.988843631, 96.390, 2511.0, 50.1099
14.041364762, 96.390, 2539.0, 50.3885
14.093885893, 96.390, 2636.0, 51.3420
14.146407023, 96.390, 2536.0, 50.3587
14.198928154, 96.390, 2929.0, 54.1202
14.251449285, 96.390, 3904.0, 62.4820
14.303970416, 96.390, 3910.0, 62.5300
14.356491546, 96.390, 2564.0, 50.6360
14.409012677, 96.390, 2516.0, 50.1597
14.461533808, 96.390, 2815.0, 53.0566
14.514054938, 96.390, 3161.0, 56.2228
14.566576069, 96.390, 2810.0, 53.0094
14.619097200, 96.390, 2359.0, 48.5695
14.671618331, 96.390, 2381.0, 48.7955
14.724139461, 96.390, 2361.0, 48.5901
14.776660592, 96.390, 2440.0, 49.3964
14.829181723, 96.390, 2402.0, 49.0102
14.881702853, 96.390, 2420.0, 49.1935
14.934223984, 96.390, 2288.0, 47.8330
14.986745115, 96.390, 2365.0, 48.6313
15.039266245, 96.390, 2444.0, 49.4368
15.091787376, 96.390, 2462.0, 49.6185
15.144308507, 96.390, 2710.0, 52.0577
15.196829638, 96.390, 2883.0, 53.6936
15.249350768, 96.390, 2962.0, 54.4243
15.301871899, 96.390, 2895.0, 53.8052
15.354393030, 96.390, 2585.0, 50.8429
15.406914160, 96.390, 2582.0, 50.8134
15.459435291, 96.390, 2352.0, 48.4974
15.511956422, 96.390, 2261.0, 47.5500
15.564477553, 96.390, 2244.0, 47.3709
15.616998683, 96.390, 2334.0, 48.3115
15.669519814, 96.390, 2416.0, 49.1528
15.722040945, 96.390, 2362.0, 48.6004
15.774562075, 96.390, 2254.0, 47.4763
15.827083206, 96.390, 2282.0, 47.7703
15.879604337, 96.390, 2249.0, 47.4236
15.932125468, 96.390, 2223.0, 47.1487
15.984646598, 96.390, 2253.0, 47.4658
16.037167729, 96.390, 2219.0, 47.1063
16.089688860, 96.390, 2307.0, 48.0312
16.142209990, 96.390, 2230.0, 47.2229
16.194731121, 96.390, 2358.0, 48.5592
16.247252252, 96.390, 2480.0, 49.7996
16.299773382, 96.390, 2761.0, 52.5452
16.352294513, 96.390, 2553.0, 50.5272
16.404815644, 96.390, 2335.0, 48.3218
16.457336775, 96.390, 2232.0, 47.2440
16.509857905, 96.390, 2161.0, 46.4866
16.562379036, 96.390, 2221.0, 47.1275
16.614900167, 96.390, 2232.0, 47.2440
16.667421297, 96.390, 2222.0, 47.1381
16.719942428, 96.390, 2194.0, 46.8402
16.772463559, 96.390, 2239.0, 47.3181
16.824984690, 96.390, 2214.0, 47.0532
16.877505820, 96.390, 2248.0, 47.4131
16.930026951, 96.390, 2168.0, 46.5618
16.982548082, 96.390, 2201.0, 46.9148
17.035069212, 96.390, 2242.0, 47.3498
17.087590343, 96.390, 2206.0, 46.9681
17.140111474, 96.390, 2276.0, 47.7074
17.192632605, 96.390, 2257.0, 47.5079
17.245153735, 96.390, 2203.0, 46.9361
17.297674866, 96.390, 2295.0, 47.9062
17.350195997, 96.390, 2353.0, 48.5077
17.402717127, 96.390, 2312.0, 48.0833
17.455238258, 96.390, 2333.0, 48.3011
17.507759389, 96.390, 2283.0, 47.7807
17.560280520, 96.390, 2255.0, 47.4868
17.612801650, 96.390, 2257.0, 47.5079
17.665322781, 96.390, 2242.0, 47.3498
17.717843912, 96.390, 2231.0, 47.2335
17.770365042, 96.390, 2233.0, 47.2546
17.822886173, 96.390, 2264.0, 47.5815
17.875407304, 96.390, 2180.0, 46.6905
17.927928434, 96.390, 2194.0, 46.8402
17.980449565, 96.390, 2312.0, 48.0833
18.032970696, 96.390, 2337.0, 48.3425
18.085491827, 96.390, 2353.0, 48.5077
18.138012957, 96.390, 2298.0, 47.9375
18.190534088, 96.390, 2333.0, 48.3011
18.243055219, 96.390, 2406.0, 49.0510
18.295576349, 96.390, 2472.0, 49.7192
18.348097480, 96.390, 2353.0, 48.5077
18.400618611, 96.390, 2549.0, 50.4876
18.453139742, 96.390, 2583.0, 50.8232
18.505660872, 96.390, 2410.0, 49.0918
18.558182003, 96.390, 2350.0, 48.4768
18.610703134, 96.390, 2333.0, 48.3011
18.663224264, 96.390, 2306.0, 48.0208
18.715745395, 96.390, 2410.0, 49.0918
18.768266526, 96.390, 2449.0, 49.4874
18.820787657, 96.390, 2781.0, 52.7352
18.873308787, 96.390, 2937.0, 54.1941
18.925829918, 96.390, 3000.0, 54.7723
18.978351049, 96.390, 3105.0, 55.7225
19.030872179, 96.390, 2859.0, 53.4696
19.083393310, 96.390, 2707.0, 52.0288
19.135914441, 96.390, 2592.0, 50.9117
19.188435572, 96.390, 2519.0, 50.1896
19.240956702, 96.390, 2449.0, 49.4874
19.293477833, 96.390, 2455.0, 49.5480
19.345998964, 96.390, 2589.0, 50.8822
19.398520094, 96.390, 2541.0, 50.4083
19.451041225, 96.390, 2668.0, 51.6527
19.503562356, 96.390, 2493.0, 49.9300
19.556083486, 96.390, 2566.0, 50.6557
19.608604617, 96.390, 2417.0, 49.1630
19.661125748, 96.390, 2625.0, 51.2348
19.713646879, 96.390, 2720.0, 52.1536
19.766168009, 96.390, 3059.0, 55.3082
19.818689140, 96.390, 2963.0, 54.4334
19.871210271, 96.390, 2847.0, 53.3573
19.923731401, 96.390, 3058.0, 55.2992
19.976252532, 96.390, 3185.0, 56.4358
20.028773663, 96.390, 3011.0, 54.8726
20.081294794, 96.390, 2654.0, 51.5170
20.133815924, 96.390, 2547.0, 50.4678
20.186337055, 96.390, 2511.0, 50.1099
20.238858186, 96.390, 2713.0, 52.0865
20.291379316, 96.390, 2750.0, 52.4404
20.343900447, 96.390, 2859.0, 53.4696
20.396421578, 96.390, 3463.0, 58.8473
20.448942709, 96.390, 3325.0, 57.6628
20.501463839, 96.390, 3061.0, 55.3263
20.553984970, 96.390, 3325.0, 57.6628
20.606506101, 96.390, 3471.0, 58.9152
20.659027231, 96.390, 4069.0, 63.7887
20.711548362, 96.390, 3996.0, 63.2139
20.764069493, 96.390, 3392.0, 58.2409
20.816590623, 96.390, 2840.0, 53.2917
20.869111754, 96.390, 2756.0, 52.4976
20.921632885, 96.390, 2712.0, 52.0769
20.974154016, 96.390, 2935.0, 54.1756
21.026675146, 96.390, 2864.0, 53.5164
21.079196277, 96.390, 2748.0, 52.4214
21.131717408, 96.390, 2748.0, 52.4214
21.184238538, 96.390, 2747.0, 52.4118
21.236759669, 96.390, 2729.0, 52.2398
21.289280800, 96.390, 2853.0, 53.4135
21.341801931, 96.390, 2798.0, 52.8961
21.394323061, 96.390, 2743.0, 52.3737
21.446844192, 96.390, 2730.0, 52.2494
21.499365323, 96.390, 2698.0, 51.9423
21.551886453, 96.390, 2763.0, 52.5642
21.604407584, 96.390, 3023.0, 54.9818
21.656928715, 96.390, 3073.0, 55.4346
21.709449846, 96.390, 2926.0, 54.0925
21.761970976, 96.390, 2865.0, 53.5257
21.814492107, 96.390, 2662.0, 51.5946
21.867013238, 96.390, 2652.0, 51.4976
21.919534368, 96.390, 2766.0, 52.5928
21.972055499, 96.390, 2731.0, 52.2590
22.024576630, 96.390, 2669.0, 51.6624
22.077097761, 96.390, 2835.0, 53.2447
22.129618891, 96.390, 2679.0, 51.7591
22.182140022, 96.390, 2677.0, 51.7397
22.234661153, 96.390, 2608.0, 51.0686
22.287182283, 96.390, 2686.0, 51.8266
22.339703414, 96.390, 2551.0, 50.5074
22.392224545, 96.390, 2667.0, 51.6430
22.444745675, 96.390, 2663.0, 51.6043
22.497266806, 96.390, 2624.0, 51.2250
22.549787937, 96.390, 2715.0, 52.1057
22.602309068, 96.390, 2739.0, 52.3355
22.654830198, 96.390, 2765.0, 52.5833
22.707351329, 96.390, 2823.0, 53.1319
22.759872460, 96.390, 2867.0, 53.5444
22.812393590, 96.390, 3097.0, 55.6507
22.864914721, 96.390, 3177.0, 56.3649
22.917435852, 96.390, 3005.0, 54.8179
22.969956983, 96.390, 2918.0, 54.0185
23.022478113, 96.390, 2943.0, 54.2494
23.074999244, 96.390, 2912.0, 53.9630
23.127520375, 96.390, 3033.0, 55.0727
23.180041505, 96.390, 3051.0, 55.2359
23.232562636, 96.390, 2934.0, 54.1664
23.285083767, 96.390, 2895.0, 53.8052
23.337604898, 96.390, 3064.0, 55.3534
23.390126028, 96.390, 3022.0, 54.9727
23.442647159, 96.390, 2863.0, 53.5070
23.495168290, 96.390, 3444.0, 58.6856
23.547689420, 96.390, 3222.0, 56.7627
23.600210551, 96.390, 2906.0, 53.9073
23.652731682, 96.390, 2605.0, 51.0392
23.705252813, 96.390, 2621.0, 51.1957
23.757773943, 96.390, 2470.0, 49.6991
23.810295074, 96.390, 2633.0, 51.3128
23.862816205, 96.390, 2497.0, 49.9700
23.915337335, 96.390, 2484.0, 49.8397
23.967858466, 96.390, 2497.0, 49.9700
24.020379597, 96.390, 2434.0, 49.3356
24.072900727, 96.390, 2526.0, 50.2593
24.125421858, 96.390, 2618.0, 51.1664
24.177942989, 96.390, 2891.0, 53.7680
24.230464120, 96.390, 2740.0, 52.3450
24.282985250, 96.390, 2548.0, 50.4777
24.335506381, 96.390, 2542.0, 50.4183
24.388027512, 96.390, 2376.0, 48.7442
24.440548642, 96.390, 2506.0, 50.0600
24.493069773, 96.390, 2516.0, 50.1597
24.545590904, 96.390, 3364.0, 58.0000
24.598112035, 96.390, 2890.0, 53.7587
24.650633165, 96.390, 2464.0, 49.6387
24.703154296, 96.390, 2275.0, 47.6970
24.755675427, 96.390, 2287.0, 47.8226
24.808196557, 96.390, 2289.0, 47.8435
24.860717688, 96.390, 2122.0, 46.0652
24.913238819, 96.390, 2232.0, 47.2440
24.965759950, 96.390, 2255.0, 47.4868
25.018281080, 96.390, 2239.0, 47.3181
25.070802211, 96.390, 2206.0, 46.9681
25.123323342, 96.390, 2265.0, 47.5920
25.175844472, 96.390, 2262.0, 47.5605
25.228365603, 96.390, 2158.0, 46.4543
25.280886734, 96.390, 2248.0, 47.4131
25.333407864, 96.390, 2886.0, 53.7215
25.385928995, 96.390, 2989.0, 54.6717
25.438450126, 96.390, 2824.0, 53.1413
25.490971257, 96.390, 2264.0, 47.5815
25.543492387, 96.390, 2142.0, 46.2817
25.596013518, 96.390, 2173.0, 46.6154
25.648534649, 96.390, 2052.0, 45.2990
25.701055779, 96.390, 2108.0, 45.9130
25.753576910, 96.390, 2131.0, 46.1628
25.806098041, 96.390, 2097.0, 45.7930
25.858619172, 96.390, 2138.0, 46.2385
25.911140302, 96.390, 2117.0, 46.0109
25.963661433, 96.390, 2147.0, 46.3357
26.016182564, 96.390, 2073.0, 45.5302
26.068703694, 96.390, 1974.0, 44.4297
26.121224825, 96.390, 1940.0, 44.0454
26.173745956, 96.390, 1937.0, 44.0114
26.226267087, 96.390, 2012.0, 44.8553
26.278788217, 96.390, 2037.0, 45.1331
26.331309348, 96.390, 2059.0, 45.3762
26.383830479, 96.390, 2098.0, 45.8039
26.436351609, 96.390, 2086.0, 45.6727
26.488872740, 96.390, 2042.0, 45.1885
26.541393871, 96.390, 2016.0, 44.8999
26.593915002, 96.390, 2076.0, 45.5631
26.646436132, 96.390, 2082.0, 45.6289
26.698957263, 96.390, 2165.0, 46.5296
26.751478394, 96.390, 2352.0, 48.4974
26.803999524, 96.390, 2526.0, 50.2593
26.856520655, 96.390, 2366.0, 48.6415
26.909041786, 96.390, 2317.0, 48.1352
26.961562916, 96.390, 2241.0, 47.3392
27.014084047, 96.390, 2542.0, 50.4183
27.066605178, 96.390, 2628.0, 51.2640
27.119126309, 96.390, 2733.0, 52.2781
27.171647439, 96.390, 3009.0, 54.8544
27.224168570, 96.390, 2850.0, 53.3854
27.276689701, 96.390, 2403.0, 49.0204
27.329210831, 96.390, 2155.0, 46.4220
27.381731962, 96.390, 2079.0, 45.5961
27.434253093, 96.390, 1904.0, 43.6348
27.486774224, 96.390, 1902.0, 43.6119
27.539295354, 96.390, 1786.0, 42.2611
27.591816485, 96.390, 1888.0, 43.4511
27.644337616, 96.390, 1914.0, 43.7493
27.696858746, 96.390, 1958.0, 44.2493
27.749379877, 96.390, 1832.0, 42.8019
27.801901008, 96.390, 1816.0, 42.6146
27.854422139, 96.390, 1854.0, 43.0581
27.906943269, 96.390, 1904.0, 43.6348
27.959464400, 96.390, 1951.0, 44.1701
28.011985531, 96.390, 1878.0, 43.3359
28.064506661, 96.390, 2012.0, 44.8553
28.117027792, 96.390, 1966.0, 44.3396
28.169548923, 96.390, 1882.0, 43.3820
28.222070054, 96.390, 2009.0, 44.8219
28.274591184, 96.390, 1948.0, 44.1362
28.327112315, 96.390, 2037.0, 45.1331
28.379633446, 96.390, 2099.0, 45.8148
28.432154576, 96.390, 1939.0, 44.0341
28.484675707, 96.390, 1988.0, 44.5870
28.537196838, 96.390, 1940.0, 44.0454
28.589717968, 96.390, 1953.0, 44.1928
28.642239099, 96.390, 1890.0, 43.4741
28.694760230, 96.390, 1865.0, 43.1856
28.747281361, 96.390, 2003.0, 44.7549
28.799802491, 96.390, 1883.0, 43.3935
28.852323622, 96.390, 1943.0, 44.0795
28.904844753, 96.390, 1972.0, 44.4072
28.957365883, 96.390, 2016.0, 44.8999
29.009887014, 96.390, 2046.0, 45.2327
29.062408145, 96.390, 2023.0, 44.9778
29.114929276, 96.390, 2230.0, 47.2229
29.167450406, 96.390, 2291.0, 47.8644
29.219971537, 96.390, 2353.0, 48.5077
29.272492668, 96.390, 2618.0, 51.1664
29.325013798, 96.390, 2541.0, 50.4083
29.377534929, 96.390, 2433.0, 49.3254
29.430056060, 96.390, 2446.0, 49.4571
29.482577191, 96.390, 2376.0, 48.7442
29.535098321, 96.390, 2192.0, 46.8188
29.587619452, 96.390, 2041.0, 45.1774
29.640140583, 96.390, 2016.0, 44.8999
29.692661713, 96.390, 2018.0, 44.9222
29.745182844, 96.390, 2012.0, 44.8553
29.797703975, 96.390, 1833.0, 42.8135
29.850225105, 96.390, 1820.0, 42.6615
29.902746236, 96.390, 1984.0, 44.5421
29.955267367, 96.390, 1925.0, 43.8748
30.007788498, 96.390, 1918.0, 43.7950
30.060309628, 96.390, 1892.0, 43.4971
30.112830759, 96.390, 1854.0, 43.0581
30.165351890, 96.390, 1823.0, 42.6966
30.217873020, 96.390, 1824.0, 42.7083
30.270394151, 96.390, 1954.0, 44.2041
30.322915282, 96.390, 1925.0, 43.8748
30.375436413, 96.390, 1941.0, 44.0568
30.427957543, 96.390, 1942.0, 44.0681
30.480478674, 96.390, 2019.0, 44.9333
30.532999805, 96.390, 1975.0, 44.4410
30.585520935, 96.390, 2109.0, 45.9239
30.638042066, 96.390, 2261.0, 47.5500
30.690563197, 96.390, 2555.0, 50.5470
30.743084328, 96.390, 2583.0, 50.8232
30.795605458, 96.390, 2554.0, 50.5371
30.848126589, 96.390, 2168.0, 46.5618
30.900647720, 96.390, 2116.0, 46.0000
30.953168850, 96.390, 1958.0, 44.2493
31.005689981, 96.390, 2115.0, 45.9891
31.058211112, 96.390, 2054.0, 45.3211
31.110732243, 96.390, 2201.0, 46.9148
31.163253373, 96.390, 2435.0, 49.3457
31.215774504, 96.390, 2680.0, 51.7687
31.268295635, 96.390, 2674.0, 51.7107
31.320816765, 96.390, 2661.0, 51.5849
31.373337896, 96.390, 2573.0, 50.7247
31.425859027, 96.390, 2508.0, 50.0799
31.478380157, 96.390, 2597.0, 50.9608
31.530901288, 96.390, 2333.0, 48.3011
31.583422419, 96.390, 2359.0, 48.5695
31.635943550, 96.390, 2317.0, 48.1352
31.688464680, 96.390, 3097.0, 55.6507
31.740985811, 96.390, 4981.0, 70.5762
31.793506942, 96.390, 4235.0, 65.0769
31.846028072, 96.390, 2328.0, 48.2494
31.898549203, 96.390, 2106.0, 45.8912
31.951070334, 96.390, 2494.0, 49.9400
32.003591465, 96.390, 2764.0, 52.5738
32.056112595, 96.390, 3142.0, 56.0535
32.108633726, 96.390, 2764.0, 52.5738
32.161154857, 96.390, 2508.0, 50.0799
32.213675987, 96.390, 2281.0, 47.7598
32.266197118, 96.390, 2324.0, 48.2079
32.318718249, 96.390, 2255.0, 47.4868
32.371239380, 96.390, 2055.0, 45.3321
32.423760510, 96.390, 1901.0, 43.6005
32.476281641, 96.390, 1855.0, 43.0697
32.528802772, 96.390, 1874.0, 43.2897
32.581323902, 96.390, 1955.0, 44.2154
32.633845033, 96.390, 1862.0, 43.1509
32.686366164, 96.390, 1877.0, 43.3244
32.738887295, 96.390, 1888.0, 43.4511
32.791408425, 96.390, 1912.0, 43.7264
32.843929556, 96.390, 1844.0, 42.9418
32.896450687, 96.390, 1920.0, 43.8178
32.948971817, 96.390, 2130.0, 46.1519
33.001492948, 96.390, 2071.0, 45.5082
33.054014079, 96.390, 2085.0, 45.6618
33.106535209, 96.390, 2217.0, 47.0850
33.159056340, 96.390, 2107.0, 45.9021
33.211577471, 96.390, 2163.0, 46.5081
33.264098602, 96.390, 2098.0, 45.8039
33.316619732, 96.390, 2158.0, 46.4543
33.369140863, 96.390, 2155.0, 46.4220
33.421661994, 96.390, 2403.0, 49.0204
33.474183124, 96.390, 3772.0, 61.4166
33.526704255, 96.390, 2745.0, 52.3927
33.579225386, 96.390, 2383.0, 48.8160
33.631746517, 96.390, 1968.0, 44.3621
33.684267647, 96.390, 2014.0, 44.8776
33.736788778, 96.390, 2036.0, 45.1221
33.789309909, 96.390, 2054.0, 45.3211
33.841831039, 96.390, 2182.0, 46.7119
33.894352170, 96.390, 2353.0, 48.5077
33.946873301, 96.390, 2437.0, 49.3660
33.999394432, 96.390, 2544.0, 50.4381
34.051915562, 96.390, 2333.0, 48.3011
34.104436693, 96.390, 2280.0, 47.7493
34.156957824, 96.390, 2241.0, 47.3392
34.209478954, 96.390, 2261.0, 47.5500
34.262000085, 96.390, 2337.0, 48.3425
34.314521216, 96.390, 2411.0, 49.1019
34.367042346, 96.390, 2337.0, 48.3425
34.419563477, 96.390, 2539.0, 50.3885
34.472084608, 96.390, 2652.0, 51.4976
34.524605739, 96.390, 2847.0, 53.3573
34.577126869, 96.390, 2862.0, 53.4977
34.629648000, 96.390, 2823.0, 53.1319
34.682169131, 96.390, 2693.0, 51.8941
34.734690261, 96.390, 2514.0, 50.1398
34.787211392, 96.390, 2539.0, 50.3885
34.839732523, 96.390, 2517.0, 50.1697
34.892253654, 96.390, 2681.0, 51.7784
34.944774784, 96.390, 2962.0, 54.4243
34.997295915, 96.390, 2897.0, 53.8238
35.049817046, 96.390, 2649.0, 51.4684
35.102338176, 96.390, 2365.0, 48.6313
35.154859307, 96.390, 2399.0, 48.9796
35.207380438, 96.390, 2528.0, 50.2792
35.259901569, 96.390, 2363.0, 48.6107
35.312422699, 96.390, 2311.0, 48.0729
35.364943830, 96.390, 2139.0, 46.2493
35.417464961, 96.390, 2062.0, 45.4093
35.469986091, 96.390, 2131.0, 46.1628
35.522507222, 96.390, 2086.0, 45.6727
35.575028353, 96.390, 2142.0, 46.2817
35.627549484, 96.390, 2053.0, 45.3100
35.680070614, 96.390, 2232.0, 47.2440
35.732591745, 96.390, 2184.0, 46.7333
35.785112876, 96.390, 2184.0, 46.7333
35.837634006, 96.390, 2124.0, 46.0869
35.890155137, 96.390, 2377.0, 48.7545
35.942676268, 96.390, 2409.0, 49.0816
35.995197398, 96.390, 2448.0, 49.4773
36.047718529, 96.390, 2301.0, 47.9687
36.100239660, 96.390, 2341.0, 48.3839
36.152760791, 96.390, 2486.0, 49.8598
36.205281921, 96.390, 2620.0, 51.1859
36.257803052, 96.390, 2277.0, 47.7179
36.310324183, 96.390, 2169.0, 46.5725
36.362845313, 96.390, 2043.0, 45.1996
36.415366444, 96.390, 1870.0, 43.2435
36.467887575, 96.390, 1868.0, 43.2204
36.520408706, 96.390, 1792.0, 42.3320
36.572929836, 96.390, 1852.0, 43.0349
36.625450967, 96.390, 2001.0, 44.7325
36.677972098, 96.390, 1964.0, 44.3170
36.730493228, 96.390, 1840.0, 42.8952
36.783014359, 96.390, 1703.0, 41.2674
36.835535490, 96.390, 1791.0, 42.3202
36.888056621, 96.390, 1750.0, 41.8330
36.940577751, 96.390, 1688.0, 41.0853
36.993098882, 96.390, 1657.0, 40.7063
37.045620013, 96.390, 1709.0, 41.3401
37.098141143, 96.390, 1714.0, 41.4005
37.150662274, 96.390, 1781.0, 42.2019
37.203183405, 96.390, 1813.0, 42.5793
37.255704535, 96.390, 1800.0, 42.4264
37.308225666, 96.390, 1807.0, 42.5088
37.360746797, 96.390, 1729.0, 41.5812
37.413267928, 96.390, 1797.0, 42.3910
37.465789058, 96.390, 1874.0, 43.2897
37.518310189, 96.390, 1879.0, 43.3474
37.570831320, 96.390, 1763.0, 41.9881
37.623352450, 96.390, 1818.0, 42.6380
37.675873581, 96.390, 1840.0, 42.8952
37.728394712, 96.390, 1967.0, 44.3509
37.780915843, 96.390, 2017.0, 44.9110
37.833436973, 96.390, 2381.0, 48.7955
37.885958104, 96.390, 2143.0, 46.2925
37.938479235, 96.390, 2052.0, 45.2990
37.991000365, 96.390, 1841.0, 42.9069
38.043521496, 96.390, 1661.0, 40.7554
38.096042627, 96.390, 1711.0, 41.3642
38.148563758, 96.390, 1794.0, 42.3556
38.201084888, 96.390, 1739.0, 41.7013
38.253606019, 96.390, 1796.0, 42.3792
38.306127150, 96.390, 1734.0, 41.6413
38.358648280, 96.390, 1603.0, 40.0375
38.411169411, 96.390, 1658.0, 40.7185
38.463690542, 96.390, 1549.0, 39.3573
38.516211673, 96.390, 1572.0, 39.6485
38.568732803, 96.390, 1666.0, 40.8167
38.621253934, 96.390, 1606.0, 40.0749
38.673775065, 96.390, 1657.0, 40.7063
38.726296195, 96.390, 1690.0, 41.1096
38.778817326, 96.390, 1719.0, 41.4608
38.831338457, 96.390, 1614.0, 40.1746
38.883859587, 96.390, 1644.0, 40.5463
38.936380718, 96.390, 1506.0, 38.8072
38.988901849, 96.390, 1512.0, 38.8844
39.041422980, 96.390, 1491.0, 38.6135
39.093944110, 96.390, 1521.0, 39.0000
39.146465241, 96.390, 1610.0, 40.1248
39.198986372, 96.390, 1477.0, 38.4318
39.251507502, 96.390, 1653.0, 40.6571
39.304028633, 96.390, 1607.0, 40.0874
39.356549764, 96.390, 1629.0, 40.3609
39.409070895, 96.390, 1668.0, 40.8412
39.461592025, 96.390, 1634.0, 40.4228
39.514113156, 96.390, 1579.0, 39.7366
39.566634287, 96.390, 1528.0, 39.0896
39.619155417, 96.390, 1579.0, 39.7366
39.671676548, 96.390, 1526.0, 39.0640
39.724197679, 96.390, 1618.0, 40.2244
39.776718810, 96.390, 1575.0, 39.6863
39.829239940, 96.390, 1572.0, 39.6485
39.881761071, 96.390, 1637.0, 40.4599
39.934282202, 96.390, 1537.0, 39.2046
39.986803332, 96.390, 1566.0, 39.5727
40.039324463, 96.390, 1535.0, 39.1791
40.091845594, 96.390, 1502.0, 38.7556
40.144366725, 96.390, 1504.0, 38.7814
40.196887855, 96.390, 1519.0, 38.9744
40.249408986, 96.390, 1402.0, 37.4433
40.301930117, 96.390, 1355.0, 36.8103
40.354451247, 96.390, 1367.0, 36.9730
40.406972378, 96.390, 1359.0, 36.8646
40.459493509, 96.390, 1417.0, 37.6431
40.512014639, 96.390, 1425.0, 37.7492
40.564535770, 96.390, 1544.0, 39.2938
40.617056901, 96.390, 1491.0, 38.6135
40.669578032, 96.390, 1407.0, 37.5100
40.722099162, 96.390, 1375.0, 37.0810
40.774620293, 96.390, 1364.0, 36.9324
40.827141424, 96.390, 1321.0, 36.3456
40.879662554, 96.390, 1274.0, 35.6931
40.932183685, 96.390, 1273.0, 35.6791
40.984704816, 96.390, 1358.0, 36.8511
41.037225947, 96.390, 1410.0, 37.5500
41.089747077, 96.390, 1431.0, 37.8286
41.142268208, 96.390, 1295.0, 35.9861
41.194789339, 96.390, 1399.0, 37.4032
41.247310469, 96.390, 1267.0, 35.5949
41.299831600, 96.390, 1408.0, 37.5233
41.352352731, 96.390, 1544.0, 39.2938
41.404873862, 96.390, 1544.0, 39.2938
41.457394992, 96.390, 1429.0, 37.8021
41.509916123, 96.390, 1450.0, 38.0789
41.562437254, 96.390, 1384.0, 37.2022
41.614958384, 96.390, 1248.0, 35.3270
41.667479515, 96.390, 1312.0, 36.2215
41.720000646, 96.390, 1351.0, 36.7560
41.772521776, 96.390, 1390.0, 37.2827
41.825042907, 96.390, 1387.0, 37.2424
41.877564038, 96.390, 1323.0, 36.3731
41.930085169, 96.390, 1293.0, 35.9583
41.982606299, 96.390, 1320.0, 36.3318
42.035127430, 96.390, 1387.0, 37.2424
42.087648561, 96.390, 1612.0, 40.1497
42.140169691, 96.390, 1661.0, 40.7554
42.192690822, 96.390, 1569.0, 39.6106
42.245211953, 96.390, 1543.0, 39.2810
42.297733084, 96.390, 1403.0, 37.4566
42.350254214, 96.390, 1349.0, 36.7287
42.402775345, 96.390, 1197.0, 34.5977
42.455296476, 96.390, 1228.0, 35.0428
42.507817606, 96.390, 1205.0, 34.7131
42.560338737, 96.390, 1347.0, 36.7015
42.612859868, 96.390, 1321.0, 36.3456
42.665380999, 96.390, 1430.0, 37.8153
42.717902129, 96.390, 1570.0, 39.6232
42.770423260, 96.390, 1684.0, 41.0366
42.822944391, 96.390, 1415.0, 37.6165
42.875465521, 96.390, 1497.0, 38.6911
42.927986652, 96.390, 1300.0, 36.0555
42.980507783, 96.390, 1291.0, 35.9305
43.033028914, 96.390, 1275.0, 35.7071
43.085550044, 96.390, 1290.0, 35.9166
43.138071175, 96.390, 1279.0, 35.7631
43.190592306, 96.390, 1319.0, 36.3180
43.243113436, 96.390, 1278.0, 35.7491
43.295634567, 96.390, 1262.0, 35.5246
43.348155698, 96.390, 1197.0, 34.5977
43.400676828, 96.390, 1174.0, 34.2637
43.453197959, 96.390, 1275.0, 35.7071
43.505719090, 96.390, 1242.0, 35.2420
43.558240221, 96.390, 1230.0, 35.0714
43.610761351, 96.390, 1244.0, 35.2704
43.663282482, 96.390, 1250.0, 35.3553
43.715803613, 96.390, 1383.0, 37.1887
43.768324743, 96.390, 1358.0, 36.8511
43.820845874, 96.390, 1296.0, 36.0000
43.873367005, 96.390, 1273.0, 35.6791
43.925888136, 96.390, 1297.0, 36.0139
43.978409266, 96.390, 1313.0, 36.2353
44.030930397, 96.390, 1289.0, 35.9026
44.083451528, 96.390, 1271.0, 35.6511
44.135972658, 96.390, 1258.0, 35.4683
44.188493789, 96.390, 1301.0, 36.0694
44.241014920, 96.390, 1278.0, 35.7491
44.293536051, 96.390, 1290.0, 35.9166
44.346057181, 96.390, 1415.0, 37.6165
44.398578312, 96.390, 1367.0, 36.9730
44.451099443, 96.390, 1345.0, 36.6742
44.503620573, 96.390, 1363.0, 36.9188
44.556141704, 96.390, 1366.0, 36.9594
44.608662835, 96.390, 1333.0, 36.5103
44.661183966, 96.390, 1267.0, 35.5949
44.713705096, 96.390, 1331.0, 36.4829
44.766226227, 96.390, 1306.0, 36.1386
44.818747358, 96.390, 1296.0, 36.0000
44.871268488, 96.390, 1278.0, 35.7491
44.923789619, 96.390, 1341.0, 36.6197
44.976310750, 96.390, 1300.0, 36.0555
45.028831880, 96.390, 1377.0, 37.1080
45.081353011, 96.390, 1425.0, 37.7492
45.133874142, 96.390, 1649.0, 40.6079
45.186395273, 96.390, 1403.0, 37.4566
45.238916403, 96.390, 1427.0, 37.7757
45.291437534, 96.390, 1466.0, 38.2884
45.343958665, 96.390, 1349.0, 36.7287
45.396479795, 96.390, 1309.0, 36.1801
45.449000926, 96.390, 1352.0, 36.7696
45.501522057, 96.390, 1329.0, 36.4555
45.554043188, 96.390, 1226.0, 35.0143
45.606564318, 96.390, 1309.0, 36.1801
45.659085449, 96.390, 1299.0, 36.0416
45.711606580, 96.390, 1345.0, 36.6742
45.764127710, 96.390, 1289.0, 35.9026
45.816648841, 96.390, 1325.0, 36.4005
45.869169972, 96.390, 1346.0, 36.6879
45.921691103, 96.390, 1242.0, 35.2420
45.974212233, 96.390, 1300.0, 36.0555
46.026733364, 96.390, 1295.0, 35.9861
46.079254495, 96.390, 1340.0, 36.6060
46.131775625, 96.390, 1390.0, 37.2827
46.184296756, 96.390, 1476.0, 38.4187
46.236817887, 96.390, 1544.0, 39.2938
46.289339017, 96.390, 1695.0, 41.1704
46.341860148, 96.390, 1472.0, 38.3667
46.394381279, 96.390, 1590.0, 39.8748
46.446902410, 96.390, 1400.0, 37.4166
46.499423540, 96.390, 1349.0, 36.7287
46.551944671, 96.390, 1329.0, 36.4555
46.604465802, 96.390, 1431.0, 37.8286
46.656986932, 96.390, 1473.0, 38.3797
46.709508063, 96.390, 1375.0, 37.0810
46.762029194, 96.390, 1399.0, 37.4032
46.814550325, 96.390, 1300.0, 36.0555
46.867071455, 96.390, 1316.0, 36.2767
46.919592586, 96.390, 1312.0, 36.2215
46.972113717, 96.390, 1374.0, 37.0675
47.024634847, 96.390, 1501.0, 38.7427
47.077155978, 96.390, 1365.0, 36.9459
47.129677109, 96.390, 1298.0, 36.0278
47.182198240, 96.390, 1228.0, 35.0428
47.234719370, 96.390, 1235.0, 35.1426
47.287240501, 96.390, 1190.0, 34.4964
47.339761632, 96.390, 1253.0, 35.3977
47.392282762, 96.390, 1317.0, 36.2905
47.444803893, 96.390, 1315.0, 36.2629
47.497325024, 96.390, 1256.0, 35.4401
47.549846155, 96.390, 1297.0, 36.0139
47.602367285, 96.390, 1299.0, 36.0416
47.654888416, 96.390, 1244.0, 35.2704
47.707409547, 96.390, 1319.0, 36.3180
47.759930677, 96.390, 1322.0, 36.3593
47.812451808, 96.390, 1253.0, 35.3977
47.864972939, 96.390, 1283.0, 35.8190
47.917494069, 96.390, 1255.0, 35.4260
47.970015200, 96.390, 1188.0, 34.4674
48.022536331, 96.390, 1224.0, 34.9857
48.075057462, 96.390, 1248.0, 35.3270
48.127578592, 96.390, 1240.0, 35.2136
48.180099723, 96.390, 1255.0, 35.4260
48.232620854, 96.390, 1233.0, 35.1141
48.285141984, 96.390, 1226.0, 35.0143
48.337663115, 96.390, 1265.0, 35.5668
48.390184246, 96.390, 1365.0, 36.9459
48.442705377, 96.390, 1360.0, 36.8782
48.495226507, 96.390, 1403.0, 37.4566
48.547747638, 96.390, 1325.0, 36.4005
48.600268769, 96.390, 1266.0, 35.5809
48.652789899, 96.390, 1220.0, 34.9285
48.705311030, 96.390, 1170.0, 34.2053
48.757832161, 96.390, 1171.0, 34.2199
48.810353292, 96.390, 1087.0, 32.9697
48.862874422, 96.390, 1115.0, 33.3916
48.915395553, 96.390, 1157.0, 34.0147
48.967916684, 96.390, 1194.0, 34.5543
49.020437814, 96.390, 1204.0, 34.6987
49.072958945, 96.390, 1145.0, 33.8378
49.125480076, 96.390, 1164.0, 34.1174
49.178001207, 96.390, 1155.0, 33.9853
49.230522337, 96.390, 1158.0, 34.0294
49.283043468, 96.390, 1212.0, 34.8138
49.335564599, 96.390, 1115.0, 33.3916
49.388085729, 96.390, 1191.0, 34.5109
49.440606860, 96.390, 1103.0, 33.2114
49.493127991, 96.390, 1077.0, 32.8177
49.545649121, 96.390, 1137.0, 33.7194
49.598170252, 96.390, 1126.0, 33.5559
49.650691383, 96.390, 1215.0, 34.8569
49.703212514, 96.390, 1128.0, 33.5857
49.755733644, 96.390, 1145.0, 33.8378
49.808254775, 96.390, 1055.0, 32.4808
49.860775906, 96.390, 1104.0, 33.2265
49.913297036, 96.390, 1059.0, 32.5423
49.965818167, 96.390, 1088.0, 32.9848
50.018339298, 96.390, 1044.0, 32.3110
50.070860429, 96.390, 1083.0, 32.9090
50.123381559, 96.390, 1140.0, 33.7639
50.175902690, 96.390, 1070.0, 32.7109
50.228423821, 96.390, 1119.0, 33.4515
50.280944951, 96.390, 1124.0, 33.5261
50.333466082, 96.390, 1165.0, 34.1321
50.385987213, 96.390, 1185.0, 34.4238
50.438508344, 96.390, 1197.0, 34.5977
50.491029474, 96.390, 1177.0, 34.3074
50.543550605, 96.390, 1132.0, 33.6452
50.596071736, 96.390, 1120.0, 33.4664
50.648592866, 96.390, 1075.0, 32.7872
50.701113997, 96.390, 1031.0, 32.1092
50.753635128, 96.390, 1074.0, 32.7719
50.806156258, 96.390, 1064.0, 32.6190
50.858677389, 96.390, 1115.0, 33.3916
50.911198520, 96.390, 1044.0, 32.3110
50.963719651, 96.390, 1184.0, 34.4093
51.016240781, 96.390, 1163.0, 34.1028
51.068761912, 96.390, 1205.0, 34.7131
51.121283043, 96.390, 1150.0, 33.9116
51.173804173, 96.390, 1166.0, 34.1467
51.226325304, 96.390, 1069.0, 32.6956
51.278846435, 96.390, 1075.0, 32.7872
51.331367566, 96.390, 951.0, 30.8383
51.383888696, 96.390, 1062.0, 32.5883
51.436409827, 96.390, 957.0, 30.9354
51.488930958, 96.390, 989.0, 31.4484
51.541452088, 96.390, 994.0, 31.5278
51.593973219, 96.390, 968.0, 31.1127
51.646494350, 96.390, 919.0, 30.3150
51.699015481, 96.390, 1021.0, 31.9531
51.751536611, 96.390, 994.0, 31.5278
51.804057742, 96.390, 1034.0, 32.1559
51.856578873, 96.390, 995.0, 31.5436
51.909100003, 96.390, 1029.0, 32.0780
51.961621134, 96.390, 1010.0, 31.7805
52.014142265, 96.390, 1002.0, 31.6544
52.066663396, 96.390, 960.0, 30.9839
52.119184526, 96.390, 1008.0, 31.7490
52.171705657, 96.390, 1009.0, 31.7648
52.224226788, 96.390, 988.0, 31.4325
52.276747918, 96.390, 1048.0, 32.3728
52.329269049, 96.390, 972.0, 31.1769
52.381790180, 96.390, 1021.0, 31.9531
52.434311310, 96.390, 1001.0, 31.6386
52.486832441, 96.390, 956.0, 30.9192
52.539353572, 96.390, 970.0, 31.1448
52.591874703, 96.390, 943.0, 30.7083
52.644395833, 96.390, 936.0, 30.5941
52.696916964, 96.390, 1001.0, 31.6386
52.749438095, 96.390, 1065.0, 32.6343
52.801959225, 96.390, 1012.0, 31.8119
52.854480356, 96.390, 999.0, 31.6070
52.907001487, 96.390, 1005.0, 31.7017
52.959522618, 96.390, 968.0, 31.1127
53.012043748, 96.390, 1004.0, 31.6860
53.064564879, 96.390, 1006.0, 31.7175
53.117086010, 96.390, 961.0, 31.0000
53.169607140, 96.390, 985.0, 31.3847
53.222128271, 96.390, 987.0, 31.4166
53.274649402, 96.390, 991.0, 31.4802
53.327170533, 96.390, 1003.0, 31.6702
53.379691663, 96.390, 972.0, 31.1769
53.432212794, 96.390, 904.0, 30.0666
53.484733925, 96.390, 952.0, 30.8545
53.537255055, 96.390, 901.0, 30.0167
53.589776186, 96.390, 919.0, 30.3150
53.642297317, 96.390, 952.0, 30.8545
53.694818448, 96.390, 908.0, 30.1330
53.747339578, 96.390, 953.0, 30.8707
53.799860709, 96.390, 915.0, 30.2490
53.852381840, 96.390, 1004.0, 31.6860
53.904902970, 96.390, 1057.0, 32.5115
53.957424101, 96.390, 1009.0, 31.7648
54.009945232, 96.390, 1045.0, 32.3265
54.062466362, 96.390, 1020.0, 31.9374
54.114987493, 96.390, 1065.0, 32.6343
54.167508624, 96.390, 1005.0, 31.7017
54.220029755, 96.390, 1086.0, 32.9545
54.272550885, 96.390, 1033.0, 32.1403
54.325072016, 96.390, 980.0, 31.3050
54.377593147, 96.390, 1047.0, 32.3574
54.430114277, 96.390, 989.0, 31.4484
54.482635408, 96.390, 983.0, 31.3528
54.535156539, 96.390, 919.0, 30.3150
54.587677670, 96.390, 875.0, 29.5804
54.640198800, 96.390, 912.0, 30.1993
54.692719931, 96.390, 875.0, 29.5804
54.745241062, 96.390, 911.0, 30.1828
54.797762192, 96.390, 889.0, 29.8161
54.850283323, 96.390, 873.0, 29.5466
54.902804454, 96.390, 879.0, 29.6479
54.955325585, 96.390, 909.0, 30.1496
55.007846715, 96.390, 867.0, 29.4449
55.060367846, 96.390, 868.0, 29.4618
55.112888977, 96.390, 829.0, 28.7924
55.165410107, 96.390, 893.0, 29.8831
55.217931238, 96.390, 838.0, 28.9482
55.270452369, 96.390, 877.0, 29.6142
55.322973499, 96.390, 834.0, 28.8791
55.375494630, 96.390, 933.0, 30.5450
55.428015761, 96.390, 934.0, 30.5614
55.480536892, 96.390, 852.0, 29.1890
55.533058022, 96.390, 829.0, 28.7924
55.585579153, 96.390, 870.0, 29.4958
55.638100284, 96.390, 854.0, 29.2233
55.690621414, 96.390, 814.0, 28.5307
55.743142545, 96.390, 855.0, 29.2404
55.795663676, 96.390, 831.0, 28.8271
55.848184807, 96.390, 820.0, 28.6356
55.900705937, 96.390, 920.0, 30.3315
55.953227068, 96.390, 881.0, 29.6816
56.005748199, 96.390, 860.0, 29.3258
56.058269329, 96.390, 928.0, 30.4631
56.110790460, 96.390, 894.0, 29.8998
56.163311591, 96.390, 889.0, 29.8161
56.215832722, 96.390, 946.0, 30.7571
56.268353852, 96.390, 874.0, 29.5635
56.320874983, 96.390, 861.0, 29.3428
56.373396114, 96.390, 890.0, 29.8329
56.425917244, 96.390, 912.0, 30.1993
56.478438375, 96.390, 869.0, 29.4788
56.530959506, 96.390, 846.0, 29.0861
56.583480637, 96.390, 843.0, 29.0345
56.636001767, 96.390, 869.0, 29.4788
56.688522898, 96.390, 834.0, 28.8791
56.741044029, 96.390, 841.0, 29.0000
56.793565159, 96.390, 834.0, 28.8791
56.846086290, 96.390, 820.0, 28.6356
56.898607421, 96.390, 885.0, 29.7489
56.951128551, 96.390, 847.0, 29.1033
57.003649682, 96.390, 854.0, 29.2233
57.056170813, 96.390, 839.0, 28.9655
57.108691944, 96.390, 833.0, 28.8617
57.161213074, 96.390, 914.0, 30.2324
57.213734205, 96.390, 850.0, 29.1548
57.266255336, 96.390, 856.0, 29.2575
57.318776466, 96.390, 875.0, 29.5804
57.371297597, 96.390, 913.0, 30.2159
57.423818728, 96.390, 839.0, 28.9655
57.476339859, 96.390, 875.0, 29.5804
57.528860989, 96.390, 834.0, 28.8791
57.581382120, 96.390, 874.0, 29.5635
57.633903251, 96.390, 856.0, 29.2575
57.686424381, 96.390, 851.0, 29.1719
57.738945512, 96.390, 823.0, 28.6880
57.791466643, 96.390, 866.0, 29.4279
57.843987774, 96.390, 872.0, 29.5296
57.896508904, 96.390, 865.0, 29.4109
57.949030035, 96.390, 876.0, 29.5973
58.001551166, 96.390, 915.0, 30.2490
58.054072296, 96.390, 1006.0, 31.7175
58.106593427, 96.390, 901.0, 30.0167
58.159114558, 96.390, 851.0, 29.1719
58.211635689, 96.390, 907.0, 30.1164
58.264156819, 96.390, 840.0, 28.9828
58.316677950, 96.390, 827.0, 28.7576
58.369199081, 96.390, 823.0, 28.6880
58.421720211, 96.390, 811.0, 28.4781
58.474241342, 96.390, 865.0, 29.4109
58.526762473, 96.390, 810.0, 28.4605
58.579283603, 96.390, 840.0, 28.9828
58.631804734, 96.390, 823.0, 28.6880
58.684325865, 96.390, 782.0, 27.9643
58.736846996, 96.390, 837.0, 28.9310
58.789368126, 96.390, 823.0, 28.6880
58.841889257, 96.390, 752.0, 27.4226
58.894410388, 96.390, 827.0, 28.7576
58.946931518, 96.390, 801.0, 28.3019
58.999452649, 96.390, 816.0, 28.5657
59.051973780, 96.390, 793.0, 28.1603
59.104494911, 96.390, 785.0, 28.0179
59.157016041, 96.390, 827.0, 28.7576
59.209537172, 96.390, 786.0, 28.0357
59.262058303, 96.390, 896.0, 29.9333
59.314579433, 96.390, 929.0, 30.4795
59.367100564, 96.390, 907.0, 30.1164
59.419621695, 96.390, 883.0, 29.7153
59.472142826, 96.390, 933.0, 30.5450
59.524663956, 96.390, 841.0, 29.0000
59.577185087, 96.390, 827.0, 28.7576
59.629706218, 96.390, 868.0, 29.4618
59.682227348, 96.390, 869.0, 29.4788
59.734748479, 96.390, 1137.0, 33.7194
59.787269610, 96.390, 918.0, 30.2985
59.839790740, 96.390, 858.0, 29.2916
59.892311871, 96.390, 1038.0, 32.2180
59.944833002, 96.390, 1016.0, 31.8748
59.997354133, 96.390, 926.0, 30.4302
60.049875263, 96.390, 913.0, 30.2159
60.102396394, 96.390, 923.0, 30.3809
60.154917525, 96.390, 921.0, 30.3480
60.207438655, 96.390, 954.0, 30.8869
60.259959786, 96.390, 997.0, 31.5753
60.312480917, 96.390, 989.0, 31.4484
60.365002048, 96.390, 976.0, 31.2410
60.417523178, 96.390, 979.0, 31.2890
60.470044309, 96.390, 989.0, 31.4484
60.522565440, 96.390, 1031.0, 32.1092
60.575086570, 96.390, 1122.0, 33.4963
60.627607701, 96.390, 1079.0, 32.8481
60.680128832, 96.390, 1028.0, 32.0624
60.732649963, 96.390, 1147.0, 33.8674
60.785171093, 96.390, 1170.0, 34.2053
60.837692224, 96.390, 1185.0, 34.4238
60.890213355, 96.390, 1192.0, 34.5254
60.942734485, 96.390, 1204.0, 34.6987
60.995255616, 96.390, 1242.0, 35.2420
61.047776747, 96.390, 1243.0, 35.2562
61.100297878, 96.390, 1245.0, 35.2846
61.152819008, 96.390, 1319.0, 36.3180
61.205340139, 96.390, 1316.0, 36.2767
61.257861270, 96.390, 1324.0, 36.3868
61.310382400, 96.390, 1240.0, 35.2136
61.362903531, 96.390, 1204.0, 34.6987
61.415424662, 96.390, 1262.0, 35.5246
61.467945792, 96.390, 1223.0, 34.9714
61.520466923, 96.390, 1207.0, 34.7419
61.572988054, 96.390, 1172.0, 34.2345
61.625509185, 96.390, 1180.0, 34.3511
61.678030315, 96.390, 1205.0, 34.7131
61.730551446, 96.390, 1155.0, 33.9853
61.783072577, 96.390, 1133.0, 33.6601
61.835593707, 96.390, 1110.0, 33.3167
61.888114838, 96.390, 1171.0, 34.2199
61.940635969, 96.390, 1128.0, 33.5857
61.993157100, 96.390, 1069.0, 32.6956
62.045678230, 96.390, 1151.0, 33.9264
62.098199361, 96.390, 1114.0, 33.3766
62.150720492, 96.390, 1033.0, 32.1403
62.203241622, 96.390, 1055.0, 32.4808
62.255762753, 96.390, 1040.0, 32.2490
62.308283884, 96.390, 1095.0, 33.0908
62.360805015, 96.390, 1012.0, 31.8119
62.413326145, 96.390, 1036.0, 32.1870
62.465847276, 96.390, 1000.0, 31.6228
62.518368407, 96.390, 992.0, 31.4960
62.570889537, 96.390, 950.0, 30.8221
62.623410668, 96.390, 956.0, 30.9192
62.675931799, 96.390, 898.0, 29.9666
62.728452930, 96.390, 1023.0, 31.9844
62.780974060, 96.390, 933.0, 30.5450
62.833495191, 96.390, 952.0, 30.8545
62.886016322, 96.390, 863.0, 29.3769
62.938537452, 96.390, 871.0, 29.5127
62.991058583, 96.390, 899.0, 29.9833
63.043579714, 96.390, 819.0, 28.6182
63.096100844, 96.390, 846.0, 29.0861
63.148621975, 96.390, 886.0, 29.7658
63.201143106, 96.390, 811.0, 28.4781
63.253664237, 96.390, 843.0, 29.0345
63.306185367, 96.390, 811.0, 28.4781
63.358706498, 96.390, 898.0, 29.9666
63.411227629, 96.390, 927.0, 30.4467
63.463748759, 96.390, 904.0, 30.0666
63.516269890, 96.390, 824.0, 28.7054
63.568791021, 96.390, 873.0, 29.5466
63.621312152, 96.390, 838.0, 28.9482
63.673833282, 96.390, 816.0, 28.5657
63.726354413, 96.390, 809.0, 28.4429
63.778875544, 96.390, 788.0, 28.0713
63.831396674, 96.390, 822.0, 28.6705
63.883917805, 96.390, 770.0, 27.7489
63.936438936, 96.390, 753.0, 27.4408
63.988960067, 96.390, 806.0, 28.3901
64.041481197, 96.390, 805.0, 28.3725
64.094002328, 96.390, 831.0, 28.8271
64.146523459, 96.390, 820.0, 28.6356
64.199044589, 96.390, 775.0, 27.8388
64.251565720, 96.390, 757.0, 27.5136
64.304086851, 96.390, 773.0, 27.8029
64.356607981, 96.390, 722.0, 26.8701
64.409129112, 96.390, 718.0, 26.7955
64.461650243, 96.390, 737.0, 27.1477
64.514171374, 96.390, 708.0, 26.6083
64.566692504, 96.390, 734.0, 27.0924
64.619213635, 96.390, 701.0, 26.4764
64.671734766, 96.390, 734.0, 27.0924
64.724255896, 96.390, 745.0, 27.2947
64.776777027, 96.390, 741.0, 27.2213
64.829298158, 96.390, 723.0, 26.8887
64.881819289, 96.390, 685.0, 26.1725
64.934340419, 96.390, 722.0, 26.8701
64.986861550, 96.390, 721.0, 26.8514