File: Files_organized_for_plots/Constant_NaOH_1mL10M_to_1gPC_28Day_repeat/AlAxial23Mar22_Act12Feb23_B1_1000M_NaOH_LS0133_Num156.csv
[Measurement conditions]
Sample identification,AlAxial23Mar22_Act12Feb23_B1_1000M_NaOH_LS0133_Num156
Comment - 1,"Configuration=Stage for Flat Samples/Holders, Owner=nmw10, Creation date=9/21/2022 10:06:30 AM"
Comment - 2,"Goniometer=Theta/Theta; Minimum step size 2Theta:0.0001; Minimum step size Omega:0.0001"
Comment - 3,"Sample stage=Stage for flat samples/holders"
Comment - 4,"Diffractometer system=EMPYREAN"
Comment - 5,"Measurement program=X:\XRD\Cement\Zerobackground scan.xrdmp, Created identifier={98A3B11C-88F9-4AA6-982C-73314A311EF5}, Created by=Titus Reed, Id=tmr79, Creation date=10/26/2021 3:01:47 PM"
Anode material,Cu
K-Alpha1 wavelength,1.5405980
K-Alpha2 wavelength,1.5444260
Ratio K-Alpha2/K-Alpha1,0.500
Divergence slit,Fixed,0.25
Monochromator used,NO
Generator voltage, 45
Tube current, 40
File date and time,15/Mar/2023 19:58
Unit cell,
h k l, 0 0 0
Scan axis,Gonio
Scan range,4.994599997,64.999991833
Scan step size,0.0262606
No. of points, 2285
Scan type,CONTINUOUS
Time per step,96.390
[Scan points]
Angle, TimePerStep, Intensity, ESD
5.007730280, 96.390, 3645.0, 60.3738
5.060251411, 96.390, 3571.0, 59.7578
5.112772541, 96.390, 3725.0, 61.0328
5.165293672, 96.390, 3525.0, 59.3717
5.217814803, 96.390, 3499.0, 59.1523
5.270335934, 96.390, 3599.0, 59.9917
5.322857064, 96.390, 3481.0, 59.0000
5.375378195, 96.390, 3387.0, 58.1979
5.427899326, 96.390, 3482.0, 59.0085
5.480420456, 96.390, 3310.0, 57.5326
5.532941587, 96.390, 3248.0, 56.9912
5.585462718, 96.390, 3329.0, 57.6975
5.637983849, 96.390, 3322.0, 57.6368
5.690504979, 96.390, 3216.0, 56.7098
5.743026110, 96.390, 3206.0, 56.6216
5.795547241, 96.390, 3212.0, 56.6745
5.848068371, 96.390, 3189.0, 56.4712
5.900589502, 96.390, 3217.0, 56.7186
5.953110633, 96.390, 3147.0, 56.0981
6.005631763, 96.390, 3119.0, 55.8480
6.058152894, 96.390, 3187.0, 56.4535
6.110674025, 96.390, 3229.0, 56.8243
6.163195156, 96.390, 3057.0, 55.2901
6.215716286, 96.390, 3208.0, 56.6392
6.268237417, 96.390, 3084.0, 55.5338
6.320758548, 96.390, 3115.0, 55.8122
6.373279678, 96.390, 3165.0, 56.2583
6.425800809, 96.390, 3023.0, 54.9818
6.478321940, 96.390, 3058.0, 55.2992
6.530843071, 96.390, 3005.0, 54.8179
6.583364201, 96.390, 3015.0, 54.9090
6.635885332, 96.390, 3042.0, 55.1543
6.688406463, 96.390, 3202.0, 56.5862
6.740927593, 96.390, 3173.0, 56.3294
6.793448724, 96.390, 3165.0, 56.2583
6.845969855, 96.390, 3164.0, 56.2494
6.898490986, 96.390, 3241.0, 56.9298
6.951012116, 96.390, 3322.0, 57.6368
7.003533247, 96.390, 3316.0, 57.5847
7.056054378, 96.390, 3727.0, 61.0492
7.108575508, 96.390, 4167.0, 64.5523
7.161096639, 96.390, 5095.0, 71.3793
7.213617770, 96.390, 5141.0, 71.7008
7.266138900, 96.390, 3226.0, 56.7979
7.318660031, 96.390, 3088.0, 55.5698
7.371181162, 96.390, 3064.0, 55.3534
7.423702293, 96.390, 2886.0, 53.7215
7.476223423, 96.390, 2992.0, 54.6992
7.528744554, 96.390, 2838.0, 53.2729
7.581265685, 96.390, 2865.0, 53.5257
7.633786815, 96.390, 2849.0, 53.3760
7.686307946, 96.390, 2837.0, 53.2635
7.738829077, 96.390, 2835.0, 53.2447
7.791350208, 96.390, 2787.0, 52.7920
7.843871338, 96.390, 2844.0, 53.3292
7.896392469, 96.390, 2852.0, 53.4041
7.948913600, 96.390, 2848.0, 53.3667
8.001434730, 96.390, 2954.0, 54.3507
8.053955861, 96.390, 2904.0, 53.8888
8.106476992, 96.390, 3118.0, 55.8391
8.158998123, 96.390, 3256.0, 57.0614
8.211519253, 96.390, 2954.0, 54.3507
8.264040384, 96.390, 2864.0, 53.5164
8.316561515, 96.390, 2785.0, 52.7731
8.369082645, 96.390, 2807.0, 52.9811
8.421603776, 96.390, 2888.0, 53.7401
8.474124907, 96.390, 2740.0, 52.3450
8.526646038, 96.390, 2867.0, 53.5444
8.579167168, 96.390, 2937.0, 54.1941
8.631688299, 96.390, 2902.0, 53.8702
8.684209430, 96.390, 2828.0, 53.1789
8.736730560, 96.390, 2768.0, 52.6118
8.789251691, 96.390, 2787.0, 52.7920
8.841772822, 96.390, 2843.0, 53.3198
8.894293952, 96.390, 2830.0, 53.1977
8.946815083, 96.390, 2948.0, 54.2955
8.999336214, 96.390, 2899.0, 53.8424
9.051857345, 96.390, 2942.0, 54.2402
9.104378475, 96.390, 2957.0, 54.3783
9.156899606, 96.390, 2907.0, 53.9166
9.209420737, 96.390, 2902.0, 53.8702
9.261941867, 96.390, 2888.0, 53.7401
9.314462998, 96.390, 2942.0, 54.2402
9.366984129, 96.390, 2977.0, 54.5619
9.419505260, 96.390, 3018.0, 54.9363
9.472026390, 96.390, 3123.0, 55.8838
9.524547521, 96.390, 3058.0, 55.2992
9.577068652, 96.390, 3101.0, 55.6866
9.629589782, 96.390, 2965.0, 54.4518
9.682110913, 96.390, 3096.0, 55.6417
9.734632044, 96.390, 3129.0, 55.9375
9.787153175, 96.390, 3106.0, 55.7315
9.839674305, 96.390, 3133.0, 55.9732
9.892195436, 96.390, 3193.0, 56.5066
9.944716567, 96.390, 3254.0, 57.0438
9.997237697, 96.390, 3401.0, 58.3181
10.049758828, 96.390, 3559.0, 59.6574
10.102279959, 96.390, 4039.0, 63.5531
10.154801090, 96.390, 4656.0, 68.2349
10.207322220, 96.390, 4373.0, 66.1287
10.259843351, 96.390, 3451.0, 58.7452
10.312364482, 96.390, 3353.0, 57.9051
10.364885612, 96.390, 3330.0, 57.7062
10.417406743, 96.390, 3391.0, 58.2323
10.469927874, 96.390, 3339.0, 57.7841
10.522449004, 96.390, 3309.0, 57.5239
10.574970135, 96.390, 3433.0, 58.5918
10.627491266, 96.390, 3333.0, 57.7321
10.680012397, 96.390, 3331.0, 57.7148
10.732533527, 96.390, 3335.0, 57.7495
10.785054658, 96.390, 3490.0, 59.0762
10.837575789, 96.390, 3371.0, 58.0603
10.890096919, 96.390, 3402.0, 58.3267
10.942618050, 96.390, 3419.0, 58.4722
10.995139181, 96.390, 3358.0, 57.9483
11.047660312, 96.390, 3428.0, 58.5491
11.100181442, 96.390, 3361.0, 57.9741
11.152702573, 96.390, 3452.0, 58.7537
11.205223704, 96.390, 3386.0, 58.1893
11.257744834, 96.390, 3356.0, 57.9310
11.310265965, 96.390, 3398.0, 58.2924
11.362787096, 96.390, 3495.0, 59.1185
11.415308227, 96.390, 3341.0, 57.8014
11.467829357, 96.390, 3375.0, 58.0948
11.520350488, 96.390, 3467.0, 58.8812
11.572871619, 96.390, 3424.0, 58.5150
11.625392749, 96.390, 3249.0, 57.0000
11.677913880, 96.390, 3291.0, 57.3672
11.730435011, 96.390, 3366.0, 58.0172
11.782956141, 96.390, 3291.0, 57.3672
11.835477272, 96.390, 3220.0, 56.7450
11.887998403, 96.390, 3242.0, 56.9386
11.940519534, 96.390, 3121.0, 55.8659
11.993040664, 96.390, 3177.0, 56.3649
12.045561795, 96.390, 3096.0, 55.6417
12.098082926, 96.390, 3070.0, 55.4076
12.150604056, 96.390, 3097.0, 55.6507
12.203125187, 96.390, 3085.0, 55.5428
12.255646318, 96.390, 3081.0, 55.5068
12.308167449, 96.390, 3170.0, 56.3028
12.360688579, 96.390, 3175.0, 56.3471
12.413209710, 96.390, 3413.0, 58.4209
12.465730841, 96.390, 3745.0, 61.1964
12.518251971, 96.390, 3307.0, 57.5065
12.570773102, 96.390, 2847.0, 53.3573
12.623294233, 96.390, 2839.0, 53.2823
12.675815364, 96.390, 2817.0, 53.0754
12.728336494, 96.390, 2755.0, 52.4881
12.780857625, 96.390, 2729.0, 52.2398
12.833378756, 96.390, 2633.0, 51.3128
12.885899886, 96.390, 2696.0, 51.9230
12.938421017, 96.390, 2592.0, 50.9117
12.990942148, 96.390, 2598.0, 50.9706
13.043463279, 96.390, 2534.0, 50.3389
13.095984409, 96.390, 2394.0, 48.9285
13.148505540, 96.390, 2512.0, 50.1199
13.201026671, 96.390, 2481.0, 49.8096
13.253547801, 96.390, 2491.0, 49.9099
13.306068932, 96.390, 2523.0, 50.2295
13.358590063, 96.390, 2473.0, 49.7293
13.411111193, 96.390, 2516.0, 50.1597
13.463632324, 96.390, 2585.0, 50.8429
13.516153455, 96.390, 2519.0, 50.1896
13.568674586, 96.390, 2365.0, 48.6313
13.621195716, 96.390, 2242.0, 47.3498
13.673716847, 96.390, 2376.0, 48.7442
13.726237978, 96.390, 2287.0, 47.8226
13.778759108, 96.390, 2273.0, 47.6760
13.831280239, 96.390, 2369.0, 48.6724
13.883801370, 96.390, 2291.0, 47.8644
13.936322501, 96.390, 2248.0, 47.4131
13.988843631, 96.390, 2094.0, 45.7602
14.041364762, 96.390, 2168.0, 46.5618
14.093885893, 96.390, 2187.0, 46.7654
14.146407023, 96.390, 2197.0, 46.8722
14.198928154, 96.390, 2413.0, 49.1223
14.251449285, 96.390, 2569.0, 50.6853
14.303970416, 96.390, 2466.0, 49.6588
14.356491546, 96.390, 2186.0, 46.7547
14.409012677, 96.390, 2298.0, 47.9375
14.461533808, 96.390, 2418.0, 49.1732
14.514054938, 96.390, 2924.0, 54.0740
14.566576069, 96.390, 2752.0, 52.4595
14.619097200, 96.390, 2198.0, 46.8828
14.671618331, 96.390, 1995.0, 44.6654
14.724139461, 96.390, 1957.0, 44.2380
14.776660592, 96.390, 1972.0, 44.4072
14.829181723, 96.390, 1953.0, 44.1928
14.881702853, 96.390, 1961.0, 44.2832
14.934223984, 96.390, 2000.0, 44.7214
14.986745115, 96.390, 1934.0, 43.9773
15.039266245, 96.390, 2011.0, 44.8442
15.091787376, 96.390, 2089.0, 45.7056
15.144308507, 96.390, 2345.0, 48.4252
15.196829638, 96.390, 2577.0, 50.7642
15.249350768, 96.390, 2790.0, 52.8205
15.301871899, 96.390, 2577.0, 50.7642
15.354393030, 96.390, 2132.0, 46.1736
15.406914160, 96.390, 1951.0, 44.1701
15.459435291, 96.390, 1918.0, 43.7950
15.511956422, 96.390, 1883.0, 43.3935
15.564477553, 96.390, 1872.0, 43.2666
15.616998683, 96.390, 1844.0, 42.9418
15.669519814, 96.390, 1889.0, 43.4626
15.722040945, 96.390, 2107.0, 45.9021
15.774562075, 96.390, 1873.0, 43.2782
15.827083206, 96.390, 1851.0, 43.0232
15.879604337, 96.390, 1811.0, 42.5558
15.932125468, 96.390, 1861.0, 43.1393
15.984646598, 96.390, 1829.0, 42.7668
16.037167729, 96.390, 2100.0, 45.8258
16.089688860, 96.390, 2358.0, 48.5592
16.142209990, 96.390, 2401.0, 49.0000
16.194731121, 96.390, 2042.0, 45.1885
16.247252252, 96.390, 2180.0, 46.6905
16.299773382, 96.390, 2501.0, 50.0100
16.352294513, 96.390, 2469.0, 49.6890
16.404815644, 96.390, 1997.0, 44.6878
16.457336775, 96.390, 1787.0, 42.2729
16.509857905, 96.390, 1780.0, 42.1900
16.562379036, 96.390, 1804.0, 42.4735
16.614900167, 96.390, 1762.0, 41.9762
16.667421297, 96.390, 1732.0, 41.6173
16.719942428, 96.390, 1807.0, 42.5088
16.772463559, 96.390, 1695.0, 41.1704
16.824984690, 96.390, 1816.0, 42.6146
16.877505820, 96.390, 1742.0, 41.7373
16.930026951, 96.390, 1781.0, 42.2019
16.982548082, 96.390, 1741.0, 41.7253
17.035069212, 96.390, 1682.0, 41.0122
17.087590343, 96.390, 1672.0, 40.8901
17.140111474, 96.390, 1758.0, 41.9285
17.192632605, 96.390, 1768.0, 42.0476
17.245153735, 96.390, 1746.0, 41.7852
17.297674866, 96.390, 1692.0, 41.1339
17.350195997, 96.390, 1778.0, 42.1663
17.402717127, 96.390, 1673.0, 40.9023
17.455238258, 96.390, 1678.0, 40.9634
17.507759389, 96.390, 1763.0, 41.9881
17.560280520, 96.390, 1746.0, 41.7852
17.612801650, 96.390, 1697.0, 41.1947
17.665322781, 96.390, 1754.0, 41.8808
17.717843912, 96.390, 1707.0, 41.3159
17.770365042, 96.390, 1723.0, 41.5090
17.822886173, 96.390, 1808.0, 42.5206
17.875407304, 96.390, 1760.0, 41.9524
17.927928434, 96.390, 1769.0, 42.0595
17.980449565, 96.390, 1781.0, 42.2019
18.032970696, 96.390, 1895.0, 43.5316
18.085491827, 96.390, 1890.0, 43.4741
18.138012957, 96.390, 1997.0, 44.6878
18.190534088, 96.390, 2073.0, 45.5302
18.243055219, 96.390, 2369.0, 48.6724
18.295576349, 96.390, 2803.0, 52.9434
18.348097480, 96.390, 2996.0, 54.7357
18.400618611, 96.390, 3334.0, 57.7408
18.453139742, 96.390, 3884.0, 62.3217
18.505660872, 96.390, 4149.0, 64.4127
18.558182003, 96.390, 4372.0, 66.1211
18.610703134, 96.390, 4492.0, 67.0224
18.663224264, 96.390, 4796.0, 69.2532
18.715745395, 96.390, 5621.0, 74.9733
18.768266526, 96.390, 6583.0, 81.1357
18.820787657, 96.390, 5705.0, 75.5315
18.873308787, 96.390, 4026.0, 63.4508
18.925829918, 96.390, 3156.0, 56.1783
18.978351049, 96.390, 2820.0, 53.1037
19.030872179, 96.390, 2418.0, 49.1732
19.083393310, 96.390, 2210.0, 47.0106
19.135914441, 96.390, 2008.0, 44.8107
19.188435572, 96.390, 1921.0, 43.8292
19.240956702, 96.390, 1962.0, 44.2945
19.293477833, 96.390, 1953.0, 44.1928
19.345998964, 96.390, 2045.0, 45.2217
19.398520094, 96.390, 2181.0, 46.7012
19.451041225, 96.390, 2175.0, 46.6369
19.503562356, 96.390, 1987.0, 44.5758
19.556083486, 96.390, 1898.0, 43.5660
19.608604617, 96.390, 1898.0, 43.5660
19.661125748, 96.390, 1922.0, 43.8406
19.713646879, 96.390, 2036.0, 45.1221
19.766168009, 96.390, 1974.0, 44.4297
19.818689140, 96.390, 1995.0, 44.6654
19.871210271, 96.390, 2202.0, 46.9255
19.923731401, 96.390, 2553.0, 50.5272
19.976252532, 96.390, 2928.0, 54.1110
20.028773663, 96.390, 2566.0, 50.6557
20.081294794, 96.390, 2357.0, 48.5489
20.133815924, 96.390, 2656.0, 51.5364
20.186337055, 96.390, 3402.0, 58.3267
20.238858186, 96.390, 4850.0, 69.6419
20.291379316, 96.390, 5736.0, 75.7364
20.343900447, 96.390, 5431.0, 73.6953
20.396421578, 96.390, 4926.0, 70.1855
20.448942709, 96.390, 4428.0, 66.5432
20.501463839, 96.390, 3619.0, 60.1581
20.553984970, 96.390, 3113.0, 55.7943
20.606506101, 96.390, 3325.0, 57.6628
20.659027231, 96.390, 3925.0, 62.6498
20.711548362, 96.390, 4982.0, 70.5833
20.764069493, 96.390, 3655.0, 60.4566
20.816590623, 96.390, 2368.0, 48.6621
20.869111754, 96.390, 2213.0, 47.0425
20.921632885, 96.390, 2099.0, 45.8148
20.974154016, 96.390, 2007.0, 44.7996
21.026675146, 96.390, 2032.0, 45.0777
21.079196277, 96.390, 1976.0, 44.4522
21.131717408, 96.390, 1925.0, 43.8748
21.184238538, 96.390, 2020.0, 44.9444
21.236759669, 96.390, 2105.0, 45.8803
21.289280800, 96.390, 2397.0, 48.9592
21.341801931, 96.390, 2320.0, 48.1664
21.394323061, 96.390, 2062.0, 45.4093
21.446844192, 96.390, 2096.0, 45.7821
21.499365323, 96.390, 2044.0, 45.2106
21.551886453, 96.390, 2317.0, 48.1352
21.604407584, 96.390, 2794.0, 52.8583
21.656928715, 96.390, 3170.0, 56.3028
21.709449846, 96.390, 2724.0, 52.1920
21.761970976, 96.390, 2241.0, 47.3392
21.814492107, 96.390, 2071.0, 45.5082
21.867013238, 96.390, 1895.0, 43.5316
21.919534368, 96.390, 1978.0, 44.4747
21.972055499, 96.390, 1908.0, 43.6807
22.024576630, 96.390, 1941.0, 44.0568
22.077097761, 96.390, 2016.0, 44.8999
22.129618891, 96.390, 2026.0, 45.0111
22.182140022, 96.390, 2000.0, 44.7214
22.234661153, 96.390, 2022.0, 44.9667
22.287182283, 96.390, 1967.0, 44.3509
22.339703414, 96.390, 2037.0, 45.1331
22.392224545, 96.390, 2097.0, 45.7930
22.444745675, 96.390, 2081.0, 45.6180
22.497266806, 96.390, 2168.0, 46.5618
22.549787937, 96.390, 2240.0, 47.3286
22.602309068, 96.390, 2306.0, 48.0208
22.654830198, 96.390, 2238.0, 47.3075
22.707351329, 96.390, 2242.0, 47.3498
22.759872460, 96.390, 2438.0, 49.3761
22.812393590, 96.390, 2690.0, 51.8652
22.864914721, 96.390, 2751.0, 52.4500
22.917435852, 96.390, 2632.0, 51.3030
22.969956983, 96.390, 2643.0, 51.4101
23.022478113, 96.390, 2553.0, 50.5272
23.074999244, 96.390, 2551.0, 50.5074
23.127520375, 96.390, 2788.0, 52.8015
23.180041505, 96.390, 2963.0, 54.4334
23.232562636, 96.390, 2839.0, 53.2823
23.285083767, 96.390, 2587.0, 50.8626
23.337604898, 96.390, 2677.0, 51.7397
23.390126028, 96.390, 2684.0, 51.8073
23.442647159, 96.390, 2629.0, 51.2738
23.495168290, 96.390, 2423.0, 49.2240
23.547689420, 96.390, 2483.0, 49.8297
23.600210551, 96.390, 2457.0, 49.5681
23.652731682, 96.390, 2332.0, 48.2908
23.705252813, 96.390, 2211.0, 47.0213
23.757773943, 96.390, 2187.0, 46.7654
23.810295074, 96.390, 2219.0, 47.1063
23.862816205, 96.390, 2427.0, 49.2646
23.915337335, 96.390, 2627.0, 51.2543
23.967858466, 96.390, 3166.0, 56.2672
24.020379597, 96.390, 3201.0, 56.5774
24.072900727, 96.390, 2761.0, 52.5452
24.125421858, 96.390, 2264.0, 47.5815
24.177942989, 96.390, 2230.0, 47.2229
24.230464120, 96.390, 2075.0, 45.5522
24.282985250, 96.390, 1956.0, 44.2267
24.335506381, 96.390, 1878.0, 43.3359
24.388027512, 96.390, 1893.0, 43.5086
24.440548642, 96.390, 1842.0, 42.9185
24.493069773, 96.390, 1790.0, 42.3084
24.545590904, 96.390, 1919.0, 43.8064
24.598112035, 96.390, 1796.0, 42.3792
24.650633165, 96.390, 1744.0, 41.7612
24.703154296, 96.390, 1799.0, 42.4146
24.755675427, 96.390, 1753.0, 41.8688
24.808196557, 96.390, 1747.0, 41.7971
24.860717688, 96.390, 1686.0, 41.0609
24.913238819, 96.390, 1651.0, 40.6325
24.965759950, 96.390, 1623.0, 40.2865
25.018281080, 96.390, 1628.0, 40.3485
25.070802211, 96.390, 1565.0, 39.5601
25.123323342, 96.390, 1474.0, 38.3927
25.175844472, 96.390, 1552.0, 39.3954
25.228365603, 96.390, 1520.0, 38.9872
25.280886734, 96.390, 1505.0, 38.7943
25.333407864, 96.390, 1626.0, 40.3237
25.385928995, 96.390, 1790.0, 42.3084
25.438450126, 96.390, 2002.0, 44.7437
25.490971257, 96.390, 1799.0, 42.4146
25.543492387, 96.390, 1673.0, 40.9023
25.596013518, 96.390, 1479.0, 38.4578
25.648534649, 96.390, 1408.0, 37.5233
25.701055779, 96.390, 1483.0, 38.5097
25.753576910, 96.390, 1443.0, 37.9868
25.806098041, 96.390, 1506.0, 38.8072
25.858619172, 96.390, 1544.0, 39.2938
25.911140302, 96.390, 1513.0, 38.8973
25.963661433, 96.390, 1498.0, 38.7040
26.016182564, 96.390, 1612.0, 40.1497
26.068703694, 96.390, 1708.0, 41.3280
26.121224825, 96.390, 1851.0, 43.0232
26.173745956, 96.390, 1600.0, 40.0000
26.226267087, 96.390, 1589.0, 39.8623
26.278788217, 96.390, 1458.0, 38.1838
26.331309348, 96.390, 1461.0, 38.2230
26.383830479, 96.390, 1502.0, 38.7556
26.436351609, 96.390, 1547.0, 39.3319
26.488872740, 96.390, 1456.0, 38.1576
26.541393871, 96.390, 1555.0, 39.4335
26.593915002, 96.390, 1527.0, 39.0768
26.646436132, 96.390, 1578.0, 39.7240
26.698957263, 96.390, 1799.0, 42.4146
26.751478394, 96.390, 2107.0, 45.9021
26.803999524, 96.390, 2299.0, 47.9479
26.856520655, 96.390, 2087.0, 45.6837
26.909041786, 96.390, 1969.0, 44.3734
26.961562916, 96.390, 2109.0, 45.9239
27.014084047, 96.390, 2500.0, 50.0000
27.066605178, 96.390, 3042.0, 55.1543
27.119126309, 96.390, 3773.0, 61.4248
27.171647439, 96.390, 3888.0, 62.3538
27.224168570, 96.390, 3404.0, 58.3438
27.276689701, 96.390, 2432.0, 49.3153
27.329210831, 96.390, 1950.0, 44.1588
27.381731962, 96.390, 1774.0, 42.1189
27.434253093, 96.390, 1803.0, 42.4617
27.486774224, 96.390, 1650.0, 40.6202
27.539295354, 96.390, 1702.0, 41.2553
27.591816485, 96.390, 1753.0, 41.8688
27.644337616, 96.390, 1901.0, 43.6005
27.696858746, 96.390, 2117.0, 46.0109
27.749379877, 96.390, 2249.0, 47.4236
27.801901008, 96.390, 2440.0, 49.3964
27.854422139, 96.390, 2385.0, 48.8365
27.906943269, 96.390, 2175.0, 46.6369
27.959464400, 96.390, 1937.0, 44.0114
28.011985531, 96.390, 1827.0, 42.7434
28.064506661, 96.390, 1793.0, 42.3438
28.117027792, 96.390, 1618.0, 40.2244
28.169548923, 96.390, 1623.0, 40.2865
28.222070054, 96.390, 1574.0, 39.6737
28.274591184, 96.390, 1545.0, 39.3065
28.327112315, 96.390, 1578.0, 39.7240
28.379633446, 96.390, 1586.0, 39.8246
28.432154576, 96.390, 1593.0, 39.9124
28.484675707, 96.390, 1552.0, 39.3954
28.537196838, 96.390, 1533.0, 39.1535
28.589717968, 96.390, 1452.0, 38.1051
28.642239099, 96.390, 1552.0, 39.3954
28.694760230, 96.390, 1564.0, 39.5474
28.747281361, 96.390, 1582.0, 39.7744
28.799802491, 96.390, 1613.0, 40.1622
28.852323622, 96.390, 1622.0, 40.2741
28.904844753, 96.390, 1479.0, 38.4578
28.957365883, 96.390, 1506.0, 38.8072
29.009887014, 96.390, 1574.0, 39.6737
29.062408145, 96.390, 1696.0, 41.1825
29.114929276, 96.390, 1947.0, 44.1248
29.167450406, 96.390, 2076.0, 45.5631
29.219971537, 96.390, 2175.0, 46.6369
29.272492668, 96.390, 2288.0, 47.8330
29.325013798, 96.390, 2485.0, 49.8498
29.377534929, 96.390, 2260.0, 47.5395
29.430056060, 96.390, 2129.0, 46.1411
29.482577191, 96.390, 2160.0, 46.4758
29.535098321, 96.390, 2030.0, 45.0555
29.587619452, 96.390, 1802.0, 42.4500
29.640140583, 96.390, 1714.0, 41.4005
29.692661713, 96.390, 1716.0, 41.4246
29.745182844, 96.390, 1670.0, 40.8656
29.797703975, 96.390, 1780.0, 42.1900
29.850225105, 96.390, 1847.0, 42.9767
29.902746236, 96.390, 2483.0, 49.8297
29.955267367, 96.390, 2809.0, 53.0000
30.007788498, 96.390, 2404.0, 49.0306
30.060309628, 96.390, 1922.0, 43.8406
30.112830759, 96.390, 1508.0, 38.8330
30.165351890, 96.390, 1500.0, 38.7298
30.217873020, 96.390, 1431.0, 37.8286
30.270394151, 96.390, 1405.0, 37.4833
30.322915282, 96.390, 1433.0, 37.8550
30.375436413, 96.390, 1488.0, 38.5746
30.427957543, 96.390, 1479.0, 38.4578
30.480478674, 96.390, 1518.0, 38.9615
30.532999805, 96.390, 1520.0, 38.9872
30.585520935, 96.390, 1713.0, 41.3884
30.638042066, 96.390, 1763.0, 41.9881
30.690563197, 96.390, 1852.0, 43.0349
30.743084328, 96.390, 1776.0, 42.1426
30.795605458, 96.390, 1968.0, 44.3621
30.848126589, 96.390, 2009.0, 44.8219
30.900647720, 96.390, 1870.0, 43.2435
30.953168850, 96.390, 1638.0, 40.4722
31.005689981, 96.390, 1608.0, 40.0999
31.058211112, 96.390, 1520.0, 38.9872
31.110732243, 96.390, 1612.0, 40.1497
31.163253373, 96.390, 2069.0, 45.4863
31.215774504, 96.390, 2439.0, 49.3862
31.268295635, 96.390, 2558.0, 50.5767
31.320816765, 96.390, 2499.0, 49.9900
31.373337896, 96.390, 2247.0, 47.4025
31.425859027, 96.390, 2008.0, 44.8107
31.478380157, 96.390, 1887.0, 43.4396
31.530901288, 96.390, 1680.0, 40.9878
31.583422419, 96.390, 1662.0, 40.7676
31.635943550, 96.390, 1625.0, 40.3113
31.688464680, 96.390, 1499.0, 38.7169
31.740985811, 96.390, 1514.0, 38.9102
31.793506942, 96.390, 1479.0, 38.4578
31.846028072, 96.390, 1477.0, 38.4318
31.898549203, 96.390, 1686.0, 41.0609
31.951070334, 96.390, 1973.0, 44.4185
32.003591465, 96.390, 2706.0, 52.0192
32.056112595, 96.390, 3712.0, 60.9262
32.108633726, 96.390, 3182.0, 56.4092
32.161154857, 96.390, 2559.0, 50.5866
32.213675987, 96.390, 2067.0, 45.4643
32.266197118, 96.390, 2121.0, 46.0543
32.318718249, 96.390, 1895.0, 43.5316
32.371239380, 96.390, 1619.0, 40.2368
32.423760510, 96.390, 1467.0, 38.3014
32.476281641, 96.390, 1485.0, 38.5357
32.528802772, 96.390, 1650.0, 40.6202
32.581323902, 96.390, 1625.0, 40.3113
32.633845033, 96.390, 1595.0, 39.9375
32.686366164, 96.390, 1687.0, 41.0731
32.738887295, 96.390, 1569.0, 39.6106
32.791408425, 96.390, 1483.0, 38.5097
32.843929556, 96.390, 1380.0, 37.1484
32.896450687, 96.390, 1447.0, 38.0395
32.948971817, 96.390, 1576.0, 39.6989
33.001492948, 96.390, 1566.0, 39.5727
33.054014079, 96.390, 1595.0, 39.9375
33.106535209, 96.390, 1685.0, 41.0488
33.159056340, 96.390, 1657.0, 40.7063
33.211577471, 96.390, 1618.0, 40.2244
33.264098602, 96.390, 1645.0, 40.5586
33.316619732, 96.390, 1524.0, 39.0384
33.369140863, 96.390, 1612.0, 40.1497
33.421661994, 96.390, 1690.0, 41.1096
33.474183124, 96.390, 1533.0, 39.1535
33.526704255, 96.390, 1606.0, 40.0749
33.579225386, 96.390, 1585.0, 39.8121
33.631746517, 96.390, 1610.0, 40.1248
33.684267647, 96.390, 1601.0, 40.0125
33.736788778, 96.390, 1599.0, 39.9875
33.789309909, 96.390, 1589.0, 39.8623
33.841831039, 96.390, 1748.0, 41.8091
33.894352170, 96.390, 1992.0, 44.6318
33.946873301, 96.390, 2407.0, 49.0612
33.999394432, 96.390, 2330.0, 48.2701
34.051915562, 96.390, 2280.0, 47.7493
34.104436693, 96.390, 2240.0, 47.3286
34.156957824, 96.390, 2475.0, 49.7494
34.209478954, 96.390, 2717.0, 52.1249
34.262000085, 96.390, 2539.0, 50.3885
34.314521216, 96.390, 2338.0, 48.3529
34.367042346, 96.390, 2283.0, 47.7807
34.419563477, 96.390, 2536.0, 50.3587
34.472084608, 96.390, 2726.0, 52.2111
34.524605739, 96.390, 3061.0, 55.3263
34.577126869, 96.390, 3240.0, 56.9210
34.629648000, 96.390, 3085.0, 55.5428
34.682169131, 96.390, 2656.0, 51.5364
34.734690261, 96.390, 2515.0, 50.1498
34.787211392, 96.390, 2419.0, 49.1833
34.839732523, 96.390, 2473.0, 49.7293
34.892253654, 96.390, 2569.0, 50.6853
34.944774784, 96.390, 2641.0, 51.3907
34.997295915, 96.390, 2573.0, 50.7247
35.049817046, 96.390, 2295.0, 47.9062
35.102338176, 96.390, 2049.0, 45.2659
35.154859307, 96.390, 2127.0, 46.1194
35.207380438, 96.390, 2140.0, 46.2601
35.259901569, 96.390, 2050.0, 45.2769
35.312422699, 96.390, 1861.0, 43.1393
35.364943830, 96.390, 1737.0, 41.6773
35.417464961, 96.390, 1671.0, 40.8779
35.469986091, 96.390, 1634.0, 40.4228
35.522507222, 96.390, 1599.0, 39.9875
35.575028353, 96.390, 1614.0, 40.1746
35.627549484, 96.390, 1679.0, 40.9756
35.680070614, 96.390, 1720.0, 41.4729
35.732591745, 96.390, 1800.0, 42.4264
35.785112876, 96.390, 1788.0, 42.2847
35.837634006, 96.390, 1782.0, 42.2137
35.890155137, 96.390, 1887.0, 43.4396
35.942676268, 96.390, 2186.0, 46.7547
35.995197398, 96.390, 2072.0, 45.5192
36.047718529, 96.390, 1967.0, 44.3509
36.100239660, 96.390, 1966.0, 44.3396
36.152760791, 96.390, 2224.0, 47.1593
36.205281921, 96.390, 2426.0, 49.2544
36.257803052, 96.390, 2087.0, 45.6837
36.310324183, 96.390, 1828.0, 42.7551
36.362845313, 96.390, 1574.0, 39.6737
36.415366444, 96.390, 1462.0, 38.2361
36.467887575, 96.390, 1434.0, 37.8682
36.520408706, 96.390, 1464.0, 38.2623
36.572929836, 96.390, 1416.0, 37.6298
36.625450967, 96.390, 1410.0, 37.5500
36.677972098, 96.390, 1317.0, 36.2905
36.730493228, 96.390, 1272.0, 35.6651
36.783014359, 96.390, 1219.0, 34.9142
36.835535490, 96.390, 1191.0, 34.5109
36.888056621, 96.390, 1136.0, 33.7046
36.940577751, 96.390, 1173.0, 34.2491
36.993098882, 96.390, 1194.0, 34.5543
37.045620013, 96.390, 1234.0, 35.1283
37.098141143, 96.390, 1247.0, 35.3129
37.150662274, 96.390, 1338.0, 36.5787
37.203183405, 96.390, 1380.0, 37.1484
37.255704535, 96.390, 1386.0, 37.2290
37.308225666, 96.390, 1394.0, 37.3363
37.360746797, 96.390, 1471.0, 38.3536
37.413267928, 96.390, 1432.0, 37.8418
37.465789058, 96.390, 1547.0, 39.3319
37.518310189, 96.390, 1659.0, 40.7308
37.570831320, 96.390, 1720.0, 41.4729
37.623352450, 96.390, 1519.0, 38.9744
37.675873581, 96.390, 1589.0, 39.8623
37.728394712, 96.390, 1739.0, 41.7013
37.780915843, 96.390, 1807.0, 42.5088
37.833436973, 96.390, 1848.0, 42.9884
37.885958104, 96.390, 1762.0, 41.9762
37.938479235, 96.390, 1755.0, 41.8927
37.991000365, 96.390, 1783.0, 42.2256
38.043521496, 96.390, 1668.0, 40.8412
38.096042627, 96.390, 1740.0, 41.7133
38.148563758, 96.390, 1625.0, 40.3113
38.201084888, 96.390, 1643.0, 40.5339
38.253606019, 96.390, 1535.0, 39.1791
38.306127150, 96.390, 1435.0, 37.8814
38.358648280, 96.390, 1367.0, 36.9730
38.411169411, 96.390, 1286.0, 35.8608
38.463690542, 96.390, 1336.0, 36.5513
38.516211673, 96.390, 1463.0, 38.2492
38.568732803, 96.390, 1399.0, 37.4032
38.621253934, 96.390, 1386.0, 37.2290
38.673775065, 96.390, 1396.0, 37.3631
38.726296195, 96.390, 1530.0, 39.1152
38.778817326, 96.390, 1534.0, 39.1663
38.831338457, 96.390, 1556.0, 39.4462
38.883859587, 96.390, 1463.0, 38.2492
38.936380718, 96.390, 1337.0, 36.5650
38.988901849, 96.390, 1335.0, 36.5377
39.041422980, 96.390, 1295.0, 35.9861
39.093944110, 96.390, 1276.0, 35.7211
39.146465241, 96.390, 1380.0, 37.1484
39.198986372, 96.390, 1431.0, 37.8286
39.251507502, 96.390, 1432.0, 37.8418
39.304028633, 96.390, 1421.0, 37.6962
39.356549764, 96.390, 1589.0, 39.8623
39.409070895, 96.390, 1687.0, 41.0731
39.461592025, 96.390, 1680.0, 40.9878
39.514113156, 96.390, 1553.0, 39.4081
39.566634287, 96.390, 1462.0, 38.2361
39.619155417, 96.390, 1417.0, 37.6431
39.671676548, 96.390, 1362.0, 36.9053
39.724197679, 96.390, 1381.0, 37.1618
39.776718810, 96.390, 1437.0, 37.9078
39.829239940, 96.390, 1480.0, 38.4708
39.881761071, 96.390, 1467.0, 38.3014
39.934282202, 96.390, 1471.0, 38.3536
39.986803332, 96.390, 1574.0, 39.6737
40.039324463, 96.390, 1497.0, 38.6911
40.091845594, 96.390, 1526.0, 39.0640
40.144366725, 96.390, 1677.0, 40.9512
40.196887855, 96.390, 1711.0, 41.3642
40.249408986, 96.390, 1737.0, 41.6773
40.301930117, 96.390, 1952.0, 44.1814
40.354451247, 96.390, 2134.0, 46.1952
40.406972378, 96.390, 2519.0, 50.1896
40.459493509, 96.390, 2985.0, 54.6352
40.512014639, 96.390, 3342.0, 57.8100
40.564535770, 96.390, 3672.0, 60.5970
40.617056901, 96.390, 3644.0, 60.3656
40.669578032, 96.390, 3130.0, 55.9464
40.722099162, 96.390, 2591.0, 50.9019
40.774620293, 96.390, 2028.0, 45.0333
40.827141424, 96.390, 1662.0, 40.7676
40.879662554, 96.390, 1452.0, 38.1051
40.932183685, 96.390, 1333.0, 36.5103
40.984704816, 96.390, 1256.0, 35.4401
41.037225947, 96.390, 1265.0, 35.5668
41.089747077, 96.390, 1271.0, 35.6511
41.142268208, 96.390, 1218.0, 34.8999
41.194789339, 96.390, 1136.0, 33.7046
41.247310469, 96.390, 1184.0, 34.4093
41.299831600, 96.390, 1298.0, 36.0278
41.352352731, 96.390, 1481.0, 38.4838
41.404873862, 96.390, 1432.0, 37.8418
41.457394992, 96.390, 1362.0, 36.9053
41.509916123, 96.390, 1321.0, 36.3456
41.562437254, 96.390, 1337.0, 36.5650
41.614958384, 96.390, 1230.0, 35.0714
41.667479515, 96.390, 1189.0, 34.4819
41.720000646, 96.390, 1277.0, 35.7351
41.772521776, 96.390, 1165.0, 34.1321
41.825042907, 96.390, 1196.0, 34.5832
41.877564038, 96.390, 1113.0, 33.3617
41.930085169, 96.390, 1159.0, 34.0441
41.982606299, 96.390, 1127.0, 33.5708
42.035127430, 96.390, 1175.0, 34.2783
42.087648561, 96.390, 1470.0, 38.3406
42.140169691, 96.390, 1679.0, 40.9756
42.192690822, 96.390, 1439.0, 37.9342
42.245211953, 96.390, 1408.0, 37.5233
42.297733084, 96.390, 1240.0, 35.2136
42.350254214, 96.390, 1116.0, 33.4066
42.402775345, 96.390, 1075.0, 32.7872
42.455296476, 96.390, 1048.0, 32.3728
42.507817606, 96.390, 1101.0, 33.1813
42.560338737, 96.390, 1050.0, 32.4037
42.612859868, 96.390, 1009.0, 31.7648
42.665380999, 96.390, 1025.0, 32.0156
42.717902129, 96.390, 1123.0, 33.5112
42.770423260, 96.390, 1120.0, 33.4664
42.822944391, 96.390, 1090.0, 33.0151
42.875465521, 96.390, 1000.0, 31.6228
42.927986652, 96.390, 980.0, 31.3050
42.980507783, 96.390, 1003.0, 31.6702
43.033028914, 96.390, 945.0, 30.7409
43.085550044, 96.390, 987.0, 31.4166
43.138071175, 96.390, 986.0, 31.4006
43.190592306, 96.390, 971.0, 31.1609
43.243113436, 96.390, 934.0, 30.5614
43.295634567, 96.390, 974.0, 31.2090
43.348155698, 96.390, 906.0, 30.0998
43.400676828, 96.390, 928.0, 30.4631
43.453197959, 96.390, 956.0, 30.9192
43.505719090, 96.390, 1027.0, 32.0468
43.558240221, 96.390, 1030.0, 32.0936
43.610761351, 96.390, 1045.0, 32.3265
43.663282482, 96.390, 1089.0, 33.0000
43.715803613, 96.390, 1200.0, 34.6410
43.768324743, 96.390, 1241.0, 35.2278
43.820845874, 96.390, 1164.0, 34.1174
43.873367005, 96.390, 1146.0, 33.8526
43.925888136, 96.390, 1064.0, 32.6190
43.978409266, 96.390, 1049.0, 32.3883
44.030930397, 96.390, 1017.0, 31.8904
44.083451528, 96.390, 1051.0, 32.4191
44.135972658, 96.390, 1130.0, 33.6155
44.188493789, 96.390, 1148.0, 33.8821
44.241014920, 96.390, 1174.0, 34.2637
44.293536051, 96.390, 1186.0, 34.4384
44.346057181, 96.390, 1215.0, 34.8569
44.398578312, 96.390, 1229.0, 35.0571
44.451099443, 96.390, 1111.0, 33.3317
44.503620573, 96.390, 1087.0, 32.9697
44.556141704, 96.390, 1024.0, 32.0000
44.608662835, 96.390, 1058.0, 32.5269
44.661183966, 96.390, 1081.0, 32.8786
44.713705096, 96.390, 1003.0, 31.6702
44.766226227, 96.390, 1082.0, 32.8938
44.818747358, 96.390, 1096.0, 33.1059
44.871268488, 96.390, 1076.0, 32.8024
44.923789619, 96.390, 1038.0, 32.2180
44.976310750, 96.390, 1000.0, 31.6228
45.028831880, 96.390, 1047.0, 32.3574
45.081353011, 96.390, 1127.0, 33.5708
45.133874142, 96.390, 1217.0, 34.8855
45.186395273, 96.390, 1165.0, 34.1321
45.238916403, 96.390, 1260.0, 35.4965
45.291437534, 96.390, 1158.0, 34.0294
45.343958665, 96.390, 1196.0, 34.5832
45.396479795, 96.390, 1184.0, 34.4093
45.449000926, 96.390, 1271.0, 35.6511
45.501522057, 96.390, 1229.0, 35.0571
45.554043188, 96.390, 1260.0, 35.4965
45.606564318, 96.390, 1227.0, 35.0286
45.659085449, 96.390, 1166.0, 34.1467
45.711606580, 96.390, 1108.0, 33.2866
45.764127710, 96.390, 1137.0, 33.7194
45.816648841, 96.390, 1090.0, 33.0151
45.869169972, 96.390, 1089.0, 33.0000
45.921691103, 96.390, 1158.0, 34.0294
45.974212233, 96.390, 1112.0, 33.3467
46.026733364, 96.390, 1116.0, 33.4066
46.079254495, 96.390, 1168.0, 34.1760
46.131775625, 96.390, 1246.0, 35.2987
46.184296756, 96.390, 1402.0, 37.4433
46.236817887, 96.390, 1373.0, 37.0540
46.289339017, 96.390, 1394.0, 37.3363
46.341860148, 96.390, 1335.0, 36.5377
46.394381279, 96.390, 1256.0, 35.4401
46.446902410, 96.390, 1200.0, 34.6410
46.499423540, 96.390, 1130.0, 33.6155
46.551944671, 96.390, 1058.0, 32.5269
46.604465802, 96.390, 1079.0, 32.8481
46.656986932, 96.390, 1107.0, 33.2716
46.709508063, 96.390, 1139.0, 33.7491
46.762029194, 96.390, 1136.0, 33.7046
46.814550325, 96.390, 1116.0, 33.4066
46.867071455, 96.390, 1074.0, 32.7719
46.919592586, 96.390, 1078.0, 32.8329
46.972113717, 96.390, 1050.0, 32.4037
47.024634847, 96.390, 1069.0, 32.6956
47.077155978, 96.390, 1035.0, 32.1714
47.129677109, 96.390, 985.0, 31.3847
47.182198240, 96.390, 1039.0, 32.2335
47.234719370, 96.390, 1057.0, 32.5115
47.287240501, 96.390, 1181.0, 34.3657
47.339761632, 96.390, 1194.0, 34.5543
47.392282762, 96.390, 1131.0, 33.6303
47.444803893, 96.390, 1136.0, 33.7046
47.497325024, 96.390, 1100.0, 33.1662
47.549846155, 96.390, 1060.0, 32.5576
47.602367285, 96.390, 1061.0, 32.5730
47.654888416, 96.390, 1023.0, 31.9844
47.707409547, 96.390, 1106.0, 33.2566
47.759930677, 96.390, 1094.0, 33.0757
47.812451808, 96.390, 1183.0, 34.3948
47.864972939, 96.390, 1062.0, 32.5883
47.917494069, 96.390, 1107.0, 33.2716
47.970015200, 96.390, 1024.0, 32.0000
48.022536331, 96.390, 1039.0, 32.2335
48.075057462, 96.390, 1044.0, 32.3110
48.127578592, 96.390, 1104.0, 33.2265
48.180099723, 96.390, 1040.0, 32.2490
48.232620854, 96.390, 1073.0, 32.7567
48.285141984, 96.390, 1050.0, 32.4037
48.337663115, 96.390, 1041.0, 32.2645
48.390184246, 96.390, 1073.0, 32.7567
48.442705377, 96.390, 1222.0, 34.9571
48.495226507, 96.390, 1309.0, 36.1801
48.547747638, 96.390, 1235.0, 35.1426
48.600268769, 96.390, 1086.0, 32.9545
48.652789899, 96.390, 1012.0, 31.8119
48.705311030, 96.390, 880.0, 29.6648
48.757832161, 96.390, 920.0, 30.3315
48.810353292, 96.390, 931.0, 30.5123
48.862874422, 96.390, 938.0, 30.6268
48.915395553, 96.390, 919.0, 30.3150
48.967916684, 96.390, 933.0, 30.5450
49.020437814, 96.390, 959.0, 30.9677
49.072958945, 96.390, 1016.0, 31.8748
49.125480076, 96.390, 1119.0, 33.4515
49.178001207, 96.390, 993.0, 31.5119
49.230522337, 96.390, 1040.0, 32.2490
49.283043468, 96.390, 940.0, 30.6594
49.335564599, 96.390, 977.0, 31.2570
49.388085729, 96.390, 882.0, 29.6985
49.440606860, 96.390, 853.0, 29.2062
49.493127991, 96.390, 942.0, 30.6920
49.545649121, 96.390, 901.0, 30.0167
49.598170252, 96.390, 940.0, 30.6594
49.650691383, 96.390, 963.0, 31.0322
49.703212514, 96.390, 969.0, 31.1288
49.755733644, 96.390, 991.0, 31.4802
49.808254775, 96.390, 910.0, 30.1662
49.860775906, 96.390, 954.0, 30.8869
49.913297036, 96.390, 863.0, 29.3769
49.965818167, 96.390, 852.0, 29.1890
50.018339298, 96.390, 807.0, 28.4077
50.070860429, 96.390, 848.0, 29.1204
50.123381559, 96.390, 821.0, 28.6531
50.175902690, 96.390, 881.0, 29.6816
50.228423821, 96.390, 968.0, 31.1127
50.280944951, 96.390, 950.0, 30.8221
50.333466082, 96.390, 954.0, 30.8869
50.385987213, 96.390, 1005.0, 31.7017
50.438508344, 96.390, 1033.0, 32.1403
50.491029474, 96.390, 1008.0, 31.7490
50.543550605, 96.390, 1033.0, 32.1403
50.596071736, 96.390, 1000.0, 31.6228
50.648592866, 96.390, 977.0, 31.2570
50.701113997, 96.390, 895.0, 29.9166
50.753635128, 96.390, 924.0, 30.3974
50.806156258, 96.390, 903.0, 30.0500
50.858677389, 96.390, 922.0, 30.3645
50.911198520, 96.390, 891.0, 29.8496
50.963719651, 96.390, 882.0, 29.6985
51.016240781, 96.390, 917.0, 30.2820
51.068761912, 96.390, 976.0, 31.2410
51.121283043, 96.390, 1010.0, 31.7805
51.173804173, 96.390, 1015.0, 31.8591
51.226325304, 96.390, 922.0, 30.3645
51.278846435, 96.390, 958.0, 30.9516
51.331367566, 96.390, 877.0, 29.6142
51.383888696, 96.390, 835.0, 28.8964
51.436409827, 96.390, 781.0, 27.9464
51.488930958, 96.390, 793.0, 28.1603
51.541452088, 96.390, 825.0, 28.7228
51.593973219, 96.390, 798.0, 28.2489
51.646494350, 96.390, 785.0, 28.0179
51.699015481, 96.390, 874.0, 29.5635
51.751536611, 96.390, 888.0, 29.7993
51.804057742, 96.390, 902.0, 30.0333
51.856578873, 96.390, 956.0, 30.9192
51.909100003, 96.390, 924.0, 30.3974
51.961621134, 96.390, 889.0, 29.8161
52.014142265, 96.390, 930.0, 30.4959
52.066663396, 96.390, 919.0, 30.3150
52.119184526, 96.390, 866.0, 29.4279
52.171705657, 96.390, 956.0, 30.9192
52.224226788, 96.390, 1022.0, 31.9687
52.276747918, 96.390, 1017.0, 31.8904
52.329269049, 96.390, 976.0, 31.2410
52.381790180, 96.390, 968.0, 31.1127
52.434311310, 96.390, 994.0, 31.5278
52.486832441, 96.390, 919.0, 30.3150
52.539353572, 96.390, 1039.0, 32.2335
52.591874703, 96.390, 1069.0, 32.6956
52.644395833, 96.390, 1099.0, 33.1512
52.696916964, 96.390, 1123.0, 33.5112
52.749438095, 96.390, 1124.0, 33.5261
52.801959225, 96.390, 1144.0, 33.8231
52.854480356, 96.390, 1122.0, 33.4963
52.907001487, 96.390, 1138.0, 33.7343
52.959522618, 96.390, 1234.0, 35.1283
53.012043748, 96.390, 1353.0, 36.7831
53.064564879, 96.390, 1559.0, 39.4842
53.117086010, 96.390, 1648.0, 40.5956
53.169607140, 96.390, 1634.0, 40.4228
53.222128271, 96.390, 1611.0, 40.1373
53.274649402, 96.390, 1461.0, 38.2230
53.327170533, 96.390, 1273.0, 35.6791
53.379691663, 96.390, 1152.0, 33.9411
53.432212794, 96.390, 1137.0, 33.7194
53.484733925, 96.390, 1090.0, 33.0151
53.537255055, 96.390, 883.0, 29.7153
53.589776186, 96.390, 875.0, 29.5804
53.642297317, 96.390, 805.0, 28.3725
53.694818448, 96.390, 825.0, 28.7228
53.747339578, 96.390, 815.0, 28.5482
53.799860709, 96.390, 819.0, 28.6182
53.852381840, 96.390, 919.0, 30.3150
53.904902970, 96.390, 926.0, 30.4302
53.957424101, 96.390, 925.0, 30.4138
54.009945232, 96.390, 950.0, 30.8221
54.062466362, 96.390, 928.0, 30.4631
54.114987493, 96.390, 959.0, 30.9677
54.167508624, 96.390, 936.0, 30.5941
54.220029755, 96.390, 961.0, 31.0000
54.272550885, 96.390, 1038.0, 32.2180
54.325072016, 96.390, 1015.0, 31.8591
54.377593147, 96.390, 954.0, 30.8869
54.430114277, 96.390, 885.0, 29.7489
54.482635408, 96.390, 844.0, 29.0517
54.535156539, 96.390, 835.0, 28.8964
54.587677670, 96.390, 697.0, 26.4008
54.640198800, 96.390, 701.0, 26.4764
54.692719931, 96.390, 719.0, 26.8142
54.745241062, 96.390, 728.0, 26.9815
54.797762192, 96.390, 707.0, 26.5895
54.850283323, 96.390, 692.0, 26.3059
54.902804454, 96.390, 662.0, 25.7294
54.955325585, 96.390, 639.0, 25.2784
55.007846715, 96.390, 676.0, 26.0000
55.060367846, 96.390, 674.0, 25.9615
55.112888977, 96.390, 662.0, 25.7294
55.165410107, 96.390, 661.0, 25.7099
55.217931238, 96.390, 678.0, 26.0384
55.270452369, 96.390, 698.0, 26.4197
55.322973499, 96.390, 712.0, 26.6833
55.375494630, 96.390, 732.0, 27.0555
55.428015761, 96.390, 753.0, 27.4408
55.480536892, 96.390, 774.0, 27.8209
55.533058022, 96.390, 720.0, 26.8328
55.585579153, 96.390, 758.0, 27.5318
55.638100284, 96.390, 738.0, 27.1662
55.690621414, 96.390, 746.0, 27.3130
55.743142545, 96.390, 741.0, 27.2213
55.795663676, 96.390, 741.0, 27.2213
55.848184807, 96.390, 686.0, 26.1916
55.900705937, 96.390, 743.0, 27.2580
55.953227068, 96.390, 784.0, 28.0000
56.005748199, 96.390, 781.0, 27.9464
56.058269329, 96.390, 785.0, 28.0179
56.110790460, 96.390, 826.0, 28.7402
56.163311591, 96.390, 793.0, 28.1603
56.215832722, 96.390, 694.0, 26.3439
56.268353852, 96.390, 741.0, 27.2213
56.320874983, 96.390, 731.0, 27.0370
56.373396114, 96.390, 724.0, 26.9072
56.425917244, 96.390, 760.0, 27.5681
56.478438375, 96.390, 759.0, 27.5500
56.530959506, 96.390, 721.0, 26.8514
56.583480637, 96.390, 720.0, 26.8328
56.636001767, 96.390, 688.0, 26.2298
56.688522898, 96.390, 692.0, 26.3059
56.741044029, 96.390, 700.0, 26.4575
56.793565159, 96.390, 644.0, 25.3772
56.846086290, 96.390, 587.0, 24.2281
56.898607421, 96.390, 647.0, 25.4362
56.951128551, 96.390, 654.0, 25.5734
57.003649682, 96.390, 650.0, 25.4951
57.056170813, 96.390, 680.0, 26.0768
57.108691944, 96.390, 710.0, 26.6458
57.161213074, 96.390, 802.0, 28.3196
57.213734205, 96.390, 784.0, 28.0000
57.266255336, 96.390, 769.0, 27.7308
57.318776466, 96.390, 777.0, 27.8747
57.371297597, 96.390, 823.0, 28.6880
57.423818728, 96.390, 762.0, 27.6043
57.476339859, 96.390, 738.0, 27.1662
57.528860989, 96.390, 828.0, 28.7750
57.581382120, 96.390, 786.0, 28.0357
57.633903251, 96.390, 780.0, 27.9285
57.686424381, 96.390, 862.0, 29.3598
57.738945512, 96.390, 805.0, 28.3725
57.791466643, 96.390, 784.0, 28.0000
57.843987774, 96.390, 741.0, 27.2213
57.896508904, 96.390, 688.0, 26.2298
57.949030035, 96.390, 672.0, 25.9230
58.001551166, 96.390, 718.0, 26.7955
58.054072296, 96.390, 781.0, 27.9464
58.106593427, 96.390, 715.0, 26.7395
58.159114558, 96.390, 718.0, 26.7955
58.211635689, 96.390, 789.0, 28.0891
58.264156819, 96.390, 704.0, 26.5330
58.316677950, 96.390, 653.0, 25.5539
58.369199081, 96.390, 681.0, 26.0960
58.421720211, 96.390, 706.0, 26.5707
58.474241342, 96.390, 726.0, 26.9444
58.526762473, 96.390, 797.0, 28.2312
58.579283603, 96.390, 766.0, 27.6767
58.631804734, 96.390, 747.0, 27.3313
58.684325865, 96.390, 709.0, 26.6271
58.736846996, 96.390, 760.0, 27.5681
58.789368126, 96.390, 721.0, 26.8514
58.841889257, 96.390, 670.0, 25.8844
58.894410388, 96.390, 726.0, 26.9444
58.946931518, 96.390, 661.0, 25.7099
58.999452649, 96.390, 695.0, 26.3629
59.051973780, 96.390, 714.0, 26.7208
59.104494911, 96.390, 776.0, 27.8568
59.157016041, 96.390, 736.0, 27.1293
59.209537172, 96.390, 781.0, 27.9464
59.262058303, 96.390, 756.0, 27.4955
59.314579433, 96.390, 756.0, 27.4955
59.367100564, 96.390, 722.0, 26.8701
59.419621695, 96.390, 823.0, 28.6880
59.472142826, 96.390, 760.0, 27.5681
59.524663956, 96.390, 764.0, 27.6405
59.577185087, 96.390, 693.0, 26.3249
59.629706218, 96.390, 690.0, 26.2679
59.682227348, 96.390, 707.0, 26.5895
59.734748479, 96.390, 692.0, 26.3059
59.787269610, 96.390, 688.0, 26.2298
59.839790740, 96.390, 698.0, 26.4197
59.892311871, 96.390, 626.0, 25.0200
59.944833002, 96.390, 691.0, 26.2869
59.997354133, 96.390, 667.0, 25.8263
60.049875263, 96.390, 679.0, 26.0576
60.102396394, 96.390, 754.0, 27.4591
60.154917525, 96.390, 734.0, 27.0924
60.207438655, 96.390, 699.0, 26.4386
60.259959786, 96.390, 738.0, 27.1662
60.312480917, 96.390, 739.0, 27.1846
60.365002048, 96.390, 749.0, 27.3679
60.417523178, 96.390, 764.0, 27.6405
60.470044309, 96.390, 862.0, 29.3598
60.522565440, 96.390, 883.0, 29.7153
60.575086570, 96.390, 890.0, 29.8329
60.627607701, 96.390, 974.0, 31.2090
60.680128832, 96.390, 1123.0, 33.5112
60.732649963, 96.390, 1084.0, 32.9242
60.785171093, 96.390, 1185.0, 34.4238
60.837692224, 96.390, 1164.0, 34.1174
60.890213355, 96.390, 1218.0, 34.8999
60.942734485, 96.390, 1176.0, 34.2929
60.995255616, 96.390, 1130.0, 33.6155
61.047776747, 96.390, 1132.0, 33.6452
61.100297878, 96.390, 1081.0, 32.8786
61.152819008, 96.390, 1091.0, 33.0303
61.205340139, 96.390, 1096.0, 33.1059
61.257861270, 96.390, 968.0, 31.1127
61.310382400, 96.390, 929.0, 30.4795
61.362903531, 96.390, 883.0, 29.7153
61.415424662, 96.390, 805.0, 28.3725
61.467945792, 96.390, 873.0, 29.5466
61.520466923, 96.390, 962.0, 31.0161
61.572988054, 96.390, 931.0, 30.5123
61.625509185, 96.390, 908.0, 30.1330
61.678030315, 96.390, 895.0, 29.9166
61.730551446, 96.390, 879.0, 29.6479
61.783072577, 96.390, 877.0, 29.6142
61.835593707, 96.390, 914.0, 30.2324
61.888114838, 96.390, 902.0, 30.0333
61.940635969, 96.390, 855.0, 29.2404
61.993157100, 96.390, 951.0, 30.8383
62.045678230, 96.390, 981.0, 31.3209
62.098199361, 96.390, 945.0, 30.7409
62.150720492, 96.390, 951.0, 30.8383
62.203241622, 96.390, 1069.0, 32.6956
62.255762753, 96.390, 971.0, 31.1609
62.308283884, 96.390, 992.0, 31.4960
62.360805015, 96.390, 925.0, 30.4138
62.413326145, 96.390, 873.0, 29.5466
62.465847276, 96.390, 819.0, 28.6182
62.518368407, 96.390, 844.0, 29.0517
62.570889537, 96.390, 797.0, 28.2312
62.623410668, 96.390, 783.0, 27.9821
62.675931799, 96.390, 821.0, 28.6531
62.728452930, 96.390, 818.0, 28.6007
62.780974060, 96.390, 776.0, 27.8568
62.833495191, 96.390, 790.0, 28.1069
62.886016322, 96.390, 717.0, 26.7769
62.938537452, 96.390, 696.0, 26.3818
62.991058583, 96.390, 615.0, 24.7992
63.043579714, 96.390, 591.0, 24.3105
63.096100844, 96.390, 585.0, 24.1868
63.148621975, 96.390, 596.0, 24.4131
63.201143106, 96.390, 586.0, 24.2074
63.253664237, 96.390, 617.0, 24.8395
63.306185367, 96.390, 606.0, 24.6171
63.358706498, 96.390, 601.0, 24.5153
63.411227629, 96.390, 632.0, 25.1396
63.463748759, 96.390, 629.0, 25.0799
63.516269890, 96.390, 647.0, 25.4362
63.568791021, 96.390, 671.0, 25.9037
63.621312152, 96.390, 720.0, 26.8328
63.673833282, 96.390, 796.0, 28.2135
63.726354413, 96.390, 860.0, 29.3258
63.778875544, 96.390, 1004.0, 31.6860
63.831396674, 96.390, 906.0, 30.0998
63.883917805, 96.390, 882.0, 29.6985
63.936438936, 96.390, 877.0, 29.6142
63.988960067, 96.390, 804.0, 28.3549
64.041481197, 96.390, 735.0, 27.1109
64.094002328, 96.390, 727.0, 26.9629
64.146523459, 96.390, 770.0, 27.7489
64.199044589, 96.390, 761.0, 27.5862
64.251565720, 96.390, 765.0, 27.6586
64.304086851, 96.390, 731.0, 27.0370
64.356607981, 96.390, 768.0, 27.7128
64.409129112, 96.390, 721.0, 26.8514
64.461650243, 96.390, 698.0, 26.4197
64.514171374, 96.390, 691.0, 26.2869
64.566692504, 96.390, 619.0, 24.8797
64.619213635, 96.390, 609.0, 24.6779
64.671734766, 96.390, 647.0, 25.4362
64.724255896, 96.390, 579.0, 24.0624
64.776777027, 96.390, 547.0, 23.3880
64.829298158, 96.390, 544.0, 23.3238
64.881819289, 96.390, 570.0, 23.8747
64.934340419, 96.390, 541.0, 23.2594
64.986861550, 96.390, 586.0, 24.2074