File: Files_organized_for_plots/Constant_NaOH_1mL10M_to_1gPC_28Day_repeat/AlCorner31Jan22_Act12Feb23_B1_0833M_NaOH_LS0153_Num155.csv
[Measurement conditions]
Sample identification,AlCorner31Jan22_Act12Feb23_B1_0833M_NaOH_LS0153_Num155
Comment - 1,"Configuration=Stage for Flat Samples/Holders, Owner=nmw10, Creation date=9/21/2022 10:06:30 AM"
Comment - 2,"Goniometer=Theta/Theta; Minimum step size 2Theta:0.0001; Minimum step size Omega:0.0001"
Comment - 3,"Sample stage=Stage for flat samples/holders"
Comment - 4,"Diffractometer system=EMPYREAN"
Comment - 5,"Measurement program=X:\XRD\Cement\Zerobackground scan.xrdmp, Created identifier={98A3B11C-88F9-4AA6-982C-73314A311EF5}, Created by=Titus Reed, Id=tmr79, Creation date=10/26/2021 3:01:47 PM"
Anode material,Cu
K-Alpha1 wavelength,1.5405980
K-Alpha2 wavelength,1.5444260
Ratio K-Alpha2/K-Alpha1,0.500
Divergence slit,Fixed,0.25
Monochromator used,NO
Generator voltage, 45
Tube current, 40
File date and time,15/Mar/2023 19:40
Unit cell,
h k l, 0 0 0
Scan axis,Gonio
Scan range,4.994599997,64.999991833
Scan step size,0.0262606
No. of points, 2285
Scan type,CONTINUOUS
Time per step,96.390
[Scan points]
Angle, TimePerStep, Intensity, ESD
5.007730280, 96.390, 3441.0, 58.6600
5.060251411, 96.390, 3581.0, 59.8415
5.112772541, 96.390, 3538.0, 59.4811
5.165293672, 96.390, 3553.0, 59.6070
5.217814803, 96.390, 3504.0, 59.1946
5.270335934, 96.390, 3374.0, 58.0861
5.322857064, 96.390, 3340.0, 57.7927
5.375378195, 96.390, 3394.0, 58.2580
5.427899326, 96.390, 3265.0, 57.1402
5.480420456, 96.390, 3185.0, 56.4358
5.532941587, 96.390, 3158.0, 56.1961
5.585462718, 96.390, 3238.0, 56.9034
5.637983849, 96.390, 3165.0, 56.2583
5.690504979, 96.390, 3097.0, 55.6507
5.743026110, 96.390, 3080.0, 55.4977
5.795547241, 96.390, 3180.0, 56.3915
5.848068371, 96.390, 3059.0, 55.3082
5.900589502, 96.390, 3108.0, 55.7494
5.953110633, 96.390, 3093.0, 55.6147
6.005631763, 96.390, 3040.0, 55.1362
6.058152894, 96.390, 3092.0, 55.6058
6.110674025, 96.390, 3068.0, 55.3895
6.163195156, 96.390, 3101.0, 55.6866
6.215716286, 96.390, 3067.0, 55.3805
6.268237417, 96.390, 2915.0, 53.9907
6.320758548, 96.390, 3102.0, 55.6956
6.373279678, 96.390, 2945.0, 54.2679
6.425800809, 96.390, 3143.0, 56.0625
6.478321940, 96.390, 3075.0, 55.4527
6.530843071, 96.390, 3169.0, 56.2939
6.583364201, 96.390, 3113.0, 55.7943
6.635885332, 96.390, 3154.0, 56.1605
6.688406463, 96.390, 3367.0, 58.0259
6.740927593, 96.390, 3487.0, 59.0508
6.793448724, 96.390, 3648.0, 60.3987
6.845969855, 96.390, 3699.0, 60.8194
6.898490986, 96.390, 4127.0, 64.2417
6.951012116, 96.390, 4704.0, 68.5857
7.003533247, 96.390, 5504.0, 74.1889
7.056054378, 96.390, 6565.0, 81.0247
7.108575508, 96.390, 8785.0, 93.7283
7.161096639, 96.390, 12204.0, 110.4717
7.213617770, 96.390, 11044.0, 105.0904
7.266138900, 96.390, 5153.0, 71.7844
7.318660031, 96.390, 3771.0, 61.4085
7.371181162, 96.390, 3305.0, 57.4891
7.423702293, 96.390, 2969.0, 54.4885
7.476223423, 96.390, 2895.0, 53.8052
7.528744554, 96.390, 2834.0, 53.2353
7.581265685, 96.390, 2866.0, 53.5350
7.633786815, 96.390, 2863.0, 53.5070
7.686307946, 96.390, 2734.0, 52.2877
7.738829077, 96.390, 2665.0, 51.6236
7.791350208, 96.390, 2759.0, 52.5262
7.843871338, 96.390, 2644.0, 51.4198
7.896392469, 96.390, 2697.0, 51.9326
7.948913600, 96.390, 2702.0, 51.9808
8.001434730, 96.390, 2727.0, 52.2207
8.053955861, 96.390, 2679.0, 51.7591
8.106476992, 96.390, 2755.0, 52.4881
8.158998123, 96.390, 2656.0, 51.5364
8.211519253, 96.390, 2657.0, 51.5461
8.264040384, 96.390, 2593.0, 50.9215
8.316561515, 96.390, 2652.0, 51.4976
8.369082645, 96.390, 2540.0, 50.3984
8.421603776, 96.390, 2758.0, 52.5167
8.474124907, 96.390, 2630.0, 51.2835
8.526646038, 96.390, 2943.0, 54.2494
8.579167168, 96.390, 3416.0, 58.4466
8.631688299, 96.390, 2657.0, 51.5461
8.684209430, 96.390, 2530.0, 50.2991
8.736730560, 96.390, 2581.0, 50.8035
8.789251691, 96.390, 2542.0, 50.4183
8.841772822, 96.390, 2603.0, 51.0196
8.894293952, 96.390, 2482.0, 49.8197
8.946815083, 96.390, 2399.0, 48.9796
8.999336214, 96.390, 2446.0, 49.4571
9.051857345, 96.390, 2365.0, 48.6313
9.104378475, 96.390, 2492.0, 49.9199
9.156899606, 96.390, 2485.0, 49.8498
9.209420737, 96.390, 2429.0, 49.2849
9.261941867, 96.390, 2455.0, 49.5480
9.314462998, 96.390, 2469.0, 49.6890
9.366984129, 96.390, 2527.0, 50.2693
9.419505260, 96.390, 2448.0, 49.4773
9.472026390, 96.390, 2511.0, 50.1099
9.524547521, 96.390, 2440.0, 49.3964
9.577068652, 96.390, 2523.0, 50.2295
9.629589782, 96.390, 2487.0, 49.8698
9.682110913, 96.390, 2557.0, 50.5668
9.734632044, 96.390, 2540.0, 50.3984
9.787153175, 96.390, 2662.0, 51.5946
9.839674305, 96.390, 2694.0, 51.9038
9.892195436, 96.390, 2813.0, 53.0377
9.944716567, 96.390, 3255.0, 57.0526
9.997237697, 96.390, 3730.0, 61.0737
10.049758828, 96.390, 4609.0, 67.8896
10.102279959, 96.390, 6099.0, 78.0961
10.154801090, 96.390, 8285.0, 91.0220
10.207322220, 96.390, 6636.0, 81.4616
10.259843351, 96.390, 3570.0, 59.7495
10.312364482, 96.390, 2859.0, 53.4696
10.364885612, 96.390, 2695.0, 51.9134
10.417406743, 96.390, 2585.0, 50.8429
10.469927874, 96.390, 2506.0, 50.0600
10.522449004, 96.390, 2552.0, 50.5173
10.574970135, 96.390, 2487.0, 49.8698
10.627491266, 96.390, 2558.0, 50.5767
10.680012397, 96.390, 2515.0, 50.1498
10.732533527, 96.390, 2550.0, 50.4975
10.785054658, 96.390, 2536.0, 50.3587
10.837575789, 96.390, 2642.0, 51.4004
10.890096919, 96.390, 2680.0, 51.7687
10.942618050, 96.390, 2862.0, 53.4977
10.995139181, 96.390, 2821.0, 53.1131
11.047660312, 96.390, 2914.0, 53.9815
11.100181442, 96.390, 3080.0, 55.4977
11.152702573, 96.390, 3100.0, 55.6776
11.205223704, 96.390, 3356.0, 57.9310
11.257744834, 96.390, 3602.0, 60.0167
11.310265965, 96.390, 3783.0, 61.5061
11.362787096, 96.390, 4249.0, 65.1844
11.415308227, 96.390, 4646.0, 68.1616
11.467829357, 96.390, 5096.0, 71.3863
11.520350488, 96.390, 5373.0, 73.3008
11.572871619, 96.390, 5739.0, 75.7562
11.625392749, 96.390, 5988.0, 77.3822
11.677913880, 96.390, 5933.0, 77.0260
11.730435011, 96.390, 5630.0, 75.0333
11.782956141, 96.390, 5355.0, 73.1779
11.835477272, 96.390, 4731.0, 68.7823
11.887998403, 96.390, 4122.0, 64.2028
11.940519534, 96.390, 3731.0, 61.0819
11.993040664, 96.390, 3401.0, 58.3181
12.045561795, 96.390, 3218.0, 56.7274
12.098082926, 96.390, 2999.0, 54.7631
12.150604056, 96.390, 3007.0, 54.8361
12.203125187, 96.390, 3117.0, 55.8301
12.255646318, 96.390, 3089.0, 55.5788
12.308167449, 96.390, 3348.0, 57.8619
12.360688579, 96.390, 4049.0, 63.6318
12.413209710, 96.390, 5327.0, 72.9863
12.465730841, 96.390, 6596.0, 81.2158
12.518251971, 96.390, 4479.0, 66.9253
12.570773102, 96.390, 2775.0, 52.6783
12.623294233, 96.390, 2430.0, 49.2950
12.675815364, 96.390, 2283.0, 47.7807
12.728336494, 96.390, 2147.0, 46.3357
12.780857625, 96.390, 2151.0, 46.3789
12.833378756, 96.390, 2105.0, 45.8803
12.885899886, 96.390, 2000.0, 44.7214
12.938421017, 96.390, 1923.0, 43.8520
12.990942148, 96.390, 1927.0, 43.8976
13.043463279, 96.390, 1992.0, 44.6318
13.095984409, 96.390, 1987.0, 44.5758
13.148505540, 96.390, 1970.0, 44.3847
13.201026671, 96.390, 1970.0, 44.3847
13.253547801, 96.390, 1898.0, 43.5660
13.306068932, 96.390, 1954.0, 44.2041
13.358590063, 96.390, 2125.0, 46.0977
13.411111193, 96.390, 2225.0, 47.1699
13.463632324, 96.390, 2741.0, 52.3546
13.516153455, 96.390, 2557.0, 50.5668
13.568674586, 96.390, 2067.0, 45.4643
13.621195716, 96.390, 1900.0, 43.5890
13.673716847, 96.390, 1798.0, 42.4028
13.726237978, 96.390, 1792.0, 42.3320
13.778759108, 96.390, 1858.0, 43.1045
13.831280239, 96.390, 2040.0, 45.1664
13.883801370, 96.390, 2170.0, 46.5833
13.936322501, 96.390, 2079.0, 45.5961
13.988843631, 96.390, 1834.0, 42.8252
14.041364762, 96.390, 1792.0, 42.3320
14.093885893, 96.390, 1895.0, 43.5316
14.146407023, 96.390, 2102.0, 45.8476
14.198928154, 96.390, 2561.0, 50.6063
14.251449285, 96.390, 2992.0, 54.6992
14.303970416, 96.390, 2470.0, 49.6991
14.356491546, 96.390, 1837.0, 42.8602
14.409012677, 96.390, 1789.0, 42.2966
14.461533808, 96.390, 1800.0, 42.4264
14.514054938, 96.390, 1839.0, 42.8836
14.566576069, 96.390, 1878.0, 43.3359
14.619097200, 96.390, 1577.0, 39.7115
14.671618331, 96.390, 1641.0, 40.5093
14.724139461, 96.390, 1700.0, 41.2311
14.776660592, 96.390, 1747.0, 41.7971
14.829181723, 96.390, 1670.0, 40.8656
14.881702853, 96.390, 1760.0, 41.9524
14.934223984, 96.390, 1765.0, 42.0119
14.986745115, 96.390, 1646.0, 40.5709
15.039266245, 96.390, 1736.0, 41.6653
15.091787376, 96.390, 1821.0, 42.6732
15.144308507, 96.390, 1936.0, 44.0000
15.196829638, 96.390, 2440.0, 49.3964
15.249350768, 96.390, 3141.0, 56.0446
15.301871899, 96.390, 2760.0, 52.5357
15.354393030, 96.390, 1900.0, 43.5890
15.406914160, 96.390, 1715.0, 41.4126
15.459435291, 96.390, 1630.0, 40.3733
15.511956422, 96.390, 1480.0, 38.4708
15.564477553, 96.390, 1572.0, 39.6485
15.616998683, 96.390, 1601.0, 40.0125
15.669519814, 96.390, 1577.0, 39.7115
15.722040945, 96.390, 1578.0, 39.7240
15.774562075, 96.390, 1595.0, 39.9375
15.827083206, 96.390, 1666.0, 40.8167
15.879604337, 96.390, 1707.0, 41.3159
15.932125468, 96.390, 1918.0, 43.7950
15.984646598, 96.390, 2310.0, 48.0625
16.037167729, 96.390, 2934.0, 54.1664
16.089688860, 96.390, 3999.0, 63.2376
16.142209990, 96.390, 4011.0, 63.3325
16.194731121, 96.390, 2496.0, 49.9600
16.247252252, 96.390, 1805.0, 42.4853
16.299773382, 96.390, 1797.0, 42.3910
16.352294513, 96.390, 1810.0, 42.5441
16.404815644, 96.390, 1744.0, 41.7612
16.457336775, 96.390, 1640.0, 40.4969
16.509857905, 96.390, 1634.0, 40.4228
16.562379036, 96.390, 1576.0, 39.6989
16.614900167, 96.390, 1557.0, 39.4588
16.667421297, 96.390, 1477.0, 38.4318
16.719942428, 96.390, 1540.0, 39.2428
16.772463559, 96.390, 1569.0, 39.6106
16.824984690, 96.390, 1481.0, 38.4838
16.877505820, 96.390, 1499.0, 38.7169
16.930026951, 96.390, 1463.0, 38.2492
16.982548082, 96.390, 1419.0, 37.6696
17.035069212, 96.390, 1418.0, 37.6563
17.087590343, 96.390, 1332.0, 36.4966
17.140111474, 96.390, 1376.0, 37.0945
17.192632605, 96.390, 1468.0, 38.3145
17.245153735, 96.390, 1330.0, 36.4692
17.297674866, 96.390, 1344.0, 36.6606
17.350195997, 96.390, 1367.0, 36.9730
17.402717127, 96.390, 1314.0, 36.2491
17.455238258, 96.390, 1392.0, 37.3095
17.507759389, 96.390, 1333.0, 36.5103
17.560280520, 96.390, 1490.0, 38.6005
17.612801650, 96.390, 1531.0, 39.1280
17.665322781, 96.390, 1610.0, 40.1248
17.717843912, 96.390, 1504.0, 38.7814
17.770365042, 96.390, 1447.0, 38.0395
17.822886173, 96.390, 1416.0, 37.6298
17.875407304, 96.390, 1475.0, 38.4057
17.927928434, 96.390, 1519.0, 38.9744
17.980449565, 96.390, 1472.0, 38.3667
18.032970696, 96.390, 1550.0, 39.3700
18.085491827, 96.390, 1676.0, 40.9390
18.138012957, 96.390, 1771.0, 42.0833
18.190534088, 96.390, 2018.0, 44.9222
18.243055219, 96.390, 2345.0, 48.4252
18.295576349, 96.390, 2837.0, 53.2635
18.348097480, 96.390, 3408.0, 58.3781
18.400618611, 96.390, 4018.0, 63.3877
18.453139742, 96.390, 4963.0, 70.4486
18.505660872, 96.390, 5739.0, 75.7562
18.558182003, 96.390, 6021.0, 77.5951
18.610703134, 96.390, 6372.0, 79.8248
18.663224264, 96.390, 6704.0, 81.8780
18.715745395, 96.390, 7325.0, 85.5862
18.768266526, 96.390, 7119.0, 84.3742
18.820787657, 96.390, 5309.0, 72.8629
18.873308787, 96.390, 3527.0, 59.3886
18.925829918, 96.390, 2583.0, 50.8232
18.978351049, 96.390, 2113.0, 45.9674
19.030872179, 96.390, 1844.0, 42.9418
19.083393310, 96.390, 1704.0, 41.2795
19.135914441, 96.390, 1702.0, 41.2553
19.188435572, 96.390, 1482.0, 38.4968
19.240956702, 96.390, 1497.0, 38.6911
19.293477833, 96.390, 1598.0, 39.9750
19.345998964, 96.390, 1819.0, 42.6497
19.398520094, 96.390, 2134.0, 46.1952
19.451041225, 96.390, 1992.0, 44.6318
19.503562356, 96.390, 1680.0, 40.9878
19.556083486, 96.390, 1483.0, 38.5097
19.608604617, 96.390, 1676.0, 40.9390
19.661125748, 96.390, 1755.0, 41.8927
19.713646879, 96.390, 1693.0, 41.1461
19.766168009, 96.390, 1706.0, 41.3038
19.818689140, 96.390, 1966.0, 44.3396
19.871210271, 96.390, 2529.0, 50.2892
19.923731401, 96.390, 3803.0, 61.6685
19.976252532, 96.390, 4394.0, 66.2873
20.028773663, 96.390, 3035.0, 55.0908
20.081294794, 96.390, 2511.0, 50.1099
20.133815924, 96.390, 3149.0, 56.1160
20.186337055, 96.390, 4398.0, 66.3174
20.238858186, 96.390, 6495.0, 80.5916
20.291379316, 96.390, 7810.0, 88.3742
20.343900447, 96.390, 7162.0, 84.6286
20.396421578, 96.390, 6284.0, 79.2717
20.448942709, 96.390, 5628.0, 75.0200
20.501463839, 96.390, 4220.0, 64.9615
20.553984970, 96.390, 3814.0, 61.7576
20.606506101, 96.390, 4692.0, 68.4982
20.659027231, 96.390, 7681.0, 87.6413
20.711548362, 96.390, 9423.0, 97.0721
20.764069493, 96.390, 5611.0, 74.9066
20.816590623, 96.390, 2510.0, 50.0999
20.869111754, 96.390, 1912.0, 43.7264
20.921632885, 96.390, 1661.0, 40.7554
20.974154016, 96.390, 1618.0, 40.2244
21.026675146, 96.390, 1464.0, 38.2623
21.079196277, 96.390, 1398.0, 37.3898
21.131717408, 96.390, 1479.0, 38.4578
21.184238538, 96.390, 1418.0, 37.6563
21.236759669, 96.390, 1414.0, 37.6032
21.289280800, 96.390, 1562.0, 39.5221
21.341801931, 96.390, 1691.0, 41.1218
21.394323061, 96.390, 1700.0, 41.2311
21.446844192, 96.390, 1661.0, 40.7554
21.499365323, 96.390, 1825.0, 42.7200
21.551886453, 96.390, 2373.0, 48.7134
21.604407584, 96.390, 3387.0, 58.1979
21.656928715, 96.390, 4812.0, 69.3686
21.709449846, 96.390, 4558.0, 67.5130
21.761970976, 96.390, 2871.0, 53.5817
21.814492107, 96.390, 1659.0, 40.7308
21.867013238, 96.390, 1473.0, 38.3797
21.919534368, 96.390, 1367.0, 36.9730
21.972055499, 96.390, 1309.0, 36.1801
22.024576630, 96.390, 1253.0, 35.3977
22.077097761, 96.390, 1256.0, 35.4401
22.129618891, 96.390, 1212.0, 34.8138
22.182140022, 96.390, 1271.0, 35.6511
22.234661153, 96.390, 1251.0, 35.3695
22.287182283, 96.390, 1251.0, 35.3695
22.339703414, 96.390, 1152.0, 33.9411
22.392224545, 96.390, 1181.0, 34.3657
22.444745675, 96.390, 1246.0, 35.2987
22.497266806, 96.390, 1242.0, 35.2420
22.549787937, 96.390, 1264.0, 35.5528
22.602309068, 96.390, 1282.0, 35.8050
22.654830198, 96.390, 1341.0, 36.6197
22.707351329, 96.390, 1354.0, 36.7967
22.759872460, 96.390, 1491.0, 38.6135
22.812393590, 96.390, 1685.0, 41.0488
22.864914721, 96.390, 1864.0, 43.1741
22.917435852, 96.390, 1814.0, 42.5911
22.969956983, 96.390, 1602.0, 40.0250
23.022478113, 96.390, 1611.0, 40.1373
23.074999244, 96.390, 1748.0, 41.8091
23.127520375, 96.390, 1887.0, 43.4396
23.180041505, 96.390, 1998.0, 44.6990
23.232562636, 96.390, 2153.0, 46.4004
23.285083767, 96.390, 2262.0, 47.5605
23.337604898, 96.390, 2478.0, 49.7795
23.390126028, 96.390, 2571.0, 50.7050
23.442647159, 96.390, 2709.0, 52.0481
23.495168290, 96.390, 2698.0, 51.9423
23.547689420, 96.390, 2712.0, 52.0769
23.600210551, 96.390, 2592.0, 50.9117
23.652731682, 96.390, 2391.0, 48.8979
23.705252813, 96.390, 2249.0, 47.4236
23.757773943, 96.390, 2221.0, 47.1275
23.810295074, 96.390, 2397.0, 48.9592
23.862816205, 96.390, 2985.0, 54.6352
23.915337335, 96.390, 4285.0, 65.4599
23.967858466, 96.390, 6720.0, 81.9756
24.020379597, 96.390, 6978.0, 83.5344
24.072900727, 96.390, 4876.0, 69.8284
24.125421858, 96.390, 3004.0, 54.8088
24.177942989, 96.390, 2337.0, 48.3425
24.230464120, 96.390, 1851.0, 43.0232
24.282985250, 96.390, 1414.0, 37.6032
24.335506381, 96.390, 1303.0, 36.0971
24.388027512, 96.390, 1221.0, 34.9428
24.440548642, 96.390, 1196.0, 34.5832
24.493069773, 96.390, 1081.0, 32.8786
24.545590904, 96.390, 1114.0, 33.3766
24.598112035, 96.390, 1064.0, 32.6190
24.650633165, 96.390, 1096.0, 33.1059
24.703154296, 96.390, 1048.0, 32.3728
24.755675427, 96.390, 1096.0, 33.1059
24.808196557, 96.390, 1050.0, 32.4037
24.860717688, 96.390, 1010.0, 31.7805
24.913238819, 96.390, 1064.0, 32.6190
24.965759950, 96.390, 1035.0, 32.1714
25.018281080, 96.390, 1065.0, 32.6343
25.070802211, 96.390, 1165.0, 34.1321
25.123323342, 96.390, 1131.0, 33.6303
25.175844472, 96.390, 1071.0, 32.7261
25.228365603, 96.390, 1126.0, 33.5559
25.280886734, 96.390, 1225.0, 35.0000
25.333407864, 96.390, 1556.0, 39.4462
25.385928995, 96.390, 2190.0, 46.7974
25.438450126, 96.390, 2593.0, 50.9215
25.490971257, 96.390, 1946.0, 44.1135
25.543492387, 96.390, 1295.0, 35.9861
25.596013518, 96.390, 1159.0, 34.0441
25.648534649, 96.390, 1049.0, 32.3883
25.701055779, 96.390, 1069.0, 32.6956
25.753576910, 96.390, 1169.0, 34.1906
25.806098041, 96.390, 1100.0, 33.1662
25.858619172, 96.390, 1192.0, 34.5254
25.911140302, 96.390, 1366.0, 36.9594
25.963661433, 96.390, 1479.0, 38.4578
26.016182564, 96.390, 1702.0, 41.2553
26.068703694, 96.390, 2308.0, 48.0416
26.121224825, 96.390, 2714.0, 52.0961
26.173745956, 96.390, 2317.0, 48.1352
26.226267087, 96.390, 1684.0, 41.0366
26.278788217, 96.390, 1269.0, 35.6230
26.331309348, 96.390, 1205.0, 34.7131
26.383830479, 96.390, 1179.0, 34.3366
26.436351609, 96.390, 1210.0, 34.7851
26.488872740, 96.390, 1201.0, 34.6554
26.541393871, 96.390, 1212.0, 34.8138
26.593915002, 96.390, 1214.0, 34.8425
26.646436132, 96.390, 1174.0, 34.2637
26.698957263, 96.390, 1272.0, 35.6651
26.751478394, 96.390, 1390.0, 37.2827
26.803999524, 96.390, 1576.0, 39.6989
26.856520655, 96.390, 1717.0, 41.4367
26.909041786, 96.390, 1856.0, 43.0813
26.961562916, 96.390, 2218.0, 47.0956
27.014084047, 96.390, 3096.0, 55.6417
27.066605178, 96.390, 5135.0, 71.6589
27.119126309, 96.390, 7532.0, 86.7871
27.171647439, 96.390, 7592.0, 87.1321
27.224168570, 96.390, 5063.0, 71.1548
27.276689701, 96.390, 2802.0, 52.9339
27.329210831, 96.390, 1850.0, 43.0116
27.381731962, 96.390, 1714.0, 41.4005
27.434253093, 96.390, 1586.0, 39.8246
27.486774224, 96.390, 1716.0, 41.4246
27.539295354, 96.390, 1696.0, 41.1825
27.591816485, 96.390, 1750.0, 41.8330
27.644337616, 96.390, 1979.0, 44.4860
27.696858746, 96.390, 2240.0, 47.3286
27.749379877, 96.390, 2433.0, 49.3254
27.801901008, 96.390, 2343.0, 48.4045
27.854422139, 96.390, 2309.0, 48.0521
27.906943269, 96.390, 2003.0, 44.7549
27.959464400, 96.390, 1856.0, 43.0813
28.011985531, 96.390, 1691.0, 41.1218
28.064506661, 96.390, 1566.0, 39.5727
28.117027792, 96.390, 1490.0, 38.6005
28.169548923, 96.390, 1326.0, 36.4143
28.222070054, 96.390, 1156.0, 34.0000
28.274591184, 96.390, 1198.0, 34.6121
28.327112315, 96.390, 1176.0, 34.2929
28.379633446, 96.390, 1210.0, 34.7851
28.432154576, 96.390, 1148.0, 33.8821
28.484675707, 96.390, 1129.0, 33.6006
28.537196838, 96.390, 1147.0, 33.8674
28.589717968, 96.390, 1180.0, 34.3511
28.642239099, 96.390, 1275.0, 35.7071
28.694760230, 96.390, 1448.0, 38.0526
28.747281361, 96.390, 1603.0, 40.0375
28.799802491, 96.390, 1460.0, 38.2099
28.852323622, 96.390, 1284.0, 35.8329
28.904844753, 96.390, 1199.0, 34.6266
28.957365883, 96.390, 1325.0, 36.4005
29.009887014, 96.390, 1502.0, 38.7556
29.062408145, 96.390, 1908.0, 43.6807
29.114929276, 96.390, 1951.0, 44.1701
29.167450406, 96.390, 1653.0, 40.6571
29.219971537, 96.390, 1367.0, 36.9730
29.272492668, 96.390, 1312.0, 36.2215
29.325013798, 96.390, 1372.0, 37.0405
29.377534929, 96.390, 1347.0, 36.7015
29.430056060, 96.390, 1321.0, 36.3456
29.482577191, 96.390, 1329.0, 36.4555
29.535098321, 96.390, 1272.0, 35.6651
29.587619452, 96.390, 1307.0, 36.1525
29.640140583, 96.390, 1373.0, 37.0540
29.692661713, 96.390, 1407.0, 37.5100
29.745182844, 96.390, 1649.0, 40.6079
29.797703975, 96.390, 2217.0, 47.0850
29.850225105, 96.390, 3337.0, 57.7668
29.902746236, 96.390, 5258.0, 72.5121
29.955267367, 96.390, 7281.0, 85.3288
30.007788498, 96.390, 5979.0, 77.3240
30.060309628, 96.390, 3972.0, 63.0238
30.112830759, 96.390, 2174.0, 46.6262
30.165351890, 96.390, 1600.0, 40.0000
30.217873020, 96.390, 1357.0, 36.8375
30.270394151, 96.390, 1262.0, 35.5246
30.322915282, 96.390, 1144.0, 33.8231
30.375436413, 96.390, 1180.0, 34.3511
30.427957543, 96.390, 1147.0, 33.8674
30.480478674, 96.390, 1158.0, 34.0294
30.532999805, 96.390, 1229.0, 35.0571
30.585520935, 96.390, 1449.0, 38.0657
30.638042066, 96.390, 1746.0, 41.7852
30.690563197, 96.390, 1724.0, 41.5211
30.743084328, 96.390, 1906.0, 43.6578
30.795605458, 96.390, 2246.0, 47.3920
30.848126589, 96.390, 2499.0, 49.9900
30.900647720, 96.390, 2071.0, 45.5082
30.953168850, 96.390, 1643.0, 40.5339
31.005689981, 96.390, 1407.0, 37.5100
31.058211112, 96.390, 1338.0, 36.5787
31.110732243, 96.390, 1716.0, 41.4246
31.163253373, 96.390, 2584.0, 50.8331
31.215774504, 96.390, 2944.0, 54.2586
31.268295635, 96.390, 2381.0, 48.7955
31.320816765, 96.390, 1870.0, 43.2435
31.373337896, 96.390, 1552.0, 39.3954
31.425859027, 96.390, 1501.0, 38.7427
31.478380157, 96.390, 1589.0, 39.8623
31.530901288, 96.390, 1697.0, 41.1947
31.583422419, 96.390, 1685.0, 41.0488
31.635943550, 96.390, 1721.0, 41.4849
31.688464680, 96.390, 1371.0, 37.0270
31.740985811, 96.390, 1311.0, 36.2077
31.793506942, 96.390, 1329.0, 36.4555
31.846028072, 96.390, 1517.0, 38.9487
31.898549203, 96.390, 2074.0, 45.5412
31.951070334, 96.390, 3363.0, 57.9914
32.003591465, 96.390, 5793.0, 76.1118
32.056112595, 96.390, 7797.0, 88.3006
32.108633726, 96.390, 5720.0, 75.6307
32.161154857, 96.390, 4009.0, 63.3167
32.213675987, 96.390, 2182.0, 46.7119
32.266197118, 96.390, 1838.0, 42.8719
32.318718249, 96.390, 1662.0, 40.7676
32.371239380, 96.390, 1578.0, 39.7240
32.423760510, 96.390, 1547.0, 39.3319
32.476281641, 96.390, 1770.0, 42.0714
32.528802772, 96.390, 2149.0, 46.3573
32.581323902, 96.390, 2230.0, 47.2229
32.633845033, 96.390, 1977.0, 44.4635
32.686366164, 96.390, 1463.0, 38.2492
32.738887295, 96.390, 1304.0, 36.1109
32.791408425, 96.390, 1143.0, 33.8083
32.843929556, 96.390, 1093.0, 33.0606
32.896450687, 96.390, 1103.0, 33.2114
32.948971817, 96.390, 1199.0, 34.6266
33.001492948, 96.390, 1204.0, 34.6987
33.054014079, 96.390, 1195.0, 34.5688
33.106535209, 96.390, 1306.0, 36.1386
33.159056340, 96.390, 1253.0, 35.3977
33.211577471, 96.390, 1371.0, 37.0270
33.264098602, 96.390, 1442.0, 37.9737
33.316619732, 96.390, 1450.0, 38.0789
33.369140863, 96.390, 1579.0, 39.7366
33.421661994, 96.390, 1684.0, 41.0366
33.474183124, 96.390, 1528.0, 39.0896
33.526704255, 96.390, 1411.0, 37.5633
33.579225386, 96.390, 1289.0, 35.9026
33.631746517, 96.390, 1315.0, 36.2629
33.684267647, 96.390, 1295.0, 35.9861
33.736788778, 96.390, 1338.0, 36.5787
33.789309909, 96.390, 1547.0, 39.3319
33.841831039, 96.390, 1885.0, 43.4166
33.894352170, 96.390, 2836.0, 53.2541
33.946873301, 96.390, 3731.0, 61.0819
33.999394432, 96.390, 3273.0, 57.2101
34.051915562, 96.390, 3237.0, 56.8946
34.104436693, 96.390, 3299.0, 57.4369
34.156957824, 96.390, 4609.0, 67.8896
34.209478954, 96.390, 5343.0, 73.0958
34.262000085, 96.390, 4226.0, 65.0077
34.314521216, 96.390, 3308.0, 57.5152
34.367042346, 96.390, 2420.0, 49.1935
34.419563477, 96.390, 2446.0, 49.4571
34.472084608, 96.390, 2457.0, 49.5681
34.524605739, 96.390, 2266.0, 47.6025
34.577126869, 96.390, 2187.0, 46.7654
34.629648000, 96.390, 2052.0, 45.2990
34.682169131, 96.390, 2163.0, 46.5081
34.734690261, 96.390, 2154.0, 46.4112
34.787211392, 96.390, 2770.0, 52.6308
34.839732523, 96.390, 3501.0, 59.1692
34.892253654, 96.390, 4441.0, 66.6408
34.944774784, 96.390, 4243.0, 65.1383
34.997295915, 96.390, 3455.0, 58.7792
35.049817046, 96.390, 2479.0, 49.7896
35.102338176, 96.390, 1858.0, 43.1045
35.154859307, 96.390, 1710.0, 41.3521
35.207380438, 96.390, 1514.0, 38.9102
35.259901569, 96.390, 1481.0, 38.4838
35.312422699, 96.390, 1406.0, 37.4967
35.364943830, 96.390, 1358.0, 36.8511
35.417464961, 96.390, 1395.0, 37.3497
35.469986091, 96.390, 1334.0, 36.5240
35.522507222, 96.390, 1323.0, 36.3731
35.575028353, 96.390, 1449.0, 38.0657
35.627549484, 96.390, 1550.0, 39.3700
35.680070614, 96.390, 1622.0, 40.2741
35.732591745, 96.390, 1799.0, 42.4146
35.785112876, 96.390, 1825.0, 42.7200
35.837634006, 96.390, 1631.0, 40.3856
35.890155137, 96.390, 1538.0, 39.2173
35.942676268, 96.390, 1435.0, 37.8814
35.995197398, 96.390, 1315.0, 36.2629
36.047718529, 96.390, 1214.0, 34.8425
36.100239660, 96.390, 1251.0, 35.3695
36.152760791, 96.390, 1338.0, 36.5787
36.205281921, 96.390, 1377.0, 37.1080
36.257803052, 96.390, 1344.0, 36.6606
36.310324183, 96.390, 1260.0, 35.4965
36.362845313, 96.390, 1243.0, 35.2562
36.415366444, 96.390, 1311.0, 36.2077
36.467887575, 96.390, 1425.0, 37.7492
36.520408706, 96.390, 1438.0, 37.9210
36.572929836, 96.390, 1475.0, 38.4057
36.625450967, 96.390, 1399.0, 37.4032
36.677972098, 96.390, 1216.0, 34.8712
36.730493228, 96.390, 1103.0, 33.2114
36.783014359, 96.390, 1047.0, 32.3574
36.835535490, 96.390, 972.0, 31.1769
36.888056621, 96.390, 910.0, 30.1662
36.940577751, 96.390, 968.0, 31.1127
36.993098882, 96.390, 980.0, 31.3050
37.045620013, 96.390, 974.0, 31.2090
37.098141143, 96.390, 1001.0, 31.6386
37.150662274, 96.390, 1073.0, 32.7567
37.203183405, 96.390, 1049.0, 32.3883
37.255704535, 96.390, 1167.0, 34.1614
37.308225666, 96.390, 1035.0, 32.1714
37.360746797, 96.390, 1124.0, 33.5261
37.413267928, 96.390, 1175.0, 34.2783
37.465789058, 96.390, 1197.0, 34.5977
37.518310189, 96.390, 1311.0, 36.2077
37.570831320, 96.390, 1442.0, 37.9737
37.623352450, 96.390, 1631.0, 40.3856
37.675873581, 96.390, 1924.0, 43.8634
37.728394712, 96.390, 2090.0, 45.7165
37.780915843, 96.390, 1937.0, 44.0114
37.833436973, 96.390, 1984.0, 44.5421
37.885958104, 96.390, 1610.0, 40.1248
37.938479235, 96.390, 1644.0, 40.5463
37.991000365, 96.390, 1727.0, 41.5572
38.043521496, 96.390, 1721.0, 41.4849
38.096042627, 96.390, 1675.0, 40.9268
38.148563758, 96.390, 1589.0, 39.8623
38.201084888, 96.390, 1553.0, 39.4081
38.253606019, 96.390, 1424.0, 37.7359
38.306127150, 96.390, 1253.0, 35.3977
38.358648280, 96.390, 1216.0, 34.8712
38.411169411, 96.390, 1213.0, 34.8281
38.463690542, 96.390, 1306.0, 36.1386
38.516211673, 96.390, 1338.0, 36.5787
38.568732803, 96.390, 1380.0, 37.1484
38.621253934, 96.390, 1347.0, 36.7015
38.673775065, 96.390, 1625.0, 40.3113
38.726296195, 96.390, 1709.0, 41.3401
38.778817326, 96.390, 1808.0, 42.5206
38.831338457, 96.390, 1526.0, 39.0640
38.883859587, 96.390, 1464.0, 38.2623
38.936380718, 96.390, 1242.0, 35.2420
38.988901849, 96.390, 1223.0, 34.9714
39.041422980, 96.390, 1256.0, 35.4401
39.093944110, 96.390, 1209.0, 34.7707
39.146465241, 96.390, 1310.0, 36.1939
39.198986372, 96.390, 1337.0, 36.5650
39.251507502, 96.390, 1513.0, 38.8973
39.304028633, 96.390, 1731.0, 41.6053
39.356549764, 96.390, 2178.0, 46.6690
39.409070895, 96.390, 2788.0, 52.8015
39.461592025, 96.390, 2643.0, 51.4101
39.514113156, 96.390, 2368.0, 48.6621
39.566634287, 96.390, 2225.0, 47.1699
39.619155417, 96.390, 1809.0, 42.5323
39.671676548, 96.390, 1644.0, 40.5463
39.724197679, 96.390, 1484.0, 38.5227
39.776718810, 96.390, 1505.0, 38.7943
39.829239940, 96.390, 1493.0, 38.6394
39.881761071, 96.390, 1465.0, 38.2753
39.934282202, 96.390, 1519.0, 38.9744
39.986803332, 96.390, 1557.0, 39.4588
40.039324463, 96.390, 1780.0, 42.1900
40.091845594, 96.390, 2045.0, 45.2217
40.144366725, 96.390, 2240.0, 47.3286
40.196887855, 96.390, 2233.0, 47.2546
40.249408986, 96.390, 2521.0, 50.2096
40.301930117, 96.390, 2597.0, 50.9608
40.354451247, 96.390, 3055.0, 55.2721
40.406972378, 96.390, 3442.0, 58.6686
40.459493509, 96.390, 4080.0, 63.8749
40.512014639, 96.390, 4592.0, 67.7643
40.564535770, 96.390, 4722.0, 68.7168
40.617056901, 96.390, 4322.0, 65.7419
40.669578032, 96.390, 3691.0, 60.7536
40.722099162, 96.390, 3001.0, 54.7814
40.774620293, 96.390, 2295.0, 47.9062
40.827141424, 96.390, 1929.0, 43.9204
40.879662554, 96.390, 1595.0, 39.9375
40.932183685, 96.390, 1416.0, 37.6298
40.984704816, 96.390, 1403.0, 37.4566
41.037225947, 96.390, 1263.0, 35.5387
41.089747077, 96.390, 1285.0, 35.8469
41.142268208, 96.390, 1244.0, 35.2704
41.194789339, 96.390, 1312.0, 36.2215
41.247310469, 96.390, 1506.0, 38.8072
41.299831600, 96.390, 1903.0, 43.6234
41.352352731, 96.390, 2264.0, 47.5815
41.404873862, 96.390, 2130.0, 46.1519
41.457394992, 96.390, 2072.0, 45.5192
41.509916123, 96.390, 2005.0, 44.7772
41.562437254, 96.390, 1805.0, 42.4853
41.614958384, 96.390, 1672.0, 40.8901
41.667479515, 96.390, 1443.0, 37.9868
41.720000646, 96.390, 1328.0, 36.4417
41.772521776, 96.390, 1193.0, 34.5398
41.825042907, 96.390, 1212.0, 34.8138
41.877564038, 96.390, 1093.0, 33.0606
41.930085169, 96.390, 1129.0, 33.6006
41.982606299, 96.390, 1035.0, 32.1714
42.035127430, 96.390, 1260.0, 35.4965
42.087648561, 96.390, 1387.0, 37.2424
42.140169691, 96.390, 1643.0, 40.5339
42.192690822, 96.390, 1546.0, 39.3192
42.245211953, 96.390, 1553.0, 39.4081
42.297733084, 96.390, 1290.0, 35.9166
42.350254214, 96.390, 1231.0, 35.0856
42.402775345, 96.390, 1065.0, 32.6343
42.455296476, 96.390, 1125.0, 33.5410
42.507817606, 96.390, 1228.0, 35.0428
42.560338737, 96.390, 1229.0, 35.0571
42.612859868, 96.390, 1158.0, 34.0294
42.665380999, 96.390, 1143.0, 33.8083
42.717902129, 96.390, 989.0, 31.4484
42.770423260, 96.390, 1009.0, 31.7648
42.822944391, 96.390, 1100.0, 33.1662
42.875465521, 96.390, 1152.0, 33.9411
42.927986652, 96.390, 1112.0, 33.3467
42.980507783, 96.390, 1054.0, 32.4654
43.033028914, 96.390, 922.0, 30.3645
43.085550044, 96.390, 902.0, 30.0333
43.138071175, 96.390, 931.0, 30.5123
43.190592306, 96.390, 876.0, 29.5973
43.243113436, 96.390, 882.0, 29.6985
43.295634567, 96.390, 916.0, 30.2655
43.348155698, 96.390, 876.0, 29.5973
43.400676828, 96.390, 936.0, 30.5941
43.453197959, 96.390, 1017.0, 31.8904
43.505719090, 96.390, 1121.0, 33.4813
43.558240221, 96.390, 1249.0, 35.3412
43.610761351, 96.390, 1297.0, 36.0139
43.663282482, 96.390, 1473.0, 38.3797
43.715803613, 96.390, 1904.0, 43.6348
43.768324743, 96.390, 1886.0, 43.4281
43.820845874, 96.390, 1613.0, 40.1622
43.873367005, 96.390, 1524.0, 39.0384
43.925888136, 96.390, 1307.0, 36.1525
43.978409266, 96.390, 1157.0, 34.0147
44.030930397, 96.390, 1154.0, 33.9706
44.083451528, 96.390, 1235.0, 35.1426
44.135972658, 96.390, 1473.0, 38.3797
44.188493789, 96.390, 1617.0, 40.2119
44.241014920, 96.390, 1619.0, 40.2368
44.293536051, 96.390, 1572.0, 39.6485
44.346057181, 96.390, 1651.0, 40.6325
44.398578312, 96.390, 1443.0, 37.9868
44.451099443, 96.390, 1261.0, 35.5106
44.503620573, 96.390, 1147.0, 33.8674
44.556141704, 96.390, 994.0, 31.5278
44.608662835, 96.390, 916.0, 30.2655
44.661183966, 96.390, 861.0, 29.3428
44.713705096, 96.390, 923.0, 30.3809
44.766226227, 96.390, 989.0, 31.4484
44.818747358, 96.390, 1091.0, 33.0303
44.871268488, 96.390, 1112.0, 33.3467
44.923789619, 96.390, 1052.0, 32.4345
44.976310750, 96.390, 1057.0, 32.5115
45.028831880, 96.390, 1228.0, 35.0428
45.081353011, 96.390, 1383.0, 37.1887
45.133874142, 96.390, 1416.0, 37.6298
45.186395273, 96.390, 1315.0, 36.2629
45.238916403, 96.390, 1469.0, 38.3275
45.291437534, 96.390, 1458.0, 38.1838
45.343958665, 96.390, 1458.0, 38.1838
45.396479795, 96.390, 1466.0, 38.2884
45.449000926, 96.390, 1594.0, 39.9249
45.501522057, 96.390, 1515.0, 38.9230
45.554043188, 96.390, 1362.0, 36.9053
45.606564318, 96.390, 1335.0, 36.5377
45.659085449, 96.390, 1125.0, 33.5410
45.711606580, 96.390, 1125.0, 33.5410
45.764127710, 96.390, 1103.0, 33.2114
45.816648841, 96.390, 1193.0, 34.5398
45.869169972, 96.390, 1066.0, 32.6497
45.921691103, 96.390, 1077.0, 32.8177
45.974212233, 96.390, 1075.0, 32.7872
46.026733364, 96.390, 1100.0, 33.1662
46.079254495, 96.390, 1134.0, 33.6749
46.131775625, 96.390, 1080.0, 32.8634
46.184296756, 96.390, 1230.0, 35.0714
46.236817887, 96.390, 1412.0, 37.5766
46.289339017, 96.390, 1292.0, 35.9444
46.341860148, 96.390, 1255.0, 35.4260
46.394381279, 96.390, 1222.0, 34.9571
46.446902410, 96.390, 1110.0, 33.3167
46.499423540, 96.390, 971.0, 31.1609
46.551944671, 96.390, 1009.0, 31.7648
46.604465802, 96.390, 1051.0, 32.4191
46.656986932, 96.390, 1057.0, 32.5115
46.709508063, 96.390, 1144.0, 33.8231
46.762029194, 96.390, 1147.0, 33.8674
46.814550325, 96.390, 1246.0, 35.2987
46.867071455, 96.390, 1337.0, 36.5650
46.919592586, 96.390, 1525.0, 39.0512
46.972113717, 96.390, 1747.0, 41.7971
47.024634847, 96.390, 1645.0, 40.5586
47.077155978, 96.390, 1614.0, 40.1746
47.129677109, 96.390, 1538.0, 39.2173
47.182198240, 96.390, 1450.0, 38.0789
47.234719370, 96.390, 1501.0, 38.7427
47.287240501, 96.390, 1737.0, 41.6773
47.339761632, 96.390, 1629.0, 40.3609
47.392282762, 96.390, 1466.0, 38.2884
47.444803893, 96.390, 1430.0, 37.8153
47.497325024, 96.390, 1247.0, 35.3129
47.549846155, 96.390, 1056.0, 32.4962
47.602367285, 96.390, 962.0, 31.0161
47.654888416, 96.390, 930.0, 30.4959
47.707409547, 96.390, 923.0, 30.3809
47.759930677, 96.390, 944.0, 30.7246
47.812451808, 96.390, 1015.0, 31.8591
47.864972939, 96.390, 1004.0, 31.6860
47.917494069, 96.390, 1202.0, 34.6699
47.970015200, 96.390, 1192.0, 34.5254
48.022536331, 96.390, 1201.0, 34.6554
48.075057462, 96.390, 1249.0, 35.3412
48.127578592, 96.390, 1256.0, 35.4401
48.180099723, 96.390, 1038.0, 32.2180
48.232620854, 96.390, 1059.0, 32.5423
48.285141984, 96.390, 931.0, 30.5123
48.337663115, 96.390, 929.0, 30.4795
48.390184246, 96.390, 1016.0, 31.8748
48.442705377, 96.390, 1137.0, 33.7194
48.495226507, 96.390, 1229.0, 35.0571
48.547747638, 96.390, 1089.0, 33.0000
48.600268769, 96.390, 1055.0, 32.4808
48.652789899, 96.390, 951.0, 30.8383
48.705311030, 96.390, 827.0, 28.7576
48.757832161, 96.390, 787.0, 28.0535
48.810353292, 96.390, 777.0, 27.8747
48.862874422, 96.390, 767.0, 27.6948
48.915395553, 96.390, 779.0, 27.9106
48.967916684, 96.390, 850.0, 29.1548
49.020437814, 96.390, 823.0, 28.6880
49.072958945, 96.390, 890.0, 29.8329
49.125480076, 96.390, 947.0, 30.7734
49.178001207, 96.390, 955.0, 30.9031
49.230522337, 96.390, 862.0, 29.3598
49.283043468, 96.390, 847.0, 29.1033
49.335564599, 96.390, 864.0, 29.3939
49.388085729, 96.390, 836.0, 28.9137
49.440606860, 96.390, 808.0, 28.4253
49.493127991, 96.390, 854.0, 29.2233
49.545649121, 96.390, 847.0, 29.1033
49.598170252, 96.390, 843.0, 29.0345
49.650691383, 96.390, 969.0, 31.1288
49.703212514, 96.390, 969.0, 31.1288
49.755733644, 96.390, 938.0, 30.6268
49.808254775, 96.390, 901.0, 30.0167
49.860775906, 96.390, 919.0, 30.3150
49.913297036, 96.390, 826.0, 28.7402
49.965818167, 96.390, 767.0, 27.6948
50.018339298, 96.390, 765.0, 27.6586
50.070860429, 96.390, 746.0, 27.3130
50.123381559, 96.390, 847.0, 29.1033
50.175902690, 96.390, 1049.0, 32.3883
50.228423821, 96.390, 1151.0, 33.9264
50.280944951, 96.390, 1103.0, 33.2114
50.333466082, 96.390, 979.0, 31.2890
50.385987213, 96.390, 978.0, 31.2730
50.438508344, 96.390, 871.0, 29.5127
50.491029474, 96.390, 810.0, 28.4605
50.543550605, 96.390, 749.0, 27.3679
50.596071736, 96.390, 737.0, 27.1477
50.648592866, 96.390, 758.0, 27.5318
50.701113997, 96.390, 752.0, 27.4226
50.753635128, 96.390, 775.0, 27.8388
50.806156258, 96.390, 765.0, 27.6586
50.858677389, 96.390, 790.0, 28.1069
50.911198520, 96.390, 786.0, 28.0357
50.963719651, 96.390, 783.0, 27.9821
51.016240781, 96.390, 795.0, 28.1957
51.068761912, 96.390, 845.0, 29.0689
51.121283043, 96.390, 851.0, 29.1719
51.173804173, 96.390, 937.0, 30.6105
51.226325304, 96.390, 1003.0, 31.6702
51.278846435, 96.390, 910.0, 30.1662
51.331367566, 96.390, 855.0, 29.2404
51.383888696, 96.390, 839.0, 28.9655
51.436409827, 96.390, 801.0, 28.3019
51.488930958, 96.390, 780.0, 27.9285
51.541452088, 96.390, 758.0, 27.5318
51.593973219, 96.390, 722.0, 26.8701
51.646494350, 96.390, 766.0, 27.6767
51.699015481, 96.390, 844.0, 29.0517
51.751536611, 96.390, 859.0, 29.3087
51.804057742, 96.390, 891.0, 29.8496
51.856578873, 96.390, 838.0, 28.9482
51.909100003, 96.390, 802.0, 28.3196
51.961621134, 96.390, 892.0, 29.8664
52.014142265, 96.390, 1046.0, 32.3419
52.066663396, 96.390, 1070.0, 32.7109
52.119184526, 96.390, 1194.0, 34.5543
52.171705657, 96.390, 1397.0, 37.3765
52.224226788, 96.390, 1443.0, 37.9868
52.276747918, 96.390, 1382.0, 37.1753
52.329269049, 96.390, 1286.0, 35.8608
52.381790180, 96.390, 1318.0, 36.3043
52.434311310, 96.390, 1168.0, 34.1760
52.486832441, 96.390, 1244.0, 35.2704
52.539353572, 96.390, 1536.0, 39.1918
52.591874703, 96.390, 1817.0, 42.6263
52.644395833, 96.390, 1981.0, 44.5084
52.696916964, 96.390, 1908.0, 43.6807
52.749438095, 96.390, 1782.0, 42.2137
52.801959225, 96.390, 1726.0, 41.5452
52.854480356, 96.390, 1672.0, 40.8901
52.907001487, 96.390, 1662.0, 40.7676
52.959522618, 96.390, 1697.0, 41.1947
53.012043748, 96.390, 1871.0, 43.2551
53.064564879, 96.390, 2011.0, 44.8442
53.117086010, 96.390, 2106.0, 45.8912
53.169607140, 96.390, 2171.0, 46.5940
53.222128271, 96.390, 1986.0, 44.5646
53.274649402, 96.390, 1768.0, 42.0476
53.327170533, 96.390, 1610.0, 40.1248
53.379691663, 96.390, 1384.0, 37.2022
53.432212794, 96.390, 1224.0, 34.9857
53.484733925, 96.390, 1091.0, 33.0303
53.537255055, 96.390, 1062.0, 32.5883
53.589776186, 96.390, 913.0, 30.2159
53.642297317, 96.390, 872.0, 29.5296
53.694818448, 96.390, 820.0, 28.6356
53.747339578, 96.390, 791.0, 28.1247
53.799860709, 96.390, 840.0, 28.9828
53.852381840, 96.390, 827.0, 28.7576
53.904902970, 96.390, 856.0, 29.2575
53.957424101, 96.390, 862.0, 29.3598
54.009945232, 96.390, 858.0, 29.2916
54.062466362, 96.390, 958.0, 30.9516
54.114987493, 96.390, 1071.0, 32.7261
54.167508624, 96.390, 1086.0, 32.9545
54.220029755, 96.390, 1250.0, 35.3553
54.272550885, 96.390, 1406.0, 37.4967
54.325072016, 96.390, 1422.0, 37.7094
54.377593147, 96.390, 1223.0, 34.9714
54.430114277, 96.390, 1118.0, 33.4365
54.482635408, 96.390, 1045.0, 32.3265
54.535156539, 96.390, 869.0, 29.4788
54.587677670, 96.390, 780.0, 27.9285
54.640198800, 96.390, 692.0, 26.3059
54.692719931, 96.390, 725.0, 26.9258
54.745241062, 96.390, 676.0, 26.0000
54.797762192, 96.390, 680.0, 26.0768
54.850283323, 96.390, 726.0, 26.9444
54.902804454, 96.390, 707.0, 26.5895
54.955325585, 96.390, 647.0, 25.4362
55.007846715, 96.390, 702.0, 26.4953
55.060367846, 96.390, 622.0, 24.9399
55.112888977, 96.390, 619.0, 24.8797
55.165410107, 96.390, 683.0, 26.1343
55.217931238, 96.390, 534.0, 23.1084
55.270452369, 96.390, 644.0, 25.3772
55.322973499, 96.390, 638.0, 25.2587
55.375494630, 96.390, 643.0, 25.3574
55.428015761, 96.390, 657.0, 25.6320
55.480536892, 96.390, 725.0, 26.9258
55.533058022, 96.390, 801.0, 28.3019
55.585579153, 96.390, 835.0, 28.8964
55.638100284, 96.390, 763.0, 27.6225
55.690621414, 96.390, 714.0, 26.7208
55.743142545, 96.390, 756.0, 27.4955
55.795663676, 96.390, 807.0, 28.4077
55.848184807, 96.390, 702.0, 26.4953
55.900705937, 96.390, 712.0, 26.6833
55.953227068, 96.390, 718.0, 26.7955
56.005748199, 96.390, 655.0, 25.5930
56.058269329, 96.390, 696.0, 26.3818
56.110790460, 96.390, 675.0, 25.9808
56.163311591, 96.390, 656.0, 25.6125
56.215832722, 96.390, 646.0, 25.4165
56.268353852, 96.390, 651.0, 25.5147
56.320874983, 96.390, 672.0, 25.9230
56.373396114, 96.390, 616.0, 24.8193
56.425917244, 96.390, 834.0, 28.8791
56.478438375, 96.390, 780.0, 27.9285
56.530959506, 96.390, 899.0, 29.9833
56.583480637, 96.390, 816.0, 28.5657
56.636001767, 96.390, 773.0, 27.8029
56.688522898, 96.390, 842.0, 29.0172
56.741044029, 96.390, 727.0, 26.9629
56.793565159, 96.390, 657.0, 25.6320
56.846086290, 96.390, 750.0, 27.3861
56.898607421, 96.390, 738.0, 27.1662
56.951128551, 96.390, 631.0, 25.1197
57.003649682, 96.390, 740.0, 27.2029
57.056170813, 96.390, 770.0, 27.7489
57.108691944, 96.390, 780.0, 27.9285
57.161213074, 96.390, 792.0, 28.1425
57.213734205, 96.390, 775.0, 27.8388
57.266255336, 96.390, 754.0, 27.4591
57.318776466, 96.390, 833.0, 28.8617
57.371297597, 96.390, 799.0, 28.2666
57.423818728, 96.390, 832.0, 28.8444
57.476339859, 96.390, 932.0, 30.5287
57.528860989, 96.390, 1062.0, 32.5883
57.581382120, 96.390, 1096.0, 33.1059
57.633903251, 96.390, 987.0, 31.4166
57.686424381, 96.390, 957.0, 30.9354
57.738945512, 96.390, 892.0, 29.8664
57.791466643, 96.390, 835.0, 28.8964
57.843987774, 96.390, 693.0, 26.3249
57.896508904, 96.390, 783.0, 27.9821
57.949030035, 96.390, 763.0, 27.6225
58.001551166, 96.390, 827.0, 28.7576
58.054072296, 96.390, 896.0, 29.9333
58.106593427, 96.390, 774.0, 27.8209
58.159114558, 96.390, 738.0, 27.1662
58.211635689, 96.390, 819.0, 28.6182
58.264156819, 96.390, 710.0, 26.6458
58.316677950, 96.390, 608.0, 24.6577
58.369199081, 96.390, 623.0, 24.9600
58.421720211, 96.390, 641.0, 25.3180
58.474241342, 96.390, 694.0, 26.3439
58.526762473, 96.390, 894.0, 29.8998
58.579283603, 96.390, 982.0, 31.3369
58.631804734, 96.390, 1111.0, 33.3317
58.684325865, 96.390, 985.0, 31.3847
58.736846996, 96.390, 941.0, 30.6757
58.789368126, 96.390, 853.0, 29.2062
58.841889257, 96.390, 817.0, 28.5832
58.894410388, 96.390, 723.0, 26.8887
58.946931518, 96.390, 740.0, 27.2029
58.999452649, 96.390, 714.0, 26.7208
59.051973780, 96.390, 691.0, 26.2869
59.104494911, 96.390, 765.0, 27.6586
59.157016041, 96.390, 785.0, 28.0179
59.209537172, 96.390, 807.0, 28.4077
59.262058303, 96.390, 829.0, 28.7924
59.314579433, 96.390, 819.0, 28.6182
59.367100564, 96.390, 742.0, 27.2397
59.419621695, 96.390, 786.0, 28.0357
59.472142826, 96.390, 756.0, 27.4955
59.524663956, 96.390, 761.0, 27.5862
59.577185087, 96.390, 739.0, 27.1846
59.629706218, 96.390, 695.0, 26.3629
59.682227348, 96.390, 658.0, 25.6515
59.734748479, 96.390, 724.0, 26.9072
59.787269610, 96.390, 747.0, 27.3313
59.839790740, 96.390, 710.0, 26.6458
59.892311871, 96.390, 682.0, 26.1151
59.944833002, 96.390, 734.0, 27.0924
59.997354133, 96.390, 727.0, 26.9629
60.049875263, 96.390, 687.0, 26.2107
60.102396394, 96.390, 694.0, 26.3439
60.154917525, 96.390, 710.0, 26.6458
60.207438655, 96.390, 807.0, 28.4077
60.259959786, 96.390, 782.0, 27.9643
60.312480917, 96.390, 699.0, 26.4386
60.365002048, 96.390, 716.0, 26.7582
60.417523178, 96.390, 689.0, 26.2488
60.470044309, 96.390, 671.0, 25.9037
60.522565440, 96.390, 671.0, 25.9037
60.575086570, 96.390, 726.0, 26.9444
60.627607701, 96.390, 829.0, 28.7924
60.680128832, 96.390, 1017.0, 31.8904
60.732649963, 96.390, 1238.0, 35.1852
60.785171093, 96.390, 1365.0, 36.9459
60.837692224, 96.390, 1453.0, 38.1182
60.890213355, 96.390, 1284.0, 35.8329
60.942734485, 96.390, 1140.0, 33.7639
60.995255616, 96.390, 1062.0, 32.5883
61.047776747, 96.390, 907.0, 30.1164
61.100297878, 96.390, 823.0, 28.6880
61.152819008, 96.390, 774.0, 27.8209
61.205340139, 96.390, 750.0, 27.3861
61.257861270, 96.390, 794.0, 28.1780
61.310382400, 96.390, 765.0, 27.6586
61.362903531, 96.390, 752.0, 27.4226
61.415424662, 96.390, 780.0, 27.9285
61.467945792, 96.390, 797.0, 28.2312
61.520466923, 96.390, 726.0, 26.9444
61.572988054, 96.390, 673.0, 25.9422
61.625509185, 96.390, 691.0, 26.2869
61.678030315, 96.390, 692.0, 26.3059
61.730551446, 96.390, 674.0, 25.9615
61.783072577, 96.390, 686.0, 26.1916
61.835593707, 96.390, 679.0, 26.0576
61.888114838, 96.390, 732.0, 27.0555
61.940635969, 96.390, 757.0, 27.5136
61.993157100, 96.390, 797.0, 28.2312
62.045678230, 96.390, 963.0, 31.0322
62.098199361, 96.390, 1097.0, 33.1210
62.150720492, 96.390, 1225.0, 35.0000
62.203241622, 96.390, 1204.0, 34.6987
62.255762753, 96.390, 1177.0, 34.3074
62.308283884, 96.390, 1106.0, 33.2566
62.360805015, 96.390, 994.0, 31.5278
62.413326145, 96.390, 893.0, 29.8831
62.465847276, 96.390, 820.0, 28.6356
62.518368407, 96.390, 784.0, 28.0000
62.570889537, 96.390, 800.0, 28.2843
62.623410668, 96.390, 787.0, 28.0535
62.675931799, 96.390, 844.0, 29.0517
62.728452930, 96.390, 825.0, 28.7228
62.780974060, 96.390, 833.0, 28.8617
62.833495191, 96.390, 797.0, 28.2312
62.886016322, 96.390, 693.0, 26.3249
62.938537452, 96.390, 669.0, 25.8650
62.991058583, 96.390, 619.0, 24.8797
63.043579714, 96.390, 575.0, 23.9792
63.096100844, 96.390, 536.0, 23.1517
63.148621975, 96.390, 590.0, 24.2899
63.201143106, 96.390, 547.0, 23.3880
63.253664237, 96.390, 643.0, 25.3574
63.306185367, 96.390, 570.0, 23.8747
63.358706498, 96.390, 634.0, 25.1794
63.411227629, 96.390, 625.0, 25.0000
63.463748759, 96.390, 671.0, 25.9037
63.516269890, 96.390, 697.0, 26.4008
63.568791021, 96.390, 730.0, 27.0185
63.621312152, 96.390, 875.0, 29.5804
63.673833282, 96.390, 986.0, 31.4006
63.726354413, 96.390, 1154.0, 33.9706
63.778875544, 96.390, 1214.0, 34.8425
63.831396674, 96.390, 1229.0, 35.0571
63.883917805, 96.390, 1091.0, 33.0303
63.936438936, 96.390, 1074.0, 32.7719
63.988960067, 96.390, 1030.0, 32.0936
64.041481197, 96.390, 877.0, 29.6142
64.094002328, 96.390, 836.0, 28.9137
64.146523459, 96.390, 868.0, 29.4618
64.199044589, 96.390, 986.0, 31.4006
64.251565720, 96.390, 997.0, 31.5753
64.304086851, 96.390, 993.0, 31.5119
64.356607981, 96.390, 937.0, 30.6105
64.409129112, 96.390, 894.0, 29.8998
64.461650243, 96.390, 834.0, 28.8791
64.514171374, 96.390, 762.0, 27.6043
64.566692504, 96.390, 637.0, 25.2389
64.619213635, 96.390, 602.0, 24.5357
64.671734766, 96.390, 601.0, 24.5153
64.724255896, 96.390, 589.0, 24.2693
64.776777027, 96.390, 644.0, 25.3772
64.829298158, 96.390, 603.0, 24.5561
64.881819289, 96.390, 603.0, 24.5561
64.934340419, 96.390, 547.0, 23.3880
64.986861550, 96.390, 604.0, 24.5764