File: Files_organized_for_plots/Constant_NaOH_1mL10M_to_1gPC_28Day_repeat/MgAxial24Jan22_Act12Feb23_B1_0714M_NaOH_LS0173_Num154.csv
[Measurement conditions],,,
Sample identification,MgAxial24Jan22_Act12Feb23_B1_0714M_NaOH_LS0173_Num154,,
Comment - 2,"Configuration=Stage for Flat Samples/Holders, Owner=nmw10, Creation date=9/21/2022 10:06:30 AM",,
Comment - 3,Goniometer=Theta/Theta; Minimum step size 2Theta:0.0001; Minimum step size Omega:0.0001,,
Comment - 4,Sample stage=Stage for flat samples/holders,,
Comment - 5,Diffractometer system=EMPYREAN,,
Comment - 6,"Measurement program=X:\XRD\Cement\Zerobackground scan.xrdmp, Created identifier={98A3B11C-88F9-4AA6-982C-73314A311EF5}, Created by=Titus Reed, Id=tmr79, Creation date=10/26/2021 3:01:47 PM",,
Anode material,Cu,,
K-Alpha1 wavelength,1.540598,,
K-Alpha2 wavelength,1.544426,,
Ratio K-Alpha2/K-Alpha1,0.5,,
Divergence slit,Fixed,0.25,
Monochromator used,NO,,
Generator voltage,45,,
Tube current,40,,
File date and time,3/15/2023 19:20,,
Unit cell,,,
h k l, 0 0 0,,
Scan axis,Gonio,,
Scan range,4.994599997,64.99999183,
Scan step size,0.0262606,,
No. of points,2285,,
Scan type,CONTINUOUS,,
Time per step,96.39,,
[Scan points],,,
Angle, TimePerStep, Intensity, ESD
5.00773028,96.39,4178,64.6375
5.060251411,96.39,4215,64.923
5.112772541,96.39,4247,65.169
5.165293672,96.39,4156,64.467
5.217814803,96.39,4144,64.3739
5.270335934,96.39,4015,63.364
5.322857064,96.39,4019,63.3956
5.375378195,96.39,3921,62.6179
5.427899326,96.39,3885,62.3298
5.480420456,96.39,3907,62.506
5.532941587,96.39,3884,62.3217
5.585462718,96.39,3837,61.9435
5.637983849,96.39,3778,61.4654
5.690504979,96.39,3839,61.9597
5.74302611,96.39,3731,61.0819
5.795547241,96.39,3712,60.9262
5.848068371,96.39,3779,61.4736
5.900589502,96.39,3873,62.2334
5.953110633,96.39,3644,60.3656
6.005631763,96.39,3701,60.8358
6.058152894,96.39,3653,60.4401
6.110674025,96.39,3553,59.607
6.163195156,96.39,3786,61.5305
6.215716286,96.39,3657,60.4731
6.268237417,96.39,3675,60.6218
6.320758548,96.39,3578,59.8164
6.373279678,96.39,3571,59.7578
6.425800809,96.39,3710,60.9098
6.47832194,96.39,3551,59.5903
6.530843071,96.39,3485,59.0339
6.583364201,96.39,3538,59.4811
6.635885332,96.39,3482,59.0085
6.688406463,96.39,3566,59.716
6.740927593,96.39,3443,58.6771
6.793448724,96.39,3494,59.1101
6.845969855,96.39,3412,58.4123
6.898490986,96.39,3384,58.1722
6.951012116,96.39,3523,59.3549
7.003533247,96.39,3477,58.9661
7.056054378,96.39,3358,57.9483
7.108575508,96.39,3471,58.9152
7.161096639,96.39,3464,58.8558
7.21361777,96.39,3363,57.9914
7.2661389,96.39,3443,58.6771
7.318660031,96.39,3379,58.1292
7.371181162,96.39,3538,59.4811
7.423702293,96.39,3402,58.3267
7.476223423,96.39,3250,57.0088
7.528744554,96.39,3354,57.9137
7.581265685,96.39,3506,59.2115
7.633786815,96.39,3462,58.8388
7.686307946,96.39,3235,56.8771
7.738829077,96.39,3300,57.4456
7.791350208,96.39,3355,57.9224
7.843871338,96.39,3404,58.3438
7.896392469,96.39,3431,58.5747
7.9489136,96.39,3417,58.4551
8.00143473,96.39,3332,57.7235
8.053955861,96.39,3456,58.7878
8.106476992,96.39,3584,59.8665
8.158998123,96.39,3648,60.3987
8.211519253,96.39,3300,57.4456
8.264040384,96.39,3223,56.7715
8.316561515,96.39,3296,57.4108
8.369082645,96.39,3295,57.4021
8.421603776,96.39,3201,56.5774
8.474124907,96.39,3317,57.5934
8.526646038,96.39,3349,57.8705
8.579167168,96.39,3241,56.9298
8.631688299,96.39,3324,57.6541
8.68420943,96.39,3219,56.7362
8.73673056,96.39,3292,57.376
8.789251691,96.39,3300,57.4456
8.841772822,96.39,3238,56.9034
8.894293952,96.39,3317,57.5934
8.946815083,96.39,3342,57.81
8.999336214,96.39,3213,56.6833
9.051857345,96.39,3270,57.1839
9.104378475,96.39,3341,57.8014
9.156899606,96.39,3374,58.0861
9.209420737,96.39,3461,58.8303
9.261941867,96.39,3396,58.2752
9.314462998,96.39,3342,57.81
9.366984129,96.39,3387,58.1979
9.41950526,96.39,3459,58.8133
9.47202639,96.39,3516,59.2959
9.524547521,96.39,3400,58.3095
9.577068652,96.39,3481,59
9.629589782,96.39,3516,59.2959
9.682110913,96.39,3462,58.8388
9.734632044,96.39,3637,60.3075
9.787153175,96.39,3648,60.3987
9.839674305,96.39,3678,60.6465
9.892195436,96.39,3560,59.6657
9.944716567,96.39,3650,60.4152
9.997237697,96.39,3670,60.5805
10.04975883,96.39,3803,61.6685
10.10227996,96.39,3637,60.3075
10.15480109,96.39,3784,61.5142
10.20732222,96.39,3788,61.5467
10.25984335,96.39,3783,61.5061
10.31236448,96.39,3871,62.2174
10.36488561,96.39,3910,62.53
10.41740674,96.39,3927,62.6658
10.46992787,96.39,4010,63.3246
10.522449,96.39,3924,62.6418
10.57497014,96.39,3982,63.1031
10.62749127,96.39,3991,63.1744
10.6800124,96.39,4024,63.435
10.73253353,96.39,4028,63.4665
10.78505466,96.39,4084,63.9062
10.83757579,96.39,4102,64.0469
10.89009692,96.39,4192,64.7457
10.94261805,96.39,4098,64.0156
10.99513918,96.39,4218,64.9461
11.04766031,96.39,4193,64.7534
11.10018144,96.39,4135,64.304
11.15270257,96.39,4250,65.192
11.2052237,96.39,4131,64.2729
11.25774483,96.39,4233,65.0615
11.31026597,96.39,4237,65.0922
11.3627871,96.39,4166,64.5446
11.41530823,96.39,4091,63.9609
11.46782936,96.39,4170,64.5755
11.52035049,96.39,3982,63.1031
11.57287162,96.39,4025,63.4429
11.62539275,96.39,3924,62.6418
11.67791388,96.39,3872,62.2254
11.73043501,96.39,3858,62.1128
11.78295614,96.39,3749,61.2291
11.83547727,96.39,3738,61.1392
11.8879984,96.39,3727,61.0492
11.94051953,96.39,3598,59.9833
11.99304066,96.39,3630,60.2495
12.0455618,96.39,3532,59.4306
12.09808293,96.39,3586,59.8832
12.15060406,96.39,3483,59.0169
12.20312519,96.39,3391,58.2323
12.25564632,96.39,3330,57.7062
12.30816745,96.39,3285,57.3149
12.36068858,96.39,3224,56.7803
12.41320971,96.39,3181,56.4004
12.46573084,96.39,3187,56.4535
12.51825197,96.39,3176,56.356
12.5707731,96.39,3032,55.0636
12.62329423,96.39,2978,54.5711
12.67581536,96.39,3038,55.1181
12.72833649,96.39,2928,54.111
12.78085763,96.39,2904,53.8888
12.83337876,96.39,2949,54.3047
12.88589989,96.39,2989,54.6717
12.93842102,96.39,2820,53.1037
12.99094215,96.39,2739,52.3355
13.04346328,96.39,2788,52.8015
13.09598441,96.39,2749,52.4309
13.14850554,96.39,2669,51.6624
13.20102667,96.39,2690,51.8652
13.2535478,96.39,2662,51.5946
13.30606893,96.39,2522,50.2195
13.35859006,96.39,2592,50.9117
13.41111119,96.39,2641,51.3907
13.46363232,96.39,2524,50.2394
13.51615346,96.39,2505,50.05
13.56867459,96.39,2535,50.3488
13.62119572,96.39,2440,49.3964
13.67371685,96.39,2453,49.5278
13.72623798,96.39,2576,50.7543
13.77875911,96.39,2500,50
13.83128024,96.39,2492,49.9199
13.88380137,96.39,2371,48.6929
13.9363225,96.39,2319,48.156
13.98884363,96.39,2349,48.4665
14.04136476,96.39,2316,48.1248
14.09388589,96.39,2386,48.8467
14.14640702,96.39,2298,47.9375
14.19892815,96.39,2325,48.2183
14.25144929,96.39,2439,49.3862
14.30397042,96.39,2425,49.2443
14.35649155,96.39,2371,48.6929
14.40901268,96.39,2459,49.5883
14.46153381,96.39,2753,52.469
14.51405494,96.39,3109,55.7584
14.56657607,96.39,2854,53.4228
14.6190972,96.39,2328,48.2494
14.67161833,96.39,2193,46.8295
14.72413946,96.39,2173,46.6154
14.77666059,96.39,2089,45.7056
14.82918172,96.39,2049,45.2659
14.88170285,96.39,2090,45.7165
14.93422398,96.39,2136,46.2169
14.98674512,96.39,2200,46.9042
15.03926625,96.39,2193,46.8295
15.09178738,96.39,2318,48.1456
15.14430851,96.39,2405,49.0408
15.19682964,96.39,2631,51.2933
15.24935077,96.39,2477,49.7695
15.3018719,96.39,2349,48.4665
15.35439303,96.39,2093,45.7493
15.40691416,96.39,2075,45.5522
15.45943529,96.39,2049,45.2659
15.51195642,96.39,2008,44.8107
15.56447755,96.39,2016,44.8999
15.61699868,96.39,2029,45.0444
15.66951981,96.39,2103,45.8585
15.72204095,96.39,2163,46.5081
15.77456208,96.39,2064,45.4313
15.82708321,96.39,2008,44.8107
15.87960434,96.39,1962,44.2945
15.93212547,96.39,1957,44.238
15.9846466,96.39,1986,44.5646
16.03716773,96.39,1966,44.3396
16.08968886,96.39,1972,44.4072
16.14220999,96.39,2038,45.1442
16.19473112,96.39,2055,45.3321
16.24725225,96.39,2319,48.156
16.29977338,96.39,2793,52.8488
16.35229451,96.39,2521,50.2096
16.40481564,96.39,2076,45.5631
16.45733678,96.39,2017,44.911
16.50985791,96.39,1930,43.9318
16.56237904,96.39,1847,42.9767
16.61490017,96.39,1846,42.9651
16.6674213,96.39,1914,43.7493
16.71994243,96.39,1825,42.72
16.77246356,96.39,1951,44.1701
16.82498469,96.39,1929,43.9204
16.87750582,96.39,1934,43.9773
16.93002695,96.39,2001,44.7325
16.98254808,96.39,1922,43.8406
17.03506921,96.39,1807,42.5088
17.08759034,96.39,1894,43.5201
17.14011147,96.39,1793,42.3438
17.19263261,96.39,1805,42.4853
17.24515374,96.39,1791,42.3202
17.29767487,96.39,1780,42.19
17.350196,96.39,1830,42.7785
17.40271713,96.39,1851,43.0232
17.45523826,96.39,1755,41.8927
17.50775939,96.39,1750,41.833
17.56028052,96.39,1816,42.6146
17.61280165,96.39,1797,42.391
17.66532278,96.39,1788,42.2847
17.71784391,96.39,1756,41.9047
17.77036504,96.39,1769,42.0595
17.82288617,96.39,1768,42.0476
17.8754073,96.39,1829,42.7668
17.92792843,96.39,1816,42.6146
17.98044957,96.39,1792,42.332
18.0329707,96.39,1860,43.1277
18.08549183,96.39,1841,42.9069
18.13801296,96.39,1883,43.3935
18.19053409,96.39,1871,43.2551
18.24305522,96.39,1882,43.382
18.29557635,96.39,1991,44.6206
18.34809748,96.39,2017,44.911
18.40061861,96.39,1888,43.4511
18.45313974,96.39,1870,43.2435
18.50566087,96.39,1805,42.4853
18.558182,96.39,1823,42.6966
18.61070313,96.39,1769,42.0595
18.66322426,96.39,1801,42.4382
18.7157454,96.39,1888,43.4511
18.76826653,96.39,2139,46.2493
18.82078766,96.39,2359,48.5695
18.87330879,96.39,2695,51.9134
18.92582992,96.39,2783,52.7541
18.97835105,96.39,2603,51.0196
19.03087218,96.39,2226,47.1805
19.08339331,96.39,2061,45.3982
19.13591444,96.39,2027,45.0222
19.18843557,96.39,1849,43
19.2409567,96.39,1964,44.317
19.29347783,96.39,1884,43.4051
19.34599896,96.39,2012,44.8553
19.39852009,96.39,1903,43.6234
19.45104123,96.39,1971,44.3959
19.50356236,96.39,1937,44.0114
19.55608349,96.39,1888,43.4511
19.60860462,96.39,1828,42.7551
19.66112575,96.39,1813,42.5793
19.71364688,96.39,1962,44.2945
19.76616801,96.39,2092,45.7384
19.81868914,96.39,2122,46.0652
19.87121027,96.39,1916,43.7721
19.9237314,96.39,1849,43
19.97625253,96.39,1776,42.1426
20.02877366,96.39,1912,43.7264
20.08129479,96.39,1916,43.7721
20.13381592,96.39,1857,43.0929
20.18633706,96.39,1909,43.6921
20.23885819,96.39,2008,44.8107
20.29137932,96.39,2021,44.9555
20.34390045,96.39,2088,45.6946
20.39642158,96.39,2293,47.8853
20.44894271,96.39,2222,47.1381
20.50146384,96.39,2190,46.7974
20.55398497,96.39,2138,46.2385
20.6065061,96.39,2409,49.0816
20.65902723,96.39,2452,49.5177
20.71154836,96.39,2491,49.9099
20.76406949,96.39,2284,47.7912
20.81659062,96.39,2176,46.6476
20.86911175,96.39,2081,45.618
20.92163289,96.39,2031,45.0666
20.97415402,96.39,2033,45.0888
21.02667515,96.39,2053,45.31
21.07919628,96.39,1920,43.8178
21.13171741,96.39,2061,45.3982
21.18423854,96.39,2098,45.8039
21.23675967,96.39,2263,47.571
21.2892808,96.39,2358,48.5592
21.34180193,96.39,2337,48.3425
21.39432306,96.39,2289,47.8435
21.44684419,96.39,2192,46.8188
21.49936532,96.39,2370,48.6826
21.55188645,96.39,2442,49.4166
21.60440758,96.39,2807,52.9811
21.65692872,96.39,2742,52.3641
21.70944985,96.39,2433,49.3254
21.76197098,96.39,2223,47.1487
21.81449211,96.39,2160,46.4758
21.86701324,96.39,2101,45.8367
21.91953437,96.39,2236,47.2864
21.9720555,96.39,2162,46.4973
22.02457663,96.39,2313,48.0937
22.07709776,96.39,2287,47.8226
22.12961889,96.39,2367,48.6518
22.18214002,96.39,2404,49.0306
22.23466115,96.39,2312,48.0833
22.28718228,96.39,2480,49.7996
22.33970341,96.39,2509,50.0899
22.39222455,96.39,2482,49.8197
22.44474568,96.39,2478,49.7795
22.49726681,96.39,2531,50.309
22.54978794,96.39,2550,50.4975
22.60230907,96.39,2522,50.2195
22.6548302,96.39,2534,50.3389
22.70735133,96.39,2696,51.923
22.75987246,96.39,2759,52.5262
22.81239359,96.39,2927,54.1018
22.86491472,96.39,2955,54.3599
22.91743585,96.39,2896,53.8145
22.96995698,96.39,2860,53.479
23.02247811,96.39,2817,53.0754
23.07499924,96.39,2935,54.1756
23.12752038,96.39,3224,56.7803
23.18004151,96.39,3327,57.6802
23.23256264,96.39,3108,55.7494
23.28508377,96.39,2760,52.5357
23.3376049,96.39,2839,53.2823
23.39012603,96.39,2857,53.4509
23.44264716,96.39,2523,50.2295
23.49516829,96.39,2402,49.0102
23.54768942,96.39,2514,50.1398
23.60021055,96.39,2443,49.4267
23.65273168,96.39,2257,47.5079
23.70525281,96.39,2099,45.8148
23.75777394,96.39,2186,46.7547
23.81029507,96.39,2195,46.8508
23.86281621,96.39,2135,46.2061
23.91533734,96.39,2105,45.8803
23.96785847,96.39,2041,45.1774
24.0203796,96.39,1969,44.3734
24.07290073,96.39,2001,44.7325
24.12542186,96.39,1975,44.441
24.17794299,96.39,1970,44.3847
24.23046412,96.39,2040,45.1664
24.28298525,96.39,2043,45.1996
24.33550638,96.39,1911,43.715
24.38802751,96.39,1846,42.9651
24.44054864,96.39,1796,42.3792
24.49306977,96.39,1875,43.3013
24.5455909,96.39,1798,42.4028
24.59811204,96.39,1959,44.2606
24.65063317,96.39,1849,43
24.7031543,96.39,1732,41.6173
24.75567543,96.39,1811,42.5558
24.80819656,96.39,1809,42.5323
24.86071769,96.39,1841,42.9069
24.91323882,96.39,1716,41.4246
24.96575995,96.39,1641,40.5093
25.01828108,96.39,1747,41.7971
25.07080221,96.39,1659,40.7308
25.12332334,96.39,1608,40.0999
25.17584447,96.39,1635,40.4351
25.2283656,96.39,1732,41.6173
25.28088673,96.39,1684,41.0366
25.33340786,96.39,1694,41.1582
25.385929,96.39,1706,41.3038
25.43845013,96.39,1671,40.8779
25.49097126,96.39,1704,41.2795
25.54349239,96.39,1656,40.694
25.59601352,96.39,1647,40.5832
25.64853465,96.39,1660,40.7431
25.70105578,96.39,1676,40.939
25.75357691,96.39,1677,40.9512
25.80609804,96.39,1595,39.9375
25.85861917,96.39,1727,41.5572
25.9111403,96.39,1790,42.3084
25.96366143,96.39,1799,42.4146
26.01618256,96.39,1748,41.8091
26.06870369,96.39,1744,41.7612
26.12122483,96.39,1741,41.7253
26.17374596,96.39,1570,39.6232
26.22626709,96.39,1574,39.6737
26.27878822,96.39,1587,39.8372
26.33130935,96.39,1635,40.4351
26.38383048,96.39,1647,40.5832
26.43635161,96.39,1662,40.7676
26.48887274,96.39,1654,40.6694
26.54139387,96.39,1744,41.7612
26.593915,96.39,1658,40.7185
26.64643613,96.39,1767,42.0357
26.69895726,96.39,1974,44.4297
26.75147839,96.39,2282,47.7703
26.80399952,96.39,2491,49.9099
26.85652066,96.39,2269,47.634
26.90904179,96.39,2150,46.3681
26.96156292,96.39,2236,47.2864
27.01408405,96.39,2527,50.2693
27.06660518,96.39,2525,50.2494
27.11912631,96.39,2588,50.8724
27.17164744,96.39,2855,53.4322
27.22416857,96.39,2616,51.1468
27.2766897,96.39,2271,47.655
27.32921083,96.39,1936,44
27.38173196,96.39,1921,43.8292
27.43425309,96.39,1813,42.5793
27.48677422,96.39,1700,41.2311
27.53929535,96.39,1659,40.7308
27.59181649,96.39,1752,41.8569
27.64433762,96.39,1679,40.9756
27.69685875,96.39,1721,41.4849
27.74937988,96.39,1668,40.8412
27.80190101,96.39,1635,40.4351
27.85442214,96.39,1699,41.2189
27.90694327,96.39,1622,40.2741
27.9594644,96.39,1707,41.3159
28.01198553,96.39,1665,40.8044
28.06450666,96.39,1766,42.0238
28.11702779,96.39,1623,40.2865
28.16954892,96.39,1710,41.3521
28.22207005,96.39,1694,41.1582
28.27459118,96.39,1686,41.0609
28.32711232,96.39,1737,41.6773
28.37963345,96.39,1855,43.0697
28.43215458,96.39,1777,42.1545
28.48467571,96.39,1761,41.9643
28.53719684,96.39,1818,42.638
28.58971797,96.39,1685,41.0488
28.6422391,96.39,1675,40.9268
28.69476023,96.39,1659,40.7308
28.74728136,96.39,1687,41.0731
28.79980249,96.39,1682,41.0122
28.85232362,96.39,1761,41.9643
28.90484475,96.39,1703,41.2674
28.95736588,96.39,1795,42.3674
29.00988701,96.39,1691,41.1218
29.06240815,96.39,1845,42.9535
29.11492928,96.39,2014,44.8776
29.16745041,96.39,2120,46.0435
29.21997154,96.39,2272,47.6655
29.27249267,96.39,2672,51.6914
29.3250138,96.39,2716,52.1153
29.37753493,96.39,2478,49.7795
29.43005606,96.39,2378,48.7647
29.48257719,96.39,2489,49.8899
29.53509832,96.39,2356,48.5386
29.58761945,96.39,2071,45.5082
29.64014058,96.39,1954,44.2041
29.69266171,96.39,1874,43.2897
29.74518284,96.39,1844,42.9418
29.79770398,96.39,1816,42.6146
29.85022511,96.39,1697,41.1947
29.90274624,96.39,1782,42.2137
29.95526737,96.39,1710,41.3521
30.0077885,96.39,1804,42.4735
30.06030963,96.39,1612,40.1497
30.11283076,96.39,1612,40.1497
30.16535189,96.39,1666,40.8167
30.21787302,96.39,1579,39.7366
30.27039415,96.39,1656,40.694
30.32291528,96.39,1572,39.6485
30.37543641,96.39,1588,39.8497
30.42795754,96.39,1684,41.0366
30.48047867,96.39,1760,41.9524
30.53299981,96.39,1731,41.6053
30.58552094,96.39,1764,42
30.63804207,96.39,1858,43.1045
30.6905632,96.39,1955,44.2154
30.74308433,96.39,1999,44.7102
30.79560546,96.39,1917,43.7836
30.84812659,96.39,1955,44.2154
30.90064772,96.39,1749,41.821
30.95316885,96.39,1786,42.2611
31.00568998,96.39,1687,41.0731
31.05821111,96.39,1761,41.9643
31.11073224,96.39,1780,42.19
31.16325337,96.39,1894,43.5201
31.2157745,96.39,2234,47.2652
31.26829564,96.39,2425,49.2443
31.32081677,96.39,2455,49.548
31.3733379,96.39,2461,49.6085
31.42585903,96.39,2114,45.9783
31.47838016,96.39,1968,44.3621
31.53090129,96.39,1847,42.9767
31.58342242,96.39,1710,41.3521
31.63594355,96.39,1750,41.833
31.68846468,96.39,1752,41.8569
31.74098581,96.39,1836,42.8486
31.79350694,96.39,1751,41.845
31.84602807,96.39,1802,42.45
31.8985492,96.39,1978,44.4747
31.95107033,96.39,1979,44.486
32.00359147,96.39,2061,45.3982
32.0561126,96.39,2075,45.5522
32.10863373,96.39,2041,45.1774
32.16115486,96.39,2221,47.1275
32.21367599,96.39,2303,47.9896
32.26619712,96.39,2553,50.5272
32.31871825,96.39,2270,47.6445
32.37123938,96.39,2151,46.3789
32.42376051,96.39,1746,41.7852
32.47628164,96.39,1732,41.6173
32.52880277,96.39,1666,40.8167
32.5813239,96.39,1699,41.2189
32.63384503,96.39,1764,42
32.68636616,96.39,1851,43.0232
32.7388873,96.39,1771,42.0833
32.79140843,96.39,1817,42.6263
32.84392956,96.39,1827,42.7434
32.89645069,96.39,1785,42.2493
32.94897182,96.39,1994,44.6542
33.00149295,96.39,1958,44.2493
33.05401408,96.39,2005,44.7772
33.10653521,96.39,1922,43.8406
33.15905634,96.39,1954,44.2041
33.21157747,96.39,1901,43.6005
33.2640986,96.39,1889,43.4626
33.31661973,96.39,1927,43.8976
33.36914086,96.39,2037,45.1331
33.42166199,96.39,2073,45.5302
33.47418312,96.39,1985,44.5533
33.52670426,96.39,1902,43.6119
33.57922539,96.39,1923,43.852
33.63174652,96.39,1948,44.1362
33.68426765,96.39,1972,44.4072
33.73678878,96.39,1956,44.2267
33.78930991,96.39,1957,44.238
33.84183104,96.39,1926,43.8862
33.89435217,96.39,2112,45.9565
33.9468733,96.39,2149,46.3573
33.99939443,96.39,2204,46.9468
34.05191556,96.39,2337,48.3425
34.10443669,96.39,2288,47.833
34.15695782,96.39,2346,48.4355
34.20947895,96.39,2386,48.8467
34.26200009,96.39,2384,48.8262
34.31452122,96.39,2476,49.7594
34.36704235,96.39,2491,49.9099
34.41956348,96.39,2707,52.0288
34.47208461,96.39,2908,53.9259
34.52460574,96.39,3125,55.9017
34.57712687,96.39,3328,57.6888
34.629648,96.39,2934,54.1664
34.68216913,96.39,2766,52.5928
34.73469026,96.39,2558,50.5767
34.78721139,96.39,2366,48.6415
34.83973252,96.39,2436,49.3559
34.89225365,96.39,2375,48.734
34.94477478,96.39,2499,49.99
34.99729592,96.39,2554,50.5371
35.04981705,96.39,2496,49.96
35.10233818,96.39,2440,49.3964
35.15485931,96.39,2434,49.3356
35.20738044,96.39,2360,48.5798
35.25990157,96.39,2260,47.5395
35.3124227,96.39,2136,46.2169
35.36494383,96.39,2009,44.8219
35.41746496,96.39,1939,44.0341
35.46998609,96.39,1866,43.1972
35.52250722,96.39,1911,43.715
35.57502835,96.39,1881,43.3705
35.62754948,96.39,1866,43.1972
35.68007061,96.39,1892,43.4971
35.73259175,96.39,1928,43.909
35.78511288,96.39,1990,44.6094
35.83763401,96.39,2014,44.8776
35.89015514,96.39,2204,46.9468
35.94267627,96.39,2399,48.9796
35.9951974,96.39,2314,48.1041
36.04771853,96.39,2246,47.392
36.10023966,96.39,2305,48.0104
36.15276079,96.39,2586,50.8527
36.20528192,96.39,2676,51.7301
36.25780305,96.39,2404,49.0306
36.31032418,96.39,2153,46.4004
36.36284531,96.39,1718,41.4488
36.41536644,96.39,1811,42.5558
36.46788758,96.39,1686,41.0609
36.52040871,96.39,1685,41.0488
36.57292984,96.39,1695,41.1704
36.62545097,96.39,1634,40.4228
36.6779721,96.39,1532,39.1408
36.73049323,96.39,1585,39.8121
36.78301436,96.39,1550,39.37
36.83553549,96.39,1404,37.47
36.88805662,96.39,1455,38.1445
36.94057775,96.39,1504,38.7814
36.99309888,96.39,1503,38.7685
37.04562001,96.39,1509,38.8458
37.09814114,96.39,1512,38.8844
37.15066227,96.39,1578,39.724
37.20318341,96.39,1659,40.7308
37.25570454,96.39,1570,39.6232
37.30822567,96.39,1584,39.7995
37.3607468,96.39,1610,40.1248
37.41326793,96.39,1639,40.4846
37.46578906,96.39,1778,42.1663
37.51831019,96.39,1714,41.4005
37.57083132,96.39,1742,41.7373
37.62335245,96.39,1738,41.6893
37.67587358,96.39,1700,41.2311
37.72839471,96.39,1744,41.7612
37.78091584,96.39,1929,43.9204
37.83343697,96.39,2091,45.7275
37.8859581,96.39,2012,44.8553
37.93847924,96.39,1889,43.4626
37.99100037,96.39,1787,42.2729
38.0435215,96.39,1707,41.3159
38.09604263,96.39,1636,40.4475
38.14856376,96.39,1638,40.4722
38.20108489,96.39,1673,40.9023
38.25360602,96.39,1641,40.5093
38.30612715,96.39,1621,40.2616
38.35864828,96.39,1499,38.7169
38.41116941,96.39,1543,39.281
38.46369054,96.39,1480,38.4708
38.51621167,96.39,1464,38.2623
38.5687328,96.39,1515,38.923
38.62125393,96.39,1579,39.7366
38.67377507,96.39,1392,37.3095
38.7262962,96.39,1480,38.4708
38.77881733,96.39,1463,38.2492
38.83133846,96.39,1484,38.5227
38.88385959,96.39,1497,38.6911
38.93638072,96.39,1384,37.2022
38.98890185,96.39,1450,38.0789
39.04142298,96.39,1407,37.51
39.09394411,96.39,1512,38.8844
39.14646524,96.39,1515,38.923
39.19898637,96.39,1571,39.6358
39.2515075,96.39,1532,39.1408
39.30402863,96.39,1497,38.6911
39.35654976,96.39,1459,38.1969
39.4090709,96.39,1415,37.6165
39.46159203,96.39,1372,37.0405
39.51411316,96.39,1456,38.1576
39.56663429,96.39,1431,37.8286
39.61915542,96.39,1369,37
39.67167655,96.39,1420,37.6829
39.72419768,96.39,1478,38.4448
39.77671881,96.39,1382,37.1753
39.82923994,96.39,1436,37.8946
39.88176107,96.39,1448,38.0526
39.9342822,96.39,1394,37.3363
39.98680333,96.39,1392,37.3095
40.03932446,96.39,1343,36.647
40.09184559,96.39,1361,36.8917
40.14436673,96.39,1394,37.3363
40.19688786,96.39,1245,35.2846
40.24940899,96.39,1274,35.6931
40.30193012,96.39,1272,35.6651
40.35445125,96.39,1221,34.9428
40.40697238,96.39,1271,35.6511
40.45949351,96.39,1275,35.7071
40.51201464,96.39,1239,35.1994
40.56453577,96.39,1292,35.9444
40.6170569,96.39,1274,35.6931
40.66957803,96.39,1279,35.7631
40.72209916,96.39,1315,36.2629
40.77462029,96.39,1262,35.5246
40.82714142,96.39,1225,35
40.87966255,96.39,1158,34.0294
40.93218369,96.39,1241,35.2278
40.98470482,96.39,1174,34.2637
41.03722595,96.39,1178,34.322
41.08974708,96.39,1223,34.9714
41.14226821,96.39,1169,34.1906
41.19478934,96.39,1190,34.4964
41.24731047,96.39,1197,34.5977
41.2998316,96.39,1188,34.4674
41.35235273,96.39,1137,33.7194
41.40487386,96.39,1143,33.8083
41.45739499,96.39,1160,34.0588
41.50991612,96.39,1135,33.6898
41.56243725,96.39,1185,34.4238
41.61495838,96.39,1232,35.0999
41.66747952,96.39,1226,35.0143
41.72000065,96.39,1212,34.8138
41.77252178,96.39,1230,35.0714
41.82504291,96.39,1178,34.322
41.87756404,96.39,1140,33.7639
41.93008517,96.39,1125,33.541
41.9826063,96.39,1165,34.1321
42.03512743,96.39,1294,35.9722
42.08764856,96.39,1480,38.4708
42.14016969,96.39,1652,40.6448
42.19269082,96.39,1559,39.4842
42.24521195,96.39,1458,38.1838
42.29773308,96.39,1337,36.565
42.35025421,96.39,1181,34.3657
42.40277535,96.39,1113,33.3617
42.45529648,96.39,1139,33.7491
42.50781761,96.39,1009,31.7648
42.56033874,96.39,1060,32.5576
42.61285987,96.39,1116,33.4066
42.665381,96.39,1043,32.2955
42.71790213,96.39,1140,33.7639
42.77042326,96.39,1183,34.3948
42.82294439,96.39,1111,33.3317
42.87546552,96.39,1124,33.5261
42.92798665,96.39,971,31.1609
42.98050778,96.39,992,31.496
43.03302891,96.39,1083,32.909
43.08555004,96.39,1050,32.4037
43.13807118,96.39,1103,33.2114
43.19059231,96.39,1051,32.4191
43.24311344,96.39,1073,32.7567
43.29563457,96.39,1027,32.0468
43.3481557,96.39,987,31.4166
43.40067683,96.39,1028,32.0624
43.45319796,96.39,1023,31.9844
43.50571909,96.39,1082,32.8938
43.55824022,96.39,1020,31.9374
43.61076135,96.39,975,31.225
43.66328248,96.39,955,30.9031
43.71580361,96.39,1043,32.2955
43.76832474,96.39,1065,32.6343
43.82084587,96.39,1104,33.2265
43.87336701,96.39,1103,33.2114
43.92588814,96.39,1022,31.9687
43.97840927,96.39,1041,32.2645
44.0309304,96.39,1075,32.7872
44.08345153,96.39,1002,31.6544
44.13597266,96.39,1073,32.7567
44.18849379,96.39,1081,32.8786
44.24101492,96.39,1096,33.1059
44.29353605,96.39,1076,32.8024
44.34605718,96.39,1183,34.3948
44.39857831,96.39,1091,33.0303
44.45109944,96.39,1108,33.2866
44.50362057,96.39,1008,31.749
44.5561417,96.39,1087,32.9697
44.60866284,96.39,1142,33.7935
44.66118397,96.39,1107,33.2716
44.7137051,96.39,1131,33.6303
44.76622623,96.39,1097,33.121
44.81874736,96.39,1201,34.6554
44.87126849,96.39,1175,34.2783
44.92378962,96.39,1126,33.5559
44.97631075,96.39,1143,33.8083
45.02883188,96.39,1150,33.9116
45.08135301,96.39,1081,32.8786
45.13387414,96.39,1171,34.2199
45.18639527,96.39,1130,33.6155
45.2389164,96.39,1109,33.3017
45.29143753,96.39,1093,33.0606
45.34395867,96.39,1103,33.2114
45.3964798,96.39,1058,32.5269
45.44900093,96.39,1086,32.9545
45.50152206,96.39,1142,33.7935
45.55404319,96.39,1104,33.2265
45.60656432,96.39,1114,33.3766
45.65908545,96.39,1124,33.5261
45.71160658,96.39,1112,33.3467
45.76412771,96.39,1081,32.8786
45.81664884,96.39,1128,33.5857
45.86916997,96.39,1124,33.5261
45.9216911,96.39,1081,32.8786
45.97421223,96.39,1134,33.6749
46.02673336,96.39,1073,32.7567
46.0792545,96.39,1170,34.2053
46.13177563,96.39,1266,35.5809
46.18429676,96.39,1357,36.8375
46.23681789,96.39,1370,37.0135
46.28933902,96.39,1358,36.8511
46.34186015,96.39,1294,35.9722
46.39438128,96.39,1257,35.4542
46.44690241,96.39,1208,34.7563
46.49942354,96.39,1201,34.6554
46.55194467,96.39,1166,34.1467
46.6044658,96.39,1070,32.7109
46.65698693,96.39,1200,34.641
46.70950806,96.39,1208,34.7563
46.76202919,96.39,1163,34.1028
46.81455033,96.39,1113,33.3617
46.86707146,96.39,1147,33.8674
46.91959259,96.39,1061,32.573
46.97211372,96.39,1035,32.1714
47.02463485,96.39,1051,32.4191
47.07715598,96.39,1058,32.5269
47.12967711,96.39,1090,33.0151
47.18219824,96.39,1114,33.3766
47.23471937,96.39,1113,33.3617
47.2872405,96.39,1147,33.8674
47.33976163,96.39,1141,33.7787
47.39228276,96.39,1142,33.7935
47.44480389,96.39,1081,32.8786
47.49732502,96.39,1099,33.1512
47.54984616,96.39,1133,33.6601
47.60236729,96.39,1132,33.6452
47.65488842,96.39,1100,33.1662
47.70740955,96.39,1108,33.2866
47.75993068,96.39,1137,33.7194
47.81245181,96.39,1125,33.541
47.86497294,96.39,1136,33.7046
47.91749407,96.39,1115,33.3916
47.9700152,96.39,1068,32.6803
48.02253633,96.39,1001,31.6386
48.07505746,96.39,1028,32.0624
48.12757859,96.39,1026,32.0312
48.18009972,96.39,980,31.305
48.23262085,96.39,940,30.6594
48.28514198,96.39,1062,32.5883
48.33766312,96.39,1094,33.0757
48.39018425,96.39,1177,34.3074
48.44270538,96.39,1230,35.0714
48.49522651,96.39,1207,34.7419
48.54774764,96.39,1210,34.7851
48.60026877,96.39,1075,32.7872
48.6527899,96.39,1012,31.8119
48.70531103,96.39,960,30.9839
48.75783216,96.39,1006,31.7175
48.81035329,96.39,923,30.3809
48.86287442,96.39,1000,31.6228
48.91539555,96.39,989,31.4484
48.96791668,96.39,933,30.545
49.02043781,96.39,1004,31.686
49.07295895,96.39,1044,32.311
49.12548008,96.39,983,31.3528
49.17800121,96.39,1052,32.4345
49.23052234,96.39,1033,32.1403
49.28304347,96.39,977,31.257
49.3355646,96.39,874,29.5635
49.38808573,96.39,906,30.0998
49.44060686,96.39,927,30.4467
49.49312799,96.39,889,29.8161
49.54564912,96.39,909,30.1496
49.59817025,96.39,969,31.1288
49.65069138,96.39,910,30.1662
49.70321251,96.39,913,30.2159
49.75573364,96.39,968,31.1127
49.80825478,96.39,958,30.9516
49.86077591,96.39,860,29.3258
49.91329704,96.39,913,30.2159
49.96581817,96.39,902,30.0333
50.0183393,96.39,822,28.6705
50.07086043,96.39,812,28.4956
50.12338156,96.39,834,28.8791
50.17590269,96.39,896,29.9333
50.22842382,96.39,918,30.2985
50.28094495,96.39,859,29.3087
50.33346608,96.39,893,29.8831
50.38598721,96.39,905,30.0832
50.43850834,96.39,980,31.305
50.49102947,96.39,1049,32.3883
50.54355061,96.39,976,31.241
50.59607174,96.39,953,30.8707
50.64859287,96.39,888,29.7993
50.701114,96.39,906,30.0998
50.75363513,96.39,913,30.2159
50.80615626,96.39,917,30.282
50.85867739,96.39,912,30.1993
50.91119852,96.39,961,31
50.96371965,96.39,872,29.5296
51.01624078,96.39,937,30.6105
51.06876191,96.39,969,31.1288
51.12128304,96.39,972,31.1769
51.17380417,96.39,898,29.9666
51.2263253,96.39,912,30.1993
51.27884644,96.39,806,28.3901
51.33136757,96.39,840,28.9828
51.3838887,96.39,778,27.8927
51.43640983,96.39,805,28.3725
51.48893096,96.39,717,26.7769
51.54145209,96.39,767,27.6948
51.59397322,96.39,810,28.4605
51.64649435,96.39,806,28.3901
51.69901548,96.39,760,27.5681
51.75153661,96.39,763,27.6225
51.80405774,96.39,825,28.7228
51.85657887,96.39,826,28.7402
51.9091,96.39,817,28.5832
51.96162113,96.39,837,28.931
52.01414227,96.39,794,28.178
52.0666634,96.39,768,27.7128
52.11918453,96.39,798,28.2489
52.17170566,96.39,773,27.8029
52.22422679,96.39,823,28.688
52.27674792,96.39,840,28.9828
52.32926905,96.39,834,28.8791
52.38179018,96.39,746,27.313
52.43431131,96.39,760,27.5681
52.48683244,96.39,785,28.0179
52.53935357,96.39,814,28.5307
52.5918747,96.39,789,28.0891
52.64439583,96.39,768,27.7128
52.69691696,96.39,760,27.5681
52.7494381,96.39,710,26.6458
52.80195923,96.39,775,27.8388
52.85448036,96.39,722,26.8701
52.90700149,96.39,805,28.3725
52.95952262,96.39,746,27.313
53.01204375,96.39,788,28.0713
53.06456488,96.39,819,28.6182
53.11708601,96.39,780,27.9285
53.16960714,96.39,778,27.8927
53.22212827,96.39,772,27.7849
53.2746494,96.39,771,27.7669
53.32717053,96.39,765,27.6586
53.37969166,96.39,790,28.1069
53.43221279,96.39,762,27.6043
53.48473393,96.39,782,27.9643
53.53725506,96.39,818,28.6007
53.58977619,96.39,753,27.4408
53.64229732,96.39,726,26.9444
53.69481845,96.39,761,27.5862
53.74733958,96.39,745,27.2947
53.79986071,96.39,817,28.5832
53.85238184,96.39,831,28.8271
53.90490297,96.39,881,29.6816
53.9574241,96.39,906,30.0998
54.00994523,96.39,872,29.5296
54.06246636,96.39,892,29.8664
54.11498749,96.39,860,29.3258
54.16750862,96.39,794,28.178
54.22002976,96.39,742,27.2397
54.27255089,96.39,855,29.2404
54.32507202,96.39,846,29.0861
54.37759315,96.39,773,27.8029
54.43011428,96.39,786,28.0357
54.48263541,96.39,761,27.5862
54.53515654,96.39,819,28.6182
54.58767767,96.39,712,26.6833
54.6401988,96.39,753,27.4408
54.69271993,96.39,660,25.6905
54.74524106,96.39,690,26.2679
54.79776219,96.39,734,27.0924
54.85028332,96.39,767,27.6948
54.90280445,96.39,693,26.3249
54.95532559,96.39,692,26.3059
55.00784672,96.39,738,27.1662
55.06036785,96.39,685,26.1725
55.11288898,96.39,716,26.7582
55.16541011,96.39,713,26.7021
55.21793124,96.39,693,26.3249
55.27045237,96.39,723,26.8887
55.3229735,96.39,720,26.8328
55.37549463,96.39,703,26.5141
55.42801576,96.39,739,27.1846
55.48053689,96.39,789,28.0891
55.53305802,96.39,730,27.0185
55.58557915,96.39,768,27.7128
55.63810028,96.39,649,25.4755
55.69062141,96.39,697,26.4008
55.74314255,96.39,706,26.5707
55.79566368,96.39,694,26.3439
55.84818481,96.39,712,26.6833
55.90070594,96.39,669,25.865
55.95322707,96.39,778,27.8927
56.0057482,96.39,775,27.8388
56.05826933,96.39,793,28.1603
56.11079046,96.39,806,28.3901
56.16331159,96.39,752,27.4226
56.21583272,96.39,807,28.4077
56.26835385,96.39,688,26.2298
56.32087498,96.39,753,27.4408
56.37339611,96.39,749,27.3679
56.42591724,96.39,743,27.258
56.47843838,96.39,728,26.9815
56.53095951,96.39,746,27.313
56.58348064,96.39,709,26.6271
56.63600177,96.39,706,26.5707
56.6885229,96.39,714,26.7208
56.74104403,96.39,697,26.4008
56.79356516,96.39,639,25.2784
56.84608629,96.39,707,26.5895
56.89860742,96.39,719,26.8142
56.95112855,96.39,738,27.1662
57.00364968,96.39,644,25.3772
57.05617081,96.39,718,26.7955
57.10869194,96.39,756,27.4955
57.16121307,96.39,761,27.5862
57.21373421,96.39,785,28.0179
57.26625534,96.39,806,28.3901
57.31877647,96.39,713,26.7021
57.3712976,96.39,709,26.6271
57.42381873,96.39,725,26.9258
57.47633986,96.39,730,27.0185
57.52886099,96.39,686,26.1916
57.58138212,96.39,757,27.5136
57.63390325,96.39,684,26.1534
57.68642438,96.39,736,27.1293
57.73894551,96.39,706,26.5707
57.79146664,96.39,735,27.1109
57.84398777,96.39,661,25.7099
57.8965089,96.39,767,27.6948
57.94903004,96.39,693,26.3249
58.00155117,96.39,742,27.2397
58.0540723,96.39,652,25.5343
58.10659343,96.39,698,26.4197
58.15911456,96.39,711,26.6646
58.21163569,96.39,690,26.2679
58.26415682,96.39,645,25.3969
58.31667795,96.39,651,25.5147
58.36919908,96.39,673,25.9422
58.42172021,96.39,698,26.4197
58.47424134,96.39,662,25.7294
58.52676247,96.39,668,25.8457
58.5792836,96.39,685,26.1725
58.63180473,96.39,655,25.593
58.68432587,96.39,652,25.5343
58.736847,96.39,669,25.865
58.78936813,96.39,647,25.4362
58.84188926,96.39,648,25.4558
58.89441039,96.39,677,26.0192
58.94693152,96.39,659,25.671
58.99945265,96.39,716,26.7582
59.05197378,96.39,707,26.5895
59.10449491,96.39,659,25.671
59.15701604,96.39,721,26.8514
59.20953717,96.39,721,26.8514
59.2620583,96.39,709,26.6271
59.31457943,96.39,671,25.9037
59.36710056,96.39,717,26.7769
59.4196217,96.39,749,27.3679
59.47214283,96.39,749,27.3679
59.52466396,96.39,747,27.3313
59.57718509,96.39,734,27.0924
59.62970622,96.39,742,27.2397
59.68222735,96.39,760,27.5681
59.73474848,96.39,840,28.9828
59.78726961,96.39,779,27.9106
59.83979074,96.39,778,27.8927
59.89231187,96.39,767,27.6948
59.944833,96.39,782,27.9643
59.99735413,96.39,834,28.8791
60.04987526,96.39,838,28.9482
60.10239639,96.39,874,29.5635
60.15491753,96.39,887,29.7825
60.20743866,96.39,986,31.4006
60.25995979,96.39,975,31.225
60.31248092,96.39,985,31.3847
60.36500205,96.39,1023,31.9844
60.41752318,96.39,1074,32.7719
60.47004431,96.39,1123,33.5112
60.52256544,96.39,1136,33.7046
60.57508657,96.39,1162,34.0881
60.6276077,96.39,1158,34.0294
60.68012883,96.39,1176,34.2929
60.73264996,96.39,1207,34.7419
60.78517109,96.39,1224,34.9857
60.83769222,96.39,1189,34.4819
60.89021336,96.39,1130,33.6155
60.94273449,96.39,1101,33.1813
60.99525562,96.39,1140,33.7639
61.04777675,96.39,1099,33.1512
61.10029788,96.39,1158,34.0294
61.15281901,96.39,1135,33.6898
61.20534014,96.39,1120,33.4664
61.25786127,96.39,1052,32.4345
61.3103824,96.39,1095,33.0908
61.36290353,96.39,1002,31.6544
61.41542466,96.39,965,31.0644
61.46794579,96.39,1010,31.7805
61.52046692,96.39,989,31.4484
61.57298805,96.39,1041,32.2645
61.62550919,96.39,1021,31.9531
61.67803032,96.39,1033,32.1403
61.73055145,96.39,927,30.4467
61.78307258,96.39,982,31.3369
61.83559371,96.39,935,30.5778
61.88811484,96.39,1024,32
61.94063597,96.39,919,30.315
61.9931571,96.39,957,30.9354
62.04567823,96.39,897,29.95
62.09819936,96.39,904,30.0666
62.15072049,96.39,914,30.2324
62.20324162,96.39,904,30.0666
62.25576275,96.39,853,29.2062
62.30828388,96.39,838,28.9482
62.36080502,96.39,821,28.6531
62.41332615,96.39,838,28.9482
62.46584728,96.39,765,27.6586
62.51836841,96.39,730,27.0185
62.57088954,96.39,777,27.8747
62.62341067,96.39,735,27.1109
62.6759318,96.39,699,26.4386
62.72845293,96.39,701,26.4764
62.78097406,96.39,735,27.1109
62.83349519,96.39,692,26.3059
62.88601632,96.39,674,25.9615
62.93853745,96.39,604,24.5764
62.99105858,96.39,611,24.7184
63.04357971,96.39,638,25.2587
63.09610084,96.39,640,25.2982
63.14862198,96.39,611,24.7184
63.20114311,96.39,624,24.98
63.25366424,96.39,585,24.1868
63.30618537,96.39,585,24.1868
63.3587065,96.39,571,23.8956
63.41122763,96.39,597,24.4336
63.46374876,96.39,652,25.5343
63.51626989,96.39,631,25.1197
63.56879102,96.39,619,24.8797
63.62131215,96.39,615,24.7992
63.67383328,96.39,596,24.4131
63.72635441,96.39,565,23.7697
63.77887554,96.39,580,24.0832
63.83139667,96.39,600,24.4949
63.88391781,96.39,586,24.2074
63.93643894,96.39,560,23.6643
63.98896007,96.39,639,25.2784
64.0414812,96.39,622,24.9399
64.09400233,96.39,563,23.7276
64.14652346,96.39,569,23.8537
64.19904459,96.39,571,23.8956
64.25156572,96.39,610,24.6982
64.30408685,96.39,585,24.1868
64.35660798,96.39,561,23.6854
64.40912911,96.39,522,22.8473
64.46165024,96.39,569,23.8537
64.51417137,96.39,581,24.1039
64.5666925,96.39,591,24.3105
64.61921364,96.39,539,23.2164
64.67173477,96.39,558,23.622
64.7242559,96.39,499,22.3383
64.77677703,96.39,555,23.5584
64.82929816,96.39,536,23.1517
64.88181929,96.39,541,23.2594
64.93434042,96.39,589,24.2693
64.98686155,96.39,564,23.7487