File: Files_organized_for_plots/Constant_NaOH_1mL10M_to_1gPC_28Day_repeat/PAxialnul_Act12Feb23_B1_0833M_NaOH_LS0153_Num158.csv
[Measurement conditions]
Sample identification,PAxialnul_Act12Feb23_B1_0833M_NaOH_LS0153_Num158
Comment - 1,"Configuration=Stage for Flat Samples/Holders, Owner=nmw10, Creation date=9/21/2022 10:06:30 AM"
Comment - 2,"Goniometer=Theta/Theta; Minimum step size 2Theta:0.0001; Minimum step size Omega:0.0001"
Comment - 3,"Sample stage=Stage for flat samples/holders"
Comment - 4,"Diffractometer system=EMPYREAN"
Comment - 5,"Measurement program=X:\XRD\Cement\Zerobackground scan.xrdmp, Created identifier={98A3B11C-88F9-4AA6-982C-73314A311EF5}, Created by=Titus Reed, Id=tmr79, Creation date=10/26/2021 3:01:47 PM"
Anode material,Cu
K-Alpha1 wavelength,1.5405980
K-Alpha2 wavelength,1.5444260
Ratio K-Alpha2/K-Alpha1,0.500
Divergence slit,Fixed,0.25
Monochromator used,NO
Generator voltage, 45
Tube current, 40
File date and time,15/Mar/2023 20:36
Unit cell,
h k l, 0 0 0
Scan axis,Gonio
Scan range,4.994599997,64.999991833
Scan step size,0.0262606
No. of points, 2285
Scan type,CONTINUOUS
Time per step,96.390
[Scan points]
Angle, TimePerStep, Intensity, ESD
5.007730280, 96.390, 4089.0, 63.9453
5.060251411, 96.390, 4190.0, 64.7302
5.112772541, 96.390, 4077.0, 63.8514
5.165293672, 96.390, 4035.0, 63.5216
5.217814803, 96.390, 3967.0, 62.9841
5.270335934, 96.390, 3954.0, 62.8808
5.322857064, 96.390, 4046.0, 63.6082
5.375378195, 96.390, 3870.0, 62.2093
5.427899326, 96.390, 3843.0, 61.9919
5.480420456, 96.390, 3916.0, 62.5780
5.532941587, 96.390, 3842.0, 61.9839
5.585462718, 96.390, 3755.0, 61.2781
5.637983849, 96.390, 3676.0, 60.6300
5.690504979, 96.390, 3710.0, 60.9098
5.743026110, 96.390, 3652.0, 60.4318
5.795547241, 96.390, 3666.0, 60.5475
5.848068371, 96.390, 3588.0, 59.8999
5.900589502, 96.390, 3675.0, 60.6218
5.953110633, 96.390, 3557.0, 59.6406
6.005631763, 96.390, 3645.0, 60.3738
6.058152894, 96.390, 3715.0, 60.9508
6.110674025, 96.390, 3539.0, 59.4895
6.163195156, 96.390, 3663.0, 60.5227
6.215716286, 96.390, 3561.0, 59.6741
6.268237417, 96.390, 3509.0, 59.2368
6.320758548, 96.390, 3532.0, 59.4306
6.373279678, 96.390, 3502.0, 59.1777
6.425800809, 96.390, 3586.0, 59.8832
6.478321940, 96.390, 3679.0, 60.6548
6.530843071, 96.390, 3593.0, 59.9416
6.583364201, 96.390, 3518.0, 59.3127
6.635885332, 96.390, 3646.0, 60.3821
6.688406463, 96.390, 3492.0, 59.0931
6.740927593, 96.390, 3571.0, 59.7578
6.793448724, 96.390, 3623.0, 60.1914
6.845969855, 96.390, 3677.0, 60.6383
6.898490986, 96.390, 3654.0, 60.4483
6.951012116, 96.390, 3539.0, 59.4895
7.003533247, 96.390, 3551.0, 59.5903
7.056054378, 96.390, 3433.0, 58.5918
7.108575508, 96.390, 3562.0, 59.6825
7.161096639, 96.390, 3560.0, 59.6657
7.213617770, 96.390, 3626.0, 60.2163
7.266138900, 96.390, 3723.0, 61.0164
7.318660031, 96.390, 3615.0, 60.1249
7.371181162, 96.390, 3730.0, 61.0737
7.423702293, 96.390, 3677.0, 60.6383
7.476223423, 96.390, 3758.0, 61.3025
7.528744554, 96.390, 3803.0, 61.6685
7.581265685, 96.390, 3943.0, 62.7933
7.633786815, 96.390, 3997.0, 63.2218
7.686307946, 96.390, 4129.0, 64.2573
7.738829077, 96.390, 4288.0, 65.4828
7.791350208, 96.390, 4461.0, 66.7907
7.843871338, 96.390, 4486.0, 66.9776
7.896392469, 96.390, 4724.0, 68.7314
7.948913600, 96.390, 5022.0, 70.8661
8.001434730, 96.390, 5384.0, 73.3757
8.053955861, 96.390, 5761.0, 75.9013
8.106476992, 96.390, 6293.0, 79.3284
8.158998123, 96.390, 6708.0, 81.9024
8.211519253, 96.390, 7125.0, 84.4097
8.264040384, 96.390, 7511.0, 86.6660
8.316561515, 96.390, 7739.0, 87.9716
8.369082645, 96.390, 8033.0, 89.6270
8.421603776, 96.390, 7764.0, 88.1136
8.474124907, 96.390, 7634.0, 87.3728
8.526646038, 96.390, 7262.0, 85.2174
8.579167168, 96.390, 6950.0, 83.3667
8.631688299, 96.390, 6589.0, 81.1727
8.684209430, 96.390, 6860.0, 82.8251
8.736730560, 96.390, 6545.0, 80.9012
8.789251691, 96.390, 6004.0, 77.4855
8.841772822, 96.390, 5488.0, 74.0810
8.894293952, 96.390, 5186.0, 72.0139
8.946815083, 96.390, 4788.0, 69.1954
8.999336214, 96.390, 4570.0, 67.6018
9.051857345, 96.390, 4285.0, 65.4599
9.104378475, 96.390, 4160.0, 64.4981
9.156899606, 96.390, 4310.0, 65.6506
9.209420737, 96.390, 4152.0, 64.4360
9.261941867, 96.390, 4061.0, 63.7260
9.314462998, 96.390, 3956.0, 62.8967
9.366984129, 96.390, 3770.0, 61.4003
9.419505260, 96.390, 3840.0, 61.9677
9.472026390, 96.390, 3663.0, 60.5227
9.524547521, 96.390, 3647.0, 60.3904
9.577068652, 96.390, 3720.0, 60.9918
9.629589782, 96.390, 3581.0, 59.8415
9.682110913, 96.390, 3610.0, 60.0833
9.734632044, 96.390, 3427.0, 58.5406
9.787153175, 96.390, 3397.0, 58.2838
9.839674305, 96.390, 3284.0, 57.3062
9.892195436, 96.390, 3365.0, 58.0086
9.944716567, 96.390, 3259.0, 57.0877
9.997237697, 96.390, 3292.0, 57.3760
10.049758828, 96.390, 3318.0, 57.6021
10.102279959, 96.390, 3203.0, 56.5951
10.154801090, 96.390, 3141.0, 56.0446
10.207322220, 96.390, 3068.0, 55.3895
10.259843351, 96.390, 3076.0, 55.4617
10.312364482, 96.390, 2963.0, 54.4334
10.364885612, 96.390, 2976.0, 54.5527
10.417406743, 96.390, 3013.0, 54.8908
10.469927874, 96.390, 2863.0, 53.5070
10.522449004, 96.390, 2875.0, 53.6190
10.574970135, 96.390, 2879.0, 53.6563
10.627491266, 96.390, 2884.0, 53.7029
10.680012397, 96.390, 2756.0, 52.4976
10.732533527, 96.390, 2846.0, 53.3479
10.785054658, 96.390, 2825.0, 53.1507
10.837575789, 96.390, 2819.0, 53.0943
10.890096919, 96.390, 2738.0, 52.3259
10.942618050, 96.390, 2708.0, 52.0384
10.995139181, 96.390, 2873.0, 53.6004
11.047660312, 96.390, 2925.0, 54.0833
11.100181442, 96.390, 3156.0, 56.1783
11.152702573, 96.390, 3579.0, 59.8247
11.205223704, 96.390, 3997.0, 63.2218
11.257744834, 96.390, 2896.0, 53.8145
11.310265965, 96.390, 2701.0, 51.9711
11.362787096, 96.390, 2700.0, 51.9615
11.415308227, 96.390, 2754.0, 52.4786
11.467829357, 96.390, 2650.0, 51.4782
11.520350488, 96.390, 2648.0, 51.4587
11.572871619, 96.390, 2536.0, 50.3587
11.625392749, 96.390, 2653.0, 51.5073
11.677913880, 96.390, 2487.0, 49.8698
11.730435011, 96.390, 2557.0, 50.5668
11.782956141, 96.390, 2540.0, 50.3984
11.835477272, 96.390, 2645.0, 51.4296
11.887998403, 96.390, 2517.0, 50.1697
11.940519534, 96.390, 2503.0, 50.0300
11.993040664, 96.390, 2574.0, 50.7346
12.045561795, 96.390, 2408.0, 49.0714
12.098082926, 96.390, 2451.0, 49.5076
12.150604056, 96.390, 2465.0, 49.6488
12.203125187, 96.390, 2392.0, 48.9081
12.255646318, 96.390, 2425.0, 49.2443
12.308167449, 96.390, 2481.0, 49.8096
12.360688579, 96.390, 2355.0, 48.5283
12.413209710, 96.390, 2370.0, 48.6826
12.465730841, 96.390, 2293.0, 47.8853
12.518251971, 96.390, 2374.0, 48.7237
12.570773102, 96.390, 2434.0, 49.3356
12.623294233, 96.390, 2493.0, 49.9300
12.675815364, 96.390, 2604.0, 51.0294
12.728336494, 96.390, 2862.0, 53.4977
12.780857625, 96.390, 3528.0, 59.3970
12.833378756, 96.390, 3228.0, 56.8155
12.885899886, 96.390, 2406.0, 49.0510
12.938421017, 96.390, 2313.0, 48.0937
12.990942148, 96.390, 2328.0, 48.2494
13.043463279, 96.390, 2292.0, 47.8748
13.095984409, 96.390, 2269.0, 47.6340
13.148505540, 96.390, 2203.0, 46.9361
13.201026671, 96.390, 2266.0, 47.6025
13.253547801, 96.390, 2250.0, 47.4342
13.306068932, 96.390, 2355.0, 48.5283
13.358590063, 96.390, 2500.0, 50.0000
13.411111193, 96.390, 3015.0, 54.9090
13.463632324, 96.390, 4106.0, 64.0781
13.516153455, 96.390, 4904.0, 70.0286
13.568674586, 96.390, 3726.0, 61.0410
13.621195716, 96.390, 2345.0, 48.4252
13.673716847, 96.390, 2283.0, 47.7807
13.726237978, 96.390, 2384.0, 48.8262
13.778759108, 96.390, 2442.0, 49.4166
13.831280239, 96.390, 2782.0, 52.7447
13.883801370, 96.390, 3197.0, 56.5420
13.936322501, 96.390, 2446.0, 49.4571
13.988843631, 96.390, 2238.0, 47.3075
14.041364762, 96.390, 2141.0, 46.2709
14.093885893, 96.390, 2069.0, 45.4863
14.146407023, 96.390, 2167.0, 46.5510
14.198928154, 96.390, 2230.0, 47.2229
14.251449285, 96.390, 2317.0, 48.1352
14.303970416, 96.390, 2500.0, 50.0000
14.356491546, 96.390, 3082.0, 55.5158
14.409012677, 96.390, 3022.0, 54.9727
14.461533808, 96.390, 2225.0, 47.1699
14.514054938, 96.390, 2109.0, 45.9239
14.566576069, 96.390, 2090.0, 45.7165
14.619097200, 96.390, 2069.0, 45.4863
14.671618331, 96.390, 1981.0, 44.5084
14.724139461, 96.390, 1922.0, 43.8406
14.776660592, 96.390, 2071.0, 45.5082
14.829181723, 96.390, 1908.0, 43.6807
14.881702853, 96.390, 2037.0, 45.1331
14.934223984, 96.390, 2024.0, 44.9889
14.986745115, 96.390, 2056.0, 45.3431
15.039266245, 96.390, 2061.0, 45.3982
15.091787376, 96.390, 2116.0, 46.0000
15.144308507, 96.390, 2121.0, 46.0543
15.196829638, 96.390, 2083.0, 45.6399
15.249350768, 96.390, 2016.0, 44.8999
15.301871899, 96.390, 1991.0, 44.6206
15.354393030, 96.390, 1955.0, 44.2154
15.406914160, 96.390, 2042.0, 45.1885
15.459435291, 96.390, 1984.0, 44.5421
15.511956422, 96.390, 1992.0, 44.6318
15.564477553, 96.390, 1949.0, 44.1475
15.616998683, 96.390, 1949.0, 44.1475
15.669519814, 96.390, 1987.0, 44.5758
15.722040945, 96.390, 1922.0, 43.8406
15.774562075, 96.390, 1949.0, 44.1475
15.827083206, 96.390, 1965.0, 44.3283
15.879604337, 96.390, 1901.0, 43.6005
15.932125468, 96.390, 2038.0, 45.1442
15.984646598, 96.390, 2240.0, 47.3286
16.037167729, 96.390, 2566.0, 50.6557
16.089688860, 96.390, 3234.0, 56.8683
16.142209990, 96.390, 4272.0, 65.3605
16.194731121, 96.390, 3325.0, 57.6628
16.247252252, 96.390, 2191.0, 46.8081
16.299773382, 96.390, 2040.0, 45.1664
16.352294513, 96.390, 2038.0, 45.1442
16.404815644, 96.390, 2057.0, 45.3542
16.457336775, 96.390, 1977.0, 44.4635
16.509857905, 96.390, 2049.0, 45.2659
16.562379036, 96.390, 1940.0, 44.0454
16.614900167, 96.390, 2097.0, 45.7930
16.667421297, 96.390, 2031.0, 45.0666
16.719942428, 96.390, 2052.0, 45.2990
16.772463559, 96.390, 2141.0, 46.2709
16.824984690, 96.390, 2177.0, 46.6583
16.877505820, 96.390, 2168.0, 46.5618
16.930026951, 96.390, 2075.0, 45.5522
16.982548082, 96.390, 2236.0, 47.2864
17.035069212, 96.390, 2185.0, 46.7440
17.087590343, 96.390, 2170.0, 46.5833
17.140111474, 96.390, 2212.0, 47.0319
17.192632605, 96.390, 2195.0, 46.8508
17.245153735, 96.390, 2270.0, 47.6445
17.297674866, 96.390, 2283.0, 47.7807
17.350195997, 96.390, 2310.0, 48.0625
17.402717127, 96.390, 2415.0, 49.1426
17.455238258, 96.390, 2462.0, 49.6185
17.507759389, 96.390, 2614.0, 51.1273
17.560280520, 96.390, 2473.0, 49.7293
17.612801650, 96.390, 2358.0, 48.5592
17.665322781, 96.390, 2374.0, 48.7237
17.717843912, 96.390, 2467.0, 49.6689
17.770365042, 96.390, 2339.0, 48.3632
17.822886173, 96.390, 2263.0, 47.5710
17.875407304, 96.390, 2280.0, 47.7493
17.927928434, 96.390, 2153.0, 46.4004
17.980449565, 96.390, 2155.0, 46.4220
18.032970696, 96.390, 2178.0, 46.6690
18.085491827, 96.390, 2104.0, 45.8694
18.138012957, 96.390, 2143.0, 46.2925
18.190534088, 96.390, 2066.0, 45.4533
18.243055219, 96.390, 2036.0, 45.1221
18.295576349, 96.390, 2136.0, 46.2169
18.348097480, 96.390, 2102.0, 45.8476
18.400618611, 96.390, 2190.0, 46.7974
18.453139742, 96.390, 2109.0, 45.9239
18.505660872, 96.390, 2082.0, 45.6289
18.558182003, 96.390, 2031.0, 45.0666
18.610703134, 96.390, 2061.0, 45.3982
18.663224264, 96.390, 2062.0, 45.4093
18.715745395, 96.390, 2042.0, 45.1885
18.768266526, 96.390, 2122.0, 46.0652
18.820787657, 96.390, 2057.0, 45.3542
18.873308787, 96.390, 2223.0, 47.1487
18.925829918, 96.390, 2171.0, 46.5940
18.978351049, 96.390, 2112.0, 45.9565
19.030872179, 96.390, 2043.0, 45.1996
19.083393310, 96.390, 2052.0, 45.2990
19.135914441, 96.390, 2000.0, 44.7214
19.188435572, 96.390, 2061.0, 45.3982
19.240956702, 96.390, 2040.0, 45.1664
19.293477833, 96.390, 1981.0, 44.5084
19.345998964, 96.390, 2068.0, 45.4753
19.398520094, 96.390, 2076.0, 45.5631
19.451041225, 96.390, 2063.0, 45.4203
19.503562356, 96.390, 2068.0, 45.4753
19.556083486, 96.390, 2027.0, 45.0222
19.608604617, 96.390, 2065.0, 45.4423
19.661125748, 96.390, 2181.0, 46.7012
19.713646879, 96.390, 2025.0, 45.0000
19.766168009, 96.390, 2067.0, 45.4643
19.818689140, 96.390, 2179.0, 46.6798
19.871210271, 96.390, 2274.0, 47.6865
19.923731401, 96.390, 2596.0, 50.9510
19.976252532, 96.390, 3371.0, 58.0603
20.028773663, 96.390, 4071.0, 63.8044
20.081294794, 96.390, 4586.0, 67.7200
20.133815924, 96.390, 5836.0, 76.3937
20.186337055, 96.390, 6846.0, 82.7406
20.238858186, 96.390, 4591.0, 67.7569
20.291379316, 96.390, 2704.0, 52.0000
20.343900447, 96.390, 2449.0, 49.4874
20.396421578, 96.390, 2127.0, 46.1194
20.448942709, 96.390, 2067.0, 45.4643
20.501463839, 96.390, 2024.0, 44.9889
20.553984970, 96.390, 2007.0, 44.7996
20.606506101, 96.390, 2013.0, 44.8665
20.659027231, 96.390, 1958.0, 44.2493
20.711548362, 96.390, 1978.0, 44.4747
20.764069493, 96.390, 1943.0, 44.0795
20.816590623, 96.390, 2049.0, 45.2659
20.869111754, 96.390, 1929.0, 43.9204
20.921632885, 96.390, 1967.0, 44.3509
20.974154016, 96.390, 1984.0, 44.5421
21.026675146, 96.390, 1958.0, 44.2493
21.079196277, 96.390, 1987.0, 44.5758
21.131717408, 96.390, 1995.0, 44.6654
21.184238538, 96.390, 2076.0, 45.5631
21.236759669, 96.390, 2112.0, 45.9565
21.289280800, 96.390, 2112.0, 45.9565
21.341801931, 96.390, 2145.0, 46.3141
21.394323061, 96.390, 2166.0, 46.5403
21.446844192, 96.390, 2045.0, 45.2217
21.499365323, 96.390, 1971.0, 44.3959
21.551886453, 96.390, 1960.0, 44.2719
21.604407584, 96.390, 2008.0, 44.8107
21.656928715, 96.390, 1907.0, 43.6692
21.709449846, 96.390, 2050.0, 45.2769
21.761970976, 96.390, 1976.0, 44.4522
21.814492107, 96.390, 1966.0, 44.3396
21.867013238, 96.390, 2055.0, 45.3321
21.919534368, 96.390, 2054.0, 45.3211
21.972055499, 96.390, 1994.0, 44.6542
22.024576630, 96.390, 2015.0, 44.8888
22.077097761, 96.390, 2094.0, 45.7602
22.129618891, 96.390, 2021.0, 44.9555
22.182140022, 96.390, 2031.0, 45.0666
22.234661153, 96.390, 1987.0, 44.5758
22.287182283, 96.390, 2087.0, 45.6837
22.339703414, 96.390, 1995.0, 44.6654
22.392224545, 96.390, 2076.0, 45.5631
22.444745675, 96.390, 2083.0, 45.6399
22.497266806, 96.390, 2036.0, 45.1221
22.549787937, 96.390, 2123.0, 46.0760
22.602309068, 96.390, 2013.0, 44.8665
22.654830198, 96.390, 2035.0, 45.1110
22.707351329, 96.390, 2011.0, 44.8442
22.759872460, 96.390, 2005.0, 44.7772
22.812393590, 96.390, 1896.0, 43.5431
22.864914721, 96.390, 1935.0, 43.9886
22.917435852, 96.390, 2002.0, 44.7437
22.969956983, 96.390, 2052.0, 45.2990
23.022478113, 96.390, 2059.0, 45.3762
23.074999244, 96.390, 2099.0, 45.8148
23.127520375, 96.390, 1937.0, 44.0114
23.180041505, 96.390, 1959.0, 44.2606
23.232562636, 96.390, 1924.0, 43.8634
23.285083767, 96.390, 1971.0, 44.3959
23.337604898, 96.390, 1998.0, 44.6990
23.390126028, 96.390, 1932.0, 43.9545
23.442647159, 96.390, 2052.0, 45.2990
23.495168290, 96.390, 1953.0, 44.1928
23.547689420, 96.390, 1948.0, 44.1362
23.600210551, 96.390, 1920.0, 43.8178
23.652731682, 96.390, 1925.0, 43.8748
23.705252813, 96.390, 1992.0, 44.6318
23.757773943, 96.390, 2082.0, 45.6289
23.810295074, 96.390, 2238.0, 47.3075
23.862816205, 96.390, 2694.0, 51.9038
23.915337335, 96.390, 3084.0, 55.5338
23.967858466, 96.390, 3020.0, 54.9545
24.020379597, 96.390, 3766.0, 61.3677
24.072900727, 96.390, 4517.0, 67.2086
24.125421858, 96.390, 3256.0, 57.0614
24.177942989, 96.390, 2312.0, 48.0833
24.230464120, 96.390, 2018.0, 44.9222
24.282985250, 96.390, 1914.0, 43.7493
24.335506381, 96.390, 1943.0, 44.0795
24.388027512, 96.390, 1864.0, 43.1741
24.440548642, 96.390, 1953.0, 44.1928
24.493069773, 96.390, 1914.0, 43.7493
24.545590904, 96.390, 1969.0, 44.3734
24.598112035, 96.390, 1914.0, 43.7493
24.650633165, 96.390, 1879.0, 43.3474
24.703154296, 96.390, 1844.0, 42.9418
24.755675427, 96.390, 1904.0, 43.6348
24.808196557, 96.390, 1956.0, 44.2267
24.860717688, 96.390, 1868.0, 43.2204
24.913238819, 96.390, 1786.0, 42.2611
24.965759950, 96.390, 1776.0, 42.1426
25.018281080, 96.390, 1789.0, 42.2966
25.070802211, 96.390, 1750.0, 41.8330
25.123323342, 96.390, 1752.0, 41.8569
25.175844472, 96.390, 1731.0, 41.6053
25.228365603, 96.390, 1791.0, 42.3202
25.280886734, 96.390, 1787.0, 42.2729
25.333407864, 96.390, 1788.0, 42.2847
25.385928995, 96.390, 1894.0, 43.5201
25.438450126, 96.390, 2089.0, 45.7056
25.490971257, 96.390, 2274.0, 47.6865
25.543492387, 96.390, 2342.0, 48.3942
25.596013518, 96.390, 1942.0, 44.0681
25.648534649, 96.390, 1851.0, 43.0232
25.701055779, 96.390, 1904.0, 43.6348
25.753576910, 96.390, 2231.0, 47.2335
25.806098041, 96.390, 2519.0, 50.1896
25.858619172, 96.390, 2272.0, 47.6655
25.911140302, 96.390, 1815.0, 42.6028
25.963661433, 96.390, 1731.0, 41.6053
26.016182564, 96.390, 1776.0, 42.1426
26.068703694, 96.390, 1724.0, 41.5211
26.121224825, 96.390, 1739.0, 41.7013
26.173745956, 96.390, 1810.0, 42.5441
26.226267087, 96.390, 1838.0, 42.8719
26.278788217, 96.390, 2135.0, 46.2061
26.331309348, 96.390, 2332.0, 48.2908
26.383830479, 96.390, 2419.0, 49.1833
26.436351609, 96.390, 2359.0, 48.5695
26.488872740, 96.390, 2167.0, 46.5510
26.541393871, 96.390, 2068.0, 45.4753
26.593915002, 96.390, 1964.0, 44.3170
26.646436132, 96.390, 1987.0, 44.5758
26.698957263, 96.390, 1923.0, 43.8520
26.751478394, 96.390, 1934.0, 43.9773
26.803999524, 96.390, 1953.0, 44.1928
26.856520655, 96.390, 1905.0, 43.6463
26.909041786, 96.390, 2011.0, 44.8442
26.961562916, 96.390, 1882.0, 43.3820
27.014084047, 96.390, 1910.0, 43.7035
27.066605178, 96.390, 1985.0, 44.5533
27.119126309, 96.390, 1903.0, 43.6234
27.171647439, 96.390, 1864.0, 43.1741
27.224168570, 96.390, 2034.0, 45.0999
27.276689701, 96.390, 2118.0, 46.0217
27.329210831, 96.390, 1931.0, 43.9431
27.381731962, 96.390, 1893.0, 43.5086
27.434253093, 96.390, 1818.0, 42.6380
27.486774224, 96.390, 1743.0, 41.7493
27.539295354, 96.390, 1780.0, 42.1900
27.591816485, 96.390, 1663.0, 40.7799
27.644337616, 96.390, 1652.0, 40.6448
27.696858746, 96.390, 1685.0, 41.0488
27.749379877, 96.390, 1722.0, 41.4970
27.801901008, 96.390, 1765.0, 42.0119
27.854422139, 96.390, 1672.0, 40.8901
27.906943269, 96.390, 1632.0, 40.3980
27.959464400, 96.390, 1786.0, 42.2611
28.011985531, 96.390, 1694.0, 41.1582
28.064506661, 96.390, 1689.0, 41.0974
28.117027792, 96.390, 1681.0, 41.0000
28.169548923, 96.390, 1655.0, 40.6817
28.222070054, 96.390, 1654.0, 40.6694
28.274591184, 96.390, 1789.0, 42.2966
28.327112315, 96.390, 1693.0, 41.1461
28.379633446, 96.390, 1705.0, 41.2916
28.432154576, 96.390, 1613.0, 40.1622
28.484675707, 96.390, 1672.0, 40.8901
28.537196838, 96.390, 1744.0, 41.7612
28.589717968, 96.390, 1776.0, 42.1426
28.642239099, 96.390, 1882.0, 43.3820
28.694760230, 96.390, 1981.0, 44.5084
28.747281361, 96.390, 1929.0, 43.9204
28.799802491, 96.390, 1833.0, 42.8135
28.852323622, 96.390, 1887.0, 43.4396
28.904844753, 96.390, 1902.0, 43.6119
28.957365883, 96.390, 2276.0, 47.7074
29.009887014, 96.390, 2700.0, 51.9615
29.062408145, 96.390, 2617.0, 51.1566
29.114929276, 96.390, 2239.0, 47.3181
29.167450406, 96.390, 1807.0, 42.5088
29.219971537, 96.390, 1698.0, 41.2068
29.272492668, 96.390, 1710.0, 41.3521
29.325013798, 96.390, 1716.0, 41.4246
29.377534929, 96.390, 1847.0, 42.9767
29.430056060, 96.390, 1894.0, 43.5201
29.482577191, 96.390, 2218.0, 47.0956
29.535098321, 96.390, 2186.0, 46.7547
29.587619452, 96.390, 2025.0, 45.0000
29.640140583, 96.390, 2184.0, 46.7333
29.692661713, 96.390, 2264.0, 47.5815
29.745182844, 96.390, 2082.0, 45.6289
29.797703975, 96.390, 1941.0, 44.0568
29.850225105, 96.390, 1901.0, 43.6005
29.902746236, 96.390, 2121.0, 46.0543
29.955267367, 96.390, 2269.0, 47.6340
30.007788498, 96.390, 2175.0, 46.6369
30.060309628, 96.390, 1984.0, 44.5421
30.112830759, 96.390, 1915.0, 43.7607
30.165351890, 96.390, 1708.0, 41.3280
30.217873020, 96.390, 1822.0, 42.6849
30.270394151, 96.390, 1781.0, 42.2019
30.322915282, 96.390, 1793.0, 42.3438
30.375436413, 96.390, 1788.0, 42.2847
30.427957543, 96.390, 1854.0, 43.0581
30.480478674, 96.390, 1953.0, 44.1928
30.532999805, 96.390, 2183.0, 46.7226
30.585520935, 96.390, 2086.0, 45.6727
30.638042066, 96.390, 1952.0, 44.1814
30.690563197, 96.390, 1862.0, 43.1509
30.743084328, 96.390, 1782.0, 42.2137
30.795605458, 96.390, 1753.0, 41.8688
30.848126589, 96.390, 1840.0, 42.8952
30.900647720, 96.390, 1710.0, 41.3521
30.953168850, 96.390, 1721.0, 41.4849
31.005689981, 96.390, 1738.0, 41.6893
31.058211112, 96.390, 1872.0, 43.2666
31.110732243, 96.390, 1724.0, 41.5211
31.163253373, 96.390, 1814.0, 42.5911
31.215774504, 96.390, 1711.0, 41.3642
31.268295635, 96.390, 1726.0, 41.5452
31.320816765, 96.390, 1745.0, 41.7732
31.373337896, 96.390, 1732.0, 41.6173
31.425859027, 96.390, 1773.0, 42.1070
31.478380157, 96.390, 2019.0, 44.9333
31.530901288, 96.390, 2255.0, 47.4868
31.583422419, 96.390, 2940.0, 54.2218
31.635943550, 96.390, 3494.0, 59.1101
31.688464680, 96.390, 2791.0, 52.8299
31.740985811, 96.390, 2483.0, 49.8297
31.793506942, 96.390, 2169.0, 46.5725
31.846028072, 96.390, 2334.0, 48.3115
31.898549203, 96.390, 2726.0, 52.2111
31.951070334, 96.390, 2722.0, 52.1728
32.003591465, 96.390, 2378.0, 48.7647
32.056112595, 96.390, 2206.0, 46.9681
32.108633726, 96.390, 2162.0, 46.4973
32.161154857, 96.390, 2569.0, 50.6853
32.213675987, 96.390, 2988.0, 54.6626
32.266197118, 96.390, 2525.0, 50.2494
32.318718249, 96.390, 2465.0, 49.6488
32.371239380, 96.390, 1940.0, 44.0454
32.423760510, 96.390, 1803.0, 42.4617
32.476281641, 96.390, 1876.0, 43.3128
32.528802772, 96.390, 2052.0, 45.2990
32.581323902, 96.390, 2407.0, 49.0612
32.633845033, 96.390, 2906.0, 53.9073
32.686366164, 96.390, 2910.0, 53.9444
32.738887295, 96.390, 2753.0, 52.4690
32.791408425, 96.390, 2367.0, 48.6518
32.843929556, 96.390, 2422.0, 49.2138
32.896450687, 96.390, 2325.0, 48.2183
32.948971817, 96.390, 2385.0, 48.8365
33.001492948, 96.390, 2480.0, 49.7996
33.054014079, 96.390, 3159.0, 56.2050
33.106535209, 96.390, 3871.0, 62.2174
33.159056340, 96.390, 3573.0, 59.7746
33.211577471, 96.390, 3024.0, 54.9909
33.264098602, 96.390, 2419.0, 49.1833
33.316619732, 96.390, 2340.0, 48.3735
33.369140863, 96.390, 2004.0, 44.7661
33.421661994, 96.390, 1919.0, 43.8064
33.474183124, 96.390, 1871.0, 43.2551
33.526704255, 96.390, 1997.0, 44.6878
33.579225386, 96.390, 1945.0, 44.1022
33.631746517, 96.390, 1974.0, 44.4297
33.684267647, 96.390, 1878.0, 43.3359
33.736788778, 96.390, 1878.0, 43.3359
33.789309909, 96.390, 2007.0, 44.7996
33.841831039, 96.390, 1941.0, 44.0568
33.894352170, 96.390, 2057.0, 45.3542
33.946873301, 96.390, 2391.0, 48.8979
33.999394432, 96.390, 2517.0, 50.1697
34.051915562, 96.390, 3242.0, 56.9386
34.104436693, 96.390, 4154.0, 64.4515
34.156957824, 96.390, 2761.0, 52.5452
34.209478954, 96.390, 2703.0, 51.9904
34.262000085, 96.390, 2106.0, 45.8912
34.314521216, 96.390, 2167.0, 46.5510
34.367042346, 96.390, 2013.0, 44.8665
34.419563477, 96.390, 1876.0, 43.3128
34.472084608, 96.390, 1831.0, 42.7902
34.524605739, 96.390, 1860.0, 43.1277
34.577126869, 96.390, 1766.0, 42.0238
34.629648000, 96.390, 1760.0, 41.9524
34.682169131, 96.390, 1796.0, 42.3792
34.734690261, 96.390, 1836.0, 42.8486
34.787211392, 96.390, 1677.0, 40.9512
34.839732523, 96.390, 1694.0, 41.1582
34.892253654, 96.390, 1711.0, 41.3642
34.944774784, 96.390, 1630.0, 40.3733
34.997295915, 96.390, 1707.0, 41.3159
35.049817046, 96.390, 1695.0, 41.1704
35.102338176, 96.390, 1691.0, 41.1218
35.154859307, 96.390, 1676.0, 40.9390
35.207380438, 96.390, 1914.0, 43.7493
35.259901569, 96.390, 2539.0, 50.3885
35.312422699, 96.390, 2775.0, 52.6783
35.364943830, 96.390, 2774.0, 52.6688
35.417464961, 96.390, 2369.0, 48.6724
35.469986091, 96.390, 1924.0, 43.8634
35.522507222, 96.390, 1713.0, 41.3884
35.575028353, 96.390, 1613.0, 40.1622
35.627549484, 96.390, 1499.0, 38.7169
35.680070614, 96.390, 1536.0, 39.1918
35.732591745, 96.390, 1658.0, 40.7185
35.785112876, 96.390, 1585.0, 39.8121
35.837634006, 96.390, 1551.0, 39.3827
35.890155137, 96.390, 1562.0, 39.5221
35.942676268, 96.390, 1494.0, 38.6523
35.995197398, 96.390, 1464.0, 38.2623
36.047718529, 96.390, 1500.0, 38.7298
36.100239660, 96.390, 1454.0, 38.1314
36.152760791, 96.390, 1514.0, 38.9102
36.205281921, 96.390, 1442.0, 37.9737
36.257803052, 96.390, 1498.0, 38.7040
36.310324183, 96.390, 1469.0, 38.3275
36.362845313, 96.390, 1562.0, 39.5221
36.415366444, 96.390, 1537.0, 39.2046
36.467887575, 96.390, 1530.0, 39.1152
36.520408706, 96.390, 1592.0, 39.8999
36.572929836, 96.390, 1780.0, 42.1900
36.625450967, 96.390, 2055.0, 45.3321
36.677972098, 96.390, 1962.0, 44.2945
36.730493228, 96.390, 1765.0, 42.0119
36.783014359, 96.390, 1617.0, 40.2119
36.835535490, 96.390, 1456.0, 38.1576
36.888056621, 96.390, 1302.0, 36.0832
36.940577751, 96.390, 1309.0, 36.1801
36.993098882, 96.390, 1253.0, 35.3977
37.045620013, 96.390, 1266.0, 35.5809
37.098141143, 96.390, 1291.0, 35.9305
37.150662274, 96.390, 1291.0, 35.9305
37.203183405, 96.390, 1347.0, 36.7015
37.255704535, 96.390, 1361.0, 36.8917
37.308225666, 96.390, 1335.0, 36.5377
37.360746797, 96.390, 1309.0, 36.1801
37.413267928, 96.390, 1280.0, 35.7771
37.465789058, 96.390, 1221.0, 34.9428
37.518310189, 96.390, 1280.0, 35.7771
37.570831320, 96.390, 1238.0, 35.1852
37.623352450, 96.390, 1218.0, 34.8999
37.675873581, 96.390, 1264.0, 35.5528
37.728394712, 96.390, 1389.0, 37.2693
37.780915843, 96.390, 1293.0, 35.9583
37.833436973, 96.390, 1231.0, 35.0856
37.885958104, 96.390, 1204.0, 34.6987
37.938479235, 96.390, 1140.0, 33.7639
37.991000365, 96.390, 1124.0, 33.5261
38.043521496, 96.390, 1093.0, 33.0606
38.096042627, 96.390, 1087.0, 32.9697
38.148563758, 96.390, 1120.0, 33.4664
38.201084888, 96.390, 1162.0, 34.0881
38.253606019, 96.390, 1193.0, 34.5398
38.306127150, 96.390, 1281.0, 35.7911
38.358648280, 96.390, 1357.0, 36.8375
38.411169411, 96.390, 1509.0, 38.8458
38.463690542, 96.390, 1496.0, 38.6782
38.516211673, 96.390, 1489.0, 38.5876
38.568732803, 96.390, 1579.0, 39.7366
38.621253934, 96.390, 1748.0, 41.8091
38.673775065, 96.390, 1585.0, 39.8121
38.726296195, 96.390, 1527.0, 39.0768
38.778817326, 96.390, 1382.0, 37.1753
38.831338457, 96.390, 1375.0, 37.0810
38.883859587, 96.390, 1191.0, 34.5109
38.936380718, 96.390, 1188.0, 34.4674
38.988901849, 96.390, 1275.0, 35.7071
39.041422980, 96.390, 1155.0, 33.9853
39.093944110, 96.390, 1108.0, 33.2866
39.146465241, 96.390, 1207.0, 34.7419
39.198986372, 96.390, 1256.0, 35.4401
39.251507502, 96.390, 1328.0, 36.4417
39.304028633, 96.390, 1459.0, 38.1969
39.356549764, 96.390, 1503.0, 38.7685
39.409070895, 96.390, 1288.0, 35.8887
39.461592025, 96.390, 1233.0, 35.1141
39.514113156, 96.390, 1324.0, 36.3868
39.566634287, 96.390, 1545.0, 39.3065
39.619155417, 96.390, 1447.0, 38.0395
39.671676548, 96.390, 1364.0, 36.9324
39.724197679, 96.390, 1290.0, 35.9166
39.776718810, 96.390, 1296.0, 36.0000
39.829239940, 96.390, 1458.0, 38.1838
39.881761071, 96.390, 1396.0, 37.3631
39.934282202, 96.390, 1264.0, 35.5528
39.986803332, 96.390, 1254.0, 35.4119
40.039324463, 96.390, 1138.0, 33.7343
40.091845594, 96.390, 1126.0, 33.5559
40.144366725, 96.390, 1091.0, 33.0303
40.196887855, 96.390, 1050.0, 32.4037
40.249408986, 96.390, 1072.0, 32.7414
40.301930117, 96.390, 1020.0, 31.9374
40.354451247, 96.390, 1029.0, 32.0780
40.406972378, 96.390, 995.0, 31.5436
40.459493509, 96.390, 1003.0, 31.6702
40.512014639, 96.390, 995.0, 31.5436
40.564535770, 96.390, 1060.0, 32.5576
40.617056901, 96.390, 1008.0, 31.7490
40.669578032, 96.390, 962.0, 31.0161
40.722099162, 96.390, 1041.0, 32.2645
40.774620293, 96.390, 989.0, 31.4484
40.827141424, 96.390, 1052.0, 32.4345
40.879662554, 96.390, 1071.0, 32.7261
40.932183685, 96.390, 1074.0, 32.7719
40.984704816, 96.390, 984.0, 31.3688
41.037225947, 96.390, 1086.0, 32.9545
41.089747077, 96.390, 1155.0, 33.9853
41.142268208, 96.390, 1021.0, 31.9531
41.194789339, 96.390, 1021.0, 31.9531
41.247310469, 96.390, 994.0, 31.5278
41.299831600, 96.390, 945.0, 30.7409
41.352352731, 96.390, 968.0, 31.1127
41.404873862, 96.390, 937.0, 30.6105
41.457394992, 96.390, 962.0, 31.0161
41.509916123, 96.390, 871.0, 29.5127
41.562437254, 96.390, 970.0, 31.1448
41.614958384, 96.390, 985.0, 31.3847
41.667479515, 96.390, 1027.0, 32.0468
41.720000646, 96.390, 1121.0, 33.4813
41.772521776, 96.390, 1179.0, 34.3366
41.825042907, 96.390, 1028.0, 32.0624
41.877564038, 96.390, 1081.0, 32.8786
41.930085169, 96.390, 1022.0, 31.9687
41.982606299, 96.390, 969.0, 31.1288
42.035127430, 96.390, 1058.0, 32.5269
42.087648561, 96.390, 1144.0, 33.8231
42.140169691, 96.390, 1161.0, 34.0735
42.192690822, 96.390, 1075.0, 32.7872
42.245211953, 96.390, 1078.0, 32.8329
42.297733084, 96.390, 1060.0, 32.5576
42.350254214, 96.390, 922.0, 30.3645
42.402775345, 96.390, 941.0, 30.6757
42.455296476, 96.390, 947.0, 30.7734
42.507817606, 96.390, 1094.0, 33.0757
42.560338737, 96.390, 1084.0, 32.9242
42.612859868, 96.390, 1081.0, 32.8786
42.665380999, 96.390, 1152.0, 33.9411
42.717902129, 96.390, 1311.0, 36.2077
42.770423260, 96.390, 1111.0, 33.3317
42.822944391, 96.390, 1098.0, 33.1361
42.875465521, 96.390, 1048.0, 32.3728
42.927986652, 96.390, 947.0, 30.7734
42.980507783, 96.390, 950.0, 30.8221
43.033028914, 96.390, 967.0, 31.0966
43.085550044, 96.390, 909.0, 30.1496
43.138071175, 96.390, 988.0, 31.4325
43.190592306, 96.390, 1013.0, 31.8277
43.243113436, 96.390, 1132.0, 33.6452
43.295634567, 96.390, 1076.0, 32.8024
43.348155698, 96.390, 1076.0, 32.8024
43.400676828, 96.390, 1111.0, 33.3317
43.453197959, 96.390, 1002.0, 31.6544
43.505719090, 96.390, 1040.0, 32.2490
43.558240221, 96.390, 1028.0, 32.0624
43.610761351, 96.390, 1129.0, 33.6006
43.663282482, 96.390, 1158.0, 34.0294
43.715803613, 96.390, 1048.0, 32.3728
43.768324743, 96.390, 1055.0, 32.4808
43.820845874, 96.390, 1078.0, 32.8329
43.873367005, 96.390, 1043.0, 32.2955
43.925888136, 96.390, 1018.0, 31.9061
43.978409266, 96.390, 976.0, 31.2410
44.030930397, 96.390, 959.0, 30.9677
44.083451528, 96.390, 944.0, 30.7246
44.135972658, 96.390, 915.0, 30.2490
44.188493789, 96.390, 964.0, 31.0483
44.241014920, 96.390, 941.0, 30.6757
44.293536051, 96.390, 997.0, 31.5753
44.346057181, 96.390, 947.0, 30.7734
44.398578312, 96.390, 966.0, 31.0805
44.451099443, 96.390, 946.0, 30.7571
44.503620573, 96.390, 955.0, 30.9031
44.556141704, 96.390, 964.0, 31.0483
44.608662835, 96.390, 941.0, 30.6757
44.661183966, 96.390, 987.0, 31.4166
44.713705096, 96.390, 963.0, 31.0322
44.766226227, 96.390, 1000.0, 31.6228
44.818747358, 96.390, 1023.0, 31.9844
44.871268488, 96.390, 959.0, 30.9677
44.923789619, 96.390, 1057.0, 32.5115
44.976310750, 96.390, 1212.0, 34.8138
45.028831880, 96.390, 1340.0, 36.6060
45.081353011, 96.390, 1134.0, 33.6749
45.133874142, 96.390, 1137.0, 33.7194
45.186395273, 96.390, 1007.0, 31.7333
45.238916403, 96.390, 973.0, 31.1929
45.291437534, 96.390, 928.0, 30.4631
45.343958665, 96.390, 884.0, 29.7321
45.396479795, 96.390, 913.0, 30.2159
45.449000926, 96.390, 890.0, 29.8329
45.501522057, 96.390, 919.0, 30.3150
45.554043188, 96.390, 916.0, 30.2655
45.606564318, 96.390, 906.0, 30.0998
45.659085449, 96.390, 892.0, 29.8664
45.711606580, 96.390, 924.0, 30.3974
45.764127710, 96.390, 866.0, 29.4279
45.816648841, 96.390, 989.0, 31.4484
45.869169972, 96.390, 918.0, 30.2985
45.921691103, 96.390, 997.0, 31.5753
45.974212233, 96.390, 957.0, 30.9354
46.026733364, 96.390, 984.0, 31.3688
46.079254495, 96.390, 956.0, 30.9192
46.131775625, 96.390, 944.0, 30.7246
46.184296756, 96.390, 967.0, 31.0966
46.236817887, 96.390, 960.0, 30.9839
46.289339017, 96.390, 915.0, 30.2490
46.341860148, 96.390, 967.0, 31.0966
46.394381279, 96.390, 1048.0, 32.3728
46.446902410, 96.390, 1112.0, 33.3467
46.499423540, 96.390, 1114.0, 33.3766
46.551944671, 96.390, 1189.0, 34.4819
46.604465802, 96.390, 1206.0, 34.7275
46.656986932, 96.390, 1295.0, 35.9861
46.709508063, 96.390, 1162.0, 34.0881
46.762029194, 96.390, 1161.0, 34.0735
46.814550325, 96.390, 1125.0, 33.5410
46.867071455, 96.390, 1049.0, 32.3883
46.919592586, 96.390, 957.0, 30.9354
46.972113717, 96.390, 979.0, 31.2890
47.024634847, 96.390, 964.0, 31.0483
47.077155978, 96.390, 1069.0, 32.6956
47.129677109, 96.390, 1063.0, 32.6037
47.182198240, 96.390, 1139.0, 33.7491
47.234719370, 96.390, 1140.0, 33.7639
47.287240501, 96.390, 1157.0, 34.0147
47.339761632, 96.390, 1194.0, 34.5543
47.392282762, 96.390, 1129.0, 33.6006
47.444803893, 96.390, 1187.0, 34.4529
47.497325024, 96.390, 1346.0, 36.6879
47.549846155, 96.390, 1317.0, 36.2905
47.602367285, 96.390, 1266.0, 35.5809
47.654888416, 96.390, 1174.0, 34.2637
47.707409547, 96.390, 1106.0, 33.2566
47.759930677, 96.390, 989.0, 31.4484
47.812451808, 96.390, 984.0, 31.3688
47.864972939, 96.390, 925.0, 30.4138
47.917494069, 96.390, 961.0, 31.0000
47.970015200, 96.390, 930.0, 30.4959
48.022536331, 96.390, 904.0, 30.0666
48.075057462, 96.390, 892.0, 29.8664
48.127578592, 96.390, 859.0, 29.3087
48.180099723, 96.390, 863.0, 29.3769
48.232620854, 96.390, 864.0, 29.3939
48.285141984, 96.390, 862.0, 29.3598
48.337663115, 96.390, 881.0, 29.6816
48.390184246, 96.390, 846.0, 29.0861
48.442705377, 96.390, 924.0, 30.3974
48.495226507, 96.390, 931.0, 30.5123
48.547747638, 96.390, 908.0, 30.1330
48.600268769, 96.390, 870.0, 29.4958
48.652789899, 96.390, 917.0, 30.2820
48.705311030, 96.390, 930.0, 30.4959
48.757832161, 96.390, 924.0, 30.3974
48.810353292, 96.390, 928.0, 30.4631
48.862874422, 96.390, 922.0, 30.3645
48.915395553, 96.390, 958.0, 30.9516
48.967916684, 96.390, 888.0, 29.7993
49.020437814, 96.390, 895.0, 29.9166
49.072958945, 96.390, 871.0, 29.5127
49.125480076, 96.390, 995.0, 31.5436
49.178001207, 96.390, 912.0, 30.1993
49.230522337, 96.390, 877.0, 29.6142
49.283043468, 96.390, 886.0, 29.7658
49.335564599, 96.390, 841.0, 29.0000
49.388085729, 96.390, 798.0, 28.2489
49.440606860, 96.390, 804.0, 28.3549
49.493127991, 96.390, 784.0, 28.0000
49.545649121, 96.390, 762.0, 27.6043
49.598170252, 96.390, 770.0, 27.7489
49.650691383, 96.390, 796.0, 28.2135
49.703212514, 96.390, 880.0, 29.6648
49.755733644, 96.390, 852.0, 29.1890
49.808254775, 96.390, 862.0, 29.3598
49.860775906, 96.390, 831.0, 28.8271
49.913297036, 96.390, 737.0, 27.1477
49.965818167, 96.390, 790.0, 28.1069
50.018339298, 96.390, 780.0, 27.9285
50.070860429, 96.390, 764.0, 27.6405
50.123381559, 96.390, 803.0, 28.3373
50.175902690, 96.390, 784.0, 28.0000
50.228423821, 96.390, 808.0, 28.4253
50.280944951, 96.390, 857.0, 29.2746
50.333466082, 96.390, 854.0, 29.2233
50.385987213, 96.390, 768.0, 27.7128
50.438508344, 96.390, 841.0, 29.0000
50.491029474, 96.390, 845.0, 29.0689
50.543550605, 96.390, 888.0, 29.7993
50.596071736, 96.390, 1022.0, 31.9687
50.648592866, 96.390, 944.0, 30.7246
50.701113997, 96.390, 925.0, 30.4138
50.753635128, 96.390, 850.0, 29.1548
50.806156258, 96.390, 825.0, 28.7228
50.858677389, 96.390, 815.0, 28.5482
50.911198520, 96.390, 807.0, 28.4077
50.963719651, 96.390, 707.0, 26.5895
51.016240781, 96.390, 742.0, 27.2397
51.068761912, 96.390, 690.0, 26.2679
51.121283043, 96.390, 721.0, 26.8514
51.173804173, 96.390, 745.0, 27.2947
51.226325304, 96.390, 726.0, 26.9444
51.278846435, 96.390, 726.0, 26.9444
51.331367566, 96.390, 698.0, 26.4197
51.383888696, 96.390, 712.0, 26.6833
51.436409827, 96.390, 699.0, 26.4386
51.488930958, 96.390, 767.0, 27.6948
51.541452088, 96.390, 718.0, 26.7955
51.593973219, 96.390, 745.0, 27.2947
51.646494350, 96.390, 801.0, 28.3019
51.699015481, 96.390, 816.0, 28.5657
51.751536611, 96.390, 923.0, 30.3809
51.804057742, 96.390, 776.0, 27.8568
51.856578873, 96.390, 863.0, 29.3769
51.909100003, 96.390, 806.0, 28.3901
51.961621134, 96.390, 1009.0, 31.7648
52.014142265, 96.390, 1110.0, 33.3167
52.066663396, 96.390, 923.0, 30.3809
52.119184526, 96.390, 983.0, 31.3528
52.171705657, 96.390, 833.0, 28.8617
52.224226788, 96.390, 820.0, 28.6356
52.276747918, 96.390, 736.0, 27.1293
52.329269049, 96.390, 767.0, 27.6948
52.381790180, 96.390, 788.0, 28.0713
52.434311310, 96.390, 751.0, 27.4044
52.486832441, 96.390, 757.0, 27.5136
52.539353572, 96.390, 716.0, 26.7582
52.591874703, 96.390, 724.0, 26.9072
52.644395833, 96.390, 806.0, 28.3901
52.696916964, 96.390, 839.0, 28.9655
52.749438095, 96.390, 803.0, 28.3373
52.801959225, 96.390, 845.0, 29.0689
52.854480356, 96.390, 875.0, 29.5804
52.907001487, 96.390, 939.0, 30.6431
52.959522618, 96.390, 890.0, 29.8329
53.012043748, 96.390, 1037.0, 32.2025
53.064564879, 96.390, 936.0, 30.5941
53.117086010, 96.390, 838.0, 28.9482
53.169607140, 96.390, 849.0, 29.1376
53.222128271, 96.390, 883.0, 29.7153
53.274649402, 96.390, 743.0, 27.2580
53.327170533, 96.390, 731.0, 27.0370
53.379691663, 96.390, 711.0, 26.6646
53.432212794, 96.390, 741.0, 27.2213
53.484733925, 96.390, 800.0, 28.2843
53.537255055, 96.390, 741.0, 27.2213
53.589776186, 96.390, 720.0, 26.8328
53.642297317, 96.390, 758.0, 27.5318
53.694818448, 96.390, 765.0, 27.6586
53.747339578, 96.390, 689.0, 26.2488
53.799860709, 96.390, 707.0, 26.5895
53.852381840, 96.390, 740.0, 27.2029
53.904902970, 96.390, 763.0, 27.6225
53.957424101, 96.390, 796.0, 28.2135
54.009945232, 96.390, 787.0, 28.0535
54.062466362, 96.390, 759.0, 27.5500
54.114987493, 96.390, 777.0, 27.8747
54.167508624, 96.390, 807.0, 28.4077
54.220029755, 96.390, 793.0, 28.1603
54.272550885, 96.390, 809.0, 28.4429
54.325072016, 96.390, 819.0, 28.6182
54.377593147, 96.390, 750.0, 27.3861
54.430114277, 96.390, 874.0, 29.5635
54.482635408, 96.390, 892.0, 29.8664
54.535156539, 96.390, 848.0, 29.1204
54.587677670, 96.390, 866.0, 29.4279
54.640198800, 96.390, 837.0, 28.9310
54.692719931, 96.390, 813.0, 28.5132
54.745241062, 96.390, 815.0, 28.5482
54.797762192, 96.390, 782.0, 27.9643
54.850283323, 96.390, 862.0, 29.3598
54.902804454, 96.390, 947.0, 30.7734
54.955325585, 96.390, 837.0, 28.9310
55.007846715, 96.390, 856.0, 29.2575
55.060367846, 96.390, 877.0, 29.6142
55.112888977, 96.390, 777.0, 27.8747
55.165410107, 96.390, 762.0, 27.6043
55.217931238, 96.390, 752.0, 27.4226
55.270452369, 96.390, 734.0, 27.0924
55.322973499, 96.390, 765.0, 27.6586
55.375494630, 96.390, 744.0, 27.2764
55.428015761, 96.390, 736.0, 27.1293
55.480536892, 96.390, 722.0, 26.8701
55.533058022, 96.390, 727.0, 26.9629
55.585579153, 96.390, 695.0, 26.3629
55.638100284, 96.390, 673.0, 25.9422
55.690621414, 96.390, 637.0, 25.2389
55.743142545, 96.390, 647.0, 25.4362
55.795663676, 96.390, 724.0, 26.9072
55.848184807, 96.390, 690.0, 26.2679
55.900705937, 96.390, 726.0, 26.9444
55.953227068, 96.390, 667.0, 25.8263
56.005748199, 96.390, 699.0, 26.4386
56.058269329, 96.390, 690.0, 26.2679
56.110790460, 96.390, 749.0, 27.3679
56.163311591, 96.390, 757.0, 27.5136
56.215832722, 96.390, 719.0, 26.8142
56.268353852, 96.390, 669.0, 25.8650
56.320874983, 96.390, 681.0, 26.0960
56.373396114, 96.390, 643.0, 25.3574
56.425917244, 96.390, 671.0, 25.9037
56.478438375, 96.390, 710.0, 26.6458
56.530959506, 96.390, 697.0, 26.4008
56.583480637, 96.390, 711.0, 26.6646
56.636001767, 96.390, 686.0, 26.1916
56.688522898, 96.390, 711.0, 26.6646
56.741044029, 96.390, 722.0, 26.8701
56.793565159, 96.390, 709.0, 26.6271
56.846086290, 96.390, 665.0, 25.7876
56.898607421, 96.390, 674.0, 25.9615
56.951128551, 96.390, 688.0, 26.2298
57.003649682, 96.390, 676.0, 26.0000
57.056170813, 96.390, 635.0, 25.1992
57.108691944, 96.390, 635.0, 25.1992
57.161213074, 96.390, 677.0, 26.0192
57.213734205, 96.390, 715.0, 26.7395
57.266255336, 96.390, 678.0, 26.0384
57.318776466, 96.390, 680.0, 26.0768
57.371297597, 96.390, 677.0, 26.0192
57.423818728, 96.390, 694.0, 26.3439
57.476339859, 96.390, 651.0, 25.5147
57.528860989, 96.390, 683.0, 26.1343
57.581382120, 96.390, 717.0, 26.7769
57.633903251, 96.390, 653.0, 25.5539
57.686424381, 96.390, 727.0, 26.9629
57.738945512, 96.390, 760.0, 27.5681
57.791466643, 96.390, 905.0, 30.0832
57.843987774, 96.390, 900.0, 30.0000
57.896508904, 96.390, 844.0, 29.0517
57.949030035, 96.390, 812.0, 28.4956
58.001551166, 96.390, 743.0, 27.2580
58.054072296, 96.390, 708.0, 26.6083
58.106593427, 96.390, 661.0, 25.7099
58.159114558, 96.390, 644.0, 25.3772
58.211635689, 96.390, 636.0, 25.2190
58.264156819, 96.390, 657.0, 25.6320
58.316677950, 96.390, 646.0, 25.4165
58.369199081, 96.390, 639.0, 25.2784
58.421720211, 96.390, 582.0, 24.1247
58.474241342, 96.390, 594.0, 24.3721
58.526762473, 96.390, 645.0, 25.3969
58.579283603, 96.390, 599.0, 24.4745
58.631804734, 96.390, 641.0, 25.3180
58.684325865, 96.390, 658.0, 25.6515
58.736846996, 96.390, 671.0, 25.9037
58.789368126, 96.390, 655.0, 25.5930
58.841889257, 96.390, 716.0, 26.7582
58.894410388, 96.390, 756.0, 27.4955
58.946931518, 96.390, 773.0, 27.8029
58.999452649, 96.390, 695.0, 26.3629
59.051973780, 96.390, 700.0, 26.4575
59.104494911, 96.390, 736.0, 27.1293
59.157016041, 96.390, 730.0, 27.0185
59.209537172, 96.390, 716.0, 26.7582
59.262058303, 96.390, 683.0, 26.1343
59.314579433, 96.390, 650.0, 25.4951
59.367100564, 96.390, 744.0, 27.2764
59.419621695, 96.390, 736.0, 27.1293
59.472142826, 96.390, 675.0, 25.9808
59.524663956, 96.390, 691.0, 26.2869
59.577185087, 96.390, 659.0, 25.6710
59.629706218, 96.390, 720.0, 26.8328
59.682227348, 96.390, 733.0, 27.0740
59.734748479, 96.390, 748.0, 27.3496
59.787269610, 96.390, 703.0, 26.5141
59.839790740, 96.390, 687.0, 26.2107
59.892311871, 96.390, 669.0, 25.8650
59.944833002, 96.390, 691.0, 26.2869
59.997354133, 96.390, 693.0, 26.3249
60.049875263, 96.390, 654.0, 25.5734
60.102396394, 96.390, 683.0, 26.1343
60.154917525, 96.390, 678.0, 26.0384
60.207438655, 96.390, 669.0, 25.8650
60.259959786, 96.390, 669.0, 25.8650
60.312480917, 96.390, 606.0, 24.6171
60.365002048, 96.390, 680.0, 26.0768
60.417523178, 96.390, 676.0, 26.0000
60.470044309, 96.390, 689.0, 26.2488
60.522565440, 96.390, 636.0, 25.2190
60.575086570, 96.390, 630.0, 25.0998
60.627607701, 96.390, 722.0, 26.8701
60.680128832, 96.390, 667.0, 25.8263
60.732649963, 96.390, 690.0, 26.2679
60.785171093, 96.390, 685.0, 26.1725
60.837692224, 96.390, 690.0, 26.2679
60.890213355, 96.390, 705.0, 26.5518
60.942734485, 96.390, 660.0, 25.6905
60.995255616, 96.390, 712.0, 26.6833
61.047776747, 96.390, 717.0, 26.7769
61.100297878, 96.390, 731.0, 27.0370
61.152819008, 96.390, 783.0, 27.9821
61.205340139, 96.390, 743.0, 27.2580
61.257861270, 96.390, 745.0, 27.2947
61.310382400, 96.390, 742.0, 27.2397
61.362903531, 96.390, 734.0, 27.0924
61.415424662, 96.390, 753.0, 27.4408
61.467945792, 96.390, 752.0, 27.4226
61.520466923, 96.390, 803.0, 28.3373
61.572988054, 96.390, 679.0, 26.0576
61.625509185, 96.390, 690.0, 26.2679
61.678030315, 96.390, 789.0, 28.0891
61.730551446, 96.390, 750.0, 27.3861
61.783072577, 96.390, 718.0, 26.7955
61.835593707, 96.390, 768.0, 27.7128
61.888114838, 96.390, 721.0, 26.8514
61.940635969, 96.390, 667.0, 25.8263
61.993157100, 96.390, 697.0, 26.4008
62.045678230, 96.390, 686.0, 26.1916
62.098199361, 96.390, 665.0, 25.7876
62.150720492, 96.390, 649.0, 25.4755
62.203241622, 96.390, 709.0, 26.6271
62.255762753, 96.390, 663.0, 25.7488
62.308283884, 96.390, 701.0, 26.4764
62.360805015, 96.390, 678.0, 26.0384
62.413326145, 96.390, 673.0, 25.9422
62.465847276, 96.390, 660.0, 25.6905
62.518368407, 96.390, 618.0, 24.8596
62.570889537, 96.390, 646.0, 25.4165
62.623410668, 96.390, 696.0, 26.3818
62.675931799, 96.390, 633.0, 25.1595
62.728452930, 96.390, 681.0, 26.0960
62.780974060, 96.390, 734.0, 27.0924
62.833495191, 96.390, 680.0, 26.0768
62.886016322, 96.390, 721.0, 26.8514
62.938537452, 96.390, 694.0, 26.3439
62.991058583, 96.390, 707.0, 26.5895
63.043579714, 96.390, 697.0, 26.4008
63.096100844, 96.390, 660.0, 25.6905
63.148621975, 96.390, 653.0, 25.5539
63.201143106, 96.390, 616.0, 24.8193
63.253664237, 96.390, 605.0, 24.5967
63.306185367, 96.390, 620.0, 24.8998
63.358706498, 96.390, 536.0, 23.1517
63.411227629, 96.390, 624.0, 24.9800
63.463748759, 96.390, 623.0, 24.9600
63.516269890, 96.390, 574.0, 23.9583
63.568791021, 96.390, 604.0, 24.5764
63.621312152, 96.390, 627.0, 25.0400
63.673833282, 96.390, 664.0, 25.7682
63.726354413, 96.390, 639.0, 25.2784
63.778875544, 96.390, 671.0, 25.9037
63.831396674, 96.390, 627.0, 25.0400
63.883917805, 96.390, 602.0, 24.5357
63.936438936, 96.390, 622.0, 24.9399
63.988960067, 96.390, 591.0, 24.3105
64.041481197, 96.390, 596.0, 24.4131
64.094002328, 96.390, 630.0, 25.0998
64.146523459, 96.390, 621.0, 24.9199
64.199044589, 96.390, 647.0, 25.4362
64.251565720, 96.390, 605.0, 24.5967
64.304086851, 96.390, 591.0, 24.3105
64.356607981, 96.390, 563.0, 23.7276
64.409129112, 96.390, 562.0, 23.7065
64.461650243, 96.390, 580.0, 24.0832
64.514171374, 96.390, 599.0, 24.4745
64.566692504, 96.390, 589.0, 24.2693
64.619213635, 96.390, 623.0, 24.9600
64.671734766, 96.390, 613.0, 24.7588
64.724255896, 96.390, 605.0, 24.5967
64.776777027, 96.390, 617.0, 24.8395
64.829298158, 96.390, 589.0, 24.2693
64.881819289, 96.390, 593.0, 24.3516
64.934340419, 96.390, 566.0, 23.7908
64.986861550, 96.390, 611.0, 24.7184