File: Files_organized_for_plots/Constant_NaOH_1mL10M_to_1gPC_28Day_repeat/PCorner10Feb22_Act12Feb23_B1_1000M_NaOH_LS0133_Num157.csv
[Measurement conditions]
Sample identification,Corner10Feb22_Act12Feb23_B1_1000M_NaOH_LS0133_Num157
Comment - 1,"Configuration=Stage for Flat Samples/Holders, Owner=nmw10, Creation date=9/21/2022 10:06:30 AM"
Comment - 2,"Goniometer=Theta/Theta; Minimum step size 2Theta:0.0001; Minimum step size Omega:0.0001"
Comment - 3,"Sample stage=Stage for flat samples/holders"
Comment - 4,"Diffractometer system=EMPYREAN"
Comment - 5,"Measurement program=X:\XRD\Cement\Zerobackground scan.xrdmp, Created identifier={98A3B11C-88F9-4AA6-982C-73314A311EF5}, Created by=Titus Reed, Id=tmr79, Creation date=10/26/2021 3:01:47 PM"
Anode material,Cu
K-Alpha1 wavelength,1.5405980
K-Alpha2 wavelength,1.5444260
Ratio K-Alpha2/K-Alpha1,0.500
Divergence slit,Fixed,0.25
Monochromator used,NO
Generator voltage, 45
Tube current, 40
File date and time,15/Mar/2023 20:17
Unit cell,
h k l, 0 0 0
Scan axis,Gonio
Scan range,4.994599997,64.999991833
Scan step size,0.0262606
No. of points, 2285
Scan type,CONTINUOUS
Time per step,96.390
[Scan points]
Angle, TimePerStep, Intensity, ESD
5.007730280, 96.390, 5020.0, 70.8520
5.060251411, 96.390, 5021.0, 70.8590
5.112772541, 96.390, 4861.0, 69.7209
5.165293672, 96.390, 5011.0, 70.7884
5.217814803, 96.390, 4824.0, 69.4550
5.270335934, 96.390, 4688.0, 68.4690
5.322857064, 96.390, 4800.0, 69.2820
5.375378195, 96.390, 4718.0, 68.6877
5.427899326, 96.390, 4557.0, 67.5056
5.480420456, 96.390, 4516.0, 67.2012
5.532941587, 96.390, 4410.0, 66.4078
5.585462718, 96.390, 4461.0, 66.7907
5.637983849, 96.390, 4386.0, 66.2269
5.690504979, 96.390, 4374.0, 66.1362
5.743026110, 96.390, 4307.0, 65.6277
5.795547241, 96.390, 4262.0, 65.2840
5.848068371, 96.390, 4268.0, 65.3299
5.900589502, 96.390, 4255.0, 65.2304
5.953110633, 96.390, 4212.0, 64.8999
6.005631763, 96.390, 4234.0, 65.0692
6.058152894, 96.390, 4316.0, 65.6963
6.110674025, 96.390, 4107.0, 64.0859
6.163195156, 96.390, 4119.0, 64.1794
6.215716286, 96.390, 4045.0, 63.6003
6.268237417, 96.390, 3969.0, 63.0000
6.320758548, 96.390, 4045.0, 63.6003
6.373279678, 96.390, 3832.0, 61.9032
6.425800809, 96.390, 3949.0, 62.8411
6.478321940, 96.390, 4007.0, 63.3009
6.530843071, 96.390, 3957.0, 62.9047
6.583364201, 96.390, 3988.0, 63.1506
6.635885332, 96.390, 3974.0, 63.0397
6.688406463, 96.390, 3959.0, 62.9206
6.740927593, 96.390, 3962.0, 62.9444
6.793448724, 96.390, 3942.0, 62.7853
6.845969855, 96.390, 4065.0, 63.7574
6.898490986, 96.390, 3993.0, 63.1902
6.951012116, 96.390, 4000.0, 63.2456
7.003533247, 96.390, 4091.0, 63.9609
7.056054378, 96.390, 4211.0, 64.8922
7.108575508, 96.390, 4306.0, 65.6201
7.161096639, 96.390, 4323.0, 65.7495
7.213617770, 96.390, 4534.0, 67.3350
7.266138900, 96.390, 4746.0, 68.8912
7.318660031, 96.390, 4929.0, 70.2068
7.371181162, 96.390, 5061.0, 71.1407
7.423702293, 96.390, 5279.0, 72.6567
7.476223423, 96.390, 5394.0, 73.4439
7.528744554, 96.390, 5725.0, 75.6637
7.581265685, 96.390, 6028.0, 77.6402
7.633786815, 96.390, 5909.0, 76.8700
7.686307946, 96.390, 6098.0, 78.0897
7.738829077, 96.390, 6136.0, 78.3326
7.791350208, 96.390, 5879.0, 76.6746
7.843871338, 96.390, 5454.0, 73.8512
7.896392469, 96.390, 4868.0, 69.7711
7.948913600, 96.390, 4551.0, 67.4611
8.001434730, 96.390, 4094.0, 63.9844
8.053955861, 96.390, 3922.0, 62.6259
8.106476992, 96.390, 3751.0, 61.2454
8.158998123, 96.390, 3537.0, 59.4727
8.211519253, 96.390, 3703.0, 60.8523
8.264040384, 96.390, 3447.0, 58.7112
8.316561515, 96.390, 3453.0, 58.7622
8.369082645, 96.390, 3405.0, 58.3524
8.421603776, 96.390, 3343.0, 57.8187
8.474124907, 96.390, 3306.0, 57.4978
8.526646038, 96.390, 3244.0, 56.9561
8.579167168, 96.390, 3245.0, 56.9649
8.631688299, 96.390, 3152.0, 56.1427
8.684209430, 96.390, 3189.0, 56.4712
8.736730560, 96.390, 3186.0, 56.4447
8.789251691, 96.390, 3151.0, 56.1338
8.841772822, 96.390, 3098.0, 55.6597
8.894293952, 96.390, 3139.0, 56.0268
8.946815083, 96.390, 3077.0, 55.4707
8.999336214, 96.390, 3153.0, 56.1516
9.051857345, 96.390, 3075.0, 55.4527
9.104378475, 96.390, 3212.0, 56.6745
9.156899606, 96.390, 3259.0, 57.0877
9.209420737, 96.390, 3283.0, 57.2975
9.261941867, 96.390, 3355.0, 57.9224
9.314462998, 96.390, 3654.0, 60.4483
9.366984129, 96.390, 3805.0, 61.6847
9.419505260, 96.390, 4357.0, 66.0076
9.472026390, 96.390, 4826.0, 69.4694
9.524547521, 96.390, 4559.0, 67.5204
9.577068652, 96.390, 3962.0, 62.9444
9.629589782, 96.390, 3421.0, 58.4893
9.682110913, 96.390, 3131.0, 55.9553
9.734632044, 96.390, 3028.0, 55.0273
9.787153175, 96.390, 2868.0, 53.5537
9.839674305, 96.390, 2803.0, 52.9434
9.892195436, 96.390, 2709.0, 52.0481
9.944716567, 96.390, 2860.0, 53.4790
9.997237697, 96.390, 2798.0, 52.8961
10.049758828, 96.390, 2721.0, 52.1632
10.102279959, 96.390, 2717.0, 52.1249
10.154801090, 96.390, 2786.0, 52.7826
10.207322220, 96.390, 2741.0, 52.3546
10.259843351, 96.390, 2723.0, 52.1824
10.312364482, 96.390, 2682.0, 51.7880
10.364885612, 96.390, 2703.0, 51.9904
10.417406743, 96.390, 2618.0, 51.1664
10.469927874, 96.390, 2668.0, 51.6527
10.522449004, 96.390, 2587.0, 50.8626
10.574970135, 96.390, 2604.0, 51.0294
10.627491266, 96.390, 2588.0, 50.8724
10.680012397, 96.390, 2555.0, 50.5470
10.732533527, 96.390, 2537.0, 50.3686
10.785054658, 96.390, 2763.0, 52.5642
10.837575789, 96.390, 2602.0, 51.0098
10.890096919, 96.390, 2586.0, 50.8527
10.942618050, 96.390, 2695.0, 51.9134
10.995139181, 96.390, 2686.0, 51.8266
11.047660312, 96.390, 2680.0, 51.7687
11.100181442, 96.390, 2829.0, 53.1883
11.152702573, 96.390, 2697.0, 51.9326
11.205223704, 96.390, 2642.0, 51.4004
11.257744834, 96.390, 2702.0, 51.9808
11.310265965, 96.390, 2682.0, 51.7880
11.362787096, 96.390, 2614.0, 51.1273
11.415308227, 96.390, 2565.0, 50.6458
11.467829357, 96.390, 2573.0, 50.7247
11.520350488, 96.390, 2633.0, 51.3128
11.572871619, 96.390, 2534.0, 50.3389
11.625392749, 96.390, 2640.0, 51.3809
11.677913880, 96.390, 2696.0, 51.9230
11.730435011, 96.390, 2593.0, 50.9215
11.782956141, 96.390, 2640.0, 51.3809
11.835477272, 96.390, 2674.0, 51.7107
11.887998403, 96.390, 2648.0, 51.4587
11.940519534, 96.390, 2708.0, 52.0384
11.993040664, 96.390, 2564.0, 50.6360
12.045561795, 96.390, 2519.0, 50.1896
12.098082926, 96.390, 2578.0, 50.7740
12.150604056, 96.390, 2528.0, 50.2792
12.203125187, 96.390, 2460.0, 49.5984
12.255646318, 96.390, 2448.0, 49.4773
12.308167449, 96.390, 2319.0, 48.1560
12.360688579, 96.390, 2342.0, 48.3942
12.413209710, 96.390, 2336.0, 48.3322
12.465730841, 96.390, 2328.0, 48.2494
12.518251971, 96.390, 2453.0, 49.5278
12.570773102, 96.390, 2478.0, 49.7795
12.623294233, 96.390, 2432.0, 49.3153
12.675815364, 96.390, 2526.0, 50.2593
12.728336494, 96.390, 2628.0, 51.2640
12.780857625, 96.390, 2677.0, 51.7397
12.833378756, 96.390, 2638.0, 51.3615
12.885899886, 96.390, 2400.0, 48.9898
12.938421017, 96.390, 2348.0, 48.4562
12.990942148, 96.390, 2417.0, 49.1630
13.043463279, 96.390, 2414.0, 49.1325
13.095984409, 96.390, 2380.0, 48.7852
13.148505540, 96.390, 2383.0, 48.8160
13.201026671, 96.390, 2524.0, 50.2394
13.253547801, 96.390, 2487.0, 49.8698
13.306068932, 96.390, 2372.0, 48.7032
13.358590063, 96.390, 2372.0, 48.7032
13.411111193, 96.390, 2236.0, 47.2864
13.463632324, 96.390, 2301.0, 47.9687
13.516153455, 96.390, 2253.0, 47.4658
13.568674586, 96.390, 2277.0, 47.7179
13.621195716, 96.390, 2325.0, 48.2183
13.673716847, 96.390, 2259.0, 47.5289
13.726237978, 96.390, 2205.0, 46.9574
13.778759108, 96.390, 2189.0, 46.7868
13.831280239, 96.390, 2234.0, 47.2652
13.883801370, 96.390, 2182.0, 46.7119
13.936322501, 96.390, 2287.0, 47.8226
13.988843631, 96.390, 2207.0, 46.9787
14.041364762, 96.390, 2266.0, 47.6025
14.093885893, 96.390, 2186.0, 46.7547
14.146407023, 96.390, 2296.0, 47.9166
14.198928154, 96.390, 2319.0, 48.1560
14.251449285, 96.390, 2310.0, 48.0625
14.303970416, 96.390, 2338.0, 48.3529
14.356491546, 96.390, 2341.0, 48.3839
14.409012677, 96.390, 2309.0, 48.0521
14.461533808, 96.390, 2304.0, 48.0000
14.514054938, 96.390, 2387.0, 48.8569
14.566576069, 96.390, 2381.0, 48.7955
14.619097200, 96.390, 2450.0, 49.4975
14.671618331, 96.390, 2540.0, 50.3984
14.724139461, 96.390, 2335.0, 48.3218
14.776660592, 96.390, 2200.0, 46.9042
14.829181723, 96.390, 2343.0, 48.4045
14.881702853, 96.390, 2253.0, 47.4658
14.934223984, 96.390, 2303.0, 47.9896
14.986745115, 96.390, 2314.0, 48.1041
15.039266245, 96.390, 2292.0, 47.8748
15.091787376, 96.390, 2404.0, 49.0306
15.144308507, 96.390, 2384.0, 48.8262
15.196829638, 96.390, 2420.0, 49.1935
15.249350768, 96.390, 2312.0, 48.0833
15.301871899, 96.390, 2307.0, 48.0312
15.354393030, 96.390, 2196.0, 46.8615
15.406914160, 96.390, 2139.0, 46.2493
15.459435291, 96.390, 2121.0, 46.0543
15.511956422, 96.390, 2064.0, 45.4313
15.564477553, 96.390, 2029.0, 45.0444
15.616998683, 96.390, 2120.0, 46.0435
15.669519814, 96.390, 2070.0, 45.4973
15.722040945, 96.390, 2021.0, 44.9555
15.774562075, 96.390, 2118.0, 46.0217
15.827083206, 96.390, 2002.0, 44.7437
15.879604337, 96.390, 2046.0, 45.2327
15.932125468, 96.390, 2027.0, 45.0222
15.984646598, 96.390, 2070.0, 45.4973
16.037167729, 96.390, 2033.0, 45.0888
16.089688860, 96.390, 1888.0, 43.4511
16.142209990, 96.390, 2111.0, 45.9456
16.194731121, 96.390, 1998.0, 44.6990
16.247252252, 96.390, 1958.0, 44.2493
16.299773382, 96.390, 1997.0, 44.6878
16.352294513, 96.390, 1904.0, 43.6348
16.404815644, 96.390, 1862.0, 43.1509
16.457336775, 96.390, 1983.0, 44.5309
16.509857905, 96.390, 1881.0, 43.3705
16.562379036, 96.390, 1931.0, 43.9431
16.614900167, 96.390, 1901.0, 43.6005
16.667421297, 96.390, 1935.0, 43.9886
16.719942428, 96.390, 1954.0, 44.2041
16.772463559, 96.390, 1931.0, 43.9431
16.824984690, 96.390, 1873.0, 43.2782
16.877505820, 96.390, 1949.0, 44.1475
16.930026951, 96.390, 1958.0, 44.2493
16.982548082, 96.390, 1892.0, 43.4971
17.035069212, 96.390, 1857.0, 43.0929
17.087590343, 96.390, 1866.0, 43.1972
17.140111474, 96.390, 1945.0, 44.1022
17.192632605, 96.390, 1853.0, 43.0465
17.245153735, 96.390, 1833.0, 42.8135
17.297674866, 96.390, 1848.0, 42.9884
17.350195997, 96.390, 1919.0, 43.8064
17.402717127, 96.390, 1781.0, 42.2019
17.455238258, 96.390, 1861.0, 43.1393
17.507759389, 96.390, 1872.0, 43.2666
17.560280520, 96.390, 1844.0, 42.9418
17.612801650, 96.390, 1833.0, 42.8135
17.665322781, 96.390, 1843.0, 42.9302
17.717843912, 96.390, 1783.0, 42.2256
17.770365042, 96.390, 1855.0, 43.0697
17.822886173, 96.390, 1885.0, 43.4166
17.875407304, 96.390, 1933.0, 43.9659
17.927928434, 96.390, 1898.0, 43.5660
17.980449565, 96.390, 1925.0, 43.8748
18.032970696, 96.390, 2039.0, 45.1553
18.085491827, 96.390, 2047.0, 45.2438
18.138012957, 96.390, 2014.0, 44.8776
18.190534088, 96.390, 2062.0, 45.4093
18.243055219, 96.390, 2038.0, 45.1442
18.295576349, 96.390, 1857.0, 43.0929
18.348097480, 96.390, 1967.0, 44.3509
18.400618611, 96.390, 1927.0, 43.8976
18.453139742, 96.390, 1991.0, 44.6206
18.505660872, 96.390, 1875.0, 43.3013
18.558182003, 96.390, 1874.0, 43.2897
18.610703134, 96.390, 1802.0, 42.4500
18.663224264, 96.390, 1837.0, 42.8602
18.715745395, 96.390, 1910.0, 43.7035
18.768266526, 96.390, 1765.0, 42.0119
18.820787657, 96.390, 1766.0, 42.0238
18.873308787, 96.390, 1827.0, 42.7434
18.925829918, 96.390, 1898.0, 43.5660
18.978351049, 96.390, 1858.0, 43.1045
19.030872179, 96.390, 1964.0, 44.3170
19.083393310, 96.390, 1881.0, 43.3705
19.135914441, 96.390, 1869.0, 43.2319
19.188435572, 96.390, 1895.0, 43.5316
19.240956702, 96.390, 1916.0, 43.7721
19.293477833, 96.390, 1881.0, 43.3705
19.345998964, 96.390, 1957.0, 44.2380
19.398520094, 96.390, 1951.0, 44.1701
19.451041225, 96.390, 1911.0, 43.7150
19.503562356, 96.390, 1957.0, 44.2380
19.556083486, 96.390, 1927.0, 43.8976
19.608604617, 96.390, 1818.0, 42.6380
19.661125748, 96.390, 1854.0, 43.0581
19.713646879, 96.390, 1931.0, 43.9431
19.766168009, 96.390, 1926.0, 43.8862
19.818689140, 96.390, 1865.0, 43.1856
19.871210271, 96.390, 1880.0, 43.3590
19.923731401, 96.390, 1875.0, 43.3013
19.976252532, 96.390, 2004.0, 44.7661
20.028773663, 96.390, 2009.0, 44.8219
20.081294794, 96.390, 1993.0, 44.6430
20.133815924, 96.390, 2016.0, 44.8999
20.186337055, 96.390, 2032.0, 45.0777
20.238858186, 96.390, 2033.0, 45.0888
20.291379316, 96.390, 2076.0, 45.5631
20.343900447, 96.390, 2049.0, 45.2659
20.396421578, 96.390, 2046.0, 45.2327
20.448942709, 96.390, 1959.0, 44.2606
20.501463839, 96.390, 2132.0, 46.1736
20.553984970, 96.390, 2023.0, 44.9778
20.606506101, 96.390, 2047.0, 45.2438
20.659027231, 96.390, 2088.0, 45.6946
20.711548362, 96.390, 2066.0, 45.4533
20.764069493, 96.390, 1991.0, 44.6206
20.816590623, 96.390, 1962.0, 44.2945
20.869111754, 96.390, 2021.0, 44.9555
20.921632885, 96.390, 1920.0, 43.8178
20.974154016, 96.390, 1928.0, 43.9090
21.026675146, 96.390, 1969.0, 44.3734
21.079196277, 96.390, 1992.0, 44.6318
21.131717408, 96.390, 1981.0, 44.5084
21.184238538, 96.390, 2025.0, 45.0000
21.236759669, 96.390, 2074.0, 45.5412
21.289280800, 96.390, 2219.0, 47.1063
21.341801931, 96.390, 2143.0, 46.2925
21.394323061, 96.390, 2262.0, 47.5605
21.446844192, 96.390, 2230.0, 47.2229
21.499365323, 96.390, 2169.0, 46.5725
21.551886453, 96.390, 2089.0, 45.7056
21.604407584, 96.390, 1989.0, 44.5982
21.656928715, 96.390, 2050.0, 45.2769
21.709449846, 96.390, 1947.0, 44.1248
21.761970976, 96.390, 2005.0, 44.7772
21.814492107, 96.390, 1975.0, 44.4410
21.867013238, 96.390, 2029.0, 45.0444
21.919534368, 96.390, 1994.0, 44.6542
21.972055499, 96.390, 1907.0, 43.6692
22.024576630, 96.390, 1987.0, 44.5758
22.077097761, 96.390, 1918.0, 43.7950
22.129618891, 96.390, 1859.0, 43.1161
22.182140022, 96.390, 1904.0, 43.6348
22.234661153, 96.390, 1817.0, 42.6263
22.287182283, 96.390, 1823.0, 42.6966
22.339703414, 96.390, 1785.0, 42.2493
22.392224545, 96.390, 1797.0, 42.3910
22.444745675, 96.390, 1766.0, 42.0238
22.497266806, 96.390, 1859.0, 43.1161
22.549787937, 96.390, 1850.0, 43.0116
22.602309068, 96.390, 1977.0, 44.4635
22.654830198, 96.390, 1887.0, 43.4396
22.707351329, 96.390, 1867.0, 43.2088
22.759872460, 96.390, 1786.0, 42.2611
22.812393590, 96.390, 1844.0, 42.9418
22.864914721, 96.390, 1967.0, 44.3509
22.917435852, 96.390, 1857.0, 43.0929
22.969956983, 96.390, 1827.0, 42.7434
23.022478113, 96.390, 1797.0, 42.3910
23.074999244, 96.390, 1868.0, 43.2204
23.127520375, 96.390, 1945.0, 44.1022
23.180041505, 96.390, 1899.0, 43.5775
23.232562636, 96.390, 1949.0, 44.1475
23.285083767, 96.390, 1922.0, 43.8406
23.337604898, 96.390, 1964.0, 44.3170
23.390126028, 96.390, 1978.0, 44.4747
23.442647159, 96.390, 1975.0, 44.4410
23.495168290, 96.390, 1902.0, 43.6119
23.547689420, 96.390, 2039.0, 45.1553
23.600210551, 96.390, 2063.0, 45.4203
23.652731682, 96.390, 1931.0, 43.9431
23.705252813, 96.390, 1964.0, 44.3170
23.757773943, 96.390, 1896.0, 43.5431
23.810295074, 96.390, 1963.0, 44.3058
23.862816205, 96.390, 1877.0, 43.3244
23.915337335, 96.390, 1921.0, 43.8292
23.967858466, 96.390, 1879.0, 43.3474
24.020379597, 96.390, 1830.0, 42.7785
24.072900727, 96.390, 1728.0, 41.5692
24.125421858, 96.390, 1793.0, 42.3438
24.177942989, 96.390, 1745.0, 41.7732
24.230464120, 96.390, 1732.0, 41.6173
24.282985250, 96.390, 1806.0, 42.4971
24.335506381, 96.390, 1752.0, 41.8569
24.388027512, 96.390, 1676.0, 40.9390
24.440548642, 96.390, 1761.0, 41.9643
24.493069773, 96.390, 1675.0, 40.9268
24.545590904, 96.390, 1676.0, 40.9390
24.598112035, 96.390, 1691.0, 41.1218
24.650633165, 96.390, 1721.0, 41.4849
24.703154296, 96.390, 1634.0, 40.4228
24.755675427, 96.390, 1664.0, 40.7922
24.808196557, 96.390, 1712.0, 41.3763
24.860717688, 96.390, 1598.0, 39.9750
24.913238819, 96.390, 1737.0, 41.6773
24.965759950, 96.390, 1731.0, 41.6053
25.018281080, 96.390, 1728.0, 41.5692
25.070802211, 96.390, 1789.0, 42.2966
25.123323342, 96.390, 1773.0, 42.1070
25.175844472, 96.390, 1742.0, 41.7373
25.228365603, 96.390, 1817.0, 42.6263
25.280886734, 96.390, 1763.0, 41.9881
25.333407864, 96.390, 1829.0, 42.7668
25.385928995, 96.390, 1796.0, 42.3792
25.438450126, 96.390, 1837.0, 42.8602
25.490971257, 96.390, 1854.0, 43.0581
25.543492387, 96.390, 1823.0, 42.6966
25.596013518, 96.390, 1917.0, 43.7836
25.648534649, 96.390, 1888.0, 43.4511
25.701055779, 96.390, 2010.0, 44.8330
25.753576910, 96.390, 1952.0, 44.1814
25.806098041, 96.390, 2031.0, 45.0666
25.858619172, 96.390, 2053.0, 45.3100
25.911140302, 96.390, 2100.0, 45.8258
25.963661433, 96.390, 2013.0, 44.8665
26.016182564, 96.390, 1980.0, 44.4972
26.068703694, 96.390, 1934.0, 43.9773
26.121224825, 96.390, 1802.0, 42.4500
26.173745956, 96.390, 1932.0, 43.9545
26.226267087, 96.390, 1916.0, 43.7721
26.278788217, 96.390, 1809.0, 42.5323
26.331309348, 96.390, 1924.0, 43.8634
26.383830479, 96.390, 1946.0, 44.1135
26.436351609, 96.390, 1912.0, 43.7264
26.488872740, 96.390, 1957.0, 44.2380
26.541393871, 96.390, 1867.0, 43.2088
26.593915002, 96.390, 1975.0, 44.4410
26.646436132, 96.390, 2054.0, 45.3211
26.698957263, 96.390, 2008.0, 44.8107
26.751478394, 96.390, 2072.0, 45.5192
26.803999524, 96.390, 1908.0, 43.6807
26.856520655, 96.390, 1942.0, 44.0681
26.909041786, 96.390, 1855.0, 43.0697
26.961562916, 96.390, 1998.0, 44.6990
27.014084047, 96.390, 2000.0, 44.7214
27.066605178, 96.390, 1971.0, 44.3959
27.119126309, 96.390, 1997.0, 44.6878
27.171647439, 96.390, 1974.0, 44.4297
27.224168570, 96.390, 1960.0, 44.2719
27.276689701, 96.390, 1956.0, 44.2267
27.329210831, 96.390, 1934.0, 43.9773
27.381731962, 96.390, 1856.0, 43.0813
27.434253093, 96.390, 1997.0, 44.6878
27.486774224, 96.390, 1911.0, 43.7150
27.539295354, 96.390, 1783.0, 42.2256
27.591816485, 96.390, 1945.0, 44.1022
27.644337616, 96.390, 1887.0, 43.4396
27.696858746, 96.390, 1958.0, 44.2493
27.749379877, 96.390, 1916.0, 43.7721
27.801901008, 96.390, 1908.0, 43.6807
27.854422139, 96.390, 1915.0, 43.7607
27.906943269, 96.390, 1852.0, 43.0349
27.959464400, 96.390, 1999.0, 44.7102
28.011985531, 96.390, 2005.0, 44.7772
28.064506661, 96.390, 1972.0, 44.4072
28.117027792, 96.390, 2029.0, 45.0444
28.169548923, 96.390, 1934.0, 43.9773
28.222070054, 96.390, 2019.0, 44.9333
28.274591184, 96.390, 2079.0, 45.5961
28.327112315, 96.390, 2080.0, 45.6070
28.379633446, 96.390, 2104.0, 45.8694
28.432154576, 96.390, 2076.0, 45.5631
28.484675707, 96.390, 2121.0, 46.0543
28.537196838, 96.390, 2164.0, 46.5188
28.589717968, 96.390, 2251.0, 47.4447
28.642239099, 96.390, 2237.0, 47.2969
28.694760230, 96.390, 2276.0, 47.7074
28.747281361, 96.390, 2327.0, 48.2390
28.799802491, 96.390, 2358.0, 48.5592
28.852323622, 96.390, 2200.0, 46.9042
28.904844753, 96.390, 2396.0, 48.9490
28.957365883, 96.390, 2325.0, 48.2183
29.009887014, 96.390, 2327.0, 48.2390
29.062408145, 96.390, 2378.0, 48.7647
29.114929276, 96.390, 2356.0, 48.5386
29.167450406, 96.390, 2456.0, 49.5580
29.219971537, 96.390, 2438.0, 49.3761
29.272492668, 96.390, 2510.0, 50.0999
29.325013798, 96.390, 2634.0, 51.3225
29.377534929, 96.390, 2520.0, 50.1996
29.430056060, 96.390, 2581.0, 50.8035
29.482577191, 96.390, 2597.0, 50.9608
29.535098321, 96.390, 2704.0, 52.0000
29.587619452, 96.390, 2716.0, 52.1153
29.640140583, 96.390, 2702.0, 51.9808
29.692661713, 96.390, 2740.0, 52.3450
29.745182844, 96.390, 2680.0, 51.7687
29.797703975, 96.390, 2675.0, 51.7204
29.850225105, 96.390, 2446.0, 49.4571
29.902746236, 96.390, 2505.0, 50.0500
29.955267367, 96.390, 2411.0, 49.1019
30.007788498, 96.390, 2401.0, 49.0000
30.060309628, 96.390, 2480.0, 49.7996
30.112830759, 96.390, 2484.0, 49.8397
30.165351890, 96.390, 2463.0, 49.6286
30.217873020, 96.390, 2402.0, 49.0102
30.270394151, 96.390, 2385.0, 48.8365
30.322915282, 96.390, 2440.0, 49.3964
30.375436413, 96.390, 2449.0, 49.4874
30.427957543, 96.390, 2436.0, 49.3559
30.480478674, 96.390, 2462.0, 49.6185
30.532999805, 96.390, 2614.0, 51.1273
30.585520935, 96.390, 2589.0, 50.8822
30.638042066, 96.390, 2495.0, 49.9500
30.690563197, 96.390, 2589.0, 50.8822
30.743084328, 96.390, 2449.0, 49.4874
30.795605458, 96.390, 2365.0, 48.6313
30.848126589, 96.390, 2284.0, 47.7912
30.900647720, 96.390, 2305.0, 48.0104
30.953168850, 96.390, 2308.0, 48.0416
31.005689981, 96.390, 2264.0, 47.5815
31.058211112, 96.390, 2362.0, 48.6004
31.110732243, 96.390, 2364.0, 48.6210
31.163253373, 96.390, 2351.0, 48.4871
31.215774504, 96.390, 2312.0, 48.0833
31.268295635, 96.390, 2387.0, 48.8569
31.320816765, 96.390, 2408.0, 49.0714
31.373337896, 96.390, 2408.0, 49.0714
31.425859027, 96.390, 2307.0, 48.0312
31.478380157, 96.390, 2321.0, 48.1768
31.530901288, 96.390, 2221.0, 47.1275
31.583422419, 96.390, 2267.0, 47.6130
31.635943550, 96.390, 2292.0, 47.8748
31.688464680, 96.390, 2207.0, 46.9787
31.740985811, 96.390, 2217.0, 47.0850
31.793506942, 96.390, 2199.0, 46.8935
31.846028072, 96.390, 2212.0, 47.0319
31.898549203, 96.390, 2107.0, 45.9021
31.951070334, 96.390, 2270.0, 47.6445
32.003591465, 96.390, 2179.0, 46.6798
32.056112595, 96.390, 2166.0, 46.5403
32.108633726, 96.390, 2216.0, 47.0744
32.161154857, 96.390, 2265.0, 47.5920
32.213675987, 96.390, 2380.0, 48.7852
32.266197118, 96.390, 2295.0, 47.9062
32.318718249, 96.390, 2251.0, 47.4447
32.371239380, 96.390, 2324.0, 48.2079
32.423760510, 96.390, 2288.0, 47.8330
32.476281641, 96.390, 2270.0, 47.6445
32.528802772, 96.390, 2219.0, 47.1063
32.581323902, 96.390, 2127.0, 46.1194
32.633845033, 96.390, 2084.0, 45.6508
32.686366164, 96.390, 2111.0, 45.9456
32.738887295, 96.390, 2137.0, 46.2277
32.791408425, 96.390, 1997.0, 44.6878
32.843929556, 96.390, 1954.0, 44.2041
32.896450687, 96.390, 2076.0, 45.5631
32.948971817, 96.390, 2044.0, 45.2106
33.001492948, 96.390, 2018.0, 44.9222
33.054014079, 96.390, 2055.0, 45.3321
33.106535209, 96.390, 2043.0, 45.1996
33.159056340, 96.390, 1963.0, 44.3058
33.211577471, 96.390, 1925.0, 43.8748
33.264098602, 96.390, 1949.0, 44.1475
33.316619732, 96.390, 1978.0, 44.4747
33.369140863, 96.390, 1938.0, 44.0227
33.421661994, 96.390, 1936.0, 44.0000
33.474183124, 96.390, 1942.0, 44.0681
33.526704255, 96.390, 2068.0, 45.4753
33.579225386, 96.390, 1950.0, 44.1588
33.631746517, 96.390, 2101.0, 45.8367
33.684267647, 96.390, 2108.0, 45.9130
33.736788778, 96.390, 2112.0, 45.9565
33.789309909, 96.390, 2062.0, 45.4093
33.841831039, 96.390, 2033.0, 45.0888
33.894352170, 96.390, 2177.0, 46.6583
33.946873301, 96.390, 2045.0, 45.2217
33.999394432, 96.390, 2017.0, 44.9110
34.051915562, 96.390, 2088.0, 45.6946
34.104436693, 96.390, 1965.0, 44.3283
34.156957824, 96.390, 1944.0, 44.0908
34.209478954, 96.390, 1875.0, 43.3013
34.262000085, 96.390, 1866.0, 43.1972
34.314521216, 96.390, 1803.0, 42.4617
34.367042346, 96.390, 1769.0, 42.0595
34.419563477, 96.390, 1770.0, 42.0714
34.472084608, 96.390, 1810.0, 42.5441
34.524605739, 96.390, 1699.0, 41.2189
34.577126869, 96.390, 1728.0, 41.5692
34.629648000, 96.390, 1760.0, 41.9524
34.682169131, 96.390, 1790.0, 42.3084
34.734690261, 96.390, 1877.0, 43.3244
34.787211392, 96.390, 1876.0, 43.3128
34.839732523, 96.390, 1833.0, 42.8135
34.892253654, 96.390, 1904.0, 43.6348
34.944774784, 96.390, 1780.0, 42.1900
34.997295915, 96.390, 1795.0, 42.3674
35.049817046, 96.390, 1761.0, 41.9643
35.102338176, 96.390, 1722.0, 41.4970
35.154859307, 96.390, 1641.0, 40.5093
35.207380438, 96.390, 1638.0, 40.4722
35.259901569, 96.390, 1552.0, 39.3954
35.312422699, 96.390, 1569.0, 39.6106
35.364943830, 96.390, 1592.0, 39.8999
35.417464961, 96.390, 1489.0, 38.5876
35.469986091, 96.390, 1517.0, 38.9487
35.522507222, 96.390, 1383.0, 37.1887
35.575028353, 96.390, 1437.0, 37.9078
35.627549484, 96.390, 1406.0, 37.4967
35.680070614, 96.390, 1408.0, 37.5233
35.732591745, 96.390, 1351.0, 36.7560
35.785112876, 96.390, 1263.0, 35.5387
35.837634006, 96.390, 1256.0, 35.4401
35.890155137, 96.390, 1330.0, 36.4692
35.942676268, 96.390, 1347.0, 36.7015
35.995197398, 96.390, 1377.0, 37.1080
36.047718529, 96.390, 1276.0, 35.7211
36.100239660, 96.390, 1264.0, 35.5528
36.152760791, 96.390, 1231.0, 35.0856
36.205281921, 96.390, 1288.0, 35.8887
36.257803052, 96.390, 1243.0, 35.2562
36.310324183, 96.390, 1287.0, 35.8748
36.362845313, 96.390, 1282.0, 35.8050
36.415366444, 96.390, 1226.0, 35.0143
36.467887575, 96.390, 1252.0, 35.3836
36.520408706, 96.390, 1313.0, 36.2353
36.572929836, 96.390, 1222.0, 34.9571
36.625450967, 96.390, 1315.0, 36.2629
36.677972098, 96.390, 1256.0, 35.4401
36.730493228, 96.390, 1370.0, 37.0135
36.783014359, 96.390, 1284.0, 35.8329
36.835535490, 96.390, 1305.0, 36.1248
36.888056621, 96.390, 1334.0, 36.5240
36.940577751, 96.390, 1286.0, 35.8608
36.993098882, 96.390, 1203.0, 34.6843
37.045620013, 96.390, 1276.0, 35.7211
37.098141143, 96.390, 1304.0, 36.1109
37.150662274, 96.390, 1229.0, 35.0571
37.203183405, 96.390, 1238.0, 35.1852
37.255704535, 96.390, 1217.0, 34.8855
37.308225666, 96.390, 1164.0, 34.1174
37.360746797, 96.390, 1241.0, 35.2278
37.413267928, 96.390, 1205.0, 34.7131
37.465789058, 96.390, 1182.0, 34.3802
37.518310189, 96.390, 1142.0, 33.7935
37.570831320, 96.390, 1123.0, 33.5112
37.623352450, 96.390, 1184.0, 34.4093
37.675873581, 96.390, 1140.0, 33.7639
37.728394712, 96.390, 1180.0, 34.3511
37.780915843, 96.390, 1171.0, 34.2199
37.833436973, 96.390, 1147.0, 33.8674
37.885958104, 96.390, 1179.0, 34.3366
37.938479235, 96.390, 1175.0, 34.2783
37.991000365, 96.390, 1182.0, 34.3802
38.043521496, 96.390, 1182.0, 34.3802
38.096042627, 96.390, 1156.0, 34.0000
38.148563758, 96.390, 1150.0, 33.9116
38.201084888, 96.390, 1178.0, 34.3220
38.253606019, 96.390, 1169.0, 34.1906
38.306127150, 96.390, 1222.0, 34.9571
38.358648280, 96.390, 1151.0, 33.9264
38.411169411, 96.390, 1120.0, 33.4664
38.463690542, 96.390, 1165.0, 34.1321
38.516211673, 96.390, 1092.0, 33.0454
38.568732803, 96.390, 1184.0, 34.4093
38.621253934, 96.390, 1163.0, 34.1028
38.673775065, 96.390, 1154.0, 33.9706
38.726296195, 96.390, 1117.0, 33.4215
38.778817326, 96.390, 1119.0, 33.4515
38.831338457, 96.390, 1087.0, 32.9697
38.883859587, 96.390, 1091.0, 33.0303
38.936380718, 96.390, 1069.0, 32.6956
38.988901849, 96.390, 1118.0, 33.4365
39.041422980, 96.390, 1131.0, 33.6303
39.093944110, 96.390, 1167.0, 34.1614
39.146465241, 96.390, 1072.0, 32.7414
39.198986372, 96.390, 1138.0, 33.7343
39.251507502, 96.390, 1108.0, 33.2866
39.304028633, 96.390, 996.0, 31.5595
39.356549764, 96.390, 1062.0, 32.5883
39.409070895, 96.390, 1047.0, 32.3574
39.461592025, 96.390, 1066.0, 32.6497
39.514113156, 96.390, 1050.0, 32.4037
39.566634287, 96.390, 1033.0, 32.1403
39.619155417, 96.390, 1026.0, 32.0312
39.671676548, 96.390, 1024.0, 32.0000
39.724197679, 96.390, 1114.0, 33.3766
39.776718810, 96.390, 1082.0, 32.8938
39.829239940, 96.390, 1086.0, 32.9545
39.881761071, 96.390, 993.0, 31.5119
39.934282202, 96.390, 1105.0, 33.2415
39.986803332, 96.390, 1087.0, 32.9697
40.039324463, 96.390, 1064.0, 32.6190
40.091845594, 96.390, 1082.0, 32.8938
40.144366725, 96.390, 1113.0, 33.3617
40.196887855, 96.390, 1125.0, 33.5410
40.249408986, 96.390, 1065.0, 32.6343
40.301930117, 96.390, 1081.0, 32.8786
40.354451247, 96.390, 970.0, 31.1448
40.406972378, 96.390, 1050.0, 32.4037
40.459493509, 96.390, 1066.0, 32.6497
40.512014639, 96.390, 982.0, 31.3369
40.564535770, 96.390, 1052.0, 32.4345
40.617056901, 96.390, 974.0, 31.2090
40.669578032, 96.390, 1043.0, 32.2955
40.722099162, 96.390, 1024.0, 32.0000
40.774620293, 96.390, 984.0, 31.3688
40.827141424, 96.390, 976.0, 31.2410
40.879662554, 96.390, 1026.0, 32.0312
40.932183685, 96.390, 1006.0, 31.7175
40.984704816, 96.390, 978.0, 31.2730
41.037225947, 96.390, 1000.0, 31.6228
41.089747077, 96.390, 973.0, 31.1929
41.142268208, 96.390, 977.0, 31.2570
41.194789339, 96.390, 1009.0, 31.7648
41.247310469, 96.390, 1016.0, 31.8748
41.299831600, 96.390, 1012.0, 31.8119
41.352352731, 96.390, 953.0, 30.8707
41.404873862, 96.390, 1042.0, 32.2800
41.457394992, 96.390, 991.0, 31.4802
41.509916123, 96.390, 939.0, 30.6431
41.562437254, 96.390, 932.0, 30.5287
41.614958384, 96.390, 969.0, 31.1288
41.667479515, 96.390, 1025.0, 32.0156
41.720000646, 96.390, 1022.0, 31.9687
41.772521776, 96.390, 1001.0, 31.6386
41.825042907, 96.390, 1107.0, 33.2716
41.877564038, 96.390, 1019.0, 31.9218
41.930085169, 96.390, 1050.0, 32.4037
41.982606299, 96.390, 1088.0, 32.9848
42.035127430, 96.390, 1067.0, 32.6650
42.087648561, 96.390, 1027.0, 32.0468
42.140169691, 96.390, 1029.0, 32.0780
42.192690822, 96.390, 1056.0, 32.4962
42.245211953, 96.390, 1096.0, 33.1059
42.297733084, 96.390, 1058.0, 32.5269
42.350254214, 96.390, 1021.0, 31.9531
42.402775345, 96.390, 1052.0, 32.4345
42.455296476, 96.390, 1040.0, 32.2490
42.507817606, 96.390, 1011.0, 31.7962
42.560338737, 96.390, 1026.0, 32.0312
42.612859868, 96.390, 999.0, 31.6070
42.665380999, 96.390, 1034.0, 32.1559
42.717902129, 96.390, 1055.0, 32.4808
42.770423260, 96.390, 1057.0, 32.5115
42.822944391, 96.390, 1053.0, 32.4500
42.875465521, 96.390, 1020.0, 31.9374
42.927986652, 96.390, 1011.0, 31.7962
42.980507783, 96.390, 1034.0, 32.1559
43.033028914, 96.390, 1028.0, 32.0624
43.085550044, 96.390, 1019.0, 31.9218
43.138071175, 96.390, 1022.0, 31.9687
43.190592306, 96.390, 988.0, 31.4325
43.243113436, 96.390, 999.0, 31.6070
43.295634567, 96.390, 973.0, 31.1929
43.348155698, 96.390, 984.0, 31.3688
43.400676828, 96.390, 977.0, 31.2570
43.453197959, 96.390, 983.0, 31.3528
43.505719090, 96.390, 1005.0, 31.7017
43.558240221, 96.390, 1043.0, 32.2955
43.610761351, 96.390, 967.0, 31.0966
43.663282482, 96.390, 1043.0, 32.2955
43.715803613, 96.390, 1018.0, 31.9061
43.768324743, 96.390, 991.0, 31.4802
43.820845874, 96.390, 1045.0, 32.3265
43.873367005, 96.390, 930.0, 30.4959
43.925888136, 96.390, 1042.0, 32.2800
43.978409266, 96.390, 981.0, 31.3209
44.030930397, 96.390, 1002.0, 31.6544
44.083451528, 96.390, 972.0, 31.1769
44.135972658, 96.390, 1052.0, 32.4345
44.188493789, 96.390, 1025.0, 32.0156
44.241014920, 96.390, 1032.0, 32.1248
44.293536051, 96.390, 1042.0, 32.2800
44.346057181, 96.390, 1004.0, 31.6860
44.398578312, 96.390, 1002.0, 31.6544
44.451099443, 96.390, 1024.0, 32.0000
44.503620573, 96.390, 1050.0, 32.4037
44.556141704, 96.390, 1022.0, 31.9687
44.608662835, 96.390, 1092.0, 33.0454
44.661183966, 96.390, 1057.0, 32.5115
44.713705096, 96.390, 1032.0, 32.1248
44.766226227, 96.390, 1040.0, 32.2490
44.818747358, 96.390, 1033.0, 32.1403
44.871268488, 96.390, 996.0, 31.5595
44.923789619, 96.390, 1069.0, 32.6956
44.976310750, 96.390, 975.0, 31.2250
45.028831880, 96.390, 1006.0, 31.7175
45.081353011, 96.390, 938.0, 30.6268
45.133874142, 96.390, 955.0, 30.9031
45.186395273, 96.390, 1038.0, 32.2180
45.238916403, 96.390, 949.0, 30.8058
45.291437534, 96.390, 967.0, 31.0966
45.343958665, 96.390, 935.0, 30.5778
45.396479795, 96.390, 915.0, 30.2490
45.449000926, 96.390, 963.0, 31.0322
45.501522057, 96.390, 859.0, 29.3087
45.554043188, 96.390, 909.0, 30.1496
45.606564318, 96.390, 923.0, 30.3809
45.659085449, 96.390, 874.0, 29.5635
45.711606580, 96.390, 838.0, 28.9482
45.764127710, 96.390, 899.0, 29.9833
45.816648841, 96.390, 872.0, 29.5296
45.869169972, 96.390, 926.0, 30.4302
45.921691103, 96.390, 940.0, 30.6594
45.974212233, 96.390, 919.0, 30.3150
46.026733364, 96.390, 905.0, 30.0832
46.079254495, 96.390, 845.0, 29.0689
46.131775625, 96.390, 939.0, 30.6431
46.184296756, 96.390, 929.0, 30.4795
46.236817887, 96.390, 910.0, 30.1662
46.289339017, 96.390, 927.0, 30.4467
46.341860148, 96.390, 904.0, 30.0666
46.394381279, 96.390, 887.0, 29.7825
46.446902410, 96.390, 866.0, 29.4279
46.499423540, 96.390, 930.0, 30.4959
46.551944671, 96.390, 858.0, 29.2916
46.604465802, 96.390, 906.0, 30.0998
46.656986932, 96.390, 855.0, 29.2404
46.709508063, 96.390, 838.0, 28.9482
46.762029194, 96.390, 847.0, 29.1033
46.814550325, 96.390, 877.0, 29.6142
46.867071455, 96.390, 835.0, 28.8964
46.919592586, 96.390, 848.0, 29.1204
46.972113717, 96.390, 809.0, 28.4429
47.024634847, 96.390, 878.0, 29.6311
47.077155978, 96.390, 916.0, 30.2655
47.129677109, 96.390, 866.0, 29.4279
47.182198240, 96.390, 871.0, 29.5127
47.234719370, 96.390, 823.0, 28.6880
47.287240501, 96.390, 837.0, 28.9310
47.339761632, 96.390, 853.0, 29.2062
47.392282762, 96.390, 841.0, 29.0000
47.444803893, 96.390, 849.0, 29.1376
47.497325024, 96.390, 882.0, 29.6985
47.549846155, 96.390, 836.0, 28.9137
47.602367285, 96.390, 835.0, 28.8964
47.654888416, 96.390, 853.0, 29.2062
47.707409547, 96.390, 805.0, 28.3725
47.759930677, 96.390, 934.0, 30.5614
47.812451808, 96.390, 807.0, 28.4077
47.864972939, 96.390, 821.0, 28.6531
47.917494069, 96.390, 859.0, 29.3087
47.970015200, 96.390, 848.0, 29.1204
48.022536331, 96.390, 802.0, 28.3196
48.075057462, 96.390, 864.0, 29.3939
48.127578592, 96.390, 815.0, 28.5482
48.180099723, 96.390, 848.0, 29.1204
48.232620854, 96.390, 840.0, 28.9828
48.285141984, 96.390, 911.0, 30.1828
48.337663115, 96.390, 866.0, 29.4279
48.390184246, 96.390, 851.0, 29.1719
48.442705377, 96.390, 867.0, 29.4449
48.495226507, 96.390, 771.0, 27.7669
48.547747638, 96.390, 900.0, 30.0000
48.600268769, 96.390, 813.0, 28.5132
48.652789899, 96.390, 848.0, 29.1204
48.705311030, 96.390, 846.0, 29.0861
48.757832161, 96.390, 896.0, 29.9333
48.810353292, 96.390, 908.0, 30.1330
48.862874422, 96.390, 861.0, 29.3428
48.915395553, 96.390, 926.0, 30.4302
48.967916684, 96.390, 886.0, 29.7658
49.020437814, 96.390, 885.0, 29.7489
49.072958945, 96.390, 927.0, 30.4467
49.125480076, 96.390, 865.0, 29.4109
49.178001207, 96.390, 913.0, 30.2159
49.230522337, 96.390, 872.0, 29.5296
49.283043468, 96.390, 876.0, 29.5973
49.335564599, 96.390, 831.0, 28.8271
49.388085729, 96.390, 899.0, 29.9833
49.440606860, 96.390, 799.0, 28.2666
49.493127991, 96.390, 855.0, 29.2404
49.545649121, 96.390, 875.0, 29.5804
49.598170252, 96.390, 837.0, 28.9310
49.650691383, 96.390, 865.0, 29.4109
49.703212514, 96.390, 818.0, 28.6007
49.755733644, 96.390, 836.0, 28.9137
49.808254775, 96.390, 810.0, 28.4605
49.860775906, 96.390, 846.0, 29.0861
49.913297036, 96.390, 813.0, 28.5132
49.965818167, 96.390, 773.0, 27.8029
50.018339298, 96.390, 770.0, 27.7489
50.070860429, 96.390, 892.0, 29.8664
50.123381559, 96.390, 832.0, 28.8444
50.175902690, 96.390, 768.0, 27.7128
50.228423821, 96.390, 863.0, 29.3769
50.280944951, 96.390, 843.0, 29.0345
50.333466082, 96.390, 731.0, 27.0370
50.385987213, 96.390, 834.0, 28.8791
50.438508344, 96.390, 848.0, 29.1204
50.491029474, 96.390, 800.0, 28.2843
50.543550605, 96.390, 847.0, 29.1033
50.596071736, 96.390, 860.0, 29.3258
50.648592866, 96.390, 804.0, 28.3549
50.701113997, 96.390, 799.0, 28.2666
50.753635128, 96.390, 857.0, 29.2746
50.806156258, 96.390, 864.0, 29.3939
50.858677389, 96.390, 817.0, 28.5832
50.911198520, 96.390, 804.0, 28.3549
50.963719651, 96.390, 826.0, 28.7402
51.016240781, 96.390, 780.0, 27.9285
51.068761912, 96.390, 876.0, 29.5973
51.121283043, 96.390, 811.0, 28.4781
51.173804173, 96.390, 769.0, 27.7308
51.226325304, 96.390, 766.0, 27.6767
51.278846435, 96.390, 801.0, 28.3019
51.331367566, 96.390, 752.0, 27.4226
51.383888696, 96.390, 764.0, 27.6405
51.436409827, 96.390, 778.0, 27.8927
51.488930958, 96.390, 781.0, 27.9464
51.541452088, 96.390, 759.0, 27.5500
51.593973219, 96.390, 773.0, 27.8029
51.646494350, 96.390, 828.0, 28.7750
51.699015481, 96.390, 771.0, 27.7669
51.751536611, 96.390, 775.0, 27.8388
51.804057742, 96.390, 747.0, 27.3313
51.856578873, 96.390, 744.0, 27.2764
51.909100003, 96.390, 713.0, 26.7021
51.961621134, 96.390, 749.0, 27.3679
52.014142265, 96.390, 730.0, 27.0185
52.066663396, 96.390, 733.0, 27.0740
52.119184526, 96.390, 800.0, 28.2843
52.171705657, 96.390, 727.0, 26.9629
52.224226788, 96.390, 750.0, 27.3861
52.276747918, 96.390, 697.0, 26.4008
52.329269049, 96.390, 778.0, 27.8927
52.381790180, 96.390, 769.0, 27.7308
52.434311310, 96.390, 748.0, 27.3496
52.486832441, 96.390, 742.0, 27.2397
52.539353572, 96.390, 726.0, 26.9444
52.591874703, 96.390, 758.0, 27.5318
52.644395833, 96.390, 727.0, 26.9629
52.696916964, 96.390, 739.0, 27.1846
52.749438095, 96.390, 752.0, 27.4226
52.801959225, 96.390, 760.0, 27.5681
52.854480356, 96.390, 747.0, 27.3313
52.907001487, 96.390, 788.0, 28.0713
52.959522618, 96.390, 780.0, 27.9285
53.012043748, 96.390, 805.0, 28.3725
53.064564879, 96.390, 800.0, 28.2843
53.117086010, 96.390, 801.0, 28.3019
53.169607140, 96.390, 800.0, 28.2843
53.222128271, 96.390, 835.0, 28.8964
53.274649402, 96.390, 810.0, 28.4605
53.327170533, 96.390, 831.0, 28.8271
53.379691663, 96.390, 712.0, 26.6833
53.432212794, 96.390, 734.0, 27.0924
53.484733925, 96.390, 778.0, 27.8927
53.537255055, 96.390, 760.0, 27.5681
53.589776186, 96.390, 764.0, 27.6405
53.642297317, 96.390, 767.0, 27.6948
53.694818448, 96.390, 733.0, 27.0740
53.747339578, 96.390, 700.0, 26.4575
53.799860709, 96.390, 780.0, 27.9285
53.852381840, 96.390, 784.0, 28.0000
53.904902970, 96.390, 786.0, 28.0357
53.957424101, 96.390, 756.0, 27.4955
54.009945232, 96.390, 752.0, 27.4226
54.062466362, 96.390, 774.0, 27.8209
54.114987493, 96.390, 808.0, 28.4253
54.167508624, 96.390, 758.0, 27.5318
54.220029755, 96.390, 751.0, 27.4044
54.272550885, 96.390, 730.0, 27.0185
54.325072016, 96.390, 776.0, 27.8568
54.377593147, 96.390, 782.0, 27.9643
54.430114277, 96.390, 776.0, 27.8568
54.482635408, 96.390, 794.0, 28.1780
54.535156539, 96.390, 768.0, 27.7128
54.587677670, 96.390, 763.0, 27.6225
54.640198800, 96.390, 804.0, 28.3549
54.692719931, 96.390, 778.0, 27.8927
54.745241062, 96.390, 725.0, 26.9258
54.797762192, 96.390, 720.0, 26.8328
54.850283323, 96.390, 732.0, 27.0555
54.902804454, 96.390, 751.0, 27.4044
54.955325585, 96.390, 778.0, 27.8927
55.007846715, 96.390, 744.0, 27.2764
55.060367846, 96.390, 732.0, 27.0555
55.112888977, 96.390, 774.0, 27.8209
55.165410107, 96.390, 731.0, 27.0370
55.217931238, 96.390, 835.0, 28.8964
55.270452369, 96.390, 775.0, 27.8388
55.322973499, 96.390, 730.0, 27.0185
55.375494630, 96.390, 809.0, 28.4429
55.428015761, 96.390, 803.0, 28.3373
55.480536892, 96.390, 754.0, 27.4591
55.533058022, 96.390, 842.0, 29.0172
55.585579153, 96.390, 750.0, 27.3861
55.638100284, 96.390, 757.0, 27.5136
55.690621414, 96.390, 777.0, 27.8747
55.743142545, 96.390, 795.0, 28.1957
55.795663676, 96.390, 743.0, 27.2580
55.848184807, 96.390, 822.0, 28.6705
55.900705937, 96.390, 752.0, 27.4226
55.953227068, 96.390, 789.0, 28.0891
56.005748199, 96.390, 737.0, 27.1477
56.058269329, 96.390, 715.0, 26.7395
56.110790460, 96.390, 780.0, 27.9285
56.163311591, 96.390, 770.0, 27.7489
56.215832722, 96.390, 710.0, 26.6458
56.268353852, 96.390, 710.0, 26.6458
56.320874983, 96.390, 736.0, 27.1293
56.373396114, 96.390, 733.0, 27.0740
56.425917244, 96.390, 712.0, 26.6833
56.478438375, 96.390, 775.0, 27.8388
56.530959506, 96.390, 687.0, 26.2107
56.583480637, 96.390, 717.0, 26.7769
56.636001767, 96.390, 720.0, 26.8328
56.688522898, 96.390, 779.0, 27.9106
56.741044029, 96.390, 740.0, 27.2029
56.793565159, 96.390, 690.0, 26.2679
56.846086290, 96.390, 755.0, 27.4773
56.898607421, 96.390, 699.0, 26.4386
56.951128551, 96.390, 727.0, 26.9629
57.003649682, 96.390, 689.0, 26.2488
57.056170813, 96.390, 756.0, 27.4955
57.108691944, 96.390, 695.0, 26.3629
57.161213074, 96.390, 754.0, 27.4591
57.213734205, 96.390, 732.0, 27.0555
57.266255336, 96.390, 750.0, 27.3861
57.318776466, 96.390, 718.0, 26.7955
57.371297597, 96.390, 705.0, 26.5518
57.423818728, 96.390, 667.0, 25.8263
57.476339859, 96.390, 681.0, 26.0960
57.528860989, 96.390, 724.0, 26.9072
57.581382120, 96.390, 732.0, 27.0555
57.633903251, 96.390, 748.0, 27.3496
57.686424381, 96.390, 746.0, 27.3130
57.738945512, 96.390, 778.0, 27.8927
57.791466643, 96.390, 711.0, 26.6646
57.843987774, 96.390, 726.0, 26.9444
57.896508904, 96.390, 764.0, 27.6405
57.949030035, 96.390, 736.0, 27.1293
58.001551166, 96.390, 751.0, 27.4044
58.054072296, 96.390, 765.0, 27.6586
58.106593427, 96.390, 784.0, 28.0000
58.159114558, 96.390, 706.0, 26.5707
58.211635689, 96.390, 714.0, 26.7208
58.264156819, 96.390, 715.0, 26.7395
58.316677950, 96.390, 663.0, 25.7488
58.369199081, 96.390, 735.0, 27.1109
58.421720211, 96.390, 700.0, 26.4575
58.474241342, 96.390, 683.0, 26.1343
58.526762473, 96.390, 748.0, 27.3496
58.579283603, 96.390, 686.0, 26.1916
58.631804734, 96.390, 713.0, 26.7021
58.684325865, 96.390, 735.0, 27.1109
58.736846996, 96.390, 721.0, 26.8514
58.789368126, 96.390, 733.0, 27.0740
58.841889257, 96.390, 732.0, 27.0555
58.894410388, 96.390, 718.0, 26.7955
58.946931518, 96.390, 673.0, 25.9422
58.999452649, 96.390, 666.0, 25.8070
59.051973780, 96.390, 712.0, 26.6833
59.104494911, 96.390, 679.0, 26.0576
59.157016041, 96.390, 690.0, 26.2679
59.209537172, 96.390, 679.0, 26.0576
59.262058303, 96.390, 697.0, 26.4008
59.314579433, 96.390, 691.0, 26.2869
59.367100564, 96.390, 634.0, 25.1794
59.419621695, 96.390, 725.0, 26.9258
59.472142826, 96.390, 680.0, 26.0768
59.524663956, 96.390, 646.0, 25.4165
59.577185087, 96.390, 762.0, 27.6043
59.629706218, 96.390, 749.0, 27.3679
59.682227348, 96.390, 722.0, 26.8701
59.734748479, 96.390, 679.0, 26.0576
59.787269610, 96.390, 694.0, 26.3439
59.839790740, 96.390, 654.0, 25.5734
59.892311871, 96.390, 687.0, 26.2107
59.944833002, 96.390, 688.0, 26.2298
59.997354133, 96.390, 717.0, 26.7769
60.049875263, 96.390, 700.0, 26.4575
60.102396394, 96.390, 735.0, 27.1109
60.154917525, 96.390, 714.0, 26.7208
60.207438655, 96.390, 672.0, 25.9230
60.259959786, 96.390, 703.0, 26.5141
60.312480917, 96.390, 662.0, 25.7294
60.365002048, 96.390, 689.0, 26.2488
60.417523178, 96.390, 730.0, 27.0185
60.470044309, 96.390, 662.0, 25.7294
60.522565440, 96.390, 686.0, 26.1916
60.575086570, 96.390, 696.0, 26.3818
60.627607701, 96.390, 692.0, 26.3059
60.680128832, 96.390, 693.0, 26.3249
60.732649963, 96.390, 686.0, 26.1916
60.785171093, 96.390, 705.0, 26.5518
60.837692224, 96.390, 737.0, 27.1477
60.890213355, 96.390, 671.0, 25.9037
60.942734485, 96.390, 762.0, 27.6043
60.995255616, 96.390, 694.0, 26.3439
61.047776747, 96.390, 657.0, 25.6320
61.100297878, 96.390, 681.0, 26.0960
61.152819008, 96.390, 684.0, 26.1534
61.205340139, 96.390, 748.0, 27.3496
61.257861270, 96.390, 668.0, 25.8457
61.310382400, 96.390, 667.0, 25.8263
61.362903531, 96.390, 687.0, 26.2107
61.415424662, 96.390, 661.0, 25.7099
61.467945792, 96.390, 689.0, 26.2488
61.520466923, 96.390, 702.0, 26.4953
61.572988054, 96.390, 672.0, 25.9230
61.625509185, 96.390, 691.0, 26.2869
61.678030315, 96.390, 687.0, 26.2107
61.730551446, 96.390, 657.0, 25.6320
61.783072577, 96.390, 679.0, 26.0576
61.835593707, 96.390, 706.0, 26.5707
61.888114838, 96.390, 708.0, 26.6083
61.940635969, 96.390, 674.0, 25.9615
61.993157100, 96.390, 683.0, 26.1343
62.045678230, 96.390, 671.0, 25.9037
62.098199361, 96.390, 700.0, 26.4575
62.150720492, 96.390, 701.0, 26.4764
62.203241622, 96.390, 716.0, 26.7582
62.255762753, 96.390, 687.0, 26.2107
62.308283884, 96.390, 646.0, 25.4165
62.360805015, 96.390, 697.0, 26.4008
62.413326145, 96.390, 639.0, 25.2784
62.465847276, 96.390, 693.0, 26.3249
62.518368407, 96.390, 682.0, 26.1151
62.570889537, 96.390, 700.0, 26.4575
62.623410668, 96.390, 663.0, 25.7488
62.675931799, 96.390, 707.0, 26.5895
62.728452930, 96.390, 653.0, 25.5539
62.780974060, 96.390, 657.0, 25.6320
62.833495191, 96.390, 639.0, 25.2784
62.886016322, 96.390, 649.0, 25.4755
62.938537452, 96.390, 647.0, 25.4362
62.991058583, 96.390, 651.0, 25.5147
63.043579714, 96.390, 647.0, 25.4362
63.096100844, 96.390, 658.0, 25.6515
63.148621975, 96.390, 654.0, 25.5734
63.201143106, 96.390, 640.0, 25.2982
63.253664237, 96.390, 619.0, 24.8797
63.306185367, 96.390, 660.0, 25.6905
63.358706498, 96.390, 610.0, 24.6982
63.411227629, 96.390, 644.0, 25.3772
63.463748759, 96.390, 656.0, 25.6125
63.516269890, 96.390, 574.0, 23.9583
63.568791021, 96.390, 636.0, 25.2190
63.621312152, 96.390, 641.0, 25.3180
63.673833282, 96.390, 612.0, 24.7386
63.726354413, 96.390, 637.0, 25.2389
63.778875544, 96.390, 641.0, 25.3180
63.831396674, 96.390, 588.0, 24.2487
63.883917805, 96.390, 621.0, 24.9199
63.936438936, 96.390, 647.0, 25.4362
63.988960067, 96.390, 645.0, 25.3969
64.041481197, 96.390, 600.0, 24.4949
64.094002328, 96.390, 626.0, 25.0200
64.146523459, 96.390, 636.0, 25.2190
64.199044589, 96.390, 624.0, 24.9800
64.251565720, 96.390, 594.0, 24.3721
64.304086851, 96.390, 635.0, 25.1992
64.356607981, 96.390, 605.0, 24.5967
64.409129112, 96.390, 586.0, 24.2074
64.461650243, 96.390, 571.0, 23.8956
64.514171374, 96.390, 654.0, 25.5734
64.566692504, 96.390, 591.0, 24.3105
64.619213635, 96.390, 563.0, 23.7276
64.671734766, 96.390, 596.0, 24.4131
64.724255896, 96.390, 551.0, 23.4734
64.776777027, 96.390, 622.0, 24.9399
64.829298158, 96.390, 610.0, 24.6982
64.881819289, 96.390, 631.0, 25.1197
64.934340419, 96.390, 562.0, 23.7065
64.986861550, 96.390, 602.0, 24.5357