File: Files_organized_for_plots/Constant_NaOH_1mL10M_to_1gPC_28Day_repeat/PO4Free14Apr22_Act12Feb23_B1_1000M_NaOH_LS0133_Num159.csv
[Measurement conditions]
Sample identification,PO4Free14Apr22_Act12Feb23_B1_1000M_NaOH_LS0133_Num159
Comment - 1,"Configuration=Stage for Flat Samples/Holders, Owner=nmw10, Creation date=9/21/2022 10:06:30 AM"
Comment - 2,"Goniometer=Theta/Theta; Minimum step size 2Theta:0.0001; Minimum step size Omega:0.0001"
Comment - 3,"Sample stage=Stage for flat samples/holders"
Comment - 4,"Diffractometer system=EMPYREAN"
Comment - 5,"Measurement program=X:\XRD\Cement\Zerobackground scan.xrdmp, Created identifier={98A3B11C-88F9-4AA6-982C-73314A311EF5}, Created by=Titus Reed, Id=tmr79, Creation date=10/26/2021 3:01:47 PM"
Anode material,Cu
K-Alpha1 wavelength,1.5405980
K-Alpha2 wavelength,1.5444260
Ratio K-Alpha2/K-Alpha1,0.500
Divergence slit,Fixed,0.25
Monochromator used,NO
Generator voltage, 45
Tube current, 40
File date and time,15/Mar/2023 20:55
Unit cell,
h k l, 0 0 0
Scan axis,Gonio
Scan range,4.994599997,64.999991833
Scan step size,0.0262606
No. of points, 2285
Scan type,CONTINUOUS
Time per step,96.390
[Scan points]
Angle, TimePerStep, Intensity, ESD
5.007730280, 96.390, 4697.0, 68.5347
5.060251411, 96.390, 4740.0, 68.8477
5.112772541, 96.390, 4837.0, 69.5485
5.165293672, 96.390, 4645.0, 68.1542
5.217814803, 96.390, 4742.0, 68.8622
5.270335934, 96.390, 4846.0, 69.6132
5.322857064, 96.390, 4813.0, 69.3758
5.375378195, 96.390, 4844.0, 69.5989
5.427899326, 96.390, 4855.0, 69.6778
5.480420456, 96.390, 5069.0, 71.1969
5.532941587, 96.390, 5013.0, 70.8025
5.585462718, 96.390, 5251.0, 72.4638
5.637983849, 96.390, 5373.0, 73.3008
5.690504979, 96.390, 5712.0, 75.5778
5.743026110, 96.390, 5998.0, 77.4468
5.795547241, 96.390, 6391.0, 79.9437
5.848068371, 96.390, 6207.0, 78.7845
5.900589502, 96.390, 6397.0, 79.9812
5.953110633, 96.390, 6223.0, 78.8860
6.005631763, 96.390, 6344.0, 79.6492
6.058152894, 96.390, 6299.0, 79.3662
6.110674025, 96.390, 6496.0, 80.5978
6.163195156, 96.390, 6303.0, 79.3914
6.215716286, 96.390, 6159.0, 78.4793
6.268237417, 96.390, 5992.0, 77.4080
6.320758548, 96.390, 6028.0, 77.6402
6.373279678, 96.390, 5778.0, 76.0132
6.425800809, 96.390, 5775.0, 75.9934
6.478321940, 96.390, 5545.0, 74.4648
6.530843071, 96.390, 5566.0, 74.6056
6.583364201, 96.390, 5379.0, 73.3417
6.635885332, 96.390, 5140.0, 71.6938
6.688406463, 96.390, 5270.0, 72.5948
6.740927593, 96.390, 5055.0, 71.0985
6.793448724, 96.390, 4933.0, 70.2353
6.845969855, 96.390, 4784.0, 69.1665
6.898490986, 96.390, 4825.0, 69.4622
6.951012116, 96.390, 4783.0, 69.1592
7.003533247, 96.390, 4689.0, 68.4763
7.056054378, 96.390, 4641.0, 68.1249
7.108575508, 96.390, 4492.0, 67.0224
7.161096639, 96.390, 4482.0, 66.9477
7.213617770, 96.390, 4335.0, 65.8407
7.266138900, 96.390, 4452.0, 66.7233
7.318660031, 96.390, 4281.0, 65.4294
7.371181162, 96.390, 4326.0, 65.7723
7.423702293, 96.390, 4058.0, 63.7024
7.476223423, 96.390, 3980.0, 63.0872
7.528744554, 96.390, 3995.0, 63.2060
7.581265685, 96.390, 4023.0, 63.4271
7.633786815, 96.390, 3933.0, 62.7136
7.686307946, 96.390, 3922.0, 62.6259
7.738829077, 96.390, 3785.0, 61.5224
7.791350208, 96.390, 3764.0, 61.3514
7.843871338, 96.390, 3789.0, 61.5549
7.896392469, 96.390, 3570.0, 59.7495
7.948913600, 96.390, 3592.0, 59.9333
8.001434730, 96.390, 3543.0, 59.5231
8.053955861, 96.390, 3506.0, 59.2115
8.106476992, 96.390, 3466.0, 58.8727
8.158998123, 96.390, 3504.0, 59.1946
8.211519253, 96.390, 3493.0, 59.1016
8.264040384, 96.390, 3354.0, 57.9137
8.316561515, 96.390, 3309.0, 57.5239
8.369082645, 96.390, 3368.0, 58.0345
8.421603776, 96.390, 3251.0, 57.0175
8.474124907, 96.390, 3314.0, 57.5674
8.526646038, 96.390, 3178.0, 56.3738
8.579167168, 96.390, 3282.0, 57.2887
8.631688299, 96.390, 3265.0, 57.1402
8.684209430, 96.390, 3059.0, 55.3082
8.736730560, 96.390, 2996.0, 54.7357
8.789251691, 96.390, 3098.0, 55.6597
8.841772822, 96.390, 3059.0, 55.3082
8.894293952, 96.390, 3003.0, 54.7996
8.946815083, 96.390, 3109.0, 55.7584
8.999336214, 96.390, 3033.0, 55.0727
9.051857345, 96.390, 3054.0, 55.2630
9.104378475, 96.390, 2988.0, 54.6626
9.156899606, 96.390, 3090.0, 55.5878
9.209420737, 96.390, 2969.0, 54.4885
9.261941867, 96.390, 2977.0, 54.5619
9.314462998, 96.390, 3038.0, 55.1181
9.366984129, 96.390, 2945.0, 54.2679
9.419505260, 96.390, 3073.0, 55.4346
9.472026390, 96.390, 2948.0, 54.2955
9.524547521, 96.390, 3027.0, 55.0182
9.577068652, 96.390, 2954.0, 54.3507
9.629589782, 96.390, 2973.0, 54.5252
9.682110913, 96.390, 3047.0, 55.1996
9.734632044, 96.390, 3103.0, 55.7046
9.787153175, 96.390, 3124.0, 55.8928
9.839674305, 96.390, 3148.0, 56.1070
9.892195436, 96.390, 3315.0, 57.5760
9.944716567, 96.390, 3557.0, 59.6406
9.997237697, 96.390, 3742.0, 61.1719
10.049758828, 96.390, 3497.0, 59.1354
10.102279959, 96.390, 3235.0, 56.8771
10.154801090, 96.390, 3211.0, 56.6657
10.207322220, 96.390, 3105.0, 55.7225
10.259843351, 96.390, 3095.0, 55.6327
10.312364482, 96.390, 3031.0, 55.0545
10.364885612, 96.390, 3052.0, 55.2449
10.417406743, 96.390, 3018.0, 54.9363
10.469927874, 96.390, 3040.0, 55.1362
10.522449004, 96.390, 3095.0, 55.6327
10.574970135, 96.390, 3118.0, 55.8391
10.627491266, 96.390, 3033.0, 55.0727
10.680012397, 96.390, 3106.0, 55.7315
10.732533527, 96.390, 3203.0, 56.5951
10.785054658, 96.390, 3196.0, 56.5332
10.837575789, 96.390, 3232.0, 56.8507
10.890096919, 96.390, 3308.0, 57.5152
10.942618050, 96.390, 3302.0, 57.4630
10.995139181, 96.390, 3423.0, 58.5064
11.047660312, 96.390, 3429.0, 58.5577
11.100181442, 96.390, 3499.0, 59.1523
11.152702573, 96.390, 3561.0, 59.6741
11.205223704, 96.390, 3701.0, 60.8358
11.257744834, 96.390, 4017.0, 63.3798
11.310265965, 96.390, 4241.0, 65.1230
11.362787096, 96.390, 4230.0, 65.0385
11.415308227, 96.390, 4523.0, 67.2533
11.467829357, 96.390, 4805.0, 69.3181
11.520350488, 96.390, 5005.0, 70.7460
11.572871619, 96.390, 5316.0, 72.9109
11.625392749, 96.390, 5363.0, 73.2325
11.677913880, 96.390, 5185.0, 72.0069
11.730435011, 96.390, 5132.0, 71.6380
11.782956141, 96.390, 4900.0, 70.0000
11.835477272, 96.390, 4614.0, 67.9264
11.887998403, 96.390, 4207.0, 64.8614
11.940519534, 96.390, 3944.0, 62.8013
11.993040664, 96.390, 3708.0, 60.8933
12.045561795, 96.390, 3517.0, 59.3043
12.098082926, 96.390, 3326.0, 57.6715
12.150604056, 96.390, 3166.0, 56.2672
12.203125187, 96.390, 3091.0, 55.5968
12.255646318, 96.390, 2863.0, 53.5070
12.308167449, 96.390, 2859.0, 53.4696
12.360688579, 96.390, 2704.0, 52.0000
12.413209710, 96.390, 2685.0, 51.8170
12.465730841, 96.390, 2597.0, 50.9608
12.518251971, 96.390, 2500.0, 50.0000
12.570773102, 96.390, 2487.0, 49.8698
12.623294233, 96.390, 2433.0, 49.3254
12.675815364, 96.390, 2362.0, 48.6004
12.728336494, 96.390, 2346.0, 48.4355
12.780857625, 96.390, 2408.0, 49.0714
12.833378756, 96.390, 2303.0, 47.9896
12.885899886, 96.390, 2321.0, 48.1768
12.938421017, 96.390, 2271.0, 47.6550
12.990942148, 96.390, 2233.0, 47.2546
13.043463279, 96.390, 2197.0, 46.8722
13.095984409, 96.390, 2249.0, 47.4236
13.148505540, 96.390, 2178.0, 46.6690
13.201026671, 96.390, 2241.0, 47.3392
13.253547801, 96.390, 2179.0, 46.6798
13.306068932, 96.390, 2191.0, 46.8081
13.358590063, 96.390, 2104.0, 45.8694
13.411111193, 96.390, 2021.0, 44.9555
13.463632324, 96.390, 1998.0, 44.6990
13.516153455, 96.390, 2097.0, 45.7930
13.568674586, 96.390, 2103.0, 45.8585
13.621195716, 96.390, 2051.0, 45.2880
13.673716847, 96.390, 2113.0, 45.9674
13.726237978, 96.390, 2097.0, 45.7930
13.778759108, 96.390, 2095.0, 45.7712
13.831280239, 96.390, 2198.0, 46.8828
13.883801370, 96.390, 2275.0, 47.6970
13.936322501, 96.390, 2402.0, 49.0102
13.988843631, 96.390, 2763.0, 52.5642
14.041364762, 96.390, 2553.0, 50.5272
14.093885893, 96.390, 2249.0, 47.4236
14.146407023, 96.390, 2018.0, 44.9222
14.198928154, 96.390, 2100.0, 45.8258
14.251449285, 96.390, 1993.0, 44.6430
14.303970416, 96.390, 2027.0, 45.0222
14.356491546, 96.390, 1920.0, 43.8178
14.409012677, 96.390, 1985.0, 44.5533
14.461533808, 96.390, 1909.0, 43.6921
14.514054938, 96.390, 1865.0, 43.1856
14.566576069, 96.390, 1952.0, 44.1814
14.619097200, 96.390, 1878.0, 43.3359
14.671618331, 96.390, 1865.0, 43.1856
14.724139461, 96.390, 1962.0, 44.2945
14.776660592, 96.390, 1889.0, 43.4626
14.829181723, 96.390, 1963.0, 44.3058
14.881702853, 96.390, 1949.0, 44.1475
14.934223984, 96.390, 1964.0, 44.3170
14.986745115, 96.390, 2038.0, 45.1442
15.039266245, 96.390, 2104.0, 45.8694
15.091787376, 96.390, 2140.0, 46.2601
15.144308507, 96.390, 2378.0, 48.7647
15.196829638, 96.390, 2429.0, 49.2849
15.249350768, 96.390, 2670.0, 51.6720
15.301871899, 96.390, 2987.0, 54.6535
15.354393030, 96.390, 3023.0, 54.9818
15.406914160, 96.390, 3033.0, 55.0727
15.459435291, 96.390, 2987.0, 54.6535
15.511956422, 96.390, 2733.0, 52.2781
15.564477553, 96.390, 2606.0, 51.0490
15.616998683, 96.390, 2454.0, 49.5379
15.669519814, 96.390, 2298.0, 47.9375
15.722040945, 96.390, 2241.0, 47.3392
15.774562075, 96.390, 2032.0, 45.0777
15.827083206, 96.390, 2012.0, 44.8553
15.879604337, 96.390, 2040.0, 45.1664
15.932125468, 96.390, 1998.0, 44.6990
15.984646598, 96.390, 1888.0, 43.4511
16.037167729, 96.390, 1935.0, 43.9886
16.089688860, 96.390, 1830.0, 42.7785
16.142209990, 96.390, 1836.0, 42.8486
16.194731121, 96.390, 1814.0, 42.5911
16.247252252, 96.390, 1846.0, 42.9651
16.299773382, 96.390, 1748.0, 41.8091
16.352294513, 96.390, 1826.0, 42.7317
16.404815644, 96.390, 1837.0, 42.8602
16.457336775, 96.390, 1906.0, 43.6578
16.509857905, 96.390, 2022.0, 44.9667
16.562379036, 96.390, 1964.0, 44.3170
16.614900167, 96.390, 1813.0, 42.5793
16.667421297, 96.390, 1804.0, 42.4735
16.719942428, 96.390, 1792.0, 42.3320
16.772463559, 96.390, 1799.0, 42.4146
16.824984690, 96.390, 1874.0, 43.2897
16.877505820, 96.390, 1926.0, 43.8862
16.930026951, 96.390, 1911.0, 43.7150
16.982548082, 96.390, 1672.0, 40.8901
17.035069212, 96.390, 1684.0, 41.0366
17.087590343, 96.390, 1687.0, 41.0731
17.140111474, 96.390, 1634.0, 40.4228
17.192632605, 96.390, 1647.0, 40.5832
17.245153735, 96.390, 1592.0, 39.8999
17.297674866, 96.390, 1639.0, 40.4846
17.350195997, 96.390, 1639.0, 40.4846
17.402717127, 96.390, 1701.0, 41.2432
17.455238258, 96.390, 1650.0, 40.6202
17.507759389, 96.390, 1625.0, 40.3113
17.560280520, 96.390, 1585.0, 39.8121
17.612801650, 96.390, 1615.0, 40.1871
17.665322781, 96.390, 1576.0, 39.6989
17.717843912, 96.390, 1711.0, 41.3642
17.770365042, 96.390, 1696.0, 41.1825
17.822886173, 96.390, 1675.0, 40.9268
17.875407304, 96.390, 1635.0, 40.4351
17.927928434, 96.390, 1636.0, 40.4475
17.980449565, 96.390, 1672.0, 40.8901
18.032970696, 96.390, 1645.0, 40.5586
18.085491827, 96.390, 1702.0, 41.2553
18.138012957, 96.390, 1574.0, 39.6737
18.190534088, 96.390, 1723.0, 41.5090
18.243055219, 96.390, 1706.0, 41.3038
18.295576349, 96.390, 1731.0, 41.6053
18.348097480, 96.390, 1725.0, 41.5331
18.400618611, 96.390, 1751.0, 41.8450
18.453139742, 96.390, 1735.0, 41.6533
18.505660872, 96.390, 1727.0, 41.5572
18.558182003, 96.390, 1790.0, 42.3084
18.610703134, 96.390, 1717.0, 41.4367
18.663224264, 96.390, 1761.0, 41.9643
18.715745395, 96.390, 1641.0, 40.5093
18.768266526, 96.390, 1751.0, 41.8450
18.820787657, 96.390, 1716.0, 41.4246
18.873308787, 96.390, 1772.0, 42.0951
18.925829918, 96.390, 1671.0, 40.8779
18.978351049, 96.390, 1737.0, 41.6773
19.030872179, 96.390, 1779.0, 42.1782
19.083393310, 96.390, 1782.0, 42.2137
19.135914441, 96.390, 1786.0, 42.2611
19.188435572, 96.390, 1760.0, 41.9524
19.240956702, 96.390, 1789.0, 42.2966
19.293477833, 96.390, 1709.0, 41.3401
19.345998964, 96.390, 1624.0, 40.2989
19.398520094, 96.390, 1729.0, 41.5812
19.451041225, 96.390, 1739.0, 41.7013
19.503562356, 96.390, 1673.0, 40.9023
19.556083486, 96.390, 1723.0, 41.5090
19.608604617, 96.390, 1689.0, 41.0974
19.661125748, 96.390, 1769.0, 42.0595
19.713646879, 96.390, 1848.0, 42.9884
19.766168009, 96.390, 1905.0, 43.6463
19.818689140, 96.390, 1881.0, 43.3705
19.871210271, 96.390, 2002.0, 44.7437
19.923731401, 96.390, 1995.0, 44.6654
19.976252532, 96.390, 2212.0, 47.0319
20.028773663, 96.390, 2352.0, 48.4974
20.081294794, 96.390, 2398.0, 48.9694
20.133815924, 96.390, 2216.0, 47.0744
20.186337055, 96.390, 2052.0, 45.2990
20.238858186, 96.390, 1912.0, 43.7264
20.291379316, 96.390, 1839.0, 42.8836
20.343900447, 96.390, 1774.0, 42.1189
20.396421578, 96.390, 1733.0, 41.6293
20.448942709, 96.390, 1772.0, 42.0951
20.501463839, 96.390, 1786.0, 42.2611
20.553984970, 96.390, 1719.0, 41.4608
20.606506101, 96.390, 1658.0, 40.7185
20.659027231, 96.390, 1711.0, 41.3642
20.711548362, 96.390, 1647.0, 40.5832
20.764069493, 96.390, 1727.0, 41.5572
20.816590623, 96.390, 1849.0, 43.0000
20.869111754, 96.390, 1656.0, 40.6940
20.921632885, 96.390, 1776.0, 42.1426
20.974154016, 96.390, 1722.0, 41.4970
21.026675146, 96.390, 1808.0, 42.5206
21.079196277, 96.390, 1816.0, 42.6146
21.131717408, 96.390, 1784.0, 42.2374
21.184238538, 96.390, 1768.0, 42.0476
21.236759669, 96.390, 1864.0, 43.1741
21.289280800, 96.390, 1653.0, 40.6571
21.341801931, 96.390, 1769.0, 42.0595
21.394323061, 96.390, 1810.0, 42.5441
21.446844192, 96.390, 1818.0, 42.6380
21.499365323, 96.390, 1869.0, 43.2319
21.551886453, 96.390, 1845.0, 42.9535
21.604407584, 96.390, 1775.0, 42.1307
21.656928715, 96.390, 1934.0, 43.9773
21.709449846, 96.390, 1805.0, 42.4853
21.761970976, 96.390, 1805.0, 42.4853
21.814492107, 96.390, 1780.0, 42.1900
21.867013238, 96.390, 1774.0, 42.1189
21.919534368, 96.390, 1754.0, 41.8808
21.972055499, 96.390, 1882.0, 43.3820
22.024576630, 96.390, 1873.0, 43.2782
22.077097761, 96.390, 1888.0, 43.4511
22.129618891, 96.390, 1910.0, 43.7035
22.182140022, 96.390, 1958.0, 44.2493
22.234661153, 96.390, 1946.0, 44.1135
22.287182283, 96.390, 2015.0, 44.8888
22.339703414, 96.390, 1951.0, 44.1701
22.392224545, 96.390, 2066.0, 45.4533
22.444745675, 96.390, 2059.0, 45.3762
22.497266806, 96.390, 2091.0, 45.7275
22.549787937, 96.390, 2187.0, 46.7654
22.602309068, 96.390, 2182.0, 46.7119
22.654830198, 96.390, 2298.0, 47.9375
22.707351329, 96.390, 2361.0, 48.5901
22.759872460, 96.390, 2440.0, 49.3964
22.812393590, 96.390, 2488.0, 49.8799
22.864914721, 96.390, 2670.0, 51.6720
22.917435852, 96.390, 2752.0, 52.4595
22.969956983, 96.390, 2937.0, 54.1941
23.022478113, 96.390, 3103.0, 55.7046
23.074999244, 96.390, 3386.0, 58.1893
23.127520375, 96.390, 3714.0, 60.9426
23.180041505, 96.390, 4013.0, 63.3482
23.232562636, 96.390, 4340.0, 65.8787
23.285083767, 96.390, 4433.0, 66.5808
23.337604898, 96.390, 4272.0, 65.3605
23.390126028, 96.390, 3952.0, 62.8649
23.442647159, 96.390, 3797.0, 61.6198
23.495168290, 96.390, 3589.0, 59.9083
23.547689420, 96.390, 3416.0, 58.4466
23.600210551, 96.390, 3317.0, 57.5934
23.652731682, 96.390, 3083.0, 55.5248
23.705252813, 96.390, 3011.0, 54.8726
23.757773943, 96.390, 2872.0, 53.5910
23.810295074, 96.390, 2603.0, 51.0196
23.862816205, 96.390, 2474.0, 49.7393
23.915337335, 96.390, 2434.0, 49.3356
23.967858466, 96.390, 2313.0, 48.0937
24.020379597, 96.390, 2340.0, 48.3735
24.072900727, 96.390, 2271.0, 47.6550
24.125421858, 96.390, 2190.0, 46.7974
24.177942989, 96.390, 2180.0, 46.6905
24.230464120, 96.390, 2342.0, 48.3942
24.282985250, 96.390, 2389.0, 48.8774
24.335506381, 96.390, 2764.0, 52.5738
24.388027512, 96.390, 2897.0, 53.8238
24.440548642, 96.390, 2560.0, 50.5964
24.493069773, 96.390, 2282.0, 47.7703
24.545590904, 96.390, 2141.0, 46.2709
24.598112035, 96.390, 2075.0, 45.5522
24.650633165, 96.390, 1983.0, 44.5309
24.703154296, 96.390, 1894.0, 43.5201
24.755675427, 96.390, 1922.0, 43.8406
24.808196557, 96.390, 1785.0, 42.2493
24.860717688, 96.390, 1841.0, 42.9069
24.913238819, 96.390, 1788.0, 42.2847
24.965759950, 96.390, 1787.0, 42.2729
25.018281080, 96.390, 1748.0, 41.8091
25.070802211, 96.390, 1778.0, 42.1663
25.123323342, 96.390, 1742.0, 41.7373
25.175844472, 96.390, 1724.0, 41.5211
25.228365603, 96.390, 1615.0, 40.1871
25.280886734, 96.390, 1714.0, 41.4005
25.333407864, 96.390, 1715.0, 41.4126
25.385928995, 96.390, 1676.0, 40.9390
25.438450126, 96.390, 1669.0, 40.8534
25.490971257, 96.390, 1635.0, 40.4351
25.543492387, 96.390, 1695.0, 41.1704
25.596013518, 96.390, 1733.0, 41.6293
25.648534649, 96.390, 1669.0, 40.8534
25.701055779, 96.390, 1655.0, 40.6817
25.753576910, 96.390, 1663.0, 40.7799
25.806098041, 96.390, 1658.0, 40.7185
25.858619172, 96.390, 1776.0, 42.1426
25.911140302, 96.390, 1715.0, 41.4126
25.963661433, 96.390, 1816.0, 42.6146
26.016182564, 96.390, 1826.0, 42.7317
26.068703694, 96.390, 1866.0, 43.1972
26.121224825, 96.390, 1786.0, 42.2611
26.173745956, 96.390, 1837.0, 42.8602
26.226267087, 96.390, 1890.0, 43.4741
26.278788217, 96.390, 2030.0, 45.0555
26.331309348, 96.390, 2158.0, 46.4543
26.383830479, 96.390, 2153.0, 46.4004
26.436351609, 96.390, 2299.0, 47.9479
26.488872740, 96.390, 2521.0, 50.2096
26.541393871, 96.390, 2918.0, 54.0185
26.593915002, 96.390, 3105.0, 55.7225
26.646436132, 96.390, 3236.0, 56.8859
26.698957263, 96.390, 3086.0, 55.5518
26.751478394, 96.390, 2776.0, 52.6878
26.803999524, 96.390, 2438.0, 49.3761
26.856520655, 96.390, 2298.0, 47.9375
26.909041786, 96.390, 2087.0, 45.6837
26.961562916, 96.390, 1994.0, 44.6542
27.014084047, 96.390, 1950.0, 44.1588
27.066605178, 96.390, 1808.0, 42.5206
27.119126309, 96.390, 1739.0, 41.7013
27.171647439, 96.390, 1798.0, 42.4028
27.224168570, 96.390, 1789.0, 42.2966
27.276689701, 96.390, 1778.0, 42.1663
27.329210831, 96.390, 1705.0, 41.2916
27.381731962, 96.390, 1633.0, 40.4104
27.434253093, 96.390, 1685.0, 41.0488
27.486774224, 96.390, 1754.0, 41.8808
27.539295354, 96.390, 1782.0, 42.2137
27.591816485, 96.390, 1737.0, 41.6773
27.644337616, 96.390, 1664.0, 40.7922
27.696858746, 96.390, 1681.0, 41.0000
27.749379877, 96.390, 1727.0, 41.5572
27.801901008, 96.390, 1626.0, 40.3237
27.854422139, 96.390, 1621.0, 40.2616
27.906943269, 96.390, 1639.0, 40.4846
27.959464400, 96.390, 1678.0, 40.9634
28.011985531, 96.390, 1740.0, 41.7133
28.064506661, 96.390, 1795.0, 42.3674
28.117027792, 96.390, 1801.0, 42.4382
28.169548923, 96.390, 1860.0, 43.1277
28.222070054, 96.390, 1713.0, 41.3884
28.274591184, 96.390, 1754.0, 41.8808
28.327112315, 96.390, 1718.0, 41.4488
28.379633446, 96.390, 1685.0, 41.0488
28.432154576, 96.390, 1712.0, 41.3763
28.484675707, 96.390, 1773.0, 42.1070
28.537196838, 96.390, 1764.0, 42.0000
28.589717968, 96.390, 1669.0, 40.8534
28.642239099, 96.390, 1763.0, 41.9881
28.694760230, 96.390, 1722.0, 41.4970
28.747281361, 96.390, 1797.0, 42.3910
28.799802491, 96.390, 1735.0, 41.6533
28.852323622, 96.390, 1777.0, 42.1545
28.904844753, 96.390, 1866.0, 43.1972
28.957365883, 96.390, 1862.0, 43.1509
29.009887014, 96.390, 1965.0, 44.3283
29.062408145, 96.390, 2050.0, 45.2769
29.114929276, 96.390, 2207.0, 46.9787
29.167450406, 96.390, 2245.0, 47.3814
29.219971537, 96.390, 2283.0, 47.7807
29.272492668, 96.390, 2257.0, 47.5079
29.325013798, 96.390, 2166.0, 46.5403
29.377534929, 96.390, 2153.0, 46.4004
29.430056060, 96.390, 2064.0, 45.4313
29.482577191, 96.390, 2062.0, 45.4093
29.535098321, 96.390, 2001.0, 44.7325
29.587619452, 96.390, 1975.0, 44.4410
29.640140583, 96.390, 1962.0, 44.2945
29.692661713, 96.390, 2033.0, 45.0888
29.745182844, 96.390, 1948.0, 44.1362
29.797703975, 96.390, 1846.0, 42.9651
29.850225105, 96.390, 1993.0, 44.6430
29.902746236, 96.390, 2008.0, 44.8107
29.955267367, 96.390, 2032.0, 45.0777
30.007788498, 96.390, 2026.0, 45.0111
30.060309628, 96.390, 2120.0, 46.0435
30.112830759, 96.390, 2091.0, 45.7275
30.165351890, 96.390, 2149.0, 46.3573
30.217873020, 96.390, 2170.0, 46.5833
30.270394151, 96.390, 2246.0, 47.3920
30.322915282, 96.390, 2242.0, 47.3498
30.375436413, 96.390, 2221.0, 47.1275
30.427957543, 96.390, 2291.0, 47.8644
30.480478674, 96.390, 2331.0, 48.2804
30.532999805, 96.390, 2385.0, 48.8365
30.585520935, 96.390, 2411.0, 49.1019
30.638042066, 96.390, 2517.0, 50.1697
30.690563197, 96.390, 2715.0, 52.1057
30.743084328, 96.390, 2940.0, 54.2218
30.795605458, 96.390, 2990.0, 54.6809
30.848126589, 96.390, 3281.0, 57.2800
30.900647720, 96.390, 3176.0, 56.3560
30.953168850, 96.390, 3208.0, 56.6392
31.005689981, 96.390, 2999.0, 54.7631
31.058211112, 96.390, 2836.0, 53.2541
31.110732243, 96.390, 2812.0, 53.0283
31.163253373, 96.390, 2604.0, 51.0294
31.215774504, 96.390, 2541.0, 50.4083
31.268295635, 96.390, 2438.0, 49.3761
31.320816765, 96.390, 2399.0, 48.9796
31.373337896, 96.390, 2321.0, 48.1768
31.425859027, 96.390, 2271.0, 47.6550
31.478380157, 96.390, 2235.0, 47.2758
31.530901288, 96.390, 2377.0, 48.7545
31.583422419, 96.390, 2453.0, 49.5278
31.635943550, 96.390, 2451.0, 49.5076
31.688464680, 96.390, 2321.0, 48.1768
31.740985811, 96.390, 2261.0, 47.5500
31.793506942, 96.390, 2272.0, 47.6655
31.846028072, 96.390, 2187.0, 46.7654
31.898549203, 96.390, 2197.0, 46.8722
31.951070334, 96.390, 2276.0, 47.7074
32.003591465, 96.390, 2262.0, 47.5605
32.056112595, 96.390, 2211.0, 47.0213
32.108633726, 96.390, 2216.0, 47.0744
32.161154857, 96.390, 2241.0, 47.3392
32.213675987, 96.390, 2449.0, 49.4874
32.266197118, 96.390, 2869.0, 53.5630
32.318718249, 96.390, 2880.0, 53.6656
32.371239380, 96.390, 2704.0, 52.0000
32.423760510, 96.390, 2672.0, 51.6914
32.476281641, 96.390, 2643.0, 51.4101
32.528802772, 96.390, 2400.0, 48.9898
32.581323902, 96.390, 2203.0, 46.9361
32.633845033, 96.390, 2060.0, 45.3872
32.686366164, 96.390, 1902.0, 43.6119
32.738887295, 96.390, 1920.0, 43.8178
32.791408425, 96.390, 1872.0, 43.2666
32.843929556, 96.390, 1818.0, 42.6380
32.896450687, 96.390, 1829.0, 42.7668
32.948971817, 96.390, 1896.0, 43.5431
33.001492948, 96.390, 1906.0, 43.6578
33.054014079, 96.390, 1873.0, 43.2782
33.106535209, 96.390, 1929.0, 43.9204
33.159056340, 96.390, 1991.0, 44.6206
33.211577471, 96.390, 2072.0, 45.5192
33.264098602, 96.390, 2068.0, 45.4753
33.316619732, 96.390, 2262.0, 47.5605
33.369140863, 96.390, 2335.0, 48.3218
33.421661994, 96.390, 2416.0, 49.1528
33.474183124, 96.390, 2410.0, 49.0918
33.526704255, 96.390, 2553.0, 50.5272
33.579225386, 96.390, 2646.0, 51.4393
33.631746517, 96.390, 2496.0, 49.9600
33.684267647, 96.390, 2318.0, 48.1456
33.736788778, 96.390, 2248.0, 47.4131
33.789309909, 96.390, 2053.0, 45.3100
33.841831039, 96.390, 2062.0, 45.4093
33.894352170, 96.390, 2099.0, 45.8148
33.946873301, 96.390, 2083.0, 45.6399
33.999394432, 96.390, 2086.0, 45.6727
34.051915562, 96.390, 2085.0, 45.6618
34.104436693, 96.390, 2276.0, 47.7074
34.156957824, 96.390, 2134.0, 46.1952
34.209478954, 96.390, 2284.0, 47.7912
34.262000085, 96.390, 2331.0, 48.2804
34.314521216, 96.390, 2220.0, 47.1169
34.367042346, 96.390, 2227.0, 47.1911
34.419563477, 96.390, 2315.0, 48.1144
34.472084608, 96.390, 2470.0, 49.6991
34.524605739, 96.390, 2544.0, 50.4381
34.577126869, 96.390, 2486.0, 49.8598
34.629648000, 96.390, 2715.0, 52.1057
34.682169131, 96.390, 2890.0, 53.7587
34.734690261, 96.390, 2822.0, 53.1225
34.787211392, 96.390, 2955.0, 54.3599
34.839732523, 96.390, 2808.0, 52.9906
34.892253654, 96.390, 2765.0, 52.5833
34.944774784, 96.390, 2601.0, 51.0000
34.997295915, 96.390, 2592.0, 50.9117
35.049817046, 96.390, 2542.0, 50.4183
35.102338176, 96.390, 2502.0, 50.0200
35.154859307, 96.390, 2412.0, 49.1121
35.207380438, 96.390, 2429.0, 49.2849
35.259901569, 96.390, 2272.0, 47.6655
35.312422699, 96.390, 2261.0, 47.5500
35.364943830, 96.390, 2144.0, 46.3033
35.417464961, 96.390, 2199.0, 46.8935
35.469986091, 96.390, 2074.0, 45.5412
35.522507222, 96.390, 2082.0, 45.6289
35.575028353, 96.390, 2064.0, 45.4313
35.627549484, 96.390, 1963.0, 44.3058
35.680070614, 96.390, 1909.0, 43.6921
35.732591745, 96.390, 1944.0, 44.0908
35.785112876, 96.390, 1977.0, 44.4635
35.837634006, 96.390, 1907.0, 43.6692
35.890155137, 96.390, 1945.0, 44.1022
35.942676268, 96.390, 1914.0, 43.7493
35.995197398, 96.390, 1742.0, 41.7373
36.047718529, 96.390, 1820.0, 42.6615
36.100239660, 96.390, 1862.0, 43.1509
36.152760791, 96.390, 1979.0, 44.4860
36.205281921, 96.390, 2118.0, 46.0217
36.257803052, 96.390, 2141.0, 46.2709
36.310324183, 96.390, 2013.0, 44.8665
36.362845313, 96.390, 1870.0, 43.2435
36.415366444, 96.390, 1696.0, 41.1825
36.467887575, 96.390, 1819.0, 42.6497
36.520408706, 96.390, 1855.0, 43.0697
36.572929836, 96.390, 1865.0, 43.1856
36.625450967, 96.390, 1916.0, 43.7721
36.677972098, 96.390, 1819.0, 42.6497
36.730493228, 96.390, 1853.0, 43.0465
36.783014359, 96.390, 1785.0, 42.2493
36.835535490, 96.390, 1742.0, 41.7373
36.888056621, 96.390, 1705.0, 41.2916
36.940577751, 96.390, 1713.0, 41.3884
36.993098882, 96.390, 1757.0, 41.9166
37.045620013, 96.390, 1695.0, 41.1704
37.098141143, 96.390, 1711.0, 41.3642
37.150662274, 96.390, 1717.0, 41.4367
37.203183405, 96.390, 1818.0, 42.6380
37.255704535, 96.390, 1783.0, 42.2256
37.308225666, 96.390, 1699.0, 41.2189
37.360746797, 96.390, 1726.0, 41.5452
37.413267928, 96.390, 1785.0, 42.2493
37.465789058, 96.390, 1769.0, 42.0595
37.518310189, 96.390, 1723.0, 41.5090
37.570831320, 96.390, 1724.0, 41.5211
37.623352450, 96.390, 1821.0, 42.6732
37.675873581, 96.390, 1718.0, 41.4488
37.728394712, 96.390, 1835.0, 42.8369
37.780915843, 96.390, 1951.0, 44.1701
37.833436973, 96.390, 2217.0, 47.0850
37.885958104, 96.390, 2237.0, 47.2969
37.938479235, 96.390, 2165.0, 46.5296
37.991000365, 96.390, 2013.0, 44.8665
38.043521496, 96.390, 1839.0, 42.8836
38.096042627, 96.390, 1708.0, 41.3280
38.148563758, 96.390, 1692.0, 41.1339
38.201084888, 96.390, 1591.0, 39.8873
38.253606019, 96.390, 1554.0, 39.4208
38.306127150, 96.390, 1571.0, 39.6358
38.358648280, 96.390, 1468.0, 38.3145
38.411169411, 96.390, 1539.0, 39.2301
38.463690542, 96.390, 1541.0, 39.2556
38.516211673, 96.390, 1533.0, 39.1535
38.568732803, 96.390, 1563.0, 39.5348
38.621253934, 96.390, 1558.0, 39.4715
38.673775065, 96.390, 1596.0, 39.9500
38.726296195, 96.390, 1497.0, 38.6911
38.778817326, 96.390, 1532.0, 39.1408
38.831338457, 96.390, 1539.0, 39.2301
38.883859587, 96.390, 1518.0, 38.9615
38.936380718, 96.390, 1516.0, 38.9358
38.988901849, 96.390, 1616.0, 40.1995
39.041422980, 96.390, 1502.0, 38.7556
39.093944110, 96.390, 1594.0, 39.9249
39.146465241, 96.390, 1618.0, 40.2244
39.198986372, 96.390, 1505.0, 38.7943
39.251507502, 96.390, 1619.0, 40.2368
39.304028633, 96.390, 1601.0, 40.0125
39.356549764, 96.390, 1539.0, 39.2301
39.409070895, 96.390, 1633.0, 40.4104
39.461592025, 96.390, 1581.0, 39.7618
39.514113156, 96.390, 1591.0, 39.8873
39.566634287, 96.390, 1559.0, 39.4842
39.619155417, 96.390, 1535.0, 39.1791
39.671676548, 96.390, 1583.0, 39.7869
39.724197679, 96.390, 1481.0, 38.4838
39.776718810, 96.390, 1541.0, 39.2556
39.829239940, 96.390, 1459.0, 38.1969
39.881761071, 96.390, 1538.0, 39.2173
39.934282202, 96.390, 1539.0, 39.2301
39.986803332, 96.390, 1525.0, 39.0512
40.039324463, 96.390, 1550.0, 39.3700
40.091845594, 96.390, 1477.0, 38.4318
40.144366725, 96.390, 1590.0, 39.8748
40.196887855, 96.390, 1643.0, 40.5339
40.249408986, 96.390, 1644.0, 40.5463
40.301930117, 96.390, 1590.0, 39.8748
40.354451247, 96.390, 1497.0, 38.6911
40.406972378, 96.390, 1455.0, 38.1445
40.459493509, 96.390, 1401.0, 37.4299
40.512014639, 96.390, 1404.0, 37.4700
40.564535770, 96.390, 1452.0, 38.1051
40.617056901, 96.390, 1551.0, 39.3827
40.669578032, 96.390, 1568.0, 39.5980
40.722099162, 96.390, 1703.0, 41.2674
40.774620293, 96.390, 1765.0, 42.0119
40.827141424, 96.390, 1694.0, 41.1582
40.879662554, 96.390, 1579.0, 39.7366
40.932183685, 96.390, 1577.0, 39.7115
40.984704816, 96.390, 1456.0, 38.1576
41.037225947, 96.390, 1548.0, 39.3446
41.089747077, 96.390, 1494.0, 38.6523
41.142268208, 96.390, 1527.0, 39.0768
41.194789339, 96.390, 1567.0, 39.5854
41.247310469, 96.390, 1588.0, 39.8497
41.299831600, 96.390, 1664.0, 40.7922
41.352352731, 96.390, 1740.0, 41.7133
41.404873862, 96.390, 1608.0, 40.0999
41.457394992, 96.390, 1605.0, 40.0625
41.509916123, 96.390, 1587.0, 39.8372
41.562437254, 96.390, 1492.0, 38.6264
41.614958384, 96.390, 1388.0, 37.2559
41.667479515, 96.390, 1410.0, 37.5500
41.720000646, 96.390, 1354.0, 36.7967
41.772521776, 96.390, 1317.0, 36.2905
41.825042907, 96.390, 1395.0, 37.3497
41.877564038, 96.390, 1393.0, 37.3229
41.930085169, 96.390, 1300.0, 36.0555
41.982606299, 96.390, 1348.0, 36.7151
42.035127430, 96.390, 1372.0, 37.0405
42.087648561, 96.390, 1341.0, 36.6197
42.140169691, 96.390, 1311.0, 36.2077
42.192690822, 96.390, 1332.0, 36.4966
42.245211953, 96.390, 1279.0, 35.7631
42.297733084, 96.390, 1336.0, 36.5513
42.350254214, 96.390, 1330.0, 36.4692
42.402775345, 96.390, 1362.0, 36.9053
42.455296476, 96.390, 1408.0, 37.5233
42.507817606, 96.390, 1385.0, 37.2156
42.560338737, 96.390, 1306.0, 36.1386
42.612859868, 96.390, 1367.0, 36.9730
42.665380999, 96.390, 1354.0, 36.7967
42.717902129, 96.390, 1347.0, 36.7015
42.770423260, 96.390, 1454.0, 38.1314
42.822944391, 96.390, 1402.0, 37.4433
42.875465521, 96.390, 1507.0, 38.8201
42.927986652, 96.390, 1414.0, 37.6032
42.980507783, 96.390, 1449.0, 38.0657
43.033028914, 96.390, 1296.0, 36.0000
43.085550044, 96.390, 1295.0, 35.9861
43.138071175, 96.390, 1223.0, 34.9714
43.190592306, 96.390, 1269.0, 35.6230
43.243113436, 96.390, 1193.0, 34.5398
43.295634567, 96.390, 1141.0, 33.7787
43.348155698, 96.390, 1184.0, 34.4093
43.400676828, 96.390, 1149.0, 33.8969
43.453197959, 96.390, 1079.0, 32.8481
43.505719090, 96.390, 1109.0, 33.3017
43.558240221, 96.390, 1139.0, 33.7491
43.610761351, 96.390, 1179.0, 34.3366
43.663282482, 96.390, 1196.0, 34.5832
43.715803613, 96.390, 1124.0, 33.5261
43.768324743, 96.390, 1214.0, 34.8425
43.820845874, 96.390, 1253.0, 35.3977
43.873367005, 96.390, 1205.0, 34.7131
43.925888136, 96.390, 1253.0, 35.3977
43.978409266, 96.390, 1093.0, 33.0606
44.030930397, 96.390, 1083.0, 32.9090
44.083451528, 96.390, 1042.0, 32.2800
44.135972658, 96.390, 1121.0, 33.4813
44.188493789, 96.390, 1056.0, 32.4962
44.241014920, 96.390, 1123.0, 33.5112
44.293536051, 96.390, 1116.0, 33.4066
44.346057181, 96.390, 1078.0, 32.8329
44.398578312, 96.390, 1091.0, 33.0303
44.451099443, 96.390, 1063.0, 32.6037
44.503620573, 96.390, 1090.0, 33.0151
44.556141704, 96.390, 1130.0, 33.6155
44.608662835, 96.390, 1078.0, 32.8329
44.661183966, 96.390, 1000.0, 31.6228
44.713705096, 96.390, 1134.0, 33.6749
44.766226227, 96.390, 1058.0, 32.5269
44.818747358, 96.390, 1144.0, 33.8231
44.871268488, 96.390, 1155.0, 33.9853
44.923789619, 96.390, 1146.0, 33.8526
44.976310750, 96.390, 1243.0, 35.2562
45.028831880, 96.390, 1389.0, 37.2693
45.081353011, 96.390, 1333.0, 36.5103
45.133874142, 96.390, 1389.0, 37.2693
45.186395273, 96.390, 1329.0, 36.4555
45.238916403, 96.390, 1236.0, 35.1568
45.291437534, 96.390, 1244.0, 35.2704
45.343958665, 96.390, 1197.0, 34.5977
45.396479795, 96.390, 1209.0, 34.7707
45.449000926, 96.390, 1138.0, 33.7343
45.501522057, 96.390, 1123.0, 33.5112
45.554043188, 96.390, 1108.0, 33.2866
45.606564318, 96.390, 1114.0, 33.3766
45.659085449, 96.390, 1178.0, 34.3220
45.711606580, 96.390, 1117.0, 33.4215
45.764127710, 96.390, 1160.0, 34.0588
45.816648841, 96.390, 1143.0, 33.8083
45.869169972, 96.390, 1231.0, 35.0856
45.921691103, 96.390, 1117.0, 33.4215
45.974212233, 96.390, 1184.0, 34.4093
46.026733364, 96.390, 1207.0, 34.7419
46.079254495, 96.390, 1184.0, 34.4093
46.131775625, 96.390, 1280.0, 35.7771
46.184296756, 96.390, 1256.0, 35.4401
46.236817887, 96.390, 1301.0, 36.0694
46.289339017, 96.390, 1204.0, 34.6987
46.341860148, 96.390, 1360.0, 36.8782
46.394381279, 96.390, 1422.0, 37.7094
46.446902410, 96.390, 1378.0, 37.1214
46.499423540, 96.390, 1285.0, 35.8469
46.551944671, 96.390, 1314.0, 36.2491
46.604465802, 96.390, 1268.0, 35.6090
46.656986932, 96.390, 1248.0, 35.3270
46.709508063, 96.390, 1285.0, 35.8469
46.762029194, 96.390, 1276.0, 35.7211
46.814550325, 96.390, 1279.0, 35.7631
46.867071455, 96.390, 1315.0, 36.2629
46.919592586, 96.390, 1333.0, 36.5103
46.972113717, 96.390, 1324.0, 36.3868
47.024634847, 96.390, 1263.0, 35.5387
47.077155978, 96.390, 1330.0, 36.4692
47.129677109, 96.390, 1307.0, 36.1525
47.182198240, 96.390, 1319.0, 36.3180
47.234719370, 96.390, 1232.0, 35.0999
47.287240501, 96.390, 1220.0, 34.9285
47.339761632, 96.390, 1283.0, 35.8190
47.392282762, 96.390, 1323.0, 36.3731
47.444803893, 96.390, 1181.0, 34.3657
47.497325024, 96.390, 1159.0, 34.0441
47.549846155, 96.390, 1193.0, 34.5398
47.602367285, 96.390, 1111.0, 33.3317
47.654888416, 96.390, 1176.0, 34.2929
47.707409547, 96.390, 1194.0, 34.5543
47.759930677, 96.390, 1099.0, 33.1512
47.812451808, 96.390, 1097.0, 33.1210
47.864972939, 96.390, 1030.0, 32.0936
47.917494069, 96.390, 1098.0, 33.1361
47.970015200, 96.390, 1057.0, 32.5115
48.022536331, 96.390, 1008.0, 31.7490
48.075057462, 96.390, 1027.0, 32.0468
48.127578592, 96.390, 993.0, 31.5119
48.180099723, 96.390, 967.0, 31.0966
48.232620854, 96.390, 1021.0, 31.9531
48.285141984, 96.390, 981.0, 31.3209
48.337663115, 96.390, 987.0, 31.4166
48.390184246, 96.390, 983.0, 31.3528
48.442705377, 96.390, 949.0, 30.8058
48.495226507, 96.390, 995.0, 31.5436
48.547747638, 96.390, 977.0, 31.2570
48.600268769, 96.390, 967.0, 31.0966
48.652789899, 96.390, 1045.0, 32.3265
48.705311030, 96.390, 971.0, 31.1609
48.757832161, 96.390, 957.0, 30.9354
48.810353292, 96.390, 927.0, 30.4467
48.862874422, 96.390, 959.0, 30.9677
48.915395553, 96.390, 944.0, 30.7246
48.967916684, 96.390, 918.0, 30.2985
49.020437814, 96.390, 875.0, 29.5804
49.072958945, 96.390, 922.0, 30.3645
49.125480076, 96.390, 923.0, 30.3809
49.178001207, 96.390, 940.0, 30.6594
49.230522337, 96.390, 938.0, 30.6268
49.283043468, 96.390, 909.0, 30.1496
49.335564599, 96.390, 920.0, 30.3315
49.388085729, 96.390, 871.0, 29.5127
49.440606860, 96.390, 948.0, 30.7896
49.493127991, 96.390, 947.0, 30.7734
49.545649121, 96.390, 891.0, 29.8496
49.598170252, 96.390, 882.0, 29.6985
49.650691383, 96.390, 873.0, 29.5466
49.703212514, 96.390, 945.0, 30.7409
49.755733644, 96.390, 927.0, 30.4467
49.808254775, 96.390, 949.0, 30.8058
49.860775906, 96.390, 918.0, 30.2985
49.913297036, 96.390, 950.0, 30.8221
49.965818167, 96.390, 926.0, 30.4302
50.018339298, 96.390, 918.0, 30.2985
50.070860429, 96.390, 1002.0, 31.6544
50.123381559, 96.390, 948.0, 30.7896
50.175902690, 96.390, 958.0, 30.9516
50.228423821, 96.390, 932.0, 30.5287
50.280944951, 96.390, 890.0, 29.8329
50.333466082, 96.390, 905.0, 30.0832
50.385987213, 96.390, 950.0, 30.8221
50.438508344, 96.390, 906.0, 30.0998
50.491029474, 96.390, 943.0, 30.7083
50.543550605, 96.390, 904.0, 30.0666
50.596071736, 96.390, 891.0, 29.8496
50.648592866, 96.390, 874.0, 29.5635
50.701113997, 96.390, 921.0, 30.3480
50.753635128, 96.390, 902.0, 30.0333
50.806156258, 96.390, 957.0, 30.9354
50.858677389, 96.390, 998.0, 31.5911
50.911198520, 96.390, 998.0, 31.5911
50.963719651, 96.390, 979.0, 31.2890
51.016240781, 96.390, 1053.0, 32.4500
51.068761912, 96.390, 1015.0, 31.8591
51.121283043, 96.390, 976.0, 31.2410
51.173804173, 96.390, 1006.0, 31.7175
51.226325304, 96.390, 1000.0, 31.6228
51.278846435, 96.390, 961.0, 31.0000
51.331367566, 96.390, 992.0, 31.4960
51.383888696, 96.390, 940.0, 30.6594
51.436409827, 96.390, 996.0, 31.5595
51.488930958, 96.390, 994.0, 31.5278
51.541452088, 96.390, 996.0, 31.5595
51.593973219, 96.390, 1060.0, 32.5576
51.646494350, 96.390, 1080.0, 32.8634
51.699015481, 96.390, 1036.0, 32.1870
51.751536611, 96.390, 971.0, 31.1609
51.804057742, 96.390, 947.0, 30.7734
51.856578873, 96.390, 934.0, 30.5614
51.909100003, 96.390, 940.0, 30.6594
51.961621134, 96.390, 907.0, 30.1164
52.014142265, 96.390, 948.0, 30.7896
52.066663396, 96.390, 995.0, 31.5436
52.119184526, 96.390, 970.0, 31.1448
52.171705657, 96.390, 972.0, 31.1769
52.224226788, 96.390, 921.0, 30.3480
52.276747918, 96.390, 959.0, 30.9677
52.329269049, 96.390, 941.0, 30.6757
52.381790180, 96.390, 985.0, 31.3847
52.434311310, 96.390, 956.0, 30.9192
52.486832441, 96.390, 974.0, 31.2090
52.539353572, 96.390, 969.0, 31.1288
52.591874703, 96.390, 973.0, 31.1929
52.644395833, 96.390, 964.0, 31.0483
52.696916964, 96.390, 898.0, 29.9666
52.749438095, 96.390, 986.0, 31.4006
52.801959225, 96.390, 965.0, 31.0644
52.854480356, 96.390, 1002.0, 31.6544
52.907001487, 96.390, 1028.0, 32.0624
52.959522618, 96.390, 1041.0, 32.2645
53.012043748, 96.390, 1069.0, 32.6956
53.064564879, 96.390, 1146.0, 33.8526
53.117086010, 96.390, 1177.0, 34.3074
53.169607140, 96.390, 1133.0, 33.6601
53.222128271, 96.390, 1109.0, 33.3017
53.274649402, 96.390, 1004.0, 31.6860
53.327170533, 96.390, 995.0, 31.5436
53.379691663, 96.390, 931.0, 30.5123
53.432212794, 96.390, 890.0, 29.8329
53.484733925, 96.390, 892.0, 29.8664
53.537255055, 96.390, 948.0, 30.7896
53.589776186, 96.390, 927.0, 30.4467
53.642297317, 96.390, 904.0, 30.0666
53.694818448, 96.390, 865.0, 29.4109
53.747339578, 96.390, 887.0, 29.7825
53.799860709, 96.390, 866.0, 29.4279
53.852381840, 96.390, 868.0, 29.4618
53.904902970, 96.390, 802.0, 28.3196
53.957424101, 96.390, 835.0, 28.8964
54.009945232, 96.390, 829.0, 28.7924
54.062466362, 96.390, 846.0, 29.0861
54.114987493, 96.390, 809.0, 28.4429
54.167508624, 96.390, 868.0, 29.4618
54.220029755, 96.390, 861.0, 29.3428
54.272550885, 96.390, 852.0, 29.1890
54.325072016, 96.390, 803.0, 28.3373
54.377593147, 96.390, 828.0, 28.7750
54.430114277, 96.390, 809.0, 28.4429
54.482635408, 96.390, 859.0, 29.3087
54.535156539, 96.390, 887.0, 29.7825
54.587677670, 96.390, 826.0, 28.7402
54.640198800, 96.390, 831.0, 28.8271
54.692719931, 96.390, 817.0, 28.5832
54.745241062, 96.390, 835.0, 28.8964
54.797762192, 96.390, 868.0, 29.4618
54.850283323, 96.390, 837.0, 28.9310
54.902804454, 96.390, 915.0, 30.2490
54.955325585, 96.390, 831.0, 28.8271
55.007846715, 96.390, 863.0, 29.3769
55.060367846, 96.390, 862.0, 29.3598
55.112888977, 96.390, 850.0, 29.1548
55.165410107, 96.390, 914.0, 30.2324
55.217931238, 96.390, 825.0, 28.7228
55.270452369, 96.390, 845.0, 29.0689
55.322973499, 96.390, 821.0, 28.6531
55.375494630, 96.390, 807.0, 28.4077
55.428015761, 96.390, 779.0, 27.9106
55.480536892, 96.390, 791.0, 28.1247
55.533058022, 96.390, 818.0, 28.6007
55.585579153, 96.390, 844.0, 29.0517
55.638100284, 96.390, 809.0, 28.4429
55.690621414, 96.390, 801.0, 28.3019
55.743142545, 96.390, 850.0, 29.1548
55.795663676, 96.390, 872.0, 29.5296
55.848184807, 96.390, 861.0, 29.3428
55.900705937, 96.390, 856.0, 29.2575
55.953227068, 96.390, 805.0, 28.3725
56.005748199, 96.390, 778.0, 27.8927
56.058269329, 96.390, 822.0, 28.6705
56.110790460, 96.390, 762.0, 27.6043
56.163311591, 96.390, 791.0, 28.1247
56.215832722, 96.390, 819.0, 28.6182
56.268353852, 96.390, 832.0, 28.8444
56.320874983, 96.390, 716.0, 26.7582
56.373396114, 96.390, 833.0, 28.8617
56.425917244, 96.390, 841.0, 29.0000
56.478438375, 96.390, 804.0, 28.3549
56.530959506, 96.390, 787.0, 28.0535
56.583480637, 96.390, 846.0, 29.0861
56.636001767, 96.390, 826.0, 28.7402
56.688522898, 96.390, 840.0, 28.9828
56.741044029, 96.390, 852.0, 29.1890
56.793565159, 96.390, 896.0, 29.9333
56.846086290, 96.390, 895.0, 29.9166
56.898607421, 96.390, 924.0, 30.3974
56.951128551, 96.390, 871.0, 29.5127
57.003649682, 96.390, 850.0, 29.1548
57.056170813, 96.390, 948.0, 30.7896
57.108691944, 96.390, 956.0, 30.9192
57.161213074, 96.390, 978.0, 31.2730
57.213734205, 96.390, 1094.0, 33.0757
57.266255336, 96.390, 1028.0, 32.0624
57.318776466, 96.390, 1110.0, 33.3167
57.371297597, 96.390, 1019.0, 31.9218
57.423818728, 96.390, 951.0, 30.8383
57.476339859, 96.390, 1000.0, 31.6228
57.528860989, 96.390, 935.0, 30.5778
57.581382120, 96.390, 865.0, 29.4109
57.633903251, 96.390, 874.0, 29.5635
57.686424381, 96.390, 862.0, 29.3598
57.738945512, 96.390, 876.0, 29.5973
57.791466643, 96.390, 853.0, 29.2062
57.843987774, 96.390, 821.0, 28.6531
57.896508904, 96.390, 778.0, 27.8927
57.949030035, 96.390, 817.0, 28.5832
58.001551166, 96.390, 782.0, 27.9643
58.054072296, 96.390, 802.0, 28.3196
58.106593427, 96.390, 834.0, 28.8791
58.159114558, 96.390, 816.0, 28.5657
58.211635689, 96.390, 891.0, 29.8496
58.264156819, 96.390, 917.0, 30.2820
58.316677950, 96.390, 918.0, 30.2985
58.369199081, 96.390, 849.0, 29.1376
58.421720211, 96.390, 929.0, 30.4795
58.474241342, 96.390, 897.0, 29.9500
58.526762473, 96.390, 864.0, 29.3939
58.579283603, 96.390, 925.0, 30.4138
58.631804734, 96.390, 891.0, 29.8496
58.684325865, 96.390, 899.0, 29.9833
58.736846996, 96.390, 904.0, 30.0666
58.789368126, 96.390, 892.0, 29.8664
58.841889257, 96.390, 867.0, 29.4449
58.894410388, 96.390, 923.0, 30.3809
58.946931518, 96.390, 876.0, 29.5973
58.999452649, 96.390, 959.0, 30.9677
59.051973780, 96.390, 879.0, 29.6479
59.104494911, 96.390, 954.0, 30.8869
59.157016041, 96.390, 953.0, 30.8707
59.209537172, 96.390, 960.0, 30.9839
59.262058303, 96.390, 904.0, 30.0666
59.314579433, 96.390, 891.0, 29.8496
59.367100564, 96.390, 939.0, 30.6431
59.419621695, 96.390, 928.0, 30.4631
59.472142826, 96.390, 947.0, 30.7734
59.524663956, 96.390, 982.0, 31.3369
59.577185087, 96.390, 1011.0, 31.7962
59.629706218, 96.390, 1030.0, 32.0936
59.682227348, 96.390, 1103.0, 33.2114
59.734748479, 96.390, 1075.0, 32.7872
59.787269610, 96.390, 1136.0, 33.7046
59.839790740, 96.390, 1120.0, 33.4664
59.892311871, 96.390, 1162.0, 34.0881
59.944833002, 96.390, 1166.0, 34.1467
59.997354133, 96.390, 1200.0, 34.6410
60.049875263, 96.390, 1074.0, 32.7719
60.102396394, 96.390, 1161.0, 34.0735
60.154917525, 96.390, 1265.0, 35.5668
60.207438655, 96.390, 1258.0, 35.4683
60.259959786, 96.390, 1320.0, 36.3318
60.312480917, 96.390, 1318.0, 36.3043
60.365002048, 96.390, 1349.0, 36.7287
60.417523178, 96.390, 1324.0, 36.3868
60.470044309, 96.390, 1349.0, 36.7287
60.522565440, 96.390, 1401.0, 37.4299
60.575086570, 96.390, 1315.0, 36.2629
60.627607701, 96.390, 1384.0, 37.2022
60.680128832, 96.390, 1313.0, 36.2353
60.732649963, 96.390, 1354.0, 36.7967
60.785171093, 96.390, 1325.0, 36.4005
60.837692224, 96.390, 1340.0, 36.6060
60.890213355, 96.390, 1286.0, 35.8608
60.942734485, 96.390, 1291.0, 35.9305
60.995255616, 96.390, 1258.0, 35.4683
61.047776747, 96.390, 1213.0, 34.8281
61.100297878, 96.390, 1175.0, 34.2783
61.152819008, 96.390, 1165.0, 34.1321
61.205340139, 96.390, 1145.0, 33.8378
61.257861270, 96.390, 1076.0, 32.8024
61.310382400, 96.390, 1142.0, 33.7935
61.362903531, 96.390, 1053.0, 32.4500
61.415424662, 96.390, 1044.0, 32.3110
61.467945792, 96.390, 1060.0, 32.5576
61.520466923, 96.390, 1065.0, 32.6343
61.572988054, 96.390, 1031.0, 32.1092
61.625509185, 96.390, 1068.0, 32.6803
61.678030315, 96.390, 993.0, 31.5119
61.730551446, 96.390, 1005.0, 31.7017
61.783072577, 96.390, 991.0, 31.4802
61.835593707, 96.390, 1042.0, 32.2800
61.888114838, 96.390, 996.0, 31.5595
61.940635969, 96.390, 1042.0, 32.2800
61.993157100, 96.390, 1044.0, 32.3110
62.045678230, 96.390, 1015.0, 31.8591
62.098199361, 96.390, 1073.0, 32.7567
62.150720492, 96.390, 1018.0, 31.9061
62.203241622, 96.390, 1039.0, 32.2335
62.255762753, 96.390, 999.0, 31.6070
62.308283884, 96.390, 1006.0, 31.7175
62.360805015, 96.390, 942.0, 30.6920
62.413326145, 96.390, 960.0, 30.9839
62.465847276, 96.390, 950.0, 30.8221
62.518368407, 96.390, 892.0, 29.8664
62.570889537, 96.390, 883.0, 29.7153
62.623410668, 96.390, 953.0, 30.8707
62.675931799, 96.390, 869.0, 29.4788
62.728452930, 96.390, 886.0, 29.7658
62.780974060, 96.390, 860.0, 29.3258
62.833495191, 96.390, 870.0, 29.4958
62.886016322, 96.390, 845.0, 29.0689
62.938537452, 96.390, 889.0, 29.8161
62.991058583, 96.390, 924.0, 30.3974
63.043579714, 96.390, 916.0, 30.2655
63.096100844, 96.390, 817.0, 28.5832
63.148621975, 96.390, 910.0, 30.1662
63.201143106, 96.390, 825.0, 28.7228
63.253664237, 96.390, 800.0, 28.2843
63.306185367, 96.390, 879.0, 29.6479
63.358706498, 96.390, 777.0, 27.8747
63.411227629, 96.390, 791.0, 28.1247
63.463748759, 96.390, 744.0, 27.2764
63.516269890, 96.390, 775.0, 27.8388
63.568791021, 96.390, 758.0, 27.5318
63.621312152, 96.390, 758.0, 27.5318
63.673833282, 96.390, 738.0, 27.1662
63.726354413, 96.390, 743.0, 27.2580
63.778875544, 96.390, 786.0, 28.0357
63.831396674, 96.390, 720.0, 26.8328
63.883917805, 96.390, 748.0, 27.3496
63.936438936, 96.390, 750.0, 27.3861
63.988960067, 96.390, 744.0, 27.2764
64.041481197, 96.390, 784.0, 28.0000
64.094002328, 96.390, 708.0, 26.6083
64.146523459, 96.390, 728.0, 26.9815
64.199044589, 96.390, 705.0, 26.5518
64.251565720, 96.390, 694.0, 26.3439
64.304086851, 96.390, 723.0, 26.8887
64.356607981, 96.390, 655.0, 25.5930
64.409129112, 96.390, 701.0, 26.4764
64.461650243, 96.390, 664.0, 25.7682
64.514171374, 96.390, 685.0, 26.1725
64.566692504, 96.390, 614.0, 24.7790
64.619213635, 96.390, 550.0, 23.4521
64.671734766, 96.390, 730.0, 27.0185
64.724255896, 96.390, 640.0, 25.2982
64.776777027, 96.390, 577.0, 24.0208
64.829298158, 96.390, 581.0, 24.1039
64.881819289, 96.390, 646.0, 25.4165
64.934340419, 96.390, 628.0, 25.0599
64.986861550, 96.390, 660.0, 25.6905