File: Files_organized_for_plots/Constant_NaOH_1mL10M_to_1gPC_28Day_repeat/SiAxial30Mar22_Act12Feb23_B1_0714M_NaOH_LS0173_Num152.csv
[Measurement conditions],,,
Sample identification,SiAxial30Mar22_Act12Feb23_B1_0714M_NaOH_LS0173_Num152,,
Comment - 2,"Configuration=Stage for Flat Samples/Holders, Owner=nmw10, Creation date=9/21/2022 10:06:30 AM",,
Comment - 3,Goniometer=Theta/Theta; Minimum step size 2Theta:0.0001; Minimum step size Omega:0.0001,,
Comment - 4,Sample stage=Stage for flat samples/holders,,
Comment - 5,Diffractometer system=EMPYREAN,,
Comment - 6,"Measurement program=X:\XRD\Cement\Zerobackground scan.xrdmp, Created identifier={98A3B11C-88F9-4AA6-982C-73314A311EF5}, Created by=Titus Reed, Id=tmr79, Creation date=10/26/2021 3:01:47 PM",,
Anode material,Cu,,
K-Alpha1 wavelength,1.540598,,
K-Alpha2 wavelength,1.544426,,
Ratio K-Alpha2/K-Alpha1,0.5,,
Divergence slit,Fixed,0.25,
Monochromator used,NO,,
Generator voltage,45,,
Tube current,40,,
File date and time,3/15/2023 18:42,,
Unit cell,,,
h k l, 0 0 0,,
Scan axis,Gonio,,
Scan range,4.994599997,64.99999183,
Scan step size,0.0262606,,
No. of points,2285,,
Scan type,CONTINUOUS,,
Time per step,96.39,,
[Scan points],,,
Angle, TimePerStep, Intensity, ESD
5.00773028,96.39,4379,66.174
5.060251411,96.39,4342,65.8939
5.112772541,96.39,4318,65.7115
5.165293672,96.39,4107,64.0859
5.217814803,96.39,4168,64.56
5.270335934,96.39,4152,64.436
5.322857064,96.39,4111,64.1171
5.375378195,96.39,3858,62.1128
5.427899326,96.39,4021,63.4114
5.480420456,96.39,3971,63.0159
5.532941587,96.39,3800,61.6441
5.585462718,96.39,3948,62.8331
5.637983849,96.39,3876,62.2575
5.690504979,96.39,3782,61.498
5.74302611,96.39,3691,60.7536
5.795547241,96.39,3760,61.3188
5.848068371,96.39,3795,61.6036
5.900589502,96.39,3766,61.3677
5.953110633,96.39,3702,60.8441
6.005631763,96.39,3702,60.8441
6.058152894,96.39,3696,60.7947
6.110674025,96.39,3665,60.5392
6.163195156,96.39,3660,60.4979
6.215716286,96.39,3670,60.5805
6.268237417,96.39,3664,60.531
6.320758548,96.39,3637,60.3075
6.373279678,96.39,3646,60.3821
6.425800809,96.39,3746,61.2046
6.47832194,96.39,3682,60.6795
6.530843071,96.39,3609,60.075
6.583364201,96.39,3717,60.9672
6.635885332,96.39,3591,59.925
6.688406463,96.39,3657,60.4731
6.740927593,96.39,3655,60.4566
6.793448724,96.39,3595,59.9583
6.845969855,96.39,3630,60.2495
6.898490986,96.39,3574,59.7829
6.951012116,96.39,3596,59.9667
7.003533247,96.39,3564,59.6992
7.056054378,96.39,3493,59.1016
7.108575508,96.39,3557,59.6406
7.161096639,96.39,3531,59.4222
7.21361777,96.39,3660,60.4979
7.2661389,96.39,3582,59.8498
7.318660031,96.39,3576,59.7997
7.371181162,96.39,3494,59.1101
7.423702293,96.39,3539,59.4895
7.476223423,96.39,3587,59.8916
7.528744554,96.39,3523,59.3549
7.581265685,96.39,3572,59.7662
7.633786815,96.39,3578,59.8164
7.686307946,96.39,3582,59.8498
7.738829077,96.39,3679,60.6548
7.791350208,96.39,3664,60.531
7.843871338,96.39,3553,59.607
7.896392469,96.39,3635,60.291
7.9489136,96.39,3599,59.9917
8.00143473,96.39,3712,60.9262
8.053955861,96.39,3563,59.6909
8.106476992,96.39,3630,60.2495
8.158998123,96.39,3658,60.4814
8.211519253,96.39,3551,59.5903
8.264040384,96.39,3529,59.4054
8.316561515,96.39,3606,60.05
8.369082645,96.39,3549,59.5735
8.421603776,96.39,3488,59.0593
8.474124907,96.39,3577,59.808
8.526646038,96.39,3548,59.5651
8.579167168,96.39,3651,60.4235
8.631688299,96.39,3541,59.5063
8.68420943,96.39,3639,60.3241
8.73673056,96.39,3564,59.6992
8.789251691,96.39,3537,59.4727
8.841772822,96.39,3404,58.3438
8.894293952,96.39,3535,59.4559
8.946815083,96.39,3620,60.1664
8.999336214,96.39,3410,58.3952
9.051857345,96.39,3407,58.3695
9.104378475,96.39,3494,59.1101
9.156899606,96.39,3353,57.9051
9.209420737,96.39,3428,58.5491
9.261941867,96.39,3421,58.4893
9.314462998,96.39,3452,58.7537
9.366984129,96.39,3372,58.0689
9.41950526,96.39,3413,58.4209
9.47202639,96.39,3402,58.3267
9.524547521,96.39,3383,58.1636
9.577068652,96.39,3374,58.0861
9.629589782,96.39,3412,58.4123
9.682110913,96.39,3297,57.4195
9.734632044,96.39,3297,57.4195
9.787153175,96.39,3385,58.1808
9.839674305,96.39,3311,57.5413
9.892195436,96.39,3285,57.3149
9.944716567,96.39,3356,57.931
9.997237697,96.39,3261,57.1052
10.04975883,96.39,3267,57.1577
10.10227996,96.39,3260,57.0964
10.15480109,96.39,3213,56.6833
10.20732222,96.39,3167,56.2761
10.25984335,96.39,3078,55.4797
10.31236448,96.39,3123,55.8838
10.36488561,96.39,3208,56.6392
10.41740674,96.39,3273,57.2101
10.46992787,96.39,3266,57.1489
10.522449,96.39,3115,55.8122
10.57497014,96.39,3081,55.5068
10.62749127,96.39,3116,55.8211
10.6800124,96.39,3053,55.254
10.73253353,96.39,2973,54.5252
10.78505466,96.39,3085,55.5428
10.83757579,96.39,3067,55.3805
10.89009692,96.39,3056,55.2811
10.94261805,96.39,3069,55.3986
10.99513918,96.39,3003,54.7996
11.04766031,96.39,2957,54.3783
11.10018144,96.39,2859,53.4696
11.15270257,96.39,2950,54.3139
11.2052237,96.39,2844,53.3292
11.25774483,96.39,2783,52.7541
11.31026597,96.39,2962,54.4243
11.3627871,96.39,2855,53.4322
11.41530823,96.39,2859,53.4696
11.46782936,96.39,2853,53.4135
11.52035049,96.39,2739,52.3355
11.57287162,96.39,2833,53.2259
11.62539275,96.39,2742,52.3641
11.67791388,96.39,2698,51.9423
11.73043501,96.39,2751,52.45
11.78295614,96.39,2878,53.647
11.83547727,96.39,2730,52.2494
11.8879984,96.39,2744,52.3832
11.94051953,96.39,2861,53.4883
11.99304066,96.39,2670,51.672
12.0455618,96.39,2738,52.3259
12.09808293,96.39,2700,51.9615
12.15060406,96.39,2570,50.6952
12.20312519,96.39,2591,50.9019
12.25564632,96.39,2632,51.303
12.30816745,96.39,2597,50.9608
12.36068858,96.39,2596,50.951
12.41320971,96.39,2601,51
12.46573084,96.39,2618,51.1664
12.51825197,96.39,2606,51.049
12.5707731,96.39,2636,51.342
12.62329423,96.39,2699,51.9519
12.67581536,96.39,2681,51.7784
12.72833649,96.39,2556,50.5569
12.78085763,96.39,2493,49.93
12.83337876,96.39,2549,50.4876
12.88589989,96.39,2442,49.4166
12.93842102,96.39,2510,50.0999
12.99094215,96.39,2444,49.4368
13.04346328,96.39,2466,49.6588
13.09598441,96.39,2482,49.8197
13.14850554,96.39,2483,49.8297
13.20102667,96.39,2499,49.99
13.2535478,96.39,2523,50.2295
13.30606893,96.39,2521,50.2096
13.35859006,96.39,2434,49.3356
13.41111119,96.39,2624,51.225
13.46363232,96.39,2879,53.6563
13.51615346,96.39,2879,53.6563
13.56867459,96.39,2517,50.1697
13.62119572,96.39,2393,48.9183
13.67371685,96.39,2461,49.6085
13.72623798,96.39,2429,49.2849
13.77875911,96.39,2763,52.5642
13.83128024,96.39,2521,50.2096
13.88380137,96.39,2645,51.4296
13.9363225,96.39,2373,48.7134
13.98884363,96.39,2330,48.2701
14.04136476,96.39,2375,48.734
14.09388589,96.39,2502,50.02
14.14640702,96.39,2613,51.1175
14.19892815,96.39,2935,54.1756
14.25144929,96.39,3519,59.3212
14.30397042,96.39,3077,55.4707
14.35649155,96.39,2429,49.2849
14.40901268,96.39,2390,48.8876
14.46153381,96.39,2281,47.7598
14.51405494,96.39,2508,50.0799
14.56657607,96.39,2328,48.2494
14.6190972,96.39,2225,47.1699
14.67161833,96.39,2250,47.4342
14.72413946,96.39,2272,47.6655
14.77666059,96.39,2326,48.2286
14.82918172,96.39,2245,47.3814
14.88170285,96.39,2350,48.4768
14.93422398,96.39,2378,48.7647
14.98674512,96.39,2353,48.5077
15.03926625,96.39,2352,48.4974
15.09178738,96.39,2463,49.6286
15.14430851,96.39,2533,50.3289
15.19682964,96.39,2846,53.3479
15.24935077,96.39,3095,55.6327
15.3018719,96.39,2937,54.1941
15.35439303,96.39,2596,50.951
15.40691416,96.39,2513,50.1298
15.45943529,96.39,2225,47.1699
15.51195642,96.39,2332,48.2908
15.56447755,96.39,2275,47.697
15.61699868,96.39,2286,47.8121
15.66951981,96.39,2215,47.0638
15.72204095,96.39,2215,47.0638
15.77456208,96.39,2176,46.6476
15.82708321,96.39,2211,47.0213
15.87960434,96.39,2238,47.3075
15.93212547,96.39,2151,46.3789
15.9846466,96.39,2237,47.2969
16.03716773,96.39,2247,47.4025
16.08968886,96.39,2210,47.0106
16.14220999,96.39,2278,47.7284
16.19473112,96.39,2264,47.5815
16.24725225,96.39,2205,46.9574
16.29977338,96.39,2173,46.6154
16.35229451,96.39,2248,47.4131
16.40481564,96.39,2135,46.2061
16.45733678,96.39,2256,47.4974
16.50985791,96.39,2229,47.2123
16.56237904,96.39,2193,46.8295
16.61490017,96.39,2098,45.8039
16.6674213,96.39,2249,47.4236
16.71994243,96.39,2188,46.7761
16.77246356,96.39,2150,46.3681
16.82498469,96.39,2136,46.2169
16.87750582,96.39,2219,47.1063
16.93002695,96.39,2252,47.4552
16.98254808,96.39,2297,47.927
17.03506921,96.39,2178,46.669
17.08759034,96.39,2181,46.7012
17.14011147,96.39,2153,46.4004
17.19263261,96.39,2148,46.3465
17.24515374,96.39,2158,46.4543
17.29767487,96.39,2154,46.4112
17.350196,96.39,2340,48.3735
17.40271713,96.39,2249,47.4236
17.45523826,96.39,2149,46.3573
17.50775939,96.39,2123,46.076
17.56028052,96.39,2114,45.9783
17.61280165,96.39,2009,44.8219
17.66532278,96.39,1994,44.6542
17.71784391,96.39,2058,45.3652
17.77036504,96.39,2076,45.5631
17.82288617,96.39,2042,45.1885
17.8754073,96.39,2081,45.618
17.92792843,96.39,2056,45.3431
17.98044957,96.39,1980,44.4972
18.0329707,96.39,2094,45.7602
18.08549183,96.39,2109,45.9239
18.13801296,96.39,2139,46.2493
18.19053409,96.39,2071,45.5082
18.24305522,96.39,2084,45.6508
18.29557635,96.39,2227,47.1911
18.34809748,96.39,2098,45.8039
18.40061861,96.39,2076,45.5631
18.45313974,96.39,2356,48.5386
18.50566087,96.39,2155,46.422
18.558182,96.39,2066,45.4533
18.61070313,96.39,2013,44.8665
18.66322426,96.39,2044,45.2106
18.7157454,96.39,2018,44.9222
18.76826653,96.39,2013,44.8665
18.82078766,96.39,2029,45.0444
18.87330879,96.39,2134,46.1952
18.92582992,96.39,2083,45.6399
18.97835105,96.39,2242,47.3498
19.03087218,96.39,2088,45.6946
19.08339331,96.39,2090,45.7165
19.13591444,96.39,2101,45.8367
19.18843557,96.39,2118,46.0217
19.2409567,96.39,2087,45.6837
19.29347783,96.39,2159,46.465
19.34599896,96.39,2344,48.4149
19.39852009,96.39,2469,49.689
19.45104123,96.39,2570,50.6952
19.50356236,96.39,2341,48.3839
19.55608349,96.39,2174,46.6262
19.60860462,96.39,2271,47.655
19.66112575,96.39,2338,48.3529
19.71364688,96.39,2409,49.0816
19.76616801,96.39,2832,53.2165
19.81868914,96.39,2813,53.0377
19.87121027,96.39,2724,52.192
19.9237314,96.39,3230,56.8331
19.97625253,96.39,3611,60.0916
20.02877366,96.39,2849,53.376
20.08129479,96.39,2205,46.9574
20.13381592,96.39,2183,46.7226
20.18633706,96.39,2236,47.2864
20.23885819,96.39,2300,47.9583
20.29137932,96.39,2318,48.1456
20.34390045,96.39,2407,49.0612
20.39642158,96.39,2528,50.2792
20.44894271,96.39,2617,51.1566
20.50146384,96.39,2880,53.6656
20.55398497,96.39,3433,58.5918
20.6065061,96.39,4217,64.9384
20.65902723,96.39,5633,75.0533
20.71154836,96.39,6324,79.5236
20.76406949,96.39,4359,66.0227
20.81659062,96.39,2729,52.2398
20.86911175,96.39,2426,49.2544
20.92163289,96.39,2246,47.392
20.97415402,96.39,2203,46.9361
21.02667515,96.39,2188,46.7761
21.07919628,96.39,2214,47.0532
21.13171741,96.39,2197,46.8722
21.18423854,96.39,2183,46.7226
21.23675967,96.39,2239,47.3181
21.2892808,96.39,2154,46.4112
21.34180193,96.39,2220,47.1169
21.39432306,96.39,2174,46.6262
21.44684419,96.39,2092,45.7384
21.49936532,96.39,2072,45.5192
21.55188645,96.39,2048,45.2548
21.60440758,96.39,2135,46.2061
21.65692872,96.39,2094,45.7602
21.70944985,96.39,2184,46.7333
21.76197098,96.39,2146,46.3249
21.81449211,96.39,2159,46.465
21.86701324,96.39,2158,46.4543
21.91953437,96.39,2203,46.9361
21.9720555,96.39,2195,46.8508
22.02457663,96.39,2169,46.5725
22.07709776,96.39,2253,47.4658
22.12961889,96.39,2282,47.7703
22.18214002,96.39,2302,47.9792
22.23466115,96.39,2219,47.1063
22.28718228,96.39,2259,47.5289
22.33970341,96.39,2365,48.6313
22.39222455,96.39,2372,48.7032
22.44474568,96.39,2328,48.2494
22.49726681,96.39,2206,46.9681
22.54978794,96.39,2296,47.9166
22.60230907,96.39,2350,48.4768
22.6548302,96.39,2297,47.927
22.70735133,96.39,2230,47.2229
22.75987246,96.39,2285,47.8017
22.81239359,96.39,2282,47.7703
22.86491472,96.39,2371,48.6929
22.91743585,96.39,2385,48.8365
22.96995698,96.39,2329,48.2597
23.02247811,96.39,2327,48.239
23.07499924,96.39,2413,49.1223
23.12752038,96.39,2543,50.4282
23.18004151,96.39,2603,51.0196
23.23256264,96.39,2499,49.99
23.28508377,96.39,2438,49.3761
23.3376049,96.39,2456,49.558
23.39012603,96.39,2439,49.3862
23.44264716,96.39,2347,48.4458
23.49516829,96.39,2390,48.8876
23.54768942,96.39,2320,48.1664
23.60021055,96.39,2413,49.1223
23.65273168,96.39,2332,48.2908
23.70525281,96.39,2384,48.8262
23.75777394,96.39,2384,48.8262
23.81029507,96.39,2391,48.8979
23.86281621,96.39,2453,49.5278
23.91533734,96.39,2400,48.9898
23.96785847,96.39,2386,48.8467
24.0203796,96.39,2449,49.4874
24.07290073,96.39,2426,49.2544
24.12542186,96.39,2576,50.7543
24.17794299,96.39,2748,52.4214
24.23046412,96.39,2577,50.7642
24.28298525,96.39,2395,48.9387
24.33550638,96.39,2404,49.0306
24.38802751,96.39,2354,48.518
24.44054864,96.39,2304,48
24.49306977,96.39,2335,48.3218
24.5455909,96.39,2273,47.676
24.59811204,96.39,2315,48.1144
24.65063317,96.39,2284,47.7912
24.7031543,96.39,2308,48.0416
24.75567543,96.39,2273,47.676
24.80819656,96.39,2231,47.2335
24.86071769,96.39,2205,46.9574
24.91323882,96.39,2304,48
24.96575995,96.39,2223,47.1487
25.01828108,96.39,2451,49.5076
25.07080221,96.39,2243,47.3603
25.12332334,96.39,2300,47.9583
25.17584447,96.39,2259,47.5289
25.2283656,96.39,2265,47.592
25.28088673,96.39,2298,47.9375
25.33340786,96.39,2567,50.6656
25.385929,96.39,2957,54.3783
25.43845013,96.39,3140,56.0357
25.49097126,96.39,2804,52.9528
25.54349239,96.39,2482,49.8197
25.59601352,96.39,2209,47
25.64853465,96.39,2218,47.0956
25.70105578,96.39,2210,47.0106
25.75357691,96.39,2251,47.4447
25.80609804,96.39,2239,47.3181
25.85861917,96.39,2286,47.8121
25.9111403,96.39,2219,47.1063
25.96366143,96.39,2318,48.1456
26.01618256,96.39,2293,47.8853
26.06870369,96.39,2242,47.3498
26.12122483,96.39,2200,46.9042
26.17374596,96.39,2231,47.2335
26.22626709,96.39,2158,46.4543
26.27878822,96.39,2183,46.7226
26.33130935,96.39,2183,46.7226
26.38383048,96.39,2177,46.6583
26.43635161,96.39,2254,47.4763
26.48887274,96.39,2253,47.4658
26.54139387,96.39,2221,47.1275
26.593915,96.39,2151,46.3789
26.64643613,96.39,2206,46.9681
26.69895726,96.39,2194,46.8402
26.75147839,96.39,2166,46.5403
26.80399952,96.39,2080,45.607
26.85652066,96.39,2150,46.3681
26.90904179,96.39,2211,47.0213
26.96156292,96.39,2215,47.0638
27.01408405,96.39,2173,46.6154
27.06660518,96.39,2452,49.5177
27.11912631,96.39,2793,52.8488
27.17164744,96.39,3103,55.7046
27.22416857,96.39,2756,52.4976
27.2766897,96.39,2477,49.7695
27.32921083,96.39,2238,47.3075
27.38173196,96.39,2157,46.4435
27.43425309,96.39,2119,46.0326
27.48677422,96.39,2039,45.1553
27.53929535,96.39,2135,46.2061
27.59181649,96.39,2092,45.7384
27.64433762,96.39,2140,46.2601
27.69685875,96.39,2167,46.551
27.74937988,96.39,2086,45.6727
27.80190101,96.39,2196,46.8615
27.85442214,96.39,2105,45.8803
27.90694327,96.39,2208,46.9894
27.9594644,96.39,2138,46.2385
28.01198553,96.39,2175,46.6369
28.06450666,96.39,2168,46.5618
28.11702779,96.39,2248,47.4131
28.16954892,96.39,2234,47.2652
28.22207005,96.39,2176,46.6476
28.27459118,96.39,2142,46.2817
28.32711232,96.39,2124,46.0869
28.37963345,96.39,2024,44.9889
28.43215458,96.39,2056,45.3431
28.48467571,96.39,2072,45.5192
28.53719684,96.39,2130,46.1519
28.58971797,96.39,2045,45.2217
28.6422391,96.39,2093,45.7493
28.69476023,96.39,2127,46.1194
28.74728136,96.39,2325,48.2183
28.79980249,96.39,2221,47.1275
28.85232362,96.39,2109,45.9239
28.90484475,96.39,2047,45.2438
28.95736588,96.39,2155,46.422
29.00988701,96.39,2228,47.2017
29.06240815,96.39,2342,48.3942
29.11492928,96.39,2395,48.9387
29.16745041,96.39,2189,46.7868
29.21997154,96.39,2113,45.9674
29.27249267,96.39,2048,45.2548
29.3250138,96.39,2034,45.0999
29.37753493,96.39,2130,46.1519
29.43005606,96.39,1962,44.2945
29.48257719,96.39,1958,44.2493
29.53509832,96.39,1989,44.5982
29.58761945,96.39,1925,43.8748
29.64014058,96.39,2022,44.9667
29.69266171,96.39,1914,43.7493
29.74518284,96.39,1941,44.0568
29.79770398,96.39,1921,43.8292
29.85022511,96.39,1987,44.5758
29.90274624,96.39,1900,43.589
29.95526737,96.39,1955,44.2154
30.0077885,96.39,1879,43.3474
30.06030963,96.39,1892,43.4971
30.11283076,96.39,1909,43.6921
30.16535189,96.39,1856,43.0813
30.21787302,96.39,1840,42.8952
30.27039415,96.39,1967,44.3509
30.32291528,96.39,2024,44.9889
30.37543641,96.39,1950,44.1588
30.42795754,96.39,1962,44.2945
30.48047867,96.39,1847,42.9767
30.53299981,96.39,1943,44.0795
30.58552094,96.39,2093,45.7493
30.63804207,96.39,2272,47.6655
30.6905632,96.39,2323,48.1975
30.74308433,96.39,2205,46.9574
30.79560546,96.39,2130,46.1519
30.84812659,96.39,2140,46.2601
30.90064772,96.39,2020,44.9444
30.95316885,96.39,1902,43.6119
31.00568998,96.39,1971,44.3959
31.05821111,96.39,2079,45.5961
31.11073224,96.39,2282,47.7703
31.16325337,96.39,2514,50.1398
31.2157745,96.39,2704,52
31.26829564,96.39,2430,49.295
31.32081677,96.39,2104,45.8694
31.3733379,96.39,2019,44.9333
31.42585903,96.39,2021,44.9555
31.47838016,96.39,2207,46.9787
31.53090129,96.39,2286,47.8121
31.58342242,96.39,2232,47.244
31.63594355,96.39,2057,45.3542
31.68846468,96.39,2076,45.5631
31.74098581,96.39,1987,44.5758
31.79350694,96.39,2143,46.2925
31.84602807,96.39,2392,48.9081
31.8985492,96.39,2543,50.4282
31.95107033,96.39,3168,56.285
32.00359147,96.39,4387,66.2344
32.0561126,96.39,5088,71.3302
32.10863373,96.39,4207,64.8614
32.16115486,96.39,3189,56.4712
32.21367599,96.39,2254,47.4763
32.26619712,96.39,1899,43.5775
32.31871825,96.39,1857,43.0929
32.37123938,96.39,1734,41.6413
32.42376051,96.39,1666,40.8167
32.47628164,96.39,1748,41.8091
32.52880277,96.39,1728,41.5692
32.5813239,96.39,1769,42.0595
32.63384503,96.39,1787,42.2729
32.68636616,96.39,1806,42.4971
32.7388873,96.39,1839,42.8836
32.79140843,96.39,1789,42.2966
32.84392956,96.39,1738,41.6893
32.89645069,96.39,1819,42.6497
32.94897182,96.39,1978,44.4747
33.00149295,96.39,2308,48.0416
33.05401408,96.39,1986,44.5646
33.10653521,96.39,2037,45.1331
33.15905634,96.39,1843,42.9302
33.21157747,96.39,1774,42.1189
33.2640986,96.39,1762,41.9762
33.31661973,96.39,1771,42.0833
33.36914086,96.39,1799,42.4146
33.42166199,96.39,3218,56.7274
33.47418312,96.39,2184,46.7333
33.52670426,96.39,2345,48.4252
33.57922539,96.39,1816,42.6146
33.63174652,96.39,1707,41.3159
33.68426765,96.39,1741,41.7253
33.73678878,96.39,1764,42
33.78930991,96.39,1915,43.7607
33.84183104,96.39,2115,45.9891
33.89435217,96.39,2529,50.2892
33.9468733,96.39,2947,54.2863
33.99939443,96.39,2840,53.2917
34.05191556,96.39,2534,50.3389
34.10443669,96.39,2254,47.4763
34.15695782,96.39,1998,44.699
34.20947895,96.39,1953,44.1928
34.26200009,96.39,1979,44.486
34.31452122,96.39,2221,47.1275
34.36704235,96.39,2108,45.913
34.41956348,96.39,2197,46.8722
34.47208461,96.39,2181,46.7012
34.52460574,96.39,2129,46.1411
34.57712687,96.39,2067,45.4643
34.629648,96.39,2043,45.1996
34.68216913,96.39,2032,45.0777
34.73469026,96.39,2045,45.2217
34.78721139,96.39,2125,46.0977
34.83973252,96.39,2526,50.2593
34.89225365,96.39,2771,52.6403
34.94477478,96.39,2915,53.9907
34.99729592,96.39,2551,50.5074
35.04981705,96.39,2201,46.9148
35.10233818,96.39,1980,44.4972
35.15485931,96.39,2168,46.5618
35.20738044,96.39,2797,52.8867
35.25990157,96.39,2125,46.0977
35.3124227,96.39,2177,46.6583
35.36494383,96.39,1704,41.2795
35.41746496,96.39,1660,40.7431
35.46998609,96.39,1738,41.6893
35.52250722,96.39,1722,41.497
35.57502835,96.39,1789,42.2966
35.62754948,96.39,1666,40.8167
35.68007061,96.39,1712,41.3763
35.73259175,96.39,1699,41.2189
35.78511288,96.39,1646,40.5709
35.83763401,96.39,1659,40.7308
35.89015514,96.39,1692,41.1339
35.94267627,96.39,1580,39.7492
35.9951974,96.39,1570,39.6232
36.04771853,96.39,1587,39.8372
36.10023966,96.39,1594,39.9249
36.15276079,96.39,1523,39.0256
36.20528192,96.39,1595,39.9375
36.25780305,96.39,1585,39.8121
36.31032418,96.39,1492,38.6264
36.36284531,96.39,1581,39.7618
36.41536644,96.39,1512,38.8844
36.46788758,96.39,1441,37.9605
36.52040871,96.39,1445,38.0132
36.57292984,96.39,1439,37.9342
36.62545097,96.39,1501,38.7427
36.6779721,96.39,1419,37.6696
36.73049323,96.39,1451,38.092
36.78301436,96.39,1453,38.1182
36.83553549,96.39,1403,37.4566
36.88805662,96.39,1406,37.4967
36.94057775,96.39,1392,37.3095
36.99309888,96.39,1398,37.3898
37.04562001,96.39,1292,35.9444
37.09814114,96.39,1408,37.5233
37.15066227,96.39,1403,37.4566
37.20318341,96.39,1304,36.1109
37.25570454,96.39,1358,36.8511
37.30822567,96.39,1303,36.0971
37.3607468,96.39,1324,36.3868
37.41326793,96.39,1322,36.3593
37.46578906,96.39,1447,38.0395
37.51831019,96.39,1304,36.1109
37.57083132,96.39,1370,37.0135
37.62335245,96.39,1438,37.921
37.67587358,96.39,1561,39.5095
37.72839471,96.39,1679,40.9756
37.78091584,96.39,1605,40.0625
37.83343697,96.39,1524,39.0384
37.8859581,96.39,1443,37.9868
37.93847924,96.39,1349,36.7287
37.99100037,96.39,1309,36.1801
38.0435215,96.39,1279,35.7631
38.09604263,96.39,1321,36.3456
38.14856376,96.39,1545,39.3065
38.20108489,96.39,1430,37.8153
38.25360602,96.39,1439,37.9342
38.30612715,96.39,1601,40.0125
38.35864828,96.39,1346,36.6879
38.41116941,96.39,1493,38.6394
38.46369054,96.39,1291,35.9305
38.51621167,96.39,1299,36.0416
38.5687328,96.39,1341,36.6197
38.62125393,96.39,1353,36.7831
38.67377507,96.39,1369,37
38.7262962,96.39,1489,38.5876
38.77881733,96.39,1539,39.2301
38.83133846,96.39,1407,37.51
38.88385959,96.39,1339,36.5923
38.93638072,96.39,1222,34.9571
38.98890185,96.39,1291,35.9305
39.04142298,96.39,1533,39.1535
39.09394411,96.39,1179,34.3366
39.14646524,96.39,1406,37.4967
39.19898637,96.39,1340,36.606
39.2515075,96.39,1315,36.2629
39.30402863,96.39,1437,37.9078
39.35654976,96.39,1604,40.05
39.4090709,96.39,1571,39.6358
39.46159203,96.39,1552,39.3954
39.51411316,96.39,1518,38.9615
39.56663429,96.39,1359,36.8646
39.61915542,96.39,1225,35
39.67167655,96.39,1270,35.6371
39.72419768,96.39,1178,34.322
39.77671881,96.39,1142,33.7935
39.82923994,96.39,1230,35.0714
39.88176107,96.39,1242,35.242
39.9342822,96.39,1262,35.5246
39.98680333,96.39,1226,35.0143
40.03932446,96.39,1227,35.0286
40.09184559,96.39,1283,35.819
40.14436673,96.39,1328,36.4417
40.19688786,96.39,1281,35.7911
40.24940899,96.39,1177,34.3074
40.30193012,96.39,1195,34.5688
40.35445125,96.39,1150,33.9116
40.40697238,96.39,1213,34.8281
40.45949351,96.39,1191,34.5109
40.51201464,96.39,1207,34.7419
40.56453577,96.39,1200,34.641
40.6170569,96.39,1168,34.176
40.66957803,96.39,1190,34.4964
40.72209916,96.39,1186,34.4384
40.77462029,96.39,1128,33.5857
40.82714142,96.39,1113,33.3617
40.87966255,96.39,1039,32.2335
40.93218369,96.39,1067,32.665
40.98470482,96.39,1141,33.7787
41.03722595,96.39,1102,33.1964
41.08974708,96.39,1139,33.7491
41.14226821,96.39,1116,33.4066
41.19478934,96.39,1090,33.0151
41.24731047,96.39,1249,35.3412
41.2998316,96.39,1331,36.4829
41.35235273,96.39,1576,39.6989
41.40487386,96.39,1472,38.3667
41.45739499,96.39,1335,36.5377
41.50991612,96.39,1337,36.565
41.56243725,96.39,1127,33.5708
41.61495838,96.39,1094,33.0757
41.66747952,96.39,1031,32.1092
41.72000065,96.39,968,31.1127
41.77252178,96.39,1065,32.6343
41.82504291,96.39,1041,32.2645
41.87756404,96.39,989,31.4484
41.93008517,96.39,1003,31.6702
41.9826063,96.39,1085,32.9393
42.03512743,96.39,1112,33.3467
42.08764856,96.39,1246,35.2987
42.14016969,96.39,1279,35.7631
42.19269082,96.39,1284,35.8329
42.24521195,96.39,1195,34.5688
42.29773308,96.39,1094,33.0757
42.35025421,96.39,1039,32.2335
42.40277535,96.39,1038,32.218
42.45529648,96.39,1109,33.3017
42.50781761,96.39,1141,33.7787
42.56033874,96.39,1154,33.9706
42.61285987,96.39,1171,34.2199
42.665381,96.39,1088,32.9848
42.71790213,96.39,1033,32.1403
42.77042326,96.39,1016,31.8748
42.82294439,96.39,1016,31.8748
42.87546552,96.39,1062,32.5883
42.92798665,96.39,1075,32.7872
42.98050778,96.39,1041,32.2645
43.03302891,96.39,990,31.4643
43.08555004,96.39,1037,32.2025
43.13807118,96.39,990,31.4643
43.19059231,96.39,978,31.273
43.24311344,96.39,997,31.5753
43.29563457,96.39,994,31.5278
43.3481557,96.39,1005,31.7017
43.40067683,96.39,1021,31.9531
43.45319796,96.39,992,31.496
43.50571909,96.39,1011,31.7962
43.55824022,96.39,966,31.0805
43.61076135,96.39,1120,33.4664
43.66328248,96.39,1183,34.3948
43.71580361,96.39,1474,38.3927
43.76832474,96.39,1484,38.5227
43.82084587,96.39,1377,37.108
43.87336701,96.39,1297,36.0139
43.92588814,96.39,1146,33.8526
43.97840927,96.39,1047,32.3574
44.0309304,96.39,1077,32.8177
44.08345153,96.39,1005,31.7017
44.13597266,96.39,1024,32
44.18849379,96.39,1010,31.7805
44.24101492,96.39,1109,33.3017
44.29353605,96.39,1173,34.2491
44.34605718,96.39,1293,35.9583
44.39857831,96.39,1304,36.1109
44.45109944,96.39,1253,35.3977
44.50362057,96.39,1228,35.0428
44.5561417,96.39,1110,33.3167
44.60866284,96.39,1114,33.3766
44.66118397,96.39,1045,32.3265
44.7137051,96.39,1036,32.187
44.76622623,96.39,1108,33.2866
44.81874736,96.39,1119,33.4515
44.87126849,96.39,1030,32.0936
44.92378962,96.39,1066,32.6497
44.97631075,96.39,1094,33.0757
45.02883188,96.39,1198,34.6121
45.08135301,96.39,1364,36.9324
45.13387414,96.39,1369,37
45.18639527,96.39,1289,35.9026
45.2389164,96.39,1400,37.4166
45.29143753,96.39,1302,36.0832
45.34395867,96.39,1305,36.1248
45.3964798,96.39,1318,36.3043
45.44900093,96.39,1305,36.1248
45.50152206,96.39,1277,35.7351
45.55404319,96.39,1190,34.4964
45.60656432,96.39,1178,34.322
45.65908545,96.39,1164,34.1174
45.71160658,96.39,1050,32.4037
45.76412771,96.39,1023,31.9844
45.81664884,96.39,1121,33.4813
45.86916997,96.39,1141,33.7787
45.9216911,96.39,1059,32.5423
45.97421223,96.39,1074,32.7719
46.02673336,96.39,1077,32.8177
46.0792545,96.39,1169,34.1906
46.13177563,96.39,1172,34.2345
46.18429676,96.39,1241,35.2278
46.23681789,96.39,1196,34.5832
46.28933902,96.39,1329,36.4555
46.34186015,96.39,1134,33.6749
46.39438128,96.39,1244,35.2704
46.44690241,96.39,1123,33.5112
46.49942354,96.39,1112,33.3467
46.55194467,96.39,1120,33.4664
46.6044658,96.39,1028,32.0624
46.65698693,96.39,1030,32.0936
46.70950806,96.39,1024,32
46.76202919,96.39,1040,32.249
46.81455033,96.39,1094,33.0757
46.86707146,96.39,1095,33.0908
46.91959259,96.39,1064,32.619
46.97211372,96.39,1182,34.3802
47.02463485,96.39,1127,33.5708
47.07715598,96.39,1037,32.2025
47.12967711,96.39,1018,31.9061
47.18219824,96.39,999,31.607
47.23471937,96.39,1006,31.7175
47.2872405,96.39,1033,32.1403
47.33976163,96.39,1054,32.4654
47.39228276,96.39,1013,31.8277
47.44480389,96.39,985,31.3847
47.49732502,96.39,1020,31.9374
47.54984616,96.39,985,31.3847
47.60236729,96.39,990,31.4643
47.65488842,96.39,1009,31.7648
47.70740955,96.39,948,30.7896
47.75993068,96.39,981,31.3209
47.81245181,96.39,1008,31.749
47.86497294,96.39,904,30.0666
47.91749407,96.39,961,31
47.9700152,96.39,984,31.3688
48.02253633,96.39,1028,32.0624
48.07505746,96.39,1012,31.8119
48.12757859,96.39,1146,33.8526
48.18009972,96.39,1055,32.4808
48.23262085,96.39,1078,32.8329
48.28514198,96.39,1013,31.8277
48.33766312,96.39,1005,31.7017
48.39018425,96.39,989,31.4484
48.44270538,96.39,1058,32.5269
48.49522651,96.39,1154,33.9706
48.54774764,96.39,1142,33.7935
48.60026877,96.39,1056,32.4962
48.6527899,96.39,1036,32.187
48.70531103,96.39,1021,31.9531
48.75783216,96.39,967,31.0966
48.81035329,96.39,933,30.545
48.86287442,96.39,926,30.4302
48.91539555,96.39,916,30.2655
48.96791668,96.39,930,30.4959
49.02043781,96.39,954,30.8869
49.07295895,96.39,902,30.0333
49.12548008,96.39,933,30.545
49.17800121,96.39,906,30.0998
49.23052234,96.39,929,30.4795
49.28304347,96.39,919,30.315
49.3355646,96.39,975,31.225
49.38808573,96.39,913,30.2159
49.44060686,96.39,908,30.133
49.49312799,96.39,919,30.315
49.54564912,96.39,974,31.209
49.59817025,96.39,890,29.8329
49.65069138,96.39,926,30.4302
49.70321251,96.39,937,30.6105
49.75573364,96.39,819,28.6182
49.80825478,96.39,869,29.4788
49.86077591,96.39,928,30.4631
49.91329704,96.39,839,28.9655
49.96581817,96.39,884,29.7321
50.0183393,96.39,889,29.8161
50.07086043,96.39,860,29.3258
50.12338156,96.39,872,29.5296
50.17590269,96.39,945,30.7409
50.22842382,96.39,1075,32.7872
50.28094495,96.39,1080,32.8634
50.33346608,96.39,918,30.2985
50.38598721,96.39,980,31.305
50.43850834,96.39,857,29.2746
50.49102947,96.39,857,29.2746
50.54355061,96.39,866,29.4279
50.59607174,96.39,853,29.2062
50.64859287,96.39,815,28.5482
50.701114,96.39,804,28.3549
50.75363513,96.39,800,28.2843
50.80615626,96.39,777,27.8747
50.85867739,96.39,864,29.3939
50.91119852,96.39,830,28.8097
50.96371965,96.39,823,28.688
51.01624078,96.39,837,28.931
51.06876191,96.39,852,29.189
51.12128304,96.39,934,30.5614
51.17380417,96.39,930,30.4959
51.2263253,96.39,909,30.1496
51.27884644,96.39,886,29.7658
51.33136757,96.39,877,29.6142
51.3838887,96.39,796,28.2135
51.43640983,96.39,803,28.3373
51.48893096,96.39,789,28.0891
51.54145209,96.39,788,28.0713
51.59397322,96.39,791,28.1247
51.64649435,96.39,797,28.2312
51.69901548,96.39,813,28.5132
51.75153661,96.39,852,29.189
51.80405774,96.39,864,29.3939
51.85657887,96.39,841,29
51.9091,96.39,779,27.9106
51.96162113,96.39,803,28.3373
52.01414227,96.39,852,29.189
52.0666634,96.39,886,29.7658
52.11918453,96.39,937,30.6105
52.17170566,96.39,998,31.5911
52.22422679,96.39,1108,33.2866
52.27674792,96.39,1003,31.6702
52.32926905,96.39,983,31.3528
52.38179018,96.39,937,30.6105
52.43431131,96.39,913,30.2159
52.48683244,96.39,779,27.9106
52.53935357,96.39,846,29.0861
52.5918747,96.39,802,28.3196
52.64439583,96.39,818,28.6007
52.69691696,96.39,825,28.7228
52.7494381,96.39,791,28.1247
52.80195923,96.39,804,28.3549
52.85448036,96.39,873,29.5466
52.90700149,96.39,827,28.7576
52.95952262,96.39,868,29.4618
53.01204375,96.39,855,29.2404
53.06456488,96.39,814,28.5307
53.11708601,96.39,802,28.3196
53.16960714,96.39,835,28.8964
53.22212827,96.39,903,30.05
53.2746494,96.39,838,28.9482
53.32717053,96.39,814,28.5307
53.37969166,96.39,879,29.6479
53.43221279,96.39,825,28.7228
53.48473393,96.39,802,28.3196
53.53725506,96.39,838,28.9482
53.58977619,96.39,826,28.7402
53.64229732,96.39,802,28.3196
53.69481845,96.39,826,28.7402
53.74733958,96.39,805,28.3725
53.79986071,96.39,760,27.5681
53.85238184,96.39,766,27.6767
53.90490297,96.39,740,27.2029
53.9574241,96.39,784,28
54.00994523,96.39,814,28.5307
54.06246636,96.39,834,28.8791
54.11498749,96.39,874,29.5635
54.16750862,96.39,906,30.0998
54.22002976,96.39,845,29.0689
54.27255089,96.39,881,29.6816
54.32507202,96.39,838,28.9482
54.37759315,96.39,864,29.3939
54.43011428,96.39,795,28.1957
54.48263541,96.39,827,28.7576
54.53515654,96.39,740,27.2029
54.58767767,96.39,743,27.258
54.6401988,96.39,764,27.6405
54.69271993,96.39,729,27
54.74524106,96.39,729,27
54.79776219,96.39,753,27.4408
54.85028332,96.39,737,27.1477
54.90280445,96.39,711,26.6646
54.95532559,96.39,905,30.0832
55.00784672,96.39,781,27.9464
55.06036785,96.39,742,27.2397
55.11288898,96.39,824,28.7054
55.16541011,96.39,775,27.8388
55.21793124,96.39,678,26.0384
55.27045237,96.39,719,26.8142
55.3229735,96.39,704,26.533
55.37549463,96.39,634,25.1794
55.42801576,96.39,757,27.5136
55.48053689,96.39,710,26.6458
55.53305802,96.39,789,28.0891
55.58557915,96.39,761,27.5862
55.63810028,96.39,737,27.1477
55.69062141,96.39,713,26.7021
55.74314255,96.39,743,27.258
55.79566368,96.39,774,27.8209
55.84818481,96.39,723,26.8887
55.90070594,96.39,714,26.7208
55.95322707,96.39,742,27.2397
56.0057482,96.39,724,26.9072
56.05826933,96.39,666,25.807
56.11079046,96.39,713,26.7021
56.16331159,96.39,744,27.2764
56.21583272,96.39,650,25.4951
56.26835385,96.39,723,26.8887
56.32087498,96.39,687,26.2107
56.37339611,96.39,719,26.8142
56.42591724,96.39,737,27.1477
56.47843838,96.39,661,25.7099
56.53095951,96.39,730,27.0185
56.58348064,96.39,686,26.1916
56.63600177,96.39,710,26.6458
56.6885229,96.39,716,26.7582
56.74104403,96.39,685,26.1725
56.79356516,96.39,706,26.5707
56.84608629,96.39,694,26.3439
56.89860742,96.39,697,26.4008
56.95112855,96.39,647,25.4362
57.00364968,96.39,723,26.8887
57.05617081,96.39,714,26.7208
57.10869194,96.39,688,26.2298
57.16121307,96.39,625,25
57.21373421,96.39,702,26.4953
57.26625534,96.39,741,27.2213
57.31877647,96.39,704,26.533
57.3712976,96.39,672,25.923
57.42381873,96.39,666,25.807
57.47633986,96.39,666,25.807
57.52886099,96.39,688,26.2298
57.58138212,96.39,674,25.9615
57.63390325,96.39,731,27.037
57.68642438,96.39,696,26.3818
57.73894551,96.39,741,27.2213
57.79146664,96.39,696,26.3818
57.84398777,96.39,754,27.4591
57.8965089,96.39,682,26.1151
57.94903004,96.39,746,27.313
58.00155117,96.39,854,29.2233
58.0540723,96.39,849,29.1376
58.10659343,96.39,801,28.3019
58.15911456,96.39,861,29.3428
58.21163569,96.39,806,28.3901
58.26415682,96.39,699,26.4386
58.31667795,96.39,713,26.7021
58.36919908,96.39,690,26.2679
58.42172021,96.39,673,25.9422
58.47424134,96.39,689,26.2488
58.52676247,96.39,688,26.2298
58.5792836,96.39,609,24.6779
58.63180473,96.39,691,26.2869
58.68432587,96.39,624,24.98
58.736847,96.39,690,26.2679
58.78936813,96.39,710,26.6458
58.84188926,96.39,689,26.2488
58.89441039,96.39,692,26.3059
58.94693152,96.39,661,25.7099
58.99945265,96.39,696,26.3818
59.05197378,96.39,642,25.3377
59.10449491,96.39,653,25.5539
59.15701604,96.39,710,26.6458
59.20953717,96.39,708,26.6083
59.2620583,96.39,683,26.1343
59.31457943,96.39,719,26.8142
59.36710056,96.39,708,26.6083
59.4196217,96.39,654,25.5734
59.47214283,96.39,744,27.2764
59.52466396,96.39,729,27
59.57718509,96.39,719,26.8142
59.62970622,96.39,712,26.6833
59.68222735,96.39,718,26.7955
59.73474848,96.39,715,26.7395
59.78726961,96.39,765,27.6586
59.83979074,96.39,752,27.4226
59.89231187,96.39,750,27.3861
59.944833,96.39,767,27.6948
59.99735413,96.39,801,28.3019
60.04987526,96.39,756,27.4955
60.10239639,96.39,751,27.4044
60.15491753,96.39,808,28.4253
60.20743866,96.39,802,28.3196
60.25995979,96.39,773,27.8029
60.31248092,96.39,719,26.8142
60.36500205,96.39,814,28.5307
60.41752318,96.39,807,28.4077
60.47004431,96.39,848,29.1204
60.52256544,96.39,799,28.2666
60.57508657,96.39,901,30.0167
60.6276077,96.39,918,30.2985
60.68012883,96.39,932,30.5287
60.73264996,96.39,920,30.3315
60.78517109,96.39,1029,32.078
60.83769222,96.39,1010,31.7805
60.89021336,96.39,1042,32.28
60.94273449,96.39,1123,33.5112
60.99525562,96.39,1123,33.5112
61.04777675,96.39,1176,34.2929
61.10029788,96.39,1098,33.1361
61.15281901,96.39,1045,32.3265
61.20534014,96.39,1053,32.45
61.25786127,96.39,996,31.5595
61.3103824,96.39,1046,32.3419
61.36290353,96.39,1034,32.1559
61.41542466,96.39,980,31.305
61.46794579,96.39,977,31.257
61.52046692,96.39,914,30.2324
61.57298805,96.39,933,30.545
61.62550919,96.39,852,29.189
61.67803032,96.39,914,30.2324
61.73055145,96.39,818,28.6007
61.78307258,96.39,817,28.5832
61.83559371,96.39,878,29.6311
61.88811484,96.39,857,29.2746
61.94063597,96.39,867,29.4449
61.9931571,96.39,744,27.2764
62.04567823,96.39,809,28.4429
62.09819936,96.39,814,28.5307
62.15072049,96.39,790,28.1069
62.20324162,96.39,730,27.0185
62.25576275,96.39,771,27.7669
62.30828388,96.39,771,27.7669
62.36080502,96.39,781,27.9464
62.41332615,96.39,689,26.2488
62.46584728,96.39,797,28.2312
62.51836841,96.39,742,27.2397
62.57088954,96.39,780,27.9285
62.62341067,96.39,721,26.8514
62.6759318,96.39,807,28.4077
62.72845293,96.39,778,27.8927
62.78097406,96.39,787,28.0535
62.83349519,96.39,755,27.4773
62.88601632,96.39,677,26.0192
62.93853745,96.39,675,25.9808
62.99105858,96.39,684,26.1534
63.04357971,96.39,633,25.1595
63.09610084,96.39,631,25.1197
63.14862198,96.39,628,25.0599
63.20114311,96.39,606,24.6171
63.25366424,96.39,670,25.8844
63.30618537,96.39,656,25.6125
63.3587065,96.39,640,25.2982
63.41122763,96.39,585,24.1868
63.46374876,96.39,641,25.318
63.51626989,96.39,668,25.8457
63.56879102,96.39,624,24.98
63.62131215,96.39,644,25.3772
63.67383328,96.39,641,25.318
63.72635441,96.39,680,26.0768
63.77887554,96.39,710,26.6458
63.83139667,96.39,660,25.6905
63.88391781,96.39,683,26.1343
63.93643894,96.39,630,25.0998
63.98896007,96.39,635,25.1992
64.0414812,96.39,677,26.0192
64.09400233,96.39,647,25.4362
64.14652346,96.39,629,25.0799
64.19904459,96.39,641,25.318
64.25156572,96.39,672,25.923
64.30408685,96.39,670,25.8844
64.35660798,96.39,654,25.5734
64.40912911,96.39,611,24.7184
64.46165024,96.39,571,23.8956
64.51417137,96.39,617,24.8395
64.5666925,96.39,617,24.8395
64.61921364,96.39,543,23.3024
64.67173477,96.39,596,24.4131
64.7242559,96.39,584,24.1661
64.77677703,96.39,547,23.388
64.82929816,96.39,572,23.9165
64.88181929,96.39,597,24.4336
64.93434042,96.39,568,23.8328
64.98686155,96.39,546,23.3666