File: Files_organized_for_plots/Constant_NaOH_1mL10M_to_1gPC_28Day_repeat/SiCorner03Nov21_Act12Feb23_B1_0833M_NaOH_LS0153_Num151.csv
[Measurement conditions]
Sample identification,SiCorner03Nov21_Act12Feb23_B1_0833M_NaOH_LS0153_Num151
Comment - 1,"Configuration=Stage for Flat Samples/Holders, Owner=nmw10, Creation date=9/21/2022 10:06:30 AM"
Comment - 2,"Goniometer=Theta/Theta; Minimum step size 2Theta:0.0001; Minimum step size Omega:0.0001"
Comment - 3,"Sample stage=Stage for flat samples/holders"
Comment - 4,"Diffractometer system=EMPYREAN"
Comment - 5,"Measurement program=X:\XRD\Cement\Zerobackground scan.xrdmp, Created identifier={98A3B11C-88F9-4AA6-982C-73314A311EF5}, Created by=Titus Reed, Id=tmr79, Creation date=10/26/2021 3:01:47 PM"
Anode material,Cu
K-Alpha1 wavelength,1.5405980
K-Alpha2 wavelength,1.5444260
Ratio K-Alpha2/K-Alpha1,0.500
Divergence slit,Fixed,0.25
Monochromator used,NO
Generator voltage, 45
Tube current, 40
File date and time,15/Mar/2023 18:23
Unit cell,
h k l, 0 0 0
Scan axis,Gonio
Scan range,4.994599997,64.999991833
Scan step size,0.0262606
No. of points, 2285
Scan type,CONTINUOUS
Time per step,96.390
[Scan points]
Angle, TimePerStep, Intensity, ESD
5.007730280, 96.390, 3938.0, 62.7535
5.060251411, 96.390, 3882.0, 62.3057
5.112772541, 96.390, 3840.0, 61.9677
5.165293672, 96.390, 3910.0, 62.5300
5.217814803, 96.390, 3647.0, 60.3904
5.270335934, 96.390, 3742.0, 61.1719
5.322857064, 96.390, 3687.0, 60.7207
5.375378195, 96.390, 3576.0, 59.7997
5.427899326, 96.390, 3554.0, 59.6154
5.480420456, 96.390, 3538.0, 59.4811
5.532941587, 96.390, 3619.0, 60.1581
5.585462718, 96.390, 3491.0, 59.0847
5.637983849, 96.390, 3588.0, 59.8999
5.690504979, 96.390, 3488.0, 59.0593
5.743026110, 96.390, 3611.0, 60.0916
5.795547241, 96.390, 3543.0, 59.5231
5.848068371, 96.390, 3531.0, 59.4222
5.900589502, 96.390, 3420.0, 58.4808
5.953110633, 96.390, 3442.0, 58.6686
6.005631763, 96.390, 3527.0, 59.3886
6.058152894, 96.390, 3485.0, 59.0339
6.110674025, 96.390, 3535.0, 59.4559
6.163195156, 96.390, 3375.0, 58.0948
6.215716286, 96.390, 3471.0, 58.9152
6.268237417, 96.390, 3489.0, 59.0678
6.320758548, 96.390, 3401.0, 58.3181
6.373279678, 96.390, 3445.0, 58.6941
6.425800809, 96.390, 3464.0, 58.8558
6.478321940, 96.390, 3489.0, 59.0678
6.530843071, 96.390, 3469.0, 58.8982
6.583364201, 96.390, 3382.0, 58.1550
6.635885332, 96.390, 3432.0, 58.5833
6.688406463, 96.390, 3381.0, 58.1464
6.740927593, 96.390, 3481.0, 59.0000
6.793448724, 96.390, 3438.0, 58.6345
6.845969855, 96.390, 3322.0, 57.6368
6.898490986, 96.390, 3397.0, 58.2838
6.951012116, 96.390, 3361.0, 57.9741
7.003533247, 96.390, 3500.0, 59.1608
7.056054378, 96.390, 3417.0, 58.4551
7.108575508, 96.390, 3355.0, 57.9224
7.161096639, 96.390, 3335.0, 57.7495
7.213617770, 96.390, 3301.0, 57.4543
7.266138900, 96.390, 3482.0, 59.0085
7.318660031, 96.390, 3414.0, 58.4294
7.371181162, 96.390, 3453.0, 58.7622
7.423702293, 96.390, 3316.0, 57.5847
7.476223423, 96.390, 3441.0, 58.6600
7.528744554, 96.390, 3324.0, 57.6541
7.581265685, 96.390, 3300.0, 57.4456
7.633786815, 96.390, 3406.0, 58.3609
7.686307946, 96.390, 3400.0, 58.3095
7.738829077, 96.390, 3418.0, 58.4637
7.791350208, 96.390, 3301.0, 57.4543
7.843871338, 96.390, 3489.0, 59.0678
7.896392469, 96.390, 3317.0, 57.5934
7.948913600, 96.390, 3435.0, 58.6089
8.001434730, 96.390, 3385.0, 58.1808
8.053955861, 96.390, 3373.0, 58.0775
8.106476992, 96.390, 3392.0, 58.2409
8.158998123, 96.390, 3469.0, 58.8982
8.211519253, 96.390, 3332.0, 57.7235
8.264040384, 96.390, 3338.0, 57.7754
8.316561515, 96.390, 3395.0, 58.2666
8.369082645, 96.390, 3192.0, 56.4978
8.421603776, 96.390, 3264.0, 57.1314
8.474124907, 96.390, 3290.0, 57.3585
8.526646038, 96.390, 3336.0, 57.7581
8.579167168, 96.390, 3337.0, 57.7668
8.631688299, 96.390, 3335.0, 57.7495
8.684209430, 96.390, 3221.0, 56.7539
8.736730560, 96.390, 3227.0, 56.8067
8.789251691, 96.390, 3270.0, 57.1839
8.841772822, 96.390, 3221.0, 56.7539
8.894293952, 96.390, 3251.0, 57.0175
8.946815083, 96.390, 3374.0, 58.0861
8.999336214, 96.390, 3279.0, 57.2626
9.051857345, 96.390, 3213.0, 56.6833
9.104378475, 96.390, 3229.0, 56.8243
9.156899606, 96.390, 3338.0, 57.7754
9.209420737, 96.390, 3285.0, 57.3149
9.261941867, 96.390, 3185.0, 56.4358
9.314462998, 96.390, 3274.0, 57.2189
9.366984129, 96.390, 3144.0, 56.0714
9.419505260, 96.390, 3227.0, 56.8067
9.472026390, 96.390, 3165.0, 56.2583
9.524547521, 96.390, 3282.0, 57.2887
9.577068652, 96.390, 3215.0, 56.7010
9.629589782, 96.390, 3094.0, 55.6237
9.682110913, 96.390, 3055.0, 55.2721
9.734632044, 96.390, 3120.0, 55.8570
9.787153175, 96.390, 3145.0, 56.0803
9.839674305, 96.390, 3146.0, 56.0892
9.892195436, 96.390, 3227.0, 56.8067
9.944716567, 96.390, 3164.0, 56.2494
9.997237697, 96.390, 3163.0, 56.2406
10.049758828, 96.390, 3189.0, 56.4712
10.102279959, 96.390, 3109.0, 55.7584
10.154801090, 96.390, 3113.0, 55.7943
10.207322220, 96.390, 3029.0, 55.0364
10.259843351, 96.390, 3103.0, 55.7046
10.312364482, 96.390, 3102.0, 55.6956
10.364885612, 96.390, 3064.0, 55.3534
10.417406743, 96.390, 3134.0, 55.9821
10.469927874, 96.390, 3250.0, 57.0088
10.522449004, 96.390, 3144.0, 56.0714
10.574970135, 96.390, 3017.0, 54.9272
10.627491266, 96.390, 2912.0, 53.9630
10.680012397, 96.390, 2887.0, 53.7308
10.732533527, 96.390, 2997.0, 54.7449
10.785054658, 96.390, 3083.0, 55.5248
10.837575789, 96.390, 2968.0, 54.4794
10.890096919, 96.390, 3026.0, 55.0091
10.942618050, 96.390, 3057.0, 55.2901
10.995139181, 96.390, 3083.0, 55.5248
11.047660312, 96.390, 3010.0, 54.8635
11.100181442, 96.390, 3008.0, 54.8452
11.152702573, 96.390, 2976.0, 54.5527
11.205223704, 96.390, 2952.0, 54.3323
11.257744834, 96.390, 2965.0, 54.4518
11.310265965, 96.390, 2904.0, 53.8888
11.362787096, 96.390, 2901.0, 53.8609
11.415308227, 96.390, 2816.0, 53.0660
11.467829357, 96.390, 2978.0, 54.5711
11.520350488, 96.390, 2949.0, 54.3047
11.572871619, 96.390, 2977.0, 54.5619
11.625392749, 96.390, 2869.0, 53.5630
11.677913880, 96.390, 2850.0, 53.3854
11.730435011, 96.390, 2762.0, 52.5547
11.782956141, 96.390, 2683.0, 51.7977
11.835477272, 96.390, 2814.0, 53.0471
11.887998403, 96.390, 2798.0, 52.8961
11.940519534, 96.390, 2732.0, 52.2685
11.993040664, 96.390, 2801.0, 52.9245
12.045561795, 96.390, 2715.0, 52.1057
12.098082926, 96.390, 2720.0, 52.1536
12.150604056, 96.390, 2647.0, 51.4490
12.203125187, 96.390, 2738.0, 52.3259
12.255646318, 96.390, 2774.0, 52.6688
12.308167449, 96.390, 2670.0, 51.6720
12.360688579, 96.390, 2620.0, 51.1859
12.413209710, 96.390, 2766.0, 52.5928
12.465730841, 96.390, 2651.0, 51.4879
12.518251971, 96.390, 2613.0, 51.1175
12.570773102, 96.390, 2676.0, 51.7301
12.623294233, 96.390, 2733.0, 52.2781
12.675815364, 96.390, 2600.0, 50.9902
12.728336494, 96.390, 2524.0, 50.2394
12.780857625, 96.390, 2703.0, 51.9904
12.833378756, 96.390, 2538.0, 50.3786
12.885899886, 96.390, 2537.0, 50.3686
12.938421017, 96.390, 2656.0, 51.5364
12.990942148, 96.390, 2505.0, 50.0500
13.043463279, 96.390, 2541.0, 50.4083
13.095984409, 96.390, 2481.0, 49.8096
13.148505540, 96.390, 2535.0, 50.3488
13.201026671, 96.390, 2425.0, 49.2443
13.253547801, 96.390, 2579.0, 50.7839
13.306068932, 96.390, 2527.0, 50.2693
13.358590063, 96.390, 2607.0, 51.0588
13.411111193, 96.390, 2669.0, 51.6624
13.463632324, 96.390, 2719.0, 52.1440
13.516153455, 96.390, 2943.0, 54.2494
13.568674586, 96.390, 2586.0, 50.8527
13.621195716, 96.390, 2423.0, 49.2240
13.673716847, 96.390, 2463.0, 49.6286
13.726237978, 96.390, 2479.0, 49.7896
13.778759108, 96.390, 2554.0, 50.5371
13.831280239, 96.390, 2665.0, 51.6236
13.883801370, 96.390, 2601.0, 51.0000
13.936322501, 96.390, 2575.0, 50.7445
13.988843631, 96.390, 2354.0, 48.5180
14.041364762, 96.390, 2393.0, 48.9183
14.093885893, 96.390, 2414.0, 49.1325
14.146407023, 96.390, 2494.0, 49.9400
14.198928154, 96.390, 2774.0, 52.6688
14.251449285, 96.390, 3110.0, 55.7674
14.303970416, 96.390, 2953.0, 54.3415
14.356491546, 96.390, 2359.0, 48.5695
14.409012677, 96.390, 2328.0, 48.2494
14.461533808, 96.390, 2310.0, 48.0625
14.514054938, 96.390, 2519.0, 50.1896
14.566576069, 96.390, 2535.0, 50.3488
14.619097200, 96.390, 2212.0, 47.0319
14.671618331, 96.390, 2218.0, 47.0956
14.724139461, 96.390, 2199.0, 46.8935
14.776660592, 96.390, 2190.0, 46.7974
14.829181723, 96.390, 2154.0, 46.4112
14.881702853, 96.390, 2198.0, 46.8828
14.934223984, 96.390, 2267.0, 47.6130
14.986745115, 96.390, 2196.0, 46.8615
15.039266245, 96.390, 2248.0, 47.4131
15.091787376, 96.390, 2345.0, 48.4252
15.144308507, 96.390, 2375.0, 48.7340
15.196829638, 96.390, 2714.0, 52.0961
15.249350768, 96.390, 2884.0, 53.7029
15.301871899, 96.390, 2909.0, 53.9351
15.354393030, 96.390, 2464.0, 49.6387
15.406914160, 96.390, 2201.0, 46.9148
15.459435291, 96.390, 2109.0, 45.9239
15.511956422, 96.390, 2126.0, 46.1086
15.564477553, 96.390, 1987.0, 44.5758
15.616998683, 96.390, 2151.0, 46.3789
15.669519814, 96.390, 2119.0, 46.0326
15.722040945, 96.390, 2122.0, 46.0652
15.774562075, 96.390, 2050.0, 45.2769
15.827083206, 96.390, 2057.0, 45.3542
15.879604337, 96.390, 2100.0, 45.8258
15.932125468, 96.390, 2034.0, 45.0999
15.984646598, 96.390, 2039.0, 45.1553
16.037167729, 96.390, 2058.0, 45.3652
16.089688860, 96.390, 2000.0, 44.7214
16.142209990, 96.390, 2016.0, 44.8999
16.194731121, 96.390, 2070.0, 45.4973
16.247252252, 96.390, 2117.0, 46.0109
16.299773382, 96.390, 2218.0, 47.0956
16.352294513, 96.390, 2170.0, 46.5833
16.404815644, 96.390, 1956.0, 44.2267
16.457336775, 96.390, 1978.0, 44.4747
16.509857905, 96.390, 2093.0, 45.7493
16.562379036, 96.390, 1931.0, 43.9431
16.614900167, 96.390, 1911.0, 43.7150
16.667421297, 96.390, 1915.0, 43.7607
16.719942428, 96.390, 2030.0, 45.0555
16.772463559, 96.390, 1941.0, 44.0568
16.824984690, 96.390, 2006.0, 44.7884
16.877505820, 96.390, 1940.0, 44.0454
16.930026951, 96.390, 1962.0, 44.2945
16.982548082, 96.390, 2049.0, 45.2659
17.035069212, 96.390, 1923.0, 43.8520
17.087590343, 96.390, 1933.0, 43.9659
17.140111474, 96.390, 1934.0, 43.9773
17.192632605, 96.390, 1895.0, 43.5316
17.245153735, 96.390, 1973.0, 44.4185
17.297674866, 96.390, 1978.0, 44.4747
17.350195997, 96.390, 1988.0, 44.5870
17.402717127, 96.390, 2151.0, 46.3789
17.455238258, 96.390, 2021.0, 44.9555
17.507759389, 96.390, 1896.0, 43.5431
17.560280520, 96.390, 1872.0, 43.2666
17.612801650, 96.390, 1914.0, 43.7493
17.665322781, 96.390, 1889.0, 43.4626
17.717843912, 96.390, 1919.0, 43.8064
17.770365042, 96.390, 1985.0, 44.5533
17.822886173, 96.390, 1914.0, 43.7493
17.875407304, 96.390, 1892.0, 43.4971
17.927928434, 96.390, 1928.0, 43.9090
17.980449565, 96.390, 1975.0, 44.4410
18.032970696, 96.390, 1906.0, 43.6578
18.085491827, 96.390, 1863.0, 43.1625
18.138012957, 96.390, 1895.0, 43.5316
18.190534088, 96.390, 1896.0, 43.5431
18.243055219, 96.390, 1981.0, 44.5084
18.295576349, 96.390, 2154.0, 46.4112
18.348097480, 96.390, 2078.0, 45.5851
18.400618611, 96.390, 2062.0, 45.4093
18.453139742, 96.390, 2042.0, 45.1885
18.505660872, 96.390, 1946.0, 44.1135
18.558182003, 96.390, 1954.0, 44.2041
18.610703134, 96.390, 1894.0, 43.5201
18.663224264, 96.390, 1930.0, 43.9318
18.715745395, 96.390, 1948.0, 44.1362
18.768266526, 96.390, 1938.0, 44.0227
18.820787657, 96.390, 1998.0, 44.6990
18.873308787, 96.390, 2167.0, 46.5510
18.925829918, 96.390, 2152.0, 46.3897
18.978351049, 96.390, 2240.0, 47.3286
19.030872179, 96.390, 2157.0, 46.4435
19.083393310, 96.390, 2038.0, 45.1442
19.135914441, 96.390, 2064.0, 45.4313
19.188435572, 96.390, 2033.0, 45.0888
19.240956702, 96.390, 1978.0, 44.4747
19.293477833, 96.390, 2107.0, 45.9021
19.345998964, 96.390, 2183.0, 46.7226
19.398520094, 96.390, 2404.0, 49.0306
19.451041225, 96.390, 2474.0, 49.7393
19.503562356, 96.390, 2339.0, 48.3632
19.556083486, 96.390, 2081.0, 45.6180
19.608604617, 96.390, 2070.0, 45.4973
19.661125748, 96.390, 2176.0, 46.6476
19.713646879, 96.390, 2241.0, 47.3392
19.766168009, 96.390, 2441.0, 49.4065
19.818689140, 96.390, 2706.0, 52.0192
19.871210271, 96.390, 2693.0, 51.8941
19.923731401, 96.390, 3000.0, 54.7723
19.976252532, 96.390, 3587.0, 59.8916
20.028773663, 96.390, 2807.0, 52.9811
20.081294794, 96.390, 2229.0, 47.2123
20.133815924, 96.390, 2110.0, 45.9347
20.186337055, 96.390, 2018.0, 44.9222
20.238858186, 96.390, 1965.0, 44.3283
20.291379316, 96.390, 2108.0, 45.9130
20.343900447, 96.390, 2271.0, 47.6550
20.396421578, 96.390, 2455.0, 49.5480
20.448942709, 96.390, 2722.0, 52.1728
20.501463839, 96.390, 2559.0, 50.5866
20.553984970, 96.390, 2870.0, 53.5724
20.606506101, 96.390, 3557.0, 59.6406
20.659027231, 96.390, 5028.0, 70.9084
20.711548362, 96.390, 6539.0, 80.8641
20.764069493, 96.390, 4583.0, 67.6979
20.816590623, 96.390, 2892.0, 53.7773
20.869111754, 96.390, 2354.0, 48.5180
20.921632885, 96.390, 2231.0, 47.2335
20.974154016, 96.390, 2224.0, 47.1593
21.026675146, 96.390, 2172.0, 46.6047
21.079196277, 96.390, 2228.0, 47.2017
21.131717408, 96.390, 2081.0, 45.6180
21.184238538, 96.390, 2153.0, 46.4004
21.236759669, 96.390, 2153.0, 46.4004
21.289280800, 96.390, 2350.0, 48.4768
21.341801931, 96.390, 2272.0, 47.6655
21.394323061, 96.390, 2179.0, 46.6798
21.446844192, 96.390, 2170.0, 46.5833
21.499365323, 96.390, 2170.0, 46.5833
21.551886453, 96.390, 2168.0, 46.5618
21.604407584, 96.390, 2333.0, 48.3011
21.656928715, 96.390, 2329.0, 48.2597
21.709449846, 96.390, 2405.0, 49.0408
21.761970976, 96.390, 2314.0, 48.1041
21.814492107, 96.390, 2342.0, 48.3942
21.867013238, 96.390, 2209.0, 47.0000
21.919534368, 96.390, 2166.0, 46.5403
21.972055499, 96.390, 2255.0, 47.4868
22.024576630, 96.390, 2202.0, 46.9255
22.077097761, 96.390, 2149.0, 46.3573
22.129618891, 96.390, 2263.0, 47.5710
22.182140022, 96.390, 2224.0, 47.1593
22.234661153, 96.390, 2233.0, 47.2546
22.287182283, 96.390, 2286.0, 47.8121
22.339703414, 96.390, 2299.0, 47.9479
22.392224545, 96.390, 2327.0, 48.2390
22.444745675, 96.390, 2325.0, 48.2183
22.497266806, 96.390, 2279.0, 47.7389
22.549787937, 96.390, 2361.0, 48.5901
22.602309068, 96.390, 2273.0, 47.6760
22.654830198, 96.390, 2311.0, 48.0729
22.707351329, 96.390, 2364.0, 48.6210
22.759872460, 96.390, 2335.0, 48.3218
22.812393590, 96.390, 2464.0, 49.6387
22.864914721, 96.390, 2518.0, 50.1797
22.917435852, 96.390, 2571.0, 50.7050
22.969956983, 96.390, 2450.0, 49.4975
23.022478113, 96.390, 2359.0, 48.5695
23.074999244, 96.390, 2326.0, 48.2286
23.127520375, 96.390, 2421.0, 49.2037
23.180041505, 96.390, 2599.0, 50.9804
23.232562636, 96.390, 2430.0, 49.2950
23.285083767, 96.390, 2412.0, 49.1121
23.337604898, 96.390, 2478.0, 49.7795
23.390126028, 96.390, 2481.0, 49.8096
23.442647159, 96.390, 2448.0, 49.4773
23.495168290, 96.390, 2545.0, 50.4480
23.547689420, 96.390, 2502.0, 50.0200
23.600210551, 96.390, 2426.0, 49.2544
23.652731682, 96.390, 2461.0, 49.6085
23.705252813, 96.390, 2270.0, 47.6445
23.757773943, 96.390, 2328.0, 48.2494
23.810295074, 96.390, 2375.0, 48.7340
23.862816205, 96.390, 2326.0, 48.2286
23.915337335, 96.390, 2317.0, 48.1352
23.967858466, 96.390, 2363.0, 48.6107
24.020379597, 96.390, 2376.0, 48.7442
24.072900727, 96.390, 2472.0, 49.7192
24.125421858, 96.390, 2642.0, 51.4004
24.177942989, 96.390, 2744.0, 52.3832
24.230464120, 96.390, 2613.0, 51.1175
24.282985250, 96.390, 2500.0, 50.0000
24.335506381, 96.390, 2370.0, 48.6826
24.388027512, 96.390, 2328.0, 48.2494
24.440548642, 96.390, 2249.0, 47.4236
24.493069773, 96.390, 2326.0, 48.2286
24.545590904, 96.390, 2307.0, 48.0312
24.598112035, 96.390, 2384.0, 48.8262
24.650633165, 96.390, 2275.0, 47.6970
24.703154296, 96.390, 2376.0, 48.7442
24.755675427, 96.390, 2388.0, 48.8672
24.808196557, 96.390, 2297.0, 47.9270
24.860717688, 96.390, 2321.0, 48.1768
24.913238819, 96.390, 2312.0, 48.0833
24.965759950, 96.390, 2231.0, 47.2335
25.018281080, 96.390, 2364.0, 48.6210
25.070802211, 96.390, 2262.0, 47.5605
25.123323342, 96.390, 2320.0, 48.1664
25.175844472, 96.390, 2346.0, 48.4355
25.228365603, 96.390, 2352.0, 48.4974
25.280886734, 96.390, 2368.0, 48.6621
25.333407864, 96.390, 2546.0, 50.4579
25.385928995, 96.390, 2926.0, 54.0925
25.438450126, 96.390, 3245.0, 56.9649
25.490971257, 96.390, 2916.0, 54.0000
25.543492387, 96.390, 2706.0, 52.0192
25.596013518, 96.390, 2355.0, 48.5283
25.648534649, 96.390, 2351.0, 48.4871
25.701055779, 96.390, 2317.0, 48.1352
25.753576910, 96.390, 2369.0, 48.6724
25.806098041, 96.390, 2336.0, 48.3322
25.858619172, 96.390, 2389.0, 48.8774
25.911140302, 96.390, 2349.0, 48.4665
25.963661433, 96.390, 2363.0, 48.6107
26.016182564, 96.390, 2391.0, 48.8979
26.068703694, 96.390, 2369.0, 48.6724
26.121224825, 96.390, 2308.0, 48.0416
26.173745956, 96.390, 2307.0, 48.0312
26.226267087, 96.390, 2330.0, 48.2701
26.278788217, 96.390, 2338.0, 48.3529
26.331309348, 96.390, 2425.0, 49.2443
26.383830479, 96.390, 2363.0, 48.6107
26.436351609, 96.390, 2419.0, 49.1833
26.488872740, 96.390, 2351.0, 48.4871
26.541393871, 96.390, 2270.0, 47.6445
26.593915002, 96.390, 2361.0, 48.5901
26.646436132, 96.390, 2421.0, 49.2037
26.698957263, 96.390, 2410.0, 49.0918
26.751478394, 96.390, 2487.0, 49.8698
26.803999524, 96.390, 2549.0, 50.4876
26.856520655, 96.390, 2487.0, 49.8698
26.909041786, 96.390, 2572.0, 50.7149
26.961562916, 96.390, 2586.0, 50.8527
27.014084047, 96.390, 2599.0, 50.9804
27.066605178, 96.390, 2818.0, 53.0848
27.119126309, 96.390, 3215.0, 56.7010
27.171647439, 96.390, 3550.0, 59.5819
27.224168570, 96.390, 3533.0, 59.4390
27.276689701, 96.390, 2927.0, 54.1018
27.329210831, 96.390, 2609.0, 51.0784
27.381731962, 96.390, 2593.0, 50.9215
27.434253093, 96.390, 2409.0, 49.0816
27.486774224, 96.390, 2358.0, 48.5592
27.539295354, 96.390, 2460.0, 49.5984
27.591816485, 96.390, 2478.0, 49.7795
27.644337616, 96.390, 2318.0, 48.1456
27.696858746, 96.390, 2362.0, 48.6004
27.749379877, 96.390, 2430.0, 49.2950
27.801901008, 96.390, 2482.0, 49.8197
27.854422139, 96.390, 2367.0, 48.6518
27.906943269, 96.390, 2355.0, 48.5283
27.959464400, 96.390, 2421.0, 49.2037
28.011985531, 96.390, 2430.0, 49.2950
28.064506661, 96.390, 2460.0, 49.5984
28.117027792, 96.390, 2400.0, 48.9898
28.169548923, 96.390, 2400.0, 48.9898
28.222070054, 96.390, 2446.0, 49.4571
28.274591184, 96.390, 2373.0, 48.7134
28.327112315, 96.390, 2416.0, 49.1528
28.379633446, 96.390, 2461.0, 49.6085
28.432154576, 96.390, 2285.0, 47.8017
28.484675707, 96.390, 2307.0, 48.0312
28.537196838, 96.390, 2321.0, 48.1768
28.589717968, 96.390, 2381.0, 48.7955
28.642239099, 96.390, 2361.0, 48.5901
28.694760230, 96.390, 2423.0, 49.2240
28.747281361, 96.390, 2614.0, 51.1273
28.799802491, 96.390, 2458.0, 49.5782
28.852323622, 96.390, 2392.0, 48.9081
28.904844753, 96.390, 2324.0, 48.2079
28.957365883, 96.390, 2280.0, 47.7493
29.009887014, 96.390, 2425.0, 49.2443
29.062408145, 96.390, 2613.0, 51.1175
29.114929276, 96.390, 2736.0, 52.3068
29.167450406, 96.390, 2689.0, 51.8556
29.219971537, 96.390, 2597.0, 50.9608
29.272492668, 96.390, 2550.0, 50.4975
29.325013798, 96.390, 2443.0, 49.4267
29.377534929, 96.390, 2469.0, 49.6890
29.430056060, 96.390, 2410.0, 49.0918
29.482577191, 96.390, 2411.0, 49.1019
29.535098321, 96.390, 2404.0, 49.0306
29.587619452, 96.390, 2315.0, 48.1144
29.640140583, 96.390, 2252.0, 47.4552
29.692661713, 96.390, 2245.0, 47.3814
29.745182844, 96.390, 2278.0, 47.7284
29.797703975, 96.390, 2073.0, 45.5302
29.850225105, 96.390, 2190.0, 46.7974
29.902746236, 96.390, 2227.0, 47.1911
29.955267367, 96.390, 2156.0, 46.4327
30.007788498, 96.390, 2211.0, 47.0213
30.060309628, 96.390, 2068.0, 45.4753
30.112830759, 96.390, 2072.0, 45.5192
30.165351890, 96.390, 2167.0, 46.5510
30.217873020, 96.390, 2090.0, 45.7165
30.270394151, 96.390, 2123.0, 46.0760
30.322915282, 96.390, 2033.0, 45.0888
30.375436413, 96.390, 2068.0, 45.4753
30.427957543, 96.390, 2199.0, 46.8935
30.480478674, 96.390, 2164.0, 46.5188
30.532999805, 96.390, 2289.0, 47.8435
30.585520935, 96.390, 2295.0, 47.9062
30.638042066, 96.390, 2463.0, 49.6286
30.690563197, 96.390, 2501.0, 50.0100
30.743084328, 96.390, 2471.0, 49.7092
30.795605458, 96.390, 2480.0, 49.7996
30.848126589, 96.390, 2366.0, 48.6415
30.900647720, 96.390, 2167.0, 46.5510
30.953168850, 96.390, 2084.0, 45.6508
31.005689981, 96.390, 2073.0, 45.5302
31.058211112, 96.390, 2067.0, 45.4643
31.110732243, 96.390, 2285.0, 47.8017
31.163253373, 96.390, 2627.0, 51.2543
31.215774504, 96.390, 2963.0, 54.4334
31.268295635, 96.390, 2765.0, 52.5833
31.320816765, 96.390, 2508.0, 50.0799
31.373337896, 96.390, 2287.0, 47.8226
31.425859027, 96.390, 2244.0, 47.3709
31.478380157, 96.390, 2222.0, 47.1381
31.530901288, 96.390, 2307.0, 48.0312
31.583422419, 96.390, 2222.0, 47.1381
31.635943550, 96.390, 2317.0, 48.1352
31.688464680, 96.390, 2328.0, 48.2494
31.740985811, 96.390, 2205.0, 46.9574
31.793506942, 96.390, 2237.0, 47.2969
31.846028072, 96.390, 2006.0, 44.7884
31.898549203, 96.390, 2229.0, 47.2123
31.951070334, 96.390, 2856.0, 53.4416
32.003591465, 96.390, 4130.0, 64.2651
32.056112595, 96.390, 5196.0, 72.0833
32.108633726, 96.390, 4345.0, 65.9166
32.161154857, 96.390, 3396.0, 58.2752
32.213675987, 96.390, 2426.0, 49.2544
32.266197118, 96.390, 2195.0, 46.8508
32.318718249, 96.390, 1963.0, 44.3058
32.371239380, 96.390, 1893.0, 43.5086
32.423760510, 96.390, 1817.0, 42.6263
32.476281641, 96.390, 1789.0, 42.2966
32.528802772, 96.390, 1728.0, 41.5692
32.581323902, 96.390, 1801.0, 42.4382
32.633845033, 96.390, 1835.0, 42.8369
32.686366164, 96.390, 1887.0, 43.4396
32.738887295, 96.390, 1860.0, 43.1277
32.791408425, 96.390, 1794.0, 42.3556
32.843929556, 96.390, 1767.0, 42.0357
32.896450687, 96.390, 1736.0, 41.6653
32.948971817, 96.390, 1801.0, 42.4382
33.001492948, 96.390, 1884.0, 43.4051
33.054014079, 96.390, 1869.0, 43.2319
33.106535209, 96.390, 1906.0, 43.6578
33.159056340, 96.390, 1962.0, 44.2945
33.211577471, 96.390, 1860.0, 43.1277
33.264098602, 96.390, 1952.0, 44.1814
33.316619732, 96.390, 1839.0, 42.8836
33.369140863, 96.390, 1854.0, 43.0581
33.421661994, 96.390, 2083.0, 45.6399
33.474183124, 96.390, 2003.0, 44.7549
33.526704255, 96.390, 1804.0, 42.4735
33.579225386, 96.390, 1691.0, 41.1218
33.631746517, 96.390, 1716.0, 41.4246
33.684267647, 96.390, 1768.0, 42.0476
33.736788778, 96.390, 1714.0, 41.4005
33.789309909, 96.390, 1739.0, 41.7013
33.841831039, 96.390, 1888.0, 43.4511
33.894352170, 96.390, 2402.0, 49.0102
33.946873301, 96.390, 2798.0, 52.8961
33.999394432, 96.390, 2612.0, 51.1077
34.051915562, 96.390, 2480.0, 49.7996
34.104436693, 96.390, 1957.0, 44.2380
34.156957824, 96.390, 1913.0, 43.7379
34.209478954, 96.390, 1811.0, 42.5558
34.262000085, 96.390, 1862.0, 43.1509
34.314521216, 96.390, 1960.0, 44.2719
34.367042346, 96.390, 1900.0, 43.5890
34.419563477, 96.390, 2058.0, 45.3652
34.472084608, 96.390, 2194.0, 46.8402
34.524605739, 96.390, 2116.0, 46.0000
34.577126869, 96.390, 2226.0, 47.1805
34.629648000, 96.390, 2077.0, 45.5741
34.682169131, 96.390, 1924.0, 43.8634
34.734690261, 96.390, 1918.0, 43.7950
34.787211392, 96.390, 2031.0, 45.0666
34.839732523, 96.390, 2248.0, 47.4131
34.892253654, 96.390, 2728.0, 52.2303
34.944774784, 96.390, 2840.0, 53.2917
34.997295915, 96.390, 2494.0, 49.9400
35.049817046, 96.390, 2340.0, 48.3735
35.102338176, 96.390, 1952.0, 44.1814
35.154859307, 96.390, 1826.0, 42.7317
35.207380438, 96.390, 1943.0, 44.0795
35.259901569, 96.390, 1789.0, 42.2966
35.312422699, 96.390, 1801.0, 42.4382
35.364943830, 96.390, 1663.0, 40.7799
35.417464961, 96.390, 1544.0, 39.2938
35.469986091, 96.390, 1612.0, 40.1497
35.522507222, 96.390, 1603.0, 40.0375
35.575028353, 96.390, 1636.0, 40.4475
35.627549484, 96.390, 1725.0, 41.5331
35.680070614, 96.390, 1625.0, 40.3113
35.732591745, 96.390, 1601.0, 40.0125
35.785112876, 96.390, 1711.0, 41.3642
35.837634006, 96.390, 1628.0, 40.3485
35.890155137, 96.390, 1646.0, 40.5709
35.942676268, 96.390, 1726.0, 41.5452
35.995197398, 96.390, 1671.0, 40.8779
36.047718529, 96.390, 1630.0, 40.3733
36.100239660, 96.390, 1664.0, 40.7922
36.152760791, 96.390, 1730.0, 41.5933
36.205281921, 96.390, 1730.0, 41.5933
36.257803052, 96.390, 1626.0, 40.3237
36.310324183, 96.390, 1621.0, 40.2616
36.362845313, 96.390, 1509.0, 38.8458
36.415366444, 96.390, 1549.0, 39.3573
36.467887575, 96.390, 1512.0, 38.8844
36.520408706, 96.390, 1448.0, 38.0526
36.572929836, 96.390, 1439.0, 37.9342
36.625450967, 96.390, 1381.0, 37.1618
36.677972098, 96.390, 1407.0, 37.5100
36.730493228, 96.390, 1361.0, 36.8917
36.783014359, 96.390, 1336.0, 36.5513
36.835535490, 96.390, 1290.0, 35.9166
36.888056621, 96.390, 1311.0, 36.2077
36.940577751, 96.390, 1307.0, 36.1525
36.993098882, 96.390, 1293.0, 35.9583
37.045620013, 96.390, 1386.0, 37.2290
37.098141143, 96.390, 1250.0, 35.3553
37.150662274, 96.390, 1348.0, 36.7151
37.203183405, 96.390, 1325.0, 36.4005
37.255704535, 96.390, 1385.0, 37.2156
37.308225666, 96.390, 1354.0, 36.7967
37.360746797, 96.390, 1297.0, 36.0139
37.413267928, 96.390, 1347.0, 36.7015
37.465789058, 96.390, 1405.0, 37.4833
37.518310189, 96.390, 1517.0, 38.9487
37.570831320, 96.390, 1450.0, 38.0789
37.623352450, 96.390, 1486.0, 38.5487
37.675873581, 96.390, 1623.0, 40.2865
37.728394712, 96.390, 1793.0, 42.3438
37.780915843, 96.390, 1714.0, 41.4005
37.833436973, 96.390, 1688.0, 41.0853
37.885958104, 96.390, 1537.0, 39.2046
37.938479235, 96.390, 1412.0, 37.5766
37.991000365, 96.390, 1407.0, 37.5100
38.043521496, 96.390, 1322.0, 36.3593
38.096042627, 96.390, 1375.0, 37.0810
38.148563758, 96.390, 1432.0, 37.8418
38.201084888, 96.390, 1474.0, 38.3927
38.253606019, 96.390, 1428.0, 37.7889
38.306127150, 96.390, 1394.0, 37.3363
38.358648280, 96.390, 1270.0, 35.6371
38.411169411, 96.390, 1340.0, 36.6060
38.463690542, 96.390, 1336.0, 36.5513
38.516211673, 96.390, 1308.0, 36.1663
38.568732803, 96.390, 1343.0, 36.6470
38.621253934, 96.390, 1409.0, 37.5366
38.673775065, 96.390, 1294.0, 35.9722
38.726296195, 96.390, 1463.0, 38.2492
38.778817326, 96.390, 1553.0, 39.4081
38.831338457, 96.390, 1384.0, 37.2022
38.883859587, 96.390, 1391.0, 37.2961
38.936380718, 96.390, 1303.0, 36.0971
38.988901849, 96.390, 1289.0, 35.9026
39.041422980, 96.390, 1251.0, 35.3695
39.093944110, 96.390, 1243.0, 35.2562
39.146465241, 96.390, 1276.0, 35.7211
39.198986372, 96.390, 1254.0, 35.4119
39.251507502, 96.390, 1376.0, 37.0945
39.304028633, 96.390, 1373.0, 37.0540
39.356549764, 96.390, 1481.0, 38.4838
39.409070895, 96.390, 1707.0, 41.3159
39.461592025, 96.390, 1608.0, 40.0999
39.514113156, 96.390, 1415.0, 37.6165
39.566634287, 96.390, 1359.0, 36.8646
39.619155417, 96.390, 1238.0, 35.1852
39.671676548, 96.390, 1265.0, 35.5668
39.724197679, 96.390, 1327.0, 36.4280
39.776718810, 96.390, 1294.0, 35.9722
39.829239940, 96.390, 1263.0, 35.5387
39.881761071, 96.390, 1264.0, 35.5528
39.934282202, 96.390, 1260.0, 35.4965
39.986803332, 96.390, 1325.0, 36.4005
40.039324463, 96.390, 1216.0, 34.8712
40.091845594, 96.390, 1303.0, 36.0971
40.144366725, 96.390, 1279.0, 35.7631
40.196887855, 96.390, 1263.0, 35.5387
40.249408986, 96.390, 1213.0, 34.8281
40.301930117, 96.390, 1149.0, 33.8969
40.354451247, 96.390, 1134.0, 33.6749
40.406972378, 96.390, 1114.0, 33.3766
40.459493509, 96.390, 1141.0, 33.7787
40.512014639, 96.390, 1239.0, 35.1994
40.564535770, 96.390, 1260.0, 35.4965
40.617056901, 96.390, 1267.0, 35.5949
40.669578032, 96.390, 1210.0, 34.7851
40.722099162, 96.390, 1263.0, 35.5387
40.774620293, 96.390, 1151.0, 33.9264
40.827141424, 96.390, 1137.0, 33.7194
40.879662554, 96.390, 1133.0, 33.6601
40.932183685, 96.390, 1088.0, 32.9848
40.984704816, 96.390, 1124.0, 33.5261
41.037225947, 96.390, 1097.0, 33.1210
41.089747077, 96.390, 1138.0, 33.7343
41.142268208, 96.390, 1129.0, 33.6006
41.194789339, 96.390, 1185.0, 34.4238
41.247310469, 96.390, 1202.0, 34.6699
41.299831600, 96.390, 1306.0, 36.1386
41.352352731, 96.390, 1612.0, 40.1497
41.404873862, 96.390, 1582.0, 39.7744
41.457394992, 96.390, 1471.0, 38.3536
41.509916123, 96.390, 1384.0, 37.2022
41.562437254, 96.390, 1155.0, 33.9853
41.614958384, 96.390, 1097.0, 33.1210
41.667479515, 96.390, 1113.0, 33.3617
41.720000646, 96.390, 1059.0, 32.5423
41.772521776, 96.390, 1108.0, 33.2866
41.825042907, 96.390, 1123.0, 33.5112
41.877564038, 96.390, 1112.0, 33.3467
41.930085169, 96.390, 1061.0, 32.5730
41.982606299, 96.390, 1129.0, 33.6006
42.035127430, 96.390, 1171.0, 34.2199
42.087648561, 96.390, 1312.0, 36.2215
42.140169691, 96.390, 1464.0, 38.2623
42.192690822, 96.390, 1386.0, 37.2290
42.245211953, 96.390, 1264.0, 35.5528
42.297733084, 96.390, 1232.0, 35.0999
42.350254214, 96.390, 1162.0, 34.0881
42.402775345, 96.390, 1027.0, 32.0468
42.455296476, 96.390, 1189.0, 34.4819
42.507817606, 96.390, 1231.0, 35.0856
42.560338737, 96.390, 1287.0, 35.8748
42.612859868, 96.390, 1178.0, 34.3220
42.665380999, 96.390, 1119.0, 33.4515
42.717902129, 96.390, 1110.0, 33.3167
42.770423260, 96.390, 1076.0, 32.8024
42.822944391, 96.390, 1069.0, 32.6956
42.875465521, 96.390, 1079.0, 32.8481
42.927986652, 96.390, 1023.0, 31.9844
42.980507783, 96.390, 1082.0, 32.8938
43.033028914, 96.390, 1063.0, 32.6037
43.085550044, 96.390, 1074.0, 32.7719
43.138071175, 96.390, 1047.0, 32.3574
43.190592306, 96.390, 1081.0, 32.8786
43.243113436, 96.390, 944.0, 30.7246
43.295634567, 96.390, 978.0, 31.2730
43.348155698, 96.390, 1027.0, 32.0468
43.400676828, 96.390, 1078.0, 32.8329
43.453197959, 96.390, 987.0, 31.4166
43.505719090, 96.390, 994.0, 31.5278
43.558240221, 96.390, 1103.0, 33.2114
43.610761351, 96.390, 1051.0, 32.4191
43.663282482, 96.390, 1254.0, 35.4119
43.715803613, 96.390, 1396.0, 37.3631
43.768324743, 96.390, 1526.0, 39.0640
43.820845874, 96.390, 1343.0, 36.6470
43.873367005, 96.390, 1378.0, 37.1214
43.925888136, 96.390, 1325.0, 36.4005
43.978409266, 96.390, 1189.0, 34.4819
44.030930397, 96.390, 1127.0, 33.5708
44.083451528, 96.390, 1086.0, 32.9545
44.135972658, 96.390, 1038.0, 32.2180
44.188493789, 96.390, 1037.0, 32.2025
44.241014920, 96.390, 1103.0, 33.2114
44.293536051, 96.390, 1233.0, 35.1141
44.346057181, 96.390, 1333.0, 36.5103
44.398578312, 96.390, 1301.0, 36.0694
44.451099443, 96.390, 1220.0, 34.9285
44.503620573, 96.390, 1269.0, 35.6230
44.556141704, 96.390, 1172.0, 34.2345
44.608662835, 96.390, 1093.0, 33.0606
44.661183966, 96.390, 1072.0, 32.7414
44.713705096, 96.390, 1128.0, 33.5857
44.766226227, 96.390, 1077.0, 32.8177
44.818747358, 96.390, 1134.0, 33.6749
44.871268488, 96.390, 1107.0, 33.2716
44.923789619, 96.390, 1075.0, 32.7872
44.976310750, 96.390, 1146.0, 33.8526
45.028831880, 96.390, 1214.0, 34.8425
45.081353011, 96.390, 1335.0, 36.5377
45.133874142, 96.390, 1432.0, 37.8418
45.186395273, 96.390, 1294.0, 35.9722
45.238916403, 96.390, 1351.0, 36.7560
45.291437534, 96.390, 1284.0, 35.8329
45.343958665, 96.390, 1293.0, 35.9583
45.396479795, 96.390, 1341.0, 36.6197
45.449000926, 96.390, 1438.0, 37.9210
45.501522057, 96.390, 1361.0, 36.8917
45.554043188, 96.390, 1313.0, 36.2353
45.606564318, 96.390, 1174.0, 34.2637
45.659085449, 96.390, 1097.0, 33.1210
45.711606580, 96.390, 1059.0, 32.5423
45.764127710, 96.390, 1083.0, 32.9090
45.816648841, 96.390, 1075.0, 32.7872
45.869169972, 96.390, 1167.0, 34.1614
45.921691103, 96.390, 1057.0, 32.5115
45.974212233, 96.390, 1082.0, 32.8938
46.026733364, 96.390, 1041.0, 32.2645
46.079254495, 96.390, 1115.0, 33.3916
46.131775625, 96.390, 1175.0, 34.2783
46.184296756, 96.390, 1284.0, 35.8329
46.236817887, 96.390, 1405.0, 37.4833
46.289339017, 96.390, 1375.0, 37.0810
46.341860148, 96.390, 1259.0, 35.4824
46.394381279, 96.390, 1209.0, 34.7707
46.446902410, 96.390, 1217.0, 34.8855
46.499423540, 96.390, 1104.0, 33.2265
46.551944671, 96.390, 1067.0, 32.6650
46.604465802, 96.390, 1131.0, 33.6303
46.656986932, 96.390, 1141.0, 33.7787
46.709508063, 96.390, 1086.0, 32.9545
46.762029194, 96.390, 1109.0, 33.3017
46.814550325, 96.390, 1180.0, 34.3511
46.867071455, 96.390, 1059.0, 32.5423
46.919592586, 96.390, 1110.0, 33.3167
46.972113717, 96.390, 1159.0, 34.0441
47.024634847, 96.390, 1123.0, 33.5112
47.077155978, 96.390, 1062.0, 32.5883
47.129677109, 96.390, 1109.0, 33.3017
47.182198240, 96.390, 1007.0, 31.7333
47.234719370, 96.390, 1066.0, 32.6497
47.287240501, 96.390, 994.0, 31.5278
47.339761632, 96.390, 1028.0, 32.0624
47.392282762, 96.390, 1025.0, 32.0156
47.444803893, 96.390, 1090.0, 33.0151
47.497325024, 96.390, 986.0, 31.4006
47.549846155, 96.390, 954.0, 30.8869
47.602367285, 96.390, 1037.0, 32.2025
47.654888416, 96.390, 1034.0, 32.1559
47.707409547, 96.390, 1080.0, 32.8634
47.759930677, 96.390, 1001.0, 31.6386
47.812451808, 96.390, 1006.0, 31.7175
47.864972939, 96.390, 977.0, 31.2570
47.917494069, 96.390, 1040.0, 32.2490
47.970015200, 96.390, 997.0, 31.5753
48.022536331, 96.390, 1050.0, 32.4037
48.075057462, 96.390, 1074.0, 32.7719
48.127578592, 96.390, 1133.0, 33.6601
48.180099723, 96.390, 1112.0, 33.3467
48.232620854, 96.390, 1157.0, 34.0147
48.285141984, 96.390, 1074.0, 32.7719
48.337663115, 96.390, 1076.0, 32.8024
48.390184246, 96.390, 1124.0, 33.5261
48.442705377, 96.390, 1166.0, 34.1467
48.495226507, 96.390, 1214.0, 34.8425
48.547747638, 96.390, 1187.0, 34.4529
48.600268769, 96.390, 1149.0, 33.8969
48.652789899, 96.390, 1082.0, 32.8938
48.705311030, 96.390, 998.0, 31.5911
48.757832161, 96.390, 948.0, 30.7896
48.810353292, 96.390, 980.0, 31.3050
48.862874422, 96.390, 980.0, 31.3050
48.915395553, 96.390, 1037.0, 32.2025
48.967916684, 96.390, 959.0, 30.9677
49.020437814, 96.390, 928.0, 30.4631
49.072958945, 96.390, 958.0, 30.9516
49.125480076, 96.390, 1002.0, 31.6544
49.178001207, 96.390, 1030.0, 32.0936
49.230522337, 96.390, 983.0, 31.3528
49.283043468, 96.390, 993.0, 31.5119
49.335564599, 96.390, 968.0, 31.1127
49.388085729, 96.390, 985.0, 31.3847
49.440606860, 96.390, 970.0, 31.1448
49.493127991, 96.390, 918.0, 30.2985
49.545649121, 96.390, 994.0, 31.5278
49.598170252, 96.390, 959.0, 30.9677
49.650691383, 96.390, 1019.0, 31.9218
49.703212514, 96.390, 964.0, 31.0483
49.755733644, 96.390, 953.0, 30.8707
49.808254775, 96.390, 923.0, 30.3809
49.860775906, 96.390, 979.0, 31.2890
49.913297036, 96.390, 922.0, 30.3645
49.965818167, 96.390, 924.0, 30.3974
50.018339298, 96.390, 874.0, 29.5635
50.070860429, 96.390, 897.0, 29.9500
50.123381559, 96.390, 940.0, 30.6594
50.175902690, 96.390, 1023.0, 31.9844
50.228423821, 96.390, 1112.0, 33.3467
50.280944951, 96.390, 1047.0, 32.3574
50.333466082, 96.390, 1075.0, 32.7872
50.385987213, 96.390, 1032.0, 32.1248
50.438508344, 96.390, 1032.0, 32.1248
50.491029474, 96.390, 989.0, 31.4484
50.543550605, 96.390, 960.0, 30.9839
50.596071736, 96.390, 941.0, 30.6757
50.648592866, 96.390, 922.0, 30.3645
50.701113997, 96.390, 867.0, 29.4449
50.753635128, 96.390, 878.0, 29.6311
50.806156258, 96.390, 926.0, 30.4302
50.858677389, 96.390, 815.0, 28.5482
50.911198520, 96.390, 883.0, 29.7153
50.963719651, 96.390, 940.0, 30.6594
51.016240781, 96.390, 959.0, 30.9677
51.068761912, 96.390, 949.0, 30.8058
51.121283043, 96.390, 947.0, 30.7734
51.173804173, 96.390, 975.0, 31.2250
51.226325304, 96.390, 1027.0, 32.0468
51.278846435, 96.390, 976.0, 31.2410
51.331367566, 96.390, 974.0, 31.2090
51.383888696, 96.390, 962.0, 31.0161
51.436409827, 96.390, 912.0, 30.1993
51.488930958, 96.390, 889.0, 29.8161
51.541452088, 96.390, 791.0, 28.1247
51.593973219, 96.390, 912.0, 30.1993
51.646494350, 96.390, 898.0, 29.9666
51.699015481, 96.390, 886.0, 29.7658
51.751536611, 96.390, 938.0, 30.6268
51.804057742, 96.390, 891.0, 29.8496
51.856578873, 96.390, 856.0, 29.2575
51.909100003, 96.390, 872.0, 29.5296
51.961621134, 96.390, 858.0, 29.2916
52.014142265, 96.390, 918.0, 30.2985
52.066663396, 96.390, 985.0, 31.3847
52.119184526, 96.390, 1004.0, 31.6860
52.171705657, 96.390, 1086.0, 32.9545
52.224226788, 96.390, 1072.0, 32.7414
52.276747918, 96.390, 1099.0, 33.1512
52.329269049, 96.390, 1009.0, 31.7648
52.381790180, 96.390, 1016.0, 31.8748
52.434311310, 96.390, 909.0, 30.1496
52.486832441, 96.390, 850.0, 29.1548
52.539353572, 96.390, 894.0, 29.8998
52.591874703, 96.390, 856.0, 29.2575
52.644395833, 96.390, 912.0, 30.1993
52.696916964, 96.390, 951.0, 30.8383
52.749438095, 96.390, 895.0, 29.9166
52.801959225, 96.390, 880.0, 29.6648
52.854480356, 96.390, 946.0, 30.7571
52.907001487, 96.390, 910.0, 30.1662
52.959522618, 96.390, 900.0, 30.0000
53.012043748, 96.390, 796.0, 28.2135
53.064564879, 96.390, 896.0, 29.9333
53.117086010, 96.390, 917.0, 30.2820
53.169607140, 96.390, 940.0, 30.6594
53.222128271, 96.390, 941.0, 30.6757
53.274649402, 96.390, 911.0, 30.1828
53.327170533, 96.390, 913.0, 30.2159
53.379691663, 96.390, 928.0, 30.4631
53.432212794, 96.390, 938.0, 30.6268
53.484733925, 96.390, 842.0, 29.0172
53.537255055, 96.390, 833.0, 28.8617
53.589776186, 96.390, 859.0, 29.3087
53.642297317, 96.390, 853.0, 29.2062
53.694818448, 96.390, 755.0, 27.4773
53.747339578, 96.390, 868.0, 29.4618
53.799860709, 96.390, 821.0, 28.6531
53.852381840, 96.390, 849.0, 29.1376
53.904902970, 96.390, 876.0, 29.5973
53.957424101, 96.390, 858.0, 29.2916
54.009945232, 96.390, 891.0, 29.8496
54.062466362, 96.390, 939.0, 30.6431
54.114987493, 96.390, 970.0, 31.1448
54.167508624, 96.390, 929.0, 30.4795
54.220029755, 96.390, 948.0, 30.7896
54.272550885, 96.390, 967.0, 31.0966
54.325072016, 96.390, 953.0, 30.8707
54.377593147, 96.390, 902.0, 30.0333
54.430114277, 96.390, 884.0, 29.7321
54.482635408, 96.390, 872.0, 29.5296
54.535156539, 96.390, 830.0, 28.8097
54.587677670, 96.390, 864.0, 29.3939
54.640198800, 96.390, 815.0, 28.5482
54.692719931, 96.390, 779.0, 27.9106
54.745241062, 96.390, 774.0, 27.8209
54.797762192, 96.390, 797.0, 28.2312
54.850283323, 96.390, 800.0, 28.2843
54.902804454, 96.390, 789.0, 28.0891
54.955325585, 96.390, 765.0, 27.6586
55.007846715, 96.390, 756.0, 27.4955
55.060367846, 96.390, 747.0, 27.3313
55.112888977, 96.390, 719.0, 26.8142
55.165410107, 96.390, 762.0, 27.6043
55.217931238, 96.390, 762.0, 27.6043
55.270452369, 96.390, 753.0, 27.4408
55.322973499, 96.390, 814.0, 28.5307
55.375494630, 96.390, 736.0, 27.1293
55.428015761, 96.390, 777.0, 27.8747
55.480536892, 96.390, 814.0, 28.5307
55.533058022, 96.390, 814.0, 28.5307
55.585579153, 96.390, 788.0, 28.0713
55.638100284, 96.390, 778.0, 27.8927
55.690621414, 96.390, 847.0, 29.1033
55.743142545, 96.390, 825.0, 28.7228
55.795663676, 96.390, 761.0, 27.5862
55.848184807, 96.390, 740.0, 27.2029
55.900705937, 96.390, 743.0, 27.2580
55.953227068, 96.390, 785.0, 28.0179
56.005748199, 96.390, 793.0, 28.1603
56.058269329, 96.390, 779.0, 27.9106
56.110790460, 96.390, 800.0, 28.2843
56.163311591, 96.390, 836.0, 28.9137
56.215832722, 96.390, 771.0, 27.7669
56.268353852, 96.390, 796.0, 28.2135
56.320874983, 96.390, 698.0, 26.4197
56.373396114, 96.390, 720.0, 26.8328
56.425917244, 96.390, 772.0, 27.7849
56.478438375, 96.390, 759.0, 27.5500
56.530959506, 96.390, 722.0, 26.8701
56.583480637, 96.390, 694.0, 26.3439
56.636001767, 96.390, 719.0, 26.8142
56.688522898, 96.390, 709.0, 26.6271
56.741044029, 96.390, 697.0, 26.4008
56.793565159, 96.390, 740.0, 27.2029
56.846086290, 96.390, 785.0, 28.0179
56.898607421, 96.390, 762.0, 27.6043
56.951128551, 96.390, 742.0, 27.2397
57.003649682, 96.390, 771.0, 27.7669
57.056170813, 96.390, 742.0, 27.2397
57.108691944, 96.390, 728.0, 26.9815
57.161213074, 96.390, 729.0, 27.0000
57.213734205, 96.390, 714.0, 26.7208
57.266255336, 96.390, 709.0, 26.6271
57.318776466, 96.390, 760.0, 27.5681
57.371297597, 96.390, 813.0, 28.5132
57.423818728, 96.390, 758.0, 27.5318
57.476339859, 96.390, 753.0, 27.4408
57.528860989, 96.390, 755.0, 27.4773
57.581382120, 96.390, 754.0, 27.4591
57.633903251, 96.390, 722.0, 26.8701
57.686424381, 96.390, 783.0, 27.9821
57.738945512, 96.390, 721.0, 26.8514
57.791466643, 96.390, 785.0, 28.0179
57.843987774, 96.390, 802.0, 28.3196
57.896508904, 96.390, 822.0, 28.6705
57.949030035, 96.390, 831.0, 28.8271
58.001551166, 96.390, 930.0, 30.4959
58.054072296, 96.390, 931.0, 30.5123
58.106593427, 96.390, 902.0, 30.0333
58.159114558, 96.390, 828.0, 28.7750
58.211635689, 96.390, 835.0, 28.8964
58.264156819, 96.390, 798.0, 28.2489
58.316677950, 96.390, 731.0, 27.0370
58.369199081, 96.390, 729.0, 27.0000
58.421720211, 96.390, 780.0, 27.9285
58.474241342, 96.390, 774.0, 27.8209
58.526762473, 96.390, 713.0, 26.7021
58.579283603, 96.390, 760.0, 27.5681
58.631804734, 96.390, 760.0, 27.5681
58.684325865, 96.390, 694.0, 26.3439
58.736846996, 96.390, 697.0, 26.4008
58.789368126, 96.390, 750.0, 27.3861
58.841889257, 96.390, 693.0, 26.3249
58.894410388, 96.390, 729.0, 27.0000
58.946931518, 96.390, 720.0, 26.8328
58.999452649, 96.390, 687.0, 26.2107
59.051973780, 96.390, 731.0, 27.0370
59.104494911, 96.390, 745.0, 27.2947
59.157016041, 96.390, 720.0, 26.8328
59.209537172, 96.390, 752.0, 27.4226
59.262058303, 96.390, 824.0, 28.7054
59.314579433, 96.390, 762.0, 27.6043
59.367100564, 96.390, 788.0, 28.0713
59.419621695, 96.390, 725.0, 26.9258
59.472142826, 96.390, 787.0, 28.0535
59.524663956, 96.390, 770.0, 27.7489
59.577185087, 96.390, 753.0, 27.4408
59.629706218, 96.390, 771.0, 27.7669
59.682227348, 96.390, 722.0, 26.8701
59.734748479, 96.390, 745.0, 27.2947
59.787269610, 96.390, 771.0, 27.7669
59.839790740, 96.390, 825.0, 28.7228
59.892311871, 96.390, 853.0, 29.2062
59.944833002, 96.390, 854.0, 29.2233
59.997354133, 96.390, 738.0, 27.1662
60.049875263, 96.390, 854.0, 29.2233
60.102396394, 96.390, 809.0, 28.4429
60.154917525, 96.390, 827.0, 28.7576
60.207438655, 96.390, 808.0, 28.4253
60.259959786, 96.390, 807.0, 28.4077
60.312480917, 96.390, 806.0, 28.3901
60.365002048, 96.390, 809.0, 28.4429
60.417523178, 96.390, 851.0, 29.1719
60.470044309, 96.390, 827.0, 28.7576
60.522565440, 96.390, 814.0, 28.5307
60.575086570, 96.390, 877.0, 29.6142
60.627607701, 96.390, 842.0, 29.0172
60.680128832, 96.390, 884.0, 29.7321
60.732649963, 96.390, 881.0, 29.6816
60.785171093, 96.390, 917.0, 30.2820
60.837692224, 96.390, 879.0, 29.6479
60.890213355, 96.390, 930.0, 30.4959
60.942734485, 96.390, 940.0, 30.6594
60.995255616, 96.390, 933.0, 30.5450
61.047776747, 96.390, 921.0, 30.3480
61.100297878, 96.390, 948.0, 30.7896
61.152819008, 96.390, 958.0, 30.9516
61.205340139, 96.390, 968.0, 31.1127
61.257861270, 96.390, 909.0, 30.1496
61.310382400, 96.390, 963.0, 31.0322
61.362903531, 96.390, 982.0, 31.3369
61.415424662, 96.390, 982.0, 31.3369
61.467945792, 96.390, 998.0, 31.5911
61.520466923, 96.390, 951.0, 30.8383
61.572988054, 96.390, 891.0, 29.8496
61.625509185, 96.390, 957.0, 30.9354
61.678030315, 96.390, 927.0, 30.4467
61.730551446, 96.390, 936.0, 30.5941
61.783072577, 96.390, 914.0, 30.2324
61.835593707, 96.390, 879.0, 29.6479
61.888114838, 96.390, 844.0, 29.0517
61.940635969, 96.390, 840.0, 28.9828
61.993157100, 96.390, 826.0, 28.7402
62.045678230, 96.390, 842.0, 29.0172
62.098199361, 96.390, 828.0, 28.7750
62.150720492, 96.390, 834.0, 28.8791
62.203241622, 96.390, 791.0, 28.1247
62.255762753, 96.390, 758.0, 27.5318
62.308283884, 96.390, 750.0, 27.3861
62.360805015, 96.390, 788.0, 28.0713
62.413326145, 96.390, 803.0, 28.3373
62.465847276, 96.390, 765.0, 27.6586
62.518368407, 96.390, 754.0, 27.4591
62.570889537, 96.390, 774.0, 27.8209
62.623410668, 96.390, 808.0, 28.4253
62.675931799, 96.390, 794.0, 28.1780
62.728452930, 96.390, 763.0, 27.6225
62.780974060, 96.390, 761.0, 27.5862
62.833495191, 96.390, 792.0, 28.1425
62.886016322, 96.390, 691.0, 26.2869
62.938537452, 96.390, 693.0, 26.3249
62.991058583, 96.390, 694.0, 26.3439
63.043579714, 96.390, 669.0, 25.8650
63.096100844, 96.390, 705.0, 26.5518
63.148621975, 96.390, 677.0, 26.0192
63.201143106, 96.390, 641.0, 25.3180
63.253664237, 96.390, 655.0, 25.5930
63.306185367, 96.390, 676.0, 26.0000
63.358706498, 96.390, 668.0, 25.8457
63.411227629, 96.390, 654.0, 25.5734
63.463748759, 96.390, 736.0, 27.1293
63.516269890, 96.390, 683.0, 26.1343
63.568791021, 96.390, 663.0, 25.7488
63.621312152, 96.390, 666.0, 25.8070
63.673833282, 96.390, 635.0, 25.1992
63.726354413, 96.390, 695.0, 26.3629
63.778875544, 96.390, 757.0, 27.5136
63.831396674, 96.390, 760.0, 27.5681
63.883917805, 96.390, 679.0, 26.0576
63.936438936, 96.390, 686.0, 26.1916
63.988960067, 96.390, 701.0, 26.4764
64.041481197, 96.390, 735.0, 27.1109
64.094002328, 96.390, 645.0, 25.3969
64.146523459, 96.390, 717.0, 26.7769
64.199044589, 96.390, 704.0, 26.5330
64.251565720, 96.390, 664.0, 25.7682
64.304086851, 96.390, 650.0, 25.4951
64.356607981, 96.390, 656.0, 25.6125
64.409129112, 96.390, 691.0, 26.2869
64.461650243, 96.390, 687.0, 26.2107
64.514171374, 96.390, 616.0, 24.8193
64.566692504, 96.390, 627.0, 25.0400
64.619213635, 96.390, 594.0, 24.3721
64.671734766, 96.390, 627.0, 25.0400
64.724255896, 96.390, 605.0, 24.5967
64.776777027, 96.390, 585.0, 24.1868
64.829298158, 96.390, 599.0, 24.4745
64.881819289, 96.390, 625.0, 25.0000
64.934340419, 96.390, 609.0, 24.6779
64.986861550, 96.390, 618.0, 24.8596