File: Files_organized_for_plots/Constant_NaOH_1mL10M_to_1gPC_28Day_repeat/zCentroid08Dec21_Act13Feb23_B1_0714M_NaOH_LS0173_Num160.csv
[Measurement conditions],,,
Sample identification,Centroid08Dec21_Act13Feb23_B1_0714M_NaOH_LS0173_Num160,,
Comment - 2,"Configuration=Stage for Flat Samples/Holders, Owner=nmw10, Creation date=9/21/2022 10:06:30 AM",,
Comment - 3,Goniometer=Theta/Theta; Minimum step size 2Theta:0.0001; Minimum step size Omega:0.0001,,
Comment - 4,Sample stage=Stage for flat samples/holders,,
Comment - 5,Diffractometer system=EMPYREAN,,
Comment - 6,"Measurement program=X:\XRD\Cement\Zerobackground scan.xrdmp, Created identifier={98A3B11C-88F9-4AA6-982C-73314A311EF5}, Created by=Titus Reed, Id=tmr79, Creation date=10/26/2021 3:01:47 PM",,
Anode material,Cu,,
K-Alpha1 wavelength,1.540598,,
K-Alpha2 wavelength,1.544426,,
Ratio K-Alpha2/K-Alpha1,0.5,,
Divergence slit,Fixed,0.25,
Monochromator used,NO,,
Generator voltage,45,,
Tube current,40,,
File date and time,3/15/2023 21:13,,
Unit cell,,,
h k l, 0 0 0,,
Scan axis,Gonio,,
Scan range,4.994599997,64.99999183,
Scan step size,0.0262606,,
No. of points,2285,,
Scan type,CONTINUOUS,,
Time per step,96.39,,
[Scan points],,,
Angle, TimePerStep, Intensity, ESD
5.00773028,96.39,4150,64.4205
5.060251411,96.39,4181,64.6607
5.112772541,96.39,4125,64.2262
5.165293672,96.39,4039,63.5531
5.217814803,96.39,3923,62.6339
5.270335934,96.39,4032,63.498
5.322857064,96.39,3993,63.1902
5.375378195,96.39,3802,61.6604
5.427899326,96.39,3758,61.3025
5.480420456,96.39,3778,61.4654
5.532941587,96.39,3710,60.9098
5.585462718,96.39,3592,59.9333
5.637983849,96.39,3753,61.2617
5.690504979,96.39,3703,60.8523
5.74302611,96.39,3595,59.9583
5.795547241,96.39,3601,60.0083
5.848068371,96.39,3680,60.663
5.900589502,96.39,3527,59.3886
5.953110633,96.39,3581,59.8415
6.005631763,96.39,3513,59.2706
6.058152894,96.39,3569,59.7411
6.110674025,96.39,3589,59.9083
6.163195156,96.39,3624,60.1997
6.215716286,96.39,3556,59.6322
6.268237417,96.39,3530,59.4138
6.320758548,96.39,3479,58.983
6.373279678,96.39,3481,59
6.425800809,96.39,3455,58.7792
6.47832194,96.39,3406,58.3609
6.530843071,96.39,3479,58.983
6.583364201,96.39,3312,57.55
6.635885332,96.39,3491,59.0847
6.688406463,96.39,3436,58.6174
6.740927593,96.39,3412,58.4123
6.793448724,96.39,3416,58.4466
6.845969855,96.39,3451,58.7452
6.898490986,96.39,3437,58.6259
6.951012116,96.39,3460,58.8218
7.003533247,96.39,3439,58.643
7.056054378,96.39,3382,58.155
7.108575508,96.39,3541,59.5063
7.161096639,96.39,3320,57.6194
7.21361777,96.39,3398,58.2924
7.2661389,96.39,3353,57.9051
7.318660031,96.39,3399,58.3009
7.371181162,96.39,3395,58.2666
7.423702293,96.39,3350,57.8792
7.476223423,96.39,3351,57.8878
7.528744554,96.39,3315,57.576
7.581265685,96.39,3345,57.836
7.633786815,96.39,3439,58.643
7.686307946,96.39,3333,57.7321
7.738829077,96.39,3420,58.4808
7.791350208,96.39,3436,58.6174
7.843871338,96.39,3341,57.8014
7.896392469,96.39,3365,58.0086
7.9489136,96.39,3415,58.438
8.00143473,96.39,3303,57.4717
8.053955861,96.39,3330,57.7062
8.106476992,96.39,3391,58.2323
8.158998123,96.39,3374,58.0861
8.211519253,96.39,3328,57.6888
8.264040384,96.39,3409,58.3866
8.316561515,96.39,3378,58.1206
8.369082645,96.39,3377,58.112
8.421603776,96.39,3397,58.2838
8.474124907,96.39,3411,58.4038
8.526646038,96.39,3457,58.7963
8.579167168,96.39,3357,57.9396
8.631688299,96.39,3290,57.3585
8.68420943,96.39,3320,57.6194
8.73673056,96.39,3434,58.6003
8.789251691,96.39,3457,58.7963
8.841772822,96.39,3379,58.1292
8.894293952,96.39,3417,58.4551
8.946815083,96.39,3432,58.5833
8.999336214,96.39,3353,57.9051
9.051857345,96.39,3188,56.4624
9.104378475,96.39,3374,58.0861
9.156899606,96.39,3274,57.2189
9.209420737,96.39,3304,57.4804
9.261941867,96.39,3379,58.1292
9.314462998,96.39,3347,57.8533
9.366984129,96.39,3309,57.5239
9.41950526,96.39,3376,58.1034
9.47202639,96.39,3405,58.3524
9.524547521,96.39,3354,57.9137
9.577068652,96.39,3380,58.1378
9.629589782,96.39,3331,57.7148
9.682110913,96.39,3372,58.0689
9.734632044,96.39,3334,57.7408
9.787153175,96.39,3296,57.4108
9.839674305,96.39,3248,56.9912
9.892195436,96.39,3282,57.2887
9.944716567,96.39,3371,58.0603
9.997237697,96.39,3283,57.2975
10.04975883,96.39,3302,57.463
10.10227996,96.39,3338,57.7754
10.15480109,96.39,3349,57.8705
10.20732222,96.39,3341,57.8014
10.25984335,96.39,3254,57.0438
10.31236448,96.39,3241,56.9298
10.36488561,96.39,3360,57.9655
10.41740674,96.39,3382,58.155
10.46992787,96.39,3324,57.6541
10.522449,96.39,3314,57.5674
10.57497014,96.39,3271,57.1927
10.62749127,96.39,3261,57.1052
10.6800124,96.39,3272,57.2014
10.73253353,96.39,3276,57.2364
10.78505466,96.39,3223,56.7715
10.83757579,96.39,3276,57.2364
10.89009692,96.39,3262,57.1139
10.94261805,96.39,3301,57.4543
10.99513918,96.39,3246,56.9737
11.04766031,96.39,3195,56.5243
11.10018144,96.39,3195,56.5243
11.15270257,96.39,3141,56.0446
11.2052237,96.39,3121,55.8659
11.25774483,96.39,3054,55.263
11.31026597,96.39,3107,55.7405
11.3627871,96.39,3149,56.116
11.41530823,96.39,3061,55.3263
11.46782936,96.39,3146,56.0892
11.52035049,96.39,3086,55.5518
11.57287162,96.39,3044,55.1725
11.62539275,96.39,3060,55.3173
11.67791388,96.39,2950,54.3139
11.73043501,96.39,3076,55.4617
11.78295614,96.39,2966,54.461
11.83547727,96.39,3061,55.3263
11.8879984,96.39,2909,53.9351
11.94051953,96.39,2883,53.6936
11.99304066,96.39,2909,53.9351
12.0455618,96.39,2927,54.1018
12.09808293,96.39,2809,53
12.15060406,96.39,2870,53.5724
12.20312519,96.39,2837,53.2635
12.25564632,96.39,2917,54.0093
12.30816745,96.39,2817,53.0754
12.36068858,96.39,2848,53.3667
12.41320971,96.39,2779,52.7162
12.46573084,96.39,2762,52.5547
12.51825197,96.39,2745,52.3927
12.5707731,96.39,2760,52.5357
12.62329423,96.39,2752,52.4595
12.67581536,96.39,2817,53.0754
12.72833649,96.39,2816,53.066
12.78085763,96.39,2782,52.7447
12.83337876,96.39,2734,52.2877
12.88589989,96.39,2620,51.1859
12.93842102,96.39,2666,51.6333
12.99094215,96.39,2572,50.7149
13.04346328,96.39,2628,51.264
13.09598441,96.39,2559,50.5866
13.14850554,96.39,2662,51.5946
13.20102667,96.39,2595,50.9411
13.2535478,96.39,2595,50.9411
13.30606893,96.39,2587,50.8626
13.35859006,96.39,2745,52.3927
13.41111119,96.39,2744,52.3832
13.46363232,96.39,2964,54.4426
13.51615346,96.39,2857,53.4509
13.56867459,96.39,2753,52.469
13.62119572,96.39,2609,51.0784
13.67371685,96.39,2551,50.5074
13.72623798,96.39,2746,52.4023
13.77875911,96.39,2878,53.647
13.83128024,96.39,2818,53.0848
13.88380137,96.39,2712,52.0769
13.9363225,96.39,2578,50.774
13.98884363,96.39,2442,49.4166
14.04136476,96.39,2487,49.8698
14.09388589,96.39,2588,50.8724
14.14640702,96.39,2736,52.3068
14.19892815,96.39,3147,56.0981
14.25144929,96.39,3241,56.9298
14.30397042,96.39,2661,51.5849
14.35649155,96.39,2442,49.4166
14.40901268,96.39,2455,49.548
14.46153381,96.39,2417,49.163
14.51405494,96.39,2396,48.949
14.56657607,96.39,2226,47.1805
14.6190972,96.39,2365,48.6313
14.67161833,96.39,2322,48.1871
14.72413946,96.39,2336,48.3322
14.77666059,96.39,2355,48.5283
14.82918172,96.39,2301,47.9687
14.88170285,96.39,2261,47.55
14.93422398,96.39,2336,48.3322
14.98674512,96.39,2300,47.9583
15.03926625,96.39,2409,49.0816
15.09178738,96.39,2480,49.7996
15.14430851,96.39,2444,49.4368
15.19682964,96.39,2851,53.3948
15.24935077,96.39,3070,55.4076
15.3018719,96.39,2643,51.4101
15.35439303,96.39,2325,48.2183
15.40691416,96.39,2330,48.2701
15.45943529,96.39,2266,47.6025
15.51195642,96.39,2199,46.8935
15.56447755,96.39,2152,46.3897
15.61699868,96.39,2166,46.5403
15.66951981,96.39,2037,45.1331
15.72204095,96.39,2113,45.9674
15.77456208,96.39,2143,46.2925
15.82708321,96.39,2139,46.2493
15.87960434,96.39,2152,46.3897
15.93212547,96.39,2124,46.0869
15.9846466,96.39,2212,47.0319
16.03716773,96.39,2169,46.5725
16.08968886,96.39,2166,46.5403
16.14220999,96.39,2155,46.422
16.19473112,96.39,2158,46.4543
16.24725225,96.39,2181,46.7012
16.29977338,96.39,2186,46.7547
16.35229451,96.39,2176,46.6476
16.40481564,96.39,2205,46.9574
16.45733678,96.39,2210,47.0106
16.50985791,96.39,2222,47.1381
16.56237904,96.39,2135,46.2061
16.61490017,96.39,2154,46.4112
16.6674213,96.39,2184,46.7333
16.71994243,96.39,2218,47.0956
16.77246356,96.39,2154,46.4112
16.82498469,96.39,2177,46.6583
16.87750582,96.39,2240,47.3286
16.93002695,96.39,2137,46.2277
16.98254808,96.39,2123,46.076
17.03506921,96.39,2121,46.0543
17.08759034,96.39,2153,46.4004
17.14011147,96.39,2103,45.8585
17.19263261,96.39,2015,44.8888
17.24515374,96.39,2068,45.4753
17.29767487,96.39,2172,46.6047
17.350196,96.39,2280,47.7493
17.40271713,96.39,2290,47.8539
17.45523826,96.39,2133,46.1844
17.50775939,96.39,2086,45.6727
17.56028052,96.39,2219,47.1063
17.61280165,96.39,2100,45.8258
17.66532278,96.39,2104,45.8694
17.71784391,96.39,2064,45.4313
17.77036504,96.39,2094,45.7602
17.82288617,96.39,2079,45.5961
17.8754073,96.39,2168,46.5618
17.92792843,96.39,2191,46.8081
17.98044957,96.39,2204,46.9468
18.0329707,96.39,2037,45.1331
18.08549183,96.39,2196,46.8615
18.13801296,96.39,2211,47.0213
18.19053409,96.39,2296,47.9166
18.24305522,96.39,2442,49.4166
18.29557635,96.39,2609,51.0784
18.34809748,96.39,2403,49.0204
18.40061861,96.39,2317,48.1352
18.45313974,96.39,2241,47.3392
18.50566087,96.39,2263,47.571
18.558182,96.39,2119,46.0326
18.61070313,96.39,2186,46.7547
18.66322426,96.39,2235,47.2758
18.7157454,96.39,2216,47.0744
18.76826653,96.39,2269,47.634
18.82078766,96.39,2174,46.6262
18.87330879,96.39,2207,46.9787
18.92582992,96.39,2260,47.5395
18.97835105,96.39,2313,48.0937
19.03087218,96.39,2160,46.4758
19.08339331,96.39,2367,48.6518
19.13591444,96.39,2245,47.3814
19.18843557,96.39,2222,47.1381
19.2409567,96.39,2260,47.5395
19.29347783,96.39,2345,48.4252
19.34599896,96.39,2426,49.2544
19.39852009,96.39,2642,51.4004
19.45104123,96.39,2719,52.144
19.50356236,96.39,2435,49.3457
19.55608349,96.39,2376,48.7442
19.60860462,96.39,2374,48.7237
19.66112575,96.39,2627,51.2543
19.71364688,96.39,2865,53.5257
19.76616801,96.39,3195,56.5243
19.81868914,96.39,3014,54.8999
19.87121027,96.39,2980,54.5894
19.9237314,96.39,3560,59.6657
19.97625253,96.39,3378,58.1206
20.02877366,96.39,2631,51.2933
20.08129479,96.39,2368,48.6621
20.13381592,96.39,2356,48.5386
20.18633706,96.39,2426,49.2544
20.23885819,96.39,2429,49.2849
20.29137932,96.39,2555,50.547
20.34390045,96.39,2991,54.69
20.39642158,96.39,3467,58.8812
20.44894271,96.39,3352,57.8965
20.50146384,96.39,3120,55.857
20.55398497,96.39,3569,59.7411
20.6065061,96.39,4479,66.9253
20.65902723,96.39,5806,76.1971
20.71154836,96.39,5336,73.0479
20.76406949,96.39,3564,59.6992
20.81659062,96.39,2761,52.5452
20.86911175,96.39,2576,50.7543
20.92163289,96.39,2549,50.4876
20.97415402,96.39,2580,50.7937
21.02667515,96.39,2435,49.3457
21.07919628,96.39,2397,48.9592
21.13171741,96.39,2344,48.4149
21.18423854,96.39,2444,49.4368
21.23675967,96.39,2366,48.6415
21.2892808,96.39,2435,49.3457
21.34180193,96.39,2404,49.0306
21.39432306,96.39,2280,47.7493
21.44684419,96.39,2353,48.5077
21.49936532,96.39,2320,48.1664
21.55188645,96.39,2352,48.4974
21.60440758,96.39,2413,49.1223
21.65692872,96.39,2515,50.1498
21.70944985,96.39,2537,50.3686
21.76197098,96.39,2443,49.4267
21.81449211,96.39,2372,48.7032
21.86701324,96.39,2318,48.1456
21.91953437,96.39,2305,48.0104
21.9720555,96.39,2383,48.816
22.02457663,96.39,2394,48.9285
22.07709776,96.39,2576,50.7543
22.12961889,96.39,2435,49.3457
22.18214002,96.39,2324,48.2079
22.23466115,96.39,2351,48.4871
22.28718228,96.39,2373,48.7134
22.33970341,96.39,2430,49.295
22.39222455,96.39,2320,48.1664
22.44474568,96.39,2431,49.3052
22.49726681,96.39,2392,48.9081
22.54978794,96.39,2330,48.2701
22.60230907,96.39,2373,48.7134
22.6548302,96.39,2441,49.4065
22.70735133,96.39,2404,49.0306
22.75987246,96.39,2428,49.2747
22.81239359,96.39,2387,48.8569
22.86491472,96.39,2420,49.1935
22.91743585,96.39,2368,48.6621
22.96995698,96.39,2309,48.0521
23.02247811,96.39,2330,48.2701
23.07499924,96.39,2287,47.8226
23.12752038,96.39,2299,47.9479
23.18004151,96.39,2358,48.5592
23.23256264,96.39,2310,48.0625
23.28508377,96.39,2302,47.9792
23.3376049,96.39,2319,48.156
23.39012603,96.39,2486,49.8598
23.44264716,96.39,2480,49.7996
23.49516829,96.39,2629,51.2738
23.54768942,96.39,2538,50.3786
23.60021055,96.39,2452,49.5177
23.65273168,96.39,2359,48.5695
23.70525281,96.39,2336,48.3322
23.75777394,96.39,2351,48.4871
23.81029507,96.39,2330,48.2701
23.86281621,96.39,2256,47.4974
23.91533734,96.39,2315,48.1144
23.96785847,96.39,2245,47.3814
24.0203796,96.39,2321,48.1768
24.07290073,96.39,2314,48.1041
24.12542186,96.39,2501,50.01
24.17794299,96.39,2758,52.5167
24.23046412,96.39,2606,51.049
24.28298525,96.39,2467,49.6689
24.33550638,96.39,2299,47.9479
24.38802751,96.39,2277,47.7179
24.44054864,96.39,2095,45.7712
24.49306977,96.39,2166,46.5403
24.5455909,96.39,2201,46.9148
24.59811204,96.39,2049,45.2659
24.65063317,96.39,1992,44.6318
24.7031543,96.39,2047,45.2438
24.75567543,96.39,1975,44.441
24.80819656,96.39,2000,44.7214
24.86071769,96.39,1988,44.587
24.91323882,96.39,2004,44.7661
24.96575995,96.39,1971,44.3959
25.01828108,96.39,1959,44.2606
25.07080221,96.39,1884,43.4051
25.12332334,96.39,1917,43.7836
25.17584447,96.39,1865,43.1856
25.2283656,96.39,1977,44.4635
25.28088673,96.39,1988,44.587
25.33340786,96.39,2302,47.9792
25.385929,96.39,2548,50.4777
25.43845013,96.39,2552,50.5173
25.49097126,96.39,2179,46.6798
25.54349239,96.39,1992,44.6318
25.59601352,96.39,1917,43.7836
25.64853465,96.39,1762,41.9762
25.70105578,96.39,1806,42.4971
25.75357691,96.39,1871,43.2551
25.80609804,96.39,1913,43.7379
25.85861917,96.39,1985,44.5533
25.9111403,96.39,1830,42.7785
25.96366143,96.39,1875,43.3013
26.01618256,96.39,1759,41.9404
26.06870369,96.39,1706,41.3038
26.12122483,96.39,1671,40.8779
26.17374596,96.39,1808,42.5206
26.22626709,96.39,1767,42.0357
26.27878822,96.39,1766,42.0238
26.33130935,96.39,1779,42.1782
26.38383048,96.39,1797,42.391
26.43635161,96.39,1838,42.8719
26.48887274,96.39,1695,41.1704
26.54139387,96.39,1717,41.4367
26.593915,96.39,1722,41.497
26.64643613,96.39,1686,41.0609
26.69895726,96.39,1743,41.7493
26.75147839,96.39,1690,41.1096
26.80399952,96.39,1711,41.3642
26.85652066,96.39,1716,41.4246
26.90904179,96.39,1863,43.1625
26.96156292,96.39,1773,42.107
27.01408405,96.39,1834,42.8252
27.06660518,96.39,1917,43.7836
27.11912631,96.39,2340,48.3735
27.17164744,96.39,2503,50.03
27.22416857,96.39,2179,46.6798
27.2766897,96.39,1891,43.4856
27.32921083,96.39,1934,43.9773
27.38173196,96.39,1774,42.1189
27.43425309,96.39,1666,40.8167
27.48677422,96.39,1661,40.7554
27.53929535,96.39,1656,40.694
27.59181649,96.39,1702,41.2553
27.64433762,96.39,1801,42.4382
27.69685875,96.39,1697,41.1947
27.74937988,96.39,1669,40.8534
27.80190101,96.39,1693,41.1461
27.85442214,96.39,1669,40.8534
27.90694327,96.39,1692,41.1339
27.9594644,96.39,1652,40.6448
28.01198553,96.39,1658,40.7185
28.06450666,96.39,1653,40.6571
28.11702779,96.39,1755,41.8927
28.16954892,96.39,1760,41.9524
28.22207005,96.39,1819,42.6497
28.27459118,96.39,1840,42.8952
28.32711232,96.39,1777,42.1545
28.37963345,96.39,1727,41.5572
28.43215458,96.39,1628,40.3485
28.48467571,96.39,1662,40.7676
28.53719684,96.39,1613,40.1622
28.58971797,96.39,1651,40.6325
28.6422391,96.39,1676,40.939
28.69476023,96.39,1749,41.821
28.74728136,96.39,1739,41.7013
28.79980249,96.39,1765,42.0119
28.85232362,96.39,1652,40.6448
28.90484475,96.39,1624,40.2989
28.95736588,96.39,1706,41.3038
29.00988701,96.39,1831,42.7902
29.06240815,96.39,1894,43.5201
29.11492928,96.39,1875,43.3013
29.16745041,96.39,1744,41.7612
29.21997154,96.39,1603,40.0375
29.27249267,96.39,1627,40.3361
29.3250138,96.39,1571,39.6358
29.37753493,96.39,1583,39.7869
29.43005606,96.39,1599,39.9875
29.48257719,96.39,1583,39.7869
29.53509832,96.39,1658,40.7185
29.58761945,96.39,1636,40.4475
29.64014058,96.39,1593,39.9124
29.69266171,96.39,1610,40.1248
29.74518284,96.39,1557,39.4588
29.79770398,96.39,1614,40.1746
29.85022511,96.39,1616,40.1995
29.90274624,96.39,1617,40.2119
29.95526737,96.39,1534,39.1663
30.0077885,96.39,1496,38.6782
30.06030963,96.39,1576,39.6989
30.11283076,96.39,1650,40.6202
30.16535189,96.39,1625,40.3113
30.21787302,96.39,1689,41.0974
30.27039415,96.39,1633,40.4104
30.32291528,96.39,1657,40.7063
30.37543641,96.39,1672,40.8901
30.42795754,96.39,1750,41.833
30.48047867,96.39,1896,43.5431
30.53299981,96.39,1823,42.6966
30.58552094,96.39,1855,43.0697
30.63804207,96.39,2060,45.3872
30.6905632,96.39,2329,48.2597
30.74308433,96.39,2156,46.4327
30.79560546,96.39,2134,46.1952
30.84812659,96.39,1872,43.2666
30.90064772,96.39,1694,41.1582
30.95316885,96.39,1637,40.4599
31.00568998,96.39,1747,41.7971
31.05821111,96.39,1779,42.1782
31.11073224,96.39,2052,45.299
31.16325337,96.39,2307,48.0312
31.2157745,96.39,2257,47.5079
31.26829564,96.39,2060,45.3872
31.32081677,96.39,1889,43.4626
31.3733379,96.39,1748,41.8091
31.42585903,96.39,1920,43.8178
31.47838016,96.39,2064,45.4313
31.53090129,96.39,2055,45.3321
31.58342242,96.39,2008,44.8107
31.63594355,96.39,2127,46.1194
31.68846468,96.39,2183,46.7226
31.74098581,96.39,2038,45.1442
31.79350694,96.39,1895,43.5316
31.84602807,96.39,1809,42.5323
31.8985492,96.39,1984,44.5421
31.95107033,96.39,2788,52.8015
32.00359147,96.39,4076,63.8436
32.0561126,96.39,3997,63.2218
32.10863373,96.39,3184,56.4269
32.16115486,96.39,2260,47.5395
32.21367599,96.39,1715,41.4126
32.26619712,96.39,1650,40.6202
32.31871825,96.39,1707,41.3159
32.37123938,96.39,1683,41.0244
32.42376051,96.39,1584,39.7995
32.47628164,96.39,1624,40.2989
32.52880277,96.39,1517,38.9487
32.5813239,96.39,1686,41.0609
32.63384503,96.39,1728,41.5692
32.68636616,96.39,1650,40.6202
32.7388873,96.39,1618,40.2244
32.79140843,96.39,1570,39.6232
32.84392956,96.39,1536,39.1918
32.89645069,96.39,1719,41.4608
32.94897182,96.39,1766,42.0238
33.00149295,96.39,1884,43.4051
33.05401408,96.39,1936,44
33.10653521,96.39,2027,45.0222
33.15905634,96.39,1920,43.8178
33.21157747,96.39,1897,43.5546
33.2640986,96.39,1870,43.2435
33.31661973,96.39,1800,42.4264
33.36914086,96.39,2109,45.9239
33.42166199,96.39,2308,48.0416
33.47418312,96.39,2055,45.3321
33.52670426,96.39,1913,43.7379
33.57922539,96.39,1687,41.0731
33.63174652,96.39,1581,39.7618
33.68426765,96.39,1809,42.5323
33.73678878,96.39,1795,42.3674
33.78930991,96.39,1864,43.1741
33.84183104,96.39,2179,46.6798
33.89435217,96.39,2613,51.1175
33.9468733,96.39,2856,53.4416
33.99939443,96.39,2588,50.8724
34.05191556,96.39,2196,46.8615
34.10443669,96.39,2130,46.1519
34.15695782,96.39,2056,45.3431
34.20947895,96.39,2141,46.2709
34.26200009,96.39,2187,46.7654
34.31452122,96.39,2200,46.9042
34.36704235,96.39,2167,46.551
34.41956348,96.39,2179,46.6798
34.47208461,96.39,2220,47.1169
34.52460574,96.39,2117,46.0109
34.57712687,96.39,2203,46.9361
34.629648,96.39,2127,46.1194
34.68216913,96.39,2193,46.8295
34.73469026,96.39,2108,45.913
34.78721139,96.39,2201,46.9148
34.83973252,96.39,2544,50.4381
34.89225365,96.39,2828,53.1789
34.94477478,96.39,2928,54.111
34.99729592,96.39,2664,51.614
35.04981705,96.39,2369,48.6724
35.10233818,96.39,2153,46.4004
35.15485931,96.39,2117,46.0109
35.20738044,96.39,2037,45.1331
35.25990157,96.39,1972,44.4072
35.3124227,96.39,1966,44.3396
35.36494383,96.39,1841,42.9069
35.41746496,96.39,1762,41.9762
35.46998609,96.39,1765,42.0119
35.52250722,96.39,1700,41.2311
35.57502835,96.39,1862,43.1509
35.62754948,96.39,1790,42.3084
35.68007061,96.39,1820,42.6615
35.73259175,96.39,1736,41.6653
35.78511288,96.39,1796,42.3792
35.83763401,96.39,1705,41.2916
35.89015514,96.39,1725,41.5331
35.94267627,96.39,1704,41.2795
35.9951974,96.39,1697,41.1947
36.04771853,96.39,1629,40.3609
36.10023966,96.39,1564,39.5474
36.15276079,96.39,1554,39.4208
36.20528192,96.39,1501,38.7427
36.25780305,96.39,1535,39.1791
36.31032418,96.39,1628,40.3485
36.36284531,96.39,1668,40.8412
36.41536644,96.39,1600,40
36.46788758,96.39,1535,39.1791
36.52040871,96.39,1486,38.5487
36.57292984,96.39,1406,37.4967
36.62545097,96.39,1413,37.5899
36.6779721,96.39,1370,37.0135
36.73049323,96.39,1435,37.8814
36.78301436,96.39,1423,37.7227
36.83553549,96.39,1379,37.1349
36.88805662,96.39,1385,37.2156
36.94057775,96.39,1365,36.9459
36.99309888,96.39,1359,36.8646
37.04562001,96.39,1336,36.5513
37.09814114,96.39,1404,37.47
37.15066227,96.39,1461,38.223
37.20318341,96.39,1308,36.1663
37.25570454,96.39,1405,37.4833
37.30822567,96.39,1379,37.1349
37.3607468,96.39,1318,36.3043
37.41326793,96.39,1435,37.8814
37.46578906,96.39,1341,36.6197
37.51831019,96.39,1424,37.7359
37.57083132,96.39,1361,36.8917
37.62335245,96.39,1500,38.7298
37.67587358,96.39,1670,40.8656
37.72839471,96.39,1677,40.9512
37.78091584,96.39,1669,40.8534
37.83343697,96.39,1509,38.8458
37.8859581,96.39,1464,38.2623
37.93847924,96.39,1387,37.2424
37.99100037,96.39,1322,36.3593
38.0435215,96.39,1358,36.8511
38.09604263,96.39,1435,37.8814
38.14856376,96.39,1546,39.3192
38.20108489,96.39,1467,38.3014
38.25360602,96.39,1508,38.833
38.30612715,96.39,1422,37.7094
38.35864828,96.39,1451,38.092
38.41116941,96.39,1419,37.6696
38.46369054,96.39,1326,36.4143
38.51621167,96.39,1336,36.5513
38.5687328,96.39,1421,37.6962
38.62125393,96.39,1380,37.1484
38.67377507,96.39,1447,38.0395
38.7262962,96.39,1445,38.0132
38.77881733,96.39,1505,38.7943
38.83133846,96.39,1452,38.1051
38.88385959,96.39,1333,36.5103
38.93638072,96.39,1243,35.2562
38.98890185,96.39,1277,35.7351
39.04142298,96.39,1299,36.0416
39.09394411,96.39,1257,35.4542
39.14646524,96.39,1310,36.1939
39.19898637,96.39,1342,36.6333
39.2515075,96.39,1414,37.6032
39.30402863,96.39,1370,37.0135
39.35654976,96.39,1550,39.37
39.4090709,96.39,1677,40.9512
39.46159203,96.39,1480,38.4708
39.51411316,96.39,1469,38.3275
39.56663429,96.39,1324,36.3868
39.61915542,96.39,1349,36.7287
39.67167655,96.39,1253,35.3977
39.72419768,96.39,1316,36.2767
39.77671881,96.39,1379,37.1349
39.82923994,96.39,1234,35.1283
39.88176107,96.39,1230,35.0714
39.9342822,96.39,1282,35.805
39.98680333,96.39,1190,34.4964
40.03932446,96.39,1246,35.2987
40.09184559,96.39,1332,36.4966
40.14436673,96.39,1228,35.0428
40.19688786,96.39,1239,35.1994
40.24940899,96.39,1242,35.242
40.30193012,96.39,1122,33.4963
40.35445125,96.39,1182,34.3802
40.40697238,96.39,1148,33.8821
40.45949351,96.39,1215,34.8569
40.51201464,96.39,1151,33.9264
40.56453577,96.39,1213,34.8281
40.6170569,96.39,1188,34.4674
40.66957803,96.39,1155,33.9853
40.72209916,96.39,1122,33.4963
40.77462029,96.39,1069,32.6956
40.82714142,96.39,1066,32.6497
40.87966255,96.39,1044,32.311
40.93218369,96.39,1038,32.218
40.98470482,96.39,1152,33.9411
41.03722595,96.39,1072,32.7414
41.08974708,96.39,1061,32.573
41.14226821,96.39,1123,33.5112
41.19478934,96.39,1067,32.665
41.24731047,96.39,1230,35.0714
41.2998316,96.39,1382,37.1753
41.35235273,96.39,1469,38.3275
41.40487386,96.39,1326,36.4143
41.45739499,96.39,1284,35.8329
41.50991612,96.39,1175,34.2783
41.56243725,96.39,1035,32.1714
41.61495838,96.39,1083,32.909
41.66747952,96.39,964,31.0483
41.72000065,96.39,1005,31.7017
41.77252178,96.39,969,31.1288
41.82504291,96.39,981,31.3209
41.87756404,96.39,1003,31.6702
41.93008517,96.39,1013,31.8277
41.9826063,96.39,1002,31.6544
42.03512743,96.39,1107,33.2716
42.08764856,96.39,1269,35.623
42.14016969,96.39,1307,36.1525
42.19269082,96.39,1177,34.3074
42.24521195,96.39,1238,35.1852
42.29773308,96.39,1102,33.1964
42.35025421,96.39,1027,32.0468
42.40277535,96.39,992,31.496
42.45529648,96.39,1061,32.573
42.50781761,96.39,1165,34.1321
42.56033874,96.39,1090,33.0151
42.61285987,96.39,1107,33.2716
42.665381,96.39,1035,32.1714
42.71790213,96.39,986,31.4006
42.77042326,96.39,987,31.4166
42.82294439,96.39,980,31.305
42.87546552,96.39,989,31.4484
42.92798665,96.39,969,31.1288
42.98050778,96.39,996,31.5595
43.03302891,96.39,970,31.1448
43.08555004,96.39,935,30.5778
43.13807118,96.39,933,30.545
43.19059231,96.39,980,31.305
43.24311344,96.39,934,30.5614
43.29563457,96.39,925,30.4138
43.3481557,96.39,924,30.3974
43.40067683,96.39,1004,31.686
43.45319796,96.39,950,30.8221
43.50571909,96.39,967,31.0966
43.55824022,96.39,1037,32.2025
43.61076135,96.39,1015,31.8591
43.66328248,96.39,1167,34.1614
43.71580361,96.39,1284,35.8329
43.76832474,96.39,1257,35.4542
43.82084587,96.39,1200,34.641
43.87336701,96.39,1168,34.176
43.92588814,96.39,1024,32
43.97840927,96.39,1016,31.8748
44.0309304,96.39,930,30.4959
44.08345153,96.39,990,31.4643
44.13597266,96.39,1019,31.9218
44.18849379,96.39,1017,31.8904
44.24101492,96.39,1092,33.0454
44.29353605,96.39,1130,33.6155
44.34605718,96.39,1176,34.2929
44.39857831,96.39,1171,34.2199
44.45109944,96.39,1069,32.6956
44.50362057,96.39,1072,32.7414
44.5561417,96.39,1081,32.8786
44.60866284,96.39,985,31.3847
44.66118397,96.39,990,31.4643
44.7137051,96.39,1068,32.6803
44.76622623,96.39,1049,32.3883
44.81874736,96.39,1100,33.1662
44.87126849,96.39,1024,32
44.92378962,96.39,1092,33.0454
44.97631075,96.39,1070,32.7109
45.02883188,96.39,1205,34.7131
45.08135301,96.39,1284,35.8329
45.13387414,96.39,1230,35.0714
45.18639527,96.39,1218,34.8999
45.2389164,96.39,1246,35.2987
45.29143753,96.39,1202,34.6699
45.34395867,96.39,1153,33.9559
45.3964798,96.39,1215,34.8569
45.44900093,96.39,1323,36.3731
45.50152206,96.39,1085,32.9393
45.55404319,96.39,1194,34.5543
45.60656432,96.39,1192,34.5254
45.65908545,96.39,1057,32.5115
45.71160658,96.39,1010,31.7805
45.76412771,96.39,1061,32.573
45.81664884,96.39,1065,32.6343
45.86916997,96.39,1066,32.6497
45.9216911,96.39,1052,32.4345
45.97421223,96.39,1056,32.4962
46.02673336,96.39,1021,31.9531
46.0792545,96.39,1102,33.1964
46.13177563,96.39,1145,33.8378
46.18429676,96.39,1253,35.3977
46.23681789,96.39,1339,36.5923
46.28933902,96.39,1274,35.6931
46.34186015,96.39,1221,34.9428
46.39438128,96.39,1139,33.7491
46.44690241,96.39,1171,34.2199
46.49942354,96.39,1148,33.8821
46.55194467,96.39,1062,32.5883
46.6044658,96.39,1116,33.4066
46.65698693,96.39,1209,34.7707
46.70950806,96.39,1211,34.7994
46.76202919,96.39,1103,33.2114
46.81455033,96.39,1151,33.9264
46.86707146,96.39,1077,32.8177
46.91959259,96.39,1097,33.121
46.97211372,96.39,1089,33
47.02463485,96.39,1091,33.0303
47.07715598,96.39,1072,32.7414
47.12967711,96.39,1021,31.9531
47.18219824,96.39,986,31.4006
47.23471937,96.39,1009,31.7648
47.2872405,96.39,989,31.4484
47.33976163,96.39,952,30.8545
47.39228276,96.39,968,31.1127
47.44480389,96.39,963,31.0322
47.49732502,96.39,1024,32
47.54984616,96.39,963,31.0322
47.60236729,96.39,928,30.4631
47.65488842,96.39,969,31.1288
47.70740955,96.39,934,30.5614
47.75993068,96.39,991,31.4802
47.81245181,96.39,945,30.7409
47.86497294,96.39,964,31.0483
47.91749407,96.39,937,30.6105
47.9700152,96.39,939,30.6431
48.02253633,96.39,1044,32.311
48.07505746,96.39,1068,32.6803
48.12757859,96.39,1048,32.3728
48.18009972,96.39,981,31.3209
48.23262085,96.39,953,30.8707
48.28514198,96.39,929,30.4795
48.33766312,96.39,935,30.5778
48.39018425,96.39,981,31.3209
48.44270538,96.39,1063,32.6037
48.49522651,96.39,1033,32.1403
48.54774764,96.39,1002,31.6544
48.60026877,96.39,982,31.3369
48.6527899,96.39,904,30.0666
48.70531103,96.39,896,29.9333
48.75783216,96.39,947,30.7734
48.81035329,96.39,931,30.5123
48.86287442,96.39,853,29.2062
48.91539555,96.39,952,30.8545
48.96791668,96.39,910,30.1662
49.02043781,96.39,924,30.3974
49.07295895,96.39,895,29.9166
49.12548008,96.39,912,30.1993
49.17800121,96.39,878,29.6311
49.23052234,96.39,873,29.5466
49.28304347,96.39,920,30.3315
49.3355646,96.39,908,30.133
49.38808573,96.39,869,29.4788
49.44060686,96.39,971,31.1609
49.49312799,96.39,919,30.315
49.54564912,96.39,928,30.4631
49.59817025,96.39,895,29.9166
49.65069138,96.39,910,30.1662
49.70321251,96.39,863,29.3769
49.75573364,96.39,904,30.0666
49.80825478,96.39,860,29.3258
49.86077591,96.39,864,29.3939
49.91329704,96.39,777,27.8747
49.96581817,96.39,797,28.2312
50.0183393,96.39,820,28.6356
50.07086043,96.39,802,28.3196
50.12338156,96.39,794,28.178
50.17590269,96.39,907,30.1164
50.22842382,96.39,942,30.692
50.28094495,96.39,896,29.9333
50.33346608,96.39,884,29.7321
50.38598721,96.39,882,29.6985
50.43850834,96.39,888,29.7993
50.49102947,96.39,820,28.6356
50.54355061,96.39,743,27.258
50.59607174,96.39,788,28.0713
50.64859287,96.39,763,27.6225
50.701114,96.39,787,28.0535
50.75363513,96.39,790,28.1069
50.80615626,96.39,747,27.3313
50.85867739,96.39,805,28.3725
50.91119852,96.39,782,27.9643
50.96371965,96.39,752,27.4226
51.01624078,96.39,866,29.4279
51.06876191,96.39,801,28.3019
51.12128304,96.39,739,27.1846
51.17380417,96.39,869,29.4788
51.2263253,96.39,833,28.8617
51.27884644,96.39,780,27.9285
51.33136757,96.39,827,28.7576
51.3838887,96.39,788,28.0713
51.43640983,96.39,744,27.2764
51.48893096,96.39,752,27.4226
51.54145209,96.39,739,27.1846
51.59397322,96.39,687,26.2107
51.64649435,96.39,762,27.6043
51.69901548,96.39,749,27.3679
51.75153661,96.39,748,27.3496
51.80405774,96.39,770,27.7489
51.85657887,96.39,772,27.7849
51.9091,96.39,786,28.0357
51.96162113,96.39,768,27.7128
52.01414227,96.39,754,27.4591
52.0666634,96.39,778,27.8927
52.11918453,96.39,883,29.7153
52.17170566,96.39,917,30.282
52.22422679,96.39,922,30.3645
52.27674792,96.39,908,30.133
52.32926905,96.39,802,28.3196
52.38179018,96.39,826,28.7402
52.43431131,96.39,771,27.7669
52.48683244,96.39,733,27.074
52.53935357,96.39,732,27.0555
52.5918747,96.39,759,27.55
52.64439583,96.39,805,28.3725
52.69691696,96.39,787,28.0535
52.7494381,96.39,745,27.2947
52.80195923,96.39,759,27.55
52.85448036,96.39,807,28.4077
52.90700149,96.39,818,28.6007
52.95952262,96.39,781,27.9464
53.01204375,96.39,747,27.3313
53.06456488,96.39,786,28.0357
53.11708601,96.39,805,28.3725
53.16960714,96.39,843,29.0345
53.22212827,96.39,695,26.3629
53.2746494,96.39,823,28.688
53.32717053,96.39,838,28.9482
53.37969166,96.39,805,28.3725
53.43221279,96.39,746,27.313
53.48473393,96.39,661,25.7099
53.53725506,96.39,705,26.5518
53.58977619,96.39,684,26.1534
53.64229732,96.39,694,26.3439
53.69481845,96.39,660,25.6905
53.74733958,96.39,701,26.4764
53.79986071,96.39,691,26.2869
53.85238184,96.39,664,25.7682
53.90490297,96.39,726,26.9444
53.9574241,96.39,702,26.4953
54.00994523,96.39,711,26.6646
54.06246636,96.39,763,27.6225
54.11498749,96.39,840,28.9828
54.16750862,96.39,781,27.9464
54.22002976,96.39,799,28.2666
54.27255089,96.39,857,29.2746
54.32507202,96.39,799,28.2666
54.37759315,96.39,740,27.2029
54.43011428,96.39,728,26.9815
54.48263541,96.39,705,26.5518
54.53515654,96.39,708,26.6083
54.58767767,96.39,729,27
54.6401988,96.39,670,25.8844
54.69271993,96.39,666,25.807
54.74524106,96.39,656,25.6125
54.79776219,96.39,649,25.4755
54.85028332,96.39,717,26.7769
54.90280445,96.39,686,26.1916
54.95532559,96.39,647,25.4362
55.00784672,96.39,731,27.037
55.06036785,96.39,725,26.9258
55.11288898,96.39,685,26.1725
55.16541011,96.39,667,25.8263
55.21793124,96.39,631,25.1197
55.27045237,96.39,674,25.9615
55.3229735,96.39,631,25.1197
55.37549463,96.39,610,24.6982
55.42801576,96.39,732,27.0555
55.48053689,96.39,656,25.6125
55.53305802,96.39,716,26.7582
55.58557915,96.39,673,25.9422
55.63810028,96.39,646,25.4165
55.69062141,96.39,672,25.923
55.74314255,96.39,650,25.4951
55.79566368,96.39,632,25.1396
55.84818481,96.39,653,25.5539
55.90070594,96.39,636,25.219
55.95322707,96.39,625,25
56.0057482,96.39,580,24.0832
56.05826933,96.39,665,25.7876
56.11079046,96.39,661,25.7099
56.16331159,96.39,634,25.1794
56.21583272,96.39,583,24.1454
56.26835385,96.39,604,24.5764
56.32087498,96.39,658,25.6515
56.37339611,96.39,654,25.5734
56.42591724,96.39,652,25.5343
56.47843838,96.39,607,24.6374
56.53095951,96.39,636,25.219
56.58348064,96.39,608,24.6577
56.63600177,96.39,613,24.7588
56.6885229,96.39,616,24.8193
56.74104403,96.39,628,25.0599
56.79356516,96.39,618,24.8596
56.84608629,96.39,608,24.6577
56.89860742,96.39,579,24.0624
56.95112855,96.39,630,25.0998
57.00364968,96.39,635,25.1992
57.05617081,96.39,599,24.4745
57.10869194,96.39,581,24.1039
57.16121307,96.39,585,24.1868
57.21373421,96.39,615,24.7992
57.26625534,96.39,633,25.1595
57.31877647,96.39,599,24.4745
57.3712976,96.39,582,24.1247
57.42381873,96.39,658,25.6515
57.47633986,96.39,706,26.5707
57.52886099,96.39,651,25.5147
57.58138212,96.39,660,25.6905
57.63390325,96.39,673,25.9422
57.68642438,96.39,680,26.0768
57.73894551,96.39,656,25.6125
57.79146664,96.39,684,26.1534
57.84398777,96.39,635,25.1992
57.8965089,96.39,595,24.3926
57.94903004,96.39,649,25.4755
58.00155117,96.39,741,27.2213
58.0540723,96.39,727,26.9629
58.10659343,96.39,687,26.2107
58.15911456,96.39,695,26.3629
58.21163569,96.39,652,25.5343
58.26415682,96.39,637,25.2389
58.31667795,96.39,659,25.671
58.36919908,96.39,605,24.5967
58.42172021,96.39,590,24.2899
58.47424134,96.39,626,25.02
58.52676247,96.39,602,24.5357
58.5792836,96.39,627,25.04
58.63180473,96.39,594,24.3721
58.68432587,96.39,613,24.7588
58.736847,96.39,602,24.5357
58.78936813,96.39,609,24.6779
58.84188926,96.39,629,25.0799
58.89441039,96.39,599,24.4745
58.94693152,96.39,581,24.1039
58.99945265,96.39,624,24.98
59.05197378,96.39,609,24.6779
59.10449491,96.39,543,23.3024
59.15701604,96.39,637,25.2389
59.20953717,96.39,645,25.3969
59.2620583,96.39,614,24.779
59.31457943,96.39,630,25.0998
59.36710056,96.39,634,25.1794
59.4196217,96.39,634,25.1794
59.47214283,96.39,608,24.6577
59.52466396,96.39,652,25.5343
59.57718509,96.39,625,25
59.62970622,96.39,619,24.8797
59.68222735,96.39,622,24.9399
59.73474848,96.39,692,26.3059
59.78726961,96.39,644,25.3772
59.83979074,96.39,653,25.5539
59.89231187,96.39,703,26.5141
59.944833,96.39,726,26.9444
59.99735413,96.39,694,26.3439
60.04987526,96.39,692,26.3059
60.10239639,96.39,738,27.1662
60.15491753,96.39,717,26.7769
60.20743866,96.39,761,27.5862
60.25995979,96.39,691,26.2869
60.31248092,96.39,748,27.3496
60.36500205,96.39,721,26.8514
60.41752318,96.39,776,27.8568
60.47004431,96.39,763,27.6225
60.52256544,96.39,779,27.9106
60.57508657,96.39,775,27.8388
60.6276077,96.39,875,29.5804
60.68012883,96.39,801,28.3019
60.73264996,96.39,850,29.1548
60.78517109,96.39,859,29.3087
60.83769222,96.39,888,29.7993
60.89021336,96.39,987,31.4166
60.94273449,96.39,907,30.1164
60.99525562,96.39,928,30.4631
61.04777675,96.39,930,30.4959
61.10029788,96.39,934,30.5614
61.15281901,96.39,973,31.1929
61.20534014,96.39,891,29.8496
61.25786127,96.39,975,31.225
61.3103824,96.39,944,30.7246
61.36290353,96.39,958,30.9516
61.41542466,96.39,949,30.8058
61.46794579,96.39,919,30.315
61.52046692,96.39,869,29.4788
61.57298805,96.39,931,30.5123
61.62550919,96.39,915,30.249
61.67803032,96.39,940,30.6594
61.73055145,96.39,873,29.5466
61.78307258,96.39,901,30.0167
61.83559371,96.39,830,28.8097
61.88811484,96.39,791,28.1247
61.94063597,96.39,821,28.6531
61.9931571,96.39,816,28.5657
62.04567823,96.39,853,29.2062
62.09819936,96.39,782,27.9643
62.15072049,96.39,771,27.7669
62.20324162,96.39,785,28.0179
62.25576275,96.39,762,27.6043
62.30828388,96.39,774,27.8209
62.36080502,96.39,790,28.1069
62.41332615,96.39,752,27.4226
62.46584728,96.39,745,27.2947
62.51836841,96.39,704,26.533
62.57088954,96.39,709,26.6271
62.62341067,96.39,713,26.7021
62.6759318,96.39,733,27.074
62.72845293,96.39,653,25.5539
62.78097406,96.39,705,26.5518
62.83349519,96.39,700,26.4575
62.88601632,96.39,680,26.0768
62.93853745,96.39,668,25.8457
62.99105858,96.39,627,25.04
63.04357971,96.39,678,26.0384
63.09610084,96.39,612,24.7386
63.14862198,96.39,615,24.7992
63.20114311,96.39,598,24.454
63.25366424,96.39,596,24.4131
63.30618537,96.39,656,25.6125
63.3587065,96.39,586,24.2074
63.41122763,96.39,594,24.3721
63.46374876,96.39,566,23.7908
63.51626989,96.39,592,24.3311
63.56879102,96.39,611,24.7184
63.62131215,96.39,658,25.6515
63.67383328,96.39,599,24.4745
63.72635441,96.39,609,24.6779
63.77887554,96.39,670,25.8844
63.83139667,96.39,614,24.779
63.88391781,96.39,638,25.2587
63.93643894,96.39,660,25.6905
63.98896007,96.39,646,25.4165
64.0414812,96.39,648,25.4558
64.09400233,96.39,606,24.6171
64.14652346,96.39,649,25.4755
64.19904459,96.39,615,24.7992
64.25156572,96.39,596,24.4131
64.30408685,96.39,582,24.1247
64.35660798,96.39,569,23.8537
64.40912911,96.39,581,24.1039
64.46165024,96.39,577,24.0208
64.51417137,96.39,535,23.1301
64.5666925,96.39,532,23.0651
64.61921364,96.39,553,23.516
64.67173477,96.39,544,23.3238
64.7242559,96.39,544,23.3238
64.77677703,96.39,535,23.1301
64.82929816,96.39,541,23.2594
64.88181929,96.39,496,22.2711
64.93434042,96.39,544,23.3238
64.98686155,96.39,535,23.1301