File: Files_organized_for_plots/Na_to_Al_1/XRD_PAxial22Nov21_Act23Jan22_B1_0307M_NaOH_LS0108_1.csv
[Measurement conditions]
Sample identification,XRD_PAxial22Nov21_Act23Jan22_B1_0307M_NaOH_LS0108_1
Comment - 1,"Configuration=Stage for Flat Samples/Holders, Owner=User-1, Creation date=7/1/2020 9:53:24 AM"
Comment - 2,"Goniometer=Theta/Theta; Minimum step size 2Theta:0.0001; Minimum step size Omega:0.0001"
Comment - 3,"Sample stage=Stage for flat samples/holders"
Comment - 4,"Diffractometer system=EMPYREAN"
Comment - 5,"Measurement program=C:\Users\ibo5034\OneDrive - The Pennsylvania State University\NEUP\Zerobackground scan.xrdmp, Identifier={98A3B11C-88F9-4AA6-982C-73314A311EF5}"
Anode material,Cu
K-Alpha1 wavelength,1.5405980
K-Alpha2 wavelength,1.5444260
Ratio K-Alpha2/K-Alpha1,0.500
Divergence slit,Fixed,0.25
Monochromator used,NO
Generator voltage, 45
Tube current, 40
File date and time,26/Jan/2022 12:01
Unit cell,
h k l, 0 0 0
Scan axis,Gonio
Scan range,4.994599997,64.999991833
Scan step size,0.0262606
No. of points, 2285
Scan type,CONTINUOUS
Time per step,96.390
[Scan points]
Angle, TimePerStep, Intensity, ESD
5.007730280, 96.390, 7040.0, 83.9047
5.060251411, 96.390, 6898.0, 83.0542
5.112772541, 96.390, 6718.0, 81.9634
5.165293672, 96.390, 6818.0, 82.5712
5.217814803, 96.390, 6582.0, 81.1295
5.270335934, 96.390, 6497.0, 80.6040
5.322857064, 96.390, 6381.0, 79.8812
5.375378195, 96.390, 6110.0, 78.1665
5.427899326, 96.390, 6263.0, 79.1391
5.480420456, 96.390, 6048.0, 77.7689
5.532941587, 96.390, 6031.0, 77.6595
5.585462718, 96.390, 5834.0, 76.3806
5.637983849, 96.390, 5762.0, 75.9078
5.690504979, 96.390, 5767.0, 75.9408
5.743026110, 96.390, 5830.0, 76.3544
5.795547241, 96.390, 5649.0, 75.1598
5.848068371, 96.390, 5569.0, 74.6257
5.900589502, 96.390, 5397.0, 73.4643
5.953110633, 96.390, 5401.0, 73.4915
6.005631763, 96.390, 5360.0, 73.2120
6.058152894, 96.390, 5372.0, 73.2939
6.110674025, 96.390, 5245.0, 72.4224
6.163195156, 96.390, 5092.0, 71.3583
6.215716286, 96.390, 5177.0, 71.9514
6.268237417, 96.390, 5196.0, 72.0833
6.320758548, 96.390, 4980.0, 70.5691
6.373279678, 96.390, 4963.0, 70.4486
6.425800809, 96.390, 5006.0, 70.7531
6.478321940, 96.390, 4841.0, 69.5773
6.530843071, 96.390, 4951.0, 70.3633
6.583364201, 96.390, 4865.0, 69.7496
6.635885332, 96.390, 4833.0, 69.5198
6.688406463, 96.390, 4767.0, 69.0435
6.740927593, 96.390, 4720.0, 68.7023
6.793448724, 96.390, 4735.0, 68.8113
6.845969855, 96.390, 4678.0, 68.3959
6.898490986, 96.390, 4804.0, 69.3109
6.951012116, 96.390, 4788.0, 69.1954
7.003533247, 96.390, 4640.0, 68.1175
7.056054378, 96.390, 4719.0, 68.6950
7.108575508, 96.390, 4628.0, 68.0294
7.161096639, 96.390, 4752.0, 68.9348
7.213617770, 96.390, 4750.0, 68.9202
7.266138900, 96.390, 4767.0, 69.0435
7.318660031, 96.390, 4906.0, 70.0428
7.371181162, 96.390, 5114.0, 71.5122
7.423702293, 96.390, 5073.0, 71.2250
7.476223423, 96.390, 5257.0, 72.5052
7.528744554, 96.390, 5274.0, 72.6223
7.581265685, 96.390, 5318.0, 72.9246
7.633786815, 96.390, 5491.0, 74.1013
7.686307946, 96.390, 5707.0, 75.5447
7.738829077, 96.390, 5748.0, 75.8156
7.791350208, 96.390, 5702.0, 75.5116
7.843871338, 96.390, 6070.0, 77.9102
7.896392469, 96.390, 5986.0, 77.3692
7.948913600, 96.390, 6184.0, 78.6384
8.001434730, 96.390, 6344.0, 79.6492
8.053955861, 96.390, 6172.0, 78.5621
8.106476992, 96.390, 5977.0, 77.3111
8.158998123, 96.390, 5812.0, 76.2365
8.211519253, 96.390, 5557.0, 74.5453
8.264040384, 96.390, 5522.0, 74.3102
8.316561515, 96.390, 5121.0, 71.5612
8.369082645, 96.390, 4812.0, 69.3686
8.421603776, 96.390, 4738.0, 68.8331
8.474124907, 96.390, 4407.0, 66.3852
8.526646038, 96.390, 4373.0, 66.1287
8.579167168, 96.390, 4185.0, 64.6916
8.631688299, 96.390, 4071.0, 63.8044
8.684209430, 96.390, 4019.0, 63.3956
8.736730560, 96.390, 3896.0, 62.4179
8.789251691, 96.390, 3782.0, 61.4980
8.841772822, 96.390, 3694.0, 60.7783
8.894293952, 96.390, 3682.0, 60.6795
8.946815083, 96.390, 3703.0, 60.8523
8.999336214, 96.390, 3582.0, 59.8498
9.051857345, 96.390, 3591.0, 59.9250
9.104378475, 96.390, 3440.0, 58.6515
9.156899606, 96.390, 3533.0, 59.4390
9.209420737, 96.390, 3439.0, 58.6430
9.261941867, 96.390, 3482.0, 59.0085
9.314462998, 96.390, 3356.0, 57.9310
9.366984129, 96.390, 3386.0, 58.1893
9.419505260, 96.390, 3288.0, 57.3411
9.472026390, 96.390, 3249.0, 57.0000
9.524547521, 96.390, 3257.0, 57.0701
9.577068652, 96.390, 3387.0, 58.1979
9.629589782, 96.390, 3260.0, 57.0964
9.682110913, 96.390, 3274.0, 57.2189
9.734632044, 96.390, 3306.0, 57.4978
9.787153175, 96.390, 3238.0, 56.9034
9.839674305, 96.390, 3225.0, 56.7891
9.892195436, 96.390, 3162.0, 56.2317
9.944716567, 96.390, 3154.0, 56.1605
9.997237697, 96.390, 3128.0, 55.9285
10.049758828, 96.390, 3140.0, 56.0357
10.102279959, 96.390, 3045.0, 55.1815
10.154801090, 96.390, 3080.0, 55.4977
10.207322220, 96.390, 3086.0, 55.5518
10.259843351, 96.390, 3072.0, 55.4256
10.312364482, 96.390, 3092.0, 55.6058
10.364885612, 96.390, 3054.0, 55.2630
10.417406743, 96.390, 3133.0, 55.9732
10.469927874, 96.390, 2991.0, 54.6900
10.522449004, 96.390, 2962.0, 54.4243
10.574970135, 96.390, 3055.0, 55.2721
10.627491266, 96.390, 2987.0, 54.6535
10.680012397, 96.390, 2988.0, 54.6626
10.732533527, 96.390, 3004.0, 54.8088
10.785054658, 96.390, 2972.0, 54.5161
10.837575789, 96.390, 2943.0, 54.2494
10.890096919, 96.390, 2848.0, 53.3667
10.942618050, 96.390, 3019.0, 54.9454
10.995139181, 96.390, 2927.0, 54.1018
11.047660312, 96.390, 2924.0, 54.0740
11.100181442, 96.390, 2917.0, 54.0093
11.152702573, 96.390, 2915.0, 53.9907
11.205223704, 96.390, 2943.0, 54.2494
11.257744834, 96.390, 2793.0, 52.8488
11.310265965, 96.390, 2844.0, 53.3292
11.362787096, 96.390, 2815.0, 53.0566
11.415308227, 96.390, 2838.0, 53.2729
11.467829357, 96.390, 2830.0, 53.1977
11.520350488, 96.390, 2797.0, 52.8867
11.572871619, 96.390, 2804.0, 52.9528
11.625392749, 96.390, 2849.0, 53.3760
11.677913880, 96.390, 2805.0, 52.9623
11.730435011, 96.390, 2844.0, 53.3292
11.782956141, 96.390, 2834.0, 53.2353
11.835477272, 96.390, 2819.0, 53.0943
11.887998403, 96.390, 2756.0, 52.4976
11.940519534, 96.390, 2770.0, 52.6308
11.993040664, 96.390, 2765.0, 52.5833
12.045561795, 96.390, 2776.0, 52.6878
12.098082926, 96.390, 2802.0, 52.9339
12.150604056, 96.390, 2697.0, 51.9326
12.203125187, 96.390, 2670.0, 51.6720
12.255646318, 96.390, 2727.0, 52.2207
12.308167449, 96.390, 2722.0, 52.1728
12.360688579, 96.390, 2706.0, 52.0192
12.413209710, 96.390, 2722.0, 52.1728
12.465730841, 96.390, 2720.0, 52.1536
12.518251971, 96.390, 2702.0, 51.9808
12.570773102, 96.390, 2788.0, 52.8015
12.623294233, 96.390, 2716.0, 52.1153
12.675815364, 96.390, 2666.0, 51.6333
12.728336494, 96.390, 2716.0, 52.1153
12.780857625, 96.390, 2571.0, 50.7050
12.833378756, 96.390, 2558.0, 50.5767
12.885899886, 96.390, 2681.0, 51.7784
12.938421017, 96.390, 2687.0, 51.8363
12.990942148, 96.390, 2683.0, 51.7977
13.043463279, 96.390, 2608.0, 51.0686
13.095984409, 96.390, 2610.0, 51.0882
13.148505540, 96.390, 2612.0, 51.1077
13.201026671, 96.390, 2621.0, 51.1957
13.253547801, 96.390, 2720.0, 52.1536
13.306068932, 96.390, 2625.0, 51.2348
13.358590063, 96.390, 2535.0, 50.3488
13.411111193, 96.390, 2585.0, 50.8429
13.463632324, 96.390, 2591.0, 50.9019
13.516153455, 96.390, 2578.0, 50.7740
13.568674586, 96.390, 2513.0, 50.1298
13.621195716, 96.390, 2550.0, 50.4975
13.673716847, 96.390, 2591.0, 50.9019
13.726237978, 96.390, 2558.0, 50.5767
13.778759108, 96.390, 2463.0, 49.6286
13.831280239, 96.390, 2492.0, 49.9199
13.883801370, 96.390, 2497.0, 49.9700
13.936322501, 96.390, 2481.0, 49.8096
13.988843631, 96.390, 2491.0, 49.9099
14.041364762, 96.390, 2524.0, 50.2394
14.093885893, 96.390, 2471.0, 49.7092
14.146407023, 96.390, 2469.0, 49.6890
14.198928154, 96.390, 2528.0, 50.2792
14.251449285, 96.390, 2481.0, 49.8096
14.303970416, 96.390, 2542.0, 50.4183
14.356491546, 96.390, 2530.0, 50.2991
14.409012677, 96.390, 2505.0, 50.0500
14.461533808, 96.390, 2640.0, 51.3809
14.514054938, 96.390, 2680.0, 51.7687
14.566576069, 96.390, 2739.0, 52.3355
14.619097200, 96.390, 2863.0, 53.5070
14.671618331, 96.390, 2811.0, 53.0189
14.724139461, 96.390, 2770.0, 52.6308
14.776660592, 96.390, 2607.0, 51.0588
14.829181723, 96.390, 2633.0, 51.3128
14.881702853, 96.390, 2540.0, 50.3984
14.934223984, 96.390, 2525.0, 50.2494
14.986745115, 96.390, 2561.0, 50.6063
15.039266245, 96.390, 2474.0, 49.7393
15.091787376, 96.390, 2512.0, 50.1199
15.144308507, 96.390, 2625.0, 51.2348
15.196829638, 96.390, 2530.0, 50.2991
15.249350768, 96.390, 2494.0, 49.9400
15.301871899, 96.390, 2594.0, 50.9313
15.354393030, 96.390, 2565.0, 50.6458
15.406914160, 96.390, 2467.0, 49.6689
15.459435291, 96.390, 2476.0, 49.7594
15.511956422, 96.390, 2472.0, 49.7192
15.564477553, 96.390, 2429.0, 49.2849
15.616998683, 96.390, 2491.0, 49.9099
15.669519814, 96.390, 2484.0, 49.8397
15.722040945, 96.390, 2489.0, 49.8899
15.774562075, 96.390, 2528.0, 50.2792
15.827083206, 96.390, 2593.0, 50.9215
15.879604337, 96.390, 2484.0, 49.8397
15.932125468, 96.390, 2568.0, 50.6754
15.984646598, 96.390, 2530.0, 50.2991
16.037167729, 96.390, 2603.0, 51.0196
16.089688860, 96.390, 2534.0, 50.3389
16.142209990, 96.390, 2548.0, 50.4777
16.194731121, 96.390, 2646.0, 51.4393
16.247252252, 96.390, 2653.0, 51.5073
16.299773382, 96.390, 2783.0, 52.7541
16.352294513, 96.390, 2691.0, 51.8748
16.404815644, 96.390, 2748.0, 52.4214
16.457336775, 96.390, 2882.0, 53.6843
16.509857905, 96.390, 2847.0, 53.3573
16.562379036, 96.390, 2914.0, 53.9815
16.614900167, 96.390, 3029.0, 55.0364
16.667421297, 96.390, 2991.0, 54.6900
16.719942428, 96.390, 2984.0, 54.6260
16.772463559, 96.390, 3044.0, 55.1725
16.824984690, 96.390, 2973.0, 54.5252
16.877505820, 96.390, 3024.0, 54.9909
16.930026951, 96.390, 2961.0, 54.4151
16.982548082, 96.390, 2809.0, 53.0000
17.035069212, 96.390, 2892.0, 53.7773
17.087590343, 96.390, 2750.0, 52.4404
17.140111474, 96.390, 2856.0, 53.4416
17.192632605, 96.390, 2697.0, 51.9326
17.245153735, 96.390, 2621.0, 51.1957
17.297674866, 96.390, 2584.0, 50.8331
17.350195997, 96.390, 2569.0, 50.6853
17.402717127, 96.390, 2573.0, 50.7247
17.455238258, 96.390, 2512.0, 50.1199
17.507759389, 96.390, 2553.0, 50.5272
17.560280520, 96.390, 2548.0, 50.4777
17.612801650, 96.390, 2427.0, 49.2646
17.665322781, 96.390, 2504.0, 50.0400
17.717843912, 96.390, 2454.0, 49.5379
17.770365042, 96.390, 2459.0, 49.5883
17.822886173, 96.390, 2362.0, 48.6004
17.875407304, 96.390, 2408.0, 49.0714
17.927928434, 96.390, 2445.0, 49.4469
17.980449565, 96.390, 2418.0, 49.1732
18.032970696, 96.390, 2388.0, 48.8672
18.085491827, 96.390, 2414.0, 49.1325
18.138012957, 96.390, 2473.0, 49.7293
18.190534088, 96.390, 2423.0, 49.2240
18.243055219, 96.390, 2311.0, 48.0729
18.295576349, 96.390, 2398.0, 48.9694
18.348097480, 96.390, 2414.0, 49.1325
18.400618611, 96.390, 2397.0, 48.9592
18.453139742, 96.390, 2413.0, 49.1223
18.505660872, 96.390, 2408.0, 49.0714
18.558182003, 96.390, 2461.0, 49.6085
18.610703134, 96.390, 2318.0, 48.1456
18.663224264, 96.390, 2313.0, 48.0937
18.715745395, 96.390, 2366.0, 48.6415
18.768266526, 96.390, 2368.0, 48.6621
18.820787657, 96.390, 2416.0, 49.1528
18.873308787, 96.390, 2386.0, 48.8467
18.925829918, 96.390, 2448.0, 49.4773
18.978351049, 96.390, 2405.0, 49.0408
19.030872179, 96.390, 2439.0, 49.3862
19.083393310, 96.390, 2480.0, 49.7996
19.135914441, 96.390, 2531.0, 50.3090
19.188435572, 96.390, 2575.0, 50.7445
19.240956702, 96.390, 2567.0, 50.6656
19.293477833, 96.390, 2554.0, 50.5371
19.345998964, 96.390, 2438.0, 49.3761
19.398520094, 96.390, 2407.0, 49.0612
19.451041225, 96.390, 2517.0, 50.1697
19.503562356, 96.390, 2392.0, 48.9081
19.556083486, 96.390, 2413.0, 49.1223
19.608604617, 96.390, 2368.0, 48.6621
19.661125748, 96.390, 2443.0, 49.4267
19.713646879, 96.390, 2476.0, 49.7594
19.766168009, 96.390, 2556.0, 50.5569
19.818689140, 96.390, 2416.0, 49.1528
19.871210271, 96.390, 2583.0, 50.8232
19.923731401, 96.390, 2505.0, 50.0500
19.976252532, 96.390, 2583.0, 50.8232
20.028773663, 96.390, 2561.0, 50.6063
20.081294794, 96.390, 2626.0, 51.2445
20.133815924, 96.390, 2690.0, 51.8652
20.186337055, 96.390, 2641.0, 51.3907
20.238858186, 96.390, 2813.0, 53.0377
20.291379316, 96.390, 2829.0, 53.1883
20.343900447, 96.390, 2905.0, 53.8981
20.396421578, 96.390, 2977.0, 54.5619
20.448942709, 96.390, 2851.0, 53.3948
20.501463839, 96.390, 2951.0, 54.3231
20.553984970, 96.390, 2863.0, 53.5070
20.606506101, 96.390, 2901.0, 53.8609
20.659027231, 96.390, 2759.0, 52.5262
20.711548362, 96.390, 2808.0, 52.9906
20.764069493, 96.390, 2847.0, 53.3573
20.816590623, 96.390, 2816.0, 53.0660
20.869111754, 96.390, 2815.0, 53.0566
20.921632885, 96.390, 2795.0, 52.8678
20.974154016, 96.390, 2704.0, 52.0000
21.026675146, 96.390, 2732.0, 52.2685
21.079196277, 96.390, 2786.0, 52.7826
21.131717408, 96.390, 2796.0, 52.8772
21.184238538, 96.390, 2764.0, 52.5738
21.236759669, 96.390, 2873.0, 53.6004
21.289280800, 96.390, 2904.0, 53.8888
21.341801931, 96.390, 2959.0, 54.3967
21.394323061, 96.390, 3000.0, 54.7723
21.446844192, 96.390, 3029.0, 55.0364
21.499365323, 96.390, 3063.0, 55.3444
21.551886453, 96.390, 3013.0, 54.8908
21.604407584, 96.390, 2947.0, 54.2863
21.656928715, 96.390, 2864.0, 53.5164
21.709449846, 96.390, 2829.0, 53.1883
21.761970976, 96.390, 2706.0, 52.0192
21.814492107, 96.390, 2738.0, 52.3259
21.867013238, 96.390, 2649.0, 51.4684
21.919534368, 96.390, 2897.0, 53.8238
21.972055499, 96.390, 2746.0, 52.4023
22.024576630, 96.390, 2742.0, 52.3641
22.077097761, 96.390, 2733.0, 52.2781
22.129618891, 96.390, 2810.0, 53.0094
22.182140022, 96.390, 2832.0, 53.2165
22.234661153, 96.390, 2782.0, 52.7447
22.287182283, 96.390, 2741.0, 52.3546
22.339703414, 96.390, 2711.0, 52.0673
22.392224545, 96.390, 2725.0, 52.2015
22.444745675, 96.390, 2601.0, 51.0000
22.497266806, 96.390, 2641.0, 51.3907
22.549787937, 96.390, 2708.0, 52.0384
22.602309068, 96.390, 2711.0, 52.0673
22.654830198, 96.390, 2627.0, 51.2543
22.707351329, 96.390, 2588.0, 50.8724
22.759872460, 96.390, 2606.0, 51.0490
22.812393590, 96.390, 2625.0, 51.2348
22.864914721, 96.390, 2630.0, 51.2835
22.917435852, 96.390, 2673.0, 51.7011
22.969956983, 96.390, 2613.0, 51.1175
23.022478113, 96.390, 2591.0, 50.9019
23.074999244, 96.390, 2612.0, 51.1077
23.127520375, 96.390, 2515.0, 50.1498
23.180041505, 96.390, 2622.0, 51.2055
23.232562636, 96.390, 2552.0, 50.5173
23.285083767, 96.390, 2613.0, 51.1175
23.337604898, 96.390, 2537.0, 50.3686
23.390126028, 96.390, 2539.0, 50.3885
23.442647159, 96.390, 2539.0, 50.3885
23.495168290, 96.390, 2684.0, 51.8073
23.547689420, 96.390, 2632.0, 51.3030
23.600210551, 96.390, 2567.0, 50.6656
23.652731682, 96.390, 2618.0, 51.1664
23.705252813, 96.390, 2650.0, 51.4782
23.757773943, 96.390, 2467.0, 49.6689
23.810295074, 96.390, 2523.0, 50.2295
23.862816205, 96.390, 2477.0, 49.7695
23.915337335, 96.390, 2605.0, 51.0392
23.967858466, 96.390, 2446.0, 49.4571
24.020379597, 96.390, 2452.0, 49.5177
24.072900727, 96.390, 2518.0, 50.1797
24.125421858, 96.390, 2360.0, 48.5798
24.177942989, 96.390, 2507.0, 50.0700
24.230464120, 96.390, 2346.0, 48.4355
24.282985250, 96.390, 2380.0, 48.7852
24.335506381, 96.390, 2396.0, 48.9490
24.388027512, 96.390, 2427.0, 49.2646
24.440548642, 96.390, 2512.0, 50.1199
24.493069773, 96.390, 2411.0, 49.1019
24.545590904, 96.390, 2489.0, 49.8899
24.598112035, 96.390, 2440.0, 49.3964
24.650633165, 96.390, 2432.0, 49.3153
24.703154296, 96.390, 2511.0, 50.1099
24.755675427, 96.390, 2573.0, 50.7247
24.808196557, 96.390, 2559.0, 50.5866
24.860717688, 96.390, 2426.0, 49.2544
24.913238819, 96.390, 2613.0, 51.1175
24.965759950, 96.390, 2535.0, 50.3488
25.018281080, 96.390, 2566.0, 50.6557
25.070802211, 96.390, 2559.0, 50.5866
25.123323342, 96.390, 2547.0, 50.4678
25.175844472, 96.390, 2504.0, 50.0400
25.228365603, 96.390, 2556.0, 50.5569
25.280886734, 96.390, 2493.0, 49.9300
25.333407864, 96.390, 2376.0, 48.7442
25.385928995, 96.390, 2397.0, 48.9592
25.438450126, 96.390, 2479.0, 49.7896
25.490971257, 96.390, 2455.0, 49.5480
25.543492387, 96.390, 2423.0, 49.2240
25.596013518, 96.390, 2448.0, 49.4773
25.648534649, 96.390, 2380.0, 48.7852
25.701055779, 96.390, 2381.0, 48.7955
25.753576910, 96.390, 2328.0, 48.2494
25.806098041, 96.390, 2432.0, 49.3153
25.858619172, 96.390, 2396.0, 48.9490
25.911140302, 96.390, 2351.0, 48.4871
25.963661433, 96.390, 2385.0, 48.8365
26.016182564, 96.390, 2305.0, 48.0104
26.068703694, 96.390, 2224.0, 47.1593
26.121224825, 96.390, 2356.0, 48.5386
26.173745956, 96.390, 2297.0, 47.9270
26.226267087, 96.390, 2297.0, 47.9270
26.278788217, 96.390, 2266.0, 47.6025
26.331309348, 96.390, 2319.0, 48.1560
26.383830479, 96.390, 2423.0, 49.2240
26.436351609, 96.390, 2363.0, 48.6107
26.488872740, 96.390, 2322.0, 48.1871
26.541393871, 96.390, 2476.0, 49.7594
26.593915002, 96.390, 2355.0, 48.5283
26.646436132, 96.390, 2407.0, 49.0612
26.698957263, 96.390, 2409.0, 49.0816
26.751478394, 96.390, 2357.0, 48.5489
26.803999524, 96.390, 2452.0, 49.5177
26.856520655, 96.390, 2444.0, 49.4368
26.909041786, 96.390, 2500.0, 50.0000
26.961562916, 96.390, 2510.0, 50.0999
27.014084047, 96.390, 2481.0, 49.8096
27.066605178, 96.390, 2529.0, 50.2892
27.119126309, 96.390, 2462.0, 49.6185
27.171647439, 96.390, 2539.0, 50.3885
27.224168570, 96.390, 2551.0, 50.5074
27.276689701, 96.390, 2642.0, 51.4004
27.329210831, 96.390, 2599.0, 50.9804
27.381731962, 96.390, 2596.0, 50.9510
27.434253093, 96.390, 2581.0, 50.8035
27.486774224, 96.390, 2668.0, 51.6527
27.539295354, 96.390, 2643.0, 51.4101
27.591816485, 96.390, 2753.0, 52.4690
27.644337616, 96.390, 2792.0, 52.8394
27.696858746, 96.390, 2681.0, 51.7784
27.749379877, 96.390, 2684.0, 51.8073
27.801901008, 96.390, 2780.0, 52.7257
27.854422139, 96.390, 2743.0, 52.3737
27.906943269, 96.390, 2713.0, 52.0865
27.959464400, 96.390, 2694.0, 51.9038
28.011985531, 96.390, 2636.0, 51.3420
28.064506661, 96.390, 2615.0, 51.1371
28.117027792, 96.390, 2622.0, 51.2055
28.169548923, 96.390, 2610.0, 51.0882
28.222070054, 96.390, 2707.0, 52.0288
28.274591184, 96.390, 2725.0, 52.2015
28.327112315, 96.390, 2631.0, 51.2933
28.379633446, 96.390, 2520.0, 50.1996
28.432154576, 96.390, 2582.0, 50.8134
28.484675707, 96.390, 2674.0, 51.7107
28.537196838, 96.390, 2569.0, 50.6853
28.589717968, 96.390, 2670.0, 51.6720
28.642239099, 96.390, 2477.0, 49.7695
28.694760230, 96.390, 2685.0, 51.8170
28.747281361, 96.390, 2551.0, 50.5074
28.799802491, 96.390, 2550.0, 50.4975
28.852323622, 96.390, 2737.0, 52.3163
28.904844753, 96.390, 2631.0, 51.2933
28.957365883, 96.390, 2665.0, 51.6236
29.009887014, 96.390, 2655.0, 51.5267
29.062408145, 96.390, 2704.0, 52.0000
29.114929276, 96.390, 2723.0, 52.1824
29.167450406, 96.390, 2673.0, 51.7011
29.219971537, 96.390, 2660.0, 51.5752
29.272492668, 96.390, 2779.0, 52.7162
29.325013798, 96.390, 2733.0, 52.2781
29.377534929, 96.390, 2849.0, 53.3760
29.430056060, 96.390, 2843.0, 53.3198
29.482577191, 96.390, 2755.0, 52.4881
29.535098321, 96.390, 2849.0, 53.3760
29.587619452, 96.390, 2747.0, 52.4118
29.640140583, 96.390, 2786.0, 52.7826
29.692661713, 96.390, 2578.0, 50.7740
29.745182844, 96.390, 2547.0, 50.4678
29.797703975, 96.390, 2628.0, 51.2640
29.850225105, 96.390, 2571.0, 50.7050
29.902746236, 96.390, 2587.0, 50.8626
29.955267367, 96.390, 2687.0, 51.8363
30.007788498, 96.390, 2668.0, 51.6527
30.060309628, 96.390, 2654.0, 51.5170
30.112830759, 96.390, 2703.0, 51.9904
30.165351890, 96.390, 2646.0, 51.4393
30.217873020, 96.390, 2747.0, 52.4118
30.270394151, 96.390, 2730.0, 52.2494
30.322915282, 96.390, 2701.0, 51.9711
30.375436413, 96.390, 2741.0, 52.3546
30.427957543, 96.390, 2859.0, 53.4696
30.480478674, 96.390, 2909.0, 53.9351
30.532999805, 96.390, 2832.0, 53.2165
30.585520935, 96.390, 2913.0, 53.9722
30.638042066, 96.390, 2789.0, 52.8110
30.690563197, 96.390, 2717.0, 52.1249
30.743084328, 96.390, 2663.0, 51.6043
30.795605458, 96.390, 2701.0, 51.9711
30.848126589, 96.390, 2719.0, 52.1440
30.900647720, 96.390, 2661.0, 51.5849
30.953168850, 96.390, 2558.0, 50.5767
31.005689981, 96.390, 2583.0, 50.8232
31.058211112, 96.390, 2635.0, 51.3323
31.110732243, 96.390, 2476.0, 49.7594
31.163253373, 96.390, 2503.0, 50.0300
31.215774504, 96.390, 2464.0, 49.6387
31.268295635, 96.390, 2383.0, 48.8160
31.320816765, 96.390, 2394.0, 48.9285
31.373337896, 96.390, 2334.0, 48.3115
31.425859027, 96.390, 2347.0, 48.4458
31.478380157, 96.390, 2284.0, 47.7912
31.530901288, 96.390, 2398.0, 48.9694
31.583422419, 96.390, 2245.0, 47.3814
31.635943550, 96.390, 2311.0, 48.0729
31.688464680, 96.390, 2300.0, 47.9583
31.740985811, 96.390, 2301.0, 47.9687
31.793506942, 96.390, 2310.0, 48.0625
31.846028072, 96.390, 2119.0, 46.0326
31.898549203, 96.390, 2263.0, 47.5710
31.951070334, 96.390, 2254.0, 47.4763
32.003591465, 96.390, 2201.0, 46.9148
32.056112595, 96.390, 2196.0, 46.8615
32.108633726, 96.390, 2205.0, 46.9574
32.161154857, 96.390, 2167.0, 46.5510
32.213675987, 96.390, 2130.0, 46.1519
32.266197118, 96.390, 2214.0, 47.0532
32.318718249, 96.390, 2129.0, 46.1411
32.371239380, 96.390, 2147.0, 46.3357
32.423760510, 96.390, 2032.0, 45.0777
32.476281641, 96.390, 2115.0, 45.9891
32.528802772, 96.390, 2144.0, 46.3033
32.581323902, 96.390, 2102.0, 45.8476
32.633845033, 96.390, 2113.0, 45.9674
32.686366164, 96.390, 2149.0, 46.3573
32.738887295, 96.390, 2208.0, 46.9894
32.791408425, 96.390, 2102.0, 45.8476
32.843929556, 96.390, 1990.0, 44.6094
32.896450687, 96.390, 2090.0, 45.7165
32.948971817, 96.390, 2125.0, 46.0977
33.001492948, 96.390, 2128.0, 46.1303
33.054014079, 96.390, 2176.0, 46.6476
33.106535209, 96.390, 2048.0, 45.2548
33.159056340, 96.390, 2127.0, 46.1194
33.211577471, 96.390, 2109.0, 45.9239
33.264098602, 96.390, 2093.0, 45.7493
33.316619732, 96.390, 2013.0, 44.8665
33.369140863, 96.390, 2078.0, 45.5851
33.421661994, 96.390, 2147.0, 46.3357
33.474183124, 96.390, 2059.0, 45.3762
33.526704255, 96.390, 2143.0, 46.2925
33.579225386, 96.390, 2027.0, 45.0222
33.631746517, 96.390, 2091.0, 45.7275
33.684267647, 96.390, 2101.0, 45.8367
33.736788778, 96.390, 2015.0, 44.8888
33.789309909, 96.390, 2061.0, 45.3982
33.841831039, 96.390, 1990.0, 44.6094
33.894352170, 96.390, 1981.0, 44.5084
33.946873301, 96.390, 2052.0, 45.2990
33.999394432, 96.390, 1891.0, 43.4856
34.051915562, 96.390, 2020.0, 44.9444
34.104436693, 96.390, 1958.0, 44.2493
34.156957824, 96.390, 1991.0, 44.6206
34.209478954, 96.390, 1931.0, 43.9431
34.262000085, 96.390, 1853.0, 43.0465
34.314521216, 96.390, 1917.0, 43.7836
34.367042346, 96.390, 1874.0, 43.2897
34.419563477, 96.390, 1877.0, 43.3244
34.472084608, 96.390, 1873.0, 43.2782
34.524605739, 96.390, 1855.0, 43.0697
34.577126869, 96.390, 1845.0, 42.9535
34.629648000, 96.390, 1823.0, 42.6966
34.682169131, 96.390, 1735.0, 41.6533
34.734690261, 96.390, 1761.0, 41.9643
34.787211392, 96.390, 1830.0, 42.7785
34.839732523, 96.390, 1714.0, 41.4005
34.892253654, 96.390, 1787.0, 42.2729
34.944774784, 96.390, 1777.0, 42.1545
34.997295915, 96.390, 1694.0, 41.1582
35.049817046, 96.390, 1724.0, 41.5211
35.102338176, 96.390, 1751.0, 41.8450
35.154859307, 96.390, 1783.0, 42.2256
35.207380438, 96.390, 1707.0, 41.3159
35.259901569, 96.390, 1752.0, 41.8569
35.312422699, 96.390, 1679.0, 40.9756
35.364943830, 96.390, 1778.0, 42.1663
35.417464961, 96.390, 1744.0, 41.7612
35.469986091, 96.390, 1730.0, 41.5933
35.522507222, 96.390, 1618.0, 40.2244
35.575028353, 96.390, 1702.0, 41.2553
35.627549484, 96.390, 1711.0, 41.3642
35.680070614, 96.390, 1686.0, 41.0609
35.732591745, 96.390, 1715.0, 41.4126
35.785112876, 96.390, 1660.0, 40.7431
35.837634006, 96.390, 1665.0, 40.8044
35.890155137, 96.390, 1670.0, 40.8656
35.942676268, 96.390, 1648.0, 40.5956
35.995197398, 96.390, 1591.0, 39.8873
36.047718529, 96.390, 1517.0, 38.9487
36.100239660, 96.390, 1591.0, 39.8873
36.152760791, 96.390, 1510.0, 38.8587
36.205281921, 96.390, 1514.0, 38.9102
36.257803052, 96.390, 1499.0, 38.7169
36.310324183, 96.390, 1451.0, 38.0920
36.362845313, 96.390, 1529.0, 39.1024
36.415366444, 96.390, 1483.0, 38.5097
36.467887575, 96.390, 1562.0, 39.5221
36.520408706, 96.390, 1503.0, 38.7685
36.572929836, 96.390, 1488.0, 38.5746
36.625450967, 96.390, 1474.0, 38.3927
36.677972098, 96.390, 1573.0, 39.6611
36.730493228, 96.390, 1600.0, 40.0000
36.783014359, 96.390, 1477.0, 38.4318
36.835535490, 96.390, 1555.0, 39.4335
36.888056621, 96.390, 1498.0, 38.7040
36.940577751, 96.390, 1475.0, 38.4057
36.993098882, 96.390, 1423.0, 37.7227
37.045620013, 96.390, 1426.0, 37.7624
37.098141143, 96.390, 1325.0, 36.4005
37.150662274, 96.390, 1415.0, 37.6165
37.203183405, 96.390, 1316.0, 36.2767
37.255704535, 96.390, 1334.0, 36.5240
37.308225666, 96.390, 1373.0, 37.0540
37.360746797, 96.390, 1364.0, 36.9324
37.413267928, 96.390, 1375.0, 37.0810
37.465789058, 96.390, 1332.0, 36.4966
37.518310189, 96.390, 1316.0, 36.2767
37.570831320, 96.390, 1188.0, 34.4674
37.623352450, 96.390, 1278.0, 35.7491
37.675873581, 96.390, 1340.0, 36.6060
37.728394712, 96.390, 1294.0, 35.9722
37.780915843, 96.390, 1367.0, 36.9730
37.833436973, 96.390, 1422.0, 37.7094
37.885958104, 96.390, 1322.0, 36.3593
37.938479235, 96.390, 1303.0, 36.0971
37.991000365, 96.390, 1307.0, 36.1525
38.043521496, 96.390, 1368.0, 36.9865
38.096042627, 96.390, 1407.0, 37.5100
38.148563758, 96.390, 1254.0, 35.4119
38.201084888, 96.390, 1349.0, 36.7287
38.253606019, 96.390, 1318.0, 36.3043
38.306127150, 96.390, 1332.0, 36.4966
38.358648280, 96.390, 1392.0, 37.3095
38.411169411, 96.390, 1347.0, 36.7015
38.463690542, 96.390, 1398.0, 37.3898
38.516211673, 96.390, 1395.0, 37.3497
38.568732803, 96.390, 1356.0, 36.8239
38.621253934, 96.390, 1477.0, 38.4318
38.673775065, 96.390, 1482.0, 38.4968
38.726296195, 96.390, 1556.0, 39.4462
38.778817326, 96.390, 1475.0, 38.4057
38.831338457, 96.390, 1569.0, 39.6106
38.883859587, 96.390, 1572.0, 39.6485
38.936380718, 96.390, 1517.0, 38.9487
38.988901849, 96.390, 1478.0, 38.4448
39.041422980, 96.390, 1455.0, 38.1445
39.093944110, 96.390, 1421.0, 37.6962
39.146465241, 96.390, 1382.0, 37.1753
39.198986372, 96.390, 1384.0, 37.2022
39.251507502, 96.390, 1349.0, 36.7287
39.304028633, 96.390, 1342.0, 36.6333
39.356549764, 96.390, 1325.0, 36.4005
39.409070895, 96.390, 1340.0, 36.6060
39.461592025, 96.390, 1334.0, 36.5240
39.514113156, 96.390, 1307.0, 36.1525
39.566634287, 96.390, 1356.0, 36.8239
39.619155417, 96.390, 1323.0, 36.3731
39.671676548, 96.390, 1293.0, 35.9583
39.724197679, 96.390, 1336.0, 36.5513
39.776718810, 96.390, 1379.0, 37.1349
39.829239940, 96.390, 1399.0, 37.4032
39.881761071, 96.390, 1283.0, 35.8190
39.934282202, 96.390, 1293.0, 35.9583
39.986803332, 96.390, 1319.0, 36.3180
40.039324463, 96.390, 1308.0, 36.1663
40.091845594, 96.390, 1373.0, 37.0540
40.144366725, 96.390, 1334.0, 36.5240
40.196887855, 96.390, 1295.0, 35.9861
40.249408986, 96.390, 1309.0, 36.1801
40.301930117, 96.390, 1271.0, 35.6511
40.354451247, 96.390, 1245.0, 35.2846
40.406972378, 96.390, 1243.0, 35.2562
40.459493509, 96.390, 1255.0, 35.4260
40.512014639, 96.390, 1217.0, 34.8855
40.564535770, 96.390, 1137.0, 33.7194
40.617056901, 96.390, 1203.0, 34.6843
40.669578032, 96.390, 1210.0, 34.7851
40.722099162, 96.390, 1265.0, 35.5668
40.774620293, 96.390, 1203.0, 34.6843
40.827141424, 96.390, 1184.0, 34.4093
40.879662554, 96.390, 1135.0, 33.6898
40.932183685, 96.390, 1183.0, 34.3948
40.984704816, 96.390, 1105.0, 33.2415
41.037225947, 96.390, 1163.0, 34.1028
41.089747077, 96.390, 1241.0, 35.2278
41.142268208, 96.390, 1153.0, 33.9559
41.194789339, 96.390, 1179.0, 34.3366
41.247310469, 96.390, 1181.0, 34.3657
41.299831600, 96.390, 1215.0, 34.8569
41.352352731, 96.390, 1199.0, 34.6266
41.404873862, 96.390, 1192.0, 34.5254
41.457394992, 96.390, 1139.0, 33.7491
41.509916123, 96.390, 1125.0, 33.5410
41.562437254, 96.390, 1170.0, 34.2053
41.614958384, 96.390, 1130.0, 33.6155
41.667479515, 96.390, 1067.0, 32.6650
41.720000646, 96.390, 1079.0, 32.8481
41.772521776, 96.390, 1140.0, 33.7639
41.825042907, 96.390, 1163.0, 34.1028
41.877564038, 96.390, 1057.0, 32.5115
41.930085169, 96.390, 1092.0, 33.0454
41.982606299, 96.390, 1122.0, 33.4963
42.035127430, 96.390, 1072.0, 32.7414
42.087648561, 96.390, 1098.0, 33.1361
42.140169691, 96.390, 1146.0, 33.8526
42.192690822, 96.390, 1100.0, 33.1662
42.245211953, 96.390, 1140.0, 33.7639
42.297733084, 96.390, 1060.0, 32.5576
42.350254214, 96.390, 1062.0, 32.5883
42.402775345, 96.390, 1080.0, 32.8634
42.455296476, 96.390, 1101.0, 33.1813
42.507817606, 96.390, 1157.0, 34.0147
42.560338737, 96.390, 1067.0, 32.6650
42.612859868, 96.390, 1111.0, 33.3317
42.665380999, 96.390, 1090.0, 33.0151
42.717902129, 96.390, 1092.0, 33.0454
42.770423260, 96.390, 1118.0, 33.4365
42.822944391, 96.390, 1105.0, 33.2415
42.875465521, 96.390, 1095.0, 33.0908
42.927986652, 96.390, 1057.0, 32.5115
42.980507783, 96.390, 1149.0, 33.8969
43.033028914, 96.390, 1035.0, 32.1714
43.085550044, 96.390, 1124.0, 33.5261
43.138071175, 96.390, 1100.0, 33.1662
43.190592306, 96.390, 1107.0, 33.2716
43.243113436, 96.390, 1100.0, 33.1662
43.295634567, 96.390, 1026.0, 32.0312
43.348155698, 96.390, 1081.0, 32.8786
43.400676828, 96.390, 1106.0, 33.2566
43.453197959, 96.390, 1084.0, 32.9242
43.505719090, 96.390, 1115.0, 33.3916
43.558240221, 96.390, 1025.0, 32.0156
43.610761351, 96.390, 1075.0, 32.7872
43.663282482, 96.390, 1088.0, 32.9848
43.715803613, 96.390, 1152.0, 33.9411
43.768324743, 96.390, 1073.0, 32.7567
43.820845874, 96.390, 1114.0, 33.3766
43.873367005, 96.390, 1098.0, 33.1361
43.925888136, 96.390, 1084.0, 32.9242
43.978409266, 96.390, 1082.0, 32.8938
44.030930397, 96.390, 1139.0, 33.7491
44.083451528, 96.390, 1126.0, 33.5559
44.135972658, 96.390, 1097.0, 33.1210
44.188493789, 96.390, 1114.0, 33.3766
44.241014920, 96.390, 1116.0, 33.4066
44.293536051, 96.390, 1149.0, 33.8969
44.346057181, 96.390, 1131.0, 33.6303
44.398578312, 96.390, 1138.0, 33.7343
44.451099443, 96.390, 1074.0, 32.7719
44.503620573, 96.390, 1205.0, 34.7131
44.556141704, 96.390, 1150.0, 33.9116
44.608662835, 96.390, 1135.0, 33.6898
44.661183966, 96.390, 1132.0, 33.6452
44.713705096, 96.390, 1218.0, 34.8999
44.766226227, 96.390, 1200.0, 34.6410
44.818747358, 96.390, 1163.0, 34.1028
44.871268488, 96.390, 1143.0, 33.8083
44.923789619, 96.390, 1175.0, 34.2783
44.976310750, 96.390, 1166.0, 34.1467
45.028831880, 96.390, 1174.0, 34.2637
45.081353011, 96.390, 1085.0, 32.9393
45.133874142, 96.390, 1129.0, 33.6006
45.186395273, 96.390, 1127.0, 33.5708
45.238916403, 96.390, 1127.0, 33.5708
45.291437534, 96.390, 1121.0, 33.4813
45.343958665, 96.390, 1128.0, 33.5857
45.396479795, 96.390, 1105.0, 33.2415
45.449000926, 96.390, 1051.0, 32.4191
45.501522057, 96.390, 1135.0, 33.6898
45.554043188, 96.390, 1088.0, 32.9848
45.606564318, 96.390, 1105.0, 33.2415
45.659085449, 96.390, 1070.0, 32.7109
45.711606580, 96.390, 1087.0, 32.9697
45.764127710, 96.390, 1110.0, 33.3167
45.816648841, 96.390, 1093.0, 33.0606
45.869169972, 96.390, 1086.0, 32.9545
45.921691103, 96.390, 1164.0, 34.1174
45.974212233, 96.390, 1090.0, 33.0151
46.026733364, 96.390, 1099.0, 33.1512
46.079254495, 96.390, 1136.0, 33.7046
46.131775625, 96.390, 1099.0, 33.1512
46.184296756, 96.390, 1153.0, 33.9559
46.236817887, 96.390, 1054.0, 32.4654
46.289339017, 96.390, 1051.0, 32.4191
46.341860148, 96.390, 1050.0, 32.4037
46.394381279, 96.390, 1104.0, 33.2265
46.446902410, 96.390, 1089.0, 33.0000
46.499423540, 96.390, 1033.0, 32.1403
46.551944671, 96.390, 1059.0, 32.5423
46.604465802, 96.390, 1069.0, 32.6956
46.656986932, 96.390, 1061.0, 32.5730
46.709508063, 96.390, 1106.0, 33.2566
46.762029194, 96.390, 1040.0, 32.2490
46.814550325, 96.390, 1009.0, 31.7648
46.867071455, 96.390, 965.0, 31.0644
46.919592586, 96.390, 1073.0, 32.7567
46.972113717, 96.390, 1012.0, 31.8119
47.024634847, 96.390, 1036.0, 32.1870
47.077155978, 96.390, 1023.0, 31.9844
47.129677109, 96.390, 1012.0, 31.8119
47.182198240, 96.390, 1068.0, 32.6803
47.234719370, 96.390, 1061.0, 32.5730
47.287240501, 96.390, 1040.0, 32.2490
47.339761632, 96.390, 987.0, 31.4166
47.392282762, 96.390, 1011.0, 31.7962
47.444803893, 96.390, 1039.0, 32.2335
47.497325024, 96.390, 1021.0, 31.9531
47.549846155, 96.390, 1025.0, 32.0156
47.602367285, 96.390, 990.0, 31.4643
47.654888416, 96.390, 1073.0, 32.7567
47.707409547, 96.390, 1081.0, 32.8786
47.759930677, 96.390, 1051.0, 32.4191
47.812451808, 96.390, 1008.0, 31.7490
47.864972939, 96.390, 1026.0, 32.0312
47.917494069, 96.390, 1029.0, 32.0780
47.970015200, 96.390, 1055.0, 32.4808
48.022536331, 96.390, 1044.0, 32.3110
48.075057462, 96.390, 1046.0, 32.3419
48.127578592, 96.390, 1005.0, 31.7017
48.180099723, 96.390, 1050.0, 32.4037
48.232620854, 96.390, 978.0, 31.2730
48.285141984, 96.390, 953.0, 30.8707
48.337663115, 96.390, 1006.0, 31.7175
48.390184246, 96.390, 1016.0, 31.8748
48.442705377, 96.390, 980.0, 31.3050
48.495226507, 96.390, 1024.0, 32.0000
48.547747638, 96.390, 963.0, 31.0322
48.600268769, 96.390, 920.0, 30.3315
48.652789899, 96.390, 977.0, 31.2570
48.705311030, 96.390, 943.0, 30.7083
48.757832161, 96.390, 963.0, 31.0322
48.810353292, 96.390, 934.0, 30.5614
48.862874422, 96.390, 919.0, 30.3150
48.915395553, 96.390, 886.0, 29.7658
48.967916684, 96.390, 921.0, 30.3480
49.020437814, 96.390, 972.0, 31.1769
49.072958945, 96.390, 917.0, 30.2820
49.125480076, 96.390, 916.0, 30.2655
49.178001207, 96.390, 889.0, 29.8161
49.230522337, 96.390, 896.0, 29.9333
49.283043468, 96.390, 933.0, 30.5450
49.335564599, 96.390, 924.0, 30.3974
49.388085729, 96.390, 916.0, 30.2655
49.440606860, 96.390, 914.0, 30.2324
49.493127991, 96.390, 989.0, 31.4484
49.545649121, 96.390, 918.0, 30.2985
49.598170252, 96.390, 922.0, 30.3645
49.650691383, 96.390, 964.0, 31.0483
49.703212514, 96.390, 952.0, 30.8545
49.755733644, 96.390, 974.0, 31.2090
49.808254775, 96.390, 956.0, 30.9192
49.860775906, 96.390, 943.0, 30.7083
49.913297036, 96.390, 906.0, 30.0998
49.965818167, 96.390, 972.0, 31.1769
50.018339298, 96.390, 906.0, 30.0998
50.070860429, 96.390, 884.0, 29.7321
50.123381559, 96.390, 943.0, 30.7083
50.175902690, 96.390, 894.0, 29.8998
50.228423821, 96.390, 922.0, 30.3645
50.280944951, 96.390, 928.0, 30.4631
50.333466082, 96.390, 902.0, 30.0333
50.385987213, 96.390, 883.0, 29.7153
50.438508344, 96.390, 906.0, 30.0998
50.491029474, 96.390, 860.0, 29.3258
50.543550605, 96.390, 909.0, 30.1496
50.596071736, 96.390, 894.0, 29.8998
50.648592866, 96.390, 886.0, 29.7658
50.701113997, 96.390, 890.0, 29.8329
50.753635128, 96.390, 871.0, 29.5127
50.806156258, 96.390, 898.0, 29.9666
50.858677389, 96.390, 878.0, 29.6311
50.911198520, 96.390, 823.0, 28.6880
50.963719651, 96.390, 921.0, 30.3480
51.016240781, 96.390, 944.0, 30.7246
51.068761912, 96.390, 892.0, 29.8664
51.121283043, 96.390, 922.0, 30.3645
51.173804173, 96.390, 896.0, 29.9333
51.226325304, 96.390, 883.0, 29.7153
51.278846435, 96.390, 867.0, 29.4449
51.331367566, 96.390, 875.0, 29.5804
51.383888696, 96.390, 892.0, 29.8664
51.436409827, 96.390, 833.0, 28.8617
51.488930958, 96.390, 884.0, 29.7321
51.541452088, 96.390, 869.0, 29.4788
51.593973219, 96.390, 841.0, 29.0000
51.646494350, 96.390, 836.0, 28.9137
51.699015481, 96.390, 854.0, 29.2233
51.751536611, 96.390, 911.0, 30.1828
51.804057742, 96.390, 849.0, 29.1376
51.856578873, 96.390, 830.0, 28.8097
51.909100003, 96.390, 864.0, 29.3939
51.961621134, 96.390, 882.0, 29.6985
52.014142265, 96.390, 940.0, 30.6594
52.066663396, 96.390, 857.0, 29.2746
52.119184526, 96.390, 899.0, 29.9833
52.171705657, 96.390, 854.0, 29.2233
52.224226788, 96.390, 841.0, 29.0000
52.276747918, 96.390, 873.0, 29.5466
52.329269049, 96.390, 880.0, 29.6648
52.381790180, 96.390, 860.0, 29.3258
52.434311310, 96.390, 916.0, 30.2655
52.486832441, 96.390, 839.0, 28.9655
52.539353572, 96.390, 863.0, 29.3769
52.591874703, 96.390, 779.0, 27.9106
52.644395833, 96.390, 844.0, 29.0517
52.696916964, 96.390, 819.0, 28.6182
52.749438095, 96.390, 821.0, 28.6531
52.801959225, 96.390, 852.0, 29.1890
52.854480356, 96.390, 822.0, 28.6705
52.907001487, 96.390, 824.0, 28.7054
52.959522618, 96.390, 874.0, 29.5635
53.012043748, 96.390, 866.0, 29.4279
53.064564879, 96.390, 814.0, 28.5307
53.117086010, 96.390, 786.0, 28.0357
53.169607140, 96.390, 853.0, 29.2062
53.222128271, 96.390, 881.0, 29.6816
53.274649402, 96.390, 828.0, 28.7750
53.327170533, 96.390, 874.0, 29.5635
53.379691663, 96.390, 815.0, 28.5482
53.432212794, 96.390, 803.0, 28.3373
53.484733925, 96.390, 813.0, 28.5132
53.537255055, 96.390, 831.0, 28.8271
53.589776186, 96.390, 852.0, 29.1890
53.642297317, 96.390, 855.0, 29.2404
53.694818448, 96.390, 830.0, 28.8097
53.747339578, 96.390, 792.0, 28.1425
53.799860709, 96.390, 858.0, 29.2916
53.852381840, 96.390, 895.0, 29.9166
53.904902970, 96.390, 825.0, 28.7228
53.957424101, 96.390, 836.0, 28.9137
54.009945232, 96.390, 866.0, 29.4279
54.062466362, 96.390, 836.0, 28.9137
54.114987493, 96.390, 873.0, 29.5466
54.167508624, 96.390, 848.0, 29.1204
54.220029755, 96.390, 837.0, 28.9310
54.272550885, 96.390, 829.0, 28.7924
54.325072016, 96.390, 878.0, 29.6311
54.377593147, 96.390, 856.0, 29.2575
54.430114277, 96.390, 863.0, 29.3769
54.482635408, 96.390, 853.0, 29.2062
54.535156539, 96.390, 823.0, 28.6880
54.587677670, 96.390, 813.0, 28.5132
54.640198800, 96.390, 836.0, 28.9137
54.692719931, 96.390, 878.0, 29.6311
54.745241062, 96.390, 876.0, 29.5973
54.797762192, 96.390, 894.0, 29.8998
54.850283323, 96.390, 887.0, 29.7825
54.902804454, 96.390, 857.0, 29.2746
54.955325585, 96.390, 878.0, 29.6311
55.007846715, 96.390, 844.0, 29.0517
55.060367846, 96.390, 854.0, 29.2233
55.112888977, 96.390, 898.0, 29.9666
55.165410107, 96.390, 902.0, 30.0333
55.217931238, 96.390, 841.0, 29.0000
55.270452369, 96.390, 878.0, 29.6311
55.322973499, 96.390, 848.0, 29.1204
55.375494630, 96.390, 833.0, 28.8617
55.428015761, 96.390, 839.0, 28.9655
55.480536892, 96.390, 818.0, 28.6007
55.533058022, 96.390, 862.0, 29.3598
55.585579153, 96.390, 899.0, 29.9833
55.638100284, 96.390, 832.0, 28.8444
55.690621414, 96.390, 856.0, 29.2575
55.743142545, 96.390, 810.0, 28.4605
55.795663676, 96.390, 797.0, 28.2312
55.848184807, 96.390, 892.0, 29.8664
55.900705937, 96.390, 842.0, 29.0172
55.953227068, 96.390, 838.0, 28.9482
56.005748199, 96.390, 821.0, 28.6531
56.058269329, 96.390, 829.0, 28.7924
56.110790460, 96.390, 793.0, 28.1603
56.163311591, 96.390, 793.0, 28.1603
56.215832722, 96.390, 803.0, 28.3373
56.268353852, 96.390, 833.0, 28.8617
56.320874983, 96.390, 863.0, 29.3769
56.373396114, 96.390, 855.0, 29.2404
56.425917244, 96.390, 843.0, 29.0345
56.478438375, 96.390, 840.0, 28.9828
56.530959506, 96.390, 862.0, 29.3598
56.583480637, 96.390, 897.0, 29.9500
56.636001767, 96.390, 829.0, 28.7924
56.688522898, 96.390, 814.0, 28.5307
56.741044029, 96.390, 818.0, 28.6007
56.793565159, 96.390, 848.0, 29.1204
56.846086290, 96.390, 878.0, 29.6311
56.898607421, 96.390, 830.0, 28.8097
56.951128551, 96.390, 834.0, 28.8791
57.003649682, 96.390, 877.0, 29.6142
57.056170813, 96.390, 850.0, 29.1548
57.108691944, 96.390, 894.0, 29.8998
57.161213074, 96.390, 855.0, 29.2404
57.213734205, 96.390, 869.0, 29.4788
57.266255336, 96.390, 862.0, 29.3598
57.318776466, 96.390, 791.0, 28.1247
57.371297597, 96.390, 817.0, 28.5832
57.423818728, 96.390, 880.0, 29.6648
57.476339859, 96.390, 800.0, 28.2843
57.528860989, 96.390, 771.0, 27.7669
57.581382120, 96.390, 811.0, 28.4781
57.633903251, 96.390, 789.0, 28.0891
57.686424381, 96.390, 836.0, 28.9137
57.738945512, 96.390, 860.0, 29.3258
57.791466643, 96.390, 824.0, 28.7054
57.843987774, 96.390, 853.0, 29.2062
57.896508904, 96.390, 788.0, 28.0713
57.949030035, 96.390, 863.0, 29.3769
58.001551166, 96.390, 828.0, 28.7750
58.054072296, 96.390, 804.0, 28.3549
58.106593427, 96.390, 797.0, 28.2312
58.159114558, 96.390, 828.0, 28.7750
58.211635689, 96.390, 767.0, 27.6948
58.264156819, 96.390, 793.0, 28.1603
58.316677950, 96.390, 782.0, 27.9643
58.369199081, 96.390, 784.0, 28.0000
58.421720211, 96.390, 829.0, 28.7924
58.474241342, 96.390, 852.0, 29.1890
58.526762473, 96.390, 813.0, 28.5132
58.579283603, 96.390, 767.0, 27.6948
58.631804734, 96.390, 785.0, 28.0179
58.684325865, 96.390, 749.0, 27.3679
58.736846996, 96.390, 819.0, 28.6182
58.789368126, 96.390, 830.0, 28.8097
58.841889257, 96.390, 807.0, 28.4077
58.894410388, 96.390, 801.0, 28.3019
58.946931518, 96.390, 835.0, 28.8964
58.999452649, 96.390, 812.0, 28.4956
59.051973780, 96.390, 865.0, 29.4109
59.104494911, 96.390, 791.0, 28.1247
59.157016041, 96.390, 797.0, 28.2312
59.209537172, 96.390, 793.0, 28.1603
59.262058303, 96.390, 825.0, 28.7228
59.314579433, 96.390, 843.0, 29.0345
59.367100564, 96.390, 864.0, 29.3939
59.419621695, 96.390, 826.0, 28.7402
59.472142826, 96.390, 764.0, 27.6405
59.524663956, 96.390, 776.0, 27.8568
59.577185087, 96.390, 865.0, 29.4109
59.629706218, 96.390, 809.0, 28.4429
59.682227348, 96.390, 854.0, 29.2233
59.734748479, 96.390, 827.0, 28.7576
59.787269610, 96.390, 788.0, 28.0713
59.839790740, 96.390, 812.0, 28.4956
59.892311871, 96.390, 842.0, 29.0172
59.944833002, 96.390, 854.0, 29.2233
59.997354133, 96.390, 885.0, 29.7489
60.049875263, 96.390, 877.0, 29.6142
60.102396394, 96.390, 885.0, 29.7489
60.154917525, 96.390, 882.0, 29.6985
60.207438655, 96.390, 846.0, 29.0861
60.259959786, 96.390, 862.0, 29.3598
60.312480917, 96.390, 850.0, 29.1548
60.365002048, 96.390, 870.0, 29.4958
60.417523178, 96.390, 916.0, 30.2655
60.470044309, 96.390, 813.0, 28.5132
60.522565440, 96.390, 857.0, 29.2746
60.575086570, 96.390, 903.0, 30.0500
60.627607701, 96.390, 891.0, 29.8496
60.680128832, 96.390, 923.0, 30.3809
60.732649963, 96.390, 933.0, 30.5450
60.785171093, 96.390, 914.0, 30.2324
60.837692224, 96.390, 951.0, 30.8383
60.890213355, 96.390, 918.0, 30.2985
60.942734485, 96.390, 913.0, 30.2159
60.995255616, 96.390, 925.0, 30.4138
61.047776747, 96.390, 916.0, 30.2655
61.100297878, 96.390, 930.0, 30.4959
61.152819008, 96.390, 930.0, 30.4959
61.205340139, 96.390, 932.0, 30.5287
61.257861270, 96.390, 903.0, 30.0500
61.310382400, 96.390, 892.0, 29.8664
61.362903531, 96.390, 847.0, 29.1033
61.415424662, 96.390, 926.0, 30.4302
61.467945792, 96.390, 912.0, 30.1993
61.520466923, 96.390, 885.0, 29.7489
61.572988054, 96.390, 851.0, 29.1719
61.625509185, 96.390, 904.0, 30.0666
61.678030315, 96.390, 883.0, 29.7153
61.730551446, 96.390, 877.0, 29.6142
61.783072577, 96.390, 869.0, 29.4788
61.835593707, 96.390, 880.0, 29.6648
61.888114838, 96.390, 842.0, 29.0172
61.940635969, 96.390, 804.0, 28.3549
61.993157100, 96.390, 855.0, 29.2404
62.045678230, 96.390, 856.0, 29.2575
62.098199361, 96.390, 832.0, 28.8444
62.150720492, 96.390, 855.0, 29.2404
62.203241622, 96.390, 823.0, 28.6880
62.255762753, 96.390, 836.0, 28.9137
62.308283884, 96.390, 858.0, 29.2916
62.360805015, 96.390, 774.0, 27.8209
62.413326145, 96.390, 803.0, 28.3373
62.465847276, 96.390, 776.0, 27.8568
62.518368407, 96.390, 785.0, 28.0179
62.570889537, 96.390, 777.0, 27.8747
62.623410668, 96.390, 816.0, 28.5657
62.675931799, 96.390, 822.0, 28.6705
62.728452930, 96.390, 772.0, 27.7849
62.780974060, 96.390, 839.0, 28.9655
62.833495191, 96.390, 818.0, 28.6007
62.886016322, 96.390, 804.0, 28.3549
62.938537452, 96.390, 803.0, 28.3373
62.991058583, 96.390, 769.0, 27.7308
63.043579714, 96.390, 808.0, 28.4253
63.096100844, 96.390, 775.0, 27.8388
63.148621975, 96.390, 834.0, 28.8791
63.201143106, 96.390, 836.0, 28.9137
63.253664237, 96.390, 785.0, 28.0179
63.306185367, 96.390, 788.0, 28.0713
63.358706498, 96.390, 790.0, 28.1069
63.411227629, 96.390, 848.0, 29.1204
63.463748759, 96.390, 832.0, 28.8444
63.516269890, 96.390, 821.0, 28.6531
63.568791021, 96.390, 772.0, 27.7849
63.621312152, 96.390, 839.0, 28.9655
63.673833282, 96.390, 811.0, 28.4781
63.726354413, 96.390, 720.0, 26.8328
63.778875544, 96.390, 803.0, 28.3373
63.831396674, 96.390, 787.0, 28.0535
63.883917805, 96.390, 803.0, 28.3373
63.936438936, 96.390, 805.0, 28.3725
63.988960067, 96.390, 764.0, 27.6405
64.041481197, 96.390, 755.0, 27.4773
64.094002328, 96.390, 773.0, 27.8029
64.146523459, 96.390, 782.0, 27.9643
64.199044589, 96.390, 763.0, 27.6225
64.251565720, 96.390, 748.0, 27.3496
64.304086851, 96.390, 798.0, 28.2489
64.356607981, 96.390, 756.0, 27.4955
64.409129112, 96.390, 757.0, 27.5136
64.461650243, 96.390, 760.0, 27.5681
64.514171374, 96.390, 719.0, 26.8142
64.566692504, 96.390, 772.0, 27.7849
64.619213635, 96.390, 787.0, 28.0535
64.671734766, 96.390, 732.0, 27.0555
64.724255896, 96.390, 714.0, 26.7208
64.776777027, 96.390, 723.0, 26.8887
64.829298158, 96.390, 708.0, 26.6083
64.881819289, 96.390, 730.0, 27.0185
64.934340419, 96.390, 756.0, 27.4955
64.986861550, 96.390, 733.0, 27.0740