File: Files_organized_for_plots/Na_to_Al_1/XRD_AlAxial01Nov21_Act07Jan22_B1_1000M_NaOH_LS0124_1.csv
[Measurement conditions]
Sample identification,XRD_AlAxial01Nov21_Act07Jan22_B1_1000M_NaOH_LS0124_1
Comment - 1,"Configuration=Stage for Flat Samples/Holders, Owner=User-1, Creation date=7/1/2020 9:53:24 AM"
Comment - 2,"Goniometer=Theta/Theta; Minimum step size 2Theta:0.0001; Minimum step size Omega:0.0001"
Comment - 3,"Sample stage=Stage for flat samples/holders"
Comment - 4,"Diffractometer system=EMPYREAN"
Comment - 5,"Measurement program=C:\Users\ibo5034\OneDrive - The Pennsylvania State University\NEUP - Reed, Titus's files\XRD\Cement\Zerobackground scan.xrdmp, Identifier={98A3B11C-88F9-4AA6-982C-73314A311EF5}"
Anode material,Cu
K-Alpha1 wavelength,1.5405980
K-Alpha2 wavelength,1.5444260
Ratio K-Alpha2/K-Alpha1,0.500
Divergence slit,Fixed,0.25
Monochromator used,NO
Generator voltage, 45
Tube current, 40
File date and time,10/Jan/2022 13:00
Unit cell,
h k l, 0 0 0
Scan axis,Gonio
Scan range,4.994599997,64.999991833
Scan step size,0.0262606
No. of points, 2285
Scan type,CONTINUOUS
Time per step,96.390
[Scan points]
Angle, TimePerStep, Intensity, ESD
5.007730280, 96.390, 3897.0, 62.4260
5.060251411, 96.390, 3866.0, 62.1772
5.112772541, 96.390, 3874.0, 62.2415
5.165293672, 96.390, 3850.0, 62.0484
5.217814803, 96.390, 3647.0, 60.3904
5.270335934, 96.390, 3684.0, 60.6960
5.322857064, 96.390, 3555.0, 59.6238
5.375378195, 96.390, 3541.0, 59.5063
5.427899326, 96.390, 3495.0, 59.1185
5.480420456, 96.390, 3484.0, 59.0254
5.532941587, 96.390, 3524.0, 59.3633
5.585462718, 96.390, 3538.0, 59.4811
5.637983849, 96.390, 3474.0, 58.9406
5.690504979, 96.390, 3496.0, 59.1270
5.743026110, 96.390, 3425.0, 58.5235
5.795547241, 96.390, 3413.0, 58.4209
5.848068371, 96.390, 3379.0, 58.1292
5.900589502, 96.390, 3429.0, 58.5577
5.953110633, 96.390, 3463.0, 58.8473
6.005631763, 96.390, 3315.0, 57.5760
6.058152894, 96.390, 3376.0, 58.1034
6.110674025, 96.390, 3260.0, 57.0964
6.163195156, 96.390, 3331.0, 57.7148
6.215716286, 96.390, 3276.0, 57.2364
6.268237417, 96.390, 3274.0, 57.2189
6.320758548, 96.390, 3312.0, 57.5500
6.373279678, 96.390, 3160.0, 56.2139
6.425800809, 96.390, 3187.0, 56.4535
6.478321940, 96.390, 3233.0, 56.8595
6.530843071, 96.390, 3157.0, 56.1872
6.583364201, 96.390, 3205.0, 56.6127
6.635885332, 96.390, 3170.0, 56.3028
6.688406463, 96.390, 3193.0, 56.5066
6.740927593, 96.390, 3271.0, 57.1927
6.793448724, 96.390, 3176.0, 56.3560
6.845969855, 96.390, 3072.0, 55.4256
6.898490986, 96.390, 3091.0, 55.5968
6.951012116, 96.390, 3068.0, 55.3895
7.003533247, 96.390, 3093.0, 55.6147
7.056054378, 96.390, 3031.0, 55.0545
7.108575508, 96.390, 3033.0, 55.0727
7.161096639, 96.390, 3098.0, 55.6597
7.213617770, 96.390, 3109.0, 55.7584
7.266138900, 96.390, 3013.0, 54.8908
7.318660031, 96.390, 3081.0, 55.5068
7.371181162, 96.390, 2974.0, 54.5344
7.423702293, 96.390, 3119.0, 55.8480
7.476223423, 96.390, 3007.0, 54.8361
7.528744554, 96.390, 3072.0, 55.4256
7.581265685, 96.390, 2949.0, 54.3047
7.633786815, 96.390, 2935.0, 54.1756
7.686307946, 96.390, 3036.0, 55.0999
7.738829077, 96.390, 3043.0, 55.1634
7.791350208, 96.390, 3051.0, 55.2359
7.843871338, 96.390, 3122.0, 55.8749
7.896392469, 96.390, 2989.0, 54.6717
7.948913600, 96.390, 3110.0, 55.7674
8.001434730, 96.390, 3031.0, 55.0545
8.053955861, 96.390, 3076.0, 55.4617
8.106476992, 96.390, 3232.0, 56.8507
8.158998123, 96.390, 3307.0, 57.5065
8.211519253, 96.390, 3188.0, 56.4624
8.264040384, 96.390, 3078.0, 55.4797
8.316561515, 96.390, 3006.0, 54.8270
8.369082645, 96.390, 2999.0, 54.7631
8.421603776, 96.390, 3019.0, 54.9454
8.474124907, 96.390, 3024.0, 54.9909
8.526646038, 96.390, 2844.0, 53.3292
8.579167168, 96.390, 3083.0, 55.5248
8.631688299, 96.390, 2980.0, 54.5894
8.684209430, 96.390, 3031.0, 55.0545
8.736730560, 96.390, 3037.0, 55.1090
8.789251691, 96.390, 2983.0, 54.6168
8.841772822, 96.390, 2981.0, 54.5985
8.894293952, 96.390, 3179.0, 56.3826
8.946815083, 96.390, 3012.0, 54.8817
8.999336214, 96.390, 3088.0, 55.5698
9.051857345, 96.390, 3097.0, 55.6507
9.104378475, 96.390, 3140.0, 56.0357
9.156899606, 96.390, 3136.0, 56.0000
9.209420737, 96.390, 3002.0, 54.7905
9.261941867, 96.390, 3143.0, 56.0625
9.314462998, 96.390, 3160.0, 56.2139
9.366984129, 96.390, 3093.0, 55.6147
9.419505260, 96.390, 3233.0, 56.8595
9.472026390, 96.390, 3129.0, 55.9375
9.524547521, 96.390, 3192.0, 56.4978
9.577068652, 96.390, 3257.0, 57.0701
9.629589782, 96.390, 3147.0, 56.0981
9.682110913, 96.390, 3204.0, 56.6039
9.734632044, 96.390, 3092.0, 55.6058
9.787153175, 96.390, 3203.0, 56.5951
9.839674305, 96.390, 3254.0, 57.0438
9.892195436, 96.390, 3281.0, 57.2800
9.944716567, 96.390, 3197.0, 56.5420
9.997237697, 96.390, 3154.0, 56.1605
10.049758828, 96.390, 3250.0, 57.0088
10.102279959, 96.390, 3277.0, 57.2451
10.154801090, 96.390, 3300.0, 57.4456
10.207322220, 96.390, 3238.0, 56.9034
10.259843351, 96.390, 3339.0, 57.7841
10.312364482, 96.390, 3347.0, 57.8533
10.364885612, 96.390, 3374.0, 58.0861
10.417406743, 96.390, 3330.0, 57.7062
10.469927874, 96.390, 3356.0, 57.9310
10.522449004, 96.390, 3363.0, 57.9914
10.574970135, 96.390, 3417.0, 58.4551
10.627491266, 96.390, 3395.0, 58.2666
10.680012397, 96.390, 3374.0, 58.0861
10.732533527, 96.390, 3396.0, 58.2752
10.785054658, 96.390, 3400.0, 58.3095
10.837575789, 96.390, 3393.0, 58.2495
10.890096919, 96.390, 3382.0, 58.1550
10.942618050, 96.390, 3387.0, 58.1979
10.995139181, 96.390, 3412.0, 58.4123
11.047660312, 96.390, 3400.0, 58.3095
11.100181442, 96.390, 3494.0, 59.1101
11.152702573, 96.390, 3557.0, 59.6406
11.205223704, 96.390, 3326.0, 57.6715
11.257744834, 96.390, 3405.0, 58.3524
11.310265965, 96.390, 3300.0, 57.4456
11.362787096, 96.390, 3313.0, 57.5587
11.415308227, 96.390, 3358.0, 57.9483
11.467829357, 96.390, 3337.0, 57.7668
11.520350488, 96.390, 3392.0, 58.2409
11.572871619, 96.390, 3248.0, 56.9912
11.625392749, 96.390, 3298.0, 57.4282
11.677913880, 96.390, 3277.0, 57.2451
11.730435011, 96.390, 3255.0, 57.0526
11.782956141, 96.390, 3271.0, 57.1927
11.835477272, 96.390, 3213.0, 56.6833
11.887998403, 96.390, 3151.0, 56.1338
11.940519534, 96.390, 3235.0, 56.8771
11.993040664, 96.390, 3141.0, 56.0446
12.045561795, 96.390, 3157.0, 56.1872
12.098082926, 96.390, 3177.0, 56.3649
12.150604056, 96.390, 3077.0, 55.4707
12.203125187, 96.390, 3073.0, 55.4346
12.255646318, 96.390, 2963.0, 54.4334
12.308167449, 96.390, 2900.0, 53.8516
12.360688579, 96.390, 2951.0, 54.3231
12.413209710, 96.390, 2857.0, 53.4509
12.465730841, 96.390, 2854.0, 53.4228
12.518251971, 96.390, 2931.0, 54.1387
12.570773102, 96.390, 2757.0, 52.5071
12.623294233, 96.390, 2882.0, 53.6843
12.675815364, 96.390, 2888.0, 53.7401
12.728336494, 96.390, 2816.0, 53.0660
12.780857625, 96.390, 2692.0, 51.8845
12.833378756, 96.390, 2715.0, 52.1057
12.885899886, 96.390, 2660.0, 51.5752
12.938421017, 96.390, 2662.0, 51.5946
12.990942148, 96.390, 2576.0, 50.7543
13.043463279, 96.390, 2583.0, 50.8232
13.095984409, 96.390, 2575.0, 50.7445
13.148505540, 96.390, 2597.0, 50.9608
13.201026671, 96.390, 2490.0, 49.8999
13.253547801, 96.390, 2554.0, 50.5371
13.306068932, 96.390, 2509.0, 50.0899
13.358590063, 96.390, 2545.0, 50.4480
13.411111193, 96.390, 2649.0, 51.4684
13.463632324, 96.390, 2559.0, 50.5866
13.516153455, 96.390, 2787.0, 52.7920
13.568674586, 96.390, 2689.0, 51.8556
13.621195716, 96.390, 2466.0, 49.6588
13.673716847, 96.390, 2392.0, 48.9081
13.726237978, 96.390, 2354.0, 48.5180
13.778759108, 96.390, 2498.0, 49.9800
13.831280239, 96.390, 2363.0, 48.6107
13.883801370, 96.390, 2354.0, 48.5180
13.936322501, 96.390, 2561.0, 50.6063
13.988843631, 96.390, 2391.0, 48.8979
14.041364762, 96.390, 2328.0, 48.2494
14.093885893, 96.390, 2328.0, 48.2494
14.146407023, 96.390, 2244.0, 47.3709
14.198928154, 96.390, 2381.0, 48.7955
14.251449285, 96.390, 2615.0, 51.1371
14.303970416, 96.390, 2672.0, 51.6914
14.356491546, 96.390, 2546.0, 50.4579
14.409012677, 96.390, 2326.0, 48.2286
14.461533808, 96.390, 2448.0, 49.4773
14.514054938, 96.390, 2703.0, 51.9904
14.566576069, 96.390, 3088.0, 55.5698
14.619097200, 96.390, 2870.0, 53.5724
14.671618331, 96.390, 2249.0, 47.4236
14.724139461, 96.390, 2130.0, 46.1519
14.776660592, 96.390, 2145.0, 46.3141
14.829181723, 96.390, 2104.0, 45.8694
14.881702853, 96.390, 1958.0, 44.2493
14.934223984, 96.390, 2008.0, 44.8107
14.986745115, 96.390, 2017.0, 44.9110
15.039266245, 96.390, 2076.0, 45.5631
15.091787376, 96.390, 2147.0, 46.3357
15.144308507, 96.390, 2359.0, 48.5695
15.196829638, 96.390, 2458.0, 49.5782
15.249350768, 96.390, 2858.0, 53.4603
15.301871899, 96.390, 2959.0, 54.3967
15.354393030, 96.390, 2819.0, 53.0943
15.406914160, 96.390, 2122.0, 46.0652
15.459435291, 96.390, 1988.0, 44.5870
15.511956422, 96.390, 1924.0, 43.8634
15.564477553, 96.390, 1940.0, 44.0454
15.616998683, 96.390, 1925.0, 43.8748
15.669519814, 96.390, 1982.0, 44.5197
15.722040945, 96.390, 2066.0, 45.4533
15.774562075, 96.390, 2114.0, 45.9783
15.827083206, 96.390, 1942.0, 44.0681
15.879604337, 96.390, 1966.0, 44.3396
15.932125468, 96.390, 1906.0, 43.6578
15.984646598, 96.390, 1856.0, 43.0813
16.037167729, 96.390, 1885.0, 43.4166
16.089688860, 96.390, 1809.0, 42.5323
16.142209990, 96.390, 1817.0, 42.6263
16.194731121, 96.390, 1904.0, 43.6348
16.247252252, 96.390, 2037.0, 45.1331
16.299773382, 96.390, 2202.0, 46.9255
16.352294513, 96.390, 2593.0, 50.9215
16.404815644, 96.390, 2549.0, 50.4876
16.457336775, 96.390, 2070.0, 45.4973
16.509857905, 96.390, 1790.0, 42.3084
16.562379036, 96.390, 1830.0, 42.7785
16.614900167, 96.390, 1807.0, 42.5088
16.667421297, 96.390, 1868.0, 43.2204
16.719942428, 96.390, 1877.0, 43.3244
16.772463559, 96.390, 1854.0, 43.0581
16.824984690, 96.390, 1849.0, 43.0000
16.877505820, 96.390, 1918.0, 43.7950
16.930026951, 96.390, 1816.0, 42.6146
16.982548082, 96.390, 1888.0, 43.4511
17.035069212, 96.390, 1904.0, 43.6348
17.087590343, 96.390, 1912.0, 43.7264
17.140111474, 96.390, 1752.0, 41.8569
17.192632605, 96.390, 1802.0, 42.4500
17.245153735, 96.390, 1908.0, 43.6807
17.297674866, 96.390, 1988.0, 44.5870
17.350195997, 96.390, 1839.0, 42.8836
17.402717127, 96.390, 1835.0, 42.8369
17.455238258, 96.390, 1862.0, 43.1509
17.507759389, 96.390, 1837.0, 42.8602
17.560280520, 96.390, 1869.0, 43.2319
17.612801650, 96.390, 1927.0, 43.8976
17.665322781, 96.390, 1841.0, 42.9069
17.717843912, 96.390, 1822.0, 42.6849
17.770365042, 96.390, 1857.0, 43.0929
17.822886173, 96.390, 1886.0, 43.4281
17.875407304, 96.390, 1985.0, 44.5533
17.927928434, 96.390, 1880.0, 43.3590
17.980449565, 96.390, 1983.0, 44.5309
18.032970696, 96.390, 2036.0, 45.1221
18.085491827, 96.390, 2171.0, 46.5940
18.138012957, 96.390, 2237.0, 47.2969
18.190534088, 96.390, 2373.0, 48.7134
18.243055219, 96.390, 2847.0, 53.3573
18.295576349, 96.390, 3300.0, 57.4456
18.348097480, 96.390, 3641.0, 60.3407
18.400618611, 96.390, 3915.0, 62.5700
18.453139742, 96.390, 4366.0, 66.0757
18.505660872, 96.390, 4843.0, 69.5917
18.558182003, 96.390, 5148.0, 71.7496
18.610703134, 96.390, 5073.0, 71.2250
18.663224264, 96.390, 5023.0, 70.8731
18.715745395, 96.390, 5551.0, 74.5050
18.768266526, 96.390, 6370.0, 79.8123
18.820787657, 96.390, 6834.0, 82.6680
18.873308787, 96.390, 5551.0, 74.5050
18.925829918, 96.390, 4054.0, 63.6710
18.978351049, 96.390, 3508.0, 59.2284
19.030872179, 96.390, 2999.0, 54.7631
19.083393310, 96.390, 2548.0, 50.4777
19.135914441, 96.390, 2385.0, 48.8365
19.188435572, 96.390, 2250.0, 47.4342
19.240956702, 96.390, 2204.0, 46.9468
19.293477833, 96.390, 2200.0, 46.9042
19.345998964, 96.390, 2269.0, 47.6340
19.398520094, 96.390, 2435.0, 49.3457
19.451041225, 96.390, 2444.0, 49.4368
19.503562356, 96.390, 2313.0, 48.0937
19.556083486, 96.390, 2205.0, 46.9574
19.608604617, 96.390, 2108.0, 45.9130
19.661125748, 96.390, 2143.0, 46.2925
19.713646879, 96.390, 2227.0, 47.1911
19.766168009, 96.390, 2392.0, 48.9081
19.818689140, 96.390, 2246.0, 47.3920
19.871210271, 96.390, 2408.0, 49.0714
19.923731401, 96.390, 2599.0, 50.9804
19.976252532, 96.390, 3065.0, 55.3624
20.028773663, 96.390, 3406.0, 58.3609
20.081294794, 96.390, 2953.0, 54.3415
20.133815924, 96.390, 2896.0, 53.8145
20.186337055, 96.390, 3401.0, 58.3181
20.238858186, 96.390, 4400.0, 66.3325
20.291379316, 96.390, 5782.0, 76.0395
20.343900447, 96.390, 6934.0, 83.2706
20.396421578, 96.390, 6264.0, 79.1454
20.448942709, 96.390, 5498.0, 74.1485
20.501463839, 96.390, 4825.0, 69.4622
20.553984970, 96.390, 4192.0, 64.7457
20.606506101, 96.390, 3838.0, 61.9516
20.659027231, 96.390, 4110.0, 64.1093
20.711548362, 96.390, 5149.0, 71.7565
20.764069493, 96.390, 6561.0, 81.0000
20.816590623, 96.390, 4448.0, 66.6933
20.869111754, 96.390, 2861.0, 53.4883
20.921632885, 96.390, 2577.0, 50.7642
20.974154016, 96.390, 2538.0, 50.3786
21.026675146, 96.390, 2544.0, 50.4381
21.079196277, 96.390, 2460.0, 49.5984
21.131717408, 96.390, 2455.0, 49.5480
21.184238538, 96.390, 2372.0, 48.7032
21.236759669, 96.390, 2507.0, 50.0700
21.289280800, 96.390, 2492.0, 49.9199
21.341801931, 96.390, 2691.0, 51.8748
21.394323061, 96.390, 2616.0, 51.1468
21.446844192, 96.390, 2480.0, 49.7996
21.499365323, 96.390, 2309.0, 48.0521
21.551886453, 96.390, 2475.0, 49.7494
21.604407584, 96.390, 2599.0, 50.9804
21.656928715, 96.390, 2841.0, 53.3010
21.709449846, 96.390, 2754.0, 52.4786
21.761970976, 96.390, 2487.0, 49.8698
21.814492107, 96.390, 2331.0, 48.2804
21.867013238, 96.390, 2333.0, 48.3011
21.919534368, 96.390, 2335.0, 48.3218
21.972055499, 96.390, 2389.0, 48.8774
22.024576630, 96.390, 2290.0, 47.8539
22.077097761, 96.390, 2322.0, 48.1871
22.129618891, 96.390, 2412.0, 49.1121
22.182140022, 96.390, 2397.0, 48.9592
22.234661153, 96.390, 2365.0, 48.6313
22.287182283, 96.390, 2476.0, 49.7594
22.339703414, 96.390, 2411.0, 49.1019
22.392224545, 96.390, 2444.0, 49.4368
22.444745675, 96.390, 2404.0, 49.0306
22.497266806, 96.390, 2438.0, 49.3761
22.549787937, 96.390, 2538.0, 50.3786
22.602309068, 96.390, 2660.0, 51.5752
22.654830198, 96.390, 2607.0, 51.0588
22.707351329, 96.390, 2641.0, 51.3907
22.759872460, 96.390, 2558.0, 50.5767
22.812393590, 96.390, 2777.0, 52.6972
22.864914721, 96.390, 2983.0, 54.6168
22.917435852, 96.390, 3108.0, 55.7494
22.969956983, 96.390, 2933.0, 54.1572
23.022478113, 96.390, 2927.0, 54.1018
23.074999244, 96.390, 2868.0, 53.5537
23.127520375, 96.390, 2882.0, 53.6843
23.180041505, 96.390, 3081.0, 55.5068
23.232562636, 96.390, 3247.0, 56.9825
23.285083767, 96.390, 3095.0, 55.6327
23.337604898, 96.390, 2932.0, 54.1479
23.390126028, 96.390, 2952.0, 54.3323
23.442647159, 96.390, 2909.0, 53.9351
23.495168290, 96.390, 2747.0, 52.4118
23.547689420, 96.390, 2670.0, 51.6720
23.600210551, 96.390, 2804.0, 52.9528
23.652731682, 96.390, 2723.0, 52.1824
23.705252813, 96.390, 2547.0, 50.4678
23.757773943, 96.390, 2565.0, 50.6458
23.810295074, 96.390, 2523.0, 50.2295
23.862816205, 96.390, 2421.0, 49.2037
23.915337335, 96.390, 2455.0, 49.5480
23.967858466, 96.390, 2405.0, 49.0408
24.020379597, 96.390, 2400.0, 48.9898
24.072900727, 96.390, 2364.0, 48.6210
24.125421858, 96.390, 2342.0, 48.3942
24.177942989, 96.390, 2409.0, 49.0816
24.230464120, 96.390, 2542.0, 50.4183
24.282985250, 96.390, 2300.0, 47.9583
24.335506381, 96.390, 2308.0, 48.0416
24.388027512, 96.390, 2245.0, 47.3814
24.440548642, 96.390, 2207.0, 46.9787
24.493069773, 96.390, 2156.0, 46.4327
24.545590904, 96.390, 2117.0, 46.0109
24.598112035, 96.390, 2147.0, 46.3357
24.650633165, 96.390, 2081.0, 45.6180
24.703154296, 96.390, 2036.0, 45.1221
24.755675427, 96.390, 2040.0, 45.1664
24.808196557, 96.390, 2011.0, 44.8442
24.860717688, 96.390, 2114.0, 45.9783
24.913238819, 96.390, 2016.0, 44.8999
24.965759950, 96.390, 2014.0, 44.8776
25.018281080, 96.390, 1896.0, 43.5431
25.070802211, 96.390, 1912.0, 43.7264
25.123323342, 96.390, 1877.0, 43.3244
25.175844472, 96.390, 1901.0, 43.6005
25.228365603, 96.390, 1875.0, 43.3013
25.280886734, 96.390, 1854.0, 43.0581
25.333407864, 96.390, 1825.0, 42.7200
25.385928995, 96.390, 1950.0, 44.1588
25.438450126, 96.390, 2141.0, 46.2709
25.490971257, 96.390, 2304.0, 48.0000
25.543492387, 96.390, 2173.0, 46.6154
25.596013518, 96.390, 1872.0, 43.2666
25.648534649, 96.390, 1723.0, 41.5090
25.701055779, 96.390, 1754.0, 41.8808
25.753576910, 96.390, 1736.0, 41.6653
25.806098041, 96.390, 1752.0, 41.8569
25.858619172, 96.390, 1860.0, 43.1277
25.911140302, 96.390, 1692.0, 41.1339
25.963661433, 96.390, 1722.0, 41.4970
26.016182564, 96.390, 1802.0, 42.4500
26.068703694, 96.390, 1735.0, 41.6533
26.121224825, 96.390, 1712.0, 41.3763
26.173745956, 96.390, 1749.0, 41.8210
26.226267087, 96.390, 1675.0, 40.9268
26.278788217, 96.390, 1714.0, 41.4005
26.331309348, 96.390, 1778.0, 42.1663
26.383830479, 96.390, 1720.0, 41.4729
26.436351609, 96.390, 1770.0, 42.0714
26.488872740, 96.390, 1767.0, 42.0357
26.541393871, 96.390, 1782.0, 42.2137
26.593915002, 96.390, 1747.0, 41.7971
26.646436132, 96.390, 1759.0, 41.9404
26.698957263, 96.390, 1925.0, 43.8748
26.751478394, 96.390, 2007.0, 44.7996
26.803999524, 96.390, 2356.0, 48.5386
26.856520655, 96.390, 2574.0, 50.7346
26.909041786, 96.390, 2409.0, 49.0816
26.961562916, 96.390, 2134.0, 46.1952
27.014084047, 96.390, 2256.0, 47.4974
27.066605178, 96.390, 2612.0, 51.1077
27.119126309, 96.390, 2883.0, 53.6936
27.171647439, 96.390, 2996.0, 54.7357
27.224168570, 96.390, 3677.0, 60.6383
27.276689701, 96.390, 3341.0, 57.8014
27.329210831, 96.390, 2632.0, 51.3030
27.381731962, 96.390, 2125.0, 46.0977
27.434253093, 96.390, 1986.0, 44.5646
27.486774224, 96.390, 1950.0, 44.1588
27.539295354, 96.390, 1967.0, 44.3509
27.591816485, 96.390, 1949.0, 44.1475
27.644337616, 96.390, 2111.0, 45.9456
27.696858746, 96.390, 2326.0, 48.2286
27.749379877, 96.390, 2499.0, 49.9900
27.801901008, 96.390, 2607.0, 51.0588
27.854422139, 96.390, 2714.0, 52.0961
27.906943269, 96.390, 2605.0, 51.0392
27.959464400, 96.390, 2503.0, 50.0300
28.011985531, 96.390, 2206.0, 46.9681
28.064506661, 96.390, 2099.0, 45.8148
28.117027792, 96.390, 2021.0, 44.9555
28.169548923, 96.390, 2065.0, 45.4423
28.222070054, 96.390, 1818.0, 42.6380
28.274591184, 96.390, 1775.0, 42.1307
28.327112315, 96.390, 1868.0, 43.2204
28.379633446, 96.390, 1914.0, 43.7493
28.432154576, 96.390, 1816.0, 42.6146
28.484675707, 96.390, 1866.0, 43.1972
28.537196838, 96.390, 1834.0, 42.8252
28.589717968, 96.390, 1878.0, 43.3359
28.642239099, 96.390, 1824.0, 42.7083
28.694760230, 96.390, 1929.0, 43.9204
28.747281361, 96.390, 1854.0, 43.0581
28.799802491, 96.390, 1961.0, 44.2832
28.852323622, 96.390, 2007.0, 44.7996
28.904844753, 96.390, 1942.0, 44.0681
28.957365883, 96.390, 1780.0, 42.1900
29.009887014, 96.390, 1812.0, 42.5676
29.062408145, 96.390, 1867.0, 43.2088
29.114929276, 96.390, 2098.0, 45.8039
29.167450406, 96.390, 2346.0, 48.4355
29.219971537, 96.390, 2403.0, 49.0204
29.272492668, 96.390, 2401.0, 49.0000
29.325013798, 96.390, 2678.0, 51.7494
29.377534929, 96.390, 2690.0, 51.8652
29.430056060, 96.390, 2484.0, 49.8397
29.482577191, 96.390, 2395.0, 48.9387
29.535098321, 96.390, 2474.0, 49.7393
29.587619452, 96.390, 2236.0, 47.2864
29.640140583, 96.390, 2064.0, 45.4313
29.692661713, 96.390, 1959.0, 44.2606
29.745182844, 96.390, 1898.0, 43.5660
29.797703975, 96.390, 1973.0, 44.4185
29.850225105, 96.390, 1768.0, 42.0476
29.902746236, 96.390, 1661.0, 40.7554
29.955267367, 96.390, 1656.0, 40.6940
30.007788498, 96.390, 1730.0, 41.5933
30.060309628, 96.390, 1684.0, 41.0366
30.112830759, 96.390, 1691.0, 41.1218
30.165351890, 96.390, 1673.0, 40.9023
30.217873020, 96.390, 1604.0, 40.0500
30.270394151, 96.390, 1572.0, 39.6485
30.322915282, 96.390, 1610.0, 40.1248
30.375436413, 96.390, 1621.0, 40.2616
30.427957543, 96.390, 1614.0, 40.1746
30.480478674, 96.390, 1788.0, 42.2847
30.532999805, 96.390, 1700.0, 41.2311
30.585520935, 96.390, 1777.0, 42.1545
30.638042066, 96.390, 1884.0, 43.4051
30.690563197, 96.390, 2028.0, 45.0333
30.743084328, 96.390, 2111.0, 45.9456
30.795605458, 96.390, 2045.0, 45.2217
30.848126589, 96.390, 1972.0, 44.4072
30.900647720, 96.390, 2035.0, 45.1110
30.953168850, 96.390, 1842.0, 42.9185
31.005689981, 96.390, 1745.0, 41.7732
31.058211112, 96.390, 1777.0, 42.1545
31.110732243, 96.390, 1763.0, 41.9881
31.163253373, 96.390, 1868.0, 43.2204
31.215774504, 96.390, 2378.0, 48.7647
31.268295635, 96.390, 2830.0, 53.1977
31.320816765, 96.390, 2764.0, 52.5738
31.373337896, 96.390, 2607.0, 51.0588
31.425859027, 96.390, 2417.0, 49.1630
31.478380157, 96.390, 2191.0, 46.8081
31.530901288, 96.390, 2078.0, 45.5851
31.583422419, 96.390, 2028.0, 45.0333
31.635943550, 96.390, 1851.0, 43.0232
31.688464680, 96.390, 1869.0, 43.2319
31.740985811, 96.390, 1755.0, 41.8927
31.793506942, 96.390, 1651.0, 40.6325
31.846028072, 96.390, 1662.0, 40.7676
31.898549203, 96.390, 1687.0, 41.0731
31.951070334, 96.390, 1956.0, 44.2267
32.003591465, 96.390, 2335.0, 48.3218
32.056112595, 96.390, 3252.0, 57.0263
32.108633726, 96.390, 4226.0, 65.0077
32.161154857, 96.390, 3613.0, 60.1082
32.213675987, 96.390, 2890.0, 53.7587
32.266197118, 96.390, 2283.0, 47.7807
32.318718249, 96.390, 2338.0, 48.3529
32.371239380, 96.390, 2094.0, 45.7602
32.423760510, 96.390, 1901.0, 43.6005
32.476281641, 96.390, 1637.0, 40.4599
32.528802772, 96.390, 1598.0, 39.9750
32.581323902, 96.390, 1655.0, 40.6817
32.633845033, 96.390, 1596.0, 39.9500
32.686366164, 96.390, 1654.0, 40.6694
32.738887295, 96.390, 1815.0, 42.6028
32.791408425, 96.390, 1750.0, 41.8330
32.843929556, 96.390, 1739.0, 41.7013
32.896450687, 96.390, 1638.0, 40.4722
32.948971817, 96.390, 1645.0, 40.5586
33.001492948, 96.390, 1744.0, 41.7612
33.054014079, 96.390, 1790.0, 42.3084
33.106535209, 96.390, 1892.0, 43.4971
33.159056340, 96.390, 1892.0, 43.4971
33.211577471, 96.390, 1856.0, 43.0813
33.264098602, 96.390, 1883.0, 43.3935
33.316619732, 96.390, 1911.0, 43.7150
33.369140863, 96.390, 1759.0, 41.9404
33.421661994, 96.390, 1711.0, 41.3642
33.474183124, 96.390, 1685.0, 41.0488
33.526704255, 96.390, 1836.0, 42.8486
33.579225386, 96.390, 1839.0, 42.8836
33.631746517, 96.390, 1885.0, 43.4166
33.684267647, 96.390, 1942.0, 44.0681
33.736788778, 96.390, 1981.0, 44.5084
33.789309909, 96.390, 2027.0, 45.0222
33.841831039, 96.390, 2078.0, 45.5851
33.894352170, 96.390, 2291.0, 47.8644
33.946873301, 96.390, 2599.0, 50.9804
33.999394432, 96.390, 3019.0, 54.9454
34.051915562, 96.390, 2959.0, 54.3967
34.104436693, 96.390, 2673.0, 51.7011
34.156957824, 96.390, 2484.0, 49.8397
34.209478954, 96.390, 2372.0, 48.7032
34.262000085, 96.390, 2382.0, 48.8057
34.314521216, 96.390, 2441.0, 49.4065
34.367042346, 96.390, 2569.0, 50.6853
34.419563477, 96.390, 2563.0, 50.6261
34.472084608, 96.390, 2875.0, 53.6190
34.524605739, 96.390, 3211.0, 56.6657
34.577126869, 96.390, 3400.0, 58.3095
34.629648000, 96.390, 3488.0, 59.0593
34.682169131, 96.390, 3202.0, 56.5862
34.734690261, 96.390, 2869.0, 53.5630
34.787211392, 96.390, 2728.0, 52.2303
34.839732523, 96.390, 2685.0, 51.8170
34.892253654, 96.390, 2825.0, 53.1507
34.944774784, 96.390, 3095.0, 55.6327
34.997295915, 96.390, 3190.0, 56.4801
35.049817046, 96.390, 2833.0, 53.2259
35.102338176, 96.390, 2681.0, 51.7784
35.154859307, 96.390, 2499.0, 49.9900
35.207380438, 96.390, 2423.0, 49.2240
35.259901569, 96.390, 2461.0, 49.6085
35.312422699, 96.390, 2302.0, 47.9792
35.364943830, 96.390, 2171.0, 46.5940
35.417464961, 96.390, 2030.0, 45.0555
35.469986091, 96.390, 1976.0, 44.4522
35.522507222, 96.390, 1947.0, 44.1248
35.575028353, 96.390, 1928.0, 43.9090
35.627549484, 96.390, 2012.0, 44.8553
35.680070614, 96.390, 1913.0, 43.7379
35.732591745, 96.390, 1960.0, 44.2719
35.785112876, 96.390, 2030.0, 45.0555
35.837634006, 96.390, 1952.0, 44.1814
35.890155137, 96.390, 2092.0, 45.7384
35.942676268, 96.390, 2203.0, 46.9361
35.995197398, 96.390, 2350.0, 48.4768
36.047718529, 96.390, 2295.0, 47.9062
36.100239660, 96.390, 2355.0, 48.5283
36.152760791, 96.390, 2352.0, 48.4974
36.205281921, 96.390, 2699.0, 51.9519
36.257803052, 96.390, 2734.0, 52.2877
36.310324183, 96.390, 2361.0, 48.5901
36.362845313, 96.390, 2043.0, 45.1996
36.415366444, 96.390, 1897.0, 43.5546
36.467887575, 96.390, 1675.0, 40.9268
36.520408706, 96.390, 1688.0, 41.0853
36.572929836, 96.390, 1674.0, 40.9145
36.625450967, 96.390, 1714.0, 41.4005
36.677972098, 96.390, 1674.0, 40.9145
36.730493228, 96.390, 1619.0, 40.2368
36.783014359, 96.390, 1505.0, 38.7943
36.835535490, 96.390, 1513.0, 38.8973
36.888056621, 96.390, 1473.0, 38.3797
36.940577751, 96.390, 1447.0, 38.0395
36.993098882, 96.390, 1463.0, 38.2492
37.045620013, 96.390, 1491.0, 38.6135
37.098141143, 96.390, 1488.0, 38.5746
37.150662274, 96.390, 1538.0, 39.2173
37.203183405, 96.390, 1563.0, 39.5348
37.255704535, 96.390, 1703.0, 41.2674
37.308225666, 96.390, 1644.0, 40.5463
37.360746797, 96.390, 1701.0, 41.2432
37.413267928, 96.390, 1644.0, 40.5463
37.465789058, 96.390, 1818.0, 42.6380
37.518310189, 96.390, 1965.0, 44.3283
37.570831320, 96.390, 1907.0, 43.6692
37.623352450, 96.390, 2042.0, 45.1885
37.675873581, 96.390, 1917.0, 43.7836
37.728394712, 96.390, 2096.0, 45.7821
37.780915843, 96.390, 2185.0, 46.7440
37.833436973, 96.390, 2004.0, 44.7661
37.885958104, 96.390, 2211.0, 47.0213
37.938479235, 96.390, 2104.0, 45.8694
37.991000365, 96.390, 2055.0, 45.3321
38.043521496, 96.390, 1981.0, 44.5084
38.096042627, 96.390, 1915.0, 43.7607
38.148563758, 96.390, 1983.0, 44.5309
38.201084888, 96.390, 2006.0, 44.7884
38.253606019, 96.390, 1949.0, 44.1475
38.306127150, 96.390, 1807.0, 42.5088
38.358648280, 96.390, 1722.0, 41.4970
38.411169411, 96.390, 1632.0, 40.3980
38.463690542, 96.390, 1630.0, 40.3733
38.516211673, 96.390, 1648.0, 40.5956
38.568732803, 96.390, 1638.0, 40.4722
38.621253934, 96.390, 1684.0, 41.0366
38.673775065, 96.390, 1638.0, 40.4722
38.726296195, 96.390, 1724.0, 41.5211
38.778817326, 96.390, 1759.0, 41.9404
38.831338457, 96.390, 1879.0, 43.3474
38.883859587, 96.390, 1715.0, 41.4126
38.936380718, 96.390, 1740.0, 41.7133
38.988901849, 96.390, 1570.0, 39.6232
39.041422980, 96.390, 1612.0, 40.1497
39.093944110, 96.390, 1618.0, 40.2244
39.146465241, 96.390, 1673.0, 40.9023
39.198986372, 96.390, 1579.0, 39.7366
39.251507502, 96.390, 1760.0, 41.9524
39.304028633, 96.390, 1747.0, 41.7971
39.356549764, 96.390, 1744.0, 41.7612
39.409070895, 96.390, 1848.0, 42.9884
39.461592025, 96.390, 2099.0, 45.8148
39.514113156, 96.390, 1951.0, 44.1701
39.566634287, 96.390, 1918.0, 43.7950
39.619155417, 96.390, 1718.0, 41.4488
39.671676548, 96.390, 1691.0, 41.1218
39.724197679, 96.390, 1629.0, 40.3609
39.776718810, 96.390, 1707.0, 41.3159
39.829239940, 96.390, 1703.0, 41.2674
39.881761071, 96.390, 1792.0, 42.3320
39.934282202, 96.390, 1753.0, 41.8688
39.986803332, 96.390, 1746.0, 41.7852
40.039324463, 96.390, 1822.0, 42.6849
40.091845594, 96.390, 1927.0, 43.8976
40.144366725, 96.390, 1972.0, 44.4072
40.196887855, 96.390, 1991.0, 44.6206
40.249408986, 96.390, 2068.0, 45.4753
40.301930117, 96.390, 2157.0, 46.4435
40.354451247, 96.390, 2250.0, 47.4342
40.406972378, 96.390, 2574.0, 50.7346
40.459493509, 96.390, 2915.0, 53.9907
40.512014639, 96.390, 3329.0, 57.6975
40.564535770, 96.390, 3805.0, 61.6847
40.617056901, 96.390, 4009.0, 63.3167
40.669578032, 96.390, 3717.0, 60.9672
40.722099162, 96.390, 3428.0, 58.5491
40.774620293, 96.390, 2890.0, 53.7587
40.827141424, 96.390, 2286.0, 47.8121
40.879662554, 96.390, 1933.0, 43.9659
40.932183685, 96.390, 1788.0, 42.2847
40.984704816, 96.390, 1643.0, 40.5339
41.037225947, 96.390, 1602.0, 40.0250
41.089747077, 96.390, 1509.0, 38.8458
41.142268208, 96.390, 1408.0, 37.5233
41.194789339, 96.390, 1383.0, 37.1887
41.247310469, 96.390, 1463.0, 38.2492
41.299831600, 96.390, 1507.0, 38.8201
41.352352731, 96.390, 1590.0, 39.8748
41.404873862, 96.390, 1834.0, 42.8252
41.457394992, 96.390, 1853.0, 43.0465
41.509916123, 96.390, 1557.0, 39.4588
41.562437254, 96.390, 1619.0, 40.2368
41.614958384, 96.390, 1417.0, 37.6431
41.667479515, 96.390, 1375.0, 37.0810
41.720000646, 96.390, 1442.0, 37.9737
41.772521776, 96.390, 1409.0, 37.5366
41.825042907, 96.390, 1461.0, 38.2230
41.877564038, 96.390, 1416.0, 37.6298
41.930085169, 96.390, 1439.0, 37.9342
41.982606299, 96.390, 1410.0, 37.5500
42.035127430, 96.390, 1358.0, 36.8511
42.087648561, 96.390, 1454.0, 38.1314
42.140169691, 96.390, 1611.0, 40.1373
42.192690822, 96.390, 1878.0, 43.3359
42.245211953, 96.390, 1642.0, 40.5216
42.297733084, 96.390, 1639.0, 40.4846
42.350254214, 96.390, 1455.0, 38.1445
42.402775345, 96.390, 1358.0, 36.8511
42.455296476, 96.390, 1199.0, 34.6266
42.507817606, 96.390, 1229.0, 35.0571
42.560338737, 96.390, 1266.0, 35.5809
42.612859868, 96.390, 1281.0, 35.7911
42.665380999, 96.390, 1236.0, 35.1568
42.717902129, 96.390, 1286.0, 35.8608
42.770423260, 96.390, 1304.0, 36.1109
42.822944391, 96.390, 1181.0, 34.3657
42.875465521, 96.390, 1264.0, 35.5528
42.927986652, 96.390, 1265.0, 35.5668
42.980507783, 96.390, 1076.0, 32.8024
43.033028914, 96.390, 1152.0, 33.9411
43.085550044, 96.390, 1150.0, 33.9116
43.138071175, 96.390, 1205.0, 34.7131
43.190592306, 96.390, 1278.0, 35.7491
43.243113436, 96.390, 1218.0, 34.8999
43.295634567, 96.390, 1238.0, 35.1852
43.348155698, 96.390, 1155.0, 33.9853
43.400676828, 96.390, 1163.0, 34.1028
43.453197959, 96.390, 1134.0, 33.6749
43.505719090, 96.390, 1194.0, 34.5543
43.558240221, 96.390, 1199.0, 34.6266
43.610761351, 96.390, 1206.0, 34.7275
43.663282482, 96.390, 1176.0, 34.2929
43.715803613, 96.390, 1344.0, 36.6606
43.768324743, 96.390, 1494.0, 38.6523
43.820845874, 96.390, 1637.0, 40.4599
43.873367005, 96.390, 1500.0, 38.7298
43.925888136, 96.390, 1484.0, 38.5227
43.978409266, 96.390, 1336.0, 36.5513
44.030930397, 96.390, 1186.0, 34.4384
44.083451528, 96.390, 1268.0, 35.6090
44.135972658, 96.390, 1273.0, 35.6791
44.188493789, 96.390, 1146.0, 33.8526
44.241014920, 96.390, 1266.0, 35.5809
44.293536051, 96.390, 1239.0, 35.1994
44.346057181, 96.390, 1406.0, 37.4967
44.398578312, 96.390, 1425.0, 37.7492
44.451099443, 96.390, 1410.0, 37.5500
44.503620573, 96.390, 1357.0, 36.8375
44.556141704, 96.390, 1318.0, 36.3043
44.608662835, 96.390, 1268.0, 35.6090
44.661183966, 96.390, 1235.0, 35.1426
44.713705096, 96.390, 1248.0, 35.3270
44.766226227, 96.390, 1180.0, 34.3511
44.818747358, 96.390, 1312.0, 36.2215
44.871268488, 96.390, 1295.0, 35.9861
44.923789619, 96.390, 1291.0, 35.9305
44.976310750, 96.390, 1331.0, 36.4829
45.028831880, 96.390, 1220.0, 34.9285
45.081353011, 96.390, 1281.0, 35.7911
45.133874142, 96.390, 1448.0, 38.0526
45.186395273, 96.390, 1473.0, 38.3797
45.238916403, 96.390, 1380.0, 37.1484
45.291437534, 96.390, 1495.0, 38.6652
45.343958665, 96.390, 1477.0, 38.4318
45.396479795, 96.390, 1437.0, 37.9078
45.449000926, 96.390, 1484.0, 38.5227
45.501522057, 96.390, 1588.0, 39.8497
45.554043188, 96.390, 1472.0, 38.3667
45.606564318, 96.390, 1421.0, 37.6962
45.659085449, 96.390, 1424.0, 37.7359
45.711606580, 96.390, 1434.0, 37.8682
45.764127710, 96.390, 1304.0, 36.1109
45.816648841, 96.390, 1310.0, 36.1939
45.869169972, 96.390, 1316.0, 36.2767
45.921691103, 96.390, 1338.0, 36.5787
45.974212233, 96.390, 1324.0, 36.3868
46.026733364, 96.390, 1351.0, 36.7560
46.079254495, 96.390, 1342.0, 36.6333
46.131775625, 96.390, 1450.0, 38.0789
46.184296756, 96.390, 1521.0, 39.0000
46.236817887, 96.390, 1665.0, 40.8044
46.289339017, 96.390, 1715.0, 41.4126
46.341860148, 96.390, 1630.0, 40.3733
46.394381279, 96.390, 1585.0, 39.8121
46.446902410, 96.390, 1466.0, 38.2884
46.499423540, 96.390, 1376.0, 37.0945
46.551944671, 96.390, 1263.0, 35.5387
46.604465802, 96.390, 1295.0, 35.9861
46.656986932, 96.390, 1310.0, 36.1939
46.709508063, 96.390, 1256.0, 35.4401
46.762029194, 96.390, 1286.0, 35.8608
46.814550325, 96.390, 1240.0, 35.2136
46.867071455, 96.390, 1330.0, 36.4692
46.919592586, 96.390, 1242.0, 35.2420
46.972113717, 96.390, 1273.0, 35.6791
47.024634847, 96.390, 1346.0, 36.6879
47.077155978, 96.390, 1265.0, 35.5668
47.129677109, 96.390, 1284.0, 35.8329
47.182198240, 96.390, 1292.0, 35.9444
47.234719370, 96.390, 1294.0, 35.9722
47.287240501, 96.390, 1272.0, 35.6651
47.339761632, 96.390, 1277.0, 35.7351
47.392282762, 96.390, 1307.0, 36.1525
47.444803893, 96.390, 1258.0, 35.4683
47.497325024, 96.390, 1358.0, 36.8511
47.549846155, 96.390, 1365.0, 36.9459
47.602367285, 96.390, 1282.0, 35.8050
47.654888416, 96.390, 1308.0, 36.1663
47.707409547, 96.390, 1255.0, 35.4260
47.759930677, 96.390, 1256.0, 35.4401
47.812451808, 96.390, 1355.0, 36.8103
47.864972939, 96.390, 1372.0, 37.0405
47.917494069, 96.390, 1293.0, 35.9583
47.970015200, 96.390, 1185.0, 34.4238
48.022536331, 96.390, 1202.0, 34.6699
48.075057462, 96.390, 1258.0, 35.4683
48.127578592, 96.390, 1282.0, 35.8050
48.180099723, 96.390, 1332.0, 36.4966
48.232620854, 96.390, 1296.0, 36.0000
48.285141984, 96.390, 1301.0, 36.0694
48.337663115, 96.390, 1172.0, 34.2345
48.390184246, 96.390, 1292.0, 35.9444
48.442705377, 96.390, 1369.0, 37.0000
48.495226507, 96.390, 1498.0, 38.7040
48.547747638, 96.390, 1556.0, 39.4462
48.600268769, 96.390, 1459.0, 38.1969
48.652789899, 96.390, 1370.0, 37.0135
48.705311030, 96.390, 1259.0, 35.4824
48.757832161, 96.390, 1178.0, 34.3220
48.810353292, 96.390, 1141.0, 33.7787
48.862874422, 96.390, 1166.0, 34.1467
48.915395553, 96.390, 1191.0, 34.5109
48.967916684, 96.390, 1211.0, 34.7994
49.020437814, 96.390, 1146.0, 33.8526
49.072958945, 96.390, 1196.0, 34.5832
49.125480076, 96.390, 1186.0, 34.4384
49.178001207, 96.390, 1326.0, 36.4143
49.230522337, 96.390, 1280.0, 35.7771
49.283043468, 96.390, 1225.0, 35.0000
49.335564599, 96.390, 1135.0, 33.6898
49.388085729, 96.390, 1117.0, 33.4215
49.440606860, 96.390, 1111.0, 33.3317
49.493127991, 96.390, 1075.0, 32.7872
49.545649121, 96.390, 1097.0, 33.1210
49.598170252, 96.390, 1130.0, 33.6155
49.650691383, 96.390, 1142.0, 33.7935
49.703212514, 96.390, 1063.0, 32.6037
49.755733644, 96.390, 1088.0, 32.9848
49.808254775, 96.390, 1155.0, 33.9853
49.860775906, 96.390, 1122.0, 33.4963
49.913297036, 96.390, 1108.0, 33.2866
49.965818167, 96.390, 1108.0, 33.2866
50.018339298, 96.390, 1044.0, 32.3110
50.070860429, 96.390, 1068.0, 32.6803
50.123381559, 96.390, 1064.0, 32.6190
50.175902690, 96.390, 1033.0, 32.1403
50.228423821, 96.390, 1078.0, 32.8329
50.280944951, 96.390, 1230.0, 35.0714
50.333466082, 96.390, 1173.0, 34.2491
50.385987213, 96.390, 1136.0, 33.7046
50.438508344, 96.390, 1234.0, 35.1283
50.491029474, 96.390, 1271.0, 35.6511
50.543550605, 96.390, 1281.0, 35.7911
50.596071736, 96.390, 1231.0, 35.0856
50.648592866, 96.390, 1160.0, 34.0588
50.701113997, 96.390, 1124.0, 33.5261
50.753635128, 96.390, 1163.0, 34.1028
50.806156258, 96.390, 1109.0, 33.3017
50.858677389, 96.390, 1095.0, 33.0908
50.911198520, 96.390, 1110.0, 33.3167
50.963719651, 96.390, 1111.0, 33.3317
51.016240781, 96.390, 1175.0, 34.2783
51.068761912, 96.390, 1144.0, 33.8231
51.121283043, 96.390, 1194.0, 34.5543
51.173804173, 96.390, 1168.0, 34.1760
51.226325304, 96.390, 1164.0, 34.1174
51.278846435, 96.390, 1138.0, 33.7343
51.331367566, 96.390, 1140.0, 33.7639
51.383888696, 96.390, 1049.0, 32.3883
51.436409827, 96.390, 1085.0, 32.9393
51.488930958, 96.390, 997.0, 31.5753
51.541452088, 96.390, 1016.0, 31.8748
51.593973219, 96.390, 969.0, 31.1288
51.646494350, 96.390, 987.0, 31.4166
51.699015481, 96.390, 962.0, 31.0161
51.751536611, 96.390, 1038.0, 32.2180
51.804057742, 96.390, 1077.0, 32.8177
51.856578873, 96.390, 1110.0, 33.3167
51.909100003, 96.390, 1045.0, 32.3265
51.961621134, 96.390, 1057.0, 32.5115
52.014142265, 96.390, 1103.0, 33.2114
52.066663396, 96.390, 1133.0, 33.6601
52.119184526, 96.390, 1108.0, 33.2866
52.171705657, 96.390, 1141.0, 33.7787
52.224226788, 96.390, 1218.0, 34.8999
52.276747918, 96.390, 1235.0, 35.1426
52.329269049, 96.390, 1266.0, 35.5809
52.381790180, 96.390, 1213.0, 34.8281
52.434311310, 96.390, 1119.0, 33.4515
52.486832441, 96.390, 1189.0, 34.4819
52.539353572, 96.390, 1079.0, 32.8481
52.591874703, 96.390, 1092.0, 33.0454
52.644395833, 96.390, 1145.0, 33.8378
52.696916964, 96.390, 1212.0, 34.8138
52.749438095, 96.390, 1143.0, 33.8083
52.801959225, 96.390, 1250.0, 35.3553
52.854480356, 96.390, 1284.0, 35.8329
52.907001487, 96.390, 1390.0, 37.2827
52.959522618, 96.390, 1470.0, 38.3406
53.012043748, 96.390, 1519.0, 38.9744
53.064564879, 96.390, 1682.0, 41.0122
53.117086010, 96.390, 1738.0, 41.6893
53.169607140, 96.390, 1850.0, 43.0116
53.222128271, 96.390, 1764.0, 42.0000
53.274649402, 96.390, 1755.0, 41.8927
53.327170533, 96.390, 1578.0, 39.7240
53.379691663, 96.390, 1435.0, 37.8814
53.432212794, 96.390, 1377.0, 37.1080
53.484733925, 96.390, 1203.0, 34.6843
53.537255055, 96.390, 1260.0, 35.4965
53.589776186, 96.390, 1172.0, 34.2345
53.642297317, 96.390, 1088.0, 32.9848
53.694818448, 96.390, 1031.0, 32.1092
53.747339578, 96.390, 1007.0, 31.7333
53.799860709, 96.390, 1069.0, 32.6956
53.852381840, 96.390, 991.0, 31.4802
53.904902970, 96.390, 1073.0, 32.7567
53.957424101, 96.390, 1123.0, 33.5112
54.009945232, 96.390, 1112.0, 33.3467
54.062466362, 96.390, 1137.0, 33.7194
54.114987493, 96.390, 1134.0, 33.6749
54.167508624, 96.390, 1190.0, 34.4964
54.220029755, 96.390, 1111.0, 33.3317
54.272550885, 96.390, 1117.0, 33.4215
54.325072016, 96.390, 1103.0, 33.2114
54.377593147, 96.390, 1111.0, 33.3317
54.430114277, 96.390, 1098.0, 33.1361
54.482635408, 96.390, 1045.0, 32.3265
54.535156539, 96.390, 971.0, 31.1609
54.587677670, 96.390, 989.0, 31.4484
54.640198800, 96.390, 949.0, 30.8058
54.692719931, 96.390, 904.0, 30.0666
54.745241062, 96.390, 910.0, 30.1662
54.797762192, 96.390, 855.0, 29.2404
54.850283323, 96.390, 855.0, 29.2404
54.902804454, 96.390, 841.0, 29.0000
54.955325585, 96.390, 891.0, 29.8496
55.007846715, 96.390, 800.0, 28.2843
55.060367846, 96.390, 841.0, 29.0000
55.112888977, 96.390, 843.0, 29.0345
55.165410107, 96.390, 824.0, 28.7054
55.217931238, 96.390, 834.0, 28.8791
55.270452369, 96.390, 775.0, 27.8388
55.322973499, 96.390, 804.0, 28.3549
55.375494630, 96.390, 864.0, 29.3939
55.428015761, 96.390, 921.0, 30.3480
55.480536892, 96.390, 910.0, 30.1662
55.533058022, 96.390, 942.0, 30.6920
55.585579153, 96.390, 931.0, 30.5123
55.638100284, 96.390, 902.0, 30.0333
55.690621414, 96.390, 831.0, 28.8271
55.743142545, 96.390, 899.0, 29.9833
55.795663676, 96.390, 989.0, 31.4484
55.848184807, 96.390, 901.0, 30.0167
55.900705937, 96.390, 901.0, 30.0167
55.953227068, 96.390, 897.0, 29.9500
56.005748199, 96.390, 929.0, 30.4795
56.058269329, 96.390, 958.0, 30.9516
56.110790460, 96.390, 981.0, 31.3209
56.163311591, 96.390, 960.0, 30.9839
56.215832722, 96.390, 921.0, 30.3480
56.268353852, 96.390, 911.0, 30.1828
56.320874983, 96.390, 873.0, 29.5466
56.373396114, 96.390, 858.0, 29.2916
56.425917244, 96.390, 814.0, 28.5307
56.478438375, 96.390, 871.0, 29.5127
56.530959506, 96.390, 874.0, 29.5635
56.583480637, 96.390, 837.0, 28.9310
56.636001767, 96.390, 818.0, 28.6007
56.688522898, 96.390, 809.0, 28.4429
56.741044029, 96.390, 809.0, 28.4429
56.793565159, 96.390, 811.0, 28.4781
56.846086290, 96.390, 762.0, 27.6043
56.898607421, 96.390, 775.0, 27.8388
56.951128551, 96.390, 823.0, 28.6880
57.003649682, 96.390, 794.0, 28.1780
57.056170813, 96.390, 767.0, 27.6948
57.108691944, 96.390, 805.0, 28.3725
57.161213074, 96.390, 938.0, 30.6268
57.213734205, 96.390, 905.0, 30.0832
57.266255336, 96.390, 946.0, 30.7571
57.318776466, 96.390, 1004.0, 31.6860
57.371297597, 96.390, 982.0, 31.3369
57.423818728, 96.390, 953.0, 30.8707
57.476339859, 96.390, 947.0, 30.7734
57.528860989, 96.390, 906.0, 30.0998
57.581382120, 96.390, 879.0, 29.6479
57.633903251, 96.390, 897.0, 29.9500
57.686424381, 96.390, 948.0, 30.7896
57.738945512, 96.390, 922.0, 30.3645
57.791466643, 96.390, 892.0, 29.8664
57.843987774, 96.390, 895.0, 29.9166
57.896508904, 96.390, 837.0, 28.9310
57.949030035, 96.390, 887.0, 29.7825
58.001551166, 96.390, 895.0, 29.9166
58.054072296, 96.390, 961.0, 31.0000
58.106593427, 96.390, 1040.0, 32.2490
58.159114558, 96.390, 894.0, 29.8998
58.211635689, 96.390, 846.0, 29.0861
58.264156819, 96.390, 910.0, 30.1662
58.316677950, 96.390, 905.0, 30.0832
58.369199081, 96.390, 831.0, 28.8271
58.421720211, 96.390, 808.0, 28.4253
58.474241342, 96.390, 808.0, 28.4253
58.526762473, 96.390, 844.0, 29.0517
58.579283603, 96.390, 881.0, 29.6816
58.631804734, 96.390, 887.0, 29.7825
58.684325865, 96.390, 836.0, 28.9137
58.736846996, 96.390, 893.0, 29.8831
58.789368126, 96.390, 837.0, 28.9310
58.841889257, 96.390, 881.0, 29.6816
58.894410388, 96.390, 820.0, 28.6356
58.946931518, 96.390, 848.0, 29.1204
58.999452649, 96.390, 829.0, 28.7924
59.051973780, 96.390, 840.0, 28.9828
59.104494911, 96.390, 899.0, 29.9833
59.157016041, 96.390, 849.0, 29.1376
59.209537172, 96.390, 866.0, 29.4279
59.262058303, 96.390, 932.0, 30.5287
59.314579433, 96.390, 933.0, 30.5450
59.367100564, 96.390, 942.0, 30.6920
59.419621695, 96.390, 956.0, 30.9192
59.472142826, 96.390, 952.0, 30.8545
59.524663956, 96.390, 902.0, 30.0333
59.577185087, 96.390, 934.0, 30.5614
59.629706218, 96.390, 898.0, 29.9666
59.682227348, 96.390, 890.0, 29.8329
59.734748479, 96.390, 886.0, 29.7658
59.787269610, 96.390, 857.0, 29.2746
59.839790740, 96.390, 851.0, 29.1719
59.892311871, 96.390, 798.0, 28.2489
59.944833002, 96.390, 875.0, 29.5804
59.997354133, 96.390, 899.0, 29.9833
60.049875263, 96.390, 852.0, 29.1890
60.102396394, 96.390, 861.0, 29.3428
60.154917525, 96.390, 981.0, 31.3209
60.207438655, 96.390, 855.0, 29.2404
60.259959786, 96.390, 950.0, 30.8221
60.312480917, 96.390, 879.0, 29.6479
60.365002048, 96.390, 951.0, 30.8383
60.417523178, 96.390, 1007.0, 31.7333
60.470044309, 96.390, 1023.0, 31.9844
60.522565440, 96.390, 1022.0, 31.9687
60.575086570, 96.390, 1074.0, 32.7719
60.627607701, 96.390, 1118.0, 33.4365
60.680128832, 96.390, 1210.0, 34.7851
60.732649963, 96.390, 1206.0, 34.7275
60.785171093, 96.390, 1215.0, 34.8569
60.837692224, 96.390, 1319.0, 36.3180
60.890213355, 96.390, 1263.0, 35.5387
60.942734485, 96.390, 1314.0, 36.2491
60.995255616, 96.390, 1302.0, 36.0832
61.047776747, 96.390, 1306.0, 36.1386
61.100297878, 96.390, 1265.0, 35.5668
61.152819008, 96.390, 1314.0, 36.2491
61.205340139, 96.390, 1303.0, 36.0971
61.257861270, 96.390, 1275.0, 35.7071
61.310382400, 96.390, 1218.0, 34.8999
61.362903531, 96.390, 1229.0, 35.0571
61.415424662, 96.390, 1123.0, 33.5112
61.467945792, 96.390, 1196.0, 34.5832
61.520466923, 96.390, 1208.0, 34.7563
61.572988054, 96.390, 1265.0, 35.5668
61.625509185, 96.390, 1166.0, 34.1467
61.678030315, 96.390, 1167.0, 34.1614
61.730551446, 96.390, 1149.0, 33.8969
61.783072577, 96.390, 1087.0, 32.9697
61.835593707, 96.390, 1163.0, 34.1028
61.888114838, 96.390, 1073.0, 32.7567
61.940635969, 96.390, 1116.0, 33.4066
61.993157100, 96.390, 1069.0, 32.6956
62.045678230, 96.390, 1121.0, 33.4813
62.098199361, 96.390, 1174.0, 34.2637
62.150720492, 96.390, 1071.0, 32.7261
62.203241622, 96.390, 1069.0, 32.6956
62.255762753, 96.390, 1156.0, 34.0000
62.308283884, 96.390, 1135.0, 33.6898
62.360805015, 96.390, 1092.0, 33.0454
62.413326145, 96.390, 1049.0, 32.3883
62.465847276, 96.390, 1051.0, 32.4191
62.518368407, 96.390, 1026.0, 32.0312
62.570889537, 96.390, 957.0, 30.9354
62.623410668, 96.390, 986.0, 31.4006
62.675931799, 96.390, 996.0, 31.5595
62.728452930, 96.390, 975.0, 31.2250
62.780974060, 96.390, 954.0, 30.8869
62.833495191, 96.390, 920.0, 30.3315
62.886016322, 96.390, 931.0, 30.5123
62.938537452, 96.390, 870.0, 29.4958
62.991058583, 96.390, 836.0, 28.9137
63.043579714, 96.390, 857.0, 29.2746
63.096100844, 96.390, 785.0, 28.0179
63.148621975, 96.390, 756.0, 27.4955
63.201143106, 96.390, 741.0, 27.2213
63.253664237, 96.390, 745.0, 27.2947
63.306185367, 96.390, 757.0, 27.5136
63.358706498, 96.390, 726.0, 26.9444
63.411227629, 96.390, 750.0, 27.3861
63.463748759, 96.390, 788.0, 28.0713
63.516269890, 96.390, 785.0, 28.0179
63.568791021, 96.390, 771.0, 27.7669
63.621312152, 96.390, 905.0, 30.0832
63.673833282, 96.390, 939.0, 30.6431
63.726354413, 96.390, 1077.0, 32.8177
63.778875544, 96.390, 1099.0, 33.1512
63.831396674, 96.390, 1231.0, 35.0856
63.883917805, 96.390, 1174.0, 34.2637
63.936438936, 96.390, 1106.0, 33.2566
63.988960067, 96.390, 1076.0, 32.8024
64.041481197, 96.390, 1035.0, 32.1714
64.094002328, 96.390, 964.0, 31.0483
64.146523459, 96.390, 888.0, 29.7993
64.199044589, 96.390, 923.0, 30.3809
64.251565720, 96.390, 1023.0, 31.9844
64.304086851, 96.390, 974.0, 31.2090
64.356607981, 96.390, 899.0, 29.9833
64.409129112, 96.390, 904.0, 30.0666
64.461650243, 96.390, 895.0, 29.9166
64.514171374, 96.390, 915.0, 30.2490
64.566692504, 96.390, 856.0, 29.2575
64.619213635, 96.390, 863.0, 29.3769
64.671734766, 96.390, 729.0, 27.0000
64.724255896, 96.390, 795.0, 28.1957
64.776777027, 96.390, 764.0, 27.6405
64.829298158, 96.390, 733.0, 27.0740
64.881819289, 96.390, 698.0, 26.4197
64.934340419, 96.390, 696.0, 26.3818
64.986861550, 96.390, 729.0, 27.0000