File: Files_organized_for_plots/Na_to_Al_1/XRD_MgAxial24Jan22_Act07Feb22_B2_0255M_NaOH_LS0146_1.csv
[Measurement conditions]
Sample identification,XRD_MgAxial24Jan22_Act07Feb22_B2_0255M_NaOH_LS0146_1
Comment - 1,"Configuration=Stage for Flat Samples/Holders, Owner=User-1, Creation date=7/1/2020 9:53:24 AM"
Comment - 2,"Goniometer=Theta/Theta; Minimum step size 2Theta:0.0001; Minimum step size Omega:0.0001"
Comment - 3,"Sample stage=Stage for flat samples/holders"
Comment - 4,"Diffractometer system=EMPYREAN"
Comment - 5,"Measurement program=C:\Users\ibo5034\OneDrive - The Pennsylvania State University\NEUP - Reed, Titus's files\XRD\Cement\Zerobackground scan.xrdmp, Identifier={98A3B11C-88F9-4AA6-982C-73314A311EF5}"
Anode material,Cu
K-Alpha1 wavelength,1.5405980
K-Alpha2 wavelength,1.5444260
Ratio K-Alpha2/K-Alpha1,0.500
Divergence slit,Fixed,0.25
Monochromator used,NO
Generator voltage, 45
Tube current, 40
File date and time,10/Feb/2022 13:19
Unit cell,
h k l, 0 0 0
Scan axis,Gonio
Scan range,4.994599997,64.999991833
Scan step size,0.0262606
No. of points, 2285
Scan type,CONTINUOUS
Time per step,96.390
[Scan points]
Angle, TimePerStep, Intensity, ESD
5.007730280, 96.390, 6727.0, 82.0183
5.060251411, 96.390, 6531.0, 80.8146
5.112772541, 96.390, 6592.0, 81.1911
5.165293672, 96.390, 6409.0, 80.0562
5.217814803, 96.390, 6458.0, 80.3617
5.270335934, 96.390, 6285.0, 79.2780
5.322857064, 96.390, 6206.0, 78.7782
5.375378195, 96.390, 6150.0, 78.4219
5.427899326, 96.390, 5957.0, 77.1816
5.480420456, 96.390, 6030.0, 77.6531
5.532941587, 96.390, 5901.0, 76.8180
5.585462718, 96.390, 5994.0, 77.4209
5.637983849, 96.390, 5968.0, 77.2528
5.690504979, 96.390, 5787.0, 76.0723
5.743026110, 96.390, 5732.0, 75.7100
5.795547241, 96.390, 5702.0, 75.5116
5.848068371, 96.390, 5680.0, 75.3658
5.900589502, 96.390, 5649.0, 75.1598
5.953110633, 96.390, 5656.0, 75.2064
6.005631763, 96.390, 5511.0, 74.2361
6.058152894, 96.390, 5610.0, 74.8999
6.110674025, 96.390, 5483.0, 74.0473
6.163195156, 96.390, 5419.0, 73.6139
6.215716286, 96.390, 5458.0, 73.8783
6.268237417, 96.390, 5332.0, 73.0205
6.320758548, 96.390, 5354.0, 73.1710
6.373279678, 96.390, 5316.0, 72.9109
6.425800809, 96.390, 5379.0, 73.3417
6.478321940, 96.390, 5313.0, 72.8903
6.530843071, 96.390, 5275.0, 72.6292
6.583364201, 96.390, 5123.0, 71.5751
6.635885332, 96.390, 5140.0, 71.6938
6.688406463, 96.390, 5013.0, 70.8025
6.740927593, 96.390, 4963.0, 70.4486
6.793448724, 96.390, 5097.0, 71.3933
6.845969855, 96.390, 5018.0, 70.8378
6.898490986, 96.390, 4994.0, 70.6682
6.951012116, 96.390, 4817.0, 69.4046
7.003533247, 96.390, 4899.0, 69.9929
7.056054378, 96.390, 4856.0, 69.6850
7.108575508, 96.390, 4790.0, 69.2098
7.161096639, 96.390, 4850.0, 69.6419
7.213617770, 96.390, 4770.0, 69.0652
7.266138900, 96.390, 4720.0, 68.7023
7.318660031, 96.390, 4806.0, 69.3253
7.371181162, 96.390, 4823.0, 69.4478
7.423702293, 96.390, 4692.0, 68.4982
7.476223423, 96.390, 4805.0, 69.3181
7.528744554, 96.390, 4651.0, 68.1982
7.581265685, 96.390, 4634.0, 68.0735
7.633786815, 96.390, 4674.0, 68.3667
7.686307946, 96.390, 4648.0, 68.1762
7.738829077, 96.390, 4529.0, 67.2978
7.791350208, 96.390, 4432.0, 66.5733
7.843871338, 96.390, 4516.0, 67.2012
7.896392469, 96.390, 4521.0, 67.2384
7.948913600, 96.390, 4452.0, 66.7233
8.001434730, 96.390, 4486.0, 66.9776
8.053955861, 96.390, 4444.0, 66.6633
8.106476992, 96.390, 4438.0, 66.6183
8.158998123, 96.390, 4406.0, 66.3777
8.211519253, 96.390, 4277.0, 65.3988
8.264040384, 96.390, 4251.0, 65.1997
8.316561515, 96.390, 4245.0, 65.1537
8.369082645, 96.390, 4467.0, 66.8356
8.421603776, 96.390, 4276.0, 65.3911
8.474124907, 96.390, 4366.0, 66.0757
8.526646038, 96.390, 4224.0, 64.9923
8.579167168, 96.390, 4231.0, 65.0461
8.631688299, 96.390, 4366.0, 66.0757
8.684209430, 96.390, 4236.0, 65.0846
8.736730560, 96.390, 4278.0, 65.4064
8.789251691, 96.390, 4350.0, 65.9545
8.841772822, 96.390, 4127.0, 64.2417
8.894293952, 96.390, 4057.0, 63.6946
8.946815083, 96.390, 4187.0, 64.7070
8.999336214, 96.390, 4048.0, 63.6239
9.051857345, 96.390, 4316.0, 65.6963
9.104378475, 96.390, 4268.0, 65.3299
9.156899606, 96.390, 4218.0, 64.9461
9.209420737, 96.390, 4129.0, 64.2573
9.261941867, 96.390, 3946.0, 62.8172
9.314462998, 96.390, 4088.0, 63.9375
9.366984129, 96.390, 4078.0, 63.8592
9.419505260, 96.390, 4104.0, 64.0625
9.472026390, 96.390, 4092.0, 63.9687
9.524547521, 96.390, 4047.0, 63.6160
9.577068652, 96.390, 4021.0, 63.4114
9.629589782, 96.390, 4111.0, 64.1171
9.682110913, 96.390, 4044.0, 63.5925
9.734632044, 96.390, 4123.0, 64.2106
9.787153175, 96.390, 4063.0, 63.7417
9.839674305, 96.390, 3974.0, 63.0397
9.892195436, 96.390, 4105.0, 64.0703
9.944716567, 96.390, 4018.0, 63.3877
9.997237697, 96.390, 4027.0, 63.4586
10.049758828, 96.390, 3936.0, 62.7375
10.102279959, 96.390, 3925.0, 62.6498
10.154801090, 96.390, 3943.0, 62.7933
10.207322220, 96.390, 4001.0, 63.2535
10.259843351, 96.390, 3807.0, 61.7009
10.312364482, 96.390, 3950.0, 62.8490
10.364885612, 96.390, 3932.0, 62.7057
10.417406743, 96.390, 3810.0, 61.7252
10.469927874, 96.390, 3829.0, 61.8789
10.522449004, 96.390, 3825.0, 61.8466
10.574970135, 96.390, 3746.0, 61.2046
10.627491266, 96.390, 3677.0, 60.6383
10.680012397, 96.390, 3832.0, 61.9032
10.732533527, 96.390, 3867.0, 62.1852
10.785054658, 96.390, 3829.0, 61.8789
10.837575789, 96.390, 3797.0, 61.6198
10.890096919, 96.390, 3745.0, 61.1964
10.942618050, 96.390, 3780.0, 61.4817
10.995139181, 96.390, 3605.0, 60.0417
11.047660312, 96.390, 3855.0, 62.0886
11.100181442, 96.390, 3775.0, 61.4410
11.152702573, 96.390, 3687.0, 60.7207
11.205223704, 96.390, 3714.0, 60.9426
11.257744834, 96.390, 3564.0, 59.6992
11.310265965, 96.390, 3583.0, 59.8582
11.362787096, 96.390, 3577.0, 59.8080
11.415308227, 96.390, 3781.0, 61.4898
11.467829357, 96.390, 3543.0, 59.5231
11.520350488, 96.390, 3542.0, 59.5147
11.572871619, 96.390, 3398.0, 58.2924
11.625392749, 96.390, 3556.0, 59.6322
11.677913880, 96.390, 3471.0, 58.9152
11.730435011, 96.390, 3421.0, 58.4893
11.782956141, 96.390, 3436.0, 58.6174
11.835477272, 96.390, 3400.0, 58.3095
11.887998403, 96.390, 3439.0, 58.6430
11.940519534, 96.390, 3326.0, 57.6715
11.993040664, 96.390, 3396.0, 58.2752
12.045561795, 96.390, 3275.0, 57.2276
12.098082926, 96.390, 3270.0, 57.1839
12.150604056, 96.390, 3279.0, 57.2626
12.203125187, 96.390, 3175.0, 56.3471
12.255646318, 96.390, 3346.0, 57.8446
12.308167449, 96.390, 3296.0, 57.4108
12.360688579, 96.390, 3140.0, 56.0357
12.413209710, 96.390, 3188.0, 56.4624
12.465730841, 96.390, 3211.0, 56.6657
12.518251971, 96.390, 3109.0, 55.7584
12.570773102, 96.390, 3084.0, 55.5338
12.623294233, 96.390, 3119.0, 55.8480
12.675815364, 96.390, 3066.0, 55.3715
12.728336494, 96.390, 3048.0, 55.2087
12.780857625, 96.390, 2979.0, 54.5802
12.833378756, 96.390, 3017.0, 54.9272
12.885899886, 96.390, 2929.0, 54.1202
12.938421017, 96.390, 2820.0, 53.1037
12.990942148, 96.390, 2911.0, 53.9537
13.043463279, 96.390, 2953.0, 54.3415
13.095984409, 96.390, 2974.0, 54.5344
13.148505540, 96.390, 2907.0, 53.9166
13.201026671, 96.390, 2865.0, 53.5257
13.253547801, 96.390, 2822.0, 53.1225
13.306068932, 96.390, 2915.0, 53.9907
13.358590063, 96.390, 2751.0, 52.4500
13.411111193, 96.390, 2749.0, 52.4309
13.463632324, 96.390, 2774.0, 52.6688
13.516153455, 96.390, 2794.0, 52.8583
13.568674586, 96.390, 2690.0, 51.8652
13.621195716, 96.390, 2812.0, 53.0283
13.673716847, 96.390, 2864.0, 53.5164
13.726237978, 96.390, 2694.0, 51.9038
13.778759108, 96.390, 2684.0, 51.8073
13.831280239, 96.390, 2698.0, 51.9423
13.883801370, 96.390, 2640.0, 51.3809
13.936322501, 96.390, 2695.0, 51.9134
13.988843631, 96.390, 2664.0, 51.6140
14.041364762, 96.390, 2614.0, 51.1273
14.093885893, 96.390, 2668.0, 51.6527
14.146407023, 96.390, 2612.0, 51.1077
14.198928154, 96.390, 2581.0, 50.8035
14.251449285, 96.390, 2633.0, 51.3128
14.303970416, 96.390, 2513.0, 50.1298
14.356491546, 96.390, 2574.0, 50.7346
14.409012677, 96.390, 2582.0, 50.8134
14.461533808, 96.390, 2599.0, 50.9804
14.514054938, 96.390, 2565.0, 50.6458
14.566576069, 96.390, 2494.0, 49.9400
14.619097200, 96.390, 2493.0, 49.9300
14.671618331, 96.390, 2522.0, 50.2195
14.724139461, 96.390, 2571.0, 50.7050
14.776660592, 96.390, 2482.0, 49.8197
14.829181723, 96.390, 2459.0, 49.5883
14.881702853, 96.390, 2558.0, 50.5767
14.934223984, 96.390, 2394.0, 48.9285
14.986745115, 96.390, 2398.0, 48.9694
15.039266245, 96.390, 2375.0, 48.7340
15.091787376, 96.390, 2502.0, 50.0200
15.144308507, 96.390, 2299.0, 47.9479
15.196829638, 96.390, 2465.0, 49.6488
15.249350768, 96.390, 2456.0, 49.5580
15.301871899, 96.390, 2480.0, 49.7996
15.354393030, 96.390, 2382.0, 48.8057
15.406914160, 96.390, 2323.0, 48.1975
15.459435291, 96.390, 2430.0, 49.2950
15.511956422, 96.390, 2368.0, 48.6621
15.564477553, 96.390, 2507.0, 50.0700
15.616998683, 96.390, 2378.0, 48.7647
15.669519814, 96.390, 2431.0, 49.3052
15.722040945, 96.390, 2343.0, 48.4045
15.774562075, 96.390, 2412.0, 49.1121
15.827083206, 96.390, 2346.0, 48.4355
15.879604337, 96.390, 2377.0, 48.7545
15.932125468, 96.390, 2262.0, 47.5605
15.984646598, 96.390, 2375.0, 48.7340
16.037167729, 96.390, 2390.0, 48.8876
16.089688860, 96.390, 2320.0, 48.1664
16.142209990, 96.390, 2435.0, 49.3457
16.194731121, 96.390, 2279.0, 47.7389
16.247252252, 96.390, 2387.0, 48.8569
16.299773382, 96.390, 2325.0, 48.2183
16.352294513, 96.390, 2363.0, 48.6107
16.404815644, 96.390, 2398.0, 48.9694
16.457336775, 96.390, 2362.0, 48.6004
16.509857905, 96.390, 2303.0, 47.9896
16.562379036, 96.390, 2352.0, 48.4974
16.614900167, 96.390, 2420.0, 49.1935
16.667421297, 96.390, 2313.0, 48.0937
16.719942428, 96.390, 2370.0, 48.6826
16.772463559, 96.390, 2296.0, 47.9166
16.824984690, 96.390, 2289.0, 47.8435
16.877505820, 96.390, 2375.0, 48.7340
16.930026951, 96.390, 2329.0, 48.2597
16.982548082, 96.390, 2304.0, 48.0000
17.035069212, 96.390, 2390.0, 48.8876
17.087590343, 96.390, 2363.0, 48.6107
17.140111474, 96.390, 2344.0, 48.4149
17.192632605, 96.390, 2305.0, 48.0104
17.245153735, 96.390, 2325.0, 48.2183
17.297674866, 96.390, 2362.0, 48.6004
17.350195997, 96.390, 2383.0, 48.8160
17.402717127, 96.390, 2382.0, 48.8057
17.455238258, 96.390, 2403.0, 49.0204
17.507759389, 96.390, 2380.0, 48.7852
17.560280520, 96.390, 2435.0, 49.3457
17.612801650, 96.390, 2343.0, 48.4045
17.665322781, 96.390, 2404.0, 49.0306
17.717843912, 96.390, 2357.0, 48.5489
17.770365042, 96.390, 2433.0, 49.3254
17.822886173, 96.390, 2358.0, 48.5592
17.875407304, 96.390, 2510.0, 50.0999
17.927928434, 96.390, 2340.0, 48.3735
17.980449565, 96.390, 2416.0, 49.1528
18.032970696, 96.390, 2498.0, 49.9800
18.085491827, 96.390, 2497.0, 49.9700
18.138012957, 96.390, 2433.0, 49.3254
18.190534088, 96.390, 2417.0, 49.1630
18.243055219, 96.390, 2489.0, 49.8899
18.295576349, 96.390, 2401.0, 49.0000
18.348097480, 96.390, 2422.0, 49.2138
18.400618611, 96.390, 2539.0, 50.3885
18.453139742, 96.390, 2495.0, 49.9500
18.505660872, 96.390, 2440.0, 49.3964
18.558182003, 96.390, 2484.0, 49.8397
18.610703134, 96.390, 2537.0, 50.3686
18.663224264, 96.390, 2631.0, 51.2933
18.715745395, 96.390, 2462.0, 49.6185
18.768266526, 96.390, 2572.0, 50.7149
18.820787657, 96.390, 2559.0, 50.5866
18.873308787, 96.390, 2535.0, 50.3488
18.925829918, 96.390, 2482.0, 49.8197
18.978351049, 96.390, 2570.0, 50.6952
19.030872179, 96.390, 2562.0, 50.6162
19.083393310, 96.390, 2550.0, 50.4975
19.135914441, 96.390, 2600.0, 50.9902
19.188435572, 96.390, 2591.0, 50.9019
19.240956702, 96.390, 2475.0, 49.7494
19.293477833, 96.390, 2588.0, 50.8724
19.345998964, 96.390, 2572.0, 50.7149
19.398520094, 96.390, 2633.0, 51.3128
19.451041225, 96.390, 2720.0, 52.1536
19.503562356, 96.390, 2605.0, 51.0392
19.556083486, 96.390, 2652.0, 51.4976
19.608604617, 96.390, 2684.0, 51.8073
19.661125748, 96.390, 2708.0, 52.0384
19.713646879, 96.390, 2699.0, 51.9519
19.766168009, 96.390, 2705.0, 52.0096
19.818689140, 96.390, 2793.0, 52.8488
19.871210271, 96.390, 2699.0, 51.9519
19.923731401, 96.390, 2654.0, 51.5170
19.976252532, 96.390, 2668.0, 51.6527
20.028773663, 96.390, 2626.0, 51.2445
20.081294794, 96.390, 2755.0, 52.4881
20.133815924, 96.390, 2779.0, 52.7162
20.186337055, 96.390, 2742.0, 52.3641
20.238858186, 96.390, 2810.0, 53.0094
20.291379316, 96.390, 2802.0, 52.9339
20.343900447, 96.390, 2778.0, 52.7067
20.396421578, 96.390, 2810.0, 53.0094
20.448942709, 96.390, 2853.0, 53.4135
20.501463839, 96.390, 2751.0, 52.4500
20.553984970, 96.390, 2860.0, 53.4790
20.606506101, 96.390, 2866.0, 53.5350
20.659027231, 96.390, 2852.0, 53.4041
20.711548362, 96.390, 2798.0, 52.8961
20.764069493, 96.390, 2796.0, 52.8772
20.816590623, 96.390, 2884.0, 53.7029
20.869111754, 96.390, 2887.0, 53.7308
20.921632885, 96.390, 2779.0, 52.7162
20.974154016, 96.390, 2822.0, 53.1225
21.026675146, 96.390, 2827.0, 53.1695
21.079196277, 96.390, 2938.0, 54.2033
21.131717408, 96.390, 2923.0, 54.0648
21.184238538, 96.390, 2899.0, 53.8424
21.236759669, 96.390, 2889.0, 53.7494
21.289280800, 96.390, 3008.0, 54.8452
21.341801931, 96.390, 2904.0, 53.8888
21.394323061, 96.390, 2964.0, 54.4426
21.446844192, 96.390, 3064.0, 55.3534
21.499365323, 96.390, 2817.0, 53.0754
21.551886453, 96.390, 2998.0, 54.7540
21.604407584, 96.390, 2995.0, 54.7266
21.656928715, 96.390, 2953.0, 54.3415
21.709449846, 96.390, 2943.0, 54.2494
21.761970976, 96.390, 2987.0, 54.6535
21.814492107, 96.390, 3024.0, 54.9909
21.867013238, 96.390, 2962.0, 54.4243
21.919534368, 96.390, 3003.0, 54.7996
21.972055499, 96.390, 2981.0, 54.5985
22.024576630, 96.390, 3066.0, 55.3715
22.077097761, 96.390, 3028.0, 55.0273
22.129618891, 96.390, 2985.0, 54.6352
22.182140022, 96.390, 3046.0, 55.1906
22.234661153, 96.390, 2932.0, 54.1479
22.287182283, 96.390, 3078.0, 55.4797
22.339703414, 96.390, 3027.0, 55.0182
22.392224545, 96.390, 2990.0, 54.6809
22.444745675, 96.390, 2968.0, 54.4794
22.497266806, 96.390, 3018.0, 54.9363
22.549787937, 96.390, 3036.0, 55.0999
22.602309068, 96.390, 3064.0, 55.3534
22.654830198, 96.390, 3131.0, 55.9553
22.707351329, 96.390, 3085.0, 55.5428
22.759872460, 96.390, 3022.0, 54.9727
22.812393590, 96.390, 2986.0, 54.6443
22.864914721, 96.390, 2932.0, 54.1479
22.917435852, 96.390, 3051.0, 55.2359
22.969956983, 96.390, 3047.0, 55.1996
23.022478113, 96.390, 3015.0, 54.9090
23.074999244, 96.390, 2989.0, 54.6717
23.127520375, 96.390, 2915.0, 53.9907
23.180041505, 96.390, 2888.0, 53.7401
23.232562636, 96.390, 2966.0, 54.4610
23.285083767, 96.390, 2942.0, 54.2402
23.337604898, 96.390, 2954.0, 54.3507
23.390126028, 96.390, 2953.0, 54.3415
23.442647159, 96.390, 2790.0, 52.8205
23.495168290, 96.390, 2873.0, 53.6004
23.547689420, 96.390, 2960.0, 54.4059
23.600210551, 96.390, 2790.0, 52.8205
23.652731682, 96.390, 2826.0, 53.1601
23.705252813, 96.390, 2864.0, 53.5164
23.757773943, 96.390, 2904.0, 53.8888
23.810295074, 96.390, 2837.0, 53.2635
23.862816205, 96.390, 2855.0, 53.4322
23.915337335, 96.390, 2873.0, 53.6004
23.967858466, 96.390, 2803.0, 52.9434
24.020379597, 96.390, 2876.0, 53.6284
24.072900727, 96.390, 2793.0, 52.8488
24.125421858, 96.390, 2799.0, 52.9056
24.177942989, 96.390, 2770.0, 52.6308
24.230464120, 96.390, 2663.0, 51.6043
24.282985250, 96.390, 2734.0, 52.2877
24.335506381, 96.390, 2776.0, 52.6878
24.388027512, 96.390, 2697.0, 51.9326
24.440548642, 96.390, 2690.0, 51.8652
24.493069773, 96.390, 2703.0, 51.9904
24.545590904, 96.390, 2768.0, 52.6118
24.598112035, 96.390, 2640.0, 51.3809
24.650633165, 96.390, 2583.0, 50.8232
24.703154296, 96.390, 2670.0, 51.6720
24.755675427, 96.390, 2711.0, 52.0673
24.808196557, 96.390, 2664.0, 51.6140
24.860717688, 96.390, 2602.0, 51.0098
24.913238819, 96.390, 2602.0, 51.0098
24.965759950, 96.390, 2694.0, 51.9038
25.018281080, 96.390, 2563.0, 50.6261
25.070802211, 96.390, 2543.0, 50.4282
25.123323342, 96.390, 2558.0, 50.5767
25.175844472, 96.390, 2504.0, 50.0400
25.228365603, 96.390, 2577.0, 50.7642
25.280886734, 96.390, 2516.0, 50.1597
25.333407864, 96.390, 2526.0, 50.2593
25.385928995, 96.390, 2532.0, 50.3190
25.438450126, 96.390, 2554.0, 50.5371
25.490971257, 96.390, 2463.0, 49.6286
25.543492387, 96.390, 2422.0, 49.2138
25.596013518, 96.390, 2418.0, 49.1732
25.648534649, 96.390, 2554.0, 50.5371
25.701055779, 96.390, 2501.0, 50.0100
25.753576910, 96.390, 2424.0, 49.2341
25.806098041, 96.390, 2414.0, 49.1325
25.858619172, 96.390, 2413.0, 49.1223
25.911140302, 96.390, 2386.0, 48.8467
25.963661433, 96.390, 2381.0, 48.7955
26.016182564, 96.390, 2413.0, 49.1223
26.068703694, 96.390, 2423.0, 49.2240
26.121224825, 96.390, 2345.0, 48.4252
26.173745956, 96.390, 2397.0, 48.9592
26.226267087, 96.390, 2337.0, 48.3425
26.278788217, 96.390, 2401.0, 49.0000
26.331309348, 96.390, 2361.0, 48.5901
26.383830479, 96.390, 2402.0, 49.0102
26.436351609, 96.390, 2393.0, 48.9183
26.488872740, 96.390, 2323.0, 48.1975
26.541393871, 96.390, 2372.0, 48.7032
26.593915002, 96.390, 2292.0, 47.8748
26.646436132, 96.390, 2336.0, 48.3322
26.698957263, 96.390, 2263.0, 47.5710
26.751478394, 96.390, 2461.0, 49.6085
26.803999524, 96.390, 2319.0, 48.1560
26.856520655, 96.390, 2261.0, 47.5500
26.909041786, 96.390, 2458.0, 49.5782
26.961562916, 96.390, 2232.0, 47.2440
27.014084047, 96.390, 2340.0, 48.3735
27.066605178, 96.390, 2319.0, 48.1560
27.119126309, 96.390, 2335.0, 48.3218
27.171647439, 96.390, 2402.0, 49.0102
27.224168570, 96.390, 2390.0, 48.8876
27.276689701, 96.390, 2343.0, 48.4045
27.329210831, 96.390, 2382.0, 48.8057
27.381731962, 96.390, 2288.0, 47.8330
27.434253093, 96.390, 2272.0, 47.6655
27.486774224, 96.390, 2342.0, 48.3942
27.539295354, 96.390, 2337.0, 48.3425
27.591816485, 96.390, 2307.0, 48.0312
27.644337616, 96.390, 2223.0, 47.1487
27.696858746, 96.390, 2289.0, 47.8435
27.749379877, 96.390, 2283.0, 47.7807
27.801901008, 96.390, 2320.0, 48.1664
27.854422139, 96.390, 2339.0, 48.3632
27.906943269, 96.390, 2301.0, 47.9687
27.959464400, 96.390, 2305.0, 48.0104
28.011985531, 96.390, 2290.0, 47.8539
28.064506661, 96.390, 2291.0, 47.8644
28.117027792, 96.390, 2253.0, 47.4658
28.169548923, 96.390, 2357.0, 48.5489
28.222070054, 96.390, 2215.0, 47.0638
28.274591184, 96.390, 2340.0, 48.3735
28.327112315, 96.390, 2242.0, 47.3498
28.379633446, 96.390, 2268.0, 47.6235
28.432154576, 96.390, 2249.0, 47.4236
28.484675707, 96.390, 2240.0, 47.3286
28.537196838, 96.390, 2279.0, 47.7389
28.589717968, 96.390, 2223.0, 47.1487
28.642239099, 96.390, 2230.0, 47.2229
28.694760230, 96.390, 2253.0, 47.4658
28.747281361, 96.390, 2298.0, 47.9375
28.799802491, 96.390, 2303.0, 47.9896
28.852323622, 96.390, 2322.0, 48.1871
28.904844753, 96.390, 2309.0, 48.0521
28.957365883, 96.390, 2209.0, 47.0000
29.009887014, 96.390, 2224.0, 47.1593
29.062408145, 96.390, 2174.0, 46.6262
29.114929276, 96.390, 2282.0, 47.7703
29.167450406, 96.390, 2280.0, 47.7493
29.219971537, 96.390, 2340.0, 48.3735
29.272492668, 96.390, 2230.0, 47.2229
29.325013798, 96.390, 2149.0, 46.3573
29.377534929, 96.390, 2236.0, 47.2864
29.430056060, 96.390, 2196.0, 46.8615
29.482577191, 96.390, 2280.0, 47.7493
29.535098321, 96.390, 2239.0, 47.3181
29.587619452, 96.390, 2174.0, 46.6262
29.640140583, 96.390, 2225.0, 47.1699
29.692661713, 96.390, 2245.0, 47.3814
29.745182844, 96.390, 2190.0, 46.7974
29.797703975, 96.390, 2206.0, 46.9681
29.850225105, 96.390, 2236.0, 47.2864
29.902746236, 96.390, 2147.0, 46.3357
29.955267367, 96.390, 2247.0, 47.4025
30.007788498, 96.390, 2231.0, 47.2335
30.060309628, 96.390, 2287.0, 47.8226
30.112830759, 96.390, 2143.0, 46.2925
30.165351890, 96.390, 2217.0, 47.0850
30.217873020, 96.390, 2221.0, 47.1275
30.270394151, 96.390, 2153.0, 46.4004
30.322915282, 96.390, 2251.0, 47.4447
30.375436413, 96.390, 2163.0, 46.5081
30.427957543, 96.390, 2243.0, 47.3603
30.480478674, 96.390, 2127.0, 46.1194
30.532999805, 96.390, 2240.0, 47.3286
30.585520935, 96.390, 2186.0, 46.7547
30.638042066, 96.390, 2164.0, 46.5188
30.690563197, 96.390, 2233.0, 47.2546
30.743084328, 96.390, 2146.0, 46.3249
30.795605458, 96.390, 2106.0, 45.8912
30.848126589, 96.390, 2106.0, 45.8912
30.900647720, 96.390, 2180.0, 46.6905
30.953168850, 96.390, 2166.0, 46.5403
31.005689981, 96.390, 2130.0, 46.1519
31.058211112, 96.390, 2077.0, 45.5741
31.110732243, 96.390, 2170.0, 46.5833
31.163253373, 96.390, 2120.0, 46.0435
31.215774504, 96.390, 2060.0, 45.3872
31.268295635, 96.390, 2178.0, 46.6690
31.320816765, 96.390, 2043.0, 45.1996
31.373337896, 96.390, 2124.0, 46.0869
31.425859027, 96.390, 2085.0, 45.6618
31.478380157, 96.390, 2075.0, 45.5522
31.530901288, 96.390, 2115.0, 45.9891
31.583422419, 96.390, 2162.0, 46.4973
31.635943550, 96.390, 2087.0, 45.6837
31.688464680, 96.390, 2108.0, 45.9130
31.740985811, 96.390, 2105.0, 45.8803
31.793506942, 96.390, 2110.0, 45.9347
31.846028072, 96.390, 2068.0, 45.4753
31.898549203, 96.390, 2024.0, 44.9889
31.951070334, 96.390, 2054.0, 45.3211
32.003591465, 96.390, 2170.0, 46.5833
32.056112595, 96.390, 2035.0, 45.1110
32.108633726, 96.390, 2117.0, 46.0109
32.161154857, 96.390, 2122.0, 46.0652
32.213675987, 96.390, 2163.0, 46.5081
32.266197118, 96.390, 2073.0, 45.5302
32.318718249, 96.390, 2031.0, 45.0666
32.371239380, 96.390, 2053.0, 45.3100
32.423760510, 96.390, 2114.0, 45.9783
32.476281641, 96.390, 2069.0, 45.4863
32.528802772, 96.390, 2112.0, 45.9565
32.581323902, 96.390, 2071.0, 45.5082
32.633845033, 96.390, 2099.0, 45.8148
32.686366164, 96.390, 1995.0, 44.6654
32.738887295, 96.390, 2049.0, 45.2659
32.791408425, 96.390, 2080.0, 45.6070
32.843929556, 96.390, 1987.0, 44.5758
32.896450687, 96.390, 2081.0, 45.6180
32.948971817, 96.390, 2057.0, 45.3542
33.001492948, 96.390, 2022.0, 44.9667
33.054014079, 96.390, 2017.0, 44.9110
33.106535209, 96.390, 2026.0, 45.0111
33.159056340, 96.390, 2013.0, 44.8665
33.211577471, 96.390, 2064.0, 45.4313
33.264098602, 96.390, 2088.0, 45.6946
33.316619732, 96.390, 2000.0, 44.7214
33.369140863, 96.390, 1990.0, 44.6094
33.421661994, 96.390, 2102.0, 45.8476
33.474183124, 96.390, 2050.0, 45.2769
33.526704255, 96.390, 2056.0, 45.3431
33.579225386, 96.390, 2115.0, 45.9891
33.631746517, 96.390, 2119.0, 46.0326
33.684267647, 96.390, 2029.0, 45.0444
33.736788778, 96.390, 2073.0, 45.5302
33.789309909, 96.390, 2134.0, 46.1952
33.841831039, 96.390, 2190.0, 46.7974
33.894352170, 96.390, 2113.0, 45.9674
33.946873301, 96.390, 2149.0, 46.3573
33.999394432, 96.390, 2220.0, 47.1169
34.051915562, 96.390, 2158.0, 46.4543
34.104436693, 96.390, 2212.0, 47.0319
34.156957824, 96.390, 2162.0, 46.4973
34.209478954, 96.390, 2308.0, 48.0416
34.262000085, 96.390, 2230.0, 47.2229
34.314521216, 96.390, 2246.0, 47.3920
34.367042346, 96.390, 2386.0, 48.8467
34.419563477, 96.390, 2298.0, 47.9375
34.472084608, 96.390, 2346.0, 48.4355
34.524605739, 96.390, 2409.0, 49.0816
34.577126869, 96.390, 2263.0, 47.5710
34.629648000, 96.390, 2370.0, 48.6826
34.682169131, 96.390, 2351.0, 48.4871
34.734690261, 96.390, 2354.0, 48.5180
34.787211392, 96.390, 2375.0, 48.7340
34.839732523, 96.390, 2520.0, 50.1996
34.892253654, 96.390, 2362.0, 48.6004
34.944774784, 96.390, 2482.0, 49.8197
34.997295915, 96.390, 2454.0, 49.5379
35.049817046, 96.390, 2484.0, 49.8397
35.102338176, 96.390, 2405.0, 49.0408
35.154859307, 96.390, 2393.0, 48.9183
35.207380438, 96.390, 2353.0, 48.5077
35.259901569, 96.390, 2381.0, 48.7955
35.312422699, 96.390, 2402.0, 49.0102
35.364943830, 96.390, 2329.0, 48.2597
35.417464961, 96.390, 2357.0, 48.5489
35.469986091, 96.390, 2257.0, 47.5079
35.522507222, 96.390, 2368.0, 48.6621
35.575028353, 96.390, 2350.0, 48.4768
35.627549484, 96.390, 2321.0, 48.1768
35.680070614, 96.390, 2314.0, 48.1041
35.732591745, 96.390, 2296.0, 47.9166
35.785112876, 96.390, 2277.0, 47.7179
35.837634006, 96.390, 2283.0, 47.7807
35.890155137, 96.390, 2316.0, 48.1248
35.942676268, 96.390, 2185.0, 46.7440
35.995197398, 96.390, 2244.0, 47.3709
36.047718529, 96.390, 2185.0, 46.7440
36.100239660, 96.390, 2170.0, 46.5833
36.152760791, 96.390, 2186.0, 46.7547
36.205281921, 96.390, 2302.0, 47.9792
36.257803052, 96.390, 2235.0, 47.2758
36.310324183, 96.390, 2142.0, 46.2817
36.362845313, 96.390, 2164.0, 46.5188
36.415366444, 96.390, 2145.0, 46.3141
36.467887575, 96.390, 2076.0, 45.5631
36.520408706, 96.390, 2196.0, 46.8615
36.572929836, 96.390, 2116.0, 46.0000
36.625450967, 96.390, 2137.0, 46.2277
36.677972098, 96.390, 2136.0, 46.2169
36.730493228, 96.390, 2182.0, 46.7119
36.783014359, 96.390, 2086.0, 45.6727
36.835535490, 96.390, 2145.0, 46.3141
36.888056621, 96.390, 1988.0, 44.5870
36.940577751, 96.390, 2044.0, 45.2106
36.993098882, 96.390, 1992.0, 44.6318
37.045620013, 96.390, 2003.0, 44.7549
37.098141143, 96.390, 2006.0, 44.7884
37.150662274, 96.390, 2004.0, 44.7661
37.203183405, 96.390, 1968.0, 44.3621
37.255704535, 96.390, 1969.0, 44.3734
37.308225666, 96.390, 1983.0, 44.5309
37.360746797, 96.390, 1957.0, 44.2380
37.413267928, 96.390, 1943.0, 44.0795
37.465789058, 96.390, 1917.0, 43.7836
37.518310189, 96.390, 1966.0, 44.3396
37.570831320, 96.390, 1897.0, 43.5546
37.623352450, 96.390, 1945.0, 44.1022
37.675873581, 96.390, 1991.0, 44.6206
37.728394712, 96.390, 1930.0, 43.9318
37.780915843, 96.390, 1869.0, 43.2319
37.833436973, 96.390, 1987.0, 44.5758
37.885958104, 96.390, 1935.0, 43.9886
37.938479235, 96.390, 1810.0, 42.5441
37.991000365, 96.390, 1910.0, 43.7035
38.043521496, 96.390, 1922.0, 43.8406
38.096042627, 96.390, 1953.0, 44.1928
38.148563758, 96.390, 1931.0, 43.9431
38.201084888, 96.390, 1821.0, 42.6732
38.253606019, 96.390, 1768.0, 42.0476
38.306127150, 96.390, 1875.0, 43.3013
38.358648280, 96.390, 1826.0, 42.7317
38.411169411, 96.390, 1855.0, 43.0697
38.463690542, 96.390, 1789.0, 42.2966
38.516211673, 96.390, 1745.0, 41.7732
38.568732803, 96.390, 1726.0, 41.5452
38.621253934, 96.390, 1837.0, 42.8602
38.673775065, 96.390, 1842.0, 42.9185
38.726296195, 96.390, 1798.0, 42.4028
38.778817326, 96.390, 1747.0, 41.7971
38.831338457, 96.390, 1770.0, 42.0714
38.883859587, 96.390, 1810.0, 42.5441
38.936380718, 96.390, 1751.0, 41.8450
38.988901849, 96.390, 1756.0, 41.9047
39.041422980, 96.390, 1780.0, 42.1900
39.093944110, 96.390, 1805.0, 42.4853
39.146465241, 96.390, 1813.0, 42.5793
39.198986372, 96.390, 1735.0, 41.6533
39.251507502, 96.390, 1764.0, 42.0000
39.304028633, 96.390, 1687.0, 41.0731
39.356549764, 96.390, 1759.0, 41.9404
39.409070895, 96.390, 1718.0, 41.4488
39.461592025, 96.390, 1714.0, 41.4005
39.514113156, 96.390, 1697.0, 41.1947
39.566634287, 96.390, 1671.0, 40.8779
39.619155417, 96.390, 1705.0, 41.2916
39.671676548, 96.390, 1758.0, 41.9285
39.724197679, 96.390, 1712.0, 41.3763
39.776718810, 96.390, 1778.0, 42.1663
39.829239940, 96.390, 1744.0, 41.7612
39.881761071, 96.390, 1696.0, 41.1825
39.934282202, 96.390, 1673.0, 40.9023
39.986803332, 96.390, 1571.0, 39.6358
40.039324463, 96.390, 1623.0, 40.2865
40.091845594, 96.390, 1679.0, 40.9756
40.144366725, 96.390, 1654.0, 40.6694
40.196887855, 96.390, 1638.0, 40.4722
40.249408986, 96.390, 1580.0, 39.7492
40.301930117, 96.390, 1606.0, 40.0749
40.354451247, 96.390, 1582.0, 39.7744
40.406972378, 96.390, 1637.0, 40.4599
40.459493509, 96.390, 1626.0, 40.3237
40.512014639, 96.390, 1478.0, 38.4448
40.564535770, 96.390, 1580.0, 39.7492
40.617056901, 96.390, 1584.0, 39.7995
40.669578032, 96.390, 1516.0, 38.9358
40.722099162, 96.390, 1583.0, 39.7869
40.774620293, 96.390, 1629.0, 40.3609
40.827141424, 96.390, 1562.0, 39.5221
40.879662554, 96.390, 1513.0, 38.8973
40.932183685, 96.390, 1606.0, 40.0749
40.984704816, 96.390, 1546.0, 39.3192
41.037225947, 96.390, 1537.0, 39.2046
41.089747077, 96.390, 1610.0, 40.1248
41.142268208, 96.390, 1528.0, 39.0896
41.194789339, 96.390, 1476.0, 38.4187
41.247310469, 96.390, 1557.0, 39.4588
41.299831600, 96.390, 1516.0, 38.9358
41.352352731, 96.390, 1558.0, 39.4715
41.404873862, 96.390, 1453.0, 38.1182
41.457394992, 96.390, 1597.0, 39.9625
41.509916123, 96.390, 1520.0, 38.9872
41.562437254, 96.390, 1500.0, 38.7298
41.614958384, 96.390, 1512.0, 38.8844
41.667479515, 96.390, 1529.0, 39.1024
41.720000646, 96.390, 1431.0, 37.8286
41.772521776, 96.390, 1438.0, 37.9210
41.825042907, 96.390, 1496.0, 38.6782
41.877564038, 96.390, 1519.0, 38.9744
41.930085169, 96.390, 1493.0, 38.6394
41.982606299, 96.390, 1540.0, 39.2428
42.035127430, 96.390, 1491.0, 38.6135
42.087648561, 96.390, 1504.0, 38.7814
42.140169691, 96.390, 1494.0, 38.6523
42.192690822, 96.390, 1488.0, 38.5746
42.245211953, 96.390, 1465.0, 38.2753
42.297733084, 96.390, 1522.0, 39.0128
42.350254214, 96.390, 1419.0, 37.6696
42.402775345, 96.390, 1526.0, 39.0640
42.455296476, 96.390, 1378.0, 37.1214
42.507817606, 96.390, 1491.0, 38.6135
42.560338737, 96.390, 1502.0, 38.7556
42.612859868, 96.390, 1416.0, 37.6298
42.665380999, 96.390, 1428.0, 37.7889
42.717902129, 96.390, 1475.0, 38.4057
42.770423260, 96.390, 1507.0, 38.8201
42.822944391, 96.390, 1455.0, 38.1445
42.875465521, 96.390, 1547.0, 39.3319
42.927986652, 96.390, 1456.0, 38.1576
42.980507783, 96.390, 1455.0, 38.1445
43.033028914, 96.390, 1465.0, 38.2753
43.085550044, 96.390, 1414.0, 37.6032
43.138071175, 96.390, 1473.0, 38.3797
43.190592306, 96.390, 1484.0, 38.5227
43.243113436, 96.390, 1547.0, 39.3319
43.295634567, 96.390, 1439.0, 37.9342
43.348155698, 96.390, 1420.0, 37.6829
43.400676828, 96.390, 1461.0, 38.2230
43.453197959, 96.390, 1473.0, 38.3797
43.505719090, 96.390, 1512.0, 38.8844
43.558240221, 96.390, 1444.0, 38.0000
43.610761351, 96.390, 1422.0, 37.7094
43.663282482, 96.390, 1408.0, 37.5233
43.715803613, 96.390, 1397.0, 37.3765
43.768324743, 96.390, 1448.0, 38.0526
43.820845874, 96.390, 1367.0, 36.9730
43.873367005, 96.390, 1490.0, 38.6005
43.925888136, 96.390, 1424.0, 37.7359
43.978409266, 96.390, 1478.0, 38.4448
44.030930397, 96.390, 1401.0, 37.4299
44.083451528, 96.390, 1471.0, 38.3536
44.135972658, 96.390, 1422.0, 37.7094
44.188493789, 96.390, 1371.0, 37.0270
44.241014920, 96.390, 1412.0, 37.5766
44.293536051, 96.390, 1449.0, 38.0657
44.346057181, 96.390, 1346.0, 36.6879
44.398578312, 96.390, 1427.0, 37.7757
44.451099443, 96.390, 1505.0, 38.7943
44.503620573, 96.390, 1417.0, 37.6431
44.556141704, 96.390, 1448.0, 38.0526
44.608662835, 96.390, 1474.0, 38.3927
44.661183966, 96.390, 1480.0, 38.4708
44.713705096, 96.390, 1372.0, 37.0405
44.766226227, 96.390, 1473.0, 38.3797
44.818747358, 96.390, 1399.0, 37.4032
44.871268488, 96.390, 1400.0, 37.4166
44.923789619, 96.390, 1412.0, 37.5766
44.976310750, 96.390, 1382.0, 37.1753
45.028831880, 96.390, 1412.0, 37.5766
45.081353011, 96.390, 1427.0, 37.7757
45.133874142, 96.390, 1471.0, 38.3536
45.186395273, 96.390, 1418.0, 37.6563
45.238916403, 96.390, 1432.0, 37.8418
45.291437534, 96.390, 1372.0, 37.0405
45.343958665, 96.390, 1383.0, 37.1887
45.396479795, 96.390, 1445.0, 38.0132
45.449000926, 96.390, 1409.0, 37.5366
45.501522057, 96.390, 1434.0, 37.8682
45.554043188, 96.390, 1421.0, 37.6962
45.606564318, 96.390, 1295.0, 35.9861
45.659085449, 96.390, 1436.0, 37.8946
45.711606580, 96.390, 1450.0, 38.0789
45.764127710, 96.390, 1386.0, 37.2290
45.816648841, 96.390, 1480.0, 38.4708
45.869169972, 96.390, 1337.0, 36.5650
45.921691103, 96.390, 1433.0, 37.8550
45.974212233, 96.390, 1456.0, 38.1576
46.026733364, 96.390, 1385.0, 37.2156
46.079254495, 96.390, 1341.0, 36.6197
46.131775625, 96.390, 1378.0, 37.1214
46.184296756, 96.390, 1351.0, 36.7560
46.236817887, 96.390, 1358.0, 36.8511
46.289339017, 96.390, 1416.0, 37.6298
46.341860148, 96.390, 1382.0, 37.1753
46.394381279, 96.390, 1341.0, 36.6197
46.446902410, 96.390, 1383.0, 37.1887
46.499423540, 96.390, 1359.0, 36.8646
46.551944671, 96.390, 1315.0, 36.2629
46.604465802, 96.390, 1324.0, 36.3868
46.656986932, 96.390, 1432.0, 37.8418
46.709508063, 96.390, 1380.0, 37.1484
46.762029194, 96.390, 1415.0, 37.6165
46.814550325, 96.390, 1349.0, 36.7287
46.867071455, 96.390, 1403.0, 37.4566
46.919592586, 96.390, 1353.0, 36.7831
46.972113717, 96.390, 1370.0, 37.0135
47.024634847, 96.390, 1352.0, 36.7696
47.077155978, 96.390, 1319.0, 36.3180
47.129677109, 96.390, 1270.0, 35.6371
47.182198240, 96.390, 1349.0, 36.7287
47.234719370, 96.390, 1327.0, 36.4280
47.287240501, 96.390, 1347.0, 36.7015
47.339761632, 96.390, 1349.0, 36.7287
47.392282762, 96.390, 1370.0, 37.0135
47.444803893, 96.390, 1362.0, 36.9053
47.497325024, 96.390, 1316.0, 36.2767
47.549846155, 96.390, 1274.0, 35.6931
47.602367285, 96.390, 1273.0, 35.6791
47.654888416, 96.390, 1301.0, 36.0694
47.707409547, 96.390, 1274.0, 35.6931
47.759930677, 96.390, 1292.0, 35.9444
47.812451808, 96.390, 1281.0, 35.7911
47.864972939, 96.390, 1273.0, 35.6791
47.917494069, 96.390, 1293.0, 35.9583
47.970015200, 96.390, 1263.0, 35.5387
48.022536331, 96.390, 1275.0, 35.7071
48.075057462, 96.390, 1346.0, 36.6879
48.127578592, 96.390, 1252.0, 35.3836
48.180099723, 96.390, 1283.0, 35.8190
48.232620854, 96.390, 1300.0, 36.0555
48.285141984, 96.390, 1245.0, 35.2846
48.337663115, 96.390, 1235.0, 35.1426
48.390184246, 96.390, 1205.0, 34.7131
48.442705377, 96.390, 1271.0, 35.6511
48.495226507, 96.390, 1257.0, 35.4542
48.547747638, 96.390, 1210.0, 34.7851
48.600268769, 96.390, 1276.0, 35.7211
48.652789899, 96.390, 1220.0, 34.9285
48.705311030, 96.390, 1291.0, 35.9305
48.757832161, 96.390, 1291.0, 35.9305
48.810353292, 96.390, 1267.0, 35.5949
48.862874422, 96.390, 1277.0, 35.7351
48.915395553, 96.390, 1225.0, 35.0000
48.967916684, 96.390, 1252.0, 35.3836
49.020437814, 96.390, 1268.0, 35.6090
49.072958945, 96.390, 1184.0, 34.4093
49.125480076, 96.390, 1236.0, 35.1568
49.178001207, 96.390, 1184.0, 34.4093
49.230522337, 96.390, 1213.0, 34.8281
49.283043468, 96.390, 1202.0, 34.6699
49.335564599, 96.390, 1179.0, 34.3366
49.388085729, 96.390, 1202.0, 34.6699
49.440606860, 96.390, 1203.0, 34.6843
49.493127991, 96.390, 1246.0, 35.2987
49.545649121, 96.390, 1217.0, 34.8855
49.598170252, 96.390, 1209.0, 34.7707
49.650691383, 96.390, 1209.0, 34.7707
49.703212514, 96.390, 1219.0, 34.9142
49.755733644, 96.390, 1247.0, 35.3129
49.808254775, 96.390, 1193.0, 34.5398
49.860775906, 96.390, 1101.0, 33.1813
49.913297036, 96.390, 1188.0, 34.4674
49.965818167, 96.390, 1187.0, 34.4529
50.018339298, 96.390, 1191.0, 34.5109
50.070860429, 96.390, 1171.0, 34.2199
50.123381559, 96.390, 1146.0, 33.8526
50.175902690, 96.390, 1181.0, 34.3657
50.228423821, 96.390, 1147.0, 33.8674
50.280944951, 96.390, 1147.0, 33.8674
50.333466082, 96.390, 1181.0, 34.3657
50.385987213, 96.390, 1127.0, 33.5708
50.438508344, 96.390, 1189.0, 34.4819
50.491029474, 96.390, 1112.0, 33.3467
50.543550605, 96.390, 1156.0, 34.0000
50.596071736, 96.390, 1124.0, 33.5261
50.648592866, 96.390, 1156.0, 34.0000
50.701113997, 96.390, 1117.0, 33.4215
50.753635128, 96.390, 1150.0, 33.9116
50.806156258, 96.390, 1159.0, 34.0441
50.858677389, 96.390, 1100.0, 33.1662
50.911198520, 96.390, 1111.0, 33.3317
50.963719651, 96.390, 1086.0, 32.9545
51.016240781, 96.390, 1162.0, 34.0881
51.068761912, 96.390, 1107.0, 33.2716
51.121283043, 96.390, 1107.0, 33.2716
51.173804173, 96.390, 1206.0, 34.7275
51.226325304, 96.390, 1087.0, 32.9697
51.278846435, 96.390, 1081.0, 32.8786
51.331367566, 96.390, 1069.0, 32.6956
51.383888696, 96.390, 1099.0, 33.1512
51.436409827, 96.390, 1163.0, 34.1028
51.488930958, 96.390, 1096.0, 33.1059
51.541452088, 96.390, 1110.0, 33.3167
51.593973219, 96.390, 1135.0, 33.6898
51.646494350, 96.390, 1092.0, 33.0454
51.699015481, 96.390, 1009.0, 31.7648
51.751536611, 96.390, 1116.0, 33.4066
51.804057742, 96.390, 1037.0, 32.2025
51.856578873, 96.390, 1104.0, 33.2265
51.909100003, 96.390, 1045.0, 32.3265
51.961621134, 96.390, 1064.0, 32.6190
52.014142265, 96.390, 1114.0, 33.3766
52.066663396, 96.390, 1047.0, 32.3574
52.119184526, 96.390, 1152.0, 33.9411
52.171705657, 96.390, 1037.0, 32.2025
52.224226788, 96.390, 1127.0, 33.5708
52.276747918, 96.390, 1081.0, 32.8786
52.329269049, 96.390, 1078.0, 32.8329
52.381790180, 96.390, 1082.0, 32.8938
52.434311310, 96.390, 1047.0, 32.3574
52.486832441, 96.390, 1073.0, 32.7567
52.539353572, 96.390, 1081.0, 32.8786
52.591874703, 96.390, 1060.0, 32.5576
52.644395833, 96.390, 1028.0, 32.0624
52.696916964, 96.390, 1037.0, 32.2025
52.749438095, 96.390, 1027.0, 32.0468
52.801959225, 96.390, 1101.0, 33.1813
52.854480356, 96.390, 1033.0, 32.1403
52.907001487, 96.390, 1064.0, 32.6190
52.959522618, 96.390, 1071.0, 32.7261
53.012043748, 96.390, 995.0, 31.5436
53.064564879, 96.390, 1083.0, 32.9090
53.117086010, 96.390, 1024.0, 32.0000
53.169607140, 96.390, 1052.0, 32.4345
53.222128271, 96.390, 1036.0, 32.1870
53.274649402, 96.390, 1021.0, 31.9531
53.327170533, 96.390, 1008.0, 31.7490
53.379691663, 96.390, 1032.0, 32.1248
53.432212794, 96.390, 1029.0, 32.0780
53.484733925, 96.390, 1062.0, 32.5883
53.537255055, 96.390, 1073.0, 32.7567
53.589776186, 96.390, 975.0, 31.2250
53.642297317, 96.390, 1001.0, 31.6386
53.694818448, 96.390, 1027.0, 32.0468
53.747339578, 96.390, 976.0, 31.2410
53.799860709, 96.390, 1107.0, 33.2716
53.852381840, 96.390, 1018.0, 31.9061
53.904902970, 96.390, 1020.0, 31.9374
53.957424101, 96.390, 1067.0, 32.6650
54.009945232, 96.390, 989.0, 31.4484
54.062466362, 96.390, 1013.0, 31.8277
54.114987493, 96.390, 985.0, 31.3847
54.167508624, 96.390, 994.0, 31.5278
54.220029755, 96.390, 1053.0, 32.4500
54.272550885, 96.390, 1022.0, 31.9687
54.325072016, 96.390, 1018.0, 31.9061
54.377593147, 96.390, 1023.0, 31.9844
54.430114277, 96.390, 987.0, 31.4166
54.482635408, 96.390, 1030.0, 32.0936
54.535156539, 96.390, 1066.0, 32.6497
54.587677670, 96.390, 960.0, 30.9839
54.640198800, 96.390, 969.0, 31.1288
54.692719931, 96.390, 973.0, 31.1929
54.745241062, 96.390, 1059.0, 32.5423
54.797762192, 96.390, 981.0, 31.3209
54.850283323, 96.390, 966.0, 31.0805
54.902804454, 96.390, 1016.0, 31.8748
54.955325585, 96.390, 1009.0, 31.7648
55.007846715, 96.390, 923.0, 30.3809
55.060367846, 96.390, 975.0, 31.2250
55.112888977, 96.390, 1018.0, 31.9061
55.165410107, 96.390, 962.0, 31.0161
55.217931238, 96.390, 1067.0, 32.6650
55.270452369, 96.390, 972.0, 31.1769
55.322973499, 96.390, 976.0, 31.2410
55.375494630, 96.390, 1018.0, 31.9061
55.428015761, 96.390, 1010.0, 31.7805
55.480536892, 96.390, 922.0, 30.3645
55.533058022, 96.390, 969.0, 31.1288
55.585579153, 96.390, 1003.0, 31.6702
55.638100284, 96.390, 1051.0, 32.4191
55.690621414, 96.390, 993.0, 31.5119
55.743142545, 96.390, 957.0, 30.9354
55.795663676, 96.390, 963.0, 31.0322
55.848184807, 96.390, 973.0, 31.1929
55.900705937, 96.390, 1020.0, 31.9374
55.953227068, 96.390, 972.0, 31.1769
56.005748199, 96.390, 972.0, 31.1769
56.058269329, 96.390, 942.0, 30.6920
56.110790460, 96.390, 981.0, 31.3209
56.163311591, 96.390, 987.0, 31.4166
56.215832722, 96.390, 996.0, 31.5595
56.268353852, 96.390, 945.0, 30.7409
56.320874983, 96.390, 983.0, 31.3528
56.373396114, 96.390, 958.0, 30.9516
56.425917244, 96.390, 1004.0, 31.6860
56.478438375, 96.390, 977.0, 31.2570
56.530959506, 96.390, 1024.0, 32.0000
56.583480637, 96.390, 1006.0, 31.7175
56.636001767, 96.390, 991.0, 31.4802
56.688522898, 96.390, 977.0, 31.2570
56.741044029, 96.390, 1051.0, 32.4191
56.793565159, 96.390, 943.0, 30.7083
56.846086290, 96.390, 1014.0, 31.8434
56.898607421, 96.390, 1004.0, 31.6860
56.951128551, 96.390, 982.0, 31.3369
57.003649682, 96.390, 958.0, 30.9516
57.056170813, 96.390, 1010.0, 31.7805
57.108691944, 96.390, 924.0, 30.3974
57.161213074, 96.390, 980.0, 31.3050
57.213734205, 96.390, 977.0, 31.2570
57.266255336, 96.390, 979.0, 31.2890
57.318776466, 96.390, 1049.0, 32.3883
57.371297597, 96.390, 974.0, 31.2090
57.423818728, 96.390, 910.0, 30.1662
57.476339859, 96.390, 995.0, 31.5436
57.528860989, 96.390, 957.0, 30.9354
57.581382120, 96.390, 951.0, 30.8383
57.633903251, 96.390, 961.0, 31.0000
57.686424381, 96.390, 994.0, 31.5278
57.738945512, 96.390, 1008.0, 31.7490
57.791466643, 96.390, 982.0, 31.3369
57.843987774, 96.390, 963.0, 31.0322
57.896508904, 96.390, 1022.0, 31.9687
57.949030035, 96.390, 964.0, 31.0483
58.001551166, 96.390, 986.0, 31.4006
58.054072296, 96.390, 969.0, 31.1288
58.106593427, 96.390, 970.0, 31.1448
58.159114558, 96.390, 964.0, 31.0483
58.211635689, 96.390, 978.0, 31.2730
58.264156819, 96.390, 962.0, 31.0161
58.316677950, 96.390, 977.0, 31.2570
58.369199081, 96.390, 1019.0, 31.9218
58.421720211, 96.390, 1048.0, 32.3728
58.474241342, 96.390, 972.0, 31.1769
58.526762473, 96.390, 1012.0, 31.8119
58.579283603, 96.390, 1027.0, 32.0468
58.631804734, 96.390, 980.0, 31.3050
58.684325865, 96.390, 1008.0, 31.7490
58.736846996, 96.390, 965.0, 31.0644
58.789368126, 96.390, 975.0, 31.2250
58.841889257, 96.390, 925.0, 30.4138
58.894410388, 96.390, 915.0, 30.2490
58.946931518, 96.390, 1020.0, 31.9374
58.999452649, 96.390, 1036.0, 32.1870
59.051973780, 96.390, 1010.0, 31.7805
59.104494911, 96.390, 1028.0, 32.0624
59.157016041, 96.390, 946.0, 30.7571
59.209537172, 96.390, 948.0, 30.7896
59.262058303, 96.390, 1030.0, 32.0936
59.314579433, 96.390, 1000.0, 31.6228
59.367100564, 96.390, 1008.0, 31.7490
59.419621695, 96.390, 1010.0, 31.7805
59.472142826, 96.390, 916.0, 30.2655
59.524663956, 96.390, 1005.0, 31.7017
59.577185087, 96.390, 1013.0, 31.8277
59.629706218, 96.390, 1044.0, 32.3110
59.682227348, 96.390, 1057.0, 32.5115
59.734748479, 96.390, 1050.0, 32.4037
59.787269610, 96.390, 1054.0, 32.4654
59.839790740, 96.390, 1075.0, 32.7872
59.892311871, 96.390, 1025.0, 32.0156
59.944833002, 96.390, 1034.0, 32.1559
59.997354133, 96.390, 1024.0, 32.0000
60.049875263, 96.390, 1071.0, 32.7261
60.102396394, 96.390, 1035.0, 32.1714
60.154917525, 96.390, 1133.0, 33.6601
60.207438655, 96.390, 1184.0, 34.4093
60.259959786, 96.390, 1165.0, 34.1321
60.312480917, 96.390, 1148.0, 33.8821
60.365002048, 96.390, 1214.0, 34.8425
60.417523178, 96.390, 1217.0, 34.8855
60.470044309, 96.390, 1171.0, 34.2199
60.522565440, 96.390, 1201.0, 34.6554
60.575086570, 96.390, 1190.0, 34.4964
60.627607701, 96.390, 1271.0, 35.6511
60.680128832, 96.390, 1290.0, 35.9166
60.732649963, 96.390, 1322.0, 36.3593
60.785171093, 96.390, 1350.0, 36.7423
60.837692224, 96.390, 1333.0, 36.5103
60.890213355, 96.390, 1372.0, 37.0405
60.942734485, 96.390, 1444.0, 38.0000
60.995255616, 96.390, 1407.0, 37.5100
61.047776747, 96.390, 1398.0, 37.3898
61.100297878, 96.390, 1401.0, 37.4299
61.152819008, 96.390, 1426.0, 37.7624
61.205340139, 96.390, 1323.0, 36.3731
61.257861270, 96.390, 1406.0, 37.4967
61.310382400, 96.390, 1425.0, 37.7492
61.362903531, 96.390, 1346.0, 36.6879
61.415424662, 96.390, 1372.0, 37.0405
61.467945792, 96.390, 1355.0, 36.8103
61.520466923, 96.390, 1373.0, 37.0540
61.572988054, 96.390, 1410.0, 37.5500
61.625509185, 96.390, 1406.0, 37.4967
61.678030315, 96.390, 1332.0, 36.4966
61.730551446, 96.390, 1384.0, 37.2022
61.783072577, 96.390, 1402.0, 37.4433
61.835593707, 96.390, 1400.0, 37.4166
61.888114838, 96.390, 1334.0, 36.5240
61.940635969, 96.390, 1308.0, 36.1663
61.993157100, 96.390, 1310.0, 36.1939
62.045678230, 96.390, 1266.0, 35.5809
62.098199361, 96.390, 1297.0, 36.0139
62.150720492, 96.390, 1288.0, 35.8887
62.203241622, 96.390, 1271.0, 35.6511
62.255762753, 96.390, 1308.0, 36.1663
62.308283884, 96.390, 1251.0, 35.3695
62.360805015, 96.390, 1240.0, 35.2136
62.413326145, 96.390, 1236.0, 35.1568
62.465847276, 96.390, 1271.0, 35.6511
62.518368407, 96.390, 1181.0, 34.3657
62.570889537, 96.390, 1164.0, 34.1174
62.623410668, 96.390, 1113.0, 33.3617
62.675931799, 96.390, 1152.0, 33.9411
62.728452930, 96.390, 1234.0, 35.1283
62.780974060, 96.390, 1163.0, 34.1028
62.833495191, 96.390, 1068.0, 32.6803
62.886016322, 96.390, 1171.0, 34.2199
62.938537452, 96.390, 1105.0, 33.2415
62.991058583, 96.390, 1154.0, 33.9706
63.043579714, 96.390, 1067.0, 32.6650
63.096100844, 96.390, 1061.0, 32.5730
63.148621975, 96.390, 1069.0, 32.6956
63.201143106, 96.390, 1114.0, 33.3766
63.253664237, 96.390, 1055.0, 32.4808
63.306185367, 96.390, 1001.0, 31.6386
63.358706498, 96.390, 1035.0, 32.1714
63.411227629, 96.390, 987.0, 31.4166
63.463748759, 96.390, 987.0, 31.4166
63.516269890, 96.390, 950.0, 30.8221
63.568791021, 96.390, 1016.0, 31.8748
63.621312152, 96.390, 946.0, 30.7571
63.673833282, 96.390, 1008.0, 31.7490
63.726354413, 96.390, 972.0, 31.1769
63.778875544, 96.390, 997.0, 31.5753
63.831396674, 96.390, 941.0, 30.6757
63.883917805, 96.390, 957.0, 30.9354
63.936438936, 96.390, 1015.0, 31.8591
63.988960067, 96.390, 954.0, 30.8869
64.041481197, 96.390, 926.0, 30.4302
64.094002328, 96.390, 929.0, 30.4795
64.146523459, 96.390, 949.0, 30.8058
64.199044589, 96.390, 977.0, 31.2570
64.251565720, 96.390, 876.0, 29.5973
64.304086851, 96.390, 899.0, 29.9833
64.356607981, 96.390, 879.0, 29.6479
64.409129112, 96.390, 891.0, 29.8496
64.461650243, 96.390, 865.0, 29.4109
64.514171374, 96.390, 900.0, 30.0000
64.566692504, 96.390, 905.0, 30.0832
64.619213635, 96.390, 905.0, 30.0832
64.671734766, 96.390, 917.0, 30.2820
64.724255896, 96.390, 876.0, 29.5973
64.776777027, 96.390, 866.0, 29.4279
64.829298158, 96.390, 854.0, 29.2233
64.881819289, 96.390, 884.0, 29.7321
64.934340419, 96.390, 861.0, 29.3428
64.986861550, 96.390, 855.0, 29.2404