File: Files_organized_for_plots/Na_to_Al_1/XRD_MgCorner17Dec21_Act18Jan22_B4_0251M_NaOH_LS0113_1.csv
[Measurement conditions]
Sample identification,XRD_MgCorner17Dec21_Act18Jan22_B4_0251M_NaOH_LS0113_1
Comment - 1,"Configuration=Stage for Flat Samples/Holders, Owner=User-1, Creation date=7/1/2020 9:53:24 AM"
Comment - 2,"Goniometer=Theta/Theta; Minimum step size 2Theta:0.0001; Minimum step size Omega:0.0001"
Comment - 3,"Sample stage=Stage for flat samples/holders"
Comment - 4,"Diffractometer system=EMPYREAN"
Comment - 5,"Measurement program=C:\Users\ibo5034\OneDrive - The Pennsylvania State University\NEUP - Reed, Titus's files\XRD\Cement\Zerobackground scan.xrdmp, Identifier={98A3B11C-88F9-4AA6-982C-73314A311EF5}"
Anode material,Cu
K-Alpha1 wavelength,1.5405980
K-Alpha2 wavelength,1.5444260
Ratio K-Alpha2/K-Alpha1,0.500
Divergence slit,Fixed,0.25
Monochromator used,NO
Generator voltage, 45
Tube current, 40
File date and time,21/Jan/2022 11:24
Unit cell,
h k l, 0 0 0
Scan axis,Gonio
Scan range,4.994599997,64.999991833
Scan step size,0.0262606
No. of points, 2285
Scan type,CONTINUOUS
Time per step,96.390
[Scan points]
Angle, TimePerStep, Intensity, ESD
5.007730280, 96.390, 6272.0, 79.1960
5.060251411, 96.390, 6480.0, 80.4984
5.112772541, 96.390, 6349.0, 79.6806
5.165293672, 96.390, 6192.0, 78.6893
5.217814803, 96.390, 6060.0, 77.8460
5.270335934, 96.390, 6070.0, 77.9102
5.322857064, 96.390, 5952.0, 77.1492
5.375378195, 96.390, 6101.0, 78.1089
5.427899326, 96.390, 5824.0, 76.3151
5.480420456, 96.390, 5868.0, 76.6029
5.532941587, 96.390, 5811.0, 76.2299
5.585462718, 96.390, 5788.0, 76.0789
5.637983849, 96.390, 5659.0, 75.2263
5.690504979, 96.390, 5818.0, 76.2758
5.743026110, 96.390, 5770.0, 75.9605
5.795547241, 96.390, 5490.0, 74.0945
5.848068371, 96.390, 5725.0, 75.6637
5.900589502, 96.390, 5645.0, 75.1332
5.953110633, 96.390, 5495.0, 74.1283
6.005631763, 96.390, 5548.0, 74.4849
6.058152894, 96.390, 5443.0, 73.7767
6.110674025, 96.390, 5655.0, 75.1997
6.163195156, 96.390, 5465.0, 73.9256
6.215716286, 96.390, 5401.0, 73.4915
6.268237417, 96.390, 5415.0, 73.5867
6.320758548, 96.390, 5414.0, 73.5799
6.373279678, 96.390, 5559.0, 74.5587
6.425800809, 96.390, 5403.0, 73.5051
6.478321940, 96.390, 5390.0, 73.4166
6.530843071, 96.390, 5253.0, 72.4776
6.583364201, 96.390, 5294.0, 72.7599
6.635885332, 96.390, 5434.0, 73.7157
6.688406463, 96.390, 5309.0, 72.8629
6.740927593, 96.390, 5354.0, 73.1710
6.793448724, 96.390, 5053.0, 71.0845
6.845969855, 96.390, 5142.0, 71.7077
6.898490986, 96.390, 5138.0, 71.6798
6.951012116, 96.390, 5055.0, 71.0985
7.003533247, 96.390, 5099.0, 71.4073
7.056054378, 96.390, 5066.0, 71.1758
7.108575508, 96.390, 5133.0, 71.6450
7.161096639, 96.390, 5120.0, 71.5542
7.213617770, 96.390, 5001.0, 70.7177
7.266138900, 96.390, 5025.0, 70.8872
7.318660031, 96.390, 5030.0, 70.9225
7.371181162, 96.390, 4953.0, 70.3776
7.423702293, 96.390, 4838.0, 69.5557
7.476223423, 96.390, 4909.0, 70.0643
7.528744554, 96.390, 4979.0, 70.5620
7.581265685, 96.390, 4830.0, 69.4982
7.633786815, 96.390, 4857.0, 69.6922
7.686307946, 96.390, 4830.0, 69.4982
7.738829077, 96.390, 4685.0, 68.4471
7.791350208, 96.390, 4797.0, 69.2604
7.843871338, 96.390, 4800.0, 69.2820
7.896392469, 96.390, 4672.0, 68.3520
7.948913600, 96.390, 4792.0, 69.2243
8.001434730, 96.390, 4772.0, 69.0797
8.053955861, 96.390, 4728.0, 68.7605
8.106476992, 96.390, 4812.0, 69.3686
8.158998123, 96.390, 4749.0, 68.9130
8.211519253, 96.390, 4592.0, 67.7643
8.264040384, 96.390, 4743.0, 68.8694
8.316561515, 96.390, 4600.0, 67.8233
8.369082645, 96.390, 4687.0, 68.4617
8.421603776, 96.390, 4730.0, 68.7750
8.474124907, 96.390, 4614.0, 67.9264
8.526646038, 96.390, 4681.0, 68.4178
8.579167168, 96.390, 4605.0, 67.8602
8.631688299, 96.390, 4597.0, 67.8012
8.684209430, 96.390, 4511.0, 67.1640
8.736730560, 96.390, 4456.0, 66.7533
8.789251691, 96.390, 4469.0, 66.8506
8.841772822, 96.390, 4594.0, 67.7791
8.894293952, 96.390, 4570.0, 67.6018
8.946815083, 96.390, 4606.0, 67.8675
8.999336214, 96.390, 4488.0, 66.9925
9.051857345, 96.390, 4489.0, 67.0000
9.104378475, 96.390, 4392.0, 66.2722
9.156899606, 96.390, 4523.0, 67.2533
9.209420737, 96.390, 4588.0, 67.7348
9.261941867, 96.390, 4370.0, 66.1060
9.314462998, 96.390, 4435.0, 66.5958
9.366984129, 96.390, 4499.0, 67.0746
9.419505260, 96.390, 4350.0, 65.9545
9.472026390, 96.390, 4545.0, 67.4166
9.524547521, 96.390, 4421.0, 66.4906
9.577068652, 96.390, 4523.0, 67.2533
9.629589782, 96.390, 4488.0, 66.9925
9.682110913, 96.390, 4469.0, 66.8506
9.734632044, 96.390, 4471.0, 66.8655
9.787153175, 96.390, 4461.0, 66.7907
9.839674305, 96.390, 4454.0, 66.7383
9.892195436, 96.390, 4590.0, 67.7495
9.944716567, 96.390, 4580.0, 67.6757
9.997237697, 96.390, 4639.0, 68.1102
10.049758828, 96.390, 4738.0, 68.8331
10.102279959, 96.390, 4498.0, 67.0671
10.154801090, 96.390, 4609.0, 67.8896
10.207322220, 96.390, 4710.0, 68.6294
10.259843351, 96.390, 4682.0, 68.4251
10.312364482, 96.390, 4770.0, 69.0652
10.364885612, 96.390, 4594.0, 67.7791
10.417406743, 96.390, 4638.0, 68.1029
10.469927874, 96.390, 4633.0, 68.0661
10.522449004, 96.390, 4725.0, 68.7386
10.574970135, 96.390, 4727.0, 68.7532
10.627491266, 96.390, 4733.0, 68.7968
10.680012397, 96.390, 4769.0, 69.0579
10.732533527, 96.390, 4675.0, 68.3740
10.785054658, 96.390, 4760.0, 68.9928
10.837575789, 96.390, 4625.0, 68.0074
10.890096919, 96.390, 4632.0, 68.0588
10.942618050, 96.390, 4667.0, 68.3154
10.995139181, 96.390, 4689.0, 68.4763
11.047660312, 96.390, 4575.0, 67.6387
11.100181442, 96.390, 4638.0, 68.1029
11.152702573, 96.390, 4532.0, 67.3201
11.205223704, 96.390, 4548.0, 67.4389
11.257744834, 96.390, 4601.0, 67.8307
11.310265965, 96.390, 4398.0, 66.3174
11.362787096, 96.390, 4364.0, 66.0606
11.415308227, 96.390, 4253.0, 65.2150
11.467829357, 96.390, 4216.0, 64.9307
11.520350488, 96.390, 4155.0, 64.4593
11.572871619, 96.390, 4173.0, 64.5988
11.625392749, 96.390, 4073.0, 63.8201
11.677913880, 96.390, 4046.0, 63.6082
11.730435011, 96.390, 3895.0, 62.4099
11.782956141, 96.390, 3971.0, 63.0159
11.835477272, 96.390, 3783.0, 61.5061
11.887998403, 96.390, 3886.0, 62.3378
11.940519534, 96.390, 3754.0, 61.2699
11.993040664, 96.390, 3730.0, 61.0737
12.045561795, 96.390, 3652.0, 60.4318
12.098082926, 96.390, 3637.0, 60.3075
12.150604056, 96.390, 3606.0, 60.0500
12.203125187, 96.390, 3472.0, 58.9237
12.255646318, 96.390, 3422.0, 58.4979
12.308167449, 96.390, 3414.0, 58.4294
12.360688579, 96.390, 3306.0, 57.4978
12.413209710, 96.390, 3321.0, 57.6281
12.465730841, 96.390, 3207.0, 56.6304
12.518251971, 96.390, 3241.0, 56.9298
12.570773102, 96.390, 3182.0, 56.4092
12.623294233, 96.390, 3181.0, 56.4004
12.675815364, 96.390, 3049.0, 55.2178
12.728336494, 96.390, 2957.0, 54.3783
12.780857625, 96.390, 2981.0, 54.5985
12.833378756, 96.390, 3020.0, 54.9545
12.885899886, 96.390, 2937.0, 54.1941
12.938421017, 96.390, 2931.0, 54.1387
12.990942148, 96.390, 2870.0, 53.5724
13.043463279, 96.390, 2735.0, 52.2972
13.095984409, 96.390, 2775.0, 52.6783
13.148505540, 96.390, 2646.0, 51.4393
13.201026671, 96.390, 2735.0, 52.2972
13.253547801, 96.390, 2742.0, 52.3641
13.306068932, 96.390, 2623.0, 51.2152
13.358590063, 96.390, 2634.0, 51.3225
13.411111193, 96.390, 2660.0, 51.5752
13.463632324, 96.390, 2553.0, 50.5272
13.516153455, 96.390, 2564.0, 50.6360
13.568674586, 96.390, 2629.0, 51.2738
13.621195716, 96.390, 2587.0, 50.8626
13.673716847, 96.390, 2495.0, 49.9500
13.726237978, 96.390, 2410.0, 49.0918
13.778759108, 96.390, 2559.0, 50.5866
13.831280239, 96.390, 2470.0, 49.6991
13.883801370, 96.390, 2434.0, 49.3356
13.936322501, 96.390, 2496.0, 49.9600
13.988843631, 96.390, 2418.0, 49.1732
14.041364762, 96.390, 2426.0, 49.2544
14.093885893, 96.390, 2412.0, 49.1121
14.146407023, 96.390, 2403.0, 49.0204
14.198928154, 96.390, 2299.0, 47.9479
14.251449285, 96.390, 2344.0, 48.4149
14.303970416, 96.390, 2311.0, 48.0729
14.356491546, 96.390, 2311.0, 48.0729
14.409012677, 96.390, 2320.0, 48.1664
14.461533808, 96.390, 2334.0, 48.3115
14.514054938, 96.390, 2333.0, 48.3011
14.566576069, 96.390, 2302.0, 47.9792
14.619097200, 96.390, 2219.0, 47.1063
14.671618331, 96.390, 2284.0, 47.7912
14.724139461, 96.390, 2265.0, 47.5920
14.776660592, 96.390, 2313.0, 48.0937
14.829181723, 96.390, 2207.0, 46.9787
14.881702853, 96.390, 2197.0, 46.8722
14.934223984, 96.390, 2094.0, 45.7602
14.986745115, 96.390, 2162.0, 46.4973
15.039266245, 96.390, 2199.0, 46.8935
15.091787376, 96.390, 2102.0, 45.8476
15.144308507, 96.390, 2195.0, 46.8508
15.196829638, 96.390, 2182.0, 46.7119
15.249350768, 96.390, 2163.0, 46.5081
15.301871899, 96.390, 2163.0, 46.5081
15.354393030, 96.390, 2112.0, 45.9565
15.406914160, 96.390, 2159.0, 46.4650
15.459435291, 96.390, 2060.0, 45.3872
15.511956422, 96.390, 2086.0, 45.6727
15.564477553, 96.390, 2117.0, 46.0109
15.616998683, 96.390, 2155.0, 46.4220
15.669519814, 96.390, 2143.0, 46.2925
15.722040945, 96.390, 2058.0, 45.3652
15.774562075, 96.390, 2120.0, 46.0435
15.827083206, 96.390, 2097.0, 45.7930
15.879604337, 96.390, 2113.0, 45.9674
15.932125468, 96.390, 2041.0, 45.1774
15.984646598, 96.390, 1984.0, 44.5421
16.037167729, 96.390, 2023.0, 44.9778
16.089688860, 96.390, 2084.0, 45.6508
16.142209990, 96.390, 2025.0, 45.0000
16.194731121, 96.390, 2000.0, 44.7214
16.247252252, 96.390, 2010.0, 44.8330
16.299773382, 96.390, 2036.0, 45.1221
16.352294513, 96.390, 2016.0, 44.8999
16.404815644, 96.390, 2058.0, 45.3652
16.457336775, 96.390, 2082.0, 45.6289
16.509857905, 96.390, 2041.0, 45.1774
16.562379036, 96.390, 2063.0, 45.4203
16.614900167, 96.390, 2011.0, 44.8442
16.667421297, 96.390, 2070.0, 45.4973
16.719942428, 96.390, 2003.0, 44.7549
16.772463559, 96.390, 1998.0, 44.6990
16.824984690, 96.390, 2024.0, 44.9889
16.877505820, 96.390, 2056.0, 45.3431
16.930026951, 96.390, 2056.0, 45.3431
16.982548082, 96.390, 2057.0, 45.3542
17.035069212, 96.390, 2002.0, 44.7437
17.087590343, 96.390, 2052.0, 45.2990
17.140111474, 96.390, 2045.0, 45.2217
17.192632605, 96.390, 2033.0, 45.0888
17.245153735, 96.390, 1989.0, 44.5982
17.297674866, 96.390, 2005.0, 44.7772
17.350195997, 96.390, 2012.0, 44.8553
17.402717127, 96.390, 2043.0, 45.1996
17.455238258, 96.390, 1958.0, 44.2493
17.507759389, 96.390, 1968.0, 44.3621
17.560280520, 96.390, 1946.0, 44.1135
17.612801650, 96.390, 1983.0, 44.5309
17.665322781, 96.390, 2004.0, 44.7661
17.717843912, 96.390, 1954.0, 44.2041
17.770365042, 96.390, 1968.0, 44.3621
17.822886173, 96.390, 2029.0, 45.0444
17.875407304, 96.390, 2079.0, 45.5961
17.927928434, 96.390, 1965.0, 44.3283
17.980449565, 96.390, 1954.0, 44.2041
18.032970696, 96.390, 2002.0, 44.7437
18.085491827, 96.390, 2036.0, 45.1221
18.138012957, 96.390, 1946.0, 44.1135
18.190534088, 96.390, 2017.0, 44.9110
18.243055219, 96.390, 2042.0, 45.1885
18.295576349, 96.390, 2031.0, 45.0666
18.348097480, 96.390, 2061.0, 45.3982
18.400618611, 96.390, 2000.0, 44.7214
18.453139742, 96.390, 2023.0, 44.9778
18.505660872, 96.390, 2059.0, 45.3762
18.558182003, 96.390, 2002.0, 44.7437
18.610703134, 96.390, 2041.0, 45.1774
18.663224264, 96.390, 2073.0, 45.5302
18.715745395, 96.390, 2001.0, 44.7325
18.768266526, 96.390, 2024.0, 44.9889
18.820787657, 96.390, 2082.0, 45.6289
18.873308787, 96.390, 1986.0, 44.5646
18.925829918, 96.390, 2078.0, 45.5851
18.978351049, 96.390, 2058.0, 45.3652
19.030872179, 96.390, 2118.0, 46.0217
19.083393310, 96.390, 2066.0, 45.4533
19.135914441, 96.390, 2095.0, 45.7712
19.188435572, 96.390, 2010.0, 44.8330
19.240956702, 96.390, 2092.0, 45.7384
19.293477833, 96.390, 1973.0, 44.4185
19.345998964, 96.390, 2082.0, 45.6289
19.398520094, 96.390, 2062.0, 45.4093
19.451041225, 96.390, 2059.0, 45.3762
19.503562356, 96.390, 2068.0, 45.4753
19.556083486, 96.390, 2175.0, 46.6369
19.608604617, 96.390, 2177.0, 46.6583
19.661125748, 96.390, 2158.0, 46.4543
19.713646879, 96.390, 2177.0, 46.6583
19.766168009, 96.390, 2206.0, 46.9681
19.818689140, 96.390, 2133.0, 46.1844
19.871210271, 96.390, 2093.0, 45.7493
19.923731401, 96.390, 2147.0, 46.3357
19.976252532, 96.390, 2140.0, 46.2601
20.028773663, 96.390, 2225.0, 47.1699
20.081294794, 96.390, 2259.0, 47.5289
20.133815924, 96.390, 2249.0, 47.4236
20.186337055, 96.390, 2263.0, 47.5710
20.238858186, 96.390, 2209.0, 47.0000
20.291379316, 96.390, 2257.0, 47.5079
20.343900447, 96.390, 2198.0, 46.8828
20.396421578, 96.390, 2312.0, 48.0833
20.448942709, 96.390, 2303.0, 47.9896
20.501463839, 96.390, 2228.0, 47.2017
20.553984970, 96.390, 2289.0, 47.8435
20.606506101, 96.390, 2393.0, 48.9183
20.659027231, 96.390, 2310.0, 48.0625
20.711548362, 96.390, 2345.0, 48.4252
20.764069493, 96.390, 2475.0, 49.7494
20.816590623, 96.390, 2399.0, 48.9796
20.869111754, 96.390, 2332.0, 48.2908
20.921632885, 96.390, 2364.0, 48.6210
20.974154016, 96.390, 2424.0, 49.2341
21.026675146, 96.390, 2375.0, 48.7340
21.079196277, 96.390, 2422.0, 49.2138
21.131717408, 96.390, 2387.0, 48.8569
21.184238538, 96.390, 2537.0, 50.3686
21.236759669, 96.390, 2550.0, 50.4975
21.289280800, 96.390, 2485.0, 49.8498
21.341801931, 96.390, 2527.0, 50.2693
21.394323061, 96.390, 2516.0, 50.1597
21.446844192, 96.390, 2454.0, 49.5379
21.499365323, 96.390, 2463.0, 49.6286
21.551886453, 96.390, 2445.0, 49.4469
21.604407584, 96.390, 2531.0, 50.3090
21.656928715, 96.390, 2497.0, 49.9700
21.709449846, 96.390, 2498.0, 49.9800
21.761970976, 96.390, 2496.0, 49.9600
21.814492107, 96.390, 2626.0, 51.2445
21.867013238, 96.390, 2556.0, 50.5569
21.919534368, 96.390, 2579.0, 50.7839
21.972055499, 96.390, 2647.0, 51.4490
22.024576630, 96.390, 2613.0, 51.1175
22.077097761, 96.390, 2577.0, 50.7642
22.129618891, 96.390, 2678.0, 51.7494
22.182140022, 96.390, 2612.0, 51.1077
22.234661153, 96.390, 2493.0, 49.9300
22.287182283, 96.390, 2691.0, 51.8748
22.339703414, 96.390, 2671.0, 51.6817
22.392224545, 96.390, 2573.0, 50.7247
22.444745675, 96.390, 2577.0, 50.7642
22.497266806, 96.390, 2561.0, 50.6063
22.549787937, 96.390, 2550.0, 50.4975
22.602309068, 96.390, 2572.0, 50.7149
22.654830198, 96.390, 2594.0, 50.9313
22.707351329, 96.390, 2548.0, 50.4777
22.759872460, 96.390, 2565.0, 50.6458
22.812393590, 96.390, 2520.0, 50.1996
22.864914721, 96.390, 2522.0, 50.2195
22.917435852, 96.390, 2513.0, 50.1298
22.969956983, 96.390, 2484.0, 49.8397
23.022478113, 96.390, 2533.0, 50.3289
23.074999244, 96.390, 2412.0, 49.1121
23.127520375, 96.390, 2546.0, 50.4579
23.180041505, 96.390, 2481.0, 49.8096
23.232562636, 96.390, 2464.0, 49.6387
23.285083767, 96.390, 2381.0, 48.7955
23.337604898, 96.390, 2403.0, 49.0204
23.390126028, 96.390, 2276.0, 47.7074
23.442647159, 96.390, 2317.0, 48.1352
23.495168290, 96.390, 2422.0, 49.2138
23.547689420, 96.390, 2297.0, 47.9270
23.600210551, 96.390, 2397.0, 48.9592
23.652731682, 96.390, 2297.0, 47.9270
23.705252813, 96.390, 2258.0, 47.5184
23.757773943, 96.390, 2346.0, 48.4355
23.810295074, 96.390, 2217.0, 47.0850
23.862816205, 96.390, 2201.0, 46.9148
23.915337335, 96.390, 2236.0, 47.2864
23.967858466, 96.390, 2233.0, 47.2546
24.020379597, 96.390, 2216.0, 47.0744
24.072900727, 96.390, 2196.0, 46.8615
24.125421858, 96.390, 2213.0, 47.0425
24.177942989, 96.390, 2156.0, 46.4327
24.230464120, 96.390, 2130.0, 46.1519
24.282985250, 96.390, 2159.0, 46.4650
24.335506381, 96.390, 2173.0, 46.6154
24.388027512, 96.390, 2113.0, 45.9674
24.440548642, 96.390, 2079.0, 45.5961
24.493069773, 96.390, 2078.0, 45.5851
24.545590904, 96.390, 2132.0, 46.1736
24.598112035, 96.390, 2062.0, 45.4093
24.650633165, 96.390, 2119.0, 46.0326
24.703154296, 96.390, 2166.0, 46.5403
24.755675427, 96.390, 2109.0, 45.9239
24.808196557, 96.390, 2037.0, 45.1331
24.860717688, 96.390, 2083.0, 45.6399
24.913238819, 96.390, 2012.0, 44.8553
24.965759950, 96.390, 2067.0, 45.4643
25.018281080, 96.390, 1969.0, 44.3734
25.070802211, 96.390, 2025.0, 45.0000
25.123323342, 96.390, 2020.0, 44.9444
25.175844472, 96.390, 2034.0, 45.0999
25.228365603, 96.390, 2112.0, 45.9565
25.280886734, 96.390, 2033.0, 45.0888
25.333407864, 96.390, 1985.0, 44.5533
25.385928995, 96.390, 1911.0, 43.7150
25.438450126, 96.390, 1966.0, 44.3396
25.490971257, 96.390, 2000.0, 44.7214
25.543492387, 96.390, 2048.0, 45.2548
25.596013518, 96.390, 1948.0, 44.1362
25.648534649, 96.390, 1995.0, 44.6654
25.701055779, 96.390, 1889.0, 43.4626
25.753576910, 96.390, 1955.0, 44.2154
25.806098041, 96.390, 1884.0, 43.4051
25.858619172, 96.390, 1984.0, 44.5421
25.911140302, 96.390, 1887.0, 43.4396
25.963661433, 96.390, 1982.0, 44.5197
26.016182564, 96.390, 1946.0, 44.1135
26.068703694, 96.390, 1955.0, 44.2154
26.121224825, 96.390, 1934.0, 43.9773
26.173745956, 96.390, 1949.0, 44.1475
26.226267087, 96.390, 1955.0, 44.2154
26.278788217, 96.390, 1940.0, 44.0454
26.331309348, 96.390, 1875.0, 43.3013
26.383830479, 96.390, 1977.0, 44.4635
26.436351609, 96.390, 1891.0, 43.4856
26.488872740, 96.390, 1925.0, 43.8748
26.541393871, 96.390, 1879.0, 43.3474
26.593915002, 96.390, 1971.0, 44.3959
26.646436132, 96.390, 1914.0, 43.7493
26.698957263, 96.390, 1917.0, 43.7836
26.751478394, 96.390, 1892.0, 43.4971
26.803999524, 96.390, 1971.0, 44.3959
26.856520655, 96.390, 1816.0, 42.6146
26.909041786, 96.390, 1903.0, 43.6234
26.961562916, 96.390, 1899.0, 43.5775
27.014084047, 96.390, 1823.0, 42.6966
27.066605178, 96.390, 1940.0, 44.0454
27.119126309, 96.390, 1902.0, 43.6119
27.171647439, 96.390, 1869.0, 43.2319
27.224168570, 96.390, 1909.0, 43.6921
27.276689701, 96.390, 1865.0, 43.1856
27.329210831, 96.390, 1880.0, 43.3590
27.381731962, 96.390, 1822.0, 42.6849
27.434253093, 96.390, 1834.0, 42.8252
27.486774224, 96.390, 1864.0, 43.1741
27.539295354, 96.390, 1880.0, 43.3590
27.591816485, 96.390, 1760.0, 41.9524
27.644337616, 96.390, 1798.0, 42.4028
27.696858746, 96.390, 1793.0, 42.3438
27.749379877, 96.390, 1929.0, 43.9204
27.801901008, 96.390, 1805.0, 42.4853
27.854422139, 96.390, 1874.0, 43.2897
27.906943269, 96.390, 1855.0, 43.0697
27.959464400, 96.390, 1825.0, 42.7200
28.011985531, 96.390, 1854.0, 43.0581
28.064506661, 96.390, 1818.0, 42.6380
28.117027792, 96.390, 1822.0, 42.6849
28.169548923, 96.390, 1817.0, 42.6263
28.222070054, 96.390, 1833.0, 42.8135
28.274591184, 96.390, 1806.0, 42.4971
28.327112315, 96.390, 1804.0, 42.4735
28.379633446, 96.390, 1831.0, 42.7902
28.432154576, 96.390, 1853.0, 43.0465
28.484675707, 96.390, 1849.0, 43.0000
28.537196838, 96.390, 1877.0, 43.3244
28.589717968, 96.390, 1827.0, 42.7434
28.642239099, 96.390, 1865.0, 43.1856
28.694760230, 96.390, 1863.0, 43.1625
28.747281361, 96.390, 1846.0, 42.9651
28.799802491, 96.390, 1874.0, 43.2897
28.852323622, 96.390, 1813.0, 42.5793
28.904844753, 96.390, 1869.0, 43.2319
28.957365883, 96.390, 1857.0, 43.0929
29.009887014, 96.390, 1901.0, 43.6005
29.062408145, 96.390, 1861.0, 43.1393
29.114929276, 96.390, 1808.0, 42.5206
29.167450406, 96.390, 1885.0, 43.4166
29.219971537, 96.390, 1842.0, 42.9185
29.272492668, 96.390, 1843.0, 42.9302
29.325013798, 96.390, 1826.0, 42.7317
29.377534929, 96.390, 1835.0, 42.8369
29.430056060, 96.390, 1785.0, 42.2493
29.482577191, 96.390, 1819.0, 42.6497
29.535098321, 96.390, 1837.0, 42.8602
29.587619452, 96.390, 1865.0, 43.1856
29.640140583, 96.390, 1789.0, 42.2966
29.692661713, 96.390, 1820.0, 42.6615
29.745182844, 96.390, 1789.0, 42.2966
29.797703975, 96.390, 1831.0, 42.7902
29.850225105, 96.390, 1776.0, 42.1426
29.902746236, 96.390, 1883.0, 43.3935
29.955267367, 96.390, 1937.0, 44.0114
30.007788498, 96.390, 1842.0, 42.9185
30.060309628, 96.390, 1844.0, 42.9418
30.112830759, 96.390, 1753.0, 41.8688
30.165351890, 96.390, 1738.0, 41.6893
30.217873020, 96.390, 1826.0, 42.7317
30.270394151, 96.390, 1767.0, 42.0357
30.322915282, 96.390, 1766.0, 42.0238
30.375436413, 96.390, 1821.0, 42.6732
30.427957543, 96.390, 1807.0, 42.5088
30.480478674, 96.390, 1822.0, 42.6849
30.532999805, 96.390, 1818.0, 42.6380
30.585520935, 96.390, 1790.0, 42.3084
30.638042066, 96.390, 1814.0, 42.5911
30.690563197, 96.390, 1732.0, 41.6173
30.743084328, 96.390, 1751.0, 41.8450
30.795605458, 96.390, 1753.0, 41.8688
30.848126589, 96.390, 1835.0, 42.8369
30.900647720, 96.390, 1857.0, 43.0929
30.953168850, 96.390, 1782.0, 42.2137
31.005689981, 96.390, 1757.0, 41.9166
31.058211112, 96.390, 1841.0, 42.9069
31.110732243, 96.390, 1708.0, 41.3280
31.163253373, 96.390, 1724.0, 41.5211
31.215774504, 96.390, 1780.0, 42.1900
31.268295635, 96.390, 1735.0, 41.6533
31.320816765, 96.390, 1742.0, 41.7373
31.373337896, 96.390, 1719.0, 41.4608
31.425859027, 96.390, 1765.0, 42.0119
31.478380157, 96.390, 1749.0, 41.8210
31.530901288, 96.390, 1757.0, 41.9166
31.583422419, 96.390, 1774.0, 42.1189
31.635943550, 96.390, 1759.0, 41.9404
31.688464680, 96.390, 1785.0, 42.2493
31.740985811, 96.390, 1815.0, 42.6028
31.793506942, 96.390, 1797.0, 42.3910
31.846028072, 96.390, 1748.0, 41.8091
31.898549203, 96.390, 1759.0, 41.9404
31.951070334, 96.390, 1710.0, 41.3521
32.003591465, 96.390, 1741.0, 41.7253
32.056112595, 96.390, 1796.0, 42.3792
32.108633726, 96.390, 1754.0, 41.8808
32.161154857, 96.390, 1762.0, 41.9762
32.213675987, 96.390, 1735.0, 41.6533
32.266197118, 96.390, 1783.0, 42.2256
32.318718249, 96.390, 1773.0, 42.1070
32.371239380, 96.390, 1788.0, 42.2847
32.423760510, 96.390, 1761.0, 41.9643
32.476281641, 96.390, 1783.0, 42.2256
32.528802772, 96.390, 1731.0, 41.6053
32.581323902, 96.390, 1808.0, 42.5206
32.633845033, 96.390, 1741.0, 41.7253
32.686366164, 96.390, 1782.0, 42.2137
32.738887295, 96.390, 1757.0, 41.9166
32.791408425, 96.390, 1752.0, 41.8569
32.843929556, 96.390, 1832.0, 42.8019
32.896450687, 96.390, 1821.0, 42.6732
32.948971817, 96.390, 1817.0, 42.6263
33.001492948, 96.390, 1803.0, 42.4617
33.054014079, 96.390, 1824.0, 42.7083
33.106535209, 96.390, 1826.0, 42.7317
33.159056340, 96.390, 1844.0, 42.9418
33.211577471, 96.390, 1879.0, 43.3474
33.264098602, 96.390, 1869.0, 43.2319
33.316619732, 96.390, 1833.0, 42.8135
33.369140863, 96.390, 1885.0, 43.4166
33.421661994, 96.390, 1929.0, 43.9204
33.474183124, 96.390, 1983.0, 44.5309
33.526704255, 96.390, 2144.0, 46.3033
33.579225386, 96.390, 2037.0, 45.1331
33.631746517, 96.390, 2114.0, 45.9783
33.684267647, 96.390, 2129.0, 46.1411
33.736788778, 96.390, 2027.0, 45.0222
33.789309909, 96.390, 2108.0, 45.9130
33.841831039, 96.390, 2243.0, 47.3603
33.894352170, 96.390, 2345.0, 48.4252
33.946873301, 96.390, 2317.0, 48.1352
33.999394432, 96.390, 2325.0, 48.2183
34.051915562, 96.390, 2376.0, 48.7442
34.104436693, 96.390, 2407.0, 49.0612
34.156957824, 96.390, 2469.0, 49.6890
34.209478954, 96.390, 2599.0, 50.9804
34.262000085, 96.390, 2515.0, 50.1498
34.314521216, 96.390, 2551.0, 50.5074
34.367042346, 96.390, 2556.0, 50.5569
34.419563477, 96.390, 2652.0, 51.4976
34.472084608, 96.390, 2563.0, 50.6261
34.524605739, 96.390, 2585.0, 50.8429
34.577126869, 96.390, 2631.0, 51.2933
34.629648000, 96.390, 2532.0, 50.3190
34.682169131, 96.390, 2615.0, 51.1371
34.734690261, 96.390, 2652.0, 51.4976
34.787211392, 96.390, 2629.0, 51.2738
34.839732523, 96.390, 2507.0, 50.0700
34.892253654, 96.390, 2602.0, 51.0098
34.944774784, 96.390, 2613.0, 51.1175
34.997295915, 96.390, 2644.0, 51.4198
35.049817046, 96.390, 2597.0, 50.9608
35.102338176, 96.390, 2648.0, 51.4587
35.154859307, 96.390, 2584.0, 50.8331
35.207380438, 96.390, 2686.0, 51.8266
35.259901569, 96.390, 2613.0, 51.1175
35.312422699, 96.390, 2518.0, 50.1797
35.364943830, 96.390, 2558.0, 50.5767
35.417464961, 96.390, 2515.0, 50.1498
35.469986091, 96.390, 2486.0, 49.8598
35.522507222, 96.390, 2459.0, 49.5883
35.575028353, 96.390, 2551.0, 50.5074
35.627549484, 96.390, 2522.0, 50.2195
35.680070614, 96.390, 2349.0, 48.4665
35.732591745, 96.390, 2489.0, 49.8899
35.785112876, 96.390, 2410.0, 49.0918
35.837634006, 96.390, 2416.0, 49.1528
35.890155137, 96.390, 2400.0, 48.9898
35.942676268, 96.390, 2404.0, 49.0306
35.995197398, 96.390, 2419.0, 49.1833
36.047718529, 96.390, 2387.0, 48.8569
36.100239660, 96.390, 2323.0, 48.1975
36.152760791, 96.390, 2421.0, 49.2037
36.205281921, 96.390, 2270.0, 47.6445
36.257803052, 96.390, 2346.0, 48.4355
36.310324183, 96.390, 2275.0, 47.6970
36.362845313, 96.390, 2355.0, 48.5283
36.415366444, 96.390, 2284.0, 47.7912
36.467887575, 96.390, 2286.0, 47.8121
36.520408706, 96.390, 2333.0, 48.3011
36.572929836, 96.390, 2256.0, 47.4974
36.625450967, 96.390, 2292.0, 47.8748
36.677972098, 96.390, 2311.0, 48.0729
36.730493228, 96.390, 2148.0, 46.3465
36.783014359, 96.390, 2287.0, 47.8226
36.835535490, 96.390, 2291.0, 47.8644
36.888056621, 96.390, 2235.0, 47.2758
36.940577751, 96.390, 2307.0, 48.0312
36.993098882, 96.390, 2115.0, 45.9891
37.045620013, 96.390, 2250.0, 47.4342
37.098141143, 96.390, 2204.0, 46.9468
37.150662274, 96.390, 2110.0, 45.9347
37.203183405, 96.390, 2103.0, 45.8585
37.255704535, 96.390, 2204.0, 46.9468
37.308225666, 96.390, 2085.0, 45.6618
37.360746797, 96.390, 2155.0, 46.4220
37.413267928, 96.390, 2131.0, 46.1628
37.465789058, 96.390, 2082.0, 45.6289
37.518310189, 96.390, 2024.0, 44.9889
37.570831320, 96.390, 2117.0, 46.0109
37.623352450, 96.390, 2134.0, 46.1952
37.675873581, 96.390, 2036.0, 45.1221
37.728394712, 96.390, 1979.0, 44.4860
37.780915843, 96.390, 1996.0, 44.6766
37.833436973, 96.390, 2050.0, 45.2769
37.885958104, 96.390, 2016.0, 44.8999
37.938479235, 96.390, 1962.0, 44.2945
37.991000365, 96.390, 1963.0, 44.3058
38.043521496, 96.390, 2037.0, 45.1331
38.096042627, 96.390, 2131.0, 46.1628
38.148563758, 96.390, 2026.0, 45.0111
38.201084888, 96.390, 1987.0, 44.5758
38.253606019, 96.390, 1979.0, 44.4860
38.306127150, 96.390, 1871.0, 43.2551
38.358648280, 96.390, 1997.0, 44.6878
38.411169411, 96.390, 1975.0, 44.4410
38.463690542, 96.390, 1980.0, 44.4972
38.516211673, 96.390, 1902.0, 43.6119
38.568732803, 96.390, 1936.0, 44.0000
38.621253934, 96.390, 1958.0, 44.2493
38.673775065, 96.390, 1905.0, 43.6463
38.726296195, 96.390, 1945.0, 44.1022
38.778817326, 96.390, 1839.0, 42.8836
38.831338457, 96.390, 1871.0, 43.2551
38.883859587, 96.390, 1924.0, 43.8634
38.936380718, 96.390, 1888.0, 43.4511
38.988901849, 96.390, 1859.0, 43.1161
39.041422980, 96.390, 1807.0, 42.5088
39.093944110, 96.390, 1898.0, 43.5660
39.146465241, 96.390, 1847.0, 42.9767
39.198986372, 96.390, 1788.0, 42.2847
39.251507502, 96.390, 1809.0, 42.5323
39.304028633, 96.390, 1817.0, 42.6263
39.356549764, 96.390, 1838.0, 42.8719
39.409070895, 96.390, 1750.0, 41.8330
39.461592025, 96.390, 1716.0, 41.4246
39.514113156, 96.390, 1767.0, 42.0357
39.566634287, 96.390, 1778.0, 42.1663
39.619155417, 96.390, 1757.0, 41.9166
39.671676548, 96.390, 1827.0, 42.7434
39.724197679, 96.390, 1708.0, 41.3280
39.776718810, 96.390, 1683.0, 41.0244
39.829239940, 96.390, 1721.0, 41.4849
39.881761071, 96.390, 1727.0, 41.5572
39.934282202, 96.390, 1643.0, 40.5339
39.986803332, 96.390, 1685.0, 41.0488
40.039324463, 96.390, 1666.0, 40.8167
40.091845594, 96.390, 1718.0, 41.4488
40.144366725, 96.390, 1765.0, 42.0119
40.196887855, 96.390, 1705.0, 41.2916
40.249408986, 96.390, 1709.0, 41.3401
40.301930117, 96.390, 1714.0, 41.4005
40.354451247, 96.390, 1674.0, 40.9145
40.406972378, 96.390, 1599.0, 39.9875
40.459493509, 96.390, 1730.0, 41.5933
40.512014639, 96.390, 1679.0, 40.9756
40.564535770, 96.390, 1611.0, 40.1373
40.617056901, 96.390, 1624.0, 40.2989
40.669578032, 96.390, 1588.0, 39.8497
40.722099162, 96.390, 1646.0, 40.5709
40.774620293, 96.390, 1628.0, 40.3485
40.827141424, 96.390, 1583.0, 39.7869
40.879662554, 96.390, 1616.0, 40.1995
40.932183685, 96.390, 1644.0, 40.5463
40.984704816, 96.390, 1589.0, 39.8623
41.037225947, 96.390, 1679.0, 40.9756
41.089747077, 96.390, 1605.0, 40.0625
41.142268208, 96.390, 1683.0, 41.0244
41.194789339, 96.390, 1615.0, 40.1871
41.247310469, 96.390, 1640.0, 40.4969
41.299831600, 96.390, 1654.0, 40.6694
41.352352731, 96.390, 1607.0, 40.0874
41.404873862, 96.390, 1600.0, 40.0000
41.457394992, 96.390, 1575.0, 39.6863
41.509916123, 96.390, 1647.0, 40.5832
41.562437254, 96.390, 1594.0, 39.9249
41.614958384, 96.390, 1632.0, 40.3980
41.667479515, 96.390, 1561.0, 39.5095
41.720000646, 96.390, 1558.0, 39.4715
41.772521776, 96.390, 1616.0, 40.1995
41.825042907, 96.390, 1658.0, 40.7185
41.877564038, 96.390, 1606.0, 40.0749
41.930085169, 96.390, 1667.0, 40.8289
41.982606299, 96.390, 1619.0, 40.2368
42.035127430, 96.390, 1717.0, 41.4367
42.087648561, 96.390, 1671.0, 40.8779
42.140169691, 96.390, 1655.0, 40.6817
42.192690822, 96.390, 1691.0, 41.1218
42.245211953, 96.390, 1760.0, 41.9524
42.297733084, 96.390, 1742.0, 41.7373
42.350254214, 96.390, 1768.0, 42.0476
42.402775345, 96.390, 1775.0, 42.1307
42.455296476, 96.390, 1897.0, 43.5546
42.507817606, 96.390, 1894.0, 43.5201
42.560338737, 96.390, 1941.0, 44.0568
42.612859868, 96.390, 1995.0, 44.6654
42.665380999, 96.390, 1940.0, 44.0454
42.717902129, 96.390, 2038.0, 45.1442
42.770423260, 96.390, 2205.0, 46.9574
42.822944391, 96.390, 2297.0, 47.9270
42.875465521, 96.390, 2378.0, 48.7647
42.927986652, 96.390, 2458.0, 49.5782
42.980507783, 96.390, 2391.0, 48.8979
43.033028914, 96.390, 2404.0, 49.0306
43.085550044, 96.390, 2314.0, 48.1041
43.138071175, 96.390, 2186.0, 46.7547
43.190592306, 96.390, 2012.0, 44.8553
43.243113436, 96.390, 2025.0, 45.0000
43.295634567, 96.390, 1952.0, 44.1814
43.348155698, 96.390, 1941.0, 44.0568
43.400676828, 96.390, 1791.0, 42.3202
43.453197959, 96.390, 1868.0, 43.2204
43.505719090, 96.390, 1759.0, 41.9404
43.558240221, 96.390, 1719.0, 41.4608
43.610761351, 96.390, 1700.0, 41.2311
43.663282482, 96.390, 1618.0, 40.2244
43.715803613, 96.390, 1747.0, 41.7971
43.768324743, 96.390, 1716.0, 41.4246
43.820845874, 96.390, 1699.0, 41.2189
43.873367005, 96.390, 1677.0, 40.9512
43.925888136, 96.390, 1645.0, 40.5586
43.978409266, 96.390, 1618.0, 40.2244
44.030930397, 96.390, 1608.0, 40.0999
44.083451528, 96.390, 1610.0, 40.1248
44.135972658, 96.390, 1546.0, 39.3192
44.188493789, 96.390, 1686.0, 41.0609
44.241014920, 96.390, 1596.0, 39.9500
44.293536051, 96.390, 1589.0, 39.8623
44.346057181, 96.390, 1542.0, 39.2683
44.398578312, 96.390, 1549.0, 39.3573
44.451099443, 96.390, 1472.0, 38.3667
44.503620573, 96.390, 1458.0, 38.1838
44.556141704, 96.390, 1520.0, 38.9872
44.608662835, 96.390, 1562.0, 39.5221
44.661183966, 96.390, 1523.0, 39.0256
44.713705096, 96.390, 1474.0, 38.3927
44.766226227, 96.390, 1437.0, 37.9078
44.818747358, 96.390, 1428.0, 37.7889
44.871268488, 96.390, 1426.0, 37.7624
44.923789619, 96.390, 1559.0, 39.4842
44.976310750, 96.390, 1482.0, 38.4968
45.028831880, 96.390, 1505.0, 38.7943
45.081353011, 96.390, 1450.0, 38.0789
45.133874142, 96.390, 1472.0, 38.3667
45.186395273, 96.390, 1409.0, 37.5366
45.238916403, 96.390, 1379.0, 37.1349
45.291437534, 96.390, 1405.0, 37.4833
45.343958665, 96.390, 1413.0, 37.5899
45.396479795, 96.390, 1366.0, 36.9594
45.449000926, 96.390, 1402.0, 37.4433
45.501522057, 96.390, 1363.0, 36.9188
45.554043188, 96.390, 1286.0, 35.8608
45.606564318, 96.390, 1313.0, 36.2353
45.659085449, 96.390, 1369.0, 37.0000
45.711606580, 96.390, 1337.0, 36.5650
45.764127710, 96.390, 1389.0, 37.2693
45.816648841, 96.390, 1310.0, 36.1939
45.869169972, 96.390, 1297.0, 36.0139
45.921691103, 96.390, 1320.0, 36.3318
45.974212233, 96.390, 1376.0, 37.0945
46.026733364, 96.390, 1336.0, 36.5513
46.079254495, 96.390, 1297.0, 36.0139
46.131775625, 96.390, 1282.0, 35.8050
46.184296756, 96.390, 1217.0, 34.8855
46.236817887, 96.390, 1354.0, 36.7967
46.289339017, 96.390, 1221.0, 34.9428
46.341860148, 96.390, 1330.0, 36.4692
46.394381279, 96.390, 1264.0, 35.5528
46.446902410, 96.390, 1229.0, 35.0571
46.499423540, 96.390, 1270.0, 35.6371
46.551944671, 96.390, 1188.0, 34.4674
46.604465802, 96.390, 1284.0, 35.8329
46.656986932, 96.390, 1246.0, 35.2987
46.709508063, 96.390, 1270.0, 35.6371
46.762029194, 96.390, 1229.0, 35.0571
46.814550325, 96.390, 1206.0, 34.7275
46.867071455, 96.390, 1281.0, 35.7911
46.919592586, 96.390, 1191.0, 34.5109
46.972113717, 96.390, 1211.0, 34.7994
47.024634847, 96.390, 1218.0, 34.8999
47.077155978, 96.390, 1212.0, 34.8138
47.129677109, 96.390, 1156.0, 34.0000
47.182198240, 96.390, 1234.0, 35.1283
47.234719370, 96.390, 1194.0, 34.5543
47.287240501, 96.390, 1108.0, 33.2866
47.339761632, 96.390, 1205.0, 34.7131
47.392282762, 96.390, 1153.0, 33.9559
47.444803893, 96.390, 1170.0, 34.2053
47.497325024, 96.390, 1240.0, 35.2136
47.549846155, 96.390, 1154.0, 33.9706
47.602367285, 96.390, 1132.0, 33.6452
47.654888416, 96.390, 1149.0, 33.8969
47.707409547, 96.390, 1187.0, 34.4529
47.759930677, 96.390, 1152.0, 33.9411
47.812451808, 96.390, 1141.0, 33.7787
47.864972939, 96.390, 1152.0, 33.9411
47.917494069, 96.390, 1120.0, 33.4664
47.970015200, 96.390, 1145.0, 33.8378
48.022536331, 96.390, 1158.0, 34.0294
48.075057462, 96.390, 1122.0, 33.4963
48.127578592, 96.390, 1129.0, 33.6006
48.180099723, 96.390, 1075.0, 32.7872
48.232620854, 96.390, 1081.0, 32.8786
48.285141984, 96.390, 1093.0, 33.0606
48.337663115, 96.390, 1114.0, 33.3766
48.390184246, 96.390, 1135.0, 33.6898
48.442705377, 96.390, 1136.0, 33.7046
48.495226507, 96.390, 1089.0, 33.0000
48.547747638, 96.390, 1081.0, 32.8786
48.600268769, 96.390, 1107.0, 33.2716
48.652789899, 96.390, 1092.0, 33.0454
48.705311030, 96.390, 1074.0, 32.7719
48.757832161, 96.390, 1029.0, 32.0780
48.810353292, 96.390, 1040.0, 32.2490
48.862874422, 96.390, 1072.0, 32.7414
48.915395553, 96.390, 1123.0, 33.5112
48.967916684, 96.390, 1046.0, 32.3419
49.020437814, 96.390, 1118.0, 33.4365
49.072958945, 96.390, 1068.0, 32.6803
49.125480076, 96.390, 1119.0, 33.4515
49.178001207, 96.390, 1093.0, 33.0606
49.230522337, 96.390, 1087.0, 32.9697
49.283043468, 96.390, 1060.0, 32.5576
49.335564599, 96.390, 1004.0, 31.6860
49.388085729, 96.390, 1090.0, 33.0151
49.440606860, 96.390, 1054.0, 32.4654
49.493127991, 96.390, 990.0, 31.4643
49.545649121, 96.390, 1060.0, 32.5576
49.598170252, 96.390, 1016.0, 31.8748
49.650691383, 96.390, 953.0, 30.8707
49.703212514, 96.390, 1076.0, 32.8024
49.755733644, 96.390, 972.0, 31.1769
49.808254775, 96.390, 1043.0, 32.2955
49.860775906, 96.390, 1032.0, 32.1248
49.913297036, 96.390, 1008.0, 31.7490
49.965818167, 96.390, 1021.0, 31.9531
50.018339298, 96.390, 997.0, 31.5753
50.070860429, 96.390, 987.0, 31.4166
50.123381559, 96.390, 989.0, 31.4484
50.175902690, 96.390, 1026.0, 32.0312
50.228423821, 96.390, 985.0, 31.3847
50.280944951, 96.390, 938.0, 30.6268
50.333466082, 96.390, 994.0, 31.5278
50.385987213, 96.390, 935.0, 30.5778
50.438508344, 96.390, 968.0, 31.1127
50.491029474, 96.390, 992.0, 31.4960
50.543550605, 96.390, 994.0, 31.5278
50.596071736, 96.390, 988.0, 31.4325
50.648592866, 96.390, 945.0, 30.7409
50.701113997, 96.390, 1001.0, 31.6386
50.753635128, 96.390, 961.0, 31.0000
50.806156258, 96.390, 981.0, 31.3209
50.858677389, 96.390, 922.0, 30.3645
50.911198520, 96.390, 986.0, 31.4006
50.963719651, 96.390, 995.0, 31.5436
51.016240781, 96.390, 925.0, 30.4138
51.068761912, 96.390, 959.0, 30.9677
51.121283043, 96.390, 976.0, 31.2410
51.173804173, 96.390, 966.0, 31.0805
51.226325304, 96.390, 942.0, 30.6920
51.278846435, 96.390, 982.0, 31.3369
51.331367566, 96.390, 910.0, 30.1662
51.383888696, 96.390, 996.0, 31.5595
51.436409827, 96.390, 921.0, 30.3480
51.488930958, 96.390, 941.0, 30.6757
51.541452088, 96.390, 936.0, 30.5941
51.593973219, 96.390, 934.0, 30.5614
51.646494350, 96.390, 888.0, 29.7993
51.699015481, 96.390, 981.0, 31.3209
51.751536611, 96.390, 957.0, 30.9354
51.804057742, 96.390, 944.0, 30.7246
51.856578873, 96.390, 964.0, 31.0483
51.909100003, 96.390, 932.0, 30.5287
51.961621134, 96.390, 962.0, 31.0161
52.014142265, 96.390, 890.0, 29.8329
52.066663396, 96.390, 963.0, 31.0322
52.119184526, 96.390, 941.0, 30.6757
52.171705657, 96.390, 892.0, 29.8664
52.224226788, 96.390, 971.0, 31.1609
52.276747918, 96.390, 937.0, 30.6105
52.329269049, 96.390, 939.0, 30.6431
52.381790180, 96.390, 865.0, 29.4109
52.434311310, 96.390, 900.0, 30.0000
52.486832441, 96.390, 979.0, 31.2890
52.539353572, 96.390, 946.0, 30.7571
52.591874703, 96.390, 890.0, 29.8329
52.644395833, 96.390, 861.0, 29.3428
52.696916964, 96.390, 862.0, 29.3598
52.749438095, 96.390, 868.0, 29.4618
52.801959225, 96.390, 947.0, 30.7734
52.854480356, 96.390, 938.0, 30.6268
52.907001487, 96.390, 937.0, 30.6105
52.959522618, 96.390, 948.0, 30.7896
53.012043748, 96.390, 884.0, 29.7321
53.064564879, 96.390, 937.0, 30.6105
53.117086010, 96.390, 938.0, 30.6268
53.169607140, 96.390, 876.0, 29.5973
53.222128271, 96.390, 909.0, 30.1496
53.274649402, 96.390, 934.0, 30.5614
53.327170533, 96.390, 915.0, 30.2490
53.379691663, 96.390, 873.0, 29.5466
53.432212794, 96.390, 847.0, 29.1033
53.484733925, 96.390, 880.0, 29.6648
53.537255055, 96.390, 926.0, 30.4302
53.589776186, 96.390, 871.0, 29.5127
53.642297317, 96.390, 922.0, 30.3645
53.694818448, 96.390, 843.0, 29.0345
53.747339578, 96.390, 927.0, 30.4467
53.799860709, 96.390, 906.0, 30.0998
53.852381840, 96.390, 917.0, 30.2820
53.904902970, 96.390, 862.0, 29.3598
53.957424101, 96.390, 838.0, 28.9482
54.009945232, 96.390, 885.0, 29.7489
54.062466362, 96.390, 902.0, 30.0333
54.114987493, 96.390, 927.0, 30.4467
54.167508624, 96.390, 862.0, 29.3598
54.220029755, 96.390, 911.0, 30.1828
54.272550885, 96.390, 880.0, 29.6648
54.325072016, 96.390, 904.0, 30.0666
54.377593147, 96.390, 899.0, 29.9833
54.430114277, 96.390, 873.0, 29.5466
54.482635408, 96.390, 954.0, 30.8869
54.535156539, 96.390, 825.0, 28.7228
54.587677670, 96.390, 866.0, 29.4279
54.640198800, 96.390, 917.0, 30.2820
54.692719931, 96.390, 933.0, 30.5450
54.745241062, 96.390, 870.0, 29.4958
54.797762192, 96.390, 901.0, 30.0167
54.850283323, 96.390, 914.0, 30.2324
54.902804454, 96.390, 871.0, 29.5127
54.955325585, 96.390, 886.0, 29.7658
55.007846715, 96.390, 894.0, 29.8998
55.060367846, 96.390, 860.0, 29.3258
55.112888977, 96.390, 904.0, 30.0666
55.165410107, 96.390, 886.0, 29.7658
55.217931238, 96.390, 928.0, 30.4631
55.270452369, 96.390, 882.0, 29.6985
55.322973499, 96.390, 879.0, 29.6479
55.375494630, 96.390, 893.0, 29.8831
55.428015761, 96.390, 852.0, 29.1890
55.480536892, 96.390, 888.0, 29.7993
55.533058022, 96.390, 932.0, 30.5287
55.585579153, 96.390, 892.0, 29.8664
55.638100284, 96.390, 864.0, 29.3939
55.690621414, 96.390, 879.0, 29.6479
55.743142545, 96.390, 852.0, 29.1890
55.795663676, 96.390, 863.0, 29.3769
55.848184807, 96.390, 850.0, 29.1548
55.900705937, 96.390, 899.0, 29.9833
55.953227068, 96.390, 851.0, 29.1719
56.005748199, 96.390, 884.0, 29.7321
56.058269329, 96.390, 861.0, 29.3428
56.110790460, 96.390, 881.0, 29.6816
56.163311591, 96.390, 842.0, 29.0172
56.215832722, 96.390, 845.0, 29.0689
56.268353852, 96.390, 852.0, 29.1890
56.320874983, 96.390, 868.0, 29.4618
56.373396114, 96.390, 876.0, 29.5973
56.425917244, 96.390, 881.0, 29.6816
56.478438375, 96.390, 860.0, 29.3258
56.530959506, 96.390, 844.0, 29.0517
56.583480637, 96.390, 872.0, 29.5296
56.636001767, 96.390, 912.0, 30.1993
56.688522898, 96.390, 865.0, 29.4109
56.741044029, 96.390, 881.0, 29.6816
56.793565159, 96.390, 917.0, 30.2820
56.846086290, 96.390, 897.0, 29.9500
56.898607421, 96.390, 878.0, 29.6311
56.951128551, 96.390, 876.0, 29.5973
57.003649682, 96.390, 867.0, 29.4449
57.056170813, 96.390, 910.0, 30.1662
57.108691944, 96.390, 894.0, 29.8998
57.161213074, 96.390, 867.0, 29.4449
57.213734205, 96.390, 824.0, 28.7054
57.266255336, 96.390, 818.0, 28.6007
57.318776466, 96.390, 812.0, 28.4956
57.371297597, 96.390, 857.0, 29.2746
57.423818728, 96.390, 857.0, 29.2746
57.476339859, 96.390, 913.0, 30.2159
57.528860989, 96.390, 922.0, 30.3645
57.581382120, 96.390, 829.0, 28.7924
57.633903251, 96.390, 856.0, 29.2575
57.686424381, 96.390, 860.0, 29.3258
57.738945512, 96.390, 940.0, 30.6594
57.791466643, 96.390, 858.0, 29.2916
57.843987774, 96.390, 873.0, 29.5466
57.896508904, 96.390, 888.0, 29.7993
57.949030035, 96.390, 933.0, 30.5450
58.001551166, 96.390, 942.0, 30.6920
58.054072296, 96.390, 914.0, 30.2324
58.106593427, 96.390, 877.0, 29.6142
58.159114558, 96.390, 894.0, 29.8998
58.211635689, 96.390, 912.0, 30.1993
58.264156819, 96.390, 912.0, 30.1993
58.316677950, 96.390, 907.0, 30.1164
58.369199081, 96.390, 957.0, 30.9354
58.421720211, 96.390, 901.0, 30.0167
58.474241342, 96.390, 899.0, 29.9833
58.526762473, 96.390, 986.0, 31.4006
58.579283603, 96.390, 985.0, 31.3847
58.631804734, 96.390, 987.0, 31.4166
58.684325865, 96.390, 958.0, 30.9516
58.736846996, 96.390, 1047.0, 32.3574
58.789368126, 96.390, 936.0, 30.5941
58.841889257, 96.390, 1011.0, 31.7962
58.894410388, 96.390, 983.0, 31.3528
58.946931518, 96.390, 996.0, 31.5595
58.999452649, 96.390, 984.0, 31.3688
59.051973780, 96.390, 1059.0, 32.5423
59.104494911, 96.390, 1029.0, 32.0780
59.157016041, 96.390, 1030.0, 32.0936
59.209537172, 96.390, 1027.0, 32.0468
59.262058303, 96.390, 1051.0, 32.4191
59.314579433, 96.390, 1106.0, 33.2566
59.367100564, 96.390, 1067.0, 32.6650
59.419621695, 96.390, 1167.0, 34.1614
59.472142826, 96.390, 1183.0, 34.3948
59.524663956, 96.390, 1185.0, 34.4238
59.577185087, 96.390, 1295.0, 35.9861
59.629706218, 96.390, 1177.0, 34.3074
59.682227348, 96.390, 1179.0, 34.3366
59.734748479, 96.390, 1240.0, 35.2136
59.787269610, 96.390, 1257.0, 35.4542
59.839790740, 96.390, 1402.0, 37.4433
59.892311871, 96.390, 1385.0, 37.2156
59.944833002, 96.390, 1399.0, 37.4032
59.997354133, 96.390, 1461.0, 38.2230
60.049875263, 96.390, 1447.0, 38.0395
60.102396394, 96.390, 1492.0, 38.6264
60.154917525, 96.390, 1458.0, 38.1838
60.207438655, 96.390, 1560.0, 39.4968
60.259959786, 96.390, 1581.0, 39.7618
60.312480917, 96.390, 1636.0, 40.4475
60.365002048, 96.390, 1543.0, 39.2810
60.417523178, 96.390, 1688.0, 41.0853
60.470044309, 96.390, 1637.0, 40.4599
60.522565440, 96.390, 1607.0, 40.0874
60.575086570, 96.390, 1622.0, 40.2741
60.627607701, 96.390, 1677.0, 40.9512
60.680128832, 96.390, 1631.0, 40.3856
60.732649963, 96.390, 1700.0, 41.2311
60.785171093, 96.390, 1626.0, 40.3237
60.837692224, 96.390, 1633.0, 40.4104
60.890213355, 96.390, 1654.0, 40.6694
60.942734485, 96.390, 1543.0, 39.2810
60.995255616, 96.390, 1589.0, 39.8623
61.047776747, 96.390, 1586.0, 39.8246
61.100297878, 96.390, 1533.0, 39.1535
61.152819008, 96.390, 1538.0, 39.2173
61.205340139, 96.390, 1461.0, 38.2230
61.257861270, 96.390, 1456.0, 38.1576
61.310382400, 96.390, 1530.0, 39.1152
61.362903531, 96.390, 1520.0, 38.9872
61.415424662, 96.390, 1484.0, 38.5227
61.467945792, 96.390, 1458.0, 38.1838
61.520466923, 96.390, 1583.0, 39.7869
61.572988054, 96.390, 1418.0, 37.6563
61.625509185, 96.390, 1438.0, 37.9210
61.678030315, 96.390, 1439.0, 37.9342
61.730551446, 96.390, 1528.0, 39.0896
61.783072577, 96.390, 1444.0, 38.0000
61.835593707, 96.390, 1424.0, 37.7359
61.888114838, 96.390, 1390.0, 37.2827
61.940635969, 96.390, 1455.0, 38.1445
61.993157100, 96.390, 1498.0, 38.7040
62.045678230, 96.390, 1525.0, 39.0512
62.098199361, 96.390, 1515.0, 38.9230
62.150720492, 96.390, 1552.0, 39.3954
62.203241622, 96.390, 1473.0, 38.3797
62.255762753, 96.390, 1557.0, 39.4588
62.308283884, 96.390, 1566.0, 39.5727
62.360805015, 96.390, 1505.0, 38.7943
62.413326145, 96.390, 1520.0, 38.9872
62.465847276, 96.390, 1485.0, 38.5357
62.518368407, 96.390, 1450.0, 38.0789
62.570889537, 96.390, 1355.0, 36.8103
62.623410668, 96.390, 1340.0, 36.6060
62.675931799, 96.390, 1377.0, 37.1080
62.728452930, 96.390, 1271.0, 35.6511
62.780974060, 96.390, 1233.0, 35.1141
62.833495191, 96.390, 1209.0, 34.7707
62.886016322, 96.390, 1206.0, 34.7275
62.938537452, 96.390, 1209.0, 34.7707
62.991058583, 96.390, 1165.0, 34.1321
63.043579714, 96.390, 1145.0, 33.8378
63.096100844, 96.390, 1148.0, 33.8821
63.148621975, 96.390, 1119.0, 33.4515
63.201143106, 96.390, 1022.0, 31.9687
63.253664237, 96.390, 1071.0, 32.7261
63.306185367, 96.390, 1063.0, 32.6037
63.358706498, 96.390, 968.0, 31.1127
63.411227629, 96.390, 1026.0, 32.0312
63.463748759, 96.390, 990.0, 31.4643
63.516269890, 96.390, 944.0, 30.7246
63.568791021, 96.390, 999.0, 31.6070
63.621312152, 96.390, 980.0, 31.3050
63.673833282, 96.390, 964.0, 31.0483
63.726354413, 96.390, 899.0, 29.9833
63.778875544, 96.390, 947.0, 30.7734
63.831396674, 96.390, 950.0, 30.8221
63.883917805, 96.390, 955.0, 30.9031
63.936438936, 96.390, 918.0, 30.2985
63.988960067, 96.390, 923.0, 30.3809
64.041481197, 96.390, 913.0, 30.2159
64.094002328, 96.390, 871.0, 29.5127
64.146523459, 96.390, 921.0, 30.3480
64.199044589, 96.390, 862.0, 29.3598
64.251565720, 96.390, 894.0, 29.8998
64.304086851, 96.390, 880.0, 29.6648
64.356607981, 96.390, 876.0, 29.5973
64.409129112, 96.390, 803.0, 28.3373
64.461650243, 96.390, 827.0, 28.7576
64.514171374, 96.390, 863.0, 29.3769
64.566692504, 96.390, 795.0, 28.1957
64.619213635, 96.390, 846.0, 29.0861
64.671734766, 96.390, 841.0, 29.0000
64.724255896, 96.390, 832.0, 28.8444
64.776777027, 96.390, 818.0, 28.6007
64.829298158, 96.390, 850.0, 29.1548
64.881819289, 96.390, 806.0, 28.3901
64.934340419, 96.390, 804.0, 28.3549
64.986861550, 96.390, 865.0, 29.4109