File: Files_organized_for_plots/Na_to_Al_1/XRD_SiCorner03Nov21_Act18Jan22_B6_0242M_NaOH_LS0106_1.csv
[Measurement conditions]
Sample identification,XRD_SiCorner03Nov21_Act18Jan22_B6_0242M_NaOH_LS0106_1
Comment - 1,"Configuration=Stage for Flat Samples/Holders, Owner=User-1, Creation date=7/1/2020 9:53:24 AM"
Comment - 2,"Goniometer=Theta/Theta; Minimum step size 2Theta:0.0001; Minimum step size Omega:0.0001"
Comment - 3,"Sample stage=Stage for flat samples/holders"
Comment - 4,"Diffractometer system=EMPYREAN"
Comment - 5,"Measurement program=C:\Users\ibo5034\OneDrive - The Pennsylvania State University\NEUP - Reed, Titus's files\XRD\Cement\Zerobackground scan.xrdmp, Identifier={98A3B11C-88F9-4AA6-982C-73314A311EF5}"
Anode material,Cu
K-Alpha1 wavelength,1.5405980
K-Alpha2 wavelength,1.5444260
Ratio K-Alpha2/K-Alpha1,0.500
Divergence slit,Fixed,0.25
Monochromator used,NO
Generator voltage, 45
Tube current, 40
File date and time,21/Jan/2022 11:44
Unit cell,
h k l, 0 0 0
Scan axis,Gonio
Scan range,4.994599997,64.999991833
Scan step size,0.0262606
No. of points, 2285
Scan type,CONTINUOUS
Time per step,96.390
[Scan points]
Angle, TimePerStep, Intensity, ESD
5.007730280, 96.390, 6023.0, 77.6080
5.060251411, 96.390, 6056.0, 77.8203
5.112772541, 96.390, 5972.0, 77.2787
5.165293672, 96.390, 5735.0, 75.7298
5.217814803, 96.390, 5694.0, 75.4586
5.270335934, 96.390, 5773.0, 75.9803
5.322857064, 96.390, 5530.0, 74.3640
5.375378195, 96.390, 5455.0, 73.8580
5.427899326, 96.390, 5485.0, 74.0608
5.480420456, 96.390, 5351.0, 73.1505
5.532941587, 96.390, 5113.0, 71.5052
5.585462718, 96.390, 5121.0, 71.5612
5.637983849, 96.390, 5160.0, 71.8331
5.690504979, 96.390, 5010.0, 70.7814
5.743026110, 96.390, 4952.0, 70.3704
5.795547241, 96.390, 4849.0, 69.6348
5.848068371, 96.390, 4953.0, 70.3776
5.900589502, 96.390, 4965.0, 70.4628
5.953110633, 96.390, 4944.0, 70.3136
6.005631763, 96.390, 4903.0, 70.0214
6.058152894, 96.390, 4658.0, 68.2495
6.110674025, 96.390, 4735.0, 68.8113
6.163195156, 96.390, 4836.0, 69.5414
6.215716286, 96.390, 4523.0, 67.2533
6.268237417, 96.390, 4645.0, 68.1542
6.320758548, 96.390, 4580.0, 67.6757
6.373279678, 96.390, 4562.0, 67.5426
6.425800809, 96.390, 4419.0, 66.4756
6.478321940, 96.390, 4576.0, 67.6461
6.530843071, 96.390, 4407.0, 66.3852
6.583364201, 96.390, 4382.0, 66.1967
6.635885332, 96.390, 4478.0, 66.9179
6.688406463, 96.390, 4355.0, 65.9924
6.740927593, 96.390, 4504.0, 67.1118
6.793448724, 96.390, 4342.0, 65.8939
6.845969855, 96.390, 4469.0, 66.8506
6.898490986, 96.390, 4280.0, 65.4217
6.951012116, 96.390, 4242.0, 65.1306
7.003533247, 96.390, 4293.0, 65.5210
7.056054378, 96.390, 4220.0, 64.9615
7.108575508, 96.390, 4246.0, 65.1613
7.161096639, 96.390, 4240.0, 65.1153
7.213617770, 96.390, 4171.0, 64.5833
7.266138900, 96.390, 4205.0, 64.8460
7.318660031, 96.390, 4093.0, 63.9766
7.371181162, 96.390, 4135.0, 64.3040
7.423702293, 96.390, 3970.0, 63.0079
7.476223423, 96.390, 4116.0, 64.1561
7.528744554, 96.390, 4005.0, 63.2851
7.581265685, 96.390, 3966.0, 62.9762
7.633786815, 96.390, 3948.0, 62.8331
7.686307946, 96.390, 3982.0, 63.1031
7.738829077, 96.390, 3927.0, 62.6658
7.791350208, 96.390, 3917.0, 62.5859
7.843871338, 96.390, 4037.0, 63.5374
7.896392469, 96.390, 3907.0, 62.5060
7.948913600, 96.390, 3831.0, 61.8951
8.001434730, 96.390, 3852.0, 62.0645
8.053955861, 96.390, 3854.0, 62.0806
8.106476992, 96.390, 3885.0, 62.3298
8.158998123, 96.390, 3798.0, 61.6279
8.211519253, 96.390, 3689.0, 60.7371
8.264040384, 96.390, 3928.0, 62.6738
8.316561515, 96.390, 3666.0, 60.5475
8.369082645, 96.390, 3899.0, 62.4420
8.421603776, 96.390, 3837.0, 61.9435
8.474124907, 96.390, 3778.0, 61.4654
8.526646038, 96.390, 3756.0, 61.2862
8.579167168, 96.390, 3817.0, 61.7819
8.631688299, 96.390, 3626.0, 60.2163
8.684209430, 96.390, 3810.0, 61.7252
8.736730560, 96.390, 3657.0, 60.4731
8.789251691, 96.390, 3592.0, 59.9333
8.841772822, 96.390, 3749.0, 61.2291
8.894293952, 96.390, 3655.0, 60.4566
8.946815083, 96.390, 3664.0, 60.5310
8.999336214, 96.390, 3648.0, 60.3987
9.051857345, 96.390, 3558.0, 59.6490
9.104378475, 96.390, 3526.0, 59.3801
9.156899606, 96.390, 3574.0, 59.7829
9.209420737, 96.390, 3606.0, 60.0500
9.261941867, 96.390, 3512.0, 59.2621
9.314462998, 96.390, 3471.0, 58.9152
9.366984129, 96.390, 3499.0, 59.1523
9.419505260, 96.390, 3554.0, 59.6154
9.472026390, 96.390, 3441.0, 58.6600
9.524547521, 96.390, 3385.0, 58.1808
9.577068652, 96.390, 3393.0, 58.2495
9.629589782, 96.390, 3508.0, 59.2284
9.682110913, 96.390, 3503.0, 59.1861
9.734632044, 96.390, 3355.0, 57.9224
9.787153175, 96.390, 3384.0, 58.1722
9.839674305, 96.390, 3346.0, 57.8446
9.892195436, 96.390, 3223.0, 56.7715
9.944716567, 96.390, 3378.0, 58.1206
9.997237697, 96.390, 3353.0, 57.9051
10.049758828, 96.390, 3311.0, 57.5413
10.102279959, 96.390, 3468.0, 58.8897
10.154801090, 96.390, 3274.0, 57.2189
10.207322220, 96.390, 3310.0, 57.5326
10.259843351, 96.390, 3312.0, 57.5500
10.312364482, 96.390, 3282.0, 57.2887
10.364885612, 96.390, 3249.0, 57.0000
10.417406743, 96.390, 3222.0, 56.7627
10.469927874, 96.390, 3162.0, 56.2317
10.522449004, 96.390, 3265.0, 57.1402
10.574970135, 96.390, 3205.0, 56.6127
10.627491266, 96.390, 3178.0, 56.3738
10.680012397, 96.390, 3232.0, 56.8507
10.732533527, 96.390, 3180.0, 56.3915
10.785054658, 96.390, 3183.0, 56.4181
10.837575789, 96.390, 3083.0, 55.5248
10.890096919, 96.390, 3106.0, 55.7315
10.942618050, 96.390, 3108.0, 55.7494
10.995139181, 96.390, 3140.0, 56.0357
11.047660312, 96.390, 3114.0, 55.8032
11.100181442, 96.390, 2931.0, 54.1387
11.152702573, 96.390, 3001.0, 54.7814
11.205223704, 96.390, 3143.0, 56.0625
11.257744834, 96.390, 3164.0, 56.2494
11.310265965, 96.390, 2989.0, 54.6717
11.362787096, 96.390, 2899.0, 53.8424
11.415308227, 96.390, 2924.0, 54.0740
11.467829357, 96.390, 2894.0, 53.7959
11.520350488, 96.390, 3015.0, 54.9090
11.572871619, 96.390, 3014.0, 54.8999
11.625392749, 96.390, 2867.0, 53.5444
11.677913880, 96.390, 2964.0, 54.4426
11.730435011, 96.390, 2865.0, 53.5257
11.782956141, 96.390, 2872.0, 53.5910
11.835477272, 96.390, 2779.0, 52.7162
11.887998403, 96.390, 2830.0, 53.1977
11.940519534, 96.390, 2850.0, 53.3854
11.993040664, 96.390, 2879.0, 53.6563
12.045561795, 96.390, 2902.0, 53.8702
12.098082926, 96.390, 2902.0, 53.8702
12.150604056, 96.390, 2842.0, 53.3104
12.203125187, 96.390, 2934.0, 54.1664
12.255646318, 96.390, 2876.0, 53.6284
12.308167449, 96.390, 2836.0, 53.2541
12.360688579, 96.390, 2842.0, 53.3104
12.413209710, 96.390, 2769.0, 52.6213
12.465730841, 96.390, 2781.0, 52.7352
12.518251971, 96.390, 2767.0, 52.6023
12.570773102, 96.390, 2794.0, 52.8583
12.623294233, 96.390, 2749.0, 52.4309
12.675815364, 96.390, 2744.0, 52.3832
12.728336494, 96.390, 2751.0, 52.4500
12.780857625, 96.390, 2659.0, 51.5655
12.833378756, 96.390, 2812.0, 53.0283
12.885899886, 96.390, 2658.0, 51.5558
12.938421017, 96.390, 2705.0, 52.0096
12.990942148, 96.390, 2736.0, 52.3068
13.043463279, 96.390, 2689.0, 51.8556
13.095984409, 96.390, 2717.0, 52.1249
13.148505540, 96.390, 2712.0, 52.0769
13.201026671, 96.390, 2705.0, 52.0096
13.253547801, 96.390, 2656.0, 51.5364
13.306068932, 96.390, 2775.0, 52.6783
13.358590063, 96.390, 2595.0, 50.9411
13.411111193, 96.390, 2610.0, 51.0882
13.463632324, 96.390, 2589.0, 50.8822
13.516153455, 96.390, 2739.0, 52.3355
13.568674586, 96.390, 2662.0, 51.5946
13.621195716, 96.390, 2602.0, 51.0098
13.673716847, 96.390, 2532.0, 50.3190
13.726237978, 96.390, 2480.0, 49.7996
13.778759108, 96.390, 2563.0, 50.6261
13.831280239, 96.390, 2615.0, 51.1371
13.883801370, 96.390, 2535.0, 50.3488
13.936322501, 96.390, 2650.0, 51.4782
13.988843631, 96.390, 2600.0, 50.9902
14.041364762, 96.390, 2538.0, 50.3786
14.093885893, 96.390, 2539.0, 50.3885
14.146407023, 96.390, 2517.0, 50.1697
14.198928154, 96.390, 2598.0, 50.9706
14.251449285, 96.390, 2495.0, 49.9500
14.303970416, 96.390, 2521.0, 50.2096
14.356491546, 96.390, 2549.0, 50.4876
14.409012677, 96.390, 2538.0, 50.3786
14.461533808, 96.390, 2485.0, 49.8498
14.514054938, 96.390, 2465.0, 49.6488
14.566576069, 96.390, 2523.0, 50.2295
14.619097200, 96.390, 2445.0, 49.4469
14.671618331, 96.390, 2421.0, 49.2037
14.724139461, 96.390, 2510.0, 50.0999
14.776660592, 96.390, 2435.0, 49.3457
14.829181723, 96.390, 2500.0, 50.0000
14.881702853, 96.390, 2453.0, 49.5278
14.934223984, 96.390, 2424.0, 49.2341
14.986745115, 96.390, 2574.0, 50.7346
15.039266245, 96.390, 2511.0, 50.1099
15.091787376, 96.390, 2555.0, 50.5470
15.144308507, 96.390, 2450.0, 49.4975
15.196829638, 96.390, 2520.0, 50.1996
15.249350768, 96.390, 2463.0, 49.6286
15.301871899, 96.390, 2457.0, 49.5681
15.354393030, 96.390, 2493.0, 49.9300
15.406914160, 96.390, 2441.0, 49.4065
15.459435291, 96.390, 2452.0, 49.5177
15.511956422, 96.390, 2555.0, 50.5470
15.564477553, 96.390, 2470.0, 49.6991
15.616998683, 96.390, 2495.0, 49.9500
15.669519814, 96.390, 2623.0, 51.2152
15.722040945, 96.390, 2403.0, 49.0204
15.774562075, 96.390, 2611.0, 51.0979
15.827083206, 96.390, 2501.0, 50.0100
15.879604337, 96.390, 2566.0, 50.6557
15.932125468, 96.390, 2525.0, 50.2494
15.984646598, 96.390, 2474.0, 49.7393
16.037167729, 96.390, 2452.0, 49.5177
16.089688860, 96.390, 2356.0, 48.5386
16.142209990, 96.390, 2580.0, 50.7937
16.194731121, 96.390, 2545.0, 50.4480
16.247252252, 96.390, 2634.0, 51.3225
16.299773382, 96.390, 2506.0, 50.0600
16.352294513, 96.390, 2490.0, 49.8999
16.404815644, 96.390, 2520.0, 50.1996
16.457336775, 96.390, 2591.0, 50.9019
16.509857905, 96.390, 2573.0, 50.7247
16.562379036, 96.390, 2496.0, 49.9600
16.614900167, 96.390, 2507.0, 50.0700
16.667421297, 96.390, 2656.0, 51.5364
16.719942428, 96.390, 2619.0, 51.1762
16.772463559, 96.390, 2660.0, 51.5752
16.824984690, 96.390, 2487.0, 49.8698
16.877505820, 96.390, 2629.0, 51.2738
16.930026951, 96.390, 2688.0, 51.8459
16.982548082, 96.390, 2637.0, 51.3517
17.035069212, 96.390, 2637.0, 51.3517
17.087590343, 96.390, 2653.0, 51.5073
17.140111474, 96.390, 2633.0, 51.3128
17.192632605, 96.390, 2614.0, 51.1273
17.245153735, 96.390, 2721.0, 52.1632
17.297674866, 96.390, 2652.0, 51.4976
17.350195997, 96.390, 2649.0, 51.4684
17.402717127, 96.390, 2677.0, 51.7397
17.455238258, 96.390, 2637.0, 51.3517
17.507759389, 96.390, 2713.0, 52.0865
17.560280520, 96.390, 2773.0, 52.6593
17.612801650, 96.390, 2775.0, 52.6783
17.665322781, 96.390, 2760.0, 52.5357
17.717843912, 96.390, 2750.0, 52.4404
17.770365042, 96.390, 2825.0, 53.1507
17.822886173, 96.390, 2802.0, 52.9339
17.875407304, 96.390, 2828.0, 53.1789
17.927928434, 96.390, 2736.0, 52.3068
17.980449565, 96.390, 2827.0, 53.1695
18.032970696, 96.390, 2885.0, 53.7122
18.085491827, 96.390, 2928.0, 54.1110
18.138012957, 96.390, 2863.0, 53.5070
18.190534088, 96.390, 2899.0, 53.8424
18.243055219, 96.390, 3001.0, 54.7814
18.295576349, 96.390, 2905.0, 53.8981
18.348097480, 96.390, 2854.0, 53.4228
18.400618611, 96.390, 2888.0, 53.7401
18.453139742, 96.390, 3017.0, 54.9272
18.505660872, 96.390, 3048.0, 55.2087
18.558182003, 96.390, 2986.0, 54.6443
18.610703134, 96.390, 3041.0, 55.1453
18.663224264, 96.390, 2974.0, 54.5344
18.715745395, 96.390, 3028.0, 55.0273
18.768266526, 96.390, 3125.0, 55.9017
18.820787657, 96.390, 3135.0, 55.9911
18.873308787, 96.390, 2978.0, 54.5711
18.925829918, 96.390, 3108.0, 55.7494
18.978351049, 96.390, 3087.0, 55.5608
19.030872179, 96.390, 3232.0, 56.8507
19.083393310, 96.390, 3184.0, 56.4269
19.135914441, 96.390, 3111.0, 55.7763
19.188435572, 96.390, 3222.0, 56.7627
19.240956702, 96.390, 3202.0, 56.5862
19.293477833, 96.390, 3261.0, 57.1052
19.345998964, 96.390, 3207.0, 56.6304
19.398520094, 96.390, 3216.0, 56.7098
19.451041225, 96.390, 3290.0, 57.3585
19.503562356, 96.390, 3328.0, 57.6888
19.556083486, 96.390, 3277.0, 57.2451
19.608604617, 96.390, 3324.0, 57.6541
19.661125748, 96.390, 3413.0, 58.4209
19.713646879, 96.390, 3460.0, 58.8218
19.766168009, 96.390, 3495.0, 59.1185
19.818689140, 96.390, 3420.0, 58.4808
19.871210271, 96.390, 3455.0, 58.7792
19.923731401, 96.390, 3518.0, 59.3127
19.976252532, 96.390, 3532.0, 59.4306
20.028773663, 96.390, 3466.0, 58.8727
20.081294794, 96.390, 3589.0, 59.9083
20.133815924, 96.390, 3700.0, 60.8276
20.186337055, 96.390, 3612.0, 60.0999
20.238858186, 96.390, 3621.0, 60.1747
20.291379316, 96.390, 3603.0, 60.0250
20.343900447, 96.390, 3620.0, 60.1664
20.396421578, 96.390, 3654.0, 60.4483
20.448942709, 96.390, 3776.0, 61.4492
20.501463839, 96.390, 3637.0, 60.3075
20.553984970, 96.390, 3687.0, 60.7207
20.606506101, 96.390, 3826.0, 61.8547
20.659027231, 96.390, 3674.0, 60.6135
20.711548362, 96.390, 3800.0, 61.6441
20.764069493, 96.390, 3818.0, 61.7900
20.816590623, 96.390, 3737.0, 61.1310
20.869111754, 96.390, 3781.0, 61.4898
20.921632885, 96.390, 3659.0, 60.4897
20.974154016, 96.390, 3712.0, 60.9262
21.026675146, 96.390, 3795.0, 61.6036
21.079196277, 96.390, 3857.0, 62.1048
21.131717408, 96.390, 3854.0, 62.0806
21.184238538, 96.390, 3874.0, 62.2415
21.236759669, 96.390, 3800.0, 61.6441
21.289280800, 96.390, 3791.0, 61.5711
21.341801931, 96.390, 3886.0, 62.3378
21.394323061, 96.390, 3861.0, 62.1369
21.446844192, 96.390, 3916.0, 62.5780
21.499365323, 96.390, 3843.0, 61.9919
21.551886453, 96.390, 3904.0, 62.4820
21.604407584, 96.390, 4019.0, 63.3956
21.656928715, 96.390, 4025.0, 63.4429
21.709449846, 96.390, 3969.0, 63.0000
21.761970976, 96.390, 3814.0, 61.7576
21.814492107, 96.390, 4013.0, 63.3482
21.867013238, 96.390, 4079.0, 63.8670
21.919534368, 96.390, 3896.0, 62.4179
21.972055499, 96.390, 4019.0, 63.3956
22.024576630, 96.390, 3996.0, 63.2139
22.077097761, 96.390, 4028.0, 63.4665
22.129618891, 96.390, 3965.0, 62.9682
22.182140022, 96.390, 4007.0, 63.3009
22.234661153, 96.390, 3926.0, 62.6578
22.287182283, 96.390, 3811.0, 61.7333
22.339703414, 96.390, 3962.0, 62.9444
22.392224545, 96.390, 3821.0, 61.8142
22.444745675, 96.390, 3932.0, 62.7057
22.497266806, 96.390, 3799.0, 61.6360
22.549787937, 96.390, 3816.0, 61.7738
22.602309068, 96.390, 3922.0, 62.6259
22.654830198, 96.390, 3759.0, 61.3107
22.707351329, 96.390, 3926.0, 62.6578
22.759872460, 96.390, 3933.0, 62.7136
22.812393590, 96.390, 3838.0, 61.9516
22.864914721, 96.390, 3820.0, 61.8061
22.917435852, 96.390, 3879.0, 62.2816
22.969956983, 96.390, 3782.0, 61.4980
23.022478113, 96.390, 3827.0, 61.8628
23.074999244, 96.390, 3798.0, 61.6279
23.127520375, 96.390, 3845.0, 62.0081
23.180041505, 96.390, 3867.0, 62.1852
23.232562636, 96.390, 3783.0, 61.5061
23.285083767, 96.390, 3757.0, 61.2944
23.337604898, 96.390, 3736.0, 61.1228
23.390126028, 96.390, 3787.0, 61.5386
23.442647159, 96.390, 3593.0, 59.9416
23.495168290, 96.390, 3699.0, 60.8194
23.547689420, 96.390, 3636.0, 60.2993
23.600210551, 96.390, 3679.0, 60.6548
23.652731682, 96.390, 3614.0, 60.1166
23.705252813, 96.390, 3606.0, 60.0500
23.757773943, 96.390, 3492.0, 59.0931
23.810295074, 96.390, 3518.0, 59.3127
23.862816205, 96.390, 3600.0, 60.0000
23.915337335, 96.390, 3598.0, 59.9833
23.967858466, 96.390, 3532.0, 59.4306
24.020379597, 96.390, 3544.0, 59.5315
24.072900727, 96.390, 3535.0, 59.4559
24.125421858, 96.390, 3424.0, 58.5150
24.177942989, 96.390, 3467.0, 58.8812
24.230464120, 96.390, 3365.0, 58.0086
24.282985250, 96.390, 3348.0, 57.8619
24.335506381, 96.390, 3402.0, 58.3267
24.388027512, 96.390, 3342.0, 57.8100
24.440548642, 96.390, 3379.0, 58.1292
24.493069773, 96.390, 3299.0, 57.4369
24.545590904, 96.390, 3353.0, 57.9051
24.598112035, 96.390, 3301.0, 57.4543
24.650633165, 96.390, 3267.0, 57.1577
24.703154296, 96.390, 3196.0, 56.5332
24.755675427, 96.390, 3167.0, 56.2761
24.808196557, 96.390, 3215.0, 56.7010
24.860717688, 96.390, 3192.0, 56.4978
24.913238819, 96.390, 3111.0, 55.7763
24.965759950, 96.390, 3128.0, 55.9285
25.018281080, 96.390, 3171.0, 56.3116
25.070802211, 96.390, 3292.0, 57.3760
25.123323342, 96.390, 3063.0, 55.3444
25.175844472, 96.390, 3089.0, 55.5788
25.228365603, 96.390, 2997.0, 54.7449
25.280886734, 96.390, 3095.0, 55.6327
25.333407864, 96.390, 2996.0, 54.7357
25.385928995, 96.390, 2998.0, 54.7540
25.438450126, 96.390, 2977.0, 54.5619
25.490971257, 96.390, 3021.0, 54.9636
25.543492387, 96.390, 2893.0, 53.7866
25.596013518, 96.390, 3025.0, 55.0000
25.648534649, 96.390, 3012.0, 54.8817
25.701055779, 96.390, 2894.0, 53.7959
25.753576910, 96.390, 2856.0, 53.4416
25.806098041, 96.390, 2831.0, 53.2071
25.858619172, 96.390, 2950.0, 54.3139
25.911140302, 96.390, 2793.0, 52.8488
25.963661433, 96.390, 3007.0, 54.8361
26.016182564, 96.390, 2830.0, 53.1977
26.068703694, 96.390, 2821.0, 53.1131
26.121224825, 96.390, 2756.0, 52.4976
26.173745956, 96.390, 2740.0, 52.3450
26.226267087, 96.390, 2763.0, 52.5642
26.278788217, 96.390, 2796.0, 52.8772
26.331309348, 96.390, 2711.0, 52.0673
26.383830479, 96.390, 2712.0, 52.0769
26.436351609, 96.390, 2709.0, 52.0481
26.488872740, 96.390, 2718.0, 52.1344
26.541393871, 96.390, 2702.0, 51.9808
26.593915002, 96.390, 2619.0, 51.1762
26.646436132, 96.390, 2628.0, 51.2640
26.698957263, 96.390, 2582.0, 50.8134
26.751478394, 96.390, 2632.0, 51.3030
26.803999524, 96.390, 2666.0, 51.6333
26.856520655, 96.390, 2561.0, 50.6063
26.909041786, 96.390, 2615.0, 51.1371
26.961562916, 96.390, 2595.0, 50.9411
27.014084047, 96.390, 2540.0, 50.3984
27.066605178, 96.390, 2549.0, 50.4876
27.119126309, 96.390, 2641.0, 51.3907
27.171647439, 96.390, 2607.0, 51.0588
27.224168570, 96.390, 2551.0, 50.5074
27.276689701, 96.390, 2524.0, 50.2394
27.329210831, 96.390, 2538.0, 50.3786
27.381731962, 96.390, 2484.0, 49.8397
27.434253093, 96.390, 2539.0, 50.3885
27.486774224, 96.390, 2420.0, 49.1935
27.539295354, 96.390, 2526.0, 50.2593
27.591816485, 96.390, 2382.0, 48.8057
27.644337616, 96.390, 2422.0, 49.2138
27.696858746, 96.390, 2462.0, 49.6185
27.749379877, 96.390, 2456.0, 49.5580
27.801901008, 96.390, 2379.0, 48.7750
27.854422139, 96.390, 2407.0, 49.0612
27.906943269, 96.390, 2429.0, 49.2849
27.959464400, 96.390, 2351.0, 48.4871
28.011985531, 96.390, 2354.0, 48.5180
28.064506661, 96.390, 2305.0, 48.0104
28.117027792, 96.390, 2436.0, 49.3559
28.169548923, 96.390, 2397.0, 48.9592
28.222070054, 96.390, 2323.0, 48.1975
28.274591184, 96.390, 2361.0, 48.5901
28.327112315, 96.390, 2299.0, 47.9479
28.379633446, 96.390, 2364.0, 48.6210
28.432154576, 96.390, 2259.0, 47.5289
28.484675707, 96.390, 2279.0, 47.7389
28.537196838, 96.390, 2310.0, 48.0625
28.589717968, 96.390, 2290.0, 47.8539
28.642239099, 96.390, 2290.0, 47.8539
28.694760230, 96.390, 2193.0, 46.8295
28.747281361, 96.390, 2228.0, 47.2017
28.799802491, 96.390, 2315.0, 48.1144
28.852323622, 96.390, 2269.0, 47.6340
28.904844753, 96.390, 2188.0, 46.7761
28.957365883, 96.390, 2264.0, 47.5815
29.009887014, 96.390, 2290.0, 47.8539
29.062408145, 96.390, 2245.0, 47.3814
29.114929276, 96.390, 2195.0, 46.8508
29.167450406, 96.390, 2268.0, 47.6235
29.219971537, 96.390, 2242.0, 47.3498
29.272492668, 96.390, 2163.0, 46.5081
29.325013798, 96.390, 2238.0, 47.3075
29.377534929, 96.390, 2145.0, 46.3141
29.430056060, 96.390, 2243.0, 47.3603
29.482577191, 96.390, 2067.0, 45.4643
29.535098321, 96.390, 2189.0, 46.7868
29.587619452, 96.390, 2195.0, 46.8508
29.640140583, 96.390, 2106.0, 45.8912
29.692661713, 96.390, 2172.0, 46.6047
29.745182844, 96.390, 2094.0, 45.7602
29.797703975, 96.390, 2169.0, 46.5725
29.850225105, 96.390, 2232.0, 47.2440
29.902746236, 96.390, 2194.0, 46.8402
29.955267367, 96.390, 2221.0, 47.1275
30.007788498, 96.390, 2151.0, 46.3789
30.060309628, 96.390, 2047.0, 45.2438
30.112830759, 96.390, 2052.0, 45.2990
30.165351890, 96.390, 2112.0, 45.9565
30.217873020, 96.390, 2093.0, 45.7493
30.270394151, 96.390, 2137.0, 46.2277
30.322915282, 96.390, 2089.0, 45.7056
30.375436413, 96.390, 2014.0, 44.8776
30.427957543, 96.390, 2006.0, 44.7884
30.480478674, 96.390, 2036.0, 45.1221
30.532999805, 96.390, 2007.0, 44.7996
30.585520935, 96.390, 2038.0, 45.1442
30.638042066, 96.390, 2033.0, 45.0888
30.690563197, 96.390, 1990.0, 44.6094
30.743084328, 96.390, 1967.0, 44.3509
30.795605458, 96.390, 2072.0, 45.5192
30.848126589, 96.390, 2054.0, 45.3211
30.900647720, 96.390, 1990.0, 44.6094
30.953168850, 96.390, 2069.0, 45.4863
31.005689981, 96.390, 1971.0, 44.3959
31.058211112, 96.390, 1996.0, 44.6766
31.110732243, 96.390, 1978.0, 44.4747
31.163253373, 96.390, 2000.0, 44.7214
31.215774504, 96.390, 2031.0, 45.0666
31.268295635, 96.390, 1910.0, 43.7035
31.320816765, 96.390, 1949.0, 44.1475
31.373337896, 96.390, 1979.0, 44.4860
31.425859027, 96.390, 1901.0, 43.6005
31.478380157, 96.390, 1989.0, 44.5982
31.530901288, 96.390, 1885.0, 43.4166
31.583422419, 96.390, 1936.0, 44.0000
31.635943550, 96.390, 1950.0, 44.1588
31.688464680, 96.390, 1976.0, 44.4522
31.740985811, 96.390, 1946.0, 44.1135
31.793506942, 96.390, 1911.0, 43.7150
31.846028072, 96.390, 1977.0, 44.4635
31.898549203, 96.390, 1839.0, 42.8836
31.951070334, 96.390, 1913.0, 43.7379
32.003591465, 96.390, 1937.0, 44.0114
32.056112595, 96.390, 1860.0, 43.1277
32.108633726, 96.390, 1911.0, 43.7150
32.161154857, 96.390, 1848.0, 42.9884
32.213675987, 96.390, 1884.0, 43.4051
32.266197118, 96.390, 1917.0, 43.7836
32.318718249, 96.390, 1842.0, 42.9185
32.371239380, 96.390, 1909.0, 43.6921
32.423760510, 96.390, 1891.0, 43.4856
32.476281641, 96.390, 1820.0, 42.6615
32.528802772, 96.390, 1868.0, 43.2204
32.581323902, 96.390, 1876.0, 43.3128
32.633845033, 96.390, 1820.0, 42.6615
32.686366164, 96.390, 1843.0, 42.9302
32.738887295, 96.390, 1735.0, 41.6533
32.791408425, 96.390, 1766.0, 42.0238
32.843929556, 96.390, 1838.0, 42.8719
32.896450687, 96.390, 1824.0, 42.7083
32.948971817, 96.390, 1868.0, 43.2204
33.001492948, 96.390, 1820.0, 42.6615
33.054014079, 96.390, 1756.0, 41.9047
33.106535209, 96.390, 1791.0, 42.3202
33.159056340, 96.390, 1704.0, 41.2795
33.211577471, 96.390, 1787.0, 42.2729
33.264098602, 96.390, 1753.0, 41.8688
33.316619732, 96.390, 1755.0, 41.8927
33.369140863, 96.390, 1755.0, 41.8927
33.421661994, 96.390, 1690.0, 41.1096
33.474183124, 96.390, 1749.0, 41.8210
33.526704255, 96.390, 1840.0, 42.8952
33.579225386, 96.390, 1724.0, 41.5211
33.631746517, 96.390, 1744.0, 41.7612
33.684267647, 96.390, 1791.0, 42.3202
33.736788778, 96.390, 1758.0, 41.9285
33.789309909, 96.390, 1721.0, 41.4849
33.841831039, 96.390, 1738.0, 41.6893
33.894352170, 96.390, 1838.0, 42.8719
33.946873301, 96.390, 1742.0, 41.7373
33.999394432, 96.390, 1753.0, 41.8688
34.051915562, 96.390, 1775.0, 42.1307
34.104436693, 96.390, 1728.0, 41.5692
34.156957824, 96.390, 1721.0, 41.4849
34.209478954, 96.390, 1780.0, 42.1900
34.262000085, 96.390, 1724.0, 41.5211
34.314521216, 96.390, 1774.0, 42.1189
34.367042346, 96.390, 1796.0, 42.3792
34.419563477, 96.390, 1841.0, 42.9069
34.472084608, 96.390, 1711.0, 41.3642
34.524605739, 96.390, 1740.0, 41.7133
34.577126869, 96.390, 1714.0, 41.4005
34.629648000, 96.390, 1784.0, 42.2374
34.682169131, 96.390, 1800.0, 42.4264
34.734690261, 96.390, 1812.0, 42.5676
34.787211392, 96.390, 1782.0, 42.2137
34.839732523, 96.390, 1811.0, 42.5558
34.892253654, 96.390, 1785.0, 42.2493
34.944774784, 96.390, 1759.0, 41.9404
34.997295915, 96.390, 1724.0, 41.5211
35.049817046, 96.390, 1821.0, 42.6732
35.102338176, 96.390, 1699.0, 41.2189
35.154859307, 96.390, 1722.0, 41.4970
35.207380438, 96.390, 1773.0, 42.1070
35.259901569, 96.390, 1689.0, 41.0974
35.312422699, 96.390, 1717.0, 41.4367
35.364943830, 96.390, 1725.0, 41.5331
35.417464961, 96.390, 1745.0, 41.7732
35.469986091, 96.390, 1752.0, 41.8569
35.522507222, 96.390, 1679.0, 40.9756
35.575028353, 96.390, 1636.0, 40.4475
35.627549484, 96.390, 1721.0, 41.4849
35.680070614, 96.390, 1728.0, 41.5692
35.732591745, 96.390, 1686.0, 41.0609
35.785112876, 96.390, 1620.0, 40.2492
35.837634006, 96.390, 1763.0, 41.9881
35.890155137, 96.390, 1672.0, 40.8901
35.942676268, 96.390, 1658.0, 40.7185
35.995197398, 96.390, 1721.0, 41.4849
36.047718529, 96.390, 1593.0, 39.9124
36.100239660, 96.390, 1633.0, 40.4104
36.152760791, 96.390, 1656.0, 40.6940
36.205281921, 96.390, 1701.0, 41.2432
36.257803052, 96.390, 1726.0, 41.5452
36.310324183, 96.390, 1639.0, 40.4846
36.362845313, 96.390, 1672.0, 40.8901
36.415366444, 96.390, 1637.0, 40.4599
36.467887575, 96.390, 1642.0, 40.5216
36.520408706, 96.390, 1605.0, 40.0625
36.572929836, 96.390, 1633.0, 40.4104
36.625450967, 96.390, 1611.0, 40.1373
36.677972098, 96.390, 1607.0, 40.0874
36.730493228, 96.390, 1551.0, 39.3827
36.783014359, 96.390, 1555.0, 39.4335
36.835535490, 96.390, 1577.0, 39.7115
36.888056621, 96.390, 1599.0, 39.9875
36.940577751, 96.390, 1569.0, 39.6106
36.993098882, 96.390, 1529.0, 39.1024
37.045620013, 96.390, 1589.0, 39.8623
37.098141143, 96.390, 1635.0, 40.4351
37.150662274, 96.390, 1478.0, 38.4448
37.203183405, 96.390, 1515.0, 38.9230
37.255704535, 96.390, 1511.0, 38.8716
37.308225666, 96.390, 1439.0, 37.9342
37.360746797, 96.390, 1536.0, 39.1918
37.413267928, 96.390, 1546.0, 39.3192
37.465789058, 96.390, 1481.0, 38.4838
37.518310189, 96.390, 1480.0, 38.4708
37.570831320, 96.390, 1474.0, 38.3927
37.623352450, 96.390, 1504.0, 38.7814
37.675873581, 96.390, 1520.0, 38.9872
37.728394712, 96.390, 1489.0, 38.5876
37.780915843, 96.390, 1440.0, 37.9473
37.833436973, 96.390, 1503.0, 38.7685
37.885958104, 96.390, 1408.0, 37.5233
37.938479235, 96.390, 1444.0, 38.0000
37.991000365, 96.390, 1413.0, 37.5899
38.043521496, 96.390, 1376.0, 37.0945
38.096042627, 96.390, 1395.0, 37.3497
38.148563758, 96.390, 1383.0, 37.1887
38.201084888, 96.390, 1405.0, 37.4833
38.253606019, 96.390, 1472.0, 38.3667
38.306127150, 96.390, 1395.0, 37.3497
38.358648280, 96.390, 1437.0, 37.9078
38.411169411, 96.390, 1423.0, 37.7227
38.463690542, 96.390, 1398.0, 37.3898
38.516211673, 96.390, 1432.0, 37.8418
38.568732803, 96.390, 1335.0, 36.5377
38.621253934, 96.390, 1421.0, 37.6962
38.673775065, 96.390, 1430.0, 37.8153
38.726296195, 96.390, 1295.0, 35.9861
38.778817326, 96.390, 1355.0, 36.8103
38.831338457, 96.390, 1333.0, 36.5103
38.883859587, 96.390, 1363.0, 36.9188
38.936380718, 96.390, 1415.0, 37.6165
38.988901849, 96.390, 1332.0, 36.4966
39.041422980, 96.390, 1354.0, 36.7967
39.093944110, 96.390, 1346.0, 36.6879
39.146465241, 96.390, 1341.0, 36.6197
39.198986372, 96.390, 1334.0, 36.5240
39.251507502, 96.390, 1315.0, 36.2629
39.304028633, 96.390, 1364.0, 36.9324
39.356549764, 96.390, 1306.0, 36.1386
39.409070895, 96.390, 1332.0, 36.4966
39.461592025, 96.390, 1327.0, 36.4280
39.514113156, 96.390, 1408.0, 37.5233
39.566634287, 96.390, 1288.0, 35.8887
39.619155417, 96.390, 1265.0, 35.5668
39.671676548, 96.390, 1302.0, 36.0832
39.724197679, 96.390, 1318.0, 36.3043
39.776718810, 96.390, 1315.0, 36.2629
39.829239940, 96.390, 1346.0, 36.6879
39.881761071, 96.390, 1273.0, 35.6791
39.934282202, 96.390, 1247.0, 35.3129
39.986803332, 96.390, 1230.0, 35.0714
40.039324463, 96.390, 1268.0, 35.6090
40.091845594, 96.390, 1260.0, 35.4965
40.144366725, 96.390, 1317.0, 36.2905
40.196887855, 96.390, 1233.0, 35.1141
40.249408986, 96.390, 1318.0, 36.3043
40.301930117, 96.390, 1255.0, 35.4260
40.354451247, 96.390, 1217.0, 34.8855
40.406972378, 96.390, 1230.0, 35.0714
40.459493509, 96.390, 1201.0, 34.6554
40.512014639, 96.390, 1246.0, 35.2987
40.564535770, 96.390, 1281.0, 35.7911
40.617056901, 96.390, 1244.0, 35.2704
40.669578032, 96.390, 1190.0, 34.4964
40.722099162, 96.390, 1217.0, 34.8855
40.774620293, 96.390, 1244.0, 35.2704
40.827141424, 96.390, 1284.0, 35.8329
40.879662554, 96.390, 1238.0, 35.1852
40.932183685, 96.390, 1243.0, 35.2562
40.984704816, 96.390, 1217.0, 34.8855
41.037225947, 96.390, 1159.0, 34.0441
41.089747077, 96.390, 1214.0, 34.8425
41.142268208, 96.390, 1224.0, 34.9857
41.194789339, 96.390, 1246.0, 35.2987
41.247310469, 96.390, 1191.0, 34.5109
41.299831600, 96.390, 1200.0, 34.6410
41.352352731, 96.390, 1257.0, 35.4542
41.404873862, 96.390, 1257.0, 35.4542
41.457394992, 96.390, 1235.0, 35.1426
41.509916123, 96.390, 1218.0, 34.8999
41.562437254, 96.390, 1232.0, 35.0999
41.614958384, 96.390, 1185.0, 34.4238
41.667479515, 96.390, 1243.0, 35.2562
41.720000646, 96.390, 1262.0, 35.5246
41.772521776, 96.390, 1165.0, 34.1321
41.825042907, 96.390, 1252.0, 35.3836
41.877564038, 96.390, 1196.0, 34.5832
41.930085169, 96.390, 1273.0, 35.6791
41.982606299, 96.390, 1192.0, 34.5254
42.035127430, 96.390, 1187.0, 34.4529
42.087648561, 96.390, 1233.0, 35.1141
42.140169691, 96.390, 1169.0, 34.1906
42.192690822, 96.390, 1121.0, 33.4813
42.245211953, 96.390, 1193.0, 34.5398
42.297733084, 96.390, 1213.0, 34.8281
42.350254214, 96.390, 1215.0, 34.8569
42.402775345, 96.390, 1220.0, 34.9285
42.455296476, 96.390, 1203.0, 34.6843
42.507817606, 96.390, 1201.0, 34.6554
42.560338737, 96.390, 1250.0, 35.3553
42.612859868, 96.390, 1185.0, 34.4238
42.665380999, 96.390, 1187.0, 34.4529
42.717902129, 96.390, 1170.0, 34.2053
42.770423260, 96.390, 1187.0, 34.4529
42.822944391, 96.390, 1130.0, 33.6155
42.875465521, 96.390, 1180.0, 34.3511
42.927986652, 96.390, 1224.0, 34.9857
42.980507783, 96.390, 1218.0, 34.8999
43.033028914, 96.390, 1227.0, 35.0286
43.085550044, 96.390, 1153.0, 33.9559
43.138071175, 96.390, 1191.0, 34.5109
43.190592306, 96.390, 1153.0, 33.9559
43.243113436, 96.390, 1144.0, 33.8231
43.295634567, 96.390, 1231.0, 35.0856
43.348155698, 96.390, 1170.0, 34.2053
43.400676828, 96.390, 1262.0, 35.5246
43.453197959, 96.390, 1204.0, 34.6987
43.505719090, 96.390, 1170.0, 34.2053
43.558240221, 96.390, 1118.0, 33.4365
43.610761351, 96.390, 1132.0, 33.6452
43.663282482, 96.390, 1188.0, 34.4674
43.715803613, 96.390, 1252.0, 35.3836
43.768324743, 96.390, 1148.0, 33.8821
43.820845874, 96.390, 1185.0, 34.4238
43.873367005, 96.390, 1110.0, 33.3167
43.925888136, 96.390, 1172.0, 34.2345
43.978409266, 96.390, 1196.0, 34.5832
44.030930397, 96.390, 1212.0, 34.8138
44.083451528, 96.390, 1187.0, 34.4529
44.135972658, 96.390, 1197.0, 34.5977
44.188493789, 96.390, 1207.0, 34.7419
44.241014920, 96.390, 1194.0, 34.5543
44.293536051, 96.390, 1132.0, 33.6452
44.346057181, 96.390, 1172.0, 34.2345
44.398578312, 96.390, 1249.0, 35.3412
44.451099443, 96.390, 1180.0, 34.3511
44.503620573, 96.390, 1224.0, 34.9857
44.556141704, 96.390, 1156.0, 34.0000
44.608662835, 96.390, 1185.0, 34.4238
44.661183966, 96.390, 1150.0, 33.9116
44.713705096, 96.390, 1143.0, 33.8083
44.766226227, 96.390, 1129.0, 33.6006
44.818747358, 96.390, 1119.0, 33.4515
44.871268488, 96.390, 1221.0, 34.9428
44.923789619, 96.390, 1101.0, 33.1813
44.976310750, 96.390, 1161.0, 34.0735
45.028831880, 96.390, 1199.0, 34.6266
45.081353011, 96.390, 1130.0, 33.6155
45.133874142, 96.390, 1143.0, 33.8083
45.186395273, 96.390, 1145.0, 33.8378
45.238916403, 96.390, 1150.0, 33.9116
45.291437534, 96.390, 1187.0, 34.4529
45.343958665, 96.390, 1164.0, 34.1174
45.396479795, 96.390, 1171.0, 34.2199
45.449000926, 96.390, 1128.0, 33.5857
45.501522057, 96.390, 1101.0, 33.1813
45.554043188, 96.390, 1096.0, 33.1059
45.606564318, 96.390, 1127.0, 33.5708
45.659085449, 96.390, 1183.0, 34.3948
45.711606580, 96.390, 1154.0, 33.9706
45.764127710, 96.390, 1119.0, 33.4515
45.816648841, 96.390, 1127.0, 33.5708
45.869169972, 96.390, 1123.0, 33.5112
45.921691103, 96.390, 1126.0, 33.5559
45.974212233, 96.390, 1154.0, 33.9706
46.026733364, 96.390, 1179.0, 34.3366
46.079254495, 96.390, 1149.0, 33.8969
46.131775625, 96.390, 1116.0, 33.4066
46.184296756, 96.390, 1100.0, 33.1662
46.236817887, 96.390, 1160.0, 34.0588
46.289339017, 96.390, 1128.0, 33.5857
46.341860148, 96.390, 1102.0, 33.1964
46.394381279, 96.390, 1130.0, 33.6155
46.446902410, 96.390, 1125.0, 33.5410
46.499423540, 96.390, 1125.0, 33.5410
46.551944671, 96.390, 1135.0, 33.6898
46.604465802, 96.390, 1121.0, 33.4813
46.656986932, 96.390, 1141.0, 33.7787
46.709508063, 96.390, 1190.0, 34.4964
46.762029194, 96.390, 1122.0, 33.4963
46.814550325, 96.390, 1146.0, 33.8526
46.867071455, 96.390, 1064.0, 32.6190
46.919592586, 96.390, 1131.0, 33.6303
46.972113717, 96.390, 1077.0, 32.8177
47.024634847, 96.390, 1093.0, 33.0606
47.077155978, 96.390, 1088.0, 32.9848
47.129677109, 96.390, 1188.0, 34.4674
47.182198240, 96.390, 1128.0, 33.5857
47.234719370, 96.390, 1099.0, 33.1512
47.287240501, 96.390, 1116.0, 33.4066
47.339761632, 96.390, 1131.0, 33.6303
47.392282762, 96.390, 1029.0, 32.0780
47.444803893, 96.390, 1040.0, 32.2490
47.497325024, 96.390, 1063.0, 32.6037
47.549846155, 96.390, 1073.0, 32.7567
47.602367285, 96.390, 1055.0, 32.4808
47.654888416, 96.390, 1054.0, 32.4654
47.707409547, 96.390, 1073.0, 32.7567
47.759930677, 96.390, 1111.0, 33.3317
47.812451808, 96.390, 1129.0, 33.6006
47.864972939, 96.390, 1082.0, 32.8938
47.917494069, 96.390, 1065.0, 32.6343
47.970015200, 96.390, 1071.0, 32.7261
48.022536331, 96.390, 1068.0, 32.6803
48.075057462, 96.390, 1067.0, 32.6650
48.127578592, 96.390, 1064.0, 32.6190
48.180099723, 96.390, 1047.0, 32.3574
48.232620854, 96.390, 1044.0, 32.3110
48.285141984, 96.390, 1069.0, 32.6956
48.337663115, 96.390, 1056.0, 32.4962
48.390184246, 96.390, 1039.0, 32.2335
48.442705377, 96.390, 1070.0, 32.7109
48.495226507, 96.390, 1115.0, 33.3916
48.547747638, 96.390, 1083.0, 32.9090
48.600268769, 96.390, 1028.0, 32.0624
48.652789899, 96.390, 1010.0, 31.7805
48.705311030, 96.390, 1047.0, 32.3574
48.757832161, 96.390, 1034.0, 32.1559
48.810353292, 96.390, 994.0, 31.5278
48.862874422, 96.390, 985.0, 31.3847
48.915395553, 96.390, 1051.0, 32.4191
48.967916684, 96.390, 1034.0, 32.1559
49.020437814, 96.390, 1048.0, 32.3728
49.072958945, 96.390, 1041.0, 32.2645
49.125480076, 96.390, 1069.0, 32.6956
49.178001207, 96.390, 1027.0, 32.0468
49.230522337, 96.390, 949.0, 30.8058
49.283043468, 96.390, 1011.0, 31.7962
49.335564599, 96.390, 944.0, 30.7246
49.388085729, 96.390, 992.0, 31.4960
49.440606860, 96.390, 1008.0, 31.7490
49.493127991, 96.390, 1016.0, 31.8748
49.545649121, 96.390, 879.0, 29.6479
49.598170252, 96.390, 984.0, 31.3688
49.650691383, 96.390, 1021.0, 31.9531
49.703212514, 96.390, 1034.0, 32.1559
49.755733644, 96.390, 1006.0, 31.7175
49.808254775, 96.390, 980.0, 31.3050
49.860775906, 96.390, 1011.0, 31.7962
49.913297036, 96.390, 984.0, 31.3688
49.965818167, 96.390, 1015.0, 31.8591
50.018339298, 96.390, 994.0, 31.5278
50.070860429, 96.390, 1001.0, 31.6386
50.123381559, 96.390, 964.0, 31.0483
50.175902690, 96.390, 964.0, 31.0483
50.228423821, 96.390, 962.0, 31.0161
50.280944951, 96.390, 986.0, 31.4006
50.333466082, 96.390, 952.0, 30.8545
50.385987213, 96.390, 887.0, 29.7825
50.438508344, 96.390, 980.0, 31.3050
50.491029474, 96.390, 975.0, 31.2250
50.543550605, 96.390, 988.0, 31.4325
50.596071736, 96.390, 1000.0, 31.6228
50.648592866, 96.390, 952.0, 30.8545
50.701113997, 96.390, 925.0, 30.4138
50.753635128, 96.390, 939.0, 30.6431
50.806156258, 96.390, 973.0, 31.1929
50.858677389, 96.390, 1000.0, 31.6228
50.911198520, 96.390, 995.0, 31.5436
50.963719651, 96.390, 942.0, 30.6920
51.016240781, 96.390, 1006.0, 31.7175
51.068761912, 96.390, 959.0, 30.9677
51.121283043, 96.390, 990.0, 31.4643
51.173804173, 96.390, 1007.0, 31.7333
51.226325304, 96.390, 959.0, 30.9677
51.278846435, 96.390, 1002.0, 31.6544
51.331367566, 96.390, 930.0, 30.4959
51.383888696, 96.390, 940.0, 30.6594
51.436409827, 96.390, 881.0, 29.6816
51.488930958, 96.390, 898.0, 29.9666
51.541452088, 96.390, 912.0, 30.1993
51.593973219, 96.390, 965.0, 31.0644
51.646494350, 96.390, 990.0, 31.4643
51.699015481, 96.390, 922.0, 30.3645
51.751536611, 96.390, 970.0, 31.1448
51.804057742, 96.390, 937.0, 30.6105
51.856578873, 96.390, 980.0, 31.3050
51.909100003, 96.390, 938.0, 30.6268
51.961621134, 96.390, 896.0, 29.9333
52.014142265, 96.390, 950.0, 30.8221
52.066663396, 96.390, 964.0, 31.0483
52.119184526, 96.390, 960.0, 30.9839
52.171705657, 96.390, 996.0, 31.5595
52.224226788, 96.390, 952.0, 30.8545
52.276747918, 96.390, 914.0, 30.2324
52.329269049, 96.390, 877.0, 29.6142
52.381790180, 96.390, 858.0, 29.2916
52.434311310, 96.390, 926.0, 30.4302
52.486832441, 96.390, 917.0, 30.2820
52.539353572, 96.390, 907.0, 30.1164
52.591874703, 96.390, 913.0, 30.2159
52.644395833, 96.390, 939.0, 30.6431
52.696916964, 96.390, 879.0, 29.6479
52.749438095, 96.390, 876.0, 29.5973
52.801959225, 96.390, 935.0, 30.5778
52.854480356, 96.390, 892.0, 29.8664
52.907001487, 96.390, 937.0, 30.6105
52.959522618, 96.390, 947.0, 30.7734
53.012043748, 96.390, 937.0, 30.6105
53.064564879, 96.390, 915.0, 30.2490
53.117086010, 96.390, 876.0, 29.5973
53.169607140, 96.390, 851.0, 29.1719
53.222128271, 96.390, 937.0, 30.6105
53.274649402, 96.390, 968.0, 31.1127
53.327170533, 96.390, 945.0, 30.7409
53.379691663, 96.390, 951.0, 30.8383
53.432212794, 96.390, 940.0, 30.6594
53.484733925, 96.390, 923.0, 30.3809
53.537255055, 96.390, 957.0, 30.9354
53.589776186, 96.390, 907.0, 30.1164
53.642297317, 96.390, 903.0, 30.0500
53.694818448, 96.390, 874.0, 29.5635
53.747339578, 96.390, 899.0, 29.9833
53.799860709, 96.390, 875.0, 29.5804
53.852381840, 96.390, 897.0, 29.9500
53.904902970, 96.390, 950.0, 30.8221
53.957424101, 96.390, 916.0, 30.2655
54.009945232, 96.390, 903.0, 30.0500
54.062466362, 96.390, 948.0, 30.7896
54.114987493, 96.390, 912.0, 30.1993
54.167508624, 96.390, 893.0, 29.8831
54.220029755, 96.390, 911.0, 30.1828
54.272550885, 96.390, 897.0, 29.9500
54.325072016, 96.390, 881.0, 29.6816
54.377593147, 96.390, 878.0, 29.6311
54.430114277, 96.390, 946.0, 30.7571
54.482635408, 96.390, 890.0, 29.8329
54.535156539, 96.390, 849.0, 29.1376
54.587677670, 96.390, 855.0, 29.2404
54.640198800, 96.390, 847.0, 29.1033
54.692719931, 96.390, 887.0, 29.7825
54.745241062, 96.390, 859.0, 29.3087
54.797762192, 96.390, 837.0, 28.9310
54.850283323, 96.390, 926.0, 30.4302
54.902804454, 96.390, 860.0, 29.3258
54.955325585, 96.390, 898.0, 29.9666
55.007846715, 96.390, 908.0, 30.1330
55.060367846, 96.390, 915.0, 30.2490
55.112888977, 96.390, 854.0, 29.2233
55.165410107, 96.390, 942.0, 30.6920
55.217931238, 96.390, 891.0, 29.8496
55.270452369, 96.390, 893.0, 29.8831
55.322973499, 96.390, 885.0, 29.7489
55.375494630, 96.390, 910.0, 30.1662
55.428015761, 96.390, 845.0, 29.0689
55.480536892, 96.390, 846.0, 29.0861
55.533058022, 96.390, 915.0, 30.2490
55.585579153, 96.390, 886.0, 29.7658
55.638100284, 96.390, 855.0, 29.2404
55.690621414, 96.390, 842.0, 29.0172
55.743142545, 96.390, 825.0, 28.7228
55.795663676, 96.390, 850.0, 29.1548
55.848184807, 96.390, 840.0, 28.9828
55.900705937, 96.390, 858.0, 29.2916
55.953227068, 96.390, 874.0, 29.5635
56.005748199, 96.390, 841.0, 29.0000
56.058269329, 96.390, 894.0, 29.8998
56.110790460, 96.390, 896.0, 29.9333
56.163311591, 96.390, 869.0, 29.4788
56.215832722, 96.390, 815.0, 28.5482
56.268353852, 96.390, 897.0, 29.9500
56.320874983, 96.390, 851.0, 29.1719
56.373396114, 96.390, 856.0, 29.2575
56.425917244, 96.390, 851.0, 29.1719
56.478438375, 96.390, 889.0, 29.8161
56.530959506, 96.390, 881.0, 29.6816
56.583480637, 96.390, 907.0, 30.1164
56.636001767, 96.390, 849.0, 29.1376
56.688522898, 96.390, 836.0, 28.9137
56.741044029, 96.390, 906.0, 30.0998
56.793565159, 96.390, 888.0, 29.7993
56.846086290, 96.390, 787.0, 28.0535
56.898607421, 96.390, 882.0, 29.6985
56.951128551, 96.390, 925.0, 30.4138
57.003649682, 96.390, 840.0, 28.9828
57.056170813, 96.390, 914.0, 30.2324
57.108691944, 96.390, 865.0, 29.4109
57.161213074, 96.390, 845.0, 29.0689
57.213734205, 96.390, 850.0, 29.1548
57.266255336, 96.390, 858.0, 29.2916
57.318776466, 96.390, 844.0, 29.0517
57.371297597, 96.390, 855.0, 29.2404
57.423818728, 96.390, 882.0, 29.6985
57.476339859, 96.390, 872.0, 29.5296
57.528860989, 96.390, 869.0, 29.4788
57.581382120, 96.390, 839.0, 28.9655
57.633903251, 96.390, 853.0, 29.2062
57.686424381, 96.390, 854.0, 29.2233
57.738945512, 96.390, 886.0, 29.7658
57.791466643, 96.390, 885.0, 29.7489
57.843987774, 96.390, 875.0, 29.5804
57.896508904, 96.390, 876.0, 29.5973
57.949030035, 96.390, 869.0, 29.4788
58.001551166, 96.390, 802.0, 28.3196
58.054072296, 96.390, 841.0, 29.0000
58.106593427, 96.390, 863.0, 29.3769
58.159114558, 96.390, 845.0, 29.0689
58.211635689, 96.390, 882.0, 29.6985
58.264156819, 96.390, 854.0, 29.2233
58.316677950, 96.390, 886.0, 29.7658
58.369199081, 96.390, 884.0, 29.7321
58.421720211, 96.390, 888.0, 29.7993
58.474241342, 96.390, 832.0, 28.8444
58.526762473, 96.390, 873.0, 29.5466
58.579283603, 96.390, 834.0, 28.8791
58.631804734, 96.390, 861.0, 29.3428
58.684325865, 96.390, 893.0, 29.8831
58.736846996, 96.390, 897.0, 29.9500
58.789368126, 96.390, 889.0, 29.8161
58.841889257, 96.390, 868.0, 29.4618
58.894410388, 96.390, 865.0, 29.4109
58.946931518, 96.390, 903.0, 30.0500
58.999452649, 96.390, 866.0, 29.4279
59.051973780, 96.390, 874.0, 29.5635
59.104494911, 96.390, 915.0, 30.2490
59.157016041, 96.390, 916.0, 30.2655
59.209537172, 96.390, 886.0, 29.7658
59.262058303, 96.390, 837.0, 28.9310
59.314579433, 96.390, 847.0, 29.1033
59.367100564, 96.390, 867.0, 29.4449
59.419621695, 96.390, 863.0, 29.3769
59.472142826, 96.390, 874.0, 29.5635
59.524663956, 96.390, 893.0, 29.8831
59.577185087, 96.390, 908.0, 30.1330
59.629706218, 96.390, 847.0, 29.1033
59.682227348, 96.390, 849.0, 29.1376
59.734748479, 96.390, 891.0, 29.8496
59.787269610, 96.390, 895.0, 29.9166
59.839790740, 96.390, 858.0, 29.2916
59.892311871, 96.390, 908.0, 30.1330
59.944833002, 96.390, 953.0, 30.8707
59.997354133, 96.390, 941.0, 30.6757
60.049875263, 96.390, 938.0, 30.6268
60.102396394, 96.390, 921.0, 30.3480
60.154917525, 96.390, 976.0, 31.2410
60.207438655, 96.390, 951.0, 30.8383
60.259959786, 96.390, 883.0, 29.7153
60.312480917, 96.390, 940.0, 30.6594
60.365002048, 96.390, 933.0, 30.5450
60.417523178, 96.390, 920.0, 30.3315
60.470044309, 96.390, 940.0, 30.6594
60.522565440, 96.390, 987.0, 31.4166
60.575086570, 96.390, 914.0, 30.2324
60.627607701, 96.390, 962.0, 31.0161
60.680128832, 96.390, 964.0, 31.0483
60.732649963, 96.390, 947.0, 30.7734
60.785171093, 96.390, 910.0, 30.1662
60.837692224, 96.390, 990.0, 31.4643
60.890213355, 96.390, 1005.0, 31.7017
60.942734485, 96.390, 969.0, 31.1288
60.995255616, 96.390, 1010.0, 31.7805
61.047776747, 96.390, 949.0, 30.8058
61.100297878, 96.390, 971.0, 31.1609
61.152819008, 96.390, 1056.0, 32.4962
61.205340139, 96.390, 1019.0, 31.9218
61.257861270, 96.390, 1057.0, 32.5115
61.310382400, 96.390, 1037.0, 32.2025
61.362903531, 96.390, 1045.0, 32.3265
61.415424662, 96.390, 1007.0, 31.7333
61.467945792, 96.390, 1066.0, 32.6497
61.520466923, 96.390, 1029.0, 32.0780
61.572988054, 96.390, 992.0, 31.4960
61.625509185, 96.390, 1042.0, 32.2800
61.678030315, 96.390, 1116.0, 33.4066
61.730551446, 96.390, 1005.0, 31.7017
61.783072577, 96.390, 969.0, 31.1288
61.835593707, 96.390, 1014.0, 31.8434
61.888114838, 96.390, 1044.0, 32.3110
61.940635969, 96.390, 1051.0, 32.4191
61.993157100, 96.390, 1034.0, 32.1559
62.045678230, 96.390, 1001.0, 31.6386
62.098199361, 96.390, 1069.0, 32.6956
62.150720492, 96.390, 958.0, 30.9516
62.203241622, 96.390, 981.0, 31.3209
62.255762753, 96.390, 950.0, 30.8221
62.308283884, 96.390, 962.0, 31.0161
62.360805015, 96.390, 984.0, 31.3688
62.413326145, 96.390, 937.0, 30.6105
62.465847276, 96.390, 1015.0, 31.8591
62.518368407, 96.390, 954.0, 30.8869
62.570889537, 96.390, 954.0, 30.8869
62.623410668, 96.390, 990.0, 31.4643
62.675931799, 96.390, 970.0, 31.1448
62.728452930, 96.390, 961.0, 31.0000
62.780974060, 96.390, 983.0, 31.3528
62.833495191, 96.390, 1001.0, 31.6386
62.886016322, 96.390, 962.0, 31.0161
62.938537452, 96.390, 935.0, 30.5778
62.991058583, 96.390, 873.0, 29.5466
63.043579714, 96.390, 920.0, 30.3315
63.096100844, 96.390, 937.0, 30.6105
63.148621975, 96.390, 929.0, 30.4795
63.201143106, 96.390, 876.0, 29.5973
63.253664237, 96.390, 930.0, 30.4959
63.306185367, 96.390, 887.0, 29.7825
63.358706498, 96.390, 880.0, 29.6648
63.411227629, 96.390, 923.0, 30.3809
63.463748759, 96.390, 941.0, 30.6757
63.516269890, 96.390, 898.0, 29.9666
63.568791021, 96.390, 850.0, 29.1548
63.621312152, 96.390, 878.0, 29.6311
63.673833282, 96.390, 857.0, 29.2746
63.726354413, 96.390, 868.0, 29.4618
63.778875544, 96.390, 865.0, 29.4109
63.831396674, 96.390, 833.0, 28.8617
63.883917805, 96.390, 849.0, 29.1376
63.936438936, 96.390, 871.0, 29.5127
63.988960067, 96.390, 848.0, 29.1204
64.041481197, 96.390, 896.0, 29.9333
64.094002328, 96.390, 819.0, 28.6182
64.146523459, 96.390, 865.0, 29.4109
64.199044589, 96.390, 860.0, 29.3258
64.251565720, 96.390, 860.0, 29.3258
64.304086851, 96.390, 827.0, 28.7576
64.356607981, 96.390, 860.0, 29.3258
64.409129112, 96.390, 887.0, 29.7825
64.461650243, 96.390, 878.0, 29.6311
64.514171374, 96.390, 917.0, 30.2820
64.566692504, 96.390, 795.0, 28.1957
64.619213635, 96.390, 851.0, 29.1719
64.671734766, 96.390, 851.0, 29.1719
64.724255896, 96.390, 832.0, 28.8444
64.776777027, 96.390, 841.0, 29.0000
64.829298158, 96.390, 823.0, 28.6880
64.881819289, 96.390, 878.0, 29.6311
64.934340419, 96.390, 839.0, 28.9655
64.986861550, 96.390, 848.0, 29.1204