File: Files_organized_for_plots/Na_to_Al_1/XRD_SiAxial12Jan22_Act07Feb22_B3_0310M_NaOH_LS0117_1.csv
[Measurement conditions]
Sample identification,XRD_SiAxial12Jan22_Act07Feb22_B3_0310M_NaOH_LS0117_1
Comment - 1,"Configuration=Stage for Flat Samples/Holders, Owner=User-1, Creation date=7/1/2020 9:53:24 AM"
Comment - 2,"Goniometer=Theta/Theta; Minimum step size 2Theta:0.0001; Minimum step size Omega:0.0001"
Comment - 3,"Sample stage=Stage for flat samples/holders"
Comment - 4,"Diffractometer system=EMPYREAN"
Comment - 5,"Measurement program=C:\Users\ibo5034\OneDrive - The Pennsylvania State University\NEUP - Reed, Titus's files\XRD\Cement\Zerobackground scan.xrdmp, Identifier={98A3B11C-88F9-4AA6-982C-73314A311EF5}"
Anode material,Cu
K-Alpha1 wavelength,1.5405980
K-Alpha2 wavelength,1.5444260
Ratio K-Alpha2/K-Alpha1,0.500
Divergence slit,Fixed,0.25
Monochromator used,NO
Generator voltage, 45
Tube current, 40
File date and time,10/Feb/2022 13:38
Unit cell,
h k l, 0 0 0
Scan axis,Gonio
Scan range,4.994599997,64.999991833
Scan step size,0.0262606
No. of points, 2285
Scan type,CONTINUOUS
Time per step,96.390
[Scan points]
Angle, TimePerStep, Intensity, ESD
5.007730280, 96.390, 5523.0, 74.3169
5.060251411, 96.390, 5621.0, 74.9733
5.112772541, 96.390, 5497.0, 74.1418
5.165293672, 96.390, 5578.0, 74.6860
5.217814803, 96.390, 5351.0, 73.1505
5.270335934, 96.390, 5299.0, 72.7942
5.322857064, 96.390, 5394.0, 73.4439
5.375378195, 96.390, 5208.0, 72.1665
5.427899326, 96.390, 5208.0, 72.1665
5.480420456, 96.390, 5233.0, 72.3395
5.532941587, 96.390, 5068.0, 71.1899
5.585462718, 96.390, 5100.0, 71.4143
5.637983849, 96.390, 4984.0, 70.5975
5.690504979, 96.390, 4947.0, 70.3349
5.743026110, 96.390, 4964.0, 70.4557
5.795547241, 96.390, 4879.0, 69.8498
5.848068371, 96.390, 5024.0, 70.8802
5.900589502, 96.390, 4856.0, 69.6850
5.953110633, 96.390, 4867.0, 69.7639
6.005631763, 96.390, 4715.0, 68.6659
6.058152894, 96.390, 4599.0, 67.8159
6.110674025, 96.390, 4715.0, 68.6659
6.163195156, 96.390, 4692.0, 68.4982
6.215716286, 96.390, 4682.0, 68.4251
6.268237417, 96.390, 4741.0, 68.8549
6.320758548, 96.390, 4730.0, 68.7750
6.373279678, 96.390, 4727.0, 68.7532
6.425800809, 96.390, 4637.0, 68.0955
6.478321940, 96.390, 4631.0, 68.0515
6.530843071, 96.390, 4598.0, 67.8086
6.583364201, 96.390, 4504.0, 67.1118
6.635885332, 96.390, 4572.0, 67.6166
6.688406463, 96.390, 4402.0, 66.3476
6.740927593, 96.390, 4495.0, 67.0448
6.793448724, 96.390, 4393.0, 66.2797
6.845969855, 96.390, 4353.0, 65.9773
6.898490986, 96.390, 4506.0, 67.1267
6.951012116, 96.390, 4470.0, 66.8581
7.003533247, 96.390, 4421.0, 66.4906
7.056054378, 96.390, 4434.0, 66.5883
7.108575508, 96.390, 4378.0, 66.1665
7.161096639, 96.390, 4368.0, 66.0908
7.213617770, 96.390, 4377.0, 66.1589
7.266138900, 96.390, 4257.0, 65.2457
7.318660031, 96.390, 4341.0, 65.8863
7.371181162, 96.390, 4321.0, 65.7343
7.423702293, 96.390, 4210.0, 64.8845
7.476223423, 96.390, 4328.0, 65.7875
7.528744554, 96.390, 4208.0, 64.8691
7.581265685, 96.390, 4212.0, 64.8999
7.633786815, 96.390, 4143.0, 64.3661
7.686307946, 96.390, 4307.0, 65.6277
7.738829077, 96.390, 4136.0, 64.3117
7.791350208, 96.390, 3984.0, 63.1189
7.843871338, 96.390, 4039.0, 63.5531
7.896392469, 96.390, 4209.0, 64.8768
7.948913600, 96.390, 4107.0, 64.0859
8.001434730, 96.390, 3985.0, 63.1269
8.053955861, 96.390, 4133.0, 64.2884
8.106476992, 96.390, 3953.0, 62.8729
8.158998123, 96.390, 3961.0, 62.9365
8.211519253, 96.390, 3890.0, 62.3699
8.264040384, 96.390, 4074.0, 63.8279
8.316561515, 96.390, 3932.0, 62.7057
8.369082645, 96.390, 4031.0, 63.4902
8.421603776, 96.390, 3909.0, 62.5220
8.474124907, 96.390, 3844.0, 62.0000
8.526646038, 96.390, 3796.0, 61.6117
8.579167168, 96.390, 3972.0, 63.0238
8.631688299, 96.390, 3691.0, 60.7536
8.684209430, 96.390, 3799.0, 61.6360
8.736730560, 96.390, 3774.0, 61.4329
8.789251691, 96.390, 3690.0, 60.7454
8.841772822, 96.390, 3831.0, 61.8951
8.894293952, 96.390, 3692.0, 60.7618
8.946815083, 96.390, 3889.0, 62.3618
8.999336214, 96.390, 3789.0, 61.5549
9.051857345, 96.390, 3664.0, 60.5310
9.104378475, 96.390, 3841.0, 61.9758
9.156899606, 96.390, 3830.0, 61.8870
9.209420737, 96.390, 3690.0, 60.7454
9.261941867, 96.390, 3664.0, 60.5310
9.314462998, 96.390, 3684.0, 60.6960
9.366984129, 96.390, 3466.0, 58.8727
9.419505260, 96.390, 3580.0, 59.8331
9.472026390, 96.390, 3693.0, 60.7701
9.524547521, 96.390, 3592.0, 59.9333
9.577068652, 96.390, 3729.0, 61.0655
9.629589782, 96.390, 3540.0, 59.4979
9.682110913, 96.390, 3494.0, 59.1101
9.734632044, 96.390, 3427.0, 58.5406
9.787153175, 96.390, 3596.0, 59.9667
9.839674305, 96.390, 3464.0, 58.8558
9.892195436, 96.390, 3504.0, 59.1946
9.944716567, 96.390, 3397.0, 58.2838
9.997237697, 96.390, 3408.0, 58.3781
10.049758828, 96.390, 3436.0, 58.6174
10.102279959, 96.390, 3360.0, 57.9655
10.154801090, 96.390, 3243.0, 56.9473
10.207322220, 96.390, 3353.0, 57.9051
10.259843351, 96.390, 3229.0, 56.8243
10.312364482, 96.390, 3341.0, 57.8014
10.364885612, 96.390, 3308.0, 57.5152
10.417406743, 96.390, 3266.0, 57.1489
10.469927874, 96.390, 3292.0, 57.3760
10.522449004, 96.390, 3214.0, 56.6922
10.574970135, 96.390, 3291.0, 57.3672
10.627491266, 96.390, 3156.0, 56.1783
10.680012397, 96.390, 3196.0, 56.5332
10.732533527, 96.390, 3244.0, 56.9561
10.785054658, 96.390, 3112.0, 55.7853
10.837575789, 96.390, 3138.0, 56.0179
10.890096919, 96.390, 3151.0, 56.1338
10.942618050, 96.390, 3118.0, 55.8391
10.995139181, 96.390, 3073.0, 55.4346
11.047660312, 96.390, 3240.0, 56.9210
11.100181442, 96.390, 3053.0, 55.2540
11.152702573, 96.390, 3147.0, 56.0981
11.205223704, 96.390, 3075.0, 55.4527
11.257744834, 96.390, 3040.0, 55.1362
11.310265965, 96.390, 3106.0, 55.7315
11.362787096, 96.390, 3178.0, 56.3738
11.415308227, 96.390, 3088.0, 55.5698
11.467829357, 96.390, 2981.0, 54.5985
11.520350488, 96.390, 3096.0, 55.6417
11.572871619, 96.390, 3073.0, 55.4346
11.625392749, 96.390, 3033.0, 55.0727
11.677913880, 96.390, 2938.0, 54.2033
11.730435011, 96.390, 2971.0, 54.5069
11.782956141, 96.390, 2859.0, 53.4696
11.835477272, 96.390, 2901.0, 53.8609
11.887998403, 96.390, 2905.0, 53.8981
11.940519534, 96.390, 2881.0, 53.6749
11.993040664, 96.390, 2881.0, 53.6749
12.045561795, 96.390, 2841.0, 53.3010
12.098082926, 96.390, 2864.0, 53.5164
12.150604056, 96.390, 2753.0, 52.4690
12.203125187, 96.390, 2820.0, 53.1037
12.255646318, 96.390, 2817.0, 53.0754
12.308167449, 96.390, 2762.0, 52.5547
12.360688579, 96.390, 2804.0, 52.9528
12.413209710, 96.390, 2745.0, 52.3927
12.465730841, 96.390, 2782.0, 52.7447
12.518251971, 96.390, 2785.0, 52.7731
12.570773102, 96.390, 2780.0, 52.7257
12.623294233, 96.390, 2724.0, 52.1920
12.675815364, 96.390, 2644.0, 51.4198
12.728336494, 96.390, 2658.0, 51.5558
12.780857625, 96.390, 2714.0, 52.0961
12.833378756, 96.390, 2847.0, 53.3573
12.885899886, 96.390, 2686.0, 51.8266
12.938421017, 96.390, 2722.0, 52.1728
12.990942148, 96.390, 2638.0, 51.3615
13.043463279, 96.390, 2684.0, 51.8073
13.095984409, 96.390, 2657.0, 51.5461
13.148505540, 96.390, 2548.0, 50.4777
13.201026671, 96.390, 2727.0, 52.2207
13.253547801, 96.390, 2618.0, 51.1664
13.306068932, 96.390, 2630.0, 51.2835
13.358590063, 96.390, 2605.0, 51.0392
13.411111193, 96.390, 2545.0, 50.4480
13.463632324, 96.390, 2599.0, 50.9804
13.516153455, 96.390, 2528.0, 50.2792
13.568674586, 96.390, 2509.0, 50.0899
13.621195716, 96.390, 2591.0, 50.9019
13.673716847, 96.390, 2617.0, 51.1566
13.726237978, 96.390, 2584.0, 50.8331
13.778759108, 96.390, 2563.0, 50.6261
13.831280239, 96.390, 2548.0, 50.4777
13.883801370, 96.390, 2502.0, 50.0200
13.936322501, 96.390, 2515.0, 50.1498
13.988843631, 96.390, 2584.0, 50.8331
14.041364762, 96.390, 2530.0, 50.2991
14.093885893, 96.390, 2474.0, 49.7393
14.146407023, 96.390, 2475.0, 49.7494
14.198928154, 96.390, 2512.0, 50.1199
14.251449285, 96.390, 2486.0, 49.8598
14.303970416, 96.390, 2467.0, 49.6689
14.356491546, 96.390, 2518.0, 50.1797
14.409012677, 96.390, 2528.0, 50.2792
14.461533808, 96.390, 2486.0, 49.8598
14.514054938, 96.390, 2478.0, 49.7795
14.566576069, 96.390, 2480.0, 49.7996
14.619097200, 96.390, 2360.0, 48.5798
14.671618331, 96.390, 2423.0, 49.2240
14.724139461, 96.390, 2453.0, 49.5278
14.776660592, 96.390, 2361.0, 48.5901
14.829181723, 96.390, 2459.0, 49.5883
14.881702853, 96.390, 2391.0, 48.8979
14.934223984, 96.390, 2399.0, 48.9796
14.986745115, 96.390, 2385.0, 48.8365
15.039266245, 96.390, 2416.0, 49.1528
15.091787376, 96.390, 2437.0, 49.3660
15.144308507, 96.390, 2387.0, 48.8569
15.196829638, 96.390, 2443.0, 49.4267
15.249350768, 96.390, 2371.0, 48.6929
15.301871899, 96.390, 2446.0, 49.4571
15.354393030, 96.390, 2405.0, 49.0408
15.406914160, 96.390, 2429.0, 49.2849
15.459435291, 96.390, 2470.0, 49.6991
15.511956422, 96.390, 2413.0, 49.1223
15.564477553, 96.390, 2300.0, 47.9583
15.616998683, 96.390, 2381.0, 48.7955
15.669519814, 96.390, 2348.0, 48.4562
15.722040945, 96.390, 2425.0, 49.2443
15.774562075, 96.390, 2349.0, 48.4665
15.827083206, 96.390, 2298.0, 47.9375
15.879604337, 96.390, 2413.0, 49.1223
15.932125468, 96.390, 2434.0, 49.3356
15.984646598, 96.390, 2308.0, 48.0416
16.037167729, 96.390, 2420.0, 49.1935
16.089688860, 96.390, 2392.0, 48.9081
16.142209990, 96.390, 2441.0, 49.4065
16.194731121, 96.390, 2406.0, 49.0510
16.247252252, 96.390, 2368.0, 48.6621
16.299773382, 96.390, 2447.0, 49.4672
16.352294513, 96.390, 2427.0, 49.2646
16.404815644, 96.390, 2446.0, 49.4571
16.457336775, 96.390, 2447.0, 49.4672
16.509857905, 96.390, 2459.0, 49.5883
16.562379036, 96.390, 2352.0, 48.4974
16.614900167, 96.390, 2515.0, 50.1498
16.667421297, 96.390, 2443.0, 49.4267
16.719942428, 96.390, 2439.0, 49.3862
16.772463559, 96.390, 2483.0, 49.8297
16.824984690, 96.390, 2425.0, 49.2443
16.877505820, 96.390, 2452.0, 49.5177
16.930026951, 96.390, 2521.0, 50.2096
16.982548082, 96.390, 2467.0, 49.6689
17.035069212, 96.390, 2495.0, 49.9500
17.087590343, 96.390, 2560.0, 50.5964
17.140111474, 96.390, 2531.0, 50.3090
17.192632605, 96.390, 2435.0, 49.3457
17.245153735, 96.390, 2488.0, 49.8799
17.297674866, 96.390, 2563.0, 50.6261
17.350195997, 96.390, 2478.0, 49.7795
17.402717127, 96.390, 2527.0, 50.2693
17.455238258, 96.390, 2440.0, 49.3964
17.507759389, 96.390, 2505.0, 50.0500
17.560280520, 96.390, 2568.0, 50.6754
17.612801650, 96.390, 2600.0, 50.9902
17.665322781, 96.390, 2540.0, 50.3984
17.717843912, 96.390, 2648.0, 51.4587
17.770365042, 96.390, 2561.0, 50.6063
17.822886173, 96.390, 2676.0, 51.7301
17.875407304, 96.390, 2550.0, 50.4975
17.927928434, 96.390, 2678.0, 51.7494
17.980449565, 96.390, 2543.0, 50.4282
18.032970696, 96.390, 2645.0, 51.4296
18.085491827, 96.390, 2630.0, 51.2835
18.138012957, 96.390, 2634.0, 51.3225
18.190534088, 96.390, 2610.0, 51.0882
18.243055219, 96.390, 2681.0, 51.7784
18.295576349, 96.390, 2655.0, 51.5267
18.348097480, 96.390, 2628.0, 51.2640
18.400618611, 96.390, 2778.0, 52.7067
18.453139742, 96.390, 2673.0, 51.7011
18.505660872, 96.390, 2757.0, 52.5071
18.558182003, 96.390, 2599.0, 50.9804
18.610703134, 96.390, 2699.0, 51.9519
18.663224264, 96.390, 2765.0, 52.5833
18.715745395, 96.390, 2817.0, 53.0754
18.768266526, 96.390, 2807.0, 52.9811
18.820787657, 96.390, 2742.0, 52.3641
18.873308787, 96.390, 2812.0, 53.0283
18.925829918, 96.390, 2757.0, 52.5071
18.978351049, 96.390, 2802.0, 52.9339
19.030872179, 96.390, 2752.0, 52.4595
19.083393310, 96.390, 2884.0, 53.7029
19.135914441, 96.390, 2800.0, 52.9150
19.188435572, 96.390, 2849.0, 53.3760
19.240956702, 96.390, 2866.0, 53.5350
19.293477833, 96.390, 2902.0, 53.8702
19.345998964, 96.390, 2922.0, 54.0555
19.398520094, 96.390, 3064.0, 55.3534
19.451041225, 96.390, 2994.0, 54.7175
19.503562356, 96.390, 2931.0, 54.1387
19.556083486, 96.390, 3003.0, 54.7996
19.608604617, 96.390, 2995.0, 54.7266
19.661125748, 96.390, 2918.0, 54.0185
19.713646879, 96.390, 3049.0, 55.2178
19.766168009, 96.390, 3000.0, 54.7723
19.818689140, 96.390, 3008.0, 54.8452
19.871210271, 96.390, 3177.0, 56.3649
19.923731401, 96.390, 3094.0, 55.6237
19.976252532, 96.390, 3098.0, 55.6597
20.028773663, 96.390, 3148.0, 56.1070
20.081294794, 96.390, 3020.0, 54.9545
20.133815924, 96.390, 3139.0, 56.0268
20.186337055, 96.390, 3129.0, 55.9375
20.238858186, 96.390, 3052.0, 55.2449
20.291379316, 96.390, 3178.0, 56.3738
20.343900447, 96.390, 3268.0, 57.1664
20.396421578, 96.390, 3283.0, 57.2975
20.448942709, 96.390, 3260.0, 57.0964
20.501463839, 96.390, 3238.0, 56.9034
20.553984970, 96.390, 3211.0, 56.6657
20.606506101, 96.390, 3105.0, 55.7225
20.659027231, 96.390, 3249.0, 57.0000
20.711548362, 96.390, 3216.0, 56.7098
20.764069493, 96.390, 3377.0, 58.1120
20.816590623, 96.390, 3271.0, 57.1927
20.869111754, 96.390, 3266.0, 57.1489
20.921632885, 96.390, 3169.0, 56.2939
20.974154016, 96.390, 3317.0, 57.5934
21.026675146, 96.390, 3305.0, 57.4891
21.079196277, 96.390, 3396.0, 58.2752
21.131717408, 96.390, 3259.0, 57.0877
21.184238538, 96.390, 3379.0, 58.1292
21.236759669, 96.390, 3247.0, 56.9825
21.289280800, 96.390, 3281.0, 57.2800
21.341801931, 96.390, 3311.0, 57.5413
21.394323061, 96.390, 3440.0, 58.6515
21.446844192, 96.390, 3371.0, 58.0603
21.499365323, 96.390, 3456.0, 58.7878
21.551886453, 96.390, 3376.0, 58.1034
21.604407584, 96.390, 3389.0, 58.2151
21.656928715, 96.390, 3354.0, 57.9137
21.709449846, 96.390, 3380.0, 58.1378
21.761970976, 96.390, 3313.0, 57.5587
21.814492107, 96.390, 3451.0, 58.7452
21.867013238, 96.390, 3328.0, 57.6888
21.919534368, 96.390, 3435.0, 58.6089
21.972055499, 96.390, 3391.0, 58.2323
22.024576630, 96.390, 3389.0, 58.2151
22.077097761, 96.390, 3474.0, 58.9406
22.129618891, 96.390, 3387.0, 58.1979
22.182140022, 96.390, 3464.0, 58.8558
22.234661153, 96.390, 3291.0, 57.3672
22.287182283, 96.390, 3350.0, 57.8792
22.339703414, 96.390, 3419.0, 58.4722
22.392224545, 96.390, 3327.0, 57.6802
22.444745675, 96.390, 3428.0, 58.5491
22.497266806, 96.390, 3443.0, 58.6771
22.549787937, 96.390, 3337.0, 57.7668
22.602309068, 96.390, 3313.0, 57.5587
22.654830198, 96.390, 3235.0, 56.8771
22.707351329, 96.390, 3423.0, 58.5064
22.759872460, 96.390, 3340.0, 57.7927
22.812393590, 96.390, 3301.0, 57.4543
22.864914721, 96.390, 3260.0, 57.0964
22.917435852, 96.390, 3405.0, 58.3524
22.969956983, 96.390, 3385.0, 58.1808
23.022478113, 96.390, 3243.0, 56.9473
23.074999244, 96.390, 3272.0, 57.2014
23.127520375, 96.390, 3347.0, 57.8533
23.180041505, 96.390, 3321.0, 57.6281
23.232562636, 96.390, 3251.0, 57.0175
23.285083767, 96.390, 3201.0, 56.5774
23.337604898, 96.390, 3223.0, 56.7715
23.390126028, 96.390, 3219.0, 56.7362
23.442647159, 96.390, 3271.0, 57.1927
23.495168290, 96.390, 3152.0, 56.1427
23.547689420, 96.390, 3219.0, 56.7362
23.600210551, 96.390, 3184.0, 56.4269
23.652731682, 96.390, 3151.0, 56.1338
23.705252813, 96.390, 3110.0, 55.7674
23.757773943, 96.390, 3152.0, 56.1427
23.810295074, 96.390, 3179.0, 56.3826
23.862816205, 96.390, 3148.0, 56.1070
23.915337335, 96.390, 3063.0, 55.3444
23.967858466, 96.390, 3075.0, 55.4527
24.020379597, 96.390, 3102.0, 55.6956
24.072900727, 96.390, 2935.0, 54.1756
24.125421858, 96.390, 3051.0, 55.2359
24.177942989, 96.390, 3205.0, 56.6127
24.230464120, 96.390, 3045.0, 55.1815
24.282985250, 96.390, 3003.0, 54.7996
24.335506381, 96.390, 2949.0, 54.3047
24.388027512, 96.390, 3031.0, 55.0545
24.440548642, 96.390, 2945.0, 54.2679
24.493069773, 96.390, 2965.0, 54.4518
24.545590904, 96.390, 2944.0, 54.2586
24.598112035, 96.390, 2921.0, 54.0463
24.650633165, 96.390, 2894.0, 53.7959
24.703154296, 96.390, 2882.0, 53.6843
24.755675427, 96.390, 2925.0, 54.0833
24.808196557, 96.390, 3004.0, 54.8088
24.860717688, 96.390, 2841.0, 53.3010
24.913238819, 96.390, 2972.0, 54.5161
24.965759950, 96.390, 2872.0, 53.5910
25.018281080, 96.390, 2815.0, 53.0566
25.070802211, 96.390, 2811.0, 53.0189
25.123323342, 96.390, 2851.0, 53.3948
25.175844472, 96.390, 2764.0, 52.5738
25.228365603, 96.390, 2772.0, 52.6498
25.280886734, 96.390, 2731.0, 52.2590
25.333407864, 96.390, 2676.0, 51.7301
25.385928995, 96.390, 2744.0, 52.3832
25.438450126, 96.390, 2667.0, 51.6430
25.490971257, 96.390, 2757.0, 52.5071
25.543492387, 96.390, 2711.0, 52.0673
25.596013518, 96.390, 2627.0, 51.2543
25.648534649, 96.390, 2655.0, 51.5267
25.701055779, 96.390, 2681.0, 51.7784
25.753576910, 96.390, 2621.0, 51.1957
25.806098041, 96.390, 2619.0, 51.1762
25.858619172, 96.390, 2627.0, 51.2543
25.911140302, 96.390, 2649.0, 51.4684
25.963661433, 96.390, 2640.0, 51.3809
26.016182564, 96.390, 2663.0, 51.6043
26.068703694, 96.390, 2655.0, 51.5267
26.121224825, 96.390, 2598.0, 50.9706
26.173745956, 96.390, 2651.0, 51.4879
26.226267087, 96.390, 2464.0, 49.6387
26.278788217, 96.390, 2642.0, 51.4004
26.331309348, 96.390, 2576.0, 50.7543
26.383830479, 96.390, 2514.0, 50.1398
26.436351609, 96.390, 2499.0, 49.9900
26.488872740, 96.390, 2555.0, 50.5470
26.541393871, 96.390, 2430.0, 49.2950
26.593915002, 96.390, 2517.0, 50.1697
26.646436132, 96.390, 2544.0, 50.4381
26.698957263, 96.390, 2485.0, 49.8498
26.751478394, 96.390, 2541.0, 50.4083
26.803999524, 96.390, 2413.0, 49.1223
26.856520655, 96.390, 2491.0, 49.9099
26.909041786, 96.390, 2474.0, 49.7393
26.961562916, 96.390, 2443.0, 49.4267
27.014084047, 96.390, 2340.0, 48.3735
27.066605178, 96.390, 2415.0, 49.1426
27.119126309, 96.390, 2453.0, 49.5278
27.171647439, 96.390, 2324.0, 48.2079
27.224168570, 96.390, 2416.0, 49.1528
27.276689701, 96.390, 2349.0, 48.4665
27.329210831, 96.390, 2382.0, 48.8057
27.381731962, 96.390, 2420.0, 49.1935
27.434253093, 96.390, 2311.0, 48.0729
27.486774224, 96.390, 2380.0, 48.7852
27.539295354, 96.390, 2319.0, 48.1560
27.591816485, 96.390, 2448.0, 49.4773
27.644337616, 96.390, 2300.0, 47.9583
27.696858746, 96.390, 2370.0, 48.6826
27.749379877, 96.390, 2396.0, 48.9490
27.801901008, 96.390, 2293.0, 47.8853
27.854422139, 96.390, 2293.0, 47.8853
27.906943269, 96.390, 2357.0, 48.5489
27.959464400, 96.390, 2245.0, 47.3814
28.011985531, 96.390, 2327.0, 48.2390
28.064506661, 96.390, 2262.0, 47.5605
28.117027792, 96.390, 2328.0, 48.2494
28.169548923, 96.390, 2257.0, 47.5079
28.222070054, 96.390, 2240.0, 47.3286
28.274591184, 96.390, 2282.0, 47.7703
28.327112315, 96.390, 2294.0, 47.8957
28.379633446, 96.390, 2258.0, 47.5184
28.432154576, 96.390, 2361.0, 48.5901
28.484675707, 96.390, 2251.0, 47.4447
28.537196838, 96.390, 2233.0, 47.2546
28.589717968, 96.390, 2262.0, 47.5605
28.642239099, 96.390, 2276.0, 47.7074
28.694760230, 96.390, 2229.0, 47.2123
28.747281361, 96.390, 2297.0, 47.9270
28.799802491, 96.390, 2235.0, 47.2758
28.852323622, 96.390, 2287.0, 47.8226
28.904844753, 96.390, 2261.0, 47.5500
28.957365883, 96.390, 2192.0, 46.8188
29.009887014, 96.390, 2190.0, 46.7974
29.062408145, 96.390, 2326.0, 48.2286
29.114929276, 96.390, 2184.0, 46.7333
29.167450406, 96.390, 2227.0, 47.1911
29.219971537, 96.390, 2178.0, 46.6690
29.272492668, 96.390, 2088.0, 45.6946
29.325013798, 96.390, 2240.0, 47.3286
29.377534929, 96.390, 2173.0, 46.6154
29.430056060, 96.390, 2133.0, 46.1844
29.482577191, 96.390, 2150.0, 46.3681
29.535098321, 96.390, 2149.0, 46.3573
29.587619452, 96.390, 2140.0, 46.2601
29.640140583, 96.390, 2179.0, 46.6798
29.692661713, 96.390, 2247.0, 47.4025
29.745182844, 96.390, 2071.0, 45.5082
29.797703975, 96.390, 2158.0, 46.4543
29.850225105, 96.390, 2236.0, 47.2864
29.902746236, 96.390, 2208.0, 46.9894
29.955267367, 96.390, 2180.0, 46.6905
30.007788498, 96.390, 2197.0, 46.8722
30.060309628, 96.390, 2156.0, 46.4327
30.112830759, 96.390, 2122.0, 46.0652
30.165351890, 96.390, 2131.0, 46.1628
30.217873020, 96.390, 2122.0, 46.0652
30.270394151, 96.390, 2127.0, 46.1194
30.322915282, 96.390, 2163.0, 46.5081
30.375436413, 96.390, 2112.0, 45.9565
30.427957543, 96.390, 2114.0, 45.9783
30.480478674, 96.390, 2172.0, 46.6047
30.532999805, 96.390, 2078.0, 45.5851
30.585520935, 96.390, 2076.0, 45.5631
30.638042066, 96.390, 2146.0, 46.3249
30.690563197, 96.390, 2088.0, 45.6946
30.743084328, 96.390, 2055.0, 45.3321
30.795605458, 96.390, 2159.0, 46.4650
30.848126589, 96.390, 2111.0, 45.9456
30.900647720, 96.390, 2016.0, 44.8999
30.953168850, 96.390, 2070.0, 45.4973
31.005689981, 96.390, 2064.0, 45.4313
31.058211112, 96.390, 2097.0, 45.7930
31.110732243, 96.390, 2044.0, 45.2106
31.163253373, 96.390, 2083.0, 45.6399
31.215774504, 96.390, 2071.0, 45.5082
31.268295635, 96.390, 2050.0, 45.2769
31.320816765, 96.390, 1965.0, 44.3283
31.373337896, 96.390, 2002.0, 44.7437
31.425859027, 96.390, 2029.0, 45.0444
31.478380157, 96.390, 2032.0, 45.0777
31.530901288, 96.390, 2058.0, 45.3652
31.583422419, 96.390, 2029.0, 45.0444
31.635943550, 96.390, 2007.0, 44.7996
31.688464680, 96.390, 2018.0, 44.9222
31.740985811, 96.390, 2054.0, 45.3211
31.793506942, 96.390, 1978.0, 44.4747
31.846028072, 96.390, 2037.0, 45.1331
31.898549203, 96.390, 2023.0, 44.9778
31.951070334, 96.390, 1982.0, 44.5197
32.003591465, 96.390, 1993.0, 44.6430
32.056112595, 96.390, 2000.0, 44.7214
32.108633726, 96.390, 1993.0, 44.6430
32.161154857, 96.390, 2016.0, 44.8999
32.213675987, 96.390, 2004.0, 44.7661
32.266197118, 96.390, 2021.0, 44.9555
32.318718249, 96.390, 1933.0, 43.9659
32.371239380, 96.390, 1993.0, 44.6430
32.423760510, 96.390, 1898.0, 43.5660
32.476281641, 96.390, 2004.0, 44.7661
32.528802772, 96.390, 1993.0, 44.6430
32.581323902, 96.390, 1968.0, 44.3621
32.633845033, 96.390, 1952.0, 44.1814
32.686366164, 96.390, 2067.0, 45.4643
32.738887295, 96.390, 1986.0, 44.5646
32.791408425, 96.390, 1964.0, 44.3170
32.843929556, 96.390, 1914.0, 43.7493
32.896450687, 96.390, 1949.0, 44.1475
32.948971817, 96.390, 1956.0, 44.2267
33.001492948, 96.390, 1934.0, 43.9773
33.054014079, 96.390, 1970.0, 44.3847
33.106535209, 96.390, 1957.0, 44.2380
33.159056340, 96.390, 1934.0, 43.9773
33.211577471, 96.390, 1868.0, 43.2204
33.264098602, 96.390, 1900.0, 43.5890
33.316619732, 96.390, 1949.0, 44.1475
33.369140863, 96.390, 1826.0, 42.7317
33.421661994, 96.390, 1865.0, 43.1856
33.474183124, 96.390, 1896.0, 43.5431
33.526704255, 96.390, 1900.0, 43.5890
33.579225386, 96.390, 1848.0, 42.9884
33.631746517, 96.390, 1784.0, 42.2374
33.684267647, 96.390, 1861.0, 43.1393
33.736788778, 96.390, 1950.0, 44.1588
33.789309909, 96.390, 1969.0, 44.3734
33.841831039, 96.390, 1921.0, 43.8292
33.894352170, 96.390, 1863.0, 43.1625
33.946873301, 96.390, 1859.0, 43.1161
33.999394432, 96.390, 1863.0, 43.1625
34.051915562, 96.390, 1923.0, 43.8520
34.104436693, 96.390, 1837.0, 42.8602
34.156957824, 96.390, 1948.0, 44.1362
34.209478954, 96.390, 1873.0, 43.2782
34.262000085, 96.390, 1945.0, 44.1022
34.314521216, 96.390, 1933.0, 43.9659
34.367042346, 96.390, 1942.0, 44.0681
34.419563477, 96.390, 1944.0, 44.0908
34.472084608, 96.390, 1937.0, 44.0114
34.524605739, 96.390, 1938.0, 44.0227
34.577126869, 96.390, 1964.0, 44.3170
34.629648000, 96.390, 2041.0, 45.1774
34.682169131, 96.390, 1893.0, 43.5086
34.734690261, 96.390, 1949.0, 44.1475
34.787211392, 96.390, 1938.0, 44.0227
34.839732523, 96.390, 1938.0, 44.0227
34.892253654, 96.390, 1969.0, 44.3734
34.944774784, 96.390, 1949.0, 44.1475
34.997295915, 96.390, 1945.0, 44.1022
35.049817046, 96.390, 1990.0, 44.6094
35.102338176, 96.390, 1931.0, 43.9431
35.154859307, 96.390, 1920.0, 43.8178
35.207380438, 96.390, 1945.0, 44.1022
35.259901569, 96.390, 1954.0, 44.2041
35.312422699, 96.390, 1959.0, 44.2606
35.364943830, 96.390, 1870.0, 43.2435
35.417464961, 96.390, 1925.0, 43.8748
35.469986091, 96.390, 1865.0, 43.1856
35.522507222, 96.390, 1964.0, 44.3170
35.575028353, 96.390, 1895.0, 43.5316
35.627549484, 96.390, 1977.0, 44.4635
35.680070614, 96.390, 1895.0, 43.5316
35.732591745, 96.390, 1918.0, 43.7950
35.785112876, 96.390, 1842.0, 42.9185
35.837634006, 96.390, 1841.0, 42.9069
35.890155137, 96.390, 1882.0, 43.3820
35.942676268, 96.390, 1883.0, 43.3935
35.995197398, 96.390, 1744.0, 41.7612
36.047718529, 96.390, 1916.0, 43.7721
36.100239660, 96.390, 1878.0, 43.3359
36.152760791, 96.390, 1819.0, 42.6497
36.205281921, 96.390, 1843.0, 42.9302
36.257803052, 96.390, 1824.0, 42.7083
36.310324183, 96.390, 1828.0, 42.7551
36.362845313, 96.390, 1858.0, 43.1045
36.415366444, 96.390, 1825.0, 42.7200
36.467887575, 96.390, 1787.0, 42.2729
36.520408706, 96.390, 1803.0, 42.4617
36.572929836, 96.390, 1748.0, 41.8091
36.625450967, 96.390, 1749.0, 41.8210
36.677972098, 96.390, 1771.0, 42.0833
36.730493228, 96.390, 1772.0, 42.0951
36.783014359, 96.390, 1725.0, 41.5331
36.835535490, 96.390, 1764.0, 42.0000
36.888056621, 96.390, 1794.0, 42.3556
36.940577751, 96.390, 1761.0, 41.9643
36.993098882, 96.390, 1772.0, 42.0951
37.045620013, 96.390, 1731.0, 41.6053
37.098141143, 96.390, 1671.0, 40.8779
37.150662274, 96.390, 1673.0, 40.9023
37.203183405, 96.390, 1656.0, 40.6940
37.255704535, 96.390, 1649.0, 40.6079
37.308225666, 96.390, 1619.0, 40.2368
37.360746797, 96.390, 1693.0, 41.1461
37.413267928, 96.390, 1631.0, 40.3856
37.465789058, 96.390, 1677.0, 40.9512
37.518310189, 96.390, 1689.0, 41.0974
37.570831320, 96.390, 1571.0, 39.6358
37.623352450, 96.390, 1559.0, 39.4842
37.675873581, 96.390, 1620.0, 40.2492
37.728394712, 96.390, 1577.0, 39.7115
37.780915843, 96.390, 1645.0, 40.5586
37.833436973, 96.390, 1573.0, 39.6611
37.885958104, 96.390, 1558.0, 39.4715
37.938479235, 96.390, 1541.0, 39.2556
37.991000365, 96.390, 1655.0, 40.6817
38.043521496, 96.390, 1659.0, 40.7308
38.096042627, 96.390, 1533.0, 39.1535
38.148563758, 96.390, 1541.0, 39.2556
38.201084888, 96.390, 1528.0, 39.0896
38.253606019, 96.390, 1655.0, 40.6817
38.306127150, 96.390, 1592.0, 39.8999
38.358648280, 96.390, 1552.0, 39.3954
38.411169411, 96.390, 1515.0, 38.9230
38.463690542, 96.390, 1541.0, 39.2556
38.516211673, 96.390, 1487.0, 38.5616
38.568732803, 96.390, 1497.0, 38.6911
38.621253934, 96.390, 1436.0, 37.8946
38.673775065, 96.390, 1653.0, 40.6571
38.726296195, 96.390, 1508.0, 38.8330
38.778817326, 96.390, 1426.0, 37.7624
38.831338457, 96.390, 1514.0, 38.9102
38.883859587, 96.390, 1473.0, 38.3797
38.936380718, 96.390, 1510.0, 38.8587
38.988901849, 96.390, 1517.0, 38.9487
39.041422980, 96.390, 1394.0, 37.3363
39.093944110, 96.390, 1436.0, 37.8946
39.146465241, 96.390, 1444.0, 38.0000
39.198986372, 96.390, 1426.0, 37.7624
39.251507502, 96.390, 1467.0, 38.3014
39.304028633, 96.390, 1362.0, 36.9053
39.356549764, 96.390, 1448.0, 38.0526
39.409070895, 96.390, 1390.0, 37.2827
39.461592025, 96.390, 1379.0, 37.1349
39.514113156, 96.390, 1403.0, 37.4566
39.566634287, 96.390, 1432.0, 37.8418
39.619155417, 96.390, 1395.0, 37.3497
39.671676548, 96.390, 1397.0, 37.3765
39.724197679, 96.390, 1389.0, 37.2693
39.776718810, 96.390, 1438.0, 37.9210
39.829239940, 96.390, 1360.0, 36.8782
39.881761071, 96.390, 1333.0, 36.5103
39.934282202, 96.390, 1424.0, 37.7359
39.986803332, 96.390, 1328.0, 36.4417
40.039324463, 96.390, 1382.0, 37.1753
40.091845594, 96.390, 1326.0, 36.4143
40.144366725, 96.390, 1405.0, 37.4833
40.196887855, 96.390, 1375.0, 37.0810
40.249408986, 96.390, 1394.0, 37.3363
40.301930117, 96.390, 1329.0, 36.4555
40.354451247, 96.390, 1400.0, 37.4166
40.406972378, 96.390, 1312.0, 36.2215
40.459493509, 96.390, 1309.0, 36.1801
40.512014639, 96.390, 1345.0, 36.6742
40.564535770, 96.390, 1397.0, 37.3765
40.617056901, 96.390, 1314.0, 36.2491
40.669578032, 96.390, 1383.0, 37.1887
40.722099162, 96.390, 1343.0, 36.6470
40.774620293, 96.390, 1325.0, 36.4005
40.827141424, 96.390, 1342.0, 36.6333
40.879662554, 96.390, 1373.0, 37.0540
40.932183685, 96.390, 1301.0, 36.0694
40.984704816, 96.390, 1304.0, 36.1109
41.037225947, 96.390, 1342.0, 36.6333
41.089747077, 96.390, 1306.0, 36.1386
41.142268208, 96.390, 1307.0, 36.1525
41.194789339, 96.390, 1276.0, 35.7211
41.247310469, 96.390, 1324.0, 36.3868
41.299831600, 96.390, 1368.0, 36.9865
41.352352731, 96.390, 1291.0, 35.9305
41.404873862, 96.390, 1221.0, 34.9428
41.457394992, 96.390, 1329.0, 36.4555
41.509916123, 96.390, 1329.0, 36.4555
41.562437254, 96.390, 1272.0, 35.6651
41.614958384, 96.390, 1295.0, 35.9861
41.667479515, 96.390, 1304.0, 36.1109
41.720000646, 96.390, 1293.0, 35.9583
41.772521776, 96.390, 1328.0, 36.4417
41.825042907, 96.390, 1255.0, 35.4260
41.877564038, 96.390, 1330.0, 36.4692
41.930085169, 96.390, 1354.0, 36.7967
41.982606299, 96.390, 1274.0, 35.6931
42.035127430, 96.390, 1401.0, 37.4299
42.087648561, 96.390, 1282.0, 35.8050
42.140169691, 96.390, 1291.0, 35.9305
42.192690822, 96.390, 1314.0, 36.2491
42.245211953, 96.390, 1305.0, 36.1248
42.297733084, 96.390, 1294.0, 35.9722
42.350254214, 96.390, 1317.0, 36.2905
42.402775345, 96.390, 1349.0, 36.7287
42.455296476, 96.390, 1285.0, 35.8469
42.507817606, 96.390, 1303.0, 36.0971
42.560338737, 96.390, 1327.0, 36.4280
42.612859868, 96.390, 1331.0, 36.4829
42.665380999, 96.390, 1328.0, 36.4417
42.717902129, 96.390, 1302.0, 36.0832
42.770423260, 96.390, 1312.0, 36.2215
42.822944391, 96.390, 1331.0, 36.4829
42.875465521, 96.390, 1299.0, 36.0416
42.927986652, 96.390, 1323.0, 36.3731
42.980507783, 96.390, 1320.0, 36.3318
43.033028914, 96.390, 1341.0, 36.6197
43.085550044, 96.390, 1330.0, 36.4692
43.138071175, 96.390, 1292.0, 35.9444
43.190592306, 96.390, 1275.0, 35.7071
43.243113436, 96.390, 1262.0, 35.5246
43.295634567, 96.390, 1234.0, 35.1283
43.348155698, 96.390, 1258.0, 35.4683
43.400676828, 96.390, 1308.0, 36.1663
43.453197959, 96.390, 1299.0, 36.0416
43.505719090, 96.390, 1234.0, 35.1283
43.558240221, 96.390, 1366.0, 36.9594
43.610761351, 96.390, 1273.0, 35.6791
43.663282482, 96.390, 1246.0, 35.2987
43.715803613, 96.390, 1306.0, 36.1386
43.768324743, 96.390, 1293.0, 35.9583
43.820845874, 96.390, 1175.0, 34.2783
43.873367005, 96.390, 1308.0, 36.1663
43.925888136, 96.390, 1297.0, 36.0139
43.978409266, 96.390, 1242.0, 35.2420
44.030930397, 96.390, 1218.0, 34.8999
44.083451528, 96.390, 1249.0, 35.3412
44.135972658, 96.390, 1256.0, 35.4401
44.188493789, 96.390, 1248.0, 35.3270
44.241014920, 96.390, 1251.0, 35.3695
44.293536051, 96.390, 1311.0, 36.2077
44.346057181, 96.390, 1295.0, 35.9861
44.398578312, 96.390, 1250.0, 35.3553
44.451099443, 96.390, 1252.0, 35.3836
44.503620573, 96.390, 1292.0, 35.9444
44.556141704, 96.390, 1245.0, 35.2846
44.608662835, 96.390, 1288.0, 35.8887
44.661183966, 96.390, 1281.0, 35.7911
44.713705096, 96.390, 1267.0, 35.5949
44.766226227, 96.390, 1261.0, 35.5106
44.818747358, 96.390, 1244.0, 35.2704
44.871268488, 96.390, 1276.0, 35.7211
44.923789619, 96.390, 1286.0, 35.8608
44.976310750, 96.390, 1285.0, 35.8469
45.028831880, 96.390, 1267.0, 35.5949
45.081353011, 96.390, 1218.0, 34.8999
45.133874142, 96.390, 1266.0, 35.5809
45.186395273, 96.390, 1235.0, 35.1426
45.238916403, 96.390, 1225.0, 35.0000
45.291437534, 96.390, 1257.0, 35.4542
45.343958665, 96.390, 1232.0, 35.0999
45.396479795, 96.390, 1223.0, 34.9714
45.449000926, 96.390, 1257.0, 35.4542
45.501522057, 96.390, 1209.0, 34.7707
45.554043188, 96.390, 1326.0, 36.4143
45.606564318, 96.390, 1265.0, 35.5668
45.659085449, 96.390, 1233.0, 35.1141
45.711606580, 96.390, 1299.0, 36.0416
45.764127710, 96.390, 1292.0, 35.9444
45.816648841, 96.390, 1247.0, 35.3129
45.869169972, 96.390, 1178.0, 34.3220
45.921691103, 96.390, 1242.0, 35.2420
45.974212233, 96.390, 1225.0, 35.0000
46.026733364, 96.390, 1253.0, 35.3977
46.079254495, 96.390, 1237.0, 35.1710
46.131775625, 96.390, 1279.0, 35.7631
46.184296756, 96.390, 1273.0, 35.6791
46.236817887, 96.390, 1210.0, 34.7851
46.289339017, 96.390, 1235.0, 35.1426
46.341860148, 96.390, 1239.0, 35.1994
46.394381279, 96.390, 1241.0, 35.2278
46.446902410, 96.390, 1151.0, 33.9264
46.499423540, 96.390, 1177.0, 34.3074
46.551944671, 96.390, 1251.0, 35.3695
46.604465802, 96.390, 1190.0, 34.4964
46.656986932, 96.390, 1223.0, 34.9714
46.709508063, 96.390, 1234.0, 35.1283
46.762029194, 96.390, 1189.0, 34.4819
46.814550325, 96.390, 1149.0, 33.8969
46.867071455, 96.390, 1206.0, 34.7275
46.919592586, 96.390, 1185.0, 34.4238
46.972113717, 96.390, 1202.0, 34.6699
47.024634847, 96.390, 1210.0, 34.7851
47.077155978, 96.390, 1201.0, 34.6554
47.129677109, 96.390, 1268.0, 35.6090
47.182198240, 96.390, 1198.0, 34.6121
47.234719370, 96.390, 1219.0, 34.9142
47.287240501, 96.390, 1190.0, 34.4964
47.339761632, 96.390, 1185.0, 34.4238
47.392282762, 96.390, 1159.0, 34.0441
47.444803893, 96.390, 1154.0, 33.9706
47.497325024, 96.390, 1193.0, 34.5398
47.549846155, 96.390, 1218.0, 34.8999
47.602367285, 96.390, 1138.0, 33.7343
47.654888416, 96.390, 1150.0, 33.9116
47.707409547, 96.390, 1159.0, 34.0441
47.759930677, 96.390, 1119.0, 33.4515
47.812451808, 96.390, 1162.0, 34.0881
47.864972939, 96.390, 1151.0, 33.9264
47.917494069, 96.390, 1130.0, 33.6155
47.970015200, 96.390, 1178.0, 34.3220
48.022536331, 96.390, 1190.0, 34.4964
48.075057462, 96.390, 1150.0, 33.9116
48.127578592, 96.390, 1130.0, 33.6155
48.180099723, 96.390, 1139.0, 33.7491
48.232620854, 96.390, 1126.0, 33.5559
48.285141984, 96.390, 1182.0, 34.3802
48.337663115, 96.390, 1094.0, 33.0757
48.390184246, 96.390, 1165.0, 34.1321
48.442705377, 96.390, 1127.0, 33.5708
48.495226507, 96.390, 1087.0, 32.9697
48.547747638, 96.390, 1124.0, 33.5261
48.600268769, 96.390, 1153.0, 33.9559
48.652789899, 96.390, 1130.0, 33.6155
48.705311030, 96.390, 1129.0, 33.6006
48.757832161, 96.390, 1157.0, 34.0147
48.810353292, 96.390, 1109.0, 33.3017
48.862874422, 96.390, 1102.0, 33.1964
48.915395553, 96.390, 1077.0, 32.8177
48.967916684, 96.390, 1128.0, 33.5857
49.020437814, 96.390, 1061.0, 32.5730
49.072958945, 96.390, 1077.0, 32.8177
49.125480076, 96.390, 1067.0, 32.6650
49.178001207, 96.390, 1044.0, 32.3110
49.230522337, 96.390, 1127.0, 33.5708
49.283043468, 96.390, 1043.0, 32.2955
49.335564599, 96.390, 1135.0, 33.6898
49.388085729, 96.390, 1011.0, 31.7962
49.440606860, 96.390, 1078.0, 32.8329
49.493127991, 96.390, 1102.0, 33.1964
49.545649121, 96.390, 1109.0, 33.3017
49.598170252, 96.390, 1034.0, 32.1559
49.650691383, 96.390, 1069.0, 32.6956
49.703212514, 96.390, 1077.0, 32.8177
49.755733644, 96.390, 1039.0, 32.2335
49.808254775, 96.390, 1146.0, 33.8526
49.860775906, 96.390, 1068.0, 32.6803
49.913297036, 96.390, 1058.0, 32.5269
49.965818167, 96.390, 1066.0, 32.6497
50.018339298, 96.390, 1058.0, 32.5269
50.070860429, 96.390, 1053.0, 32.4500
50.123381559, 96.390, 1053.0, 32.4500
50.175902690, 96.390, 1076.0, 32.8024
50.228423821, 96.390, 1067.0, 32.6650
50.280944951, 96.390, 1039.0, 32.2335
50.333466082, 96.390, 1051.0, 32.4191
50.385987213, 96.390, 1025.0, 32.0156
50.438508344, 96.390, 983.0, 31.3528
50.491029474, 96.390, 1044.0, 32.3110
50.543550605, 96.390, 1028.0, 32.0624
50.596071736, 96.390, 1025.0, 32.0156
50.648592866, 96.390, 1047.0, 32.3574
50.701113997, 96.390, 1092.0, 33.0454
50.753635128, 96.390, 994.0, 31.5278
50.806156258, 96.390, 1058.0, 32.5269
50.858677389, 96.390, 1010.0, 31.7805
50.911198520, 96.390, 1047.0, 32.3574
50.963719651, 96.390, 989.0, 31.4484
51.016240781, 96.390, 1025.0, 32.0156
51.068761912, 96.390, 1074.0, 32.7719
51.121283043, 96.390, 1029.0, 32.0780
51.173804173, 96.390, 1016.0, 31.8748
51.226325304, 96.390, 1004.0, 31.6860
51.278846435, 96.390, 1063.0, 32.6037
51.331367566, 96.390, 1009.0, 31.7648
51.383888696, 96.390, 980.0, 31.3050
51.436409827, 96.390, 973.0, 31.1929
51.488930958, 96.390, 1006.0, 31.7175
51.541452088, 96.390, 974.0, 31.2090
51.593973219, 96.390, 1050.0, 32.4037
51.646494350, 96.390, 991.0, 31.4802
51.699015481, 96.390, 1039.0, 32.2335
51.751536611, 96.390, 965.0, 31.0644
51.804057742, 96.390, 1017.0, 31.8904
51.856578873, 96.390, 988.0, 31.4325
51.909100003, 96.390, 1039.0, 32.2335
51.961621134, 96.390, 1009.0, 31.7648
52.014142265, 96.390, 1033.0, 32.1403
52.066663396, 96.390, 986.0, 31.4006
52.119184526, 96.390, 969.0, 31.1288
52.171705657, 96.390, 980.0, 31.3050
52.224226788, 96.390, 935.0, 30.5778
52.276747918, 96.390, 1000.0, 31.6228
52.329269049, 96.390, 1030.0, 32.0936
52.381790180, 96.390, 980.0, 31.3050
52.434311310, 96.390, 1006.0, 31.7175
52.486832441, 96.390, 948.0, 30.7896
52.539353572, 96.390, 995.0, 31.5436
52.591874703, 96.390, 951.0, 30.8383
52.644395833, 96.390, 1020.0, 31.9374
52.696916964, 96.390, 958.0, 30.9516
52.749438095, 96.390, 1005.0, 31.7017
52.801959225, 96.390, 987.0, 31.4166
52.854480356, 96.390, 1021.0, 31.9531
52.907001487, 96.390, 994.0, 31.5278
52.959522618, 96.390, 1014.0, 31.8434
53.012043748, 96.390, 975.0, 31.2250
53.064564879, 96.390, 921.0, 30.3480
53.117086010, 96.390, 960.0, 30.9839
53.169607140, 96.390, 1011.0, 31.7962
53.222128271, 96.390, 976.0, 31.2410
53.274649402, 96.390, 986.0, 31.4006
53.327170533, 96.390, 982.0, 31.3369
53.379691663, 96.390, 922.0, 30.3645
53.432212794, 96.390, 947.0, 30.7734
53.484733925, 96.390, 943.0, 30.7083
53.537255055, 96.390, 958.0, 30.9516
53.589776186, 96.390, 947.0, 30.7734
53.642297317, 96.390, 938.0, 30.6268
53.694818448, 96.390, 932.0, 30.5287
53.747339578, 96.390, 978.0, 31.2730
53.799860709, 96.390, 966.0, 31.0805
53.852381840, 96.390, 986.0, 31.4006
53.904902970, 96.390, 901.0, 30.0167
53.957424101, 96.390, 954.0, 30.8869
54.009945232, 96.390, 930.0, 30.4959
54.062466362, 96.390, 926.0, 30.4302
54.114987493, 96.390, 964.0, 31.0483
54.167508624, 96.390, 933.0, 30.5450
54.220029755, 96.390, 886.0, 29.7658
54.272550885, 96.390, 928.0, 30.4631
54.325072016, 96.390, 970.0, 31.1448
54.377593147, 96.390, 973.0, 31.1929
54.430114277, 96.390, 966.0, 31.0805
54.482635408, 96.390, 968.0, 31.1127
54.535156539, 96.390, 954.0, 30.8869
54.587677670, 96.390, 903.0, 30.0500
54.640198800, 96.390, 988.0, 31.4325
54.692719931, 96.390, 971.0, 31.1609
54.745241062, 96.390, 963.0, 31.0322
54.797762192, 96.390, 945.0, 30.7409
54.850283323, 96.390, 938.0, 30.6268
54.902804454, 96.390, 966.0, 31.0805
54.955325585, 96.390, 927.0, 30.4467
55.007846715, 96.390, 911.0, 30.1828
55.060367846, 96.390, 943.0, 30.7083
55.112888977, 96.390, 882.0, 29.6985
55.165410107, 96.390, 894.0, 29.8998
55.217931238, 96.390, 931.0, 30.5123
55.270452369, 96.390, 902.0, 30.0333
55.322973499, 96.390, 943.0, 30.7083
55.375494630, 96.390, 882.0, 29.6985
55.428015761, 96.390, 985.0, 31.3847
55.480536892, 96.390, 897.0, 29.9500
55.533058022, 96.390, 939.0, 30.6431
55.585579153, 96.390, 940.0, 30.6594
55.638100284, 96.390, 948.0, 30.7896
55.690621414, 96.390, 866.0, 29.4279
55.743142545, 96.390, 911.0, 30.1828
55.795663676, 96.390, 929.0, 30.4795
55.848184807, 96.390, 923.0, 30.3809
55.900705937, 96.390, 927.0, 30.4467
55.953227068, 96.390, 902.0, 30.0333
56.005748199, 96.390, 940.0, 30.6594
56.058269329, 96.390, 978.0, 31.2730
56.110790460, 96.390, 928.0, 30.4631
56.163311591, 96.390, 953.0, 30.8707
56.215832722, 96.390, 972.0, 31.1769
56.268353852, 96.390, 987.0, 31.4166
56.320874983, 96.390, 978.0, 31.2730
56.373396114, 96.390, 956.0, 30.9192
56.425917244, 96.390, 934.0, 30.5614
56.478438375, 96.390, 907.0, 30.1164
56.530959506, 96.390, 904.0, 30.0666
56.583480637, 96.390, 909.0, 30.1496
56.636001767, 96.390, 929.0, 30.4795
56.688522898, 96.390, 910.0, 30.1662
56.741044029, 96.390, 938.0, 30.6268
56.793565159, 96.390, 932.0, 30.5287
56.846086290, 96.390, 853.0, 29.2062
56.898607421, 96.390, 947.0, 30.7734
56.951128551, 96.390, 932.0, 30.5287
57.003649682, 96.390, 891.0, 29.8496
57.056170813, 96.390, 976.0, 31.2410
57.108691944, 96.390, 902.0, 30.0333
57.161213074, 96.390, 879.0, 29.6479
57.213734205, 96.390, 918.0, 30.2985
57.266255336, 96.390, 905.0, 30.0832
57.318776466, 96.390, 952.0, 30.8545
57.371297597, 96.390, 943.0, 30.7083
57.423818728, 96.390, 912.0, 30.1993
57.476339859, 96.390, 883.0, 29.7153
57.528860989, 96.390, 933.0, 30.5450
57.581382120, 96.390, 943.0, 30.7083
57.633903251, 96.390, 942.0, 30.6920
57.686424381, 96.390, 880.0, 29.6648
57.738945512, 96.390, 979.0, 31.2890
57.791466643, 96.390, 914.0, 30.2324
57.843987774, 96.390, 884.0, 29.7321
57.896508904, 96.390, 931.0, 30.5123
57.949030035, 96.390, 900.0, 30.0000
58.001551166, 96.390, 951.0, 30.8383
58.054072296, 96.390, 946.0, 30.7571
58.106593427, 96.390, 893.0, 29.8831
58.159114558, 96.390, 972.0, 31.1769
58.211635689, 96.390, 933.0, 30.5450
58.264156819, 96.390, 936.0, 30.5941
58.316677950, 96.390, 908.0, 30.1330
58.369199081, 96.390, 865.0, 29.4109
58.421720211, 96.390, 952.0, 30.8545
58.474241342, 96.390, 933.0, 30.5450
58.526762473, 96.390, 944.0, 30.7246
58.579283603, 96.390, 921.0, 30.3480
58.631804734, 96.390, 958.0, 30.9516
58.684325865, 96.390, 934.0, 30.5614
58.736846996, 96.390, 907.0, 30.1164
58.789368126, 96.390, 912.0, 30.1993
58.841889257, 96.390, 901.0, 30.0167
58.894410388, 96.390, 942.0, 30.6920
58.946931518, 96.390, 928.0, 30.4631
58.999452649, 96.390, 953.0, 30.8707
59.051973780, 96.390, 918.0, 30.2985
59.104494911, 96.390, 931.0, 30.5123
59.157016041, 96.390, 977.0, 31.2570
59.209537172, 96.390, 926.0, 30.4302
59.262058303, 96.390, 865.0, 29.4109
59.314579433, 96.390, 906.0, 30.0998
59.367100564, 96.390, 933.0, 30.5450
59.419621695, 96.390, 956.0, 30.9192
59.472142826, 96.390, 888.0, 29.7993
59.524663956, 96.390, 959.0, 30.9677
59.577185087, 96.390, 911.0, 30.1828
59.629706218, 96.390, 926.0, 30.4302
59.682227348, 96.390, 921.0, 30.3480
59.734748479, 96.390, 908.0, 30.1330
59.787269610, 96.390, 896.0, 29.9333
59.839790740, 96.390, 930.0, 30.4959
59.892311871, 96.390, 927.0, 30.4467
59.944833002, 96.390, 927.0, 30.4467
59.997354133, 96.390, 945.0, 30.7409
60.049875263, 96.390, 969.0, 31.1288
60.102396394, 96.390, 960.0, 30.9839
60.154917525, 96.390, 961.0, 31.0000
60.207438655, 96.390, 964.0, 31.0483
60.259959786, 96.390, 1016.0, 31.8748
60.312480917, 96.390, 952.0, 30.8545
60.365002048, 96.390, 947.0, 30.7734
60.417523178, 96.390, 984.0, 31.3688
60.470044309, 96.390, 978.0, 31.2730
60.522565440, 96.390, 1017.0, 31.8904
60.575086570, 96.390, 974.0, 31.2090
60.627607701, 96.390, 1001.0, 31.6386
60.680128832, 96.390, 992.0, 31.4960
60.732649963, 96.390, 993.0, 31.5119
60.785171093, 96.390, 1029.0, 32.0780
60.837692224, 96.390, 1043.0, 32.2955
60.890213355, 96.390, 1049.0, 32.3883
60.942734485, 96.390, 1069.0, 32.6956
60.995255616, 96.390, 1051.0, 32.4191
61.047776747, 96.390, 1010.0, 31.7805
61.100297878, 96.390, 1117.0, 33.4215
61.152819008, 96.390, 1068.0, 32.6803
61.205340139, 96.390, 1102.0, 33.1964
61.257861270, 96.390, 1136.0, 33.7046
61.310382400, 96.390, 1033.0, 32.1403
61.362903531, 96.390, 1088.0, 32.9848
61.415424662, 96.390, 1070.0, 32.7109
61.467945792, 96.390, 1116.0, 33.4066
61.520466923, 96.390, 1050.0, 32.4037
61.572988054, 96.390, 1134.0, 33.6749
61.625509185, 96.390, 1052.0, 32.4345
61.678030315, 96.390, 1149.0, 33.8969
61.730551446, 96.390, 1131.0, 33.6303
61.783072577, 96.390, 1056.0, 32.4962
61.835593707, 96.390, 1116.0, 33.4066
61.888114838, 96.390, 1054.0, 32.4654
61.940635969, 96.390, 1044.0, 32.3110
61.993157100, 96.390, 1100.0, 33.1662
62.045678230, 96.390, 1092.0, 33.0454
62.098199361, 96.390, 1121.0, 33.4813
62.150720492, 96.390, 1092.0, 33.0454
62.203241622, 96.390, 1042.0, 32.2800
62.255762753, 96.390, 1038.0, 32.2180
62.308283884, 96.390, 1017.0, 31.8904
62.360805015, 96.390, 1049.0, 32.3883
62.413326145, 96.390, 1070.0, 32.7109
62.465847276, 96.390, 1005.0, 31.7017
62.518368407, 96.390, 1101.0, 33.1813
62.570889537, 96.390, 1062.0, 32.5883
62.623410668, 96.390, 1047.0, 32.3574
62.675931799, 96.390, 996.0, 31.5595
62.728452930, 96.390, 970.0, 31.1448
62.780974060, 96.390, 999.0, 31.6070
62.833495191, 96.390, 1022.0, 31.9687
62.886016322, 96.390, 935.0, 30.5778
62.938537452, 96.390, 1052.0, 32.4345
62.991058583, 96.390, 993.0, 31.5119
63.043579714, 96.390, 1036.0, 32.1870
63.096100844, 96.390, 974.0, 31.2090
63.148621975, 96.390, 952.0, 30.8545
63.201143106, 96.390, 969.0, 31.1288
63.253664237, 96.390, 974.0, 31.2090
63.306185367, 96.390, 949.0, 30.8058
63.358706498, 96.390, 942.0, 30.6920
63.411227629, 96.390, 910.0, 30.1662
63.463748759, 96.390, 973.0, 31.1929
63.516269890, 96.390, 899.0, 29.9833
63.568791021, 96.390, 924.0, 30.3974
63.621312152, 96.390, 935.0, 30.5778
63.673833282, 96.390, 932.0, 30.5287
63.726354413, 96.390, 944.0, 30.7246
63.778875544, 96.390, 950.0, 30.8221
63.831396674, 96.390, 951.0, 30.8383
63.883917805, 96.390, 849.0, 29.1376
63.936438936, 96.390, 902.0, 30.0333
63.988960067, 96.390, 900.0, 30.0000
64.041481197, 96.390, 984.0, 31.3688
64.094002328, 96.390, 919.0, 30.3150
64.146523459, 96.390, 919.0, 30.3150
64.199044589, 96.390, 881.0, 29.6816
64.251565720, 96.390, 910.0, 30.1662
64.304086851, 96.390, 922.0, 30.3645
64.356607981, 96.390, 891.0, 29.8496
64.409129112, 96.390, 912.0, 30.1993
64.461650243, 96.390, 899.0, 29.9833
64.514171374, 96.390, 880.0, 29.6648
64.566692504, 96.390, 873.0, 29.5466
64.619213635, 96.390, 820.0, 28.6356
64.671734766, 96.390, 888.0, 29.7993
64.724255896, 96.390, 872.0, 29.5296
64.776777027, 96.390, 889.0, 29.8161
64.829298158, 96.390, 879.0, 29.6479
64.881819289, 96.390, 897.0, 29.9500
64.934340419, 96.390, 858.0, 29.2916
64.986861550, 96.390, 829.0, 28.7924