File: Files_organized_for_plots/Na_to_Al_1/XRD_AlCorner27Oct21_Act08Jan22_B1_0833M_NaOH_LS0143_1.csv
[Measurement conditions]
Sample identification,XRD_AlCorner27Oct21_Act08Jan22_B1_0833M_NaOH_LS0143_1
Comment - 1,"Configuration=Stage for Flat Samples/Holders, Owner=User-1, Creation date=7/1/2020 9:53:24 AM"
Comment - 2,"Goniometer=Theta/Theta; Minimum step size 2Theta:0.0001; Minimum step size Omega:0.0001"
Comment - 3,"Sample stage=Stage for flat samples/holders"
Comment - 4,"Diffractometer system=EMPYREAN"
Comment - 5,"Measurement program=C:\Users\ibo5034\OneDrive - The Pennsylvania State University\NEUP - Reed, Titus's files\XRD\Cement\Zerobackground scan.xrdmp, Identifier={98A3B11C-88F9-4AA6-982C-73314A311EF5}"
Anode material,Cu
K-Alpha1 wavelength,1.5405980
K-Alpha2 wavelength,1.5444260
Ratio K-Alpha2/K-Alpha1,0.500
Divergence slit,Fixed,0.25
Monochromator used,NO
Generator voltage, 45
Tube current, 40
File date and time,11/Jan/2022 12:49
Unit cell,
h k l, 0 0 0
Scan axis,Gonio
Scan range,4.994599997,64.999991833
Scan step size,0.0262606
No. of points, 2285
Scan type,CONTINUOUS
Time per step,96.390
[Scan points]
Angle, TimePerStep, Intensity, ESD
5.007730280, 96.390, 4048.0, 63.6239
5.060251411, 96.390, 3885.0, 62.3298
5.112772541, 96.390, 3971.0, 63.0159
5.165293672, 96.390, 3887.0, 62.3458
5.217814803, 96.390, 3945.0, 62.8092
5.270335934, 96.390, 3706.0, 60.8769
5.322857064, 96.390, 3660.0, 60.4979
5.375378195, 96.390, 3662.0, 60.5145
5.427899326, 96.390, 3720.0, 60.9918
5.480420456, 96.390, 3576.0, 59.7997
5.532941587, 96.390, 3637.0, 60.3075
5.585462718, 96.390, 3578.0, 59.8164
5.637983849, 96.390, 3572.0, 59.7662
5.690504979, 96.390, 3516.0, 59.2959
5.743026110, 96.390, 3452.0, 58.7537
5.795547241, 96.390, 3347.0, 57.8533
5.848068371, 96.390, 3362.0, 57.9828
5.900589502, 96.390, 3355.0, 57.9224
5.953110633, 96.390, 3361.0, 57.9741
6.005631763, 96.390, 3454.0, 58.7707
6.058152894, 96.390, 3408.0, 58.3781
6.110674025, 96.390, 3420.0, 58.4808
6.163195156, 96.390, 3318.0, 57.6021
6.215716286, 96.390, 3338.0, 57.7754
6.268237417, 96.390, 3428.0, 58.5491
6.320758548, 96.390, 3373.0, 58.0775
6.373279678, 96.390, 3292.0, 57.3760
6.425800809, 96.390, 3381.0, 58.1464
6.478321940, 96.390, 3555.0, 59.6238
6.530843071, 96.390, 3366.0, 58.0172
6.583364201, 96.390, 3366.0, 58.0172
6.635885332, 96.390, 3452.0, 58.7537
6.688406463, 96.390, 3510.0, 59.2453
6.740927593, 96.390, 3478.0, 58.9746
6.793448724, 96.390, 3687.0, 60.7207
6.845969855, 96.390, 3859.0, 62.1208
6.898490986, 96.390, 4003.0, 63.2693
6.951012116, 96.390, 4285.0, 65.4599
7.003533247, 96.390, 4755.0, 68.9565
7.056054378, 96.390, 5399.0, 73.4779
7.108575508, 96.390, 6315.0, 79.4670
7.161096639, 96.390, 7731.0, 87.9261
7.213617770, 96.390, 10160.0, 100.7968
7.266138900, 96.390, 7947.0, 89.1459
7.318660031, 96.390, 4464.0, 66.8132
7.371181162, 96.390, 3707.0, 60.8851
7.423702293, 96.390, 3379.0, 58.1292
7.476223423, 96.390, 3244.0, 56.9561
7.528744554, 96.390, 3128.0, 55.9285
7.581265685, 96.390, 3046.0, 55.1906
7.633786815, 96.390, 3050.0, 55.2268
7.686307946, 96.390, 3163.0, 56.2406
7.738829077, 96.390, 2930.0, 54.1295
7.791350208, 96.390, 2982.0, 54.6077
7.843871338, 96.390, 2878.0, 53.6470
7.896392469, 96.390, 2839.0, 53.2823
7.948913600, 96.390, 2896.0, 53.8145
8.001434730, 96.390, 2841.0, 53.3010
8.053955861, 96.390, 2806.0, 52.9717
8.106476992, 96.390, 2671.0, 51.6817
8.158998123, 96.390, 2803.0, 52.9434
8.211519253, 96.390, 2796.0, 52.8772
8.264040384, 96.390, 2854.0, 53.4228
8.316561515, 96.390, 2785.0, 52.7731
8.369082645, 96.390, 2763.0, 52.5642
8.421603776, 96.390, 2889.0, 53.7494
8.474124907, 96.390, 2828.0, 53.1789
8.526646038, 96.390, 2937.0, 54.1941
8.579167168, 96.390, 3344.0, 57.8273
8.631688299, 96.390, 3625.0, 60.2080
8.684209430, 96.390, 3007.0, 54.8361
8.736730560, 96.390, 2789.0, 52.8110
8.789251691, 96.390, 2645.0, 51.4296
8.841772822, 96.390, 2669.0, 51.6624
8.894293952, 96.390, 2684.0, 51.8073
8.946815083, 96.390, 2601.0, 51.0000
8.999336214, 96.390, 2635.0, 51.3323
9.051857345, 96.390, 2697.0, 51.9326
9.104378475, 96.390, 2619.0, 51.1762
9.156899606, 96.390, 2698.0, 51.9423
9.209420737, 96.390, 2684.0, 51.8073
9.261941867, 96.390, 2740.0, 52.3450
9.314462998, 96.390, 2607.0, 51.0588
9.366984129, 96.390, 2694.0, 51.9038
9.419505260, 96.390, 2619.0, 51.1762
9.472026390, 96.390, 2636.0, 51.3420
9.524547521, 96.390, 2660.0, 51.5752
9.577068652, 96.390, 2653.0, 51.5073
9.629589782, 96.390, 2690.0, 51.8652
9.682110913, 96.390, 2870.0, 53.5724
9.734632044, 96.390, 2974.0, 54.5344
9.787153175, 96.390, 3004.0, 54.8088
9.839674305, 96.390, 3134.0, 55.9821
9.892195436, 96.390, 3263.0, 57.1227
9.944716567, 96.390, 3429.0, 58.5577
9.997237697, 96.390, 3696.0, 60.7947
10.049758828, 96.390, 4243.0, 65.1383
10.102279959, 96.390, 4849.0, 69.6348
10.154801090, 96.390, 5986.0, 77.3692
10.207322220, 96.390, 7342.0, 85.6855
10.259843351, 96.390, 5821.0, 76.2955
10.312364482, 96.390, 3906.0, 62.4980
10.364885612, 96.390, 3485.0, 59.0339
10.417406743, 96.390, 3434.0, 58.6003
10.469927874, 96.390, 3329.0, 57.6975
10.522449004, 96.390, 3184.0, 56.4269
10.574970135, 96.390, 3163.0, 56.2406
10.627491266, 96.390, 3230.0, 56.8331
10.680012397, 96.390, 3223.0, 56.7715
10.732533527, 96.390, 3334.0, 57.7408
10.785054658, 96.390, 3283.0, 57.2975
10.837575789, 96.390, 3437.0, 58.6259
10.890096919, 96.390, 3354.0, 57.9137
10.942618050, 96.390, 3343.0, 57.8187
10.995139181, 96.390, 3433.0, 58.5918
11.047660312, 96.390, 3425.0, 58.5235
11.100181442, 96.390, 3370.0, 58.0517
11.152702573, 96.390, 3493.0, 59.1016
11.205223704, 96.390, 3333.0, 57.7321
11.257744834, 96.390, 3426.0, 58.5320
11.310265965, 96.390, 3358.0, 57.9483
11.362787096, 96.390, 3433.0, 58.5918
11.415308227, 96.390, 3540.0, 59.4979
11.467829357, 96.390, 3420.0, 58.4808
11.520350488, 96.390, 3508.0, 59.2284
11.572871619, 96.390, 3321.0, 57.6281
11.625392749, 96.390, 3466.0, 58.8727
11.677913880, 96.390, 3424.0, 58.5150
11.730435011, 96.390, 3412.0, 58.4123
11.782956141, 96.390, 3368.0, 58.0345
11.835477272, 96.390, 3339.0, 57.7841
11.887998403, 96.390, 3308.0, 57.5152
11.940519534, 96.390, 3250.0, 57.0088
11.993040664, 96.390, 3332.0, 57.7235
12.045561795, 96.390, 3189.0, 56.4712
12.098082926, 96.390, 3184.0, 56.4269
12.150604056, 96.390, 3157.0, 56.1872
12.203125187, 96.390, 3310.0, 57.5326
12.255646318, 96.390, 3380.0, 58.1378
12.308167449, 96.390, 3728.0, 61.0574
12.360688579, 96.390, 3721.0, 61.0000
12.413209710, 96.390, 4320.0, 65.7267
12.465730841, 96.390, 5290.0, 72.7324
12.518251971, 96.390, 6048.0, 77.7689
12.570773102, 96.390, 4223.0, 64.9846
12.623294233, 96.390, 3153.0, 56.1516
12.675815364, 96.390, 2941.0, 54.2310
12.728336494, 96.390, 2760.0, 52.5357
12.780857625, 96.390, 2593.0, 50.9215
12.833378756, 96.390, 2633.0, 51.3128
12.885899886, 96.390, 2562.0, 50.6162
12.938421017, 96.390, 2477.0, 49.7695
12.990942148, 96.390, 2423.0, 49.2240
13.043463279, 96.390, 2463.0, 49.6286
13.095984409, 96.390, 2310.0, 48.0625
13.148505540, 96.390, 2280.0, 47.7493
13.201026671, 96.390, 2256.0, 47.4974
13.253547801, 96.390, 2245.0, 47.3814
13.306068932, 96.390, 2241.0, 47.3392
13.358590063, 96.390, 2259.0, 47.5289
13.411111193, 96.390, 2319.0, 48.1560
13.463632324, 96.390, 2617.0, 51.1566
13.516153455, 96.390, 2853.0, 53.4135
13.568674586, 96.390, 2526.0, 50.2593
13.621195716, 96.390, 2168.0, 46.5618
13.673716847, 96.390, 2086.0, 45.6727
13.726237978, 96.390, 2071.0, 45.5082
13.778759108, 96.390, 2147.0, 46.3357
13.831280239, 96.390, 2143.0, 46.2925
13.883801370, 96.390, 2205.0, 46.9574
13.936322501, 96.390, 2344.0, 48.4149
13.988843631, 96.390, 2171.0, 46.5940
14.041364762, 96.390, 1935.0, 43.9886
14.093885893, 96.390, 2003.0, 44.7549
14.146407023, 96.390, 2027.0, 45.0222
14.198928154, 96.390, 2206.0, 46.9681
14.251449285, 96.390, 2461.0, 49.6085
14.303970416, 96.390, 2850.0, 53.3854
14.356491546, 96.390, 2214.0, 47.0532
14.409012677, 96.390, 1880.0, 43.3590
14.461533808, 96.390, 1813.0, 42.5793
14.514054938, 96.390, 1816.0, 42.6146
14.566576069, 96.390, 1837.0, 42.8602
14.619097200, 96.390, 1775.0, 42.1307
14.671618331, 96.390, 1748.0, 41.8091
14.724139461, 96.390, 1783.0, 42.2256
14.776660592, 96.390, 1804.0, 42.4735
14.829181723, 96.390, 1771.0, 42.0833
14.881702853, 96.390, 1907.0, 43.6692
14.934223984, 96.390, 1962.0, 44.2945
14.986745115, 96.390, 1929.0, 43.9204
15.039266245, 96.390, 1747.0, 41.7971
15.091787376, 96.390, 1764.0, 42.0000
15.144308507, 96.390, 1832.0, 42.8019
15.196829638, 96.390, 2055.0, 45.3321
15.249350768, 96.390, 2411.0, 49.1019
15.301871899, 96.390, 2940.0, 54.2218
15.354393030, 96.390, 2336.0, 48.3322
15.406914160, 96.390, 1790.0, 42.3084
15.459435291, 96.390, 1762.0, 41.9762
15.511956422, 96.390, 1792.0, 42.3320
15.564477553, 96.390, 1615.0, 40.1871
15.616998683, 96.390, 1647.0, 40.5832
15.669519814, 96.390, 1706.0, 41.3038
15.722040945, 96.390, 1672.0, 40.8901
15.774562075, 96.390, 1675.0, 40.9268
15.827083206, 96.390, 1701.0, 41.2432
15.879604337, 96.390, 1754.0, 41.8808
15.932125468, 96.390, 1883.0, 43.3935
15.984646598, 96.390, 2078.0, 45.5851
16.037167729, 96.390, 2322.0, 48.1871
16.089688860, 96.390, 2962.0, 54.4243
16.142209990, 96.390, 3605.0, 60.0417
16.194731121, 96.390, 3399.0, 58.3009
16.247252252, 96.390, 2452.0, 49.5177
16.299773382, 96.390, 2085.0, 45.6618
16.352294513, 96.390, 1810.0, 42.5441
16.404815644, 96.390, 2093.0, 45.7493
16.457336775, 96.390, 1957.0, 44.2380
16.509857905, 96.390, 1814.0, 42.5911
16.562379036, 96.390, 1773.0, 42.1070
16.614900167, 96.390, 1642.0, 40.5216
16.667421297, 96.390, 1649.0, 40.6079
16.719942428, 96.390, 1623.0, 40.2865
16.772463559, 96.390, 1620.0, 40.2492
16.824984690, 96.390, 1578.0, 39.7240
16.877505820, 96.390, 1535.0, 39.1791
16.930026951, 96.390, 1505.0, 38.7943
16.982548082, 96.390, 1553.0, 39.4081
17.035069212, 96.390, 1443.0, 37.9868
17.087590343, 96.390, 1484.0, 38.5227
17.140111474, 96.390, 1507.0, 38.8201
17.192632605, 96.390, 1512.0, 38.8844
17.245153735, 96.390, 1483.0, 38.5097
17.297674866, 96.390, 1519.0, 38.9744
17.350195997, 96.390, 1536.0, 39.1918
17.402717127, 96.390, 1494.0, 38.6523
17.455238258, 96.390, 1513.0, 38.8973
17.507759389, 96.390, 1522.0, 39.0128
17.560280520, 96.390, 1532.0, 39.1408
17.612801650, 96.390, 1557.0, 39.4588
17.665322781, 96.390, 1638.0, 40.4722
17.717843912, 96.390, 1744.0, 41.7612
17.770365042, 96.390, 1710.0, 41.3521
17.822886173, 96.390, 1534.0, 39.1663
17.875407304, 96.390, 1645.0, 40.5586
17.927928434, 96.390, 1634.0, 40.4228
17.980449565, 96.390, 1595.0, 39.9375
18.032970696, 96.390, 1829.0, 42.7668
18.085491827, 96.390, 1902.0, 43.6119
18.138012957, 96.390, 2087.0, 45.6837
18.190534088, 96.390, 2416.0, 49.1528
18.243055219, 96.390, 2742.0, 52.3641
18.295576349, 96.390, 3533.0, 59.4390
18.348097480, 96.390, 4407.0, 66.3852
18.400618611, 96.390, 5475.0, 73.9932
18.453139742, 96.390, 6479.0, 80.4922
18.505660872, 96.390, 6978.0, 83.5344
18.558182003, 96.390, 6910.0, 83.1264
18.610703134, 96.390, 6840.0, 82.7043
18.663224264, 96.390, 6633.0, 81.4432
18.715745395, 96.390, 6656.0, 81.5843
18.768266526, 96.390, 7175.0, 84.7054
18.820787657, 96.390, 6490.0, 80.5605
18.873308787, 96.390, 4400.0, 66.3325
18.925829918, 96.390, 2883.0, 53.6936
18.978351049, 96.390, 2299.0, 47.9479
19.030872179, 96.390, 1916.0, 43.7721
19.083393310, 96.390, 1770.0, 42.0714
19.135914441, 96.390, 1755.0, 41.8927
19.188435572, 96.390, 1754.0, 41.8808
19.240956702, 96.390, 1639.0, 40.4846
19.293477833, 96.390, 1687.0, 41.0731
19.345998964, 96.390, 1795.0, 42.3674
19.398520094, 96.390, 1978.0, 44.4747
19.451041225, 96.390, 2269.0, 47.6340
19.503562356, 96.390, 1952.0, 44.1814
19.556083486, 96.390, 1637.0, 40.4599
19.608604617, 96.390, 1661.0, 40.7554
19.661125748, 96.390, 1795.0, 42.3674
19.713646879, 96.390, 1862.0, 43.1509
19.766168009, 96.390, 1891.0, 43.4856
19.818689140, 96.390, 1839.0, 42.8836
19.871210271, 96.390, 2125.0, 46.0977
19.923731401, 96.390, 2848.0, 53.3667
19.976252532, 96.390, 4033.0, 63.5059
20.028773663, 96.390, 3942.0, 62.7853
20.081294794, 96.390, 2986.0, 54.6443
20.133815924, 96.390, 2880.0, 53.6656
20.186337055, 96.390, 3744.0, 61.1882
20.238858186, 96.390, 5289.0, 72.7255
20.291379316, 96.390, 7490.0, 86.5448
20.343900447, 96.390, 8872.0, 94.1913
20.396421578, 96.390, 7684.0, 87.6584
20.448942709, 96.390, 7027.0, 83.8272
20.501463839, 96.390, 6435.0, 80.2185
20.553984970, 96.390, 5082.0, 71.2881
20.606506101, 96.390, 4482.0, 66.9477
20.659027231, 96.390, 5511.0, 74.2361
20.711548362, 96.390, 8232.0, 90.7304
20.764069493, 96.390, 8251.0, 90.8350
20.816590623, 96.390, 4661.0, 68.2715
20.869111754, 96.390, 2612.0, 51.1077
20.921632885, 96.390, 2117.0, 46.0109
20.974154016, 96.390, 1967.0, 44.3509
21.026675146, 96.390, 1907.0, 43.6692
21.079196277, 96.390, 1754.0, 41.8808
21.131717408, 96.390, 1712.0, 41.3763
21.184238538, 96.390, 1609.0, 40.1123
21.236759669, 96.390, 1707.0, 41.3159
21.289280800, 96.390, 1732.0, 41.6173
21.341801931, 96.390, 1803.0, 42.4617
21.394323061, 96.390, 1914.0, 43.7493
21.446844192, 96.390, 1881.0, 43.3705
21.499365323, 96.390, 1998.0, 44.6990
21.551886453, 96.390, 2121.0, 46.0543
21.604407584, 96.390, 2435.0, 49.3457
21.656928715, 96.390, 3146.0, 56.0892
21.709449846, 96.390, 4156.0, 64.4670
21.761970976, 96.390, 4197.0, 64.7843
21.814492107, 96.390, 2847.0, 53.3573
21.867013238, 96.390, 1999.0, 44.7102
21.919534368, 96.390, 1834.0, 42.8252
21.972055499, 96.390, 1686.0, 41.0609
22.024576630, 96.390, 1692.0, 41.1339
22.077097761, 96.390, 1594.0, 39.9249
22.129618891, 96.390, 1605.0, 40.0625
22.182140022, 96.390, 1687.0, 41.0731
22.234661153, 96.390, 1944.0, 44.0908
22.287182283, 96.390, 1879.0, 43.3474
22.339703414, 96.390, 1798.0, 42.4028
22.392224545, 96.390, 1679.0, 40.9756
22.444745675, 96.390, 1612.0, 40.1497
22.497266806, 96.390, 1654.0, 40.6694
22.549787937, 96.390, 1575.0, 39.6863
22.602309068, 96.390, 1700.0, 41.2311
22.654830198, 96.390, 1687.0, 41.0731
22.707351329, 96.390, 1683.0, 41.0244
22.759872460, 96.390, 1733.0, 41.6293
22.812393590, 96.390, 1907.0, 43.6692
22.864914721, 96.390, 2041.0, 45.1774
22.917435852, 96.390, 2145.0, 46.3141
22.969956983, 96.390, 2052.0, 45.2990
23.022478113, 96.390, 1960.0, 44.2719
23.074999244, 96.390, 1946.0, 44.1135
23.127520375, 96.390, 1905.0, 43.6463
23.180041505, 96.390, 1841.0, 42.9069
23.232562636, 96.390, 2006.0, 44.7884
23.285083767, 96.390, 1944.0, 44.0908
23.337604898, 96.390, 2028.0, 45.0333
23.390126028, 96.390, 2060.0, 45.3872
23.442647159, 96.390, 1977.0, 44.4635
23.495168290, 96.390, 2072.0, 45.5192
23.547689420, 96.390, 2072.0, 45.5192
23.600210551, 96.390, 2147.0, 46.3357
23.652731682, 96.390, 2164.0, 46.5188
23.705252813, 96.390, 2252.0, 47.4552
23.757773943, 96.390, 2363.0, 48.6107
23.810295074, 96.390, 2479.0, 49.7896
23.862816205, 96.390, 2776.0, 52.6878
23.915337335, 96.390, 3315.0, 57.5760
23.967858466, 96.390, 4246.0, 65.1613
24.020379597, 96.390, 5803.0, 76.1774
24.072900727, 96.390, 6439.0, 80.2434
24.125421858, 96.390, 4784.0, 69.1665
24.177942989, 96.390, 3584.0, 59.8665
24.230464120, 96.390, 2949.0, 54.3047
24.282985250, 96.390, 2337.0, 48.3425
24.335506381, 96.390, 2055.0, 45.3321
24.388027512, 96.390, 1803.0, 42.4617
24.440548642, 96.390, 1736.0, 41.6653
24.493069773, 96.390, 1679.0, 40.9756
24.545590904, 96.390, 1674.0, 40.9145
24.598112035, 96.390, 1580.0, 39.7492
24.650633165, 96.390, 1467.0, 38.3014
24.703154296, 96.390, 1509.0, 38.8458
24.755675427, 96.390, 1457.0, 38.1707
24.808196557, 96.390, 1434.0, 37.8682
24.860717688, 96.390, 1326.0, 36.4143
24.913238819, 96.390, 1425.0, 37.7492
24.965759950, 96.390, 1357.0, 36.8375
25.018281080, 96.390, 1337.0, 36.5650
25.070802211, 96.390, 1364.0, 36.9324
25.123323342, 96.390, 1337.0, 36.5650
25.175844472, 96.390, 1422.0, 37.7094
25.228365603, 96.390, 1369.0, 37.0000
25.280886734, 96.390, 1419.0, 37.6696
25.333407864, 96.390, 1442.0, 37.9737
25.385928995, 96.390, 1772.0, 42.0951
25.438450126, 96.390, 2295.0, 47.9062
25.490971257, 96.390, 2514.0, 50.1398
25.543492387, 96.390, 1966.0, 44.3396
25.596013518, 96.390, 1493.0, 38.6394
25.648534649, 96.390, 1410.0, 37.5500
25.701055779, 96.390, 1279.0, 35.7631
25.753576910, 96.390, 1335.0, 36.5377
25.806098041, 96.390, 1264.0, 35.5528
25.858619172, 96.390, 1355.0, 36.8103
25.911140302, 96.390, 1403.0, 37.4566
25.963661433, 96.390, 1556.0, 39.4462
26.016182564, 96.390, 1779.0, 42.1782
26.068703694, 96.390, 1976.0, 44.4522
26.121224825, 96.390, 2258.0, 47.5184
26.173745956, 96.390, 2616.0, 51.1468
26.226267087, 96.390, 2372.0, 48.7032
26.278788217, 96.390, 1975.0, 44.4410
26.331309348, 96.390, 1622.0, 40.2741
26.383830479, 96.390, 1511.0, 38.8716
26.436351609, 96.390, 1370.0, 37.0135
26.488872740, 96.390, 1487.0, 38.5616
26.541393871, 96.390, 1546.0, 39.3192
26.593915002, 96.390, 1528.0, 39.0896
26.646436132, 96.390, 1523.0, 39.0256
26.698957263, 96.390, 1538.0, 39.2173
26.751478394, 96.390, 1622.0, 40.2741
26.803999524, 96.390, 1714.0, 41.4005
26.856520655, 96.390, 1964.0, 44.3170
26.909041786, 96.390, 2163.0, 46.5081
26.961562916, 96.390, 2306.0, 48.0208
27.014084047, 96.390, 2631.0, 51.2933
27.066605178, 96.390, 3033.0, 55.0727
27.119126309, 96.390, 4493.0, 67.0298
27.171647439, 96.390, 6516.0, 80.7217
27.224168570, 96.390, 6725.0, 82.0061
27.276689701, 96.390, 4721.0, 68.7095
27.329210831, 96.390, 2883.0, 53.6936
27.381731962, 96.390, 2292.0, 47.8748
27.434253093, 96.390, 2004.0, 44.7661
27.486774224, 96.390, 1904.0, 43.6348
27.539295354, 96.390, 1969.0, 44.3734
27.591816485, 96.390, 2172.0, 46.6047
27.644337616, 96.390, 2066.0, 45.4533
27.696858746, 96.390, 2306.0, 48.0208
27.749379877, 96.390, 2447.0, 49.4672
27.801901008, 96.390, 2488.0, 49.8799
27.854422139, 96.390, 2700.0, 51.9615
27.906943269, 96.390, 2466.0, 49.6588
27.959464400, 96.390, 2149.0, 46.3573
28.011985531, 96.390, 2013.0, 44.8665
28.064506661, 96.390, 1882.0, 43.3820
28.117027792, 96.390, 1851.0, 43.0232
28.169548923, 96.390, 1716.0, 41.4246
28.222070054, 96.390, 1532.0, 39.1408
28.274591184, 96.390, 1427.0, 37.7757
28.327112315, 96.390, 1489.0, 38.5876
28.379633446, 96.390, 1386.0, 37.2290
28.432154576, 96.390, 1490.0, 38.6005
28.484675707, 96.390, 1349.0, 36.7287
28.537196838, 96.390, 1352.0, 36.7696
28.589717968, 96.390, 1327.0, 36.4280
28.642239099, 96.390, 1357.0, 36.8375
28.694760230, 96.390, 1500.0, 38.7298
28.747281361, 96.390, 1712.0, 41.3763
28.799802491, 96.390, 1805.0, 42.4853
28.852323622, 96.390, 1681.0, 41.0000
28.904844753, 96.390, 1441.0, 37.9605
28.957365883, 96.390, 1436.0, 37.8946
29.009887014, 96.390, 1539.0, 39.2301
29.062408145, 96.390, 1766.0, 42.0238
29.114929276, 96.390, 2066.0, 45.4533
29.167450406, 96.390, 2004.0, 44.7661
29.219971537, 96.390, 1680.0, 40.9878
29.272492668, 96.390, 1492.0, 38.6264
29.325013798, 96.390, 1436.0, 37.8946
29.377534929, 96.390, 1484.0, 38.5227
29.430056060, 96.390, 1559.0, 39.4842
29.482577191, 96.390, 1545.0, 39.3065
29.535098321, 96.390, 1571.0, 39.6358
29.587619452, 96.390, 1613.0, 40.1622
29.640140583, 96.390, 1593.0, 39.9124
29.692661713, 96.390, 1659.0, 40.7308
29.745182844, 96.390, 1790.0, 42.3084
29.797703975, 96.390, 1955.0, 44.2154
29.850225105, 96.390, 2414.0, 49.1325
29.902746236, 96.390, 3156.0, 56.1783
29.955267367, 96.390, 4622.0, 67.9853
30.007788498, 96.390, 5865.0, 76.5833
30.060309628, 96.390, 5447.0, 73.8038
30.112830759, 96.390, 4121.0, 64.1950
30.165351890, 96.390, 2753.0, 52.4690
30.217873020, 96.390, 2159.0, 46.4650
30.270394151, 96.390, 1769.0, 42.0595
30.322915282, 96.390, 1625.0, 40.3113
30.375436413, 96.390, 1483.0, 38.5097
30.427957543, 96.390, 1457.0, 38.1707
30.480478674, 96.390, 1430.0, 37.8153
30.532999805, 96.390, 1425.0, 37.7492
30.585520935, 96.390, 1543.0, 39.2810
30.638042066, 96.390, 1693.0, 41.1461
30.690563197, 96.390, 1952.0, 44.1814
30.743084328, 96.390, 1801.0, 42.4382
30.795605458, 96.390, 1996.0, 44.6766
30.848126589, 96.390, 2189.0, 46.7868
30.900647720, 96.390, 2459.0, 49.5883
30.953168850, 96.390, 2367.0, 48.6518
31.005689981, 96.390, 1968.0, 44.3621
31.058211112, 96.390, 1687.0, 41.0731
31.110732243, 96.390, 1743.0, 41.7493
31.163253373, 96.390, 2127.0, 46.1194
31.215774504, 96.390, 2811.0, 53.0189
31.268295635, 96.390, 2898.0, 53.8331
31.320816765, 96.390, 2362.0, 48.6004
31.373337896, 96.390, 1934.0, 43.9773
31.425859027, 96.390, 1853.0, 43.0465
31.478380157, 96.390, 1766.0, 42.0238
31.530901288, 96.390, 1898.0, 43.5660
31.583422419, 96.390, 1859.0, 43.1161
31.635943550, 96.390, 1810.0, 42.5441
31.688464680, 96.390, 1809.0, 42.5323
31.740985811, 96.390, 1541.0, 39.2556
31.793506942, 96.390, 1484.0, 38.5227
31.846028072, 96.390, 1490.0, 38.6005
31.898549203, 96.390, 1750.0, 41.8330
31.951070334, 96.390, 2264.0, 47.5815
32.003591465, 96.390, 3646.0, 60.3821
32.056112595, 96.390, 6047.0, 77.7625
32.108633726, 96.390, 6772.0, 82.2922
32.161154857, 96.390, 4853.0, 69.6635
32.213675987, 96.390, 3269.0, 57.1752
32.266197118, 96.390, 2104.0, 45.8694
32.318718249, 96.390, 1759.0, 41.9404
32.371239380, 96.390, 1659.0, 40.7308
32.423760510, 96.390, 1616.0, 40.1995
32.476281641, 96.390, 1607.0, 40.0874
32.528802772, 96.390, 1847.0, 42.9767
32.581323902, 96.390, 2146.0, 46.3249
32.633845033, 96.390, 2169.0, 46.5725
32.686366164, 96.390, 1960.0, 44.2719
32.738887295, 96.390, 1676.0, 40.9390
32.791408425, 96.390, 1480.0, 38.4708
32.843929556, 96.390, 1403.0, 37.4566
32.896450687, 96.390, 1399.0, 37.4032
32.948971817, 96.390, 1425.0, 37.7492
33.001492948, 96.390, 1416.0, 37.6298
33.054014079, 96.390, 1453.0, 38.1182
33.106535209, 96.390, 1499.0, 38.7169
33.159056340, 96.390, 1730.0, 41.5933
33.211577471, 96.390, 1662.0, 40.7676
33.264098602, 96.390, 1582.0, 39.7744
33.316619732, 96.390, 1737.0, 41.6773
33.369140863, 96.390, 1823.0, 42.6966
33.421661994, 96.390, 1828.0, 42.7551
33.474183124, 96.390, 1798.0, 42.4028
33.526704255, 96.390, 1868.0, 43.2204
33.579225386, 96.390, 1742.0, 41.7373
33.631746517, 96.390, 1700.0, 41.2311
33.684267647, 96.390, 1778.0, 42.1663
33.736788778, 96.390, 1797.0, 42.3910
33.789309909, 96.390, 1984.0, 44.5421
33.841831039, 96.390, 2282.0, 47.7703
33.894352170, 96.390, 2613.0, 51.1175
33.946873301, 96.390, 3602.0, 60.0167
33.999394432, 96.390, 4154.0, 64.4515
34.051915562, 96.390, 3742.0, 61.1719
34.104436693, 96.390, 3516.0, 59.2959
34.156957824, 96.390, 3523.0, 59.3549
34.209478954, 96.390, 4292.0, 65.5134
34.262000085, 96.390, 5029.0, 70.9154
34.314521216, 96.390, 4498.0, 67.0671
34.367042346, 96.390, 3823.0, 61.8304
34.419563477, 96.390, 3402.0, 58.3267
34.472084608, 96.390, 3270.0, 57.1839
34.524605739, 96.390, 3214.0, 56.6922
34.577126869, 96.390, 2927.0, 54.1018
34.629648000, 96.390, 2707.0, 52.0288
34.682169131, 96.390, 2475.0, 49.7494
34.734690261, 96.390, 2566.0, 50.6557
34.787211392, 96.390, 2614.0, 51.1273
34.839732523, 96.390, 2689.0, 51.8556
34.892253654, 96.390, 3433.0, 58.5918
34.944774784, 96.390, 3854.0, 62.0806
34.997295915, 96.390, 3496.0, 59.1270
35.049817046, 96.390, 2942.0, 54.2402
35.102338176, 96.390, 2408.0, 49.0714
35.154859307, 96.390, 1995.0, 44.6654
35.207380438, 96.390, 1813.0, 42.5793
35.259901569, 96.390, 1840.0, 42.8952
35.312422699, 96.390, 1792.0, 42.3320
35.364943830, 96.390, 1784.0, 42.2374
35.417464961, 96.390, 1687.0, 41.0731
35.469986091, 96.390, 1608.0, 40.0999
35.522507222, 96.390, 1656.0, 40.6940
35.575028353, 96.390, 1704.0, 41.2795
35.627549484, 96.390, 1866.0, 43.1972
35.680070614, 96.390, 1826.0, 42.7317
35.732591745, 96.390, 1799.0, 42.4146
35.785112876, 96.390, 1823.0, 42.6966
35.837634006, 96.390, 1941.0, 44.0568
35.890155137, 96.390, 1968.0, 44.3621
35.942676268, 96.390, 1800.0, 42.4264
35.995197398, 96.390, 1661.0, 40.7554
36.047718529, 96.390, 1611.0, 40.1373
36.100239660, 96.390, 1616.0, 40.1995
36.152760791, 96.390, 1526.0, 39.0640
36.205281921, 96.390, 1551.0, 39.3827
36.257803052, 96.390, 1590.0, 39.8748
36.310324183, 96.390, 1594.0, 39.9249
36.362845313, 96.390, 1556.0, 39.4462
36.415366444, 96.390, 1606.0, 40.0749
36.467887575, 96.390, 1557.0, 39.4588
36.520408706, 96.390, 1721.0, 41.4849
36.572929836, 96.390, 1861.0, 43.1393
36.625450967, 96.390, 1812.0, 42.5676
36.677972098, 96.390, 1619.0, 40.2368
36.730493228, 96.390, 1496.0, 38.6782
36.783014359, 96.390, 1312.0, 36.2215
36.835535490, 96.390, 1351.0, 36.7560
36.888056621, 96.390, 1270.0, 35.6371
36.940577751, 96.390, 1301.0, 36.0694
36.993098882, 96.390, 1287.0, 35.8748
37.045620013, 96.390, 1340.0, 36.6060
37.098141143, 96.390, 1275.0, 35.7071
37.150662274, 96.390, 1309.0, 36.1801
37.203183405, 96.390, 1318.0, 36.3043
37.255704535, 96.390, 1370.0, 37.0135
37.308225666, 96.390, 1420.0, 37.6829
37.360746797, 96.390, 1443.0, 37.9868
37.413267928, 96.390, 1521.0, 39.0000
37.465789058, 96.390, 1485.0, 38.5357
37.518310189, 96.390, 1608.0, 40.0999
37.570831320, 96.390, 1621.0, 40.2616
37.623352450, 96.390, 1783.0, 42.2256
37.675873581, 96.390, 1832.0, 42.8019
37.728394712, 96.390, 2247.0, 47.4025
37.780915843, 96.390, 2309.0, 48.0521
37.833436973, 96.390, 2083.0, 45.6399
37.885958104, 96.390, 2021.0, 44.9555
37.938479235, 96.390, 1850.0, 43.0116
37.991000365, 96.390, 1875.0, 43.3013
38.043521496, 96.390, 1946.0, 44.1135
38.096042627, 96.390, 2078.0, 45.5851
38.148563758, 96.390, 2017.0, 44.9110
38.201084888, 96.390, 2026.0, 45.0111
38.253606019, 96.390, 1749.0, 41.8210
38.306127150, 96.390, 1693.0, 41.1461
38.358648280, 96.390, 1571.0, 39.6358
38.411169411, 96.390, 1570.0, 39.6232
38.463690542, 96.390, 1556.0, 39.4462
38.516211673, 96.390, 1630.0, 40.3733
38.568732803, 96.390, 1665.0, 40.8044
38.621253934, 96.390, 1742.0, 41.7373
38.673775065, 96.390, 1729.0, 41.5812
38.726296195, 96.390, 1915.0, 43.7607
38.778817326, 96.390, 2107.0, 45.9021
38.831338457, 96.390, 2045.0, 45.2217
38.883859587, 96.390, 1806.0, 42.4971
38.936380718, 96.390, 1657.0, 40.7063
38.988901849, 96.390, 1578.0, 39.7240
39.041422980, 96.390, 1510.0, 38.8587
39.093944110, 96.390, 1387.0, 37.2424
39.146465241, 96.390, 1510.0, 38.8587
39.198986372, 96.390, 1503.0, 38.7685
39.251507502, 96.390, 1575.0, 39.6863
39.304028633, 96.390, 1651.0, 40.6325
39.356549764, 96.390, 1816.0, 42.6146
39.409070895, 96.390, 2208.0, 46.9894
39.461592025, 96.390, 2513.0, 50.1298
39.514113156, 96.390, 2226.0, 47.1805
39.566634287, 96.390, 2075.0, 45.5522
39.619155417, 96.390, 1721.0, 41.4849
39.671676548, 96.390, 1615.0, 40.1871
39.724197679, 96.390, 1657.0, 40.7063
39.776718810, 96.390, 1619.0, 40.2368
39.829239940, 96.390, 1584.0, 39.7995
39.881761071, 96.390, 1696.0, 41.1825
39.934282202, 96.390, 1748.0, 41.8091
39.986803332, 96.390, 1739.0, 41.7013
40.039324463, 96.390, 1905.0, 43.6463
40.091845594, 96.390, 2014.0, 44.8776
40.144366725, 96.390, 2295.0, 47.9062
40.196887855, 96.390, 2384.0, 48.8262
40.249408986, 96.390, 2543.0, 50.4282
40.301930117, 96.390, 2767.0, 52.6023
40.354451247, 96.390, 2845.0, 53.3385
40.406972378, 96.390, 3234.0, 56.8683
40.459493509, 96.390, 3548.0, 59.5651
40.512014639, 96.390, 4017.0, 63.3798
40.564535770, 96.390, 4323.0, 65.7495
40.617056901, 96.390, 4478.0, 66.9179
40.669578032, 96.390, 4013.0, 63.3482
40.722099162, 96.390, 3535.0, 59.4559
40.774620293, 96.390, 2890.0, 53.7587
40.827141424, 96.390, 2331.0, 48.2804
40.879662554, 96.390, 2115.0, 45.9891
40.932183685, 96.390, 1832.0, 42.8019
40.984704816, 96.390, 1712.0, 41.3763
41.037225947, 96.390, 1649.0, 40.6079
41.089747077, 96.390, 1501.0, 38.7427
41.142268208, 96.390, 1493.0, 38.6394
41.194789339, 96.390, 1518.0, 38.9615
41.247310469, 96.390, 1515.0, 38.9230
41.299831600, 96.390, 1742.0, 41.7373
41.352352731, 96.390, 2068.0, 45.4753
41.404873862, 96.390, 2313.0, 48.0937
41.457394992, 96.390, 2237.0, 47.2969
41.509916123, 96.390, 2165.0, 46.5296
41.562437254, 96.390, 2015.0, 44.8888
41.614958384, 96.390, 1946.0, 44.1135
41.667479515, 96.390, 1879.0, 43.3474
41.720000646, 96.390, 1708.0, 41.3280
41.772521776, 96.390, 1498.0, 38.7040
41.825042907, 96.390, 1443.0, 37.9868
41.877564038, 96.390, 1392.0, 37.3095
41.930085169, 96.390, 1345.0, 36.6742
41.982606299, 96.390, 1336.0, 36.5513
42.035127430, 96.390, 1382.0, 37.1753
42.087648561, 96.390, 1451.0, 38.0920
42.140169691, 96.390, 1599.0, 39.9875
42.192690822, 96.390, 1682.0, 41.0122
42.245211953, 96.390, 1611.0, 40.1373
42.297733084, 96.390, 1616.0, 40.1995
42.350254214, 96.390, 1532.0, 39.1408
42.402775345, 96.390, 1373.0, 37.0540
42.455296476, 96.390, 1338.0, 36.5787
42.507817606, 96.390, 1479.0, 38.4578
42.560338737, 96.390, 1477.0, 38.4318
42.612859868, 96.390, 1448.0, 38.0526
42.665380999, 96.390, 1357.0, 36.8375
42.717902129, 96.390, 1350.0, 36.7423
42.770423260, 96.390, 1189.0, 34.4819
42.822944391, 96.390, 1136.0, 33.7046
42.875465521, 96.390, 1226.0, 35.0143
42.927986652, 96.390, 1344.0, 36.6606
42.980507783, 96.390, 1261.0, 35.5106
43.033028914, 96.390, 1201.0, 34.6554
43.085550044, 96.390, 1186.0, 34.4384
43.138071175, 96.390, 1176.0, 34.2929
43.190592306, 96.390, 1164.0, 34.1174
43.243113436, 96.390, 1121.0, 33.4813
43.295634567, 96.390, 1167.0, 34.1614
43.348155698, 96.390, 1121.0, 33.4813
43.400676828, 96.390, 1153.0, 33.9559
43.453197959, 96.390, 1153.0, 33.9559
43.505719090, 96.390, 1295.0, 35.9861
43.558240221, 96.390, 1383.0, 37.1887
43.610761351, 96.390, 1487.0, 38.5616
43.663282482, 96.390, 1535.0, 39.1791
43.715803613, 96.390, 1763.0, 41.9881
43.768324743, 96.390, 2030.0, 45.0555
43.820845874, 96.390, 1995.0, 44.6654
43.873367005, 96.390, 1803.0, 42.4617
43.925888136, 96.390, 1671.0, 40.8779
43.978409266, 96.390, 1365.0, 36.9459
44.030930397, 96.390, 1320.0, 36.3318
44.083451528, 96.390, 1302.0, 36.0832
44.135972658, 96.390, 1348.0, 36.7151
44.188493789, 96.390, 1456.0, 38.1576
44.241014920, 96.390, 1672.0, 40.8901
44.293536051, 96.390, 1688.0, 41.0853
44.346057181, 96.390, 1834.0, 42.8252
44.398578312, 96.390, 1736.0, 41.6653
44.451099443, 96.390, 1694.0, 41.1582
44.503620573, 96.390, 1517.0, 38.9487
44.556141704, 96.390, 1370.0, 37.0135
44.608662835, 96.390, 1209.0, 34.7707
44.661183966, 96.390, 1118.0, 33.4365
44.713705096, 96.390, 1111.0, 33.3317
44.766226227, 96.390, 1094.0, 33.0757
44.818747358, 96.390, 1242.0, 35.2420
44.871268488, 96.390, 1363.0, 36.9188
44.923789619, 96.390, 1281.0, 35.7911
44.976310750, 96.390, 1257.0, 35.4542
45.028831880, 96.390, 1365.0, 36.9459
45.081353011, 96.390, 1416.0, 37.6298
45.133874142, 96.390, 1725.0, 41.5331
45.186395273, 96.390, 1536.0, 39.1918
45.238916403, 96.390, 1509.0, 38.8458
45.291437534, 96.390, 1561.0, 39.5095
45.343958665, 96.390, 1654.0, 40.6694
45.396479795, 96.390, 1606.0, 40.0749
45.449000926, 96.390, 1798.0, 42.4028
45.501522057, 96.390, 1840.0, 42.8952
45.554043188, 96.390, 1637.0, 40.4599
45.606564318, 96.390, 1529.0, 39.1024
45.659085449, 96.390, 1451.0, 38.0920
45.711606580, 96.390, 1332.0, 36.4966
45.764127710, 96.390, 1353.0, 36.7831
45.816648841, 96.390, 1367.0, 36.9730
45.869169972, 96.390, 1377.0, 37.1080
45.921691103, 96.390, 1353.0, 36.7831
45.974212233, 96.390, 1289.0, 35.9026
46.026733364, 96.390, 1297.0, 36.0139
46.079254495, 96.390, 1300.0, 36.0555
46.131775625, 96.390, 1288.0, 35.8887
46.184296756, 96.390, 1301.0, 36.0694
46.236817887, 96.390, 1393.0, 37.3229
46.289339017, 96.390, 1515.0, 38.9230
46.341860148, 96.390, 1388.0, 37.2559
46.394381279, 96.390, 1448.0, 38.0526
46.446902410, 96.390, 1366.0, 36.9594
46.499423540, 96.390, 1237.0, 35.1710
46.551944671, 96.390, 1184.0, 34.4093
46.604465802, 96.390, 1233.0, 35.1141
46.656986932, 96.390, 1158.0, 34.0294
46.709508063, 96.390, 1131.0, 33.6303
46.762029194, 96.390, 1129.0, 33.6006
46.814550325, 96.390, 1101.0, 33.1813
46.867071455, 96.390, 1103.0, 33.2114
46.919592586, 96.390, 1151.0, 33.9264
46.972113717, 96.390, 1307.0, 36.1525
47.024634847, 96.390, 1382.0, 37.1753
47.077155978, 96.390, 1259.0, 35.4824
47.129677109, 96.390, 1328.0, 36.4417
47.182198240, 96.390, 1321.0, 36.3456
47.234719370, 96.390, 1261.0, 35.5106
47.287240501, 96.390, 1382.0, 37.1753
47.339761632, 96.390, 1429.0, 37.8021
47.392282762, 96.390, 1520.0, 38.9872
47.444803893, 96.390, 1487.0, 38.5616
47.497325024, 96.390, 1499.0, 38.7169
47.549846155, 96.390, 1344.0, 36.6606
47.602367285, 96.390, 1289.0, 35.9026
47.654888416, 96.390, 1183.0, 34.3948
47.707409547, 96.390, 1133.0, 33.6601
47.759930677, 96.390, 1104.0, 33.2265
47.812451808, 96.390, 1127.0, 33.5708
47.864972939, 96.390, 1112.0, 33.3467
47.917494069, 96.390, 1185.0, 34.4238
47.970015200, 96.390, 1311.0, 36.2077
48.022536331, 96.390, 1389.0, 37.2693
48.075057462, 96.390, 1360.0, 36.8782
48.127578592, 96.390, 1436.0, 37.8946
48.180099723, 96.390, 1410.0, 37.5500
48.232620854, 96.390, 1437.0, 37.9078
48.285141984, 96.390, 1287.0, 35.8748
48.337663115, 96.390, 1155.0, 33.9853
48.390184246, 96.390, 1209.0, 34.7707
48.442705377, 96.390, 1140.0, 33.7639
48.495226507, 96.390, 1329.0, 36.4555
48.547747638, 96.390, 1318.0, 36.3043
48.600268769, 96.390, 1219.0, 34.9142
48.652789899, 96.390, 1204.0, 34.6987
48.705311030, 96.390, 1096.0, 33.1059
48.757832161, 96.390, 1081.0, 32.8786
48.810353292, 96.390, 1072.0, 32.7414
48.862874422, 96.390, 1028.0, 32.0624
48.915395553, 96.390, 1033.0, 32.1403
48.967916684, 96.390, 1075.0, 32.7872
49.020437814, 96.390, 1111.0, 33.3317
49.072958945, 96.390, 1074.0, 32.7719
49.125480076, 96.390, 1055.0, 32.4808
49.178001207, 96.390, 1141.0, 33.7787
49.230522337, 96.390, 1153.0, 33.9559
49.283043468, 96.390, 1095.0, 33.0908
49.335564599, 96.390, 1068.0, 32.6803
49.388085729, 96.390, 1105.0, 33.2415
49.440606860, 96.390, 1076.0, 32.8024
49.493127991, 96.390, 1070.0, 32.7109
49.545649121, 96.390, 994.0, 31.5278
49.598170252, 96.390, 1019.0, 31.9218
49.650691383, 96.390, 995.0, 31.5436
49.703212514, 96.390, 1021.0, 31.9531
49.755733644, 96.390, 1091.0, 33.0303
49.808254775, 96.390, 1145.0, 33.8378
49.860775906, 96.390, 1039.0, 32.2335
49.913297036, 96.390, 1070.0, 32.7109
49.965818167, 96.390, 1038.0, 32.2180
50.018339298, 96.390, 926.0, 30.4302
50.070860429, 96.390, 905.0, 30.0832
50.123381559, 96.390, 927.0, 30.4467
50.175902690, 96.390, 1053.0, 32.4500
50.228423821, 96.390, 1145.0, 33.8378
50.280944951, 96.390, 1327.0, 36.4280
50.333466082, 96.390, 1161.0, 34.0735
50.385987213, 96.390, 1185.0, 34.4238
50.438508344, 96.390, 1096.0, 33.1059
50.491029474, 96.390, 968.0, 31.1127
50.543550605, 96.390, 942.0, 30.6920
50.596071736, 96.390, 923.0, 30.3809
50.648592866, 96.390, 900.0, 30.0000
50.701113997, 96.390, 881.0, 29.6816
50.753635128, 96.390, 910.0, 30.1662
50.806156258, 96.390, 929.0, 30.4795
50.858677389, 96.390, 942.0, 30.6920
50.911198520, 96.390, 877.0, 29.6142
50.963719651, 96.390, 927.0, 30.4467
51.016240781, 96.390, 923.0, 30.3809
51.068761912, 96.390, 985.0, 31.3847
51.121283043, 96.390, 990.0, 31.4643
51.173804173, 96.390, 1040.0, 32.2490
51.226325304, 96.390, 1115.0, 33.3916
51.278846435, 96.390, 1153.0, 33.9559
51.331367566, 96.390, 1094.0, 33.0757
51.383888696, 96.390, 1052.0, 32.4345
51.436409827, 96.390, 963.0, 31.0322
51.488930958, 96.390, 935.0, 30.5778
51.541452088, 96.390, 930.0, 30.4959
51.593973219, 96.390, 934.0, 30.5614
51.646494350, 96.390, 961.0, 31.0000
51.699015481, 96.390, 979.0, 31.2890
51.751536611, 96.390, 1085.0, 32.9393
51.804057742, 96.390, 1078.0, 32.8329
51.856578873, 96.390, 1056.0, 32.4962
51.909100003, 96.390, 1117.0, 33.4215
51.961621134, 96.390, 1043.0, 32.2955
52.014142265, 96.390, 1095.0, 33.0908
52.066663396, 96.390, 1193.0, 34.5398
52.119184526, 96.390, 1253.0, 35.3977
52.171705657, 96.390, 1400.0, 37.4166
52.224226788, 96.390, 1594.0, 39.9249
52.276747918, 96.390, 1611.0, 40.1373
52.329269049, 96.390, 1615.0, 40.1871
52.381790180, 96.390, 1469.0, 38.3275
52.434311310, 96.390, 1444.0, 38.0000
52.486832441, 96.390, 1336.0, 36.5513
52.539353572, 96.390, 1374.0, 37.0675
52.591874703, 96.390, 1529.0, 39.1024
52.644395833, 96.390, 1748.0, 41.8091
52.696916964, 96.390, 2013.0, 44.8665
52.749438095, 96.390, 1876.0, 43.3128
52.801959225, 96.390, 1936.0, 44.0000
52.854480356, 96.390, 1882.0, 43.3820
52.907001487, 96.390, 1830.0, 42.7785
52.959522618, 96.390, 1770.0, 42.0714
53.012043748, 96.390, 1809.0, 42.5323
53.064564879, 96.390, 1920.0, 43.8178
53.117086010, 96.390, 2015.0, 44.8888
53.169607140, 96.390, 2042.0, 45.1885
53.222128271, 96.390, 2096.0, 45.7821
53.274649402, 96.390, 1924.0, 43.8634
53.327170533, 96.390, 1738.0, 41.6893
53.379691663, 96.390, 1524.0, 39.0384
53.432212794, 96.390, 1357.0, 36.8375
53.484733925, 96.390, 1370.0, 37.0135
53.537255055, 96.390, 1246.0, 35.2987
53.589776186, 96.390, 1101.0, 33.1813
53.642297317, 96.390, 1072.0, 32.7414
53.694818448, 96.390, 1016.0, 31.8748
53.747339578, 96.390, 976.0, 31.2410
53.799860709, 96.390, 957.0, 30.9354
53.852381840, 96.390, 974.0, 31.2090
53.904902970, 96.390, 936.0, 30.5941
53.957424101, 96.390, 966.0, 31.0805
54.009945232, 96.390, 976.0, 31.2410
54.062466362, 96.390, 1095.0, 33.0908
54.114987493, 96.390, 1096.0, 33.1059
54.167508624, 96.390, 1198.0, 34.6121
54.220029755, 96.390, 1206.0, 34.7275
54.272550885, 96.390, 1234.0, 35.1283
54.325072016, 96.390, 1388.0, 37.2559
54.377593147, 96.390, 1430.0, 37.8153
54.430114277, 96.390, 1330.0, 36.4692
54.482635408, 96.390, 1196.0, 34.5832
54.535156539, 96.390, 1129.0, 33.6006
54.587677670, 96.390, 1018.0, 31.9061
54.640198800, 96.390, 880.0, 29.6648
54.692719931, 96.390, 818.0, 28.6007
54.745241062, 96.390, 853.0, 29.2062
54.797762192, 96.390, 836.0, 28.9137
54.850283323, 96.390, 803.0, 28.3373
54.902804454, 96.390, 845.0, 29.0689
54.955325585, 96.390, 795.0, 28.1957
55.007846715, 96.390, 888.0, 29.7993
55.060367846, 96.390, 857.0, 29.2746
55.112888977, 96.390, 778.0, 27.8927
55.165410107, 96.390, 746.0, 27.3130
55.217931238, 96.390, 734.0, 27.0924
55.270452369, 96.390, 792.0, 28.1425
55.322973499, 96.390, 718.0, 26.7955
55.375494630, 96.390, 753.0, 27.4408
55.428015761, 96.390, 797.0, 28.2312
55.480536892, 96.390, 843.0, 29.0345
55.533058022, 96.390, 868.0, 29.4618
55.585579153, 96.390, 900.0, 30.0000
55.638100284, 96.390, 958.0, 30.9516
55.690621414, 96.390, 876.0, 29.5973
55.743142545, 96.390, 916.0, 30.2655
55.795663676, 96.390, 912.0, 30.1993
55.848184807, 96.390, 828.0, 28.7750
55.900705937, 96.390, 869.0, 29.4788
55.953227068, 96.390, 841.0, 29.0000
56.005748199, 96.390, 848.0, 29.1204
56.058269329, 96.390, 876.0, 29.5973
56.110790460, 96.390, 830.0, 28.8097
56.163311591, 96.390, 781.0, 27.9464
56.215832722, 96.390, 826.0, 28.7402
56.268353852, 96.390, 804.0, 28.3549
56.320874983, 96.390, 723.0, 26.8887
56.373396114, 96.390, 785.0, 28.0179
56.425917244, 96.390, 774.0, 27.8209
56.478438375, 96.390, 855.0, 29.2404
56.530959506, 96.390, 846.0, 29.0861
56.583480637, 96.390, 914.0, 30.2324
56.636001767, 96.390, 896.0, 29.9333
56.688522898, 96.390, 901.0, 30.0167
56.741044029, 96.390, 834.0, 28.8791
56.793565159, 96.390, 772.0, 27.7849
56.846086290, 96.390, 811.0, 28.4781
56.898607421, 96.390, 768.0, 27.7128
56.951128551, 96.390, 759.0, 27.5500
57.003649682, 96.390, 779.0, 27.9106
57.056170813, 96.390, 803.0, 28.3373
57.108691944, 96.390, 845.0, 29.0689
57.161213074, 96.390, 827.0, 28.7576
57.213734205, 96.390, 845.0, 29.0689
57.266255336, 96.390, 856.0, 29.2575
57.318776466, 96.390, 835.0, 28.8964
57.371297597, 96.390, 878.0, 29.6311
57.423818728, 96.390, 895.0, 29.9166
57.476339859, 96.390, 959.0, 30.9677
57.528860989, 96.390, 994.0, 31.5278
57.581382120, 96.390, 1048.0, 32.3728
57.633903251, 96.390, 1119.0, 33.4515
57.686424381, 96.390, 1098.0, 33.1361
57.738945512, 96.390, 1009.0, 31.7648
57.791466643, 96.390, 997.0, 31.5753
57.843987774, 96.390, 932.0, 30.5287
57.896508904, 96.390, 925.0, 30.4138
57.949030035, 96.390, 805.0, 28.3725
58.001551166, 96.390, 908.0, 30.1330
58.054072296, 96.390, 987.0, 31.4166
58.106593427, 96.390, 1117.0, 33.4215
58.159114558, 96.390, 876.0, 29.5973
58.211635689, 96.390, 871.0, 29.5127
58.264156819, 96.390, 873.0, 29.5466
58.316677950, 96.390, 828.0, 28.7750
58.369199081, 96.390, 766.0, 27.6767
58.421720211, 96.390, 786.0, 28.0357
58.474241342, 96.390, 768.0, 27.7128
58.526762473, 96.390, 869.0, 29.4788
58.579283603, 96.390, 977.0, 31.2570
58.631804734, 96.390, 1044.0, 32.3110
58.684325865, 96.390, 1172.0, 34.2345
58.736846996, 96.390, 1036.0, 32.1870
58.789368126, 96.390, 1030.0, 32.0936
58.841889257, 96.390, 1005.0, 31.7017
58.894410388, 96.390, 959.0, 30.9677
58.946931518, 96.390, 889.0, 29.8161
58.999452649, 96.390, 920.0, 30.3315
59.051973780, 96.390, 842.0, 29.0172
59.104494911, 96.390, 835.0, 28.8964
59.157016041, 96.390, 850.0, 29.1548
59.209537172, 96.390, 897.0, 29.9500
59.262058303, 96.390, 998.0, 31.5911
59.314579433, 96.390, 1011.0, 31.7962
59.367100564, 96.390, 856.0, 29.2575
59.419621695, 96.390, 909.0, 30.1496
59.472142826, 96.390, 899.0, 29.9833
59.524663956, 96.390, 910.0, 30.1662
59.577185087, 96.390, 878.0, 29.6311
59.629706218, 96.390, 838.0, 28.9482
59.682227348, 96.390, 775.0, 27.8388
59.734748479, 96.390, 821.0, 28.6531
59.787269610, 96.390, 852.0, 29.1890
59.839790740, 96.390, 815.0, 28.5482
59.892311871, 96.390, 786.0, 28.0357
59.944833002, 96.390, 871.0, 29.5127
59.997354133, 96.390, 856.0, 29.2575
60.049875263, 96.390, 844.0, 29.0517
60.102396394, 96.390, 898.0, 29.9666
60.154917525, 96.390, 828.0, 28.7750
60.207438655, 96.390, 855.0, 29.2404
60.259959786, 96.390, 912.0, 30.1993
60.312480917, 96.390, 876.0, 29.5973
60.365002048, 96.390, 864.0, 29.3939
60.417523178, 96.390, 918.0, 30.2985
60.470044309, 96.390, 953.0, 30.8707
60.522565440, 96.390, 915.0, 30.2490
60.575086570, 96.390, 908.0, 30.1330
60.627607701, 96.390, 944.0, 30.7246
60.680128832, 96.390, 1053.0, 32.4500
60.732649963, 96.390, 1100.0, 33.1662
60.785171093, 96.390, 1260.0, 35.4965
60.837692224, 96.390, 1332.0, 36.4966
60.890213355, 96.390, 1474.0, 38.3927
60.942734485, 96.390, 1406.0, 37.4967
60.995255616, 96.390, 1363.0, 36.9188
61.047776747, 96.390, 1302.0, 36.0832
61.100297878, 96.390, 1128.0, 33.5857
61.152819008, 96.390, 1111.0, 33.3317
61.205340139, 96.390, 1076.0, 32.8024
61.257861270, 96.390, 1033.0, 32.1403
61.310382400, 96.390, 1030.0, 32.0936
61.362903531, 96.390, 928.0, 30.4631
61.415424662, 96.390, 912.0, 30.1993
61.467945792, 96.390, 1007.0, 31.7333
61.520466923, 96.390, 1006.0, 31.7175
61.572988054, 96.390, 975.0, 31.2250
61.625509185, 96.390, 862.0, 29.3598
61.678030315, 96.390, 873.0, 29.5466
61.730551446, 96.390, 902.0, 30.0333
61.783072577, 96.390, 884.0, 29.7321
61.835593707, 96.390, 879.0, 29.6479
61.888114838, 96.390, 946.0, 30.7571
61.940635969, 96.390, 965.0, 31.0644
61.993157100, 96.390, 1041.0, 32.2645
62.045678230, 96.390, 1063.0, 32.6037
62.098199361, 96.390, 1028.0, 32.0624
62.150720492, 96.390, 1070.0, 32.7109
62.203241622, 96.390, 1070.0, 32.7109
62.255762753, 96.390, 1136.0, 33.7046
62.308283884, 96.390, 1084.0, 32.9242
62.360805015, 96.390, 1072.0, 32.7414
62.413326145, 96.390, 1031.0, 32.1092
62.465847276, 96.390, 1054.0, 32.4654
62.518368407, 96.390, 951.0, 30.8383
62.570889537, 96.390, 951.0, 30.8383
62.623410668, 96.390, 984.0, 31.3688
62.675931799, 96.390, 1002.0, 31.6544
62.728452930, 96.390, 946.0, 30.7571
62.780974060, 96.390, 917.0, 30.2820
62.833495191, 96.390, 963.0, 31.0322
62.886016322, 96.390, 927.0, 30.4467
62.938537452, 96.390, 848.0, 29.1204
62.991058583, 96.390, 810.0, 28.4605
63.043579714, 96.390, 738.0, 27.1662
63.096100844, 96.390, 688.0, 26.2298
63.148621975, 96.390, 659.0, 25.6710
63.201143106, 96.390, 729.0, 27.0000
63.253664237, 96.390, 696.0, 26.3818
63.306185367, 96.390, 736.0, 27.1293
63.358706498, 96.390, 744.0, 27.2764
63.411227629, 96.390, 777.0, 27.8747
63.463748759, 96.390, 754.0, 27.4591
63.516269890, 96.390, 774.0, 27.8209
63.568791021, 96.390, 785.0, 28.0179
63.621312152, 96.390, 874.0, 29.5635
63.673833282, 96.390, 952.0, 30.8545
63.726354413, 96.390, 1153.0, 33.9559
63.778875544, 96.390, 1314.0, 36.2491
63.831396674, 96.390, 1341.0, 36.6197
63.883917805, 96.390, 1299.0, 36.0416
63.936438936, 96.390, 1218.0, 34.8999
63.988960067, 96.390, 1171.0, 34.2199
64.041481197, 96.390, 1115.0, 33.3916
64.094002328, 96.390, 1039.0, 32.2335
64.146523459, 96.390, 997.0, 31.5753
64.199044589, 96.390, 1006.0, 31.7175
64.251565720, 96.390, 1043.0, 32.2955
64.304086851, 96.390, 1048.0, 32.3728
64.356607981, 96.390, 1085.0, 32.9393
64.409129112, 96.390, 1034.0, 32.1559
64.461650243, 96.390, 1011.0, 31.7962
64.514171374, 96.390, 887.0, 29.7825
64.566692504, 96.390, 886.0, 29.7658
64.619213635, 96.390, 808.0, 28.4253
64.671734766, 96.390, 791.0, 28.1247
64.724255896, 96.390, 739.0, 27.1846
64.776777027, 96.390, 771.0, 27.7669
64.829298158, 96.390, 730.0, 27.0185
64.881819289, 96.390, 674.0, 25.9615
64.934340419, 96.390, 710.0, 26.6458
64.986861550, 96.390, 703.0, 26.5141