File: Files_organized_for_plots/470_day/29Al-Axial_SolventExchange.csv
[Measurement conditions]
Sample identification,29_AlAxial01Nov21_Act07Jan22_B2_1000M_NaOH_LS0132_SolventExchange
Comment - 1,"Configuration=Stage for Flat Samples/Holders, Owner=User-1, Creation date=7/1/2020 9:53:24 AM"
Comment - 2,"Goniometer=Theta/Theta; Minimum step size 2Theta:0.0001; Minimum step size Omega:0.0001"
Comment - 3,"Sample stage=Stage for flat samples/holders"
Comment - 4,"Diffractometer system=EMPYREAN"
Comment - 5,"Measurement program=C:\Users\tmr79\OneDrive - The Pennsylvania State University\Documents\NEUP\XRD\Cement\Zerobackground scan.xrdmp, Identifier={98A3B11C-88F9-4AA6-982C-73314A311EF5}"
Anode material,Cu
K-Alpha1 wavelength,1.5405980
K-Alpha2 wavelength,1.5444260
Ratio K-Alpha2/K-Alpha1,0.500
Divergence slit,Fixed,0.25
Monochromator used,NO
Generator voltage, 45
Tube current, 40
File date and time,25/Apr/2023 16:03
Unit cell,
h k l, 0 0 0
Scan axis,Gonio
Scan range,4.994599997,64.999991833
Scan step size,0.0262606
No. of points, 2285
Scan type,CONTINUOUS
Time per step,96.390
[Scan points]
Angle, TimePerStep, Intensity, ESD
5.007730280, 96.390, 3091.0, 55.5968
5.060251411, 96.390, 3153.0, 56.1516
5.112772541, 96.390, 3031.0, 55.0545
5.165293672, 96.390, 2933.0, 54.1572
5.217814803, 96.390, 2908.0, 53.9259
5.270335934, 96.390, 2964.0, 54.4426
5.322857064, 96.390, 2925.0, 54.0833
5.375378195, 96.390, 2895.0, 53.8052
5.427899326, 96.390, 2938.0, 54.2033
5.480420456, 96.390, 2799.0, 52.9056
5.532941587, 96.390, 3017.0, 54.9272
5.585462718, 96.390, 2814.0, 53.0471
5.637983849, 96.390, 2875.0, 53.6190
5.690504979, 96.390, 2827.0, 53.1695
5.743026110, 96.390, 2868.0, 53.5537
5.795547241, 96.390, 2891.0, 53.7680
5.848068371, 96.390, 2787.0, 52.7920
5.900589502, 96.390, 2902.0, 53.8702
5.953110633, 96.390, 2896.0, 53.8145
6.005631763, 96.390, 2960.0, 54.4059
6.058152894, 96.390, 2979.0, 54.5802
6.110674025, 96.390, 3052.0, 55.2449
6.163195156, 96.390, 2839.0, 53.2823
6.215716286, 96.390, 2850.0, 53.3854
6.268237417, 96.390, 2715.0, 52.1057
6.320758548, 96.390, 2608.0, 51.0686
6.373279678, 96.390, 2607.0, 51.0588
6.425800809, 96.390, 2716.0, 52.1153
6.478321940, 96.390, 2799.0, 52.9056
6.530843071, 96.390, 2662.0, 51.5946
6.583364201, 96.390, 2684.0, 51.8073
6.635885332, 96.390, 2629.0, 51.2738
6.688406463, 96.390, 2653.0, 51.5073
6.740927593, 96.390, 2684.0, 51.8073
6.793448724, 96.390, 2681.0, 51.7784
6.845969855, 96.390, 2753.0, 52.4690
6.898490986, 96.390, 2938.0, 54.2033
6.951012116, 96.390, 2996.0, 54.7357
7.003533247, 96.390, 3131.0, 55.9553
7.056054378, 96.390, 3389.0, 58.2151
7.108575508, 96.390, 3912.0, 62.5460
7.161096639, 96.390, 4735.0, 68.8113
7.213617770, 96.390, 4982.0, 70.5833
7.266138900, 96.390, 3039.0, 55.1271
7.318660031, 96.390, 2741.0, 52.3546
7.371181162, 96.390, 2541.0, 50.4083
7.423702293, 96.390, 2500.0, 50.0000
7.476223423, 96.390, 2605.0, 51.0392
7.528744554, 96.390, 2466.0, 49.6588
7.581265685, 96.390, 2586.0, 50.8527
7.633786815, 96.390, 2489.0, 49.8899
7.686307946, 96.390, 2535.0, 50.3488
7.738829077, 96.390, 2591.0, 50.9019
7.791350208, 96.390, 2423.0, 49.2240
7.843871338, 96.390, 2581.0, 50.8035
7.896392469, 96.390, 2516.0, 50.1597
7.948913600, 96.390, 2481.0, 49.8096
8.001434730, 96.390, 2567.0, 50.6656
8.053955861, 96.390, 2633.0, 51.3128
8.106476992, 96.390, 2831.0, 53.2071
8.158998123, 96.390, 2828.0, 53.1789
8.211519253, 96.390, 2588.0, 50.8724
8.264040384, 96.390, 2393.0, 48.9183
8.316561515, 96.390, 2498.0, 49.9800
8.369082645, 96.390, 2503.0, 50.0300
8.421603776, 96.390, 2558.0, 50.5767
8.474124907, 96.390, 2465.0, 49.6488
8.526646038, 96.390, 2510.0, 50.0999
8.579167168, 96.390, 2546.0, 50.4579
8.631688299, 96.390, 2546.0, 50.4579
8.684209430, 96.390, 2498.0, 49.9800
8.736730560, 96.390, 2542.0, 50.4183
8.789251691, 96.390, 2459.0, 49.5883
8.841772822, 96.390, 2497.0, 49.9700
8.894293952, 96.390, 2544.0, 50.4381
8.946815083, 96.390, 2547.0, 50.4678
8.999336214, 96.390, 2544.0, 50.4381
9.051857345, 96.390, 2592.0, 50.9117
9.104378475, 96.390, 2568.0, 50.6754
9.156899606, 96.390, 2632.0, 51.3030
9.209420737, 96.390, 2529.0, 50.2892
9.261941867, 96.390, 2614.0, 51.1273
9.314462998, 96.390, 2731.0, 52.2590
9.366984129, 96.390, 2686.0, 51.8266
9.419505260, 96.390, 2693.0, 51.8941
9.472026390, 96.390, 2612.0, 51.1077
9.524547521, 96.390, 2729.0, 52.2398
9.577068652, 96.390, 2703.0, 51.9904
9.629589782, 96.390, 2771.0, 52.6403
9.682110913, 96.390, 2725.0, 52.2015
9.734632044, 96.390, 2723.0, 52.1824
9.787153175, 96.390, 2784.0, 52.7636
9.839674305, 96.390, 2823.0, 53.1319
9.892195436, 96.390, 2988.0, 54.6626
9.944716567, 96.390, 3026.0, 55.0091
9.997237697, 96.390, 3052.0, 55.2449
10.049758828, 96.390, 3336.0, 57.7581
10.102279959, 96.390, 3638.0, 60.3158
10.154801090, 96.390, 4331.0, 65.8103
10.207322220, 96.390, 4052.0, 63.6553
10.259843351, 96.390, 3049.0, 55.2178
10.312364482, 96.390, 2950.0, 54.3139
10.364885612, 96.390, 2808.0, 52.9906
10.417406743, 96.390, 2791.0, 52.8299
10.469927874, 96.390, 2792.0, 52.8394
10.522449004, 96.390, 2768.0, 52.6118
10.574970135, 96.390, 2801.0, 52.9245
10.627491266, 96.390, 2712.0, 52.0769
10.680012397, 96.390, 2766.0, 52.5928
10.732533527, 96.390, 2837.0, 53.2635
10.785054658, 96.390, 2778.0, 52.7067
10.837575789, 96.390, 2843.0, 53.3198
10.890096919, 96.390, 2764.0, 52.5738
10.942618050, 96.390, 2768.0, 52.6118
10.995139181, 96.390, 2738.0, 52.3259
11.047660312, 96.390, 2742.0, 52.3641
11.100181442, 96.390, 2760.0, 52.5357
11.152702573, 96.390, 2732.0, 52.2685
11.205223704, 96.390, 2720.0, 52.1536
11.257744834, 96.390, 2839.0, 53.2823
11.310265965, 96.390, 2698.0, 51.9423
11.362787096, 96.390, 2649.0, 51.4684
11.415308227, 96.390, 2673.0, 51.7011
11.467829357, 96.390, 2587.0, 50.8626
11.520350488, 96.390, 2722.0, 52.1728
11.572871619, 96.390, 2654.0, 51.5170
11.625392749, 96.390, 2708.0, 52.0384
11.677913880, 96.390, 2656.0, 51.5364
11.730435011, 96.390, 2649.0, 51.4684
11.782956141, 96.390, 2599.0, 50.9804
11.835477272, 96.390, 2584.0, 50.8331
11.887998403, 96.390, 2503.0, 50.0300
11.940519534, 96.390, 2581.0, 50.8035
11.993040664, 96.390, 2515.0, 50.1498
12.045561795, 96.390, 2437.0, 49.3660
12.098082926, 96.390, 2502.0, 50.0200
12.150604056, 96.390, 2495.0, 49.9500
12.203125187, 96.390, 2449.0, 49.4874
12.255646318, 96.390, 2498.0, 49.9800
12.308167449, 96.390, 2638.0, 51.3615
12.360688579, 96.390, 2639.0, 51.3712
12.413209710, 96.390, 2947.0, 54.2863
12.465730841, 96.390, 3332.0, 57.7235
12.518251971, 96.390, 2988.0, 54.6626
12.570773102, 96.390, 2444.0, 49.4368
12.623294233, 96.390, 2295.0, 47.9062
12.675815364, 96.390, 2133.0, 46.1844
12.728336494, 96.390, 2299.0, 47.9479
12.780857625, 96.390, 2159.0, 46.4650
12.833378756, 96.390, 2100.0, 45.8258
12.885899886, 96.390, 2228.0, 47.2017
12.938421017, 96.390, 2188.0, 46.7761
12.990942148, 96.390, 2075.0, 45.5522
13.043463279, 96.390, 2125.0, 46.0977
13.095984409, 96.390, 2165.0, 46.5296
13.148505540, 96.390, 2100.0, 45.8258
13.201026671, 96.390, 2098.0, 45.8039
13.253547801, 96.390, 2078.0, 45.5851
13.306068932, 96.390, 2027.0, 45.0222
13.358590063, 96.390, 2070.0, 45.4973
13.411111193, 96.390, 2062.0, 45.4093
13.463632324, 96.390, 2040.0, 45.1664
13.516153455, 96.390, 1957.0, 44.2380
13.568674586, 96.390, 1965.0, 44.3283
13.621195716, 96.390, 1942.0, 44.0681
13.673716847, 96.390, 1847.0, 42.9767
13.726237978, 96.390, 2046.0, 45.2327
13.778759108, 96.390, 1859.0, 43.1161
13.831280239, 96.390, 1915.0, 43.7607
13.883801370, 96.390, 2019.0, 44.9333
13.936322501, 96.390, 1904.0, 43.6348
13.988843631, 96.390, 1895.0, 43.5316
14.041364762, 96.390, 1902.0, 43.6119
14.093885893, 96.390, 1969.0, 44.3734
14.146407023, 96.390, 1867.0, 43.2088
14.198928154, 96.390, 1821.0, 42.6732
14.251449285, 96.390, 1834.0, 42.8252
14.303970416, 96.390, 1898.0, 43.5660
14.356491546, 96.390, 1937.0, 44.0114
14.409012677, 96.390, 2171.0, 46.5940
14.461533808, 96.390, 2308.0, 48.0416
14.514054938, 96.390, 3002.0, 54.7905
14.566576069, 96.390, 2825.0, 53.1507
14.619097200, 96.390, 1916.0, 43.7721
14.671618331, 96.390, 1872.0, 43.2666
14.724139461, 96.390, 1809.0, 42.5323
14.776660592, 96.390, 1734.0, 41.6413
14.829181723, 96.390, 1811.0, 42.5558
14.881702853, 96.390, 1779.0, 42.1782
14.934223984, 96.390, 1768.0, 42.0476
14.986745115, 96.390, 1809.0, 42.5323
15.039266245, 96.390, 1843.0, 42.9302
15.091787376, 96.390, 1858.0, 43.1045
15.144308507, 96.390, 1999.0, 44.7102
15.196829638, 96.390, 2340.0, 48.3735
15.249350768, 96.390, 2259.0, 47.5289
15.301871899, 96.390, 2160.0, 46.4758
15.354393030, 96.390, 1988.0, 44.5870
15.406914160, 96.390, 1935.0, 43.9886
15.459435291, 96.390, 1724.0, 41.5211
15.511956422, 96.390, 1692.0, 41.1339
15.564477553, 96.390, 1626.0, 40.3237
15.616998683, 96.390, 1669.0, 40.8534
15.669519814, 96.390, 1855.0, 43.0697
15.722040945, 96.390, 1962.0, 44.2945
15.774562075, 96.390, 1726.0, 41.5452
15.827083206, 96.390, 1679.0, 40.9756
15.879604337, 96.390, 1720.0, 41.4729
15.932125468, 96.390, 1657.0, 40.7063
15.984646598, 96.390, 1737.0, 41.6773
16.037167729, 96.390, 1906.0, 43.6578
16.089688860, 96.390, 2261.0, 47.5500
16.142209990, 96.390, 2474.0, 49.7393
16.194731121, 96.390, 2038.0, 45.1442
16.247252252, 96.390, 2029.0, 45.0444
16.299773382, 96.390, 2403.0, 49.0204
16.352294513, 96.390, 2454.0, 49.5379
16.404815644, 96.390, 1755.0, 41.8927
16.457336775, 96.390, 1661.0, 40.7554
16.509857905, 96.390, 1617.0, 40.2119
16.562379036, 96.390, 1579.0, 39.7366
16.614900167, 96.390, 1510.0, 38.8587
16.667421297, 96.390, 1546.0, 39.3192
16.719942428, 96.390, 1570.0, 39.6232
16.772463559, 96.390, 1500.0, 38.7298
16.824984690, 96.390, 1481.0, 38.4838
16.877505820, 96.390, 1577.0, 39.7115
16.930026951, 96.390, 1464.0, 38.2623
16.982548082, 96.390, 1561.0, 39.5095
17.035069212, 96.390, 1496.0, 38.6782
17.087590343, 96.390, 1525.0, 39.0512
17.140111474, 96.390, 1527.0, 39.0768
17.192632605, 96.390, 1526.0, 39.0640
17.245153735, 96.390, 1558.0, 39.4715
17.297674866, 96.390, 1495.0, 38.6652
17.350195997, 96.390, 1502.0, 38.7556
17.402717127, 96.390, 1536.0, 39.1918
17.455238258, 96.390, 1553.0, 39.4081
17.507759389, 96.390, 1543.0, 39.2810
17.560280520, 96.390, 1485.0, 38.5357
17.612801650, 96.390, 1573.0, 39.6611
17.665322781, 96.390, 1583.0, 39.7869
17.717843912, 96.390, 1606.0, 40.0749
17.770365042, 96.390, 1538.0, 39.2173
17.822886173, 96.390, 1547.0, 39.3319
17.875407304, 96.390, 1583.0, 39.7869
17.927928434, 96.390, 1544.0, 39.2938
17.980449565, 96.390, 1567.0, 39.5854
18.032970696, 96.390, 1640.0, 40.4969
18.085491827, 96.390, 1765.0, 42.0119
18.138012957, 96.390, 1971.0, 44.3959
18.190534088, 96.390, 2236.0, 47.2864
18.243055219, 96.390, 2533.0, 50.3289
18.295576349, 96.390, 2929.0, 54.1202
18.348097480, 96.390, 3177.0, 56.3649
18.400618611, 96.390, 3478.0, 58.9746
18.453139742, 96.390, 3818.0, 61.7900
18.505660872, 96.390, 3978.0, 63.0714
18.558182003, 96.390, 4020.0, 63.4035
18.610703134, 96.390, 4071.0, 63.8044
18.663224264, 96.390, 4324.0, 65.7571
18.715745395, 96.390, 5120.0, 71.5542
18.768266526, 96.390, 5624.0, 74.9933
18.820787657, 96.390, 4840.0, 69.5701
18.873308787, 96.390, 3770.0, 61.4003
18.925829918, 96.390, 3056.0, 55.2811
18.978351049, 96.390, 2866.0, 53.5350
19.030872179, 96.390, 2186.0, 46.7547
19.083393310, 96.390, 2086.0, 45.6727
19.135914441, 96.390, 1999.0, 44.7102
19.188435572, 96.390, 1780.0, 42.1900
19.240956702, 96.390, 1750.0, 41.8330
19.293477833, 96.390, 1714.0, 41.4005
19.345998964, 96.390, 1825.0, 42.7200
19.398520094, 96.390, 1752.0, 41.8569
19.451041225, 96.390, 1784.0, 42.2374
19.503562356, 96.390, 1763.0, 41.9881
19.556083486, 96.390, 1690.0, 41.1096
19.608604617, 96.390, 1748.0, 41.8091
19.661125748, 96.390, 1786.0, 42.2611
19.713646879, 96.390, 1756.0, 41.9047
19.766168009, 96.390, 1680.0, 40.9878
19.818689140, 96.390, 1810.0, 42.5441
19.871210271, 96.390, 1693.0, 41.1461
19.923731401, 96.390, 1828.0, 42.7551
19.976252532, 96.390, 1968.0, 44.3621
20.028773663, 96.390, 2098.0, 45.8039
20.081294794, 96.390, 2257.0, 47.5079
20.133815924, 96.390, 2532.0, 50.3190
20.186337055, 96.390, 3210.0, 56.6569
20.238858186, 96.390, 4416.0, 66.4530
20.291379316, 96.390, 5503.0, 74.1822
20.343900447, 96.390, 5056.0, 71.1056
20.396421578, 96.390, 4464.0, 66.8132
20.448942709, 96.390, 4061.0, 63.7260
20.501463839, 96.390, 3441.0, 58.6600
20.553984970, 96.390, 2968.0, 54.4794
20.606506101, 96.390, 2811.0, 53.0189
20.659027231, 96.390, 2748.0, 52.4214
20.711548362, 96.390, 2991.0, 54.6900
20.764069493, 96.390, 2587.0, 50.8626
20.816590623, 96.390, 2198.0, 46.8828
20.869111754, 96.390, 2096.0, 45.7821
20.921632885, 96.390, 1957.0, 44.2380
20.974154016, 96.390, 1900.0, 43.5890
21.026675146, 96.390, 1853.0, 43.0465
21.079196277, 96.390, 1773.0, 42.1070
21.131717408, 96.390, 1837.0, 42.8602
21.184238538, 96.390, 1872.0, 43.2666
21.236759669, 96.390, 1909.0, 43.6921
21.289280800, 96.390, 2172.0, 46.6047
21.341801931, 96.390, 2209.0, 47.0000
21.394323061, 96.390, 2048.0, 45.2548
21.446844192, 96.390, 1912.0, 43.7264
21.499365323, 96.390, 1861.0, 43.1393
21.551886453, 96.390, 2261.0, 47.5500
21.604407584, 96.390, 2803.0, 52.9434
21.656928715, 96.390, 3279.0, 57.2626
21.709449846, 96.390, 2905.0, 53.8981
21.761970976, 96.390, 2225.0, 47.1699
21.814492107, 96.390, 1897.0, 43.5546
21.867013238, 96.390, 1779.0, 42.1782
21.919534368, 96.390, 1741.0, 41.7253
21.972055499, 96.390, 1799.0, 42.4146
22.024576630, 96.390, 1743.0, 41.7493
22.077097761, 96.390, 1737.0, 41.6773
22.129618891, 96.390, 1818.0, 42.6380
22.182140022, 96.390, 1779.0, 42.1782
22.234661153, 96.390, 1795.0, 42.3674
22.287182283, 96.390, 1847.0, 42.9767
22.339703414, 96.390, 1865.0, 43.1856
22.392224545, 96.390, 1909.0, 43.6921
22.444745675, 96.390, 1915.0, 43.7607
22.497266806, 96.390, 1948.0, 44.1362
22.549787937, 96.390, 2033.0, 45.0888
22.602309068, 96.390, 2111.0, 45.9456
22.654830198, 96.390, 2083.0, 45.6399
22.707351329, 96.390, 2121.0, 46.0543
22.759872460, 96.390, 2201.0, 46.9148
22.812393590, 96.390, 2553.0, 50.5272
22.864914721, 96.390, 2763.0, 52.5642
22.917435852, 96.390, 2551.0, 50.5074
22.969956983, 96.390, 2346.0, 48.4355
23.022478113, 96.390, 2557.0, 50.5668
23.074999244, 96.390, 2539.0, 50.3885
23.127520375, 96.390, 2966.0, 54.4610
23.180041505, 96.390, 3383.0, 58.1636
23.232562636, 96.390, 3345.0, 57.8360
23.285083767, 96.390, 2691.0, 51.8748
23.337604898, 96.390, 2686.0, 51.8266
23.390126028, 96.390, 2800.0, 52.9150
23.442647159, 96.390, 2565.0, 50.6458
23.495168290, 96.390, 2380.0, 48.7852
23.547689420, 96.390, 2387.0, 48.8569
23.600210551, 96.390, 2359.0, 48.5695
23.652731682, 96.390, 2254.0, 47.4763
23.705252813, 96.390, 2122.0, 46.0652
23.757773943, 96.390, 2154.0, 46.4112
23.810295074, 96.390, 2329.0, 48.2597
23.862816205, 96.390, 2459.0, 49.5883
23.915337335, 96.390, 2669.0, 51.6624
23.967858466, 96.390, 3450.0, 58.7367
24.020379597, 96.390, 3527.0, 59.3886
24.072900727, 96.390, 2915.0, 53.9907
24.125421858, 96.390, 2397.0, 48.9592
24.177942989, 96.390, 2105.0, 45.8803
24.230464120, 96.390, 2055.0, 45.3321
24.282985250, 96.390, 1942.0, 44.0681
24.335506381, 96.390, 1918.0, 43.7950
24.388027512, 96.390, 1834.0, 42.8252
24.440548642, 96.390, 1787.0, 42.2729
24.493069773, 96.390, 1729.0, 41.5812
24.545590904, 96.390, 1746.0, 41.7852
24.598112035, 96.390, 1653.0, 40.6571
24.650633165, 96.390, 1722.0, 41.4970
24.703154296, 96.390, 1747.0, 41.7971
24.755675427, 96.390, 1703.0, 41.2674
24.808196557, 96.390, 1785.0, 42.2493
24.860717688, 96.390, 1644.0, 40.5463
24.913238819, 96.390, 1723.0, 41.5090
24.965759950, 96.390, 1647.0, 40.5832
25.018281080, 96.390, 1584.0, 39.7995
25.070802211, 96.390, 1560.0, 39.4968
25.123323342, 96.390, 1530.0, 39.1152
25.175844472, 96.390, 1541.0, 39.2556
25.228365603, 96.390, 1507.0, 38.8201
25.280886734, 96.390, 1416.0, 37.6298
25.333407864, 96.390, 1394.0, 37.3363
25.385928995, 96.390, 1424.0, 37.7359
25.438450126, 96.390, 1453.0, 38.1182
25.490971257, 96.390, 1386.0, 37.2290
25.543492387, 96.390, 1454.0, 38.1314
25.596013518, 96.390, 1390.0, 37.2827
25.648534649, 96.390, 1407.0, 37.5100
25.701055779, 96.390, 1485.0, 38.5357
25.753576910, 96.390, 1394.0, 37.3363
25.806098041, 96.390, 1408.0, 37.5233
25.858619172, 96.390, 1429.0, 37.8021
25.911140302, 96.390, 1459.0, 38.1969
25.963661433, 96.390, 1527.0, 39.0768
26.016182564, 96.390, 1614.0, 40.1746
26.068703694, 96.390, 1757.0, 41.9166
26.121224825, 96.390, 1918.0, 43.7950
26.173745956, 96.390, 1823.0, 42.6966
26.226267087, 96.390, 1587.0, 39.8372
26.278788217, 96.390, 1527.0, 39.0768
26.331309348, 96.390, 1479.0, 38.4578
26.383830479, 96.390, 1537.0, 39.2046
26.436351609, 96.390, 1550.0, 39.3700
26.488872740, 96.390, 1651.0, 40.6325
26.541393871, 96.390, 1719.0, 41.4608
26.593915002, 96.390, 1784.0, 42.2374
26.646436132, 96.390, 1729.0, 41.5812
26.698957263, 96.390, 1817.0, 42.6263
26.751478394, 96.390, 2153.0, 46.4004
26.803999524, 96.390, 2556.0, 50.5569
26.856520655, 96.390, 2204.0, 46.9468
26.909041786, 96.390, 1920.0, 43.8178
26.961562916, 96.390, 2014.0, 44.8776
27.014084047, 96.390, 2585.0, 50.8429
27.066605178, 96.390, 3073.0, 55.4346
27.119126309, 96.390, 3613.0, 60.1082
27.171647439, 96.390, 3837.0, 61.9435
27.224168570, 96.390, 3349.0, 57.8705
27.276689701, 96.390, 2487.0, 49.8698
27.329210831, 96.390, 1873.0, 43.2782
27.381731962, 96.390, 1705.0, 41.2916
27.434253093, 96.390, 1661.0, 40.7554
27.486774224, 96.390, 1621.0, 40.2616
27.539295354, 96.390, 1643.0, 40.5339
27.591816485, 96.390, 1677.0, 40.9512
27.644337616, 96.390, 1761.0, 41.9643
27.696858746, 96.390, 1894.0, 43.5201
27.749379877, 96.390, 2079.0, 45.5961
27.801901008, 96.390, 2128.0, 46.1303
27.854422139, 96.390, 2012.0, 44.8553
27.906943269, 96.390, 1911.0, 43.7150
27.959464400, 96.390, 1787.0, 42.2729
28.011985531, 96.390, 1687.0, 41.0731
28.064506661, 96.390, 1615.0, 40.1871
28.117027792, 96.390, 1559.0, 39.4842
28.169548923, 96.390, 1556.0, 39.4462
28.222070054, 96.390, 1424.0, 37.7359
28.274591184, 96.390, 1435.0, 37.8814
28.327112315, 96.390, 1440.0, 37.9473
28.379633446, 96.390, 1583.0, 39.7869
28.432154576, 96.390, 1461.0, 38.2230
28.484675707, 96.390, 1524.0, 39.0384
28.537196838, 96.390, 1497.0, 38.6911
28.589717968, 96.390, 1502.0, 38.7556
28.642239099, 96.390, 1367.0, 36.9730
28.694760230, 96.390, 1405.0, 37.4833
28.747281361, 96.390, 1380.0, 37.1484
28.799802491, 96.390, 1419.0, 37.6696
28.852323622, 96.390, 1454.0, 38.1314
28.904844753, 96.390, 1498.0, 38.7040
28.957365883, 96.390, 1484.0, 38.5227
29.009887014, 96.390, 1447.0, 38.0395
29.062408145, 96.390, 1543.0, 39.2810
29.114929276, 96.390, 1638.0, 40.4722
29.167450406, 96.390, 1983.0, 44.5309
29.219971537, 96.390, 2086.0, 45.6727
29.272492668, 96.390, 2544.0, 50.4381
29.325013798, 96.390, 2689.0, 51.8556
29.377534929, 96.390, 2313.0, 48.0937
29.430056060, 96.390, 2220.0, 47.1169
29.482577191, 96.390, 2435.0, 49.3457
29.535098321, 96.390, 2103.0, 45.8585
29.587619452, 96.390, 1887.0, 43.4396
29.640140583, 96.390, 1695.0, 41.1704
29.692661713, 96.390, 1702.0, 41.2553
29.745182844, 96.390, 1706.0, 41.3038
29.797703975, 96.390, 1684.0, 41.0366
29.850225105, 96.390, 1854.0, 43.0581
29.902746236, 96.390, 2340.0, 48.3735
29.955267367, 96.390, 3023.0, 54.9818
30.007788498, 96.390, 2783.0, 52.7541
30.060309628, 96.390, 2264.0, 47.5815
30.112830759, 96.390, 1829.0, 42.7668
30.165351890, 96.390, 1582.0, 39.7744
30.217873020, 96.390, 1511.0, 38.8716
30.270394151, 96.390, 1449.0, 38.0657
30.322915282, 96.390, 1459.0, 38.1969
30.375436413, 96.390, 1472.0, 38.3667
30.427957543, 96.390, 1562.0, 39.5221
30.480478674, 96.390, 1428.0, 37.7889
30.532999805, 96.390, 1427.0, 37.7757
30.585520935, 96.390, 1518.0, 38.9615
30.638042066, 96.390, 1548.0, 39.3446
30.690563197, 96.390, 1603.0, 40.0375
30.743084328, 96.390, 1776.0, 42.1426
30.795605458, 96.390, 1861.0, 43.1393
30.848126589, 96.390, 2062.0, 45.4093
30.900647720, 96.390, 1895.0, 43.5316
30.953168850, 96.390, 1768.0, 42.0476
31.005689981, 96.390, 1528.0, 39.0896
31.058211112, 96.390, 1563.0, 39.5348
31.110732243, 96.390, 1447.0, 38.0395
31.163253373, 96.390, 1570.0, 39.6232
31.215774504, 96.390, 1964.0, 44.3170
31.268295635, 96.390, 2356.0, 48.5386
31.320816765, 96.390, 2364.0, 48.6210
31.373337896, 96.390, 2353.0, 48.5077
31.425859027, 96.390, 1830.0, 42.7785
31.478380157, 96.390, 1574.0, 39.6737
31.530901288, 96.390, 1486.0, 38.5487
31.583422419, 96.390, 1411.0, 37.5633
31.635943550, 96.390, 1331.0, 36.4829
31.688464680, 96.390, 1356.0, 36.8239
31.740985811, 96.390, 1366.0, 36.9594
31.793506942, 96.390, 1356.0, 36.8239
31.846028072, 96.390, 1584.0, 39.7995
31.898549203, 96.390, 1694.0, 41.1582
31.951070334, 96.390, 1737.0, 41.6773
32.003591465, 96.390, 1620.0, 40.2492
32.056112595, 96.390, 1749.0, 41.8210
32.108633726, 96.390, 1777.0, 42.1545
32.161154857, 96.390, 1618.0, 40.2244
32.213675987, 96.390, 1864.0, 43.1741
32.266197118, 96.390, 2211.0, 47.0213
32.318718249, 96.390, 1950.0, 44.1588
32.371239380, 96.390, 1598.0, 39.9750
32.423760510, 96.390, 1392.0, 37.3095
32.476281641, 96.390, 1358.0, 36.8511
32.528802772, 96.390, 1554.0, 39.4208
32.581323902, 96.390, 1723.0, 41.5090
32.633845033, 96.390, 1677.0, 40.9512
32.686366164, 96.390, 1571.0, 39.6358
32.738887295, 96.390, 1599.0, 39.9875
32.791408425, 96.390, 1527.0, 39.0768
32.843929556, 96.390, 1418.0, 37.6563
32.896450687, 96.390, 1480.0, 38.4708
32.948971817, 96.390, 1648.0, 40.5956
33.001492948, 96.390, 1624.0, 40.2989
33.054014079, 96.390, 1689.0, 41.0974
33.106535209, 96.390, 1670.0, 40.8656
33.159056340, 96.390, 1582.0, 39.7744
33.211577471, 96.390, 1626.0, 40.3237
33.264098602, 96.390, 1619.0, 40.2368
33.316619732, 96.390, 1576.0, 39.6989
33.369140863, 96.390, 1559.0, 39.4842
33.421661994, 96.390, 1561.0, 39.5095
33.474183124, 96.390, 1577.0, 39.7115
33.526704255, 96.390, 1531.0, 39.1280
33.579225386, 96.390, 1537.0, 39.2046
33.631746517, 96.390, 1658.0, 40.7185
33.684267647, 96.390, 1731.0, 41.6053
33.736788778, 96.390, 1727.0, 41.5572
33.789309909, 96.390, 1561.0, 39.5095
33.841831039, 96.390, 1788.0, 42.2847
33.894352170, 96.390, 1931.0, 43.9431
33.946873301, 96.390, 2121.0, 46.0543
33.999394432, 96.390, 2409.0, 49.0816
34.051915562, 96.390, 2517.0, 50.1697
34.104436693, 96.390, 2825.0, 53.1507
34.156957824, 96.390, 3245.0, 56.9649
34.209478954, 96.390, 3296.0, 57.4108
34.262000085, 96.390, 3057.0, 55.2901
34.314521216, 96.390, 2618.0, 51.1664
34.367042346, 96.390, 2407.0, 49.0612
34.419563477, 96.390, 2507.0, 50.0700
34.472084608, 96.390, 2726.0, 52.2111
34.524605739, 96.390, 2981.0, 54.5985
34.577126869, 96.390, 3254.0, 57.0438
34.629648000, 96.390, 2854.0, 53.4228
34.682169131, 96.390, 2483.0, 49.8297
34.734690261, 96.390, 2214.0, 47.0532
34.787211392, 96.390, 2064.0, 45.4313
34.839732523, 96.390, 2093.0, 45.7493
34.892253654, 96.390, 1946.0, 44.1135
34.944774784, 96.390, 1866.0, 43.1972
34.997295915, 96.390, 1913.0, 43.7379
35.049817046, 96.390, 2057.0, 45.3542
35.102338176, 96.390, 2045.0, 45.2217
35.154859307, 96.390, 1994.0, 44.6542
35.207380438, 96.390, 1919.0, 43.8064
35.259901569, 96.390, 1910.0, 43.7035
35.312422699, 96.390, 1684.0, 41.0366
35.364943830, 96.390, 1659.0, 40.7308
35.417464961, 96.390, 1637.0, 40.4599
35.469986091, 96.390, 1618.0, 40.2244
35.522507222, 96.390, 1522.0, 39.0128
35.575028353, 96.390, 1559.0, 39.4842
35.627549484, 96.390, 1633.0, 40.4104
35.680070614, 96.390, 1665.0, 40.8044
35.732591745, 96.390, 1772.0, 42.0951
35.785112876, 96.390, 1708.0, 41.3280
35.837634006, 96.390, 1735.0, 41.6533
35.890155137, 96.390, 1978.0, 44.4747
35.942676268, 96.390, 2298.0, 47.9375
35.995197398, 96.390, 2083.0, 45.6399
36.047718529, 96.390, 2149.0, 46.3573
36.100239660, 96.390, 2096.0, 45.7821
36.152760791, 96.390, 2391.0, 48.8979
36.205281921, 96.390, 2694.0, 51.9038
36.257803052, 96.390, 2127.0, 46.1194
36.310324183, 96.390, 1962.0, 44.2945
36.362845313, 96.390, 1567.0, 39.5854
36.415366444, 96.390, 1412.0, 37.5766
36.467887575, 96.390, 1465.0, 38.2753
36.520408706, 96.390, 1517.0, 38.9487
36.572929836, 96.390, 1473.0, 38.3797
36.625450967, 96.390, 1451.0, 38.0920
36.677972098, 96.390, 1364.0, 36.9324
36.730493228, 96.390, 1255.0, 35.4260
36.783014359, 96.390, 1212.0, 34.8138
36.835535490, 96.390, 1244.0, 35.2704
36.888056621, 96.390, 1279.0, 35.7631
36.940577751, 96.390, 1231.0, 35.0856
36.993098882, 96.390, 1303.0, 36.0971
37.045620013, 96.390, 1272.0, 35.6651
37.098141143, 96.390, 1388.0, 37.2559
37.150662274, 96.390, 1389.0, 37.2693
37.203183405, 96.390, 1510.0, 38.8587
37.255704535, 96.390, 1551.0, 39.3827
37.308225666, 96.390, 1441.0, 37.9605
37.360746797, 96.390, 1450.0, 38.0789
37.413267928, 96.390, 1489.0, 38.5876
37.465789058, 96.390, 1728.0, 41.5692
37.518310189, 96.390, 1716.0, 41.4246
37.570831320, 96.390, 1717.0, 41.4367
37.623352450, 96.390, 1589.0, 39.8623
37.675873581, 96.390, 1608.0, 40.0999
37.728394712, 96.390, 1523.0, 39.0256
37.780915843, 96.390, 1750.0, 41.8330
37.833436973, 96.390, 1880.0, 43.3590
37.885958104, 96.390, 1770.0, 42.0714
37.938479235, 96.390, 1786.0, 42.2611
37.991000365, 96.390, 1765.0, 42.0119
38.043521496, 96.390, 1671.0, 40.8779
38.096042627, 96.390, 1595.0, 39.9375
38.148563758, 96.390, 1547.0, 39.3319
38.201084888, 96.390, 1540.0, 39.2428
38.253606019, 96.390, 1480.0, 38.4708
38.306127150, 96.390, 1417.0, 37.6431
38.358648280, 96.390, 1298.0, 36.0278
38.411169411, 96.390, 1320.0, 36.3318
38.463690542, 96.390, 1292.0, 35.9444
38.516211673, 96.390, 1280.0, 35.7771
38.568732803, 96.390, 1356.0, 36.8239
38.621253934, 96.390, 1291.0, 35.9305
38.673775065, 96.390, 1273.0, 35.6791
38.726296195, 96.390, 1301.0, 36.0694
38.778817326, 96.390, 1323.0, 36.3731
38.831338457, 96.390, 1279.0, 35.7631
38.883859587, 96.390, 1267.0, 35.5949
38.936380718, 96.390, 1281.0, 35.7911
38.988901849, 96.390, 1231.0, 35.0856
39.041422980, 96.390, 1203.0, 34.6843
39.093944110, 96.390, 1304.0, 36.1109
39.146465241, 96.390, 1252.0, 35.3836
39.198986372, 96.390, 1353.0, 36.7831
39.251507502, 96.390, 1408.0, 37.5233
39.304028633, 96.390, 1342.0, 36.6333
39.356549764, 96.390, 1280.0, 35.7771
39.409070895, 96.390, 1362.0, 36.9053
39.461592025, 96.390, 1346.0, 36.6879
39.514113156, 96.390, 1371.0, 37.0270
39.566634287, 96.390, 1359.0, 36.8646
39.619155417, 96.390, 1345.0, 36.6742
39.671676548, 96.390, 1345.0, 36.6742
39.724197679, 96.390, 1365.0, 36.9459
39.776718810, 96.390, 1469.0, 38.3275
39.829239940, 96.390, 1513.0, 38.8973
39.881761071, 96.390, 1428.0, 37.7889
39.934282202, 96.390, 1413.0, 37.5899
39.986803332, 96.390, 1469.0, 38.3275
40.039324463, 96.390, 1459.0, 38.1969
40.091845594, 96.390, 1454.0, 38.1314
40.144366725, 96.390, 1575.0, 39.6863
40.196887855, 96.390, 1606.0, 40.0749
40.249408986, 96.390, 1643.0, 40.5339
40.301930117, 96.390, 1812.0, 42.5676
40.354451247, 96.390, 2046.0, 45.2327
40.406972378, 96.390, 2316.0, 48.1248
40.459493509, 96.390, 2598.0, 50.9706
40.512014639, 96.390, 2875.0, 53.6190
40.564535770, 96.390, 3022.0, 54.9727
40.617056901, 96.390, 3022.0, 54.9727
40.669578032, 96.390, 2837.0, 53.2635
40.722099162, 96.390, 2459.0, 49.5883
40.774620293, 96.390, 1965.0, 44.3283
40.827141424, 96.390, 1651.0, 40.6325
40.879662554, 96.390, 1427.0, 37.7757
40.932183685, 96.390, 1350.0, 36.7423
40.984704816, 96.390, 1285.0, 35.8469
41.037225947, 96.390, 1249.0, 35.3412
41.089747077, 96.390, 1277.0, 35.7351
41.142268208, 96.390, 1199.0, 34.6266
41.194789339, 96.390, 1232.0, 35.0999
41.247310469, 96.390, 1208.0, 34.7563
41.299831600, 96.390, 1096.0, 33.1059
41.352352731, 96.390, 1154.0, 33.9706
41.404873862, 96.390, 1127.0, 33.5708
41.457394992, 96.390, 1176.0, 34.2929
41.509916123, 96.390, 1279.0, 35.7631
41.562437254, 96.390, 1200.0, 34.6410
41.614958384, 96.390, 1228.0, 35.0428
41.667479515, 96.390, 1200.0, 34.6410
41.720000646, 96.390, 1255.0, 35.4260
41.772521776, 96.390, 1386.0, 37.2290
41.825042907, 96.390, 1216.0, 34.8712
41.877564038, 96.390, 1163.0, 34.1028
41.930085169, 96.390, 1103.0, 33.2114
41.982606299, 96.390, 1085.0, 32.9393
42.035127430, 96.390, 1179.0, 34.3366
42.087648561, 96.390, 1390.0, 37.2827
42.140169691, 96.390, 1639.0, 40.4846
42.192690822, 96.390, 1547.0, 39.3319
42.245211953, 96.390, 1447.0, 38.0395
42.297733084, 96.390, 1344.0, 36.6606
42.350254214, 96.390, 1231.0, 35.0856
42.402775345, 96.390, 1093.0, 33.0606
42.455296476, 96.390, 1102.0, 33.1964
42.507817606, 96.390, 981.0, 31.3209
42.560338737, 96.390, 1012.0, 31.8119
42.612859868, 96.390, 1003.0, 31.6702
42.665380999, 96.390, 1094.0, 33.0757
42.717902129, 96.390, 1162.0, 34.0881
42.770423260, 96.390, 1064.0, 32.6190
42.822944391, 96.390, 1066.0, 32.6497
42.875465521, 96.390, 1067.0, 32.6650
42.927986652, 96.390, 1030.0, 32.0936
42.980507783, 96.390, 950.0, 30.8221
43.033028914, 96.390, 993.0, 31.5119
43.085550044, 96.390, 1028.0, 32.0624
43.138071175, 96.390, 1191.0, 34.5109
43.190592306, 96.390, 998.0, 31.5911
43.243113436, 96.390, 1010.0, 31.7805
43.295634567, 96.390, 912.0, 30.1993
43.348155698, 96.390, 925.0, 30.4138
43.400676828, 96.390, 1024.0, 32.0000
43.453197959, 96.390, 988.0, 31.4325
43.505719090, 96.390, 1029.0, 32.0780
43.558240221, 96.390, 986.0, 31.4006
43.610761351, 96.390, 1013.0, 31.8277
43.663282482, 96.390, 1034.0, 32.1559
43.715803613, 96.390, 953.0, 30.8707
43.768324743, 96.390, 930.0, 30.4959
43.820845874, 96.390, 978.0, 31.2730
43.873367005, 96.390, 1053.0, 32.4500
43.925888136, 96.390, 1022.0, 31.9687
43.978409266, 96.390, 1004.0, 31.6860
44.030930397, 96.390, 998.0, 31.5911
44.083451528, 96.390, 1075.0, 32.7872
44.135972658, 96.390, 1198.0, 34.6121
44.188493789, 96.390, 1187.0, 34.4529
44.241014920, 96.390, 1166.0, 34.1467
44.293536051, 96.390, 1170.0, 34.2053
44.346057181, 96.390, 1215.0, 34.8569
44.398578312, 96.390, 1025.0, 32.0156
44.451099443, 96.390, 1044.0, 32.3110
44.503620573, 96.390, 991.0, 31.4802
44.556141704, 96.390, 1071.0, 32.7261
44.608662835, 96.390, 1080.0, 32.8634
44.661183966, 96.390, 1021.0, 31.9531
44.713705096, 96.390, 1041.0, 32.2645
44.766226227, 96.390, 1082.0, 32.8938
44.818747358, 96.390, 1035.0, 32.1714
44.871268488, 96.390, 1045.0, 32.3265
44.923789619, 96.390, 1067.0, 32.6650
44.976310750, 96.390, 1015.0, 31.8591
45.028831880, 96.390, 928.0, 30.4631
45.081353011, 96.390, 1004.0, 31.6860
45.133874142, 96.390, 1056.0, 32.4962
45.186395273, 96.390, 1074.0, 32.7719
45.238916403, 96.390, 1008.0, 31.7490
45.291437534, 96.390, 1025.0, 32.0156
45.343958665, 96.390, 974.0, 31.2090
45.396479795, 96.390, 1014.0, 31.8434
45.449000926, 96.390, 1021.0, 31.9531
45.501522057, 96.390, 1045.0, 32.3265
45.554043188, 96.390, 1097.0, 33.1210
45.606564318, 96.390, 1104.0, 33.2265
45.659085449, 96.390, 1020.0, 31.9374
45.711606580, 96.390, 1116.0, 33.4066
45.764127710, 96.390, 1116.0, 33.4066
45.816648841, 96.390, 1117.0, 33.4215
45.869169972, 96.390, 1070.0, 32.7109
45.921691103, 96.390, 1038.0, 32.2180
45.974212233, 96.390, 1101.0, 33.1813
46.026733364, 96.390, 1056.0, 32.4962
46.079254495, 96.390, 1099.0, 33.1512
46.131775625, 96.390, 1222.0, 34.9571
46.184296756, 96.390, 1327.0, 36.4280
46.236817887, 96.390, 1370.0, 37.0135
46.289339017, 96.390, 1248.0, 35.3270
46.341860148, 96.390, 1204.0, 34.6987
46.394381279, 96.390, 1121.0, 33.4813
46.446902410, 96.390, 1112.0, 33.3467
46.499423540, 96.390, 1071.0, 32.7261
46.551944671, 96.390, 1033.0, 32.1403
46.604465802, 96.390, 1029.0, 32.0780
46.656986932, 96.390, 1080.0, 32.8634
46.709508063, 96.390, 1155.0, 33.9853
46.762029194, 96.390, 1070.0, 32.7109
46.814550325, 96.390, 1045.0, 32.3265
46.867071455, 96.390, 1036.0, 32.1870
46.919592586, 96.390, 970.0, 31.1448
46.972113717, 96.390, 1011.0, 31.7962
47.024634847, 96.390, 973.0, 31.1929
47.077155978, 96.390, 995.0, 31.5436
47.129677109, 96.390, 1022.0, 31.9687
47.182198240, 96.390, 1014.0, 31.8434
47.234719370, 96.390, 1054.0, 32.4654
47.287240501, 96.390, 1074.0, 32.7719
47.339761632, 96.390, 1179.0, 34.3366
47.392282762, 96.390, 1203.0, 34.6843
47.444803893, 96.390, 1198.0, 34.6121
47.497325024, 96.390, 1212.0, 34.8138
47.549846155, 96.390, 1091.0, 33.0303
47.602367285, 96.390, 1034.0, 32.1559
47.654888416, 96.390, 1062.0, 32.5883
47.707409547, 96.390, 1046.0, 32.3419
47.759930677, 96.390, 1164.0, 34.1174
47.812451808, 96.390, 1139.0, 33.7491
47.864972939, 96.390, 1095.0, 33.0908
47.917494069, 96.390, 1080.0, 32.8634
47.970015200, 96.390, 1057.0, 32.5115
48.022536331, 96.390, 1029.0, 32.0780
48.075057462, 96.390, 1052.0, 32.4345
48.127578592, 96.390, 982.0, 31.3369
48.180099723, 96.390, 938.0, 30.6268
48.232620854, 96.390, 1010.0, 31.7805
48.285141984, 96.390, 947.0, 30.7734
48.337663115, 96.390, 1048.0, 32.3728
48.390184246, 96.390, 1140.0, 33.7639
48.442705377, 96.390, 1281.0, 35.7911
48.495226507, 96.390, 1195.0, 34.5688
48.547747638, 96.390, 1182.0, 34.3802
48.600268769, 96.390, 1040.0, 32.2490
48.652789899, 96.390, 1046.0, 32.3419
48.705311030, 96.390, 938.0, 30.6268
48.757832161, 96.390, 932.0, 30.5287
48.810353292, 96.390, 1028.0, 32.0624
48.862874422, 96.390, 958.0, 30.9516
48.915395553, 96.390, 952.0, 30.8545
48.967916684, 96.390, 1058.0, 32.5269
49.020437814, 96.390, 1077.0, 32.8177
49.072958945, 96.390, 1097.0, 33.1210
49.125480076, 96.390, 1167.0, 34.1614
49.178001207, 96.390, 1143.0, 33.8083
49.230522337, 96.390, 1111.0, 33.3317
49.283043468, 96.390, 937.0, 30.6105
49.335564599, 96.390, 903.0, 30.0500
49.388085729, 96.390, 942.0, 30.6920
49.440606860, 96.390, 875.0, 29.5804
49.493127991, 96.390, 874.0, 29.5635
49.545649121, 96.390, 898.0, 29.9666
49.598170252, 96.390, 920.0, 30.3315
49.650691383, 96.390, 1027.0, 32.0468
49.703212514, 96.390, 957.0, 30.9354
49.755733644, 96.390, 1033.0, 32.1403
49.808254775, 96.390, 1026.0, 32.0312
49.860775906, 96.390, 923.0, 30.3809
49.913297036, 96.390, 894.0, 29.8998
49.965818167, 96.390, 896.0, 29.9333
50.018339298, 96.390, 854.0, 29.2233
50.070860429, 96.390, 811.0, 28.4781
50.123381559, 96.390, 837.0, 28.9310
50.175902690, 96.390, 825.0, 28.7228
50.228423821, 96.390, 855.0, 29.2404
50.280944951, 96.390, 826.0, 28.7402
50.333466082, 96.390, 904.0, 30.0666
50.385987213, 96.390, 898.0, 29.9666
50.438508344, 96.390, 1037.0, 32.2025
50.491029474, 96.390, 1093.0, 33.0606
50.543550605, 96.390, 1030.0, 32.0936
50.596071736, 96.390, 1008.0, 31.7490
50.648592866, 96.390, 958.0, 30.9516
50.701113997, 96.390, 971.0, 31.1609
50.753635128, 96.390, 933.0, 30.5450
50.806156258, 96.390, 968.0, 31.1127
50.858677389, 96.390, 927.0, 30.4467
50.911198520, 96.390, 920.0, 30.3315
50.963719651, 96.390, 974.0, 31.2090
51.016240781, 96.390, 975.0, 31.2250
51.068761912, 96.390, 1022.0, 31.9687
51.121283043, 96.390, 991.0, 31.4802
51.173804173, 96.390, 896.0, 29.9333
51.226325304, 96.390, 918.0, 30.2985
51.278846435, 96.390, 865.0, 29.4109
51.331367566, 96.390, 797.0, 28.2312
51.383888696, 96.390, 788.0, 28.0713
51.436409827, 96.390, 786.0, 28.0357
51.488930958, 96.390, 788.0, 28.0713
51.541452088, 96.390, 791.0, 28.1247
51.593973219, 96.390, 816.0, 28.5657
51.646494350, 96.390, 860.0, 29.3258
51.699015481, 96.390, 807.0, 28.4077
51.751536611, 96.390, 799.0, 28.2666
51.804057742, 96.390, 930.0, 30.4959
51.856578873, 96.390, 963.0, 31.0322
51.909100003, 96.390, 911.0, 30.1828
51.961621134, 96.390, 897.0, 29.9500
52.014142265, 96.390, 911.0, 30.1828
52.066663396, 96.390, 885.0, 29.7489
52.119184526, 96.390, 959.0, 30.9677
52.171705657, 96.390, 866.0, 29.4279
52.224226788, 96.390, 809.0, 28.4429
52.276747918, 96.390, 889.0, 29.8161
52.329269049, 96.390, 838.0, 28.9482
52.381790180, 96.390, 885.0, 29.7489
52.434311310, 96.390, 913.0, 30.2159
52.486832441, 96.390, 970.0, 31.1448
52.539353572, 96.390, 1050.0, 32.4037
52.591874703, 96.390, 1060.0, 32.5576
52.644395833, 96.390, 1121.0, 33.4813
52.696916964, 96.390, 1104.0, 33.2265
52.749438095, 96.390, 1166.0, 34.1467
52.801959225, 96.390, 1129.0, 33.6006
52.854480356, 96.390, 1157.0, 34.0147
52.907001487, 96.390, 1151.0, 33.9264
52.959522618, 96.390, 1182.0, 34.3802
53.012043748, 96.390, 1301.0, 36.0694
53.064564879, 96.390, 1396.0, 37.3631
53.117086010, 96.390, 1480.0, 38.4708
53.169607140, 96.390, 1534.0, 39.1663
53.222128271, 96.390, 1380.0, 37.1484
53.274649402, 96.390, 1313.0, 36.2353
53.327170533, 96.390, 1280.0, 35.7771
53.379691663, 96.390, 1166.0, 34.1467
53.432212794, 96.390, 971.0, 31.1609
53.484733925, 96.390, 1007.0, 31.7333
53.537255055, 96.390, 884.0, 29.7321
53.589776186, 96.390, 906.0, 30.0998
53.642297317, 96.390, 855.0, 29.2404
53.694818448, 96.390, 803.0, 28.3373
53.747339578, 96.390, 817.0, 28.5832
53.799860709, 96.390, 841.0, 29.0000
53.852381840, 96.390, 943.0, 30.7083
53.904902970, 96.390, 1032.0, 32.1248
53.957424101, 96.390, 1043.0, 32.2955
54.009945232, 96.390, 984.0, 31.3688
54.062466362, 96.390, 958.0, 30.9516
54.114987493, 96.390, 916.0, 30.2655
54.167508624, 96.390, 847.0, 29.1033
54.220029755, 96.390, 948.0, 30.7896
54.272550885, 96.390, 916.0, 30.2655
54.325072016, 96.390, 1002.0, 31.6544
54.377593147, 96.390, 988.0, 31.4325
54.430114277, 96.390, 945.0, 30.7409
54.482635408, 96.390, 885.0, 29.7489
54.535156539, 96.390, 783.0, 27.9821
54.587677670, 96.390, 722.0, 26.8701
54.640198800, 96.390, 743.0, 27.2580
54.692719931, 96.390, 780.0, 27.9285
54.745241062, 96.390, 672.0, 25.9230
54.797762192, 96.390, 745.0, 27.2947
54.850283323, 96.390, 697.0, 26.4008
54.902804454, 96.390, 710.0, 26.6458
54.955325585, 96.390, 693.0, 26.3249
55.007846715, 96.390, 679.0, 26.0576
55.060367846, 96.390, 691.0, 26.2869
55.112888977, 96.390, 687.0, 26.2107
55.165410107, 96.390, 662.0, 25.7294
55.217931238, 96.390, 672.0, 25.9230
55.270452369, 96.390, 767.0, 27.6948
55.322973499, 96.390, 694.0, 26.3439
55.375494630, 96.390, 784.0, 28.0000
55.428015761, 96.390, 767.0, 27.6948
55.480536892, 96.390, 726.0, 26.9444
55.533058022, 96.390, 716.0, 26.7582
55.585579153, 96.390, 696.0, 26.3818
55.638100284, 96.390, 695.0, 26.3629
55.690621414, 96.390, 654.0, 25.5734
55.743142545, 96.390, 680.0, 26.0768
55.795663676, 96.390, 683.0, 26.1343
55.848184807, 96.390, 774.0, 27.8209
55.900705937, 96.390, 756.0, 27.4955
55.953227068, 96.390, 705.0, 26.5518
56.005748199, 96.390, 788.0, 28.0713
56.058269329, 96.390, 824.0, 28.7054
56.110790460, 96.390, 786.0, 28.0357
56.163311591, 96.390, 824.0, 28.7054
56.215832722, 96.390, 831.0, 28.8271
56.268353852, 96.390, 773.0, 27.8029
56.320874983, 96.390, 741.0, 27.2213
56.373396114, 96.390, 658.0, 25.6515
56.425917244, 96.390, 745.0, 27.2947
56.478438375, 96.390, 787.0, 28.0535
56.530959506, 96.390, 809.0, 28.4429
56.583480637, 96.390, 688.0, 26.2298
56.636001767, 96.390, 798.0, 28.2489
56.688522898, 96.390, 733.0, 27.0740
56.741044029, 96.390, 666.0, 25.8070
56.793565159, 96.390, 603.0, 24.5561
56.846086290, 96.390, 666.0, 25.8070
56.898607421, 96.390, 670.0, 25.8844
56.951128551, 96.390, 645.0, 25.3969
57.003649682, 96.390, 693.0, 26.3249
57.056170813, 96.390, 725.0, 26.9258
57.108691944, 96.390, 750.0, 27.3861
57.161213074, 96.390, 838.0, 28.9482
57.213734205, 96.390, 815.0, 28.5482
57.266255336, 96.390, 857.0, 29.2746
57.318776466, 96.390, 827.0, 28.7576
57.371297597, 96.390, 870.0, 29.4958
57.423818728, 96.390, 813.0, 28.5132
57.476339859, 96.390, 763.0, 27.6225
57.528860989, 96.390, 823.0, 28.6880
57.581382120, 96.390, 836.0, 28.9137
57.633903251, 96.390, 815.0, 28.5482
57.686424381, 96.390, 852.0, 29.1890
57.738945512, 96.390, 826.0, 28.7402
57.791466643, 96.390, 779.0, 27.9106
57.843987774, 96.390, 755.0, 27.4773
57.896508904, 96.390, 758.0, 27.5318
57.949030035, 96.390, 670.0, 25.8844
58.001551166, 96.390, 739.0, 27.1846
58.054072296, 96.390, 783.0, 27.9821
58.106593427, 96.390, 728.0, 26.9815
58.159114558, 96.390, 694.0, 26.3439
58.211635689, 96.390, 680.0, 26.0768
58.264156819, 96.390, 659.0, 25.6710
58.316677950, 96.390, 682.0, 26.1151
58.369199081, 96.390, 658.0, 25.6515
58.421720211, 96.390, 708.0, 26.6083
58.474241342, 96.390, 702.0, 26.4953
58.526762473, 96.390, 682.0, 26.1151
58.579283603, 96.390, 757.0, 27.5136
58.631804734, 96.390, 788.0, 28.0713
58.684325865, 96.390, 802.0, 28.3196
58.736846996, 96.390, 784.0, 28.0000
58.789368126, 96.390, 735.0, 27.1109
58.841889257, 96.390, 729.0, 27.0000
58.894410388, 96.390, 718.0, 26.7955
58.946931518, 96.390, 744.0, 27.2764
58.999452649, 96.390, 707.0, 26.5895
59.051973780, 96.390, 791.0, 28.1247
59.104494911, 96.390, 732.0, 27.0555
59.157016041, 96.390, 692.0, 26.3059
59.209537172, 96.390, 758.0, 27.5318
59.262058303, 96.390, 778.0, 27.8927
59.314579433, 96.390, 748.0, 27.3496
59.367100564, 96.390, 726.0, 26.9444
59.419621695, 96.390, 742.0, 27.2397
59.472142826, 96.390, 738.0, 27.1662
59.524663956, 96.390, 738.0, 27.1662
59.577185087, 96.390, 690.0, 26.2679
59.629706218, 96.390, 668.0, 25.8457
59.682227348, 96.390, 659.0, 25.6710
59.734748479, 96.390, 687.0, 26.2107
59.787269610, 96.390, 660.0, 25.6905
59.839790740, 96.390, 679.0, 26.0576
59.892311871, 96.390, 692.0, 26.3059
59.944833002, 96.390, 641.0, 25.3180
59.997354133, 96.390, 695.0, 26.3629
60.049875263, 96.390, 649.0, 25.4755
60.102396394, 96.390, 735.0, 27.1109
60.154917525, 96.390, 741.0, 27.2213
60.207438655, 96.390, 768.0, 27.7128
60.259959786, 96.390, 794.0, 28.1780
60.312480917, 96.390, 730.0, 27.0185
60.365002048, 96.390, 833.0, 28.8617
60.417523178, 96.390, 851.0, 29.1719
60.470044309, 96.390, 911.0, 30.1828
60.522565440, 96.390, 911.0, 30.1828
60.575086570, 96.390, 894.0, 29.8998
60.627607701, 96.390, 1079.0, 32.8481
60.680128832, 96.390, 1071.0, 32.7261
60.732649963, 96.390, 1107.0, 33.2716
60.785171093, 96.390, 1163.0, 34.1028
60.837692224, 96.390, 1214.0, 34.8425
60.890213355, 96.390, 1271.0, 35.6511
60.942734485, 96.390, 1193.0, 34.5398
60.995255616, 96.390, 1230.0, 35.0714
61.047776747, 96.390, 1179.0, 34.3366
61.100297878, 96.390, 1166.0, 34.1467
61.152819008, 96.390, 1134.0, 33.6749
61.205340139, 96.390, 1101.0, 33.1813
61.257861270, 96.390, 1119.0, 33.4515
61.310382400, 96.390, 1020.0, 31.9374
61.362903531, 96.390, 969.0, 31.1288
61.415424662, 96.390, 948.0, 30.7896
61.467945792, 96.390, 938.0, 30.6268
61.520466923, 96.390, 921.0, 30.3480
61.572988054, 96.390, 979.0, 31.2890
61.625509185, 96.390, 918.0, 30.2985
61.678030315, 96.390, 862.0, 29.3598
61.730551446, 96.390, 917.0, 30.2820
61.783072577, 96.390, 896.0, 29.9333
61.835593707, 96.390, 865.0, 29.4109
61.888114838, 96.390, 867.0, 29.4449
61.940635969, 96.390, 915.0, 30.2490
61.993157100, 96.390, 897.0, 29.9500
62.045678230, 96.390, 881.0, 29.6816
62.098199361, 96.390, 903.0, 30.0500
62.150720492, 96.390, 860.0, 29.3258
62.203241622, 96.390, 899.0, 29.9833
62.255762753, 96.390, 896.0, 29.9333
62.308283884, 96.390, 976.0, 31.2410
62.360805015, 96.390, 937.0, 30.6105
62.413326145, 96.390, 914.0, 30.2324
62.465847276, 96.390, 897.0, 29.9500
62.518368407, 96.390, 829.0, 28.7924
62.570889537, 96.390, 758.0, 27.5318
62.623410668, 96.390, 780.0, 27.9285
62.675931799, 96.390, 731.0, 27.0370
62.728452930, 96.390, 745.0, 27.2947
62.780974060, 96.390, 839.0, 28.9655
62.833495191, 96.390, 750.0, 27.3861
62.886016322, 96.390, 705.0, 26.5518
62.938537452, 96.390, 666.0, 25.8070
62.991058583, 96.390, 692.0, 26.3059
63.043579714, 96.390, 630.0, 25.0998
63.096100844, 96.390, 633.0, 25.1595
63.148621975, 96.390, 580.0, 24.0832
63.201143106, 96.390, 663.0, 25.7488
63.253664237, 96.390, 616.0, 24.8193
63.306185367, 96.390, 645.0, 25.3969
63.358706498, 96.390, 649.0, 25.4755
63.411227629, 96.390, 621.0, 24.9199
63.463748759, 96.390, 628.0, 25.0599
63.516269890, 96.390, 639.0, 25.2784
63.568791021, 96.390, 728.0, 26.9815
63.621312152, 96.390, 732.0, 27.0555
63.673833282, 96.390, 796.0, 28.2135
63.726354413, 96.390, 836.0, 28.9137
63.778875544, 96.390, 902.0, 30.0333
63.831396674, 96.390, 933.0, 30.5450
63.883917805, 96.390, 849.0, 29.1376
63.936438936, 96.390, 858.0, 29.2916
63.988960067, 96.390, 797.0, 28.2312
64.041481197, 96.390, 750.0, 27.3861
64.094002328, 96.390, 764.0, 27.6405
64.146523459, 96.390, 722.0, 26.8701
64.199044589, 96.390, 752.0, 27.4226
64.251565720, 96.390, 784.0, 28.0000
64.304086851, 96.390, 770.0, 27.7489
64.356607981, 96.390, 748.0, 27.3496
64.409129112, 96.390, 723.0, 26.8887
64.461650243, 96.390, 766.0, 27.6767
64.514171374, 96.390, 667.0, 25.8263
64.566692504, 96.390, 659.0, 25.6710
64.619213635, 96.390, 632.0, 25.1396
64.671734766, 96.390, 639.0, 25.2784
64.724255896, 96.390, 597.0, 24.4336
64.776777027, 96.390, 572.0, 23.9165
64.829298158, 96.390, 549.0, 23.4307
64.881819289, 96.390, 587.0, 24.2281
64.934340419, 96.390, 540.0, 23.2379
64.986861550, 96.390, 533.0, 23.0868