File: Files_organized_for_plots/470_day/31Mg-Axial_SolventExchange.csv
[Measurement conditions]
Sample identification,31_MgAxial12Nov21_Act07Jan22_B2_0714M_NaOH_LS0173_SolventExchange
Comment - 1,"Configuration=Stage for Flat Samples/Holders, Owner=User-1, Creation date=7/1/2020 9:53:24 AM"
Comment - 2,"Goniometer=Theta/Theta; Minimum step size 2Theta:0.0001; Minimum step size Omega:0.0001"
Comment - 3,"Sample stage=Stage for flat samples/holders"
Comment - 4,"Diffractometer system=EMPYREAN"
Comment - 5,"Measurement program=C:\Users\tmr79\OneDrive - The Pennsylvania State University\Documents\NEUP\XRD\Cement\Zerobackground scan.xrdmp, Identifier={98A3B11C-88F9-4AA6-982C-73314A311EF5}"
Anode material,Cu
K-Alpha1 wavelength,1.5405980
K-Alpha2 wavelength,1.5444260
Ratio K-Alpha2/K-Alpha1,0.500
Divergence slit,Fixed,0.25
Monochromator used,NO
Generator voltage, 45
Tube current, 40
File date and time,25/Apr/2023 15:44
Unit cell,
h k l, 0 0 0
Scan axis,Gonio
Scan range,4.994599997,64.999991833
Scan step size,0.0262606
No. of points, 2285
Scan type,CONTINUOUS
Time per step,96.390
[Scan points]
Angle, TimePerStep, Intensity, ESD
5.007730280, 96.390, 4132.0, 64.2806
5.060251411, 96.390, 4166.0, 64.5446
5.112772541, 96.390, 4123.0, 64.2106
5.165293672, 96.390, 4047.0, 63.6160
5.217814803, 96.390, 4175.0, 64.6142
5.270335934, 96.390, 4030.0, 63.4823
5.322857064, 96.390, 3947.0, 62.8252
5.375378195, 96.390, 3995.0, 63.2060
5.427899326, 96.390, 3926.0, 62.6578
5.480420456, 96.390, 4001.0, 63.2535
5.532941587, 96.390, 3866.0, 62.1772
5.585462718, 96.390, 3881.0, 62.2977
5.637983849, 96.390, 3852.0, 62.0645
5.690504979, 96.390, 3886.0, 62.3378
5.743026110, 96.390, 3836.0, 61.9355
5.795547241, 96.390, 3799.0, 61.6360
5.848068371, 96.390, 3825.0, 61.8466
5.900589502, 96.390, 3731.0, 61.0819
5.953110633, 96.390, 3758.0, 61.3025
6.005631763, 96.390, 3661.0, 60.5062
6.058152894, 96.390, 3732.0, 61.0901
6.110674025, 96.390, 3697.0, 60.8030
6.163195156, 96.390, 3607.0, 60.0583
6.215716286, 96.390, 3638.0, 60.3158
6.268237417, 96.390, 3773.0, 61.4248
6.320758548, 96.390, 3690.0, 60.7454
6.373279678, 96.390, 3634.0, 60.2827
6.425800809, 96.390, 3559.0, 59.6574
6.478321940, 96.390, 3654.0, 60.4483
6.530843071, 96.390, 3437.0, 58.6259
6.583364201, 96.390, 3561.0, 59.6741
6.635885332, 96.390, 3508.0, 59.2284
6.688406463, 96.390, 3489.0, 59.0678
6.740927593, 96.390, 3523.0, 59.3549
6.793448724, 96.390, 3439.0, 58.6430
6.845969855, 96.390, 3441.0, 58.6600
6.898490986, 96.390, 3423.0, 58.5064
6.951012116, 96.390, 3390.0, 58.2237
7.003533247, 96.390, 3310.0, 57.5326
7.056054378, 96.390, 3399.0, 58.3009
7.108575508, 96.390, 3377.0, 58.1120
7.161096639, 96.390, 3200.0, 56.5685
7.213617770, 96.390, 3322.0, 57.6368
7.266138900, 96.390, 3299.0, 57.4369
7.318660031, 96.390, 3183.0, 56.4181
7.371181162, 96.390, 3121.0, 55.8659
7.423702293, 96.390, 3204.0, 56.6039
7.476223423, 96.390, 3198.0, 56.5509
7.528744554, 96.390, 3075.0, 55.4527
7.581265685, 96.390, 3184.0, 56.4269
7.633786815, 96.390, 3098.0, 55.6597
7.686307946, 96.390, 3099.0, 55.6687
7.738829077, 96.390, 3056.0, 55.2811
7.791350208, 96.390, 3112.0, 55.7853
7.843871338, 96.390, 3010.0, 54.8635
7.896392469, 96.390, 3002.0, 54.7905
7.948913600, 96.390, 2970.0, 54.4977
8.001434730, 96.390, 2989.0, 54.6717
8.053955861, 96.390, 3140.0, 56.0357
8.106476992, 96.390, 2997.0, 54.7449
8.158998123, 96.390, 2981.0, 54.5985
8.211519253, 96.390, 2904.0, 53.8888
8.264040384, 96.390, 2975.0, 54.5436
8.316561515, 96.390, 2978.0, 54.5711
8.369082645, 96.390, 2923.0, 54.0648
8.421603776, 96.390, 2928.0, 54.1110
8.474124907, 96.390, 2982.0, 54.6077
8.526646038, 96.390, 2901.0, 53.8609
8.579167168, 96.390, 2843.0, 53.3198
8.631688299, 96.390, 2980.0, 54.5894
8.684209430, 96.390, 2903.0, 53.8795
8.736730560, 96.390, 2957.0, 54.3783
8.789251691, 96.390, 2845.0, 53.3385
8.841772822, 96.390, 2869.0, 53.5630
8.894293952, 96.390, 2842.0, 53.3104
8.946815083, 96.390, 2895.0, 53.8052
8.999336214, 96.390, 2837.0, 53.2635
9.051857345, 96.390, 2940.0, 54.2218
9.104378475, 96.390, 2922.0, 54.0555
9.156899606, 96.390, 2874.0, 53.6097
9.209420737, 96.390, 2885.0, 53.7122
9.261941867, 96.390, 2970.0, 54.4977
9.314462998, 96.390, 2807.0, 52.9811
9.366984129, 96.390, 2953.0, 54.3415
9.419505260, 96.390, 3018.0, 54.9363
9.472026390, 96.390, 2974.0, 54.5344
9.524547521, 96.390, 3093.0, 55.6147
9.577068652, 96.390, 2997.0, 54.7449
9.629589782, 96.390, 3066.0, 55.3715
9.682110913, 96.390, 2940.0, 54.2218
9.734632044, 96.390, 3052.0, 55.2449
9.787153175, 96.390, 3130.0, 55.9464
9.839674305, 96.390, 3113.0, 55.7943
9.892195436, 96.390, 3112.0, 55.7853
9.944716567, 96.390, 3143.0, 56.0625
9.997237697, 96.390, 3232.0, 56.8507
10.049758828, 96.390, 3107.0, 55.7405
10.102279959, 96.390, 3101.0, 55.6866
10.154801090, 96.390, 3315.0, 57.5760
10.207322220, 96.390, 3169.0, 56.2939
10.259843351, 96.390, 3216.0, 56.7098
10.312364482, 96.390, 3239.0, 56.9122
10.364885612, 96.390, 3349.0, 57.8705
10.417406743, 96.390, 3310.0, 57.5326
10.469927874, 96.390, 3410.0, 58.3952
10.522449004, 96.390, 3548.0, 59.5651
10.574970135, 96.390, 3434.0, 58.6003
10.627491266, 96.390, 3523.0, 59.3549
10.680012397, 96.390, 3423.0, 58.5064
10.732533527, 96.390, 3565.0, 59.7076
10.785054658, 96.390, 3535.0, 59.4559
10.837575789, 96.390, 3644.0, 60.3656
10.890096919, 96.390, 3602.0, 60.0167
10.942618050, 96.390, 3664.0, 60.5310
10.995139181, 96.390, 3652.0, 60.4318
11.047660312, 96.390, 3641.0, 60.3407
11.100181442, 96.390, 3707.0, 60.8851
11.152702573, 96.390, 3657.0, 60.4731
11.205223704, 96.390, 3651.0, 60.4235
11.257744834, 96.390, 3731.0, 61.0819
11.310265965, 96.390, 3643.0, 60.3573
11.362787096, 96.390, 3645.0, 60.3738
11.415308227, 96.390, 3597.0, 59.9750
11.467829357, 96.390, 3513.0, 59.2706
11.520350488, 96.390, 3556.0, 59.6322
11.572871619, 96.390, 3543.0, 59.5231
11.625392749, 96.390, 3481.0, 59.0000
11.677913880, 96.390, 3475.0, 58.9491
11.730435011, 96.390, 3477.0, 58.9661
11.782956141, 96.390, 3322.0, 57.6368
11.835477272, 96.390, 3388.0, 58.2065
11.887998403, 96.390, 3303.0, 57.4717
11.940519534, 96.390, 3261.0, 57.1052
11.993040664, 96.390, 3222.0, 56.7627
12.045561795, 96.390, 3267.0, 57.1577
12.098082926, 96.390, 3101.0, 55.6866
12.150604056, 96.390, 2975.0, 54.5436
12.203125187, 96.390, 3060.0, 55.3173
12.255646318, 96.390, 2932.0, 54.1479
12.308167449, 96.390, 2898.0, 53.8331
12.360688579, 96.390, 2860.0, 53.4790
12.413209710, 96.390, 2796.0, 52.8772
12.465730841, 96.390, 2798.0, 52.8961
12.518251971, 96.390, 2705.0, 52.0096
12.570773102, 96.390, 2623.0, 51.2152
12.623294233, 96.390, 2675.0, 51.7204
12.675815364, 96.390, 2561.0, 50.6063
12.728336494, 96.390, 2537.0, 50.3686
12.780857625, 96.390, 2532.0, 50.3190
12.833378756, 96.390, 2498.0, 49.9800
12.885899886, 96.390, 2379.0, 48.7750
12.938421017, 96.390, 2453.0, 49.5278
12.990942148, 96.390, 2386.0, 48.8467
13.043463279, 96.390, 2361.0, 48.5901
13.095984409, 96.390, 2348.0, 48.4562
13.148505540, 96.390, 2173.0, 46.6154
13.201026671, 96.390, 2341.0, 48.3839
13.253547801, 96.390, 2246.0, 47.3920
13.306068932, 96.390, 2194.0, 46.8402
13.358590063, 96.390, 2143.0, 46.2925
13.411111193, 96.390, 2196.0, 46.8615
13.463632324, 96.390, 2135.0, 46.2061
13.516153455, 96.390, 2154.0, 46.4112
13.568674586, 96.390, 2109.0, 45.9239
13.621195716, 96.390, 2075.0, 45.5522
13.673716847, 96.390, 2024.0, 44.9889
13.726237978, 96.390, 2037.0, 45.1331
13.778759108, 96.390, 2118.0, 46.0217
13.831280239, 96.390, 1975.0, 44.4410
13.883801370, 96.390, 2015.0, 44.8888
13.936322501, 96.390, 1910.0, 43.7035
13.988843631, 96.390, 1954.0, 44.2041
14.041364762, 96.390, 1883.0, 43.3935
14.093885893, 96.390, 1939.0, 44.0341
14.146407023, 96.390, 1936.0, 44.0000
14.198928154, 96.390, 1978.0, 44.4747
14.251449285, 96.390, 1821.0, 42.6732
14.303970416, 96.390, 1916.0, 43.7721
14.356491546, 96.390, 1893.0, 43.5086
14.409012677, 96.390, 1818.0, 42.6380
14.461533808, 96.390, 1911.0, 43.7150
14.514054938, 96.390, 1862.0, 43.1509
14.566576069, 96.390, 1915.0, 43.7607
14.619097200, 96.390, 1819.0, 42.6497
14.671618331, 96.390, 1836.0, 42.8486
14.724139461, 96.390, 1772.0, 42.0951
14.776660592, 96.390, 1810.0, 42.5441
14.829181723, 96.390, 1766.0, 42.0238
14.881702853, 96.390, 1782.0, 42.2137
14.934223984, 96.390, 1722.0, 41.4970
14.986745115, 96.390, 1847.0, 42.9767
15.039266245, 96.390, 1779.0, 42.1782
15.091787376, 96.390, 1708.0, 41.3280
15.144308507, 96.390, 1722.0, 41.4970
15.196829638, 96.390, 1701.0, 41.2432
15.249350768, 96.390, 1686.0, 41.0609
15.301871899, 96.390, 1753.0, 41.8688
15.354393030, 96.390, 1781.0, 42.2019
15.406914160, 96.390, 1639.0, 40.4846
15.459435291, 96.390, 1723.0, 41.5090
15.511956422, 96.390, 1688.0, 41.0853
15.564477553, 96.390, 1710.0, 41.3521
15.616998683, 96.390, 1710.0, 41.3521
15.669519814, 96.390, 1627.0, 40.3361
15.722040945, 96.390, 1714.0, 41.4005
15.774562075, 96.390, 1692.0, 41.1339
15.827083206, 96.390, 1680.0, 40.9878
15.879604337, 96.390, 1638.0, 40.4722
15.932125468, 96.390, 1589.0, 39.8623
15.984646598, 96.390, 1659.0, 40.7308
16.037167729, 96.390, 1707.0, 41.3159
16.089688860, 96.390, 1728.0, 41.5692
16.142209990, 96.390, 1692.0, 41.1339
16.194731121, 96.390, 1611.0, 40.1373
16.247252252, 96.390, 1585.0, 39.8121
16.299773382, 96.390, 1691.0, 41.1218
16.352294513, 96.390, 1627.0, 40.3361
16.404815644, 96.390, 1564.0, 39.5474
16.457336775, 96.390, 1666.0, 40.8167
16.509857905, 96.390, 1642.0, 40.5216
16.562379036, 96.390, 1610.0, 40.1248
16.614900167, 96.390, 1631.0, 40.3856
16.667421297, 96.390, 1559.0, 39.4842
16.719942428, 96.390, 1640.0, 40.4969
16.772463559, 96.390, 1583.0, 39.7869
16.824984690, 96.390, 1613.0, 40.1622
16.877505820, 96.390, 1630.0, 40.3733
16.930026951, 96.390, 1617.0, 40.2119
16.982548082, 96.390, 1647.0, 40.5832
17.035069212, 96.390, 1576.0, 39.6989
17.087590343, 96.390, 1579.0, 39.7366
17.140111474, 96.390, 1632.0, 40.3980
17.192632605, 96.390, 1573.0, 39.6611
17.245153735, 96.390, 1579.0, 39.7366
17.297674866, 96.390, 1615.0, 40.1871
17.350195997, 96.390, 1538.0, 39.2173
17.402717127, 96.390, 1603.0, 40.0375
17.455238258, 96.390, 1601.0, 40.0125
17.507759389, 96.390, 1659.0, 40.7308
17.560280520, 96.390, 1582.0, 39.7744
17.612801650, 96.390, 1596.0, 39.9500
17.665322781, 96.390, 1582.0, 39.7744
17.717843912, 96.390, 1638.0, 40.4722
17.770365042, 96.390, 1556.0, 39.4462
17.822886173, 96.390, 1586.0, 39.8246
17.875407304, 96.390, 1572.0, 39.6485
17.927928434, 96.390, 1641.0, 40.5093
17.980449565, 96.390, 1579.0, 39.7366
18.032970696, 96.390, 1605.0, 40.0625
18.085491827, 96.390, 1583.0, 39.7869
18.138012957, 96.390, 1727.0, 41.5572
18.190534088, 96.390, 1641.0, 40.5093
18.243055219, 96.390, 1717.0, 41.4367
18.295576349, 96.390, 1582.0, 39.7744
18.348097480, 96.390, 1659.0, 40.7308
18.400618611, 96.390, 1610.0, 40.1248
18.453139742, 96.390, 1622.0, 40.2741
18.505660872, 96.390, 1568.0, 39.5980
18.558182003, 96.390, 1708.0, 41.3280
18.610703134, 96.390, 1618.0, 40.2244
18.663224264, 96.390, 1593.0, 39.9124
18.715745395, 96.390, 1649.0, 40.6079
18.768266526, 96.390, 1701.0, 41.2432
18.820787657, 96.390, 1709.0, 41.3401
18.873308787, 96.390, 1646.0, 40.5709
18.925829918, 96.390, 1678.0, 40.9634
18.978351049, 96.390, 1758.0, 41.9285
19.030872179, 96.390, 1780.0, 42.1900
19.083393310, 96.390, 1817.0, 42.6263
19.135914441, 96.390, 1801.0, 42.4382
19.188435572, 96.390, 1810.0, 42.5441
19.240956702, 96.390, 1793.0, 42.3438
19.293477833, 96.390, 1835.0, 42.8369
19.345998964, 96.390, 1799.0, 42.4146
19.398520094, 96.390, 1783.0, 42.2256
19.451041225, 96.390, 1831.0, 42.7902
19.503562356, 96.390, 1824.0, 42.7083
19.556083486, 96.390, 1824.0, 42.7083
19.608604617, 96.390, 1809.0, 42.5323
19.661125748, 96.390, 1834.0, 42.8252
19.713646879, 96.390, 1817.0, 42.6263
19.766168009, 96.390, 1765.0, 42.0119
19.818689140, 96.390, 1879.0, 43.3474
19.871210271, 96.390, 1913.0, 43.7379
19.923731401, 96.390, 1899.0, 43.5775
19.976252532, 96.390, 1857.0, 43.0929
20.028773663, 96.390, 1886.0, 43.4281
20.081294794, 96.390, 1835.0, 42.8369
20.133815924, 96.390, 1867.0, 43.2088
20.186337055, 96.390, 1910.0, 43.7035
20.238858186, 96.390, 1904.0, 43.6348
20.291379316, 96.390, 1964.0, 44.3170
20.343900447, 96.390, 2011.0, 44.8442
20.396421578, 96.390, 1981.0, 44.5084
20.448942709, 96.390, 2148.0, 46.3465
20.501463839, 96.390, 2262.0, 47.5605
20.553984970, 96.390, 2334.0, 48.3115
20.606506101, 96.390, 2465.0, 49.6488
20.659027231, 96.390, 2686.0, 51.8266
20.711548362, 96.390, 2826.0, 53.1601
20.764069493, 96.390, 2744.0, 52.3832
20.816590623, 96.390, 2717.0, 52.1249
20.869111754, 96.390, 2541.0, 50.4083
20.921632885, 96.390, 2433.0, 49.3254
20.974154016, 96.390, 2292.0, 47.8748
21.026675146, 96.390, 2171.0, 46.5940
21.079196277, 96.390, 2089.0, 45.7056
21.131717408, 96.390, 1992.0, 44.6318
21.184238538, 96.390, 2050.0, 45.2769
21.236759669, 96.390, 1858.0, 43.1045
21.289280800, 96.390, 1948.0, 44.1362
21.341801931, 96.390, 1982.0, 44.5197
21.394323061, 96.390, 2058.0, 45.3652
21.446844192, 96.390, 1945.0, 44.1022
21.499365323, 96.390, 2034.0, 45.0999
21.551886453, 96.390, 2014.0, 44.8776
21.604407584, 96.390, 2038.0, 45.1442
21.656928715, 96.390, 2054.0, 45.3211
21.709449846, 96.390, 2043.0, 45.1996
21.761970976, 96.390, 2054.0, 45.3211
21.814492107, 96.390, 1983.0, 44.5309
21.867013238, 96.390, 2057.0, 45.3542
21.919534368, 96.390, 2044.0, 45.2106
21.972055499, 96.390, 2115.0, 45.9891
22.024576630, 96.390, 2107.0, 45.9021
22.077097761, 96.390, 2159.0, 46.4650
22.129618891, 96.390, 2260.0, 47.5395
22.182140022, 96.390, 2200.0, 46.9042
22.234661153, 96.390, 2206.0, 46.9681
22.287182283, 96.390, 2297.0, 47.9270
22.339703414, 96.390, 2408.0, 49.0714
22.392224545, 96.390, 2389.0, 48.8774
22.444745675, 96.390, 2495.0, 49.9500
22.497266806, 96.390, 2470.0, 49.6991
22.549787937, 96.390, 2464.0, 49.6387
22.602309068, 96.390, 2403.0, 49.0204
22.654830198, 96.390, 2332.0, 48.2908
22.707351329, 96.390, 2371.0, 48.6929
22.759872460, 96.390, 2365.0, 48.6313
22.812393590, 96.390, 2357.0, 48.5489
22.864914721, 96.390, 2316.0, 48.1248
22.917435852, 96.390, 2317.0, 48.1352
22.969956983, 96.390, 2399.0, 48.9796
23.022478113, 96.390, 2471.0, 49.7092
23.074999244, 96.390, 2437.0, 49.3660
23.127520375, 96.390, 2656.0, 51.5364
23.180041505, 96.390, 2893.0, 53.7866
23.232562636, 96.390, 2845.0, 53.3385
23.285083767, 96.390, 2483.0, 49.8297
23.337604898, 96.390, 2324.0, 48.2079
23.390126028, 96.390, 2288.0, 47.8330
23.442647159, 96.390, 2173.0, 46.6154
23.495168290, 96.390, 2145.0, 46.3141
23.547689420, 96.390, 2309.0, 48.0521
23.600210551, 96.390, 2281.0, 47.7598
23.652731682, 96.390, 2174.0, 46.6262
23.705252813, 96.390, 2304.0, 48.0000
23.757773943, 96.390, 2276.0, 47.7074
23.810295074, 96.390, 2245.0, 47.3814
23.862816205, 96.390, 2232.0, 47.2440
23.915337335, 96.390, 2285.0, 47.8017
23.967858466, 96.390, 2132.0, 46.1736
24.020379597, 96.390, 2247.0, 47.4025
24.072900727, 96.390, 2231.0, 47.2335
24.125421858, 96.390, 2209.0, 47.0000
24.177942989, 96.390, 2139.0, 46.2493
24.230464120, 96.390, 2066.0, 45.4533
24.282985250, 96.390, 1948.0, 44.1362
24.335506381, 96.390, 1800.0, 42.4264
24.388027512, 96.390, 1876.0, 43.3128
24.440548642, 96.390, 1811.0, 42.5558
24.493069773, 96.390, 1819.0, 42.6497
24.545590904, 96.390, 1817.0, 42.6263
24.598112035, 96.390, 1782.0, 42.2137
24.650633165, 96.390, 1769.0, 42.0595
24.703154296, 96.390, 1742.0, 41.7373
24.755675427, 96.390, 1685.0, 41.0488
24.808196557, 96.390, 1611.0, 40.1373
24.860717688, 96.390, 1656.0, 40.6940
24.913238819, 96.390, 1658.0, 40.7185
24.965759950, 96.390, 1642.0, 40.5216
25.018281080, 96.390, 1632.0, 40.3980
25.070802211, 96.390, 1634.0, 40.4228
25.123323342, 96.390, 1612.0, 40.1497
25.175844472, 96.390, 1689.0, 41.0974
25.228365603, 96.390, 1635.0, 40.4351
25.280886734, 96.390, 1652.0, 40.6448
25.333407864, 96.390, 1623.0, 40.2865
25.385928995, 96.390, 1643.0, 40.5339
25.438450126, 96.390, 1679.0, 40.9756
25.490971257, 96.390, 1698.0, 41.2068
25.543492387, 96.390, 1627.0, 40.3361
25.596013518, 96.390, 1702.0, 41.2553
25.648534649, 96.390, 1721.0, 41.4849
25.701055779, 96.390, 1609.0, 40.1123
25.753576910, 96.390, 1581.0, 39.7618
25.806098041, 96.390, 1705.0, 41.2916
25.858619172, 96.390, 1617.0, 40.2119
25.911140302, 96.390, 1703.0, 41.2674
25.963661433, 96.390, 1724.0, 41.5211
26.016182564, 96.390, 1854.0, 43.0581
26.068703694, 96.390, 1892.0, 43.4971
26.121224825, 96.390, 1749.0, 41.8210
26.173745956, 96.390, 1676.0, 40.9390
26.226267087, 96.390, 1615.0, 40.1871
26.278788217, 96.390, 1650.0, 40.6202
26.331309348, 96.390, 1655.0, 40.6817
26.383830479, 96.390, 1652.0, 40.6448
26.436351609, 96.390, 1636.0, 40.4475
26.488872740, 96.390, 1561.0, 39.5095
26.541393871, 96.390, 1623.0, 40.2865
26.593915002, 96.390, 1656.0, 40.6940
26.646436132, 96.390, 1574.0, 39.6737
26.698957263, 96.390, 1622.0, 40.2741
26.751478394, 96.390, 1673.0, 40.9023
26.803999524, 96.390, 1636.0, 40.4475
26.856520655, 96.390, 1733.0, 41.6293
26.909041786, 96.390, 1615.0, 40.1871
26.961562916, 96.390, 1674.0, 40.9145
27.014084047, 96.390, 1648.0, 40.5956
27.066605178, 96.390, 1633.0, 40.4104
27.119126309, 96.390, 1562.0, 39.5221
27.171647439, 96.390, 1644.0, 40.5463
27.224168570, 96.390, 1647.0, 40.5832
27.276689701, 96.390, 1629.0, 40.3609
27.329210831, 96.390, 1636.0, 40.4475
27.381731962, 96.390, 1612.0, 40.1497
27.434253093, 96.390, 1659.0, 40.7308
27.486774224, 96.390, 1637.0, 40.4599
27.539295354, 96.390, 1609.0, 40.1123
27.591816485, 96.390, 1602.0, 40.0250
27.644337616, 96.390, 1663.0, 40.7799
27.696858746, 96.390, 1623.0, 40.2865
27.749379877, 96.390, 1588.0, 39.8497
27.801901008, 96.390, 1610.0, 40.1248
27.854422139, 96.390, 1559.0, 39.4842
27.906943269, 96.390, 1543.0, 39.2810
27.959464400, 96.390, 1606.0, 40.0749
28.011985531, 96.390, 1630.0, 40.3733
28.064506661, 96.390, 1595.0, 39.9375
28.117027792, 96.390, 1625.0, 40.3113
28.169548923, 96.390, 1663.0, 40.7799
28.222070054, 96.390, 1606.0, 40.0749
28.274591184, 96.390, 1634.0, 40.4228
28.327112315, 96.390, 1688.0, 41.0853
28.379633446, 96.390, 1614.0, 40.1746
28.432154576, 96.390, 1609.0, 40.1123
28.484675707, 96.390, 1595.0, 39.9375
28.537196838, 96.390, 1670.0, 40.8656
28.589717968, 96.390, 1624.0, 40.2989
28.642239099, 96.390, 1560.0, 39.4968
28.694760230, 96.390, 1670.0, 40.8656
28.747281361, 96.390, 1601.0, 40.0125
28.799802491, 96.390, 1640.0, 40.4969
28.852323622, 96.390, 1680.0, 40.9878
28.904844753, 96.390, 1644.0, 40.5463
28.957365883, 96.390, 1593.0, 39.9124
29.009887014, 96.390, 1706.0, 41.3038
29.062408145, 96.390, 1650.0, 40.6202
29.114929276, 96.390, 1639.0, 40.4846
29.167450406, 96.390, 1582.0, 39.7744
29.219971537, 96.390, 1651.0, 40.6325
29.272492668, 96.390, 1622.0, 40.2741
29.325013798, 96.390, 1615.0, 40.1871
29.377534929, 96.390, 1710.0, 41.3521
29.430056060, 96.390, 1585.0, 39.8121
29.482577191, 96.390, 1623.0, 40.2865
29.535098321, 96.390, 1661.0, 40.7554
29.587619452, 96.390, 1518.0, 38.9615
29.640140583, 96.390, 1687.0, 41.0731
29.692661713, 96.390, 1526.0, 39.0640
29.745182844, 96.390, 1708.0, 41.3280
29.797703975, 96.390, 1645.0, 40.5586
29.850225105, 96.390, 1644.0, 40.5463
29.902746236, 96.390, 1714.0, 41.4005
29.955267367, 96.390, 1730.0, 41.5933
30.007788498, 96.390, 1622.0, 40.2741
30.060309628, 96.390, 1616.0, 40.1995
30.112830759, 96.390, 1667.0, 40.8289
30.165351890, 96.390, 1656.0, 40.6940
30.217873020, 96.390, 1526.0, 39.0640
30.270394151, 96.390, 1597.0, 39.9625
30.322915282, 96.390, 1572.0, 39.6485
30.375436413, 96.390, 1551.0, 39.3827
30.427957543, 96.390, 1486.0, 38.5487
30.480478674, 96.390, 1548.0, 39.3446
30.532999805, 96.390, 1476.0, 38.4187
30.585520935, 96.390, 1578.0, 39.7240
30.638042066, 96.390, 1580.0, 39.7492
30.690563197, 96.390, 1530.0, 39.1152
30.743084328, 96.390, 1633.0, 40.4104
30.795605458, 96.390, 1578.0, 39.7240
30.848126589, 96.390, 1510.0, 38.8587
30.900647720, 96.390, 1640.0, 40.4969
30.953168850, 96.390, 1553.0, 39.4081
31.005689981, 96.390, 1576.0, 39.6989
31.058211112, 96.390, 1584.0, 39.7995
31.110732243, 96.390, 1640.0, 40.4969
31.163253373, 96.390, 1637.0, 40.4599
31.215774504, 96.390, 1644.0, 40.5463
31.268295635, 96.390, 1682.0, 41.0122
31.320816765, 96.390, 1668.0, 40.8412
31.373337896, 96.390, 1689.0, 41.0974
31.425859027, 96.390, 1641.0, 40.5093
31.478380157, 96.390, 1639.0, 40.4846
31.530901288, 96.390, 1642.0, 40.5216
31.583422419, 96.390, 1534.0, 39.1663
31.635943550, 96.390, 1562.0, 39.5221
31.688464680, 96.390, 1672.0, 40.8901
31.740985811, 96.390, 1633.0, 40.4104
31.793506942, 96.390, 1689.0, 41.0974
31.846028072, 96.390, 1847.0, 42.9767
31.898549203, 96.390, 2088.0, 45.6946
31.951070334, 96.390, 2185.0, 46.7440
32.003591465, 96.390, 2280.0, 47.7493
32.056112595, 96.390, 2099.0, 45.8148
32.108633726, 96.390, 1957.0, 44.2380
32.161154857, 96.390, 1758.0, 41.9285
32.213675987, 96.390, 1642.0, 40.5216
32.266197118, 96.390, 1567.0, 39.5854
32.318718249, 96.390, 1626.0, 40.3237
32.371239380, 96.390, 1581.0, 39.7618
32.423760510, 96.390, 1567.0, 39.5854
32.476281641, 96.390, 1588.0, 39.8497
32.528802772, 96.390, 1658.0, 40.7185
32.581323902, 96.390, 1592.0, 39.8999
32.633845033, 96.390, 1636.0, 40.4475
32.686366164, 96.390, 1642.0, 40.5216
32.738887295, 96.390, 1730.0, 41.5933
32.791408425, 96.390, 1801.0, 42.4382
32.843929556, 96.390, 1822.0, 42.6849
32.896450687, 96.390, 1887.0, 43.4396
32.948971817, 96.390, 1985.0, 44.5533
33.001492948, 96.390, 2000.0, 44.7214
33.054014079, 96.390, 2058.0, 45.3652
33.106535209, 96.390, 1969.0, 44.3734
33.159056340, 96.390, 1861.0, 43.1393
33.211577471, 96.390, 1728.0, 41.5692
33.264098602, 96.390, 1772.0, 42.0951
33.316619732, 96.390, 1767.0, 42.0357
33.369140863, 96.390, 1850.0, 43.0116
33.421661994, 96.390, 1873.0, 43.2782
33.474183124, 96.390, 1934.0, 43.9773
33.526704255, 96.390, 1932.0, 43.9545
33.579225386, 96.390, 1987.0, 44.5758
33.631746517, 96.390, 1996.0, 44.6766
33.684267647, 96.390, 2085.0, 45.6618
33.736788778, 96.390, 2347.0, 48.4458
33.789309909, 96.390, 2411.0, 49.1019
33.841831039, 96.390, 2694.0, 51.9038
33.894352170, 96.390, 2856.0, 53.4416
33.946873301, 96.390, 3035.0, 55.0908
33.999394432, 96.390, 3225.0, 56.7891
34.051915562, 96.390, 3381.0, 58.1464
34.104436693, 96.390, 3487.0, 59.0508
34.156957824, 96.390, 3624.0, 60.1997
34.209478954, 96.390, 3581.0, 59.8415
34.262000085, 96.390, 3327.0, 57.6802
34.314521216, 96.390, 3265.0, 57.1402
34.367042346, 96.390, 3287.0, 57.3324
34.419563477, 96.390, 3183.0, 56.4181
34.472084608, 96.390, 3153.0, 56.1516
34.524605739, 96.390, 3027.0, 55.0182
34.577126869, 96.390, 2854.0, 53.4228
34.629648000, 96.390, 2953.0, 54.3415
34.682169131, 96.390, 2848.0, 53.3667
34.734690261, 96.390, 2997.0, 54.7449
34.787211392, 96.390, 2813.0, 53.0377
34.839732523, 96.390, 2909.0, 53.9351
34.892253654, 96.390, 2892.0, 53.7773
34.944774784, 96.390, 2913.0, 53.9722
34.997295915, 96.390, 2784.0, 52.7636
35.049817046, 96.390, 2696.0, 51.9230
35.102338176, 96.390, 2581.0, 50.8035
35.154859307, 96.390, 2650.0, 51.4782
35.207380438, 96.390, 2552.0, 50.5173
35.259901569, 96.390, 2460.0, 49.5984
35.312422699, 96.390, 2376.0, 48.7442
35.364943830, 96.390, 2310.0, 48.0625
35.417464961, 96.390, 2388.0, 48.8672
35.469986091, 96.390, 2290.0, 47.8539
35.522507222, 96.390, 2254.0, 47.4763
35.575028353, 96.390, 2209.0, 47.0000
35.627549484, 96.390, 2148.0, 46.3465
35.680070614, 96.390, 2111.0, 45.9456
35.732591745, 96.390, 2150.0, 46.3681
35.785112876, 96.390, 2132.0, 46.1736
35.837634006, 96.390, 2041.0, 45.1774
35.890155137, 96.390, 2015.0, 44.8888
35.942676268, 96.390, 1948.0, 44.1362
35.995197398, 96.390, 2046.0, 45.2327
36.047718529, 96.390, 1931.0, 43.9431
36.100239660, 96.390, 2002.0, 44.7437
36.152760791, 96.390, 1852.0, 43.0349
36.205281921, 96.390, 1898.0, 43.5660
36.257803052, 96.390, 1856.0, 43.0813
36.310324183, 96.390, 1827.0, 42.7434
36.362845313, 96.390, 1841.0, 42.9069
36.415366444, 96.390, 1745.0, 41.7732
36.467887575, 96.390, 1734.0, 41.6413
36.520408706, 96.390, 1779.0, 42.1782
36.572929836, 96.390, 1799.0, 42.4146
36.625450967, 96.390, 1727.0, 41.5572
36.677972098, 96.390, 1784.0, 42.2374
36.730493228, 96.390, 1748.0, 41.8091
36.783014359, 96.390, 1791.0, 42.3202
36.835535490, 96.390, 1721.0, 41.4849
36.888056621, 96.390, 1713.0, 41.3884
36.940577751, 96.390, 1685.0, 41.0488
36.993098882, 96.390, 1787.0, 42.2729
37.045620013, 96.390, 1710.0, 41.3521
37.098141143, 96.390, 1689.0, 41.0974
37.150662274, 96.390, 1676.0, 40.9390
37.203183405, 96.390, 1658.0, 40.7185
37.255704535, 96.390, 1559.0, 39.4842
37.308225666, 96.390, 1650.0, 40.6202
37.360746797, 96.390, 1560.0, 39.4968
37.413267928, 96.390, 1728.0, 41.5692
37.465789058, 96.390, 1710.0, 41.3521
37.518310189, 96.390, 1672.0, 40.8901
37.570831320, 96.390, 1637.0, 40.4599
37.623352450, 96.390, 1619.0, 40.2368
37.675873581, 96.390, 1631.0, 40.3856
37.728394712, 96.390, 1615.0, 40.1871
37.780915843, 96.390, 1586.0, 39.8246
37.833436973, 96.390, 1679.0, 40.9756
37.885958104, 96.390, 1719.0, 41.4608
37.938479235, 96.390, 1647.0, 40.5832
37.991000365, 96.390, 1579.0, 39.7366
38.043521496, 96.390, 1672.0, 40.8901
38.096042627, 96.390, 1583.0, 39.7869
38.148563758, 96.390, 1590.0, 39.8748
38.201084888, 96.390, 1602.0, 40.0250
38.253606019, 96.390, 1564.0, 39.5474
38.306127150, 96.390, 1486.0, 38.5487
38.358648280, 96.390, 1556.0, 39.4462
38.411169411, 96.390, 1616.0, 40.1995
38.463690542, 96.390, 1686.0, 41.0609
38.516211673, 96.390, 1541.0, 39.2556
38.568732803, 96.390, 1569.0, 39.6106
38.621253934, 96.390, 1576.0, 39.6989
38.673775065, 96.390, 1594.0, 39.9249
38.726296195, 96.390, 1539.0, 39.2301
38.778817326, 96.390, 1586.0, 39.8246
38.831338457, 96.390, 1591.0, 39.8873
38.883859587, 96.390, 1615.0, 40.1871
38.936380718, 96.390, 1565.0, 39.5601
38.988901849, 96.390, 1562.0, 39.5221
39.041422980, 96.390, 1540.0, 39.2428
39.093944110, 96.390, 1648.0, 40.5956
39.146465241, 96.390, 1546.0, 39.3192
39.198986372, 96.390, 1550.0, 39.3700
39.251507502, 96.390, 1513.0, 38.8973
39.304028633, 96.390, 1504.0, 38.7814
39.356549764, 96.390, 1527.0, 39.0768
39.409070895, 96.390, 1493.0, 38.6394
39.461592025, 96.390, 1464.0, 38.2623
39.514113156, 96.390, 1549.0, 39.3573
39.566634287, 96.390, 1449.0, 38.0657
39.619155417, 96.390, 1464.0, 38.2623
39.671676548, 96.390, 1521.0, 39.0000
39.724197679, 96.390, 1456.0, 38.1576
39.776718810, 96.390, 1493.0, 38.6394
39.829239940, 96.390, 1472.0, 38.3667
39.881761071, 96.390, 1378.0, 37.1214
39.934282202, 96.390, 1394.0, 37.3363
39.986803332, 96.390, 1456.0, 38.1576
40.039324463, 96.390, 1389.0, 37.2693
40.091845594, 96.390, 1392.0, 37.3095
40.144366725, 96.390, 1444.0, 38.0000
40.196887855, 96.390, 1349.0, 36.7287
40.249408986, 96.390, 1388.0, 37.2559
40.301930117, 96.390, 1377.0, 37.1080
40.354451247, 96.390, 1326.0, 36.4143
40.406972378, 96.390, 1305.0, 36.1248
40.459493509, 96.390, 1300.0, 36.0555
40.512014639, 96.390, 1307.0, 36.1525
40.564535770, 96.390, 1303.0, 36.0971
40.617056901, 96.390, 1250.0, 35.3553
40.669578032, 96.390, 1280.0, 35.7771
40.722099162, 96.390, 1288.0, 35.8887
40.774620293, 96.390, 1277.0, 35.7351
40.827141424, 96.390, 1287.0, 35.8748
40.879662554, 96.390, 1188.0, 34.4674
40.932183685, 96.390, 1326.0, 36.4143
40.984704816, 96.390, 1229.0, 35.0571
41.037225947, 96.390, 1258.0, 35.4683
41.089747077, 96.390, 1338.0, 36.5787
41.142268208, 96.390, 1320.0, 36.3318
41.194789339, 96.390, 1366.0, 36.9594
41.247310469, 96.390, 1303.0, 36.0971
41.299831600, 96.390, 1258.0, 35.4683
41.352352731, 96.390, 1276.0, 35.7211
41.404873862, 96.390, 1250.0, 35.3553
41.457394992, 96.390, 1292.0, 35.9444
41.509916123, 96.390, 1264.0, 35.5528
41.562437254, 96.390, 1183.0, 34.3948
41.614958384, 96.390, 1171.0, 34.2199
41.667479515, 96.390, 1209.0, 34.7707
41.720000646, 96.390, 1135.0, 33.6898
41.772521776, 96.390, 1147.0, 33.8674
41.825042907, 96.390, 1105.0, 33.2415
41.877564038, 96.390, 1161.0, 34.0735
41.930085169, 96.390, 1147.0, 33.8674
41.982606299, 96.390, 1164.0, 34.1174
42.035127430, 96.390, 1149.0, 33.8969
42.087648561, 96.390, 1173.0, 34.2491
42.140169691, 96.390, 1175.0, 34.2783
42.192690822, 96.390, 1141.0, 33.7787
42.245211953, 96.390, 1142.0, 33.7935
42.297733084, 96.390, 1154.0, 33.9706
42.350254214, 96.390, 1212.0, 34.8138
42.402775345, 96.390, 1183.0, 34.3948
42.455296476, 96.390, 1085.0, 32.9393
42.507817606, 96.390, 1132.0, 33.6452
42.560338737, 96.390, 1173.0, 34.2491
42.612859868, 96.390, 1086.0, 32.9545
42.665380999, 96.390, 1162.0, 34.0881
42.717902129, 96.390, 1059.0, 32.5423
42.770423260, 96.390, 1131.0, 33.6303
42.822944391, 96.390, 1052.0, 32.4345
42.875465521, 96.390, 1092.0, 33.0454
42.927986652, 96.390, 1110.0, 33.3167
42.980507783, 96.390, 1142.0, 33.7935
43.033028914, 96.390, 1065.0, 32.6343
43.085550044, 96.390, 1115.0, 33.3916
43.138071175, 96.390, 1122.0, 33.4963
43.190592306, 96.390, 1035.0, 32.1714
43.243113436, 96.390, 1082.0, 32.8938
43.295634567, 96.390, 1152.0, 33.9411
43.348155698, 96.390, 1065.0, 32.6343
43.400676828, 96.390, 1051.0, 32.4191
43.453197959, 96.390, 1040.0, 32.2490
43.505719090, 96.390, 1049.0, 32.3883
43.558240221, 96.390, 1070.0, 32.7109
43.610761351, 96.390, 1089.0, 33.0000
43.663282482, 96.390, 1103.0, 33.2114
43.715803613, 96.390, 1130.0, 33.6155
43.768324743, 96.390, 1121.0, 33.4813
43.820845874, 96.390, 1129.0, 33.6006
43.873367005, 96.390, 1160.0, 34.0588
43.925888136, 96.390, 1183.0, 34.3948
43.978409266, 96.390, 1151.0, 33.9264
44.030930397, 96.390, 1095.0, 33.0908
44.083451528, 96.390, 1068.0, 32.6803
44.135972658, 96.390, 1143.0, 33.8083
44.188493789, 96.390, 1186.0, 34.4384
44.241014920, 96.390, 1139.0, 33.7491
44.293536051, 96.390, 1110.0, 33.3167
44.346057181, 96.390, 1078.0, 32.8329
44.398578312, 96.390, 1132.0, 33.6452
44.451099443, 96.390, 1119.0, 33.4515
44.503620573, 96.390, 1111.0, 33.3317
44.556141704, 96.390, 1147.0, 33.8674
44.608662835, 96.390, 1075.0, 32.7872
44.661183966, 96.390, 1140.0, 33.7639
44.713705096, 96.390, 1090.0, 33.0151
44.766226227, 96.390, 1131.0, 33.6303
44.818747358, 96.390, 1051.0, 32.4191
44.871268488, 96.390, 1101.0, 33.1813
44.923789619, 96.390, 1047.0, 32.3574
44.976310750, 96.390, 1075.0, 32.7872
45.028831880, 96.390, 1145.0, 33.8378
45.081353011, 96.390, 1075.0, 32.7872
45.133874142, 96.390, 1042.0, 32.2800
45.186395273, 96.390, 1157.0, 34.0147
45.238916403, 96.390, 1074.0, 32.7719
45.291437534, 96.390, 1157.0, 34.0147
45.343958665, 96.390, 1138.0, 33.7343
45.396479795, 96.390, 1144.0, 33.8231
45.449000926, 96.390, 1102.0, 33.1964
45.501522057, 96.390, 1235.0, 35.1426
45.554043188, 96.390, 1158.0, 34.0294
45.606564318, 96.390, 1184.0, 34.4093
45.659085449, 96.390, 1247.0, 35.3129
45.711606580, 96.390, 1197.0, 34.5977
45.764127710, 96.390, 1167.0, 34.1614
45.816648841, 96.390, 1218.0, 34.8999
45.869169972, 96.390, 1150.0, 33.9116
45.921691103, 96.390, 1142.0, 33.7935
45.974212233, 96.390, 1132.0, 33.6452
46.026733364, 96.390, 1185.0, 34.4238
46.079254495, 96.390, 1190.0, 34.4964
46.131775625, 96.390, 1139.0, 33.7491
46.184296756, 96.390, 1225.0, 35.0000
46.236817887, 96.390, 1153.0, 33.9559
46.289339017, 96.390, 1135.0, 33.6898
46.341860148, 96.390, 1168.0, 34.1760
46.394381279, 96.390, 1158.0, 34.0294
46.446902410, 96.390, 1127.0, 33.5708
46.499423540, 96.390, 1194.0, 34.5543
46.551944671, 96.390, 1159.0, 34.0441
46.604465802, 96.390, 1095.0, 33.0908
46.656986932, 96.390, 1161.0, 34.0735
46.709508063, 96.390, 1164.0, 34.1174
46.762029194, 96.390, 1180.0, 34.3511
46.814550325, 96.390, 1157.0, 34.0147
46.867071455, 96.390, 1118.0, 33.4365
46.919592586, 96.390, 1125.0, 33.5410
46.972113717, 96.390, 1045.0, 32.3265
47.024634847, 96.390, 1051.0, 32.4191
47.077155978, 96.390, 1080.0, 32.8634
47.129677109, 96.390, 1112.0, 33.3467
47.182198240, 96.390, 1053.0, 32.4500
47.234719370, 96.390, 1120.0, 33.4664
47.287240501, 96.390, 1204.0, 34.6987
47.339761632, 96.390, 1192.0, 34.5254
47.392282762, 96.390, 1186.0, 34.4384
47.444803893, 96.390, 1173.0, 34.2491
47.497325024, 96.390, 1166.0, 34.1467
47.549846155, 96.390, 1100.0, 33.1662
47.602367285, 96.390, 1082.0, 32.8938
47.654888416, 96.390, 1135.0, 33.6898
47.707409547, 96.390, 987.0, 31.4166
47.759930677, 96.390, 1009.0, 31.7648
47.812451808, 96.390, 1037.0, 32.2025
47.864972939, 96.390, 1122.0, 33.4963
47.917494069, 96.390, 999.0, 31.6070
47.970015200, 96.390, 976.0, 31.2410
48.022536331, 96.390, 1084.0, 32.9242
48.075057462, 96.390, 1028.0, 32.0624
48.127578592, 96.390, 1047.0, 32.3574
48.180099723, 96.390, 1094.0, 33.0757
48.232620854, 96.390, 1069.0, 32.6956
48.285141984, 96.390, 1091.0, 33.0303
48.337663115, 96.390, 1118.0, 33.4365
48.390184246, 96.390, 1100.0, 33.1662
48.442705377, 96.390, 1114.0, 33.3766
48.495226507, 96.390, 1098.0, 33.1361
48.547747638, 96.390, 1091.0, 33.0303
48.600268769, 96.390, 1063.0, 32.6037
48.652789899, 96.390, 1056.0, 32.4962
48.705311030, 96.390, 1096.0, 33.1059
48.757832161, 96.390, 1081.0, 32.8786
48.810353292, 96.390, 1039.0, 32.2335
48.862874422, 96.390, 1064.0, 32.6190
48.915395553, 96.390, 1016.0, 31.8748
48.967916684, 96.390, 1035.0, 32.1714
49.020437814, 96.390, 1076.0, 32.8024
49.072958945, 96.390, 1093.0, 33.0606
49.125480076, 96.390, 1095.0, 33.0908
49.178001207, 96.390, 1086.0, 32.9545
49.230522337, 96.390, 1064.0, 32.6190
49.283043468, 96.390, 1081.0, 32.8786
49.335564599, 96.390, 1007.0, 31.7333
49.388085729, 96.390, 1035.0, 32.1714
49.440606860, 96.390, 1140.0, 33.7639
49.493127991, 96.390, 1070.0, 32.7109
49.545649121, 96.390, 980.0, 31.3050
49.598170252, 96.390, 1015.0, 31.8591
49.650691383, 96.390, 982.0, 31.3369
49.703212514, 96.390, 1029.0, 32.0780
49.755733644, 96.390, 913.0, 30.2159
49.808254775, 96.390, 948.0, 30.7896
49.860775906, 96.390, 911.0, 30.1828
49.913297036, 96.390, 882.0, 29.6985
49.965818167, 96.390, 864.0, 29.3939
50.018339298, 96.390, 919.0, 30.3150
50.070860429, 96.390, 949.0, 30.8058
50.123381559, 96.390, 895.0, 29.9166
50.175902690, 96.390, 910.0, 30.1662
50.228423821, 96.390, 905.0, 30.0832
50.280944951, 96.390, 925.0, 30.4138
50.333466082, 96.390, 910.0, 30.1662
50.385987213, 96.390, 874.0, 29.5635
50.438508344, 96.390, 829.0, 28.7924
50.491029474, 96.390, 855.0, 29.2404
50.543550605, 96.390, 858.0, 29.2916
50.596071736, 96.390, 896.0, 29.9333
50.648592866, 96.390, 862.0, 29.3598
50.701113997, 96.390, 873.0, 29.5466
50.753635128, 96.390, 883.0, 29.7153
50.806156258, 96.390, 866.0, 29.4279
50.858677389, 96.390, 845.0, 29.0689
50.911198520, 96.390, 825.0, 28.7228
50.963719651, 96.390, 861.0, 29.3428
51.016240781, 96.390, 887.0, 29.7825
51.068761912, 96.390, 856.0, 29.2575
51.121283043, 96.390, 872.0, 29.5296
51.173804173, 96.390, 836.0, 28.9137
51.226325304, 96.390, 758.0, 27.5318
51.278846435, 96.390, 891.0, 29.8496
51.331367566, 96.390, 830.0, 28.8097
51.383888696, 96.390, 818.0, 28.6007
51.436409827, 96.390, 778.0, 27.8927
51.488930958, 96.390, 823.0, 28.6880
51.541452088, 96.390, 840.0, 28.9828
51.593973219, 96.390, 814.0, 28.5307
51.646494350, 96.390, 785.0, 28.0179
51.699015481, 96.390, 801.0, 28.3019
51.751536611, 96.390, 867.0, 29.4449
51.804057742, 96.390, 790.0, 28.1069
51.856578873, 96.390, 741.0, 27.2213
51.909100003, 96.390, 779.0, 27.9106
51.961621134, 96.390, 823.0, 28.6880
52.014142265, 96.390, 853.0, 29.2062
52.066663396, 96.390, 775.0, 27.8388
52.119184526, 96.390, 859.0, 29.3087
52.171705657, 96.390, 859.0, 29.3087
52.224226788, 96.390, 863.0, 29.3769
52.276747918, 96.390, 861.0, 29.3428
52.329269049, 96.390, 923.0, 30.3809
52.381790180, 96.390, 860.0, 29.3258
52.434311310, 96.390, 860.0, 29.3258
52.486832441, 96.390, 873.0, 29.5466
52.539353572, 96.390, 859.0, 29.3087
52.591874703, 96.390, 841.0, 29.0000
52.644395833, 96.390, 840.0, 28.9828
52.696916964, 96.390, 782.0, 27.9643
52.749438095, 96.390, 831.0, 28.8271
52.801959225, 96.390, 845.0, 29.0689
52.854480356, 96.390, 846.0, 29.0861
52.907001487, 96.390, 744.0, 27.2764
52.959522618, 96.390, 780.0, 27.9285
53.012043748, 96.390, 802.0, 28.3196
53.064564879, 96.390, 807.0, 28.4077
53.117086010, 96.390, 815.0, 28.5482
53.169607140, 96.390, 817.0, 28.5832
53.222128271, 96.390, 832.0, 28.8444
53.274649402, 96.390, 787.0, 28.0535
53.327170533, 96.390, 827.0, 28.7576
53.379691663, 96.390, 844.0, 29.0517
53.432212794, 96.390, 859.0, 29.3087
53.484733925, 96.390, 887.0, 29.7825
53.537255055, 96.390, 854.0, 29.2233
53.589776186, 96.390, 909.0, 30.1496
53.642297317, 96.390, 897.0, 29.9500
53.694818448, 96.390, 827.0, 28.7576
53.747339578, 96.390, 864.0, 29.3939
53.799860709, 96.390, 786.0, 28.0357
53.852381840, 96.390, 843.0, 29.0345
53.904902970, 96.390, 837.0, 28.9310
53.957424101, 96.390, 829.0, 28.7924
54.009945232, 96.390, 773.0, 27.8029
54.062466362, 96.390, 774.0, 27.8209
54.114987493, 96.390, 729.0, 27.0000
54.167508624, 96.390, 815.0, 28.5482
54.220029755, 96.390, 792.0, 28.1425
54.272550885, 96.390, 814.0, 28.5307
54.325072016, 96.390, 766.0, 27.6767
54.377593147, 96.390, 787.0, 28.0535
54.430114277, 96.390, 739.0, 27.1846
54.482635408, 96.390, 758.0, 27.5318
54.535156539, 96.390, 785.0, 28.0179
54.587677670, 96.390, 778.0, 27.8927
54.640198800, 96.390, 762.0, 27.6043
54.692719931, 96.390, 773.0, 27.8029
54.745241062, 96.390, 725.0, 26.9258
54.797762192, 96.390, 780.0, 27.9285
54.850283323, 96.390, 773.0, 27.8029
54.902804454, 96.390, 802.0, 28.3196
54.955325585, 96.390, 799.0, 28.2666
55.007846715, 96.390, 763.0, 27.6225
55.060367846, 96.390, 731.0, 27.0370
55.112888977, 96.390, 746.0, 27.3130
55.165410107, 96.390, 770.0, 27.7489
55.217931238, 96.390, 779.0, 27.9106
55.270452369, 96.390, 769.0, 27.7308
55.322973499, 96.390, 725.0, 26.9258
55.375494630, 96.390, 775.0, 27.8388
55.428015761, 96.390, 733.0, 27.0740
55.480536892, 96.390, 716.0, 26.7582
55.533058022, 96.390, 766.0, 27.6767
55.585579153, 96.390, 728.0, 26.9815
55.638100284, 96.390, 743.0, 27.2580
55.690621414, 96.390, 753.0, 27.4408
55.743142545, 96.390, 762.0, 27.6043
55.795663676, 96.390, 690.0, 26.2679
55.848184807, 96.390, 765.0, 27.6586
55.900705937, 96.390, 724.0, 26.9072
55.953227068, 96.390, 761.0, 27.5862
56.005748199, 96.390, 764.0, 27.6405
56.058269329, 96.390, 739.0, 27.1846
56.110790460, 96.390, 765.0, 27.6586
56.163311591, 96.390, 763.0, 27.6225
56.215832722, 96.390, 719.0, 26.8142
56.268353852, 96.390, 719.0, 26.8142
56.320874983, 96.390, 731.0, 27.0370
56.373396114, 96.390, 771.0, 27.7669
56.425917244, 96.390, 756.0, 27.4955
56.478438375, 96.390, 780.0, 27.9285
56.530959506, 96.390, 739.0, 27.1846
56.583480637, 96.390, 731.0, 27.0370
56.636001767, 96.390, 752.0, 27.4226
56.688522898, 96.390, 761.0, 27.5862
56.741044029, 96.390, 778.0, 27.8927
56.793565159, 96.390, 718.0, 26.7955
56.846086290, 96.390, 671.0, 25.9037
56.898607421, 96.390, 734.0, 27.0924
56.951128551, 96.390, 704.0, 26.5330
57.003649682, 96.390, 783.0, 27.9821
57.056170813, 96.390, 755.0, 27.4773
57.108691944, 96.390, 728.0, 26.9815
57.161213074, 96.390, 777.0, 27.8747
57.213734205, 96.390, 693.0, 26.3249
57.266255336, 96.390, 749.0, 27.3679
57.318776466, 96.390, 700.0, 26.4575
57.371297597, 96.390, 681.0, 26.0960
57.423818728, 96.390, 729.0, 27.0000
57.476339859, 96.390, 784.0, 28.0000
57.528860989, 96.390, 757.0, 27.5136
57.581382120, 96.390, 715.0, 26.7395
57.633903251, 96.390, 746.0, 27.3130
57.686424381, 96.390, 735.0, 27.1109
57.738945512, 96.390, 717.0, 26.7769
57.791466643, 96.390, 799.0, 28.2666
57.843987774, 96.390, 764.0, 27.6405
57.896508904, 96.390, 823.0, 28.6880
57.949030035, 96.390, 791.0, 28.1247
58.001551166, 96.390, 824.0, 28.7054
58.054072296, 96.390, 759.0, 27.5500
58.106593427, 96.390, 785.0, 28.0179
58.159114558, 96.390, 767.0, 27.6948
58.211635689, 96.390, 751.0, 27.4044
58.264156819, 96.390, 747.0, 27.3313
58.316677950, 96.390, 787.0, 28.0535
58.369199081, 96.390, 762.0, 27.6043
58.421720211, 96.390, 755.0, 27.4773
58.474241342, 96.390, 758.0, 27.5318
58.526762473, 96.390, 748.0, 27.3496
58.579283603, 96.390, 739.0, 27.1846
58.631804734, 96.390, 736.0, 27.1293
58.684325865, 96.390, 775.0, 27.8388
58.736846996, 96.390, 733.0, 27.0740
58.789368126, 96.390, 762.0, 27.6043
58.841889257, 96.390, 729.0, 27.0000
58.894410388, 96.390, 779.0, 27.9106
58.946931518, 96.390, 800.0, 28.2843
58.999452649, 96.390, 742.0, 27.2397
59.051973780, 96.390, 796.0, 28.2135
59.104494911, 96.390, 782.0, 27.9643
59.157016041, 96.390, 791.0, 28.1247
59.209537172, 96.390, 769.0, 27.7308
59.262058303, 96.390, 808.0, 28.4253
59.314579433, 96.390, 829.0, 28.7924
59.367100564, 96.390, 801.0, 28.3019
59.419621695, 96.390, 804.0, 28.3549
59.472142826, 96.390, 843.0, 29.0345
59.524663956, 96.390, 792.0, 28.1425
59.577185087, 96.390, 834.0, 28.8791
59.629706218, 96.390, 840.0, 28.9828
59.682227348, 96.390, 890.0, 29.8329
59.734748479, 96.390, 914.0, 30.2324
59.787269610, 96.390, 885.0, 29.7489
59.839790740, 96.390, 993.0, 31.5119
59.892311871, 96.390, 928.0, 30.4631
59.944833002, 96.390, 981.0, 31.3209
59.997354133, 96.390, 1085.0, 32.9393
60.049875263, 96.390, 1077.0, 32.8177
60.102396394, 96.390, 1017.0, 31.8904
60.154917525, 96.390, 1167.0, 34.1614
60.207438655, 96.390, 1151.0, 33.9264
60.259959786, 96.390, 1226.0, 35.0143
60.312480917, 96.390, 1223.0, 34.9714
60.365002048, 96.390, 1230.0, 35.0714
60.417523178, 96.390, 1315.0, 36.2629
60.470044309, 96.390, 1298.0, 36.0278
60.522565440, 96.390, 1388.0, 37.2559
60.575086570, 96.390, 1409.0, 37.5366
60.627607701, 96.390, 1339.0, 36.5923
60.680128832, 96.390, 1441.0, 37.9605
60.732649963, 96.390, 1354.0, 36.7967
60.785171093, 96.390, 1442.0, 37.9737
60.837692224, 96.390, 1464.0, 38.2623
60.890213355, 96.390, 1344.0, 36.6606
60.942734485, 96.390, 1367.0, 36.9730
60.995255616, 96.390, 1340.0, 36.6060
61.047776747, 96.390, 1359.0, 36.8646
61.100297878, 96.390, 1361.0, 36.8917
61.152819008, 96.390, 1295.0, 35.9861
61.205340139, 96.390, 1319.0, 36.3180
61.257861270, 96.390, 1245.0, 35.2846
61.310382400, 96.390, 1260.0, 35.4965
61.362903531, 96.390, 1190.0, 34.4964
61.415424662, 96.390, 1184.0, 34.4093
61.467945792, 96.390, 1226.0, 35.0143
61.520466923, 96.390, 1099.0, 33.1512
61.572988054, 96.390, 1209.0, 34.7707
61.625509185, 96.390, 1141.0, 33.7787
61.678030315, 96.390, 1104.0, 33.2265
61.730551446, 96.390, 1118.0, 33.4365
61.783072577, 96.390, 1130.0, 33.6155
61.835593707, 96.390, 1113.0, 33.3617
61.888114838, 96.390, 1078.0, 32.8329
61.940635969, 96.390, 1052.0, 32.4345
61.993157100, 96.390, 1038.0, 32.2180
62.045678230, 96.390, 999.0, 31.6070
62.098199361, 96.390, 1017.0, 31.8904
62.150720492, 96.390, 1022.0, 31.9687
62.203241622, 96.390, 960.0, 30.9839
62.255762753, 96.390, 925.0, 30.4138
62.308283884, 96.390, 1005.0, 31.7017
62.360805015, 96.390, 915.0, 30.2490
62.413326145, 96.390, 861.0, 29.3428
62.465847276, 96.390, 857.0, 29.2746
62.518368407, 96.390, 855.0, 29.2404
62.570889537, 96.390, 886.0, 29.7658
62.623410668, 96.390, 789.0, 28.0891
62.675931799, 96.390, 821.0, 28.6531
62.728452930, 96.390, 716.0, 26.7582
62.780974060, 96.390, 702.0, 26.4953
62.833495191, 96.390, 736.0, 27.1293
62.886016322, 96.390, 742.0, 27.2397
62.938537452, 96.390, 726.0, 26.9444
62.991058583, 96.390, 687.0, 26.2107
63.043579714, 96.390, 742.0, 27.2397
63.096100844, 96.390, 675.0, 25.9808
63.148621975, 96.390, 741.0, 27.2213
63.201143106, 96.390, 664.0, 25.7682
63.253664237, 96.390, 651.0, 25.5147
63.306185367, 96.390, 662.0, 25.7294
63.358706498, 96.390, 666.0, 25.8070
63.411227629, 96.390, 629.0, 25.0799
63.463748759, 96.390, 650.0, 25.4951
63.516269890, 96.390, 614.0, 24.7790
63.568791021, 96.390, 654.0, 25.5734
63.621312152, 96.390, 628.0, 25.0599
63.673833282, 96.390, 620.0, 24.8998
63.726354413, 96.390, 674.0, 25.9615
63.778875544, 96.390, 660.0, 25.6905
63.831396674, 96.390, 666.0, 25.8070
63.883917805, 96.390, 609.0, 24.6779
63.936438936, 96.390, 627.0, 25.0400
63.988960067, 96.390, 614.0, 24.7790
64.041481197, 96.390, 621.0, 24.9199
64.094002328, 96.390, 642.0, 25.3377
64.146523459, 96.390, 662.0, 25.7294
64.199044589, 96.390, 626.0, 25.0200
64.251565720, 96.390, 623.0, 24.9600
64.304086851, 96.390, 677.0, 26.0192
64.356607981, 96.390, 679.0, 26.0576
64.409129112, 96.390, 627.0, 25.0400
64.461650243, 96.390, 666.0, 25.8070
64.514171374, 96.390, 650.0, 25.4951
64.566692504, 96.390, 628.0, 25.0599
64.619213635, 96.390, 624.0, 24.9800
64.671734766, 96.390, 637.0, 25.2389
64.724255896, 96.390, 606.0, 24.6171
64.776777027, 96.390, 627.0, 25.0400
64.829298158, 96.390, 594.0, 24.3721
64.881819289, 96.390, 643.0, 25.3574
64.934340419, 96.390, 643.0, 25.3574
64.986861550, 96.390, 582.0, 24.1247