File: Files_organized_for_plots/470_day/33Mg-Corner_SolventExchange.csv
[Measurement conditions]
Sample identification,33_MgCorner17Dec21_Act08Jan22_B2_0714M_NaOH_LS0173_SolventExchange
Comment - 1,"Configuration=Stage for Flat Samples/Holders, Owner=User-1, Creation date=7/1/2020 9:53:24 AM"
Comment - 2,"Goniometer=Theta/Theta; Minimum step size 2Theta:0.0001; Minimum step size Omega:0.0001"
Comment - 3,"Sample stage=Stage for flat samples/holders"
Comment - 4,"Diffractometer system=EMPYREAN"
Comment - 5,"Measurement program=C:\Users\tmr79\OneDrive - The Pennsylvania State University\Documents\NEUP\XRD\Cement\Zerobackground scan.xrdmp, Identifier={98A3B11C-88F9-4AA6-982C-73314A311EF5}"
Anode material,Cu
K-Alpha1 wavelength,1.5405980
K-Alpha2 wavelength,1.5444260
Ratio K-Alpha2/K-Alpha1,0.500
Divergence slit,Fixed,0.25
Monochromator used,NO
Generator voltage, 45
Tube current, 40
File date and time,25/Apr/2023 15:25
Unit cell,
h k l, 0 0 0
Scan axis,Gonio
Scan range,4.994599997,64.999991833
Scan step size,0.0262606
No. of points, 2285
Scan type,CONTINUOUS
Time per step,96.390
[Scan points]
Angle, TimePerStep, Intensity, ESD
5.007730280, 96.390, 3883.0, 62.3137
5.060251411, 96.390, 3807.0, 61.7009
5.112772541, 96.390, 3705.0, 60.8687
5.165293672, 96.390, 3799.0, 61.6360
5.217814803, 96.390, 3728.0, 61.0574
5.270335934, 96.390, 3742.0, 61.1719
5.322857064, 96.390, 3718.0, 60.9754
5.375378195, 96.390, 3714.0, 60.9426
5.427899326, 96.390, 3734.0, 61.1065
5.480420456, 96.390, 3778.0, 61.4654
5.532941587, 96.390, 3647.0, 60.3904
5.585462718, 96.390, 3696.0, 60.7947
5.637983849, 96.390, 3610.0, 60.0833
5.690504979, 96.390, 3704.0, 60.8605
5.743026110, 96.390, 3798.0, 61.6279
5.795547241, 96.390, 3781.0, 61.4898
5.848068371, 96.390, 3625.0, 60.2080
5.900589502, 96.390, 3813.0, 61.7495
5.953110633, 96.390, 3736.0, 61.1228
6.005631763, 96.390, 3712.0, 60.9262
6.058152894, 96.390, 3706.0, 60.8769
6.110674025, 96.390, 3772.0, 61.4166
6.163195156, 96.390, 3607.0, 60.0583
6.215716286, 96.390, 3790.0, 61.5630
6.268237417, 96.390, 3760.0, 61.3188
6.320758548, 96.390, 3740.0, 61.1555
6.373279678, 96.390, 3757.0, 61.2944
6.425800809, 96.390, 3653.0, 60.4401
6.478321940, 96.390, 3789.0, 61.5549
6.530843071, 96.390, 3728.0, 61.0574
6.583364201, 96.390, 3782.0, 61.4980
6.635885332, 96.390, 3677.0, 60.6383
6.688406463, 96.390, 3861.0, 62.1369
6.740927593, 96.390, 3771.0, 61.4085
6.793448724, 96.390, 3685.0, 60.7042
6.845969855, 96.390, 3648.0, 60.3987
6.898490986, 96.390, 3749.0, 61.2291
6.951012116, 96.390, 3586.0, 59.8832
7.003533247, 96.390, 3698.0, 60.8112
7.056054378, 96.390, 3707.0, 60.8851
7.108575508, 96.390, 3724.0, 61.0246
7.161096639, 96.390, 3667.0, 60.5558
7.213617770, 96.390, 3711.0, 60.9180
7.266138900, 96.390, 3596.0, 59.9667
7.318660031, 96.390, 3619.0, 60.1581
7.371181162, 96.390, 3631.0, 60.2578
7.423702293, 96.390, 3634.0, 60.2827
7.476223423, 96.390, 3627.0, 60.2246
7.528744554, 96.390, 3564.0, 59.6992
7.581265685, 96.390, 3508.0, 59.2284
7.633786815, 96.390, 3495.0, 59.1185
7.686307946, 96.390, 3425.0, 58.5235
7.738829077, 96.390, 3418.0, 58.4637
7.791350208, 96.390, 3308.0, 57.5152
7.843871338, 96.390, 3229.0, 56.8243
7.896392469, 96.390, 3379.0, 58.1292
7.948913600, 96.390, 3421.0, 58.4893
8.001434730, 96.390, 3329.0, 57.6975
8.053955861, 96.390, 3390.0, 58.2237
8.106476992, 96.390, 3332.0, 57.7235
8.158998123, 96.390, 3654.0, 60.4483
8.211519253, 96.390, 3397.0, 58.2838
8.264040384, 96.390, 3170.0, 56.3028
8.316561515, 96.390, 3072.0, 55.4256
8.369082645, 96.390, 3016.0, 54.9181
8.421603776, 96.390, 3060.0, 55.3173
8.474124907, 96.390, 3100.0, 55.6776
8.526646038, 96.390, 3008.0, 54.8452
8.579167168, 96.390, 2968.0, 54.4794
8.631688299, 96.390, 2902.0, 53.8702
8.684209430, 96.390, 2920.0, 54.0370
8.736730560, 96.390, 2936.0, 54.1849
8.789251691, 96.390, 2992.0, 54.6992
8.841772822, 96.390, 2988.0, 54.6626
8.894293952, 96.390, 2868.0, 53.5537
8.946815083, 96.390, 2882.0, 53.6843
8.999336214, 96.390, 2793.0, 52.8488
9.051857345, 96.390, 2886.0, 53.7215
9.104378475, 96.390, 2947.0, 54.2863
9.156899606, 96.390, 2774.0, 52.6688
9.209420737, 96.390, 2877.0, 53.6377
9.261941867, 96.390, 2818.0, 53.0848
9.314462998, 96.390, 2865.0, 53.5257
9.366984129, 96.390, 2816.0, 53.0660
9.419505260, 96.390, 2751.0, 52.4500
9.472026390, 96.390, 2724.0, 52.1920
9.524547521, 96.390, 2881.0, 53.6749
9.577068652, 96.390, 2835.0, 53.2447
9.629589782, 96.390, 2833.0, 53.2259
9.682110913, 96.390, 2931.0, 54.1387
9.734632044, 96.390, 2871.0, 53.5817
9.787153175, 96.390, 2955.0, 54.3599
9.839674305, 96.390, 2840.0, 53.2917
9.892195436, 96.390, 2939.0, 54.2125
9.944716567, 96.390, 3039.0, 55.1271
9.997237697, 96.390, 2956.0, 54.3691
10.049758828, 96.390, 3002.0, 54.7905
10.102279959, 96.390, 3114.0, 55.8032
10.154801090, 96.390, 3125.0, 55.9017
10.207322220, 96.390, 3198.0, 56.5509
10.259843351, 96.390, 3302.0, 57.4630
10.312364482, 96.390, 3297.0, 57.4195
10.364885612, 96.390, 3332.0, 57.7235
10.417406743, 96.390, 3396.0, 58.2752
10.469927874, 96.390, 3514.0, 59.2790
10.522449004, 96.390, 3412.0, 58.4123
10.574970135, 96.390, 3488.0, 59.0593
10.627491266, 96.390, 3570.0, 59.7495
10.680012397, 96.390, 3657.0, 60.4731
10.732533527, 96.390, 3737.0, 61.1310
10.785054658, 96.390, 3922.0, 62.6259
10.837575789, 96.390, 3798.0, 61.6279
10.890096919, 96.390, 3918.0, 62.5939
10.942618050, 96.390, 4011.0, 63.3325
10.995139181, 96.390, 3933.0, 62.7136
11.047660312, 96.390, 4331.0, 65.8103
11.100181442, 96.390, 4376.0, 66.1513
11.152702573, 96.390, 4784.0, 69.1665
11.205223704, 96.390, 4905.0, 70.0357
11.257744834, 96.390, 5467.0, 73.9392
11.310265965, 96.390, 6687.0, 81.7741
11.362787096, 96.390, 8683.0, 93.1826
11.415308227, 96.390, 12217.0, 110.5305
11.467829357, 96.390, 13728.0, 117.1665
11.520350488, 96.390, 12821.0, 113.2299
11.572871619, 96.390, 7505.0, 86.6314
11.625392749, 96.390, 4261.0, 65.2763
11.677913880, 96.390, 3738.0, 61.1392
11.730435011, 96.390, 3717.0, 60.9672
11.782956141, 96.390, 3418.0, 58.4637
11.835477272, 96.390, 3330.0, 57.7062
11.887998403, 96.390, 3273.0, 57.2101
11.940519534, 96.390, 3210.0, 56.6569
11.993040664, 96.390, 3121.0, 55.8659
12.045561795, 96.390, 2980.0, 54.5894
12.098082926, 96.390, 2939.0, 54.2125
12.150604056, 96.390, 2894.0, 53.7959
12.203125187, 96.390, 2826.0, 53.1601
12.255646318, 96.390, 2688.0, 51.8459
12.308167449, 96.390, 2681.0, 51.7784
12.360688579, 96.390, 2574.0, 50.7346
12.413209710, 96.390, 2564.0, 50.6360
12.465730841, 96.390, 2570.0, 50.6952
12.518251971, 96.390, 2321.0, 48.1768
12.570773102, 96.390, 2331.0, 48.2804
12.623294233, 96.390, 2360.0, 48.5798
12.675815364, 96.390, 2282.0, 47.7703
12.728336494, 96.390, 2320.0, 48.1664
12.780857625, 96.390, 2206.0, 46.9681
12.833378756, 96.390, 2206.0, 46.9681
12.885899886, 96.390, 2190.0, 46.7974
12.938421017, 96.390, 2052.0, 45.2990
12.990942148, 96.390, 2074.0, 45.5412
13.043463279, 96.390, 2009.0, 44.8219
13.095984409, 96.390, 1956.0, 44.2267
13.148505540, 96.390, 2022.0, 44.9667
13.201026671, 96.390, 1946.0, 44.1135
13.253547801, 96.390, 1912.0, 43.7264
13.306068932, 96.390, 1908.0, 43.6807
13.358590063, 96.390, 1950.0, 44.1588
13.411111193, 96.390, 1876.0, 43.3128
13.463632324, 96.390, 1897.0, 43.5546
13.516153455, 96.390, 1803.0, 42.4617
13.568674586, 96.390, 1737.0, 41.6773
13.621195716, 96.390, 1812.0, 42.5676
13.673716847, 96.390, 1712.0, 41.3763
13.726237978, 96.390, 1777.0, 42.1545
13.778759108, 96.390, 1746.0, 41.7852
13.831280239, 96.390, 1711.0, 41.3642
13.883801370, 96.390, 1643.0, 40.5339
13.936322501, 96.390, 1690.0, 41.1096
13.988843631, 96.390, 1684.0, 41.0366
14.041364762, 96.390, 1687.0, 41.0731
14.093885893, 96.390, 1627.0, 40.3361
14.146407023, 96.390, 1711.0, 41.3642
14.198928154, 96.390, 1661.0, 40.7554
14.251449285, 96.390, 1759.0, 41.9404
14.303970416, 96.390, 1661.0, 40.7554
14.356491546, 96.390, 1743.0, 41.7493
14.409012677, 96.390, 1797.0, 42.3910
14.461533808, 96.390, 2138.0, 46.2385
14.514054938, 96.390, 2466.0, 49.6588
14.566576069, 96.390, 3048.0, 55.2087
14.619097200, 96.390, 2147.0, 46.3357
14.671618331, 96.390, 1659.0, 40.7308
14.724139461, 96.390, 1682.0, 41.0122
14.776660592, 96.390, 1511.0, 38.8716
14.829181723, 96.390, 1596.0, 39.9500
14.881702853, 96.390, 1550.0, 39.3700
14.934223984, 96.390, 1589.0, 39.8623
14.986745115, 96.390, 1573.0, 39.6611
15.039266245, 96.390, 1660.0, 40.7431
15.091787376, 96.390, 1712.0, 41.3763
15.144308507, 96.390, 1830.0, 42.7785
15.196829638, 96.390, 2200.0, 46.9042
15.249350768, 96.390, 2181.0, 46.7012
15.301871899, 96.390, 2036.0, 45.1221
15.354393030, 96.390, 1664.0, 40.7922
15.406914160, 96.390, 1537.0, 39.2046
15.459435291, 96.390, 1477.0, 38.4318
15.511956422, 96.390, 1498.0, 38.7040
15.564477553, 96.390, 1560.0, 39.4968
15.616998683, 96.390, 1535.0, 39.1791
15.669519814, 96.390, 1593.0, 39.9124
15.722040945, 96.390, 1716.0, 41.4246
15.774562075, 96.390, 1691.0, 41.1218
15.827083206, 96.390, 1542.0, 39.2683
15.879604337, 96.390, 1463.0, 38.2492
15.932125468, 96.390, 1464.0, 38.2623
15.984646598, 96.390, 1416.0, 37.6298
16.037167729, 96.390, 1462.0, 38.2361
16.089688860, 96.390, 1523.0, 39.0256
16.142209990, 96.390, 1515.0, 38.9230
16.194731121, 96.390, 1582.0, 39.7744
16.247252252, 96.390, 1649.0, 40.6079
16.299773382, 96.390, 1912.0, 43.7264
16.352294513, 96.390, 2471.0, 49.7092
16.404815644, 96.390, 1825.0, 42.7200
16.457336775, 96.390, 1451.0, 38.0920
16.509857905, 96.390, 1418.0, 37.6563
16.562379036, 96.390, 1426.0, 37.7624
16.614900167, 96.390, 1388.0, 37.2559
16.667421297, 96.390, 1480.0, 38.4708
16.719942428, 96.390, 1359.0, 36.8646
16.772463559, 96.390, 1439.0, 37.9342
16.824984690, 96.390, 1419.0, 37.6696
16.877505820, 96.390, 1420.0, 37.6829
16.930026951, 96.390, 1419.0, 37.6696
16.982548082, 96.390, 1406.0, 37.4967
17.035069212, 96.390, 1390.0, 37.2827
17.087590343, 96.390, 1391.0, 37.2961
17.140111474, 96.390, 1426.0, 37.7624
17.192632605, 96.390, 1398.0, 37.3898
17.245153735, 96.390, 1423.0, 37.7227
17.297674866, 96.390, 1332.0, 36.4966
17.350195997, 96.390, 1394.0, 37.3363
17.402717127, 96.390, 1334.0, 36.5240
17.455238258, 96.390, 1389.0, 37.2693
17.507759389, 96.390, 1333.0, 36.5103
17.560280520, 96.390, 1410.0, 37.5500
17.612801650, 96.390, 1376.0, 37.0945
17.665322781, 96.390, 1460.0, 38.2099
17.717843912, 96.390, 1392.0, 37.3095
17.770365042, 96.390, 1406.0, 37.4967
17.822886173, 96.390, 1342.0, 36.6333
17.875407304, 96.390, 1387.0, 37.2424
17.927928434, 96.390, 1377.0, 37.1080
17.980449565, 96.390, 1412.0, 37.5766
18.032970696, 96.390, 1337.0, 36.5650
18.085491827, 96.390, 1398.0, 37.3898
18.138012957, 96.390, 1431.0, 37.8286
18.190534088, 96.390, 1403.0, 37.4566
18.243055219, 96.390, 1416.0, 37.6298
18.295576349, 96.390, 1429.0, 37.8021
18.348097480, 96.390, 1466.0, 38.2884
18.400618611, 96.390, 1381.0, 37.1618
18.453139742, 96.390, 1450.0, 38.0789
18.505660872, 96.390, 1390.0, 37.2827
18.558182003, 96.390, 1440.0, 37.9473
18.610703134, 96.390, 1450.0, 38.0789
18.663224264, 96.390, 1442.0, 37.9737
18.715745395, 96.390, 1549.0, 39.3573
18.768266526, 96.390, 1586.0, 39.8246
18.820787657, 96.390, 1840.0, 42.8952
18.873308787, 96.390, 2298.0, 47.9375
18.925829918, 96.390, 2556.0, 50.5569
18.978351049, 96.390, 2561.0, 50.6063
19.030872179, 96.390, 2356.0, 48.5386
19.083393310, 96.390, 1904.0, 43.6348
19.135914441, 96.390, 1900.0, 43.5890
19.188435572, 96.390, 1677.0, 40.9512
19.240956702, 96.390, 1574.0, 39.6737
19.293477833, 96.390, 1652.0, 40.6448
19.345998964, 96.390, 1742.0, 41.7373
19.398520094, 96.390, 1715.0, 41.4126
19.451041225, 96.390, 1543.0, 39.2810
19.503562356, 96.390, 1507.0, 38.8201
19.556083486, 96.390, 1547.0, 39.3319
19.608604617, 96.390, 1577.0, 39.7115
19.661125748, 96.390, 1533.0, 39.1535
19.713646879, 96.390, 1477.0, 38.4318
19.766168009, 96.390, 1507.0, 38.8201
19.818689140, 96.390, 1524.0, 39.0384
19.871210271, 96.390, 1442.0, 37.9737
19.923731401, 96.390, 1548.0, 39.3446
19.976252532, 96.390, 1501.0, 38.7427
20.028773663, 96.390, 1551.0, 39.3827
20.081294794, 96.390, 1582.0, 39.7744
20.133815924, 96.390, 1595.0, 39.9375
20.186337055, 96.390, 1574.0, 39.6737
20.238858186, 96.390, 1550.0, 39.3700
20.291379316, 96.390, 1610.0, 40.1248
20.343900447, 96.390, 1673.0, 40.9023
20.396421578, 96.390, 1695.0, 41.1704
20.448942709, 96.390, 1693.0, 41.1461
20.501463839, 96.390, 1728.0, 41.5692
20.553984970, 96.390, 1907.0, 43.6692
20.606506101, 96.390, 2072.0, 45.5192
20.659027231, 96.390, 2316.0, 48.1248
20.711548362, 96.390, 2501.0, 50.0100
20.764069493, 96.390, 2446.0, 49.4571
20.816590623, 96.390, 2188.0, 46.7761
20.869111754, 96.390, 1987.0, 44.5758
20.921632885, 96.390, 1907.0, 43.6692
20.974154016, 96.390, 1778.0, 42.1663
21.026675146, 96.390, 1690.0, 41.1096
21.079196277, 96.390, 1670.0, 40.8656
21.131717408, 96.390, 1710.0, 41.3521
21.184238538, 96.390, 1672.0, 40.8901
21.236759669, 96.390, 1743.0, 41.7493
21.289280800, 96.390, 1878.0, 43.3359
21.341801931, 96.390, 2239.0, 47.3181
21.394323061, 96.390, 2028.0, 45.0333
21.446844192, 96.390, 1801.0, 42.4382
21.499365323, 96.390, 1856.0, 43.0813
21.551886453, 96.390, 1965.0, 44.3283
21.604407584, 96.390, 2330.0, 48.2701
21.656928715, 96.390, 2783.0, 52.7541
21.709449846, 96.390, 2306.0, 48.0208
21.761970976, 96.390, 1927.0, 43.8976
21.814492107, 96.390, 1836.0, 42.8486
21.867013238, 96.390, 1894.0, 43.5201
21.919534368, 96.390, 1882.0, 43.3820
21.972055499, 96.390, 1882.0, 43.3820
22.024576630, 96.390, 1937.0, 44.0114
22.077097761, 96.390, 2043.0, 45.1996
22.129618891, 96.390, 1959.0, 44.2606
22.182140022, 96.390, 2067.0, 45.4643
22.234661153, 96.390, 2016.0, 44.8999
22.287182283, 96.390, 2155.0, 46.4220
22.339703414, 96.390, 2242.0, 47.3498
22.392224545, 96.390, 2307.0, 48.0312
22.444745675, 96.390, 2222.0, 47.1381
22.497266806, 96.390, 2242.0, 47.3498
22.549787937, 96.390, 2276.0, 47.7074
22.602309068, 96.390, 2394.0, 48.9285
22.654830198, 96.390, 2579.0, 50.7839
22.707351329, 96.390, 2492.0, 49.9199
22.759872460, 96.390, 2638.0, 51.3615
22.812393590, 96.390, 3122.0, 55.8749
22.864914721, 96.390, 3925.0, 62.6498
22.917435852, 96.390, 4774.0, 69.0941
22.969956983, 96.390, 4936.0, 70.2567
23.022478113, 96.390, 4934.0, 70.2424
23.074999244, 96.390, 5018.0, 70.8378
23.127520375, 96.390, 5278.0, 72.6498
23.180041505, 96.390, 4868.0, 69.7711
23.232562636, 96.390, 4025.0, 63.4429
23.285083767, 96.390, 2968.0, 54.4794
23.337604898, 96.390, 2524.0, 50.2394
23.390126028, 96.390, 2775.0, 52.6783
23.442647159, 96.390, 2594.0, 50.9313
23.495168290, 96.390, 2301.0, 47.9687
23.547689420, 96.390, 2176.0, 46.6476
23.600210551, 96.390, 2274.0, 47.6865
23.652731682, 96.390, 2044.0, 45.2106
23.705252813, 96.390, 1952.0, 44.1814
23.757773943, 96.390, 1897.0, 43.5546
23.810295074, 96.390, 1822.0, 42.6849
23.862816205, 96.390, 1835.0, 42.8369
23.915337335, 96.390, 1812.0, 42.5676
23.967858466, 96.390, 1858.0, 43.1045
24.020379597, 96.390, 1746.0, 41.7852
24.072900727, 96.390, 1706.0, 41.3038
24.125421858, 96.390, 1748.0, 41.8091
24.177942989, 96.390, 1643.0, 40.5339
24.230464120, 96.390, 1590.0, 39.8748
24.282985250, 96.390, 1609.0, 40.1123
24.335506381, 96.390, 1522.0, 39.0128
24.388027512, 96.390, 1497.0, 38.6911
24.440548642, 96.390, 1460.0, 38.2099
24.493069773, 96.390, 1493.0, 38.6394
24.545590904, 96.390, 1487.0, 38.5616
24.598112035, 96.390, 1468.0, 38.3145
24.650633165, 96.390, 1497.0, 38.6911
24.703154296, 96.390, 1379.0, 37.1349
24.755675427, 96.390, 1449.0, 38.0657
24.808196557, 96.390, 1527.0, 39.0768
24.860717688, 96.390, 1409.0, 37.5366
24.913238819, 96.390, 1419.0, 37.6696
24.965759950, 96.390, 1459.0, 38.1969
25.018281080, 96.390, 1374.0, 37.0675
25.070802211, 96.390, 1348.0, 36.7151
25.123323342, 96.390, 1344.0, 36.6606
25.175844472, 96.390, 1249.0, 35.3412
25.228365603, 96.390, 1290.0, 35.9166
25.280886734, 96.390, 1327.0, 36.4280
25.333407864, 96.390, 1284.0, 35.8329
25.385928995, 96.390, 1334.0, 36.5240
25.438450126, 96.390, 1228.0, 35.0428
25.490971257, 96.390, 1285.0, 35.8469
25.543492387, 96.390, 1313.0, 36.2353
25.596013518, 96.390, 1239.0, 35.1994
25.648534649, 96.390, 1311.0, 36.2077
25.701055779, 96.390, 1267.0, 35.5949
25.753576910, 96.390, 1237.0, 35.1710
25.806098041, 96.390, 1320.0, 36.3318
25.858619172, 96.390, 1329.0, 36.4555
25.911140302, 96.390, 1331.0, 36.4829
25.963661433, 96.390, 1216.0, 34.8712
26.016182564, 96.390, 1366.0, 36.9594
26.068703694, 96.390, 1357.0, 36.8375
26.121224825, 96.390, 1328.0, 36.4417
26.173745956, 96.390, 1291.0, 35.9305
26.226267087, 96.390, 1244.0, 35.2704
26.278788217, 96.390, 1240.0, 35.2136
26.331309348, 96.390, 1254.0, 35.4119
26.383830479, 96.390, 1325.0, 36.4005
26.436351609, 96.390, 1236.0, 35.1568
26.488872740, 96.390, 1286.0, 35.8608
26.541393871, 96.390, 1193.0, 34.5398
26.593915002, 96.390, 1242.0, 35.2420
26.646436132, 96.390, 1333.0, 36.5103
26.698957263, 96.390, 1459.0, 38.1969
26.751478394, 96.390, 1790.0, 42.3084
26.803999524, 96.390, 2179.0, 46.6798
26.856520655, 96.390, 2410.0, 49.0918
26.909041786, 96.390, 1902.0, 43.6119
26.961562916, 96.390, 1693.0, 41.1461
27.014084047, 96.390, 1932.0, 43.9545
27.066605178, 96.390, 2423.0, 49.2240
27.119126309, 96.390, 2104.0, 45.8694
27.171647439, 96.390, 2432.0, 49.3153
27.224168570, 96.390, 2717.0, 52.1249
27.276689701, 96.390, 2090.0, 45.7165
27.329210831, 96.390, 1679.0, 40.9756
27.381731962, 96.390, 1345.0, 36.6742
27.434253093, 96.390, 1389.0, 37.2693
27.486774224, 96.390, 1285.0, 35.8469
27.539295354, 96.390, 1229.0, 35.0571
27.591816485, 96.390, 1274.0, 35.6931
27.644337616, 96.390, 1222.0, 34.9571
27.696858746, 96.390, 1254.0, 35.4119
27.749379877, 96.390, 1263.0, 35.5387
27.801901008, 96.390, 1240.0, 35.2136
27.854422139, 96.390, 1235.0, 35.1426
27.906943269, 96.390, 1202.0, 34.6699
27.959464400, 96.390, 1219.0, 34.9142
28.011985531, 96.390, 1249.0, 35.3412
28.064506661, 96.390, 1254.0, 35.4119
28.117027792, 96.390, 1243.0, 35.2562
28.169548923, 96.390, 1264.0, 35.5528
28.222070054, 96.390, 1260.0, 35.4965
28.274591184, 96.390, 1267.0, 35.5949
28.327112315, 96.390, 1233.0, 35.1141
28.379633446, 96.390, 1367.0, 36.9730
28.432154576, 96.390, 1398.0, 37.3898
28.484675707, 96.390, 1325.0, 36.4005
28.537196838, 96.390, 1362.0, 36.9053
28.589717968, 96.390, 1296.0, 36.0000
28.642239099, 96.390, 1272.0, 35.6651
28.694760230, 96.390, 1256.0, 35.4401
28.747281361, 96.390, 1271.0, 35.6511
28.799802491, 96.390, 1241.0, 35.2278
28.852323622, 96.390, 1293.0, 35.9583
28.904844753, 96.390, 1346.0, 36.6879
28.957365883, 96.390, 1324.0, 36.3868
29.009887014, 96.390, 1274.0, 35.6931
29.062408145, 96.390, 1331.0, 36.4829
29.114929276, 96.390, 1493.0, 38.6394
29.167450406, 96.390, 1756.0, 41.9047
29.219971537, 96.390, 2004.0, 44.7661
29.272492668, 96.390, 2279.0, 47.7389
29.325013798, 96.390, 2635.0, 51.3323
29.377534929, 96.390, 2335.0, 48.3218
29.430056060, 96.390, 2153.0, 46.4004
29.482577191, 96.390, 2204.0, 46.9468
29.535098321, 96.390, 2448.0, 49.4773
29.587619452, 96.390, 1868.0, 43.2204
29.640140583, 96.390, 1663.0, 40.7799
29.692661713, 96.390, 1565.0, 39.5601
29.745182844, 96.390, 1495.0, 38.6652
29.797703975, 96.390, 1431.0, 37.8286
29.850225105, 96.390, 1338.0, 36.5787
29.902746236, 96.390, 1207.0, 34.7419
29.955267367, 96.390, 1305.0, 36.1248
30.007788498, 96.390, 1448.0, 38.0526
30.060309628, 96.390, 1403.0, 37.4566
30.112830759, 96.390, 1354.0, 36.7967
30.165351890, 96.390, 1312.0, 36.2215
30.217873020, 96.390, 1266.0, 35.5809
30.270394151, 96.390, 1235.0, 35.1426
30.322915282, 96.390, 1267.0, 35.5949
30.375436413, 96.390, 1257.0, 35.4542
30.427957543, 96.390, 1319.0, 36.3180
30.480478674, 96.390, 1305.0, 36.1248
30.532999805, 96.390, 1244.0, 35.2704
30.585520935, 96.390, 1270.0, 35.6371
30.638042066, 96.390, 1410.0, 37.5500
30.690563197, 96.390, 1478.0, 38.4448
30.743084328, 96.390, 1354.0, 36.7967
30.795605458, 96.390, 1456.0, 38.1576
30.848126589, 96.390, 1587.0, 39.8372
30.900647720, 96.390, 1525.0, 39.0512
30.953168850, 96.390, 1419.0, 37.6696
31.005689981, 96.390, 1315.0, 36.2629
31.058211112, 96.390, 1312.0, 36.2215
31.110732243, 96.390, 1387.0, 37.2424
31.163253373, 96.390, 1404.0, 37.4700
31.215774504, 96.390, 1703.0, 41.2674
31.268295635, 96.390, 2341.0, 48.3839
31.320816765, 96.390, 2399.0, 48.9796
31.373337896, 96.390, 2231.0, 47.2335
31.425859027, 96.390, 1993.0, 44.6430
31.478380157, 96.390, 1564.0, 39.5474
31.530901288, 96.390, 1458.0, 38.1838
31.583422419, 96.390, 1323.0, 36.3731
31.635943550, 96.390, 1298.0, 36.0278
31.688464680, 96.390, 1178.0, 34.3220
31.740985811, 96.390, 1234.0, 35.1283
31.793506942, 96.390, 1280.0, 35.7771
31.846028072, 96.390, 1335.0, 36.5377
31.898549203, 96.390, 1415.0, 37.6165
31.951070334, 96.390, 1517.0, 38.9487
32.003591465, 96.390, 1453.0, 38.1182
32.056112595, 96.390, 1467.0, 38.3014
32.108633726, 96.390, 1611.0, 40.1373
32.161154857, 96.390, 1764.0, 42.0000
32.213675987, 96.390, 1733.0, 41.6293
32.266197118, 96.390, 2033.0, 45.0888
32.318718249, 96.390, 2274.0, 47.6865
32.371239380, 96.390, 1729.0, 41.5812
32.423760510, 96.390, 1532.0, 39.1408
32.476281641, 96.390, 1365.0, 36.9459
32.528802772, 96.390, 1307.0, 36.1525
32.581323902, 96.390, 1282.0, 35.8050
32.633845033, 96.390, 1362.0, 36.9053
32.686366164, 96.390, 1506.0, 38.8072
32.738887295, 96.390, 1584.0, 39.7995
32.791408425, 96.390, 1486.0, 38.5487
32.843929556, 96.390, 1455.0, 38.1445
32.896450687, 96.390, 1445.0, 38.0132
32.948971817, 96.390, 1516.0, 38.9358
33.001492948, 96.390, 1516.0, 38.9358
33.054014079, 96.390, 1678.0, 40.9634
33.106535209, 96.390, 1652.0, 40.6448
33.159056340, 96.390, 1504.0, 38.7814
33.211577471, 96.390, 1609.0, 40.1123
33.264098602, 96.390, 1656.0, 40.6940
33.316619732, 96.390, 1616.0, 40.1995
33.369140863, 96.390, 1498.0, 38.7040
33.421661994, 96.390, 1574.0, 39.6737
33.474183124, 96.390, 1572.0, 39.6485
33.526704255, 96.390, 1689.0, 41.0974
33.579225386, 96.390, 1729.0, 41.5812
33.631746517, 96.390, 1853.0, 43.0465
33.684267647, 96.390, 1969.0, 44.3734
33.736788778, 96.390, 2150.0, 46.3681
33.789309909, 96.390, 2140.0, 46.2601
33.841831039, 96.390, 2264.0, 47.5815
33.894352170, 96.390, 2446.0, 49.4571
33.946873301, 96.390, 2665.0, 51.6236
33.999394432, 96.390, 2807.0, 52.9811
34.051915562, 96.390, 3083.0, 55.5248
34.104436693, 96.390, 3080.0, 55.4977
34.156957824, 96.390, 3196.0, 56.5332
34.209478954, 96.390, 3147.0, 56.0981
34.262000085, 96.390, 2987.0, 54.6535
34.314521216, 96.390, 2992.0, 54.6992
34.367042346, 96.390, 3011.0, 54.8726
34.419563477, 96.390, 3171.0, 56.3116
34.472084608, 96.390, 3331.0, 57.7148
34.524605739, 96.390, 3728.0, 61.0574
34.577126869, 96.390, 3895.0, 62.4099
34.629648000, 96.390, 4082.0, 63.8905
34.682169131, 96.390, 4329.0, 65.7951
34.734690261, 96.390, 4866.0, 69.7567
34.787211392, 96.390, 4568.0, 67.5870
34.839732523, 96.390, 3826.0, 61.8547
34.892253654, 96.390, 3195.0, 56.5243
34.944774784, 96.390, 2760.0, 52.5357
34.997295915, 96.390, 2589.0, 50.8822
35.049817046, 96.390, 2700.0, 51.9615
35.102338176, 96.390, 2709.0, 52.0481
35.154859307, 96.390, 2651.0, 51.4879
35.207380438, 96.390, 2694.0, 51.9038
35.259901569, 96.390, 2598.0, 50.9706
35.312422699, 96.390, 2535.0, 50.3488
35.364943830, 96.390, 2350.0, 48.4768
35.417464961, 96.390, 2246.0, 47.3920
35.469986091, 96.390, 2150.0, 46.3681
35.522507222, 96.390, 2122.0, 46.0652
35.575028353, 96.390, 2130.0, 46.1519
35.627549484, 96.390, 2103.0, 45.8585
35.680070614, 96.390, 2213.0, 47.0425
35.732591745, 96.390, 2279.0, 47.7389
35.785112876, 96.390, 2214.0, 47.0532
35.837634006, 96.390, 2338.0, 48.3529
35.890155137, 96.390, 2576.0, 50.7543
35.942676268, 96.390, 2855.0, 53.4322
35.995197398, 96.390, 3018.0, 54.9363
36.047718529, 96.390, 2689.0, 51.8556
36.100239660, 96.390, 2900.0, 53.8516
36.152760791, 96.390, 2872.0, 53.5910
36.205281921, 96.390, 3517.0, 59.3043
36.257803052, 96.390, 3314.0, 57.5674
36.310324183, 96.390, 2709.0, 52.0481
36.362845313, 96.390, 2199.0, 46.8935
36.415366444, 96.390, 1955.0, 44.2154
36.467887575, 96.390, 1870.0, 43.2435
36.520408706, 96.390, 1901.0, 43.6005
36.572929836, 96.390, 1913.0, 43.7379
36.625450967, 96.390, 2024.0, 44.9889
36.677972098, 96.390, 1850.0, 43.0116
36.730493228, 96.390, 1902.0, 43.6119
36.783014359, 96.390, 1874.0, 43.2897
36.835535490, 96.390, 1894.0, 43.5201
36.888056621, 96.390, 1868.0, 43.2204
36.940577751, 96.390, 1850.0, 43.0116
36.993098882, 96.390, 1847.0, 42.9767
37.045620013, 96.390, 1820.0, 42.6615
37.098141143, 96.390, 1838.0, 42.8719
37.150662274, 96.390, 1993.0, 44.6430
37.203183405, 96.390, 1986.0, 44.5646
37.255704535, 96.390, 2072.0, 45.5192
37.308225666, 96.390, 1924.0, 43.8634
37.360746797, 96.390, 1995.0, 44.6654
37.413267928, 96.390, 2036.0, 45.1221
37.465789058, 96.390, 2134.0, 46.1952
37.518310189, 96.390, 2215.0, 47.0638
37.570831320, 96.390, 2150.0, 46.3681
37.623352450, 96.390, 2168.0, 46.5618
37.675873581, 96.390, 1972.0, 44.4072
37.728394712, 96.390, 2017.0, 44.9110
37.780915843, 96.390, 2171.0, 46.5940
37.833436973, 96.390, 2487.0, 49.8698
37.885958104, 96.390, 2604.0, 51.0294
37.938479235, 96.390, 2406.0, 49.0510
37.991000365, 96.390, 2397.0, 48.9592
38.043521496, 96.390, 2188.0, 46.7761
38.096042627, 96.390, 2075.0, 45.5522
38.148563758, 96.390, 1995.0, 44.6654
38.201084888, 96.390, 2253.0, 47.4658
38.253606019, 96.390, 2121.0, 46.0543
38.306127150, 96.390, 1932.0, 43.9545
38.358648280, 96.390, 1865.0, 43.1856
38.411169411, 96.390, 1849.0, 43.0000
38.463690542, 96.390, 1688.0, 41.0853
38.516211673, 96.390, 1862.0, 43.1509
38.568732803, 96.390, 1788.0, 42.2847
38.621253934, 96.390, 1811.0, 42.5558
38.673775065, 96.390, 1728.0, 41.5692
38.726296195, 96.390, 1737.0, 41.6773
38.778817326, 96.390, 1704.0, 41.2795
38.831338457, 96.390, 1762.0, 41.9762
38.883859587, 96.390, 1721.0, 41.4849
38.936380718, 96.390, 1794.0, 42.3556
38.988901849, 96.390, 1914.0, 43.7493
39.041422980, 96.390, 2158.0, 46.4543
39.093944110, 96.390, 2686.0, 51.8266
39.146465241, 96.390, 3088.0, 55.5698
39.198986372, 96.390, 3275.0, 57.2276
39.251507502, 96.390, 3056.0, 55.2811
39.304028633, 96.390, 2533.0, 50.3289
39.356549764, 96.390, 2209.0, 47.0000
39.409070895, 96.390, 1861.0, 43.1393
39.461592025, 96.390, 1622.0, 40.2741
39.514113156, 96.390, 1622.0, 40.2741
39.566634287, 96.390, 1581.0, 39.7618
39.619155417, 96.390, 1599.0, 39.9875
39.671676548, 96.390, 1537.0, 39.2046
39.724197679, 96.390, 1546.0, 39.3192
39.776718810, 96.390, 1500.0, 38.7298
39.829239940, 96.390, 1592.0, 39.8999
39.881761071, 96.390, 1602.0, 40.0250
39.934282202, 96.390, 1567.0, 39.5854
39.986803332, 96.390, 1628.0, 40.3485
40.039324463, 96.390, 1575.0, 39.6863
40.091845594, 96.390, 1541.0, 39.2556
40.144366725, 96.390, 1491.0, 38.6135
40.196887855, 96.390, 1486.0, 38.5487
40.249408986, 96.390, 1419.0, 37.6696
40.301930117, 96.390, 1343.0, 36.6470
40.354451247, 96.390, 1366.0, 36.9594
40.406972378, 96.390, 1321.0, 36.3456
40.459493509, 96.390, 1332.0, 36.4966
40.512014639, 96.390, 1336.0, 36.5513
40.564535770, 96.390, 1377.0, 37.1080
40.617056901, 96.390, 1488.0, 38.5746
40.669578032, 96.390, 1482.0, 38.4968
40.722099162, 96.390, 1525.0, 39.0512
40.774620293, 96.390, 1402.0, 37.4433
40.827141424, 96.390, 1351.0, 36.7560
40.879662554, 96.390, 1324.0, 36.3868
40.932183685, 96.390, 1297.0, 36.0139
40.984704816, 96.390, 1308.0, 36.1663
41.037225947, 96.390, 1376.0, 37.0945
41.089747077, 96.390, 1365.0, 36.9459
41.142268208, 96.390, 1364.0, 36.9324
41.194789339, 96.390, 1305.0, 36.1248
41.247310469, 96.390, 1423.0, 37.7227
41.299831600, 96.390, 1384.0, 37.2022
41.352352731, 96.390, 1413.0, 37.5899
41.404873862, 96.390, 1402.0, 37.4433
41.457394992, 96.390, 1399.0, 37.4032
41.509916123, 96.390, 1436.0, 37.8946
41.562437254, 96.390, 1315.0, 36.2629
41.614958384, 96.390, 1350.0, 36.7423
41.667479515, 96.390, 1267.0, 35.5949
41.720000646, 96.390, 1342.0, 36.6333
41.772521776, 96.390, 1375.0, 37.0810
41.825042907, 96.390, 1445.0, 38.0132
41.877564038, 96.390, 1366.0, 36.9594
41.930085169, 96.390, 1318.0, 36.3043
41.982606299, 96.390, 1234.0, 35.1283
42.035127430, 96.390, 1259.0, 35.4824
42.087648561, 96.390, 1538.0, 39.2173
42.140169691, 96.390, 1824.0, 42.7083
42.192690822, 96.390, 1850.0, 43.0116
42.245211953, 96.390, 1608.0, 40.0999
42.297733084, 96.390, 1509.0, 38.8458
42.350254214, 96.390, 1351.0, 36.7560
42.402775345, 96.390, 1255.0, 35.4260
42.455296476, 96.390, 1187.0, 34.4529
42.507817606, 96.390, 1191.0, 34.5109
42.560338737, 96.390, 1140.0, 33.7639
42.612859868, 96.390, 1177.0, 34.3074
42.665380999, 96.390, 1179.0, 34.3366
42.717902129, 96.390, 1324.0, 36.3868
42.770423260, 96.390, 1231.0, 35.0856
42.822944391, 96.390, 1236.0, 35.1568
42.875465521, 96.390, 1221.0, 34.9428
42.927986652, 96.390, 1152.0, 33.9411
42.980507783, 96.390, 1150.0, 33.9116
43.033028914, 96.390, 1159.0, 34.0441
43.085550044, 96.390, 1197.0, 34.5977
43.138071175, 96.390, 1252.0, 35.3836
43.190592306, 96.390, 1215.0, 34.8569
43.243113436, 96.390, 1159.0, 34.0441
43.295634567, 96.390, 1166.0, 34.1467
43.348155698, 96.390, 1168.0, 34.1760
43.400676828, 96.390, 1082.0, 32.8938
43.453197959, 96.390, 1129.0, 33.6006
43.505719090, 96.390, 1128.0, 33.5857
43.558240221, 96.390, 1205.0, 34.7131
43.610761351, 96.390, 1133.0, 33.6601
43.663282482, 96.390, 1140.0, 33.7639
43.715803613, 96.390, 1145.0, 33.8378
43.768324743, 96.390, 1209.0, 34.7707
43.820845874, 96.390, 1115.0, 33.3916
43.873367005, 96.390, 1207.0, 34.7419
43.925888136, 96.390, 1209.0, 34.7707
43.978409266, 96.390, 1187.0, 34.4529
44.030930397, 96.390, 1190.0, 34.4964
44.083451528, 96.390, 1208.0, 34.7563
44.135972658, 96.390, 1265.0, 35.5668
44.188493789, 96.390, 1164.0, 34.1174
44.241014920, 96.390, 1263.0, 35.5387
44.293536051, 96.390, 1166.0, 34.1467
44.346057181, 96.390, 1245.0, 35.2846
44.398578312, 96.390, 1213.0, 34.8281
44.451099443, 96.390, 1151.0, 33.9264
44.503620573, 96.390, 1194.0, 34.5543
44.556141704, 96.390, 1169.0, 34.1906
44.608662835, 96.390, 1277.0, 35.7351
44.661183966, 96.390, 1277.0, 35.7351
44.713705096, 96.390, 1241.0, 35.2278
44.766226227, 96.390, 1255.0, 35.4260
44.818747358, 96.390, 1307.0, 36.1525
44.871268488, 96.390, 1277.0, 35.7351
44.923789619, 96.390, 1125.0, 33.5410
44.976310750, 96.390, 1235.0, 35.1426
45.028831880, 96.390, 1212.0, 34.8138
45.081353011, 96.390, 1258.0, 35.4683
45.133874142, 96.390, 1370.0, 37.0135
45.186395273, 96.390, 1306.0, 36.1386
45.238916403, 96.390, 1331.0, 36.4829
45.291437534, 96.390, 1279.0, 35.7631
45.343958665, 96.390, 1217.0, 34.8855
45.396479795, 96.390, 1133.0, 33.6601
45.449000926, 96.390, 1074.0, 32.7719
45.501522057, 96.390, 1159.0, 34.0441
45.554043188, 96.390, 1096.0, 33.1059
45.606564318, 96.390, 1116.0, 33.4066
45.659085449, 96.390, 1145.0, 33.8378
45.711606580, 96.390, 1080.0, 32.8634
45.764127710, 96.390, 1147.0, 33.8674
45.816648841, 96.390, 1124.0, 33.5261
45.869169972, 96.390, 1043.0, 32.2955
45.921691103, 96.390, 1085.0, 32.9393
45.974212233, 96.390, 1146.0, 33.8526
46.026733364, 96.390, 1157.0, 34.0147
46.079254495, 96.390, 1220.0, 34.9285
46.131775625, 96.390, 1335.0, 36.5377
46.184296756, 96.390, 1633.0, 40.4104
46.236817887, 96.390, 1783.0, 42.2256
46.289339017, 96.390, 2076.0, 45.5631
46.341860148, 96.390, 2156.0, 46.4327
46.394381279, 96.390, 2230.0, 47.2229
46.446902410, 96.390, 2338.0, 48.3529
46.499423540, 96.390, 2369.0, 48.6724
46.551944671, 96.390, 2243.0, 47.3603
46.604465802, 96.390, 2010.0, 44.8330
46.656986932, 96.390, 1839.0, 42.8836
46.709508063, 96.390, 1647.0, 40.5832
46.762029194, 96.390, 1432.0, 37.8418
46.814550325, 96.390, 1207.0, 34.7419
46.867071455, 96.390, 1156.0, 34.0000
46.919592586, 96.390, 1065.0, 32.6343
46.972113717, 96.390, 1071.0, 32.7261
47.024634847, 96.390, 1007.0, 31.7333
47.077155978, 96.390, 1029.0, 32.0780
47.129677109, 96.390, 1048.0, 32.3728
47.182198240, 96.390, 1046.0, 32.3419
47.234719370, 96.390, 1014.0, 31.8434
47.287240501, 96.390, 1075.0, 32.7872
47.339761632, 96.390, 1050.0, 32.4037
47.392282762, 96.390, 1092.0, 33.0454
47.444803893, 96.390, 1156.0, 34.0000
47.497325024, 96.390, 1135.0, 33.6898
47.549846155, 96.390, 1083.0, 32.9090
47.602367285, 96.390, 1019.0, 31.9218
47.654888416, 96.390, 1037.0, 32.2025
47.707409547, 96.390, 1070.0, 32.7109
47.759930677, 96.390, 1186.0, 34.4384
47.812451808, 96.390, 1231.0, 35.0856
47.864972939, 96.390, 1104.0, 33.2265
47.917494069, 96.390, 1066.0, 32.6497
47.970015200, 96.390, 1089.0, 33.0000
48.022536331, 96.390, 986.0, 31.4006
48.075057462, 96.390, 999.0, 31.6070
48.127578592, 96.390, 1004.0, 31.6860
48.180099723, 96.390, 1056.0, 32.4962
48.232620854, 96.390, 1015.0, 31.8591
48.285141984, 96.390, 1046.0, 32.3419
48.337663115, 96.390, 1041.0, 32.2645
48.390184246, 96.390, 1168.0, 34.1760
48.442705377, 96.390, 1351.0, 36.7560
48.495226507, 96.390, 1353.0, 36.7831
48.547747638, 96.390, 1161.0, 34.0735
48.600268769, 96.390, 1178.0, 34.3220
48.652789899, 96.390, 1048.0, 32.3728
48.705311030, 96.390, 936.0, 30.5941
48.757832161, 96.390, 1017.0, 31.8904
48.810353292, 96.390, 892.0, 29.8664
48.862874422, 96.390, 1014.0, 31.8434
48.915395553, 96.390, 969.0, 31.1288
48.967916684, 96.390, 1010.0, 31.7805
49.020437814, 96.390, 1094.0, 33.0757
49.072958945, 96.390, 1058.0, 32.5269
49.125480076, 96.390, 1129.0, 33.6006
49.178001207, 96.390, 1154.0, 33.9706
49.230522337, 96.390, 1185.0, 34.4238
49.283043468, 96.390, 1105.0, 33.2415
49.335564599, 96.390, 1057.0, 32.5115
49.388085729, 96.390, 1124.0, 33.5261
49.440606860, 96.390, 1036.0, 32.1870
49.493127991, 96.390, 1002.0, 31.6544
49.545649121, 96.390, 1023.0, 31.9844
49.598170252, 96.390, 1015.0, 31.8591
49.650691383, 96.390, 998.0, 31.5911
49.703212514, 96.390, 1022.0, 31.9687
49.755733644, 96.390, 935.0, 30.5778
49.808254775, 96.390, 989.0, 31.4484
49.860775906, 96.390, 952.0, 30.8545
49.913297036, 96.390, 883.0, 29.7153
49.965818167, 96.390, 886.0, 29.7658
50.018339298, 96.390, 825.0, 28.7228
50.070860429, 96.390, 882.0, 29.6985
50.123381559, 96.390, 816.0, 28.5657
50.175902690, 96.390, 849.0, 29.1376
50.228423821, 96.390, 841.0, 29.0000
50.280944951, 96.390, 839.0, 28.9655
50.333466082, 96.390, 840.0, 28.9828
50.385987213, 96.390, 879.0, 29.6479
50.438508344, 96.390, 1012.0, 31.8119
50.491029474, 96.390, 1112.0, 33.3467
50.543550605, 96.390, 1185.0, 34.4238
50.596071736, 96.390, 1045.0, 32.3265
50.648592866, 96.390, 989.0, 31.4484
50.701113997, 96.390, 1052.0, 32.4345
50.753635128, 96.390, 927.0, 30.4467
50.806156258, 96.390, 924.0, 30.3974
50.858677389, 96.390, 985.0, 31.3847
50.911198520, 96.390, 903.0, 30.0500
50.963719651, 96.390, 938.0, 30.6268
51.016240781, 96.390, 1063.0, 32.6037
51.068761912, 96.390, 1120.0, 33.4664
51.121283043, 96.390, 1038.0, 32.2180
51.173804173, 96.390, 966.0, 31.0805
51.226325304, 96.390, 958.0, 30.9516
51.278846435, 96.390, 903.0, 30.0500
51.331367566, 96.390, 860.0, 29.3258
51.383888696, 96.390, 829.0, 28.7924
51.436409827, 96.390, 778.0, 27.8927
51.488930958, 96.390, 769.0, 27.7308
51.541452088, 96.390, 755.0, 27.4773
51.593973219, 96.390, 787.0, 28.0535
51.646494350, 96.390, 840.0, 28.9828
51.699015481, 96.390, 764.0, 27.6405
51.751536611, 96.390, 861.0, 29.3428
51.804057742, 96.390, 871.0, 29.5127
51.856578873, 96.390, 922.0, 30.3645
51.909100003, 96.390, 874.0, 29.5635
51.961621134, 96.390, 868.0, 29.4618
52.014142265, 96.390, 886.0, 29.7658
52.066663396, 96.390, 877.0, 29.6142
52.119184526, 96.390, 848.0, 29.1204
52.171705657, 96.390, 890.0, 29.8329
52.224226788, 96.390, 864.0, 29.3939
52.276747918, 96.390, 989.0, 31.4484
52.329269049, 96.390, 918.0, 30.2985
52.381790180, 96.390, 961.0, 31.0000
52.434311310, 96.390, 961.0, 31.0000
52.486832441, 96.390, 1053.0, 32.4500
52.539353572, 96.390, 1006.0, 31.7175
52.591874703, 96.390, 1013.0, 31.8277
52.644395833, 96.390, 930.0, 30.4959
52.696916964, 96.390, 943.0, 30.7083
52.749438095, 96.390, 915.0, 30.2490
52.801959225, 96.390, 911.0, 30.1828
52.854480356, 96.390, 868.0, 29.4618
52.907001487, 96.390, 806.0, 28.3901
52.959522618, 96.390, 875.0, 29.5804
53.012043748, 96.390, 842.0, 29.0172
53.064564879, 96.390, 790.0, 28.1069
53.117086010, 96.390, 814.0, 28.5307
53.169607140, 96.390, 835.0, 28.8964
53.222128271, 96.390, 755.0, 27.4773
53.274649402, 96.390, 788.0, 28.0713
53.327170533, 96.390, 815.0, 28.5482
53.379691663, 96.390, 827.0, 28.7576
53.432212794, 96.390, 841.0, 29.0000
53.484733925, 96.390, 834.0, 28.8791
53.537255055, 96.390, 895.0, 29.9166
53.589776186, 96.390, 832.0, 28.8444
53.642297317, 96.390, 861.0, 29.3428
53.694818448, 96.390, 762.0, 27.6043
53.747339578, 96.390, 757.0, 27.5136
53.799860709, 96.390, 792.0, 28.1425
53.852381840, 96.390, 902.0, 30.0333
53.904902970, 96.390, 992.0, 31.4960
53.957424101, 96.390, 1044.0, 32.3110
54.009945232, 96.390, 996.0, 31.5595
54.062466362, 96.390, 1003.0, 31.6702
54.114987493, 96.390, 889.0, 29.8161
54.167508624, 96.390, 828.0, 28.7750
54.220029755, 96.390, 883.0, 29.7153
54.272550885, 96.390, 908.0, 30.1330
54.325072016, 96.390, 864.0, 29.3939
54.377593147, 96.390, 905.0, 30.0832
54.430114277, 96.390, 920.0, 30.3315
54.482635408, 96.390, 860.0, 29.3258
54.535156539, 96.390, 853.0, 29.2062
54.587677670, 96.390, 806.0, 28.3901
54.640198800, 96.390, 756.0, 27.4955
54.692719931, 96.390, 707.0, 26.5895
54.745241062, 96.390, 714.0, 26.7208
54.797762192, 96.390, 759.0, 27.5500
54.850283323, 96.390, 771.0, 27.7669
54.902804454, 96.390, 753.0, 27.4408
54.955325585, 96.390, 722.0, 26.8701
55.007846715, 96.390, 747.0, 27.3313
55.060367846, 96.390, 736.0, 27.1293
55.112888977, 96.390, 780.0, 27.9285
55.165410107, 96.390, 717.0, 26.7769
55.217931238, 96.390, 765.0, 27.6586
55.270452369, 96.390, 770.0, 27.7489
55.322973499, 96.390, 834.0, 28.8791
55.375494630, 96.390, 911.0, 30.1828
55.428015761, 96.390, 882.0, 29.6985
55.480536892, 96.390, 852.0, 29.1890
55.533058022, 96.390, 870.0, 29.4958
55.585579153, 96.390, 894.0, 29.8998
55.638100284, 96.390, 801.0, 28.3019
55.690621414, 96.390, 862.0, 29.3598
55.743142545, 96.390, 852.0, 29.1890
55.795663676, 96.390, 881.0, 29.6816
55.848184807, 96.390, 846.0, 29.0861
55.900705937, 96.390, 961.0, 31.0000
55.953227068, 96.390, 882.0, 29.6985
56.005748199, 96.390, 933.0, 30.5450
56.058269329, 96.390, 926.0, 30.4302
56.110790460, 96.390, 968.0, 31.1127
56.163311591, 96.390, 854.0, 29.2233
56.215832722, 96.390, 907.0, 30.1164
56.268353852, 96.390, 855.0, 29.2404
56.320874983, 96.390, 811.0, 28.4781
56.373396114, 96.390, 823.0, 28.6880
56.425917244, 96.390, 840.0, 28.9828
56.478438375, 96.390, 801.0, 28.3019
56.530959506, 96.390, 878.0, 29.6311
56.583480637, 96.390, 790.0, 28.1069
56.636001767, 96.390, 788.0, 28.0713
56.688522898, 96.390, 761.0, 27.5862
56.741044029, 96.390, 718.0, 26.7955
56.793565159, 96.390, 708.0, 26.6083
56.846086290, 96.390, 696.0, 26.3818
56.898607421, 96.390, 744.0, 27.2764
56.951128551, 96.390, 775.0, 27.8388
57.003649682, 96.390, 715.0, 26.7395
57.056170813, 96.390, 687.0, 26.2107
57.108691944, 96.390, 732.0, 27.0555
57.161213074, 96.390, 800.0, 28.2843
57.213734205, 96.390, 905.0, 30.0832
57.266255336, 96.390, 830.0, 28.8097
57.318776466, 96.390, 776.0, 27.8568
57.371297597, 96.390, 757.0, 27.5136
57.423818728, 96.390, 776.0, 27.8568
57.476339859, 96.390, 755.0, 27.4773
57.528860989, 96.390, 780.0, 27.9285
57.581382120, 96.390, 741.0, 27.2213
57.633903251, 96.390, 738.0, 27.1662
57.686424381, 96.390, 781.0, 27.9464
57.738945512, 96.390, 787.0, 28.0535
57.791466643, 96.390, 826.0, 28.7402
57.843987774, 96.390, 840.0, 28.9828
57.896508904, 96.390, 785.0, 28.0179
57.949030035, 96.390, 822.0, 28.6705
58.001551166, 96.390, 848.0, 29.1204
58.054072296, 96.390, 820.0, 28.6356
58.106593427, 96.390, 815.0, 28.5482
58.159114558, 96.390, 784.0, 28.0000
58.211635689, 96.390, 776.0, 27.8568
58.264156819, 96.390, 706.0, 26.5707
58.316677950, 96.390, 759.0, 27.5500
58.369199081, 96.390, 762.0, 27.6043
58.421720211, 96.390, 784.0, 28.0000
58.474241342, 96.390, 807.0, 28.4077
58.526762473, 96.390, 838.0, 28.9482
58.579283603, 96.390, 807.0, 28.4077
58.631804734, 96.390, 797.0, 28.2312
58.684325865, 96.390, 799.0, 28.2666
58.736846996, 96.390, 834.0, 28.8791
58.789368126, 96.390, 820.0, 28.6356
58.841889257, 96.390, 854.0, 29.2233
58.894410388, 96.390, 871.0, 29.5127
58.946931518, 96.390, 961.0, 31.0000
58.999452649, 96.390, 958.0, 30.9516
59.051973780, 96.390, 883.0, 29.7153
59.104494911, 96.390, 980.0, 31.3050
59.157016041, 96.390, 955.0, 30.9031
59.209537172, 96.390, 1001.0, 31.6386
59.262058303, 96.390, 983.0, 31.3528
59.314579433, 96.390, 969.0, 31.1288
59.367100564, 96.390, 1082.0, 32.8938
59.419621695, 96.390, 1030.0, 32.0936
59.472142826, 96.390, 1145.0, 33.8378
59.524663956, 96.390, 1152.0, 33.9411
59.577185087, 96.390, 1192.0, 34.5254
59.629706218, 96.390, 1218.0, 34.8999
59.682227348, 96.390, 1334.0, 36.5240
59.734748479, 96.390, 1366.0, 36.9594
59.787269610, 96.390, 1309.0, 36.1801
59.839790740, 96.390, 1349.0, 36.7287
59.892311871, 96.390, 1423.0, 37.7227
59.944833002, 96.390, 1490.0, 38.6005
59.997354133, 96.390, 1506.0, 38.8072
60.049875263, 96.390, 1507.0, 38.8201
60.102396394, 96.390, 1671.0, 40.8779
60.154917525, 96.390, 1616.0, 40.1995
60.207438655, 96.390, 1727.0, 41.5572
60.259959786, 96.390, 1721.0, 41.4849
60.312480917, 96.390, 1840.0, 42.8952
60.365002048, 96.390, 1749.0, 41.8210
60.417523178, 96.390, 1925.0, 43.8748
60.470044309, 96.390, 2010.0, 44.8330
60.522565440, 96.390, 2237.0, 47.2969
60.575086570, 96.390, 2269.0, 47.6340
60.627607701, 96.390, 2033.0, 45.0888
60.680128832, 96.390, 1998.0, 44.6990
60.732649963, 96.390, 1859.0, 43.1161
60.785171093, 96.390, 1746.0, 41.7852
60.837692224, 96.390, 1488.0, 38.5746
60.890213355, 96.390, 1529.0, 39.1024
60.942734485, 96.390, 1375.0, 37.0810
60.995255616, 96.390, 1419.0, 37.6696
61.047776747, 96.390, 1427.0, 37.7757
61.100297878, 96.390, 1336.0, 36.5513
61.152819008, 96.390, 1391.0, 37.2961
61.205340139, 96.390, 1373.0, 37.0540
61.257861270, 96.390, 1375.0, 37.0810
61.310382400, 96.390, 1225.0, 35.0000
61.362903531, 96.390, 1266.0, 35.5809
61.415424662, 96.390, 1156.0, 34.0000
61.467945792, 96.390, 1240.0, 35.2136
61.520466923, 96.390, 1292.0, 35.9444
61.572988054, 96.390, 1141.0, 33.7787
61.625509185, 96.390, 1145.0, 33.8378
61.678030315, 96.390, 1223.0, 34.9714
61.730551446, 96.390, 1375.0, 37.0810
61.783072577, 96.390, 1557.0, 39.4588
61.835593707, 96.390, 1684.0, 41.0366
61.888114838, 96.390, 1593.0, 39.9124
61.940635969, 96.390, 1508.0, 38.8330
61.993157100, 96.390, 1307.0, 36.1525
62.045678230, 96.390, 1234.0, 35.1283
62.098199361, 96.390, 1117.0, 33.4215
62.150720492, 96.390, 999.0, 31.6070
62.203241622, 96.390, 965.0, 31.0644
62.255762753, 96.390, 838.0, 28.9482
62.308283884, 96.390, 854.0, 29.2233
62.360805015, 96.390, 862.0, 29.3598
62.413326145, 96.390, 868.0, 29.4618
62.465847276, 96.390, 803.0, 28.3373
62.518368407, 96.390, 833.0, 28.8617
62.570889537, 96.390, 790.0, 28.1069
62.623410668, 96.390, 796.0, 28.2135
62.675931799, 96.390, 800.0, 28.2843
62.728452930, 96.390, 779.0, 27.9106
62.780974060, 96.390, 778.0, 27.8927
62.833495191, 96.390, 809.0, 28.4429
62.886016322, 96.390, 766.0, 27.6767
62.938537452, 96.390, 779.0, 27.9106
62.991058583, 96.390, 784.0, 28.0000
63.043579714, 96.390, 739.0, 27.1846
63.096100844, 96.390, 702.0, 26.4953
63.148621975, 96.390, 679.0, 26.0576
63.201143106, 96.390, 655.0, 25.5930
63.253664237, 96.390, 668.0, 25.8457
63.306185367, 96.390, 655.0, 25.5930
63.358706498, 96.390, 666.0, 25.8070
63.411227629, 96.390, 635.0, 25.1992
63.463748759, 96.390, 640.0, 25.2982
63.516269890, 96.390, 661.0, 25.7099
63.568791021, 96.390, 622.0, 24.9399
63.621312152, 96.390, 664.0, 25.7682
63.673833282, 96.390, 578.0, 24.0416
63.726354413, 96.390, 617.0, 24.8395
63.778875544, 96.390, 664.0, 25.7682
63.831396674, 96.390, 613.0, 24.7588
63.883917805, 96.390, 643.0, 25.3574
63.936438936, 96.390, 609.0, 24.6779
63.988960067, 96.390, 609.0, 24.6779
64.041481197, 96.390, 588.0, 24.2487
64.094002328, 96.390, 591.0, 24.3105
64.146523459, 96.390, 607.0, 24.6374
64.199044589, 96.390, 655.0, 25.5930
64.251565720, 96.390, 585.0, 24.1868
64.304086851, 96.390, 644.0, 25.3772
64.356607981, 96.390, 636.0, 25.2190
64.409129112, 96.390, 612.0, 24.7386
64.461650243, 96.390, 575.0, 23.9792
64.514171374, 96.390, 578.0, 24.0416
64.566692504, 96.390, 579.0, 24.0624
64.619213635, 96.390, 555.0, 23.5584
64.671734766, 96.390, 584.0, 24.1661
64.724255896, 96.390, 599.0, 24.4745
64.776777027, 96.390, 593.0, 24.3516
64.829298158, 96.390, 578.0, 24.0416
64.881819289, 96.390, 621.0, 24.9199
64.934340419, 96.390, 622.0, 24.9399
64.986861550, 96.390, 632.0, 25.1396