File: Files_organized_for_plots/470_day/35Al-Corner_SolventExchange.csv
[Measurement conditions]
Sample identification,35_AlCorner27Oct21_Act08Jan22_B2_0833M_NaOH_LS0152_solvent_exchange
Comment - 1,"Configuration=Stage for Flat Samples/Holders, Owner=User-1, Creation date=7/1/2020 9:53:24 AM"
Comment - 2,"Goniometer=Theta/Theta; Minimum step size 2Theta:0.0001; Minimum step size Omega:0.0001"
Comment - 3,"Sample stage=Stage for flat samples/holders"
Comment - 4,"Diffractometer system=EMPYREAN"
Comment - 5,"Measurement program=C:\Users\tmr79\OneDrive - The Pennsylvania State University\Documents\NEUP\XRD\Cement\Zerobackground scan.xrdmp, Identifier={98A3B11C-88F9-4AA6-982C-73314A311EF5}"
Anode material,Cu
K-Alpha1 wavelength,1.5405980
K-Alpha2 wavelength,1.5444260
Ratio K-Alpha2/K-Alpha1,0.500
Divergence slit,Fixed,0.25
Monochromator used,NO
Generator voltage, 45
Tube current, 40
File date and time,25/Apr/2023 15:07
Unit cell,
h k l, 0 0 0
Scan axis,Gonio
Scan range,4.994599997,64.999991833
Scan step size,0.0262606
No. of points, 2285
Scan type,CONTINUOUS
Time per step,96.390
[Scan points]
Angle, TimePerStep, Intensity, ESD
5.007730280, 96.390, 3030.0, 55.0454
5.060251411, 96.390, 2971.0, 54.5069
5.112772541, 96.390, 2846.0, 53.3479
5.165293672, 96.390, 2807.0, 52.9811
5.217814803, 96.390, 2942.0, 54.2402
5.270335934, 96.390, 2821.0, 53.1131
5.322857064, 96.390, 2842.0, 53.3104
5.375378195, 96.390, 2835.0, 53.2447
5.427899326, 96.390, 2844.0, 53.3292
5.480420456, 96.390, 2806.0, 52.9717
5.532941587, 96.390, 2755.0, 52.4881
5.585462718, 96.390, 2771.0, 52.6403
5.637983849, 96.390, 2731.0, 52.2590
5.690504979, 96.390, 2712.0, 52.0769
5.743026110, 96.390, 2759.0, 52.5262
5.795547241, 96.390, 2750.0, 52.4404
5.848068371, 96.390, 2764.0, 52.5738
5.900589502, 96.390, 2760.0, 52.5357
5.953110633, 96.390, 2618.0, 51.1664
6.005631763, 96.390, 2782.0, 52.7447
6.058152894, 96.390, 2639.0, 51.3712
6.110674025, 96.390, 2729.0, 52.2398
6.163195156, 96.390, 2662.0, 51.5946
6.215716286, 96.390, 2669.0, 51.6624
6.268237417, 96.390, 2710.0, 52.0577
6.320758548, 96.390, 2607.0, 51.0588
6.373279678, 96.390, 2587.0, 50.8626
6.425800809, 96.390, 2665.0, 51.6236
6.478321940, 96.390, 2582.0, 50.8134
6.530843071, 96.390, 2696.0, 51.9230
6.583364201, 96.390, 2678.0, 51.7494
6.635885332, 96.390, 2731.0, 52.2590
6.688406463, 96.390, 2694.0, 51.9038
6.740927593, 96.390, 2769.0, 52.6213
6.793448724, 96.390, 2808.0, 52.9906
6.845969855, 96.390, 3010.0, 54.8635
6.898490986, 96.390, 3122.0, 55.8749
6.951012116, 96.390, 3403.0, 58.3352
7.003533247, 96.390, 3892.0, 62.3859
7.056054378, 96.390, 4404.0, 66.3626
7.108575508, 96.390, 5450.0, 73.8241
7.161096639, 96.390, 7173.0, 84.6936
7.213617770, 96.390, 7345.0, 85.7030
7.266138900, 96.390, 3858.0, 62.1128
7.318660031, 96.390, 2762.0, 52.5547
7.371181162, 96.390, 2555.0, 50.5470
7.423702293, 96.390, 2424.0, 49.2341
7.476223423, 96.390, 2334.0, 48.3115
7.528744554, 96.390, 2316.0, 48.1248
7.581265685, 96.390, 2302.0, 47.9792
7.633786815, 96.390, 2421.0, 49.2037
7.686307946, 96.390, 2331.0, 48.2804
7.738829077, 96.390, 2221.0, 47.1275
7.791350208, 96.390, 2232.0, 47.2440
7.843871338, 96.390, 2194.0, 46.8402
7.896392469, 96.390, 2236.0, 47.2864
7.948913600, 96.390, 2262.0, 47.5605
8.001434730, 96.390, 2318.0, 48.1456
8.053955861, 96.390, 2143.0, 46.2925
8.106476992, 96.390, 2231.0, 47.2335
8.158998123, 96.390, 2251.0, 47.4447
8.211519253, 96.390, 2227.0, 47.1911
8.264040384, 96.390, 2136.0, 46.2169
8.316561515, 96.390, 2207.0, 46.9787
8.369082645, 96.390, 2129.0, 46.1411
8.421603776, 96.390, 2116.0, 46.0000
8.474124907, 96.390, 2098.0, 45.8039
8.526646038, 96.390, 2141.0, 46.2709
8.579167168, 96.390, 2152.0, 46.3897
8.631688299, 96.390, 2191.0, 46.8081
8.684209430, 96.390, 2240.0, 47.3286
8.736730560, 96.390, 2113.0, 45.9674
8.789251691, 96.390, 2166.0, 46.5403
8.841772822, 96.390, 2006.0, 44.7884
8.894293952, 96.390, 2085.0, 45.6618
8.946815083, 96.390, 2027.0, 45.0222
8.999336214, 96.390, 2087.0, 45.6837
9.051857345, 96.390, 2049.0, 45.2659
9.104378475, 96.390, 2018.0, 44.9222
9.156899606, 96.390, 1940.0, 44.0454
9.209420737, 96.390, 2085.0, 45.6618
9.261941867, 96.390, 2100.0, 45.8258
9.314462998, 96.390, 2074.0, 45.5412
9.366984129, 96.390, 2045.0, 45.2217
9.419505260, 96.390, 1973.0, 44.4185
9.472026390, 96.390, 1981.0, 44.5084
9.524547521, 96.390, 2116.0, 46.0000
9.577068652, 96.390, 1991.0, 44.6206
9.629589782, 96.390, 2076.0, 45.5631
9.682110913, 96.390, 2081.0, 45.6180
9.734632044, 96.390, 2113.0, 45.9674
9.787153175, 96.390, 2162.0, 46.4973
9.839674305, 96.390, 2127.0, 46.1194
9.892195436, 96.390, 2293.0, 47.8853
9.944716567, 96.390, 2384.0, 48.8262
9.997237697, 96.390, 2688.0, 51.8459
10.049758828, 96.390, 3036.0, 55.0999
10.102279959, 96.390, 3873.0, 62.2334
10.154801090, 96.390, 5136.0, 71.6659
10.207322220, 96.390, 4815.0, 69.3902
10.259843351, 96.390, 2699.0, 51.9519
10.312364482, 96.390, 2231.0, 47.2335
10.364885612, 96.390, 2032.0, 45.0777
10.417406743, 96.390, 1954.0, 44.2041
10.469927874, 96.390, 1966.0, 44.3396
10.522449004, 96.390, 2016.0, 44.8999
10.574970135, 96.390, 2020.0, 44.9444
10.627491266, 96.390, 2050.0, 45.2769
10.680012397, 96.390, 1950.0, 44.1588
10.732533527, 96.390, 2047.0, 45.2438
10.785054658, 96.390, 1958.0, 44.2493
10.837575789, 96.390, 2016.0, 44.8999
10.890096919, 96.390, 2029.0, 45.0444
10.942618050, 96.390, 2176.0, 46.6476
10.995139181, 96.390, 2148.0, 46.3465
11.047660312, 96.390, 2298.0, 47.9375
11.100181442, 96.390, 2282.0, 47.7703
11.152702573, 96.390, 2376.0, 48.7442
11.205223704, 96.390, 2575.0, 50.7445
11.257744834, 96.390, 2560.0, 50.5964
11.310265965, 96.390, 2910.0, 53.9444
11.362787096, 96.390, 3171.0, 56.3116
11.415308227, 96.390, 3807.0, 61.7009
11.467829357, 96.390, 4497.0, 67.0597
11.520350488, 96.390, 5254.0, 72.4845
11.572871619, 96.390, 6472.0, 80.4487
11.625392749, 96.390, 7313.0, 85.5161
11.677913880, 96.390, 7746.0, 88.0114
11.730435011, 96.390, 6866.0, 82.8613
11.782956141, 96.390, 5410.0, 73.5527
11.835477272, 96.390, 4267.0, 65.3223
11.887998403, 96.390, 3326.0, 57.6715
11.940519534, 96.390, 2837.0, 53.2635
11.993040664, 96.390, 2597.0, 50.9608
12.045561795, 96.390, 2414.0, 49.1325
12.098082926, 96.390, 2233.0, 47.2546
12.150604056, 96.390, 2183.0, 46.7226
12.203125187, 96.390, 2295.0, 47.9062
12.255646318, 96.390, 2303.0, 47.9896
12.308167449, 96.390, 2563.0, 50.6261
12.360688579, 96.390, 2818.0, 53.0848
12.413209710, 96.390, 3239.0, 56.9122
12.465730841, 96.390, 4054.0, 63.6710
12.518251971, 96.390, 3140.0, 56.0357
12.570773102, 96.390, 2186.0, 46.7547
12.623294233, 96.390, 1879.0, 43.3474
12.675815364, 96.390, 1879.0, 43.3474
12.728336494, 96.390, 1851.0, 43.0232
12.780857625, 96.390, 1841.0, 42.9069
12.833378756, 96.390, 1692.0, 41.1339
12.885899886, 96.390, 1763.0, 41.9881
12.938421017, 96.390, 1753.0, 41.8688
12.990942148, 96.390, 1635.0, 40.4351
13.043463279, 96.390, 1690.0, 41.1096
13.095984409, 96.390, 1705.0, 41.2916
13.148505540, 96.390, 1562.0, 39.5221
13.201026671, 96.390, 1686.0, 41.0609
13.253547801, 96.390, 1661.0, 40.7554
13.306068932, 96.390, 1727.0, 41.5572
13.358590063, 96.390, 1687.0, 41.0731
13.411111193, 96.390, 1901.0, 43.6005
13.463632324, 96.390, 2094.0, 45.7602
13.516153455, 96.390, 2212.0, 47.0319
13.568674586, 96.390, 1838.0, 42.8719
13.621195716, 96.390, 1795.0, 42.3674
13.673716847, 96.390, 1910.0, 43.7035
13.726237978, 96.390, 2056.0, 45.3431
13.778759108, 96.390, 2216.0, 47.0744
13.831280239, 96.390, 2553.0, 50.5272
13.883801370, 96.390, 3054.0, 55.2630
13.936322501, 96.390, 3699.0, 60.8194
13.988843631, 96.390, 3381.0, 58.1464
14.041364762, 96.390, 2398.0, 48.9694
14.093885893, 96.390, 2071.0, 45.5082
14.146407023, 96.390, 1950.0, 44.1588
14.198928154, 96.390, 2086.0, 45.6727
14.251449285, 96.390, 2231.0, 47.2335
14.303970416, 96.390, 2228.0, 47.2017
14.356491546, 96.390, 1609.0, 40.1123
14.409012677, 96.390, 1520.0, 38.9872
14.461533808, 96.390, 1559.0, 39.4842
14.514054938, 96.390, 1517.0, 38.9487
14.566576069, 96.390, 1429.0, 37.8021
14.619097200, 96.390, 1450.0, 38.0789
14.671618331, 96.390, 1376.0, 37.0945
14.724139461, 96.390, 1436.0, 37.8946
14.776660592, 96.390, 1357.0, 36.8375
14.829181723, 96.390, 1384.0, 37.2022
14.881702853, 96.390, 1386.0, 37.2290
14.934223984, 96.390, 1349.0, 36.7287
14.986745115, 96.390, 1410.0, 37.5500
15.039266245, 96.390, 1430.0, 37.8153
15.091787376, 96.390, 1502.0, 38.7556
15.144308507, 96.390, 1608.0, 40.0999
15.196829638, 96.390, 1829.0, 42.7668
15.249350768, 96.390, 2267.0, 47.6130
15.301871899, 96.390, 2243.0, 47.3603
15.354393030, 96.390, 1587.0, 39.8372
15.406914160, 96.390, 1398.0, 37.3898
15.459435291, 96.390, 1402.0, 37.4433
15.511956422, 96.390, 1331.0, 36.4829
15.564477553, 96.390, 1313.0, 36.2353
15.616998683, 96.390, 1334.0, 36.5240
15.669519814, 96.390, 1287.0, 35.8748
15.722040945, 96.390, 1306.0, 36.1386
15.774562075, 96.390, 1303.0, 36.0971
15.827083206, 96.390, 1394.0, 37.3363
15.879604337, 96.390, 1433.0, 37.8550
15.932125468, 96.390, 1474.0, 38.3927
15.984646598, 96.390, 1679.0, 40.9756
16.037167729, 96.390, 1904.0, 43.6348
16.089688860, 96.390, 2505.0, 50.0500
16.142209990, 96.390, 2650.0, 51.4782
16.194731121, 96.390, 1901.0, 43.6005
16.247252252, 96.390, 1469.0, 38.3275
16.299773382, 96.390, 1349.0, 36.7287
16.352294513, 96.390, 1362.0, 36.9053
16.404815644, 96.390, 1313.0, 36.2353
16.457336775, 96.390, 1362.0, 36.9053
16.509857905, 96.390, 1266.0, 35.5809
16.562379036, 96.390, 1347.0, 36.7015
16.614900167, 96.390, 1270.0, 35.6371
16.667421297, 96.390, 1277.0, 35.7351
16.719942428, 96.390, 1207.0, 34.7419
16.772463559, 96.390, 1263.0, 35.5387
16.824984690, 96.390, 1236.0, 35.1568
16.877505820, 96.390, 1301.0, 36.0694
16.930026951, 96.390, 1224.0, 34.9857
16.982548082, 96.390, 1187.0, 34.4529
17.035069212, 96.390, 1158.0, 34.0294
17.087590343, 96.390, 1219.0, 34.9142
17.140111474, 96.390, 1216.0, 34.8712
17.192632605, 96.390, 1267.0, 35.5949
17.245153735, 96.390, 1177.0, 34.3074
17.297674866, 96.390, 1155.0, 33.9853
17.350195997, 96.390, 1157.0, 34.0147
17.402717127, 96.390, 1146.0, 33.8526
17.455238258, 96.390, 1205.0, 34.7131
17.507759389, 96.390, 1196.0, 34.5832
17.560280520, 96.390, 1158.0, 34.0294
17.612801650, 96.390, 1313.0, 36.2353
17.665322781, 96.390, 1284.0, 35.8329
17.717843912, 96.390, 1293.0, 35.9583
17.770365042, 96.390, 1270.0, 35.6371
17.822886173, 96.390, 1360.0, 36.8782
17.875407304, 96.390, 1364.0, 36.9324
17.927928434, 96.390, 1310.0, 36.1939
17.980449565, 96.390, 1455.0, 38.1445
18.032970696, 96.390, 1622.0, 40.2741
18.085491827, 96.390, 1818.0, 42.6380
18.138012957, 96.390, 2234.0, 47.2652
18.190534088, 96.390, 2965.0, 54.4518
18.243055219, 96.390, 4492.0, 67.0224
18.295576349, 96.390, 6272.0, 79.1960
18.348097480, 96.390, 5871.0, 76.6225
18.400618611, 96.390, 6128.0, 78.2815
18.453139742, 96.390, 6679.0, 81.7251
18.505660872, 96.390, 6264.0, 79.1454
18.558182003, 96.390, 5326.0, 72.9794
18.610703134, 96.390, 4782.0, 69.1520
18.663224264, 96.390, 4700.0, 68.5565
18.715745395, 96.390, 4752.0, 68.9348
18.768266526, 96.390, 4981.0, 70.5762
18.820787657, 96.390, 3901.0, 62.4580
18.873308787, 96.390, 2685.0, 51.8170
18.925829918, 96.390, 2122.0, 46.0652
18.978351049, 96.390, 1687.0, 41.0731
19.030872179, 96.390, 1508.0, 38.8330
19.083393310, 96.390, 1462.0, 38.2361
19.135914441, 96.390, 1398.0, 37.3898
19.188435572, 96.390, 1366.0, 36.9594
19.240956702, 96.390, 1395.0, 37.3497
19.293477833, 96.390, 1408.0, 37.5233
19.345998964, 96.390, 1543.0, 39.2810
19.398520094, 96.390, 1813.0, 42.5793
19.451041225, 96.390, 1834.0, 42.8252
19.503562356, 96.390, 1547.0, 39.3319
19.556083486, 96.390, 1412.0, 37.5766
19.608604617, 96.390, 1438.0, 37.9210
19.661125748, 96.390, 1588.0, 39.8497
19.713646879, 96.390, 1672.0, 40.8901
19.766168009, 96.390, 1632.0, 40.3980
19.818689140, 96.390, 1696.0, 41.1825
19.871210271, 96.390, 2023.0, 44.9778
19.923731401, 96.390, 2686.0, 51.8266
19.976252532, 96.390, 3717.0, 60.9672
20.028773663, 96.390, 2732.0, 52.2685
20.081294794, 96.390, 2209.0, 47.0000
20.133815924, 96.390, 2612.0, 51.1077
20.186337055, 96.390, 3860.0, 62.1289
20.238858186, 96.390, 5876.0, 76.6551
20.291379316, 96.390, 7587.0, 87.1034
20.343900447, 96.390, 6240.0, 78.9937
20.396421578, 96.390, 5386.0, 73.3894
20.448942709, 96.390, 4994.0, 70.6682
20.501463839, 96.390, 4319.0, 65.7191
20.553984970, 96.390, 3676.0, 60.6300
20.606506101, 96.390, 4087.0, 63.9296
20.659027231, 96.390, 5453.0, 73.8444
20.711548362, 96.390, 7522.0, 86.7295
20.764069493, 96.390, 4758.0, 68.9783
20.816590623, 96.390, 2397.0, 48.9592
20.869111754, 96.390, 1715.0, 41.4126
20.921632885, 96.390, 1526.0, 39.0640
20.974154016, 96.390, 1480.0, 38.4708
21.026675146, 96.390, 1338.0, 36.5787
21.079196277, 96.390, 1284.0, 35.8329
21.131717408, 96.390, 1249.0, 35.3412
21.184238538, 96.390, 1197.0, 34.5977
21.236759669, 96.390, 1273.0, 35.6791
21.289280800, 96.390, 1372.0, 37.0405
21.341801931, 96.390, 1545.0, 39.3065
21.394323061, 96.390, 1703.0, 41.2674
21.446844192, 96.390, 1594.0, 39.9249
21.499365323, 96.390, 1473.0, 38.3797
21.551886453, 96.390, 1593.0, 39.9124
21.604407584, 96.390, 2064.0, 45.4313
21.656928715, 96.390, 2897.0, 53.8238
21.709449846, 96.390, 3027.0, 55.0182
21.761970976, 96.390, 2081.0, 45.6180
21.814492107, 96.390, 1372.0, 37.0405
21.867013238, 96.390, 1228.0, 35.0428
21.919534368, 96.390, 1141.0, 33.7787
21.972055499, 96.390, 1098.0, 33.1361
22.024576630, 96.390, 1100.0, 33.1662
22.077097761, 96.390, 1135.0, 33.6898
22.129618891, 96.390, 1066.0, 32.6497
22.182140022, 96.390, 1164.0, 34.1174
22.234661153, 96.390, 1137.0, 33.7194
22.287182283, 96.390, 1221.0, 34.9428
22.339703414, 96.390, 1305.0, 36.1248
22.392224545, 96.390, 1373.0, 37.0540
22.444745675, 96.390, 1333.0, 36.5103
22.497266806, 96.390, 1293.0, 35.9583
22.549787937, 96.390, 1250.0, 35.3553
22.602309068, 96.390, 1245.0, 35.2846
22.654830198, 96.390, 1172.0, 34.2345
22.707351329, 96.390, 1166.0, 34.1467
22.759872460, 96.390, 1233.0, 35.1141
22.812393590, 96.390, 1312.0, 36.2215
22.864914721, 96.390, 1397.0, 37.3765
22.917435852, 96.390, 1395.0, 37.3497
22.969956983, 96.390, 1375.0, 37.0810
23.022478113, 96.390, 1484.0, 38.5227
23.074999244, 96.390, 1633.0, 40.4104
23.127520375, 96.390, 1915.0, 43.7607
23.180041505, 96.390, 2162.0, 46.4973
23.232562636, 96.390, 2140.0, 46.2601
23.285083767, 96.390, 2178.0, 46.6690
23.337604898, 96.390, 2519.0, 50.1896
23.390126028, 96.390, 2988.0, 54.6626
23.442647159, 96.390, 3480.0, 58.9915
23.495168290, 96.390, 3578.0, 59.8164
23.547689420, 96.390, 3359.0, 57.9569
23.600210551, 96.390, 2943.0, 54.2494
23.652731682, 96.390, 2354.0, 48.5180
23.705252813, 96.390, 2214.0, 47.0532
23.757773943, 96.390, 2008.0, 44.8107
23.810295074, 96.390, 2079.0, 45.5961
23.862816205, 96.390, 2468.0, 49.6790
23.915337335, 96.390, 3212.0, 56.6745
23.967858466, 96.390, 4414.0, 66.4379
24.020379597, 96.390, 5036.0, 70.9648
24.072900727, 96.390, 4128.0, 64.2495
24.125421858, 96.390, 3477.0, 58.9661
24.177942989, 96.390, 3686.0, 60.7124
24.230464120, 96.390, 4197.0, 64.7843
24.282985250, 96.390, 4642.0, 68.1322
24.335506381, 96.390, 4053.0, 63.6632
24.388027512, 96.390, 3176.0, 56.3560
24.440548642, 96.390, 2419.0, 49.1833
24.493069773, 96.390, 1990.0, 44.6094
24.545590904, 96.390, 1736.0, 41.6653
24.598112035, 96.390, 1454.0, 38.1314
24.650633165, 96.390, 1366.0, 36.9594
24.703154296, 96.390, 1287.0, 35.8748
24.755675427, 96.390, 1255.0, 35.4260
24.808196557, 96.390, 1141.0, 33.7787
24.860717688, 96.390, 1199.0, 34.6266
24.913238819, 96.390, 1151.0, 33.9264
24.965759950, 96.390, 1125.0, 33.5410
25.018281080, 96.390, 1112.0, 33.3467
25.070802211, 96.390, 1096.0, 33.1059
25.123323342, 96.390, 1101.0, 33.1813
25.175844472, 96.390, 1069.0, 32.6956
25.228365603, 96.390, 1023.0, 31.9844
25.280886734, 96.390, 1037.0, 32.2025
25.333407864, 96.390, 1289.0, 35.9026
25.385928995, 96.390, 1594.0, 39.9249
25.438450126, 96.390, 2113.0, 45.9674
25.490971257, 96.390, 1778.0, 42.1663
25.543492387, 96.390, 1382.0, 37.1753
25.596013518, 96.390, 1075.0, 32.7872
25.648534649, 96.390, 1105.0, 33.2415
25.701055779, 96.390, 995.0, 31.5436
25.753576910, 96.390, 1009.0, 31.7648
25.806098041, 96.390, 1088.0, 32.9848
25.858619172, 96.390, 1065.0, 32.6343
25.911140302, 96.390, 1156.0, 34.0000
25.963661433, 96.390, 1389.0, 37.2693
26.016182564, 96.390, 1566.0, 39.5727
26.068703694, 96.390, 1658.0, 40.7185
26.121224825, 96.390, 2026.0, 45.0111
26.173745956, 96.390, 1746.0, 41.7852
26.226267087, 96.390, 1452.0, 38.1051
26.278788217, 96.390, 1185.0, 34.4238
26.331309348, 96.390, 1125.0, 33.5410
26.383830479, 96.390, 1171.0, 34.2199
26.436351609, 96.390, 1177.0, 34.3074
26.488872740, 96.390, 1226.0, 35.0143
26.541393871, 96.390, 1225.0, 35.0000
26.593915002, 96.390, 1169.0, 34.1906
26.646436132, 96.390, 1191.0, 34.5109
26.698957263, 96.390, 1262.0, 35.5246
26.751478394, 96.390, 1232.0, 35.0999
26.803999524, 96.390, 1362.0, 36.9053
26.856520655, 96.390, 1449.0, 38.0657
26.909041786, 96.390, 1607.0, 40.0874
26.961562916, 96.390, 1823.0, 42.6966
27.014084047, 96.390, 2147.0, 46.3357
27.066605178, 96.390, 3034.0, 55.0818
27.119126309, 96.390, 4605.0, 67.8602
27.171647439, 96.390, 5034.0, 70.9507
27.224168570, 96.390, 3850.0, 62.0484
27.276689701, 96.390, 2732.0, 52.2685
27.329210831, 96.390, 2079.0, 45.5961
27.381731962, 96.390, 2152.0, 46.3897
27.434253093, 96.390, 2240.0, 47.3286
27.486774224, 96.390, 2342.0, 48.3942
27.539295354, 96.390, 2174.0, 46.6262
27.591816485, 96.390, 1953.0, 44.1928
27.644337616, 96.390, 1915.0, 43.7607
27.696858746, 96.390, 1990.0, 44.6094
27.749379877, 96.390, 1979.0, 44.4860
27.801901008, 96.390, 2115.0, 45.9891
27.854422139, 96.390, 2023.0, 44.9778
27.906943269, 96.390, 1875.0, 43.3013
27.959464400, 96.390, 1745.0, 41.7732
28.011985531, 96.390, 1702.0, 41.2553
28.064506661, 96.390, 1522.0, 39.0128
28.117027792, 96.390, 1444.0, 38.0000
28.169548923, 96.390, 1300.0, 36.0555
28.222070054, 96.390, 1198.0, 34.6121
28.274591184, 96.390, 1102.0, 33.1964
28.327112315, 96.390, 1127.0, 33.5708
28.379633446, 96.390, 1015.0, 31.8591
28.432154576, 96.390, 1053.0, 32.4500
28.484675707, 96.390, 1076.0, 32.8024
28.537196838, 96.390, 963.0, 31.0322
28.589717968, 96.390, 1021.0, 31.9531
28.642239099, 96.390, 1116.0, 33.4066
28.694760230, 96.390, 1233.0, 35.1141
28.747281361, 96.390, 1380.0, 37.1484
28.799802491, 96.390, 1394.0, 37.3363
28.852323622, 96.390, 1138.0, 33.7343
28.904844753, 96.390, 1097.0, 33.1210
28.957365883, 96.390, 1041.0, 32.2645
29.009887014, 96.390, 1198.0, 34.6121
29.062408145, 96.390, 1361.0, 36.8917
29.114929276, 96.390, 1617.0, 40.2119
29.167450406, 96.390, 1382.0, 37.1753
29.219971537, 96.390, 1160.0, 34.0588
29.272492668, 96.390, 943.0, 30.7083
29.325013798, 96.390, 1000.0, 31.6228
29.377534929, 96.390, 979.0, 31.2890
29.430056060, 96.390, 958.0, 30.9516
29.482577191, 96.390, 1017.0, 31.8904
29.535098321, 96.390, 997.0, 31.5753
29.587619452, 96.390, 1076.0, 32.8024
29.640140583, 96.390, 1095.0, 33.0908
29.692661713, 96.390, 1123.0, 33.5112
29.745182844, 96.390, 1287.0, 35.8748
29.797703975, 96.390, 1526.0, 39.0640
29.850225105, 96.390, 2148.0, 46.3465
29.902746236, 96.390, 3090.0, 55.5878
29.955267367, 96.390, 4435.0, 66.5958
30.007788498, 96.390, 3740.0, 61.1555
30.060309628, 96.390, 2869.0, 53.5630
30.112830759, 96.390, 1867.0, 43.2088
30.165351890, 96.390, 1443.0, 37.9868
30.217873020, 96.390, 1240.0, 35.2136
30.270394151, 96.390, 1114.0, 33.3766
30.322915282, 96.390, 1130.0, 33.6155
30.375436413, 96.390, 992.0, 31.4960
30.427957543, 96.390, 1059.0, 32.5423
30.480478674, 96.390, 1049.0, 32.3883
30.532999805, 96.390, 1115.0, 33.3916
30.585520935, 96.390, 1237.0, 35.1710
30.638042066, 96.390, 1486.0, 38.5487
30.690563197, 96.390, 1423.0, 37.7227
30.743084328, 96.390, 1495.0, 38.6652
30.795605458, 96.390, 1590.0, 39.8748
30.848126589, 96.390, 1845.0, 42.9535
30.900647720, 96.390, 1564.0, 39.5474
30.953168850, 96.390, 1381.0, 37.1618
31.005689981, 96.390, 1280.0, 35.7771
31.058211112, 96.390, 1228.0, 35.0428
31.110732243, 96.390, 1501.0, 38.7427
31.163253373, 96.390, 1937.0, 44.0114
31.215774504, 96.390, 2471.0, 49.7092
31.268295635, 96.390, 2028.0, 45.0333
31.320816765, 96.390, 1645.0, 40.5586
31.373337896, 96.390, 1530.0, 39.1152
31.425859027, 96.390, 1646.0, 40.5709
31.478380157, 96.390, 1734.0, 41.6413
31.530901288, 96.390, 1810.0, 42.5441
31.583422419, 96.390, 1779.0, 42.1782
31.635943550, 96.390, 1669.0, 40.8534
31.688464680, 96.390, 1540.0, 39.2428
31.740985811, 96.390, 1439.0, 37.9342
31.793506942, 96.390, 1482.0, 38.4968
31.846028072, 96.390, 1754.0, 41.8808
31.898549203, 96.390, 2137.0, 46.2277
31.951070334, 96.390, 2810.0, 53.0094
32.003591465, 96.390, 4118.0, 64.1716
32.056112595, 96.390, 5971.0, 77.2722
32.108633726, 96.390, 4772.0, 69.0797
32.161154857, 96.390, 3307.0, 57.5065
32.213675987, 96.390, 2004.0, 44.7661
32.266197118, 96.390, 1620.0, 40.2492
32.318718249, 96.390, 1504.0, 38.7814
32.371239380, 96.390, 1435.0, 37.8814
32.423760510, 96.390, 1501.0, 38.7427
32.476281641, 96.390, 1645.0, 40.5586
32.528802772, 96.390, 2042.0, 45.1885
32.581323902, 96.390, 2232.0, 47.2440
32.633845033, 96.390, 2005.0, 44.7772
32.686366164, 96.390, 1641.0, 40.5093
32.738887295, 96.390, 1515.0, 38.9230
32.791408425, 96.390, 1339.0, 36.5923
32.843929556, 96.390, 1462.0, 38.2361
32.896450687, 96.390, 1448.0, 38.0526
32.948971817, 96.390, 1481.0, 38.4838
33.001492948, 96.390, 1449.0, 38.0657
33.054014079, 96.390, 1387.0, 37.2424
33.106535209, 96.390, 1394.0, 37.3363
33.159056340, 96.390, 1405.0, 37.4833
33.211577471, 96.390, 1234.0, 35.1283
33.264098602, 96.390, 1248.0, 35.3270
33.316619732, 96.390, 1322.0, 36.3593
33.369140863, 96.390, 1446.0, 38.0263
33.421661994, 96.390, 1443.0, 37.9868
33.474183124, 96.390, 1413.0, 37.5899
33.526704255, 96.390, 1295.0, 35.9861
33.579225386, 96.390, 1347.0, 36.7015
33.631746517, 96.390, 1336.0, 36.5513
33.684267647, 96.390, 1319.0, 36.3180
33.736788778, 96.390, 1508.0, 38.8330
33.789309909, 96.390, 1710.0, 41.3521
33.841831039, 96.390, 1903.0, 43.6234
33.894352170, 96.390, 2621.0, 51.1957
33.946873301, 96.390, 3468.0, 58.8897
33.999394432, 96.390, 3528.0, 59.3970
34.051915562, 96.390, 3392.0, 58.2409
34.104436693, 96.390, 3323.0, 57.6455
34.156957824, 96.390, 3823.0, 61.8304
34.209478954, 96.390, 4415.0, 66.4455
34.262000085, 96.390, 3841.0, 61.9758
34.314521216, 96.390, 3269.0, 57.1752
34.367042346, 96.390, 2811.0, 53.0189
34.419563477, 96.390, 2748.0, 52.4214
34.472084608, 96.390, 2966.0, 54.4610
34.524605739, 96.390, 2662.0, 51.5946
34.577126869, 96.390, 2684.0, 51.8073
34.629648000, 96.390, 2459.0, 49.5883
34.682169131, 96.390, 2420.0, 49.1935
34.734690261, 96.390, 2431.0, 49.3052
34.787211392, 96.390, 2773.0, 52.6593
34.839732523, 96.390, 3191.0, 56.4889
34.892253654, 96.390, 4317.0, 65.7039
34.944774784, 96.390, 4461.0, 66.7907
34.997295915, 96.390, 3480.0, 58.9915
35.049817046, 96.390, 2782.0, 52.7447
35.102338176, 96.390, 1860.0, 43.1277
35.154859307, 96.390, 1716.0, 41.4246
35.207380438, 96.390, 1563.0, 39.5348
35.259901569, 96.390, 1392.0, 37.3095
35.312422699, 96.390, 1496.0, 38.6782
35.364943830, 96.390, 1378.0, 37.1214
35.417464961, 96.390, 1344.0, 36.6606
35.469986091, 96.390, 1287.0, 35.8748
35.522507222, 96.390, 1235.0, 35.1426
35.575028353, 96.390, 1393.0, 37.3229
35.627549484, 96.390, 1498.0, 38.7040
35.680070614, 96.390, 1488.0, 38.5746
35.732591745, 96.390, 1399.0, 37.4032
35.785112876, 96.390, 1498.0, 38.7040
35.837634006, 96.390, 1452.0, 38.1051
35.890155137, 96.390, 1279.0, 35.7631
35.942676268, 96.390, 1254.0, 35.4119
35.995197398, 96.390, 1150.0, 33.9116
36.047718529, 96.390, 1176.0, 34.2929
36.100239660, 96.390, 1233.0, 35.1141
36.152760791, 96.390, 1273.0, 35.6791
36.205281921, 96.390, 1238.0, 35.1852
36.257803052, 96.390, 1273.0, 35.6791
36.310324183, 96.390, 1366.0, 36.9594
36.362845313, 96.390, 1442.0, 37.9737
36.415366444, 96.390, 1396.0, 37.3631
36.467887575, 96.390, 1448.0, 38.0526
36.520408706, 96.390, 1462.0, 38.2361
36.572929836, 96.390, 1605.0, 40.0625
36.625450967, 96.390, 1512.0, 38.8844
36.677972098, 96.390, 1432.0, 37.8418
36.730493228, 96.390, 1301.0, 36.0694
36.783014359, 96.390, 1237.0, 35.1710
36.835535490, 96.390, 1256.0, 35.4401
36.888056621, 96.390, 1328.0, 36.4417
36.940577751, 96.390, 1331.0, 36.4829
36.993098882, 96.390, 1498.0, 38.7040
37.045620013, 96.390, 1415.0, 37.6165
37.098141143, 96.390, 1354.0, 36.7967
37.150662274, 96.390, 1298.0, 36.0278
37.203183405, 96.390, 1277.0, 35.7351
37.255704535, 96.390, 1303.0, 36.0971
37.308225666, 96.390, 1323.0, 36.3731
37.360746797, 96.390, 1382.0, 37.1753
37.413267928, 96.390, 1446.0, 38.0263
37.465789058, 96.390, 1464.0, 38.2623
37.518310189, 96.390, 1590.0, 39.8748
37.570831320, 96.390, 1692.0, 41.1339
37.623352450, 96.390, 1873.0, 43.2782
37.675873581, 96.390, 2035.0, 45.1110
37.728394712, 96.390, 2270.0, 47.6445
37.780915843, 96.390, 2100.0, 45.8258
37.833436973, 96.390, 2076.0, 45.5631
37.885958104, 96.390, 1841.0, 42.9069
37.938479235, 96.390, 1695.0, 41.1704
37.991000365, 96.390, 1737.0, 41.6773
38.043521496, 96.390, 1549.0, 39.3573
38.096042627, 96.390, 1540.0, 39.2428
38.148563758, 96.390, 1566.0, 39.5727
38.201084888, 96.390, 1475.0, 38.4057
38.253606019, 96.390, 1360.0, 36.8782
38.306127150, 96.390, 1281.0, 35.7911
38.358648280, 96.390, 1198.0, 34.6121
38.411169411, 96.390, 1166.0, 34.1467
38.463690542, 96.390, 1219.0, 34.9142
38.516211673, 96.390, 1281.0, 35.7911
38.568732803, 96.390, 1243.0, 35.2562
38.621253934, 96.390, 1202.0, 34.6699
38.673775065, 96.390, 1215.0, 34.8569
38.726296195, 96.390, 1392.0, 37.3095
38.778817326, 96.390, 1553.0, 39.4081
38.831338457, 96.390, 1413.0, 37.5899
38.883859587, 96.390, 1384.0, 37.2022
38.936380718, 96.390, 1242.0, 35.2420
38.988901849, 96.390, 1121.0, 33.4813
39.041422980, 96.390, 1142.0, 33.7935
39.093944110, 96.390, 1170.0, 34.2053
39.146465241, 96.390, 1251.0, 35.3695
39.198986372, 96.390, 1302.0, 36.0832
39.251507502, 96.390, 1457.0, 38.1707
39.304028633, 96.390, 1711.0, 41.3642
39.356549764, 96.390, 2137.0, 46.2277
39.409070895, 96.390, 2687.0, 51.8363
39.461592025, 96.390, 2897.0, 53.8238
39.514113156, 96.390, 2723.0, 52.1824
39.566634287, 96.390, 2432.0, 49.3153
39.619155417, 96.390, 2085.0, 45.6618
39.671676548, 96.390, 1792.0, 42.3320
39.724197679, 96.390, 1647.0, 40.5832
39.776718810, 96.390, 1500.0, 38.7298
39.829239940, 96.390, 1403.0, 37.4566
39.881761071, 96.390, 1410.0, 37.5500
39.934282202, 96.390, 1423.0, 37.7227
39.986803332, 96.390, 1540.0, 39.2428
40.039324463, 96.390, 1649.0, 40.6079
40.091845594, 96.390, 1808.0, 42.5206
40.144366725, 96.390, 1844.0, 42.9418
40.196887855, 96.390, 1844.0, 42.9418
40.249408986, 96.390, 1877.0, 43.3244
40.301930117, 96.390, 1910.0, 43.7035
40.354451247, 96.390, 2099.0, 45.8148
40.406972378, 96.390, 2246.0, 47.3920
40.459493509, 96.390, 2530.0, 50.2991
40.512014639, 96.390, 2825.0, 53.1507
40.564535770, 96.390, 3060.0, 55.3173
40.617056901, 96.390, 2939.0, 54.2125
40.669578032, 96.390, 2560.0, 50.5964
40.722099162, 96.390, 2110.0, 45.9347
40.774620293, 96.390, 1674.0, 40.9145
40.827141424, 96.390, 1401.0, 37.4299
40.879662554, 96.390, 1277.0, 35.7351
40.932183685, 96.390, 1293.0, 35.9583
40.984704816, 96.390, 1209.0, 34.7707
41.037225947, 96.390, 1294.0, 35.9722
41.089747077, 96.390, 1279.0, 35.7631
41.142268208, 96.390, 1294.0, 35.9722
41.194789339, 96.390, 1252.0, 35.3836
41.247310469, 96.390, 1365.0, 36.9459
41.299831600, 96.390, 1562.0, 39.5221
41.352352731, 96.390, 1915.0, 43.7607
41.404873862, 96.390, 2284.0, 47.7912
41.457394992, 96.390, 1952.0, 44.1814
41.509916123, 96.390, 1953.0, 44.1928
41.562437254, 96.390, 1628.0, 40.3485
41.614958384, 96.390, 1528.0, 39.0896
41.667479515, 96.390, 1450.0, 38.0789
41.720000646, 96.390, 1256.0, 35.4401
41.772521776, 96.390, 1191.0, 34.5109
41.825042907, 96.390, 1129.0, 33.6006
41.877564038, 96.390, 1137.0, 33.7194
41.930085169, 96.390, 1087.0, 32.9697
41.982606299, 96.390, 1048.0, 32.3728
42.035127430, 96.390, 1133.0, 33.6601
42.087648561, 96.390, 1094.0, 33.0757
42.140169691, 96.390, 1317.0, 36.2905
42.192690822, 96.390, 1360.0, 36.8782
42.245211953, 96.390, 1305.0, 36.1248
42.297733084, 96.390, 1202.0, 34.6699
42.350254214, 96.390, 1142.0, 33.7935
42.402775345, 96.390, 1162.0, 34.0881
42.455296476, 96.390, 1213.0, 34.8281
42.507817606, 96.390, 1362.0, 36.9053
42.560338737, 96.390, 1664.0, 40.7922
42.612859868, 96.390, 1559.0, 39.4842
42.665380999, 96.390, 1759.0, 41.9404
42.717902129, 96.390, 1854.0, 43.0581
42.770423260, 96.390, 1828.0, 42.7551
42.822944391, 96.390, 1616.0, 40.1995
42.875465521, 96.390, 1610.0, 40.1248
42.927986652, 96.390, 1301.0, 36.0694
42.980507783, 96.390, 1236.0, 35.1568
43.033028914, 96.390, 1120.0, 33.4664
43.085550044, 96.390, 1059.0, 32.5423
43.138071175, 96.390, 977.0, 31.2570
43.190592306, 96.390, 936.0, 30.5941
43.243113436, 96.390, 922.0, 30.3645
43.295634567, 96.390, 884.0, 29.7321
43.348155698, 96.390, 930.0, 30.4959
43.400676828, 96.390, 934.0, 30.5614
43.453197959, 96.390, 1019.0, 31.9218
43.505719090, 96.390, 1017.0, 31.8904
43.558240221, 96.390, 1114.0, 33.3766
43.610761351, 96.390, 1124.0, 33.5261
43.663282482, 96.390, 1263.0, 35.5387
43.715803613, 96.390, 1519.0, 38.9744
43.768324743, 96.390, 1794.0, 42.3556
43.820845874, 96.390, 1429.0, 37.8021
43.873367005, 96.390, 1419.0, 37.6696
43.925888136, 96.390, 1268.0, 35.6090
43.978409266, 96.390, 1099.0, 33.1512
44.030930397, 96.390, 1094.0, 33.0757
44.083451528, 96.390, 1209.0, 34.7707
44.135972658, 96.390, 1353.0, 36.7831
44.188493789, 96.390, 1472.0, 38.3667
44.241014920, 96.390, 1384.0, 37.2022
44.293536051, 96.390, 1422.0, 37.7094
44.346057181, 96.390, 1538.0, 39.2173
44.398578312, 96.390, 1430.0, 37.8153
44.451099443, 96.390, 1250.0, 35.3553
44.503620573, 96.390, 1136.0, 33.7046
44.556141704, 96.390, 998.0, 31.5911
44.608662835, 96.390, 925.0, 30.4138
44.661183966, 96.390, 926.0, 30.4302
44.713705096, 96.390, 919.0, 30.3150
44.766226227, 96.390, 913.0, 30.2159
44.818747358, 96.390, 1082.0, 32.8938
44.871268488, 96.390, 1057.0, 32.5115
44.923789619, 96.390, 961.0, 31.0000
44.976310750, 96.390, 1059.0, 32.5423
45.028831880, 96.390, 1044.0, 32.3110
45.081353011, 96.390, 1235.0, 35.1426
45.133874142, 96.390, 1335.0, 36.5377
45.186395273, 96.390, 1195.0, 34.5688
45.238916403, 96.390, 1282.0, 35.8050
45.291437534, 96.390, 1332.0, 36.4966
45.343958665, 96.390, 1390.0, 37.2827
45.396479795, 96.390, 1397.0, 37.3765
45.449000926, 96.390, 1640.0, 40.4969
45.501522057, 96.390, 1644.0, 40.5463
45.554043188, 96.390, 1333.0, 36.5103
45.606564318, 96.390, 1248.0, 35.3270
45.659085449, 96.390, 1149.0, 33.8969
45.711606580, 96.390, 1101.0, 33.1813
45.764127710, 96.390, 1034.0, 32.1559
45.816648841, 96.390, 1041.0, 32.2645
45.869169972, 96.390, 1008.0, 31.7490
45.921691103, 96.390, 975.0, 31.2250
45.974212233, 96.390, 960.0, 30.9839
46.026733364, 96.390, 960.0, 30.9839
46.079254495, 96.390, 963.0, 31.0322
46.131775625, 96.390, 1005.0, 31.7017
46.184296756, 96.390, 986.0, 31.4006
46.236817887, 96.390, 1097.0, 33.1210
46.289339017, 96.390, 1207.0, 34.7419
46.341860148, 96.390, 1017.0, 31.8904
46.394381279, 96.390, 1121.0, 33.4813
46.446902410, 96.390, 1016.0, 31.8748
46.499423540, 96.390, 999.0, 31.6070
46.551944671, 96.390, 1037.0, 32.2025
46.604465802, 96.390, 927.0, 30.4467
46.656986932, 96.390, 1037.0, 32.2025
46.709508063, 96.390, 1064.0, 32.6190
46.762029194, 96.390, 1225.0, 35.0000
46.814550325, 96.390, 1273.0, 35.6791
46.867071455, 96.390, 1466.0, 38.2884
46.919592586, 96.390, 1716.0, 41.4246
46.972113717, 96.390, 2009.0, 44.8219
47.024634847, 96.390, 2030.0, 45.0555
47.077155978, 96.390, 1884.0, 43.4051
47.129677109, 96.390, 1859.0, 43.1161
47.182198240, 96.390, 1626.0, 40.3237
47.234719370, 96.390, 1620.0, 40.2492
47.287240501, 96.390, 1534.0, 39.1663
47.339761632, 96.390, 1600.0, 40.0000
47.392282762, 96.390, 1409.0, 37.5366
47.444803893, 96.390, 1338.0, 36.5787
47.497325024, 96.390, 1189.0, 34.4819
47.549846155, 96.390, 1142.0, 33.7935
47.602367285, 96.390, 947.0, 30.7734
47.654888416, 96.390, 892.0, 29.8664
47.707409547, 96.390, 857.0, 29.2746
47.759930677, 96.390, 776.0, 27.8568
47.812451808, 96.390, 889.0, 29.8161
47.864972939, 96.390, 917.0, 30.2820
47.917494069, 96.390, 981.0, 31.3209
47.970015200, 96.390, 1007.0, 31.7333
48.022536331, 96.390, 1014.0, 31.8434
48.075057462, 96.390, 1057.0, 32.5115
48.127578592, 96.390, 1137.0, 33.7194
48.180099723, 96.390, 1090.0, 33.0151
48.232620854, 96.390, 1063.0, 32.6037
48.285141984, 96.390, 1056.0, 32.4962
48.337663115, 96.390, 878.0, 29.6311
48.390184246, 96.390, 865.0, 29.4109
48.442705377, 96.390, 951.0, 30.8383
48.495226507, 96.390, 1049.0, 32.3883
48.547747638, 96.390, 1021.0, 31.9531
48.600268769, 96.390, 871.0, 29.5127
48.652789899, 96.390, 937.0, 30.6105
48.705311030, 96.390, 788.0, 28.0713
48.757832161, 96.390, 785.0, 28.0179
48.810353292, 96.390, 776.0, 27.8568
48.862874422, 96.390, 801.0, 28.3019
48.915395553, 96.390, 771.0, 27.7669
48.967916684, 96.390, 751.0, 27.4044
49.020437814, 96.390, 865.0, 29.4109
49.072958945, 96.390, 895.0, 29.9166
49.125480076, 96.390, 871.0, 29.5127
49.178001207, 96.390, 910.0, 30.1662
49.230522337, 96.390, 826.0, 28.7402
49.283043468, 96.390, 829.0, 28.7924
49.335564599, 96.390, 802.0, 28.3196
49.388085729, 96.390, 799.0, 28.2666
49.440606860, 96.390, 739.0, 27.1846
49.493127991, 96.390, 797.0, 28.2312
49.545649121, 96.390, 748.0, 27.3496
49.598170252, 96.390, 758.0, 27.5318
49.650691383, 96.390, 797.0, 28.2312
49.703212514, 96.390, 894.0, 29.8998
49.755733644, 96.390, 881.0, 29.6816
49.808254775, 96.390, 843.0, 29.0345
49.860775906, 96.390, 774.0, 27.8209
49.913297036, 96.390, 838.0, 28.9482
49.965818167, 96.390, 749.0, 27.3679
50.018339298, 96.390, 786.0, 28.0357
50.070860429, 96.390, 839.0, 28.9655
50.123381559, 96.390, 792.0, 28.1425
50.175902690, 96.390, 945.0, 30.7409
50.228423821, 96.390, 1157.0, 34.0147
50.280944951, 96.390, 1118.0, 33.4365
50.333466082, 96.390, 951.0, 30.8383
50.385987213, 96.390, 1033.0, 32.1403
50.438508344, 96.390, 936.0, 30.5941
50.491029474, 96.390, 944.0, 30.7246
50.543550605, 96.390, 889.0, 29.8161
50.596071736, 96.390, 926.0, 30.4302
50.648592866, 96.390, 831.0, 28.8271
50.701113997, 96.390, 795.0, 28.1957
50.753635128, 96.390, 742.0, 27.2397
50.806156258, 96.390, 726.0, 26.9444
50.858677389, 96.390, 732.0, 27.0555
50.911198520, 96.390, 782.0, 27.9643
50.963719651, 96.390, 763.0, 27.6225
51.016240781, 96.390, 772.0, 27.7849
51.068761912, 96.390, 735.0, 27.1109
51.121283043, 96.390, 791.0, 28.1247
51.173804173, 96.390, 834.0, 28.8791
51.226325304, 96.390, 936.0, 30.5941
51.278846435, 96.390, 829.0, 28.7924
51.331367566, 96.390, 799.0, 28.2666
51.383888696, 96.390, 775.0, 27.8388
51.436409827, 96.390, 773.0, 27.8029
51.488930958, 96.390, 752.0, 27.4226
51.541452088, 96.390, 741.0, 27.2213
51.593973219, 96.390, 779.0, 27.9106
51.646494350, 96.390, 779.0, 27.9106
51.699015481, 96.390, 748.0, 27.3496
51.751536611, 96.390, 928.0, 30.4631
51.804057742, 96.390, 980.0, 31.3050
51.856578873, 96.390, 1058.0, 32.5269
51.909100003, 96.390, 1158.0, 34.0294
51.961621134, 96.390, 1236.0, 35.1568
52.014142265, 96.390, 1221.0, 34.9428
52.066663396, 96.390, 1188.0, 34.4674
52.119184526, 96.390, 1304.0, 36.1109
52.171705657, 96.390, 1568.0, 39.5980
52.224226788, 96.390, 1552.0, 39.3954
52.276747918, 96.390, 1495.0, 38.6652
52.329269049, 96.390, 1406.0, 37.4967
52.381790180, 96.390, 1241.0, 35.2278
52.434311310, 96.390, 1311.0, 36.2077
52.486832441, 96.390, 1207.0, 34.7419
52.539353572, 96.390, 1225.0, 35.0000
52.591874703, 96.390, 1393.0, 37.3229
52.644395833, 96.390, 1545.0, 39.3065
52.696916964, 96.390, 1442.0, 37.9737
52.749438095, 96.390, 1381.0, 37.1618
52.801959225, 96.390, 1285.0, 35.8469
52.854480356, 96.390, 1352.0, 36.7696
52.907001487, 96.390, 1281.0, 35.7911
52.959522618, 96.390, 1278.0, 35.7491
53.012043748, 96.390, 1447.0, 38.0395
53.064564879, 96.390, 1572.0, 39.6485
53.117086010, 96.390, 1636.0, 40.4475
53.169607140, 96.390, 1703.0, 41.2674
53.222128271, 96.390, 1696.0, 41.1825
53.274649402, 96.390, 1511.0, 38.8716
53.327170533, 96.390, 1303.0, 36.0971
53.379691663, 96.390, 1254.0, 35.4119
53.432212794, 96.390, 1203.0, 34.6843
53.484733925, 96.390, 1133.0, 33.6601
53.537255055, 96.390, 998.0, 31.5911
53.589776186, 96.390, 1014.0, 31.8434
53.642297317, 96.390, 888.0, 29.7993
53.694818448, 96.390, 850.0, 29.1548
53.747339578, 96.390, 814.0, 28.5307
53.799860709, 96.390, 723.0, 26.8887
53.852381840, 96.390, 794.0, 28.1780
53.904902970, 96.390, 772.0, 27.7849
53.957424101, 96.390, 770.0, 27.7489
54.009945232, 96.390, 771.0, 27.7669
54.062466362, 96.390, 779.0, 27.9106
54.114987493, 96.390, 903.0, 30.0500
54.167508624, 96.390, 1054.0, 32.4654
54.220029755, 96.390, 974.0, 31.2090
54.272550885, 96.390, 1055.0, 32.4808
54.325072016, 96.390, 1212.0, 34.8138
54.377593147, 96.390, 1129.0, 33.6006
54.430114277, 96.390, 1032.0, 32.1248
54.482635408, 96.390, 943.0, 30.7083
54.535156539, 96.390, 903.0, 30.0500
54.587677670, 96.390, 805.0, 28.3725
54.640198800, 96.390, 704.0, 26.5330
54.692719931, 96.390, 708.0, 26.6083
54.745241062, 96.390, 690.0, 26.2679
54.797762192, 96.390, 616.0, 24.8193
54.850283323, 96.390, 683.0, 26.1343
54.902804454, 96.390, 639.0, 25.2784
54.955325585, 96.390, 669.0, 25.8650
55.007846715, 96.390, 659.0, 25.6710
55.060367846, 96.390, 685.0, 26.1725
55.112888977, 96.390, 689.0, 26.2488
55.165410107, 96.390, 621.0, 24.9199
55.217931238, 96.390, 641.0, 25.3180
55.270452369, 96.390, 678.0, 26.0384
55.322973499, 96.390, 687.0, 26.2107
55.375494630, 96.390, 720.0, 26.8328
55.428015761, 96.390, 670.0, 25.8844
55.480536892, 96.390, 686.0, 26.1916
55.533058022, 96.390, 678.0, 26.0384
55.585579153, 96.390, 818.0, 28.6007
55.638100284, 96.390, 757.0, 27.5136
55.690621414, 96.390, 745.0, 27.2947
55.743142545, 96.390, 792.0, 28.1425
55.795663676, 96.390, 777.0, 27.8747
55.848184807, 96.390, 712.0, 26.6833
55.900705937, 96.390, 731.0, 27.0370
55.953227068, 96.390, 733.0, 27.0740
56.005748199, 96.390, 740.0, 27.2029
56.058269329, 96.390, 728.0, 26.9815
56.110790460, 96.390, 728.0, 26.9815
56.163311591, 96.390, 762.0, 27.6043
56.215832722, 96.390, 719.0, 26.8142
56.268353852, 96.390, 759.0, 27.5500
56.320874983, 96.390, 738.0, 27.1662
56.373396114, 96.390, 765.0, 27.6586
56.425917244, 96.390, 773.0, 27.8029
56.478438375, 96.390, 844.0, 29.0517
56.530959506, 96.390, 869.0, 29.4788
56.583480637, 96.390, 871.0, 29.5127
56.636001767, 96.390, 858.0, 29.2916
56.688522898, 96.390, 786.0, 28.0357
56.741044029, 96.390, 750.0, 27.3861
56.793565159, 96.390, 719.0, 26.8142
56.846086290, 96.390, 727.0, 26.9629
56.898607421, 96.390, 702.0, 26.4953
56.951128551, 96.390, 704.0, 26.5330
57.003649682, 96.390, 702.0, 26.4953
57.056170813, 96.390, 720.0, 26.8328
57.108691944, 96.390, 725.0, 26.9258
57.161213074, 96.390, 718.0, 26.7955
57.213734205, 96.390, 749.0, 27.3679
57.266255336, 96.390, 743.0, 27.2580
57.318776466, 96.390, 708.0, 26.6083
57.371297597, 96.390, 773.0, 27.8029
57.423818728, 96.390, 788.0, 28.0713
57.476339859, 96.390, 874.0, 29.5635
57.528860989, 96.390, 955.0, 30.9031
57.581382120, 96.390, 946.0, 30.7571
57.633903251, 96.390, 899.0, 29.9833
57.686424381, 96.390, 883.0, 29.7153
57.738945512, 96.390, 903.0, 30.0500
57.791466643, 96.390, 835.0, 28.8964
57.843987774, 96.390, 816.0, 28.5657
57.896508904, 96.390, 841.0, 29.0000
57.949030035, 96.390, 809.0, 28.4429
58.001551166, 96.390, 962.0, 31.0161
58.054072296, 96.390, 1141.0, 33.7787
58.106593427, 96.390, 1142.0, 33.7935
58.159114558, 96.390, 1013.0, 31.8277
58.211635689, 96.390, 1035.0, 32.1714
58.264156819, 96.390, 865.0, 29.4109
58.316677950, 96.390, 804.0, 28.3549
58.369199081, 96.390, 803.0, 28.3373
58.421720211, 96.390, 764.0, 27.6405
58.474241342, 96.390, 714.0, 26.7208
58.526762473, 96.390, 796.0, 28.2135
58.579283603, 96.390, 961.0, 31.0000
58.631804734, 96.390, 986.0, 31.4006
58.684325865, 96.390, 866.0, 29.4279
58.736846996, 96.390, 867.0, 29.4449
58.789368126, 96.390, 823.0, 28.6880
58.841889257, 96.390, 763.0, 27.6225
58.894410388, 96.390, 730.0, 27.0185
58.946931518, 96.390, 706.0, 26.5707
58.999452649, 96.390, 726.0, 26.9444
59.051973780, 96.390, 701.0, 26.4764
59.104494911, 96.390, 635.0, 25.1992
59.157016041, 96.390, 720.0, 26.8328
59.209537172, 96.390, 760.0, 27.5681
59.262058303, 96.390, 743.0, 27.2580
59.314579433, 96.390, 751.0, 27.4044
59.367100564, 96.390, 687.0, 26.2107
59.419621695, 96.390, 643.0, 25.3574
59.472142826, 96.390, 699.0, 26.4386
59.524663956, 96.390, 609.0, 24.6779
59.577185087, 96.390, 682.0, 26.1151
59.629706218, 96.390, 687.0, 26.2107
59.682227348, 96.390, 700.0, 26.4575
59.734748479, 96.390, 711.0, 26.6646
59.787269610, 96.390, 703.0, 26.5141
59.839790740, 96.390, 690.0, 26.2679
59.892311871, 96.390, 669.0, 25.8650
59.944833002, 96.390, 739.0, 27.1846
59.997354133, 96.390, 758.0, 27.5318
60.049875263, 96.390, 738.0, 27.1662
60.102396394, 96.390, 797.0, 28.2312
60.154917525, 96.390, 856.0, 29.2575
60.207438655, 96.390, 835.0, 28.8964
60.259959786, 96.390, 888.0, 29.7993
60.312480917, 96.390, 790.0, 28.1069
60.365002048, 96.390, 740.0, 27.2029
60.417523178, 96.390, 775.0, 27.8388
60.470044309, 96.390, 810.0, 28.4605
60.522565440, 96.390, 732.0, 27.0555
60.575086570, 96.390, 854.0, 29.2233
60.627607701, 96.390, 913.0, 30.2159
60.680128832, 96.390, 969.0, 31.1288
60.732649963, 96.390, 1157.0, 34.0147
60.785171093, 96.390, 1458.0, 38.1838
60.837692224, 96.390, 1554.0, 39.4208
60.890213355, 96.390, 1371.0, 37.0270
60.942734485, 96.390, 1214.0, 34.8425
60.995255616, 96.390, 1196.0, 34.5832
61.047776747, 96.390, 1019.0, 31.9218
61.100297878, 96.390, 810.0, 28.4605
61.152819008, 96.390, 757.0, 27.5136
61.205340139, 96.390, 800.0, 28.2843
61.257861270, 96.390, 777.0, 27.8747
61.310382400, 96.390, 742.0, 27.2397
61.362903531, 96.390, 724.0, 26.9072
61.415424662, 96.390, 765.0, 27.6586
61.467945792, 96.390, 791.0, 28.1247
61.520466923, 96.390, 856.0, 29.2575
61.572988054, 96.390, 669.0, 25.8650
61.625509185, 96.390, 694.0, 26.3439
61.678030315, 96.390, 778.0, 27.8927
61.730551446, 96.390, 742.0, 27.2397
61.783072577, 96.390, 740.0, 27.2029
61.835593707, 96.390, 827.0, 28.7576
61.888114838, 96.390, 849.0, 29.1376
61.940635969, 96.390, 936.0, 30.5941
61.993157100, 96.390, 972.0, 31.1769
62.045678230, 96.390, 1091.0, 33.0303
62.098199361, 96.390, 1181.0, 34.3657
62.150720492, 96.390, 1353.0, 36.7831
62.203241622, 96.390, 1369.0, 37.0000
62.255762753, 96.390, 1212.0, 34.8138
62.308283884, 96.390, 1218.0, 34.8999
62.360805015, 96.390, 1107.0, 33.2716
62.413326145, 96.390, 947.0, 30.7734
62.465847276, 96.390, 794.0, 28.1780
62.518368407, 96.390, 794.0, 28.1780
62.570889537, 96.390, 695.0, 26.3629
62.623410668, 96.390, 741.0, 27.2213
62.675931799, 96.390, 797.0, 28.2312
62.728452930, 96.390, 828.0, 28.7750
62.780974060, 96.390, 801.0, 28.3019
62.833495191, 96.390, 759.0, 27.5500
62.886016322, 96.390, 726.0, 26.9444
62.938537452, 96.390, 628.0, 25.0599
62.991058583, 96.390, 599.0, 24.4745
63.043579714, 96.390, 532.0, 23.0651
63.096100844, 96.390, 555.0, 23.5584
63.148621975, 96.390, 545.0, 23.3452
63.201143106, 96.390, 564.0, 23.7487
63.253664237, 96.390, 622.0, 24.9399
63.306185367, 96.390, 602.0, 24.5357
63.358706498, 96.390, 660.0, 25.6905
63.411227629, 96.390, 627.0, 25.0400
63.463748759, 96.390, 683.0, 26.1343
63.516269890, 96.390, 733.0, 27.0740
63.568791021, 96.390, 741.0, 27.2213
63.621312152, 96.390, 922.0, 30.3645
63.673833282, 96.390, 1022.0, 31.9687
63.726354413, 96.390, 1254.0, 35.4119
63.778875544, 96.390, 1403.0, 37.4566
63.831396674, 96.390, 1346.0, 36.6879
63.883917805, 96.390, 1290.0, 35.9166
63.936438936, 96.390, 1244.0, 35.2704
63.988960067, 96.390, 1205.0, 34.7131
64.041481197, 96.390, 1052.0, 32.4345
64.094002328, 96.390, 925.0, 30.4138
64.146523459, 96.390, 867.0, 29.4449
64.199044589, 96.390, 976.0, 31.2410
64.251565720, 96.390, 1001.0, 31.6386
64.304086851, 96.390, 972.0, 31.1769
64.356607981, 96.390, 900.0, 30.0000
64.409129112, 96.390, 844.0, 29.0517
64.461650243, 96.390, 848.0, 29.1204
64.514171374, 96.390, 778.0, 27.8927
64.566692504, 96.390, 748.0, 27.3496
64.619213635, 96.390, 758.0, 27.5318
64.671734766, 96.390, 695.0, 26.3629
64.724255896, 96.390, 645.0, 25.3969
64.776777027, 96.390, 604.0, 24.5764
64.829298158, 96.390, 589.0, 24.2693
64.881819289, 96.390, 561.0, 23.6854
64.934340419, 96.390, 558.0, 23.6220
64.986861550, 96.390, 575.0, 23.9792