File: Files_organized_for_plots/470_day/eXRD_005Centroid20Oct21_Act27Oct21_B2_0714M_NaOH_LS0173_num5_515day.csv
[Measurement conditions]
Sample identification,Centroid20Oct21_Act27Oct21_B2_0714M_NaOH_LS0173_5
Comment - 1,"Configuration=Stage for Flat Samples/Holders, Owner=User-1, Creation date=7/1/2020 9:53:24 AM"
Comment - 2,"Goniometer=Theta/Theta; Minimum step size 2Theta:0.0001; Minimum step size Omega:0.0001"
Comment - 3,"Sample stage=Stage for flat samples/holders"
Comment - 4,"Diffractometer system=EMPYREAN"
Comment - 5,"Measurement program=X:\XRD\Cement\Zerobackground scan.xrdmp, Identifier={98A3B11C-88F9-4AA6-982C-73314A311EF5}"
Anode material,Cu
K-Alpha1 wavelength,1.5405980
K-Alpha2 wavelength,1.5444260
Ratio K-Alpha2/K-Alpha1,0.500
Divergence slit,Fixed,0.25
Monochromator used,NO
Generator voltage, 45
Tube current, 40
File date and time,29/Mar/2023 19:08
Unit cell,
h k l, 0 0 0
Scan axis,Gonio
Scan range,4.994599997,64.999991833
Scan step size,0.0262606
No. of points, 2285
Scan type,CONTINUOUS
Time per step,96.390
[Scan points]
Angle, TimePerStep, Intensity, ESD
5.007730280, 96.390, 3865.0, 62.1691
5.060251411, 96.390, 3796.0, 61.6117
5.112772541, 96.390, 3714.0, 60.9426
5.165293672, 96.390, 3775.0, 61.4410
5.217814803, 96.390, 3707.0, 60.8851
5.270335934, 96.390, 3676.0, 60.6300
5.322857064, 96.390, 3400.0, 58.3095
5.375378195, 96.390, 3531.0, 59.4222
5.427899326, 96.390, 3619.0, 60.1581
5.480420456, 96.390, 3489.0, 59.0678
5.532941587, 96.390, 3534.0, 59.4475
5.585462718, 96.390, 3552.0, 59.5987
5.637983849, 96.390, 3382.0, 58.1550
5.690504979, 96.390, 3465.0, 58.8643
5.743026110, 96.390, 3455.0, 58.7792
5.795547241, 96.390, 3268.0, 57.1664
5.848068371, 96.390, 3385.0, 58.1808
5.900589502, 96.390, 3485.0, 59.0339
5.953110633, 96.390, 3388.0, 58.2065
6.005631763, 96.390, 3400.0, 58.3095
6.058152894, 96.390, 3337.0, 57.7668
6.110674025, 96.390, 3383.0, 58.1636
6.163195156, 96.390, 3395.0, 58.2666
6.215716286, 96.390, 3348.0, 57.8619
6.268237417, 96.390, 3251.0, 57.0175
6.320758548, 96.390, 3176.0, 56.3560
6.373279678, 96.390, 3328.0, 57.6888
6.425800809, 96.390, 3404.0, 58.3438
6.478321940, 96.390, 3307.0, 57.5065
6.530843071, 96.390, 3225.0, 56.7891
6.583364201, 96.390, 3234.0, 56.8683
6.635885332, 96.390, 3228.0, 56.8155
6.688406463, 96.390, 3237.0, 56.8946
6.740927593, 96.390, 3237.0, 56.8946
6.793448724, 96.390, 3194.0, 56.5155
6.845969855, 96.390, 3151.0, 56.1338
6.898490986, 96.390, 3167.0, 56.2761
6.951012116, 96.390, 3191.0, 56.4889
7.003533247, 96.390, 3221.0, 56.7539
7.056054378, 96.390, 3152.0, 56.1427
7.108575508, 96.390, 3177.0, 56.3649
7.161096639, 96.390, 3177.0, 56.3649
7.213617770, 96.390, 3044.0, 55.1725
7.266138900, 96.390, 3116.0, 55.8211
7.318660031, 96.390, 3164.0, 56.2494
7.371181162, 96.390, 3179.0, 56.3826
7.423702293, 96.390, 3182.0, 56.4092
7.476223423, 96.390, 3150.0, 56.1249
7.528744554, 96.390, 3153.0, 56.1516
7.581265685, 96.390, 3024.0, 54.9909
7.633786815, 96.390, 3153.0, 56.1516
7.686307946, 96.390, 3203.0, 56.5951
7.738829077, 96.390, 3130.0, 55.9464
7.791350208, 96.390, 3083.0, 55.5248
7.843871338, 96.390, 3137.0, 56.0089
7.896392469, 96.390, 3044.0, 55.1725
7.948913600, 96.390, 3191.0, 56.4889
8.001434730, 96.390, 3213.0, 56.6833
8.053955861, 96.390, 3191.0, 56.4889
8.106476992, 96.390, 3119.0, 55.8480
8.158998123, 96.390, 3167.0, 56.2761
8.211519253, 96.390, 3189.0, 56.4712
8.264040384, 96.390, 3135.0, 55.9911
8.316561515, 96.390, 3166.0, 56.2672
8.369082645, 96.390, 3079.0, 55.4887
8.421603776, 96.390, 3042.0, 55.1543
8.474124907, 96.390, 3127.0, 55.9196
8.526646038, 96.390, 3219.0, 56.7362
8.579167168, 96.390, 3173.0, 56.3294
8.631688299, 96.390, 3132.0, 55.9643
8.684209430, 96.390, 3057.0, 55.2901
8.736730560, 96.390, 3235.0, 56.8771
8.789251691, 96.390, 3142.0, 56.0535
8.841772822, 96.390, 3107.0, 55.7405
8.894293952, 96.390, 3228.0, 56.8155
8.946815083, 96.390, 3165.0, 56.2583
8.999336214, 96.390, 3138.0, 56.0179
9.051857345, 96.390, 3189.0, 56.4712
9.104378475, 96.390, 3136.0, 56.0000
9.156899606, 96.390, 3134.0, 55.9821
9.209420737, 96.390, 3027.0, 55.0182
9.261941867, 96.390, 3083.0, 55.5248
9.314462998, 96.390, 3191.0, 56.4889
9.366984129, 96.390, 3058.0, 55.2992
9.419505260, 96.390, 3194.0, 56.5155
9.472026390, 96.390, 2974.0, 54.5344
9.524547521, 96.390, 3076.0, 55.4617
9.577068652, 96.390, 3050.0, 55.2268
9.629589782, 96.390, 3126.0, 55.9106
9.682110913, 96.390, 3098.0, 55.6597
9.734632044, 96.390, 3212.0, 56.6745
9.787153175, 96.390, 3199.0, 56.5597
9.839674305, 96.390, 2998.0, 54.7540
9.892195436, 96.390, 2957.0, 54.3783
9.944716567, 96.390, 2973.0, 54.5252
9.997237697, 96.390, 3024.0, 54.9909
10.049758828, 96.390, 3089.0, 55.5788
10.102279959, 96.390, 3188.0, 56.4624
10.154801090, 96.390, 3017.0, 54.9272
10.207322220, 96.390, 3078.0, 55.4797
10.259843351, 96.390, 3147.0, 56.0981
10.312364482, 96.390, 3138.0, 56.0179
10.364885612, 96.390, 3232.0, 56.8507
10.417406743, 96.390, 3428.0, 58.5491
10.469927874, 96.390, 3978.0, 63.0714
10.522449004, 96.390, 2956.0, 54.3691
10.574970135, 96.390, 2877.0, 53.6377
10.627491266, 96.390, 2991.0, 54.6900
10.680012397, 96.390, 2986.0, 54.6443
10.732533527, 96.390, 2960.0, 54.4059
10.785054658, 96.390, 2971.0, 54.5069
10.837575789, 96.390, 2955.0, 54.3599
10.890096919, 96.390, 3052.0, 55.2449
10.942618050, 96.390, 3196.0, 56.5332
10.995139181, 96.390, 3268.0, 57.1664
11.047660312, 96.390, 3163.0, 56.2406
11.100181442, 96.390, 2927.0, 54.1018
11.152702573, 96.390, 2832.0, 53.2165
11.205223704, 96.390, 2801.0, 52.9245
11.257744834, 96.390, 2897.0, 53.8238
11.310265965, 96.390, 2877.0, 53.6377
11.362787096, 96.390, 2809.0, 53.0000
11.415308227, 96.390, 2789.0, 52.8110
11.467829357, 96.390, 2913.0, 53.9722
11.520350488, 96.390, 2792.0, 52.8394
11.572871619, 96.390, 2825.0, 53.1507
11.625392749, 96.390, 2875.0, 53.6190
11.677913880, 96.390, 2745.0, 52.3927
11.730435011, 96.390, 2735.0, 52.2972
11.782956141, 96.390, 2790.0, 52.8205
11.835477272, 96.390, 2746.0, 52.4023
11.887998403, 96.390, 2734.0, 52.2877
11.940519534, 96.390, 2648.0, 51.4587
11.993040664, 96.390, 2748.0, 52.4214
12.045561795, 96.390, 2577.0, 50.7642
12.098082926, 96.390, 2661.0, 51.5849
12.150604056, 96.390, 2707.0, 52.0288
12.203125187, 96.390, 2640.0, 51.3809
12.255646318, 96.390, 2650.0, 51.4782
12.308167449, 96.390, 2478.0, 49.7795
12.360688579, 96.390, 2537.0, 50.3686
12.413209710, 96.390, 2487.0, 49.8698
12.465730841, 96.390, 2499.0, 49.9900
12.518251971, 96.390, 2529.0, 50.2892
12.570773102, 96.390, 2347.0, 48.4458
12.623294233, 96.390, 2351.0, 48.4871
12.675815364, 96.390, 2438.0, 49.3761
12.728336494, 96.390, 2414.0, 49.1325
12.780857625, 96.390, 2424.0, 49.2341
12.833378756, 96.390, 2452.0, 49.5177
12.885899886, 96.390, 2454.0, 49.5379
12.938421017, 96.390, 2394.0, 48.9285
12.990942148, 96.390, 2369.0, 48.6724
13.043463279, 96.390, 2276.0, 47.7074
13.095984409, 96.390, 2381.0, 48.7955
13.148505540, 96.390, 2396.0, 48.9490
13.201026671, 96.390, 2417.0, 49.1630
13.253547801, 96.390, 2293.0, 47.8853
13.306068932, 96.390, 2233.0, 47.2546
13.358590063, 96.390, 2355.0, 48.5283
13.411111193, 96.390, 2237.0, 47.2969
13.463632324, 96.390, 2296.0, 47.9166
13.516153455, 96.390, 2356.0, 48.5386
13.568674586, 96.390, 2514.0, 50.1398
13.621195716, 96.390, 2481.0, 49.8096
13.673716847, 96.390, 2505.0, 50.0500
13.726237978, 96.390, 2514.0, 50.1398
13.778759108, 96.390, 3838.0, 61.9516
13.831280239, 96.390, 4004.0, 63.2772
13.883801370, 96.390, 2346.0, 48.4355
13.936322501, 96.390, 2271.0, 47.6550
13.988843631, 96.390, 2236.0, 47.2864
14.041364762, 96.390, 2244.0, 47.3709
14.093885893, 96.390, 2204.0, 46.9468
14.146407023, 96.390, 2311.0, 48.0729
14.198928154, 96.390, 2667.0, 51.6430
14.251449285, 96.390, 3901.0, 62.4580
14.303970416, 96.390, 5514.0, 74.2563
14.356491546, 96.390, 2564.0, 50.6360
14.409012677, 96.390, 2054.0, 45.3211
14.461533808, 96.390, 2120.0, 46.0435
14.514054938, 96.390, 2183.0, 46.7226
14.566576069, 96.390, 2062.0, 45.4093
14.619097200, 96.390, 2009.0, 44.8219
14.671618331, 96.390, 1953.0, 44.1928
14.724139461, 96.390, 2090.0, 45.7165
14.776660592, 96.390, 1968.0, 44.3621
14.829181723, 96.390, 1932.0, 43.9545
14.881702853, 96.390, 2028.0, 45.0333
14.934223984, 96.390, 1998.0, 44.6990
14.986745115, 96.390, 2093.0, 45.7493
15.039266245, 96.390, 1972.0, 44.4072
15.091787376, 96.390, 1877.0, 43.3244
15.144308507, 96.390, 1983.0, 44.5309
15.196829638, 96.390, 1910.0, 43.7035
15.249350768, 96.390, 1997.0, 44.6878
15.301871899, 96.390, 1952.0, 44.1814
15.354393030, 96.390, 1929.0, 43.9204
15.406914160, 96.390, 1895.0, 43.5316
15.459435291, 96.390, 1955.0, 44.2154
15.511956422, 96.390, 1947.0, 44.1248
15.564477553, 96.390, 1906.0, 43.6578
15.616998683, 96.390, 1875.0, 43.3013
15.669519814, 96.390, 1988.0, 44.5870
15.722040945, 96.390, 1934.0, 43.9773
15.774562075, 96.390, 1894.0, 43.5201
15.827083206, 96.390, 1916.0, 43.7721
15.879604337, 96.390, 1927.0, 43.8976
15.932125468, 96.390, 1899.0, 43.5775
15.984646598, 96.390, 1910.0, 43.7035
16.037167729, 96.390, 2012.0, 44.8553
16.089688860, 96.390, 1867.0, 43.2088
16.142209990, 96.390, 1840.0, 42.8952
16.194731121, 96.390, 1991.0, 44.6206
16.247252252, 96.390, 1909.0, 43.6921
16.299773382, 96.390, 1856.0, 43.0813
16.352294513, 96.390, 1914.0, 43.7493
16.404815644, 96.390, 1890.0, 43.4741
16.457336775, 96.390, 1892.0, 43.4971
16.509857905, 96.390, 1877.0, 43.3244
16.562379036, 96.390, 1868.0, 43.2204
16.614900167, 96.390, 1818.0, 42.6380
16.667421297, 96.390, 1887.0, 43.4396
16.719942428, 96.390, 1917.0, 43.7836
16.772463559, 96.390, 1926.0, 43.8862
16.824984690, 96.390, 1960.0, 44.2719
16.877505820, 96.390, 1955.0, 44.2154
16.930026951, 96.390, 2225.0, 47.1699
16.982548082, 96.390, 2023.0, 44.9778
17.035069212, 96.390, 1822.0, 42.6849
17.087590343, 96.390, 1836.0, 42.8486
17.140111474, 96.390, 1928.0, 43.9090
17.192632605, 96.390, 1937.0, 44.0114
17.245153735, 96.390, 1933.0, 43.9659
17.297674866, 96.390, 2039.0, 45.1553
17.350195997, 96.390, 2091.0, 45.7275
17.402717127, 96.390, 2316.0, 48.1248
17.455238258, 96.390, 2073.0, 45.5302
17.507759389, 96.390, 1942.0, 44.0681
17.560280520, 96.390, 1915.0, 43.7607
17.612801650, 96.390, 1955.0, 44.2154
17.665322781, 96.390, 1921.0, 43.8292
17.717843912, 96.390, 1836.0, 42.8486
17.770365042, 96.390, 1948.0, 44.1362
17.822886173, 96.390, 1891.0, 43.4856
17.875407304, 96.390, 1954.0, 44.2041
17.927928434, 96.390, 1949.0, 44.1475
17.980449565, 96.390, 1888.0, 43.4511
18.032970696, 96.390, 1994.0, 44.6542
18.085491827, 96.390, 2126.0, 46.1086
18.138012957, 96.390, 2212.0, 47.0319
18.190534088, 96.390, 2179.0, 46.6798
18.243055219, 96.390, 2455.0, 49.5480
18.295576349, 96.390, 2865.0, 53.5257
18.348097480, 96.390, 2481.0, 49.8096
18.400618611, 96.390, 2492.0, 49.9199
18.453139742, 96.390, 2767.0, 52.6023
18.505660872, 96.390, 2327.0, 48.2390
18.558182003, 96.390, 2000.0, 44.7214
18.610703134, 96.390, 1960.0, 44.2719
18.663224264, 96.390, 2002.0, 44.7437
18.715745395, 96.390, 2016.0, 44.8999
18.768266526, 96.390, 2084.0, 45.6508
18.820787657, 96.390, 2080.0, 45.6070
18.873308787, 96.390, 2140.0, 46.2601
18.925829918, 96.390, 2195.0, 46.8508
18.978351049, 96.390, 2502.0, 50.0200
19.030872179, 96.390, 2332.0, 48.2908
19.083393310, 96.390, 2062.0, 45.4093
19.135914441, 96.390, 2089.0, 45.7056
19.188435572, 96.390, 2071.0, 45.5082
19.240956702, 96.390, 2046.0, 45.2327
19.293477833, 96.390, 2162.0, 46.4973
19.345998964, 96.390, 2171.0, 46.5940
19.398520094, 96.390, 2584.0, 50.8331
19.451041225, 96.390, 2679.0, 51.7591
19.503562356, 96.390, 2866.0, 53.5350
19.556083486, 96.390, 2521.0, 50.2096
19.608604617, 96.390, 2245.0, 47.3814
19.661125748, 96.390, 2320.0, 48.1664
19.713646879, 96.390, 2859.0, 53.4696
19.766168009, 96.390, 3565.0, 59.7076
19.818689140, 96.390, 2919.0, 54.0278
19.871210271, 96.390, 2345.0, 48.4252
19.923731401, 96.390, 2120.0, 46.0435
19.976252532, 96.390, 2250.0, 47.4342
20.028773663, 96.390, 2214.0, 47.0532
20.081294794, 96.390, 2237.0, 47.2969
20.133815924, 96.390, 2186.0, 46.7547
20.186337055, 96.390, 2288.0, 47.8330
20.238858186, 96.390, 2311.0, 48.0729
20.291379316, 96.390, 2375.0, 48.7340
20.343900447, 96.390, 2932.0, 54.1479
20.396421578, 96.390, 3754.0, 61.2699
20.448942709, 96.390, 6075.0, 77.9423
20.501463839, 96.390, 4065.0, 63.7574
20.553984970, 96.390, 2895.0, 53.8052
20.606506101, 96.390, 3119.0, 55.8480
20.659027231, 96.390, 2762.0, 52.5547
20.711548362, 96.390, 2422.0, 49.2138
20.764069493, 96.390, 2331.0, 48.2804
20.816590623, 96.390, 2326.0, 48.2286
20.869111754, 96.390, 2330.0, 48.2701
20.921632885, 96.390, 2428.0, 49.2747
20.974154016, 96.390, 2536.0, 50.3587
21.026675146, 96.390, 2497.0, 49.9700
21.079196277, 96.390, 2302.0, 47.9792
21.131717408, 96.390, 2302.0, 47.9792
21.184238538, 96.390, 2225.0, 47.1699
21.236759669, 96.390, 2272.0, 47.6655
21.289280800, 96.390, 2286.0, 47.8121
21.341801931, 96.390, 2319.0, 48.1560
21.394323061, 96.390, 2292.0, 47.8748
21.446844192, 96.390, 2340.0, 48.3735
21.499365323, 96.390, 2353.0, 48.5077
21.551886453, 96.390, 2251.0, 47.4447
21.604407584, 96.390, 2391.0, 48.8979
21.656928715, 96.390, 2516.0, 50.1597
21.709449846, 96.390, 2877.0, 53.6377
21.761970976, 96.390, 2507.0, 50.0700
21.814492107, 96.390, 2427.0, 49.2646
21.867013238, 96.390, 2355.0, 48.5283
21.919534368, 96.390, 2333.0, 48.3011
21.972055499, 96.390, 2333.0, 48.3011
22.024576630, 96.390, 2415.0, 49.1426
22.077097761, 96.390, 2373.0, 48.7134
22.129618891, 96.390, 2447.0, 49.4672
22.182140022, 96.390, 2460.0, 49.5984
22.234661153, 96.390, 2396.0, 48.9490
22.287182283, 96.390, 2413.0, 49.1223
22.339703414, 96.390, 2397.0, 48.9592
22.392224545, 96.390, 2384.0, 48.8262
22.444745675, 96.390, 2379.0, 48.7750
22.497266806, 96.390, 2561.0, 50.6063
22.549787937, 96.390, 2548.0, 50.4777
22.602309068, 96.390, 2642.0, 51.4004
22.654830198, 96.390, 2466.0, 49.6588
22.707351329, 96.390, 2380.0, 48.7852
22.759872460, 96.390, 2394.0, 48.9285
22.812393590, 96.390, 2586.0, 50.8527
22.864914721, 96.390, 2704.0, 52.0000
22.917435852, 96.390, 2546.0, 50.4579
22.969956983, 96.390, 2459.0, 49.5883
23.022478113, 96.390, 2385.0, 48.8365
23.074999244, 96.390, 2339.0, 48.3632
23.127520375, 96.390, 2459.0, 49.5883
23.180041505, 96.390, 2490.0, 49.8999
23.232562636, 96.390, 2417.0, 49.1630
23.285083767, 96.390, 2482.0, 49.8197
23.337604898, 96.390, 2850.0, 53.3854
23.390126028, 96.390, 2852.0, 53.4041
23.442647159, 96.390, 2971.0, 54.5069
23.495168290, 96.390, 3729.0, 61.0655
23.547689420, 96.390, 3803.0, 61.6685
23.600210551, 96.390, 2912.0, 53.9630
23.652731682, 96.390, 2362.0, 48.6004
23.705252813, 96.390, 2357.0, 48.5489
23.757773943, 96.390, 2356.0, 48.5386
23.810295074, 96.390, 2267.0, 47.6130
23.862816205, 96.390, 2306.0, 48.0208
23.915337335, 96.390, 2273.0, 47.6760
23.967858466, 96.390, 2278.0, 47.7284
24.020379597, 96.390, 2259.0, 47.5289
24.072900727, 96.390, 2418.0, 49.1732
24.125421858, 96.390, 2490.0, 49.8999
24.177942989, 96.390, 2781.0, 52.7352
24.230464120, 96.390, 3363.0, 57.9914
24.282985250, 96.390, 3149.0, 56.1160
24.335506381, 96.390, 2972.0, 54.5161
24.388027512, 96.390, 2512.0, 50.1199
24.440548642, 96.390, 2394.0, 48.9285
24.493069773, 96.390, 2374.0, 48.7237
24.545590904, 96.390, 2702.0, 51.9808
24.598112035, 96.390, 2466.0, 49.6588
24.650633165, 96.390, 2301.0, 47.9687
24.703154296, 96.390, 2132.0, 46.1736
24.755675427, 96.390, 2056.0, 45.3431
24.808196557, 96.390, 2086.0, 45.6727
24.860717688, 96.390, 1960.0, 44.2719
24.913238819, 96.390, 2104.0, 45.8694
24.965759950, 96.390, 2085.0, 45.6618
25.018281080, 96.390, 2178.0, 46.6690
25.070802211, 96.390, 2043.0, 45.1996
25.123323342, 96.390, 1988.0, 44.5870
25.175844472, 96.390, 1873.0, 43.2782
25.228365603, 96.390, 1956.0, 44.2267
25.280886734, 96.390, 2001.0, 44.7325
25.333407864, 96.390, 2095.0, 45.7712
25.385928995, 96.390, 2434.0, 49.3356
25.438450126, 96.390, 2700.0, 51.9615
25.490971257, 96.390, 2253.0, 47.4658
25.543492387, 96.390, 1922.0, 43.8406
25.596013518, 96.390, 1943.0, 44.0795
25.648534649, 96.390, 2005.0, 44.7772
25.701055779, 96.390, 1981.0, 44.5084
25.753576910, 96.390, 1945.0, 44.1022
25.806098041, 96.390, 2039.0, 45.1553
25.858619172, 96.390, 2211.0, 47.0213
25.911140302, 96.390, 2000.0, 44.7214
25.963661433, 96.390, 1890.0, 43.4741
26.016182564, 96.390, 1779.0, 42.1782
26.068703694, 96.390, 1805.0, 42.4853
26.121224825, 96.390, 1773.0, 42.1070
26.173745956, 96.390, 1767.0, 42.0357
26.226267087, 96.390, 1881.0, 43.3705
26.278788217, 96.390, 1884.0, 43.4051
26.331309348, 96.390, 1807.0, 42.5088
26.383830479, 96.390, 1836.0, 42.8486
26.436351609, 96.390, 1784.0, 42.2374
26.488872740, 96.390, 1729.0, 41.5812
26.541393871, 96.390, 1837.0, 42.8602
26.593915002, 96.390, 1813.0, 42.5793
26.646436132, 96.390, 1902.0, 43.6119
26.698957263, 96.390, 1926.0, 43.8862
26.751478394, 96.390, 1850.0, 43.0116
26.803999524, 96.390, 1764.0, 42.0000
26.856520655, 96.390, 1885.0, 43.4166
26.909041786, 96.390, 1879.0, 43.3474
26.961562916, 96.390, 2023.0, 44.9778
27.014084047, 96.390, 1979.0, 44.4860
27.066605178, 96.390, 1851.0, 43.0232
27.119126309, 96.390, 1856.0, 43.0813
27.171647439, 96.390, 1855.0, 43.0697
27.224168570, 96.390, 1916.0, 43.7721
27.276689701, 96.390, 2081.0, 45.6180
27.329210831, 96.390, 2292.0, 47.8748
27.381731962, 96.390, 2060.0, 45.3872
27.434253093, 96.390, 1834.0, 42.8252
27.486774224, 96.390, 1729.0, 41.5812
27.539295354, 96.390, 1734.0, 41.6413
27.591816485, 96.390, 1842.0, 42.9185
27.644337616, 96.390, 1924.0, 43.8634
27.696858746, 96.390, 2154.0, 46.4112
27.749379877, 96.390, 2035.0, 45.1110
27.801901008, 96.390, 1940.0, 44.0454
27.854422139, 96.390, 1957.0, 44.2380
27.906943269, 96.390, 1744.0, 41.7612
27.959464400, 96.390, 1698.0, 41.2068
28.011985531, 96.390, 1699.0, 41.2189
28.064506661, 96.390, 1761.0, 41.9643
28.117027792, 96.390, 1762.0, 41.9762
28.169548923, 96.390, 1764.0, 42.0000
28.222070054, 96.390, 2235.0, 47.2758
28.274591184, 96.390, 2581.0, 50.8035
28.327112315, 96.390, 2297.0, 47.9270
28.379633446, 96.390, 1818.0, 42.6380
28.432154576, 96.390, 1678.0, 40.9634
28.484675707, 96.390, 1787.0, 42.2729
28.537196838, 96.390, 1820.0, 42.6615
28.589717968, 96.390, 1725.0, 41.5331
28.642239099, 96.390, 1726.0, 41.5452
28.694760230, 96.390, 1711.0, 41.3642
28.747281361, 96.390, 1702.0, 41.2553
28.799802491, 96.390, 1674.0, 40.9145
28.852323622, 96.390, 1801.0, 42.4382
28.904844753, 96.390, 1774.0, 42.1189
28.957365883, 96.390, 1772.0, 42.0951
29.009887014, 96.390, 1683.0, 41.0244
29.062408145, 96.390, 1744.0, 41.7612
29.114929276, 96.390, 1850.0, 43.0116
29.167450406, 96.390, 1824.0, 42.7083
29.219971537, 96.390, 1797.0, 42.3910
29.272492668, 96.390, 1725.0, 41.5331
29.325013798, 96.390, 1760.0, 41.9524
29.377534929, 96.390, 1817.0, 42.6263
29.430056060, 96.390, 1739.0, 41.7013
29.482577191, 96.390, 1807.0, 42.5088
29.535098321, 96.390, 1730.0, 41.5933
29.587619452, 96.390, 1878.0, 43.3359
29.640140583, 96.390, 1854.0, 43.0581
29.692661713, 96.390, 1718.0, 41.4488
29.745182844, 96.390, 1663.0, 40.7799
29.797703975, 96.390, 1758.0, 41.9285
29.850225105, 96.390, 1725.0, 41.5331
29.902746236, 96.390, 1679.0, 40.9756
29.955267367, 96.390, 1712.0, 41.3763
30.007788498, 96.390, 1652.0, 40.6448
30.060309628, 96.390, 1701.0, 41.2432
30.112830759, 96.390, 1611.0, 40.1373
30.165351890, 96.390, 1648.0, 40.5956
30.217873020, 96.390, 1668.0, 40.8412
30.270394151, 96.390, 1660.0, 40.7431
30.322915282, 96.390, 1672.0, 40.8901
30.375436413, 96.390, 1743.0, 41.7493
30.427957543, 96.390, 1873.0, 43.2782
30.480478674, 96.390, 3127.0, 55.9196
30.532999805, 96.390, 2368.0, 48.6621
30.585520935, 96.390, 2373.0, 48.7134
30.638042066, 96.390, 2722.0, 52.1728
30.690563197, 96.390, 4008.0, 63.3088
30.743084328, 96.390, 5894.0, 76.7724
30.795605458, 96.390, 3963.0, 62.9524
30.848126589, 96.390, 2322.0, 48.1871
30.900647720, 96.390, 1890.0, 43.4741
30.953168850, 96.390, 1853.0, 43.0465
31.005689981, 96.390, 1841.0, 42.9069
31.058211112, 96.390, 1886.0, 43.4281
31.110732243, 96.390, 1874.0, 43.2897
31.163253373, 96.390, 1710.0, 41.3521
31.215774504, 96.390, 1630.0, 40.3733
31.268295635, 96.390, 1729.0, 41.5812
31.320816765, 96.390, 1780.0, 42.1900
31.373337896, 96.390, 1878.0, 43.3359
31.425859027, 96.390, 1840.0, 42.8952
31.478380157, 96.390, 2045.0, 45.2217
31.530901288, 96.390, 1915.0, 43.7607
31.583422419, 96.390, 1791.0, 42.3202
31.635943550, 96.390, 2238.0, 47.3075
31.688464680, 96.390, 2814.0, 53.0471
31.740985811, 96.390, 3434.0, 58.6003
31.793506942, 96.390, 2387.0, 48.8569
31.846028072, 96.390, 1935.0, 43.9886
31.898549203, 96.390, 1833.0, 42.8135
31.951070334, 96.390, 1999.0, 44.7102
32.003591465, 96.390, 1846.0, 42.9651
32.056112595, 96.390, 1749.0, 41.8210
32.108633726, 96.390, 1696.0, 41.1825
32.161154857, 96.390, 1775.0, 42.1307
32.213675987, 96.390, 1631.0, 40.3856
32.266197118, 96.390, 1706.0, 41.3038
32.318718249, 96.390, 1756.0, 41.9047
32.371239380, 96.390, 1805.0, 42.4853
32.423760510, 96.390, 1711.0, 41.3642
32.476281641, 96.390, 1778.0, 42.1663
32.528802772, 96.390, 1597.0, 39.9625
32.581323902, 96.390, 1747.0, 41.7971
32.633845033, 96.390, 1866.0, 43.1972
32.686366164, 96.390, 1938.0, 44.0227
32.738887295, 96.390, 1803.0, 42.4617
32.791408425, 96.390, 1592.0, 39.8999
32.843929556, 96.390, 1673.0, 40.9023
32.896450687, 96.390, 1937.0, 44.0114
32.948971817, 96.390, 2033.0, 45.0888
33.001492948, 96.390, 2205.0, 46.9574
33.054014079, 96.390, 2578.0, 50.7740
33.106535209, 96.390, 2908.0, 53.9259
33.159056340, 96.390, 2688.0, 51.8459
33.211577471, 96.390, 2381.0, 48.7955
33.264098602, 96.390, 2187.0, 46.7654
33.316619732, 96.390, 2017.0, 44.9110
33.369140863, 96.390, 2548.0, 50.4777
33.421661994, 96.390, 3919.0, 62.6019
33.474183124, 96.390, 4495.0, 67.0448
33.526704255, 96.390, 3094.0, 55.6237
33.579225386, 96.390, 2305.0, 48.0104
33.631746517, 96.390, 1658.0, 40.7185
33.684267647, 96.390, 1654.0, 40.6694
33.736788778, 96.390, 1688.0, 41.0853
33.789309909, 96.390, 1727.0, 41.5572
33.841831039, 96.390, 1772.0, 42.0951
33.894352170, 96.390, 2012.0, 44.8553
33.946873301, 96.390, 1980.0, 44.4972
33.999394432, 96.390, 1974.0, 44.4297
34.051915562, 96.390, 1890.0, 43.4741
34.104436693, 96.390, 1794.0, 42.3556
34.156957824, 96.390, 1823.0, 42.6966
34.209478954, 96.390, 1952.0, 44.1814
34.262000085, 96.390, 1989.0, 44.5982
34.314521216, 96.390, 2371.0, 48.6929
34.367042346, 96.390, 2289.0, 47.8435
34.419563477, 96.390, 2103.0, 45.8585
34.472084608, 96.390, 2076.0, 45.5631
34.524605739, 96.390, 2019.0, 44.9333
34.577126869, 96.390, 2127.0, 46.1194
34.629648000, 96.390, 2281.0, 47.7598
34.682169131, 96.390, 2493.0, 49.9300
34.734690261, 96.390, 2349.0, 48.4665
34.787211392, 96.390, 2352.0, 48.4974
34.839732523, 96.390, 2105.0, 45.8803
34.892253654, 96.390, 2162.0, 46.4973
34.944774784, 96.390, 2454.0, 49.5379
34.997295915, 96.390, 3295.0, 57.4021
35.049817046, 96.390, 2719.0, 52.1440
35.102338176, 96.390, 2671.0, 51.6817
35.154859307, 96.390, 2291.0, 47.8644
35.207380438, 96.390, 2801.0, 52.9245
35.259901569, 96.390, 2428.0, 49.2747
35.312422699, 96.390, 2381.0, 48.7955
35.364943830, 96.390, 1990.0, 44.6094
35.417464961, 96.390, 1854.0, 43.0581
35.469986091, 96.390, 1900.0, 43.5890
35.522507222, 96.390, 1920.0, 43.8178
35.575028353, 96.390, 1931.0, 43.9431
35.627549484, 96.390, 1915.0, 43.7607
35.680070614, 96.390, 2036.0, 45.1221
35.732591745, 96.390, 1866.0, 43.1972
35.785112876, 96.390, 1869.0, 43.2319
35.837634006, 96.390, 1861.0, 43.1393
35.890155137, 96.390, 1877.0, 43.3244
35.942676268, 96.390, 2050.0, 45.2769
35.995197398, 96.390, 2227.0, 47.1911
36.047718529, 96.390, 1931.0, 43.9431
36.100239660, 96.390, 1883.0, 43.3935
36.152760791, 96.390, 1683.0, 41.0244
36.205281921, 96.390, 1656.0, 40.6940
36.257803052, 96.390, 1643.0, 40.5339
36.310324183, 96.390, 1898.0, 43.5660
36.362845313, 96.390, 1970.0, 44.3847
36.415366444, 96.390, 1814.0, 42.5911
36.467887575, 96.390, 1809.0, 42.5323
36.520408706, 96.390, 1651.0, 40.6325
36.572929836, 96.390, 1479.0, 38.4578
36.625450967, 96.390, 1577.0, 39.7115
36.677972098, 96.390, 1728.0, 41.5692
36.730493228, 96.390, 1637.0, 40.4599
36.783014359, 96.390, 1540.0, 39.2428
36.835535490, 96.390, 1482.0, 38.4968
36.888056621, 96.390, 1441.0, 37.9605
36.940577751, 96.390, 1393.0, 37.3229
36.993098882, 96.390, 1423.0, 37.7227
37.045620013, 96.390, 1457.0, 38.1707
37.098141143, 96.390, 1455.0, 38.1445
37.150662274, 96.390, 1443.0, 37.9868
37.203183405, 96.390, 1465.0, 38.2753
37.255704535, 96.390, 1415.0, 37.6165
37.308225666, 96.390, 1442.0, 37.9737
37.360746797, 96.390, 1554.0, 39.4208
37.413267928, 96.390, 1459.0, 38.1969
37.465789058, 96.390, 1479.0, 38.4578
37.518310189, 96.390, 1400.0, 37.4166
37.570831320, 96.390, 1361.0, 36.8917
37.623352450, 96.390, 1459.0, 38.1969
37.675873581, 96.390, 1491.0, 38.6135
37.728394712, 96.390, 1395.0, 37.3497
37.780915843, 96.390, 1530.0, 39.1152
37.833436973, 96.390, 1714.0, 41.4005
37.885958104, 96.390, 1722.0, 41.4970
37.938479235, 96.390, 1673.0, 40.9023
37.991000365, 96.390, 1581.0, 39.7618
38.043521496, 96.390, 1454.0, 38.1314
38.096042627, 96.390, 1515.0, 38.9230
38.148563758, 96.390, 1491.0, 38.6135
38.201084888, 96.390, 1663.0, 40.7799
38.253606019, 96.390, 2005.0, 44.7772
38.306127150, 96.390, 2264.0, 47.5815
38.358648280, 96.390, 1861.0, 43.1393
38.411169411, 96.390, 1849.0, 43.0000
38.463690542, 96.390, 1534.0, 39.1663
38.516211673, 96.390, 1445.0, 38.0132
38.568732803, 96.390, 1358.0, 36.8511
38.621253934, 96.390, 1404.0, 37.4700
38.673775065, 96.390, 1446.0, 38.0263
38.726296195, 96.390, 1388.0, 37.2559
38.778817326, 96.390, 1404.0, 37.4700
38.831338457, 96.390, 1336.0, 36.5513
38.883859587, 96.390, 1319.0, 36.3180
38.936380718, 96.390, 1312.0, 36.2215
38.988901849, 96.390, 1544.0, 39.2938
39.041422980, 96.390, 1542.0, 39.2683
39.093944110, 96.390, 1423.0, 37.7227
39.146465241, 96.390, 1474.0, 38.3927
39.198986372, 96.390, 2313.0, 48.0937
39.251507502, 96.390, 2902.0, 53.8702
39.304028633, 96.390, 1930.0, 43.9318
39.356549764, 96.390, 2053.0, 45.3100
39.409070895, 96.390, 1417.0, 37.6431
39.461592025, 96.390, 1278.0, 35.7491
39.514113156, 96.390, 1292.0, 35.9444
39.566634287, 96.390, 1348.0, 36.7151
39.619155417, 96.390, 1390.0, 37.2827
39.671676548, 96.390, 1345.0, 36.6742
39.724197679, 96.390, 1581.0, 39.7618
39.776718810, 96.390, 1691.0, 41.1218
39.829239940, 96.390, 1767.0, 42.0357
39.881761071, 96.390, 1509.0, 38.8458
39.934282202, 96.390, 1496.0, 38.6782
39.986803332, 96.390, 1250.0, 35.3553
40.039324463, 96.390, 1357.0, 36.8375
40.091845594, 96.390, 1293.0, 35.9583
40.144366725, 96.390, 1533.0, 39.1535
40.196887855, 96.390, 1527.0, 39.0768
40.249408986, 96.390, 1398.0, 37.3898
40.301930117, 96.390, 1361.0, 36.8917
40.354451247, 96.390, 1259.0, 35.4824
40.406972378, 96.390, 1219.0, 34.9142
40.459493509, 96.390, 1153.0, 33.9559
40.512014639, 96.390, 1144.0, 33.8231
40.564535770, 96.390, 1236.0, 35.1568
40.617056901, 96.390, 1196.0, 34.5832
40.669578032, 96.390, 1201.0, 34.6554
40.722099162, 96.390, 1155.0, 33.9853
40.774620293, 96.390, 1191.0, 34.5109
40.827141424, 96.390, 1113.0, 33.3617
40.879662554, 96.390, 1158.0, 34.0294
40.932183685, 96.390, 1103.0, 33.2114
40.984704816, 96.390, 1176.0, 34.2929
41.037225947, 96.390, 1119.0, 33.4515
41.089747077, 96.390, 1156.0, 34.0000
41.142268208, 96.390, 1201.0, 34.6554
41.194789339, 96.390, 1221.0, 34.9428
41.247310469, 96.390, 1121.0, 33.4813
41.299831600, 96.390, 1258.0, 35.4683
41.352352731, 96.390, 1693.0, 41.1461
41.404873862, 96.390, 1398.0, 37.3898
41.457394992, 96.390, 1348.0, 36.7151
41.509916123, 96.390, 1252.0, 35.3836
41.562437254, 96.390, 1184.0, 34.4093
41.614958384, 96.390, 1076.0, 32.8024
41.667479515, 96.390, 1079.0, 32.8481
41.720000646, 96.390, 1092.0, 33.0454
41.772521776, 96.390, 1055.0, 32.4808
41.825042907, 96.390, 1030.0, 32.0936
41.877564038, 96.390, 1086.0, 32.9545
41.930085169, 96.390, 1080.0, 32.8634
41.982606299, 96.390, 1055.0, 32.4808
42.035127430, 96.390, 1058.0, 32.5269
42.087648561, 96.390, 1297.0, 36.0139
42.140169691, 96.390, 1637.0, 40.4599
42.192690822, 96.390, 1431.0, 37.8286
42.245211953, 96.390, 1545.0, 39.3065
42.297733084, 96.390, 1382.0, 37.1753
42.350254214, 96.390, 1159.0, 34.0441
42.402775345, 96.390, 1068.0, 32.6803
42.455296476, 96.390, 1040.0, 32.2490
42.507817606, 96.390, 1049.0, 32.3883
42.560338737, 96.390, 1202.0, 34.6699
42.612859868, 96.390, 1141.0, 33.7787
42.665380999, 96.390, 1160.0, 34.0588
42.717902129, 96.390, 1292.0, 35.9444
42.770423260, 96.390, 1224.0, 34.9857
42.822944391, 96.390, 1103.0, 33.2114
42.875465521, 96.390, 1119.0, 33.4515
42.927986652, 96.390, 1081.0, 32.8786
42.980507783, 96.390, 1056.0, 32.4962
43.033028914, 96.390, 1041.0, 32.2645
43.085550044, 96.390, 1052.0, 32.4345
43.138071175, 96.390, 1061.0, 32.5730
43.190592306, 96.390, 1068.0, 32.6803
43.243113436, 96.390, 1044.0, 32.3110
43.295634567, 96.390, 1076.0, 32.8024
43.348155698, 96.390, 1043.0, 32.2955
43.400676828, 96.390, 1049.0, 32.3883
43.453197959, 96.390, 1016.0, 31.8748
43.505719090, 96.390, 1111.0, 33.3317
43.558240221, 96.390, 1148.0, 33.8821
43.610761351, 96.390, 1148.0, 33.8821
43.663282482, 96.390, 1052.0, 32.4345
43.715803613, 96.390, 1072.0, 32.7414
43.768324743, 96.390, 1044.0, 32.3110
43.820845874, 96.390, 1027.0, 32.0468
43.873367005, 96.390, 1006.0, 31.7175
43.925888136, 96.390, 1067.0, 32.6650
43.978409266, 96.390, 996.0, 31.5595
44.030930397, 96.390, 1056.0, 32.4962
44.083451528, 96.390, 1029.0, 32.0780
44.135972658, 96.390, 1071.0, 32.7261
44.188493789, 96.390, 1146.0, 33.8526
44.241014920, 96.390, 1250.0, 35.3553
44.293536051, 96.390, 1108.0, 33.2866
44.346057181, 96.390, 1119.0, 33.4515
44.398578312, 96.390, 1134.0, 33.6749
44.451099443, 96.390, 1072.0, 32.7414
44.503620573, 96.390, 1054.0, 32.4654
44.556141704, 96.390, 1125.0, 33.5410
44.608662835, 96.390, 1105.0, 33.2415
44.661183966, 96.390, 1108.0, 33.2866
44.713705096, 96.390, 1221.0, 34.9428
44.766226227, 96.390, 1359.0, 36.8646
44.818747358, 96.390, 1277.0, 35.7351
44.871268488, 96.390, 1389.0, 37.2693
44.923789619, 96.390, 1183.0, 34.3948
44.976310750, 96.390, 1214.0, 34.8425
45.028831880, 96.390, 1113.0, 33.3617
45.081353011, 96.390, 1241.0, 35.2278
45.133874142, 96.390, 1403.0, 37.4566
45.186395273, 96.390, 1202.0, 34.6699
45.238916403, 96.390, 1337.0, 36.5650
45.291437534, 96.390, 1180.0, 34.3511
45.343958665, 96.390, 1170.0, 34.2053
45.396479795, 96.390, 1210.0, 34.7851
45.449000926, 96.390, 1170.0, 34.2053
45.501522057, 96.390, 1159.0, 34.0441
45.554043188, 96.390, 1203.0, 34.6843
45.606564318, 96.390, 1318.0, 36.3043
45.659085449, 96.390, 1238.0, 35.1852
45.711606580, 96.390, 1276.0, 35.7211
45.764127710, 96.390, 1256.0, 35.4401
45.816648841, 96.390, 1114.0, 33.3766
45.869169972, 96.390, 1206.0, 34.7275
45.921691103, 96.390, 1144.0, 33.8231
45.974212233, 96.390, 1150.0, 33.9116
46.026733364, 96.390, 1138.0, 33.7343
46.079254495, 96.390, 1226.0, 35.0143
46.131775625, 96.390, 1406.0, 37.4967
46.184296756, 96.390, 1879.0, 43.3474
46.236817887, 96.390, 1562.0, 39.5221
46.289339017, 96.390, 1805.0, 42.4853
46.341860148, 96.390, 1596.0, 39.9500
46.394381279, 96.390, 1515.0, 38.9230
46.446902410, 96.390, 1508.0, 38.8330
46.499423540, 96.390, 1358.0, 36.8511
46.551944671, 96.390, 1397.0, 37.3765
46.604465802, 96.390, 1331.0, 36.4829
46.656986932, 96.390, 1448.0, 38.0526
46.709508063, 96.390, 1469.0, 38.3275
46.762029194, 96.390, 1274.0, 35.6931
46.814550325, 96.390, 1323.0, 36.3731
46.867071455, 96.390, 1118.0, 33.4365
46.919592586, 96.390, 1070.0, 32.7109
46.972113717, 96.390, 1035.0, 32.1714
47.024634847, 96.390, 1060.0, 32.5576
47.077155978, 96.390, 1058.0, 32.5269
47.129677109, 96.390, 1085.0, 32.9393
47.182198240, 96.390, 1028.0, 32.0624
47.234719370, 96.390, 1116.0, 33.4066
47.287240501, 96.390, 1049.0, 32.3883
47.339761632, 96.390, 1117.0, 33.4215
47.392282762, 96.390, 1051.0, 32.4191
47.444803893, 96.390, 1096.0, 33.1059
47.497325024, 96.390, 1056.0, 32.4962
47.549846155, 96.390, 1134.0, 33.6749
47.602367285, 96.390, 1053.0, 32.4500
47.654888416, 96.390, 1036.0, 32.1870
47.707409547, 96.390, 1117.0, 33.4215
47.759930677, 96.390, 1029.0, 32.0780
47.812451808, 96.390, 943.0, 30.7083
47.864972939, 96.390, 1026.0, 32.0312
47.917494069, 96.390, 1073.0, 32.7567
47.970015200, 96.390, 1076.0, 32.8024
48.022536331, 96.390, 1101.0, 33.1813
48.075057462, 96.390, 1064.0, 32.6190
48.127578592, 96.390, 1201.0, 34.6554
48.180099723, 96.390, 1040.0, 32.2490
48.232620854, 96.390, 1042.0, 32.2800
48.285141984, 96.390, 1030.0, 32.0936
48.337663115, 96.390, 1092.0, 33.0454
48.390184246, 96.390, 1027.0, 32.0468
48.442705377, 96.390, 1123.0, 33.5112
48.495226507, 96.390, 1131.0, 33.6303
48.547747638, 96.390, 1127.0, 33.5708
48.600268769, 96.390, 1114.0, 33.3766
48.652789899, 96.390, 1006.0, 31.7175
48.705311030, 96.390, 1116.0, 33.4066
48.757832161, 96.390, 1086.0, 32.9545
48.810353292, 96.390, 1082.0, 32.8938
48.862874422, 96.390, 1005.0, 31.7017
48.915395553, 96.390, 993.0, 31.5119
48.967916684, 96.390, 1020.0, 31.9374
49.020437814, 96.390, 989.0, 31.4484
49.072958945, 96.390, 1040.0, 32.2490
49.125480076, 96.390, 1083.0, 32.9090
49.178001207, 96.390, 981.0, 31.3209
49.230522337, 96.390, 999.0, 31.6070
49.283043468, 96.390, 947.0, 30.7734
49.335564599, 96.390, 1007.0, 31.7333
49.388085729, 96.390, 1038.0, 32.2180
49.440606860, 96.390, 1042.0, 32.2800
49.493127991, 96.390, 991.0, 31.4802
49.545649121, 96.390, 1020.0, 31.9374
49.598170252, 96.390, 1065.0, 32.6343
49.650691383, 96.390, 1133.0, 33.6601
49.703212514, 96.390, 1091.0, 33.0303
49.755733644, 96.390, 1099.0, 33.1512
49.808254775, 96.390, 1010.0, 31.7805
49.860775906, 96.390, 967.0, 31.0966
49.913297036, 96.390, 978.0, 31.2730
49.965818167, 96.390, 893.0, 29.8831
50.018339298, 96.390, 836.0, 28.9137
50.070860429, 96.390, 891.0, 29.8496
50.123381559, 96.390, 888.0, 29.7993
50.175902690, 96.390, 948.0, 30.7896
50.228423821, 96.390, 871.0, 29.5127
50.280944951, 96.390, 954.0, 30.8869
50.333466082, 96.390, 907.0, 30.1164
50.385987213, 96.390, 849.0, 29.1376
50.438508344, 96.390, 848.0, 29.1204
50.491029474, 96.390, 847.0, 29.1033
50.543550605, 96.390, 916.0, 30.2655
50.596071736, 96.390, 806.0, 28.3901
50.648592866, 96.390, 890.0, 29.8329
50.701113997, 96.390, 874.0, 29.5635
50.753635128, 96.390, 846.0, 29.0861
50.806156258, 96.390, 885.0, 29.7489
50.858677389, 96.390, 873.0, 29.5466
50.911198520, 96.390, 839.0, 28.9655
50.963719651, 96.390, 980.0, 31.3050
51.016240781, 96.390, 1107.0, 33.2716
51.068761912, 96.390, 961.0, 31.0000
51.121283043, 96.390, 954.0, 30.8869
51.173804173, 96.390, 951.0, 30.8383
51.226325304, 96.390, 839.0, 28.9655
51.278846435, 96.390, 799.0, 28.2666
51.331367566, 96.390, 840.0, 28.9828
51.383888696, 96.390, 1058.0, 32.5269
51.436409827, 96.390, 1031.0, 32.1092
51.488930958, 96.390, 894.0, 29.8998
51.541452088, 96.390, 940.0, 30.6594
51.593973219, 96.390, 871.0, 29.5127
51.646494350, 96.390, 871.0, 29.5127
51.699015481, 96.390, 848.0, 29.1204
51.751536611, 96.390, 817.0, 28.5832
51.804057742, 96.390, 835.0, 28.8964
51.856578873, 96.390, 811.0, 28.4781
51.909100003, 96.390, 913.0, 30.2159
51.961621134, 96.390, 818.0, 28.6007
52.014142265, 96.390, 851.0, 29.1719
52.066663396, 96.390, 838.0, 28.9482
52.119184526, 96.390, 790.0, 28.1069
52.171705657, 96.390, 818.0, 28.6007
52.224226788, 96.390, 796.0, 28.2135
52.276747918, 96.390, 817.0, 28.5832
52.329269049, 96.390, 854.0, 29.2233
52.381790180, 96.390, 979.0, 31.2890
52.434311310, 96.390, 997.0, 31.5753
52.486832441, 96.390, 881.0, 29.6816
52.539353572, 96.390, 959.0, 30.9677
52.591874703, 96.390, 968.0, 31.1127
52.644395833, 96.390, 868.0, 29.4618
52.696916964, 96.390, 1045.0, 32.3265
52.749438095, 96.390, 950.0, 30.8221
52.801959225, 96.390, 877.0, 29.6142
52.854480356, 96.390, 986.0, 31.4006
52.907001487, 96.390, 1050.0, 32.4037
52.959522618, 96.390, 941.0, 30.6757
53.012043748, 96.390, 927.0, 30.4467
53.064564879, 96.390, 923.0, 30.3809
53.117086010, 96.390, 962.0, 31.0161
53.169607140, 96.390, 1059.0, 32.5423
53.222128271, 96.390, 880.0, 29.6648
53.274649402, 96.390, 902.0, 30.0333
53.327170533, 96.390, 905.0, 30.0832
53.379691663, 96.390, 807.0, 28.4077
53.432212794, 96.390, 793.0, 28.1603
53.484733925, 96.390, 828.0, 28.7750
53.537255055, 96.390, 781.0, 27.9464
53.589776186, 96.390, 728.0, 26.9815
53.642297317, 96.390, 755.0, 27.4773
53.694818448, 96.390, 761.0, 27.5862
53.747339578, 96.390, 772.0, 27.7849
53.799860709, 96.390, 845.0, 29.0689
53.852381840, 96.390, 929.0, 30.4795
53.904902970, 96.390, 898.0, 29.9666
53.957424101, 96.390, 844.0, 29.0517
54.009945232, 96.390, 873.0, 29.5466
54.062466362, 96.390, 937.0, 30.6105
54.114987493, 96.390, 975.0, 31.2250
54.167508624, 96.390, 971.0, 31.1609
54.220029755, 96.390, 823.0, 28.6880
54.272550885, 96.390, 928.0, 30.4631
54.325072016, 96.390, 919.0, 30.3150
54.377593147, 96.390, 848.0, 29.1204
54.430114277, 96.390, 853.0, 29.2062
54.482635408, 96.390, 777.0, 27.8747
54.535156539, 96.390, 774.0, 27.8209
54.587677670, 96.390, 918.0, 30.2985
54.640198800, 96.390, 850.0, 29.1548
54.692719931, 96.390, 844.0, 29.0517
54.745241062, 96.390, 834.0, 28.8791
54.797762192, 96.390, 844.0, 29.0517
54.850283323, 96.390, 851.0, 29.1719
54.902804454, 96.390, 913.0, 30.2159
54.955325585, 96.390, 939.0, 30.6431
55.007846715, 96.390, 960.0, 30.9839
55.060367846, 96.390, 902.0, 30.0333
55.112888977, 96.390, 885.0, 29.7489
55.165410107, 96.390, 835.0, 28.8964
55.217931238, 96.390, 772.0, 27.7849
55.270452369, 96.390, 727.0, 26.9629
55.322973499, 96.390, 730.0, 27.0185
55.375494630, 96.390, 821.0, 28.6531
55.428015761, 96.390, 895.0, 29.9166
55.480536892, 96.390, 831.0, 28.8271
55.533058022, 96.390, 781.0, 27.9464
55.585579153, 96.390, 807.0, 28.4077
55.638100284, 96.390, 771.0, 27.7669
55.690621414, 96.390, 728.0, 26.9815
55.743142545, 96.390, 733.0, 27.0740
55.795663676, 96.390, 705.0, 26.5518
55.848184807, 96.390, 735.0, 27.1109
55.900705937, 96.390, 737.0, 27.1477
55.953227068, 96.390, 731.0, 27.0370
56.005748199, 96.390, 762.0, 27.6043
56.058269329, 96.390, 794.0, 28.1780
56.110790460, 96.390, 722.0, 26.8701
56.163311591, 96.390, 736.0, 27.1293
56.215832722, 96.390, 738.0, 27.1662
56.268353852, 96.390, 732.0, 27.0555
56.320874983, 96.390, 715.0, 26.7395
56.373396114, 96.390, 749.0, 27.3679
56.425917244, 96.390, 752.0, 27.4226
56.478438375, 96.390, 708.0, 26.6083
56.530959506, 96.390, 775.0, 27.8388
56.583480637, 96.390, 726.0, 26.9444
56.636001767, 96.390, 733.0, 27.0740
56.688522898, 96.390, 714.0, 26.7208
56.741044029, 96.390, 712.0, 26.6833
56.793565159, 96.390, 643.0, 25.3574
56.846086290, 96.390, 760.0, 27.5681
56.898607421, 96.390, 687.0, 26.2107
56.951128551, 96.390, 668.0, 25.8457
57.003649682, 96.390, 668.0, 25.8457
57.056170813, 96.390, 709.0, 26.6271
57.108691944, 96.390, 710.0, 26.6458
57.161213074, 96.390, 663.0, 25.7488
57.213734205, 96.390, 709.0, 26.6271
57.266255336, 96.390, 691.0, 26.2869
57.318776466, 96.390, 698.0, 26.4197
57.371297597, 96.390, 737.0, 27.1477
57.423818728, 96.390, 784.0, 28.0000
57.476339859, 96.390, 841.0, 29.0000
57.528860989, 96.390, 800.0, 28.2843
57.581382120, 96.390, 803.0, 28.3373
57.633903251, 96.390, 1061.0, 32.5730
57.686424381, 96.390, 1171.0, 34.2199
57.738945512, 96.390, 893.0, 29.8831
57.791466643, 96.390, 957.0, 30.9354
57.843987774, 96.390, 987.0, 31.4166
57.896508904, 96.390, 801.0, 28.3019
57.949030035, 96.390, 688.0, 26.2298
58.001551166, 96.390, 742.0, 27.2397
58.054072296, 96.390, 714.0, 26.7208
58.106593427, 96.390, 692.0, 26.3059
58.159114558, 96.390, 717.0, 26.7769
58.211635689, 96.390, 680.0, 26.0768
58.264156819, 96.390, 757.0, 27.5136
58.316677950, 96.390, 709.0, 26.6271
58.369199081, 96.390, 725.0, 26.9258
58.421720211, 96.390, 761.0, 27.5862
58.474241342, 96.390, 729.0, 27.0000
58.526762473, 96.390, 745.0, 27.2947
58.579283603, 96.390, 698.0, 26.4197
58.631804734, 96.390, 695.0, 26.3629
58.684325865, 96.390, 627.0, 25.0400
58.736846996, 96.390, 711.0, 26.6646
58.789368126, 96.390, 733.0, 27.0740
58.841889257, 96.390, 678.0, 26.0384
58.894410388, 96.390, 694.0, 26.3439
58.946931518, 96.390, 686.0, 26.1916
58.999452649, 96.390, 644.0, 25.3772
59.051973780, 96.390, 679.0, 26.0576
59.104494911, 96.390, 684.0, 26.1534
59.157016041, 96.390, 714.0, 26.7208
59.209537172, 96.390, 719.0, 26.8142
59.262058303, 96.390, 694.0, 26.3439
59.314579433, 96.390, 767.0, 27.6948
59.367100564, 96.390, 753.0, 27.4408
59.419621695, 96.390, 686.0, 26.1916
59.472142826, 96.390, 750.0, 27.3861
59.524663956, 96.390, 684.0, 26.1534
59.577185087, 96.390, 706.0, 26.5707
59.629706218, 96.390, 795.0, 28.1957
59.682227348, 96.390, 771.0, 27.7669
59.734748479, 96.390, 755.0, 27.4773
59.787269610, 96.390, 707.0, 26.5895
59.839790740, 96.390, 766.0, 27.6767
59.892311871, 96.390, 742.0, 27.2397
59.944833002, 96.390, 756.0, 27.4955
59.997354133, 96.390, 797.0, 28.2312
60.049875263, 96.390, 727.0, 26.9629
60.102396394, 96.390, 716.0, 26.7582
60.154917525, 96.390, 783.0, 27.9821
60.207438655, 96.390, 774.0, 27.8209
60.259959786, 96.390, 780.0, 27.9285
60.312480917, 96.390, 773.0, 27.8029
60.365002048, 96.390, 837.0, 28.9310
60.417523178, 96.390, 910.0, 30.1662
60.470044309, 96.390, 925.0, 30.4138
60.522565440, 96.390, 880.0, 29.6648
60.575086570, 96.390, 945.0, 30.7409
60.627607701, 96.390, 980.0, 31.3050
60.680128832, 96.390, 982.0, 31.3369
60.732649963, 96.390, 963.0, 31.0322
60.785171093, 96.390, 1008.0, 31.7490
60.837692224, 96.390, 1082.0, 32.8938
60.890213355, 96.390, 1000.0, 31.6228
60.942734485, 96.390, 1058.0, 32.5269
60.995255616, 96.390, 1146.0, 33.8526
61.047776747, 96.390, 1238.0, 35.1852
61.100297878, 96.390, 1135.0, 33.6898
61.152819008, 96.390, 1153.0, 33.9559
61.205340139, 96.390, 1143.0, 33.8083
61.257861270, 96.390, 1144.0, 33.8231
61.310382400, 96.390, 1121.0, 33.4813
61.362903531, 96.390, 1094.0, 33.0757
61.415424662, 96.390, 984.0, 31.3688
61.467945792, 96.390, 1001.0, 31.6386
61.520466923, 96.390, 1087.0, 32.9697
61.572988054, 96.390, 1021.0, 31.9531
61.625509185, 96.390, 1040.0, 32.2490
61.678030315, 96.390, 976.0, 31.2410
61.730551446, 96.390, 936.0, 30.5941
61.783072577, 96.390, 1056.0, 32.4962
61.835593707, 96.390, 956.0, 30.9192
61.888114838, 96.390, 993.0, 31.5119
61.940635969, 96.390, 997.0, 31.5753
61.993157100, 96.390, 980.0, 31.3050
62.045678230, 96.390, 972.0, 31.1769
62.098199361, 96.390, 998.0, 31.5911
62.150720492, 96.390, 926.0, 30.4302
62.203241622, 96.390, 976.0, 31.2410
62.255762753, 96.390, 969.0, 31.1288
62.308283884, 96.390, 931.0, 30.5123
62.360805015, 96.390, 963.0, 31.0322
62.413326145, 96.390, 894.0, 29.8998
62.465847276, 96.390, 953.0, 30.8707
62.518368407, 96.390, 890.0, 29.8329
62.570889537, 96.390, 841.0, 29.0000
62.623410668, 96.390, 869.0, 29.4788
62.675931799, 96.390, 824.0, 28.7054
62.728452930, 96.390, 828.0, 28.7750
62.780974060, 96.390, 811.0, 28.4781
62.833495191, 96.390, 783.0, 27.9821
62.886016322, 96.390, 831.0, 28.8271
62.938537452, 96.390, 742.0, 27.2397
62.991058583, 96.390, 713.0, 26.7021
63.043579714, 96.390, 748.0, 27.3496
63.096100844, 96.390, 752.0, 27.4226
63.148621975, 96.390, 744.0, 27.2764
63.201143106, 96.390, 752.0, 27.4226
63.253664237, 96.390, 731.0, 27.0370
63.306185367, 96.390, 699.0, 26.4386
63.358706498, 96.390, 713.0, 26.7021
63.411227629, 96.390, 699.0, 26.4386
63.463748759, 96.390, 693.0, 26.3249
63.516269890, 96.390, 703.0, 26.5141
63.568791021, 96.390, 702.0, 26.4953
63.621312152, 96.390, 687.0, 26.2107
63.673833282, 96.390, 650.0, 25.4951
63.726354413, 96.390, 647.0, 25.4362
63.778875544, 96.390, 664.0, 25.7682
63.831396674, 96.390, 729.0, 27.0000
63.883917805, 96.390, 731.0, 27.0370
63.936438936, 96.390, 742.0, 27.2397
63.988960067, 96.390, 777.0, 27.8747
64.041481197, 96.390, 696.0, 26.3818
64.094002328, 96.390, 765.0, 27.6586
64.146523459, 96.390, 747.0, 27.3313
64.199044589, 96.390, 668.0, 25.8457
64.251565720, 96.390, 687.0, 26.2107
64.304086851, 96.390, 626.0, 25.0200
64.356607981, 96.390, 684.0, 26.1534
64.409129112, 96.390, 607.0, 24.6374
64.461650243, 96.390, 580.0, 24.0832
64.514171374, 96.390, 635.0, 25.1992
64.566692504, 96.390, 602.0, 24.5357
64.619213635, 96.390, 622.0, 24.9399
64.671734766, 96.390, 701.0, 26.4764
64.724255896, 96.390, 740.0, 27.2029
64.776777027, 96.390, 680.0, 26.0768
64.829298158, 96.390, 618.0, 24.8596
64.881819289, 96.390, 709.0, 26.6271
64.934340419, 96.390, 650.0, 25.4951
64.986861550, 96.390, 653.0, 25.5539