File: Files_organized_for_plots/470_day/fXRD_110_P04Free.csv
[Measurement conditions]
Sample identification,110_P04Free14Apr22_Act18Apr22_B1_1000M_NaOH_LS0132_470day
Comment - 1,"Configuration=Stage for Flat Samples/Holders, Owner=nmw10, Creation date=9/21/2022 10:06:30 AM"
Comment - 2,"Goniometer=Theta/Theta; Minimum step size 2Theta:0.0001; Minimum step size Omega:0.0001"
Comment - 3,"Sample stage=Stage for flat samples/holders"
Comment - 4,"Diffractometer system=EMPYREAN"
Comment - 5,"Measurement program=C:\Users\tmr79\OneDrive - The Pennsylvania State University\Documents\NEUP\XRD\Cement\Zerobackground scan.xrdmp, Created identifier={98A3B11C-88F9-4AA6-982C-73314A311EF5}, Created by=Titus Reed, Id=tmr79, Creation date=10/26/2021 3:01:47 PM"
Anode material,Cu
K-Alpha1 wavelength,1.5405980
K-Alpha2 wavelength,1.5444260
Ratio K-Alpha2/K-Alpha1,0.500
Divergence slit,Fixed,0.25
Monochromator used,NO
Generator voltage, 45
Tube current, 40
File date and time,10/Aug/2023 08:34
Unit cell,
h k l, 0 0 0
Scan axis,Gonio
Scan range,4.994599997,64.999991833
Scan step size,0.0262606
No. of points, 2285
Scan type,CONTINUOUS
Time per step,96.390
[Scan points]
Angle, TimePerStep, Intensity, ESD
5.007730280, 96.390, 5191.0, 72.0486
5.060251411, 96.390, 5347.0, 73.1232
5.112772541, 96.390, 5325.0, 72.9726
5.165293672, 96.390, 5260.0, 72.5259
5.217814803, 96.390, 5391.0, 73.4234
5.270335934, 96.390, 5317.0, 72.9178
5.322857064, 96.390, 5522.0, 74.3102
5.375378195, 96.390, 5567.0, 74.6123
5.427899326, 96.390, 5585.0, 74.7329
5.480420456, 96.390, 5850.0, 76.4853
5.532941587, 96.390, 5915.0, 76.9090
5.585462718, 96.390, 6155.0, 78.4538
5.637983849, 96.390, 6590.0, 81.1788
5.690504979, 96.390, 6711.0, 81.9207
5.743026110, 96.390, 6930.0, 83.2466
5.795547241, 96.390, 7035.0, 83.8749
5.848068371, 96.390, 7009.0, 83.7198
5.900589502, 96.390, 6948.0, 83.3547
5.953110633, 96.390, 6946.0, 83.3427
6.005631763, 96.390, 6809.0, 82.5167
6.058152894, 96.390, 6831.0, 82.6499
6.110674025, 96.390, 6685.0, 81.7618
6.163195156, 96.390, 6596.0, 81.2158
6.215716286, 96.390, 6402.0, 80.0125
6.268237417, 96.390, 6283.0, 79.2654
6.320758548, 96.390, 6134.0, 78.3199
6.373279678, 96.390, 6150.0, 78.4219
6.425800809, 96.390, 5995.0, 77.4274
6.478321940, 96.390, 5759.0, 75.8881
6.530843071, 96.390, 5700.0, 75.4983
6.583364201, 96.390, 5689.0, 75.4255
6.635885332, 96.390, 5545.0, 74.4648
6.688406463, 96.390, 5497.0, 74.1418
6.740927593, 96.390, 5325.0, 72.9726
6.793448724, 96.390, 5319.0, 72.9315
6.845969855, 96.390, 5121.0, 71.5612
6.898490986, 96.390, 5174.0, 71.9305
6.951012116, 96.390, 5234.0, 72.3464
7.003533247, 96.390, 4908.0, 70.0571
7.056054378, 96.390, 4765.0, 69.0290
7.108575508, 96.390, 4979.0, 70.5620
7.161096639, 96.390, 4655.0, 68.2276
7.213617770, 96.390, 4445.0, 66.6708
7.266138900, 96.390, 4464.0, 66.8132
7.318660031, 96.390, 4440.0, 66.6333
7.371181162, 96.390, 4286.0, 65.4675
7.423702293, 96.390, 4141.0, 64.3506
7.476223423, 96.390, 3849.0, 62.0403
7.528744554, 96.390, 3829.0, 61.8789
7.581265685, 96.390, 3788.0, 61.5467
7.633786815, 96.390, 3868.0, 62.1932
7.686307946, 96.390, 3643.0, 60.3573
7.738829077, 96.390, 3498.0, 59.1439
7.791350208, 96.390, 3484.0, 59.0254
7.843871338, 96.390, 3372.0, 58.0689
7.896392469, 96.390, 3325.0, 57.6628
7.948913600, 96.390, 3197.0, 56.5420
8.001434730, 96.390, 3172.0, 56.3205
8.053955861, 96.390, 3225.0, 56.7891
8.106476992, 96.390, 3212.0, 56.6745
8.158998123, 96.390, 3177.0, 56.3649
8.211519253, 96.390, 3122.0, 55.8749
8.264040384, 96.390, 3033.0, 55.0727
8.316561515, 96.390, 3123.0, 55.8838
8.369082645, 96.390, 2965.0, 54.4518
8.421603776, 96.390, 2906.0, 53.9073
8.474124907, 96.390, 3029.0, 55.0364
8.526646038, 96.390, 2943.0, 54.2494
8.579167168, 96.390, 2900.0, 53.8516
8.631688299, 96.390, 2917.0, 54.0093
8.684209430, 96.390, 2840.0, 53.2917
8.736730560, 96.390, 2822.0, 53.1225
8.789251691, 96.390, 2841.0, 53.3010
8.841772822, 96.390, 2765.0, 52.5833
8.894293952, 96.390, 2730.0, 52.2494
8.946815083, 96.390, 2787.0, 52.7920
8.999336214, 96.390, 2843.0, 53.3198
9.051857345, 96.390, 2722.0, 52.1728
9.104378475, 96.390, 2867.0, 53.5444
9.156899606, 96.390, 2803.0, 52.9434
9.209420737, 96.390, 2877.0, 53.6377
9.261941867, 96.390, 2687.0, 51.8363
9.314462998, 96.390, 2796.0, 52.8772
9.366984129, 96.390, 2783.0, 52.7541
9.419505260, 96.390, 2796.0, 52.8772
9.472026390, 96.390, 2830.0, 53.1977
9.524547521, 96.390, 2694.0, 51.9038
9.577068652, 96.390, 2886.0, 53.7215
9.629589782, 96.390, 2801.0, 52.9245
9.682110913, 96.390, 2965.0, 54.4518
9.734632044, 96.390, 3010.0, 54.8635
9.787153175, 96.390, 3216.0, 56.7098
9.839674305, 96.390, 3244.0, 56.9561
9.892195436, 96.390, 3459.0, 58.8133
9.944716567, 96.390, 3358.0, 57.9483
9.997237697, 96.390, 3306.0, 57.4978
10.049758828, 96.390, 3101.0, 55.6866
10.102279959, 96.390, 2978.0, 54.5711
10.154801090, 96.390, 2858.0, 53.4603
10.207322220, 96.390, 2782.0, 52.7447
10.259843351, 96.390, 2920.0, 54.0370
10.312364482, 96.390, 2936.0, 54.1849
10.364885612, 96.390, 2859.0, 53.4696
10.417406743, 96.390, 2956.0, 54.3691
10.469927874, 96.390, 2825.0, 53.1507
10.522449004, 96.390, 2852.0, 53.4041
10.574970135, 96.390, 2889.0, 53.7494
10.627491266, 96.390, 2960.0, 54.4059
10.680012397, 96.390, 2989.0, 54.6717
10.732533527, 96.390, 2952.0, 54.3323
10.785054658, 96.390, 2951.0, 54.3231
10.837575789, 96.390, 3033.0, 55.0727
10.890096919, 96.390, 2776.0, 52.6878
10.942618050, 96.390, 2958.0, 54.3875
10.995139181, 96.390, 2949.0, 54.3047
11.047660312, 96.390, 2979.0, 54.5802
11.100181442, 96.390, 3097.0, 55.6507
11.152702573, 96.390, 3026.0, 55.0091
11.205223704, 96.390, 3085.0, 55.5428
11.257744834, 96.390, 3096.0, 55.6417
11.310265965, 96.390, 3083.0, 55.5248
11.362787096, 96.390, 3145.0, 56.0803
11.415308227, 96.390, 3175.0, 56.3471
11.467829357, 96.390, 3120.0, 55.8570
11.520350488, 96.390, 3271.0, 57.1927
11.572871619, 96.390, 3442.0, 58.6686
11.625392749, 96.390, 3268.0, 57.1664
11.677913880, 96.390, 3259.0, 57.0877
11.730435011, 96.390, 3207.0, 56.6304
11.782956141, 96.390, 3212.0, 56.6745
11.835477272, 96.390, 3061.0, 55.3263
11.887998403, 96.390, 2990.0, 54.6809
11.940519534, 96.390, 2961.0, 54.4151
11.993040664, 96.390, 2847.0, 53.3573
12.045561795, 96.390, 2786.0, 52.7826
12.098082926, 96.390, 2817.0, 53.0754
12.150604056, 96.390, 2765.0, 52.5833
12.203125187, 96.390, 2597.0, 50.9608
12.255646318, 96.390, 2572.0, 50.7149
12.308167449, 96.390, 2512.0, 50.1199
12.360688579, 96.390, 2548.0, 50.4777
12.413209710, 96.390, 2554.0, 50.5371
12.465730841, 96.390, 2359.0, 48.5695
12.518251971, 96.390, 2417.0, 49.1630
12.570773102, 96.390, 2408.0, 49.0714
12.623294233, 96.390, 2230.0, 47.2229
12.675815364, 96.390, 2314.0, 48.1041
12.728336494, 96.390, 2221.0, 47.1275
12.780857625, 96.390, 2246.0, 47.3920
12.833378756, 96.390, 2204.0, 46.9468
12.885899886, 96.390, 2248.0, 47.4131
12.938421017, 96.390, 2129.0, 46.1411
12.990942148, 96.390, 2145.0, 46.3141
13.043463279, 96.390, 2173.0, 46.6154
13.095984409, 96.390, 2126.0, 46.1086
13.148505540, 96.390, 2036.0, 45.1221
13.201026671, 96.390, 2062.0, 45.4093
13.253547801, 96.390, 2135.0, 46.2061
13.306068932, 96.390, 2062.0, 45.4093
13.358590063, 96.390, 2053.0, 45.3100
13.411111193, 96.390, 2092.0, 45.7384
13.463632324, 96.390, 2005.0, 44.7772
13.516153455, 96.390, 2081.0, 45.6180
13.568674586, 96.390, 2062.0, 45.4093
13.621195716, 96.390, 2117.0, 46.0109
13.673716847, 96.390, 2311.0, 48.0729
13.726237978, 96.390, 2461.0, 49.6085
13.778759108, 96.390, 2821.0, 53.1131
13.831280239, 96.390, 3226.0, 56.7979
13.883801370, 96.390, 4402.0, 66.3476
13.936322501, 96.390, 5103.0, 71.4353
13.988843631, 96.390, 3579.0, 59.8247
14.041364762, 96.390, 2626.0, 51.2445
14.093885893, 96.390, 2251.0, 47.4447
14.146407023, 96.390, 2082.0, 45.6289
14.198928154, 96.390, 1984.0, 44.5421
14.251449285, 96.390, 1945.0, 44.1022
14.303970416, 96.390, 1815.0, 42.6028
14.356491546, 96.390, 1878.0, 43.3359
14.409012677, 96.390, 1905.0, 43.6463
14.461533808, 96.390, 1776.0, 42.1426
14.514054938, 96.390, 1830.0, 42.7785
14.566576069, 96.390, 1855.0, 43.0697
14.619097200, 96.390, 1776.0, 42.1426
14.671618331, 96.390, 1783.0, 42.2256
14.724139461, 96.390, 1739.0, 41.7013
14.776660592, 96.390, 1766.0, 42.0238
14.829181723, 96.390, 1804.0, 42.4735
14.881702853, 96.390, 1844.0, 42.9418
14.934223984, 96.390, 1813.0, 42.5793
14.986745115, 96.390, 1909.0, 43.6921
15.039266245, 96.390, 2024.0, 44.9889
15.091787376, 96.390, 2115.0, 45.9891
15.144308507, 96.390, 2250.0, 47.4342
15.196829638, 96.390, 2396.0, 48.9490
15.249350768, 96.390, 2458.0, 49.5782
15.301871899, 96.390, 2470.0, 49.6991
15.354393030, 96.390, 2354.0, 48.5180
15.406914160, 96.390, 2280.0, 47.7493
15.459435291, 96.390, 2164.0, 46.5188
15.511956422, 96.390, 2070.0, 45.4973
15.564477553, 96.390, 2002.0, 44.7437
15.616998683, 96.390, 1837.0, 42.8602
15.669519814, 96.390, 1754.0, 41.8808
15.722040945, 96.390, 1758.0, 41.9285
15.774562075, 96.390, 1797.0, 42.3910
15.827083206, 96.390, 1691.0, 41.1218
15.879604337, 96.390, 1690.0, 41.1096
15.932125468, 96.390, 1652.0, 40.6448
15.984646598, 96.390, 1652.0, 40.6448
16.037167729, 96.390, 1685.0, 41.0488
16.089688860, 96.390, 1676.0, 40.9390
16.142209990, 96.390, 1705.0, 41.2916
16.194731121, 96.390, 1605.0, 40.0625
16.247252252, 96.390, 1643.0, 40.5339
16.299773382, 96.390, 1599.0, 39.9875
16.352294513, 96.390, 1626.0, 40.3237
16.404815644, 96.390, 1701.0, 41.2432
16.457336775, 96.390, 1869.0, 43.2319
16.509857905, 96.390, 1800.0, 42.4264
16.562379036, 96.390, 1573.0, 39.6611
16.614900167, 96.390, 1545.0, 39.3065
16.667421297, 96.390, 1545.0, 39.3065
16.719942428, 96.390, 1677.0, 40.9512
16.772463559, 96.390, 1701.0, 41.2432
16.824984690, 96.390, 1824.0, 42.7083
16.877505820, 96.390, 1774.0, 42.1189
16.930026951, 96.390, 1572.0, 39.6485
16.982548082, 96.390, 1501.0, 38.7427
17.035069212, 96.390, 1525.0, 39.0512
17.087590343, 96.390, 1505.0, 38.7943
17.140111474, 96.390, 1521.0, 39.0000
17.192632605, 96.390, 1512.0, 38.8844
17.245153735, 96.390, 1494.0, 38.6523
17.297674866, 96.390, 1529.0, 39.1024
17.350195997, 96.390, 1520.0, 38.9872
17.402717127, 96.390, 1518.0, 38.9615
17.455238258, 96.390, 1472.0, 38.3667
17.507759389, 96.390, 1494.0, 38.6523
17.560280520, 96.390, 1544.0, 39.2938
17.612801650, 96.390, 1536.0, 39.1918
17.665322781, 96.390, 1593.0, 39.9124
17.717843912, 96.390, 1538.0, 39.2173
17.770365042, 96.390, 1493.0, 38.6394
17.822886173, 96.390, 1533.0, 39.1535
17.875407304, 96.390, 1504.0, 38.7814
17.927928434, 96.390, 1497.0, 38.6911
17.980449565, 96.390, 1502.0, 38.7556
18.032970696, 96.390, 1544.0, 39.2938
18.085491827, 96.390, 1467.0, 38.3014
18.138012957, 96.390, 1625.0, 40.3113
18.190534088, 96.390, 1550.0, 39.3700
18.243055219, 96.390, 1633.0, 40.4104
18.295576349, 96.390, 1595.0, 39.9375
18.348097480, 96.390, 1624.0, 40.2989
18.400618611, 96.390, 1682.0, 41.0122
18.453139742, 96.390, 1536.0, 39.1918
18.505660872, 96.390, 1667.0, 40.8289
18.558182003, 96.390, 1531.0, 39.1280
18.610703134, 96.390, 1566.0, 39.5727
18.663224264, 96.390, 1507.0, 38.8201
18.715745395, 96.390, 1648.0, 40.5956
18.768266526, 96.390, 1656.0, 40.6940
18.820787657, 96.390, 1639.0, 40.4846
18.873308787, 96.390, 1616.0, 40.1995
18.925829918, 96.390, 1546.0, 39.3192
18.978351049, 96.390, 1703.0, 41.2674
19.030872179, 96.390, 1625.0, 40.3113
19.083393310, 96.390, 1685.0, 41.0488
19.135914441, 96.390, 1587.0, 39.8372
19.188435572, 96.390, 1692.0, 41.1339
19.240956702, 96.390, 1678.0, 40.9634
19.293477833, 96.390, 1701.0, 41.2432
19.345998964, 96.390, 1633.0, 40.4104
19.398520094, 96.390, 1659.0, 40.7308
19.451041225, 96.390, 1808.0, 42.5206
19.503562356, 96.390, 1782.0, 42.2137
19.556083486, 96.390, 1721.0, 41.4849
19.608604617, 96.390, 1827.0, 42.7434
19.661125748, 96.390, 1911.0, 43.7150
19.713646879, 96.390, 2043.0, 45.1996
19.766168009, 96.390, 2030.0, 45.0555
19.818689140, 96.390, 2173.0, 46.6154
19.871210271, 96.390, 2200.0, 46.9042
19.923731401, 96.390, 2317.0, 48.1352
19.976252532, 96.390, 2237.0, 47.2969
20.028773663, 96.390, 2169.0, 46.5725
20.081294794, 96.390, 1982.0, 44.5197
20.133815924, 96.390, 1851.0, 43.0232
20.186337055, 96.390, 1745.0, 41.7732
20.238858186, 96.390, 1687.0, 41.0731
20.291379316, 96.390, 1718.0, 41.4488
20.343900447, 96.390, 1699.0, 41.2189
20.396421578, 96.390, 1631.0, 40.3856
20.448942709, 96.390, 1683.0, 41.0244
20.501463839, 96.390, 1595.0, 39.9375
20.553984970, 96.390, 1560.0, 39.4968
20.606506101, 96.390, 1532.0, 39.1408
20.659027231, 96.390, 1614.0, 40.1746
20.711548362, 96.390, 1623.0, 40.2865
20.764069493, 96.390, 1726.0, 41.5452
20.816590623, 96.390, 1638.0, 40.4722
20.869111754, 96.390, 1649.0, 40.6079
20.921632885, 96.390, 1678.0, 40.9634
20.974154016, 96.390, 1624.0, 40.2989
21.026675146, 96.390, 1652.0, 40.6448
21.079196277, 96.390, 1641.0, 40.5093
21.131717408, 96.390, 1603.0, 40.0375
21.184238538, 96.390, 1676.0, 40.9390
21.236759669, 96.390, 1602.0, 40.0250
21.289280800, 96.390, 1675.0, 40.9268
21.341801931, 96.390, 1603.0, 40.0375
21.394323061, 96.390, 1729.0, 41.5812
21.446844192, 96.390, 1867.0, 43.2088
21.499365323, 96.390, 1712.0, 41.3763
21.551886453, 96.390, 1785.0, 42.2493
21.604407584, 96.390, 1660.0, 40.7431
21.656928715, 96.390, 1646.0, 40.5709
21.709449846, 96.390, 1658.0, 40.7185
21.761970976, 96.390, 1608.0, 40.0999
21.814492107, 96.390, 1635.0, 40.4351
21.867013238, 96.390, 1688.0, 41.0853
21.919534368, 96.390, 1686.0, 41.0609
21.972055499, 96.390, 1765.0, 42.0119
22.024576630, 96.390, 1751.0, 41.8450
22.077097761, 96.390, 1853.0, 43.0465
22.129618891, 96.390, 1958.0, 44.2493
22.182140022, 96.390, 1811.0, 42.5558
22.234661153, 96.390, 1808.0, 42.5206
22.287182283, 96.390, 1896.0, 43.5431
22.339703414, 96.390, 1833.0, 42.8135
22.392224545, 96.390, 1836.0, 42.8486
22.444745675, 96.390, 1982.0, 44.5197
22.497266806, 96.390, 1977.0, 44.4635
22.549787937, 96.390, 2056.0, 45.3431
22.602309068, 96.390, 2051.0, 45.2880
22.654830198, 96.390, 2060.0, 45.3872
22.707351329, 96.390, 2265.0, 47.5920
22.759872460, 96.390, 2197.0, 46.8722
22.812393590, 96.390, 2386.0, 48.8467
22.864914721, 96.390, 2439.0, 49.3862
22.917435852, 96.390, 2537.0, 50.3686
22.969956983, 96.390, 2755.0, 52.4881
23.022478113, 96.390, 3053.0, 55.2540
23.074999244, 96.390, 3211.0, 56.6657
23.127520375, 96.390, 3371.0, 58.0603
23.180041505, 96.390, 3328.0, 57.6888
23.232562636, 96.390, 3188.0, 56.4624
23.285083767, 96.390, 3021.0, 54.9636
23.337604898, 96.390, 2971.0, 54.5069
23.390126028, 96.390, 2899.0, 53.8424
23.442647159, 96.390, 2656.0, 51.5364
23.495168290, 96.390, 2704.0, 52.0000
23.547689420, 96.390, 2566.0, 50.6557
23.600210551, 96.390, 2453.0, 49.5278
23.652731682, 96.390, 2347.0, 48.4458
23.705252813, 96.390, 2262.0, 47.5605
23.757773943, 96.390, 2262.0, 47.5605
23.810295074, 96.390, 2180.0, 46.6905
23.862816205, 96.390, 2208.0, 46.9894
23.915337335, 96.390, 2315.0, 48.1144
23.967858466, 96.390, 2352.0, 48.4974
24.020379597, 96.390, 2354.0, 48.5180
24.072900727, 96.390, 2553.0, 50.5272
24.125421858, 96.390, 2994.0, 54.7175
24.177942989, 96.390, 3804.0, 61.6766
24.230464120, 96.390, 5157.0, 71.8123
24.282985250, 96.390, 6223.0, 78.8860
24.335506381, 96.390, 5295.0, 72.7668
24.388027512, 96.390, 3906.0, 62.4980
24.440548642, 96.390, 2982.0, 54.6077
24.493069773, 96.390, 2500.0, 50.0000
24.545590904, 96.390, 2193.0, 46.8295
24.598112035, 96.390, 2087.0, 45.6837
24.650633165, 96.390, 1980.0, 44.4972
24.703154296, 96.390, 1958.0, 44.2493
24.755675427, 96.390, 1850.0, 43.0116
24.808196557, 96.390, 1822.0, 42.6849
24.860717688, 96.390, 1697.0, 41.1947
24.913238819, 96.390, 1690.0, 41.1096
24.965759950, 96.390, 1719.0, 41.4608
25.018281080, 96.390, 1555.0, 39.4335
25.070802211, 96.390, 1663.0, 40.7799
25.123323342, 96.390, 1662.0, 40.7676
25.175844472, 96.390, 1609.0, 40.1123
25.228365603, 96.390, 1618.0, 40.2244
25.280886734, 96.390, 1634.0, 40.4228
25.333407864, 96.390, 1572.0, 39.6485
25.385928995, 96.390, 1507.0, 38.8201
25.438450126, 96.390, 1549.0, 39.3573
25.490971257, 96.390, 1477.0, 38.4318
25.543492387, 96.390, 1449.0, 38.0657
25.596013518, 96.390, 1536.0, 39.1918
25.648534649, 96.390, 1495.0, 38.6652
25.701055779, 96.390, 1454.0, 38.1314
25.753576910, 96.390, 1577.0, 39.7115
25.806098041, 96.390, 1521.0, 39.0000
25.858619172, 96.390, 1537.0, 39.2046
25.911140302, 96.390, 1550.0, 39.3700
25.963661433, 96.390, 1647.0, 40.5832
26.016182564, 96.390, 1643.0, 40.5339
26.068703694, 96.390, 1685.0, 41.0488
26.121224825, 96.390, 1800.0, 42.4264
26.173745956, 96.390, 1816.0, 42.6146
26.226267087, 96.390, 1840.0, 42.8952
26.278788217, 96.390, 1882.0, 43.3820
26.331309348, 96.390, 1978.0, 44.4747
26.383830479, 96.390, 2066.0, 45.4533
26.436351609, 96.390, 2393.0, 48.9183
26.488872740, 96.390, 2590.0, 50.8920
26.541393871, 96.390, 2553.0, 50.5272
26.593915002, 96.390, 2473.0, 49.7293
26.646436132, 96.390, 2245.0, 47.3814
26.698957263, 96.390, 2017.0, 44.9110
26.751478394, 96.390, 1982.0, 44.5197
26.803999524, 96.390, 1809.0, 42.5323
26.856520655, 96.390, 1659.0, 40.7308
26.909041786, 96.390, 1630.0, 40.3733
26.961562916, 96.390, 1673.0, 40.9023
27.014084047, 96.390, 1612.0, 40.1497
27.066605178, 96.390, 1516.0, 38.9358
27.119126309, 96.390, 1549.0, 39.3573
27.171647439, 96.390, 1604.0, 40.0500
27.224168570, 96.390, 1575.0, 39.6863
27.276689701, 96.390, 1573.0, 39.6611
27.329210831, 96.390, 1383.0, 37.1887
27.381731962, 96.390, 1531.0, 39.1280
27.434253093, 96.390, 1579.0, 39.7366
27.486774224, 96.390, 1521.0, 39.0000
27.539295354, 96.390, 1535.0, 39.1791
27.591816485, 96.390, 1601.0, 40.0125
27.644337616, 96.390, 1525.0, 39.0512
27.696858746, 96.390, 1506.0, 38.8072
27.749379877, 96.390, 1477.0, 38.4318
27.801901008, 96.390, 1571.0, 39.6358
27.854422139, 96.390, 1563.0, 39.5348
27.906943269, 96.390, 1564.0, 39.5474
27.959464400, 96.390, 1598.0, 39.9750
28.011985531, 96.390, 1669.0, 40.8534
28.064506661, 96.390, 1713.0, 41.3884
28.117027792, 96.390, 1884.0, 43.4051
28.169548923, 96.390, 1922.0, 43.8406
28.222070054, 96.390, 1760.0, 41.9524
28.274591184, 96.390, 1705.0, 41.2916
28.327112315, 96.390, 1645.0, 40.5586
28.379633446, 96.390, 1649.0, 40.6079
28.432154576, 96.390, 1556.0, 39.4462
28.484675707, 96.390, 1587.0, 39.8372
28.537196838, 96.390, 1663.0, 40.7799
28.589717968, 96.390, 1681.0, 41.0000
28.642239099, 96.390, 1632.0, 40.3980
28.694760230, 96.390, 1605.0, 40.0625
28.747281361, 96.390, 1696.0, 41.1825
28.799802491, 96.390, 1618.0, 40.2244
28.852323622, 96.390, 1776.0, 42.1426
28.904844753, 96.390, 1812.0, 42.5676
28.957365883, 96.390, 1835.0, 42.8369
29.009887014, 96.390, 1890.0, 43.4741
29.062408145, 96.390, 1865.0, 43.1856
29.114929276, 96.390, 2004.0, 44.7661
29.167450406, 96.390, 1791.0, 42.3202
29.219971537, 96.390, 1844.0, 42.9418
29.272492668, 96.390, 1843.0, 42.9302
29.325013798, 96.390, 1805.0, 42.4853
29.377534929, 96.390, 1835.0, 42.8369
29.430056060, 96.390, 1668.0, 40.8412
29.482577191, 96.390, 1733.0, 41.6293
29.535098321, 96.390, 1597.0, 39.9625
29.587619452, 96.390, 1695.0, 41.1704
29.640140583, 96.390, 1720.0, 41.4729
29.692661713, 96.390, 1700.0, 41.2311
29.745182844, 96.390, 1663.0, 40.7799
29.797703975, 96.390, 1773.0, 42.1070
29.850225105, 96.390, 1711.0, 41.3642
29.902746236, 96.390, 1643.0, 40.5339
29.955267367, 96.390, 1686.0, 41.0609
30.007788498, 96.390, 1791.0, 42.3202
30.060309628, 96.390, 1725.0, 41.5331
30.112830759, 96.390, 1859.0, 43.1161
30.165351890, 96.390, 1815.0, 42.6028
30.217873020, 96.390, 1840.0, 42.8952
30.270394151, 96.390, 1871.0, 43.2551
30.322915282, 96.390, 1821.0, 42.6732
30.375436413, 96.390, 1987.0, 44.5758
30.427957543, 96.390, 2039.0, 45.1553
30.480478674, 96.390, 2056.0, 45.3431
30.532999805, 96.390, 2240.0, 47.3286
30.585520935, 96.390, 2380.0, 48.7852
30.638042066, 96.390, 2346.0, 48.4355
30.690563197, 96.390, 2460.0, 49.5984
30.743084328, 96.390, 2636.0, 51.3420
30.795605458, 96.390, 2452.0, 49.5177
30.848126589, 96.390, 2490.0, 49.8999
30.900647720, 96.390, 2437.0, 49.3660
30.953168850, 96.390, 2352.0, 48.4974
31.005689981, 96.390, 2213.0, 47.0425
31.058211112, 96.390, 2189.0, 46.7868
31.110732243, 96.390, 2181.0, 46.7012
31.163253373, 96.390, 2185.0, 46.7440
31.215774504, 96.390, 2113.0, 45.9674
31.268295635, 96.390, 2115.0, 45.9891
31.320816765, 96.390, 2223.0, 47.1487
31.373337896, 96.390, 2360.0, 48.5798
31.425859027, 96.390, 2727.0, 52.2207
31.478380157, 96.390, 3161.0, 56.2228
31.530901288, 96.390, 3334.0, 57.7408
31.583422419, 96.390, 3068.0, 55.3895
31.635943550, 96.390, 2772.0, 52.6498
31.688464680, 96.390, 2366.0, 48.6415
31.740985811, 96.390, 2272.0, 47.6655
31.793506942, 96.390, 2122.0, 46.0652
31.846028072, 96.390, 1988.0, 44.5870
31.898549203, 96.390, 2011.0, 44.8442
31.951070334, 96.390, 1910.0, 43.7035
32.003591465, 96.390, 1878.0, 43.3359
32.056112595, 96.390, 1888.0, 43.4511
32.108633726, 96.390, 2008.0, 44.8107
32.161154857, 96.390, 2355.0, 48.5283
32.213675987, 96.390, 2898.0, 53.8331
32.266197118, 96.390, 2827.0, 53.1695
32.318718249, 96.390, 2558.0, 50.5767
32.371239380, 96.390, 2439.0, 49.3862
32.423760510, 96.390, 2422.0, 49.2138
32.476281641, 96.390, 2293.0, 47.8853
32.528802772, 96.390, 1926.0, 43.8862
32.581323902, 96.390, 1753.0, 41.8688
32.633845033, 96.390, 1787.0, 42.2729
32.686366164, 96.390, 1633.0, 40.4104
32.738887295, 96.390, 1678.0, 40.9634
32.791408425, 96.390, 1600.0, 40.0000
32.843929556, 96.390, 1618.0, 40.2244
32.896450687, 96.390, 1526.0, 39.0640
32.948971817, 96.390, 1683.0, 41.0244
33.001492948, 96.390, 1617.0, 40.2119
33.054014079, 96.390, 1641.0, 40.5093
33.106535209, 96.390, 1722.0, 41.4970
33.159056340, 96.390, 1862.0, 43.1509
33.211577471, 96.390, 1932.0, 43.9545
33.264098602, 96.390, 2183.0, 46.7226
33.316619732, 96.390, 2289.0, 47.8435
33.369140863, 96.390, 2290.0, 47.8539
33.421661994, 96.390, 2246.0, 47.3920
33.474183124, 96.390, 2475.0, 49.7494
33.526704255, 96.390, 2639.0, 51.3712
33.579225386, 96.390, 2276.0, 47.7074
33.631746517, 96.390, 2132.0, 46.1736
33.684267647, 96.390, 1998.0, 44.6990
33.736788778, 96.390, 1807.0, 42.5088
33.789309909, 96.390, 1796.0, 42.3792
33.841831039, 96.390, 1883.0, 43.3935
33.894352170, 96.390, 1875.0, 43.3013
33.946873301, 96.390, 1918.0, 43.7950
33.999394432, 96.390, 1964.0, 44.3170
34.051915562, 96.390, 2066.0, 45.4533
34.104436693, 96.390, 2025.0, 45.0000
34.156957824, 96.390, 2065.0, 45.4423
34.209478954, 96.390, 2095.0, 45.7712
34.262000085, 96.390, 2048.0, 45.2548
34.314521216, 96.390, 2172.0, 46.6047
34.367042346, 96.390, 2221.0, 47.1275
34.419563477, 96.390, 2386.0, 48.8467
34.472084608, 96.390, 2649.0, 51.4684
34.524605739, 96.390, 2913.0, 53.9722
34.577126869, 96.390, 3729.0, 61.0655
34.629648000, 96.390, 4037.0, 63.5374
34.682169131, 96.390, 3861.0, 62.1369
34.734690261, 96.390, 3180.0, 56.3915
34.787211392, 96.390, 2677.0, 51.7397
34.839732523, 96.390, 2441.0, 49.4065
34.892253654, 96.390, 2326.0, 48.2286
34.944774784, 96.390, 2149.0, 46.3573
34.997295915, 96.390, 2112.0, 45.9565
35.049817046, 96.390, 2065.0, 45.4423
35.102338176, 96.390, 2077.0, 45.5741
35.154859307, 96.390, 2004.0, 44.7661
35.207380438, 96.390, 1960.0, 44.2719
35.259901569, 96.390, 1963.0, 44.3058
35.312422699, 96.390, 1847.0, 42.9767
35.364943830, 96.390, 1914.0, 43.7493
35.417464961, 96.390, 1749.0, 41.8210
35.469986091, 96.390, 1845.0, 42.9535
35.522507222, 96.390, 1752.0, 41.8569
35.575028353, 96.390, 1707.0, 41.3159
35.627549484, 96.390, 1788.0, 42.2847
35.680070614, 96.390, 1776.0, 42.1426
35.732591745, 96.390, 1679.0, 40.9756
35.785112876, 96.390, 1652.0, 40.6448
35.837634006, 96.390, 1692.0, 41.1339
35.890155137, 96.390, 1710.0, 41.3521
35.942676268, 96.390, 1624.0, 40.2989
35.995197398, 96.390, 1753.0, 41.8688
36.047718529, 96.390, 1745.0, 41.7732
36.100239660, 96.390, 1791.0, 42.3202
36.152760791, 96.390, 1915.0, 43.7607
36.205281921, 96.390, 1964.0, 44.3170
36.257803052, 96.390, 1920.0, 43.8178
36.310324183, 96.390, 1796.0, 42.3792
36.362845313, 96.390, 1688.0, 41.0853
36.415366444, 96.390, 1728.0, 41.5692
36.467887575, 96.390, 1737.0, 41.6773
36.520408706, 96.390, 1692.0, 41.1339
36.572929836, 96.390, 1762.0, 41.9762
36.625450967, 96.390, 1811.0, 42.5558
36.677972098, 96.390, 1689.0, 41.0974
36.730493228, 96.390, 1658.0, 40.7185
36.783014359, 96.390, 1555.0, 39.4335
36.835535490, 96.390, 1631.0, 40.3856
36.888056621, 96.390, 1564.0, 39.5474
36.940577751, 96.390, 1576.0, 39.6989
36.993098882, 96.390, 1632.0, 40.3980
37.045620013, 96.390, 1587.0, 39.8372
37.098141143, 96.390, 1534.0, 39.1663
37.150662274, 96.390, 1630.0, 40.3733
37.203183405, 96.390, 1618.0, 40.2244
37.255704535, 96.390, 1604.0, 40.0500
37.308225666, 96.390, 1565.0, 39.5601
37.360746797, 96.390, 1625.0, 40.3113
37.413267928, 96.390, 1657.0, 40.7063
37.465789058, 96.390, 1787.0, 42.2729
37.518310189, 96.390, 1950.0, 44.1588
37.570831320, 96.390, 1755.0, 41.8927
37.623352450, 96.390, 1768.0, 42.0476
37.675873581, 96.390, 1726.0, 41.5452
37.728394712, 96.390, 1734.0, 41.6413
37.780915843, 96.390, 2121.0, 46.0543
37.833436973, 96.390, 2360.0, 48.5798
37.885958104, 96.390, 2053.0, 45.3100
37.938479235, 96.390, 1896.0, 43.5431
37.991000365, 96.390, 1625.0, 40.3113
38.043521496, 96.390, 1484.0, 38.5227
38.096042627, 96.390, 1530.0, 39.1152
38.148563758, 96.390, 1418.0, 37.6563
38.201084888, 96.390, 1353.0, 36.7831
38.253606019, 96.390, 1362.0, 36.9053
38.306127150, 96.390, 1303.0, 36.0971
38.358648280, 96.390, 1344.0, 36.6606
38.411169411, 96.390, 1294.0, 35.9722
38.463690542, 96.390, 1354.0, 36.7967
38.516211673, 96.390, 1288.0, 35.8887
38.568732803, 96.390, 1338.0, 36.5787
38.621253934, 96.390, 1299.0, 36.0416
38.673775065, 96.390, 1405.0, 37.4833
38.726296195, 96.390, 1228.0, 35.0428
38.778817326, 96.390, 1295.0, 35.9861
38.831338457, 96.390, 1278.0, 35.7491
38.883859587, 96.390, 1278.0, 35.7491
38.936380718, 96.390, 1251.0, 35.3695
38.988901849, 96.390, 1242.0, 35.2420
39.041422980, 96.390, 1263.0, 35.5387
39.093944110, 96.390, 1227.0, 35.0286
39.146465241, 96.390, 1244.0, 35.2704
39.198986372, 96.390, 1174.0, 34.2637
39.251507502, 96.390, 1210.0, 34.7851
39.304028633, 96.390, 1212.0, 34.8138
39.356549764, 96.390, 1231.0, 35.0856
39.409070895, 96.390, 1210.0, 34.7851
39.461592025, 96.390, 1195.0, 34.5688
39.514113156, 96.390, 1188.0, 34.4674
39.566634287, 96.390, 1248.0, 35.3270
39.619155417, 96.390, 1241.0, 35.2278
39.671676548, 96.390, 1210.0, 34.7851
39.724197679, 96.390, 1267.0, 35.5949
39.776718810, 96.390, 1313.0, 36.2353
39.829239940, 96.390, 1182.0, 34.3802
39.881761071, 96.390, 1213.0, 34.8281
39.934282202, 96.390, 1212.0, 34.8138
39.986803332, 96.390, 1192.0, 34.5254
40.039324463, 96.390, 1201.0, 34.6554
40.091845594, 96.390, 1336.0, 36.5513
40.144366725, 96.390, 1386.0, 37.2290
40.196887855, 96.390, 1443.0, 37.9868
40.249408986, 96.390, 1324.0, 36.3868
40.301930117, 96.390, 1306.0, 36.1386
40.354451247, 96.390, 1251.0, 35.3695
40.406972378, 96.390, 1273.0, 35.6791
40.459493509, 96.390, 1286.0, 35.8608
40.512014639, 96.390, 1276.0, 35.7211
40.564535770, 96.390, 1356.0, 36.8239
40.617056901, 96.390, 1367.0, 36.9730
40.669578032, 96.390, 1438.0, 37.9210
40.722099162, 96.390, 1350.0, 36.7423
40.774620293, 96.390, 1299.0, 36.0416
40.827141424, 96.390, 1247.0, 35.3129
40.879662554, 96.390, 1216.0, 34.8712
40.932183685, 96.390, 1189.0, 34.4819
40.984704816, 96.390, 1201.0, 34.6554
41.037225947, 96.390, 1142.0, 33.7935
41.089747077, 96.390, 1208.0, 34.7563
41.142268208, 96.390, 1181.0, 34.3657
41.194789339, 96.390, 1332.0, 36.4966
41.247310469, 96.390, 1343.0, 36.6470
41.299831600, 96.390, 1369.0, 37.0000
41.352352731, 96.390, 1268.0, 35.6090
41.404873862, 96.390, 1254.0, 35.4119
41.457394992, 96.390, 1214.0, 34.8425
41.509916123, 96.390, 1129.0, 33.6006
41.562437254, 96.390, 1189.0, 34.4819
41.614958384, 96.390, 1094.0, 33.0757
41.667479515, 96.390, 1075.0, 32.7872
41.720000646, 96.390, 1122.0, 33.4963
41.772521776, 96.390, 1146.0, 33.8526
41.825042907, 96.390, 1139.0, 33.7491
41.877564038, 96.390, 1135.0, 33.6898
41.930085169, 96.390, 1085.0, 32.9393
41.982606299, 96.390, 1165.0, 34.1321
42.035127430, 96.390, 1094.0, 33.0757
42.087648561, 96.390, 1088.0, 32.9848
42.140169691, 96.390, 1148.0, 33.8821
42.192690822, 96.390, 1120.0, 33.4664
42.245211953, 96.390, 1162.0, 34.0881
42.297733084, 96.390, 1108.0, 33.2866
42.350254214, 96.390, 1166.0, 34.1467
42.402775345, 96.390, 1263.0, 35.5387
42.455296476, 96.390, 1173.0, 34.2491
42.507817606, 96.390, 1204.0, 34.6987
42.560338737, 96.390, 1314.0, 36.2491
42.612859868, 96.390, 1424.0, 37.7359
42.665380999, 96.390, 1677.0, 40.9512
42.717902129, 96.390, 2120.0, 46.0435
42.770423260, 96.390, 2275.0, 47.6970
42.822944391, 96.390, 2089.0, 45.7056
42.875465521, 96.390, 1978.0, 44.4747
42.927986652, 96.390, 1566.0, 39.5727
42.980507783, 96.390, 1342.0, 36.6333
43.033028914, 96.390, 1347.0, 36.7015
43.085550044, 96.390, 1209.0, 34.7707
43.138071175, 96.390, 1113.0, 33.3617
43.190592306, 96.390, 1075.0, 32.7872
43.243113436, 96.390, 1093.0, 33.0606
43.295634567, 96.390, 1059.0, 32.5423
43.348155698, 96.390, 1080.0, 32.8634
43.400676828, 96.390, 1094.0, 33.0757
43.453197959, 96.390, 1043.0, 32.2955
43.505719090, 96.390, 1008.0, 31.7490
43.558240221, 96.390, 1001.0, 31.6386
43.610761351, 96.390, 1011.0, 31.7962
43.663282482, 96.390, 1038.0, 32.2180
43.715803613, 96.390, 1131.0, 33.6303
43.768324743, 96.390, 1136.0, 33.7046
43.820845874, 96.390, 1038.0, 32.2180
43.873367005, 96.390, 1062.0, 32.5883
43.925888136, 96.390, 957.0, 30.9354
43.978409266, 96.390, 934.0, 30.5614
44.030930397, 96.390, 966.0, 31.0805
44.083451528, 96.390, 889.0, 29.8161
44.135972658, 96.390, 985.0, 31.3847
44.188493789, 96.390, 981.0, 31.3209
44.241014920, 96.390, 972.0, 31.1769
44.293536051, 96.390, 970.0, 31.1448
44.346057181, 96.390, 979.0, 31.2890
44.398578312, 96.390, 943.0, 30.7083
44.451099443, 96.390, 959.0, 30.9677
44.503620573, 96.390, 930.0, 30.4959
44.556141704, 96.390, 911.0, 30.1828
44.608662835, 96.390, 919.0, 30.3150
44.661183966, 96.390, 962.0, 31.0161
44.713705096, 96.390, 1034.0, 32.1559
44.766226227, 96.390, 964.0, 31.0483
44.818747358, 96.390, 995.0, 31.5436
44.871268488, 96.390, 1041.0, 32.2645
44.923789619, 96.390, 1178.0, 34.3220
44.976310750, 96.390, 1276.0, 35.7211
45.028831880, 96.390, 1228.0, 35.0428
45.081353011, 96.390, 1232.0, 35.0999
45.133874142, 96.390, 1222.0, 34.9571
45.186395273, 96.390, 1196.0, 34.5832
45.238916403, 96.390, 1169.0, 34.1906
45.291437534, 96.390, 1084.0, 32.9242
45.343958665, 96.390, 1051.0, 32.4191
45.396479795, 96.390, 1009.0, 31.7648
45.449000926, 96.390, 1003.0, 31.6702
45.501522057, 96.390, 985.0, 31.3847
45.554043188, 96.390, 1053.0, 32.4500
45.606564318, 96.390, 989.0, 31.4484
45.659085449, 96.390, 1014.0, 31.8434
45.711606580, 96.390, 939.0, 30.6431
45.764127710, 96.390, 963.0, 31.0322
45.816648841, 96.390, 966.0, 31.0805
45.869169972, 96.390, 938.0, 30.6268
45.921691103, 96.390, 1002.0, 31.6544
45.974212233, 96.390, 936.0, 30.5941
46.026733364, 96.390, 986.0, 31.4006
46.079254495, 96.390, 996.0, 31.5595
46.131775625, 96.390, 1041.0, 32.2645
46.184296756, 96.390, 1035.0, 32.1714
46.236817887, 96.390, 1014.0, 31.8434
46.289339017, 96.390, 994.0, 31.5278
46.341860148, 96.390, 1003.0, 31.6702
46.394381279, 96.390, 992.0, 31.4960
46.446902410, 96.390, 957.0, 30.9354
46.499423540, 96.390, 963.0, 31.0322
46.551944671, 96.390, 981.0, 31.3209
46.604465802, 96.390, 938.0, 30.6268
46.656986932, 96.390, 927.0, 30.4467
46.709508063, 96.390, 991.0, 31.4802
46.762029194, 96.390, 959.0, 30.9677
46.814550325, 96.390, 964.0, 31.0483
46.867071455, 96.390, 931.0, 30.5123
46.919592586, 96.390, 915.0, 30.2490
46.972113717, 96.390, 969.0, 31.1288
47.024634847, 96.390, 918.0, 30.2985
47.077155978, 96.390, 973.0, 31.1929
47.129677109, 96.390, 968.0, 31.1127
47.182198240, 96.390, 945.0, 30.7409
47.234719370, 96.390, 952.0, 30.8545
47.287240501, 96.390, 977.0, 31.2570
47.339761632, 96.390, 956.0, 30.9192
47.392282762, 96.390, 892.0, 29.8664
47.444803893, 96.390, 832.0, 28.8444
47.497325024, 96.390, 890.0, 29.8329
47.549846155, 96.390, 959.0, 30.9677
47.602367285, 96.390, 915.0, 30.2490
47.654888416, 96.390, 904.0, 30.0666
47.707409547, 96.390, 861.0, 29.3428
47.759930677, 96.390, 891.0, 29.8496
47.812451808, 96.390, 903.0, 30.0500
47.864972939, 96.390, 816.0, 28.5657
47.917494069, 96.390, 817.0, 28.5832
47.970015200, 96.390, 841.0, 29.0000
48.022536331, 96.390, 821.0, 28.6531
48.075057462, 96.390, 826.0, 28.7402
48.127578592, 96.390, 768.0, 27.7128
48.180099723, 96.390, 813.0, 28.5132
48.232620854, 96.390, 816.0, 28.5657
48.285141984, 96.390, 804.0, 28.3549
48.337663115, 96.390, 761.0, 27.5862
48.390184246, 96.390, 839.0, 28.9655
48.442705377, 96.390, 815.0, 28.5482
48.495226507, 96.390, 821.0, 28.6531
48.547747638, 96.390, 837.0, 28.9310
48.600268769, 96.390, 828.0, 28.7750
48.652789899, 96.390, 747.0, 27.3313
48.705311030, 96.390, 838.0, 28.9482
48.757832161, 96.390, 798.0, 28.2489
48.810353292, 96.390, 759.0, 27.5500
48.862874422, 96.390, 720.0, 26.8328
48.915395553, 96.390, 767.0, 27.6948
48.967916684, 96.390, 758.0, 27.5318
49.020437814, 96.390, 765.0, 27.6586
49.072958945, 96.390, 772.0, 27.7849
49.125480076, 96.390, 741.0, 27.2213
49.178001207, 96.390, 707.0, 26.5895
49.230522337, 96.390, 736.0, 27.1293
49.283043468, 96.390, 762.0, 27.6043
49.335564599, 96.390, 708.0, 26.6083
49.388085729, 96.390, 685.0, 26.1725
49.440606860, 96.390, 801.0, 28.3019
49.493127991, 96.390, 781.0, 27.9464
49.545649121, 96.390, 721.0, 26.8514
49.598170252, 96.390, 744.0, 27.2764
49.650691383, 96.390, 758.0, 27.5318
49.703212514, 96.390, 794.0, 28.1780
49.755733644, 96.390, 868.0, 29.4618
49.808254775, 96.390, 897.0, 29.9500
49.860775906, 96.390, 933.0, 30.5450
49.913297036, 96.390, 867.0, 29.4449
49.965818167, 96.390, 838.0, 28.9482
50.018339298, 96.390, 831.0, 28.8271
50.070860429, 96.390, 832.0, 28.8444
50.123381559, 96.390, 754.0, 27.4591
50.175902690, 96.390, 769.0, 27.7308
50.228423821, 96.390, 798.0, 28.2489
50.280944951, 96.390, 746.0, 27.3130
50.333466082, 96.390, 779.0, 27.9106
50.385987213, 96.390, 749.0, 27.3679
50.438508344, 96.390, 775.0, 27.8388
50.491029474, 96.390, 751.0, 27.4044
50.543550605, 96.390, 768.0, 27.7128
50.596071736, 96.390, 806.0, 28.3901
50.648592866, 96.390, 771.0, 27.7669
50.701113997, 96.390, 727.0, 26.9629
50.753635128, 96.390, 779.0, 27.9106
50.806156258, 96.390, 814.0, 28.5307
50.858677389, 96.390, 833.0, 28.8617
50.911198520, 96.390, 783.0, 27.9821
50.963719651, 96.390, 813.0, 28.5132
51.016240781, 96.390, 894.0, 29.8998
51.068761912, 96.390, 826.0, 28.7402
51.121283043, 96.390, 799.0, 28.2666
51.173804173, 96.390, 781.0, 27.9464
51.226325304, 96.390, 822.0, 28.6705
51.278846435, 96.390, 794.0, 28.1780
51.331367566, 96.390, 856.0, 29.2575
51.383888696, 96.390, 854.0, 29.2233
51.436409827, 96.390, 856.0, 29.2575
51.488930958, 96.390, 826.0, 28.7402
51.541452088, 96.390, 896.0, 29.9333
51.593973219, 96.390, 785.0, 28.0179
51.646494350, 96.390, 820.0, 28.6356
51.699015481, 96.390, 771.0, 27.7669
51.751536611, 96.390, 894.0, 29.8998
51.804057742, 96.390, 910.0, 30.1662
51.856578873, 96.390, 837.0, 28.9310
51.909100003, 96.390, 1007.0, 31.7333
51.961621134, 96.390, 1179.0, 34.3366
52.014142265, 96.390, 1174.0, 34.2637
52.066663396, 96.390, 1074.0, 32.7719
52.119184526, 96.390, 1020.0, 31.9374
52.171705657, 96.390, 922.0, 30.3645
52.224226788, 96.390, 884.0, 29.7321
52.276747918, 96.390, 864.0, 29.3939
52.329269049, 96.390, 816.0, 28.5657
52.381790180, 96.390, 826.0, 28.7402
52.434311310, 96.390, 876.0, 29.5973
52.486832441, 96.390, 814.0, 28.5307
52.539353572, 96.390, 804.0, 28.3549
52.591874703, 96.390, 857.0, 29.2746
52.644395833, 96.390, 784.0, 28.0000
52.696916964, 96.390, 839.0, 28.9655
52.749438095, 96.390, 852.0, 29.1890
52.801959225, 96.390, 849.0, 29.1376
52.854480356, 96.390, 858.0, 29.2916
52.907001487, 96.390, 852.0, 29.1890
52.959522618, 96.390, 922.0, 30.3645
53.012043748, 96.390, 871.0, 29.5127
53.064564879, 96.390, 832.0, 28.8444
53.117086010, 96.390, 800.0, 28.2843
53.169607140, 96.390, 757.0, 27.5136
53.222128271, 96.390, 756.0, 27.4955
53.274649402, 96.390, 776.0, 27.8568
53.327170533, 96.390, 769.0, 27.7308
53.379691663, 96.390, 733.0, 27.0740
53.432212794, 96.390, 690.0, 26.2679
53.484733925, 96.390, 704.0, 26.5330
53.537255055, 96.390, 684.0, 26.1534
53.589776186, 96.390, 674.0, 25.9615
53.642297317, 96.390, 682.0, 26.1151
53.694818448, 96.390, 633.0, 25.1595
53.747339578, 96.390, 666.0, 25.8070
53.799860709, 96.390, 649.0, 25.4755
53.852381840, 96.390, 680.0, 26.0768
53.904902970, 96.390, 628.0, 25.0599
53.957424101, 96.390, 665.0, 25.7876
54.009945232, 96.390, 659.0, 25.6710
54.062466362, 96.390, 692.0, 26.3059
54.114987493, 96.390, 637.0, 25.2389
54.167508624, 96.390, 671.0, 25.9037
54.220029755, 96.390, 718.0, 26.7955
54.272550885, 96.390, 704.0, 26.5330
54.325072016, 96.390, 678.0, 26.0384
54.377593147, 96.390, 679.0, 26.0576
54.430114277, 96.390, 704.0, 26.5330
54.482635408, 96.390, 709.0, 26.6271
54.535156539, 96.390, 684.0, 26.1534
54.587677670, 96.390, 678.0, 26.0384
54.640198800, 96.390, 679.0, 26.0576
54.692719931, 96.390, 656.0, 25.6125
54.745241062, 96.390, 733.0, 27.0740
54.797762192, 96.390, 684.0, 26.1534
54.850283323, 96.390, 637.0, 25.2389
54.902804454, 96.390, 686.0, 26.1916
54.955325585, 96.390, 692.0, 26.3059
55.007846715, 96.390, 689.0, 26.2488
55.060367846, 96.390, 748.0, 27.3496
55.112888977, 96.390, 706.0, 26.5707
55.165410107, 96.390, 720.0, 26.8328
55.217931238, 96.390, 673.0, 25.9422
55.270452369, 96.390, 663.0, 25.7488
55.322973499, 96.390, 688.0, 26.2298
55.375494630, 96.390, 606.0, 24.6171
55.428015761, 96.390, 666.0, 25.8070
55.480536892, 96.390, 630.0, 25.0998
55.533058022, 96.390, 655.0, 25.5930
55.585579153, 96.390, 637.0, 25.2389
55.638100284, 96.390, 701.0, 26.4764
55.690621414, 96.390, 774.0, 27.8209
55.743142545, 96.390, 683.0, 26.1343
55.795663676, 96.390, 692.0, 26.3059
55.848184807, 96.390, 672.0, 25.9230
55.900705937, 96.390, 629.0, 25.0799
55.953227068, 96.390, 645.0, 25.3969
56.005748199, 96.390, 654.0, 25.5734
56.058269329, 96.390, 636.0, 25.2190
56.110790460, 96.390, 660.0, 25.6905
56.163311591, 96.390, 727.0, 26.9629
56.215832722, 96.390, 681.0, 26.0960
56.268353852, 96.390, 691.0, 26.2869
56.320874983, 96.390, 657.0, 25.6320
56.373396114, 96.390, 683.0, 26.1343
56.425917244, 96.390, 643.0, 25.3574
56.478438375, 96.390, 650.0, 25.4951
56.530959506, 96.390, 735.0, 27.1109
56.583480637, 96.390, 668.0, 25.8457
56.636001767, 96.390, 686.0, 26.1916
56.688522898, 96.390, 764.0, 27.6405
56.741044029, 96.390, 762.0, 27.6043
56.793565159, 96.390, 793.0, 28.1603
56.846086290, 96.390, 780.0, 27.9285
56.898607421, 96.390, 795.0, 28.1957
56.951128551, 96.390, 805.0, 28.3725
57.003649682, 96.390, 832.0, 28.8444
57.056170813, 96.390, 818.0, 28.6007
57.108691944, 96.390, 924.0, 30.3974
57.161213074, 96.390, 989.0, 31.4484
57.213734205, 96.390, 834.0, 28.8791
57.266255336, 96.390, 923.0, 30.3809
57.318776466, 96.390, 845.0, 29.0689
57.371297597, 96.390, 771.0, 27.7669
57.423818728, 96.390, 759.0, 27.5500
57.476339859, 96.390, 729.0, 27.0000
57.528860989, 96.390, 692.0, 26.3059
57.581382120, 96.390, 741.0, 27.2213
57.633903251, 96.390, 718.0, 26.7955
57.686424381, 96.390, 672.0, 25.9230
57.738945512, 96.390, 702.0, 26.4953
57.791466643, 96.390, 686.0, 26.1916
57.843987774, 96.390, 736.0, 27.1293
57.896508904, 96.390, 637.0, 25.2389
57.949030035, 96.390, 761.0, 27.5862
58.001551166, 96.390, 734.0, 27.0924
58.054072296, 96.390, 790.0, 28.1069
58.106593427, 96.390, 939.0, 30.6431
58.159114558, 96.390, 1082.0, 32.8938
58.211635689, 96.390, 1115.0, 33.3916
58.264156819, 96.390, 1011.0, 31.7962
58.316677950, 96.390, 1022.0, 31.9687
58.369199081, 96.390, 914.0, 30.2324
58.421720211, 96.390, 804.0, 28.3549
58.474241342, 96.390, 745.0, 27.2947
58.526762473, 96.390, 734.0, 27.0924
58.579283603, 96.390, 778.0, 27.8927
58.631804734, 96.390, 723.0, 26.8887
58.684325865, 96.390, 746.0, 27.3130
58.736846996, 96.390, 735.0, 27.1109
58.789368126, 96.390, 705.0, 26.5518
58.841889257, 96.390, 680.0, 26.0768
58.894410388, 96.390, 776.0, 27.8568
58.946931518, 96.390, 731.0, 27.0370
58.999452649, 96.390, 729.0, 27.0000
59.051973780, 96.390, 737.0, 27.1477
59.104494911, 96.390, 766.0, 27.6767
59.157016041, 96.390, 778.0, 27.8927
59.209537172, 96.390, 734.0, 27.0924
59.262058303, 96.390, 779.0, 27.9106
59.314579433, 96.390, 773.0, 27.8029
59.367100564, 96.390, 848.0, 29.1204
59.419621695, 96.390, 816.0, 28.5657
59.472142826, 96.390, 870.0, 29.4958
59.524663956, 96.390, 864.0, 29.3939
59.577185087, 96.390, 892.0, 29.8664
59.629706218, 96.390, 1010.0, 31.7805
59.682227348, 96.390, 975.0, 31.2250
59.734748479, 96.390, 1035.0, 32.1714
59.787269610, 96.390, 1082.0, 32.8938
59.839790740, 96.390, 1020.0, 31.9374
59.892311871, 96.390, 1119.0, 33.4515
59.944833002, 96.390, 1132.0, 33.6452
59.997354133, 96.390, 1157.0, 34.0147
60.049875263, 96.390, 1180.0, 34.3511
60.102396394, 96.390, 1328.0, 36.4417
60.154917525, 96.390, 1407.0, 37.5100
60.207438655, 96.390, 1403.0, 37.4566
60.259959786, 96.390, 1404.0, 37.4700
60.312480917, 96.390, 1352.0, 36.7696
60.365002048, 96.390, 1330.0, 36.4692
60.417523178, 96.390, 1363.0, 36.9188
60.470044309, 96.390, 1263.0, 35.5387
60.522565440, 96.390, 1192.0, 34.5254
60.575086570, 96.390, 1203.0, 34.6843
60.627607701, 96.390, 1177.0, 34.3074
60.680128832, 96.390, 1219.0, 34.9142
60.732649963, 96.390, 1138.0, 33.7343
60.785171093, 96.390, 1032.0, 32.1248
60.837692224, 96.390, 1077.0, 32.8177
60.890213355, 96.390, 1016.0, 31.8748
60.942734485, 96.390, 946.0, 30.7571
60.995255616, 96.390, 906.0, 30.0998
61.047776747, 96.390, 912.0, 30.1993
61.100297878, 96.390, 917.0, 30.2820
61.152819008, 96.390, 915.0, 30.2490
61.205340139, 96.390, 833.0, 28.8617
61.257861270, 96.390, 897.0, 29.9500
61.310382400, 96.390, 823.0, 28.6880
61.362903531, 96.390, 792.0, 28.1425
61.415424662, 96.390, 827.0, 28.7576
61.467945792, 96.390, 816.0, 28.5657
61.520466923, 96.390, 805.0, 28.3725
61.572988054, 96.390, 827.0, 28.7576
61.625509185, 96.390, 808.0, 28.4253
61.678030315, 96.390, 829.0, 28.7924
61.730551446, 96.390, 820.0, 28.6356
61.783072577, 96.390, 836.0, 28.9137
61.835593707, 96.390, 826.0, 28.7402
61.888114838, 96.390, 845.0, 29.0689
61.940635969, 96.390, 876.0, 29.5973
61.993157100, 96.390, 887.0, 29.7825
62.045678230, 96.390, 962.0, 31.0161
62.098199361, 96.390, 986.0, 31.4006
62.150720492, 96.390, 927.0, 30.4467
62.203241622, 96.390, 896.0, 29.9333
62.255762753, 96.390, 879.0, 29.6479
62.308283884, 96.390, 779.0, 27.9106
62.360805015, 96.390, 681.0, 26.0960
62.413326145, 96.390, 680.0, 26.0768
62.465847276, 96.390, 706.0, 26.5707
62.518368407, 96.390, 703.0, 26.5141
62.570889537, 96.390, 702.0, 26.4953
62.623410668, 96.390, 677.0, 26.0192
62.675931799, 96.390, 710.0, 26.6458
62.728452930, 96.390, 741.0, 27.2213
62.780974060, 96.390, 723.0, 26.8887
62.833495191, 96.390, 767.0, 27.6948
62.886016322, 96.390, 681.0, 26.0960
62.938537452, 96.390, 682.0, 26.1151
62.991058583, 96.390, 691.0, 26.2869
63.043579714, 96.390, 626.0, 25.0200
63.096100844, 96.390, 660.0, 25.6905
63.148621975, 96.390, 611.0, 24.7184
63.201143106, 96.390, 649.0, 25.4755
63.253664237, 96.390, 641.0, 25.3180
63.306185367, 96.390, 589.0, 24.2693
63.358706498, 96.390, 602.0, 24.5357
63.411227629, 96.390, 563.0, 23.7276
63.463748759, 96.390, 578.0, 24.0416
63.516269890, 96.390, 593.0, 24.3516
63.568791021, 96.390, 643.0, 25.3574
63.621312152, 96.390, 557.0, 23.6008
63.673833282, 96.390, 639.0, 25.2784
63.726354413, 96.390, 639.0, 25.2784
63.778875544, 96.390, 672.0, 25.9230
63.831396674, 96.390, 637.0, 25.2389
63.883917805, 96.390, 636.0, 25.2190
63.936438936, 96.390, 751.0, 27.4044
63.988960067, 96.390, 771.0, 27.7669
64.041481197, 96.390, 726.0, 26.9444
64.094002328, 96.390, 688.0, 26.2298
64.146523459, 96.390, 646.0, 25.4165
64.199044589, 96.390, 697.0, 26.4008
64.251565720, 96.390, 602.0, 24.5357
64.304086851, 96.390, 583.0, 24.1454
64.356607981, 96.390, 550.0, 23.4521
64.409129112, 96.390, 555.0, 23.5584
64.461650243, 96.390, 541.0, 23.2594
64.514171374, 96.390, 524.0, 22.8910
64.566692504, 96.390, 562.0, 23.7065
64.619213635, 96.390, 505.0, 22.4722
64.671734766, 96.390, 543.0, 23.3024
64.724255896, 96.390, 512.0, 22.6274
64.776777027, 96.390, 502.0, 22.4054
64.829298158, 96.390, 511.0, 22.6053
64.881819289, 96.390, 498.0, 22.3159
64.934340419, 96.390, 520.0, 22.8035
64.986861550, 96.390, 550.0, 23.4521