File: Files_organized_for_plots/134_days/A_XRD_142_AlAxial23Mar22_Act16Nov22_B1_1000M_NaOH_LS0133.csv
[Measurement conditions]
Sample identification,142_AlAxial23Mar22_Act16Nov22_B1_1000M_NaOH_LS0133
Comment - 1,"Configuration=Stage for Flat Samples/Holders, Owner=User-1, Creation date=7/1/2020 9:53:24 AM"
Comment - 2,"Goniometer=Theta/Theta; Minimum step size 2Theta:0.0001; Minimum step size Omega:0.0001"
Comment - 3,"Sample stage=Stage for flat samples/holders"
Comment - 4,"Diffractometer system=EMPYREAN"
Comment - 5,"Measurement program=C:\Users\tmr79\OneDrive - The Pennsylvania State University\Documents\NEUP\XRD\Cement\Zerobackground scan.xrdmp, Identifier={98A3B11C-88F9-4AA6-982C-73314A311EF5}"
Anode material,Cu
K-Alpha1 wavelength,1.5405980
K-Alpha2 wavelength,1.5444260
Ratio K-Alpha2/K-Alpha1,0.500
Divergence slit,Fixed,0.25
Monochromator used,NO
Generator voltage, 45
Tube current, 40
File date and time,03/Apr/2023 11:18
Unit cell,
h k l, 0 0 0
Scan axis,Gonio
Scan range,4.994599997,64.999991833
Scan step size,0.0262606
No. of points, 2285
Scan type,CONTINUOUS
Time per step,96.390
[Scan points]
Angle, TimePerStep, Intensity, ESD
5.007730280, 96.390, 3825.0, 61.8466
5.060251411, 96.390, 3830.0, 61.8870
5.112772541, 96.390, 3803.0, 61.6685
5.165293672, 96.390, 3761.0, 61.3270
5.217814803, 96.390, 3687.0, 60.7207
5.270335934, 96.390, 3702.0, 60.8441
5.322857064, 96.390, 3637.0, 60.3075
5.375378195, 96.390, 3770.0, 61.4003
5.427899326, 96.390, 3738.0, 61.1392
5.480420456, 96.390, 3702.0, 60.8441
5.532941587, 96.390, 3578.0, 59.8164
5.585462718, 96.390, 3608.0, 60.0666
5.637983849, 96.390, 3672.0, 60.5970
5.690504979, 96.390, 3700.0, 60.8276
5.743026110, 96.390, 3598.0, 59.9833
5.795547241, 96.390, 3695.0, 60.7865
5.848068371, 96.390, 3675.0, 60.6218
5.900589502, 96.390, 3669.0, 60.5723
5.953110633, 96.390, 3559.0, 59.6574
6.005631763, 96.390, 3677.0, 60.6383
6.058152894, 96.390, 3667.0, 60.5558
6.110674025, 96.390, 3611.0, 60.0916
6.163195156, 96.390, 3533.0, 59.4390
6.215716286, 96.390, 3651.0, 60.4235
6.268237417, 96.390, 3571.0, 59.7578
6.320758548, 96.390, 3572.0, 59.7662
6.373279678, 96.390, 3543.0, 59.5231
6.425800809, 96.390, 3459.0, 58.8133
6.478321940, 96.390, 3541.0, 59.5063
6.530843071, 96.390, 3621.0, 60.1747
6.583364201, 96.390, 3425.0, 58.5235
6.635885332, 96.390, 3470.0, 58.9067
6.688406463, 96.390, 3506.0, 59.2115
6.740927593, 96.390, 3519.0, 59.3212
6.793448724, 96.390, 3549.0, 59.5735
6.845969855, 96.390, 3497.0, 59.1354
6.898490986, 96.390, 3514.0, 59.2790
6.951012116, 96.390, 3428.0, 58.5491
7.003533247, 96.390, 3452.0, 58.7537
7.056054378, 96.390, 3401.0, 58.3181
7.108575508, 96.390, 3419.0, 58.4722
7.161096639, 96.390, 3557.0, 59.6406
7.213617770, 96.390, 3479.0, 58.9830
7.266138900, 96.390, 3386.0, 58.1893
7.318660031, 96.390, 3447.0, 58.7112
7.371181162, 96.390, 3383.0, 58.1636
7.423702293, 96.390, 3355.0, 57.9224
7.476223423, 96.390, 3355.0, 57.9224
7.528744554, 96.390, 3414.0, 58.4294
7.581265685, 96.390, 3431.0, 58.5747
7.633786815, 96.390, 3228.0, 56.8155
7.686307946, 96.390, 3330.0, 57.7062
7.738829077, 96.390, 3231.0, 56.8419
7.791350208, 96.390, 3238.0, 56.9034
7.843871338, 96.390, 3273.0, 57.2101
7.896392469, 96.390, 3219.0, 56.7362
7.948913600, 96.390, 3247.0, 56.9825
8.001434730, 96.390, 3329.0, 57.6975
8.053955861, 96.390, 3125.0, 55.9017
8.106476992, 96.390, 3214.0, 56.6922
8.158998123, 96.390, 3167.0, 56.2761
8.211519253, 96.390, 3250.0, 57.0088
8.264040384, 96.390, 3166.0, 56.2672
8.316561515, 96.390, 3184.0, 56.4269
8.369082645, 96.390, 3270.0, 57.1839
8.421603776, 96.390, 3189.0, 56.4712
8.474124907, 96.390, 3147.0, 56.0981
8.526646038, 96.390, 3071.0, 55.4166
8.579167168, 96.390, 3209.0, 56.6480
8.631688299, 96.390, 3170.0, 56.3028
8.684209430, 96.390, 3099.0, 55.6687
8.736730560, 96.390, 3115.0, 55.8122
8.789251691, 96.390, 3192.0, 56.4978
8.841772822, 96.390, 3006.0, 54.8270
8.894293952, 96.390, 3071.0, 55.4166
8.946815083, 96.390, 3018.0, 54.9363
8.999336214, 96.390, 3034.0, 55.0818
9.051857345, 96.390, 2994.0, 54.7175
9.104378475, 96.390, 2935.0, 54.1756
9.156899606, 96.390, 3065.0, 55.3624
9.209420737, 96.390, 3105.0, 55.7225
9.261941867, 96.390, 2989.0, 54.6717
9.314462998, 96.390, 2904.0, 53.8888
9.366984129, 96.390, 2974.0, 54.5344
9.419505260, 96.390, 2784.0, 52.7636
9.472026390, 96.390, 2869.0, 53.5630
9.524547521, 96.390, 3064.0, 55.3534
9.577068652, 96.390, 3021.0, 54.9636
9.629589782, 96.390, 2928.0, 54.1110
9.682110913, 96.390, 2977.0, 54.5619
9.734632044, 96.390, 2814.0, 53.0471
9.787153175, 96.390, 2853.0, 53.4135
9.839674305, 96.390, 2856.0, 53.4416
9.892195436, 96.390, 2903.0, 53.8795
9.944716567, 96.390, 2928.0, 54.1110
9.997237697, 96.390, 2873.0, 53.6004
10.049758828, 96.390, 2906.0, 53.9073
10.102279959, 96.390, 2776.0, 52.6878
10.154801090, 96.390, 2779.0, 52.7162
10.207322220, 96.390, 2793.0, 52.8488
10.259843351, 96.390, 2814.0, 53.0471
10.312364482, 96.390, 2732.0, 52.2685
10.364885612, 96.390, 2768.0, 52.6118
10.417406743, 96.390, 2792.0, 52.8394
10.469927874, 96.390, 2808.0, 52.9906
10.522449004, 96.390, 2794.0, 52.8583
10.574970135, 96.390, 2715.0, 52.1057
10.627491266, 96.390, 2649.0, 51.4684
10.680012397, 96.390, 2686.0, 51.8266
10.732533527, 96.390, 2647.0, 51.4490
10.785054658, 96.390, 2769.0, 52.6213
10.837575789, 96.390, 2659.0, 51.5655
10.890096919, 96.390, 2714.0, 52.0961
10.942618050, 96.390, 2657.0, 51.5461
10.995139181, 96.390, 2670.0, 51.6720
11.047660312, 96.390, 2580.0, 50.7937
11.100181442, 96.390, 2619.0, 51.1762
11.152702573, 96.390, 2621.0, 51.1957
11.205223704, 96.390, 2629.0, 51.2738
11.257744834, 96.390, 2608.0, 51.0686
11.310265965, 96.390, 2610.0, 51.0882
11.362787096, 96.390, 2606.0, 51.0490
11.415308227, 96.390, 2643.0, 51.4101
11.467829357, 96.390, 2539.0, 50.3885
11.520350488, 96.390, 2674.0, 51.7107
11.572871619, 96.390, 2466.0, 49.6588
11.625392749, 96.390, 2563.0, 50.6261
11.677913880, 96.390, 2561.0, 50.6063
11.730435011, 96.390, 2467.0, 49.6689
11.782956141, 96.390, 2588.0, 50.8724
11.835477272, 96.390, 2638.0, 51.3615
11.887998403, 96.390, 2500.0, 50.0000
11.940519534, 96.390, 2528.0, 50.2792
11.993040664, 96.390, 2550.0, 50.4975
12.045561795, 96.390, 2526.0, 50.2593
12.098082926, 96.390, 2520.0, 50.1996
12.150604056, 96.390, 2522.0, 50.2195
12.203125187, 96.390, 2431.0, 49.3052
12.255646318, 96.390, 2519.0, 50.1896
12.308167449, 96.390, 2472.0, 49.7192
12.360688579, 96.390, 2422.0, 49.2138
12.413209710, 96.390, 2388.0, 48.8672
12.465730841, 96.390, 2434.0, 49.3356
12.518251971, 96.390, 2371.0, 48.6929
12.570773102, 96.390, 2458.0, 49.5782
12.623294233, 96.390, 2442.0, 49.4166
12.675815364, 96.390, 2481.0, 49.8096
12.728336494, 96.390, 2429.0, 49.2849
12.780857625, 96.390, 2384.0, 48.8262
12.833378756, 96.390, 2373.0, 48.7134
12.885899886, 96.390, 2384.0, 48.8262
12.938421017, 96.390, 2366.0, 48.6415
12.990942148, 96.390, 2373.0, 48.7134
13.043463279, 96.390, 2382.0, 48.8057
13.095984409, 96.390, 2337.0, 48.3425
13.148505540, 96.390, 2457.0, 49.5681
13.201026671, 96.390, 2397.0, 48.9592
13.253547801, 96.390, 2268.0, 47.6235
13.306068932, 96.390, 2331.0, 48.2804
13.358590063, 96.390, 2376.0, 48.7442
13.411111193, 96.390, 2197.0, 46.8722
13.463632324, 96.390, 2329.0, 48.2597
13.516153455, 96.390, 2258.0, 47.5184
13.568674586, 96.390, 2314.0, 48.1041
13.621195716, 96.390, 2307.0, 48.0312
13.673716847, 96.390, 2290.0, 47.8539
13.726237978, 96.390, 2298.0, 47.9375
13.778759108, 96.390, 2243.0, 47.3603
13.831280239, 96.390, 2334.0, 48.3115
13.883801370, 96.390, 2263.0, 47.5710
13.936322501, 96.390, 2269.0, 47.6340
13.988843631, 96.390, 2297.0, 47.9270
14.041364762, 96.390, 2266.0, 47.6025
14.093885893, 96.390, 2267.0, 47.6130
14.146407023, 96.390, 2252.0, 47.4552
14.198928154, 96.390, 2303.0, 47.9896
14.251449285, 96.390, 2219.0, 47.1063
14.303970416, 96.390, 2188.0, 46.7761
14.356491546, 96.390, 2283.0, 47.7807
14.409012677, 96.390, 2206.0, 46.9681
14.461533808, 96.390, 2188.0, 46.7761
14.514054938, 96.390, 2193.0, 46.8295
14.566576069, 96.390, 2141.0, 46.2709
14.619097200, 96.390, 2245.0, 47.3814
14.671618331, 96.390, 2129.0, 46.1411
14.724139461, 96.390, 2123.0, 46.0760
14.776660592, 96.390, 2207.0, 46.9787
14.829181723, 96.390, 2218.0, 47.0956
14.881702853, 96.390, 2216.0, 47.0744
14.934223984, 96.390, 2230.0, 47.2229
14.986745115, 96.390, 2137.0, 46.2277
15.039266245, 96.390, 2172.0, 46.6047
15.091787376, 96.390, 2188.0, 46.7761
15.144308507, 96.390, 2186.0, 46.7547
15.196829638, 96.390, 2148.0, 46.3465
15.249350768, 96.390, 2220.0, 47.1169
15.301871899, 96.390, 2217.0, 47.0850
15.354393030, 96.390, 2144.0, 46.3033
15.406914160, 96.390, 2168.0, 46.5618
15.459435291, 96.390, 2153.0, 46.4004
15.511956422, 96.390, 2144.0, 46.3033
15.564477553, 96.390, 2175.0, 46.6369
15.616998683, 96.390, 2078.0, 45.5851
15.669519814, 96.390, 2193.0, 46.8295
15.722040945, 96.390, 2063.0, 45.4203
15.774562075, 96.390, 2099.0, 45.8148
15.827083206, 96.390, 2135.0, 46.2061
15.879604337, 96.390, 2142.0, 46.2817
15.932125468, 96.390, 2074.0, 45.5412
15.984646598, 96.390, 2203.0, 46.9361
16.037167729, 96.390, 2109.0, 45.9239
16.089688860, 96.390, 2057.0, 45.3542
16.142209990, 96.390, 2185.0, 46.7440
16.194731121, 96.390, 2173.0, 46.6154
16.247252252, 96.390, 2062.0, 45.4093
16.299773382, 96.390, 2094.0, 45.7602
16.352294513, 96.390, 2086.0, 45.6727
16.404815644, 96.390, 2142.0, 46.2817
16.457336775, 96.390, 2175.0, 46.6369
16.509857905, 96.390, 2132.0, 46.1736
16.562379036, 96.390, 2201.0, 46.9148
16.614900167, 96.390, 2154.0, 46.4112
16.667421297, 96.390, 2120.0, 46.0435
16.719942428, 96.390, 2113.0, 45.9674
16.772463559, 96.390, 2178.0, 46.6690
16.824984690, 96.390, 2133.0, 46.1844
16.877505820, 96.390, 2125.0, 46.0977
16.930026951, 96.390, 2292.0, 47.8748
16.982548082, 96.390, 2179.0, 46.6798
17.035069212, 96.390, 2190.0, 46.7974
17.087590343, 96.390, 2153.0, 46.4004
17.140111474, 96.390, 2184.0, 46.7333
17.192632605, 96.390, 2343.0, 48.4045
17.245153735, 96.390, 2210.0, 47.0106
17.297674866, 96.390, 2229.0, 47.2123
17.350195997, 96.390, 2147.0, 46.3357
17.402717127, 96.390, 2187.0, 46.7654
17.455238258, 96.390, 2223.0, 47.1487
17.507759389, 96.390, 2307.0, 48.0312
17.560280520, 96.390, 2150.0, 46.3681
17.612801650, 96.390, 2194.0, 46.8402
17.665322781, 96.390, 2173.0, 46.6154
17.717843912, 96.390, 2118.0, 46.0217
17.770365042, 96.390, 2106.0, 45.8912
17.822886173, 96.390, 2185.0, 46.7440
17.875407304, 96.390, 2220.0, 47.1169
17.927928434, 96.390, 2250.0, 47.4342
17.980449565, 96.390, 2221.0, 47.1275
18.032970696, 96.390, 2199.0, 46.8935
18.085491827, 96.390, 2243.0, 47.3603
18.138012957, 96.390, 2280.0, 47.7493
18.190534088, 96.390, 2236.0, 47.2864
18.243055219, 96.390, 2137.0, 46.2277
18.295576349, 96.390, 2252.0, 47.4552
18.348097480, 96.390, 2159.0, 46.4650
18.400618611, 96.390, 2214.0, 47.0532
18.453139742, 96.390, 2317.0, 48.1352
18.505660872, 96.390, 2255.0, 47.4868
18.558182003, 96.390, 2273.0, 47.6760
18.610703134, 96.390, 2272.0, 47.6655
18.663224264, 96.390, 2282.0, 47.7703
18.715745395, 96.390, 2179.0, 46.6798
18.768266526, 96.390, 2288.0, 47.8330
18.820787657, 96.390, 2282.0, 47.7703
18.873308787, 96.390, 2276.0, 47.7074
18.925829918, 96.390, 2267.0, 47.6130
18.978351049, 96.390, 2343.0, 48.4045
19.030872179, 96.390, 2279.0, 47.7389
19.083393310, 96.390, 2333.0, 48.3011
19.135914441, 96.390, 2208.0, 46.9894
19.188435572, 96.390, 2244.0, 47.3709
19.240956702, 96.390, 2255.0, 47.4868
19.293477833, 96.390, 2331.0, 48.2804
19.345998964, 96.390, 2316.0, 48.1248
19.398520094, 96.390, 2408.0, 49.0714
19.451041225, 96.390, 2242.0, 47.3498
19.503562356, 96.390, 2341.0, 48.3839
19.556083486, 96.390, 2403.0, 49.0204
19.608604617, 96.390, 2355.0, 48.5283
19.661125748, 96.390, 2318.0, 48.1456
19.713646879, 96.390, 2354.0, 48.5180
19.766168009, 96.390, 2322.0, 48.1871
19.818689140, 96.390, 2402.0, 49.0102
19.871210271, 96.390, 2448.0, 49.4773
19.923731401, 96.390, 2449.0, 49.4874
19.976252532, 96.390, 2323.0, 48.1975
20.028773663, 96.390, 2547.0, 50.4678
20.081294794, 96.390, 2460.0, 49.5984
20.133815924, 96.390, 2439.0, 49.3862
20.186337055, 96.390, 2465.0, 49.6488
20.238858186, 96.390, 2470.0, 49.6991
20.291379316, 96.390, 2450.0, 49.4975
20.343900447, 96.390, 2468.0, 49.6790
20.396421578, 96.390, 2457.0, 49.5681
20.448942709, 96.390, 2442.0, 49.4166
20.501463839, 96.390, 2470.0, 49.6991
20.553984970, 96.390, 2510.0, 50.0999
20.606506101, 96.390, 2562.0, 50.6162
20.659027231, 96.390, 2504.0, 50.0400
20.711548362, 96.390, 2457.0, 49.5681
20.764069493, 96.390, 2597.0, 50.9608
20.816590623, 96.390, 2435.0, 49.3457
20.869111754, 96.390, 2463.0, 49.6286
20.921632885, 96.390, 2531.0, 50.3090
20.974154016, 96.390, 2520.0, 50.1996
21.026675146, 96.390, 2469.0, 49.6890
21.079196277, 96.390, 2567.0, 50.6656
21.131717408, 96.390, 2564.0, 50.6360
21.184238538, 96.390, 2503.0, 50.0300
21.236759669, 96.390, 2571.0, 50.7050
21.289280800, 96.390, 2555.0, 50.5470
21.341801931, 96.390, 2610.0, 51.0882
21.394323061, 96.390, 2515.0, 50.1498
21.446844192, 96.390, 2649.0, 51.4684
21.499365323, 96.390, 2467.0, 49.6689
21.551886453, 96.390, 2599.0, 50.9804
21.604407584, 96.390, 2617.0, 51.1566
21.656928715, 96.390, 2614.0, 51.1273
21.709449846, 96.390, 2564.0, 50.6360
21.761970976, 96.390, 2524.0, 50.2394
21.814492107, 96.390, 2497.0, 49.9700
21.867013238, 96.390, 2611.0, 51.0979
21.919534368, 96.390, 2534.0, 50.3389
21.972055499, 96.390, 2634.0, 51.3225
22.024576630, 96.390, 2734.0, 52.2877
22.077097761, 96.390, 2440.0, 49.3964
22.129618891, 96.390, 2630.0, 51.2835
22.182140022, 96.390, 2590.0, 50.8920
22.234661153, 96.390, 2654.0, 51.5170
22.287182283, 96.390, 2615.0, 51.1371
22.339703414, 96.390, 2542.0, 50.4183
22.392224545, 96.390, 2512.0, 50.1199
22.444745675, 96.390, 2634.0, 51.3225
22.497266806, 96.390, 2646.0, 51.4393
22.549787937, 96.390, 2504.0, 50.0400
22.602309068, 96.390, 2536.0, 50.3587
22.654830198, 96.390, 2535.0, 50.3488
22.707351329, 96.390, 2522.0, 50.2195
22.759872460, 96.390, 2563.0, 50.6261
22.812393590, 96.390, 2642.0, 51.4004
22.864914721, 96.390, 2493.0, 49.9300
22.917435852, 96.390, 2543.0, 50.4282
22.969956983, 96.390, 2478.0, 49.7795
23.022478113, 96.390, 2540.0, 50.3984
23.074999244, 96.390, 2497.0, 49.9700
23.127520375, 96.390, 2627.0, 51.2543
23.180041505, 96.390, 2490.0, 49.8999
23.232562636, 96.390, 2551.0, 50.5074
23.285083767, 96.390, 2521.0, 50.2096
23.337604898, 96.390, 2511.0, 50.1099
23.390126028, 96.390, 2441.0, 49.4065
23.442647159, 96.390, 2528.0, 50.2792
23.495168290, 96.390, 2496.0, 49.9600
23.547689420, 96.390, 2484.0, 49.8397
23.600210551, 96.390, 2544.0, 50.4381
23.652731682, 96.390, 2429.0, 49.2849
23.705252813, 96.390, 2497.0, 49.9700
23.757773943, 96.390, 2570.0, 50.6952
23.810295074, 96.390, 2453.0, 49.5278
23.862816205, 96.390, 2454.0, 49.5379
23.915337335, 96.390, 2410.0, 49.0918
23.967858466, 96.390, 2407.0, 49.0612
24.020379597, 96.390, 2425.0, 49.2443
24.072900727, 96.390, 2425.0, 49.2443
24.125421858, 96.390, 2420.0, 49.1935
24.177942989, 96.390, 2342.0, 48.3942
24.230464120, 96.390, 2466.0, 49.6588
24.282985250, 96.390, 2440.0, 49.3964
24.335506381, 96.390, 2421.0, 49.2037
24.388027512, 96.390, 2359.0, 48.5695
24.440548642, 96.390, 2415.0, 49.1426
24.493069773, 96.390, 2399.0, 48.9796
24.545590904, 96.390, 2407.0, 49.0612
24.598112035, 96.390, 2314.0, 48.1041
24.650633165, 96.390, 2276.0, 47.7074
24.703154296, 96.390, 2391.0, 48.8979
24.755675427, 96.390, 2330.0, 48.2701
24.808196557, 96.390, 2280.0, 47.7493
24.860717688, 96.390, 2302.0, 47.9792
24.913238819, 96.390, 2357.0, 48.5489
24.965759950, 96.390, 2329.0, 48.2597
25.018281080, 96.390, 2291.0, 47.8644
25.070802211, 96.390, 2410.0, 49.0918
25.123323342, 96.390, 2349.0, 48.4665
25.175844472, 96.390, 2242.0, 47.3498
25.228365603, 96.390, 2269.0, 47.6340
25.280886734, 96.390, 2199.0, 46.8935
25.333407864, 96.390, 2343.0, 48.4045
25.385928995, 96.390, 2309.0, 48.0521
25.438450126, 96.390, 2240.0, 47.3286
25.490971257, 96.390, 2298.0, 47.9375
25.543492387, 96.390, 2187.0, 46.7654
25.596013518, 96.390, 2218.0, 47.0956
25.648534649, 96.390, 2212.0, 47.0319
25.701055779, 96.390, 2205.0, 46.9574
25.753576910, 96.390, 2213.0, 47.0425
25.806098041, 96.390, 2203.0, 46.9361
25.858619172, 96.390, 2283.0, 47.7807
25.911140302, 96.390, 2215.0, 47.0638
25.963661433, 96.390, 2165.0, 46.5296
26.016182564, 96.390, 2203.0, 46.9361
26.068703694, 96.390, 2103.0, 45.8585
26.121224825, 96.390, 2182.0, 46.7119
26.173745956, 96.390, 2168.0, 46.5618
26.226267087, 96.390, 2118.0, 46.0217
26.278788217, 96.390, 2202.0, 46.9255
26.331309348, 96.390, 2170.0, 46.5833
26.383830479, 96.390, 2152.0, 46.3897
26.436351609, 96.390, 2129.0, 46.1411
26.488872740, 96.390, 2083.0, 45.6399
26.541393871, 96.390, 2100.0, 45.8258
26.593915002, 96.390, 2095.0, 45.7712
26.646436132, 96.390, 2086.0, 45.6727
26.698957263, 96.390, 2056.0, 45.3431
26.751478394, 96.390, 2128.0, 46.1303
26.803999524, 96.390, 2058.0, 45.3652
26.856520655, 96.390, 2083.0, 45.6399
26.909041786, 96.390, 2105.0, 45.8803
26.961562916, 96.390, 2130.0, 46.1519
27.014084047, 96.390, 2085.0, 45.6618
27.066605178, 96.390, 1992.0, 44.6318
27.119126309, 96.390, 2022.0, 44.9667
27.171647439, 96.390, 2049.0, 45.2659
27.224168570, 96.390, 2053.0, 45.3100
27.276689701, 96.390, 2056.0, 45.3431
27.329210831, 96.390, 2125.0, 46.0977
27.381731962, 96.390, 1999.0, 44.7102
27.434253093, 96.390, 2030.0, 45.0555
27.486774224, 96.390, 2067.0, 45.4643
27.539295354, 96.390, 2033.0, 45.0888
27.591816485, 96.390, 1960.0, 44.2719
27.644337616, 96.390, 1951.0, 44.1701
27.696858746, 96.390, 1930.0, 43.9318
27.749379877, 96.390, 2089.0, 45.7056
27.801901008, 96.390, 1994.0, 44.6542
27.854422139, 96.390, 1998.0, 44.6990
27.906943269, 96.390, 1938.0, 44.0227
27.959464400, 96.390, 1951.0, 44.1701
28.011985531, 96.390, 1933.0, 43.9659
28.064506661, 96.390, 1950.0, 44.1588
28.117027792, 96.390, 2012.0, 44.8553
28.169548923, 96.390, 1946.0, 44.1135
28.222070054, 96.390, 1909.0, 43.6921
28.274591184, 96.390, 1930.0, 43.9318
28.327112315, 96.390, 1981.0, 44.5084
28.379633446, 96.390, 2062.0, 45.4093
28.432154576, 96.390, 1970.0, 44.3847
28.484675707, 96.390, 1904.0, 43.6348
28.537196838, 96.390, 1938.0, 44.0227
28.589717968, 96.390, 1920.0, 43.8178
28.642239099, 96.390, 1927.0, 43.8976
28.694760230, 96.390, 1815.0, 42.6028
28.747281361, 96.390, 1925.0, 43.8748
28.799802491, 96.390, 1946.0, 44.1135
28.852323622, 96.390, 1852.0, 43.0349
28.904844753, 96.390, 1941.0, 44.0568
28.957365883, 96.390, 1782.0, 42.2137
29.009887014, 96.390, 1849.0, 43.0000
29.062408145, 96.390, 1909.0, 43.6921
29.114929276, 96.390, 1886.0, 43.4281
29.167450406, 96.390, 1820.0, 42.6615
29.219971537, 96.390, 1830.0, 42.7785
29.272492668, 96.390, 1818.0, 42.6380
29.325013798, 96.390, 1923.0, 43.8520
29.377534929, 96.390, 1873.0, 43.2782
29.430056060, 96.390, 1833.0, 42.8135
29.482577191, 96.390, 1823.0, 42.6966
29.535098321, 96.390, 1865.0, 43.1856
29.587619452, 96.390, 1879.0, 43.3474
29.640140583, 96.390, 1840.0, 42.8952
29.692661713, 96.390, 1821.0, 42.6732
29.745182844, 96.390, 1783.0, 42.2256
29.797703975, 96.390, 1825.0, 42.7200
29.850225105, 96.390, 1831.0, 42.7902
29.902746236, 96.390, 1837.0, 42.8602
29.955267367, 96.390, 1853.0, 43.0465
30.007788498, 96.390, 1805.0, 42.4853
30.060309628, 96.390, 1870.0, 43.2435
30.112830759, 96.390, 1682.0, 41.0122
30.165351890, 96.390, 1815.0, 42.6028
30.217873020, 96.390, 1834.0, 42.8252
30.270394151, 96.390, 1784.0, 42.2374
30.322915282, 96.390, 1819.0, 42.6497
30.375436413, 96.390, 1764.0, 42.0000
30.427957543, 96.390, 1745.0, 41.7732
30.480478674, 96.390, 1699.0, 41.2189
30.532999805, 96.390, 1736.0, 41.6653
30.585520935, 96.390, 1798.0, 42.4028
30.638042066, 96.390, 1773.0, 42.1070
30.690563197, 96.390, 1761.0, 41.9643
30.743084328, 96.390, 1812.0, 42.5676
30.795605458, 96.390, 1771.0, 42.0833
30.848126589, 96.390, 1722.0, 41.4970
30.900647720, 96.390, 1684.0, 41.0366
30.953168850, 96.390, 1690.0, 41.1096
31.005689981, 96.390, 1719.0, 41.4608
31.058211112, 96.390, 1682.0, 41.0122
31.110732243, 96.390, 1682.0, 41.0122
31.163253373, 96.390, 1701.0, 41.2432
31.215774504, 96.390, 1721.0, 41.4849
31.268295635, 96.390, 1722.0, 41.4970
31.320816765, 96.390, 1722.0, 41.4970
31.373337896, 96.390, 1728.0, 41.5692
31.425859027, 96.390, 1674.0, 40.9145
31.478380157, 96.390, 1660.0, 40.7431
31.530901288, 96.390, 1707.0, 41.3159
31.583422419, 96.390, 1640.0, 40.4969
31.635943550, 96.390, 1646.0, 40.5709
31.688464680, 96.390, 1740.0, 41.7133
31.740985811, 96.390, 1706.0, 41.3038
31.793506942, 96.390, 1633.0, 40.4104
31.846028072, 96.390, 1642.0, 40.5216
31.898549203, 96.390, 1705.0, 41.2916
31.951070334, 96.390, 1653.0, 40.6571
32.003591465, 96.390, 1625.0, 40.3113
32.056112595, 96.390, 1739.0, 41.7013
32.108633726, 96.390, 1623.0, 40.2865
32.161154857, 96.390, 1707.0, 41.3159
32.213675987, 96.390, 1666.0, 40.8167
32.266197118, 96.390, 1646.0, 40.5709
32.318718249, 96.390, 1590.0, 39.8748
32.371239380, 96.390, 1641.0, 40.5093
32.423760510, 96.390, 1645.0, 40.5586
32.476281641, 96.390, 1676.0, 40.9390
32.528802772, 96.390, 1608.0, 40.0999
32.581323902, 96.390, 1617.0, 40.2119
32.633845033, 96.390, 1563.0, 39.5348
32.686366164, 96.390, 1593.0, 39.9124
32.738887295, 96.390, 1535.0, 39.1791
32.791408425, 96.390, 1553.0, 39.4081
32.843929556, 96.390, 1593.0, 39.9124
32.896450687, 96.390, 1561.0, 39.5095
32.948971817, 96.390, 1559.0, 39.4842
33.001492948, 96.390, 1593.0, 39.9124
33.054014079, 96.390, 1509.0, 38.8458
33.106535209, 96.390, 1621.0, 40.2616
33.159056340, 96.390, 1519.0, 38.9744
33.211577471, 96.390, 1498.0, 38.7040
33.264098602, 96.390, 1553.0, 39.4081
33.316619732, 96.390, 1470.0, 38.3406
33.369140863, 96.390, 1614.0, 40.1746
33.421661994, 96.390, 1505.0, 38.7943
33.474183124, 96.390, 1592.0, 39.8999
33.526704255, 96.390, 1497.0, 38.6911
33.579225386, 96.390, 1505.0, 38.7943
33.631746517, 96.390, 1531.0, 39.1280
33.684267647, 96.390, 1551.0, 39.3827
33.736788778, 96.390, 1535.0, 39.1791
33.789309909, 96.390, 1436.0, 37.8946
33.841831039, 96.390, 1459.0, 38.1969
33.894352170, 96.390, 1441.0, 37.9605
33.946873301, 96.390, 1511.0, 38.8716
33.999394432, 96.390, 1460.0, 38.2099
34.051915562, 96.390, 1442.0, 37.9737
34.104436693, 96.390, 1402.0, 37.4433
34.156957824, 96.390, 1396.0, 37.3631
34.209478954, 96.390, 1506.0, 38.8072
34.262000085, 96.390, 1451.0, 38.0920
34.314521216, 96.390, 1448.0, 38.0526
34.367042346, 96.390, 1473.0, 38.3797
34.419563477, 96.390, 1418.0, 37.6563
34.472084608, 96.390, 1406.0, 37.4967
34.524605739, 96.390, 1424.0, 37.7359
34.577126869, 96.390, 1420.0, 37.6829
34.629648000, 96.390, 1426.0, 37.7624
34.682169131, 96.390, 1421.0, 37.6962
34.734690261, 96.390, 1388.0, 37.2559
34.787211392, 96.390, 1394.0, 37.3363
34.839732523, 96.390, 1418.0, 37.6563
34.892253654, 96.390, 1373.0, 37.0540
34.944774784, 96.390, 1373.0, 37.0540
34.997295915, 96.390, 1407.0, 37.5100
35.049817046, 96.390, 1418.0, 37.6563
35.102338176, 96.390, 1394.0, 37.3363
35.154859307, 96.390, 1297.0, 36.0139
35.207380438, 96.390, 1305.0, 36.1248
35.259901569, 96.390, 1346.0, 36.6879
35.312422699, 96.390, 1300.0, 36.0555
35.364943830, 96.390, 1365.0, 36.9459
35.417464961, 96.390, 1377.0, 37.1080
35.469986091, 96.390, 1400.0, 37.4166
35.522507222, 96.390, 1297.0, 36.0139
35.575028353, 96.390, 1336.0, 36.5513
35.627549484, 96.390, 1337.0, 36.5650
35.680070614, 96.390, 1324.0, 36.3868
35.732591745, 96.390, 1250.0, 35.3553
35.785112876, 96.390, 1335.0, 36.5377
35.837634006, 96.390, 1289.0, 35.9026
35.890155137, 96.390, 1267.0, 35.5949
35.942676268, 96.390, 1317.0, 36.2905
35.995197398, 96.390, 1338.0, 36.5787
36.047718529, 96.390, 1287.0, 35.8748
36.100239660, 96.390, 1289.0, 35.9026
36.152760791, 96.390, 1287.0, 35.8748
36.205281921, 96.390, 1305.0, 36.1248
36.257803052, 96.390, 1310.0, 36.1939
36.310324183, 96.390, 1303.0, 36.0971
36.362845313, 96.390, 1279.0, 35.7631
36.415366444, 96.390, 1308.0, 36.1663
36.467887575, 96.390, 1275.0, 35.7071
36.520408706, 96.390, 1277.0, 35.7351
36.572929836, 96.390, 1197.0, 34.5977
36.625450967, 96.390, 1261.0, 35.5106
36.677972098, 96.390, 1194.0, 34.5543
36.730493228, 96.390, 1236.0, 35.1568
36.783014359, 96.390, 1214.0, 34.8425
36.835535490, 96.390, 1272.0, 35.6651
36.888056621, 96.390, 1195.0, 34.5688
36.940577751, 96.390, 1237.0, 35.1710
36.993098882, 96.390, 1247.0, 35.3129
37.045620013, 96.390, 1253.0, 35.3977
37.098141143, 96.390, 1225.0, 35.0000
37.150662274, 96.390, 1205.0, 34.7131
37.203183405, 96.390, 1185.0, 34.4238
37.255704535, 96.390, 1241.0, 35.2278
37.308225666, 96.390, 1205.0, 34.7131
37.360746797, 96.390, 1238.0, 35.1852
37.413267928, 96.390, 1211.0, 34.7994
37.465789058, 96.390, 1221.0, 34.9428
37.518310189, 96.390, 1189.0, 34.4819
37.570831320, 96.390, 1244.0, 35.2704
37.623352450, 96.390, 1145.0, 33.8378
37.675873581, 96.390, 1227.0, 35.0286
37.728394712, 96.390, 1168.0, 34.1760
37.780915843, 96.390, 1139.0, 33.7491
37.833436973, 96.390, 1220.0, 34.9285
37.885958104, 96.390, 1218.0, 34.8999
37.938479235, 96.390, 1194.0, 34.5543
37.991000365, 96.390, 1163.0, 34.1028
38.043521496, 96.390, 1188.0, 34.4674
38.096042627, 96.390, 1132.0, 33.6452
38.148563758, 96.390, 1124.0, 33.5261
38.201084888, 96.390, 1131.0, 33.6303
38.253606019, 96.390, 1128.0, 33.5857
38.306127150, 96.390, 1180.0, 34.3511
38.358648280, 96.390, 1170.0, 34.2053
38.411169411, 96.390, 1115.0, 33.3916
38.463690542, 96.390, 1168.0, 34.1760
38.516211673, 96.390, 1178.0, 34.3220
38.568732803, 96.390, 1111.0, 33.3317
38.621253934, 96.390, 1179.0, 34.3366
38.673775065, 96.390, 1171.0, 34.2199
38.726296195, 96.390, 1140.0, 33.7639
38.778817326, 96.390, 1175.0, 34.2783
38.831338457, 96.390, 1140.0, 33.7639
38.883859587, 96.390, 1179.0, 34.3366
38.936380718, 96.390, 1074.0, 32.7719
38.988901849, 96.390, 1088.0, 32.9848
39.041422980, 96.390, 1134.0, 33.6749
39.093944110, 96.390, 1105.0, 33.2415
39.146465241, 96.390, 1118.0, 33.4365
39.198986372, 96.390, 1133.0, 33.6601
39.251507502, 96.390, 1132.0, 33.6452
39.304028633, 96.390, 1026.0, 32.0312
39.356549764, 96.390, 1140.0, 33.7639
39.409070895, 96.390, 1137.0, 33.7194
39.461592025, 96.390, 1102.0, 33.1964
39.514113156, 96.390, 1046.0, 32.3419
39.566634287, 96.390, 1108.0, 33.2866
39.619155417, 96.390, 1145.0, 33.8378
39.671676548, 96.390, 1139.0, 33.7491
39.724197679, 96.390, 1085.0, 32.9393
39.776718810, 96.390, 1102.0, 33.1964
39.829239940, 96.390, 1081.0, 32.8786
39.881761071, 96.390, 1094.0, 33.0757
39.934282202, 96.390, 1182.0, 34.3802
39.986803332, 96.390, 1127.0, 33.5708
40.039324463, 96.390, 1047.0, 32.3574
40.091845594, 96.390, 1119.0, 33.4515
40.144366725, 96.390, 1065.0, 32.6343
40.196887855, 96.390, 1096.0, 33.1059
40.249408986, 96.390, 1078.0, 32.8329
40.301930117, 96.390, 1135.0, 33.6898
40.354451247, 96.390, 1072.0, 32.7414
40.406972378, 96.390, 1119.0, 33.4515
40.459493509, 96.390, 1108.0, 33.2866
40.512014639, 96.390, 1180.0, 34.3511
40.564535770, 96.390, 1123.0, 33.5112
40.617056901, 96.390, 1071.0, 32.7261
40.669578032, 96.390, 1036.0, 32.1870
40.722099162, 96.390, 1052.0, 32.4345
40.774620293, 96.390, 1000.0, 31.6228
40.827141424, 96.390, 1076.0, 32.8024
40.879662554, 96.390, 1064.0, 32.6190
40.932183685, 96.390, 1044.0, 32.3110
40.984704816, 96.390, 1043.0, 32.2955
41.037225947, 96.390, 1088.0, 32.9848
41.089747077, 96.390, 1075.0, 32.7872
41.142268208, 96.390, 1036.0, 32.1870
41.194789339, 96.390, 1076.0, 32.8024
41.247310469, 96.390, 1070.0, 32.7109
41.299831600, 96.390, 1086.0, 32.9545
41.352352731, 96.390, 1064.0, 32.6190
41.404873862, 96.390, 1057.0, 32.5115
41.457394992, 96.390, 1081.0, 32.8786
41.509916123, 96.390, 1124.0, 33.5261
41.562437254, 96.390, 1081.0, 32.8786
41.614958384, 96.390, 1051.0, 32.4191
41.667479515, 96.390, 1037.0, 32.2025
41.720000646, 96.390, 963.0, 31.0322
41.772521776, 96.390, 1100.0, 33.1662
41.825042907, 96.390, 1012.0, 31.8119
41.877564038, 96.390, 1049.0, 32.3883
41.930085169, 96.390, 1043.0, 32.2955
41.982606299, 96.390, 1109.0, 33.3017
42.035127430, 96.390, 1040.0, 32.2490
42.087648561, 96.390, 984.0, 31.3688
42.140169691, 96.390, 1055.0, 32.4808
42.192690822, 96.390, 1086.0, 32.9545
42.245211953, 96.390, 1050.0, 32.4037
42.297733084, 96.390, 1017.0, 31.8904
42.350254214, 96.390, 1067.0, 32.6650
42.402775345, 96.390, 999.0, 31.6070
42.455296476, 96.390, 1002.0, 31.6544
42.507817606, 96.390, 1027.0, 32.0468
42.560338737, 96.390, 1064.0, 32.6190
42.612859868, 96.390, 1025.0, 32.0156
42.665380999, 96.390, 1081.0, 32.8786
42.717902129, 96.390, 1055.0, 32.4808
42.770423260, 96.390, 1025.0, 32.0156
42.822944391, 96.390, 1027.0, 32.0468
42.875465521, 96.390, 983.0, 31.3528
42.927986652, 96.390, 986.0, 31.4006
42.980507783, 96.390, 970.0, 31.1448
43.033028914, 96.390, 1034.0, 32.1559
43.085550044, 96.390, 1037.0, 32.2025
43.138071175, 96.390, 1029.0, 32.0780
43.190592306, 96.390, 968.0, 31.1127
43.243113436, 96.390, 991.0, 31.4802
43.295634567, 96.390, 972.0, 31.1769
43.348155698, 96.390, 1002.0, 31.6544
43.400676828, 96.390, 1038.0, 32.2180
43.453197959, 96.390, 972.0, 31.1769
43.505719090, 96.390, 998.0, 31.5911
43.558240221, 96.390, 1047.0, 32.3574
43.610761351, 96.390, 1017.0, 31.8904
43.663282482, 96.390, 1054.0, 32.4654
43.715803613, 96.390, 1039.0, 32.2335
43.768324743, 96.390, 1018.0, 31.9061
43.820845874, 96.390, 941.0, 30.6757
43.873367005, 96.390, 1005.0, 31.7017
43.925888136, 96.390, 1020.0, 31.9374
43.978409266, 96.390, 928.0, 30.4631
44.030930397, 96.390, 940.0, 30.6594
44.083451528, 96.390, 931.0, 30.5123
44.135972658, 96.390, 918.0, 30.2985
44.188493789, 96.390, 1015.0, 31.8591
44.241014920, 96.390, 1050.0, 32.4037
44.293536051, 96.390, 983.0, 31.3528
44.346057181, 96.390, 999.0, 31.6070
44.398578312, 96.390, 1003.0, 31.6702
44.451099443, 96.390, 952.0, 30.8545
44.503620573, 96.390, 1017.0, 31.8904
44.556141704, 96.390, 1003.0, 31.6702
44.608662835, 96.390, 1017.0, 31.8904
44.661183966, 96.390, 988.0, 31.4325
44.713705096, 96.390, 996.0, 31.5595
44.766226227, 96.390, 932.0, 30.5287
44.818747358, 96.390, 1053.0, 32.4500
44.871268488, 96.390, 955.0, 30.9031
44.923789619, 96.390, 923.0, 30.3809
44.976310750, 96.390, 873.0, 29.5466
45.028831880, 96.390, 924.0, 30.3974
45.081353011, 96.390, 944.0, 30.7246
45.133874142, 96.390, 984.0, 31.3688
45.186395273, 96.390, 957.0, 30.9354
45.238916403, 96.390, 978.0, 31.2730
45.291437534, 96.390, 923.0, 30.3809
45.343958665, 96.390, 903.0, 30.0500
45.396479795, 96.390, 946.0, 30.7571
45.449000926, 96.390, 856.0, 29.2575
45.501522057, 96.390, 1041.0, 32.2645
45.554043188, 96.390, 925.0, 30.4138
45.606564318, 96.390, 942.0, 30.6920
45.659085449, 96.390, 930.0, 30.4959
45.711606580, 96.390, 932.0, 30.5287
45.764127710, 96.390, 894.0, 29.8998
45.816648841, 96.390, 925.0, 30.4138
45.869169972, 96.390, 941.0, 30.6757
45.921691103, 96.390, 941.0, 30.6757
45.974212233, 96.390, 909.0, 30.1496
46.026733364, 96.390, 938.0, 30.6268
46.079254495, 96.390, 905.0, 30.0832
46.131775625, 96.390, 954.0, 30.8869
46.184296756, 96.390, 943.0, 30.7083
46.236817887, 96.390, 900.0, 30.0000
46.289339017, 96.390, 950.0, 30.8221
46.341860148, 96.390, 884.0, 29.7321
46.394381279, 96.390, 961.0, 31.0000
46.446902410, 96.390, 936.0, 30.5941
46.499423540, 96.390, 923.0, 30.3809
46.551944671, 96.390, 917.0, 30.2820
46.604465802, 96.390, 919.0, 30.3150
46.656986932, 96.390, 940.0, 30.6594
46.709508063, 96.390, 946.0, 30.7571
46.762029194, 96.390, 934.0, 30.5614
46.814550325, 96.390, 843.0, 29.0345
46.867071455, 96.390, 903.0, 30.0500
46.919592586, 96.390, 929.0, 30.4795
46.972113717, 96.390, 849.0, 29.1376
47.024634847, 96.390, 879.0, 29.6479
47.077155978, 96.390, 887.0, 29.7825
47.129677109, 96.390, 881.0, 29.6816
47.182198240, 96.390, 863.0, 29.3769
47.234719370, 96.390, 874.0, 29.5635
47.287240501, 96.390, 862.0, 29.3598
47.339761632, 96.390, 834.0, 28.8791
47.392282762, 96.390, 893.0, 29.8831
47.444803893, 96.390, 902.0, 30.0333
47.497325024, 96.390, 833.0, 28.8617
47.549846155, 96.390, 852.0, 29.1890
47.602367285, 96.390, 857.0, 29.2746
47.654888416, 96.390, 766.0, 27.6767
47.707409547, 96.390, 860.0, 29.3258
47.759930677, 96.390, 898.0, 29.9666
47.812451808, 96.390, 859.0, 29.3087
47.864972939, 96.390, 803.0, 28.3373
47.917494069, 96.390, 863.0, 29.3769
47.970015200, 96.390, 852.0, 29.1890
48.022536331, 96.390, 828.0, 28.7750
48.075057462, 96.390, 814.0, 28.5307
48.127578592, 96.390, 827.0, 28.7576
48.180099723, 96.390, 840.0, 28.9828
48.232620854, 96.390, 870.0, 29.4958
48.285141984, 96.390, 850.0, 29.1548
48.337663115, 96.390, 870.0, 29.4958
48.390184246, 96.390, 802.0, 28.3196
48.442705377, 96.390, 805.0, 28.3725
48.495226507, 96.390, 819.0, 28.6182
48.547747638, 96.390, 837.0, 28.9310
48.600268769, 96.390, 816.0, 28.5657
48.652789899, 96.390, 849.0, 29.1376
48.705311030, 96.390, 836.0, 28.9137
48.757832161, 96.390, 791.0, 28.1247
48.810353292, 96.390, 885.0, 29.7489
48.862874422, 96.390, 893.0, 29.8831
48.915395553, 96.390, 847.0, 29.1033
48.967916684, 96.390, 799.0, 28.2666
49.020437814, 96.390, 794.0, 28.1780
49.072958945, 96.390, 863.0, 29.3769
49.125480076, 96.390, 816.0, 28.5657
49.178001207, 96.390, 814.0, 28.5307
49.230522337, 96.390, 827.0, 28.7576
49.283043468, 96.390, 851.0, 29.1719
49.335564599, 96.390, 820.0, 28.6356
49.388085729, 96.390, 822.0, 28.6705
49.440606860, 96.390, 806.0, 28.3901
49.493127991, 96.390, 840.0, 28.9828
49.545649121, 96.390, 778.0, 27.8927
49.598170252, 96.390, 773.0, 27.8029
49.650691383, 96.390, 838.0, 28.9482
49.703212514, 96.390, 874.0, 29.5635
49.755733644, 96.390, 754.0, 27.4591
49.808254775, 96.390, 800.0, 28.2843
49.860775906, 96.390, 833.0, 28.8617
49.913297036, 96.390, 850.0, 29.1548
49.965818167, 96.390, 823.0, 28.6880
50.018339298, 96.390, 836.0, 28.9137
50.070860429, 96.390, 848.0, 29.1204
50.123381559, 96.390, 802.0, 28.3196
50.175902690, 96.390, 784.0, 28.0000
50.228423821, 96.390, 867.0, 29.4449
50.280944951, 96.390, 799.0, 28.2666
50.333466082, 96.390, 851.0, 29.1719
50.385987213, 96.390, 813.0, 28.5132
50.438508344, 96.390, 829.0, 28.7924
50.491029474, 96.390, 816.0, 28.5657
50.543550605, 96.390, 780.0, 27.9285
50.596071736, 96.390, 824.0, 28.7054
50.648592866, 96.390, 769.0, 27.7308
50.701113997, 96.390, 807.0, 28.4077
50.753635128, 96.390, 742.0, 27.2397
50.806156258, 96.390, 807.0, 28.4077
50.858677389, 96.390, 780.0, 27.9285
50.911198520, 96.390, 773.0, 27.8029
50.963719651, 96.390, 806.0, 28.3901
51.016240781, 96.390, 830.0, 28.8097
51.068761912, 96.390, 747.0, 27.3313
51.121283043, 96.390, 774.0, 27.8209
51.173804173, 96.390, 735.0, 27.1109
51.226325304, 96.390, 768.0, 27.7128
51.278846435, 96.390, 748.0, 27.3496
51.331367566, 96.390, 768.0, 27.7128
51.383888696, 96.390, 766.0, 27.6767
51.436409827, 96.390, 788.0, 28.0713
51.488930958, 96.390, 804.0, 28.3549
51.541452088, 96.390, 810.0, 28.4605
51.593973219, 96.390, 781.0, 27.9464
51.646494350, 96.390, 781.0, 27.9464
51.699015481, 96.390, 774.0, 27.8209
51.751536611, 96.390, 732.0, 27.0555
51.804057742, 96.390, 763.0, 27.6225
51.856578873, 96.390, 764.0, 27.6405
51.909100003, 96.390, 782.0, 27.9643
51.961621134, 96.390, 755.0, 27.4773
52.014142265, 96.390, 792.0, 28.1425
52.066663396, 96.390, 782.0, 27.9643
52.119184526, 96.390, 720.0, 26.8328
52.171705657, 96.390, 781.0, 27.9464
52.224226788, 96.390, 786.0, 28.0357
52.276747918, 96.390, 767.0, 27.6948
52.329269049, 96.390, 797.0, 28.2312
52.381790180, 96.390, 768.0, 27.7128
52.434311310, 96.390, 742.0, 27.2397
52.486832441, 96.390, 751.0, 27.4044
52.539353572, 96.390, 746.0, 27.3130
52.591874703, 96.390, 748.0, 27.3496
52.644395833, 96.390, 759.0, 27.5500
52.696916964, 96.390, 759.0, 27.5500
52.749438095, 96.390, 724.0, 26.9072
52.801959225, 96.390, 790.0, 28.1069
52.854480356, 96.390, 798.0, 28.2489
52.907001487, 96.390, 783.0, 27.9821
52.959522618, 96.390, 756.0, 27.4955
53.012043748, 96.390, 822.0, 28.6705
53.064564879, 96.390, 781.0, 27.9464
53.117086010, 96.390, 759.0, 27.5500
53.169607140, 96.390, 763.0, 27.6225
53.222128271, 96.390, 738.0, 27.1662
53.274649402, 96.390, 743.0, 27.2580
53.327170533, 96.390, 737.0, 27.1477
53.379691663, 96.390, 747.0, 27.3313
53.432212794, 96.390, 764.0, 27.6405
53.484733925, 96.390, 770.0, 27.7489
53.537255055, 96.390, 739.0, 27.1846
53.589776186, 96.390, 786.0, 28.0357
53.642297317, 96.390, 728.0, 26.9815
53.694818448, 96.390, 751.0, 27.4044
53.747339578, 96.390, 754.0, 27.4591
53.799860709, 96.390, 766.0, 27.6767
53.852381840, 96.390, 751.0, 27.4044
53.904902970, 96.390, 775.0, 27.8388
53.957424101, 96.390, 771.0, 27.7669
54.009945232, 96.390, 741.0, 27.2213
54.062466362, 96.390, 745.0, 27.2947
54.114987493, 96.390, 752.0, 27.4226
54.167508624, 96.390, 778.0, 27.8927
54.220029755, 96.390, 735.0, 27.1109
54.272550885, 96.390, 755.0, 27.4773
54.325072016, 96.390, 771.0, 27.7669
54.377593147, 96.390, 811.0, 28.4781
54.430114277, 96.390, 804.0, 28.3549
54.482635408, 96.390, 731.0, 27.0370
54.535156539, 96.390, 652.0, 25.5343
54.587677670, 96.390, 734.0, 27.0924
54.640198800, 96.390, 776.0, 27.8568
54.692719931, 96.390, 759.0, 27.5500
54.745241062, 96.390, 755.0, 27.4773
54.797762192, 96.390, 770.0, 27.7489
54.850283323, 96.390, 771.0, 27.7669
54.902804454, 96.390, 731.0, 27.0370
54.955325585, 96.390, 761.0, 27.5862
55.007846715, 96.390, 733.0, 27.0740
55.060367846, 96.390, 721.0, 26.8514
55.112888977, 96.390, 723.0, 26.8887
55.165410107, 96.390, 796.0, 28.2135
55.217931238, 96.390, 768.0, 27.7128
55.270452369, 96.390, 738.0, 27.1662
55.322973499, 96.390, 738.0, 27.1662
55.375494630, 96.390, 718.0, 26.7955
55.428015761, 96.390, 721.0, 26.8514
55.480536892, 96.390, 674.0, 25.9615
55.533058022, 96.390, 737.0, 27.1477
55.585579153, 96.390, 781.0, 27.9464
55.638100284, 96.390, 735.0, 27.1109
55.690621414, 96.390, 727.0, 26.9629
55.743142545, 96.390, 765.0, 27.6586
55.795663676, 96.390, 738.0, 27.1662
55.848184807, 96.390, 787.0, 28.0535
55.900705937, 96.390, 790.0, 28.1069
55.953227068, 96.390, 715.0, 26.7395
56.005748199, 96.390, 761.0, 27.5862
56.058269329, 96.390, 802.0, 28.3196
56.110790460, 96.390, 673.0, 25.9422
56.163311591, 96.390, 751.0, 27.4044
56.215832722, 96.390, 762.0, 27.6043
56.268353852, 96.390, 715.0, 26.7395
56.320874983, 96.390, 695.0, 26.3629
56.373396114, 96.390, 682.0, 26.1151
56.425917244, 96.390, 771.0, 27.7669
56.478438375, 96.390, 739.0, 27.1846
56.530959506, 96.390, 710.0, 26.6458
56.583480637, 96.390, 723.0, 26.8887
56.636001767, 96.390, 714.0, 26.7208
56.688522898, 96.390, 786.0, 28.0357
56.741044029, 96.390, 724.0, 26.9072
56.793565159, 96.390, 719.0, 26.8142
56.846086290, 96.390, 700.0, 26.4575
56.898607421, 96.390, 785.0, 28.0179
56.951128551, 96.390, 733.0, 27.0740
57.003649682, 96.390, 765.0, 27.6586
57.056170813, 96.390, 728.0, 26.9815
57.108691944, 96.390, 733.0, 27.0740
57.161213074, 96.390, 712.0, 26.6833
57.213734205, 96.390, 701.0, 26.4764
57.266255336, 96.390, 704.0, 26.5330
57.318776466, 96.390, 765.0, 27.6586
57.371297597, 96.390, 741.0, 27.2213
57.423818728, 96.390, 729.0, 27.0000
57.476339859, 96.390, 727.0, 26.9629
57.528860989, 96.390, 721.0, 26.8514
57.581382120, 96.390, 737.0, 27.1477
57.633903251, 96.390, 754.0, 27.4591
57.686424381, 96.390, 826.0, 28.7402
57.738945512, 96.390, 757.0, 27.5136
57.791466643, 96.390, 720.0, 26.8328
57.843987774, 96.390, 761.0, 27.5862
57.896508904, 96.390, 743.0, 27.2580
57.949030035, 96.390, 742.0, 27.2397
58.001551166, 96.390, 741.0, 27.2213
58.054072296, 96.390, 743.0, 27.2580
58.106593427, 96.390, 767.0, 27.6948
58.159114558, 96.390, 735.0, 27.1109
58.211635689, 96.390, 739.0, 27.1846
58.264156819, 96.390, 718.0, 26.7955
58.316677950, 96.390, 702.0, 26.4953
58.369199081, 96.390, 714.0, 26.7208
58.421720211, 96.390, 749.0, 27.3679
58.474241342, 96.390, 740.0, 27.2029
58.526762473, 96.390, 740.0, 27.2029
58.579283603, 96.390, 713.0, 26.7021
58.631804734, 96.390, 770.0, 27.7489
58.684325865, 96.390, 775.0, 27.8388
58.736846996, 96.390, 772.0, 27.7849
58.789368126, 96.390, 729.0, 27.0000
58.841889257, 96.390, 762.0, 27.6043
58.894410388, 96.390, 761.0, 27.5862
58.946931518, 96.390, 720.0, 26.8328
58.999452649, 96.390, 759.0, 27.5500
59.051973780, 96.390, 793.0, 28.1603
59.104494911, 96.390, 709.0, 26.6271
59.157016041, 96.390, 779.0, 27.9106
59.209537172, 96.390, 759.0, 27.5500
59.262058303, 96.390, 744.0, 27.2764
59.314579433, 96.390, 771.0, 27.7669
59.367100564, 96.390, 692.0, 26.3059
59.419621695, 96.390, 736.0, 27.1293
59.472142826, 96.390, 727.0, 26.9629
59.524663956, 96.390, 737.0, 27.1477
59.577185087, 96.390, 754.0, 27.4591
59.629706218, 96.390, 748.0, 27.3496
59.682227348, 96.390, 751.0, 27.4044
59.734748479, 96.390, 726.0, 26.9444
59.787269610, 96.390, 735.0, 27.1109
59.839790740, 96.390, 723.0, 26.8887
59.892311871, 96.390, 726.0, 26.9444
59.944833002, 96.390, 755.0, 27.4773
59.997354133, 96.390, 741.0, 27.2213
60.049875263, 96.390, 758.0, 27.5318
60.102396394, 96.390, 765.0, 27.6586
60.154917525, 96.390, 779.0, 27.9106
60.207438655, 96.390, 709.0, 26.6271
60.259959786, 96.390, 749.0, 27.3679
60.312480917, 96.390, 719.0, 26.8142
60.365002048, 96.390, 744.0, 27.2764
60.417523178, 96.390, 701.0, 26.4764
60.470044309, 96.390, 680.0, 26.0768
60.522565440, 96.390, 707.0, 26.5895
60.575086570, 96.390, 774.0, 27.8209
60.627607701, 96.390, 770.0, 27.7489
60.680128832, 96.390, 752.0, 27.4226
60.732649963, 96.390, 707.0, 26.5895
60.785171093, 96.390, 755.0, 27.4773
60.837692224, 96.390, 736.0, 27.1293
60.890213355, 96.390, 789.0, 28.0891
60.942734485, 96.390, 757.0, 27.5136
60.995255616, 96.390, 782.0, 27.9643
61.047776747, 96.390, 763.0, 27.6225
61.100297878, 96.390, 782.0, 27.9643
61.152819008, 96.390, 762.0, 27.6043
61.205340139, 96.390, 746.0, 27.3130
61.257861270, 96.390, 824.0, 28.7054
61.310382400, 96.390, 764.0, 27.6405
61.362903531, 96.390, 753.0, 27.4408
61.415424662, 96.390, 750.0, 27.3861
61.467945792, 96.390, 824.0, 28.7054
61.520466923, 96.390, 763.0, 27.6225
61.572988054, 96.390, 721.0, 26.8514
61.625509185, 96.390, 730.0, 27.0185
61.678030315, 96.390, 762.0, 27.6043
61.730551446, 96.390, 752.0, 27.4226
61.783072577, 96.390, 763.0, 27.6225
61.835593707, 96.390, 785.0, 28.0179
61.888114838, 96.390, 756.0, 27.4955
61.940635969, 96.390, 753.0, 27.4408
61.993157100, 96.390, 786.0, 28.0357
62.045678230, 96.390, 702.0, 26.4953
62.098199361, 96.390, 753.0, 27.4408
62.150720492, 96.390, 733.0, 27.0740
62.203241622, 96.390, 699.0, 26.4386
62.255762753, 96.390, 744.0, 27.2764
62.308283884, 96.390, 719.0, 26.8142
62.360805015, 96.390, 713.0, 26.7021
62.413326145, 96.390, 734.0, 27.0924
62.465847276, 96.390, 705.0, 26.5518
62.518368407, 96.390, 714.0, 26.7208
62.570889537, 96.390, 768.0, 27.7128
62.623410668, 96.390, 754.0, 27.4591
62.675931799, 96.390, 741.0, 27.2213
62.728452930, 96.390, 706.0, 26.5707
62.780974060, 96.390, 742.0, 27.2397
62.833495191, 96.390, 716.0, 26.7582
62.886016322, 96.390, 685.0, 26.1725
62.938537452, 96.390, 731.0, 27.0370
62.991058583, 96.390, 737.0, 27.1477
63.043579714, 96.390, 736.0, 27.1293
63.096100844, 96.390, 769.0, 27.7308
63.148621975, 96.390, 758.0, 27.5318
63.201143106, 96.390, 708.0, 26.6083
63.253664237, 96.390, 734.0, 27.0924
63.306185367, 96.390, 729.0, 27.0000
63.358706498, 96.390, 716.0, 26.7582
63.411227629, 96.390, 700.0, 26.4575
63.463748759, 96.390, 732.0, 27.0555
63.516269890, 96.390, 789.0, 28.0891
63.568791021, 96.390, 697.0, 26.4008
63.621312152, 96.390, 757.0, 27.5136
63.673833282, 96.390, 663.0, 25.7488
63.726354413, 96.390, 713.0, 26.7021
63.778875544, 96.390, 737.0, 27.1477
63.831396674, 96.390, 711.0, 26.6646
63.883917805, 96.390, 678.0, 26.0384
63.936438936, 96.390, 773.0, 27.8029
63.988960067, 96.390, 711.0, 26.6646
64.041481197, 96.390, 673.0, 25.9422
64.094002328, 96.390, 714.0, 26.7208
64.146523459, 96.390, 692.0, 26.3059
64.199044589, 96.390, 699.0, 26.4386
64.251565720, 96.390, 658.0, 25.6515
64.304086851, 96.390, 749.0, 27.3679
64.356607981, 96.390, 732.0, 27.0555
64.409129112, 96.390, 704.0, 26.5330
64.461650243, 96.390, 707.0, 26.5895
64.514171374, 96.390, 712.0, 26.6833
64.566692504, 96.390, 711.0, 26.6646
64.619213635, 96.390, 724.0, 26.9072
64.671734766, 96.390, 721.0, 26.8514
64.724255896, 96.390, 689.0, 26.2488
64.776777027, 96.390, 676.0, 26.0000
64.829298158, 96.390, 699.0, 26.4386
64.881819289, 96.390, 682.0, 26.1151
64.934340419, 96.390, 699.0, 26.4386
64.986861550, 96.390, 690.0, 26.2679