File: Files_organized_for_plots/134_days/C_XRD_130_Centroid16Mar22_Act16Nov22_B1_0714M_NaOH_LS0173.csv
[Measurement conditions]
Sample identification,130_Centroid16Mar22_Act16Nov22_B1_0714M_NaOH_LS0173
Comment - 1,"Configuration=Stage for Flat Samples/Holders, Owner=User-1, Creation date=7/1/2020 9:53:24 AM"
Comment - 2,"Goniometer=Theta/Theta; Minimum step size 2Theta:0.0001; Minimum step size Omega:0.0001"
Comment - 3,"Sample stage=Stage for flat samples/holders"
Comment - 4,"Diffractometer system=EMPYREAN"
Comment - 5,"Measurement program=C:\Users\tmr79\OneDrive - The Pennsylvania State University\Documents\NEUP\XRD\Cement\Zerobackground scan.xrdmp, Identifier={98A3B11C-88F9-4AA6-982C-73314A311EF5}"
Anode material,Cu
K-Alpha1 wavelength,1.5405980
K-Alpha2 wavelength,1.5444260
Ratio K-Alpha2/K-Alpha1,0.500
Divergence slit,Fixed,0.25
Monochromator used,NO
Generator voltage, 45
Tube current, 40
File date and time,03/Apr/2023 09:05
Unit cell,
h k l, 0 0 0
Scan axis,Gonio
Scan range,4.994599997,64.999991833
Scan step size,0.0262606
No. of points, 2285
Scan type,CONTINUOUS
Time per step,96.390
[Scan points]
Angle, TimePerStep, Intensity, ESD
5.007730280, 96.390, 4175.0, 64.6142
5.060251411, 96.390, 4161.0, 64.5058
5.112772541, 96.390, 4136.0, 64.3117
5.165293672, 96.390, 4127.0, 64.2417
5.217814803, 96.390, 4024.0, 63.4350
5.270335934, 96.390, 3786.0, 61.5305
5.322857064, 96.390, 3987.0, 63.1427
5.375378195, 96.390, 3809.0, 61.7171
5.427899326, 96.390, 3819.0, 61.7981
5.480420456, 96.390, 3751.0, 61.2454
5.532941587, 96.390, 3643.0, 60.3573
5.585462718, 96.390, 3645.0, 60.3738
5.637983849, 96.390, 3660.0, 60.4979
5.690504979, 96.390, 3629.0, 60.2412
5.743026110, 96.390, 3639.0, 60.3241
5.795547241, 96.390, 3530.0, 59.4138
5.848068371, 96.390, 3584.0, 59.8665
5.900589502, 96.390, 3507.0, 59.2199
5.953110633, 96.390, 3465.0, 58.8643
6.005631763, 96.390, 3528.0, 59.3970
6.058152894, 96.390, 3384.0, 58.1722
6.110674025, 96.390, 3339.0, 57.7841
6.163195156, 96.390, 3345.0, 57.8360
6.215716286, 96.390, 3480.0, 58.9915
6.268237417, 96.390, 3294.0, 57.3934
6.320758548, 96.390, 3368.0, 58.0345
6.373279678, 96.390, 3270.0, 57.1839
6.425800809, 96.390, 3331.0, 57.7148
6.478321940, 96.390, 3179.0, 56.3826
6.530843071, 96.390, 3249.0, 57.0000
6.583364201, 96.390, 3129.0, 55.9375
6.635885332, 96.390, 3229.0, 56.8243
6.688406463, 96.390, 3225.0, 56.7891
6.740927593, 96.390, 3254.0, 57.0438
6.793448724, 96.390, 3174.0, 56.3383
6.845969855, 96.390, 3141.0, 56.0446
6.898490986, 96.390, 3234.0, 56.8683
6.951012116, 96.390, 3128.0, 55.9285
7.003533247, 96.390, 3029.0, 55.0364
7.056054378, 96.390, 3111.0, 55.7763
7.108575508, 96.390, 3152.0, 56.1427
7.161096639, 96.390, 3137.0, 56.0089
7.213617770, 96.390, 3048.0, 55.2087
7.266138900, 96.390, 3191.0, 56.4889
7.318660031, 96.390, 3170.0, 56.3028
7.371181162, 96.390, 3059.0, 55.3082
7.423702293, 96.390, 3024.0, 54.9909
7.476223423, 96.390, 2977.0, 54.5619
7.528744554, 96.390, 2960.0, 54.4059
7.581265685, 96.390, 2959.0, 54.3967
7.633786815, 96.390, 3088.0, 55.5698
7.686307946, 96.390, 3060.0, 55.3173
7.738829077, 96.390, 3064.0, 55.3534
7.791350208, 96.390, 3056.0, 55.2811
7.843871338, 96.390, 2993.0, 54.7083
7.896392469, 96.390, 3040.0, 55.1362
7.948913600, 96.390, 3009.0, 54.8544
8.001434730, 96.390, 2914.0, 53.9815
8.053955861, 96.390, 3111.0, 55.7763
8.106476992, 96.390, 3076.0, 55.4617
8.158998123, 96.390, 3147.0, 56.0981
8.211519253, 96.390, 3100.0, 55.6776
8.264040384, 96.390, 3084.0, 55.5338
8.316561515, 96.390, 3161.0, 56.2228
8.369082645, 96.390, 3229.0, 56.8243
8.421603776, 96.390, 3262.0, 57.1139
8.474124907, 96.390, 3429.0, 58.5577
8.526646038, 96.390, 3506.0, 59.2115
8.579167168, 96.390, 3558.0, 59.6490
8.631688299, 96.390, 3781.0, 61.4898
8.684209430, 96.390, 3819.0, 61.7981
8.736730560, 96.390, 3663.0, 60.5227
8.789251691, 96.390, 3748.0, 61.2209
8.841772822, 96.390, 3512.0, 59.2621
8.894293952, 96.390, 3464.0, 58.8558
8.946815083, 96.390, 3361.0, 57.9741
8.999336214, 96.390, 3376.0, 58.1034
9.051857345, 96.390, 3391.0, 58.2323
9.104378475, 96.390, 3414.0, 58.4294
9.156899606, 96.390, 3175.0, 56.3471
9.209420737, 96.390, 3265.0, 57.1402
9.261941867, 96.390, 3422.0, 58.4979
9.314462998, 96.390, 3342.0, 57.8100
9.366984129, 96.390, 3220.0, 56.7450
9.419505260, 96.390, 3442.0, 58.6686
9.472026390, 96.390, 3484.0, 59.0254
9.524547521, 96.390, 3436.0, 58.6174
9.577068652, 96.390, 3389.0, 58.2151
9.629589782, 96.390, 3420.0, 58.4808
9.682110913, 96.390, 3496.0, 59.1270
9.734632044, 96.390, 3535.0, 59.4559
9.787153175, 96.390, 3442.0, 58.6686
9.839674305, 96.390, 3491.0, 59.0847
9.892195436, 96.390, 3439.0, 58.6430
9.944716567, 96.390, 3440.0, 58.6515
9.997237697, 96.390, 3545.0, 59.5399
10.049758828, 96.390, 3411.0, 58.4038
10.102279959, 96.390, 3601.0, 60.0083
10.154801090, 96.390, 3490.0, 59.0762
10.207322220, 96.390, 3379.0, 58.1292
10.259843351, 96.390, 3426.0, 58.5320
10.312364482, 96.390, 3405.0, 58.3524
10.364885612, 96.390, 3416.0, 58.4466
10.417406743, 96.390, 3475.0, 58.9491
10.469927874, 96.390, 3333.0, 57.7321
10.522449004, 96.390, 3438.0, 58.6345
10.574970135, 96.390, 3303.0, 57.4717
10.627491266, 96.390, 3352.0, 57.8965
10.680012397, 96.390, 3354.0, 57.9137
10.732533527, 96.390, 3349.0, 57.8705
10.785054658, 96.390, 3296.0, 57.4108
10.837575789, 96.390, 3100.0, 55.6776
10.890096919, 96.390, 3123.0, 55.8838
10.942618050, 96.390, 3061.0, 55.3263
10.995139181, 96.390, 3088.0, 55.5698
11.047660312, 96.390, 3021.0, 54.9636
11.100181442, 96.390, 3169.0, 56.2939
11.152702573, 96.390, 3177.0, 56.3649
11.205223704, 96.390, 3202.0, 56.5862
11.257744834, 96.390, 3580.0, 59.8331
11.310265965, 96.390, 3759.0, 61.3107
11.362787096, 96.390, 3827.0, 61.8628
11.415308227, 96.390, 3533.0, 59.4390
11.467829357, 96.390, 3397.0, 58.2838
11.520350488, 96.390, 3223.0, 56.7715
11.572871619, 96.390, 2996.0, 54.7357
11.625392749, 96.390, 2994.0, 54.7175
11.677913880, 96.390, 2945.0, 54.2679
11.730435011, 96.390, 2982.0, 54.6077
11.782956141, 96.390, 2949.0, 54.3047
11.835477272, 96.390, 2927.0, 54.1018
11.887998403, 96.390, 2900.0, 53.8516
11.940519534, 96.390, 2987.0, 54.6535
11.993040664, 96.390, 3027.0, 55.0182
12.045561795, 96.390, 2948.0, 54.2955
12.098082926, 96.390, 3040.0, 55.1362
12.150604056, 96.390, 3019.0, 54.9454
12.203125187, 96.390, 3082.0, 55.5158
12.255646318, 96.390, 3143.0, 56.0625
12.308167449, 96.390, 3057.0, 55.2901
12.360688579, 96.390, 2962.0, 54.4243
12.413209710, 96.390, 3028.0, 55.0273
12.465730841, 96.390, 3014.0, 54.8999
12.518251971, 96.390, 2993.0, 54.7083
12.570773102, 96.390, 2952.0, 54.3323
12.623294233, 96.390, 2870.0, 53.5724
12.675815364, 96.390, 2742.0, 52.3641
12.728336494, 96.390, 2776.0, 52.6878
12.780857625, 96.390, 2801.0, 52.9245
12.833378756, 96.390, 2760.0, 52.5357
12.885899886, 96.390, 2712.0, 52.0769
12.938421017, 96.390, 2654.0, 51.5170
12.990942148, 96.390, 2649.0, 51.4684
13.043463279, 96.390, 2617.0, 51.1566
13.095984409, 96.390, 2462.0, 49.6185
13.148505540, 96.390, 2460.0, 49.5984
13.201026671, 96.390, 2318.0, 48.1456
13.253547801, 96.390, 2250.0, 47.4342
13.306068932, 96.390, 2288.0, 47.8330
13.358590063, 96.390, 2396.0, 48.9490
13.411111193, 96.390, 2220.0, 47.1169
13.463632324, 96.390, 2212.0, 47.0319
13.516153455, 96.390, 2157.0, 46.4435
13.568674586, 96.390, 2269.0, 47.6340
13.621195716, 96.390, 2227.0, 47.1911
13.673716847, 96.390, 2151.0, 46.3789
13.726237978, 96.390, 2147.0, 46.3357
13.778759108, 96.390, 2156.0, 46.4327
13.831280239, 96.390, 2102.0, 45.8476
13.883801370, 96.390, 2199.0, 46.8935
13.936322501, 96.390, 2010.0, 44.8330
13.988843631, 96.390, 2046.0, 45.2327
14.041364762, 96.390, 2009.0, 44.8219
14.093885893, 96.390, 1945.0, 44.1022
14.146407023, 96.390, 1940.0, 44.0454
14.198928154, 96.390, 1945.0, 44.1022
14.251449285, 96.390, 2038.0, 45.1442
14.303970416, 96.390, 2006.0, 44.7884
14.356491546, 96.390, 2048.0, 45.2548
14.409012677, 96.390, 1954.0, 44.2041
14.461533808, 96.390, 1965.0, 44.3283
14.514054938, 96.390, 1996.0, 44.6766
14.566576069, 96.390, 1937.0, 44.0114
14.619097200, 96.390, 1963.0, 44.3058
14.671618331, 96.390, 1947.0, 44.1248
14.724139461, 96.390, 1987.0, 44.5758
14.776660592, 96.390, 2008.0, 44.8107
14.829181723, 96.390, 1986.0, 44.5646
14.881702853, 96.390, 1950.0, 44.1588
14.934223984, 96.390, 2009.0, 44.8219
14.986745115, 96.390, 2024.0, 44.9889
15.039266245, 96.390, 1991.0, 44.6206
15.091787376, 96.390, 2071.0, 45.5082
15.144308507, 96.390, 2016.0, 44.8999
15.196829638, 96.390, 1962.0, 44.2945
15.249350768, 96.390, 2068.0, 45.4753
15.301871899, 96.390, 2145.0, 46.3141
15.354393030, 96.390, 1935.0, 43.9886
15.406914160, 96.390, 2089.0, 45.7056
15.459435291, 96.390, 2068.0, 45.4753
15.511956422, 96.390, 2045.0, 45.2217
15.564477553, 96.390, 2019.0, 44.9333
15.616998683, 96.390, 1915.0, 43.7607
15.669519814, 96.390, 2026.0, 45.0111
15.722040945, 96.390, 1898.0, 43.5660
15.774562075, 96.390, 1931.0, 43.9431
15.827083206, 96.390, 1961.0, 44.2832
15.879604337, 96.390, 1907.0, 43.6692
15.932125468, 96.390, 1882.0, 43.3820
15.984646598, 96.390, 1912.0, 43.7264
16.037167729, 96.390, 1944.0, 44.0908
16.089688860, 96.390, 1958.0, 44.2493
16.142209990, 96.390, 1996.0, 44.6766
16.194731121, 96.390, 1966.0, 44.3396
16.247252252, 96.390, 1902.0, 43.6119
16.299773382, 96.390, 1866.0, 43.1972
16.352294513, 96.390, 1862.0, 43.1509
16.404815644, 96.390, 1971.0, 44.3959
16.457336775, 96.390, 1921.0, 43.8292
16.509857905, 96.390, 1935.0, 43.9886
16.562379036, 96.390, 1892.0, 43.4971
16.614900167, 96.390, 1964.0, 44.3170
16.667421297, 96.390, 1883.0, 43.3935
16.719942428, 96.390, 1933.0, 43.9659
16.772463559, 96.390, 2038.0, 45.1442
16.824984690, 96.390, 2049.0, 45.2659
16.877505820, 96.390, 2141.0, 46.2709
16.930026951, 96.390, 2073.0, 45.5302
16.982548082, 96.390, 2297.0, 47.9270
17.035069212, 96.390, 2296.0, 47.9166
17.087590343, 96.390, 2474.0, 49.7393
17.140111474, 96.390, 2581.0, 50.8035
17.192632605, 96.390, 2708.0, 52.0384
17.245153735, 96.390, 2752.0, 52.4595
17.297674866, 96.390, 2662.0, 51.5946
17.350195997, 96.390, 2720.0, 52.1536
17.402717127, 96.390, 2658.0, 51.5558
17.455238258, 96.390, 2647.0, 51.4490
17.507759389, 96.390, 2529.0, 50.2892
17.560280520, 96.390, 2512.0, 50.1199
17.612801650, 96.390, 2522.0, 50.2195
17.665322781, 96.390, 2366.0, 48.6415
17.717843912, 96.390, 2413.0, 49.1223
17.770365042, 96.390, 2321.0, 48.1768
17.822886173, 96.390, 2421.0, 49.2037
17.875407304, 96.390, 2240.0, 47.3286
17.927928434, 96.390, 2342.0, 48.3942
17.980449565, 96.390, 2241.0, 47.3392
18.032970696, 96.390, 2262.0, 47.5605
18.085491827, 96.390, 2212.0, 47.0319
18.138012957, 96.390, 2284.0, 47.7912
18.190534088, 96.390, 2265.0, 47.5920
18.243055219, 96.390, 2323.0, 48.1975
18.295576349, 96.390, 2313.0, 48.0937
18.348097480, 96.390, 2254.0, 47.4763
18.400618611, 96.390, 2118.0, 46.0217
18.453139742, 96.390, 2323.0, 48.1975
18.505660872, 96.390, 2281.0, 47.7598
18.558182003, 96.390, 2249.0, 47.4236
18.610703134, 96.390, 2250.0, 47.4342
18.663224264, 96.390, 2157.0, 46.4435
18.715745395, 96.390, 2188.0, 46.7761
18.768266526, 96.390, 2207.0, 46.9787
18.820787657, 96.390, 2115.0, 45.9891
18.873308787, 96.390, 2134.0, 46.1952
18.925829918, 96.390, 2103.0, 45.8585
18.978351049, 96.390, 2141.0, 46.2709
19.030872179, 96.390, 2176.0, 46.6476
19.083393310, 96.390, 2137.0, 46.2277
19.135914441, 96.390, 2118.0, 46.0217
19.188435572, 96.390, 2151.0, 46.3789
19.240956702, 96.390, 2210.0, 47.0106
19.293477833, 96.390, 2140.0, 46.2601
19.345998964, 96.390, 2238.0, 47.3075
19.398520094, 96.390, 2160.0, 46.4758
19.451041225, 96.390, 2242.0, 47.3498
19.503562356, 96.390, 2192.0, 46.8188
19.556083486, 96.390, 2211.0, 47.0213
19.608604617, 96.390, 2268.0, 47.6235
19.661125748, 96.390, 2104.0, 45.8694
19.713646879, 96.390, 2222.0, 47.1381
19.766168009, 96.390, 2196.0, 46.8615
19.818689140, 96.390, 2177.0, 46.6583
19.871210271, 96.390, 2193.0, 46.8295
19.923731401, 96.390, 2214.0, 47.0532
19.976252532, 96.390, 2194.0, 46.8402
20.028773663, 96.390, 2171.0, 46.5940
20.081294794, 96.390, 2198.0, 46.8828
20.133815924, 96.390, 2254.0, 47.4763
20.186337055, 96.390, 2132.0, 46.1736
20.238858186, 96.390, 2169.0, 46.5725
20.291379316, 96.390, 2239.0, 47.3181
20.343900447, 96.390, 2107.0, 45.9021
20.396421578, 96.390, 2212.0, 47.0319
20.448942709, 96.390, 2250.0, 47.4342
20.501463839, 96.390, 2186.0, 46.7547
20.553984970, 96.390, 2248.0, 47.4131
20.606506101, 96.390, 2269.0, 47.6340
20.659027231, 96.390, 2145.0, 46.3141
20.711548362, 96.390, 2290.0, 47.8539
20.764069493, 96.390, 2259.0, 47.5289
20.816590623, 96.390, 2242.0, 47.3498
20.869111754, 96.390, 2148.0, 46.3465
20.921632885, 96.390, 2173.0, 46.6154
20.974154016, 96.390, 2266.0, 47.6025
21.026675146, 96.390, 2264.0, 47.5815
21.079196277, 96.390, 2234.0, 47.2652
21.131717408, 96.390, 2313.0, 48.0937
21.184238538, 96.390, 2232.0, 47.2440
21.236759669, 96.390, 2283.0, 47.7807
21.289280800, 96.390, 2251.0, 47.4447
21.341801931, 96.390, 2264.0, 47.5815
21.394323061, 96.390, 2285.0, 47.8017
21.446844192, 96.390, 2239.0, 47.3181
21.499365323, 96.390, 2272.0, 47.6655
21.551886453, 96.390, 2311.0, 48.0729
21.604407584, 96.390, 2327.0, 48.2390
21.656928715, 96.390, 2371.0, 48.6929
21.709449846, 96.390, 2314.0, 48.1041
21.761970976, 96.390, 2272.0, 47.6655
21.814492107, 96.390, 2306.0, 48.0208
21.867013238, 96.390, 2283.0, 47.7807
21.919534368, 96.390, 2381.0, 48.7955
21.972055499, 96.390, 2477.0, 49.7695
22.024576630, 96.390, 2495.0, 49.9500
22.077097761, 96.390, 2483.0, 49.8297
22.129618891, 96.390, 2508.0, 50.0799
22.182140022, 96.390, 2462.0, 49.6185
22.234661153, 96.390, 2567.0, 50.6656
22.287182283, 96.390, 2772.0, 52.6498
22.339703414, 96.390, 2812.0, 53.0283
22.392224545, 96.390, 2849.0, 53.3760
22.444745675, 96.390, 2966.0, 54.4610
22.497266806, 96.390, 3083.0, 55.5248
22.549787937, 96.390, 3238.0, 56.9034
22.602309068, 96.390, 3298.0, 57.4282
22.654830198, 96.390, 3497.0, 59.1354
22.707351329, 96.390, 3375.0, 58.0948
22.759872460, 96.390, 3266.0, 57.1489
22.812393590, 96.390, 3051.0, 55.2359
22.864914721, 96.390, 3007.0, 54.8361
22.917435852, 96.390, 2798.0, 52.8961
22.969956983, 96.390, 2755.0, 52.4881
23.022478113, 96.390, 2631.0, 51.2933
23.074999244, 96.390, 2640.0, 51.3809
23.127520375, 96.390, 2549.0, 50.4876
23.180041505, 96.390, 2541.0, 50.4083
23.232562636, 96.390, 2457.0, 49.5681
23.285083767, 96.390, 2442.0, 49.4166
23.337604898, 96.390, 2513.0, 50.1298
23.390126028, 96.390, 2482.0, 49.8197
23.442647159, 96.390, 2521.0, 50.2096
23.495168290, 96.390, 2507.0, 50.0700
23.547689420, 96.390, 2473.0, 49.7293
23.600210551, 96.390, 2514.0, 50.1398
23.652731682, 96.390, 2453.0, 49.5278
23.705252813, 96.390, 2429.0, 49.2849
23.757773943, 96.390, 2482.0, 49.8197
23.810295074, 96.390, 2448.0, 49.4773
23.862816205, 96.390, 2459.0, 49.5883
23.915337335, 96.390, 2491.0, 49.9099
23.967858466, 96.390, 2358.0, 48.5592
24.020379597, 96.390, 2454.0, 49.5379
24.072900727, 96.390, 2315.0, 48.1144
24.125421858, 96.390, 2397.0, 48.9592
24.177942989, 96.390, 2196.0, 46.8615
24.230464120, 96.390, 2304.0, 48.0000
24.282985250, 96.390, 2352.0, 48.4974
24.335506381, 96.390, 2268.0, 47.6235
24.388027512, 96.390, 2112.0, 45.9565
24.440548642, 96.390, 2227.0, 47.1911
24.493069773, 96.390, 2216.0, 47.0744
24.545590904, 96.390, 2164.0, 46.5188
24.598112035, 96.390, 2110.0, 45.9347
24.650633165, 96.390, 2202.0, 46.9255
24.703154296, 96.390, 2072.0, 45.5192
24.755675427, 96.390, 2206.0, 46.9681
24.808196557, 96.390, 2019.0, 44.9333
24.860717688, 96.390, 2057.0, 45.3542
24.913238819, 96.390, 2069.0, 45.4863
24.965759950, 96.390, 2016.0, 44.8999
25.018281080, 96.390, 2011.0, 44.8442
25.070802211, 96.390, 2022.0, 44.9667
25.123323342, 96.390, 1932.0, 43.9545
25.175844472, 96.390, 1868.0, 43.2204
25.228365603, 96.390, 1952.0, 44.1814
25.280886734, 96.390, 1955.0, 44.2154
25.333407864, 96.390, 1943.0, 44.0795
25.385928995, 96.390, 2003.0, 44.7549
25.438450126, 96.390, 2030.0, 45.0555
25.490971257, 96.390, 1999.0, 44.7102
25.543492387, 96.390, 1951.0, 44.1701
25.596013518, 96.390, 2003.0, 44.7549
25.648534649, 96.390, 1963.0, 44.3058
25.701055779, 96.390, 1949.0, 44.1475
25.753576910, 96.390, 2021.0, 44.9555
25.806098041, 96.390, 1990.0, 44.6094
25.858619172, 96.390, 2058.0, 45.3652
25.911140302, 96.390, 2022.0, 44.9667
25.963661433, 96.390, 2128.0, 46.1303
26.016182564, 96.390, 2068.0, 45.4753
26.068703694, 96.390, 2229.0, 47.2123
26.121224825, 96.390, 2260.0, 47.5395
26.173745956, 96.390, 2260.0, 47.5395
26.226267087, 96.390, 2295.0, 47.9062
26.278788217, 96.390, 2239.0, 47.3181
26.331309348, 96.390, 2235.0, 47.2758
26.383830479, 96.390, 2098.0, 45.8039
26.436351609, 96.390, 2108.0, 45.9130
26.488872740, 96.390, 2061.0, 45.3982
26.541393871, 96.390, 1935.0, 43.9886
26.593915002, 96.390, 1954.0, 44.2041
26.646436132, 96.390, 1923.0, 43.8520
26.698957263, 96.390, 1833.0, 42.8135
26.751478394, 96.390, 1858.0, 43.1045
26.803999524, 96.390, 1905.0, 43.6463
26.856520655, 96.390, 1828.0, 42.7551
26.909041786, 96.390, 1859.0, 43.1161
26.961562916, 96.390, 1858.0, 43.1045
27.014084047, 96.390, 1871.0, 43.2551
27.066605178, 96.390, 1847.0, 42.9767
27.119126309, 96.390, 1744.0, 41.7612
27.171647439, 96.390, 1756.0, 41.9047
27.224168570, 96.390, 1795.0, 42.3674
27.276689701, 96.390, 1746.0, 41.7852
27.329210831, 96.390, 1782.0, 42.2137
27.381731962, 96.390, 1754.0, 41.8808
27.434253093, 96.390, 1764.0, 42.0000
27.486774224, 96.390, 1738.0, 41.6893
27.539295354, 96.390, 1704.0, 41.2795
27.591816485, 96.390, 1788.0, 42.2847
27.644337616, 96.390, 1665.0, 40.8044
27.696858746, 96.390, 1744.0, 41.7612
27.749379877, 96.390, 1715.0, 41.4126
27.801901008, 96.390, 1832.0, 42.8019
27.854422139, 96.390, 1720.0, 41.4729
27.906943269, 96.390, 1719.0, 41.4608
27.959464400, 96.390, 1761.0, 41.9643
28.011985531, 96.390, 1785.0, 42.2493
28.064506661, 96.390, 1733.0, 41.6293
28.117027792, 96.390, 1760.0, 41.9524
28.169548923, 96.390, 1752.0, 41.8569
28.222070054, 96.390, 1647.0, 40.5832
28.274591184, 96.390, 1699.0, 41.2189
28.327112315, 96.390, 1642.0, 40.5216
28.379633446, 96.390, 1763.0, 41.9881
28.432154576, 96.390, 1688.0, 41.0853
28.484675707, 96.390, 1645.0, 40.5586
28.537196838, 96.390, 1715.0, 41.4126
28.589717968, 96.390, 1784.0, 42.2374
28.642239099, 96.390, 1726.0, 41.5452
28.694760230, 96.390, 1671.0, 40.8779
28.747281361, 96.390, 1739.0, 41.7013
28.799802491, 96.390, 1755.0, 41.8927
28.852323622, 96.390, 1634.0, 40.4228
28.904844753, 96.390, 1600.0, 40.0000
28.957365883, 96.390, 1679.0, 40.9756
29.009887014, 96.390, 1731.0, 41.6053
29.062408145, 96.390, 1741.0, 41.7253
29.114929276, 96.390, 1736.0, 41.6653
29.167450406, 96.390, 1680.0, 40.9878
29.219971537, 96.390, 1708.0, 41.3280
29.272492668, 96.390, 1720.0, 41.4729
29.325013798, 96.390, 1755.0, 41.8927
29.377534929, 96.390, 1773.0, 42.1070
29.430056060, 96.390, 1830.0, 42.7785
29.482577191, 96.390, 1773.0, 42.1070
29.535098321, 96.390, 1803.0, 42.4617
29.587619452, 96.390, 1989.0, 44.5982
29.640140583, 96.390, 1846.0, 42.9651
29.692661713, 96.390, 1905.0, 43.6463
29.745182844, 96.390, 1913.0, 43.7379
29.797703975, 96.390, 1921.0, 43.8292
29.850225105, 96.390, 1968.0, 44.3621
29.902746236, 96.390, 1949.0, 44.1475
29.955267367, 96.390, 2040.0, 45.1664
30.007788498, 96.390, 1943.0, 44.0795
30.060309628, 96.390, 1943.0, 44.0795
30.112830759, 96.390, 1888.0, 43.4511
30.165351890, 96.390, 1936.0, 44.0000
30.217873020, 96.390, 1904.0, 43.6348
30.270394151, 96.390, 1954.0, 44.2041
30.322915282, 96.390, 1891.0, 43.4856
30.375436413, 96.390, 1828.0, 42.7551
30.427957543, 96.390, 1866.0, 43.1972
30.480478674, 96.390, 1860.0, 43.1277
30.532999805, 96.390, 1756.0, 41.9047
30.585520935, 96.390, 1796.0, 42.3792
30.638042066, 96.390, 1832.0, 42.8019
30.690563197, 96.390, 1716.0, 41.4246
30.743084328, 96.390, 1685.0, 41.0488
30.795605458, 96.390, 1691.0, 41.1218
30.848126589, 96.390, 1713.0, 41.3884
30.900647720, 96.390, 1672.0, 40.8901
30.953168850, 96.390, 1701.0, 41.2432
31.005689981, 96.390, 1630.0, 40.3733
31.058211112, 96.390, 1639.0, 40.4846
31.110732243, 96.390, 1660.0, 40.7431
31.163253373, 96.390, 1584.0, 39.7995
31.215774504, 96.390, 1653.0, 40.6571
31.268295635, 96.390, 1590.0, 39.8748
31.320816765, 96.390, 1615.0, 40.1871
31.373337896, 96.390, 1529.0, 39.1024
31.425859027, 96.390, 1595.0, 39.9375
31.478380157, 96.390, 1556.0, 39.4462
31.530901288, 96.390, 1580.0, 39.7492
31.583422419, 96.390, 1541.0, 39.2556
31.635943550, 96.390, 1567.0, 39.5854
31.688464680, 96.390, 1618.0, 40.2244
31.740985811, 96.390, 1566.0, 39.5727
31.793506942, 96.390, 1544.0, 39.2938
31.846028072, 96.390, 1568.0, 39.5980
31.898549203, 96.390, 1580.0, 39.7492
31.951070334, 96.390, 1444.0, 38.0000
32.003591465, 96.390, 1536.0, 39.1918
32.056112595, 96.390, 1533.0, 39.1535
32.108633726, 96.390, 1586.0, 39.8246
32.161154857, 96.390, 1487.0, 38.5616
32.213675987, 96.390, 1513.0, 38.8973
32.266197118, 96.390, 1560.0, 39.4968
32.318718249, 96.390, 1497.0, 38.6911
32.371239380, 96.390, 1547.0, 39.3319
32.423760510, 96.390, 1507.0, 38.8201
32.476281641, 96.390, 1495.0, 38.6652
32.528802772, 96.390, 1554.0, 39.4208
32.581323902, 96.390, 1454.0, 38.1314
32.633845033, 96.390, 1515.0, 38.9230
32.686366164, 96.390, 1506.0, 38.8072
32.738887295, 96.390, 1477.0, 38.4318
32.791408425, 96.390, 1443.0, 37.9868
32.843929556, 96.390, 1501.0, 38.7427
32.896450687, 96.390, 1479.0, 38.4578
32.948971817, 96.390, 1484.0, 38.5227
33.001492948, 96.390, 1517.0, 38.9487
33.054014079, 96.390, 1485.0, 38.5357
33.106535209, 96.390, 1449.0, 38.0657
33.159056340, 96.390, 1485.0, 38.5357
33.211577471, 96.390, 1544.0, 39.2938
33.264098602, 96.390, 1447.0, 38.0395
33.316619732, 96.390, 1460.0, 38.2099
33.369140863, 96.390, 1451.0, 38.0920
33.421661994, 96.390, 1495.0, 38.6652
33.474183124, 96.390, 1590.0, 39.8748
33.526704255, 96.390, 1527.0, 39.0768
33.579225386, 96.390, 1539.0, 39.2301
33.631746517, 96.390, 1452.0, 38.1051
33.684267647, 96.390, 1500.0, 38.7298
33.736788778, 96.390, 1557.0, 39.4588
33.789309909, 96.390, 1571.0, 39.6358
33.841831039, 96.390, 1553.0, 39.4081
33.894352170, 96.390, 1530.0, 39.1152
33.946873301, 96.390, 1610.0, 40.1248
33.999394432, 96.390, 1580.0, 39.7492
34.051915562, 96.390, 1679.0, 40.9756
34.104436693, 96.390, 1728.0, 41.5692
34.156957824, 96.390, 1800.0, 42.4264
34.209478954, 96.390, 1912.0, 43.7264
34.262000085, 96.390, 1936.0, 44.0000
34.314521216, 96.390, 2032.0, 45.0777
34.367042346, 96.390, 2131.0, 46.1628
34.419563477, 96.390, 2107.0, 45.9021
34.472084608, 96.390, 2283.0, 47.7807
34.524605739, 96.390, 2297.0, 47.9270
34.577126869, 96.390, 2386.0, 48.8467
34.629648000, 96.390, 2391.0, 48.8979
34.682169131, 96.390, 2357.0, 48.5489
34.734690261, 96.390, 2370.0, 48.6826
34.787211392, 96.390, 2399.0, 48.9796
34.839732523, 96.390, 2370.0, 48.6826
34.892253654, 96.390, 2371.0, 48.6929
34.944774784, 96.390, 2413.0, 49.1223
34.997295915, 96.390, 2247.0, 47.4025
35.049817046, 96.390, 2134.0, 46.1952
35.102338176, 96.390, 2248.0, 47.4131
35.154859307, 96.390, 2159.0, 46.4650
35.207380438, 96.390, 2049.0, 45.2659
35.259901569, 96.390, 2117.0, 46.0109
35.312422699, 96.390, 1992.0, 44.6318
35.364943830, 96.390, 2023.0, 44.9778
35.417464961, 96.390, 1901.0, 43.6005
35.469986091, 96.390, 1969.0, 44.3734
35.522507222, 96.390, 1859.0, 43.1161
35.575028353, 96.390, 1851.0, 43.0232
35.627549484, 96.390, 1859.0, 43.1161
35.680070614, 96.390, 1846.0, 42.9651
35.732591745, 96.390, 1893.0, 43.5086
35.785112876, 96.390, 1832.0, 42.8019
35.837634006, 96.390, 1852.0, 43.0349
35.890155137, 96.390, 1876.0, 43.3128
35.942676268, 96.390, 1770.0, 42.0714
35.995197398, 96.390, 1832.0, 42.8019
36.047718529, 96.390, 1859.0, 43.1161
36.100239660, 96.390, 1823.0, 42.6966
36.152760791, 96.390, 1759.0, 41.9404
36.205281921, 96.390, 1798.0, 42.4028
36.257803052, 96.390, 1658.0, 40.7185
36.310324183, 96.390, 1692.0, 41.1339
36.362845313, 96.390, 1678.0, 40.9634
36.415366444, 96.390, 1793.0, 42.3438
36.467887575, 96.390, 1719.0, 41.4608
36.520408706, 96.390, 1748.0, 41.8091
36.572929836, 96.390, 1693.0, 41.1461
36.625450967, 96.390, 1767.0, 42.0357
36.677972098, 96.390, 1687.0, 41.0731
36.730493228, 96.390, 1719.0, 41.4608
36.783014359, 96.390, 1712.0, 41.3763
36.835535490, 96.390, 1729.0, 41.5812
36.888056621, 96.390, 1707.0, 41.3159
36.940577751, 96.390, 1715.0, 41.4126
36.993098882, 96.390, 1723.0, 41.5090
37.045620013, 96.390, 1596.0, 39.9500
37.098141143, 96.390, 1590.0, 39.8748
37.150662274, 96.390, 1601.0, 40.0125
37.203183405, 96.390, 1537.0, 39.2046
37.255704535, 96.390, 1566.0, 39.5727
37.308225666, 96.390, 1605.0, 40.0625
37.360746797, 96.390, 1538.0, 39.2173
37.413267928, 96.390, 1523.0, 39.0256
37.465789058, 96.390, 1572.0, 39.6485
37.518310189, 96.390, 1468.0, 38.3145
37.570831320, 96.390, 1425.0, 37.7492
37.623352450, 96.390, 1405.0, 37.4833
37.675873581, 96.390, 1442.0, 37.9737
37.728394712, 96.390, 1408.0, 37.5233
37.780915843, 96.390, 1415.0, 37.6165
37.833436973, 96.390, 1410.0, 37.5500
37.885958104, 96.390, 1403.0, 37.4566
37.938479235, 96.390, 1457.0, 38.1707
37.991000365, 96.390, 1440.0, 37.9473
38.043521496, 96.390, 1370.0, 37.0135
38.096042627, 96.390, 1433.0, 37.8550
38.148563758, 96.390, 1446.0, 38.0263
38.201084888, 96.390, 1325.0, 36.4005
38.253606019, 96.390, 1306.0, 36.1386
38.306127150, 96.390, 1344.0, 36.6606
38.358648280, 96.390, 1378.0, 37.1214
38.411169411, 96.390, 1401.0, 37.4299
38.463690542, 96.390, 1399.0, 37.4032
38.516211673, 96.390, 1352.0, 36.7696
38.568732803, 96.390, 1335.0, 36.5377
38.621253934, 96.390, 1328.0, 36.4417
38.673775065, 96.390, 1264.0, 35.5528
38.726296195, 96.390, 1378.0, 37.1214
38.778817326, 96.390, 1271.0, 35.6511
38.831338457, 96.390, 1317.0, 36.2905
38.883859587, 96.390, 1229.0, 35.0571
38.936380718, 96.390, 1215.0, 34.8569
38.988901849, 96.390, 1202.0, 34.6699
39.041422980, 96.390, 1304.0, 36.1109
39.093944110, 96.390, 1229.0, 35.0571
39.146465241, 96.390, 1242.0, 35.2420
39.198986372, 96.390, 1178.0, 34.3220
39.251507502, 96.390, 1196.0, 34.5832
39.304028633, 96.390, 1260.0, 35.4965
39.356549764, 96.390, 1211.0, 34.7994
39.409070895, 96.390, 1252.0, 35.3836
39.461592025, 96.390, 1232.0, 35.0999
39.514113156, 96.390, 1220.0, 34.9285
39.566634287, 96.390, 1247.0, 35.3129
39.619155417, 96.390, 1225.0, 35.0000
39.671676548, 96.390, 1229.0, 35.0571
39.724197679, 96.390, 1167.0, 34.1614
39.776718810, 96.390, 1203.0, 34.6843
39.829239940, 96.390, 1212.0, 34.8138
39.881761071, 96.390, 1169.0, 34.1906
39.934282202, 96.390, 1170.0, 34.2053
39.986803332, 96.390, 1137.0, 33.7194
40.039324463, 96.390, 1150.0, 33.9116
40.091845594, 96.390, 1104.0, 33.2265
40.144366725, 96.390, 1096.0, 33.1059
40.196887855, 96.390, 1138.0, 33.7343
40.249408986, 96.390, 1097.0, 33.1210
40.301930117, 96.390, 1112.0, 33.3467
40.354451247, 96.390, 1081.0, 32.8786
40.406972378, 96.390, 1178.0, 34.3220
40.459493509, 96.390, 1131.0, 33.6303
40.512014639, 96.390, 1196.0, 34.5832
40.564535770, 96.390, 1164.0, 34.1174
40.617056901, 96.390, 1180.0, 34.3511
40.669578032, 96.390, 1162.0, 34.0881
40.722099162, 96.390, 1154.0, 33.9706
40.774620293, 96.390, 1130.0, 33.6155
40.827141424, 96.390, 1079.0, 32.8481
40.879662554, 96.390, 1091.0, 33.0303
40.932183685, 96.390, 1063.0, 32.6037
40.984704816, 96.390, 1097.0, 33.1210
41.037225947, 96.390, 1087.0, 32.9697
41.089747077, 96.390, 1089.0, 33.0000
41.142268208, 96.390, 1011.0, 31.7962
41.194789339, 96.390, 1050.0, 32.4037
41.247310469, 96.390, 1050.0, 32.4037
41.299831600, 96.390, 1090.0, 33.0151
41.352352731, 96.390, 992.0, 31.4960
41.404873862, 96.390, 1052.0, 32.4345
41.457394992, 96.390, 1058.0, 32.5269
41.509916123, 96.390, 1085.0, 32.9393
41.562437254, 96.390, 1068.0, 32.6803
41.614958384, 96.390, 1052.0, 32.4345
41.667479515, 96.390, 1080.0, 32.8634
41.720000646, 96.390, 1016.0, 31.8748
41.772521776, 96.390, 1020.0, 31.9374
41.825042907, 96.390, 1039.0, 32.2335
41.877564038, 96.390, 1024.0, 32.0000
41.930085169, 96.390, 952.0, 30.8545
41.982606299, 96.390, 1021.0, 31.9531
42.035127430, 96.390, 980.0, 31.3050
42.087648561, 96.390, 1010.0, 31.7805
42.140169691, 96.390, 976.0, 31.2410
42.192690822, 96.390, 1021.0, 31.9531
42.245211953, 96.390, 1001.0, 31.6386
42.297733084, 96.390, 971.0, 31.1609
42.350254214, 96.390, 943.0, 30.7083
42.402775345, 96.390, 955.0, 30.9031
42.455296476, 96.390, 944.0, 30.7246
42.507817606, 96.390, 987.0, 31.4166
42.560338737, 96.390, 982.0, 31.3369
42.612859868, 96.390, 962.0, 31.0161
42.665380999, 96.390, 916.0, 30.2655
42.717902129, 96.390, 981.0, 31.3209
42.770423260, 96.390, 926.0, 30.4302
42.822944391, 96.390, 992.0, 31.4960
42.875465521, 96.390, 957.0, 30.9354
42.927986652, 96.390, 918.0, 30.2985
42.980507783, 96.390, 976.0, 31.2410
43.033028914, 96.390, 986.0, 31.4006
43.085550044, 96.390, 957.0, 30.9354
43.138071175, 96.390, 970.0, 31.1448
43.190592306, 96.390, 967.0, 31.0966
43.243113436, 96.390, 962.0, 31.0161
43.295634567, 96.390, 999.0, 31.6070
43.348155698, 96.390, 973.0, 31.1929
43.400676828, 96.390, 906.0, 30.0998
43.453197959, 96.390, 900.0, 30.0000
43.505719090, 96.390, 959.0, 30.9677
43.558240221, 96.390, 955.0, 30.9031
43.610761351, 96.390, 942.0, 30.6920
43.663282482, 96.390, 998.0, 31.5911
43.715803613, 96.390, 963.0, 31.0322
43.768324743, 96.390, 977.0, 31.2570
43.820845874, 96.390, 992.0, 31.4960
43.873367005, 96.390, 1022.0, 31.9687
43.925888136, 96.390, 979.0, 31.2890
43.978409266, 96.390, 990.0, 31.4643
44.030930397, 96.390, 926.0, 30.4302
44.083451528, 96.390, 968.0, 31.1127
44.135972658, 96.390, 983.0, 31.3528
44.188493789, 96.390, 969.0, 31.1288
44.241014920, 96.390, 991.0, 31.4802
44.293536051, 96.390, 1026.0, 32.0312
44.346057181, 96.390, 994.0, 31.5278
44.398578312, 96.390, 1006.0, 31.7175
44.451099443, 96.390, 1011.0, 31.7962
44.503620573, 96.390, 1045.0, 32.3265
44.556141704, 96.390, 1041.0, 32.2645
44.608662835, 96.390, 1036.0, 32.1870
44.661183966, 96.390, 1026.0, 32.0312
44.713705096, 96.390, 980.0, 31.3050
44.766226227, 96.390, 1054.0, 32.4654
44.818747358, 96.390, 1028.0, 32.0624
44.871268488, 96.390, 1019.0, 31.9218
44.923789619, 96.390, 1124.0, 33.5261
44.976310750, 96.390, 1070.0, 32.7109
45.028831880, 96.390, 1086.0, 32.9545
45.081353011, 96.390, 1055.0, 32.4808
45.133874142, 96.390, 1081.0, 32.8786
45.186395273, 96.390, 1002.0, 31.6544
45.238916403, 96.390, 1044.0, 32.3110
45.291437534, 96.390, 1057.0, 32.5115
45.343958665, 96.390, 1041.0, 32.2645
45.396479795, 96.390, 1062.0, 32.5883
45.449000926, 96.390, 1083.0, 32.9090
45.501522057, 96.390, 1078.0, 32.8329
45.554043188, 96.390, 1032.0, 32.1248
45.606564318, 96.390, 1079.0, 32.8481
45.659085449, 96.390, 1056.0, 32.4962
45.711606580, 96.390, 1102.0, 33.1964
45.764127710, 96.390, 1096.0, 33.1059
45.816648841, 96.390, 1166.0, 34.1467
45.869169972, 96.390, 1097.0, 33.1210
45.921691103, 96.390, 1160.0, 34.0588
45.974212233, 96.390, 1153.0, 33.9559
46.026733364, 96.390, 1182.0, 34.3802
46.079254495, 96.390, 1178.0, 34.3220
46.131775625, 96.390, 1179.0, 34.3366
46.184296756, 96.390, 1221.0, 34.9428
46.236817887, 96.390, 1256.0, 35.4401
46.289339017, 96.390, 1223.0, 34.9714
46.341860148, 96.390, 1284.0, 35.8329
46.394381279, 96.390, 1300.0, 36.0555
46.446902410, 96.390, 1264.0, 35.5528
46.499423540, 96.390, 1200.0, 34.6410
46.551944671, 96.390, 1249.0, 35.3412
46.604465802, 96.390, 1223.0, 34.9714
46.656986932, 96.390, 1235.0, 35.1426
46.709508063, 96.390, 1206.0, 34.7275
46.762029194, 96.390, 1193.0, 34.5398
46.814550325, 96.390, 1203.0, 34.6843
46.867071455, 96.390, 1205.0, 34.7131
46.919592586, 96.390, 1162.0, 34.0881
46.972113717, 96.390, 1209.0, 34.7707
47.024634847, 96.390, 1159.0, 34.0441
47.077155978, 96.390, 1213.0, 34.8281
47.129677109, 96.390, 1178.0, 34.3220
47.182198240, 96.390, 1174.0, 34.2637
47.234719370, 96.390, 1148.0, 33.8821
47.287240501, 96.390, 1148.0, 33.8821
47.339761632, 96.390, 1180.0, 34.3511
47.392282762, 96.390, 1230.0, 35.0714
47.444803893, 96.390, 1114.0, 33.3766
47.497325024, 96.390, 1107.0, 33.2716
47.549846155, 96.390, 1085.0, 32.9393
47.602367285, 96.390, 1037.0, 32.2025
47.654888416, 96.390, 1066.0, 32.6497
47.707409547, 96.390, 1033.0, 32.1403
47.759930677, 96.390, 1041.0, 32.2645
47.812451808, 96.390, 1041.0, 32.2645
47.864972939, 96.390, 1023.0, 31.9844
47.917494069, 96.390, 1032.0, 32.1248
47.970015200, 96.390, 1092.0, 33.0454
48.022536331, 96.390, 1080.0, 32.8634
48.075057462, 96.390, 975.0, 31.2250
48.127578592, 96.390, 1003.0, 31.6702
48.180099723, 96.390, 999.0, 31.6070
48.232620854, 96.390, 1007.0, 31.7333
48.285141984, 96.390, 968.0, 31.1127
48.337663115, 96.390, 1014.0, 31.8434
48.390184246, 96.390, 993.0, 31.5119
48.442705377, 96.390, 959.0, 30.9677
48.495226507, 96.390, 951.0, 30.8383
48.547747638, 96.390, 946.0, 30.7571
48.600268769, 96.390, 892.0, 29.8664
48.652789899, 96.390, 995.0, 31.5436
48.705311030, 96.390, 877.0, 29.6142
48.757832161, 96.390, 958.0, 30.9516
48.810353292, 96.390, 917.0, 30.2820
48.862874422, 96.390, 896.0, 29.9333
48.915395553, 96.390, 924.0, 30.3974
48.967916684, 96.390, 889.0, 29.8161
49.020437814, 96.390, 890.0, 29.8329
49.072958945, 96.390, 857.0, 29.2746
49.125480076, 96.390, 859.0, 29.3087
49.178001207, 96.390, 881.0, 29.6816
49.230522337, 96.390, 906.0, 30.0998
49.283043468, 96.390, 871.0, 29.5127
49.335564599, 96.390, 856.0, 29.2575
49.388085729, 96.390, 845.0, 29.0689
49.440606860, 96.390, 839.0, 28.9655
49.493127991, 96.390, 794.0, 28.1780
49.545649121, 96.390, 789.0, 28.0891
49.598170252, 96.390, 838.0, 28.9482
49.650691383, 96.390, 844.0, 29.0517
49.703212514, 96.390, 837.0, 28.9310
49.755733644, 96.390, 805.0, 28.3725
49.808254775, 96.390, 795.0, 28.1957
49.860775906, 96.390, 813.0, 28.5132
49.913297036, 96.390, 796.0, 28.2135
49.965818167, 96.390, 826.0, 28.7402
50.018339298, 96.390, 871.0, 29.5127
50.070860429, 96.390, 847.0, 29.1033
50.123381559, 96.390, 847.0, 29.1033
50.175902690, 96.390, 806.0, 28.3901
50.228423821, 96.390, 786.0, 28.0357
50.280944951, 96.390, 809.0, 28.4429
50.333466082, 96.390, 857.0, 29.2746
50.385987213, 96.390, 831.0, 28.8271
50.438508344, 96.390, 877.0, 29.6142
50.491029474, 96.390, 842.0, 29.0172
50.543550605, 96.390, 858.0, 29.2916
50.596071736, 96.390, 844.0, 29.0517
50.648592866, 96.390, 851.0, 29.1719
50.701113997, 96.390, 895.0, 29.9166
50.753635128, 96.390, 835.0, 28.8964
50.806156258, 96.390, 802.0, 28.3196
50.858677389, 96.390, 828.0, 28.7750
50.911198520, 96.390, 788.0, 28.0713
50.963719651, 96.390, 769.0, 27.7308
51.016240781, 96.390, 857.0, 29.2746
51.068761912, 96.390, 755.0, 27.4773
51.121283043, 96.390, 844.0, 29.0517
51.173804173, 96.390, 829.0, 28.7924
51.226325304, 96.390, 854.0, 29.2233
51.278846435, 96.390, 810.0, 28.4605
51.331367566, 96.390, 797.0, 28.2312
51.383888696, 96.390, 786.0, 28.0357
51.436409827, 96.390, 827.0, 28.7576
51.488930958, 96.390, 810.0, 28.4605
51.541452088, 96.390, 822.0, 28.6705
51.593973219, 96.390, 817.0, 28.5832
51.646494350, 96.390, 814.0, 28.5307
51.699015481, 96.390, 761.0, 27.5862
51.751536611, 96.390, 807.0, 28.4077
51.804057742, 96.390, 828.0, 28.7750
51.856578873, 96.390, 859.0, 29.3087
51.909100003, 96.390, 821.0, 28.6531
51.961621134, 96.390, 857.0, 29.2746
52.014142265, 96.390, 767.0, 27.6948
52.066663396, 96.390, 789.0, 28.0891
52.119184526, 96.390, 846.0, 29.0861
52.171705657, 96.390, 750.0, 27.3861
52.224226788, 96.390, 830.0, 28.8097
52.276747918, 96.390, 864.0, 29.3939
52.329269049, 96.390, 838.0, 28.9482
52.381790180, 96.390, 769.0, 27.7308
52.434311310, 96.390, 861.0, 29.3428
52.486832441, 96.390, 867.0, 29.4449
52.539353572, 96.390, 864.0, 29.3939
52.591874703, 96.390, 882.0, 29.6985
52.644395833, 96.390, 837.0, 28.9310
52.696916964, 96.390, 833.0, 28.8617
52.749438095, 96.390, 829.0, 28.7924
52.801959225, 96.390, 828.0, 28.7750
52.854480356, 96.390, 865.0, 29.4109
52.907001487, 96.390, 891.0, 29.8496
52.959522618, 96.390, 826.0, 28.7402
53.012043748, 96.390, 896.0, 29.9333
53.064564879, 96.390, 887.0, 29.7825
53.117086010, 96.390, 858.0, 29.2916
53.169607140, 96.390, 849.0, 29.1376
53.222128271, 96.390, 877.0, 29.6142
53.274649402, 96.390, 854.0, 29.2233
53.327170533, 96.390, 883.0, 29.7153
53.379691663, 96.390, 906.0, 30.0998
53.432212794, 96.390, 873.0, 29.5466
53.484733925, 96.390, 887.0, 29.7825
53.537255055, 96.390, 892.0, 29.8664
53.589776186, 96.390, 832.0, 28.8444
53.642297317, 96.390, 864.0, 29.3939
53.694818448, 96.390, 899.0, 29.9833
53.747339578, 96.390, 839.0, 28.9655
53.799860709, 96.390, 890.0, 29.8329
53.852381840, 96.390, 908.0, 30.1330
53.904902970, 96.390, 882.0, 29.6985
53.957424101, 96.390, 866.0, 29.4279
54.009945232, 96.390, 830.0, 28.8097
54.062466362, 96.390, 845.0, 29.0689
54.114987493, 96.390, 848.0, 29.1204
54.167508624, 96.390, 842.0, 29.0172
54.220029755, 96.390, 813.0, 28.5132
54.272550885, 96.390, 800.0, 28.2843
54.325072016, 96.390, 777.0, 27.8747
54.377593147, 96.390, 836.0, 28.9137
54.430114277, 96.390, 833.0, 28.8617
54.482635408, 96.390, 815.0, 28.5482
54.535156539, 96.390, 766.0, 27.6767
54.587677670, 96.390, 823.0, 28.6880
54.640198800, 96.390, 749.0, 27.3679
54.692719931, 96.390, 820.0, 28.6356
54.745241062, 96.390, 749.0, 27.3679
54.797762192, 96.390, 763.0, 27.6225
54.850283323, 96.390, 796.0, 28.2135
54.902804454, 96.390, 744.0, 27.2764
54.955325585, 96.390, 773.0, 27.8029
55.007846715, 96.390, 748.0, 27.3496
55.060367846, 96.390, 758.0, 27.5318
55.112888977, 96.390, 769.0, 27.7308
55.165410107, 96.390, 769.0, 27.7308
55.217931238, 96.390, 778.0, 27.8927
55.270452369, 96.390, 818.0, 28.6007
55.322973499, 96.390, 805.0, 28.3725
55.375494630, 96.390, 794.0, 28.1780
55.428015761, 96.390, 787.0, 28.0535
55.480536892, 96.390, 754.0, 27.4591
55.533058022, 96.390, 768.0, 27.7128
55.585579153, 96.390, 762.0, 27.6043
55.638100284, 96.390, 781.0, 27.9464
55.690621414, 96.390, 761.0, 27.5862
55.743142545, 96.390, 792.0, 28.1425
55.795663676, 96.390, 814.0, 28.5307
55.848184807, 96.390, 827.0, 28.7576
55.900705937, 96.390, 743.0, 27.2580
55.953227068, 96.390, 786.0, 28.0357
56.005748199, 96.390, 702.0, 26.4953
56.058269329, 96.390, 776.0, 27.8568
56.110790460, 96.390, 722.0, 26.8701
56.163311591, 96.390, 798.0, 28.2489
56.215832722, 96.390, 773.0, 27.8029
56.268353852, 96.390, 801.0, 28.3019
56.320874983, 96.390, 774.0, 27.8209
56.373396114, 96.390, 750.0, 27.3861
56.425917244, 96.390, 826.0, 28.7402
56.478438375, 96.390, 709.0, 26.6271
56.530959506, 96.390, 738.0, 27.1662
56.583480637, 96.390, 759.0, 27.5500
56.636001767, 96.390, 724.0, 26.9072
56.688522898, 96.390, 775.0, 27.8388
56.741044029, 96.390, 719.0, 26.8142
56.793565159, 96.390, 750.0, 27.3861
56.846086290, 96.390, 723.0, 26.8887
56.898607421, 96.390, 780.0, 27.9285
56.951128551, 96.390, 719.0, 26.8142
57.003649682, 96.390, 716.0, 26.7582
57.056170813, 96.390, 720.0, 26.8328
57.108691944, 96.390, 659.0, 25.6710
57.161213074, 96.390, 700.0, 26.4575
57.213734205, 96.390, 755.0, 27.4773
57.266255336, 96.390, 715.0, 26.7395
57.318776466, 96.390, 731.0, 27.0370
57.371297597, 96.390, 738.0, 27.1662
57.423818728, 96.390, 719.0, 26.8142
57.476339859, 96.390, 702.0, 26.4953
57.528860989, 96.390, 732.0, 27.0555
57.581382120, 96.390, 746.0, 27.3130
57.633903251, 96.390, 698.0, 26.4197
57.686424381, 96.390, 721.0, 26.8514
57.738945512, 96.390, 714.0, 26.7208
57.791466643, 96.390, 750.0, 27.3861
57.843987774, 96.390, 669.0, 25.8650
57.896508904, 96.390, 705.0, 26.5518
57.949030035, 96.390, 721.0, 26.8514
58.001551166, 96.390, 706.0, 26.5707
58.054072296, 96.390, 763.0, 27.6225
58.106593427, 96.390, 727.0, 26.9629
58.159114558, 96.390, 732.0, 27.0555
58.211635689, 96.390, 782.0, 27.9643
58.264156819, 96.390, 747.0, 27.3313
58.316677950, 96.390, 705.0, 26.5518
58.369199081, 96.390, 703.0, 26.5141
58.421720211, 96.390, 738.0, 27.1662
58.474241342, 96.390, 738.0, 27.1662
58.526762473, 96.390, 686.0, 26.1916
58.579283603, 96.390, 752.0, 27.4226
58.631804734, 96.390, 703.0, 26.5141
58.684325865, 96.390, 740.0, 27.2029
58.736846996, 96.390, 684.0, 26.1534
58.789368126, 96.390, 707.0, 26.5895
58.841889257, 96.390, 742.0, 27.2397
58.894410388, 96.390, 733.0, 27.0740
58.946931518, 96.390, 720.0, 26.8328
58.999452649, 96.390, 740.0, 27.2029
59.051973780, 96.390, 706.0, 26.5707
59.104494911, 96.390, 704.0, 26.5330
59.157016041, 96.390, 685.0, 26.1725
59.209537172, 96.390, 770.0, 27.7489
59.262058303, 96.390, 713.0, 26.7021
59.314579433, 96.390, 691.0, 26.2869
59.367100564, 96.390, 696.0, 26.3818
59.419621695, 96.390, 738.0, 27.1662
59.472142826, 96.390, 733.0, 27.0740
59.524663956, 96.390, 761.0, 27.5862
59.577185087, 96.390, 689.0, 26.2488
59.629706218, 96.390, 735.0, 27.1109
59.682227348, 96.390, 710.0, 26.6458
59.734748479, 96.390, 733.0, 27.0740
59.787269610, 96.390, 788.0, 28.0713
59.839790740, 96.390, 717.0, 26.7769
59.892311871, 96.390, 759.0, 27.5500
59.944833002, 96.390, 711.0, 26.6646
59.997354133, 96.390, 691.0, 26.2869
60.049875263, 96.390, 743.0, 27.2580
60.102396394, 96.390, 773.0, 27.8029
60.154917525, 96.390, 737.0, 27.1477
60.207438655, 96.390, 763.0, 27.6225
60.259959786, 96.390, 788.0, 28.0713
60.312480917, 96.390, 812.0, 28.4956
60.365002048, 96.390, 782.0, 27.9643
60.417523178, 96.390, 787.0, 28.0535
60.470044309, 96.390, 826.0, 28.7402
60.522565440, 96.390, 808.0, 28.4253
60.575086570, 96.390, 826.0, 28.7402
60.627607701, 96.390, 897.0, 29.9500
60.680128832, 96.390, 854.0, 29.2233
60.732649963, 96.390, 927.0, 30.4467
60.785171093, 96.390, 868.0, 29.4618
60.837692224, 96.390, 871.0, 29.5127
60.890213355, 96.390, 917.0, 30.2820
60.942734485, 96.390, 936.0, 30.5941
60.995255616, 96.390, 935.0, 30.5778
61.047776747, 96.390, 934.0, 30.5614
61.100297878, 96.390, 931.0, 30.5123
61.152819008, 96.390, 906.0, 30.0998
61.205340139, 96.390, 887.0, 29.7825
61.257861270, 96.390, 922.0, 30.3645
61.310382400, 96.390, 945.0, 30.7409
61.362903531, 96.390, 928.0, 30.4631
61.415424662, 96.390, 929.0, 30.4795
61.467945792, 96.390, 915.0, 30.2490
61.520466923, 96.390, 912.0, 30.1993
61.572988054, 96.390, 913.0, 30.2159
61.625509185, 96.390, 935.0, 30.5778
61.678030315, 96.390, 878.0, 29.6311
61.730551446, 96.390, 865.0, 29.4109
61.783072577, 96.390, 868.0, 29.4618
61.835593707, 96.390, 872.0, 29.5296
61.888114838, 96.390, 881.0, 29.6816
61.940635969, 96.390, 890.0, 29.8329
61.993157100, 96.390, 839.0, 28.9655
62.045678230, 96.390, 890.0, 29.8329
62.098199361, 96.390, 904.0, 30.0666
62.150720492, 96.390, 849.0, 29.1376
62.203241622, 96.390, 899.0, 29.9833
62.255762753, 96.390, 869.0, 29.4788
62.308283884, 96.390, 867.0, 29.4449
62.360805015, 96.390, 849.0, 29.1376
62.413326145, 96.390, 849.0, 29.1376
62.465847276, 96.390, 873.0, 29.5466
62.518368407, 96.390, 775.0, 27.8388
62.570889537, 96.390, 874.0, 29.5635
62.623410668, 96.390, 801.0, 28.3019
62.675931799, 96.390, 861.0, 29.3428
62.728452930, 96.390, 860.0, 29.3258
62.780974060, 96.390, 826.0, 28.7402
62.833495191, 96.390, 820.0, 28.6356
62.886016322, 96.390, 795.0, 28.1957
62.938537452, 96.390, 801.0, 28.3019
62.991058583, 96.390, 760.0, 27.5681
63.043579714, 96.390, 788.0, 28.0713
63.096100844, 96.390, 797.0, 28.2312
63.148621975, 96.390, 739.0, 27.1846
63.201143106, 96.390, 725.0, 26.9258
63.253664237, 96.390, 778.0, 27.8927
63.306185367, 96.390, 747.0, 27.3313
63.358706498, 96.390, 731.0, 27.0370
63.411227629, 96.390, 764.0, 27.6405
63.463748759, 96.390, 753.0, 27.4408
63.516269890, 96.390, 756.0, 27.4955
63.568791021, 96.390, 732.0, 27.0555
63.621312152, 96.390, 698.0, 26.4197
63.673833282, 96.390, 724.0, 26.9072
63.726354413, 96.390, 735.0, 27.1109
63.778875544, 96.390, 730.0, 27.0185
63.831396674, 96.390, 752.0, 27.4226
63.883917805, 96.390, 739.0, 27.1846
63.936438936, 96.390, 694.0, 26.3439
63.988960067, 96.390, 698.0, 26.4197
64.041481197, 96.390, 764.0, 27.6405
64.094002328, 96.390, 700.0, 26.4575
64.146523459, 96.390, 680.0, 26.0768
64.199044589, 96.390, 714.0, 26.7208
64.251565720, 96.390, 760.0, 27.5681
64.304086851, 96.390, 721.0, 26.8514
64.356607981, 96.390, 681.0, 26.0960
64.409129112, 96.390, 655.0, 25.5930
64.461650243, 96.390, 710.0, 26.6458
64.514171374, 96.390, 724.0, 26.9072
64.566692504, 96.390, 660.0, 25.6905
64.619213635, 96.390, 664.0, 25.7682
64.671734766, 96.390, 703.0, 26.5141
64.724255896, 96.390, 717.0, 26.7769
64.776777027, 96.390, 700.0, 26.4575
64.829298158, 96.390, 688.0, 26.2298
64.881819289, 96.390, 705.0, 26.5518
64.934340419, 96.390, 682.0, 26.1151
64.986861550, 96.390, 669.0, 25.8650