File: Files_organized_for_plots/134_days/E_XRD_136_MgCorner11May22_Act16Nov22_B1_0714M_NaOH_LS0173.csv
[Measurement conditions]
Sample identification,136_MgCorner11May22_Act16Nov22_B1_0714M_NaOH_LS0173
Comment - 1,"Configuration=Stage for Flat Samples/Holders, Owner=User-1, Creation date=7/1/2020 9:53:24 AM"
Comment - 2,"Goniometer=Theta/Theta; Minimum step size 2Theta:0.0001; Minimum step size Omega:0.0001"
Comment - 3,"Sample stage=Stage for flat samples/holders"
Comment - 4,"Diffractometer system=EMPYREAN"
Comment - 5,"Measurement program=C:\Users\tmr79\OneDrive - The Pennsylvania State University\Documents\NEUP\XRD\Cement\Zerobackground scan.xrdmp, Identifier={98A3B11C-88F9-4AA6-982C-73314A311EF5}"
Anode material,Cu
K-Alpha1 wavelength,1.5405980
K-Alpha2 wavelength,1.5444260
Ratio K-Alpha2/K-Alpha1,0.500
Divergence slit,Fixed,0.25
Monochromator used,NO
Generator voltage, 45
Tube current, 40
File date and time,03/Apr/2023 10:02
Unit cell,
h k l, 0 0 0
Scan axis,Gonio
Scan range,4.994599997,64.999991833
Scan step size,0.0262606
No. of points, 2285
Scan type,CONTINUOUS
Time per step,96.390
[Scan points]
Angle, TimePerStep, Intensity, ESD
5.007730280, 96.390, 4719.0, 68.6950
5.060251411, 96.390, 4580.0, 67.6757
5.112772541, 96.390, 4627.0, 68.0221
5.165293672, 96.390, 4636.0, 68.0882
5.217814803, 96.390, 4624.0, 68.0000
5.270335934, 96.390, 4497.0, 67.0597
5.322857064, 96.390, 4449.0, 66.7008
5.375378195, 96.390, 4659.0, 68.2569
5.427899326, 96.390, 4491.0, 67.0149
5.480420456, 96.390, 4462.0, 66.7982
5.532941587, 96.390, 4413.0, 66.4304
5.585462718, 96.390, 4356.0, 66.0000
5.637983849, 96.390, 4448.0, 66.6933
5.690504979, 96.390, 4489.0, 67.0000
5.743026110, 96.390, 4380.0, 66.1816
5.795547241, 96.390, 4404.0, 66.3626
5.848068371, 96.390, 4358.0, 66.0151
5.900589502, 96.390, 4398.0, 66.3174
5.953110633, 96.390, 4291.0, 65.5057
6.005631763, 96.390, 4242.0, 65.1306
6.058152894, 96.390, 4358.0, 66.0151
6.110674025, 96.390, 4245.0, 65.1537
6.163195156, 96.390, 4258.0, 65.2534
6.215716286, 96.390, 4482.0, 66.9477
6.268237417, 96.390, 4402.0, 66.3476
6.320758548, 96.390, 4310.0, 65.6506
6.373279678, 96.390, 4153.0, 64.4438
6.425800809, 96.390, 4121.0, 64.1950
6.478321940, 96.390, 4358.0, 66.0151
6.530843071, 96.390, 4306.0, 65.6201
6.583364201, 96.390, 4277.0, 65.3988
6.635885332, 96.390, 4181.0, 64.6607
6.688406463, 96.390, 4276.0, 65.3911
6.740927593, 96.390, 4233.0, 65.0615
6.793448724, 96.390, 4147.0, 64.3972
6.845969855, 96.390, 4133.0, 64.2884
6.898490986, 96.390, 4131.0, 64.2729
6.951012116, 96.390, 4032.0, 63.4980
7.003533247, 96.390, 4063.0, 63.7417
7.056054378, 96.390, 4089.0, 63.9453
7.108575508, 96.390, 4091.0, 63.9609
7.161096639, 96.390, 4160.0, 64.4981
7.213617770, 96.390, 3989.0, 63.1585
7.266138900, 96.390, 4048.0, 63.6239
7.318660031, 96.390, 4017.0, 63.3798
7.371181162, 96.390, 3933.0, 62.7136
7.423702293, 96.390, 3960.0, 62.9285
7.476223423, 96.390, 3951.0, 62.8570
7.528744554, 96.390, 3960.0, 62.9285
7.581265685, 96.390, 3932.0, 62.7057
7.633786815, 96.390, 4047.0, 63.6160
7.686307946, 96.390, 3830.0, 61.8870
7.738829077, 96.390, 3923.0, 62.6339
7.791350208, 96.390, 3886.0, 62.3378
7.843871338, 96.390, 3758.0, 61.3025
7.896392469, 96.390, 3843.0, 61.9919
7.948913600, 96.390, 3830.0, 61.8870
8.001434730, 96.390, 3995.0, 63.2060
8.053955861, 96.390, 3832.0, 61.9032
8.106476992, 96.390, 3762.0, 61.3351
8.158998123, 96.390, 3895.0, 62.4099
8.211519253, 96.390, 3950.0, 62.8490
8.264040384, 96.390, 3941.0, 62.7774
8.316561515, 96.390, 4097.0, 64.0078
8.369082645, 96.390, 4178.0, 64.6375
8.421603776, 96.390, 4386.0, 66.2269
8.474124907, 96.390, 4644.0, 68.1469
8.526646038, 96.390, 4061.0, 63.7260
8.579167168, 96.390, 3797.0, 61.6198
8.631688299, 96.390, 3762.0, 61.3351
8.684209430, 96.390, 3661.0, 60.5062
8.736730560, 96.390, 3610.0, 60.0833
8.789251691, 96.390, 3608.0, 60.0666
8.841772822, 96.390, 3782.0, 61.4980
8.894293952, 96.390, 3594.0, 59.9500
8.946815083, 96.390, 3557.0, 59.6406
8.999336214, 96.390, 3647.0, 60.3904
9.051857345, 96.390, 3612.0, 60.0999
9.104378475, 96.390, 3624.0, 60.1997
9.156899606, 96.390, 3594.0, 59.9500
9.209420737, 96.390, 3641.0, 60.3407
9.261941867, 96.390, 3653.0, 60.4401
9.314462998, 96.390, 3648.0, 60.3987
9.366984129, 96.390, 3556.0, 59.6322
9.419505260, 96.390, 3661.0, 60.5062
9.472026390, 96.390, 3691.0, 60.7536
9.524547521, 96.390, 3689.0, 60.7371
9.577068652, 96.390, 3638.0, 60.3158
9.629589782, 96.390, 3605.0, 60.0417
9.682110913, 96.390, 3660.0, 60.4979
9.734632044, 96.390, 3765.0, 61.3596
9.787153175, 96.390, 3749.0, 61.2291
9.839674305, 96.390, 3739.0, 61.1474
9.892195436, 96.390, 3719.0, 60.9836
9.944716567, 96.390, 3834.0, 61.9193
9.997237697, 96.390, 3908.0, 62.5140
10.049758828, 96.390, 3948.0, 62.8331
10.102279959, 96.390, 3959.0, 62.9206
10.154801090, 96.390, 4020.0, 63.4035
10.207322220, 96.390, 3967.0, 62.9841
10.259843351, 96.390, 4099.0, 64.0234
10.312364482, 96.390, 4071.0, 63.8044
10.364885612, 96.390, 4070.0, 63.7966
10.417406743, 96.390, 4074.0, 63.8279
10.469927874, 96.390, 4234.0, 65.0692
10.522449004, 96.390, 4235.0, 65.0769
10.574970135, 96.390, 4178.0, 64.6375
10.627491266, 96.390, 4133.0, 64.2884
10.680012397, 96.390, 4440.0, 66.6333
10.732533527, 96.390, 4196.0, 64.7765
10.785054658, 96.390, 4578.0, 67.6609
10.837575789, 96.390, 4577.0, 67.6535
10.890096919, 96.390, 4589.0, 67.7422
10.942618050, 96.390, 4548.0, 67.4389
10.995139181, 96.390, 4577.0, 67.6535
11.047660312, 96.390, 4561.0, 67.5352
11.100181442, 96.390, 4547.0, 67.4314
11.152702573, 96.390, 4676.0, 68.3813
11.205223704, 96.390, 4550.0, 67.4537
11.257744834, 96.390, 4500.0, 67.0820
11.310265965, 96.390, 4381.0, 66.1891
11.362787096, 96.390, 4596.0, 67.7938
11.415308227, 96.390, 4394.0, 66.2873
11.467829357, 96.390, 4206.0, 64.8537
11.520350488, 96.390, 4234.0, 65.0692
11.572871619, 96.390, 4048.0, 63.6239
11.625392749, 96.390, 3866.0, 62.1772
11.677913880, 96.390, 3903.0, 62.4740
11.730435011, 96.390, 3659.0, 60.4897
11.782956141, 96.390, 3630.0, 60.2495
11.835477272, 96.390, 3475.0, 58.9491
11.887998403, 96.390, 3378.0, 58.1206
11.940519534, 96.390, 3421.0, 58.4893
11.993040664, 96.390, 3191.0, 56.4889
12.045561795, 96.390, 3180.0, 56.3915
12.098082926, 96.390, 3097.0, 55.6507
12.150604056, 96.390, 3020.0, 54.9545
12.203125187, 96.390, 3014.0, 54.8999
12.255646318, 96.390, 2949.0, 54.3047
12.308167449, 96.390, 2935.0, 54.1756
12.360688579, 96.390, 2852.0, 53.4041
12.413209710, 96.390, 2747.0, 52.4118
12.465730841, 96.390, 2735.0, 52.2972
12.518251971, 96.390, 2649.0, 51.4684
12.570773102, 96.390, 2596.0, 50.9510
12.623294233, 96.390, 2540.0, 50.3984
12.675815364, 96.390, 2655.0, 51.5267
12.728336494, 96.390, 2489.0, 49.8899
12.780857625, 96.390, 2520.0, 50.1996
12.833378756, 96.390, 2487.0, 49.8698
12.885899886, 96.390, 2469.0, 49.6890
12.938421017, 96.390, 2415.0, 49.1426
12.990942148, 96.390, 2394.0, 48.9285
13.043463279, 96.390, 2317.0, 48.1352
13.095984409, 96.390, 2311.0, 48.0729
13.148505540, 96.390, 2263.0, 47.5710
13.201026671, 96.390, 2282.0, 47.7703
13.253547801, 96.390, 2234.0, 47.2652
13.306068932, 96.390, 2129.0, 46.1411
13.358590063, 96.390, 2180.0, 46.6905
13.411111193, 96.390, 2187.0, 46.7654
13.463632324, 96.390, 2140.0, 46.2601
13.516153455, 96.390, 2163.0, 46.5081
13.568674586, 96.390, 2109.0, 45.9239
13.621195716, 96.390, 2133.0, 46.1844
13.673716847, 96.390, 2144.0, 46.3033
13.726237978, 96.390, 2178.0, 46.6690
13.778759108, 96.390, 2191.0, 46.8081
13.831280239, 96.390, 2064.0, 45.4313
13.883801370, 96.390, 1976.0, 44.4522
13.936322501, 96.390, 1981.0, 44.5084
13.988843631, 96.390, 2004.0, 44.7661
14.041364762, 96.390, 1987.0, 44.5758
14.093885893, 96.390, 1981.0, 44.5084
14.146407023, 96.390, 2066.0, 45.4533
14.198928154, 96.390, 2171.0, 46.5940
14.251449285, 96.390, 2068.0, 45.4753
14.303970416, 96.390, 2008.0, 44.8107
14.356491546, 96.390, 1884.0, 43.4051
14.409012677, 96.390, 1975.0, 44.4410
14.461533808, 96.390, 1891.0, 43.4856
14.514054938, 96.390, 1867.0, 43.2088
14.566576069, 96.390, 1853.0, 43.0465
14.619097200, 96.390, 1904.0, 43.6348
14.671618331, 96.390, 1898.0, 43.5660
14.724139461, 96.390, 1790.0, 42.3084
14.776660592, 96.390, 1821.0, 42.6732
14.829181723, 96.390, 1819.0, 42.6497
14.881702853, 96.390, 1840.0, 42.8952
14.934223984, 96.390, 1738.0, 41.6893
14.986745115, 96.390, 1776.0, 42.1426
15.039266245, 96.390, 1808.0, 42.5206
15.091787376, 96.390, 1814.0, 42.5911
15.144308507, 96.390, 1875.0, 43.3013
15.196829638, 96.390, 1935.0, 43.9886
15.249350768, 96.390, 1901.0, 43.6005
15.301871899, 96.390, 1864.0, 43.1741
15.354393030, 96.390, 1818.0, 42.6380
15.406914160, 96.390, 1811.0, 42.5558
15.459435291, 96.390, 1749.0, 41.8210
15.511956422, 96.390, 1661.0, 40.7554
15.564477553, 96.390, 1791.0, 42.3202
15.616998683, 96.390, 1716.0, 41.4246
15.669519814, 96.390, 1647.0, 40.5832
15.722040945, 96.390, 1712.0, 41.3763
15.774562075, 96.390, 1666.0, 40.8167
15.827083206, 96.390, 1721.0, 41.4849
15.879604337, 96.390, 1669.0, 40.8534
15.932125468, 96.390, 1593.0, 39.9124
15.984646598, 96.390, 1658.0, 40.7185
16.037167729, 96.390, 1656.0, 40.6940
16.089688860, 96.390, 1599.0, 39.9875
16.142209990, 96.390, 1660.0, 40.7431
16.194731121, 96.390, 1648.0, 40.5956
16.247252252, 96.390, 1609.0, 40.1123
16.299773382, 96.390, 1633.0, 40.4104
16.352294513, 96.390, 1656.0, 40.6940
16.404815644, 96.390, 1645.0, 40.5586
16.457336775, 96.390, 1521.0, 39.0000
16.509857905, 96.390, 1642.0, 40.5216
16.562379036, 96.390, 1562.0, 39.5221
16.614900167, 96.390, 1700.0, 41.2311
16.667421297, 96.390, 1626.0, 40.3237
16.719942428, 96.390, 1645.0, 40.5586
16.772463559, 96.390, 1598.0, 39.9750
16.824984690, 96.390, 1608.0, 40.0999
16.877505820, 96.390, 1657.0, 40.7063
16.930026951, 96.390, 1695.0, 41.1704
16.982548082, 96.390, 1651.0, 40.6325
17.035069212, 96.390, 1615.0, 40.1871
17.087590343, 96.390, 1609.0, 40.1123
17.140111474, 96.390, 1639.0, 40.4846
17.192632605, 96.390, 1630.0, 40.3733
17.245153735, 96.390, 1601.0, 40.0125
17.297674866, 96.390, 1676.0, 40.9390
17.350195997, 96.390, 1726.0, 41.5452
17.402717127, 96.390, 1662.0, 40.7676
17.455238258, 96.390, 1535.0, 39.1791
17.507759389, 96.390, 1621.0, 40.2616
17.560280520, 96.390, 1585.0, 39.8121
17.612801650, 96.390, 1590.0, 39.8748
17.665322781, 96.390, 1600.0, 40.0000
17.717843912, 96.390, 1557.0, 39.4588
17.770365042, 96.390, 1596.0, 39.9500
17.822886173, 96.390, 1612.0, 40.1497
17.875407304, 96.390, 1615.0, 40.1871
17.927928434, 96.390, 1605.0, 40.0625
17.980449565, 96.390, 1648.0, 40.5956
18.032970696, 96.390, 1601.0, 40.0125
18.085491827, 96.390, 1595.0, 39.9375
18.138012957, 96.390, 1651.0, 40.6325
18.190534088, 96.390, 1665.0, 40.8044
18.243055219, 96.390, 1714.0, 41.4005
18.295576349, 96.390, 1783.0, 42.2256
18.348097480, 96.390, 1705.0, 41.2916
18.400618611, 96.390, 1662.0, 40.7676
18.453139742, 96.390, 1782.0, 42.2137
18.505660872, 96.390, 1589.0, 39.8623
18.558182003, 96.390, 1650.0, 40.6202
18.610703134, 96.390, 1652.0, 40.6448
18.663224264, 96.390, 1652.0, 40.6448
18.715745395, 96.390, 1634.0, 40.4228
18.768266526, 96.390, 1625.0, 40.3113
18.820787657, 96.390, 1605.0, 40.0625
18.873308787, 96.390, 1605.0, 40.0625
18.925829918, 96.390, 1703.0, 41.2674
18.978351049, 96.390, 1671.0, 40.8779
19.030872179, 96.390, 1758.0, 41.9285
19.083393310, 96.390, 1665.0, 40.8044
19.135914441, 96.390, 1746.0, 41.7852
19.188435572, 96.390, 1695.0, 41.1704
19.240956702, 96.390, 1661.0, 40.7554
19.293477833, 96.390, 1732.0, 41.6173
19.345998964, 96.390, 1658.0, 40.7185
19.398520094, 96.390, 1778.0, 42.1663
19.451041225, 96.390, 1758.0, 41.9285
19.503562356, 96.390, 1820.0, 42.6615
19.556083486, 96.390, 1744.0, 41.7612
19.608604617, 96.390, 1789.0, 42.2966
19.661125748, 96.390, 1794.0, 42.3556
19.713646879, 96.390, 1899.0, 43.5775
19.766168009, 96.390, 2038.0, 45.1442
19.818689140, 96.390, 1816.0, 42.6146
19.871210271, 96.390, 1845.0, 42.9535
19.923731401, 96.390, 1860.0, 43.1277
19.976252532, 96.390, 2246.0, 47.3920
20.028773663, 96.390, 1947.0, 44.1248
20.081294794, 96.390, 1789.0, 42.2966
20.133815924, 96.390, 1807.0, 42.5088
20.186337055, 96.390, 1709.0, 41.3401
20.238858186, 96.390, 1776.0, 42.1426
20.291379316, 96.390, 1882.0, 43.3820
20.343900447, 96.390, 2001.0, 44.7325
20.396421578, 96.390, 2219.0, 47.1063
20.448942709, 96.390, 1965.0, 44.3283
20.501463839, 96.390, 2039.0, 45.1553
20.553984970, 96.390, 2218.0, 47.0956
20.606506101, 96.390, 2015.0, 44.8888
20.659027231, 96.390, 1833.0, 42.8135
20.711548362, 96.390, 1894.0, 43.5201
20.764069493, 96.390, 1875.0, 43.3013
20.816590623, 96.390, 1926.0, 43.8862
20.869111754, 96.390, 1832.0, 42.8019
20.921632885, 96.390, 1840.0, 42.8952
20.974154016, 96.390, 1929.0, 43.9204
21.026675146, 96.390, 1931.0, 43.9431
21.079196277, 96.390, 1920.0, 43.8178
21.131717408, 96.390, 2021.0, 44.9555
21.184238538, 96.390, 1908.0, 43.6807
21.236759669, 96.390, 1956.0, 44.2267
21.289280800, 96.390, 2024.0, 44.9889
21.341801931, 96.390, 1911.0, 43.7150
21.394323061, 96.390, 1993.0, 44.6430
21.446844192, 96.390, 2070.0, 45.4973
21.499365323, 96.390, 1992.0, 44.6318
21.551886453, 96.390, 2091.0, 45.7275
21.604407584, 96.390, 2126.0, 46.1086
21.656928715, 96.390, 1940.0, 44.0454
21.709449846, 96.390, 2101.0, 45.8367
21.761970976, 96.390, 2053.0, 45.3100
21.814492107, 96.390, 2166.0, 46.5403
21.867013238, 96.390, 2196.0, 46.8615
21.919534368, 96.390, 2158.0, 46.4543
21.972055499, 96.390, 2134.0, 46.1952
22.024576630, 96.390, 2229.0, 47.2123
22.077097761, 96.390, 2295.0, 47.9062
22.129618891, 96.390, 2143.0, 46.2925
22.182140022, 96.390, 2200.0, 46.9042
22.234661153, 96.390, 2288.0, 47.8330
22.287182283, 96.390, 2206.0, 46.9681
22.339703414, 96.390, 2337.0, 48.3425
22.392224545, 96.390, 2236.0, 47.2864
22.444745675, 96.390, 2379.0, 48.7750
22.497266806, 96.390, 2230.0, 47.2229
22.549787937, 96.390, 2354.0, 48.5180
22.602309068, 96.390, 2357.0, 48.5489
22.654830198, 96.390, 2394.0, 48.9285
22.707351329, 96.390, 2399.0, 48.9796
22.759872460, 96.390, 2443.0, 49.4267
22.812393590, 96.390, 2418.0, 49.1732
22.864914721, 96.390, 2401.0, 49.0000
22.917435852, 96.390, 2291.0, 47.8644
22.969956983, 96.390, 2350.0, 48.4768
23.022478113, 96.390, 2287.0, 47.8226
23.074999244, 96.390, 2228.0, 47.2017
23.127520375, 96.390, 2168.0, 46.5618
23.180041505, 96.390, 2199.0, 46.8935
23.232562636, 96.390, 2148.0, 46.3465
23.285083767, 96.390, 2113.0, 45.9674
23.337604898, 96.390, 2053.0, 45.3100
23.390126028, 96.390, 2068.0, 45.4753
23.442647159, 96.390, 2175.0, 46.6369
23.495168290, 96.390, 2168.0, 46.5618
23.547689420, 96.390, 1975.0, 44.4410
23.600210551, 96.390, 1978.0, 44.4747
23.652731682, 96.390, 1975.0, 44.4410
23.705252813, 96.390, 1929.0, 43.9204
23.757773943, 96.390, 1943.0, 44.0795
23.810295074, 96.390, 1854.0, 43.0581
23.862816205, 96.390, 1858.0, 43.1045
23.915337335, 96.390, 1847.0, 42.9767
23.967858466, 96.390, 1860.0, 43.1277
24.020379597, 96.390, 1844.0, 42.9418
24.072900727, 96.390, 1846.0, 42.9651
24.125421858, 96.390, 1824.0, 42.7083
24.177942989, 96.390, 1908.0, 43.6807
24.230464120, 96.390, 1915.0, 43.7607
24.282985250, 96.390, 1842.0, 42.9185
24.335506381, 96.390, 1778.0, 42.1663
24.388027512, 96.390, 1690.0, 41.1096
24.440548642, 96.390, 1658.0, 40.7185
24.493069773, 96.390, 1736.0, 41.6653
24.545590904, 96.390, 1691.0, 41.1218
24.598112035, 96.390, 1670.0, 40.8656
24.650633165, 96.390, 1630.0, 40.3733
24.703154296, 96.390, 1666.0, 40.8167
24.755675427, 96.390, 1712.0, 41.3763
24.808196557, 96.390, 1710.0, 41.3521
24.860717688, 96.390, 1643.0, 40.5339
24.913238819, 96.390, 1609.0, 40.1123
24.965759950, 96.390, 1663.0, 40.7799
25.018281080, 96.390, 1553.0, 39.4081
25.070802211, 96.390, 1570.0, 39.6232
25.123323342, 96.390, 1565.0, 39.5601
25.175844472, 96.390, 1660.0, 40.7431
25.228365603, 96.390, 1597.0, 39.9625
25.280886734, 96.390, 1618.0, 40.2244
25.333407864, 96.390, 1643.0, 40.5339
25.385928995, 96.390, 1675.0, 40.9268
25.438450126, 96.390, 1596.0, 39.9500
25.490971257, 96.390, 1558.0, 39.4715
25.543492387, 96.390, 1637.0, 40.4599
25.596013518, 96.390, 1664.0, 40.7922
25.648534649, 96.390, 1639.0, 40.4846
25.701055779, 96.390, 1553.0, 39.4081
25.753576910, 96.390, 1471.0, 38.3536
25.806098041, 96.390, 1573.0, 39.6611
25.858619172, 96.390, 1513.0, 38.8973
25.911140302, 96.390, 1619.0, 40.2368
25.963661433, 96.390, 1544.0, 39.2938
26.016182564, 96.390, 1529.0, 39.1024
26.068703694, 96.390, 1539.0, 39.2301
26.121224825, 96.390, 1525.0, 39.0512
26.173745956, 96.390, 1545.0, 39.3065
26.226267087, 96.390, 1432.0, 37.8418
26.278788217, 96.390, 1557.0, 39.4588
26.331309348, 96.390, 1548.0, 39.3446
26.383830479, 96.390, 1512.0, 38.8844
26.436351609, 96.390, 1572.0, 39.6485
26.488872740, 96.390, 1482.0, 38.4968
26.541393871, 96.390, 1546.0, 39.3192
26.593915002, 96.390, 1450.0, 38.0789
26.646436132, 96.390, 1543.0, 39.2810
26.698957263, 96.390, 1535.0, 39.1791
26.751478394, 96.390, 1546.0, 39.3192
26.803999524, 96.390, 1571.0, 39.6358
26.856520655, 96.390, 1541.0, 39.2556
26.909041786, 96.390, 1527.0, 39.0768
26.961562916, 96.390, 1536.0, 39.1918
27.014084047, 96.390, 1489.0, 38.5876
27.066605178, 96.390, 1528.0, 39.0896
27.119126309, 96.390, 1455.0, 38.1445
27.171647439, 96.390, 1473.0, 38.3797
27.224168570, 96.390, 1459.0, 38.1969
27.276689701, 96.390, 1522.0, 39.0128
27.329210831, 96.390, 1527.0, 39.0768
27.381731962, 96.390, 1538.0, 39.2173
27.434253093, 96.390, 1464.0, 38.2623
27.486774224, 96.390, 1481.0, 38.4838
27.539295354, 96.390, 1534.0, 39.1663
27.591816485, 96.390, 1514.0, 38.9102
27.644337616, 96.390, 1482.0, 38.4968
27.696858746, 96.390, 1547.0, 39.3319
27.749379877, 96.390, 1475.0, 38.4057
27.801901008, 96.390, 1427.0, 37.7757
27.854422139, 96.390, 1407.0, 37.5100
27.906943269, 96.390, 1428.0, 37.7889
27.959464400, 96.390, 1438.0, 37.9210
28.011985531, 96.390, 1430.0, 37.8153
28.064506661, 96.390, 1393.0, 37.3229
28.117027792, 96.390, 1415.0, 37.6165
28.169548923, 96.390, 1531.0, 39.1280
28.222070054, 96.390, 1507.0, 38.8201
28.274591184, 96.390, 1496.0, 38.6782
28.327112315, 96.390, 1428.0, 37.7889
28.379633446, 96.390, 1508.0, 38.8330
28.432154576, 96.390, 1492.0, 38.6264
28.484675707, 96.390, 1365.0, 36.9459
28.537196838, 96.390, 1392.0, 37.3095
28.589717968, 96.390, 1385.0, 37.2156
28.642239099, 96.390, 1382.0, 37.1753
28.694760230, 96.390, 1407.0, 37.5100
28.747281361, 96.390, 1410.0, 37.5500
28.799802491, 96.390, 1386.0, 37.2290
28.852323622, 96.390, 1404.0, 37.4700
28.904844753, 96.390, 1428.0, 37.7889
28.957365883, 96.390, 1436.0, 37.8946
29.009887014, 96.390, 1511.0, 38.8716
29.062408145, 96.390, 1451.0, 38.0920
29.114929276, 96.390, 1415.0, 37.6165
29.167450406, 96.390, 1476.0, 38.4187
29.219971537, 96.390, 1510.0, 38.8587
29.272492668, 96.390, 1471.0, 38.3536
29.325013798, 96.390, 1339.0, 36.5923
29.377534929, 96.390, 1443.0, 37.9868
29.430056060, 96.390, 1453.0, 38.1182
29.482577191, 96.390, 1373.0, 37.0540
29.535098321, 96.390, 1420.0, 37.6829
29.587619452, 96.390, 1380.0, 37.1484
29.640140583, 96.390, 1396.0, 37.3631
29.692661713, 96.390, 1384.0, 37.2022
29.745182844, 96.390, 1389.0, 37.2693
29.797703975, 96.390, 1492.0, 38.6264
29.850225105, 96.390, 1408.0, 37.5233
29.902746236, 96.390, 1381.0, 37.1618
29.955267367, 96.390, 1418.0, 37.6563
30.007788498, 96.390, 1419.0, 37.6696
30.060309628, 96.390, 1385.0, 37.2156
30.112830759, 96.390, 1371.0, 37.0270
30.165351890, 96.390, 1390.0, 37.2827
30.217873020, 96.390, 1436.0, 37.8946
30.270394151, 96.390, 1422.0, 37.7094
30.322915282, 96.390, 1444.0, 38.0000
30.375436413, 96.390, 1408.0, 37.5233
30.427957543, 96.390, 1448.0, 38.0526
30.480478674, 96.390, 1482.0, 38.4968
30.532999805, 96.390, 1422.0, 37.7094
30.585520935, 96.390, 1465.0, 38.2753
30.638042066, 96.390, 1487.0, 38.5616
30.690563197, 96.390, 1703.0, 41.2674
30.743084328, 96.390, 1540.0, 39.2428
30.795605458, 96.390, 1499.0, 38.7169
30.848126589, 96.390, 1452.0, 38.1051
30.900647720, 96.390, 1399.0, 37.4032
30.953168850, 96.390, 1497.0, 38.6911
31.005689981, 96.390, 1478.0, 38.4448
31.058211112, 96.390, 1590.0, 39.8748
31.110732243, 96.390, 1636.0, 40.4475
31.163253373, 96.390, 1591.0, 39.8873
31.215774504, 96.390, 1492.0, 38.6264
31.268295635, 96.390, 1452.0, 38.1051
31.320816765, 96.390, 1378.0, 37.1214
31.373337896, 96.390, 1461.0, 38.2230
31.425859027, 96.390, 1441.0, 37.9605
31.478380157, 96.390, 1407.0, 37.5100
31.530901288, 96.390, 1356.0, 36.8239
31.583422419, 96.390, 1437.0, 37.9078
31.635943550, 96.390, 1476.0, 38.4187
31.688464680, 96.390, 1545.0, 39.3065
31.740985811, 96.390, 1452.0, 38.1051
31.793506942, 96.390, 1392.0, 37.3095
31.846028072, 96.390, 1405.0, 37.4833
31.898549203, 96.390, 1457.0, 38.1707
31.951070334, 96.390, 1405.0, 37.4833
32.003591465, 96.390, 1413.0, 37.5899
32.056112595, 96.390, 1402.0, 37.4433
32.108633726, 96.390, 1429.0, 37.8021
32.161154857, 96.390, 1347.0, 36.7015
32.213675987, 96.390, 1394.0, 37.3363
32.266197118, 96.390, 1402.0, 37.4433
32.318718249, 96.390, 1385.0, 37.2156
32.371239380, 96.390, 1394.0, 37.3363
32.423760510, 96.390, 1440.0, 37.9473
32.476281641, 96.390, 1477.0, 38.4318
32.528802772, 96.390, 1443.0, 37.9868
32.581323902, 96.390, 1369.0, 37.0000
32.633845033, 96.390, 1417.0, 37.6431
32.686366164, 96.390, 1432.0, 37.8418
32.738887295, 96.390, 1461.0, 38.2230
32.791408425, 96.390, 1420.0, 37.6829
32.843929556, 96.390, 1409.0, 37.5366
32.896450687, 96.390, 1454.0, 38.1314
32.948971817, 96.390, 1585.0, 39.8121
33.001492948, 96.390, 1594.0, 39.9249
33.054014079, 96.390, 1646.0, 40.5709
33.106535209, 96.390, 1777.0, 42.1545
33.159056340, 96.390, 1626.0, 40.3237
33.211577471, 96.390, 1632.0, 40.3980
33.264098602, 96.390, 1690.0, 41.1096
33.316619732, 96.390, 1695.0, 41.1704
33.369140863, 96.390, 1750.0, 41.8330
33.421661994, 96.390, 2032.0, 45.0777
33.474183124, 96.390, 1941.0, 44.0568
33.526704255, 96.390, 1869.0, 43.2319
33.579225386, 96.390, 1781.0, 42.2019
33.631746517, 96.390, 1707.0, 41.3159
33.684267647, 96.390, 1824.0, 42.7083
33.736788778, 96.390, 1835.0, 42.8369
33.789309909, 96.390, 1978.0, 44.4747
33.841831039, 96.390, 1984.0, 44.5421
33.894352170, 96.390, 2109.0, 45.9239
33.946873301, 96.390, 2132.0, 46.1736
33.999394432, 96.390, 2195.0, 46.8508
34.051915562, 96.390, 2206.0, 46.9681
34.104436693, 96.390, 2229.0, 47.2123
34.156957824, 96.390, 2279.0, 47.7389
34.209478954, 96.390, 2280.0, 47.7493
34.262000085, 96.390, 2251.0, 47.4447
34.314521216, 96.390, 2503.0, 50.0300
34.367042346, 96.390, 2423.0, 49.2240
34.419563477, 96.390, 2550.0, 50.4975
34.472084608, 96.390, 2498.0, 49.9800
34.524605739, 96.390, 2548.0, 50.4777
34.577126869, 96.390, 2612.0, 51.1077
34.629648000, 96.390, 2599.0, 50.9804
34.682169131, 96.390, 2591.0, 50.9019
34.734690261, 96.390, 2646.0, 51.4393
34.787211392, 96.390, 2562.0, 50.6162
34.839732523, 96.390, 2494.0, 49.9400
34.892253654, 96.390, 2519.0, 50.1896
34.944774784, 96.390, 2508.0, 50.0799
34.997295915, 96.390, 2617.0, 51.1566
35.049817046, 96.390, 2417.0, 49.1630
35.102338176, 96.390, 2356.0, 48.5386
35.154859307, 96.390, 2401.0, 49.0000
35.207380438, 96.390, 2354.0, 48.5180
35.259901569, 96.390, 2312.0, 48.0833
35.312422699, 96.390, 2225.0, 47.1699
35.364943830, 96.390, 2226.0, 47.1805
35.417464961, 96.390, 2216.0, 47.0744
35.469986091, 96.390, 2198.0, 46.8828
35.522507222, 96.390, 2148.0, 46.3465
35.575028353, 96.390, 2112.0, 45.9565
35.627549484, 96.390, 2138.0, 46.2385
35.680070614, 96.390, 2198.0, 46.8828
35.732591745, 96.390, 2114.0, 45.9783
35.785112876, 96.390, 2076.0, 45.5631
35.837634006, 96.390, 2085.0, 45.6618
35.890155137, 96.390, 2096.0, 45.7821
35.942676268, 96.390, 2160.0, 46.4758
35.995197398, 96.390, 2183.0, 46.7226
36.047718529, 96.390, 2046.0, 45.2327
36.100239660, 96.390, 2003.0, 44.7549
36.152760791, 96.390, 1970.0, 44.3847
36.205281921, 96.390, 1969.0, 44.3734
36.257803052, 96.390, 1963.0, 44.3058
36.310324183, 96.390, 2004.0, 44.7661
36.362845313, 96.390, 2138.0, 46.2385
36.415366444, 96.390, 1946.0, 44.1135
36.467887575, 96.390, 1913.0, 43.7379
36.520408706, 96.390, 1983.0, 44.5309
36.572929836, 96.390, 1915.0, 43.7607
36.625450967, 96.390, 1972.0, 44.4072
36.677972098, 96.390, 1865.0, 43.1856
36.730493228, 96.390, 1872.0, 43.2666
36.783014359, 96.390, 1880.0, 43.3590
36.835535490, 96.390, 1793.0, 42.3438
36.888056621, 96.390, 1873.0, 43.2782
36.940577751, 96.390, 1867.0, 43.2088
36.993098882, 96.390, 1838.0, 42.8719
37.045620013, 96.390, 1812.0, 42.5676
37.098141143, 96.390, 1798.0, 42.4028
37.150662274, 96.390, 1748.0, 41.8091
37.203183405, 96.390, 1812.0, 42.5676
37.255704535, 96.390, 1717.0, 41.4367
37.308225666, 96.390, 1767.0, 42.0357
37.360746797, 96.390, 1781.0, 42.2019
37.413267928, 96.390, 1807.0, 42.5088
37.465789058, 96.390, 1717.0, 41.4367
37.518310189, 96.390, 1732.0, 41.6173
37.570831320, 96.390, 1638.0, 40.4722
37.623352450, 96.390, 1750.0, 41.8330
37.675873581, 96.390, 1781.0, 42.2019
37.728394712, 96.390, 1784.0, 42.2374
37.780915843, 96.390, 1884.0, 43.4051
37.833436973, 96.390, 1789.0, 42.2966
37.885958104, 96.390, 1687.0, 41.0731
37.938479235, 96.390, 1743.0, 41.7493
37.991000365, 96.390, 1731.0, 41.6053
38.043521496, 96.390, 1662.0, 40.7676
38.096042627, 96.390, 1744.0, 41.7612
38.148563758, 96.390, 1681.0, 41.0000
38.201084888, 96.390, 1710.0, 41.3521
38.253606019, 96.390, 1701.0, 41.2432
38.306127150, 96.390, 1780.0, 42.1900
38.358648280, 96.390, 1730.0, 41.5933
38.411169411, 96.390, 1709.0, 41.3401
38.463690542, 96.390, 1691.0, 41.1218
38.516211673, 96.390, 1571.0, 39.6358
38.568732803, 96.390, 1642.0, 40.5216
38.621253934, 96.390, 1650.0, 40.6202
38.673775065, 96.390, 1688.0, 41.0853
38.726296195, 96.390, 1657.0, 40.7063
38.778817326, 96.390, 1626.0, 40.3237
38.831338457, 96.390, 1704.0, 41.2795
38.883859587, 96.390, 1751.0, 41.8450
38.936380718, 96.390, 1743.0, 41.7493
38.988901849, 96.390, 1707.0, 41.3159
39.041422980, 96.390, 1690.0, 41.1096
39.093944110, 96.390, 1614.0, 40.1746
39.146465241, 96.390, 1696.0, 41.1825
39.198986372, 96.390, 1698.0, 41.2068
39.251507502, 96.390, 1701.0, 41.2432
39.304028633, 96.390, 1611.0, 40.1373
39.356549764, 96.390, 1559.0, 39.4842
39.409070895, 96.390, 1569.0, 39.6106
39.461592025, 96.390, 1517.0, 38.9487
39.514113156, 96.390, 1503.0, 38.7685
39.566634287, 96.390, 1454.0, 38.1314
39.619155417, 96.390, 1523.0, 39.0256
39.671676548, 96.390, 1488.0, 38.5746
39.724197679, 96.390, 1462.0, 38.2361
39.776718810, 96.390, 1446.0, 38.0263
39.829239940, 96.390, 1426.0, 37.7624
39.881761071, 96.390, 1396.0, 37.3631
39.934282202, 96.390, 1434.0, 37.8682
39.986803332, 96.390, 1350.0, 36.7423
40.039324463, 96.390, 1405.0, 37.4833
40.091845594, 96.390, 1450.0, 38.0789
40.144366725, 96.390, 1392.0, 37.3095
40.196887855, 96.390, 1341.0, 36.6197
40.249408986, 96.390, 1352.0, 36.7696
40.301930117, 96.390, 1412.0, 37.5766
40.354451247, 96.390, 1343.0, 36.6470
40.406972378, 96.390, 1340.0, 36.6060
40.459493509, 96.390, 1301.0, 36.0694
40.512014639, 96.390, 1289.0, 35.9026
40.564535770, 96.390, 1342.0, 36.6333
40.617056901, 96.390, 1346.0, 36.6879
40.669578032, 96.390, 1309.0, 36.1801
40.722099162, 96.390, 1326.0, 36.4143
40.774620293, 96.390, 1266.0, 35.5809
40.827141424, 96.390, 1278.0, 35.7491
40.879662554, 96.390, 1261.0, 35.5106
40.932183685, 96.390, 1241.0, 35.2278
40.984704816, 96.390, 1283.0, 35.8190
41.037225947, 96.390, 1293.0, 35.9583
41.089747077, 96.390, 1263.0, 35.5387
41.142268208, 96.390, 1222.0, 34.9571
41.194789339, 96.390, 1246.0, 35.2987
41.247310469, 96.390, 1224.0, 34.9857
41.299831600, 96.390, 1290.0, 35.9166
41.352352731, 96.390, 1219.0, 34.9142
41.404873862, 96.390, 1221.0, 34.9428
41.457394992, 96.390, 1182.0, 34.3802
41.509916123, 96.390, 1236.0, 35.1568
41.562437254, 96.390, 1265.0, 35.5668
41.614958384, 96.390, 1221.0, 34.9428
41.667479515, 96.390, 1178.0, 34.3220
41.720000646, 96.390, 1213.0, 34.8281
41.772521776, 96.390, 1206.0, 34.7275
41.825042907, 96.390, 1212.0, 34.8138
41.877564038, 96.390, 1214.0, 34.8425
41.930085169, 96.390, 1180.0, 34.3511
41.982606299, 96.390, 1222.0, 34.9571
42.035127430, 96.390, 1207.0, 34.7419
42.087648561, 96.390, 1226.0, 35.0143
42.140169691, 96.390, 1278.0, 35.7491
42.192690822, 96.390, 1353.0, 36.7831
42.245211953, 96.390, 1273.0, 35.6791
42.297733084, 96.390, 1213.0, 34.8281
42.350254214, 96.390, 1194.0, 34.5543
42.402775345, 96.390, 1231.0, 35.0856
42.455296476, 96.390, 1259.0, 35.4824
42.507817606, 96.390, 1194.0, 34.5543
42.560338737, 96.390, 1167.0, 34.1614
42.612859868, 96.390, 1148.0, 33.8821
42.665380999, 96.390, 1167.0, 34.1614
42.717902129, 96.390, 1144.0, 33.8231
42.770423260, 96.390, 1229.0, 35.0571
42.822944391, 96.390, 1193.0, 34.5398
42.875465521, 96.390, 1166.0, 34.1467
42.927986652, 96.390, 1151.0, 33.9264
42.980507783, 96.390, 1170.0, 34.2053
43.033028914, 96.390, 1146.0, 33.8526
43.085550044, 96.390, 1146.0, 33.8526
43.138071175, 96.390, 1171.0, 34.2199
43.190592306, 96.390, 1156.0, 34.0000
43.243113436, 96.390, 1130.0, 33.6155
43.295634567, 96.390, 1205.0, 34.7131
43.348155698, 96.390, 1195.0, 34.5688
43.400676828, 96.390, 1136.0, 33.7046
43.453197959, 96.390, 1213.0, 34.8281
43.505719090, 96.390, 1105.0, 33.2415
43.558240221, 96.390, 1146.0, 33.8526
43.610761351, 96.390, 1131.0, 33.6303
43.663282482, 96.390, 1197.0, 34.5977
43.715803613, 96.390, 1098.0, 33.1361
43.768324743, 96.390, 1132.0, 33.6452
43.820845874, 96.390, 1154.0, 33.9706
43.873367005, 96.390, 1155.0, 33.9853
43.925888136, 96.390, 1149.0, 33.8969
43.978409266, 96.390, 1174.0, 34.2637
44.030930397, 96.390, 1132.0, 33.6452
44.083451528, 96.390, 1121.0, 33.4813
44.135972658, 96.390, 1164.0, 34.1174
44.188493789, 96.390, 1092.0, 33.0454
44.241014920, 96.390, 1142.0, 33.7935
44.293536051, 96.390, 1147.0, 33.8674
44.346057181, 96.390, 1118.0, 33.4365
44.398578312, 96.390, 1138.0, 33.7343
44.451099443, 96.390, 1069.0, 32.6956
44.503620573, 96.390, 1149.0, 33.8969
44.556141704, 96.390, 1131.0, 33.6303
44.608662835, 96.390, 1218.0, 34.8999
44.661183966, 96.390, 1225.0, 35.0000
44.713705096, 96.390, 1188.0, 34.4674
44.766226227, 96.390, 1188.0, 34.4674
44.818747358, 96.390, 1144.0, 33.8231
44.871268488, 96.390, 1142.0, 33.7935
44.923789619, 96.390, 1072.0, 32.7414
44.976310750, 96.390, 1072.0, 32.7414
45.028831880, 96.390, 1111.0, 33.3317
45.081353011, 96.390, 1048.0, 32.3728
45.133874142, 96.390, 1115.0, 33.3916
45.186395273, 96.390, 1162.0, 34.0881
45.238916403, 96.390, 1060.0, 32.5576
45.291437534, 96.390, 1134.0, 33.6749
45.343958665, 96.390, 1142.0, 33.7935
45.396479795, 96.390, 1192.0, 34.5254
45.449000926, 96.390, 1114.0, 33.3766
45.501522057, 96.390, 1086.0, 32.9545
45.554043188, 96.390, 1089.0, 33.0000
45.606564318, 96.390, 1187.0, 34.4529
45.659085449, 96.390, 1139.0, 33.7491
45.711606580, 96.390, 1119.0, 33.4515
45.764127710, 96.390, 1126.0, 33.5559
45.816648841, 96.390, 1106.0, 33.2566
45.869169972, 96.390, 1134.0, 33.6749
45.921691103, 96.390, 1178.0, 34.3220
45.974212233, 96.390, 1130.0, 33.6155
46.026733364, 96.390, 1156.0, 34.0000
46.079254495, 96.390, 1161.0, 34.0735
46.131775625, 96.390, 1195.0, 34.5688
46.184296756, 96.390, 1214.0, 34.8425
46.236817887, 96.390, 1137.0, 33.7194
46.289339017, 96.390, 1143.0, 33.8083
46.341860148, 96.390, 1152.0, 33.9411
46.394381279, 96.390, 1118.0, 33.4365
46.446902410, 96.390, 1032.0, 32.1248
46.499423540, 96.390, 1106.0, 33.2566
46.551944671, 96.390, 1107.0, 33.2716
46.604465802, 96.390, 1093.0, 33.0606
46.656986932, 96.390, 1134.0, 33.6749
46.709508063, 96.390, 1090.0, 33.0151
46.762029194, 96.390, 1114.0, 33.3766
46.814550325, 96.390, 1056.0, 32.4962
46.867071455, 96.390, 1012.0, 31.8119
46.919592586, 96.390, 1040.0, 32.2490
46.972113717, 96.390, 1016.0, 31.8748
47.024634847, 96.390, 972.0, 31.1769
47.077155978, 96.390, 997.0, 31.5753
47.129677109, 96.390, 961.0, 31.0000
47.182198240, 96.390, 1016.0, 31.8748
47.234719370, 96.390, 986.0, 31.4006
47.287240501, 96.390, 976.0, 31.2410
47.339761632, 96.390, 928.0, 30.4631
47.392282762, 96.390, 963.0, 31.0322
47.444803893, 96.390, 923.0, 30.3809
47.497325024, 96.390, 940.0, 30.6594
47.549846155, 96.390, 939.0, 30.6431
47.602367285, 96.390, 914.0, 30.2324
47.654888416, 96.390, 948.0, 30.7896
47.707409547, 96.390, 881.0, 29.6816
47.759930677, 96.390, 940.0, 30.6594
47.812451808, 96.390, 939.0, 30.6431
47.864972939, 96.390, 946.0, 30.7571
47.917494069, 96.390, 880.0, 29.6648
47.970015200, 96.390, 966.0, 31.0805
48.022536331, 96.390, 932.0, 30.5287
48.075057462, 96.390, 883.0, 29.7153
48.127578592, 96.390, 876.0, 29.5973
48.180099723, 96.390, 942.0, 30.6920
48.232620854, 96.390, 901.0, 30.0167
48.285141984, 96.390, 836.0, 28.9137
48.337663115, 96.390, 891.0, 29.8496
48.390184246, 96.390, 901.0, 30.0167
48.442705377, 96.390, 954.0, 30.8869
48.495226507, 96.390, 878.0, 29.6311
48.547747638, 96.390, 921.0, 30.3480
48.600268769, 96.390, 862.0, 29.3598
48.652789899, 96.390, 855.0, 29.2404
48.705311030, 96.390, 875.0, 29.5804
48.757832161, 96.390, 908.0, 30.1330
48.810353292, 96.390, 855.0, 29.2404
48.862874422, 96.390, 814.0, 28.5307
48.915395553, 96.390, 856.0, 29.2575
48.967916684, 96.390, 857.0, 29.2746
49.020437814, 96.390, 870.0, 29.4958
49.072958945, 96.390, 900.0, 30.0000
49.125480076, 96.390, 779.0, 27.9106
49.178001207, 96.390, 842.0, 29.0172
49.230522337, 96.390, 875.0, 29.5804
49.283043468, 96.390, 815.0, 28.5482
49.335564599, 96.390, 885.0, 29.7489
49.388085729, 96.390, 866.0, 29.4279
49.440606860, 96.390, 868.0, 29.4618
49.493127991, 96.390, 822.0, 28.6705
49.545649121, 96.390, 849.0, 29.1376
49.598170252, 96.390, 844.0, 29.0517
49.650691383, 96.390, 873.0, 29.5466
49.703212514, 96.390, 842.0, 29.0172
49.755733644, 96.390, 850.0, 29.1548
49.808254775, 96.390, 807.0, 28.4077
49.860775906, 96.390, 808.0, 28.4253
49.913297036, 96.390, 797.0, 28.2312
49.965818167, 96.390, 757.0, 27.5136
50.018339298, 96.390, 794.0, 28.1780
50.070860429, 96.390, 837.0, 28.9310
50.123381559, 96.390, 817.0, 28.5832
50.175902690, 96.390, 845.0, 29.0689
50.228423821, 96.390, 776.0, 27.8568
50.280944951, 96.390, 798.0, 28.2489
50.333466082, 96.390, 856.0, 29.2575
50.385987213, 96.390, 808.0, 28.4253
50.438508344, 96.390, 783.0, 27.9821
50.491029474, 96.390, 783.0, 27.9821
50.543550605, 96.390, 754.0, 27.4591
50.596071736, 96.390, 774.0, 27.8209
50.648592866, 96.390, 762.0, 27.6043
50.701113997, 96.390, 792.0, 28.1425
50.753635128, 96.390, 822.0, 28.6705
50.806156258, 96.390, 823.0, 28.6880
50.858677389, 96.390, 842.0, 29.0172
50.911198520, 96.390, 752.0, 27.4226
50.963719651, 96.390, 761.0, 27.5862
51.016240781, 96.390, 807.0, 28.4077
51.068761912, 96.390, 785.0, 28.0179
51.121283043, 96.390, 748.0, 27.3496
51.173804173, 96.390, 803.0, 28.3373
51.226325304, 96.390, 762.0, 27.6043
51.278846435, 96.390, 737.0, 27.1477
51.331367566, 96.390, 749.0, 27.3679
51.383888696, 96.390, 753.0, 27.4408
51.436409827, 96.390, 753.0, 27.4408
51.488930958, 96.390, 778.0, 27.8927
51.541452088, 96.390, 772.0, 27.7849
51.593973219, 96.390, 780.0, 27.9285
51.646494350, 96.390, 784.0, 28.0000
51.699015481, 96.390, 774.0, 27.8209
51.751536611, 96.390, 746.0, 27.3130
51.804057742, 96.390, 760.0, 27.5681
51.856578873, 96.390, 776.0, 27.8568
51.909100003, 96.390, 743.0, 27.2580
51.961621134, 96.390, 817.0, 28.5832
52.014142265, 96.390, 742.0, 27.2397
52.066663396, 96.390, 702.0, 26.4953
52.119184526, 96.390, 821.0, 28.6531
52.171705657, 96.390, 792.0, 28.1425
52.224226788, 96.390, 770.0, 27.7489
52.276747918, 96.390, 798.0, 28.2489
52.329269049, 96.390, 792.0, 28.1425
52.381790180, 96.390, 769.0, 27.7308
52.434311310, 96.390, 812.0, 28.4956
52.486832441, 96.390, 821.0, 28.6531
52.539353572, 96.390, 819.0, 28.6182
52.591874703, 96.390, 779.0, 27.9106
52.644395833, 96.390, 821.0, 28.6531
52.696916964, 96.390, 793.0, 28.1603
52.749438095, 96.390, 810.0, 28.4605
52.801959225, 96.390, 759.0, 27.5500
52.854480356, 96.390, 805.0, 28.3725
52.907001487, 96.390, 744.0, 27.2764
52.959522618, 96.390, 770.0, 27.7489
53.012043748, 96.390, 724.0, 26.9072
53.064564879, 96.390, 754.0, 27.4591
53.117086010, 96.390, 802.0, 28.3196
53.169607140, 96.390, 779.0, 27.9106
53.222128271, 96.390, 754.0, 27.4591
53.274649402, 96.390, 769.0, 27.7308
53.327170533, 96.390, 817.0, 28.5832
53.379691663, 96.390, 772.0, 27.7849
53.432212794, 96.390, 719.0, 26.8142
53.484733925, 96.390, 703.0, 26.5141
53.537255055, 96.390, 795.0, 28.1957
53.589776186, 96.390, 712.0, 26.6833
53.642297317, 96.390, 806.0, 28.3901
53.694818448, 96.390, 692.0, 26.3059
53.747339578, 96.390, 769.0, 27.7308
53.799860709, 96.390, 736.0, 27.1293
53.852381840, 96.390, 713.0, 26.7021
53.904902970, 96.390, 793.0, 28.1603
53.957424101, 96.390, 721.0, 26.8514
54.009945232, 96.390, 763.0, 27.6225
54.062466362, 96.390, 810.0, 28.4605
54.114987493, 96.390, 764.0, 27.6405
54.167508624, 96.390, 714.0, 26.7208
54.220029755, 96.390, 769.0, 27.7308
54.272550885, 96.390, 798.0, 28.2489
54.325072016, 96.390, 727.0, 26.9629
54.377593147, 96.390, 701.0, 26.4764
54.430114277, 96.390, 740.0, 27.2029
54.482635408, 96.390, 710.0, 26.6458
54.535156539, 96.390, 741.0, 27.2213
54.587677670, 96.390, 760.0, 27.5681
54.640198800, 96.390, 735.0, 27.1109
54.692719931, 96.390, 745.0, 27.2947
54.745241062, 96.390, 695.0, 26.3629
54.797762192, 96.390, 751.0, 27.4044
54.850283323, 96.390, 754.0, 27.4591
54.902804454, 96.390, 761.0, 27.5862
54.955325585, 96.390, 719.0, 26.8142
55.007846715, 96.390, 753.0, 27.4408
55.060367846, 96.390, 712.0, 26.6833
55.112888977, 96.390, 699.0, 26.4386
55.165410107, 96.390, 735.0, 27.1109
55.217931238, 96.390, 709.0, 26.6271
55.270452369, 96.390, 758.0, 27.5318
55.322973499, 96.390, 752.0, 27.4226
55.375494630, 96.390, 781.0, 27.9464
55.428015761, 96.390, 718.0, 26.7955
55.480536892, 96.390, 739.0, 27.1846
55.533058022, 96.390, 692.0, 26.3059
55.585579153, 96.390, 712.0, 26.6833
55.638100284, 96.390, 711.0, 26.6646
55.690621414, 96.390, 717.0, 26.7769
55.743142545, 96.390, 692.0, 26.3059
55.795663676, 96.390, 738.0, 27.1662
55.848184807, 96.390, 689.0, 26.2488
55.900705937, 96.390, 705.0, 26.5518
55.953227068, 96.390, 698.0, 26.4197
56.005748199, 96.390, 681.0, 26.0960
56.058269329, 96.390, 742.0, 27.2397
56.110790460, 96.390, 671.0, 25.9037
56.163311591, 96.390, 655.0, 25.5930
56.215832722, 96.390, 703.0, 26.5141
56.268353852, 96.390, 707.0, 26.5895
56.320874983, 96.390, 691.0, 26.2869
56.373396114, 96.390, 678.0, 26.0384
56.425917244, 96.390, 693.0, 26.3249
56.478438375, 96.390, 644.0, 25.3772
56.530959506, 96.390, 688.0, 26.2298
56.583480637, 96.390, 709.0, 26.6271
56.636001767, 96.390, 636.0, 25.2190
56.688522898, 96.390, 663.0, 25.7488
56.741044029, 96.390, 690.0, 26.2679
56.793565159, 96.390, 693.0, 26.3249
56.846086290, 96.390, 632.0, 25.1396
56.898607421, 96.390, 696.0, 26.3818
56.951128551, 96.390, 707.0, 26.5895
57.003649682, 96.390, 707.0, 26.5895
57.056170813, 96.390, 717.0, 26.7769
57.108691944, 96.390, 748.0, 27.3496
57.161213074, 96.390, 691.0, 26.2869
57.213734205, 96.390, 698.0, 26.4197
57.266255336, 96.390, 669.0, 25.8650
57.318776466, 96.390, 692.0, 26.3059
57.371297597, 96.390, 702.0, 26.4953
57.423818728, 96.390, 686.0, 26.1916
57.476339859, 96.390, 722.0, 26.8701
57.528860989, 96.390, 680.0, 26.0768
57.581382120, 96.390, 733.0, 27.0740
57.633903251, 96.390, 756.0, 27.4955
57.686424381, 96.390, 735.0, 27.1109
57.738945512, 96.390, 737.0, 27.1477
57.791466643, 96.390, 731.0, 27.0370
57.843987774, 96.390, 763.0, 27.6225
57.896508904, 96.390, 706.0, 26.5707
57.949030035, 96.390, 663.0, 25.7488
58.001551166, 96.390, 716.0, 26.7582
58.054072296, 96.390, 715.0, 26.7395
58.106593427, 96.390, 691.0, 26.2869
58.159114558, 96.390, 713.0, 26.7021
58.211635689, 96.390, 749.0, 27.3679
58.264156819, 96.390, 697.0, 26.4008
58.316677950, 96.390, 760.0, 27.5681
58.369199081, 96.390, 795.0, 28.1957
58.421720211, 96.390, 713.0, 26.7021
58.474241342, 96.390, 738.0, 27.1662
58.526762473, 96.390, 796.0, 28.2135
58.579283603, 96.390, 758.0, 27.5318
58.631804734, 96.390, 810.0, 28.4605
58.684325865, 96.390, 823.0, 28.6880
58.736846996, 96.390, 788.0, 28.0713
58.789368126, 96.390, 833.0, 28.8617
58.841889257, 96.390, 815.0, 28.5482
58.894410388, 96.390, 800.0, 28.2843
58.946931518, 96.390, 860.0, 29.3258
58.999452649, 96.390, 879.0, 29.6479
59.051973780, 96.390, 845.0, 29.0689
59.104494911, 96.390, 840.0, 28.9828
59.157016041, 96.390, 976.0, 31.2410
59.209537172, 96.390, 903.0, 30.0500
59.262058303, 96.390, 955.0, 30.9031
59.314579433, 96.390, 991.0, 31.4802
59.367100564, 96.390, 1008.0, 31.7490
59.419621695, 96.390, 1021.0, 31.9531
59.472142826, 96.390, 1094.0, 33.0757
59.524663956, 96.390, 1109.0, 33.3017
59.577185087, 96.390, 1116.0, 33.4066
59.629706218, 96.390, 1149.0, 33.8969
59.682227348, 96.390, 1229.0, 35.0571
59.734748479, 96.390, 1277.0, 35.7351
59.787269610, 96.390, 1251.0, 35.3695
59.839790740, 96.390, 1272.0, 35.6651
59.892311871, 96.390, 1295.0, 35.9861
59.944833002, 96.390, 1312.0, 36.2215
59.997354133, 96.390, 1337.0, 36.5650
60.049875263, 96.390, 1480.0, 38.4708
60.102396394, 96.390, 1509.0, 38.8458
60.154917525, 96.390, 1489.0, 38.5876
60.207438655, 96.390, 1526.0, 39.0640
60.259959786, 96.390, 1452.0, 38.1051
60.312480917, 96.390, 1593.0, 39.9124
60.365002048, 96.390, 1495.0, 38.6652
60.417523178, 96.390, 1621.0, 40.2616
60.470044309, 96.390, 1537.0, 39.2046
60.522565440, 96.390, 1463.0, 38.2492
60.575086570, 96.390, 1532.0, 39.1408
60.627607701, 96.390, 1406.0, 37.4967
60.680128832, 96.390, 1338.0, 36.5787
60.732649963, 96.390, 1389.0, 37.2693
60.785171093, 96.390, 1357.0, 36.8375
60.837692224, 96.390, 1303.0, 36.0971
60.890213355, 96.390, 1284.0, 35.8329
60.942734485, 96.390, 1318.0, 36.3043
60.995255616, 96.390, 1233.0, 35.1141
61.047776747, 96.390, 1246.0, 35.2987
61.100297878, 96.390, 1258.0, 35.4683
61.152819008, 96.390, 1182.0, 34.3802
61.205340139, 96.390, 1188.0, 34.4674
61.257861270, 96.390, 1148.0, 33.8821
61.310382400, 96.390, 1142.0, 33.7935
61.362903531, 96.390, 1128.0, 33.5857
61.415424662, 96.390, 1152.0, 33.9411
61.467945792, 96.390, 1073.0, 32.7567
61.520466923, 96.390, 1058.0, 32.5269
61.572988054, 96.390, 1125.0, 33.5410
61.625509185, 96.390, 1097.0, 33.1210
61.678030315, 96.390, 1061.0, 32.5730
61.730551446, 96.390, 1058.0, 32.5269
61.783072577, 96.390, 1005.0, 31.7017
61.835593707, 96.390, 1005.0, 31.7017
61.888114838, 96.390, 1003.0, 31.6702
61.940635969, 96.390, 962.0, 31.0161
61.993157100, 96.390, 942.0, 30.6920
62.045678230, 96.390, 970.0, 31.1448
62.098199361, 96.390, 893.0, 29.8831
62.150720492, 96.390, 884.0, 29.7321
62.203241622, 96.390, 857.0, 29.2746
62.255762753, 96.390, 855.0, 29.2404
62.308283884, 96.390, 822.0, 28.6705
62.360805015, 96.390, 851.0, 29.1719
62.413326145, 96.390, 811.0, 28.4781
62.465847276, 96.390, 815.0, 28.5482
62.518368407, 96.390, 758.0, 27.5318
62.570889537, 96.390, 785.0, 28.0179
62.623410668, 96.390, 769.0, 27.7308
62.675931799, 96.390, 734.0, 27.0924
62.728452930, 96.390, 721.0, 26.8514
62.780974060, 96.390, 748.0, 27.3496
62.833495191, 96.390, 765.0, 27.6586
62.886016322, 96.390, 763.0, 27.6225
62.938537452, 96.390, 721.0, 26.8514
62.991058583, 96.390, 656.0, 25.6125
63.043579714, 96.390, 703.0, 26.5141
63.096100844, 96.390, 685.0, 26.1725
63.148621975, 96.390, 660.0, 25.6905
63.201143106, 96.390, 732.0, 27.0555
63.253664237, 96.390, 710.0, 26.6458
63.306185367, 96.390, 695.0, 26.3629
63.358706498, 96.390, 649.0, 25.4755
63.411227629, 96.390, 661.0, 25.7099
63.463748759, 96.390, 655.0, 25.5930
63.516269890, 96.390, 677.0, 26.0192
63.568791021, 96.390, 664.0, 25.7682
63.621312152, 96.390, 663.0, 25.7488
63.673833282, 96.390, 639.0, 25.2784
63.726354413, 96.390, 601.0, 24.5153
63.778875544, 96.390, 645.0, 25.3969
63.831396674, 96.390, 641.0, 25.3180
63.883917805, 96.390, 646.0, 25.4165
63.936438936, 96.390, 651.0, 25.5147
63.988960067, 96.390, 671.0, 25.9037
64.041481197, 96.390, 596.0, 24.4131
64.094002328, 96.390, 668.0, 25.8457
64.146523459, 96.390, 605.0, 24.5967
64.199044589, 96.390, 607.0, 24.6374
64.251565720, 96.390, 623.0, 24.9600
64.304086851, 96.390, 551.0, 23.4734
64.356607981, 96.390, 605.0, 24.5967
64.409129112, 96.390, 619.0, 24.8797
64.461650243, 96.390, 668.0, 25.8457
64.514171374, 96.390, 604.0, 24.5764
64.566692504, 96.390, 638.0, 25.2587
64.619213635, 96.390, 571.0, 23.8956
64.671734766, 96.390, 608.0, 24.6577
64.724255896, 96.390, 577.0, 24.0208
64.776777027, 96.390, 579.0, 24.0624
64.829298158, 96.390, 618.0, 24.8596
64.881819289, 96.390, 574.0, 23.9583
64.934340419, 96.390, 625.0, 25.0000
64.986861550, 96.390, 616.0, 24.8193