File: Files_organized_for_plots/134_days/G_XRD_148_PO4Free14Apr22_Act16Nov22_B1_1000M_NaOH_LS0133.csv
[Measurement conditions]
Sample identification,148_PO4Free14Apr22_Act16Nov22_B1_1000M_NaOH_LS0133
Comment - 1,"Configuration=Stage for Flat Samples/Holders, Owner=User-1, Creation date=7/1/2020 9:53:24 AM"
Comment - 2,"Goniometer=Theta/Theta; Minimum step size 2Theta:0.0001; Minimum step size Omega:0.0001"
Comment - 3,"Sample stage=Stage for flat samples/holders"
Comment - 4,"Diffractometer system=EMPYREAN"
Comment - 5,"Measurement program=C:\Users\tmr79\OneDrive - The Pennsylvania State University\Documents\NEUP\XRD\Cement\Zerobackground scan.xrdmp, Identifier={98A3B11C-88F9-4AA6-982C-73314A311EF5}"
Anode material,Cu
K-Alpha1 wavelength,1.5405980
K-Alpha2 wavelength,1.5444260
Ratio K-Alpha2/K-Alpha1,0.500
Divergence slit,Fixed,0.25
Monochromator used,NO
Generator voltage, 45
Tube current, 40
File date and time,03/Apr/2023 11:55
Unit cell,
h k l, 0 0 0
Scan axis,Gonio
Scan range,4.994599997,64.999991833
Scan step size,0.0262606
No. of points, 2285
Scan type,CONTINUOUS
Time per step,96.390
[Scan points]
Angle, TimePerStep, Intensity, ESD
5.007730280, 96.390, 4997.0, 70.6895
5.060251411, 96.390, 4941.0, 70.2922
5.112772541, 96.390, 4981.0, 70.5762
5.165293672, 96.390, 4776.0, 69.1086
5.217814803, 96.390, 4891.0, 69.9357
5.270335934, 96.390, 4612.0, 67.9117
5.322857064, 96.390, 4621.0, 67.9779
5.375378195, 96.390, 4582.0, 67.6905
5.427899326, 96.390, 4597.0, 67.8012
5.480420456, 96.390, 4474.0, 66.8880
5.532941587, 96.390, 4368.0, 66.0908
5.585462718, 96.390, 4453.0, 66.7308
5.637983849, 96.390, 4344.0, 65.9090
5.690504979, 96.390, 4330.0, 65.8027
5.743026110, 96.390, 4210.0, 64.8845
5.795547241, 96.390, 4007.0, 63.3009
5.848068371, 96.390, 4136.0, 64.3117
5.900589502, 96.390, 4178.0, 64.6375
5.953110633, 96.390, 4188.0, 64.7148
6.005631763, 96.390, 4209.0, 64.8768
6.058152894, 96.390, 4072.0, 63.8122
6.110674025, 96.390, 4012.0, 63.3404
6.163195156, 96.390, 3905.0, 62.4900
6.215716286, 96.390, 3916.0, 62.5780
6.268237417, 96.390, 3861.0, 62.1369
6.320758548, 96.390, 3850.0, 62.0484
6.373279678, 96.390, 3797.0, 61.6198
6.425800809, 96.390, 3956.0, 62.8967
6.478321940, 96.390, 3845.0, 62.0081
6.530843071, 96.390, 3777.0, 61.4573
6.583364201, 96.390, 3756.0, 61.2862
6.635885332, 96.390, 3890.0, 62.3699
6.688406463, 96.390, 3738.0, 61.1392
6.740927593, 96.390, 3690.0, 60.7454
6.793448724, 96.390, 3636.0, 60.2993
6.845969855, 96.390, 3636.0, 60.2993
6.898490986, 96.390, 3598.0, 59.9833
6.951012116, 96.390, 3637.0, 60.3075
7.003533247, 96.390, 3550.0, 59.5819
7.056054378, 96.390, 3528.0, 59.3970
7.108575508, 96.390, 3623.0, 60.1914
7.161096639, 96.390, 3546.0, 59.5483
7.213617770, 96.390, 3426.0, 58.5320
7.266138900, 96.390, 3510.0, 59.2453
7.318660031, 96.390, 3495.0, 59.1185
7.371181162, 96.390, 3498.0, 59.1439
7.423702293, 96.390, 3472.0, 58.9237
7.476223423, 96.390, 3295.0, 57.4021
7.528744554, 96.390, 3419.0, 58.4722
7.581265685, 96.390, 3317.0, 57.5934
7.633786815, 96.390, 3458.0, 58.8048
7.686307946, 96.390, 3313.0, 57.5587
7.738829077, 96.390, 3365.0, 58.0086
7.791350208, 96.390, 3362.0, 57.9828
7.843871338, 96.390, 3320.0, 57.6194
7.896392469, 96.390, 3311.0, 57.5413
7.948913600, 96.390, 3376.0, 58.1034
8.001434730, 96.390, 3286.0, 57.3236
8.053955861, 96.390, 3313.0, 57.5587
8.106476992, 96.390, 3298.0, 57.4282
8.158998123, 96.390, 3223.0, 56.7715
8.211519253, 96.390, 3133.0, 55.9732
8.264040384, 96.390, 3129.0, 55.9375
8.316561515, 96.390, 3183.0, 56.4181
8.369082645, 96.390, 3280.0, 57.2713
8.421603776, 96.390, 3119.0, 55.8480
8.474124907, 96.390, 3118.0, 55.8391
8.526646038, 96.390, 3206.0, 56.6216
8.579167168, 96.390, 3085.0, 55.5428
8.631688299, 96.390, 3151.0, 56.1338
8.684209430, 96.390, 3158.0, 56.1961
8.736730560, 96.390, 3052.0, 55.2449
8.789251691, 96.390, 3140.0, 56.0357
8.841772822, 96.390, 3079.0, 55.4887
8.894293952, 96.390, 3170.0, 56.3028
8.946815083, 96.390, 3129.0, 55.9375
8.999336214, 96.390, 3036.0, 55.0999
9.051857345, 96.390, 3111.0, 55.7763
9.104378475, 96.390, 3066.0, 55.3715
9.156899606, 96.390, 3029.0, 55.0364
9.209420737, 96.390, 3051.0, 55.2359
9.261941867, 96.390, 3131.0, 55.9553
9.314462998, 96.390, 3137.0, 56.0089
9.366984129, 96.390, 3062.0, 55.3353
9.419505260, 96.390, 2999.0, 54.7631
9.472026390, 96.390, 3058.0, 55.2992
9.524547521, 96.390, 3100.0, 55.6776
9.577068652, 96.390, 3075.0, 55.4527
9.629589782, 96.390, 3148.0, 56.1070
9.682110913, 96.390, 3148.0, 56.1070
9.734632044, 96.390, 3036.0, 55.0999
9.787153175, 96.390, 3135.0, 55.9911
9.839674305, 96.390, 3105.0, 55.7225
9.892195436, 96.390, 3096.0, 55.6417
9.944716567, 96.390, 3081.0, 55.5068
9.997237697, 96.390, 3058.0, 55.2992
10.049758828, 96.390, 3105.0, 55.7225
10.102279959, 96.390, 3052.0, 55.2449
10.154801090, 96.390, 2983.0, 54.6168
10.207322220, 96.390, 3067.0, 55.3805
10.259843351, 96.390, 3094.0, 55.6237
10.312364482, 96.390, 3000.0, 54.7723
10.364885612, 96.390, 3197.0, 56.5420
10.417406743, 96.390, 2963.0, 54.4334
10.469927874, 96.390, 3136.0, 56.0000
10.522449004, 96.390, 3166.0, 56.2672
10.574970135, 96.390, 3126.0, 55.9106
10.627491266, 96.390, 3161.0, 56.2228
10.680012397, 96.390, 3228.0, 56.8155
10.732533527, 96.390, 3304.0, 57.4804
10.785054658, 96.390, 3307.0, 57.5065
10.837575789, 96.390, 3318.0, 57.6021
10.890096919, 96.390, 3625.0, 60.2080
10.942618050, 96.390, 3367.0, 58.0259
10.995139181, 96.390, 3566.0, 59.7160
11.047660312, 96.390, 3832.0, 61.9032
11.100181442, 96.390, 3889.0, 62.3618
11.152702573, 96.390, 4000.0, 63.2456
11.205223704, 96.390, 4360.0, 66.0303
11.257744834, 96.390, 4456.0, 66.7533
11.310265965, 96.390, 5066.0, 71.1758
11.362787096, 96.390, 5341.0, 73.0821
11.415308227, 96.390, 5763.0, 75.9144
11.467829357, 96.390, 6250.0, 79.0569
11.520350488, 96.390, 6384.0, 79.8999
11.572871619, 96.390, 6500.0, 80.6226
11.625392749, 96.390, 6630.0, 81.4248
11.677913880, 96.390, 6278.0, 79.2338
11.730435011, 96.390, 5479.0, 74.0203
11.782956141, 96.390, 5166.0, 71.8749
11.835477272, 96.390, 4635.0, 68.0808
11.887998403, 96.390, 4437.0, 66.6108
11.940519534, 96.390, 4192.0, 64.7457
11.993040664, 96.390, 3784.0, 61.5142
12.045561795, 96.390, 3567.0, 59.7244
12.098082926, 96.390, 3393.0, 58.2495
12.150604056, 96.390, 3250.0, 57.0088
12.203125187, 96.390, 3178.0, 56.3738
12.255646318, 96.390, 3016.0, 54.9181
12.308167449, 96.390, 2872.0, 53.5910
12.360688579, 96.390, 2896.0, 53.8145
12.413209710, 96.390, 2786.0, 52.7826
12.465730841, 96.390, 2771.0, 52.6403
12.518251971, 96.390, 2668.0, 51.6527
12.570773102, 96.390, 2635.0, 51.3323
12.623294233, 96.390, 2691.0, 51.8748
12.675815364, 96.390, 2545.0, 50.4480
12.728336494, 96.390, 2499.0, 49.9900
12.780857625, 96.390, 2526.0, 50.2593
12.833378756, 96.390, 2565.0, 50.6458
12.885899886, 96.390, 2387.0, 48.8569
12.938421017, 96.390, 2412.0, 49.1121
12.990942148, 96.390, 2408.0, 49.0714
13.043463279, 96.390, 2503.0, 50.0300
13.095984409, 96.390, 2391.0, 48.8979
13.148505540, 96.390, 2356.0, 48.5386
13.201026671, 96.390, 2410.0, 49.0918
13.253547801, 96.390, 2417.0, 49.1630
13.306068932, 96.390, 2328.0, 48.2494
13.358590063, 96.390, 2365.0, 48.6313
13.411111193, 96.390, 2346.0, 48.4355
13.463632324, 96.390, 2261.0, 47.5500
13.516153455, 96.390, 2353.0, 48.5077
13.568674586, 96.390, 2301.0, 47.9687
13.621195716, 96.390, 2321.0, 48.1768
13.673716847, 96.390, 2256.0, 47.4974
13.726237978, 96.390, 2311.0, 48.0729
13.778759108, 96.390, 2124.0, 46.0869
13.831280239, 96.390, 2220.0, 47.1169
13.883801370, 96.390, 2220.0, 47.1169
13.936322501, 96.390, 2049.0, 45.2659
13.988843631, 96.390, 2189.0, 46.7868
14.041364762, 96.390, 2145.0, 46.3141
14.093885893, 96.390, 2176.0, 46.6476
14.146407023, 96.390, 2136.0, 46.2169
14.198928154, 96.390, 2051.0, 45.2880
14.251449285, 96.390, 2141.0, 46.2709
14.303970416, 96.390, 2052.0, 45.2990
14.356491546, 96.390, 2030.0, 45.0555
14.409012677, 96.390, 2092.0, 45.7384
14.461533808, 96.390, 2130.0, 46.1519
14.514054938, 96.390, 2191.0, 46.8081
14.566576069, 96.390, 2140.0, 46.2601
14.619097200, 96.390, 2060.0, 45.3872
14.671618331, 96.390, 2157.0, 46.4435
14.724139461, 96.390, 2106.0, 45.8912
14.776660592, 96.390, 2064.0, 45.4313
14.829181723, 96.390, 2142.0, 46.2817
14.881702853, 96.390, 2045.0, 45.2217
14.934223984, 96.390, 2034.0, 45.0999
14.986745115, 96.390, 2009.0, 44.8219
15.039266245, 96.390, 2095.0, 45.7712
15.091787376, 96.390, 2027.0, 45.0222
15.144308507, 96.390, 2045.0, 45.2217
15.196829638, 96.390, 2093.0, 45.7493
15.249350768, 96.390, 2052.0, 45.2990
15.301871899, 96.390, 2006.0, 44.7884
15.354393030, 96.390, 2028.0, 45.0333
15.406914160, 96.390, 2041.0, 45.1774
15.459435291, 96.390, 2038.0, 45.1442
15.511956422, 96.390, 1948.0, 44.1362
15.564477553, 96.390, 2042.0, 45.1885
15.616998683, 96.390, 2004.0, 44.7661
15.669519814, 96.390, 2007.0, 44.7996
15.722040945, 96.390, 2057.0, 45.3542
15.774562075, 96.390, 2011.0, 44.8442
15.827083206, 96.390, 2070.0, 45.4973
15.879604337, 96.390, 2044.0, 45.2106
15.932125468, 96.390, 1994.0, 44.6542
15.984646598, 96.390, 2041.0, 45.1774
16.037167729, 96.390, 2042.0, 45.1885
16.089688860, 96.390, 2090.0, 45.7165
16.142209990, 96.390, 1980.0, 44.4972
16.194731121, 96.390, 2019.0, 44.9333
16.247252252, 96.390, 2093.0, 45.7493
16.299773382, 96.390, 1974.0, 44.4297
16.352294513, 96.390, 2047.0, 45.2438
16.404815644, 96.390, 1939.0, 44.0341
16.457336775, 96.390, 2042.0, 45.1885
16.509857905, 96.390, 2058.0, 45.3652
16.562379036, 96.390, 2030.0, 45.0555
16.614900167, 96.390, 2009.0, 44.8219
16.667421297, 96.390, 2052.0, 45.2990
16.719942428, 96.390, 2080.0, 45.6070
16.772463559, 96.390, 2034.0, 45.0999
16.824984690, 96.390, 2056.0, 45.3431
16.877505820, 96.390, 2100.0, 45.8258
16.930026951, 96.390, 2030.0, 45.0555
16.982548082, 96.390, 2022.0, 44.9667
17.035069212, 96.390, 2051.0, 45.2880
17.087590343, 96.390, 2052.0, 45.2990
17.140111474, 96.390, 2159.0, 46.4650
17.192632605, 96.390, 2197.0, 46.8722
17.245153735, 96.390, 2090.0, 45.7165
17.297674866, 96.390, 2120.0, 46.0435
17.350195997, 96.390, 2079.0, 45.5961
17.402717127, 96.390, 2149.0, 46.3573
17.455238258, 96.390, 2063.0, 45.4203
17.507759389, 96.390, 2094.0, 45.7602
17.560280520, 96.390, 2082.0, 45.6289
17.612801650, 96.390, 2070.0, 45.4973
17.665322781, 96.390, 2154.0, 46.4112
17.717843912, 96.390, 2165.0, 46.5296
17.770365042, 96.390, 2152.0, 46.3897
17.822886173, 96.390, 2158.0, 46.4543
17.875407304, 96.390, 2113.0, 45.9674
17.927928434, 96.390, 2185.0, 46.7440
17.980449565, 96.390, 2080.0, 45.6070
18.032970696, 96.390, 2110.0, 45.9347
18.085491827, 96.390, 2105.0, 45.8803
18.138012957, 96.390, 2166.0, 46.5403
18.190534088, 96.390, 2180.0, 46.6905
18.243055219, 96.390, 2129.0, 46.1411
18.295576349, 96.390, 2232.0, 47.2440
18.348097480, 96.390, 2144.0, 46.3033
18.400618611, 96.390, 2164.0, 46.5188
18.453139742, 96.390, 2234.0, 47.2652
18.505660872, 96.390, 2224.0, 47.1593
18.558182003, 96.390, 2201.0, 46.9148
18.610703134, 96.390, 2220.0, 47.1169
18.663224264, 96.390, 2199.0, 46.8935
18.715745395, 96.390, 2292.0, 47.8748
18.768266526, 96.390, 2269.0, 47.6340
18.820787657, 96.390, 2223.0, 47.1487
18.873308787, 96.390, 2222.0, 47.1381
18.925829918, 96.390, 2264.0, 47.5815
18.978351049, 96.390, 2263.0, 47.5710
19.030872179, 96.390, 2304.0, 48.0000
19.083393310, 96.390, 2273.0, 47.6760
19.135914441, 96.390, 2360.0, 48.5798
19.188435572, 96.390, 2314.0, 48.1041
19.240956702, 96.390, 2422.0, 49.2138
19.293477833, 96.390, 2409.0, 49.0816
19.345998964, 96.390, 2369.0, 48.6724
19.398520094, 96.390, 2370.0, 48.6826
19.451041225, 96.390, 2377.0, 48.7545
19.503562356, 96.390, 2382.0, 48.8057
19.556083486, 96.390, 2409.0, 49.0816
19.608604617, 96.390, 2391.0, 48.8979
19.661125748, 96.390, 2450.0, 49.4975
19.713646879, 96.390, 2401.0, 49.0000
19.766168009, 96.390, 2436.0, 49.3559
19.818689140, 96.390, 2503.0, 50.0300
19.871210271, 96.390, 2553.0, 50.5272
19.923731401, 96.390, 2469.0, 49.6890
19.976252532, 96.390, 2410.0, 49.0918
20.028773663, 96.390, 2474.0, 49.7393
20.081294794, 96.390, 2478.0, 49.7795
20.133815924, 96.390, 2521.0, 50.2096
20.186337055, 96.390, 2520.0, 50.1996
20.238858186, 96.390, 2619.0, 51.1762
20.291379316, 96.390, 2685.0, 51.8170
20.343900447, 96.390, 2675.0, 51.7204
20.396421578, 96.390, 2630.0, 51.2835
20.448942709, 96.390, 2634.0, 51.3225
20.501463839, 96.390, 2549.0, 50.4876
20.553984970, 96.390, 2606.0, 51.0490
20.606506101, 96.390, 2694.0, 51.9038
20.659027231, 96.390, 2617.0, 51.1566
20.711548362, 96.390, 2609.0, 51.0784
20.764069493, 96.390, 2683.0, 51.7977
20.816590623, 96.390, 2754.0, 52.4786
20.869111754, 96.390, 2687.0, 51.8363
20.921632885, 96.390, 2653.0, 51.5073
20.974154016, 96.390, 2664.0, 51.6140
21.026675146, 96.390, 2676.0, 51.7301
21.079196277, 96.390, 2756.0, 52.4976
21.131717408, 96.390, 2833.0, 53.2259
21.184238538, 96.390, 2738.0, 52.3259
21.236759669, 96.390, 2745.0, 52.3927
21.289280800, 96.390, 2737.0, 52.3163
21.341801931, 96.390, 2679.0, 51.7591
21.394323061, 96.390, 2842.0, 53.3104
21.446844192, 96.390, 2794.0, 52.8583
21.499365323, 96.390, 2902.0, 53.8702
21.551886453, 96.390, 2848.0, 53.3667
21.604407584, 96.390, 2871.0, 53.5817
21.656928715, 96.390, 2918.0, 54.0185
21.709449846, 96.390, 2848.0, 53.3667
21.761970976, 96.390, 2785.0, 52.7731
21.814492107, 96.390, 2886.0, 53.7215
21.867013238, 96.390, 2851.0, 53.3948
21.919534368, 96.390, 2829.0, 53.1883
21.972055499, 96.390, 2789.0, 52.8110
22.024576630, 96.390, 2927.0, 54.1018
22.077097761, 96.390, 2902.0, 53.8702
22.129618891, 96.390, 2968.0, 54.4794
22.182140022, 96.390, 2935.0, 54.1756
22.234661153, 96.390, 2880.0, 53.6656
22.287182283, 96.390, 3043.0, 55.1634
22.339703414, 96.390, 2919.0, 54.0278
22.392224545, 96.390, 2929.0, 54.1202
22.444745675, 96.390, 3022.0, 54.9727
22.497266806, 96.390, 2998.0, 54.7540
22.549787937, 96.390, 3064.0, 55.3534
22.602309068, 96.390, 3153.0, 56.1516
22.654830198, 96.390, 3238.0, 56.9034
22.707351329, 96.390, 3180.0, 56.3915
22.759872460, 96.390, 3339.0, 57.7841
22.812393590, 96.390, 3224.0, 56.7803
22.864914721, 96.390, 3390.0, 58.2237
22.917435852, 96.390, 3434.0, 58.6003
22.969956983, 96.390, 3384.0, 58.1722
23.022478113, 96.390, 3483.0, 59.0169
23.074999244, 96.390, 3487.0, 59.0508
23.127520375, 96.390, 3647.0, 60.3904
23.180041505, 96.390, 3560.0, 59.6657
23.232562636, 96.390, 3777.0, 61.4573
23.285083767, 96.390, 3722.0, 61.0082
23.337604898, 96.390, 3876.0, 62.2575
23.390126028, 96.390, 3891.0, 62.3779
23.442647159, 96.390, 3760.0, 61.3188
23.495168290, 96.390, 3765.0, 61.3596
23.547689420, 96.390, 3480.0, 58.9915
23.600210551, 96.390, 3370.0, 58.0517
23.652731682, 96.390, 3278.0, 57.2538
23.705252813, 96.390, 3095.0, 55.6327
23.757773943, 96.390, 3029.0, 55.0364
23.810295074, 96.390, 2950.0, 54.3139
23.862816205, 96.390, 2967.0, 54.4702
23.915337335, 96.390, 2888.0, 53.7401
23.967858466, 96.390, 2753.0, 52.4690
24.020379597, 96.390, 2857.0, 53.4509
24.072900727, 96.390, 2660.0, 51.5752
24.125421858, 96.390, 2687.0, 51.8363
24.177942989, 96.390, 2571.0, 50.7050
24.230464120, 96.390, 2546.0, 50.4579
24.282985250, 96.390, 2563.0, 50.6261
24.335506381, 96.390, 2512.0, 50.1199
24.388027512, 96.390, 2471.0, 49.7092
24.440548642, 96.390, 2419.0, 49.1833
24.493069773, 96.390, 2524.0, 50.2394
24.545590904, 96.390, 2447.0, 49.4672
24.598112035, 96.390, 2394.0, 48.9285
24.650633165, 96.390, 2440.0, 49.3964
24.703154296, 96.390, 2416.0, 49.1528
24.755675427, 96.390, 2341.0, 48.3839
24.808196557, 96.390, 2389.0, 48.8774
24.860717688, 96.390, 2299.0, 47.9479
24.913238819, 96.390, 2368.0, 48.6621
24.965759950, 96.390, 2356.0, 48.5386
25.018281080, 96.390, 2241.0, 47.3392
25.070802211, 96.390, 2271.0, 47.6550
25.123323342, 96.390, 2323.0, 48.1975
25.175844472, 96.390, 2246.0, 47.3920
25.228365603, 96.390, 2235.0, 47.2758
25.280886734, 96.390, 2299.0, 47.9479
25.333407864, 96.390, 2105.0, 45.8803
25.385928995, 96.390, 2260.0, 47.5395
25.438450126, 96.390, 2165.0, 46.5296
25.490971257, 96.390, 2209.0, 47.0000
25.543492387, 96.390, 2187.0, 46.7654
25.596013518, 96.390, 2229.0, 47.2123
25.648534649, 96.390, 2096.0, 45.7821
25.701055779, 96.390, 2146.0, 46.3249
25.753576910, 96.390, 2139.0, 46.2493
25.806098041, 96.390, 2143.0, 46.2925
25.858619172, 96.390, 2128.0, 46.1303
25.911140302, 96.390, 2161.0, 46.4866
25.963661433, 96.390, 2139.0, 46.2493
26.016182564, 96.390, 1936.0, 44.0000
26.068703694, 96.390, 2038.0, 45.1442
26.121224825, 96.390, 2043.0, 45.1996
26.173745956, 96.390, 2000.0, 44.7214
26.226267087, 96.390, 1967.0, 44.3509
26.278788217, 96.390, 2081.0, 45.6180
26.331309348, 96.390, 1960.0, 44.2719
26.383830479, 96.390, 2002.0, 44.7437
26.436351609, 96.390, 2040.0, 45.1664
26.488872740, 96.390, 1988.0, 44.5870
26.541393871, 96.390, 1986.0, 44.5646
26.593915002, 96.390, 1985.0, 44.5533
26.646436132, 96.390, 1971.0, 44.3959
26.698957263, 96.390, 2002.0, 44.7437
26.751478394, 96.390, 1926.0, 43.8862
26.803999524, 96.390, 1967.0, 44.3509
26.856520655, 96.390, 1997.0, 44.6878
26.909041786, 96.390, 1953.0, 44.1928
26.961562916, 96.390, 1951.0, 44.1701
27.014084047, 96.390, 1890.0, 43.4741
27.066605178, 96.390, 1988.0, 44.5870
27.119126309, 96.390, 1950.0, 44.1588
27.171647439, 96.390, 1913.0, 43.7379
27.224168570, 96.390, 1753.0, 41.8688
27.276689701, 96.390, 1945.0, 44.1022
27.329210831, 96.390, 1952.0, 44.1814
27.381731962, 96.390, 1785.0, 42.2493
27.434253093, 96.390, 1957.0, 44.2380
27.486774224, 96.390, 1851.0, 43.0232
27.539295354, 96.390, 1786.0, 42.2611
27.591816485, 96.390, 1825.0, 42.7200
27.644337616, 96.390, 1790.0, 42.3084
27.696858746, 96.390, 1758.0, 41.9285
27.749379877, 96.390, 1822.0, 42.6849
27.801901008, 96.390, 1808.0, 42.5206
27.854422139, 96.390, 1829.0, 42.7668
27.906943269, 96.390, 1837.0, 42.8602
27.959464400, 96.390, 1752.0, 41.8569
28.011985531, 96.390, 1788.0, 42.2847
28.064506661, 96.390, 1803.0, 42.4617
28.117027792, 96.390, 1866.0, 43.1972
28.169548923, 96.390, 1778.0, 42.1663
28.222070054, 96.390, 1759.0, 41.9404
28.274591184, 96.390, 1840.0, 42.8952
28.327112315, 96.390, 1731.0, 41.6053
28.379633446, 96.390, 1703.0, 41.2674
28.432154576, 96.390, 1701.0, 41.2432
28.484675707, 96.390, 1762.0, 41.9762
28.537196838, 96.390, 1682.0, 41.0122
28.589717968, 96.390, 1797.0, 42.3910
28.642239099, 96.390, 1707.0, 41.3159
28.694760230, 96.390, 1717.0, 41.4367
28.747281361, 96.390, 1697.0, 41.1947
28.799802491, 96.390, 1629.0, 40.3609
28.852323622, 96.390, 1745.0, 41.7732
28.904844753, 96.390, 1638.0, 40.4722
28.957365883, 96.390, 1627.0, 40.3361
29.009887014, 96.390, 1668.0, 40.8412
29.062408145, 96.390, 1702.0, 41.2553
29.114929276, 96.390, 1695.0, 41.1704
29.167450406, 96.390, 1676.0, 40.9390
29.219971537, 96.390, 1627.0, 40.3361
29.272492668, 96.390, 1623.0, 40.2865
29.325013798, 96.390, 1601.0, 40.0125
29.377534929, 96.390, 1634.0, 40.4228
29.430056060, 96.390, 1633.0, 40.4104
29.482577191, 96.390, 1628.0, 40.3485
29.535098321, 96.390, 1613.0, 40.1622
29.587619452, 96.390, 1570.0, 39.6232
29.640140583, 96.390, 1636.0, 40.4475
29.692661713, 96.390, 1605.0, 40.0625
29.745182844, 96.390, 1500.0, 38.7298
29.797703975, 96.390, 1575.0, 39.6863
29.850225105, 96.390, 1565.0, 39.5601
29.902746236, 96.390, 1517.0, 38.9487
29.955267367, 96.390, 1576.0, 39.6989
30.007788498, 96.390, 1544.0, 39.2938
30.060309628, 96.390, 1536.0, 39.1918
30.112830759, 96.390, 1526.0, 39.0640
30.165351890, 96.390, 1496.0, 38.6782
30.217873020, 96.390, 1504.0, 38.7814
30.270394151, 96.390, 1437.0, 37.9078
30.322915282, 96.390, 1432.0, 37.8418
30.375436413, 96.390, 1486.0, 38.5487
30.427957543, 96.390, 1570.0, 39.6232
30.480478674, 96.390, 1553.0, 39.4081
30.532999805, 96.390, 1493.0, 38.6394
30.585520935, 96.390, 1517.0, 38.9487
30.638042066, 96.390, 1515.0, 38.9230
30.690563197, 96.390, 1398.0, 37.3898
30.743084328, 96.390, 1489.0, 38.5876
30.795605458, 96.390, 1570.0, 39.6232
30.848126589, 96.390, 1506.0, 38.8072
30.900647720, 96.390, 1391.0, 37.2961
30.953168850, 96.390, 1429.0, 37.8021
31.005689981, 96.390, 1461.0, 38.2230
31.058211112, 96.390, 1421.0, 37.6962
31.110732243, 96.390, 1457.0, 38.1707
31.163253373, 96.390, 1459.0, 38.1969
31.215774504, 96.390, 1423.0, 37.7227
31.268295635, 96.390, 1386.0, 37.2290
31.320816765, 96.390, 1444.0, 38.0000
31.373337896, 96.390, 1396.0, 37.3631
31.425859027, 96.390, 1449.0, 38.0657
31.478380157, 96.390, 1440.0, 37.9473
31.530901288, 96.390, 1390.0, 37.2827
31.583422419, 96.390, 1428.0, 37.7889
31.635943550, 96.390, 1488.0, 38.5746
31.688464680, 96.390, 1451.0, 38.0920
31.740985811, 96.390, 1350.0, 36.7423
31.793506942, 96.390, 1363.0, 36.9188
31.846028072, 96.390, 1444.0, 38.0000
31.898549203, 96.390, 1439.0, 37.9342
31.951070334, 96.390, 1414.0, 37.6032
32.003591465, 96.390, 1298.0, 36.0278
32.056112595, 96.390, 1342.0, 36.6333
32.108633726, 96.390, 1400.0, 37.4166
32.161154857, 96.390, 1258.0, 35.4683
32.213675987, 96.390, 1420.0, 37.6829
32.266197118, 96.390, 1364.0, 36.9324
32.318718249, 96.390, 1373.0, 37.0540
32.371239380, 96.390, 1369.0, 37.0000
32.423760510, 96.390, 1429.0, 37.8021
32.476281641, 96.390, 1284.0, 35.8329
32.528802772, 96.390, 1287.0, 35.8748
32.581323902, 96.390, 1399.0, 37.4032
32.633845033, 96.390, 1416.0, 37.6298
32.686366164, 96.390, 1314.0, 36.2491
32.738887295, 96.390, 1349.0, 36.7287
32.791408425, 96.390, 1323.0, 36.3731
32.843929556, 96.390, 1345.0, 36.6742
32.896450687, 96.390, 1349.0, 36.7287
32.948971817, 96.390, 1325.0, 36.4005
33.001492948, 96.390, 1328.0, 36.4417
33.054014079, 96.390, 1251.0, 35.3695
33.106535209, 96.390, 1325.0, 36.4005
33.159056340, 96.390, 1319.0, 36.3180
33.211577471, 96.390, 1348.0, 36.7151
33.264098602, 96.390, 1338.0, 36.5787
33.316619732, 96.390, 1275.0, 35.7071
33.369140863, 96.390, 1284.0, 35.8329
33.421661994, 96.390, 1301.0, 36.0694
33.474183124, 96.390, 1296.0, 36.0000
33.526704255, 96.390, 1353.0, 36.7831
33.579225386, 96.390, 1379.0, 37.1349
33.631746517, 96.390, 1388.0, 37.2559
33.684267647, 96.390, 1334.0, 36.5240
33.736788778, 96.390, 1410.0, 37.5500
33.789309909, 96.390, 1389.0, 37.2693
33.841831039, 96.390, 1414.0, 37.6032
33.894352170, 96.390, 1530.0, 39.1152
33.946873301, 96.390, 1479.0, 38.4578
33.999394432, 96.390, 1535.0, 39.1791
34.051915562, 96.390, 1605.0, 40.0625
34.104436693, 96.390, 1600.0, 40.0000
34.156957824, 96.390, 1645.0, 40.5586
34.209478954, 96.390, 1586.0, 39.8246
34.262000085, 96.390, 1736.0, 41.6653
34.314521216, 96.390, 1697.0, 41.1947
34.367042346, 96.390, 1763.0, 41.9881
34.419563477, 96.390, 1941.0, 44.0568
34.472084608, 96.390, 1942.0, 44.0681
34.524605739, 96.390, 1996.0, 44.6766
34.577126869, 96.390, 2069.0, 45.4863
34.629648000, 96.390, 2184.0, 46.7333
34.682169131, 96.390, 2275.0, 47.6970
34.734690261, 96.390, 2352.0, 48.4974
34.787211392, 96.390, 2487.0, 49.8698
34.839732523, 96.390, 2550.0, 50.4975
34.892253654, 96.390, 2571.0, 50.7050
34.944774784, 96.390, 2460.0, 49.5984
34.997295915, 96.390, 2353.0, 48.5077
35.049817046, 96.390, 2311.0, 48.0729
35.102338176, 96.390, 2047.0, 45.2438
35.154859307, 96.390, 2012.0, 44.8553
35.207380438, 96.390, 1954.0, 44.2041
35.259901569, 96.390, 1922.0, 43.8406
35.312422699, 96.390, 1834.0, 42.8252
35.364943830, 96.390, 1816.0, 42.6146
35.417464961, 96.390, 1743.0, 41.7493
35.469986091, 96.390, 1762.0, 41.9762
35.522507222, 96.390, 1700.0, 41.2311
35.575028353, 96.390, 1774.0, 42.1189
35.627549484, 96.390, 1686.0, 41.0609
35.680070614, 96.390, 1639.0, 40.4846
35.732591745, 96.390, 1638.0, 40.4722
35.785112876, 96.390, 1647.0, 40.5832
35.837634006, 96.390, 1594.0, 39.9249
35.890155137, 96.390, 1695.0, 41.1704
35.942676268, 96.390, 1566.0, 39.5727
35.995197398, 96.390, 1553.0, 39.4081
36.047718529, 96.390, 1536.0, 39.1918
36.100239660, 96.390, 1581.0, 39.7618
36.152760791, 96.390, 1516.0, 38.9358
36.205281921, 96.390, 1532.0, 39.1408
36.257803052, 96.390, 1546.0, 39.3192
36.310324183, 96.390, 1505.0, 38.7943
36.362845313, 96.390, 1509.0, 38.8458
36.415366444, 96.390, 1420.0, 37.6829
36.467887575, 96.390, 1487.0, 38.5616
36.520408706, 96.390, 1499.0, 38.7169
36.572929836, 96.390, 1487.0, 38.5616
36.625450967, 96.390, 1484.0, 38.5227
36.677972098, 96.390, 1470.0, 38.3406
36.730493228, 96.390, 1531.0, 39.1280
36.783014359, 96.390, 1454.0, 38.1314
36.835535490, 96.390, 1498.0, 38.7040
36.888056621, 96.390, 1448.0, 38.0526
36.940577751, 96.390, 1484.0, 38.5227
36.993098882, 96.390, 1449.0, 38.0657
37.045620013, 96.390, 1470.0, 38.3406
37.098141143, 96.390, 1418.0, 37.6563
37.150662274, 96.390, 1410.0, 37.5500
37.203183405, 96.390, 1416.0, 37.6298
37.255704535, 96.390, 1444.0, 38.0000
37.308225666, 96.390, 1417.0, 37.6431
37.360746797, 96.390, 1404.0, 37.4700
37.413267928, 96.390, 1452.0, 38.1051
37.465789058, 96.390, 1345.0, 36.6742
37.518310189, 96.390, 1453.0, 38.1182
37.570831320, 96.390, 1380.0, 37.1484
37.623352450, 96.390, 1356.0, 36.8239
37.675873581, 96.390, 1442.0, 37.9737
37.728394712, 96.390, 1429.0, 37.8021
37.780915843, 96.390, 1295.0, 35.9861
37.833436973, 96.390, 1337.0, 36.5650
37.885958104, 96.390, 1326.0, 36.4143
37.938479235, 96.390, 1391.0, 37.2961
37.991000365, 96.390, 1359.0, 36.8646
38.043521496, 96.390, 1342.0, 36.6333
38.096042627, 96.390, 1403.0, 37.4566
38.148563758, 96.390, 1380.0, 37.1484
38.201084888, 96.390, 1416.0, 37.6298
38.253606019, 96.390, 1425.0, 37.7492
38.306127150, 96.390, 1406.0, 37.4967
38.358648280, 96.390, 1422.0, 37.7094
38.411169411, 96.390, 1380.0, 37.1484
38.463690542, 96.390, 1420.0, 37.6829
38.516211673, 96.390, 1426.0, 37.7624
38.568732803, 96.390, 1409.0, 37.5366
38.621253934, 96.390, 1425.0, 37.7492
38.673775065, 96.390, 1463.0, 38.2492
38.726296195, 96.390, 1479.0, 38.4578
38.778817326, 96.390, 1455.0, 38.1445
38.831338457, 96.390, 1614.0, 40.1746
38.883859587, 96.390, 1568.0, 39.5980
38.936380718, 96.390, 1580.0, 39.7492
38.988901849, 96.390, 1638.0, 40.4722
39.041422980, 96.390, 1669.0, 40.8534
39.093944110, 96.390, 1719.0, 41.4608
39.146465241, 96.390, 1700.0, 41.2311
39.198986372, 96.390, 1687.0, 41.0731
39.251507502, 96.390, 1681.0, 41.0000
39.304028633, 96.390, 1711.0, 41.3642
39.356549764, 96.390, 1786.0, 42.2611
39.409070895, 96.390, 1825.0, 42.7200
39.461592025, 96.390, 1796.0, 42.3792
39.514113156, 96.390, 1813.0, 42.5793
39.566634287, 96.390, 1648.0, 40.5956
39.619155417, 96.390, 1601.0, 40.0125
39.671676548, 96.390, 1515.0, 38.9230
39.724197679, 96.390, 1415.0, 37.6165
39.776718810, 96.390, 1477.0, 38.4318
39.829239940, 96.390, 1408.0, 37.5233
39.881761071, 96.390, 1388.0, 37.2559
39.934282202, 96.390, 1354.0, 36.7967
39.986803332, 96.390, 1299.0, 36.0416
40.039324463, 96.390, 1257.0, 35.4542
40.091845594, 96.390, 1376.0, 37.0945
40.144366725, 96.390, 1275.0, 35.7071
40.196887855, 96.390, 1320.0, 36.3318
40.249408986, 96.390, 1244.0, 35.2704
40.301930117, 96.390, 1352.0, 36.7696
40.354451247, 96.390, 1179.0, 34.3366
40.406972378, 96.390, 1291.0, 35.9305
40.459493509, 96.390, 1264.0, 35.5528
40.512014639, 96.390, 1244.0, 35.2704
40.564535770, 96.390, 1172.0, 34.2345
40.617056901, 96.390, 1127.0, 33.5708
40.669578032, 96.390, 1179.0, 34.3366
40.722099162, 96.390, 1160.0, 34.0588
40.774620293, 96.390, 1176.0, 34.2929
40.827141424, 96.390, 1179.0, 34.3366
40.879662554, 96.390, 1160.0, 34.0588
40.932183685, 96.390, 1162.0, 34.0881
40.984704816, 96.390, 1166.0, 34.1467
41.037225947, 96.390, 1166.0, 34.1467
41.089747077, 96.390, 1171.0, 34.2199
41.142268208, 96.390, 1135.0, 33.6898
41.194789339, 96.390, 1135.0, 33.6898
41.247310469, 96.390, 1094.0, 33.0757
41.299831600, 96.390, 1119.0, 33.4515
41.352352731, 96.390, 1093.0, 33.0606
41.404873862, 96.390, 1139.0, 33.7491
41.457394992, 96.390, 1049.0, 32.3883
41.509916123, 96.390, 1122.0, 33.4963
41.562437254, 96.390, 1116.0, 33.4066
41.614958384, 96.390, 1119.0, 33.4515
41.667479515, 96.390, 1114.0, 33.3766
41.720000646, 96.390, 1127.0, 33.5708
41.772521776, 96.390, 1127.0, 33.5708
41.825042907, 96.390, 1079.0, 32.8481
41.877564038, 96.390, 1046.0, 32.3419
41.930085169, 96.390, 1121.0, 33.4813
41.982606299, 96.390, 1144.0, 33.8231
42.035127430, 96.390, 1107.0, 33.2716
42.087648561, 96.390, 1056.0, 32.4962
42.140169691, 96.390, 1116.0, 33.4066
42.192690822, 96.390, 1033.0, 32.1403
42.245211953, 96.390, 1090.0, 33.0151
42.297733084, 96.390, 1051.0, 32.4191
42.350254214, 96.390, 1093.0, 33.0606
42.402775345, 96.390, 1105.0, 33.2415
42.455296476, 96.390, 1085.0, 32.9393
42.507817606, 96.390, 1039.0, 32.2335
42.560338737, 96.390, 1071.0, 32.7261
42.612859868, 96.390, 1119.0, 33.4515
42.665380999, 96.390, 1021.0, 31.9531
42.717902129, 96.390, 1025.0, 32.0156
42.770423260, 96.390, 1078.0, 32.8329
42.822944391, 96.390, 1068.0, 32.6803
42.875465521, 96.390, 1032.0, 32.1248
42.927986652, 96.390, 1112.0, 33.3467
42.980507783, 96.390, 1054.0, 32.4654
43.033028914, 96.390, 1038.0, 32.2180
43.085550044, 96.390, 1020.0, 31.9374
43.138071175, 96.390, 1051.0, 32.4191
43.190592306, 96.390, 1016.0, 31.8748
43.243113436, 96.390, 1031.0, 32.1092
43.295634567, 96.390, 1073.0, 32.7567
43.348155698, 96.390, 1062.0, 32.5883
43.400676828, 96.390, 1083.0, 32.9090
43.453197959, 96.390, 1046.0, 32.3419
43.505719090, 96.390, 1055.0, 32.4808
43.558240221, 96.390, 1054.0, 32.4654
43.610761351, 96.390, 1025.0, 32.0156
43.663282482, 96.390, 1029.0, 32.0780
43.715803613, 96.390, 1042.0, 32.2800
43.768324743, 96.390, 1114.0, 33.3766
43.820845874, 96.390, 1086.0, 32.9545
43.873367005, 96.390, 1093.0, 33.0606
43.925888136, 96.390, 1060.0, 32.5576
43.978409266, 96.390, 1068.0, 32.6803
44.030930397, 96.390, 1075.0, 32.7872
44.083451528, 96.390, 1056.0, 32.4962
44.135972658, 96.390, 1052.0, 32.4345
44.188493789, 96.390, 1004.0, 31.6860
44.241014920, 96.390, 1024.0, 32.0000
44.293536051, 96.390, 1043.0, 32.2955
44.346057181, 96.390, 1073.0, 32.7567
44.398578312, 96.390, 1069.0, 32.6956
44.451099443, 96.390, 993.0, 31.5119
44.503620573, 96.390, 1019.0, 31.9218
44.556141704, 96.390, 1057.0, 32.5115
44.608662835, 96.390, 1085.0, 32.9393
44.661183966, 96.390, 1007.0, 31.7333
44.713705096, 96.390, 1012.0, 31.8119
44.766226227, 96.390, 1075.0, 32.7872
44.818747358, 96.390, 1043.0, 32.2955
44.871268488, 96.390, 1059.0, 32.5423
44.923789619, 96.390, 1038.0, 32.2180
44.976310750, 96.390, 1053.0, 32.4500
45.028831880, 96.390, 1082.0, 32.8938
45.081353011, 96.390, 1054.0, 32.4654
45.133874142, 96.390, 1083.0, 32.9090
45.186395273, 96.390, 1037.0, 32.2025
45.238916403, 96.390, 1133.0, 33.6601
45.291437534, 96.390, 1036.0, 32.1870
45.343958665, 96.390, 1084.0, 32.9242
45.396479795, 96.390, 1096.0, 33.1059
45.449000926, 96.390, 1063.0, 32.6037
45.501522057, 96.390, 1112.0, 33.3467
45.554043188, 96.390, 1115.0, 33.3916
45.606564318, 96.390, 1152.0, 33.9411
45.659085449, 96.390, 1129.0, 33.6006
45.711606580, 96.390, 1139.0, 33.7491
45.764127710, 96.390, 1185.0, 34.4238
45.816648841, 96.390, 1125.0, 33.5410
45.869169972, 96.390, 1160.0, 34.0588
45.921691103, 96.390, 1073.0, 32.7567
45.974212233, 96.390, 1193.0, 34.5398
46.026733364, 96.390, 1190.0, 34.4964
46.079254495, 96.390, 1159.0, 34.0441
46.131775625, 96.390, 1256.0, 35.4401
46.184296756, 96.390, 1265.0, 35.5668
46.236817887, 96.390, 1274.0, 35.6931
46.289339017, 96.390, 1281.0, 35.7911
46.341860148, 96.390, 1294.0, 35.9722
46.394381279, 96.390, 1257.0, 35.4542
46.446902410, 96.390, 1247.0, 35.3129
46.499423540, 96.390, 1302.0, 36.0832
46.551944671, 96.390, 1247.0, 35.3129
46.604465802, 96.390, 1280.0, 35.7771
46.656986932, 96.390, 1347.0, 36.7015
46.709508063, 96.390, 1426.0, 37.7624
46.762029194, 96.390, 1434.0, 37.8682
46.814550325, 96.390, 1432.0, 37.8418
46.867071455, 96.390, 1379.0, 37.1349
46.919592586, 96.390, 1416.0, 37.6298
46.972113717, 96.390, 1437.0, 37.9078
47.024634847, 96.390, 1403.0, 37.4566
47.077155978, 96.390, 1367.0, 36.9730
47.129677109, 96.390, 1343.0, 36.6470
47.182198240, 96.390, 1233.0, 35.1141
47.234719370, 96.390, 1284.0, 35.8329
47.287240501, 96.390, 1145.0, 33.8378
47.339761632, 96.390, 1139.0, 33.7491
47.392282762, 96.390, 1138.0, 33.7343
47.444803893, 96.390, 1101.0, 33.1813
47.497325024, 96.390, 1050.0, 32.4037
47.549846155, 96.390, 1120.0, 33.4664
47.602367285, 96.390, 1029.0, 32.0780
47.654888416, 96.390, 1090.0, 33.0151
47.707409547, 96.390, 1041.0, 32.2645
47.759930677, 96.390, 1064.0, 32.6190
47.812451808, 96.390, 1018.0, 31.9061
47.864972939, 96.390, 1059.0, 32.5423
47.917494069, 96.390, 1006.0, 31.7175
47.970015200, 96.390, 1034.0, 32.1559
48.022536331, 96.390, 982.0, 31.3369
48.075057462, 96.390, 1011.0, 31.7962
48.127578592, 96.390, 1013.0, 31.8277
48.180099723, 96.390, 988.0, 31.4325
48.232620854, 96.390, 1012.0, 31.8119
48.285141984, 96.390, 953.0, 30.8707
48.337663115, 96.390, 915.0, 30.2490
48.390184246, 96.390, 994.0, 31.5278
48.442705377, 96.390, 963.0, 31.0322
48.495226507, 96.390, 929.0, 30.4795
48.547747638, 96.390, 947.0, 30.7734
48.600268769, 96.390, 963.0, 31.0322
48.652789899, 96.390, 904.0, 30.0666
48.705311030, 96.390, 917.0, 30.2820
48.757832161, 96.390, 906.0, 30.0998
48.810353292, 96.390, 894.0, 29.8998
48.862874422, 96.390, 876.0, 29.5973
48.915395553, 96.390, 973.0, 31.1929
48.967916684, 96.390, 889.0, 29.8161
49.020437814, 96.390, 932.0, 30.5287
49.072958945, 96.390, 880.0, 29.6648
49.125480076, 96.390, 883.0, 29.7153
49.178001207, 96.390, 936.0, 30.5941
49.230522337, 96.390, 939.0, 30.6431
49.283043468, 96.390, 826.0, 28.7402
49.335564599, 96.390, 886.0, 29.7658
49.388085729, 96.390, 836.0, 28.9137
49.440606860, 96.390, 893.0, 29.8831
49.493127991, 96.390, 839.0, 28.9655
49.545649121, 96.390, 894.0, 29.8998
49.598170252, 96.390, 864.0, 29.3939
49.650691383, 96.390, 852.0, 29.1890
49.703212514, 96.390, 885.0, 29.7489
49.755733644, 96.390, 853.0, 29.2062
49.808254775, 96.390, 869.0, 29.4788
49.860775906, 96.390, 866.0, 29.4279
49.913297036, 96.390, 859.0, 29.3087
49.965818167, 96.390, 881.0, 29.6816
50.018339298, 96.390, 825.0, 28.7228
50.070860429, 96.390, 846.0, 29.0861
50.123381559, 96.390, 853.0, 29.2062
50.175902690, 96.390, 895.0, 29.9166
50.228423821, 96.390, 836.0, 28.9137
50.280944951, 96.390, 856.0, 29.2575
50.333466082, 96.390, 865.0, 29.4109
50.385987213, 96.390, 888.0, 29.7993
50.438508344, 96.390, 846.0, 29.0861
50.491029474, 96.390, 890.0, 29.8329
50.543550605, 96.390, 874.0, 29.5635
50.596071736, 96.390, 809.0, 28.4429
50.648592866, 96.390, 822.0, 28.6705
50.701113997, 96.390, 815.0, 28.5482
50.753635128, 96.390, 840.0, 28.9828
50.806156258, 96.390, 868.0, 29.4618
50.858677389, 96.390, 816.0, 28.5657
50.911198520, 96.390, 785.0, 28.0179
50.963719651, 96.390, 845.0, 29.0689
51.016240781, 96.390, 834.0, 28.8791
51.068761912, 96.390, 778.0, 27.8927
51.121283043, 96.390, 806.0, 28.3901
51.173804173, 96.390, 846.0, 29.0861
51.226325304, 96.390, 858.0, 29.2916
51.278846435, 96.390, 801.0, 28.3019
51.331367566, 96.390, 816.0, 28.5657
51.383888696, 96.390, 843.0, 29.0345
51.436409827, 96.390, 791.0, 28.1247
51.488930958, 96.390, 821.0, 28.6531
51.541452088, 96.390, 793.0, 28.1603
51.593973219, 96.390, 762.0, 27.6043
51.646494350, 96.390, 805.0, 28.3725
51.699015481, 96.390, 844.0, 29.0517
51.751536611, 96.390, 826.0, 28.7402
51.804057742, 96.390, 825.0, 28.7228
51.856578873, 96.390, 822.0, 28.6705
51.909100003, 96.390, 780.0, 27.9285
51.961621134, 96.390, 759.0, 27.5500
52.014142265, 96.390, 847.0, 29.1033
52.066663396, 96.390, 777.0, 27.8747
52.119184526, 96.390, 723.0, 26.8887
52.171705657, 96.390, 789.0, 28.0891
52.224226788, 96.390, 820.0, 28.6356
52.276747918, 96.390, 809.0, 28.4429
52.329269049, 96.390, 798.0, 28.2489
52.381790180, 96.390, 812.0, 28.4956
52.434311310, 96.390, 783.0, 27.9821
52.486832441, 96.390, 789.0, 28.0891
52.539353572, 96.390, 825.0, 28.7228
52.591874703, 96.390, 776.0, 27.8568
52.644395833, 96.390, 810.0, 28.4605
52.696916964, 96.390, 823.0, 28.6880
52.749438095, 96.390, 870.0, 29.4958
52.801959225, 96.390, 787.0, 28.0535
52.854480356, 96.390, 809.0, 28.4429
52.907001487, 96.390, 842.0, 29.0172
52.959522618, 96.390, 808.0, 28.4253
53.012043748, 96.390, 803.0, 28.3373
53.064564879, 96.390, 782.0, 27.9643
53.117086010, 96.390, 841.0, 29.0000
53.169607140, 96.390, 787.0, 28.0535
53.222128271, 96.390, 783.0, 27.9821
53.274649402, 96.390, 818.0, 28.6007
53.327170533, 96.390, 786.0, 28.0357
53.379691663, 96.390, 738.0, 27.1662
53.432212794, 96.390, 761.0, 27.5862
53.484733925, 96.390, 748.0, 27.3496
53.537255055, 96.390, 784.0, 28.0000
53.589776186, 96.390, 733.0, 27.0740
53.642297317, 96.390, 781.0, 27.9464
53.694818448, 96.390, 769.0, 27.7308
53.747339578, 96.390, 757.0, 27.5136
53.799860709, 96.390, 802.0, 28.3196
53.852381840, 96.390, 749.0, 27.3679
53.904902970, 96.390, 699.0, 26.4386
53.957424101, 96.390, 746.0, 27.3130
54.009945232, 96.390, 731.0, 27.0370
54.062466362, 96.390, 737.0, 27.1477
54.114987493, 96.390, 713.0, 26.7021
54.167508624, 96.390, 761.0, 27.5862
54.220029755, 96.390, 701.0, 26.4764
54.272550885, 96.390, 739.0, 27.1846
54.325072016, 96.390, 777.0, 27.8747
54.377593147, 96.390, 718.0, 26.7955
54.430114277, 96.390, 763.0, 27.6225
54.482635408, 96.390, 722.0, 26.8701
54.535156539, 96.390, 754.0, 27.4591
54.587677670, 96.390, 762.0, 27.6043
54.640198800, 96.390, 754.0, 27.4591
54.692719931, 96.390, 765.0, 27.6586
54.745241062, 96.390, 685.0, 26.1725
54.797762192, 96.390, 730.0, 27.0185
54.850283323, 96.390, 730.0, 27.0185
54.902804454, 96.390, 701.0, 26.4764
54.955325585, 96.390, 706.0, 26.5707
55.007846715, 96.390, 731.0, 27.0370
55.060367846, 96.390, 754.0, 27.4591
55.112888977, 96.390, 722.0, 26.8701
55.165410107, 96.390, 741.0, 27.2213
55.217931238, 96.390, 691.0, 26.2869
55.270452369, 96.390, 726.0, 26.9444
55.322973499, 96.390, 734.0, 27.0924
55.375494630, 96.390, 761.0, 27.5862
55.428015761, 96.390, 762.0, 27.6043
55.480536892, 96.390, 714.0, 26.7208
55.533058022, 96.390, 788.0, 28.0713
55.585579153, 96.390, 738.0, 27.1662
55.638100284, 96.390, 736.0, 27.1293
55.690621414, 96.390, 717.0, 26.7769
55.743142545, 96.390, 765.0, 27.6586
55.795663676, 96.390, 746.0, 27.3130
55.848184807, 96.390, 745.0, 27.2947
55.900705937, 96.390, 730.0, 27.0185
55.953227068, 96.390, 722.0, 26.8701
56.005748199, 96.390, 780.0, 27.9285
56.058269329, 96.390, 738.0, 27.1662
56.110790460, 96.390, 794.0, 28.1780
56.163311591, 96.390, 728.0, 26.9815
56.215832722, 96.390, 768.0, 27.7128
56.268353852, 96.390, 784.0, 28.0000
56.320874983, 96.390, 755.0, 27.4773
56.373396114, 96.390, 737.0, 27.1477
56.425917244, 96.390, 766.0, 27.6767
56.478438375, 96.390, 783.0, 27.9821
56.530959506, 96.390, 753.0, 27.4408
56.583480637, 96.390, 740.0, 27.2029
56.636001767, 96.390, 729.0, 27.0000
56.688522898, 96.390, 682.0, 26.1151
56.741044029, 96.390, 757.0, 27.5136
56.793565159, 96.390, 697.0, 26.4008
56.846086290, 96.390, 729.0, 27.0000
56.898607421, 96.390, 710.0, 26.6458
56.951128551, 96.390, 735.0, 27.1109
57.003649682, 96.390, 764.0, 27.6405
57.056170813, 96.390, 704.0, 26.5330
57.108691944, 96.390, 670.0, 25.8844
57.161213074, 96.390, 697.0, 26.4008
57.213734205, 96.390, 717.0, 26.7769
57.266255336, 96.390, 700.0, 26.4575
57.318776466, 96.390, 718.0, 26.7955
57.371297597, 96.390, 698.0, 26.4197
57.423818728, 96.390, 727.0, 26.9629
57.476339859, 96.390, 677.0, 26.0192
57.528860989, 96.390, 696.0, 26.3818
57.581382120, 96.390, 700.0, 26.4575
57.633903251, 96.390, 722.0, 26.8701
57.686424381, 96.390, 743.0, 27.2580
57.738945512, 96.390, 736.0, 27.1293
57.791466643, 96.390, 744.0, 27.2764
57.843987774, 96.390, 757.0, 27.5136
57.896508904, 96.390, 691.0, 26.2869
57.949030035, 96.390, 738.0, 27.1662
58.001551166, 96.390, 706.0, 26.5707
58.054072296, 96.390, 712.0, 26.6833
58.106593427, 96.390, 710.0, 26.6458
58.159114558, 96.390, 683.0, 26.1343
58.211635689, 96.390, 705.0, 26.5518
58.264156819, 96.390, 714.0, 26.7208
58.316677950, 96.390, 690.0, 26.2679
58.369199081, 96.390, 734.0, 27.0924
58.421720211, 96.390, 726.0, 26.9444
58.474241342, 96.390, 754.0, 27.4591
58.526762473, 96.390, 747.0, 27.3313
58.579283603, 96.390, 716.0, 26.7582
58.631804734, 96.390, 730.0, 27.0185
58.684325865, 96.390, 758.0, 27.5318
58.736846996, 96.390, 717.0, 26.7769
58.789368126, 96.390, 683.0, 26.1343
58.841889257, 96.390, 724.0, 26.9072
58.894410388, 96.390, 712.0, 26.6833
58.946931518, 96.390, 749.0, 27.3679
58.999452649, 96.390, 744.0, 27.2764
59.051973780, 96.390, 775.0, 27.8388
59.104494911, 96.390, 743.0, 27.2580
59.157016041, 96.390, 758.0, 27.5318
59.209537172, 96.390, 753.0, 27.4408
59.262058303, 96.390, 810.0, 28.4605
59.314579433, 96.390, 801.0, 28.3019
59.367100564, 96.390, 768.0, 27.7128
59.419621695, 96.390, 786.0, 28.0357
59.472142826, 96.390, 778.0, 27.8927
59.524663956, 96.390, 722.0, 26.8701
59.577185087, 96.390, 793.0, 28.1603
59.629706218, 96.390, 856.0, 29.2575
59.682227348, 96.390, 816.0, 28.5657
59.734748479, 96.390, 876.0, 29.5973
59.787269610, 96.390, 811.0, 28.4781
59.839790740, 96.390, 879.0, 29.6479
59.892311871, 96.390, 911.0, 30.1828
59.944833002, 96.390, 866.0, 29.4279
59.997354133, 96.390, 990.0, 31.4643
60.049875263, 96.390, 952.0, 30.8545
60.102396394, 96.390, 924.0, 30.3974
60.154917525, 96.390, 1013.0, 31.8277
60.207438655, 96.390, 1001.0, 31.6386
60.259959786, 96.390, 963.0, 31.0322
60.312480917, 96.390, 1068.0, 32.6803
60.365002048, 96.390, 1073.0, 32.7567
60.417523178, 96.390, 1091.0, 33.0303
60.470044309, 96.390, 1185.0, 34.4238
60.522565440, 96.390, 1116.0, 33.4066
60.575086570, 96.390, 1135.0, 33.6898
60.627607701, 96.390, 1274.0, 35.6931
60.680128832, 96.390, 1212.0, 34.8138
60.732649963, 96.390, 1236.0, 35.1568
60.785171093, 96.390, 1199.0, 34.6266
60.837692224, 96.390, 1277.0, 35.7351
60.890213355, 96.390, 1227.0, 35.0286
60.942734485, 96.390, 1302.0, 36.0832
60.995255616, 96.390, 1173.0, 34.2491
61.047776747, 96.390, 1179.0, 34.3366
61.100297878, 96.390, 1115.0, 33.3916
61.152819008, 96.390, 1117.0, 33.4215
61.205340139, 96.390, 1136.0, 33.7046
61.257861270, 96.390, 1072.0, 32.7414
61.310382400, 96.390, 1076.0, 32.8024
61.362903531, 96.390, 1144.0, 33.8231
61.415424662, 96.390, 1054.0, 32.4654
61.467945792, 96.390, 1086.0, 32.9545
61.520466923, 96.390, 1043.0, 32.2955
61.572988054, 96.390, 1098.0, 33.1361
61.625509185, 96.390, 1039.0, 32.2335
61.678030315, 96.390, 1107.0, 33.2716
61.730551446, 96.390, 1107.0, 33.2716
61.783072577, 96.390, 1130.0, 33.6155
61.835593707, 96.390, 1150.0, 33.9116
61.888114838, 96.390, 1121.0, 33.4813
61.940635969, 96.390, 1109.0, 33.3017
61.993157100, 96.390, 1141.0, 33.7787
62.045678230, 96.390, 1098.0, 33.1361
62.098199361, 96.390, 1148.0, 33.8821
62.150720492, 96.390, 1108.0, 33.2866
62.203241622, 96.390, 1138.0, 33.7343
62.255762753, 96.390, 1102.0, 33.1964
62.308283884, 96.390, 1127.0, 33.5708
62.360805015, 96.390, 997.0, 31.5753
62.413326145, 96.390, 1018.0, 31.9061
62.465847276, 96.390, 1027.0, 32.0468
62.518368407, 96.390, 965.0, 31.0644
62.570889537, 96.390, 897.0, 29.9500
62.623410668, 96.390, 922.0, 30.3645
62.675931799, 96.390, 1018.0, 31.9061
62.728452930, 96.390, 850.0, 29.1548
62.780974060, 96.390, 909.0, 30.1496
62.833495191, 96.390, 884.0, 29.7321
62.886016322, 96.390, 911.0, 30.1828
62.938537452, 96.390, 885.0, 29.7489
62.991058583, 96.390, 858.0, 29.2916
63.043579714, 96.390, 844.0, 29.0517
63.096100844, 96.390, 861.0, 29.3428
63.148621975, 96.390, 789.0, 28.0891
63.201143106, 96.390, 835.0, 28.8964
63.253664237, 96.390, 793.0, 28.1603
63.306185367, 96.390, 793.0, 28.1603
63.358706498, 96.390, 811.0, 28.4781
63.411227629, 96.390, 851.0, 29.1719
63.463748759, 96.390, 808.0, 28.4253
63.516269890, 96.390, 847.0, 29.1033
63.568791021, 96.390, 806.0, 28.3901
63.621312152, 96.390, 832.0, 28.8444
63.673833282, 96.390, 803.0, 28.3373
63.726354413, 96.390, 859.0, 29.3087
63.778875544, 96.390, 816.0, 28.5657
63.831396674, 96.390, 786.0, 28.0357
63.883917805, 96.390, 809.0, 28.4429
63.936438936, 96.390, 864.0, 29.3939
63.988960067, 96.390, 799.0, 28.2666
64.041481197, 96.390, 786.0, 28.0357
64.094002328, 96.390, 813.0, 28.5132
64.146523459, 96.390, 835.0, 28.8964
64.199044589, 96.390, 828.0, 28.7750
64.251565720, 96.390, 800.0, 28.2843
64.304086851, 96.390, 812.0, 28.4956
64.356607981, 96.390, 799.0, 28.2666
64.409129112, 96.390, 820.0, 28.6356
64.461650243, 96.390, 778.0, 27.8927
64.514171374, 96.390, 744.0, 27.2764
64.566692504, 96.390, 880.0, 29.6648
64.619213635, 96.390, 812.0, 28.4956
64.671734766, 96.390, 814.0, 28.5307
64.724255896, 96.390, 757.0, 27.5136
64.776777027, 96.390, 799.0, 28.2666
64.829298158, 96.390, 818.0, 28.6007
64.881819289, 96.390, 817.0, 28.5832
64.934340419, 96.390, 795.0, 28.1957
64.986861550, 96.390, 796.0, 28.2135