File: Files_organized_for_plots/134_days/H_XRD_134_SiAxial30Mar22_Act16Nov22_B1_0714M_NaOH_LS0173.csv
[Measurement conditions]
Sample identification,134_SiAxial30Mar22_Act16Nov22_B1_0714M_NaOH_LS0173
Comment - 1,"Configuration=Stage for Flat Samples/Holders, Owner=User-1, Creation date=7/1/2020 9:53:24 AM"
Comment - 2,"Goniometer=Theta/Theta; Minimum step size 2Theta:0.0001; Minimum step size Omega:0.0001"
Comment - 3,"Sample stage=Stage for flat samples/holders"
Comment - 4,"Diffractometer system=EMPYREAN"
Comment - 5,"Measurement program=C:\Users\tmr79\OneDrive - The Pennsylvania State University\Documents\NEUP\XRD\Cement\Zerobackground scan.xrdmp, Identifier={98A3B11C-88F9-4AA6-982C-73314A311EF5}"
Anode material,Cu
K-Alpha1 wavelength,1.5405980
K-Alpha2 wavelength,1.5444260
Ratio K-Alpha2/K-Alpha1,0.500
Divergence slit,Fixed,0.25
Monochromator used,NO
Generator voltage, 45
Tube current, 40
File date and time,03/Apr/2023 09:43
Unit cell,
h k l, 0 0 0
Scan axis,Gonio
Scan range,4.994599997,64.999991833
Scan step size,0.0262606
No. of points, 2285
Scan type,CONTINUOUS
Time per step,96.390
[Scan points]
Angle, TimePerStep, Intensity, ESD
5.007730280, 96.390, 4434.0, 66.5883
5.060251411, 96.390, 4351.0, 65.9621
5.112772541, 96.390, 4233.0, 65.0615
5.165293672, 96.390, 4173.0, 64.5988
5.217814803, 96.390, 4221.0, 64.9692
5.270335934, 96.390, 4104.0, 64.0625
5.322857064, 96.390, 4131.0, 64.2729
5.375378195, 96.390, 3858.0, 62.1128
5.427899326, 96.390, 4105.0, 64.0703
5.480420456, 96.390, 3935.0, 62.7296
5.532941587, 96.390, 3902.0, 62.4660
5.585462718, 96.390, 3944.0, 62.8013
5.637983849, 96.390, 3851.0, 62.0564
5.690504979, 96.390, 3934.0, 62.7216
5.743026110, 96.390, 3762.0, 61.3351
5.795547241, 96.390, 3824.0, 61.8385
5.848068371, 96.390, 3750.0, 61.2372
5.900589502, 96.390, 3761.0, 61.3270
5.953110633, 96.390, 3618.0, 60.1498
6.005631763, 96.390, 3615.0, 60.1249
6.058152894, 96.390, 3595.0, 59.9583
6.110674025, 96.390, 3623.0, 60.1914
6.163195156, 96.390, 3490.0, 59.0762
6.215716286, 96.390, 3579.0, 59.8247
6.268237417, 96.390, 3477.0, 58.9661
6.320758548, 96.390, 3435.0, 58.6089
6.373279678, 96.390, 3523.0, 59.3549
6.425800809, 96.390, 3469.0, 58.8982
6.478321940, 96.390, 3558.0, 59.6490
6.530843071, 96.390, 3413.0, 58.4209
6.583364201, 96.390, 3470.0, 58.9067
6.635885332, 96.390, 3428.0, 58.5491
6.688406463, 96.390, 3340.0, 57.7927
6.740927593, 96.390, 3436.0, 58.6174
6.793448724, 96.390, 3376.0, 58.1034
6.845969855, 96.390, 3411.0, 58.4038
6.898490986, 96.390, 3276.0, 57.2364
6.951012116, 96.390, 3294.0, 57.3934
7.003533247, 96.390, 3395.0, 58.2666
7.056054378, 96.390, 3360.0, 57.9655
7.108575508, 96.390, 3377.0, 58.1120
7.161096639, 96.390, 3227.0, 56.8067
7.213617770, 96.390, 3313.0, 57.5587
7.266138900, 96.390, 3215.0, 56.7010
7.318660031, 96.390, 3383.0, 58.1636
7.371181162, 96.390, 3252.0, 57.0263
7.423702293, 96.390, 3146.0, 56.0892
7.476223423, 96.390, 3197.0, 56.5420
7.528744554, 96.390, 3230.0, 56.8331
7.581265685, 96.390, 3152.0, 56.1427
7.633786815, 96.390, 3145.0, 56.0803
7.686307946, 96.390, 3151.0, 56.1338
7.738829077, 96.390, 3306.0, 57.4978
7.791350208, 96.390, 3246.0, 56.9737
7.843871338, 96.390, 3185.0, 56.4358
7.896392469, 96.390, 3158.0, 56.1961
7.948913600, 96.390, 3249.0, 57.0000
8.001434730, 96.390, 3182.0, 56.4092
8.053955861, 96.390, 3261.0, 57.1052
8.106476992, 96.390, 3444.0, 58.6856
8.158998123, 96.390, 3427.0, 58.5406
8.211519253, 96.390, 3570.0, 59.7495
8.264040384, 96.390, 3745.0, 61.1964
8.316561515, 96.390, 3917.0, 62.5859
8.369082645, 96.390, 4245.0, 65.1537
8.421603776, 96.390, 4581.0, 67.6831
8.474124907, 96.390, 5022.0, 70.8661
8.526646038, 96.390, 5715.0, 75.5976
8.579167168, 96.390, 5972.0, 77.2787
8.631688299, 96.390, 6013.0, 77.5435
8.684209430, 96.390, 5459.0, 73.8850
8.736730560, 96.390, 4651.0, 68.1982
8.789251691, 96.390, 4157.0, 64.4748
8.841772822, 96.390, 3714.0, 60.9426
8.894293952, 96.390, 3572.0, 59.7662
8.946815083, 96.390, 3511.0, 59.2537
8.999336214, 96.390, 3388.0, 58.2065
9.051857345, 96.390, 3305.0, 57.4891
9.104378475, 96.390, 3343.0, 57.8187
9.156899606, 96.390, 3238.0, 56.9034
9.209420737, 96.390, 3175.0, 56.3471
9.261941867, 96.390, 3261.0, 57.1052
9.314462998, 96.390, 3282.0, 57.2887
9.366984129, 96.390, 3208.0, 56.6392
9.419505260, 96.390, 3242.0, 56.9386
9.472026390, 96.390, 3163.0, 56.2406
9.524547521, 96.390, 3254.0, 57.0438
9.577068652, 96.390, 3244.0, 56.9561
9.629589782, 96.390, 3081.0, 55.5068
9.682110913, 96.390, 3184.0, 56.4269
9.734632044, 96.390, 3085.0, 55.5428
9.787153175, 96.390, 3036.0, 55.0999
9.839674305, 96.390, 2989.0, 54.6717
9.892195436, 96.390, 3069.0, 55.3986
9.944716567, 96.390, 3008.0, 54.8452
9.997237697, 96.390, 2996.0, 54.7357
10.049758828, 96.390, 2956.0, 54.3691
10.102279959, 96.390, 2905.0, 53.8981
10.154801090, 96.390, 2846.0, 53.3479
10.207322220, 96.390, 2866.0, 53.5350
10.259843351, 96.390, 2784.0, 52.7636
10.312364482, 96.390, 2861.0, 53.4883
10.364885612, 96.390, 2749.0, 52.4309
10.417406743, 96.390, 2743.0, 52.3737
10.469927874, 96.390, 2740.0, 52.3450
10.522449004, 96.390, 2801.0, 52.9245
10.574970135, 96.390, 2841.0, 53.3010
10.627491266, 96.390, 2595.0, 50.9411
10.680012397, 96.390, 2785.0, 52.7731
10.732533527, 96.390, 2728.0, 52.2303
10.785054658, 96.390, 2668.0, 51.6527
10.837575789, 96.390, 2654.0, 51.5170
10.890096919, 96.390, 2694.0, 51.9038
10.942618050, 96.390, 2678.0, 51.7494
10.995139181, 96.390, 2565.0, 50.6458
11.047660312, 96.390, 2548.0, 50.4777
11.100181442, 96.390, 2546.0, 50.4579
11.152702573, 96.390, 2574.0, 50.7346
11.205223704, 96.390, 2620.0, 51.1859
11.257744834, 96.390, 2628.0, 51.2640
11.310265965, 96.390, 2487.0, 49.8698
11.362787096, 96.390, 2536.0, 50.3587
11.415308227, 96.390, 2464.0, 49.6387
11.467829357, 96.390, 2465.0, 49.6488
11.520350488, 96.390, 2486.0, 49.8598
11.572871619, 96.390, 2421.0, 49.2037
11.625392749, 96.390, 2365.0, 48.6313
11.677913880, 96.390, 2394.0, 48.9285
11.730435011, 96.390, 2404.0, 49.0306
11.782956141, 96.390, 2492.0, 49.9199
11.835477272, 96.390, 2360.0, 48.5798
11.887998403, 96.390, 2363.0, 48.6107
11.940519534, 96.390, 2419.0, 49.1833
11.993040664, 96.390, 2416.0, 49.1528
12.045561795, 96.390, 2424.0, 49.2341
12.098082926, 96.390, 2417.0, 49.1630
12.150604056, 96.390, 2496.0, 49.9600
12.203125187, 96.390, 2445.0, 49.4469
12.255646318, 96.390, 2385.0, 48.8365
12.308167449, 96.390, 2486.0, 49.8598
12.360688579, 96.390, 2359.0, 48.5695
12.413209710, 96.390, 2310.0, 48.0625
12.465730841, 96.390, 2337.0, 48.3425
12.518251971, 96.390, 2355.0, 48.5283
12.570773102, 96.390, 2408.0, 49.0714
12.623294233, 96.390, 2268.0, 47.6235
12.675815364, 96.390, 2312.0, 48.0833
12.728336494, 96.390, 2273.0, 47.6760
12.780857625, 96.390, 2301.0, 47.9687
12.833378756, 96.390, 2281.0, 47.7598
12.885899886, 96.390, 2248.0, 47.4131
12.938421017, 96.390, 2331.0, 48.2804
12.990942148, 96.390, 2205.0, 46.9574
13.043463279, 96.390, 2133.0, 46.1844
13.095984409, 96.390, 2155.0, 46.4220
13.148505540, 96.390, 2175.0, 46.6369
13.201026671, 96.390, 2048.0, 45.2548
13.253547801, 96.390, 2042.0, 45.1885
13.306068932, 96.390, 2124.0, 46.0869
13.358590063, 96.390, 2038.0, 45.1442
13.411111193, 96.390, 2011.0, 44.8442
13.463632324, 96.390, 2170.0, 46.5833
13.516153455, 96.390, 2104.0, 45.8694
13.568674586, 96.390, 2032.0, 45.0777
13.621195716, 96.390, 2125.0, 46.0977
13.673716847, 96.390, 2003.0, 44.7549
13.726237978, 96.390, 2006.0, 44.7884
13.778759108, 96.390, 2026.0, 45.0111
13.831280239, 96.390, 2030.0, 45.0555
13.883801370, 96.390, 2056.0, 45.3431
13.936322501, 96.390, 1933.0, 43.9659
13.988843631, 96.390, 1970.0, 44.3847
14.041364762, 96.390, 1980.0, 44.4972
14.093885893, 96.390, 1892.0, 43.4971
14.146407023, 96.390, 2023.0, 44.9778
14.198928154, 96.390, 1939.0, 44.0341
14.251449285, 96.390, 1902.0, 43.6119
14.303970416, 96.390, 1945.0, 44.1022
14.356491546, 96.390, 1892.0, 43.4971
14.409012677, 96.390, 1978.0, 44.4747
14.461533808, 96.390, 1992.0, 44.6318
14.514054938, 96.390, 1898.0, 43.5660
14.566576069, 96.390, 1926.0, 43.8862
14.619097200, 96.390, 1961.0, 44.2832
14.671618331, 96.390, 2020.0, 44.9444
14.724139461, 96.390, 1972.0, 44.4072
14.776660592, 96.390, 1833.0, 42.8135
14.829181723, 96.390, 1923.0, 43.8520
14.881702853, 96.390, 1907.0, 43.6692
14.934223984, 96.390, 1972.0, 44.4072
14.986745115, 96.390, 2016.0, 44.8999
15.039266245, 96.390, 2036.0, 45.1221
15.091787376, 96.390, 2047.0, 45.2438
15.144308507, 96.390, 2074.0, 45.5412
15.196829638, 96.390, 1944.0, 44.0908
15.249350768, 96.390, 2077.0, 45.5741
15.301871899, 96.390, 2063.0, 45.4203
15.354393030, 96.390, 1985.0, 44.5533
15.406914160, 96.390, 2009.0, 44.8219
15.459435291, 96.390, 2010.0, 44.8330
15.511956422, 96.390, 1927.0, 43.8976
15.564477553, 96.390, 1998.0, 44.6990
15.616998683, 96.390, 1977.0, 44.4635
15.669519814, 96.390, 1975.0, 44.4410
15.722040945, 96.390, 1988.0, 44.5870
15.774562075, 96.390, 2056.0, 45.3431
15.827083206, 96.390, 1917.0, 43.7836
15.879604337, 96.390, 2042.0, 45.1885
15.932125468, 96.390, 1957.0, 44.2380
15.984646598, 96.390, 2005.0, 44.7772
16.037167729, 96.390, 1916.0, 43.7721
16.089688860, 96.390, 2006.0, 44.7884
16.142209990, 96.390, 2045.0, 45.2217
16.194731121, 96.390, 1966.0, 44.3396
16.247252252, 96.390, 2003.0, 44.7549
16.299773382, 96.390, 2021.0, 44.9555
16.352294513, 96.390, 2036.0, 45.1221
16.404815644, 96.390, 2025.0, 45.0000
16.457336775, 96.390, 2060.0, 45.3872
16.509857905, 96.390, 1959.0, 44.2606
16.562379036, 96.390, 2013.0, 44.8665
16.614900167, 96.390, 1977.0, 44.4635
16.667421297, 96.390, 2045.0, 45.2217
16.719942428, 96.390, 2016.0, 44.8999
16.772463559, 96.390, 2090.0, 45.7165
16.824984690, 96.390, 2029.0, 45.0444
16.877505820, 96.390, 2041.0, 45.1774
16.930026951, 96.390, 2111.0, 45.9456
16.982548082, 96.390, 2192.0, 46.8188
17.035069212, 96.390, 2188.0, 46.7761
17.087590343, 96.390, 2212.0, 47.0319
17.140111474, 96.390, 2256.0, 47.4974
17.192632605, 96.390, 2267.0, 47.6130
17.245153735, 96.390, 2293.0, 47.8853
17.297674866, 96.390, 2363.0, 48.6107
17.350195997, 96.390, 2223.0, 47.1487
17.402717127, 96.390, 2247.0, 47.4025
17.455238258, 96.390, 2315.0, 48.1144
17.507759389, 96.390, 2342.0, 48.3942
17.560280520, 96.390, 2267.0, 47.6130
17.612801650, 96.390, 2348.0, 48.4562
17.665322781, 96.390, 2297.0, 47.9270
17.717843912, 96.390, 2438.0, 49.3761
17.770365042, 96.390, 2262.0, 47.5605
17.822886173, 96.390, 2330.0, 48.2701
17.875407304, 96.390, 2403.0, 49.0204
17.927928434, 96.390, 2293.0, 47.8853
17.980449565, 96.390, 2276.0, 47.7074
18.032970696, 96.390, 2346.0, 48.4355
18.085491827, 96.390, 2310.0, 48.0625
18.138012957, 96.390, 2313.0, 48.0937
18.190534088, 96.390, 2287.0, 47.8226
18.243055219, 96.390, 2370.0, 48.6826
18.295576349, 96.390, 2439.0, 49.3862
18.348097480, 96.390, 2394.0, 48.9285
18.400618611, 96.390, 2359.0, 48.5695
18.453139742, 96.390, 2336.0, 48.3322
18.505660872, 96.390, 2415.0, 49.1426
18.558182003, 96.390, 2375.0, 48.7340
18.610703134, 96.390, 2314.0, 48.1041
18.663224264, 96.390, 2285.0, 47.8017
18.715745395, 96.390, 2322.0, 48.1871
18.768266526, 96.390, 2336.0, 48.3322
18.820787657, 96.390, 2321.0, 48.1768
18.873308787, 96.390, 2278.0, 47.7284
18.925829918, 96.390, 2395.0, 48.9387
18.978351049, 96.390, 2282.0, 47.7703
19.030872179, 96.390, 2432.0, 49.3153
19.083393310, 96.390, 2393.0, 48.9183
19.135914441, 96.390, 2377.0, 48.7545
19.188435572, 96.390, 2423.0, 49.2240
19.240956702, 96.390, 2402.0, 49.0102
19.293477833, 96.390, 2345.0, 48.4252
19.345998964, 96.390, 2444.0, 49.4368
19.398520094, 96.390, 2375.0, 48.7340
19.451041225, 96.390, 2446.0, 49.4571
19.503562356, 96.390, 2477.0, 49.7695
19.556083486, 96.390, 2508.0, 50.0799
19.608604617, 96.390, 2515.0, 50.1498
19.661125748, 96.390, 2504.0, 50.0400
19.713646879, 96.390, 2525.0, 50.2494
19.766168009, 96.390, 2556.0, 50.5569
19.818689140, 96.390, 2538.0, 50.3786
19.871210271, 96.390, 2425.0, 49.2443
19.923731401, 96.390, 2453.0, 49.5278
19.976252532, 96.390, 2683.0, 51.7977
20.028773663, 96.390, 2542.0, 50.4183
20.081294794, 96.390, 2519.0, 50.1896
20.133815924, 96.390, 2577.0, 50.7642
20.186337055, 96.390, 2535.0, 50.3488
20.238858186, 96.390, 2541.0, 50.4083
20.291379316, 96.390, 2589.0, 50.8822
20.343900447, 96.390, 2554.0, 50.5371
20.396421578, 96.390, 2668.0, 51.6527
20.448942709, 96.390, 2587.0, 50.8626
20.501463839, 96.390, 2597.0, 50.9608
20.553984970, 96.390, 2586.0, 50.8527
20.606506101, 96.390, 2548.0, 50.4777
20.659027231, 96.390, 2621.0, 51.1957
20.711548362, 96.390, 2614.0, 51.1273
20.764069493, 96.390, 2660.0, 51.5752
20.816590623, 96.390, 2539.0, 50.3885
20.869111754, 96.390, 2677.0, 51.7397
20.921632885, 96.390, 2594.0, 50.9313
20.974154016, 96.390, 2609.0, 51.0784
21.026675146, 96.390, 2635.0, 51.3323
21.079196277, 96.390, 2665.0, 51.6236
21.131717408, 96.390, 2689.0, 51.8556
21.184238538, 96.390, 2674.0, 51.7107
21.236759669, 96.390, 2581.0, 50.8035
21.289280800, 96.390, 2665.0, 51.6236
21.341801931, 96.390, 2673.0, 51.7011
21.394323061, 96.390, 2694.0, 51.9038
21.446844192, 96.390, 2645.0, 51.4296
21.499365323, 96.390, 2614.0, 51.1273
21.551886453, 96.390, 2743.0, 52.3737
21.604407584, 96.390, 2708.0, 52.0384
21.656928715, 96.390, 2746.0, 52.4023
21.709449846, 96.390, 2724.0, 52.1920
21.761970976, 96.390, 2710.0, 52.0577
21.814492107, 96.390, 2735.0, 52.2972
21.867013238, 96.390, 2712.0, 52.0769
21.919534368, 96.390, 2852.0, 53.4041
21.972055499, 96.390, 2839.0, 53.2823
22.024576630, 96.390, 2887.0, 53.7308
22.077097761, 96.390, 2866.0, 53.5350
22.129618891, 96.390, 2787.0, 52.7920
22.182140022, 96.390, 2675.0, 51.7204
22.234661153, 96.390, 2689.0, 51.8556
22.287182283, 96.390, 2752.0, 52.4595
22.339703414, 96.390, 2792.0, 52.8394
22.392224545, 96.390, 2887.0, 53.7308
22.444745675, 96.390, 2954.0, 54.3507
22.497266806, 96.390, 2920.0, 54.0370
22.549787937, 96.390, 2936.0, 54.1849
22.602309068, 96.390, 2962.0, 54.4243
22.654830198, 96.390, 2930.0, 54.1295
22.707351329, 96.390, 2889.0, 53.7494
22.759872460, 96.390, 2885.0, 53.7122
22.812393590, 96.390, 2812.0, 53.0283
22.864914721, 96.390, 2692.0, 51.8845
22.917435852, 96.390, 2743.0, 52.3737
22.969956983, 96.390, 2714.0, 52.0961
23.022478113, 96.390, 2735.0, 52.2972
23.074999244, 96.390, 2778.0, 52.7067
23.127520375, 96.390, 2721.0, 52.1632
23.180041505, 96.390, 2713.0, 52.0865
23.232562636, 96.390, 2709.0, 52.0481
23.285083767, 96.390, 2727.0, 52.2207
23.337604898, 96.390, 2570.0, 50.6952
23.390126028, 96.390, 2725.0, 52.2015
23.442647159, 96.390, 2612.0, 51.1077
23.495168290, 96.390, 2625.0, 51.2348
23.547689420, 96.390, 2535.0, 50.3488
23.600210551, 96.390, 2634.0, 51.3225
23.652731682, 96.390, 2589.0, 50.8822
23.705252813, 96.390, 2728.0, 52.2303
23.757773943, 96.390, 2644.0, 51.4198
23.810295074, 96.390, 2567.0, 50.6656
23.862816205, 96.390, 2531.0, 50.3090
23.915337335, 96.390, 2514.0, 50.1398
23.967858466, 96.390, 2544.0, 50.4381
24.020379597, 96.390, 2527.0, 50.2693
24.072900727, 96.390, 2628.0, 51.2640
24.125421858, 96.390, 2479.0, 49.7896
24.177942989, 96.390, 2430.0, 49.2950
24.230464120, 96.390, 2526.0, 50.2593
24.282985250, 96.390, 2417.0, 49.1630
24.335506381, 96.390, 2441.0, 49.4065
24.388027512, 96.390, 2479.0, 49.7896
24.440548642, 96.390, 2441.0, 49.4065
24.493069773, 96.390, 2439.0, 49.3862
24.545590904, 96.390, 2356.0, 48.5386
24.598112035, 96.390, 2396.0, 48.9490
24.650633165, 96.390, 2311.0, 48.0729
24.703154296, 96.390, 2265.0, 47.5920
24.755675427, 96.390, 2247.0, 47.4025
24.808196557, 96.390, 2400.0, 48.9898
24.860717688, 96.390, 2137.0, 46.2277
24.913238819, 96.390, 2172.0, 46.6047
24.965759950, 96.390, 2134.0, 46.1952
25.018281080, 96.390, 2272.0, 47.6655
25.070802211, 96.390, 2226.0, 47.1805
25.123323342, 96.390, 2289.0, 47.8435
25.175844472, 96.390, 2162.0, 46.4973
25.228365603, 96.390, 2160.0, 46.4758
25.280886734, 96.390, 2181.0, 46.7012
25.333407864, 96.390, 2172.0, 46.6047
25.385928995, 96.390, 2182.0, 46.7119
25.438450126, 96.390, 2035.0, 45.1110
25.490971257, 96.390, 2068.0, 45.4753
25.543492387, 96.390, 2205.0, 46.9574
25.596013518, 96.390, 2169.0, 46.5725
25.648534649, 96.390, 2065.0, 45.4423
25.701055779, 96.390, 2065.0, 45.4423
25.753576910, 96.390, 2046.0, 45.2327
25.806098041, 96.390, 2073.0, 45.5302
25.858619172, 96.390, 2053.0, 45.3100
25.911140302, 96.390, 2070.0, 45.4973
25.963661433, 96.390, 2034.0, 45.0999
26.016182564, 96.390, 2055.0, 45.3321
26.068703694, 96.390, 2178.0, 46.6690
26.121224825, 96.390, 2061.0, 45.3982
26.173745956, 96.390, 2113.0, 45.9674
26.226267087, 96.390, 2166.0, 46.5403
26.278788217, 96.390, 2227.0, 47.1911
26.331309348, 96.390, 2112.0, 45.9565
26.383830479, 96.390, 2112.0, 45.9565
26.436351609, 96.390, 2100.0, 45.8258
26.488872740, 96.390, 2074.0, 45.5412
26.541393871, 96.390, 2040.0, 45.1664
26.593915002, 96.390, 2032.0, 45.0777
26.646436132, 96.390, 2049.0, 45.2659
26.698957263, 96.390, 2089.0, 45.7056
26.751478394, 96.390, 1975.0, 44.4410
26.803999524, 96.390, 2059.0, 45.3762
26.856520655, 96.390, 2032.0, 45.0777
26.909041786, 96.390, 2028.0, 45.0333
26.961562916, 96.390, 2049.0, 45.2659
27.014084047, 96.390, 2003.0, 44.7549
27.066605178, 96.390, 1880.0, 43.3590
27.119126309, 96.390, 1986.0, 44.5646
27.171647439, 96.390, 1910.0, 43.7035
27.224168570, 96.390, 1930.0, 43.9318
27.276689701, 96.390, 1862.0, 43.1509
27.329210831, 96.390, 1894.0, 43.5201
27.381731962, 96.390, 1872.0, 43.2666
27.434253093, 96.390, 1810.0, 42.5441
27.486774224, 96.390, 1838.0, 42.8719
27.539295354, 96.390, 1846.0, 42.9651
27.591816485, 96.390, 1861.0, 43.1393
27.644337616, 96.390, 1810.0, 42.5441
27.696858746, 96.390, 1768.0, 42.0476
27.749379877, 96.390, 1858.0, 43.1045
27.801901008, 96.390, 1785.0, 42.2493
27.854422139, 96.390, 1784.0, 42.2374
27.906943269, 96.390, 1851.0, 43.0232
27.959464400, 96.390, 1842.0, 42.9185
28.011985531, 96.390, 1815.0, 42.6028
28.064506661, 96.390, 1790.0, 42.3084
28.117027792, 96.390, 1753.0, 41.8688
28.169548923, 96.390, 1695.0, 41.1704
28.222070054, 96.390, 1707.0, 41.3159
28.274591184, 96.390, 1805.0, 42.4853
28.327112315, 96.390, 1810.0, 42.5441
28.379633446, 96.390, 1770.0, 42.0714
28.432154576, 96.390, 1694.0, 41.1582
28.484675707, 96.390, 1745.0, 41.7732
28.537196838, 96.390, 1785.0, 42.2493
28.589717968, 96.390, 1746.0, 41.7852
28.642239099, 96.390, 1752.0, 41.8569
28.694760230, 96.390, 1770.0, 42.0714
28.747281361, 96.390, 1724.0, 41.5211
28.799802491, 96.390, 1792.0, 42.3320
28.852323622, 96.390, 1833.0, 42.8135
28.904844753, 96.390, 1663.0, 40.7799
28.957365883, 96.390, 1715.0, 41.4126
29.009887014, 96.390, 1745.0, 41.7732
29.062408145, 96.390, 1773.0, 42.1070
29.114929276, 96.390, 1838.0, 42.8719
29.167450406, 96.390, 1729.0, 41.5812
29.219971537, 96.390, 1713.0, 41.3884
29.272492668, 96.390, 1663.0, 40.7799
29.325013798, 96.390, 1714.0, 41.4005
29.377534929, 96.390, 1711.0, 41.3642
29.430056060, 96.390, 1720.0, 41.4729
29.482577191, 96.390, 1716.0, 41.4246
29.535098321, 96.390, 1779.0, 42.1782
29.587619452, 96.390, 1693.0, 41.1461
29.640140583, 96.390, 1751.0, 41.8450
29.692661713, 96.390, 1786.0, 42.2611
29.745182844, 96.390, 1784.0, 42.2374
29.797703975, 96.390, 1745.0, 41.7732
29.850225105, 96.390, 1785.0, 42.2493
29.902746236, 96.390, 1784.0, 42.2374
29.955267367, 96.390, 1707.0, 41.3159
30.007788498, 96.390, 1801.0, 42.4382
30.060309628, 96.390, 1838.0, 42.8719
30.112830759, 96.390, 1782.0, 42.2137
30.165351890, 96.390, 1743.0, 41.7493
30.217873020, 96.390, 1830.0, 42.7785
30.270394151, 96.390, 1685.0, 41.0488
30.322915282, 96.390, 1771.0, 42.0833
30.375436413, 96.390, 1826.0, 42.7317
30.427957543, 96.390, 1740.0, 41.7133
30.480478674, 96.390, 1724.0, 41.5211
30.532999805, 96.390, 1727.0, 41.5572
30.585520935, 96.390, 1710.0, 41.3521
30.638042066, 96.390, 1733.0, 41.6293
30.690563197, 96.390, 1700.0, 41.2311
30.743084328, 96.390, 1661.0, 40.7554
30.795605458, 96.390, 1577.0, 39.7115
30.848126589, 96.390, 1655.0, 40.6817
30.900647720, 96.390, 1633.0, 40.4104
30.953168850, 96.390, 1633.0, 40.4104
31.005689981, 96.390, 1546.0, 39.3192
31.058211112, 96.390, 1525.0, 39.0512
31.110732243, 96.390, 1587.0, 39.8372
31.163253373, 96.390, 1619.0, 40.2368
31.215774504, 96.390, 1544.0, 39.2938
31.268295635, 96.390, 1537.0, 39.2046
31.320816765, 96.390, 1593.0, 39.9124
31.373337896, 96.390, 1519.0, 38.9744
31.425859027, 96.390, 1531.0, 39.1280
31.478380157, 96.390, 1503.0, 38.7685
31.530901288, 96.390, 1607.0, 40.0874
31.583422419, 96.390, 1475.0, 38.4057
31.635943550, 96.390, 1630.0, 40.3733
31.688464680, 96.390, 1648.0, 40.5956
31.740985811, 96.390, 1621.0, 40.2616
31.793506942, 96.390, 1608.0, 40.0999
31.846028072, 96.390, 1564.0, 39.5474
31.898549203, 96.390, 1562.0, 39.5221
31.951070334, 96.390, 1611.0, 40.1373
32.003591465, 96.390, 1509.0, 38.8458
32.056112595, 96.390, 1532.0, 39.1408
32.108633726, 96.390, 1527.0, 39.0768
32.161154857, 96.390, 1460.0, 38.2099
32.213675987, 96.390, 1532.0, 39.1408
32.266197118, 96.390, 1537.0, 39.2046
32.318718249, 96.390, 1557.0, 39.4588
32.371239380, 96.390, 1509.0, 38.8458
32.423760510, 96.390, 1576.0, 39.6989
32.476281641, 96.390, 1450.0, 38.0789
32.528802772, 96.390, 1540.0, 39.2428
32.581323902, 96.390, 1533.0, 39.1535
32.633845033, 96.390, 1509.0, 38.8458
32.686366164, 96.390, 1530.0, 39.1152
32.738887295, 96.390, 1451.0, 38.0920
32.791408425, 96.390, 1540.0, 39.2428
32.843929556, 96.390, 1528.0, 39.0896
32.896450687, 96.390, 1565.0, 39.5601
32.948971817, 96.390, 1500.0, 38.7298
33.001492948, 96.390, 1506.0, 38.8072
33.054014079, 96.390, 1539.0, 39.2301
33.106535209, 96.390, 1609.0, 40.1123
33.159056340, 96.390, 1546.0, 39.3192
33.211577471, 96.390, 1475.0, 38.4057
33.264098602, 96.390, 1546.0, 39.3192
33.316619732, 96.390, 1544.0, 39.2938
33.369140863, 96.390, 1489.0, 38.5876
33.421661994, 96.390, 1460.0, 38.2099
33.474183124, 96.390, 1545.0, 39.3065
33.526704255, 96.390, 1469.0, 38.3275
33.579225386, 96.390, 1508.0, 38.8330
33.631746517, 96.390, 1529.0, 39.1024
33.684267647, 96.390, 1491.0, 38.6135
33.736788778, 96.390, 1480.0, 38.4708
33.789309909, 96.390, 1561.0, 39.5095
33.841831039, 96.390, 1490.0, 38.6005
33.894352170, 96.390, 1509.0, 38.8458
33.946873301, 96.390, 1539.0, 39.2301
33.999394432, 96.390, 1561.0, 39.5095
34.051915562, 96.390, 1500.0, 38.7298
34.104436693, 96.390, 1556.0, 39.4462
34.156957824, 96.390, 1566.0, 39.5727
34.209478954, 96.390, 1582.0, 39.7744
34.262000085, 96.390, 1560.0, 39.4968
34.314521216, 96.390, 1632.0, 40.3980
34.367042346, 96.390, 1615.0, 40.1871
34.419563477, 96.390, 1618.0, 40.2244
34.472084608, 96.390, 1648.0, 40.5956
34.524605739, 96.390, 1635.0, 40.4351
34.577126869, 96.390, 1659.0, 40.7308
34.629648000, 96.390, 1703.0, 41.2674
34.682169131, 96.390, 1775.0, 42.1307
34.734690261, 96.390, 1728.0, 41.5692
34.787211392, 96.390, 1726.0, 41.5452
34.839732523, 96.390, 1717.0, 41.4367
34.892253654, 96.390, 1823.0, 42.6966
34.944774784, 96.390, 1746.0, 41.7852
34.997295915, 96.390, 1787.0, 42.2729
35.049817046, 96.390, 1779.0, 42.1782
35.102338176, 96.390, 1727.0, 41.5572
35.154859307, 96.390, 1701.0, 41.2432
35.207380438, 96.390, 1724.0, 41.5211
35.259901569, 96.390, 1603.0, 40.0375
35.312422699, 96.390, 1600.0, 40.0000
35.364943830, 96.390, 1616.0, 40.1995
35.417464961, 96.390, 1595.0, 39.9375
35.469986091, 96.390, 1562.0, 39.5221
35.522507222, 96.390, 1618.0, 40.2244
35.575028353, 96.390, 1547.0, 39.3319
35.627549484, 96.390, 1571.0, 39.6358
35.680070614, 96.390, 1500.0, 38.7298
35.732591745, 96.390, 1555.0, 39.4335
35.785112876, 96.390, 1548.0, 39.3446
35.837634006, 96.390, 1560.0, 39.4968
35.890155137, 96.390, 1519.0, 38.9744
35.942676268, 96.390, 1465.0, 38.2753
35.995197398, 96.390, 1500.0, 38.7298
36.047718529, 96.390, 1525.0, 39.0512
36.100239660, 96.390, 1465.0, 38.2753
36.152760791, 96.390, 1491.0, 38.6135
36.205281921, 96.390, 1463.0, 38.2492
36.257803052, 96.390, 1489.0, 38.5876
36.310324183, 96.390, 1422.0, 37.7094
36.362845313, 96.390, 1444.0, 38.0000
36.415366444, 96.390, 1417.0, 37.6431
36.467887575, 96.390, 1403.0, 37.4566
36.520408706, 96.390, 1444.0, 38.0000
36.572929836, 96.390, 1425.0, 37.7492
36.625450967, 96.390, 1413.0, 37.5899
36.677972098, 96.390, 1442.0, 37.9737
36.730493228, 96.390, 1384.0, 37.2022
36.783014359, 96.390, 1384.0, 37.2022
36.835535490, 96.390, 1409.0, 37.5366
36.888056621, 96.390, 1450.0, 38.0789
36.940577751, 96.390, 1354.0, 36.7967
36.993098882, 96.390, 1332.0, 36.4966
37.045620013, 96.390, 1340.0, 36.6060
37.098141143, 96.390, 1306.0, 36.1386
37.150662274, 96.390, 1360.0, 36.8782
37.203183405, 96.390, 1280.0, 35.7771
37.255704535, 96.390, 1210.0, 34.7851
37.308225666, 96.390, 1279.0, 35.7631
37.360746797, 96.390, 1254.0, 35.4119
37.413267928, 96.390, 1246.0, 35.2987
37.465789058, 96.390, 1235.0, 35.1426
37.518310189, 96.390, 1240.0, 35.2136
37.570831320, 96.390, 1251.0, 35.3695
37.623352450, 96.390, 1230.0, 35.0714
37.675873581, 96.390, 1245.0, 35.2846
37.728394712, 96.390, 1192.0, 34.5254
37.780915843, 96.390, 1201.0, 34.6554
37.833436973, 96.390, 1219.0, 34.9142
37.885958104, 96.390, 1190.0, 34.4964
37.938479235, 96.390, 1265.0, 35.5668
37.991000365, 96.390, 1194.0, 34.5543
38.043521496, 96.390, 1228.0, 35.0428
38.096042627, 96.390, 1238.0, 35.1852
38.148563758, 96.390, 1176.0, 34.2929
38.201084888, 96.390, 1167.0, 34.1614
38.253606019, 96.390, 1210.0, 34.7851
38.306127150, 96.390, 1260.0, 35.4965
38.358648280, 96.390, 1214.0, 34.8425
38.411169411, 96.390, 1186.0, 34.4384
38.463690542, 96.390, 1204.0, 34.6987
38.516211673, 96.390, 1195.0, 34.5688
38.568732803, 96.390, 1200.0, 34.6410
38.621253934, 96.390, 1257.0, 35.4542
38.673775065, 96.390, 1191.0, 34.5109
38.726296195, 96.390, 1214.0, 34.8425
38.778817326, 96.390, 1091.0, 33.0303
38.831338457, 96.390, 1131.0, 33.6303
38.883859587, 96.390, 1115.0, 33.3916
38.936380718, 96.390, 1100.0, 33.1662
38.988901849, 96.390, 1159.0, 34.0441
39.041422980, 96.390, 1121.0, 33.4813
39.093944110, 96.390, 1061.0, 32.5730
39.146465241, 96.390, 1113.0, 33.3617
39.198986372, 96.390, 1078.0, 32.8329
39.251507502, 96.390, 1098.0, 33.1361
39.304028633, 96.390, 1075.0, 32.7872
39.356549764, 96.390, 994.0, 31.5278
39.409070895, 96.390, 1039.0, 32.2335
39.461592025, 96.390, 1067.0, 32.6650
39.514113156, 96.390, 1092.0, 33.0454
39.566634287, 96.390, 1038.0, 32.2180
39.619155417, 96.390, 1039.0, 32.2335
39.671676548, 96.390, 1046.0, 32.3419
39.724197679, 96.390, 1053.0, 32.4500
39.776718810, 96.390, 1024.0, 32.0000
39.829239940, 96.390, 1060.0, 32.5576
39.881761071, 96.390, 1032.0, 32.1248
39.934282202, 96.390, 980.0, 31.3050
39.986803332, 96.390, 1001.0, 31.6386
40.039324463, 96.390, 957.0, 30.9354
40.091845594, 96.390, 1027.0, 32.0468
40.144366725, 96.390, 959.0, 30.9677
40.196887855, 96.390, 1001.0, 31.6386
40.249408986, 96.390, 972.0, 31.1769
40.301930117, 96.390, 1027.0, 32.0468
40.354451247, 96.390, 995.0, 31.5436
40.406972378, 96.390, 977.0, 31.2570
40.459493509, 96.390, 1070.0, 32.7109
40.512014639, 96.390, 1005.0, 31.7017
40.564535770, 96.390, 995.0, 31.5436
40.617056901, 96.390, 983.0, 31.3528
40.669578032, 96.390, 989.0, 31.4484
40.722099162, 96.390, 1024.0, 32.0000
40.774620293, 96.390, 1002.0, 31.6544
40.827141424, 96.390, 977.0, 31.2570
40.879662554, 96.390, 991.0, 31.4802
40.932183685, 96.390, 989.0, 31.4484
40.984704816, 96.390, 976.0, 31.2410
41.037225947, 96.390, 939.0, 30.6431
41.089747077, 96.390, 994.0, 31.5278
41.142268208, 96.390, 967.0, 31.0966
41.194789339, 96.390, 906.0, 30.0998
41.247310469, 96.390, 951.0, 30.8383
41.299831600, 96.390, 919.0, 30.3150
41.352352731, 96.390, 924.0, 30.3974
41.404873862, 96.390, 970.0, 31.1448
41.457394992, 96.390, 971.0, 31.1609
41.509916123, 96.390, 915.0, 30.2490
41.562437254, 96.390, 966.0, 31.0805
41.614958384, 96.390, 911.0, 30.1828
41.667479515, 96.390, 969.0, 31.1288
41.720000646, 96.390, 984.0, 31.3688
41.772521776, 96.390, 945.0, 30.7409
41.825042907, 96.390, 937.0, 30.6105
41.877564038, 96.390, 898.0, 29.9666
41.930085169, 96.390, 912.0, 30.1993
41.982606299, 96.390, 954.0, 30.8869
42.035127430, 96.390, 949.0, 30.8058
42.087648561, 96.390, 952.0, 30.8545
42.140169691, 96.390, 939.0, 30.6431
42.192690822, 96.390, 919.0, 30.3150
42.245211953, 96.390, 967.0, 31.0966
42.297733084, 96.390, 910.0, 30.1662
42.350254214, 96.390, 916.0, 30.2655
42.402775345, 96.390, 976.0, 31.2410
42.455296476, 96.390, 959.0, 30.9677
42.507817606, 96.390, 925.0, 30.4138
42.560338737, 96.390, 933.0, 30.5450
42.612859868, 96.390, 934.0, 30.5614
42.665380999, 96.390, 906.0, 30.0998
42.717902129, 96.390, 886.0, 29.7658
42.770423260, 96.390, 947.0, 30.7734
42.822944391, 96.390, 888.0, 29.7993
42.875465521, 96.390, 878.0, 29.6311
42.927986652, 96.390, 882.0, 29.6985
42.980507783, 96.390, 926.0, 30.4302
43.033028914, 96.390, 924.0, 30.3974
43.085550044, 96.390, 925.0, 30.4138
43.138071175, 96.390, 927.0, 30.4467
43.190592306, 96.390, 891.0, 29.8496
43.243113436, 96.390, 899.0, 29.9833
43.295634567, 96.390, 967.0, 31.0966
43.348155698, 96.390, 921.0, 30.3480
43.400676828, 96.390, 962.0, 31.0161
43.453197959, 96.390, 914.0, 30.2324
43.505719090, 96.390, 963.0, 31.0322
43.558240221, 96.390, 1000.0, 31.6228
43.610761351, 96.390, 948.0, 30.7896
43.663282482, 96.390, 889.0, 29.8161
43.715803613, 96.390, 890.0, 29.8329
43.768324743, 96.390, 917.0, 30.2820
43.820845874, 96.390, 1000.0, 31.6228
43.873367005, 96.390, 935.0, 30.5778
43.925888136, 96.390, 921.0, 30.3480
43.978409266, 96.390, 876.0, 29.5973
44.030930397, 96.390, 920.0, 30.3315
44.083451528, 96.390, 891.0, 29.8496
44.135972658, 96.390, 949.0, 30.8058
44.188493789, 96.390, 924.0, 30.3974
44.241014920, 96.390, 913.0, 30.2159
44.293536051, 96.390, 885.0, 29.7489
44.346057181, 96.390, 943.0, 30.7083
44.398578312, 96.390, 912.0, 30.1993
44.451099443, 96.390, 881.0, 29.6816
44.503620573, 96.390, 932.0, 30.5287
44.556141704, 96.390, 900.0, 30.0000
44.608662835, 96.390, 942.0, 30.6920
44.661183966, 96.390, 925.0, 30.4138
44.713705096, 96.390, 933.0, 30.5450
44.766226227, 96.390, 1005.0, 31.7017
44.818747358, 96.390, 965.0, 31.0644
44.871268488, 96.390, 952.0, 30.8545
44.923789619, 96.390, 980.0, 31.3050
44.976310750, 96.390, 983.0, 31.3528
45.028831880, 96.390, 959.0, 30.9677
45.081353011, 96.390, 1005.0, 31.7017
45.133874142, 96.390, 950.0, 30.8221
45.186395273, 96.390, 908.0, 30.1330
45.238916403, 96.390, 940.0, 30.6594
45.291437534, 96.390, 918.0, 30.2985
45.343958665, 96.390, 965.0, 31.0644
45.396479795, 96.390, 933.0, 30.5450
45.449000926, 96.390, 1025.0, 32.0156
45.501522057, 96.390, 923.0, 30.3809
45.554043188, 96.390, 948.0, 30.7896
45.606564318, 96.390, 877.0, 29.6142
45.659085449, 96.390, 948.0, 30.7896
45.711606580, 96.390, 921.0, 30.3480
45.764127710, 96.390, 946.0, 30.7571
45.816648841, 96.390, 955.0, 30.9031
45.869169972, 96.390, 935.0, 30.5778
45.921691103, 96.390, 950.0, 30.8221
45.974212233, 96.390, 933.0, 30.5450
46.026733364, 96.390, 962.0, 31.0161
46.079254495, 96.390, 947.0, 30.7734
46.131775625, 96.390, 919.0, 30.3150
46.184296756, 96.390, 960.0, 30.9839
46.236817887, 96.390, 1098.0, 33.1361
46.289339017, 96.390, 1013.0, 31.8277
46.341860148, 96.390, 996.0, 31.5595
46.394381279, 96.390, 1058.0, 32.5269
46.446902410, 96.390, 994.0, 31.5278
46.499423540, 96.390, 942.0, 30.6920
46.551944671, 96.390, 1039.0, 32.2335
46.604465802, 96.390, 1004.0, 31.6860
46.656986932, 96.390, 950.0, 30.8221
46.709508063, 96.390, 948.0, 30.7896
46.762029194, 96.390, 945.0, 30.7409
46.814550325, 96.390, 927.0, 30.4467
46.867071455, 96.390, 902.0, 30.0333
46.919592586, 96.390, 901.0, 30.0167
46.972113717, 96.390, 914.0, 30.2324
47.024634847, 96.390, 983.0, 31.3528
47.077155978, 96.390, 927.0, 30.4467
47.129677109, 96.390, 949.0, 30.8058
47.182198240, 96.390, 905.0, 30.0832
47.234719370, 96.390, 939.0, 30.6431
47.287240501, 96.390, 907.0, 30.1164
47.339761632, 96.390, 895.0, 29.9166
47.392282762, 96.390, 917.0, 30.2820
47.444803893, 96.390, 912.0, 30.1993
47.497325024, 96.390, 932.0, 30.5287
47.549846155, 96.390, 909.0, 30.1496
47.602367285, 96.390, 942.0, 30.6920
47.654888416, 96.390, 873.0, 29.5466
47.707409547, 96.390, 845.0, 29.0689
47.759930677, 96.390, 923.0, 30.3809
47.812451808, 96.390, 857.0, 29.2746
47.864972939, 96.390, 899.0, 29.9833
47.917494069, 96.390, 889.0, 29.8161
47.970015200, 96.390, 863.0, 29.3769
48.022536331, 96.390, 908.0, 30.1330
48.075057462, 96.390, 895.0, 29.9166
48.127578592, 96.390, 856.0, 29.2575
48.180099723, 96.390, 864.0, 29.3939
48.232620854, 96.390, 871.0, 29.5127
48.285141984, 96.390, 853.0, 29.2062
48.337663115, 96.390, 827.0, 28.7576
48.390184246, 96.390, 809.0, 28.4429
48.442705377, 96.390, 829.0, 28.7924
48.495226507, 96.390, 876.0, 29.5973
48.547747638, 96.390, 824.0, 28.7054
48.600268769, 96.390, 857.0, 29.2746
48.652789899, 96.390, 835.0, 28.8964
48.705311030, 96.390, 836.0, 28.9137
48.757832161, 96.390, 825.0, 28.7228
48.810353292, 96.390, 816.0, 28.5657
48.862874422, 96.390, 861.0, 29.3428
48.915395553, 96.390, 801.0, 28.3019
48.967916684, 96.390, 765.0, 27.6586
49.020437814, 96.390, 752.0, 27.4226
49.072958945, 96.390, 835.0, 28.8964
49.125480076, 96.390, 823.0, 28.6880
49.178001207, 96.390, 792.0, 28.1425
49.230522337, 96.390, 796.0, 28.2135
49.283043468, 96.390, 799.0, 28.2666
49.335564599, 96.390, 803.0, 28.3373
49.388085729, 96.390, 795.0, 28.1957
49.440606860, 96.390, 807.0, 28.4077
49.493127991, 96.390, 776.0, 27.8568
49.545649121, 96.390, 745.0, 27.2947
49.598170252, 96.390, 794.0, 28.1780
49.650691383, 96.390, 777.0, 27.8747
49.703212514, 96.390, 765.0, 27.6586
49.755733644, 96.390, 764.0, 27.6405
49.808254775, 96.390, 773.0, 27.8029
49.860775906, 96.390, 764.0, 27.6405
49.913297036, 96.390, 735.0, 27.1109
49.965818167, 96.390, 720.0, 26.8328
50.018339298, 96.390, 754.0, 27.4591
50.070860429, 96.390, 722.0, 26.8701
50.123381559, 96.390, 795.0, 28.1957
50.175902690, 96.390, 811.0, 28.4781
50.228423821, 96.390, 787.0, 28.0535
50.280944951, 96.390, 753.0, 27.4408
50.333466082, 96.390, 815.0, 28.5482
50.385987213, 96.390, 742.0, 27.2397
50.438508344, 96.390, 778.0, 27.8927
50.491029474, 96.390, 728.0, 26.9815
50.543550605, 96.390, 747.0, 27.3313
50.596071736, 96.390, 755.0, 27.4773
50.648592866, 96.390, 762.0, 27.6043
50.701113997, 96.390, 784.0, 28.0000
50.753635128, 96.390, 765.0, 27.6586
50.806156258, 96.390, 754.0, 27.4591
50.858677389, 96.390, 765.0, 27.6586
50.911198520, 96.390, 690.0, 26.2679
50.963719651, 96.390, 699.0, 26.4386
51.016240781, 96.390, 774.0, 27.8209
51.068761912, 96.390, 752.0, 27.4226
51.121283043, 96.390, 755.0, 27.4773
51.173804173, 96.390, 732.0, 27.0555
51.226325304, 96.390, 724.0, 26.9072
51.278846435, 96.390, 708.0, 26.6083
51.331367566, 96.390, 717.0, 26.7769
51.383888696, 96.390, 735.0, 27.1109
51.436409827, 96.390, 704.0, 26.5330
51.488930958, 96.390, 766.0, 27.6767
51.541452088, 96.390, 719.0, 26.8142
51.593973219, 96.390, 694.0, 26.3439
51.646494350, 96.390, 676.0, 26.0000
51.699015481, 96.390, 704.0, 26.5330
51.751536611, 96.390, 742.0, 27.2397
51.804057742, 96.390, 705.0, 26.5518
51.856578873, 96.390, 685.0, 26.1725
51.909100003, 96.390, 727.0, 26.9629
51.961621134, 96.390, 693.0, 26.3249
52.014142265, 96.390, 731.0, 27.0370
52.066663396, 96.390, 731.0, 27.0370
52.119184526, 96.390, 726.0, 26.9444
52.171705657, 96.390, 722.0, 26.8701
52.224226788, 96.390, 732.0, 27.0555
52.276747918, 96.390, 725.0, 26.9258
52.329269049, 96.390, 689.0, 26.2488
52.381790180, 96.390, 676.0, 26.0000
52.434311310, 96.390, 715.0, 26.7395
52.486832441, 96.390, 701.0, 26.4764
52.539353572, 96.390, 727.0, 26.9629
52.591874703, 96.390, 714.0, 26.7208
52.644395833, 96.390, 661.0, 25.7099
52.696916964, 96.390, 665.0, 25.7876
52.749438095, 96.390, 678.0, 26.0384
52.801959225, 96.390, 696.0, 26.3818
52.854480356, 96.390, 719.0, 26.8142
52.907001487, 96.390, 700.0, 26.4575
52.959522618, 96.390, 693.0, 26.3249
53.012043748, 96.390, 730.0, 27.0185
53.064564879, 96.390, 702.0, 26.4953
53.117086010, 96.390, 734.0, 27.0924
53.169607140, 96.390, 701.0, 26.4764
53.222128271, 96.390, 697.0, 26.4008
53.274649402, 96.390, 711.0, 26.6646
53.327170533, 96.390, 740.0, 27.2029
53.379691663, 96.390, 722.0, 26.8701
53.432212794, 96.390, 670.0, 25.8844
53.484733925, 96.390, 664.0, 25.7682
53.537255055, 96.390, 717.0, 26.7769
53.589776186, 96.390, 723.0, 26.8887
53.642297317, 96.390, 703.0, 26.5141
53.694818448, 96.390, 726.0, 26.9444
53.747339578, 96.390, 726.0, 26.9444
53.799860709, 96.390, 716.0, 26.7582
53.852381840, 96.390, 721.0, 26.8514
53.904902970, 96.390, 719.0, 26.8142
53.957424101, 96.390, 740.0, 27.2029
54.009945232, 96.390, 723.0, 26.8887
54.062466362, 96.390, 761.0, 27.5862
54.114987493, 96.390, 748.0, 27.3496
54.167508624, 96.390, 775.0, 27.8388
54.220029755, 96.390, 754.0, 27.4591
54.272550885, 96.390, 742.0, 27.2397
54.325072016, 96.390, 747.0, 27.3313
54.377593147, 96.390, 696.0, 26.3818
54.430114277, 96.390, 713.0, 26.7021
54.482635408, 96.390, 679.0, 26.0576
54.535156539, 96.390, 690.0, 26.2679
54.587677670, 96.390, 691.0, 26.2869
54.640198800, 96.390, 637.0, 25.2389
54.692719931, 96.390, 693.0, 26.3249
54.745241062, 96.390, 681.0, 26.0960
54.797762192, 96.390, 748.0, 27.3496
54.850283323, 96.390, 680.0, 26.0768
54.902804454, 96.390, 700.0, 26.4575
54.955325585, 96.390, 668.0, 25.8457
55.007846715, 96.390, 680.0, 26.0768
55.060367846, 96.390, 719.0, 26.8142
55.112888977, 96.390, 702.0, 26.4953
55.165410107, 96.390, 669.0, 25.8650
55.217931238, 96.390, 695.0, 26.3629
55.270452369, 96.390, 689.0, 26.2488
55.322973499, 96.390, 671.0, 25.9037
55.375494630, 96.390, 666.0, 25.8070
55.428015761, 96.390, 659.0, 25.6710
55.480536892, 96.390, 682.0, 26.1151
55.533058022, 96.390, 678.0, 26.0384
55.585579153, 96.390, 637.0, 25.2389
55.638100284, 96.390, 690.0, 26.2679
55.690621414, 96.390, 683.0, 26.1343
55.743142545, 96.390, 695.0, 26.3629
55.795663676, 96.390, 626.0, 25.0200
55.848184807, 96.390, 654.0, 25.5734
55.900705937, 96.390, 683.0, 26.1343
55.953227068, 96.390, 642.0, 25.3377
56.005748199, 96.390, 627.0, 25.0400
56.058269329, 96.390, 661.0, 25.7099
56.110790460, 96.390, 621.0, 24.9199
56.163311591, 96.390, 684.0, 26.1534
56.215832722, 96.390, 638.0, 25.2587
56.268353852, 96.390, 688.0, 26.2298
56.320874983, 96.390, 642.0, 25.3377
56.373396114, 96.390, 681.0, 26.0960
56.425917244, 96.390, 640.0, 25.2982
56.478438375, 96.390, 665.0, 25.7876
56.530959506, 96.390, 636.0, 25.2190
56.583480637, 96.390, 685.0, 26.1725
56.636001767, 96.390, 674.0, 25.9615
56.688522898, 96.390, 620.0, 24.8998
56.741044029, 96.390, 590.0, 24.2899
56.793565159, 96.390, 628.0, 25.0599
56.846086290, 96.390, 706.0, 26.5707
56.898607421, 96.390, 622.0, 24.9399
56.951128551, 96.390, 636.0, 25.2190
57.003649682, 96.390, 670.0, 25.8844
57.056170813, 96.390, 634.0, 25.1794
57.108691944, 96.390, 647.0, 25.4362
57.161213074, 96.390, 650.0, 25.4951
57.213734205, 96.390, 672.0, 25.9230
57.266255336, 96.390, 633.0, 25.1595
57.318776466, 96.390, 624.0, 24.9800
57.371297597, 96.390, 627.0, 25.0400
57.423818728, 96.390, 605.0, 24.5967
57.476339859, 96.390, 619.0, 24.8797
57.528860989, 96.390, 604.0, 24.5764
57.581382120, 96.390, 640.0, 25.2982
57.633903251, 96.390, 580.0, 24.0832
57.686424381, 96.390, 683.0, 26.1343
57.738945512, 96.390, 646.0, 25.4165
57.791466643, 96.390, 590.0, 24.2899
57.843987774, 96.390, 637.0, 25.2389
57.896508904, 96.390, 652.0, 25.5343
57.949030035, 96.390, 656.0, 25.6125
58.001551166, 96.390, 592.0, 24.3311
58.054072296, 96.390, 621.0, 24.9199
58.106593427, 96.390, 650.0, 25.4951
58.159114558, 96.390, 633.0, 25.1595
58.211635689, 96.390, 623.0, 24.9600
58.264156819, 96.390, 620.0, 24.8998
58.316677950, 96.390, 628.0, 25.0599
58.369199081, 96.390, 582.0, 24.1247
58.421720211, 96.390, 621.0, 24.9199
58.474241342, 96.390, 622.0, 24.9399
58.526762473, 96.390, 643.0, 25.3574
58.579283603, 96.390, 634.0, 25.1794
58.631804734, 96.390, 635.0, 25.1992
58.684325865, 96.390, 637.0, 25.2389
58.736846996, 96.390, 575.0, 23.9792
58.789368126, 96.390, 623.0, 24.9600
58.841889257, 96.390, 659.0, 25.6710
58.894410388, 96.390, 678.0, 26.0384
58.946931518, 96.390, 651.0, 25.5147
58.999452649, 96.390, 663.0, 25.7488
59.051973780, 96.390, 610.0, 24.6982
59.104494911, 96.390, 666.0, 25.8070
59.157016041, 96.390, 631.0, 25.1197
59.209537172, 96.390, 654.0, 25.5734
59.262058303, 96.390, 656.0, 25.6125
59.314579433, 96.390, 599.0, 24.4745
59.367100564, 96.390, 631.0, 25.1197
59.419621695, 96.390, 686.0, 26.1916
59.472142826, 96.390, 643.0, 25.3574
59.524663956, 96.390, 621.0, 24.9199
59.577185087, 96.390, 626.0, 25.0200
59.629706218, 96.390, 587.0, 24.2281
59.682227348, 96.390, 635.0, 25.1992
59.734748479, 96.390, 628.0, 25.0599
59.787269610, 96.390, 650.0, 25.4951
59.839790740, 96.390, 702.0, 26.4953
59.892311871, 96.390, 648.0, 25.4558
59.944833002, 96.390, 692.0, 26.3059
59.997354133, 96.390, 659.0, 25.6710
60.049875263, 96.390, 655.0, 25.5930
60.102396394, 96.390, 708.0, 26.6083
60.154917525, 96.390, 709.0, 26.6271
60.207438655, 96.390, 675.0, 25.9808
60.259959786, 96.390, 695.0, 26.3629
60.312480917, 96.390, 690.0, 26.2679
60.365002048, 96.390, 718.0, 26.7955
60.417523178, 96.390, 653.0, 25.5539
60.470044309, 96.390, 766.0, 27.6767
60.522565440, 96.390, 719.0, 26.8142
60.575086570, 96.390, 734.0, 27.0924
60.627607701, 96.390, 742.0, 27.2397
60.680128832, 96.390, 753.0, 27.4408
60.732649963, 96.390, 760.0, 27.5681
60.785171093, 96.390, 727.0, 26.9629
60.837692224, 96.390, 797.0, 28.2312
60.890213355, 96.390, 757.0, 27.5136
60.942734485, 96.390, 788.0, 28.0713
60.995255616, 96.390, 816.0, 28.5657
61.047776747, 96.390, 764.0, 27.6405
61.100297878, 96.390, 823.0, 28.6880
61.152819008, 96.390, 829.0, 28.7924
61.205340139, 96.390, 816.0, 28.5657
61.257861270, 96.390, 805.0, 28.3725
61.310382400, 96.390, 848.0, 29.1204
61.362903531, 96.390, 785.0, 28.0179
61.415424662, 96.390, 813.0, 28.5132
61.467945792, 96.390, 782.0, 27.9643
61.520466923, 96.390, 790.0, 28.1069
61.572988054, 96.390, 839.0, 28.9655
61.625509185, 96.390, 769.0, 27.7308
61.678030315, 96.390, 854.0, 29.2233
61.730551446, 96.390, 798.0, 28.2489
61.783072577, 96.390, 830.0, 28.8097
61.835593707, 96.390, 772.0, 27.7849
61.888114838, 96.390, 796.0, 28.2135
61.940635969, 96.390, 776.0, 27.8568
61.993157100, 96.390, 757.0, 27.5136
62.045678230, 96.390, 761.0, 27.5862
62.098199361, 96.390, 739.0, 27.1846
62.150720492, 96.390, 778.0, 27.8927
62.203241622, 96.390, 799.0, 28.2666
62.255762753, 96.390, 765.0, 27.6586
62.308283884, 96.390, 719.0, 26.8142
62.360805015, 96.390, 737.0, 27.1477
62.413326145, 96.390, 718.0, 26.7955
62.465847276, 96.390, 739.0, 27.1846
62.518368407, 96.390, 758.0, 27.5318
62.570889537, 96.390, 737.0, 27.1477
62.623410668, 96.390, 676.0, 26.0000
62.675931799, 96.390, 662.0, 25.7294
62.728452930, 96.390, 728.0, 26.9815
62.780974060, 96.390, 713.0, 26.7021
62.833495191, 96.390, 652.0, 25.5343
62.886016322, 96.390, 681.0, 26.0960
62.938537452, 96.390, 644.0, 25.3772
62.991058583, 96.390, 684.0, 26.1534
63.043579714, 96.390, 739.0, 27.1846
63.096100844, 96.390, 653.0, 25.5539
63.148621975, 96.390, 668.0, 25.8457
63.201143106, 96.390, 657.0, 25.6320
63.253664237, 96.390, 681.0, 26.0960
63.306185367, 96.390, 662.0, 25.7294
63.358706498, 96.390, 642.0, 25.3377
63.411227629, 96.390, 640.0, 25.2982
63.463748759, 96.390, 643.0, 25.3574
63.516269890, 96.390, 604.0, 24.5764
63.568791021, 96.390, 626.0, 25.0200
63.621312152, 96.390, 619.0, 24.8797
63.673833282, 96.390, 578.0, 24.0416
63.726354413, 96.390, 641.0, 25.3180
63.778875544, 96.390, 644.0, 25.3772
63.831396674, 96.390, 597.0, 24.4336
63.883917805, 96.390, 622.0, 24.9399
63.936438936, 96.390, 635.0, 25.1992
63.988960067, 96.390, 625.0, 25.0000
64.041481197, 96.390, 602.0, 24.5357
64.094002328, 96.390, 653.0, 25.5539
64.146523459, 96.390, 639.0, 25.2784
64.199044589, 96.390, 623.0, 24.9600
64.251565720, 96.390, 615.0, 24.7992
64.304086851, 96.390, 601.0, 24.5153
64.356607981, 96.390, 579.0, 24.0624
64.409129112, 96.390, 627.0, 25.0400
64.461650243, 96.390, 584.0, 24.1661
64.514171374, 96.390, 628.0, 25.0599
64.566692504, 96.390, 580.0, 24.0832
64.619213635, 96.390, 633.0, 25.1595
64.671734766, 96.390, 659.0, 25.6710
64.724255896, 96.390, 562.0, 23.7065
64.776777027, 96.390, 576.0, 24.0000
64.829298158, 96.390, 565.0, 23.7697
64.881819289, 96.390, 559.0, 23.6432
64.934340419, 96.390, 612.0, 24.7386
64.986861550, 96.390, 596.0, 24.4131