File: Files_organized_for_plots/134_days/J_XRD_132_SiCorner03Feb22_Act16Nov22_B1_0833M_NaOH_LS0153.csv
[Measurement conditions]
Sample identification,132_SiCorner03Feb22_Act16Nov22_B1_0833M_NaOH_LS0153
Comment - 1,"Configuration=Stage for Flat Samples/Holders, Owner=User-1, Creation date=7/1/2020 9:53:24 AM"
Comment - 2,"Goniometer=Theta/Theta; Minimum step size 2Theta:0.0001; Minimum step size Omega:0.0001"
Comment - 3,"Sample stage=Stage for flat samples/holders"
Comment - 4,"Diffractometer system=EMPYREAN"
Comment - 5,"Measurement program=C:\Users\tmr79\OneDrive - The Pennsylvania State University\Documents\NEUP\XRD\Cement\Zerobackground scan.xrdmp, Identifier={98A3B11C-88F9-4AA6-982C-73314A311EF5}"
Anode material,Cu
K-Alpha1 wavelength,1.5405980
K-Alpha2 wavelength,1.5444260
Ratio K-Alpha2/K-Alpha1,0.500
Divergence slit,Fixed,0.25
Monochromator used,NO
Generator voltage, 45
Tube current, 40
File date and time,03/Apr/2023 09:24
Unit cell,
h k l, 0 0 0
Scan axis,Gonio
Scan range,4.994599997,64.999991833
Scan step size,0.0262606
No. of points, 2285
Scan type,CONTINUOUS
Time per step,96.390
[Scan points]
Angle, TimePerStep, Intensity, ESD
5.007730280, 96.390, 4514.0, 67.1863
5.060251411, 96.390, 4426.0, 66.5282
5.112772541, 96.390, 4398.0, 66.3174
5.165293672, 96.390, 4217.0, 64.9384
5.217814803, 96.390, 4276.0, 65.3911
5.270335934, 96.390, 4202.0, 64.8228
5.322857064, 96.390, 4163.0, 64.5213
5.375378195, 96.390, 4000.0, 63.2456
5.427899326, 96.390, 3922.0, 62.6259
5.480420456, 96.390, 3931.0, 62.6977
5.532941587, 96.390, 3887.0, 62.3458
5.585462718, 96.390, 3971.0, 63.0159
5.637983849, 96.390, 3875.0, 62.2495
5.690504979, 96.390, 3788.0, 61.5467
5.743026110, 96.390, 3833.0, 61.9112
5.795547241, 96.390, 3840.0, 61.9677
5.848068371, 96.390, 3774.0, 61.4329
5.900589502, 96.390, 3730.0, 61.0737
5.953110633, 96.390, 3777.0, 61.4573
6.005631763, 96.390, 3729.0, 61.0655
6.058152894, 96.390, 3629.0, 60.2412
6.110674025, 96.390, 3543.0, 59.5231
6.163195156, 96.390, 3761.0, 61.3270
6.215716286, 96.390, 3566.0, 59.7160
6.268237417, 96.390, 3552.0, 59.5987
6.320758548, 96.390, 3585.0, 59.8749
6.373279678, 96.390, 3454.0, 58.7707
6.425800809, 96.390, 3458.0, 58.8048
6.478321940, 96.390, 3482.0, 59.0085
6.530843071, 96.390, 3379.0, 58.1292
6.583364201, 96.390, 3487.0, 59.0508
6.635885332, 96.390, 3588.0, 59.8999
6.688406463, 96.390, 3492.0, 59.0931
6.740927593, 96.390, 3386.0, 58.1893
6.793448724, 96.390, 3388.0, 58.2065
6.845969855, 96.390, 3375.0, 58.0948
6.898490986, 96.390, 3466.0, 58.8727
6.951012116, 96.390, 3327.0, 57.6802
7.003533247, 96.390, 3453.0, 58.7622
7.056054378, 96.390, 3340.0, 57.7927
7.108575508, 96.390, 3453.0, 58.7622
7.161096639, 96.390, 3304.0, 57.4804
7.213617770, 96.390, 3292.0, 57.3760
7.266138900, 96.390, 3293.0, 57.3847
7.318660031, 96.390, 3361.0, 57.9741
7.371181162, 96.390, 3241.0, 56.9298
7.423702293, 96.390, 3307.0, 57.5065
7.476223423, 96.390, 3254.0, 57.0438
7.528744554, 96.390, 3415.0, 58.4380
7.581265685, 96.390, 3309.0, 57.5239
7.633786815, 96.390, 3142.0, 56.0535
7.686307946, 96.390, 3227.0, 56.8067
7.738829077, 96.390, 3196.0, 56.5332
7.791350208, 96.390, 3199.0, 56.5597
7.843871338, 96.390, 3137.0, 56.0089
7.896392469, 96.390, 3085.0, 55.5428
7.948913600, 96.390, 3122.0, 55.8749
8.001434730, 96.390, 3135.0, 55.9911
8.053955861, 96.390, 3123.0, 55.8838
8.106476992, 96.390, 3102.0, 55.6956
8.158998123, 96.390, 3155.0, 56.1694
8.211519253, 96.390, 3056.0, 55.2811
8.264040384, 96.390, 3050.0, 55.2268
8.316561515, 96.390, 3034.0, 55.0818
8.369082645, 96.390, 3102.0, 55.6956
8.421603776, 96.390, 3108.0, 55.7494
8.474124907, 96.390, 3014.0, 54.8999
8.526646038, 96.390, 3093.0, 55.6147
8.579167168, 96.390, 2909.0, 53.9351
8.631688299, 96.390, 2938.0, 54.2033
8.684209430, 96.390, 3059.0, 55.3082
8.736730560, 96.390, 2955.0, 54.3599
8.789251691, 96.390, 2975.0, 54.5436
8.841772822, 96.390, 2991.0, 54.6900
8.894293952, 96.390, 3076.0, 55.4617
8.946815083, 96.390, 3021.0, 54.9636
8.999336214, 96.390, 2916.0, 54.0000
9.051857345, 96.390, 2927.0, 54.1018
9.104378475, 96.390, 2914.0, 53.9815
9.156899606, 96.390, 2940.0, 54.2218
9.209420737, 96.390, 2869.0, 53.5630
9.261941867, 96.390, 2844.0, 53.3292
9.314462998, 96.390, 2813.0, 53.0377
9.366984129, 96.390, 2819.0, 53.0943
9.419505260, 96.390, 2923.0, 54.0648
9.472026390, 96.390, 2855.0, 53.4322
9.524547521, 96.390, 3017.0, 54.9272
9.577068652, 96.390, 2775.0, 52.6783
9.629589782, 96.390, 2856.0, 53.4416
9.682110913, 96.390, 2823.0, 53.1319
9.734632044, 96.390, 2802.0, 52.9339
9.787153175, 96.390, 2790.0, 52.8205
9.839674305, 96.390, 2750.0, 52.4404
9.892195436, 96.390, 2834.0, 53.2353
9.944716567, 96.390, 2774.0, 52.6688
9.997237697, 96.390, 2788.0, 52.8015
10.049758828, 96.390, 2719.0, 52.1440
10.102279959, 96.390, 2750.0, 52.4404
10.154801090, 96.390, 2630.0, 51.2835
10.207322220, 96.390, 2610.0, 51.0882
10.259843351, 96.390, 2682.0, 51.7880
10.312364482, 96.390, 2667.0, 51.6430
10.364885612, 96.390, 2604.0, 51.0294
10.417406743, 96.390, 2656.0, 51.5364
10.469927874, 96.390, 2608.0, 51.0686
10.522449004, 96.390, 2605.0, 51.0392
10.574970135, 96.390, 2591.0, 50.9019
10.627491266, 96.390, 2551.0, 50.5074
10.680012397, 96.390, 2482.0, 49.8197
10.732533527, 96.390, 2576.0, 50.7543
10.785054658, 96.390, 2577.0, 50.7642
10.837575789, 96.390, 2544.0, 50.4381
10.890096919, 96.390, 2487.0, 49.8698
10.942618050, 96.390, 2548.0, 50.4777
10.995139181, 96.390, 2490.0, 49.8999
11.047660312, 96.390, 2560.0, 50.5964
11.100181442, 96.390, 2543.0, 50.4282
11.152702573, 96.390, 2446.0, 49.4571
11.205223704, 96.390, 2593.0, 50.9215
11.257744834, 96.390, 2589.0, 50.8822
11.310265965, 96.390, 2497.0, 49.9700
11.362787096, 96.390, 2443.0, 49.4267
11.415308227, 96.390, 2427.0, 49.2646
11.467829357, 96.390, 2455.0, 49.5480
11.520350488, 96.390, 2396.0, 48.9490
11.572871619, 96.390, 2440.0, 49.3964
11.625392749, 96.390, 2335.0, 48.3218
11.677913880, 96.390, 2294.0, 47.8957
11.730435011, 96.390, 2333.0, 48.3011
11.782956141, 96.390, 2332.0, 48.2908
11.835477272, 96.390, 2269.0, 47.6340
11.887998403, 96.390, 2307.0, 48.0312
11.940519534, 96.390, 2346.0, 48.4355
11.993040664, 96.390, 2284.0, 47.7912
12.045561795, 96.390, 2189.0, 46.7868
12.098082926, 96.390, 2269.0, 47.6340
12.150604056, 96.390, 2272.0, 47.6655
12.203125187, 96.390, 2306.0, 48.0208
12.255646318, 96.390, 2341.0, 48.3839
12.308167449, 96.390, 2302.0, 47.9792
12.360688579, 96.390, 2270.0, 47.6445
12.413209710, 96.390, 2307.0, 48.0312
12.465730841, 96.390, 2265.0, 47.5920
12.518251971, 96.390, 2267.0, 47.6130
12.570773102, 96.390, 2226.0, 47.1805
12.623294233, 96.390, 2198.0, 46.8828
12.675815364, 96.390, 2148.0, 46.3465
12.728336494, 96.390, 2126.0, 46.1086
12.780857625, 96.390, 2213.0, 47.0425
12.833378756, 96.390, 2179.0, 46.6798
12.885899886, 96.390, 2150.0, 46.3681
12.938421017, 96.390, 2295.0, 47.9062
12.990942148, 96.390, 2201.0, 46.9148
13.043463279, 96.390, 2151.0, 46.3789
13.095984409, 96.390, 2125.0, 46.0977
13.148505540, 96.390, 2265.0, 47.5920
13.201026671, 96.390, 2137.0, 46.2277
13.253547801, 96.390, 2180.0, 46.6905
13.306068932, 96.390, 2160.0, 46.4758
13.358590063, 96.390, 2090.0, 45.7165
13.411111193, 96.390, 2106.0, 45.8912
13.463632324, 96.390, 2110.0, 45.9347
13.516153455, 96.390, 2082.0, 45.6289
13.568674586, 96.390, 2082.0, 45.6289
13.621195716, 96.390, 2139.0, 46.2493
13.673716847, 96.390, 2063.0, 45.4203
13.726237978, 96.390, 2160.0, 46.4758
13.778759108, 96.390, 2088.0, 45.6946
13.831280239, 96.390, 2084.0, 45.6508
13.883801370, 96.390, 2035.0, 45.1110
13.936322501, 96.390, 2053.0, 45.3100
13.988843631, 96.390, 2097.0, 45.7930
14.041364762, 96.390, 2107.0, 45.9021
14.093885893, 96.390, 2100.0, 45.8258
14.146407023, 96.390, 2076.0, 45.5631
14.198928154, 96.390, 2109.0, 45.9239
14.251449285, 96.390, 2067.0, 45.4643
14.303970416, 96.390, 2051.0, 45.2880
14.356491546, 96.390, 2099.0, 45.8148
14.409012677, 96.390, 2079.0, 45.5961
14.461533808, 96.390, 2087.0, 45.6837
14.514054938, 96.390, 2060.0, 45.3872
14.566576069, 96.390, 2059.0, 45.3762
14.619097200, 96.390, 1976.0, 44.4522
14.671618331, 96.390, 2139.0, 46.2493
14.724139461, 96.390, 2046.0, 45.2327
14.776660592, 96.390, 2021.0, 44.9555
14.829181723, 96.390, 1984.0, 44.5421
14.881702853, 96.390, 1976.0, 44.4522
14.934223984, 96.390, 1945.0, 44.1022
14.986745115, 96.390, 2024.0, 44.9889
15.039266245, 96.390, 2063.0, 45.4203
15.091787376, 96.390, 1952.0, 44.1814
15.144308507, 96.390, 1998.0, 44.6990
15.196829638, 96.390, 2004.0, 44.7661
15.249350768, 96.390, 1997.0, 44.6878
15.301871899, 96.390, 2003.0, 44.7549
15.354393030, 96.390, 2033.0, 45.0888
15.406914160, 96.390, 1977.0, 44.4635
15.459435291, 96.390, 2005.0, 44.7772
15.511956422, 96.390, 2002.0, 44.7437
15.564477553, 96.390, 2007.0, 44.7996
15.616998683, 96.390, 2049.0, 45.2659
15.669519814, 96.390, 2006.0, 44.7884
15.722040945, 96.390, 2029.0, 45.0444
15.774562075, 96.390, 2011.0, 44.8442
15.827083206, 96.390, 2012.0, 44.8553
15.879604337, 96.390, 2043.0, 45.1996
15.932125468, 96.390, 1970.0, 44.3847
15.984646598, 96.390, 1980.0, 44.4972
16.037167729, 96.390, 2012.0, 44.8553
16.089688860, 96.390, 1997.0, 44.6878
16.142209990, 96.390, 2064.0, 45.4313
16.194731121, 96.390, 2042.0, 45.1885
16.247252252, 96.390, 2122.0, 46.0652
16.299773382, 96.390, 1980.0, 44.4972
16.352294513, 96.390, 2058.0, 45.3652
16.404815644, 96.390, 2141.0, 46.2709
16.457336775, 96.390, 2053.0, 45.3100
16.509857905, 96.390, 2084.0, 45.6508
16.562379036, 96.390, 2100.0, 45.8258
16.614900167, 96.390, 2168.0, 46.5618
16.667421297, 96.390, 2111.0, 45.9456
16.719942428, 96.390, 2108.0, 45.9130
16.772463559, 96.390, 2125.0, 46.0977
16.824984690, 96.390, 2080.0, 45.6070
16.877505820, 96.390, 2169.0, 46.5725
16.930026951, 96.390, 2208.0, 46.9894
16.982548082, 96.390, 2121.0, 46.0543
17.035069212, 96.390, 2102.0, 45.8476
17.087590343, 96.390, 2227.0, 47.1911
17.140111474, 96.390, 2149.0, 46.3573
17.192632605, 96.390, 2102.0, 45.8476
17.245153735, 96.390, 2246.0, 47.3920
17.297674866, 96.390, 2077.0, 45.5741
17.350195997, 96.390, 2257.0, 47.5079
17.402717127, 96.390, 2192.0, 46.8188
17.455238258, 96.390, 2233.0, 47.2546
17.507759389, 96.390, 2351.0, 48.4871
17.560280520, 96.390, 2149.0, 46.3573
17.612801650, 96.390, 2230.0, 47.2229
17.665322781, 96.390, 2209.0, 47.0000
17.717843912, 96.390, 2252.0, 47.4552
17.770365042, 96.390, 2202.0, 46.9255
17.822886173, 96.390, 2339.0, 48.3632
17.875407304, 96.390, 2332.0, 48.2908
17.927928434, 96.390, 2301.0, 47.9687
17.980449565, 96.390, 2276.0, 47.7074
18.032970696, 96.390, 2334.0, 48.3115
18.085491827, 96.390, 2283.0, 47.7807
18.138012957, 96.390, 2328.0, 48.2494
18.190534088, 96.390, 2413.0, 49.1223
18.243055219, 96.390, 2374.0, 48.7237
18.295576349, 96.390, 2338.0, 48.3529
18.348097480, 96.390, 2425.0, 49.2443
18.400618611, 96.390, 2398.0, 48.9694
18.453139742, 96.390, 2437.0, 49.3660
18.505660872, 96.390, 2417.0, 49.1630
18.558182003, 96.390, 2420.0, 49.1935
18.610703134, 96.390, 2546.0, 50.4579
18.663224264, 96.390, 2500.0, 50.0000
18.715745395, 96.390, 2485.0, 49.8498
18.768266526, 96.390, 2457.0, 49.5681
18.820787657, 96.390, 2555.0, 50.5470
18.873308787, 96.390, 2524.0, 50.2394
18.925829918, 96.390, 2568.0, 50.6754
18.978351049, 96.390, 2597.0, 50.9608
19.030872179, 96.390, 2494.0, 49.9400
19.083393310, 96.390, 2625.0, 51.2348
19.135914441, 96.390, 2643.0, 51.4101
19.188435572, 96.390, 2587.0, 50.8626
19.240956702, 96.390, 2635.0, 51.3323
19.293477833, 96.390, 2754.0, 52.4786
19.345998964, 96.390, 2782.0, 52.7447
19.398520094, 96.390, 2706.0, 52.0192
19.451041225, 96.390, 2723.0, 52.1824
19.503562356, 96.390, 2733.0, 52.2781
19.556083486, 96.390, 2780.0, 52.7257
19.608604617, 96.390, 2830.0, 53.1977
19.661125748, 96.390, 2727.0, 52.2207
19.713646879, 96.390, 2848.0, 53.3667
19.766168009, 96.390, 2870.0, 53.5724
19.818689140, 96.390, 2827.0, 53.1695
19.871210271, 96.390, 2890.0, 53.7587
19.923731401, 96.390, 2860.0, 53.4790
19.976252532, 96.390, 2955.0, 54.3599
20.028773663, 96.390, 2873.0, 53.6004
20.081294794, 96.390, 2825.0, 53.1507
20.133815924, 96.390, 2895.0, 53.8052
20.186337055, 96.390, 3056.0, 55.2811
20.238858186, 96.390, 3005.0, 54.8179
20.291379316, 96.390, 2991.0, 54.6900
20.343900447, 96.390, 2933.0, 54.1572
20.396421578, 96.390, 2988.0, 54.6626
20.448942709, 96.390, 2990.0, 54.6809
20.501463839, 96.390, 2940.0, 54.2218
20.553984970, 96.390, 2916.0, 54.0000
20.606506101, 96.390, 3094.0, 55.6237
20.659027231, 96.390, 2974.0, 54.5344
20.711548362, 96.390, 3111.0, 55.7763
20.764069493, 96.390, 2959.0, 54.3967
20.816590623, 96.390, 3065.0, 55.3624
20.869111754, 96.390, 3075.0, 55.4527
20.921632885, 96.390, 3034.0, 55.0818
20.974154016, 96.390, 3092.0, 55.6058
21.026675146, 96.390, 3097.0, 55.6507
21.079196277, 96.390, 3147.0, 56.0981
21.131717408, 96.390, 3129.0, 55.9375
21.184238538, 96.390, 3194.0, 56.5155
21.236759669, 96.390, 3163.0, 56.2406
21.289280800, 96.390, 3222.0, 56.7627
21.341801931, 96.390, 3169.0, 56.2939
21.394323061, 96.390, 3132.0, 55.9643
21.446844192, 96.390, 3042.0, 55.1543
21.499365323, 96.390, 3245.0, 56.9649
21.551886453, 96.390, 3209.0, 56.6480
21.604407584, 96.390, 3182.0, 56.4092
21.656928715, 96.390, 3293.0, 57.3847
21.709449846, 96.390, 3182.0, 56.4092
21.761970976, 96.390, 3171.0, 56.3116
21.814492107, 96.390, 3185.0, 56.4358
21.867013238, 96.390, 3211.0, 56.6657
21.919534368, 96.390, 3237.0, 56.8946
21.972055499, 96.390, 3238.0, 56.9034
22.024576630, 96.390, 3093.0, 55.6147
22.077097761, 96.390, 3098.0, 55.6597
22.129618891, 96.390, 3183.0, 56.4181
22.182140022, 96.390, 3239.0, 56.9122
22.234661153, 96.390, 3069.0, 55.3986
22.287182283, 96.390, 3201.0, 56.5774
22.339703414, 96.390, 3193.0, 56.5066
22.392224545, 96.390, 3277.0, 57.2451
22.444745675, 96.390, 3134.0, 55.9821
22.497266806, 96.390, 3131.0, 55.9553
22.549787937, 96.390, 3164.0, 56.2494
22.602309068, 96.390, 3215.0, 56.7010
22.654830198, 96.390, 3178.0, 56.3738
22.707351329, 96.390, 3196.0, 56.5332
22.759872460, 96.390, 3242.0, 56.9386
22.812393590, 96.390, 3098.0, 55.6597
22.864914721, 96.390, 3070.0, 55.4076
22.917435852, 96.390, 3172.0, 56.3205
22.969956983, 96.390, 3107.0, 55.7405
23.022478113, 96.390, 3111.0, 55.7763
23.074999244, 96.390, 3066.0, 55.3715
23.127520375, 96.390, 3130.0, 55.9464
23.180041505, 96.390, 3200.0, 56.5685
23.232562636, 96.390, 2998.0, 54.7540
23.285083767, 96.390, 3014.0, 54.8999
23.337604898, 96.390, 2976.0, 54.5527
23.390126028, 96.390, 2887.0, 53.7308
23.442647159, 96.390, 2955.0, 54.3599
23.495168290, 96.390, 2923.0, 54.0648
23.547689420, 96.390, 2914.0, 53.9815
23.600210551, 96.390, 2935.0, 54.1756
23.652731682, 96.390, 2909.0, 53.9351
23.705252813, 96.390, 2972.0, 54.5161
23.757773943, 96.390, 2887.0, 53.7308
23.810295074, 96.390, 2949.0, 54.3047
23.862816205, 96.390, 2883.0, 53.6936
23.915337335, 96.390, 2917.0, 54.0093
23.967858466, 96.390, 2948.0, 54.2955
24.020379597, 96.390, 2858.0, 53.4603
24.072900727, 96.390, 2905.0, 53.8981
24.125421858, 96.390, 2907.0, 53.9166
24.177942989, 96.390, 2835.0, 53.2447
24.230464120, 96.390, 2742.0, 52.3641
24.282985250, 96.390, 2746.0, 52.4023
24.335506381, 96.390, 2723.0, 52.1824
24.388027512, 96.390, 2696.0, 51.9230
24.440548642, 96.390, 2794.0, 52.8583
24.493069773, 96.390, 2833.0, 53.2259
24.545590904, 96.390, 2676.0, 51.7301
24.598112035, 96.390, 2678.0, 51.7494
24.650633165, 96.390, 2616.0, 51.1468
24.703154296, 96.390, 2632.0, 51.3030
24.755675427, 96.390, 2668.0, 51.6527
24.808196557, 96.390, 2640.0, 51.3809
24.860717688, 96.390, 2657.0, 51.5461
24.913238819, 96.390, 2633.0, 51.3128
24.965759950, 96.390, 2689.0, 51.8556
25.018281080, 96.390, 2546.0, 50.4579
25.070802211, 96.390, 2515.0, 50.1498
25.123323342, 96.390, 2483.0, 49.8297
25.175844472, 96.390, 2596.0, 50.9510
25.228365603, 96.390, 2528.0, 50.2792
25.280886734, 96.390, 2472.0, 49.7192
25.333407864, 96.390, 2612.0, 51.1077
25.385928995, 96.390, 2464.0, 49.6387
25.438450126, 96.390, 2485.0, 49.8498
25.490971257, 96.390, 2493.0, 49.9300
25.543492387, 96.390, 2448.0, 49.4773
25.596013518, 96.390, 2324.0, 48.2079
25.648534649, 96.390, 2455.0, 49.5480
25.701055779, 96.390, 2391.0, 48.8979
25.753576910, 96.390, 2479.0, 49.7896
25.806098041, 96.390, 2333.0, 48.3011
25.858619172, 96.390, 2347.0, 48.4458
25.911140302, 96.390, 2394.0, 48.9285
25.963661433, 96.390, 2319.0, 48.1560
26.016182564, 96.390, 2368.0, 48.6621
26.068703694, 96.390, 2325.0, 48.2183
26.121224825, 96.390, 2335.0, 48.3218
26.173745956, 96.390, 2342.0, 48.3942
26.226267087, 96.390, 2299.0, 47.9479
26.278788217, 96.390, 2279.0, 47.7389
26.331309348, 96.390, 2222.0, 47.1381
26.383830479, 96.390, 2215.0, 47.0638
26.436351609, 96.390, 2173.0, 46.6154
26.488872740, 96.390, 2220.0, 47.1169
26.541393871, 96.390, 2250.0, 47.4342
26.593915002, 96.390, 2249.0, 47.4236
26.646436132, 96.390, 2253.0, 47.4658
26.698957263, 96.390, 2238.0, 47.3075
26.751478394, 96.390, 2152.0, 46.3897
26.803999524, 96.390, 2170.0, 46.5833
26.856520655, 96.390, 2153.0, 46.4004
26.909041786, 96.390, 2182.0, 46.7119
26.961562916, 96.390, 2205.0, 46.9574
27.014084047, 96.390, 2234.0, 47.2652
27.066605178, 96.390, 2193.0, 46.8295
27.119126309, 96.390, 2167.0, 46.5510
27.171647439, 96.390, 2189.0, 46.7868
27.224168570, 96.390, 2187.0, 46.7654
27.276689701, 96.390, 2183.0, 46.7226
27.329210831, 96.390, 2067.0, 45.4643
27.381731962, 96.390, 2059.0, 45.3762
27.434253093, 96.390, 2112.0, 45.9565
27.486774224, 96.390, 2068.0, 45.4753
27.539295354, 96.390, 2079.0, 45.5961
27.591816485, 96.390, 2029.0, 45.0444
27.644337616, 96.390, 2082.0, 45.6289
27.696858746, 96.390, 2149.0, 46.3573
27.749379877, 96.390, 1951.0, 44.1701
27.801901008, 96.390, 2005.0, 44.7772
27.854422139, 96.390, 2016.0, 44.8999
27.906943269, 96.390, 1963.0, 44.3058
27.959464400, 96.390, 1974.0, 44.4297
28.011985531, 96.390, 2049.0, 45.2659
28.064506661, 96.390, 1989.0, 44.5982
28.117027792, 96.390, 2052.0, 45.2990
28.169548923, 96.390, 1937.0, 44.0114
28.222070054, 96.390, 2006.0, 44.7884
28.274591184, 96.390, 1979.0, 44.4860
28.327112315, 96.390, 1987.0, 44.5758
28.379633446, 96.390, 1973.0, 44.4185
28.432154576, 96.390, 1912.0, 43.7264
28.484675707, 96.390, 1864.0, 43.1741
28.537196838, 96.390, 1985.0, 44.5533
28.589717968, 96.390, 1991.0, 44.6206
28.642239099, 96.390, 1950.0, 44.1588
28.694760230, 96.390, 1836.0, 42.8486
28.747281361, 96.390, 1858.0, 43.1045
28.799802491, 96.390, 1926.0, 43.8862
28.852323622, 96.390, 1862.0, 43.1509
28.904844753, 96.390, 1881.0, 43.3705
28.957365883, 96.390, 1890.0, 43.4741
29.009887014, 96.390, 1934.0, 43.9773
29.062408145, 96.390, 1857.0, 43.0929
29.114929276, 96.390, 1859.0, 43.1161
29.167450406, 96.390, 1800.0, 42.4264
29.219971537, 96.390, 1877.0, 43.3244
29.272492668, 96.390, 1886.0, 43.4281
29.325013798, 96.390, 1811.0, 42.5558
29.377534929, 96.390, 1862.0, 43.1509
29.430056060, 96.390, 1910.0, 43.7035
29.482577191, 96.390, 1905.0, 43.6463
29.535098321, 96.390, 1749.0, 41.8210
29.587619452, 96.390, 1829.0, 42.7668
29.640140583, 96.390, 1784.0, 42.2374
29.692661713, 96.390, 1825.0, 42.7200
29.745182844, 96.390, 1836.0, 42.8486
29.797703975, 96.390, 1792.0, 42.3320
29.850225105, 96.390, 1818.0, 42.6380
29.902746236, 96.390, 1852.0, 43.0349
29.955267367, 96.390, 1798.0, 42.4028
30.007788498, 96.390, 1818.0, 42.6380
30.060309628, 96.390, 1784.0, 42.2374
30.112830759, 96.390, 1790.0, 42.3084
30.165351890, 96.390, 1757.0, 41.9166
30.217873020, 96.390, 1782.0, 42.2137
30.270394151, 96.390, 1822.0, 42.6849
30.322915282, 96.390, 1744.0, 41.7612
30.375436413, 96.390, 1678.0, 40.9634
30.427957543, 96.390, 1638.0, 40.4722
30.480478674, 96.390, 1683.0, 41.0244
30.532999805, 96.390, 1781.0, 42.2019
30.585520935, 96.390, 1735.0, 41.6533
30.638042066, 96.390, 1687.0, 41.0731
30.690563197, 96.390, 1841.0, 42.9069
30.743084328, 96.390, 1662.0, 40.7676
30.795605458, 96.390, 1665.0, 40.8044
30.848126589, 96.390, 1637.0, 40.4599
30.900647720, 96.390, 1724.0, 41.5211
30.953168850, 96.390, 1734.0, 41.6413
31.005689981, 96.390, 1612.0, 40.1497
31.058211112, 96.390, 1748.0, 41.8091
31.110732243, 96.390, 1698.0, 41.2068
31.163253373, 96.390, 1729.0, 41.5812
31.215774504, 96.390, 1655.0, 40.6817
31.268295635, 96.390, 1705.0, 41.2916
31.320816765, 96.390, 1667.0, 40.8289
31.373337896, 96.390, 1649.0, 40.6079
31.425859027, 96.390, 1704.0, 41.2795
31.478380157, 96.390, 1613.0, 40.1622
31.530901288, 96.390, 1691.0, 41.1218
31.583422419, 96.390, 1644.0, 40.5463
31.635943550, 96.390, 1564.0, 39.5474
31.688464680, 96.390, 1633.0, 40.4104
31.740985811, 96.390, 1584.0, 39.7995
31.793506942, 96.390, 1599.0, 39.9875
31.846028072, 96.390, 1608.0, 40.0999
31.898549203, 96.390, 1557.0, 39.4588
31.951070334, 96.390, 1560.0, 39.4968
32.003591465, 96.390, 1516.0, 38.9358
32.056112595, 96.390, 1568.0, 39.5980
32.108633726, 96.390, 1532.0, 39.1408
32.161154857, 96.390, 1538.0, 39.2173
32.213675987, 96.390, 1569.0, 39.6106
32.266197118, 96.390, 1521.0, 39.0000
32.318718249, 96.390, 1446.0, 38.0263
32.371239380, 96.390, 1582.0, 39.7744
32.423760510, 96.390, 1516.0, 38.9358
32.476281641, 96.390, 1515.0, 38.9230
32.528802772, 96.390, 1606.0, 40.0749
32.581323902, 96.390, 1519.0, 38.9744
32.633845033, 96.390, 1516.0, 38.9358
32.686366164, 96.390, 1521.0, 39.0000
32.738887295, 96.390, 1426.0, 37.7624
32.791408425, 96.390, 1479.0, 38.4578
32.843929556, 96.390, 1492.0, 38.6264
32.896450687, 96.390, 1486.0, 38.5487
32.948971817, 96.390, 1466.0, 38.2884
33.001492948, 96.390, 1480.0, 38.4708
33.054014079, 96.390, 1470.0, 38.3406
33.106535209, 96.390, 1445.0, 38.0132
33.159056340, 96.390, 1520.0, 38.9872
33.211577471, 96.390, 1446.0, 38.0263
33.264098602, 96.390, 1430.0, 37.8153
33.316619732, 96.390, 1429.0, 37.8021
33.369140863, 96.390, 1458.0, 38.1838
33.421661994, 96.390, 1462.0, 38.2361
33.474183124, 96.390, 1478.0, 38.4448
33.526704255, 96.390, 1435.0, 37.8814
33.579225386, 96.390, 1442.0, 37.9737
33.631746517, 96.390, 1433.0, 37.8550
33.684267647, 96.390, 1390.0, 37.2827
33.736788778, 96.390, 1451.0, 38.0920
33.789309909, 96.390, 1410.0, 37.5500
33.841831039, 96.390, 1420.0, 37.6829
33.894352170, 96.390, 1377.0, 37.1080
33.946873301, 96.390, 1479.0, 38.4578
33.999394432, 96.390, 1314.0, 36.2491
34.051915562, 96.390, 1357.0, 36.8375
34.104436693, 96.390, 1405.0, 37.4833
34.156957824, 96.390, 1509.0, 38.8458
34.209478954, 96.390, 1463.0, 38.2492
34.262000085, 96.390, 1427.0, 37.7757
34.314521216, 96.390, 1454.0, 38.1314
34.367042346, 96.390, 1386.0, 37.2290
34.419563477, 96.390, 1475.0, 38.4057
34.472084608, 96.390, 1518.0, 38.9615
34.524605739, 96.390, 1413.0, 37.5899
34.577126869, 96.390, 1426.0, 37.7624
34.629648000, 96.390, 1521.0, 39.0000
34.682169131, 96.390, 1453.0, 38.1182
34.734690261, 96.390, 1388.0, 37.2559
34.787211392, 96.390, 1338.0, 36.5787
34.839732523, 96.390, 1412.0, 37.5766
34.892253654, 96.390, 1469.0, 38.3275
34.944774784, 96.390, 1457.0, 38.1707
34.997295915, 96.390, 1457.0, 38.1707
35.049817046, 96.390, 1461.0, 38.2230
35.102338176, 96.390, 1423.0, 37.7227
35.154859307, 96.390, 1449.0, 38.0657
35.207380438, 96.390, 1385.0, 37.2156
35.259901569, 96.390, 1382.0, 37.1753
35.312422699, 96.390, 1358.0, 36.8511
35.364943830, 96.390, 1464.0, 38.2623
35.417464961, 96.390, 1423.0, 37.7227
35.469986091, 96.390, 1416.0, 37.6298
35.522507222, 96.390, 1357.0, 36.8375
35.575028353, 96.390, 1358.0, 36.8511
35.627549484, 96.390, 1430.0, 37.8153
35.680070614, 96.390, 1332.0, 36.4966
35.732591745, 96.390, 1361.0, 36.8917
35.785112876, 96.390, 1426.0, 37.7624
35.837634006, 96.390, 1346.0, 36.6879
35.890155137, 96.390, 1329.0, 36.4555
35.942676268, 96.390, 1389.0, 37.2693
35.995197398, 96.390, 1379.0, 37.1349
36.047718529, 96.390, 1387.0, 37.2424
36.100239660, 96.390, 1411.0, 37.5633
36.152760791, 96.390, 1316.0, 36.2767
36.205281921, 96.390, 1348.0, 36.7151
36.257803052, 96.390, 1342.0, 36.6333
36.310324183, 96.390, 1292.0, 35.9444
36.362845313, 96.390, 1249.0, 35.3412
36.415366444, 96.390, 1300.0, 36.0555
36.467887575, 96.390, 1296.0, 36.0000
36.520408706, 96.390, 1323.0, 36.3731
36.572929836, 96.390, 1225.0, 35.0000
36.625450967, 96.390, 1319.0, 36.3180
36.677972098, 96.390, 1315.0, 36.2629
36.730493228, 96.390, 1302.0, 36.0832
36.783014359, 96.390, 1208.0, 34.7563
36.835535490, 96.390, 1211.0, 34.7994
36.888056621, 96.390, 1239.0, 35.1994
36.940577751, 96.390, 1207.0, 34.7419
36.993098882, 96.390, 1257.0, 35.4542
37.045620013, 96.390, 1306.0, 36.1386
37.098141143, 96.390, 1191.0, 34.5109
37.150662274, 96.390, 1257.0, 35.4542
37.203183405, 96.390, 1182.0, 34.3802
37.255704535, 96.390, 1171.0, 34.2199
37.308225666, 96.390, 1133.0, 33.6601
37.360746797, 96.390, 1158.0, 34.0294
37.413267928, 96.390, 1223.0, 34.9714
37.465789058, 96.390, 1233.0, 35.1141
37.518310189, 96.390, 1180.0, 34.3511
37.570831320, 96.390, 1177.0, 34.3074
37.623352450, 96.390, 1209.0, 34.7707
37.675873581, 96.390, 1159.0, 34.0441
37.728394712, 96.390, 1179.0, 34.3366
37.780915843, 96.390, 1196.0, 34.5832
37.833436973, 96.390, 1202.0, 34.6699
37.885958104, 96.390, 1200.0, 34.6410
37.938479235, 96.390, 1123.0, 33.5112
37.991000365, 96.390, 1164.0, 34.1174
38.043521496, 96.390, 1103.0, 33.2114
38.096042627, 96.390, 1203.0, 34.6843
38.148563758, 96.390, 1160.0, 34.0588
38.201084888, 96.390, 1124.0, 33.5261
38.253606019, 96.390, 1128.0, 33.5857
38.306127150, 96.390, 1108.0, 33.2866
38.358648280, 96.390, 1080.0, 32.8634
38.411169411, 96.390, 1130.0, 33.6155
38.463690542, 96.390, 1114.0, 33.3766
38.516211673, 96.390, 1077.0, 32.8177
38.568732803, 96.390, 1110.0, 33.3167
38.621253934, 96.390, 1090.0, 33.0151
38.673775065, 96.390, 1118.0, 33.4365
38.726296195, 96.390, 1085.0, 32.9393
38.778817326, 96.390, 1053.0, 32.4500
38.831338457, 96.390, 1105.0, 33.2415
38.883859587, 96.390, 1065.0, 32.6343
38.936380718, 96.390, 1020.0, 31.9374
38.988901849, 96.390, 1098.0, 33.1361
39.041422980, 96.390, 1022.0, 31.9687
39.093944110, 96.390, 1045.0, 32.3265
39.146465241, 96.390, 1038.0, 32.2180
39.198986372, 96.390, 1078.0, 32.8329
39.251507502, 96.390, 1045.0, 32.3265
39.304028633, 96.390, 1024.0, 32.0000
39.356549764, 96.390, 1062.0, 32.5883
39.409070895, 96.390, 995.0, 31.5436
39.461592025, 96.390, 1084.0, 32.9242
39.514113156, 96.390, 979.0, 31.2890
39.566634287, 96.390, 1013.0, 31.8277
39.619155417, 96.390, 992.0, 31.4960
39.671676548, 96.390, 1079.0, 32.8481
39.724197679, 96.390, 973.0, 31.1929
39.776718810, 96.390, 975.0, 31.2250
39.829239940, 96.390, 1021.0, 31.9531
39.881761071, 96.390, 1074.0, 32.7719
39.934282202, 96.390, 992.0, 31.4960
39.986803332, 96.390, 1028.0, 32.0624
40.039324463, 96.390, 1022.0, 31.9687
40.091845594, 96.390, 989.0, 31.4484
40.144366725, 96.390, 984.0, 31.3688
40.196887855, 96.390, 1025.0, 32.0156
40.249408986, 96.390, 981.0, 31.3209
40.301930117, 96.390, 1008.0, 31.7490
40.354451247, 96.390, 1011.0, 31.7962
40.406972378, 96.390, 978.0, 31.2730
40.459493509, 96.390, 961.0, 31.0000
40.512014639, 96.390, 955.0, 30.9031
40.564535770, 96.390, 1021.0, 31.9531
40.617056901, 96.390, 1008.0, 31.7490
40.669578032, 96.390, 993.0, 31.5119
40.722099162, 96.390, 1074.0, 32.7719
40.774620293, 96.390, 957.0, 30.9354
40.827141424, 96.390, 958.0, 30.9516
40.879662554, 96.390, 1023.0, 31.9844
40.932183685, 96.390, 922.0, 30.3645
40.984704816, 96.390, 972.0, 31.1769
41.037225947, 96.390, 1003.0, 31.6702
41.089747077, 96.390, 970.0, 31.1448
41.142268208, 96.390, 966.0, 31.0805
41.194789339, 96.390, 968.0, 31.1127
41.247310469, 96.390, 979.0, 31.2890
41.299831600, 96.390, 971.0, 31.1609
41.352352731, 96.390, 1017.0, 31.8904
41.404873862, 96.390, 1045.0, 32.3265
41.457394992, 96.390, 946.0, 30.7571
41.509916123, 96.390, 959.0, 30.9677
41.562437254, 96.390, 961.0, 31.0000
41.614958384, 96.390, 981.0, 31.3209
41.667479515, 96.390, 891.0, 29.8496
41.720000646, 96.390, 940.0, 30.6594
41.772521776, 96.390, 1011.0, 31.7962
41.825042907, 96.390, 983.0, 31.3528
41.877564038, 96.390, 1001.0, 31.6386
41.930085169, 96.390, 929.0, 30.4795
41.982606299, 96.390, 984.0, 31.3688
42.035127430, 96.390, 924.0, 30.3974
42.087648561, 96.390, 916.0, 30.2655
42.140169691, 96.390, 988.0, 31.4325
42.192690822, 96.390, 966.0, 31.0805
42.245211953, 96.390, 961.0, 31.0000
42.297733084, 96.390, 1011.0, 31.7962
42.350254214, 96.390, 965.0, 31.0644
42.402775345, 96.390, 928.0, 30.4631
42.455296476, 96.390, 983.0, 31.3528
42.507817606, 96.390, 908.0, 30.1330
42.560338737, 96.390, 958.0, 30.9516
42.612859868, 96.390, 935.0, 30.5778
42.665380999, 96.390, 928.0, 30.4631
42.717902129, 96.390, 944.0, 30.7246
42.770423260, 96.390, 969.0, 31.1288
42.822944391, 96.390, 958.0, 30.9516
42.875465521, 96.390, 886.0, 29.7658
42.927986652, 96.390, 1018.0, 31.9061
42.980507783, 96.390, 908.0, 30.1330
43.033028914, 96.390, 981.0, 31.3209
43.085550044, 96.390, 986.0, 31.4006
43.138071175, 96.390, 960.0, 30.9839
43.190592306, 96.390, 923.0, 30.3809
43.243113436, 96.390, 897.0, 29.9500
43.295634567, 96.390, 953.0, 30.8707
43.348155698, 96.390, 931.0, 30.5123
43.400676828, 96.390, 932.0, 30.5287
43.453197959, 96.390, 996.0, 31.5595
43.505719090, 96.390, 980.0, 31.3050
43.558240221, 96.390, 964.0, 31.0483
43.610761351, 96.390, 891.0, 29.8496
43.663282482, 96.390, 1000.0, 31.6228
43.715803613, 96.390, 967.0, 31.0966
43.768324743, 96.390, 949.0, 30.8058
43.820845874, 96.390, 955.0, 30.9031
43.873367005, 96.390, 1014.0, 31.8434
43.925888136, 96.390, 935.0, 30.5778
43.978409266, 96.390, 998.0, 31.5911
44.030930397, 96.390, 921.0, 30.3480
44.083451528, 96.390, 912.0, 30.1993
44.135972658, 96.390, 1025.0, 32.0156
44.188493789, 96.390, 915.0, 30.2490
44.241014920, 96.390, 942.0, 30.6920
44.293536051, 96.390, 952.0, 30.8545
44.346057181, 96.390, 920.0, 30.3315
44.398578312, 96.390, 930.0, 30.4959
44.451099443, 96.390, 950.0, 30.8221
44.503620573, 96.390, 945.0, 30.7409
44.556141704, 96.390, 1017.0, 31.8904
44.608662835, 96.390, 938.0, 30.6268
44.661183966, 96.390, 913.0, 30.2159
44.713705096, 96.390, 918.0, 30.2985
44.766226227, 96.390, 905.0, 30.0832
44.818747358, 96.390, 984.0, 31.3688
44.871268488, 96.390, 924.0, 30.3974
44.923789619, 96.390, 903.0, 30.0500
44.976310750, 96.390, 892.0, 29.8664
45.028831880, 96.390, 948.0, 30.7896
45.081353011, 96.390, 935.0, 30.5778
45.133874142, 96.390, 909.0, 30.1496
45.186395273, 96.390, 958.0, 30.9516
45.238916403, 96.390, 874.0, 29.5635
45.291437534, 96.390, 947.0, 30.7734
45.343958665, 96.390, 875.0, 29.5804
45.396479795, 96.390, 889.0, 29.8161
45.449000926, 96.390, 890.0, 29.8329
45.501522057, 96.390, 919.0, 30.3150
45.554043188, 96.390, 886.0, 29.7658
45.606564318, 96.390, 888.0, 29.7993
45.659085449, 96.390, 909.0, 30.1496
45.711606580, 96.390, 959.0, 30.9677
45.764127710, 96.390, 909.0, 30.1496
45.816648841, 96.390, 884.0, 29.7321
45.869169972, 96.390, 936.0, 30.5941
45.921691103, 96.390, 986.0, 31.4006
45.974212233, 96.390, 859.0, 29.3087
46.026733364, 96.390, 940.0, 30.6594
46.079254495, 96.390, 909.0, 30.1496
46.131775625, 96.390, 822.0, 28.6705
46.184296756, 96.390, 939.0, 30.6431
46.236817887, 96.390, 940.0, 30.6594
46.289339017, 96.390, 878.0, 29.6311
46.341860148, 96.390, 850.0, 29.1548
46.394381279, 96.390, 860.0, 29.3258
46.446902410, 96.390, 896.0, 29.9333
46.499423540, 96.390, 912.0, 30.1993
46.551944671, 96.390, 902.0, 30.0333
46.604465802, 96.390, 913.0, 30.2159
46.656986932, 96.390, 848.0, 29.1204
46.709508063, 96.390, 903.0, 30.0500
46.762029194, 96.390, 912.0, 30.1993
46.814550325, 96.390, 885.0, 29.7489
46.867071455, 96.390, 871.0, 29.5127
46.919592586, 96.390, 812.0, 28.4956
46.972113717, 96.390, 872.0, 29.5296
47.024634847, 96.390, 814.0, 28.5307
47.077155978, 96.390, 875.0, 29.5804
47.129677109, 96.390, 908.0, 30.1330
47.182198240, 96.390, 890.0, 29.8329
47.234719370, 96.390, 819.0, 28.6182
47.287240501, 96.390, 847.0, 29.1033
47.339761632, 96.390, 877.0, 29.6142
47.392282762, 96.390, 913.0, 30.2159
47.444803893, 96.390, 829.0, 28.7924
47.497325024, 96.390, 862.0, 29.3598
47.549846155, 96.390, 877.0, 29.6142
47.602367285, 96.390, 842.0, 29.0172
47.654888416, 96.390, 934.0, 30.5614
47.707409547, 96.390, 858.0, 29.2916
47.759930677, 96.390, 863.0, 29.3769
47.812451808, 96.390, 904.0, 30.0666
47.864972939, 96.390, 836.0, 28.9137
47.917494069, 96.390, 794.0, 28.1780
47.970015200, 96.390, 865.0, 29.4109
48.022536331, 96.390, 853.0, 29.2062
48.075057462, 96.390, 845.0, 29.0689
48.127578592, 96.390, 784.0, 28.0000
48.180099723, 96.390, 830.0, 28.8097
48.232620854, 96.390, 843.0, 29.0345
48.285141984, 96.390, 863.0, 29.3769
48.337663115, 96.390, 835.0, 28.8964
48.390184246, 96.390, 818.0, 28.6007
48.442705377, 96.390, 810.0, 28.4605
48.495226507, 96.390, 827.0, 28.7576
48.547747638, 96.390, 803.0, 28.3373
48.600268769, 96.390, 867.0, 29.4449
48.652789899, 96.390, 778.0, 27.8927
48.705311030, 96.390, 798.0, 28.2489
48.757832161, 96.390, 817.0, 28.5832
48.810353292, 96.390, 821.0, 28.6531
48.862874422, 96.390, 817.0, 28.5832
48.915395553, 96.390, 818.0, 28.6007
48.967916684, 96.390, 854.0, 29.2233
49.020437814, 96.390, 743.0, 27.2580
49.072958945, 96.390, 769.0, 27.7308
49.125480076, 96.390, 822.0, 28.6705
49.178001207, 96.390, 836.0, 28.9137
49.230522337, 96.390, 807.0, 28.4077
49.283043468, 96.390, 801.0, 28.3019
49.335564599, 96.390, 814.0, 28.5307
49.388085729, 96.390, 798.0, 28.2489
49.440606860, 96.390, 784.0, 28.0000
49.493127991, 96.390, 816.0, 28.5657
49.545649121, 96.390, 808.0, 28.4253
49.598170252, 96.390, 770.0, 27.7489
49.650691383, 96.390, 853.0, 29.2062
49.703212514, 96.390, 782.0, 27.9643
49.755733644, 96.390, 818.0, 28.6007
49.808254775, 96.390, 818.0, 28.6007
49.860775906, 96.390, 831.0, 28.8271
49.913297036, 96.390, 819.0, 28.6182
49.965818167, 96.390, 798.0, 28.2489
50.018339298, 96.390, 757.0, 27.5136
50.070860429, 96.390, 831.0, 28.8271
50.123381559, 96.390, 789.0, 28.0891
50.175902690, 96.390, 770.0, 27.7489
50.228423821, 96.390, 807.0, 28.4077
50.280944951, 96.390, 783.0, 27.9821
50.333466082, 96.390, 796.0, 28.2135
50.385987213, 96.390, 780.0, 27.9285
50.438508344, 96.390, 748.0, 27.3496
50.491029474, 96.390, 772.0, 27.7849
50.543550605, 96.390, 803.0, 28.3373
50.596071736, 96.390, 767.0, 27.6948
50.648592866, 96.390, 763.0, 27.6225
50.701113997, 96.390, 771.0, 27.7669
50.753635128, 96.390, 797.0, 28.2312
50.806156258, 96.390, 738.0, 27.1662
50.858677389, 96.390, 755.0, 27.4773
50.911198520, 96.390, 766.0, 27.6767
50.963719651, 96.390, 736.0, 27.1293
51.016240781, 96.390, 795.0, 28.1957
51.068761912, 96.390, 739.0, 27.1846
51.121283043, 96.390, 760.0, 27.5681
51.173804173, 96.390, 794.0, 28.1780
51.226325304, 96.390, 771.0, 27.7669
51.278846435, 96.390, 779.0, 27.9106
51.331367566, 96.390, 728.0, 26.9815
51.383888696, 96.390, 803.0, 28.3373
51.436409827, 96.390, 801.0, 28.3019
51.488930958, 96.390, 783.0, 27.9821
51.541452088, 96.390, 795.0, 28.1957
51.593973219, 96.390, 777.0, 27.8747
51.646494350, 96.390, 776.0, 27.8568
51.699015481, 96.390, 718.0, 26.7955
51.751536611, 96.390, 781.0, 27.9464
51.804057742, 96.390, 791.0, 28.1247
51.856578873, 96.390, 742.0, 27.2397
51.909100003, 96.390, 792.0, 28.1425
51.961621134, 96.390, 763.0, 27.6225
52.014142265, 96.390, 770.0, 27.7489
52.066663396, 96.390, 754.0, 27.4591
52.119184526, 96.390, 746.0, 27.3130
52.171705657, 96.390, 731.0, 27.0370
52.224226788, 96.390, 752.0, 27.4226
52.276747918, 96.390, 783.0, 27.9821
52.329269049, 96.390, 773.0, 27.8029
52.381790180, 96.390, 732.0, 27.0555
52.434311310, 96.390, 746.0, 27.3130
52.486832441, 96.390, 709.0, 26.6271
52.539353572, 96.390, 728.0, 26.9815
52.591874703, 96.390, 757.0, 27.5136
52.644395833, 96.390, 745.0, 27.2947
52.696916964, 96.390, 717.0, 26.7769
52.749438095, 96.390, 728.0, 26.9815
52.801959225, 96.390, 697.0, 26.4008
52.854480356, 96.390, 709.0, 26.6271
52.907001487, 96.390, 747.0, 27.3313
52.959522618, 96.390, 772.0, 27.7849
53.012043748, 96.390, 745.0, 27.2947
53.064564879, 96.390, 726.0, 26.9444
53.117086010, 96.390, 732.0, 27.0555
53.169607140, 96.390, 749.0, 27.3679
53.222128271, 96.390, 758.0, 27.5318
53.274649402, 96.390, 756.0, 27.4955
53.327170533, 96.390, 754.0, 27.4591
53.379691663, 96.390, 723.0, 26.8887
53.432212794, 96.390, 667.0, 25.8263
53.484733925, 96.390, 726.0, 26.9444
53.537255055, 96.390, 685.0, 26.1725
53.589776186, 96.390, 685.0, 26.1725
53.642297317, 96.390, 691.0, 26.2869
53.694818448, 96.390, 730.0, 27.0185
53.747339578, 96.390, 724.0, 26.9072
53.799860709, 96.390, 751.0, 27.4044
53.852381840, 96.390, 658.0, 25.6515
53.904902970, 96.390, 709.0, 26.6271
53.957424101, 96.390, 704.0, 26.5330
54.009945232, 96.390, 717.0, 26.7769
54.062466362, 96.390, 757.0, 27.5136
54.114987493, 96.390, 630.0, 25.0998
54.167508624, 96.390, 683.0, 26.1343
54.220029755, 96.390, 686.0, 26.1916
54.272550885, 96.390, 710.0, 26.6458
54.325072016, 96.390, 666.0, 25.8070
54.377593147, 96.390, 700.0, 26.4575
54.430114277, 96.390, 719.0, 26.8142
54.482635408, 96.390, 710.0, 26.6458
54.535156539, 96.390, 759.0, 27.5500
54.587677670, 96.390, 777.0, 27.8747
54.640198800, 96.390, 682.0, 26.1151
54.692719931, 96.390, 681.0, 26.0960
54.745241062, 96.390, 690.0, 26.2679
54.797762192, 96.390, 690.0, 26.2679
54.850283323, 96.390, 726.0, 26.9444
54.902804454, 96.390, 745.0, 27.2947
54.955325585, 96.390, 731.0, 27.0370
55.007846715, 96.390, 702.0, 26.4953
55.060367846, 96.390, 691.0, 26.2869
55.112888977, 96.390, 733.0, 27.0740
55.165410107, 96.390, 705.0, 26.5518
55.217931238, 96.390, 733.0, 27.0740
55.270452369, 96.390, 759.0, 27.5500
55.322973499, 96.390, 669.0, 25.8650
55.375494630, 96.390, 726.0, 26.9444
55.428015761, 96.390, 705.0, 26.5518
55.480536892, 96.390, 744.0, 27.2764
55.533058022, 96.390, 721.0, 26.8514
55.585579153, 96.390, 673.0, 25.9422
55.638100284, 96.390, 717.0, 26.7769
55.690621414, 96.390, 666.0, 25.8070
55.743142545, 96.390, 653.0, 25.5539
55.795663676, 96.390, 686.0, 26.1916
55.848184807, 96.390, 697.0, 26.4008
55.900705937, 96.390, 708.0, 26.6083
55.953227068, 96.390, 677.0, 26.0192
56.005748199, 96.390, 737.0, 27.1477
56.058269329, 96.390, 681.0, 26.0960
56.110790460, 96.390, 709.0, 26.6271
56.163311591, 96.390, 730.0, 27.0185
56.215832722, 96.390, 722.0, 26.8701
56.268353852, 96.390, 653.0, 25.5539
56.320874983, 96.390, 775.0, 27.8388
56.373396114, 96.390, 677.0, 26.0192
56.425917244, 96.390, 655.0, 25.5930
56.478438375, 96.390, 675.0, 25.9808
56.530959506, 96.390, 729.0, 27.0000
56.583480637, 96.390, 693.0, 26.3249
56.636001767, 96.390, 719.0, 26.8142
56.688522898, 96.390, 696.0, 26.3818
56.741044029, 96.390, 674.0, 25.9615
56.793565159, 96.390, 637.0, 25.2389
56.846086290, 96.390, 681.0, 26.0960
56.898607421, 96.390, 704.0, 26.5330
56.951128551, 96.390, 718.0, 26.7955
57.003649682, 96.390, 720.0, 26.8328
57.056170813, 96.390, 743.0, 27.2580
57.108691944, 96.390, 673.0, 25.9422
57.161213074, 96.390, 735.0, 27.1109
57.213734205, 96.390, 728.0, 26.9815
57.266255336, 96.390, 700.0, 26.4575
57.318776466, 96.390, 683.0, 26.1343
57.371297597, 96.390, 706.0, 26.5707
57.423818728, 96.390, 711.0, 26.6646
57.476339859, 96.390, 656.0, 25.6125
57.528860989, 96.390, 713.0, 26.7021
57.581382120, 96.390, 698.0, 26.4197
57.633903251, 96.390, 689.0, 26.2488
57.686424381, 96.390, 750.0, 27.3861
57.738945512, 96.390, 695.0, 26.3629
57.791466643, 96.390, 685.0, 26.1725
57.843987774, 96.390, 692.0, 26.3059
57.896508904, 96.390, 678.0, 26.0384
57.949030035, 96.390, 700.0, 26.4575
58.001551166, 96.390, 723.0, 26.8887
58.054072296, 96.390, 756.0, 27.4955
58.106593427, 96.390, 698.0, 26.4197
58.159114558, 96.390, 727.0, 26.9629
58.211635689, 96.390, 754.0, 27.4591
58.264156819, 96.390, 697.0, 26.4008
58.316677950, 96.390, 725.0, 26.9258
58.369199081, 96.390, 657.0, 25.6320
58.421720211, 96.390, 701.0, 26.4764
58.474241342, 96.390, 755.0, 27.4773
58.526762473, 96.390, 691.0, 26.2869
58.579283603, 96.390, 709.0, 26.6271
58.631804734, 96.390, 724.0, 26.9072
58.684325865, 96.390, 697.0, 26.4008
58.736846996, 96.390, 715.0, 26.7395
58.789368126, 96.390, 665.0, 25.7876
58.841889257, 96.390, 702.0, 26.4953
58.894410388, 96.390, 680.0, 26.0768
58.946931518, 96.390, 734.0, 27.0924
58.999452649, 96.390, 706.0, 26.5707
59.051973780, 96.390, 734.0, 27.0924
59.104494911, 96.390, 669.0, 25.8650
59.157016041, 96.390, 672.0, 25.9230
59.209537172, 96.390, 725.0, 26.9258
59.262058303, 96.390, 722.0, 26.8701
59.314579433, 96.390, 704.0, 26.5330
59.367100564, 96.390, 704.0, 26.5330
59.419621695, 96.390, 723.0, 26.8887
59.472142826, 96.390, 691.0, 26.2869
59.524663956, 96.390, 704.0, 26.5330
59.577185087, 96.390, 747.0, 27.3313
59.629706218, 96.390, 683.0, 26.1343
59.682227348, 96.390, 707.0, 26.5895
59.734748479, 96.390, 708.0, 26.6083
59.787269610, 96.390, 668.0, 25.8457
59.839790740, 96.390, 666.0, 25.8070
59.892311871, 96.390, 712.0, 26.6833
59.944833002, 96.390, 702.0, 26.4953
59.997354133, 96.390, 730.0, 27.0185
60.049875263, 96.390, 737.0, 27.1477
60.102396394, 96.390, 728.0, 26.9815
60.154917525, 96.390, 700.0, 26.4575
60.207438655, 96.390, 796.0, 28.2135
60.259959786, 96.390, 760.0, 27.5681
60.312480917, 96.390, 745.0, 27.2947
60.365002048, 96.390, 703.0, 26.5141
60.417523178, 96.390, 748.0, 27.3496
60.470044309, 96.390, 729.0, 27.0000
60.522565440, 96.390, 757.0, 27.5136
60.575086570, 96.390, 749.0, 27.3679
60.627607701, 96.390, 750.0, 27.3861
60.680128832, 96.390, 761.0, 27.5862
60.732649963, 96.390, 770.0, 27.7489
60.785171093, 96.390, 814.0, 28.5307
60.837692224, 96.390, 768.0, 27.7128
60.890213355, 96.390, 774.0, 27.8209
60.942734485, 96.390, 772.0, 27.7849
60.995255616, 96.390, 786.0, 28.0357
61.047776747, 96.390, 830.0, 28.8097
61.100297878, 96.390, 791.0, 28.1247
61.152819008, 96.390, 827.0, 28.7576
61.205340139, 96.390, 786.0, 28.0357
61.257861270, 96.390, 776.0, 27.8568
61.310382400, 96.390, 799.0, 28.2666
61.362903531, 96.390, 829.0, 28.7924
61.415424662, 96.390, 836.0, 28.9137
61.467945792, 96.390, 788.0, 28.0713
61.520466923, 96.390, 806.0, 28.3901
61.572988054, 96.390, 842.0, 29.0172
61.625509185, 96.390, 849.0, 29.1376
61.678030315, 96.390, 757.0, 27.5136
61.730551446, 96.390, 780.0, 27.9285
61.783072577, 96.390, 836.0, 28.9137
61.835593707, 96.390, 798.0, 28.2489
61.888114838, 96.390, 806.0, 28.3901
61.940635969, 96.390, 778.0, 27.8927
61.993157100, 96.390, 800.0, 28.2843
62.045678230, 96.390, 808.0, 28.4253
62.098199361, 96.390, 761.0, 27.5862
62.150720492, 96.390, 785.0, 28.0179
62.203241622, 96.390, 756.0, 27.4955
62.255762753, 96.390, 755.0, 27.4773
62.308283884, 96.390, 785.0, 28.0179
62.360805015, 96.390, 795.0, 28.1957
62.413326145, 96.390, 765.0, 27.6586
62.465847276, 96.390, 738.0, 27.1662
62.518368407, 96.390, 766.0, 27.6767
62.570889537, 96.390, 752.0, 27.4226
62.623410668, 96.390, 719.0, 26.8142
62.675931799, 96.390, 747.0, 27.3313
62.728452930, 96.390, 763.0, 27.6225
62.780974060, 96.390, 772.0, 27.7849
62.833495191, 96.390, 728.0, 26.9815
62.886016322, 96.390, 756.0, 27.4955
62.938537452, 96.390, 752.0, 27.4226
62.991058583, 96.390, 728.0, 26.9815
63.043579714, 96.390, 739.0, 27.1846
63.096100844, 96.390, 689.0, 26.2488
63.148621975, 96.390, 727.0, 26.9629
63.201143106, 96.390, 702.0, 26.4953
63.253664237, 96.390, 710.0, 26.6458
63.306185367, 96.390, 680.0, 26.0768
63.358706498, 96.390, 743.0, 27.2580
63.411227629, 96.390, 661.0, 25.7099
63.463748759, 96.390, 659.0, 25.6710
63.516269890, 96.390, 741.0, 27.2213
63.568791021, 96.390, 684.0, 26.1534
63.621312152, 96.390, 735.0, 27.1109
63.673833282, 96.390, 657.0, 25.6320
63.726354413, 96.390, 715.0, 26.7395
63.778875544, 96.390, 712.0, 26.6833
63.831396674, 96.390, 687.0, 26.2107
63.883917805, 96.390, 660.0, 25.6905
63.936438936, 96.390, 684.0, 26.1534
63.988960067, 96.390, 721.0, 26.8514
64.041481197, 96.390, 699.0, 26.4386
64.094002328, 96.390, 714.0, 26.7208
64.146523459, 96.390, 679.0, 26.0576
64.199044589, 96.390, 647.0, 25.4362
64.251565720, 96.390, 658.0, 25.6515
64.304086851, 96.390, 702.0, 26.4953
64.356607981, 96.390, 699.0, 26.4386
64.409129112, 96.390, 676.0, 26.0000
64.461650243, 96.390, 666.0, 25.8070
64.514171374, 96.390, 673.0, 25.9422
64.566692504, 96.390, 701.0, 26.4764
64.619213635, 96.390, 645.0, 25.3969
64.671734766, 96.390, 709.0, 26.6271
64.724255896, 96.390, 704.0, 26.5330
64.776777027, 96.390, 683.0, 26.1343
64.829298158, 96.390, 678.0, 26.0384
64.881819289, 96.390, 694.0, 26.3439
64.934340419, 96.390, 721.0, 26.8514
64.986861550, 96.390, 676.0, 26.0000