File: Files_organized_for_plots/Centroid_changing_NaOH_V2/XRD1_PC_CentroidPrecursor08Dec21_B3_1.csv
[Measurement conditions]
Sample identification,XRD_CentroidPrecursor08Dec21_B3_1
Comment - 1,"Configuration=Stage for Flat Samples/Holders, Owner=User-1, Creation date=7/1/2020 9:53:24 AM"
Comment - 2,"Goniometer=Theta/Theta; Minimum step size 2Theta:0.0001; Minimum step size Omega:0.0001"
Comment - 3,"Sample stage=Stage for flat samples/holders"
Comment - 4,"Diffractometer system=EMPYREAN"
Comment - 5,"Measurement program=C:\Users\ibo5034\OneDrive - The Pennsylvania State University\NEUP\Zerobackground scan.xrdmp, Identifier={98A3B11C-88F9-4AA6-982C-73314A311EF5}"
Anode material,Cu
K-Alpha1 wavelength,1.5405980
K-Alpha2 wavelength,1.5444260
Ratio K-Alpha2/K-Alpha1,0.500
Divergence slit,Fixed,0.25
Monochromator used,NO
Generator voltage, 45
Tube current, 40
File date and time,10/Mar/2022 12:48
Unit cell,
h k l, 0 0 0
Scan axis,Gonio
Scan range,4.994599997,64.999991833
Scan step size,0.0262606
No. of points, 2285
Scan type,CONTINUOUS
Time per step,96.390
[Scan points]
Angle, TimePerStep, Intensity, ESD
5.007730280, 96.390, 4729.0, 68.7677
5.060251411, 96.390, 4607.0, 67.8749
5.112772541, 96.390, 4565.0, 67.5648
5.165293672, 96.390, 4530.0, 67.3053
5.217814803, 96.390, 4449.0, 66.7008
5.270335934, 96.390, 4528.0, 67.2904
5.322857064, 96.390, 4262.0, 65.2840
5.375378195, 96.390, 4302.0, 65.5896
5.427899326, 96.390, 4193.0, 64.7534
5.480420456, 96.390, 4106.0, 64.0781
5.532941587, 96.390, 4135.0, 64.3040
5.585462718, 96.390, 4014.0, 63.3561
5.637983849, 96.390, 3935.0, 62.7296
5.690504979, 96.390, 4031.0, 63.4902
5.743026110, 96.390, 3911.0, 62.5380
5.795547241, 96.390, 3691.0, 60.7536
5.848068371, 96.390, 3849.0, 62.0403
5.900589502, 96.390, 3905.0, 62.4900
5.953110633, 96.390, 3810.0, 61.7252
6.005631763, 96.390, 3683.0, 60.6877
6.058152894, 96.390, 3788.0, 61.5467
6.110674025, 96.390, 3672.0, 60.5970
6.163195156, 96.390, 3608.0, 60.0666
6.215716286, 96.390, 3567.0, 59.7244
6.268237417, 96.390, 3655.0, 60.4566
6.320758548, 96.390, 3570.0, 59.7495
6.373279678, 96.390, 3660.0, 60.4979
6.425800809, 96.390, 3494.0, 59.1101
6.478321940, 96.390, 3641.0, 60.3407
6.530843071, 96.390, 3563.0, 59.6909
6.583364201, 96.390, 3376.0, 58.1034
6.635885332, 96.390, 3432.0, 58.5833
6.688406463, 96.390, 3423.0, 58.5064
6.740927593, 96.390, 3507.0, 59.2199
6.793448724, 96.390, 3359.0, 57.9569
6.845969855, 96.390, 3480.0, 58.9915
6.898490986, 96.390, 3289.0, 57.3498
6.951012116, 96.390, 3277.0, 57.2451
7.003533247, 96.390, 3372.0, 58.0689
7.056054378, 96.390, 3238.0, 56.9034
7.108575508, 96.390, 3229.0, 56.8243
7.161096639, 96.390, 3249.0, 57.0000
7.213617770, 96.390, 3282.0, 57.2887
7.266138900, 96.390, 3143.0, 56.0625
7.318660031, 96.390, 3307.0, 57.5065
7.371181162, 96.390, 3242.0, 56.9386
7.423702293, 96.390, 3210.0, 56.6569
7.476223423, 96.390, 3156.0, 56.1783
7.528744554, 96.390, 3215.0, 56.7010
7.581265685, 96.390, 3158.0, 56.1961
7.633786815, 96.390, 3083.0, 55.5248
7.686307946, 96.390, 3143.0, 56.0625
7.738829077, 96.390, 2986.0, 54.6443
7.791350208, 96.390, 3196.0, 56.5332
7.843871338, 96.390, 3027.0, 55.0182
7.896392469, 96.390, 3032.0, 55.0636
7.948913600, 96.390, 3046.0, 55.1906
8.001434730, 96.390, 3073.0, 55.4346
8.053955861, 96.390, 2977.0, 54.5619
8.106476992, 96.390, 2881.0, 53.6749
8.158998123, 96.390, 2900.0, 53.8516
8.211519253, 96.390, 2907.0, 53.9166
8.264040384, 96.390, 3004.0, 54.8088
8.316561515, 96.390, 2937.0, 54.1941
8.369082645, 96.390, 2970.0, 54.4977
8.421603776, 96.390, 2980.0, 54.5894
8.474124907, 96.390, 2873.0, 53.6004
8.526646038, 96.390, 2919.0, 54.0278
8.579167168, 96.390, 2963.0, 54.4334
8.631688299, 96.390, 2813.0, 53.0377
8.684209430, 96.390, 2941.0, 54.2310
8.736730560, 96.390, 2850.0, 53.3854
8.789251691, 96.390, 2898.0, 53.8331
8.841772822, 96.390, 2733.0, 52.2781
8.894293952, 96.390, 2807.0, 52.9811
8.946815083, 96.390, 2825.0, 53.1507
8.999336214, 96.390, 2706.0, 52.0192
9.051857345, 96.390, 2837.0, 53.2635
9.104378475, 96.390, 2800.0, 52.9150
9.156899606, 96.390, 2830.0, 53.1977
9.209420737, 96.390, 2713.0, 52.0865
9.261941867, 96.390, 2718.0, 52.1344
9.314462998, 96.390, 2658.0, 51.5558
9.366984129, 96.390, 2772.0, 52.6498
9.419505260, 96.390, 2718.0, 52.1344
9.472026390, 96.390, 2719.0, 52.1440
9.524547521, 96.390, 2678.0, 51.7494
9.577068652, 96.390, 2668.0, 51.6527
9.629589782, 96.390, 2730.0, 52.2494
9.682110913, 96.390, 2669.0, 51.6624
9.734632044, 96.390, 2697.0, 51.9326
9.787153175, 96.390, 2654.0, 51.5170
9.839674305, 96.390, 2595.0, 50.9411
9.892195436, 96.390, 2622.0, 51.2055
9.944716567, 96.390, 2633.0, 51.3128
9.997237697, 96.390, 2647.0, 51.4490
10.049758828, 96.390, 2624.0, 51.2250
10.102279959, 96.390, 2540.0, 50.3984
10.154801090, 96.390, 2454.0, 49.5379
10.207322220, 96.390, 2549.0, 50.4876
10.259843351, 96.390, 2521.0, 50.2096
10.312364482, 96.390, 2621.0, 51.1957
10.364885612, 96.390, 2609.0, 51.0784
10.417406743, 96.390, 2525.0, 50.2494
10.469927874, 96.390, 2546.0, 50.4579
10.522449004, 96.390, 2513.0, 50.1298
10.574970135, 96.390, 2511.0, 50.1099
10.627491266, 96.390, 2528.0, 50.2792
10.680012397, 96.390, 2496.0, 49.9600
10.732533527, 96.390, 2571.0, 50.7050
10.785054658, 96.390, 2443.0, 49.4267
10.837575789, 96.390, 2446.0, 49.4571
10.890096919, 96.390, 2420.0, 49.1935
10.942618050, 96.390, 2515.0, 50.1498
10.995139181, 96.390, 2433.0, 49.3254
11.047660312, 96.390, 2338.0, 48.3529
11.100181442, 96.390, 2434.0, 49.3356
11.152702573, 96.390, 2483.0, 49.8297
11.205223704, 96.390, 2426.0, 49.2544
11.257744834, 96.390, 2316.0, 48.1248
11.310265965, 96.390, 2457.0, 49.5681
11.362787096, 96.390, 2413.0, 49.1223
11.415308227, 96.390, 2358.0, 48.5592
11.467829357, 96.390, 2397.0, 48.9592
11.520350488, 96.390, 2344.0, 48.4149
11.572871619, 96.390, 2356.0, 48.5386
11.625392749, 96.390, 2342.0, 48.3942
11.677913880, 96.390, 2283.0, 47.7807
11.730435011, 96.390, 2276.0, 47.7074
11.782956141, 96.390, 2292.0, 47.8748
11.835477272, 96.390, 2313.0, 48.0937
11.887998403, 96.390, 2318.0, 48.1456
11.940519534, 96.390, 2325.0, 48.2183
11.993040664, 96.390, 2318.0, 48.1456
12.045561795, 96.390, 2254.0, 47.4763
12.098082926, 96.390, 2326.0, 48.2286
12.150604056, 96.390, 2330.0, 48.2701
12.203125187, 96.390, 2292.0, 47.8748
12.255646318, 96.390, 2191.0, 46.8081
12.308167449, 96.390, 2265.0, 47.5920
12.360688579, 96.390, 2170.0, 46.5833
12.413209710, 96.390, 2277.0, 47.7179
12.465730841, 96.390, 2276.0, 47.7074
12.518251971, 96.390, 2272.0, 47.6655
12.570773102, 96.390, 2175.0, 46.6369
12.623294233, 96.390, 2180.0, 46.6905
12.675815364, 96.390, 2183.0, 46.7226
12.728336494, 96.390, 2174.0, 46.6262
12.780857625, 96.390, 2154.0, 46.4112
12.833378756, 96.390, 2187.0, 46.7654
12.885899886, 96.390, 2215.0, 47.0638
12.938421017, 96.390, 2139.0, 46.2493
12.990942148, 96.390, 2214.0, 47.0532
13.043463279, 96.390, 2164.0, 46.5188
13.095984409, 96.390, 2190.0, 46.7974
13.148505540, 96.390, 2113.0, 45.9674
13.201026671, 96.390, 2152.0, 46.3897
13.253547801, 96.390, 2170.0, 46.5833
13.306068932, 96.390, 2104.0, 45.8694
13.358590063, 96.390, 2154.0, 46.4112
13.411111193, 96.390, 2125.0, 46.0977
13.463632324, 96.390, 2076.0, 45.5631
13.516153455, 96.390, 2133.0, 46.1844
13.568674586, 96.390, 2199.0, 46.8935
13.621195716, 96.390, 2143.0, 46.2925
13.673716847, 96.390, 2104.0, 45.8694
13.726237978, 96.390, 2146.0, 46.3249
13.778759108, 96.390, 2071.0, 45.5082
13.831280239, 96.390, 2140.0, 46.2601
13.883801370, 96.390, 2146.0, 46.3249
13.936322501, 96.390, 2121.0, 46.0543
13.988843631, 96.390, 2068.0, 45.4753
14.041364762, 96.390, 2108.0, 45.9130
14.093885893, 96.390, 2062.0, 45.4093
14.146407023, 96.390, 2072.0, 45.5192
14.198928154, 96.390, 2051.0, 45.2880
14.251449285, 96.390, 2094.0, 45.7602
14.303970416, 96.390, 2043.0, 45.1996
14.356491546, 96.390, 2045.0, 45.2217
14.409012677, 96.390, 2009.0, 44.8219
14.461533808, 96.390, 2103.0, 45.8585
14.514054938, 96.390, 2038.0, 45.1442
14.566576069, 96.390, 1997.0, 44.6878
14.619097200, 96.390, 1996.0, 44.6766
14.671618331, 96.390, 2069.0, 45.4863
14.724139461, 96.390, 2111.0, 45.9456
14.776660592, 96.390, 2014.0, 44.8776
14.829181723, 96.390, 2046.0, 45.2327
14.881702853, 96.390, 1999.0, 44.7102
14.934223984, 96.390, 2032.0, 45.0777
14.986745115, 96.390, 1999.0, 44.7102
15.039266245, 96.390, 2068.0, 45.4753
15.091787376, 96.390, 2039.0, 45.1553
15.144308507, 96.390, 2086.0, 45.6727
15.196829638, 96.390, 1997.0, 44.6878
15.249350768, 96.390, 2011.0, 44.8442
15.301871899, 96.390, 2097.0, 45.7930
15.354393030, 96.390, 2041.0, 45.1774
15.406914160, 96.390, 2080.0, 45.6070
15.459435291, 96.390, 2069.0, 45.4863
15.511956422, 96.390, 2046.0, 45.2327
15.564477553, 96.390, 2020.0, 44.9444
15.616998683, 96.390, 2021.0, 44.9555
15.669519814, 96.390, 2014.0, 44.8776
15.722040945, 96.390, 2063.0, 45.4203
15.774562075, 96.390, 2081.0, 45.6180
15.827083206, 96.390, 2015.0, 44.8888
15.879604337, 96.390, 2035.0, 45.1110
15.932125468, 96.390, 2066.0, 45.4533
15.984646598, 96.390, 2065.0, 45.4423
16.037167729, 96.390, 2021.0, 44.9555
16.089688860, 96.390, 2008.0, 44.8107
16.142209990, 96.390, 2115.0, 45.9891
16.194731121, 96.390, 2078.0, 45.5851
16.247252252, 96.390, 2066.0, 45.4533
16.299773382, 96.390, 2067.0, 45.4643
16.352294513, 96.390, 2091.0, 45.7275
16.404815644, 96.390, 2107.0, 45.9021
16.457336775, 96.390, 2115.0, 45.9891
16.509857905, 96.390, 2028.0, 45.0333
16.562379036, 96.390, 2219.0, 47.1063
16.614900167, 96.390, 2057.0, 45.3542
16.667421297, 96.390, 2019.0, 44.9333
16.719942428, 96.390, 2078.0, 45.5851
16.772463559, 96.390, 2112.0, 45.9565
16.824984690, 96.390, 2070.0, 45.4973
16.877505820, 96.390, 2086.0, 45.6727
16.930026951, 96.390, 2219.0, 47.1063
16.982548082, 96.390, 2113.0, 45.9674
17.035069212, 96.390, 2188.0, 46.7761
17.087590343, 96.390, 2127.0, 46.1194
17.140111474, 96.390, 2141.0, 46.2709
17.192632605, 96.390, 2190.0, 46.7974
17.245153735, 96.390, 2194.0, 46.8402
17.297674866, 96.390, 2143.0, 46.2925
17.350195997, 96.390, 2236.0, 47.2864
17.402717127, 96.390, 2135.0, 46.2061
17.455238258, 96.390, 2217.0, 47.0850
17.507759389, 96.390, 2226.0, 47.1805
17.560280520, 96.390, 2222.0, 47.1381
17.612801650, 96.390, 2238.0, 47.3075
17.665322781, 96.390, 2182.0, 46.7119
17.717843912, 96.390, 2210.0, 47.0106
17.770365042, 96.390, 2263.0, 47.5710
17.822886173, 96.390, 2239.0, 47.3181
17.875407304, 96.390, 2219.0, 47.1063
17.927928434, 96.390, 2302.0, 47.9792
17.980449565, 96.390, 2222.0, 47.1381
18.032970696, 96.390, 2256.0, 47.4974
18.085491827, 96.390, 2341.0, 48.3839
18.138012957, 96.390, 2304.0, 48.0000
18.190534088, 96.390, 2238.0, 47.3075
18.243055219, 96.390, 2385.0, 48.8365
18.295576349, 96.390, 2314.0, 48.1041
18.348097480, 96.390, 2305.0, 48.0104
18.400618611, 96.390, 2269.0, 47.6340
18.453139742, 96.390, 2298.0, 47.9375
18.505660872, 96.390, 2360.0, 48.5798
18.558182003, 96.390, 2401.0, 49.0000
18.610703134, 96.390, 2398.0, 48.9694
18.663224264, 96.390, 2309.0, 48.0521
18.715745395, 96.390, 2467.0, 49.6689
18.768266526, 96.390, 2441.0, 49.4065
18.820787657, 96.390, 2413.0, 49.1223
18.873308787, 96.390, 2513.0, 50.1298
18.925829918, 96.390, 2421.0, 49.2037
18.978351049, 96.390, 2421.0, 49.2037
19.030872179, 96.390, 2491.0, 49.9099
19.083393310, 96.390, 2510.0, 50.0999
19.135914441, 96.390, 2522.0, 50.2195
19.188435572, 96.390, 2512.0, 50.1199
19.240956702, 96.390, 2608.0, 51.0686
19.293477833, 96.390, 2596.0, 50.9510
19.345998964, 96.390, 2580.0, 50.7937
19.398520094, 96.390, 2603.0, 51.0196
19.451041225, 96.390, 2613.0, 51.1175
19.503562356, 96.390, 2606.0, 51.0490
19.556083486, 96.390, 2576.0, 50.7543
19.608604617, 96.390, 2593.0, 50.9215
19.661125748, 96.390, 2714.0, 52.0961
19.713646879, 96.390, 2689.0, 51.8556
19.766168009, 96.390, 2645.0, 51.4296
19.818689140, 96.390, 2679.0, 51.7591
19.871210271, 96.390, 2783.0, 52.7541
19.923731401, 96.390, 2698.0, 51.9423
19.976252532, 96.390, 2788.0, 52.8015
20.028773663, 96.390, 2785.0, 52.7731
20.081294794, 96.390, 2791.0, 52.8299
20.133815924, 96.390, 2751.0, 52.4500
20.186337055, 96.390, 2757.0, 52.5071
20.238858186, 96.390, 2803.0, 52.9434
20.291379316, 96.390, 2830.0, 53.1977
20.343900447, 96.390, 2834.0, 53.2353
20.396421578, 96.390, 2900.0, 53.8516
20.448942709, 96.390, 3010.0, 54.8635
20.501463839, 96.390, 2987.0, 54.6535
20.553984970, 96.390, 2918.0, 54.0185
20.606506101, 96.390, 2940.0, 54.2218
20.659027231, 96.390, 2987.0, 54.6535
20.711548362, 96.390, 2983.0, 54.6168
20.764069493, 96.390, 3094.0, 55.6237
20.816590623, 96.390, 3050.0, 55.2268
20.869111754, 96.390, 3031.0, 55.0545
20.921632885, 96.390, 3178.0, 56.3738
20.974154016, 96.390, 3024.0, 54.9909
21.026675146, 96.390, 3107.0, 55.7405
21.079196277, 96.390, 3100.0, 55.6776
21.131717408, 96.390, 3144.0, 56.0714
21.184238538, 96.390, 3074.0, 55.4437
21.236759669, 96.390, 3020.0, 54.9545
21.289280800, 96.390, 3139.0, 56.0268
21.341801931, 96.390, 3214.0, 56.6922
21.394323061, 96.390, 3160.0, 56.2139
21.446844192, 96.390, 3165.0, 56.2583
21.499365323, 96.390, 3164.0, 56.2494
21.551886453, 96.390, 3313.0, 57.5587
21.604407584, 96.390, 3255.0, 57.0526
21.656928715, 96.390, 3273.0, 57.2101
21.709449846, 96.390, 3266.0, 57.1489
21.761970976, 96.390, 3178.0, 56.3738
21.814492107, 96.390, 3314.0, 57.5674
21.867013238, 96.390, 3369.0, 58.0431
21.919534368, 96.390, 3269.0, 57.1752
21.972055499, 96.390, 3451.0, 58.7452
22.024576630, 96.390, 3387.0, 58.1979
22.077097761, 96.390, 3410.0, 58.3952
22.129618891, 96.390, 3323.0, 57.6455
22.182140022, 96.390, 3338.0, 57.7754
22.234661153, 96.390, 3317.0, 57.5934
22.287182283, 96.390, 3428.0, 58.5491
22.339703414, 96.390, 3358.0, 57.9483
22.392224545, 96.390, 3415.0, 58.4380
22.444745675, 96.390, 3475.0, 58.9491
22.497266806, 96.390, 3497.0, 59.1354
22.549787937, 96.390, 3352.0, 57.8965
22.602309068, 96.390, 3401.0, 58.3181
22.654830198, 96.390, 3497.0, 59.1354
22.707351329, 96.390, 3519.0, 59.3212
22.759872460, 96.390, 3427.0, 58.5406
22.812393590, 96.390, 3407.0, 58.3695
22.864914721, 96.390, 3409.0, 58.3866
22.917435852, 96.390, 3395.0, 58.2666
22.969956983, 96.390, 3409.0, 58.3866
23.022478113, 96.390, 3452.0, 58.7537
23.074999244, 96.390, 3459.0, 58.8133
23.127520375, 96.390, 3419.0, 58.4722
23.180041505, 96.390, 3472.0, 58.9237
23.232562636, 96.390, 3496.0, 59.1270
23.285083767, 96.390, 3267.0, 57.1577
23.337604898, 96.390, 3402.0, 58.3267
23.390126028, 96.390, 3361.0, 57.9741
23.442647159, 96.390, 3286.0, 57.3236
23.495168290, 96.390, 3322.0, 57.6368
23.547689420, 96.390, 3346.0, 57.8446
23.600210551, 96.390, 3309.0, 57.5239
23.652731682, 96.390, 3415.0, 58.4380
23.705252813, 96.390, 3398.0, 58.2924
23.757773943, 96.390, 3350.0, 57.8792
23.810295074, 96.390, 3274.0, 57.2189
23.862816205, 96.390, 3349.0, 57.8705
23.915337335, 96.390, 3298.0, 57.4282
23.967858466, 96.390, 3266.0, 57.1489
24.020379597, 96.390, 3253.0, 57.0351
24.072900727, 96.390, 3260.0, 57.0964
24.125421858, 96.390, 3167.0, 56.2761
24.177942989, 96.390, 3312.0, 57.5500
24.230464120, 96.390, 3268.0, 57.1664
24.282985250, 96.390, 3248.0, 56.9912
24.335506381, 96.390, 3193.0, 56.5066
24.388027512, 96.390, 3250.0, 57.0088
24.440548642, 96.390, 3111.0, 55.7763
24.493069773, 96.390, 3239.0, 56.9122
24.545590904, 96.390, 3158.0, 56.1961
24.598112035, 96.390, 3181.0, 56.4004
24.650633165, 96.390, 3183.0, 56.4181
24.703154296, 96.390, 3094.0, 55.6237
24.755675427, 96.390, 3157.0, 56.1872
24.808196557, 96.390, 3179.0, 56.3826
24.860717688, 96.390, 3091.0, 55.5968
24.913238819, 96.390, 3132.0, 55.9643
24.965759950, 96.390, 3213.0, 56.6833
25.018281080, 96.390, 3105.0, 55.7225
25.070802211, 96.390, 3090.0, 55.5878
25.123323342, 96.390, 3054.0, 55.2630
25.175844472, 96.390, 3054.0, 55.2630
25.228365603, 96.390, 3030.0, 55.0454
25.280886734, 96.390, 3096.0, 55.6417
25.333407864, 96.390, 2998.0, 54.7540
25.385928995, 96.390, 2991.0, 54.6900
25.438450126, 96.390, 3035.0, 55.0908
25.490971257, 96.390, 3083.0, 55.5248
25.543492387, 96.390, 2987.0, 54.6535
25.596013518, 96.390, 2952.0, 54.3323
25.648534649, 96.390, 2947.0, 54.2863
25.701055779, 96.390, 2972.0, 54.5161
25.753576910, 96.390, 2947.0, 54.2863
25.806098041, 96.390, 3000.0, 54.7723
25.858619172, 96.390, 2838.0, 53.2729
25.911140302, 96.390, 2876.0, 53.6284
25.963661433, 96.390, 2905.0, 53.8981
26.016182564, 96.390, 2899.0, 53.8424
26.068703694, 96.390, 2907.0, 53.9166
26.121224825, 96.390, 2816.0, 53.0660
26.173745956, 96.390, 2913.0, 53.9722
26.226267087, 96.390, 2882.0, 53.6843
26.278788217, 96.390, 2826.0, 53.1601
26.331309348, 96.390, 2696.0, 51.9230
26.383830479, 96.390, 2900.0, 53.8516
26.436351609, 96.390, 2780.0, 52.7257
26.488872740, 96.390, 2814.0, 53.0471
26.541393871, 96.390, 2846.0, 53.3479
26.593915002, 96.390, 2853.0, 53.4135
26.646436132, 96.390, 2838.0, 53.2729
26.698957263, 96.390, 2845.0, 53.3385
26.751478394, 96.390, 2820.0, 53.1037
26.803999524, 96.390, 2751.0, 52.4500
26.856520655, 96.390, 2691.0, 51.8748
26.909041786, 96.390, 2721.0, 52.1632
26.961562916, 96.390, 2703.0, 51.9904
27.014084047, 96.390, 2680.0, 51.7687
27.066605178, 96.390, 2793.0, 52.8488
27.119126309, 96.390, 2637.0, 51.3517
27.171647439, 96.390, 2802.0, 52.9339
27.224168570, 96.390, 2668.0, 51.6527
27.276689701, 96.390, 2718.0, 52.1344
27.329210831, 96.390, 2634.0, 51.3225
27.381731962, 96.390, 2602.0, 51.0098
27.434253093, 96.390, 2618.0, 51.1664
27.486774224, 96.390, 2604.0, 51.0294
27.539295354, 96.390, 2608.0, 51.0686
27.591816485, 96.390, 2599.0, 50.9804
27.644337616, 96.390, 2538.0, 50.3786
27.696858746, 96.390, 2499.0, 49.9900
27.749379877, 96.390, 2589.0, 50.8822
27.801901008, 96.390, 2559.0, 50.5866
27.854422139, 96.390, 2577.0, 50.7642
27.906943269, 96.390, 2499.0, 49.9900
27.959464400, 96.390, 2526.0, 50.2593
28.011985531, 96.390, 2545.0, 50.4480
28.064506661, 96.390, 2447.0, 49.4672
28.117027792, 96.390, 2465.0, 49.6488
28.169548923, 96.390, 2422.0, 49.2138
28.222070054, 96.390, 2415.0, 49.1426
28.274591184, 96.390, 2439.0, 49.3862
28.327112315, 96.390, 2487.0, 49.8698
28.379633446, 96.390, 2495.0, 49.9500
28.432154576, 96.390, 2430.0, 49.2950
28.484675707, 96.390, 2363.0, 48.6107
28.537196838, 96.390, 2400.0, 48.9898
28.589717968, 96.390, 2451.0, 49.5076
28.642239099, 96.390, 2328.0, 48.2494
28.694760230, 96.390, 2298.0, 47.9375
28.747281361, 96.390, 2348.0, 48.4562
28.799802491, 96.390, 2340.0, 48.3735
28.852323622, 96.390, 2299.0, 47.9479
28.904844753, 96.390, 2321.0, 48.1768
28.957365883, 96.390, 2323.0, 48.1975
29.009887014, 96.390, 2330.0, 48.2701
29.062408145, 96.390, 2255.0, 47.4868
29.114929276, 96.390, 2288.0, 47.8330
29.167450406, 96.390, 2324.0, 48.2079
29.219971537, 96.390, 2248.0, 47.4131
29.272492668, 96.390, 2334.0, 48.3115
29.325013798, 96.390, 2281.0, 47.7598
29.377534929, 96.390, 2273.0, 47.6760
29.430056060, 96.390, 2225.0, 47.1699
29.482577191, 96.390, 2278.0, 47.7284
29.535098321, 96.390, 2209.0, 47.0000
29.587619452, 96.390, 2242.0, 47.3498
29.640140583, 96.390, 2179.0, 46.6798
29.692661713, 96.390, 2119.0, 46.0326
29.745182844, 96.390, 2218.0, 47.0956
29.797703975, 96.390, 2249.0, 47.4236
29.850225105, 96.390, 2166.0, 46.5403
29.902746236, 96.390, 2191.0, 46.8081
29.955267367, 96.390, 2137.0, 46.2277
30.007788498, 96.390, 2091.0, 45.7275
30.060309628, 96.390, 2065.0, 45.4423
30.112830759, 96.390, 2152.0, 46.3897
30.165351890, 96.390, 2068.0, 45.4753
30.217873020, 96.390, 2077.0, 45.5741
30.270394151, 96.390, 2196.0, 46.8615
30.322915282, 96.390, 2198.0, 46.8828
30.375436413, 96.390, 2072.0, 45.5192
30.427957543, 96.390, 2105.0, 45.8803
30.480478674, 96.390, 2096.0, 45.7821
30.532999805, 96.390, 2078.0, 45.5851
30.585520935, 96.390, 2073.0, 45.5302
30.638042066, 96.390, 2021.0, 44.9555
30.690563197, 96.390, 2027.0, 45.0222
30.743084328, 96.390, 2020.0, 44.9444
30.795605458, 96.390, 2035.0, 45.1110
30.848126589, 96.390, 1936.0, 44.0000
30.900647720, 96.390, 2010.0, 44.8330
30.953168850, 96.390, 2002.0, 44.7437
31.005689981, 96.390, 1991.0, 44.6206
31.058211112, 96.390, 1924.0, 43.8634
31.110732243, 96.390, 1966.0, 44.3396
31.163253373, 96.390, 1998.0, 44.6990
31.215774504, 96.390, 1943.0, 44.0795
31.268295635, 96.390, 1876.0, 43.3128
31.320816765, 96.390, 1949.0, 44.1475
31.373337896, 96.390, 1898.0, 43.5660
31.425859027, 96.390, 1903.0, 43.6234
31.478380157, 96.390, 1817.0, 42.6263
31.530901288, 96.390, 1914.0, 43.7493
31.583422419, 96.390, 1861.0, 43.1393
31.635943550, 96.390, 1866.0, 43.1972
31.688464680, 96.390, 1889.0, 43.4626
31.740985811, 96.390, 1918.0, 43.7950
31.793506942, 96.390, 1859.0, 43.1161
31.846028072, 96.390, 1835.0, 42.8369
31.898549203, 96.390, 1780.0, 42.1900
31.951070334, 96.390, 1802.0, 42.4500
32.003591465, 96.390, 1843.0, 42.9302
32.056112595, 96.390, 1885.0, 43.4166
32.108633726, 96.390, 1822.0, 42.6849
32.161154857, 96.390, 1808.0, 42.5206
32.213675987, 96.390, 1827.0, 42.7434
32.266197118, 96.390, 1776.0, 42.1426
32.318718249, 96.390, 1791.0, 42.3202
32.371239380, 96.390, 1754.0, 41.8808
32.423760510, 96.390, 1730.0, 41.5933
32.476281641, 96.390, 1735.0, 41.6533
32.528802772, 96.390, 1722.0, 41.4970
32.581323902, 96.390, 1739.0, 41.7013
32.633845033, 96.390, 1767.0, 42.0357
32.686366164, 96.390, 1712.0, 41.3763
32.738887295, 96.390, 1678.0, 40.9634
32.791408425, 96.390, 1719.0, 41.4608
32.843929556, 96.390, 1665.0, 40.8044
32.896450687, 96.390, 1680.0, 40.9878
32.948971817, 96.390, 1688.0, 41.0853
33.001492948, 96.390, 1709.0, 41.3401
33.054014079, 96.390, 1618.0, 40.2244
33.106535209, 96.390, 1773.0, 42.1070
33.159056340, 96.390, 1702.0, 41.2553
33.211577471, 96.390, 1582.0, 39.7744
33.264098602, 96.390, 1735.0, 41.6533
33.316619732, 96.390, 1662.0, 40.7676
33.369140863, 96.390, 1592.0, 39.8999
33.421661994, 96.390, 1534.0, 39.1663
33.474183124, 96.390, 1574.0, 39.6737
33.526704255, 96.390, 1615.0, 40.1871
33.579225386, 96.390, 1567.0, 39.5854
33.631746517, 96.390, 1620.0, 40.2492
33.684267647, 96.390, 1598.0, 39.9750
33.736788778, 96.390, 1525.0, 39.0512
33.789309909, 96.390, 1638.0, 40.4722
33.841831039, 96.390, 1494.0, 38.6523
33.894352170, 96.390, 1628.0, 40.3485
33.946873301, 96.390, 1496.0, 38.6782
33.999394432, 96.390, 1568.0, 39.5980
34.051915562, 96.390, 1578.0, 39.7240
34.104436693, 96.390, 1572.0, 39.6485
34.156957824, 96.390, 1478.0, 38.4448
34.209478954, 96.390, 1519.0, 38.9744
34.262000085, 96.390, 1488.0, 38.5746
34.314521216, 96.390, 1451.0, 38.0920
34.367042346, 96.390, 1390.0, 37.2827
34.419563477, 96.390, 1499.0, 38.7169
34.472084608, 96.390, 1411.0, 37.5633
34.524605739, 96.390, 1466.0, 38.2884
34.577126869, 96.390, 1475.0, 38.4057
34.629648000, 96.390, 1500.0, 38.7298
34.682169131, 96.390, 1473.0, 38.3797
34.734690261, 96.390, 1416.0, 37.6298
34.787211392, 96.390, 1469.0, 38.3275
34.839732523, 96.390, 1451.0, 38.0920
34.892253654, 96.390, 1404.0, 37.4700
34.944774784, 96.390, 1410.0, 37.5500
34.997295915, 96.390, 1383.0, 37.1887
35.049817046, 96.390, 1489.0, 38.5876
35.102338176, 96.390, 1415.0, 37.6165
35.154859307, 96.390, 1385.0, 37.2156
35.207380438, 96.390, 1426.0, 37.7624
35.259901569, 96.390, 1465.0, 38.2753
35.312422699, 96.390, 1398.0, 37.3898
35.364943830, 96.390, 1378.0, 37.1214
35.417464961, 96.390, 1386.0, 37.2290
35.469986091, 96.390, 1385.0, 37.2156
35.522507222, 96.390, 1311.0, 36.2077
35.575028353, 96.390, 1348.0, 36.7151
35.627549484, 96.390, 1270.0, 35.6371
35.680070614, 96.390, 1299.0, 36.0416
35.732591745, 96.390, 1276.0, 35.7211
35.785112876, 96.390, 1400.0, 37.4166
35.837634006, 96.390, 1367.0, 36.9730
35.890155137, 96.390, 1304.0, 36.1109
35.942676268, 96.390, 1302.0, 36.0832
35.995197398, 96.390, 1304.0, 36.1109
36.047718529, 96.390, 1335.0, 36.5377
36.100239660, 96.390, 1317.0, 36.2905
36.152760791, 96.390, 1218.0, 34.8999
36.205281921, 96.390, 1304.0, 36.1109
36.257803052, 96.390, 1303.0, 36.0971
36.310324183, 96.390, 1269.0, 35.6230
36.362845313, 96.390, 1326.0, 36.4143
36.415366444, 96.390, 1290.0, 35.9166
36.467887575, 96.390, 1224.0, 34.9857
36.520408706, 96.390, 1240.0, 35.2136
36.572929836, 96.390, 1224.0, 34.9857
36.625450967, 96.390, 1242.0, 35.2420
36.677972098, 96.390, 1222.0, 34.9571
36.730493228, 96.390, 1225.0, 35.0000
36.783014359, 96.390, 1267.0, 35.5949
36.835535490, 96.390, 1238.0, 35.1852
36.888056621, 96.390, 1104.0, 33.2265
36.940577751, 96.390, 1211.0, 34.7994
36.993098882, 96.390, 1151.0, 33.9264
37.045620013, 96.390, 1272.0, 35.6651
37.098141143, 96.390, 1158.0, 34.0294
37.150662274, 96.390, 1183.0, 34.3948
37.203183405, 96.390, 1204.0, 34.6987
37.255704535, 96.390, 1226.0, 35.0143
37.308225666, 96.390, 1198.0, 34.6121
37.360746797, 96.390, 1194.0, 34.5543
37.413267928, 96.390, 1189.0, 34.4819
37.465789058, 96.390, 1133.0, 33.6601
37.518310189, 96.390, 1202.0, 34.6699
37.570831320, 96.390, 1119.0, 33.4515
37.623352450, 96.390, 1136.0, 33.7046
37.675873581, 96.390, 1219.0, 34.9142
37.728394712, 96.390, 1132.0, 33.6452
37.780915843, 96.390, 1148.0, 33.8821
37.833436973, 96.390, 1196.0, 34.5832
37.885958104, 96.390, 1158.0, 34.0294
37.938479235, 96.390, 1144.0, 33.8231
37.991000365, 96.390, 1143.0, 33.8083
38.043521496, 96.390, 1152.0, 33.9411
38.096042627, 96.390, 1112.0, 33.3467
38.148563758, 96.390, 1099.0, 33.1512
38.201084888, 96.390, 1142.0, 33.7935
38.253606019, 96.390, 1141.0, 33.7787
38.306127150, 96.390, 1100.0, 33.1662
38.358648280, 96.390, 1118.0, 33.4365
38.411169411, 96.390, 1044.0, 32.3110
38.463690542, 96.390, 1093.0, 33.0606
38.516211673, 96.390, 1115.0, 33.3916
38.568732803, 96.390, 1086.0, 32.9545
38.621253934, 96.390, 1140.0, 33.7639
38.673775065, 96.390, 1176.0, 34.2929
38.726296195, 96.390, 1089.0, 33.0000
38.778817326, 96.390, 1147.0, 33.8674
38.831338457, 96.390, 1099.0, 33.1512
38.883859587, 96.390, 1093.0, 33.0606
38.936380718, 96.390, 1101.0, 33.1813
38.988901849, 96.390, 1070.0, 32.7109
39.041422980, 96.390, 1106.0, 33.2566
39.093944110, 96.390, 1075.0, 32.7872
39.146465241, 96.390, 1019.0, 31.9218
39.198986372, 96.390, 1068.0, 32.6803
39.251507502, 96.390, 1072.0, 32.7414
39.304028633, 96.390, 1024.0, 32.0000
39.356549764, 96.390, 1070.0, 32.7109
39.409070895, 96.390, 1102.0, 33.1964
39.461592025, 96.390, 1046.0, 32.3419
39.514113156, 96.390, 1069.0, 32.6956
39.566634287, 96.390, 1037.0, 32.2025
39.619155417, 96.390, 1026.0, 32.0312
39.671676548, 96.390, 1059.0, 32.5423
39.724197679, 96.390, 1088.0, 32.9848
39.776718810, 96.390, 1091.0, 33.0303
39.829239940, 96.390, 1061.0, 32.5730
39.881761071, 96.390, 1081.0, 32.8786
39.934282202, 96.390, 977.0, 31.2570
39.986803332, 96.390, 1025.0, 32.0156
40.039324463, 96.390, 1071.0, 32.7261
40.091845594, 96.390, 1007.0, 31.7333
40.144366725, 96.390, 1035.0, 32.1714
40.196887855, 96.390, 1081.0, 32.8786
40.249408986, 96.390, 1030.0, 32.0936
40.301930117, 96.390, 1054.0, 32.4654
40.354451247, 96.390, 1066.0, 32.6497
40.406972378, 96.390, 1019.0, 31.9218
40.459493509, 96.390, 1054.0, 32.4654
40.512014639, 96.390, 988.0, 31.4325
40.564535770, 96.390, 1022.0, 31.9687
40.617056901, 96.390, 1066.0, 32.6497
40.669578032, 96.390, 989.0, 31.4484
40.722099162, 96.390, 1030.0, 32.0936
40.774620293, 96.390, 1073.0, 32.7567
40.827141424, 96.390, 1047.0, 32.3574
40.879662554, 96.390, 997.0, 31.5753
40.932183685, 96.390, 1022.0, 31.9687
40.984704816, 96.390, 1049.0, 32.3883
41.037225947, 96.390, 1060.0, 32.5576
41.089747077, 96.390, 1024.0, 32.0000
41.142268208, 96.390, 1064.0, 32.6190
41.194789339, 96.390, 1047.0, 32.3574
41.247310469, 96.390, 1021.0, 31.9531
41.299831600, 96.390, 1006.0, 31.7175
41.352352731, 96.390, 985.0, 31.3847
41.404873862, 96.390, 1009.0, 31.7648
41.457394992, 96.390, 1014.0, 31.8434
41.509916123, 96.390, 1022.0, 31.9687
41.562437254, 96.390, 973.0, 31.1929
41.614958384, 96.390, 1013.0, 31.8277
41.667479515, 96.390, 1017.0, 31.8904
41.720000646, 96.390, 991.0, 31.4802
41.772521776, 96.390, 970.0, 31.1448
41.825042907, 96.390, 962.0, 31.0161
41.877564038, 96.390, 1019.0, 31.9218
41.930085169, 96.390, 983.0, 31.3528
41.982606299, 96.390, 1019.0, 31.9218
42.035127430, 96.390, 1033.0, 32.1403
42.087648561, 96.390, 998.0, 31.5911
42.140169691, 96.390, 1075.0, 32.7872
42.192690822, 96.390, 1034.0, 32.1559
42.245211953, 96.390, 1042.0, 32.2800
42.297733084, 96.390, 1021.0, 31.9531
42.350254214, 96.390, 1001.0, 31.6386
42.402775345, 96.390, 992.0, 31.4960
42.455296476, 96.390, 1066.0, 32.6497
42.507817606, 96.390, 997.0, 31.5753
42.560338737, 96.390, 1033.0, 32.1403
42.612859868, 96.390, 954.0, 30.8869
42.665380999, 96.390, 1030.0, 32.0936
42.717902129, 96.390, 992.0, 31.4960
42.770423260, 96.390, 1026.0, 32.0312
42.822944391, 96.390, 1029.0, 32.0780
42.875465521, 96.390, 1028.0, 32.0624
42.927986652, 96.390, 1007.0, 31.7333
42.980507783, 96.390, 1011.0, 31.7962
43.033028914, 96.390, 994.0, 31.5278
43.085550044, 96.390, 999.0, 31.6070
43.138071175, 96.390, 957.0, 30.9354
43.190592306, 96.390, 989.0, 31.4484
43.243113436, 96.390, 1013.0, 31.8277
43.295634567, 96.390, 1048.0, 32.3728
43.348155698, 96.390, 1002.0, 31.6544
43.400676828, 96.390, 971.0, 31.1609
43.453197959, 96.390, 1000.0, 31.6228
43.505719090, 96.390, 1000.0, 31.6228
43.558240221, 96.390, 979.0, 31.2890
43.610761351, 96.390, 984.0, 31.3688
43.663282482, 96.390, 1023.0, 31.9844
43.715803613, 96.390, 985.0, 31.3847
43.768324743, 96.390, 996.0, 31.5595
43.820845874, 96.390, 1000.0, 31.6228
43.873367005, 96.390, 996.0, 31.5595
43.925888136, 96.390, 986.0, 31.4006
43.978409266, 96.390, 978.0, 31.2730
44.030930397, 96.390, 1007.0, 31.7333
44.083451528, 96.390, 988.0, 31.4325
44.135972658, 96.390, 956.0, 30.9192
44.188493789, 96.390, 959.0, 30.9677
44.241014920, 96.390, 1020.0, 31.9374
44.293536051, 96.390, 951.0, 30.8383
44.346057181, 96.390, 981.0, 31.3209
44.398578312, 96.390, 897.0, 29.9500
44.451099443, 96.390, 1026.0, 32.0312
44.503620573, 96.390, 946.0, 30.7571
44.556141704, 96.390, 929.0, 30.4795
44.608662835, 96.390, 955.0, 30.9031
44.661183966, 96.390, 1001.0, 31.6386
44.713705096, 96.390, 1022.0, 31.9687
44.766226227, 96.390, 957.0, 30.9354
44.818747358, 96.390, 965.0, 31.0644
44.871268488, 96.390, 945.0, 30.7409
44.923789619, 96.390, 927.0, 30.4467
44.976310750, 96.390, 1007.0, 31.7333
45.028831880, 96.390, 937.0, 30.6105
45.081353011, 96.390, 950.0, 30.8221
45.133874142, 96.390, 1009.0, 31.7648
45.186395273, 96.390, 985.0, 31.3847
45.238916403, 96.390, 994.0, 31.5278
45.291437534, 96.390, 925.0, 30.4138
45.343958665, 96.390, 922.0, 30.3645
45.396479795, 96.390, 860.0, 29.3258
45.449000926, 96.390, 896.0, 29.9333
45.501522057, 96.390, 986.0, 31.4006
45.554043188, 96.390, 972.0, 31.1769
45.606564318, 96.390, 950.0, 30.8221
45.659085449, 96.390, 943.0, 30.7083
45.711606580, 96.390, 915.0, 30.2490
45.764127710, 96.390, 914.0, 30.2324
45.816648841, 96.390, 916.0, 30.2655
45.869169972, 96.390, 943.0, 30.7083
45.921691103, 96.390, 946.0, 30.7571
45.974212233, 96.390, 873.0, 29.5466
46.026733364, 96.390, 914.0, 30.2324
46.079254495, 96.390, 960.0, 30.9839
46.131775625, 96.390, 889.0, 29.8161
46.184296756, 96.390, 881.0, 29.6816
46.236817887, 96.390, 942.0, 30.6920
46.289339017, 96.390, 940.0, 30.6594
46.341860148, 96.390, 913.0, 30.2159
46.394381279, 96.390, 890.0, 29.8329
46.446902410, 96.390, 907.0, 30.1164
46.499423540, 96.390, 908.0, 30.1330
46.551944671, 96.390, 934.0, 30.5614
46.604465802, 96.390, 951.0, 30.8383
46.656986932, 96.390, 934.0, 30.5614
46.709508063, 96.390, 940.0, 30.6594
46.762029194, 96.390, 909.0, 30.1496
46.814550325, 96.390, 979.0, 31.2890
46.867071455, 96.390, 899.0, 29.9833
46.919592586, 96.390, 957.0, 30.9354
46.972113717, 96.390, 907.0, 30.1164
47.024634847, 96.390, 931.0, 30.5123
47.077155978, 96.390, 979.0, 31.2890
47.129677109, 96.390, 938.0, 30.6268
47.182198240, 96.390, 940.0, 30.6594
47.234719370, 96.390, 923.0, 30.3809
47.287240501, 96.390, 1012.0, 31.8119
47.339761632, 96.390, 962.0, 31.0161
47.392282762, 96.390, 919.0, 30.3150
47.444803893, 96.390, 874.0, 29.5635
47.497325024, 96.390, 936.0, 30.5941
47.549846155, 96.390, 890.0, 29.8329
47.602367285, 96.390, 950.0, 30.8221
47.654888416, 96.390, 948.0, 30.7896
47.707409547, 96.390, 860.0, 29.3258
47.759930677, 96.390, 859.0, 29.3087
47.812451808, 96.390, 878.0, 29.6311
47.864972939, 96.390, 903.0, 30.0500
47.917494069, 96.390, 895.0, 29.9166
47.970015200, 96.390, 912.0, 30.1993
48.022536331, 96.390, 846.0, 29.0861
48.075057462, 96.390, 873.0, 29.5466
48.127578592, 96.390, 899.0, 29.9833
48.180099723, 96.390, 940.0, 30.6594
48.232620854, 96.390, 847.0, 29.1033
48.285141984, 96.390, 917.0, 30.2820
48.337663115, 96.390, 933.0, 30.5450
48.390184246, 96.390, 906.0, 30.0998
48.442705377, 96.390, 932.0, 30.5287
48.495226507, 96.390, 921.0, 30.3480
48.547747638, 96.390, 890.0, 29.8329
48.600268769, 96.390, 870.0, 29.4958
48.652789899, 96.390, 922.0, 30.3645
48.705311030, 96.390, 917.0, 30.2820
48.757832161, 96.390, 881.0, 29.6816
48.810353292, 96.390, 888.0, 29.7993
48.862874422, 96.390, 897.0, 29.9500
48.915395553, 96.390, 903.0, 30.0500
48.967916684, 96.390, 842.0, 29.0172
49.020437814, 96.390, 902.0, 30.0333
49.072958945, 96.390, 873.0, 29.5466
49.125480076, 96.390, 812.0, 28.4956
49.178001207, 96.390, 888.0, 29.7993
49.230522337, 96.390, 887.0, 29.7825
49.283043468, 96.390, 862.0, 29.3598
49.335564599, 96.390, 838.0, 28.9482
49.388085729, 96.390, 859.0, 29.3087
49.440606860, 96.390, 895.0, 29.9166
49.493127991, 96.390, 899.0, 29.9833
49.545649121, 96.390, 859.0, 29.3087
49.598170252, 96.390, 830.0, 28.8097
49.650691383, 96.390, 899.0, 29.9833
49.703212514, 96.390, 831.0, 28.8271
49.755733644, 96.390, 837.0, 28.9310
49.808254775, 96.390, 925.0, 30.4138
49.860775906, 96.390, 893.0, 29.8831
49.913297036, 96.390, 828.0, 28.7750
49.965818167, 96.390, 878.0, 29.6311
50.018339298, 96.390, 914.0, 30.2324
50.070860429, 96.390, 903.0, 30.0500
50.123381559, 96.390, 854.0, 29.2233
50.175902690, 96.390, 876.0, 29.5973
50.228423821, 96.390, 870.0, 29.4958
50.280944951, 96.390, 889.0, 29.8161
50.333466082, 96.390, 886.0, 29.7658
50.385987213, 96.390, 825.0, 28.7228
50.438508344, 96.390, 857.0, 29.2746
50.491029474, 96.390, 859.0, 29.3087
50.543550605, 96.390, 862.0, 29.3598
50.596071736, 96.390, 888.0, 29.7993
50.648592866, 96.390, 956.0, 30.9192
50.701113997, 96.390, 864.0, 29.3939
50.753635128, 96.390, 852.0, 29.1890
50.806156258, 96.390, 872.0, 29.5296
50.858677389, 96.390, 841.0, 29.0000
50.911198520, 96.390, 823.0, 28.6880
50.963719651, 96.390, 883.0, 29.7153
51.016240781, 96.390, 912.0, 30.1993
51.068761912, 96.390, 889.0, 29.8161
51.121283043, 96.390, 872.0, 29.5296
51.173804173, 96.390, 847.0, 29.1033
51.226325304, 96.390, 842.0, 29.0172
51.278846435, 96.390, 905.0, 30.0832
51.331367566, 96.390, 864.0, 29.3939
51.383888696, 96.390, 841.0, 29.0000
51.436409827, 96.390, 878.0, 29.6311
51.488930958, 96.390, 879.0, 29.6479
51.541452088, 96.390, 830.0, 28.8097
51.593973219, 96.390, 864.0, 29.3939
51.646494350, 96.390, 875.0, 29.5804
51.699015481, 96.390, 873.0, 29.5466
51.751536611, 96.390, 922.0, 30.3645
51.804057742, 96.390, 808.0, 28.4253
51.856578873, 96.390, 874.0, 29.5635
51.909100003, 96.390, 879.0, 29.6479
51.961621134, 96.390, 885.0, 29.7489
52.014142265, 96.390, 865.0, 29.4109
52.066663396, 96.390, 890.0, 29.8329
52.119184526, 96.390, 821.0, 28.6531
52.171705657, 96.390, 874.0, 29.5635
52.224226788, 96.390, 797.0, 28.2312
52.276747918, 96.390, 859.0, 29.3087
52.329269049, 96.390, 855.0, 29.2404
52.381790180, 96.390, 855.0, 29.2404
52.434311310, 96.390, 835.0, 28.8964
52.486832441, 96.390, 855.0, 29.2404
52.539353572, 96.390, 874.0, 29.5635
52.591874703, 96.390, 879.0, 29.6479
52.644395833, 96.390, 900.0, 30.0000
52.696916964, 96.390, 886.0, 29.7658
52.749438095, 96.390, 810.0, 28.4605
52.801959225, 96.390, 820.0, 28.6356
52.854480356, 96.390, 846.0, 29.0861
52.907001487, 96.390, 882.0, 29.6985
52.959522618, 96.390, 870.0, 29.4958
53.012043748, 96.390, 854.0, 29.2233
53.064564879, 96.390, 861.0, 29.3428
53.117086010, 96.390, 862.0, 29.3598
53.169607140, 96.390, 899.0, 29.9833
53.222128271, 96.390, 849.0, 29.1376
53.274649402, 96.390, 875.0, 29.5804
53.327170533, 96.390, 872.0, 29.5296
53.379691663, 96.390, 878.0, 29.6311
53.432212794, 96.390, 867.0, 29.4449
53.484733925, 96.390, 830.0, 28.8097
53.537255055, 96.390, 911.0, 30.1828
53.589776186, 96.390, 848.0, 29.1204
53.642297317, 96.390, 887.0, 29.7825
53.694818448, 96.390, 829.0, 28.7924
53.747339578, 96.390, 858.0, 29.2916
53.799860709, 96.390, 841.0, 29.0000
53.852381840, 96.390, 874.0, 29.5635
53.904902970, 96.390, 835.0, 28.8964
53.957424101, 96.390, 827.0, 28.7576
54.009945232, 96.390, 923.0, 30.3809
54.062466362, 96.390, 787.0, 28.0535
54.114987493, 96.390, 854.0, 29.2233
54.167508624, 96.390, 870.0, 29.4958
54.220029755, 96.390, 907.0, 30.1164
54.272550885, 96.390, 792.0, 28.1425
54.325072016, 96.390, 849.0, 29.1376
54.377593147, 96.390, 858.0, 29.2916
54.430114277, 96.390, 806.0, 28.3901
54.482635408, 96.390, 866.0, 29.4279
54.535156539, 96.390, 889.0, 29.8161
54.587677670, 96.390, 897.0, 29.9500
54.640198800, 96.390, 860.0, 29.3258
54.692719931, 96.390, 868.0, 29.4618
54.745241062, 96.390, 888.0, 29.7993
54.797762192, 96.390, 803.0, 28.3373
54.850283323, 96.390, 878.0, 29.6311
54.902804454, 96.390, 792.0, 28.1425
54.955325585, 96.390, 822.0, 28.6705
55.007846715, 96.390, 869.0, 29.4788
55.060367846, 96.390, 854.0, 29.2233
55.112888977, 96.390, 851.0, 29.1719
55.165410107, 96.390, 876.0, 29.5973
55.217931238, 96.390, 879.0, 29.6479
55.270452369, 96.390, 797.0, 28.2312
55.322973499, 96.390, 906.0, 30.0998
55.375494630, 96.390, 877.0, 29.6142
55.428015761, 96.390, 875.0, 29.5804
55.480536892, 96.390, 817.0, 28.5832
55.533058022, 96.390, 908.0, 30.1330
55.585579153, 96.390, 839.0, 28.9655
55.638100284, 96.390, 845.0, 29.0689
55.690621414, 96.390, 862.0, 29.3598
55.743142545, 96.390, 898.0, 29.9666
55.795663676, 96.390, 849.0, 29.1376
55.848184807, 96.390, 830.0, 28.8097
55.900705937, 96.390, 803.0, 28.3373
55.953227068, 96.390, 829.0, 28.7924
56.005748199, 96.390, 848.0, 29.1204
56.058269329, 96.390, 904.0, 30.0666
56.110790460, 96.390, 831.0, 28.8271
56.163311591, 96.390, 819.0, 28.6182
56.215832722, 96.390, 876.0, 29.5973
56.268353852, 96.390, 875.0, 29.5804
56.320874983, 96.390, 842.0, 29.0172
56.373396114, 96.390, 845.0, 29.0689
56.425917244, 96.390, 879.0, 29.6479
56.478438375, 96.390, 834.0, 28.8791
56.530959506, 96.390, 844.0, 29.0517
56.583480637, 96.390, 856.0, 29.2575
56.636001767, 96.390, 855.0, 29.2404
56.688522898, 96.390, 891.0, 29.8496
56.741044029, 96.390, 829.0, 28.7924
56.793565159, 96.390, 850.0, 29.1548
56.846086290, 96.390, 858.0, 29.2916
56.898607421, 96.390, 889.0, 29.8161
56.951128551, 96.390, 862.0, 29.3598
57.003649682, 96.390, 825.0, 28.7228
57.056170813, 96.390, 851.0, 29.1719
57.108691944, 96.390, 842.0, 29.0172
57.161213074, 96.390, 849.0, 29.1376
57.213734205, 96.390, 813.0, 28.5132
57.266255336, 96.390, 883.0, 29.7153
57.318776466, 96.390, 832.0, 28.8444
57.371297597, 96.390, 866.0, 29.4279
57.423818728, 96.390, 854.0, 29.2233
57.476339859, 96.390, 825.0, 28.7228
57.528860989, 96.390, 864.0, 29.3939
57.581382120, 96.390, 884.0, 29.7321
57.633903251, 96.390, 873.0, 29.5466
57.686424381, 96.390, 850.0, 29.1548
57.738945512, 96.390, 833.0, 28.8617
57.791466643, 96.390, 842.0, 29.0172
57.843987774, 96.390, 902.0, 30.0333
57.896508904, 96.390, 829.0, 28.7924
57.949030035, 96.390, 882.0, 29.6985
58.001551166, 96.390, 877.0, 29.6142
58.054072296, 96.390, 894.0, 29.8998
58.106593427, 96.390, 877.0, 29.6142
58.159114558, 96.390, 878.0, 29.6311
58.211635689, 96.390, 859.0, 29.3087
58.264156819, 96.390, 827.0, 28.7576
58.316677950, 96.390, 869.0, 29.4788
58.369199081, 96.390, 826.0, 28.7402
58.421720211, 96.390, 893.0, 29.8831
58.474241342, 96.390, 866.0, 29.4279
58.526762473, 96.390, 847.0, 29.1033
58.579283603, 96.390, 816.0, 28.5657
58.631804734, 96.390, 843.0, 29.0345
58.684325865, 96.390, 828.0, 28.7750
58.736846996, 96.390, 802.0, 28.3196
58.789368126, 96.390, 870.0, 29.4958
58.841889257, 96.390, 798.0, 28.2489
58.894410388, 96.390, 838.0, 28.9482
58.946931518, 96.390, 818.0, 28.6007
58.999452649, 96.390, 849.0, 29.1376
59.051973780, 96.390, 836.0, 28.9137
59.104494911, 96.390, 849.0, 29.1376
59.157016041, 96.390, 876.0, 29.5973
59.209537172, 96.390, 864.0, 29.3939
59.262058303, 96.390, 816.0, 28.5657
59.314579433, 96.390, 891.0, 29.8496
59.367100564, 96.390, 830.0, 28.8097
59.419621695, 96.390, 855.0, 29.2404
59.472142826, 96.390, 825.0, 28.7228
59.524663956, 96.390, 865.0, 29.4109
59.577185087, 96.390, 882.0, 29.6985
59.629706218, 96.390, 878.0, 29.6311
59.682227348, 96.390, 828.0, 28.7750
59.734748479, 96.390, 837.0, 28.9310
59.787269610, 96.390, 875.0, 29.5804
59.839790740, 96.390, 889.0, 29.8161
59.892311871, 96.390, 856.0, 29.2575
59.944833002, 96.390, 830.0, 28.8097
59.997354133, 96.390, 803.0, 28.3373
60.049875263, 96.390, 791.0, 28.1247
60.102396394, 96.390, 817.0, 28.5832
60.154917525, 96.390, 859.0, 29.3087
60.207438655, 96.390, 856.0, 29.2575
60.259959786, 96.390, 832.0, 28.8444
60.312480917, 96.390, 827.0, 28.7576
60.365002048, 96.390, 808.0, 28.4253
60.417523178, 96.390, 874.0, 29.5635
60.470044309, 96.390, 855.0, 29.2404
60.522565440, 96.390, 838.0, 28.9482
60.575086570, 96.390, 922.0, 30.3645
60.627607701, 96.390, 871.0, 29.5127
60.680128832, 96.390, 856.0, 29.2575
60.732649963, 96.390, 826.0, 28.7402
60.785171093, 96.390, 784.0, 28.0000
60.837692224, 96.390, 812.0, 28.4956
60.890213355, 96.390, 821.0, 28.6531
60.942734485, 96.390, 864.0, 29.3939
60.995255616, 96.390, 827.0, 28.7576
61.047776747, 96.390, 832.0, 28.8444
61.100297878, 96.390, 826.0, 28.7402
61.152819008, 96.390, 834.0, 28.8791
61.205340139, 96.390, 862.0, 29.3598
61.257861270, 96.390, 854.0, 29.2233
61.310382400, 96.390, 867.0, 29.4449
61.362903531, 96.390, 898.0, 29.9666
61.415424662, 96.390, 903.0, 30.0500
61.467945792, 96.390, 837.0, 28.9310
61.520466923, 96.390, 821.0, 28.6531
61.572988054, 96.390, 885.0, 29.7489
61.625509185, 96.390, 824.0, 28.7054
61.678030315, 96.390, 832.0, 28.8444
61.730551446, 96.390, 831.0, 28.8271
61.783072577, 96.390, 929.0, 30.4795
61.835593707, 96.390, 884.0, 29.7321
61.888114838, 96.390, 893.0, 29.8831
61.940635969, 96.390, 895.0, 29.9166
61.993157100, 96.390, 850.0, 29.1548
62.045678230, 96.390, 857.0, 29.2746
62.098199361, 96.390, 854.0, 29.2233
62.150720492, 96.390, 797.0, 28.2312
62.203241622, 96.390, 902.0, 30.0333
62.255762753, 96.390, 813.0, 28.5132
62.308283884, 96.390, 855.0, 29.2404
62.360805015, 96.390, 872.0, 29.5296
62.413326145, 96.390, 825.0, 28.7228
62.465847276, 96.390, 821.0, 28.6531
62.518368407, 96.390, 891.0, 29.8496
62.570889537, 96.390, 855.0, 29.2404
62.623410668, 96.390, 800.0, 28.2843
62.675931799, 96.390, 868.0, 29.4618
62.728452930, 96.390, 839.0, 28.9655
62.780974060, 96.390, 896.0, 29.9333
62.833495191, 96.390, 782.0, 27.9643
62.886016322, 96.390, 783.0, 27.9821
62.938537452, 96.390, 800.0, 28.2843
62.991058583, 96.390, 873.0, 29.5466
63.043579714, 96.390, 841.0, 29.0000
63.096100844, 96.390, 820.0, 28.6356
63.148621975, 96.390, 849.0, 29.1376
63.201143106, 96.390, 812.0, 28.4956
63.253664237, 96.390, 872.0, 29.5296
63.306185367, 96.390, 823.0, 28.6880
63.358706498, 96.390, 824.0, 28.7054
63.411227629, 96.390, 840.0, 28.9828
63.463748759, 96.390, 839.0, 28.9655
63.516269890, 96.390, 842.0, 29.0172
63.568791021, 96.390, 853.0, 29.2062
63.621312152, 96.390, 820.0, 28.6356
63.673833282, 96.390, 860.0, 29.3258
63.726354413, 96.390, 849.0, 29.1376
63.778875544, 96.390, 812.0, 28.4956
63.831396674, 96.390, 814.0, 28.5307
63.883917805, 96.390, 828.0, 28.7750
63.936438936, 96.390, 875.0, 29.5804
63.988960067, 96.390, 930.0, 30.4959
64.041481197, 96.390, 832.0, 28.8444
64.094002328, 96.390, 883.0, 29.7153
64.146523459, 96.390, 810.0, 28.4605
64.199044589, 96.390, 889.0, 29.8161
64.251565720, 96.390, 850.0, 29.1548
64.304086851, 96.390, 837.0, 28.9310
64.356607981, 96.390, 844.0, 29.0517
64.409129112, 96.390, 819.0, 28.6182
64.461650243, 96.390, 824.0, 28.7054
64.514171374, 96.390, 827.0, 28.7576
64.566692504, 96.390, 830.0, 28.8097
64.619213635, 96.390, 852.0, 29.1890
64.671734766, 96.390, 852.0, 29.1890
64.724255896, 96.390, 822.0, 28.6705
64.776777027, 96.390, 811.0, 28.4781
64.829298158, 96.390, 820.0, 28.6356
64.881819289, 96.390, 822.0, 28.6705
64.934340419, 96.390, 850.0, 29.1548
64.986861550, 96.390, 809.0, 28.4429