File: Files_organized_for_plots/Centroid_changing_NaOH_V2/XRD9_Centroid16Mar22_Act21Mar22_B4_0893M_NaOH_LS0168_1.csv
[Measurement conditions]
Sample identification,XRD_Centroid16Mar22_Act21Mar22_B4_0893M_NaOH_LS0168_1
Comment - 1,"Configuration=Stage for Flat Samples/Holders, Owner=User-1, Creation date=7/1/2020 9:53:24 AM"
Comment - 2,"Goniometer=Theta/Theta; Minimum step size 2Theta:0.0001; Minimum step size Omega:0.0001"
Comment - 3,"Sample stage=Stage for flat samples/holders"
Comment - 4,"Diffractometer system=EMPYREAN"
Comment - 5,"Measurement program=C:\Users\ibo5034\OneDrive - The Pennsylvania State University\NEUP\Zerobackground scan.xrdmp, Identifier={98A3B11C-88F9-4AA6-982C-73314A311EF5}"
Anode material,Cu
K-Alpha1 wavelength,1.5405980
K-Alpha2 wavelength,1.5444260
Ratio K-Alpha2/K-Alpha1,0.500
Divergence slit,Fixed,0.25
Monochromator used,NO
Generator voltage, 45
Tube current, 40
File date and time,24/Mar/2022 19:03
Unit cell,
h k l, 0 0 0
Scan axis,Gonio
Scan range,4.994599997,64.999991833
Scan step size,0.0262606
No. of points, 2285
Scan type,CONTINUOUS
Time per step,96.390
[Scan points]
Angle, TimePerStep, Intensity, ESD
5.007730280, 96.390, 3720.0, 60.9918
5.060251411, 96.390, 3804.0, 61.6766
5.112772541, 96.390, 3762.0, 61.3351
5.165293672, 96.390, 3686.0, 60.7124
5.217814803, 96.390, 3696.0, 60.7947
5.270335934, 96.390, 3685.0, 60.7042
5.322857064, 96.390, 3615.0, 60.1249
5.375378195, 96.390, 3557.0, 59.6406
5.427899326, 96.390, 3408.0, 58.3781
5.480420456, 96.390, 3540.0, 59.4979
5.532941587, 96.390, 3513.0, 59.2706
5.585462718, 96.390, 3443.0, 58.6771
5.637983849, 96.390, 3450.0, 58.7367
5.690504979, 96.390, 3334.0, 57.7408
5.743026110, 96.390, 3398.0, 58.2924
5.795547241, 96.390, 3382.0, 58.1550
5.848068371, 96.390, 3402.0, 58.3267
5.900589502, 96.390, 3373.0, 58.0775
5.953110633, 96.390, 3269.0, 57.1752
6.005631763, 96.390, 3355.0, 57.9224
6.058152894, 96.390, 3283.0, 57.2975
6.110674025, 96.390, 3243.0, 56.9473
6.163195156, 96.390, 3337.0, 57.7668
6.215716286, 96.390, 3244.0, 56.9561
6.268237417, 96.390, 3269.0, 57.1752
6.320758548, 96.390, 3246.0, 56.9737
6.373279678, 96.390, 3308.0, 57.5152
6.425800809, 96.390, 3151.0, 56.1338
6.478321940, 96.390, 3194.0, 56.5155
6.530843071, 96.390, 3225.0, 56.7891
6.583364201, 96.390, 3328.0, 57.6888
6.635885332, 96.390, 3243.0, 56.9473
6.688406463, 96.390, 3257.0, 57.0701
6.740927593, 96.390, 3166.0, 56.2672
6.793448724, 96.390, 3116.0, 55.8211
6.845969855, 96.390, 3193.0, 56.5066
6.898490986, 96.390, 3217.0, 56.7186
6.951012116, 96.390, 3168.0, 56.2850
7.003533247, 96.390, 3174.0, 56.3383
7.056054378, 96.390, 3201.0, 56.5774
7.108575508, 96.390, 3052.0, 55.2449
7.161096639, 96.390, 3164.0, 56.2494
7.213617770, 96.390, 3128.0, 55.9285
7.266138900, 96.390, 3016.0, 54.9181
7.318660031, 96.390, 3135.0, 55.9911
7.371181162, 96.390, 3196.0, 56.5332
7.423702293, 96.390, 3129.0, 55.9375
7.476223423, 96.390, 3042.0, 55.1543
7.528744554, 96.390, 3061.0, 55.3263
7.581265685, 96.390, 3097.0, 55.6507
7.633786815, 96.390, 3167.0, 56.2761
7.686307946, 96.390, 3147.0, 56.0981
7.738829077, 96.390, 3141.0, 56.0446
7.791350208, 96.390, 3175.0, 56.3471
7.843871338, 96.390, 3130.0, 55.9464
7.896392469, 96.390, 3208.0, 56.6392
7.948913600, 96.390, 3246.0, 56.9737
8.001434730, 96.390, 3319.0, 57.6108
8.053955861, 96.390, 3293.0, 57.3847
8.106476992, 96.390, 3505.0, 59.2030
8.158998123, 96.390, 3473.0, 58.9322
8.211519253, 96.390, 3152.0, 56.1427
8.264040384, 96.390, 3035.0, 55.0908
8.316561515, 96.390, 3132.0, 55.9643
8.369082645, 96.390, 3185.0, 56.4358
8.421603776, 96.390, 3217.0, 56.7186
8.474124907, 96.390, 3214.0, 56.6922
8.526646038, 96.390, 3541.0, 59.5063
8.579167168, 96.390, 3475.0, 58.9491
8.631688299, 96.390, 3287.0, 57.3324
8.684209430, 96.390, 3160.0, 56.2139
8.736730560, 96.390, 3202.0, 56.5862
8.789251691, 96.390, 3193.0, 56.5066
8.841772822, 96.390, 3149.0, 56.1160
8.894293952, 96.390, 3056.0, 55.2811
8.946815083, 96.390, 3179.0, 56.3826
8.999336214, 96.390, 3117.0, 55.8301
9.051857345, 96.390, 3109.0, 55.7584
9.104378475, 96.390, 3188.0, 56.4624
9.156899606, 96.390, 3048.0, 55.2087
9.209420737, 96.390, 3079.0, 55.4887
9.261941867, 96.390, 3002.0, 54.7905
9.314462998, 96.390, 2997.0, 54.7449
9.366984129, 96.390, 3216.0, 56.7098
9.419505260, 96.390, 3164.0, 56.2494
9.472026390, 96.390, 3202.0, 56.5862
9.524547521, 96.390, 3133.0, 55.9732
9.577068652, 96.390, 3160.0, 56.2139
9.629589782, 96.390, 3215.0, 56.7010
9.682110913, 96.390, 3113.0, 55.7943
9.734632044, 96.390, 3140.0, 56.0357
9.787153175, 96.390, 3103.0, 55.7046
9.839674305, 96.390, 3141.0, 56.0446
9.892195436, 96.390, 3122.0, 55.8749
9.944716567, 96.390, 3155.0, 56.1694
9.997237697, 96.390, 3173.0, 56.3294
10.049758828, 96.390, 3166.0, 56.2672
10.102279959, 96.390, 3168.0, 56.2850
10.154801090, 96.390, 3143.0, 56.0625
10.207322220, 96.390, 3095.0, 55.6327
10.259843351, 96.390, 3210.0, 56.6569
10.312364482, 96.390, 3264.0, 57.1314
10.364885612, 96.390, 3336.0, 57.7581
10.417406743, 96.390, 3188.0, 56.4624
10.469927874, 96.390, 3260.0, 57.0964
10.522449004, 96.390, 3262.0, 57.1139
10.574970135, 96.390, 3239.0, 56.9122
10.627491266, 96.390, 3305.0, 57.4891
10.680012397, 96.390, 3273.0, 57.2101
10.732533527, 96.390, 3289.0, 57.3498
10.785054658, 96.390, 3271.0, 57.1927
10.837575789, 96.390, 3283.0, 57.2975
10.890096919, 96.390, 3256.0, 57.0614
10.942618050, 96.390, 3241.0, 56.9298
10.995139181, 96.390, 3339.0, 57.7841
11.047660312, 96.390, 3357.0, 57.9396
11.100181442, 96.390, 3309.0, 57.5239
11.152702573, 96.390, 3250.0, 57.0088
11.205223704, 96.390, 3187.0, 56.4535
11.257744834, 96.390, 3161.0, 56.2228
11.310265965, 96.390, 3219.0, 56.7362
11.362787096, 96.390, 3174.0, 56.3383
11.415308227, 96.390, 3238.0, 56.9034
11.467829357, 96.390, 3029.0, 55.0364
11.520350488, 96.390, 3127.0, 55.9196
11.572871619, 96.390, 3038.0, 55.1181
11.625392749, 96.390, 2964.0, 54.4426
11.677913880, 96.390, 3079.0, 55.4887
11.730435011, 96.390, 3016.0, 54.9181
11.782956141, 96.390, 3012.0, 54.8817
11.835477272, 96.390, 2958.0, 54.3875
11.887998403, 96.390, 2988.0, 54.6626
11.940519534, 96.390, 2951.0, 54.3231
11.993040664, 96.390, 2901.0, 53.8609
12.045561795, 96.390, 2999.0, 54.7631
12.098082926, 96.390, 2925.0, 54.0833
12.150604056, 96.390, 2846.0, 53.3479
12.203125187, 96.390, 2755.0, 52.4881
12.255646318, 96.390, 2802.0, 52.9339
12.308167449, 96.390, 2723.0, 52.1824
12.360688579, 96.390, 2692.0, 51.8845
12.413209710, 96.390, 2740.0, 52.3450
12.465730841, 96.390, 2796.0, 52.8772
12.518251971, 96.390, 2621.0, 51.1957
12.570773102, 96.390, 2675.0, 51.7204
12.623294233, 96.390, 2709.0, 52.0481
12.675815364, 96.390, 2811.0, 53.0189
12.728336494, 96.390, 2796.0, 52.8772
12.780857625, 96.390, 2685.0, 51.8170
12.833378756, 96.390, 2563.0, 50.6261
12.885899886, 96.390, 2619.0, 51.1762
12.938421017, 96.390, 2505.0, 50.0500
12.990942148, 96.390, 2635.0, 51.3323
13.043463279, 96.390, 2504.0, 50.0400
13.095984409, 96.390, 2499.0, 49.9900
13.148505540, 96.390, 2500.0, 50.0000
13.201026671, 96.390, 2547.0, 50.4678
13.253547801, 96.390, 2571.0, 50.7050
13.306068932, 96.390, 2467.0, 49.6689
13.358590063, 96.390, 2521.0, 50.2096
13.411111193, 96.390, 2535.0, 50.3488
13.463632324, 96.390, 2692.0, 51.8845
13.516153455, 96.390, 2837.0, 53.2635
13.568674586, 96.390, 2446.0, 49.4571
13.621195716, 96.390, 2403.0, 49.0204
13.673716847, 96.390, 2292.0, 47.8748
13.726237978, 96.390, 2454.0, 49.5379
13.778759108, 96.390, 2610.0, 51.0882
13.831280239, 96.390, 2682.0, 51.7880
13.883801370, 96.390, 2580.0, 50.7937
13.936322501, 96.390, 2546.0, 50.4579
13.988843631, 96.390, 2418.0, 49.1732
14.041364762, 96.390, 2388.0, 48.8672
14.093885893, 96.390, 2461.0, 49.6085
14.146407023, 96.390, 2471.0, 49.7092
14.198928154, 96.390, 2753.0, 52.4690
14.251449285, 96.390, 3186.0, 56.4447
14.303970416, 96.390, 3042.0, 55.1543
14.356491546, 96.390, 2446.0, 49.4571
14.409012677, 96.390, 2603.0, 51.0196
14.461533808, 96.390, 2848.0, 53.3667
14.514054938, 96.390, 3524.0, 59.3633
14.566576069, 96.390, 3238.0, 56.9034
14.619097200, 96.390, 2292.0, 47.8748
14.671618331, 96.390, 2194.0, 46.8402
14.724139461, 96.390, 2170.0, 46.5833
14.776660592, 96.390, 2232.0, 47.2440
14.829181723, 96.390, 2138.0, 46.2385
14.881702853, 96.390, 2290.0, 47.8539
14.934223984, 96.390, 2237.0, 47.2969
14.986745115, 96.390, 2325.0, 48.2183
15.039266245, 96.390, 2325.0, 48.2183
15.091787376, 96.390, 2457.0, 49.5681
15.144308507, 96.390, 2740.0, 52.3450
15.196829638, 96.390, 3304.0, 57.4804
15.249350768, 96.390, 3445.0, 58.6941
15.301871899, 96.390, 3382.0, 58.1550
15.354393030, 96.390, 2484.0, 49.8397
15.406914160, 96.390, 2274.0, 47.6865
15.459435291, 96.390, 2207.0, 46.9787
15.511956422, 96.390, 2160.0, 46.4758
15.564477553, 96.390, 2021.0, 44.9555
15.616998683, 96.390, 2135.0, 46.2061
15.669519814, 96.390, 2231.0, 47.2335
15.722040945, 96.390, 2329.0, 48.2597
15.774562075, 96.390, 2102.0, 45.8476
15.827083206, 96.390, 2107.0, 45.9021
15.879604337, 96.390, 2025.0, 45.0000
15.932125468, 96.390, 2036.0, 45.1221
15.984646598, 96.390, 2034.0, 45.0999
16.037167729, 96.390, 2117.0, 46.0109
16.089688860, 96.390, 2147.0, 46.3357
16.142209990, 96.390, 2137.0, 46.2277
16.194731121, 96.390, 2211.0, 47.0213
16.247252252, 96.390, 2412.0, 49.1121
16.299773382, 96.390, 2915.0, 53.9907
16.352294513, 96.390, 3138.0, 56.0179
16.404815644, 96.390, 2335.0, 48.3218
16.457336775, 96.390, 2128.0, 46.1303
16.509857905, 96.390, 2158.0, 46.4543
16.562379036, 96.390, 2011.0, 44.8442
16.614900167, 96.390, 2066.0, 45.4533
16.667421297, 96.390, 2030.0, 45.0555
16.719942428, 96.390, 2013.0, 44.8665
16.772463559, 96.390, 2039.0, 45.1553
16.824984690, 96.390, 2004.0, 44.7661
16.877505820, 96.390, 2048.0, 45.2548
16.930026951, 96.390, 2061.0, 45.3982
16.982548082, 96.390, 2083.0, 45.6399
17.035069212, 96.390, 1970.0, 44.3847
17.087590343, 96.390, 2030.0, 45.0555
17.140111474, 96.390, 1947.0, 44.1248
17.192632605, 96.390, 2020.0, 44.9444
17.245153735, 96.390, 2049.0, 45.2659
17.297674866, 96.390, 2101.0, 45.8367
17.350195997, 96.390, 2178.0, 46.6690
17.402717127, 96.390, 2367.0, 48.6518
17.455238258, 96.390, 2164.0, 46.5188
17.507759389, 96.390, 2010.0, 44.8330
17.560280520, 96.390, 2043.0, 45.1996
17.612801650, 96.390, 1900.0, 43.5890
17.665322781, 96.390, 2042.0, 45.1885
17.717843912, 96.390, 2042.0, 45.1885
17.770365042, 96.390, 1949.0, 44.1475
17.822886173, 96.390, 2032.0, 45.0777
17.875407304, 96.390, 2000.0, 44.7214
17.927928434, 96.390, 1997.0, 44.6878
17.980449565, 96.390, 2053.0, 45.3100
18.032970696, 96.390, 2028.0, 45.0333
18.085491827, 96.390, 2132.0, 46.1736
18.138012957, 96.390, 2111.0, 45.9456
18.190534088, 96.390, 2109.0, 45.9239
18.243055219, 96.390, 2243.0, 47.3603
18.295576349, 96.390, 2481.0, 49.8096
18.348097480, 96.390, 2466.0, 49.6588
18.400618611, 96.390, 2362.0, 48.6004
18.453139742, 96.390, 2362.0, 48.6004
18.505660872, 96.390, 2191.0, 46.8081
18.558182003, 96.390, 2152.0, 46.3897
18.610703134, 96.390, 2085.0, 45.6618
18.663224264, 96.390, 2217.0, 47.0850
18.715745395, 96.390, 2377.0, 48.7545
18.768266526, 96.390, 2578.0, 50.7740
18.820787657, 96.390, 2820.0, 53.1037
18.873308787, 96.390, 3272.0, 57.2014
18.925829918, 96.390, 3177.0, 56.3649
18.978351049, 96.390, 3411.0, 58.4038
19.030872179, 96.390, 2836.0, 53.2541
19.083393310, 96.390, 2574.0, 50.7346
19.135914441, 96.390, 2475.0, 49.7494
19.188435572, 96.390, 2323.0, 48.1975
19.240956702, 96.390, 2203.0, 46.9361
19.293477833, 96.390, 2356.0, 48.5386
19.345998964, 96.390, 2530.0, 50.2991
19.398520094, 96.390, 2647.0, 51.4490
19.451041225, 96.390, 2761.0, 52.5452
19.503562356, 96.390, 2683.0, 51.7977
19.556083486, 96.390, 2417.0, 49.1630
19.608604617, 96.390, 2467.0, 49.6689
19.661125748, 96.390, 2413.0, 49.1223
19.713646879, 96.390, 2600.0, 50.9902
19.766168009, 96.390, 2978.0, 54.5711
19.818689140, 96.390, 3154.0, 56.1605
19.871210271, 96.390, 2881.0, 53.6749
19.923731401, 96.390, 3280.0, 57.2713
19.976252532, 96.390, 3989.0, 63.1585
20.028773663, 96.390, 3165.0, 56.2583
20.081294794, 96.390, 2442.0, 49.4166
20.133815924, 96.390, 2376.0, 48.7442
20.186337055, 96.390, 2363.0, 48.6107
20.238858186, 96.390, 2366.0, 48.6415
20.291379316, 96.390, 2471.0, 49.7092
20.343900447, 96.390, 2759.0, 52.5262
20.396421578, 96.390, 3331.0, 57.7148
20.448942709, 96.390, 3745.0, 61.1964
20.501463839, 96.390, 3210.0, 56.6569
20.553984970, 96.390, 3225.0, 56.7891
20.606506101, 96.390, 3925.0, 62.6498
20.659027231, 96.390, 5116.0, 71.5262
20.711548362, 96.390, 6927.0, 83.2286
20.764069493, 96.390, 4627.0, 68.0221
20.816590623, 96.390, 2786.0, 52.7826
20.869111754, 96.390, 2470.0, 49.6991
20.921632885, 96.390, 2369.0, 48.6724
20.974154016, 96.390, 2356.0, 48.5386
21.026675146, 96.390, 2368.0, 48.6621
21.079196277, 96.390, 2430.0, 49.2950
21.131717408, 96.390, 2363.0, 48.6107
21.184238538, 96.390, 2392.0, 48.9081
21.236759669, 96.390, 2590.0, 50.8920
21.289280800, 96.390, 2731.0, 52.2590
21.341801931, 96.390, 2841.0, 53.3010
21.394323061, 96.390, 2581.0, 50.8035
21.446844192, 96.390, 2462.0, 49.6185
21.499365323, 96.390, 2481.0, 49.8096
21.551886453, 96.390, 2781.0, 52.7352
21.604407584, 96.390, 3177.0, 56.3649
21.656928715, 96.390, 3275.0, 57.2276
21.709449846, 96.390, 2710.0, 52.0577
21.761970976, 96.390, 2551.0, 50.5074
21.814492107, 96.390, 2451.0, 49.5076
21.867013238, 96.390, 2354.0, 48.5180
21.919534368, 96.390, 2389.0, 48.8774
21.972055499, 96.390, 2416.0, 49.1528
22.024576630, 96.390, 2445.0, 49.4469
22.077097761, 96.390, 2513.0, 50.1298
22.129618891, 96.390, 2603.0, 51.0196
22.182140022, 96.390, 2591.0, 50.9019
22.234661153, 96.390, 2569.0, 50.6853
22.287182283, 96.390, 2518.0, 50.1797
22.339703414, 96.390, 2430.0, 49.2950
22.392224545, 96.390, 2505.0, 50.0500
22.444745675, 96.390, 2527.0, 50.2693
22.497266806, 96.390, 2691.0, 51.8748
22.549787937, 96.390, 2675.0, 51.7204
22.602309068, 96.390, 2824.0, 53.1413
22.654830198, 96.390, 2788.0, 52.8015
22.707351329, 96.390, 2644.0, 51.4198
22.759872460, 96.390, 2905.0, 53.8981
22.812393590, 96.390, 3298.0, 57.4282
22.864914721, 96.390, 3479.0, 58.9830
22.917435852, 96.390, 3217.0, 56.7186
22.969956983, 96.390, 3149.0, 56.1160
23.022478113, 96.390, 3017.0, 54.9272
23.074999244, 96.390, 2953.0, 54.3415
23.127520375, 96.390, 3238.0, 56.9034
23.180041505, 96.390, 3672.0, 60.5970
23.232562636, 96.390, 3460.0, 58.8218
23.285083767, 96.390, 3193.0, 56.5066
23.337604898, 96.390, 3058.0, 55.2992
23.390126028, 96.390, 3198.0, 56.5509
23.442647159, 96.390, 3018.0, 54.9363
23.495168290, 96.390, 2960.0, 54.4059
23.547689420, 96.390, 2860.0, 53.4790
23.600210551, 96.390, 2855.0, 53.4322
23.652731682, 96.390, 2663.0, 51.6043
23.705252813, 96.390, 2448.0, 49.4773
23.757773943, 96.390, 2395.0, 48.9387
23.810295074, 96.390, 2441.0, 49.4065
23.862816205, 96.390, 2481.0, 49.8096
23.915337335, 96.390, 2453.0, 49.5278
23.967858466, 96.390, 2375.0, 48.7340
24.020379597, 96.390, 2399.0, 48.9796
24.072900727, 96.390, 2508.0, 50.0799
24.125421858, 96.390, 2645.0, 51.4296
24.177942989, 96.390, 2877.0, 53.6377
24.230464120, 96.390, 2780.0, 52.7257
24.282985250, 96.390, 2623.0, 51.2152
24.335506381, 96.390, 2506.0, 50.0600
24.388027512, 96.390, 2278.0, 47.7284
24.440548642, 96.390, 2268.0, 47.6235
24.493069773, 96.390, 2313.0, 48.0937
24.545590904, 96.390, 2288.0, 47.8330
24.598112035, 96.390, 2359.0, 48.5695
24.650633165, 96.390, 2317.0, 48.1352
24.703154296, 96.390, 2144.0, 46.3033
24.755675427, 96.390, 2221.0, 47.1275
24.808196557, 96.390, 2262.0, 47.5605
24.860717688, 96.390, 2222.0, 47.1381
24.913238819, 96.390, 2178.0, 46.6690
24.965759950, 96.390, 2115.0, 45.9891
25.018281080, 96.390, 2134.0, 46.1952
25.070802211, 96.390, 2017.0, 44.9110
25.123323342, 96.390, 2054.0, 45.3211
25.175844472, 96.390, 2094.0, 45.7602
25.228365603, 96.390, 2023.0, 44.9778
25.280886734, 96.390, 2070.0, 45.4973
25.333407864, 96.390, 2229.0, 47.2123
25.385928995, 96.390, 2596.0, 50.9510
25.438450126, 96.390, 2906.0, 53.9073
25.490971257, 96.390, 2596.0, 50.9510
25.543492387, 96.390, 2209.0, 47.0000
25.596013518, 96.390, 1924.0, 43.8634
25.648534649, 96.390, 2023.0, 44.9778
25.701055779, 96.390, 1909.0, 43.6921
25.753576910, 96.390, 1996.0, 44.6766
25.806098041, 96.390, 1988.0, 44.5870
25.858619172, 96.390, 2194.0, 46.8402
25.911140302, 96.390, 2202.0, 46.9255
25.963661433, 96.390, 2118.0, 46.0217
26.016182564, 96.390, 2033.0, 45.0888
26.068703694, 96.390, 1937.0, 44.0114
26.121224825, 96.390, 1778.0, 42.1663
26.173745956, 96.390, 1810.0, 42.5441
26.226267087, 96.390, 1854.0, 43.0581
26.278788217, 96.390, 1877.0, 43.3244
26.331309348, 96.390, 1922.0, 43.8406
26.383830479, 96.390, 1910.0, 43.7035
26.436351609, 96.390, 2025.0, 45.0000
26.488872740, 96.390, 1903.0, 43.6234
26.541393871, 96.390, 1859.0, 43.1161
26.593915002, 96.390, 1873.0, 43.2782
26.646436132, 96.390, 1912.0, 43.7264
26.698957263, 96.390, 2229.0, 47.2123
26.751478394, 96.390, 2599.0, 50.9804
26.803999524, 96.390, 3151.0, 56.1338
26.856520655, 96.390, 2937.0, 54.1941
26.909041786, 96.390, 2527.0, 50.2693
26.961562916, 96.390, 2493.0, 49.9300
27.014084047, 96.390, 3014.0, 54.8999
27.066605178, 96.390, 3293.0, 57.3847
27.119126309, 96.390, 3359.0, 57.9569
27.171647439, 96.390, 4327.0, 65.7799
27.224168570, 96.390, 4017.0, 63.3798
27.276689701, 96.390, 3078.0, 55.4797
27.329210831, 96.390, 2241.0, 47.3392
27.381731962, 96.390, 2096.0, 45.7821
27.434253093, 96.390, 2007.0, 44.7996
27.486774224, 96.390, 1874.0, 43.2897
27.539295354, 96.390, 1754.0, 41.8808
27.591816485, 96.390, 1915.0, 43.7607
27.644337616, 96.390, 2002.0, 44.7437
27.696858746, 96.390, 1905.0, 43.6463
27.749379877, 96.390, 1931.0, 43.9431
27.801901008, 96.390, 1944.0, 44.0908
27.854422139, 96.390, 1877.0, 43.3244
27.906943269, 96.390, 1792.0, 42.3320
27.959464400, 96.390, 1945.0, 44.1022
28.011985531, 96.390, 1966.0, 44.3396
28.064506661, 96.390, 1933.0, 43.9659
28.117027792, 96.390, 1973.0, 44.4185
28.169548923, 96.390, 1911.0, 43.7150
28.222070054, 96.390, 1934.0, 43.9773
28.274591184, 96.390, 2038.0, 45.1442
28.327112315, 96.390, 2066.0, 45.4533
28.379633446, 96.390, 1992.0, 44.6318
28.432154576, 96.390, 1952.0, 44.1814
28.484675707, 96.390, 1942.0, 44.0681
28.537196838, 96.390, 2008.0, 44.8107
28.589717968, 96.390, 1923.0, 43.8520
28.642239099, 96.390, 1901.0, 43.6005
28.694760230, 96.390, 1962.0, 44.2945
28.747281361, 96.390, 2162.0, 46.4973
28.799802491, 96.390, 2041.0, 45.1774
28.852323622, 96.390, 2099.0, 45.8148
28.904844753, 96.390, 1980.0, 44.4972
28.957365883, 96.390, 1954.0, 44.2041
29.009887014, 96.390, 2068.0, 45.4753
29.062408145, 96.390, 2284.0, 47.7912
29.114929276, 96.390, 2668.0, 51.6527
29.167450406, 96.390, 2797.0, 52.8867
29.219971537, 96.390, 2694.0, 51.9038
29.272492668, 96.390, 3105.0, 55.7225
29.325013798, 96.390, 3427.0, 58.5406
29.377534929, 96.390, 2977.0, 54.5619
29.430056060, 96.390, 2820.0, 53.1037
29.482577191, 96.390, 3069.0, 55.3986
29.535098321, 96.390, 2684.0, 51.8073
29.587619452, 96.390, 2518.0, 50.1797
29.640140583, 96.390, 2278.0, 47.7284
29.692661713, 96.390, 2152.0, 46.3897
29.745182844, 96.390, 2153.0, 46.4004
29.797703975, 96.390, 2037.0, 45.1331
29.850225105, 96.390, 1908.0, 43.6807
29.902746236, 96.390, 1956.0, 44.2267
29.955267367, 96.390, 2010.0, 44.8330
30.007788498, 96.390, 1992.0, 44.6318
30.060309628, 96.390, 1967.0, 44.3509
30.112830759, 96.390, 1870.0, 43.2435
30.165351890, 96.390, 1805.0, 42.4853
30.217873020, 96.390, 1882.0, 43.3820
30.270394151, 96.390, 1838.0, 42.8719
30.322915282, 96.390, 1921.0, 43.8292
30.375436413, 96.390, 2021.0, 44.9555
30.427957543, 96.390, 2139.0, 46.2493
30.480478674, 96.390, 2258.0, 47.5184
30.532999805, 96.390, 2145.0, 46.3141
30.585520935, 96.390, 2330.0, 48.2701
30.638042066, 96.390, 2674.0, 51.7107
30.690563197, 96.390, 2729.0, 52.2398
30.743084328, 96.390, 3324.0, 57.6541
30.795605458, 96.390, 2883.0, 53.6936
30.848126589, 96.390, 2931.0, 54.1387
30.900647720, 96.390, 2407.0, 49.0612
30.953168850, 96.390, 2258.0, 47.5184
31.005689981, 96.390, 2219.0, 47.1063
31.058211112, 96.390, 2108.0, 45.9130
31.110732243, 96.390, 2332.0, 48.2908
31.163253373, 96.390, 2849.0, 53.3760
31.215774504, 96.390, 3876.0, 62.2575
31.268295635, 96.390, 3842.0, 61.9839
31.320816765, 96.390, 3796.0, 61.6117
31.373337896, 96.390, 3381.0, 58.1464
31.425859027, 96.390, 2956.0, 54.3691
31.478380157, 96.390, 2742.0, 52.3641
31.530901288, 96.390, 2674.0, 51.7107
31.583422419, 96.390, 2433.0, 49.3254
31.635943550, 96.390, 2388.0, 48.8672
31.688464680, 96.390, 2472.0, 49.7192
31.740985811, 96.390, 2429.0, 49.2849
31.793506942, 96.390, 2206.0, 46.9681
31.846028072, 96.390, 2085.0, 45.6618
31.898549203, 96.390, 2295.0, 47.9062
31.951070334, 96.390, 2841.0, 53.3010
32.003591465, 96.390, 3990.0, 63.1664
32.056112595, 96.390, 5764.0, 75.9210
32.108633726, 96.390, 4932.0, 70.2282
32.161154857, 96.390, 3951.0, 62.8570
32.213675987, 96.390, 2839.0, 53.2823
32.266197118, 96.390, 3097.0, 55.6507
32.318718249, 96.390, 2794.0, 52.8583
32.371239380, 96.390, 2468.0, 49.6790
32.423760510, 96.390, 2051.0, 45.2880
32.476281641, 96.390, 1907.0, 43.6692
32.528802772, 96.390, 1867.0, 43.2088
32.581323902, 96.390, 1877.0, 43.3244
32.633845033, 96.390, 2116.0, 46.0000
32.686366164, 96.390, 2172.0, 46.6047
32.738887295, 96.390, 2098.0, 45.8039
32.791408425, 96.390, 1827.0, 42.7434
32.843929556, 96.390, 1844.0, 42.9418
32.896450687, 96.390, 1932.0, 43.9545
32.948971817, 96.390, 2133.0, 46.1844
33.001492948, 96.390, 2297.0, 47.9270
33.054014079, 96.390, 2367.0, 48.6518
33.106535209, 96.390, 2529.0, 50.2892
33.159056340, 96.390, 2478.0, 49.7795
33.211577471, 96.390, 2490.0, 49.8999
33.264098602, 96.390, 2376.0, 48.7442
33.316619732, 96.390, 2303.0, 47.9896
33.369140863, 96.390, 2300.0, 47.9583
33.421661994, 96.390, 2479.0, 49.7896
33.474183124, 96.390, 2444.0, 49.4368
33.526704255, 96.390, 2136.0, 46.2169
33.579225386, 96.390, 2004.0, 44.7661
33.631746517, 96.390, 1985.0, 44.5533
33.684267647, 96.390, 1882.0, 43.3820
33.736788778, 96.390, 1950.0, 44.1588
33.789309909, 96.390, 1914.0, 43.7493
33.841831039, 96.390, 2062.0, 45.4093
33.894352170, 96.390, 2560.0, 50.5964
33.946873301, 96.390, 3123.0, 55.8838
33.999394432, 96.390, 2858.0, 53.4603
34.051915562, 96.390, 2465.0, 49.6488
34.104436693, 96.390, 2043.0, 45.1996
34.156957824, 96.390, 2133.0, 46.1844
34.209478954, 96.390, 2076.0, 45.5631
34.262000085, 96.390, 2234.0, 47.2652
34.314521216, 96.390, 2367.0, 48.6518
34.367042346, 96.390, 2515.0, 50.1498
34.419563477, 96.390, 2810.0, 53.0094
34.472084608, 96.390, 3351.0, 57.8878
34.524605739, 96.390, 3645.0, 60.3738
34.577126869, 96.390, 3836.0, 61.9355
34.629648000, 96.390, 3364.0, 58.0000
34.682169131, 96.390, 2964.0, 54.4426
34.734690261, 96.390, 2773.0, 52.6593
34.787211392, 96.390, 2719.0, 52.1440
34.839732523, 96.390, 2923.0, 54.0648
34.892253654, 96.390, 3506.0, 59.2115
34.944774784, 96.390, 3690.0, 60.7454
34.997295915, 96.390, 3561.0, 59.6741
35.049817046, 96.390, 3290.0, 57.3585
35.102338176, 96.390, 2955.0, 54.3599
35.154859307, 96.390, 2826.0, 53.1601
35.207380438, 96.390, 2937.0, 54.1941
35.259901569, 96.390, 2662.0, 51.5946
35.312422699, 96.390, 2338.0, 48.3529
35.364943830, 96.390, 2111.0, 45.9456
35.417464961, 96.390, 2080.0, 45.6070
35.469986091, 96.390, 2054.0, 45.3211
35.522507222, 96.390, 2001.0, 44.7325
35.575028353, 96.390, 2196.0, 46.8615
35.627549484, 96.390, 2151.0, 46.3789
35.680070614, 96.390, 2243.0, 47.3603
35.732591745, 96.390, 2267.0, 47.6130
35.785112876, 96.390, 2211.0, 47.0213
35.837634006, 96.390, 2359.0, 48.5695
35.890155137, 96.390, 2696.0, 51.9230
35.942676268, 96.390, 3097.0, 55.6507
35.995197398, 96.390, 2763.0, 52.5642
36.047718529, 96.390, 2773.0, 52.6593
36.100239660, 96.390, 2690.0, 51.8652
36.152760791, 96.390, 3039.0, 55.1271
36.205281921, 96.390, 3421.0, 58.4893
36.257803052, 96.390, 2708.0, 52.0384
36.310324183, 96.390, 2522.0, 50.2195
36.362845313, 96.390, 1995.0, 44.6654
36.415366444, 96.390, 1941.0, 44.0568
36.467887575, 96.390, 1973.0, 44.4185
36.520408706, 96.390, 1810.0, 42.5441
36.572929836, 96.390, 1862.0, 43.1509
36.625450967, 96.390, 1810.0, 42.5441
36.677972098, 96.390, 1661.0, 40.7554
36.730493228, 96.390, 1797.0, 42.3910
36.783014359, 96.390, 1664.0, 40.7922
36.835535490, 96.390, 1610.0, 40.1248
36.888056621, 96.390, 1631.0, 40.3856
36.940577751, 96.390, 1593.0, 39.9124
36.993098882, 96.390, 1601.0, 40.0125
37.045620013, 96.390, 1663.0, 40.7799
37.098141143, 96.390, 1740.0, 41.7133
37.150662274, 96.390, 1854.0, 43.0581
37.203183405, 96.390, 1893.0, 43.5086
37.255704535, 96.390, 1915.0, 43.7607
37.308225666, 96.390, 1760.0, 41.9524
37.360746797, 96.390, 1883.0, 43.3935
37.413267928, 96.390, 1833.0, 42.8135
37.465789058, 96.390, 2068.0, 45.4753
37.518310189, 96.390, 2078.0, 45.5851
37.570831320, 96.390, 2190.0, 46.7974
37.623352450, 96.390, 1990.0, 44.6094
37.675873581, 96.390, 2124.0, 46.0869
37.728394712, 96.390, 2366.0, 48.6415
37.780915843, 96.390, 2388.0, 48.8672
37.833436973, 96.390, 2633.0, 51.3128
37.885958104, 96.390, 2355.0, 48.5283
37.938479235, 96.390, 2169.0, 46.5725
37.991000365, 96.390, 2167.0, 46.5510
38.043521496, 96.390, 2009.0, 44.8219
38.096042627, 96.390, 1956.0, 44.2267
38.148563758, 96.390, 1999.0, 44.7102
38.201084888, 96.390, 2074.0, 45.5412
38.253606019, 96.390, 2021.0, 44.9555
38.306127150, 96.390, 1964.0, 44.3170
38.358648280, 96.390, 1761.0, 41.9643
38.411169411, 96.390, 1742.0, 41.7373
38.463690542, 96.390, 1784.0, 42.2374
38.516211673, 96.390, 1760.0, 41.9524
38.568732803, 96.390, 1800.0, 42.4264
38.621253934, 96.390, 1819.0, 42.6497
38.673775065, 96.390, 1833.0, 42.8135
38.726296195, 96.390, 1912.0, 43.7264
38.778817326, 96.390, 1954.0, 44.2041
38.831338457, 96.390, 1760.0, 41.9524
38.883859587, 96.390, 1731.0, 41.6053
38.936380718, 96.390, 1601.0, 40.0125
38.988901849, 96.390, 1511.0, 38.8716
39.041422980, 96.390, 1573.0, 39.6611
39.093944110, 96.390, 1545.0, 39.3065
39.146465241, 96.390, 1608.0, 40.0999
39.198986372, 96.390, 1817.0, 42.6263
39.251507502, 96.390, 1793.0, 42.3438
39.304028633, 96.390, 1783.0, 42.2256
39.356549764, 96.390, 1840.0, 42.8952
39.409070895, 96.390, 2079.0, 45.5961
39.461592025, 96.390, 2042.0, 45.1885
39.514113156, 96.390, 1965.0, 44.3283
39.566634287, 96.390, 1826.0, 42.7317
39.619155417, 96.390, 1700.0, 41.2311
39.671676548, 96.390, 1662.0, 40.7676
39.724197679, 96.390, 1687.0, 41.0731
39.776718810, 96.390, 1722.0, 41.4970
39.829239940, 96.390, 1837.0, 42.8602
39.881761071, 96.390, 1746.0, 41.7852
39.934282202, 96.390, 1742.0, 41.7373
39.986803332, 96.390, 1747.0, 41.7971
40.039324463, 96.390, 1751.0, 41.8450
40.091845594, 96.390, 1712.0, 41.3763
40.144366725, 96.390, 1713.0, 41.3884
40.196887855, 96.390, 1524.0, 39.0384
40.249408986, 96.390, 1604.0, 40.0500
40.301930117, 96.390, 1396.0, 37.3631
40.354451247, 96.390, 1518.0, 38.9615
40.406972378, 96.390, 1508.0, 38.8330
40.459493509, 96.390, 1520.0, 38.9872
40.512014639, 96.390, 1574.0, 39.6737
40.564535770, 96.390, 1700.0, 41.2311
40.617056901, 96.390, 1811.0, 42.5558
40.669578032, 96.390, 1692.0, 41.1339
40.722099162, 96.390, 1667.0, 40.8289
40.774620293, 96.390, 1490.0, 38.6005
40.827141424, 96.390, 1474.0, 38.3927
40.879662554, 96.390, 1327.0, 36.4280
40.932183685, 96.390, 1413.0, 37.5899
40.984704816, 96.390, 1384.0, 37.2022
41.037225947, 96.390, 1383.0, 37.1887
41.089747077, 96.390, 1346.0, 36.6879
41.142268208, 96.390, 1328.0, 36.4417
41.194789339, 96.390, 1291.0, 35.9305
41.247310469, 96.390, 1416.0, 37.6298
41.299831600, 96.390, 1585.0, 39.8121
41.352352731, 96.390, 1847.0, 42.9767
41.404873862, 96.390, 1891.0, 43.4856
41.457394992, 96.390, 1666.0, 40.8167
41.509916123, 96.390, 1664.0, 40.7922
41.562437254, 96.390, 1507.0, 38.8201
41.614958384, 96.390, 1372.0, 37.0405
41.667479515, 96.390, 1413.0, 37.5899
41.720000646, 96.390, 1408.0, 37.5233
41.772521776, 96.390, 1520.0, 38.9872
41.825042907, 96.390, 1500.0, 38.7298
41.877564038, 96.390, 1435.0, 37.8814
41.930085169, 96.390, 1407.0, 37.5100
41.982606299, 96.390, 1378.0, 37.1214
42.035127430, 96.390, 1613.0, 40.1622
42.087648561, 96.390, 1877.0, 43.3244
42.140169691, 96.390, 2356.0, 48.5386
42.192690822, 96.390, 2049.0, 45.2659
42.245211953, 96.390, 1826.0, 42.7317
42.297733084, 96.390, 1744.0, 41.7612
42.350254214, 96.390, 1507.0, 38.8201
42.402775345, 96.390, 1358.0, 36.8511
42.455296476, 96.390, 1332.0, 36.4966
42.507817606, 96.390, 1328.0, 36.4417
42.560338737, 96.390, 1434.0, 37.8682
42.612859868, 96.390, 1431.0, 37.8286
42.665380999, 96.390, 1426.0, 37.7624
42.717902129, 96.390, 1519.0, 38.9744
42.770423260, 96.390, 1436.0, 37.8946
42.822944391, 96.390, 1388.0, 37.2559
42.875465521, 96.390, 1425.0, 37.7492
42.927986652, 96.390, 1257.0, 35.4542
42.980507783, 96.390, 1297.0, 36.0139
43.033028914, 96.390, 1238.0, 35.1852
43.085550044, 96.390, 1290.0, 35.9166
43.138071175, 96.390, 1392.0, 37.3095
43.190592306, 96.390, 1312.0, 36.2215
43.243113436, 96.390, 1254.0, 35.4119
43.295634567, 96.390, 1259.0, 35.4824
43.348155698, 96.390, 1242.0, 35.2420
43.400676828, 96.390, 1145.0, 33.8378
43.453197959, 96.390, 1226.0, 35.0143
43.505719090, 96.390, 1258.0, 35.4683
43.558240221, 96.390, 1219.0, 34.9142
43.610761351, 96.390, 1282.0, 35.8050
43.663282482, 96.390, 1351.0, 36.7560
43.715803613, 96.390, 1610.0, 40.1248
43.768324743, 96.390, 1749.0, 41.8210
43.820845874, 96.390, 1578.0, 39.7240
43.873367005, 96.390, 1624.0, 40.2989
43.925888136, 96.390, 1439.0, 37.9342
43.978409266, 96.390, 1355.0, 36.8103
44.030930397, 96.390, 1309.0, 36.1801
44.083451528, 96.390, 1268.0, 35.6090
44.135972658, 96.390, 1343.0, 36.6470
44.188493789, 96.390, 1372.0, 37.0405
44.241014920, 96.390, 1429.0, 37.8021
44.293536051, 96.390, 1649.0, 40.6079
44.346057181, 96.390, 1651.0, 40.6325
44.398578312, 96.390, 1745.0, 41.7732
44.451099443, 96.390, 1537.0, 39.2046
44.503620573, 96.390, 1525.0, 39.0512
44.556141704, 96.390, 1493.0, 38.6394
44.608662835, 96.390, 1428.0, 37.7889
44.661183966, 96.390, 1405.0, 37.4833
44.713705096, 96.390, 1431.0, 37.8286
44.766226227, 96.390, 1564.0, 39.5474
44.818747358, 96.390, 1576.0, 39.6989
44.871268488, 96.390, 1615.0, 40.1871
44.923789619, 96.390, 1482.0, 38.4968
44.976310750, 96.390, 1438.0, 37.9210
45.028831880, 96.390, 1493.0, 38.6394
45.081353011, 96.390, 1604.0, 40.0500
45.133874142, 96.390, 1683.0, 41.0244
45.186395273, 96.390, 1719.0, 41.4608
45.238916403, 96.390, 1688.0, 41.0853
45.291437534, 96.390, 1660.0, 40.7431
45.343958665, 96.390, 1686.0, 41.0609
45.396479795, 96.390, 1612.0, 40.1497
45.449000926, 96.390, 1682.0, 41.0122
45.501522057, 96.390, 1553.0, 39.4081
45.554043188, 96.390, 1551.0, 39.3827
45.606564318, 96.390, 1520.0, 38.9872
45.659085449, 96.390, 1457.0, 38.1707
45.711606580, 96.390, 1380.0, 37.1484
45.764127710, 96.390, 1473.0, 38.3797
45.816648841, 96.390, 1474.0, 38.3927
45.869169972, 96.390, 1350.0, 36.7423
45.921691103, 96.390, 1412.0, 37.5766
45.974212233, 96.390, 1373.0, 37.0540
46.026733364, 96.390, 1481.0, 38.4838
46.079254495, 96.390, 1479.0, 38.4578
46.131775625, 96.390, 1760.0, 41.9524
46.184296756, 96.390, 1889.0, 43.4626
46.236817887, 96.390, 2182.0, 46.7119
46.289339017, 96.390, 2173.0, 46.6154
46.341860148, 96.390, 1921.0, 43.8292
46.394381279, 96.390, 1843.0, 42.9302
46.446902410, 96.390, 1719.0, 41.4608
46.499423540, 96.390, 1556.0, 39.4462
46.551944671, 96.390, 1507.0, 38.8201
46.604465802, 96.390, 1570.0, 39.6232
46.656986932, 96.390, 1564.0, 39.5474
46.709508063, 96.390, 1741.0, 41.7253
46.762029194, 96.390, 1667.0, 40.8289
46.814550325, 96.390, 1515.0, 38.9230
46.867071455, 96.390, 1473.0, 38.3797
46.919592586, 96.390, 1490.0, 38.6005
46.972113717, 96.390, 1564.0, 39.5474
47.024634847, 96.390, 1437.0, 37.9078
47.077155978, 96.390, 1470.0, 38.3406
47.129677109, 96.390, 1507.0, 38.8201
47.182198240, 96.390, 1349.0, 36.7287
47.234719370, 96.390, 1345.0, 36.6742
47.287240501, 96.390, 1386.0, 37.2290
47.339761632, 96.390, 1412.0, 37.5766
47.392282762, 96.390, 1422.0, 37.7094
47.444803893, 96.390, 1402.0, 37.4433
47.497325024, 96.390, 1473.0, 38.3797
47.549846155, 96.390, 1435.0, 37.8814
47.602367285, 96.390, 1436.0, 37.8946
47.654888416, 96.390, 1416.0, 37.6298
47.707409547, 96.390, 1498.0, 38.7040
47.759930677, 96.390, 1493.0, 38.6394
47.812451808, 96.390, 1546.0, 39.3192
47.864972939, 96.390, 1416.0, 37.6298
47.917494069, 96.390, 1457.0, 38.1707
47.970015200, 96.390, 1389.0, 37.2693
48.022536331, 96.390, 1411.0, 37.5633
48.075057462, 96.390, 1484.0, 38.5227
48.127578592, 96.390, 1542.0, 39.2683
48.180099723, 96.390, 1496.0, 38.6782
48.232620854, 96.390, 1413.0, 37.5899
48.285141984, 96.390, 1439.0, 37.9342
48.337663115, 96.390, 1455.0, 38.1445
48.390184246, 96.390, 1616.0, 40.1995
48.442705377, 96.390, 1696.0, 41.1825
48.495226507, 96.390, 1789.0, 42.2966
48.547747638, 96.390, 1669.0, 40.8534
48.600268769, 96.390, 1409.0, 37.5366
48.652789899, 96.390, 1420.0, 37.6829
48.705311030, 96.390, 1226.0, 35.0143
48.757832161, 96.390, 1211.0, 34.7994
48.810353292, 96.390, 1214.0, 34.8425
48.862874422, 96.390, 1162.0, 34.0881
48.915395553, 96.390, 1232.0, 35.0999
48.967916684, 96.390, 1233.0, 35.1141
49.020437814, 96.390, 1228.0, 35.0428
49.072958945, 96.390, 1307.0, 36.1525
49.125480076, 96.390, 1281.0, 35.7911
49.178001207, 96.390, 1326.0, 36.4143
49.230522337, 96.390, 1339.0, 36.5923
49.283043468, 96.390, 1255.0, 35.4260
49.335564599, 96.390, 1209.0, 34.7707
49.388085729, 96.390, 1205.0, 34.7131
49.440606860, 96.390, 1177.0, 34.3074
49.493127991, 96.390, 1220.0, 34.9285
49.545649121, 96.390, 1205.0, 34.7131
49.598170252, 96.390, 1256.0, 35.4401
49.650691383, 96.390, 1343.0, 36.6470
49.703212514, 96.390, 1272.0, 35.6651
49.755733644, 96.390, 1354.0, 36.7967
49.808254775, 96.390, 1344.0, 36.6606
49.860775906, 96.390, 1250.0, 35.3553
49.913297036, 96.390, 1203.0, 34.6843
49.965818167, 96.390, 1099.0, 33.1512
50.018339298, 96.390, 1127.0, 33.5708
50.070860429, 96.390, 1117.0, 33.4215
50.123381559, 96.390, 1142.0, 33.7935
50.175902690, 96.390, 1220.0, 34.9285
50.228423821, 96.390, 1347.0, 36.7015
50.280944951, 96.390, 1345.0, 36.6742
50.333466082, 96.390, 1381.0, 37.1618
50.385987213, 96.390, 1375.0, 37.0810
50.438508344, 96.390, 1425.0, 37.7492
50.491029474, 96.390, 1464.0, 38.2623
50.543550605, 96.390, 1377.0, 37.1080
50.596071736, 96.390, 1368.0, 36.9865
50.648592866, 96.390, 1276.0, 35.7211
50.701113997, 96.390, 1285.0, 35.8469
50.753635128, 96.390, 1176.0, 34.2929
50.806156258, 96.390, 1221.0, 34.9428
50.858677389, 96.390, 1111.0, 33.3317
50.911198520, 96.390, 1195.0, 34.5688
50.963719651, 96.390, 1306.0, 36.1386
51.016240781, 96.390, 1322.0, 36.3593
51.068761912, 96.390, 1395.0, 37.3497
51.121283043, 96.390, 1324.0, 36.3868
51.173804173, 96.390, 1255.0, 35.4260
51.226325304, 96.390, 1335.0, 36.5377
51.278846435, 96.390, 1206.0, 34.7275
51.331367566, 96.390, 1165.0, 34.1321
51.383888696, 96.390, 1085.0, 32.9393
51.436409827, 96.390, 1114.0, 33.3766
51.488930958, 96.390, 1064.0, 32.6190
51.541452088, 96.390, 963.0, 31.0322
51.593973219, 96.390, 994.0, 31.5278
51.646494350, 96.390, 1074.0, 32.7719
51.699015481, 96.390, 1052.0, 32.4345
51.751536611, 96.390, 1066.0, 32.6497
51.804057742, 96.390, 1121.0, 33.4813
51.856578873, 96.390, 1157.0, 34.0147
51.909100003, 96.390, 1211.0, 34.7994
51.961621134, 96.390, 1106.0, 33.2566
52.014142265, 96.390, 1156.0, 34.0000
52.066663396, 96.390, 1179.0, 34.3366
52.119184526, 96.390, 1201.0, 34.6554
52.171705657, 96.390, 1275.0, 35.7071
52.224226788, 96.390, 1304.0, 36.1109
52.276747918, 96.390, 1289.0, 35.9026
52.329269049, 96.390, 1222.0, 34.9571
52.381790180, 96.390, 1198.0, 34.6121
52.434311310, 96.390, 1144.0, 33.8231
52.486832441, 96.390, 1091.0, 33.0303
52.539353572, 96.390, 1128.0, 33.5857
52.591874703, 96.390, 1067.0, 32.6650
52.644395833, 96.390, 1097.0, 33.1210
52.696916964, 96.390, 1157.0, 34.0147
52.749438095, 96.390, 1143.0, 33.8083
52.801959225, 96.390, 1141.0, 33.7787
52.854480356, 96.390, 1178.0, 34.3220
52.907001487, 96.390, 1152.0, 33.9411
52.959522618, 96.390, 1178.0, 34.3220
53.012043748, 96.390, 1103.0, 33.2114
53.064564879, 96.390, 1220.0, 34.9285
53.117086010, 96.390, 1215.0, 34.8569
53.169607140, 96.390, 1211.0, 34.7994
53.222128271, 96.390, 1186.0, 34.4384
53.274649402, 96.390, 1210.0, 34.7851
53.327170533, 96.390, 1134.0, 33.6749
53.379691663, 96.390, 1198.0, 34.6121
53.432212794, 96.390, 1122.0, 33.4963
53.484733925, 96.390, 1024.0, 32.0000
53.537255055, 96.390, 1063.0, 32.6037
53.589776186, 96.390, 1028.0, 32.0624
53.642297317, 96.390, 1009.0, 31.7648
53.694818448, 96.390, 934.0, 30.5614
53.747339578, 96.390, 988.0, 31.4325
53.799860709, 96.390, 992.0, 31.4960
53.852381840, 96.390, 1177.0, 34.3074
53.904902970, 96.390, 1355.0, 36.8103
53.957424101, 96.390, 1289.0, 35.9026
54.009945232, 96.390, 1352.0, 36.7696
54.062466362, 96.390, 1321.0, 36.3456
54.114987493, 96.390, 1368.0, 36.9865
54.167508624, 96.390, 1365.0, 36.9459
54.220029755, 96.390, 1305.0, 36.1248
54.272550885, 96.390, 1320.0, 36.3318
54.325072016, 96.390, 1294.0, 35.9722
54.377593147, 96.390, 1244.0, 35.2704
54.430114277, 96.390, 1199.0, 34.6266
54.482635408, 96.390, 1107.0, 33.2716
54.535156539, 96.390, 1072.0, 32.7414
54.587677670, 96.390, 1097.0, 33.1210
54.640198800, 96.390, 1019.0, 31.9218
54.692719931, 96.390, 982.0, 31.3369
54.745241062, 96.390, 962.0, 31.0161
54.797762192, 96.390, 958.0, 30.9516
54.850283323, 96.390, 975.0, 31.2250
54.902804454, 96.390, 957.0, 30.9354
54.955325585, 96.390, 963.0, 31.0322
55.007846715, 96.390, 985.0, 31.3847
55.060367846, 96.390, 914.0, 30.2324
55.112888977, 96.390, 930.0, 30.4959
55.165410107, 96.390, 912.0, 30.1993
55.217931238, 96.390, 918.0, 30.2985
55.270452369, 96.390, 932.0, 30.5287
55.322973499, 96.390, 957.0, 30.9354
55.375494630, 96.390, 1040.0, 32.2490
55.428015761, 96.390, 963.0, 31.0322
55.480536892, 96.390, 997.0, 31.5753
55.533058022, 96.390, 1009.0, 31.7648
55.585579153, 96.390, 1035.0, 32.1714
55.638100284, 96.390, 964.0, 31.0483
55.690621414, 96.390, 926.0, 30.4302
55.743142545, 96.390, 914.0, 30.2324
55.795663676, 96.390, 919.0, 30.3150
55.848184807, 96.390, 964.0, 31.0483
55.900705937, 96.390, 1004.0, 31.6860
55.953227068, 96.390, 995.0, 31.5436
56.005748199, 96.390, 980.0, 31.3050
56.058269329, 96.390, 1119.0, 33.4515
56.110790460, 96.390, 1127.0, 33.5708
56.163311591, 96.390, 1096.0, 33.1059
56.215832722, 96.390, 1117.0, 33.4215
56.268353852, 96.390, 1001.0, 31.6386
56.320874983, 96.390, 1017.0, 31.8904
56.373396114, 96.390, 919.0, 30.3150
56.425917244, 96.390, 957.0, 30.9354
56.478438375, 96.390, 1024.0, 32.0000
56.530959506, 96.390, 985.0, 31.3847
56.583480637, 96.390, 899.0, 29.9833
56.636001767, 96.390, 953.0, 30.8707
56.688522898, 96.390, 923.0, 30.3809
56.741044029, 96.390, 853.0, 29.2062
56.793565159, 96.390, 826.0, 28.7402
56.846086290, 96.390, 875.0, 29.5804
56.898607421, 96.390, 850.0, 29.1548
56.951128551, 96.390, 882.0, 29.6985
57.003649682, 96.390, 936.0, 30.5941
57.056170813, 96.390, 868.0, 29.4618
57.108691944, 96.390, 956.0, 30.9192
57.161213074, 96.390, 1011.0, 31.7962
57.213734205, 96.390, 1034.0, 32.1559
57.266255336, 96.390, 1015.0, 31.8591
57.318776466, 96.390, 955.0, 30.9031
57.371297597, 96.390, 914.0, 30.2324
57.423818728, 96.390, 943.0, 30.7083
57.476339859, 96.390, 958.0, 30.9516
57.528860989, 96.390, 951.0, 30.8383
57.581382120, 96.390, 957.0, 30.9354
57.633903251, 96.390, 1014.0, 31.8434
57.686424381, 96.390, 981.0, 31.3209
57.738945512, 96.390, 1027.0, 32.0468
57.791466643, 96.390, 944.0, 30.7246
57.843987774, 96.390, 941.0, 30.6757
57.896508904, 96.390, 954.0, 30.8869
57.949030035, 96.390, 1022.0, 31.9687
58.001551166, 96.390, 1071.0, 32.7261
58.054072296, 96.390, 1129.0, 33.6006
58.106593427, 96.390, 1086.0, 32.9545
58.159114558, 96.390, 1038.0, 32.2180
58.211635689, 96.390, 972.0, 31.1769
58.264156819, 96.390, 982.0, 31.3369
58.316677950, 96.390, 849.0, 29.1376
58.369199081, 96.390, 849.0, 29.1376
58.421720211, 96.390, 925.0, 30.4138
58.474241342, 96.390, 901.0, 30.0167
58.526762473, 96.390, 886.0, 29.7658
58.579283603, 96.390, 906.0, 30.0998
58.631804734, 96.390, 869.0, 29.4788
58.684325865, 96.390, 870.0, 29.4958
58.736846996, 96.390, 879.0, 29.6479
58.789368126, 96.390, 854.0, 29.2233
58.841889257, 96.390, 872.0, 29.5296
58.894410388, 96.390, 885.0, 29.7489
58.946931518, 96.390, 876.0, 29.5973
58.999452649, 96.390, 867.0, 29.4449
59.051973780, 96.390, 812.0, 28.4956
59.104494911, 96.390, 886.0, 29.7658
59.157016041, 96.390, 874.0, 29.5635
59.209537172, 96.390, 958.0, 30.9516
59.262058303, 96.390, 904.0, 30.0666
59.314579433, 96.390, 905.0, 30.0832
59.367100564, 96.390, 900.0, 30.0000
59.419621695, 96.390, 976.0, 31.2410
59.472142826, 96.390, 973.0, 31.1929
59.524663956, 96.390, 917.0, 30.2820
59.577185087, 96.390, 913.0, 30.2159
59.629706218, 96.390, 923.0, 30.3809
59.682227348, 96.390, 877.0, 29.6142
59.734748479, 96.390, 1017.0, 31.8904
59.787269610, 96.390, 940.0, 30.6594
59.839790740, 96.390, 905.0, 30.0832
59.892311871, 96.390, 913.0, 30.2159
59.944833002, 96.390, 959.0, 30.9677
59.997354133, 96.390, 1056.0, 32.4962
60.049875263, 96.390, 1009.0, 31.7648
60.102396394, 96.390, 1075.0, 32.7872
60.154917525, 96.390, 1045.0, 32.3265
60.207438655, 96.390, 1056.0, 32.4962
60.259959786, 96.390, 1083.0, 32.9090
60.312480917, 96.390, 1015.0, 31.8591
60.365002048, 96.390, 1082.0, 32.8938
60.417523178, 96.390, 1184.0, 34.4093
60.470044309, 96.390, 1141.0, 33.7787
60.522565440, 96.390, 1192.0, 34.5254
60.575086570, 96.390, 1202.0, 34.6699
60.627607701, 96.390, 1294.0, 35.9722
60.680128832, 96.390, 1379.0, 37.1349
60.732649963, 96.390, 1340.0, 36.6060
60.785171093, 96.390, 1401.0, 37.4299
60.837692224, 96.390, 1390.0, 37.2827
60.890213355, 96.390, 1399.0, 37.4032
60.942734485, 96.390, 1384.0, 37.2022
60.995255616, 96.390, 1451.0, 38.0920
61.047776747, 96.390, 1383.0, 37.1887
61.100297878, 96.390, 1375.0, 37.0810
61.152819008, 96.390, 1413.0, 37.5899
61.205340139, 96.390, 1338.0, 36.5787
61.257861270, 96.390, 1360.0, 36.8782
61.310382400, 96.390, 1424.0, 37.7359
61.362903531, 96.390, 1349.0, 36.7287
61.415424662, 96.390, 1365.0, 36.9459
61.467945792, 96.390, 1312.0, 36.2215
61.520466923, 96.390, 1369.0, 37.0000
61.572988054, 96.390, 1377.0, 37.1080
61.625509185, 96.390, 1369.0, 37.0000
61.678030315, 96.390, 1279.0, 35.7631
61.730551446, 96.390, 1283.0, 35.8190
61.783072577, 96.390, 1293.0, 35.9583
61.835593707, 96.390, 1286.0, 35.8608
61.888114838, 96.390, 1204.0, 34.6987
61.940635969, 96.390, 1175.0, 34.2783
61.993157100, 96.390, 1125.0, 33.5410
62.045678230, 96.390, 1223.0, 34.9714
62.098199361, 96.390, 1178.0, 34.3220
62.150720492, 96.390, 1211.0, 34.7994
62.203241622, 96.390, 1209.0, 34.7707
62.255762753, 96.390, 1214.0, 34.8425
62.308283884, 96.390, 1167.0, 34.1614
62.360805015, 96.390, 1173.0, 34.2491
62.413326145, 96.390, 1113.0, 33.3617
62.465847276, 96.390, 1171.0, 34.2199
62.518368407, 96.390, 1072.0, 32.7414
62.570889537, 96.390, 1059.0, 32.5423
62.623410668, 96.390, 1140.0, 33.7639
62.675931799, 96.390, 1085.0, 32.9393
62.728452930, 96.390, 1037.0, 32.2025
62.780974060, 96.390, 984.0, 31.3688
62.833495191, 96.390, 1011.0, 31.7962
62.886016322, 96.390, 949.0, 30.8058
62.938537452, 96.390, 901.0, 30.0167
62.991058583, 96.390, 908.0, 30.1330
63.043579714, 96.390, 841.0, 29.0000
63.096100844, 96.390, 866.0, 29.4279
63.148621975, 96.390, 854.0, 29.2233
63.201143106, 96.390, 846.0, 29.0861
63.253664237, 96.390, 811.0, 28.4781
63.306185367, 96.390, 827.0, 28.7576
63.358706498, 96.390, 871.0, 29.5127
63.411227629, 96.390, 899.0, 29.9833
63.463748759, 96.390, 863.0, 29.3769
63.516269890, 96.390, 804.0, 28.3549
63.568791021, 96.390, 876.0, 29.5973
63.621312152, 96.390, 881.0, 29.6816
63.673833282, 96.390, 863.0, 29.3769
63.726354413, 96.390, 897.0, 29.9500
63.778875544, 96.390, 969.0, 31.1288
63.831396674, 96.390, 896.0, 29.9333
63.883917805, 96.390, 872.0, 29.5296
63.936438936, 96.390, 876.0, 29.5973
63.988960067, 96.390, 928.0, 30.4631
64.041481197, 96.390, 913.0, 30.2159
64.094002328, 96.390, 877.0, 29.6142
64.146523459, 96.390, 847.0, 29.1033
64.199044589, 96.390, 921.0, 30.3480
64.251565720, 96.390, 850.0, 29.1548
64.304086851, 96.390, 857.0, 29.2746
64.356607981, 96.390, 778.0, 27.8927
64.409129112, 96.390, 781.0, 27.9464
64.461650243, 96.390, 814.0, 28.5307
64.514171374, 96.390, 728.0, 26.9815
64.566692504, 96.390, 734.0, 27.0924
64.619213635, 96.390, 751.0, 27.4044
64.671734766, 96.390, 857.0, 29.2746
64.724255896, 96.390, 719.0, 26.8142
64.776777027, 96.390, 763.0, 27.6225
64.829298158, 96.390, 763.0, 27.6225
64.881819289, 96.390, 733.0, 27.0740
64.934340419, 96.390, 732.0, 27.0555
64.986861550, 96.390, 760.0, 27.5681