File: Files_organized_for_plots/Centroid_changing_NaOH_V2/XRDa_Centroid20Oct21_Act14Feb22_B2_1000M_NaOH_LS0171_1.csv
[Measurement conditions]
Sample identification,XRD_Centroid20Oct21_Act14Feb22_B2_1000M_NaOH_LS0171_1
Comment - 1,"Configuration=Stage for Flat Samples/Holders, Owner=User-1, Creation date=7/1/2020 9:53:24 AM"
Comment - 2,"Goniometer=Theta/Theta; Minimum step size 2Theta:0.0001; Minimum step size Omega:0.0001"
Comment - 3,"Sample stage=Stage for flat samples/holders"
Comment - 4,"Diffractometer system=EMPYREAN"
Comment - 5,"Measurement program=C:\Users\ibo5034\OneDrive - The Pennsylvania State University\NEUP\Zerobackground scan.xrdmp, Identifier={98A3B11C-88F9-4AA6-982C-73314A311EF5}"
Anode material,Cu
K-Alpha1 wavelength,1.5405980
K-Alpha2 wavelength,1.5444260
Ratio K-Alpha2/K-Alpha1,0.500
Divergence slit,Fixed,0.25
Monochromator used,NO
Generator voltage, 45
Tube current, 40
File date and time,17/Feb/2022 12:48
Unit cell,
h k l, 0 0 0
Scan axis,Gonio
Scan range,4.994599997,64.999991833
Scan step size,0.0262606
No. of points, 2285
Scan type,CONTINUOUS
Time per step,96.390
[Scan points]
Angle, TimePerStep, Intensity, ESD
5.007730280, 96.390, 3592.0, 59.9333
5.060251411, 96.390, 3604.0, 60.0333
5.112772541, 96.390, 3587.0, 59.8916
5.165293672, 96.390, 3485.0, 59.0339
5.217814803, 96.390, 3412.0, 58.4123
5.270335934, 96.390, 3386.0, 58.1893
5.322857064, 96.390, 3522.0, 59.3464
5.375378195, 96.390, 3479.0, 58.9830
5.427899326, 96.390, 3270.0, 57.1839
5.480420456, 96.390, 3403.0, 58.3352
5.532941587, 96.390, 3292.0, 57.3760
5.585462718, 96.390, 3283.0, 57.2975
5.637983849, 96.390, 3319.0, 57.6108
5.690504979, 96.390, 3260.0, 57.0964
5.743026110, 96.390, 3234.0, 56.8683
5.795547241, 96.390, 3243.0, 56.9473
5.848068371, 96.390, 3195.0, 56.5243
5.900589502, 96.390, 3145.0, 56.0803
5.953110633, 96.390, 3154.0, 56.1605
6.005631763, 96.390, 3056.0, 55.2811
6.058152894, 96.390, 3189.0, 56.4712
6.110674025, 96.390, 3148.0, 56.1070
6.163195156, 96.390, 3033.0, 55.0727
6.215716286, 96.390, 3130.0, 55.9464
6.268237417, 96.390, 3135.0, 55.9911
6.320758548, 96.390, 3109.0, 55.7584
6.373279678, 96.390, 3192.0, 56.4978
6.425800809, 96.390, 3067.0, 55.3805
6.478321940, 96.390, 3015.0, 54.9090
6.530843071, 96.390, 3174.0, 56.3383
6.583364201, 96.390, 3045.0, 55.1815
6.635885332, 96.390, 2949.0, 54.3047
6.688406463, 96.390, 3034.0, 55.0818
6.740927593, 96.390, 3012.0, 54.8817
6.793448724, 96.390, 3009.0, 54.8544
6.845969855, 96.390, 3038.0, 55.1181
6.898490986, 96.390, 3102.0, 55.6956
6.951012116, 96.390, 2913.0, 53.9722
7.003533247, 96.390, 2927.0, 54.1018
7.056054378, 96.390, 2898.0, 53.8331
7.108575508, 96.390, 2939.0, 54.2125
7.161096639, 96.390, 3017.0, 54.9272
7.213617770, 96.390, 2937.0, 54.1941
7.266138900, 96.390, 3011.0, 54.8726
7.318660031, 96.390, 2903.0, 53.8795
7.371181162, 96.390, 2814.0, 53.0471
7.423702293, 96.390, 2862.0, 53.4977
7.476223423, 96.390, 2857.0, 53.4509
7.528744554, 96.390, 2932.0, 54.1479
7.581265685, 96.390, 2845.0, 53.3385
7.633786815, 96.390, 2781.0, 52.7352
7.686307946, 96.390, 2864.0, 53.5164
7.738829077, 96.390, 2783.0, 52.7541
7.791350208, 96.390, 2793.0, 52.8488
7.843871338, 96.390, 2850.0, 53.3854
7.896392469, 96.390, 2809.0, 53.0000
7.948913600, 96.390, 2771.0, 52.6403
8.001434730, 96.390, 2872.0, 53.5910
8.053955861, 96.390, 2795.0, 52.8678
8.106476992, 96.390, 2681.0, 51.7784
8.158998123, 96.390, 2934.0, 54.1664
8.211519253, 96.390, 2829.0, 53.1883
8.264040384, 96.390, 2872.0, 53.5910
8.316561515, 96.390, 2766.0, 52.5928
8.369082645, 96.390, 2828.0, 53.1789
8.421603776, 96.390, 2771.0, 52.6403
8.474124907, 96.390, 2766.0, 52.5928
8.526646038, 96.390, 2809.0, 53.0000
8.579167168, 96.390, 2673.0, 51.7011
8.631688299, 96.390, 2804.0, 52.9528
8.684209430, 96.390, 2813.0, 53.0377
8.736730560, 96.390, 2804.0, 52.9528
8.789251691, 96.390, 2777.0, 52.6972
8.841772822, 96.390, 2821.0, 53.1131
8.894293952, 96.390, 2830.0, 53.1977
8.946815083, 96.390, 2865.0, 53.5257
8.999336214, 96.390, 2841.0, 53.3010
9.051857345, 96.390, 2780.0, 52.7257
9.104378475, 96.390, 2791.0, 52.8299
9.156899606, 96.390, 2760.0, 52.5357
9.209420737, 96.390, 2833.0, 53.2259
9.261941867, 96.390, 2804.0, 52.9528
9.314462998, 96.390, 2794.0, 52.8583
9.366984129, 96.390, 2806.0, 52.9717
9.419505260, 96.390, 2852.0, 53.4041
9.472026390, 96.390, 2857.0, 53.4509
9.524547521, 96.390, 2895.0, 53.8052
9.577068652, 96.390, 2942.0, 54.2402
9.629589782, 96.390, 2932.0, 54.1479
9.682110913, 96.390, 2883.0, 53.6936
9.734632044, 96.390, 3002.0, 54.7905
9.787153175, 96.390, 2944.0, 54.2586
9.839674305, 96.390, 2904.0, 53.8888
9.892195436, 96.390, 2971.0, 54.5069
9.944716567, 96.390, 2992.0, 54.6992
9.997237697, 96.390, 3023.0, 54.9818
10.049758828, 96.390, 3132.0, 55.9643
10.102279959, 96.390, 3165.0, 56.2583
10.154801090, 96.390, 3297.0, 57.4195
10.207322220, 96.390, 3204.0, 56.6039
10.259843351, 96.390, 3206.0, 56.6216
10.312364482, 96.390, 3235.0, 56.8771
10.364885612, 96.390, 3431.0, 58.5747
10.417406743, 96.390, 3511.0, 59.2537
10.469927874, 96.390, 4245.0, 65.1537
10.522449004, 96.390, 4180.0, 64.6529
10.574970135, 96.390, 3349.0, 57.8705
10.627491266, 96.390, 3326.0, 57.6715
10.680012397, 96.390, 3433.0, 58.5918
10.732533527, 96.390, 3417.0, 58.4551
10.785054658, 96.390, 3354.0, 57.9137
10.837575789, 96.390, 3501.0, 59.1692
10.890096919, 96.390, 3542.0, 59.5147
10.942618050, 96.390, 3509.0, 59.2368
10.995139181, 96.390, 3691.0, 60.7536
11.047660312, 96.390, 3863.0, 62.1530
11.100181442, 96.390, 3612.0, 60.0999
11.152702573, 96.390, 3553.0, 59.6070
11.205223704, 96.390, 3555.0, 59.6238
11.257744834, 96.390, 3627.0, 60.2246
11.310265965, 96.390, 3627.0, 60.2246
11.362787096, 96.390, 3556.0, 59.6322
11.415308227, 96.390, 3589.0, 59.9083
11.467829357, 96.390, 3419.0, 58.4722
11.520350488, 96.390, 3446.0, 58.7026
11.572871619, 96.390, 3545.0, 59.5399
11.625392749, 96.390, 3470.0, 58.9067
11.677913880, 96.390, 3538.0, 59.4811
11.730435011, 96.390, 3508.0, 59.2284
11.782956141, 96.390, 3388.0, 58.2065
11.835477272, 96.390, 3385.0, 58.1808
11.887998403, 96.390, 3235.0, 56.8771
11.940519534, 96.390, 3293.0, 57.3847
11.993040664, 96.390, 3229.0, 56.8243
12.045561795, 96.390, 3282.0, 57.2887
12.098082926, 96.390, 3195.0, 56.5243
12.150604056, 96.390, 3136.0, 56.0000
12.203125187, 96.390, 3117.0, 55.8301
12.255646318, 96.390, 3022.0, 54.9727
12.308167449, 96.390, 2953.0, 54.3415
12.360688579, 96.390, 2970.0, 54.4977
12.413209710, 96.390, 2892.0, 53.7773
12.465730841, 96.390, 2860.0, 53.4790
12.518251971, 96.390, 2751.0, 52.4500
12.570773102, 96.390, 2708.0, 52.0384
12.623294233, 96.390, 2797.0, 52.8867
12.675815364, 96.390, 2700.0, 51.9615
12.728336494, 96.390, 2684.0, 51.8073
12.780857625, 96.390, 2687.0, 51.8363
12.833378756, 96.390, 2686.0, 51.8266
12.885899886, 96.390, 2567.0, 50.6656
12.938421017, 96.390, 2617.0, 51.1566
12.990942148, 96.390, 2416.0, 49.1528
13.043463279, 96.390, 2587.0, 50.8626
13.095984409, 96.390, 2504.0, 50.0400
13.148505540, 96.390, 2512.0, 50.1199
13.201026671, 96.390, 2457.0, 49.5681
13.253547801, 96.390, 2381.0, 48.7955
13.306068932, 96.390, 2345.0, 48.4252
13.358590063, 96.390, 2411.0, 49.1019
13.411111193, 96.390, 2477.0, 49.7695
13.463632324, 96.390, 2517.0, 50.1697
13.516153455, 96.390, 2746.0, 52.4023
13.568674586, 96.390, 2611.0, 51.0979
13.621195716, 96.390, 2571.0, 50.7050
13.673716847, 96.390, 2510.0, 50.0999
13.726237978, 96.390, 2657.0, 51.5461
13.778759108, 96.390, 3273.0, 57.2101
13.831280239, 96.390, 4653.0, 68.2129
13.883801370, 96.390, 3511.0, 59.2537
13.936322501, 96.390, 2485.0, 49.8498
13.988843631, 96.390, 2265.0, 47.5920
14.041364762, 96.390, 2297.0, 47.9270
14.093885893, 96.390, 2621.0, 51.1957
14.146407023, 96.390, 2797.0, 52.8867
14.198928154, 96.390, 3361.0, 57.9741
14.251449285, 96.390, 4408.0, 66.3928
14.303970416, 96.390, 6876.0, 82.9216
14.356491546, 96.390, 5727.0, 75.6769
14.409012677, 96.390, 2210.0, 47.0106
14.461533808, 96.390, 1964.0, 44.3170
14.514054938, 96.390, 1982.0, 44.5197
14.566576069, 96.390, 2053.0, 45.3100
14.619097200, 96.390, 1983.0, 44.5309
14.671618331, 96.390, 1981.0, 44.5084
14.724139461, 96.390, 1891.0, 43.4856
14.776660592, 96.390, 1935.0, 43.9886
14.829181723, 96.390, 1803.0, 42.4617
14.881702853, 96.390, 1906.0, 43.6578
14.934223984, 96.390, 1943.0, 44.0795
14.986745115, 96.390, 1911.0, 43.7150
15.039266245, 96.390, 1952.0, 44.1814
15.091787376, 96.390, 1927.0, 43.8976
15.144308507, 96.390, 1974.0, 44.4297
15.196829638, 96.390, 2062.0, 45.4093
15.249350768, 96.390, 2265.0, 47.5920
15.301871899, 96.390, 2497.0, 49.9700
15.354393030, 96.390, 2287.0, 47.8226
15.406914160, 96.390, 1945.0, 44.1022
15.459435291, 96.390, 1922.0, 43.8406
15.511956422, 96.390, 1838.0, 42.8719
15.564477553, 96.390, 1804.0, 42.4735
15.616998683, 96.390, 1731.0, 41.6053
15.669519814, 96.390, 1795.0, 42.3674
15.722040945, 96.390, 1784.0, 42.2374
15.774562075, 96.390, 1766.0, 42.0238
15.827083206, 96.390, 1710.0, 41.3521
15.879604337, 96.390, 1676.0, 40.9390
15.932125468, 96.390, 1810.0, 42.5441
15.984646598, 96.390, 1833.0, 42.8135
16.037167729, 96.390, 1809.0, 42.5323
16.089688860, 96.390, 1875.0, 43.3013
16.142209990, 96.390, 1752.0, 41.8569
16.194731121, 96.390, 1789.0, 42.2966
16.247252252, 96.390, 1675.0, 40.9268
16.299773382, 96.390, 1654.0, 40.6694
16.352294513, 96.390, 1792.0, 42.3320
16.404815644, 96.390, 1686.0, 41.0609
16.457336775, 96.390, 1750.0, 41.8330
16.509857905, 96.390, 1753.0, 41.8688
16.562379036, 96.390, 1757.0, 41.9166
16.614900167, 96.390, 1729.0, 41.5812
16.667421297, 96.390, 1737.0, 41.6773
16.719942428, 96.390, 1796.0, 42.3792
16.772463559, 96.390, 1705.0, 41.2916
16.824984690, 96.390, 1803.0, 42.4617
16.877505820, 96.390, 1850.0, 43.0116
16.930026951, 96.390, 2075.0, 45.5522
16.982548082, 96.390, 2354.0, 48.5180
17.035069212, 96.390, 1967.0, 44.3509
17.087590343, 96.390, 1717.0, 41.4367
17.140111474, 96.390, 1758.0, 41.9285
17.192632605, 96.390, 1708.0, 41.3280
17.245153735, 96.390, 1677.0, 40.9512
17.297674866, 96.390, 1807.0, 42.5088
17.350195997, 96.390, 2103.0, 45.8585
17.402717127, 96.390, 2394.0, 48.9285
17.455238258, 96.390, 2388.0, 48.8672
17.507759389, 96.390, 1900.0, 43.5890
17.560280520, 96.390, 1811.0, 42.5558
17.612801650, 96.390, 1777.0, 42.1545
17.665322781, 96.390, 1740.0, 41.7133
17.717843912, 96.390, 1677.0, 40.9512
17.770365042, 96.390, 1673.0, 40.9023
17.822886173, 96.390, 1696.0, 41.1825
17.875407304, 96.390, 1667.0, 40.8289
17.927928434, 96.390, 1761.0, 41.9643
17.980449565, 96.390, 1781.0, 42.2019
18.032970696, 96.390, 1817.0, 42.6263
18.085491827, 96.390, 1918.0, 43.7950
18.138012957, 96.390, 2194.0, 46.8402
18.190534088, 96.390, 2125.0, 46.0977
18.243055219, 96.390, 2617.0, 51.1566
18.295576349, 96.390, 2992.0, 54.6992
18.348097480, 96.390, 3581.0, 59.8415
18.400618611, 96.390, 2917.0, 54.0093
18.453139742, 96.390, 2945.0, 54.2679
18.505660872, 96.390, 2774.0, 52.6688
18.558182003, 96.390, 2027.0, 45.0222
18.610703134, 96.390, 1789.0, 42.2966
18.663224264, 96.390, 1767.0, 42.0357
18.715745395, 96.390, 1808.0, 42.5206
18.768266526, 96.390, 1813.0, 42.5793
18.820787657, 96.390, 1837.0, 42.8602
18.873308787, 96.390, 1826.0, 42.7317
18.925829918, 96.390, 2007.0, 44.7996
18.978351049, 96.390, 2096.0, 45.7821
19.030872179, 96.390, 2321.0, 48.1768
19.083393310, 96.390, 2011.0, 44.8442
19.135914441, 96.390, 1716.0, 41.4246
19.188435572, 96.390, 1779.0, 42.1782
19.240956702, 96.390, 1874.0, 43.2897
19.293477833, 96.390, 1864.0, 43.1741
19.345998964, 96.390, 2012.0, 44.8553
19.398520094, 96.390, 2259.0, 47.5289
19.451041225, 96.390, 2713.0, 52.0865
19.503562356, 96.390, 3193.0, 56.5066
19.556083486, 96.390, 2906.0, 53.9073
19.608604617, 96.390, 2238.0, 47.3075
19.661125748, 96.390, 2149.0, 46.3573
19.713646879, 96.390, 2884.0, 53.7029
19.766168009, 96.390, 3604.0, 60.0333
19.818689140, 96.390, 5652.0, 75.1798
19.871210271, 96.390, 3859.0, 62.1208
19.923731401, 96.390, 2626.0, 51.2445
19.976252532, 96.390, 2974.0, 54.5344
20.028773663, 96.390, 3071.0, 55.4166
20.081294794, 96.390, 2424.0, 49.2341
20.133815924, 96.390, 2095.0, 45.7712
20.186337055, 96.390, 2022.0, 44.9667
20.238858186, 96.390, 2051.0, 45.2880
20.291379316, 96.390, 2306.0, 48.0208
20.343900447, 96.390, 2666.0, 51.6333
20.396421578, 96.390, 3568.0, 59.7327
20.448942709, 96.390, 5560.0, 74.5654
20.501463839, 96.390, 4325.0, 65.7647
20.553984970, 96.390, 3267.0, 57.1577
20.606506101, 96.390, 4237.0, 65.0922
20.659027231, 96.390, 5504.0, 74.1889
20.711548362, 96.390, 5938.0, 77.0584
20.764069493, 96.390, 5395.0, 73.4507
20.816590623, 96.390, 3603.0, 60.0250
20.869111754, 96.390, 2447.0, 49.4672
20.921632885, 96.390, 2321.0, 48.1768
20.974154016, 96.390, 2228.0, 47.2017
21.026675146, 96.390, 2573.0, 50.7247
21.079196277, 96.390, 2225.0, 47.1699
21.131717408, 96.390, 2015.0, 44.8888
21.184238538, 96.390, 1958.0, 44.2493
21.236759669, 96.390, 1914.0, 43.7493
21.289280800, 96.390, 1944.0, 44.0908
21.341801931, 96.390, 1941.0, 44.0568
21.394323061, 96.390, 1920.0, 43.8178
21.446844192, 96.390, 1946.0, 44.1135
21.499365323, 96.390, 1952.0, 44.1814
21.551886453, 96.390, 1997.0, 44.6878
21.604407584, 96.390, 1962.0, 44.2945
21.656928715, 96.390, 2271.0, 47.6550
21.709449846, 96.390, 2455.0, 49.5480
21.761970976, 96.390, 2924.0, 54.0740
21.814492107, 96.390, 2468.0, 49.6790
21.867013238, 96.390, 2048.0, 45.2548
21.919534368, 96.390, 2036.0, 45.1221
21.972055499, 96.390, 2051.0, 45.2880
22.024576630, 96.390, 2048.0, 45.2548
22.077097761, 96.390, 2168.0, 46.5618
22.129618891, 96.390, 2048.0, 45.2548
22.182140022, 96.390, 2069.0, 45.4863
22.234661153, 96.390, 2156.0, 46.4327
22.287182283, 96.390, 2096.0, 45.7821
22.339703414, 96.390, 2204.0, 46.9468
22.392224545, 96.390, 2203.0, 46.9361
22.444745675, 96.390, 2207.0, 46.9787
22.497266806, 96.390, 2424.0, 49.2341
22.549787937, 96.390, 2568.0, 50.6754
22.602309068, 96.390, 2600.0, 50.9902
22.654830198, 96.390, 2452.0, 49.5177
22.707351329, 96.390, 2343.0, 48.4045
22.759872460, 96.390, 2316.0, 48.1248
22.812393590, 96.390, 2345.0, 48.4252
22.864914721, 96.390, 2719.0, 52.1440
22.917435852, 96.390, 2567.0, 50.6656
22.969956983, 96.390, 2434.0, 49.3356
23.022478113, 96.390, 2378.0, 48.7647
23.074999244, 96.390, 2430.0, 49.2950
23.127520375, 96.390, 2568.0, 50.6754
23.180041505, 96.390, 2605.0, 51.0392
23.232562636, 96.390, 2530.0, 50.2991
23.285083767, 96.390, 2479.0, 49.7896
23.337604898, 96.390, 2453.0, 49.5278
23.390126028, 96.390, 2451.0, 49.5076
23.442647159, 96.390, 2725.0, 52.2015
23.495168290, 96.390, 3344.0, 57.8273
23.547689420, 96.390, 4371.0, 66.1135
23.600210551, 96.390, 3521.0, 59.3380
23.652731682, 96.390, 2618.0, 51.1664
23.705252813, 96.390, 2324.0, 48.2079
23.757773943, 96.390, 2263.0, 47.5710
23.810295074, 96.390, 2336.0, 48.3322
23.862816205, 96.390, 2250.0, 47.4342
23.915337335, 96.390, 2283.0, 47.7807
23.967858466, 96.390, 2239.0, 47.3181
24.020379597, 96.390, 2270.0, 47.6445
24.072900727, 96.390, 2334.0, 48.3115
24.125421858, 96.390, 2700.0, 51.9615
24.177942989, 96.390, 2851.0, 53.3948
24.230464120, 96.390, 3686.0, 60.7124
24.282985250, 96.390, 4277.0, 65.3988
24.335506381, 96.390, 3428.0, 58.5491
24.388027512, 96.390, 2851.0, 53.3948
24.440548642, 96.390, 2506.0, 50.0600
24.493069773, 96.390, 2247.0, 47.4025
24.545590904, 96.390, 2857.0, 53.4509
24.598112035, 96.390, 3370.0, 58.0517
24.650633165, 96.390, 2640.0, 51.3809
24.703154296, 96.390, 1955.0, 44.2154
24.755675427, 96.390, 1904.0, 43.6348
24.808196557, 96.390, 1859.0, 43.1161
24.860717688, 96.390, 1843.0, 42.9302
24.913238819, 96.390, 1729.0, 41.5812
24.965759950, 96.390, 1901.0, 43.6005
25.018281080, 96.390, 2022.0, 44.9667
25.070802211, 96.390, 2163.0, 46.5081
25.123323342, 96.390, 1950.0, 44.1588
25.175844472, 96.390, 1754.0, 41.8808
25.228365603, 96.390, 1830.0, 42.7785
25.280886734, 96.390, 1873.0, 43.2782
25.333407864, 96.390, 2096.0, 45.7821
25.385928995, 96.390, 2920.0, 54.0370
25.438450126, 96.390, 4082.0, 63.8905
25.490971257, 96.390, 3442.0, 58.6686
25.543492387, 96.390, 2516.0, 50.1597
25.596013518, 96.390, 1906.0, 43.6578
25.648534649, 96.390, 1771.0, 42.0833
25.701055779, 96.390, 1777.0, 42.1545
25.753576910, 96.390, 1711.0, 41.3642
25.806098041, 96.390, 1940.0, 44.0454
25.858619172, 96.390, 2326.0, 48.2286
25.911140302, 96.390, 2373.0, 48.7134
25.963661433, 96.390, 1980.0, 44.4972
26.016182564, 96.390, 1757.0, 41.9166
26.068703694, 96.390, 1755.0, 41.8927
26.121224825, 96.390, 1747.0, 41.7971
26.173745956, 96.390, 1703.0, 41.2674
26.226267087, 96.390, 1653.0, 40.6571
26.278788217, 96.390, 1675.0, 40.9268
26.331309348, 96.390, 1867.0, 43.2088
26.383830479, 96.390, 1772.0, 42.0951
26.436351609, 96.390, 1680.0, 40.9878
26.488872740, 96.390, 1709.0, 41.3401
26.541393871, 96.390, 1679.0, 40.9756
26.593915002, 96.390, 1626.0, 40.3237
26.646436132, 96.390, 1799.0, 42.4146
26.698957263, 96.390, 1794.0, 42.3556
26.751478394, 96.390, 1772.0, 42.0951
26.803999524, 96.390, 1731.0, 41.6053
26.856520655, 96.390, 1639.0, 40.4846
26.909041786, 96.390, 1770.0, 42.0714
26.961562916, 96.390, 1919.0, 43.8064
27.014084047, 96.390, 1957.0, 44.2380
27.066605178, 96.390, 2017.0, 44.9110
27.119126309, 96.390, 2070.0, 45.4973
27.171647439, 96.390, 2434.0, 49.3356
27.224168570, 96.390, 2662.0, 51.5946
27.276689701, 96.390, 2557.0, 50.5668
27.329210831, 96.390, 2608.0, 51.0686
27.381731962, 96.390, 2835.0, 53.2447
27.434253093, 96.390, 2317.0, 48.1352
27.486774224, 96.390, 1784.0, 42.2374
27.539295354, 96.390, 1722.0, 41.4970
27.591816485, 96.390, 1811.0, 42.5558
27.644337616, 96.390, 2177.0, 46.6583
27.696858746, 96.390, 2820.0, 53.1037
27.749379877, 96.390, 2894.0, 53.7959
27.801901008, 96.390, 2426.0, 49.2544
27.854422139, 96.390, 2222.0, 47.1381
27.906943269, 96.390, 1999.0, 44.7102
27.959464400, 96.390, 1813.0, 42.5793
28.011985531, 96.390, 1873.0, 43.2782
28.064506661, 96.390, 1785.0, 42.2493
28.117027792, 96.390, 1755.0, 41.8927
28.169548923, 96.390, 1895.0, 43.5316
28.222070054, 96.390, 2033.0, 45.0888
28.274591184, 96.390, 2292.0, 47.8748
28.327112315, 96.390, 2096.0, 45.7821
28.379633446, 96.390, 1897.0, 43.5546
28.432154576, 96.390, 1719.0, 41.4608
28.484675707, 96.390, 1835.0, 42.8369
28.537196838, 96.390, 1995.0, 44.6654
28.589717968, 96.390, 1966.0, 44.3396
28.642239099, 96.390, 1835.0, 42.8369
28.694760230, 96.390, 1718.0, 41.4488
28.747281361, 96.390, 1844.0, 42.9418
28.799802491, 96.390, 1982.0, 44.5197
28.852323622, 96.390, 1847.0, 42.9767
28.904844753, 96.390, 1861.0, 43.1393
28.957365883, 96.390, 1856.0, 43.0813
29.009887014, 96.390, 1996.0, 44.6766
29.062408145, 96.390, 1963.0, 44.3058
29.114929276, 96.390, 2209.0, 47.0000
29.167450406, 96.390, 2212.0, 47.0319
29.219971537, 96.390, 2062.0, 45.4093
29.272492668, 96.390, 1888.0, 43.4511
29.325013798, 96.390, 1761.0, 41.9643
29.377534929, 96.390, 1742.0, 41.7373
29.430056060, 96.390, 1849.0, 43.0000
29.482577191, 96.390, 1855.0, 43.0697
29.535098321, 96.390, 1699.0, 41.2189
29.587619452, 96.390, 1739.0, 41.7013
29.640140583, 96.390, 1910.0, 43.7035
29.692661713, 96.390, 1936.0, 44.0000
29.745182844, 96.390, 1801.0, 42.4382
29.797703975, 96.390, 1767.0, 42.0357
29.850225105, 96.390, 1888.0, 43.4511
29.902746236, 96.390, 1786.0, 42.2611
29.955267367, 96.390, 1852.0, 43.0349
30.007788498, 96.390, 1719.0, 41.4608
30.060309628, 96.390, 1737.0, 41.6773
30.112830759, 96.390, 1725.0, 41.5331
30.165351890, 96.390, 1706.0, 41.3038
30.217873020, 96.390, 1712.0, 41.3763
30.270394151, 96.390, 1786.0, 42.2611
30.322915282, 96.390, 1760.0, 41.9524
30.375436413, 96.390, 1748.0, 41.8091
30.427957543, 96.390, 1988.0, 44.5870
30.480478674, 96.390, 2594.0, 50.9313
30.532999805, 96.390, 2684.0, 51.8073
30.585520935, 96.390, 2569.0, 50.6853
30.638042066, 96.390, 2755.0, 52.4881
30.690563197, 96.390, 3545.0, 59.5399
30.743084328, 96.390, 4809.0, 69.3470
30.795605458, 96.390, 3565.0, 59.7076
30.848126589, 96.390, 3142.0, 56.0535
30.900647720, 96.390, 2448.0, 49.4773
30.953168850, 96.390, 2213.0, 47.0425
31.005689981, 96.390, 2081.0, 45.6180
31.058211112, 96.390, 2410.0, 49.0918
31.110732243, 96.390, 2194.0, 46.8402
31.163253373, 96.390, 2370.0, 48.6826
31.215774504, 96.390, 2570.0, 50.6952
31.268295635, 96.390, 2547.0, 50.4678
31.320816765, 96.390, 2398.0, 48.9694
31.373337896, 96.390, 2459.0, 49.5883
31.425859027, 96.390, 2387.0, 48.8569
31.478380157, 96.390, 2505.0, 50.0500
31.530901288, 96.390, 2513.0, 50.1298
31.583422419, 96.390, 2463.0, 49.6286
31.635943550, 96.390, 2673.0, 51.7011
31.688464680, 96.390, 3627.0, 60.2246
31.740985811, 96.390, 7098.0, 84.2496
31.793506942, 96.390, 5263.0, 72.5465
31.846028072, 96.390, 4102.0, 64.0469
31.898549203, 96.390, 2559.0, 50.5866
31.951070334, 96.390, 2813.0, 53.0377
32.003591465, 96.390, 3591.0, 59.9250
32.056112595, 96.390, 4397.0, 66.3099
32.108633726, 96.390, 4855.0, 69.6778
32.161154857, 96.390, 3756.0, 61.2862
32.213675987, 96.390, 2960.0, 54.4059
32.266197118, 96.390, 2173.0, 46.6154
32.318718249, 96.390, 1930.0, 43.9318
32.371239380, 96.390, 1982.0, 44.5197
32.423760510, 96.390, 2277.0, 47.7179
32.476281641, 96.390, 1925.0, 43.8748
32.528802772, 96.390, 1912.0, 43.7264
32.581323902, 96.390, 1607.0, 40.0874
32.633845033, 96.390, 1903.0, 43.6234
32.686366164, 96.390, 2404.0, 49.0306
32.738887295, 96.390, 2446.0, 49.4571
32.791408425, 96.390, 2147.0, 46.3357
32.843929556, 96.390, 1857.0, 43.0929
32.896450687, 96.390, 1969.0, 44.3734
32.948971817, 96.390, 2612.0, 51.1077
33.001492948, 96.390, 3516.0, 59.2959
33.054014079, 96.390, 3250.0, 57.0088
33.106535209, 96.390, 3608.0, 60.0666
33.159056340, 96.390, 3302.0, 57.4630
33.211577471, 96.390, 3191.0, 56.4889
33.264098602, 96.390, 2836.0, 53.2541
33.316619732, 96.390, 2678.0, 51.7494
33.369140863, 96.390, 2676.0, 51.7301
33.421661994, 96.390, 3415.0, 58.4380
33.474183124, 96.390, 5209.0, 72.1734
33.526704255, 96.390, 4627.0, 68.0221
33.579225386, 96.390, 3555.0, 59.6238
33.631746517, 96.390, 2105.0, 45.8803
33.684267647, 96.390, 1710.0, 41.3521
33.736788778, 96.390, 1666.0, 40.8167
33.789309909, 96.390, 1763.0, 41.9881
33.841831039, 96.390, 1964.0, 44.3170
33.894352170, 96.390, 2627.0, 51.2543
33.946873301, 96.390, 3201.0, 56.5774
33.999394432, 96.390, 3760.0, 61.3188
34.051915562, 96.390, 2803.0, 52.9434
34.104436693, 96.390, 2603.0, 51.0196
34.156957824, 96.390, 2134.0, 46.1952
34.209478954, 96.390, 2064.0, 45.4313
34.262000085, 96.390, 2333.0, 48.3011
34.314521216, 96.390, 2845.0, 53.3385
34.367042346, 96.390, 3100.0, 55.6776
34.419563477, 96.390, 2752.0, 52.4595
34.472084608, 96.390, 2755.0, 52.4881
34.524605739, 96.390, 2587.0, 50.8626
34.577126869, 96.390, 2580.0, 50.7937
34.629648000, 96.390, 2862.0, 53.4977
34.682169131, 96.390, 3365.0, 58.0086
34.734690261, 96.390, 3277.0, 57.2451
34.787211392, 96.390, 3206.0, 56.6216
34.839732523, 96.390, 2878.0, 53.6470
34.892253654, 96.390, 2865.0, 53.5257
34.944774784, 96.390, 3458.0, 58.8048
34.997295915, 96.390, 4120.0, 64.1872
35.049817046, 96.390, 5087.0, 71.3232
35.102338176, 96.390, 3364.0, 58.0000
35.154859307, 96.390, 3175.0, 56.3471
35.207380438, 96.390, 2898.0, 53.8331
35.259901569, 96.390, 3112.0, 55.7853
35.312422699, 96.390, 2720.0, 52.1536
35.364943830, 96.390, 2369.0, 48.6724
35.417464961, 96.390, 1970.0, 44.3847
35.469986091, 96.390, 1769.0, 42.0595
35.522507222, 96.390, 1892.0, 43.4971
35.575028353, 96.390, 1984.0, 44.5421
35.627549484, 96.390, 1970.0, 44.3847
35.680070614, 96.390, 2089.0, 45.7056
35.732591745, 96.390, 2077.0, 45.5741
35.785112876, 96.390, 1983.0, 44.5309
35.837634006, 96.390, 1972.0, 44.4072
35.890155137, 96.390, 1881.0, 43.3705
35.942676268, 96.390, 2040.0, 45.1664
35.995197398, 96.390, 2287.0, 47.8226
36.047718529, 96.390, 2018.0, 44.9222
36.100239660, 96.390, 1802.0, 42.4500
36.152760791, 96.390, 1550.0, 39.3700
36.205281921, 96.390, 1437.0, 37.9078
36.257803052, 96.390, 1524.0, 39.0384
36.310324183, 96.390, 1612.0, 40.1497
36.362845313, 96.390, 2301.0, 47.9687
36.415366444, 96.390, 2983.0, 54.6168
36.467887575, 96.390, 2447.0, 49.4672
36.520408706, 96.390, 2061.0, 45.3982
36.572929836, 96.390, 1509.0, 38.8458
36.625450967, 96.390, 1479.0, 38.4578
36.677972098, 96.390, 1649.0, 40.6079
36.730493228, 96.390, 1646.0, 40.5709
36.783014359, 96.390, 1474.0, 38.3927
36.835535490, 96.390, 1377.0, 37.1080
36.888056621, 96.390, 1259.0, 35.4824
36.940577751, 96.390, 1314.0, 36.2491
36.993098882, 96.390, 1201.0, 34.6554
37.045620013, 96.390, 1282.0, 35.8050
37.098141143, 96.390, 1378.0, 37.1214
37.150662274, 96.390, 1388.0, 37.2559
37.203183405, 96.390, 1368.0, 36.9865
37.255704535, 96.390, 1304.0, 36.1109
37.308225666, 96.390, 1208.0, 34.7563
37.360746797, 96.390, 1282.0, 35.8050
37.413267928, 96.390, 1343.0, 36.6470
37.465789058, 96.390, 1451.0, 38.0920
37.518310189, 96.390, 1382.0, 37.1753
37.570831320, 96.390, 1330.0, 36.4692
37.623352450, 96.390, 1360.0, 36.8782
37.675873581, 96.390, 1607.0, 40.0874
37.728394712, 96.390, 1660.0, 40.7431
37.780915843, 96.390, 1931.0, 43.9431
37.833436973, 96.390, 2175.0, 46.6369
37.885958104, 96.390, 2263.0, 47.5710
37.938479235, 96.390, 1840.0, 42.8952
37.991000365, 96.390, 1643.0, 40.5339
38.043521496, 96.390, 1461.0, 38.2230
38.096042627, 96.390, 1433.0, 37.8550
38.148563758, 96.390, 1707.0, 41.3159
38.201084888, 96.390, 1892.0, 43.4971
38.253606019, 96.390, 1877.0, 43.3244
38.306127150, 96.390, 2244.0, 47.3709
38.358648280, 96.390, 2547.0, 50.4678
38.411169411, 96.390, 1763.0, 41.9881
38.463690542, 96.390, 1964.0, 44.3170
38.516211673, 96.390, 1636.0, 40.4475
38.568732803, 96.390, 1524.0, 39.0384
38.621253934, 96.390, 1611.0, 40.1373
38.673775065, 96.390, 1682.0, 41.0122
38.726296195, 96.390, 1787.0, 42.2729
38.778817326, 96.390, 1692.0, 41.1339
38.831338457, 96.390, 1764.0, 42.0000
38.883859587, 96.390, 1555.0, 39.4335
38.936380718, 96.390, 1614.0, 40.1746
38.988901849, 96.390, 1510.0, 38.8587
39.041422980, 96.390, 1532.0, 39.1408
39.093944110, 96.390, 1520.0, 38.9872
39.146465241, 96.390, 1602.0, 40.0250
39.198986372, 96.390, 1880.0, 43.3590
39.251507502, 96.390, 2264.0, 47.5815
39.304028633, 96.390, 2075.0, 45.5522
39.356549764, 96.390, 2017.0, 44.9110
39.409070895, 96.390, 1834.0, 42.8252
39.461592025, 96.390, 1817.0, 42.6263
39.514113156, 96.390, 1743.0, 41.7493
39.566634287, 96.390, 1762.0, 41.9762
39.619155417, 96.390, 1695.0, 41.1704
39.671676548, 96.390, 1651.0, 40.6325
39.724197679, 96.390, 1720.0, 41.4729
39.776718810, 96.390, 1798.0, 42.4028
39.829239940, 96.390, 2603.0, 51.0196
39.881761071, 96.390, 1991.0, 44.6206
39.934282202, 96.390, 2053.0, 45.3100
39.986803332, 96.390, 1645.0, 40.5586
40.039324463, 96.390, 1553.0, 39.4081
40.091845594, 96.390, 1572.0, 39.6485
40.144366725, 96.390, 1743.0, 41.7493
40.196887855, 96.390, 2065.0, 45.4423
40.249408986, 96.390, 1797.0, 42.3910
40.301930117, 96.390, 1659.0, 40.7308
40.354451247, 96.390, 1574.0, 39.6737
40.406972378, 96.390, 1253.0, 35.3977
40.459493509, 96.390, 1307.0, 36.1525
40.512014639, 96.390, 1363.0, 36.9188
40.564535770, 96.390, 1358.0, 36.8511
40.617056901, 96.390, 1538.0, 39.2173
40.669578032, 96.390, 1442.0, 37.9737
40.722099162, 96.390, 1392.0, 37.3095
40.774620293, 96.390, 1382.0, 37.1753
40.827141424, 96.390, 1206.0, 34.7275
40.879662554, 96.390, 1183.0, 34.3948
40.932183685, 96.390, 1146.0, 33.8526
40.984704816, 96.390, 1224.0, 34.9857
41.037225947, 96.390, 1277.0, 35.7351
41.089747077, 96.390, 1276.0, 35.7211
41.142268208, 96.390, 1315.0, 36.2629
41.194789339, 96.390, 1296.0, 36.0000
41.247310469, 96.390, 1297.0, 36.0139
41.299831600, 96.390, 1395.0, 37.3497
41.352352731, 96.390, 1683.0, 41.0244
41.404873862, 96.390, 1901.0, 43.6005
41.457394992, 96.390, 1690.0, 41.1096
41.509916123, 96.390, 1728.0, 41.5692
41.562437254, 96.390, 1494.0, 38.6523
41.614958384, 96.390, 1216.0, 34.8712
41.667479515, 96.390, 1187.0, 34.4529
41.720000646, 96.390, 1177.0, 34.3074
41.772521776, 96.390, 1124.0, 33.5261
41.825042907, 96.390, 1117.0, 33.4215
41.877564038, 96.390, 1039.0, 32.2335
41.930085169, 96.390, 1098.0, 33.1361
41.982606299, 96.390, 1061.0, 32.5730
42.035127430, 96.390, 1085.0, 32.9393
42.087648561, 96.390, 1258.0, 35.4683
42.140169691, 96.390, 1971.0, 44.3959
42.192690822, 96.390, 2378.0, 48.7647
42.245211953, 96.390, 1891.0, 43.4856
42.297733084, 96.390, 2135.0, 46.2061
42.350254214, 96.390, 1598.0, 39.9750
42.402775345, 96.390, 1220.0, 34.9285
42.455296476, 96.390, 1297.0, 36.0139
42.507817606, 96.390, 1130.0, 33.6155
42.560338737, 96.390, 1376.0, 37.0945
42.612859868, 96.390, 1507.0, 38.8201
42.665380999, 96.390, 1506.0, 38.8072
42.717902129, 96.390, 1495.0, 38.6652
42.770423260, 96.390, 1735.0, 41.6533
42.822944391, 96.390, 1345.0, 36.6742
42.875465521, 96.390, 1328.0, 36.4417
42.927986652, 96.390, 1145.0, 33.8378
42.980507783, 96.390, 1063.0, 32.6037
43.033028914, 96.390, 1101.0, 33.1813
43.085550044, 96.390, 1100.0, 33.1662
43.138071175, 96.390, 1027.0, 32.0468
43.190592306, 96.390, 976.0, 31.2410
43.243113436, 96.390, 1034.0, 32.1559
43.295634567, 96.390, 1045.0, 32.3265
43.348155698, 96.390, 1050.0, 32.4037
43.400676828, 96.390, 995.0, 31.5436
43.453197959, 96.390, 1032.0, 32.1248
43.505719090, 96.390, 904.0, 30.0666
43.558240221, 96.390, 1089.0, 33.0000
43.610761351, 96.390, 1208.0, 34.7563
43.663282482, 96.390, 1118.0, 33.4365
43.715803613, 96.390, 1279.0, 35.7631
43.768324743, 96.390, 1484.0, 38.5227
43.820845874, 96.390, 1487.0, 38.5616
43.873367005, 96.390, 1298.0, 36.0278
43.925888136, 96.390, 1343.0, 36.6470
43.978409266, 96.390, 1126.0, 33.5559
44.030930397, 96.390, 1094.0, 33.0757
44.083451528, 96.390, 1010.0, 31.7805
44.135972658, 96.390, 980.0, 31.3050
44.188493789, 96.390, 1123.0, 33.5112
44.241014920, 96.390, 1449.0, 38.0657
44.293536051, 96.390, 1897.0, 43.5546
44.346057181, 96.390, 1441.0, 37.9605
44.398578312, 96.390, 1695.0, 41.1704
44.451099443, 96.390, 1386.0, 37.2290
44.503620573, 96.390, 1243.0, 35.2562
44.556141704, 96.390, 1151.0, 33.9264
44.608662835, 96.390, 1085.0, 32.9393
44.661183966, 96.390, 1169.0, 34.1906
44.713705096, 96.390, 1252.0, 35.3836
44.766226227, 96.390, 1468.0, 38.3145
44.818747358, 96.390, 1611.0, 40.1373
44.871268488, 96.390, 1522.0, 39.0128
44.923789619, 96.390, 1511.0, 38.8716
44.976310750, 96.390, 1304.0, 36.1109
45.028831880, 96.390, 1276.0, 35.7211
45.081353011, 96.390, 1346.0, 36.6879
45.133874142, 96.390, 1544.0, 39.2938
45.186395273, 96.390, 1744.0, 41.7612
45.238916403, 96.390, 1551.0, 39.3827
45.291437534, 96.390, 1556.0, 39.4462
45.343958665, 96.390, 1532.0, 39.1408
45.396479795, 96.390, 1452.0, 38.1051
45.449000926, 96.390, 1535.0, 39.1791
45.501522057, 96.390, 1575.0, 39.6863
45.554043188, 96.390, 1480.0, 38.4708
45.606564318, 96.390, 1610.0, 40.1248
45.659085449, 96.390, 1632.0, 40.3980
45.711606580, 96.390, 1486.0, 38.5487
45.764127710, 96.390, 1589.0, 39.8623
45.816648841, 96.390, 1387.0, 37.2424
45.869169972, 96.390, 1358.0, 36.8511
45.921691103, 96.390, 1289.0, 35.9026
45.974212233, 96.390, 1185.0, 34.4238
46.026733364, 96.390, 1263.0, 35.5387
46.079254495, 96.390, 1325.0, 36.4005
46.131775625, 96.390, 1536.0, 39.1918
46.184296756, 96.390, 1768.0, 42.0476
46.236817887, 96.390, 2201.0, 46.9148
46.289339017, 96.390, 2126.0, 46.1086
46.341860148, 96.390, 2283.0, 47.7807
46.394381279, 96.390, 1991.0, 44.6206
46.446902410, 96.390, 2328.0, 48.2494
46.499423540, 96.390, 2147.0, 46.3357
46.551944671, 96.390, 1780.0, 42.1900
46.604465802, 96.390, 1855.0, 43.0697
46.656986932, 96.390, 1856.0, 43.0813
46.709508063, 96.390, 2225.0, 47.1699
46.762029194, 96.390, 2011.0, 44.8442
46.814550325, 96.390, 1689.0, 41.0974
46.867071455, 96.390, 1539.0, 39.2301
46.919592586, 96.390, 1340.0, 36.6060
46.972113717, 96.390, 1317.0, 36.2905
47.024634847, 96.390, 1335.0, 36.5377
47.077155978, 96.390, 1244.0, 35.2704
47.129677109, 96.390, 1250.0, 35.3553
47.182198240, 96.390, 1287.0, 35.8748
47.234719370, 96.390, 1207.0, 34.7419
47.287240501, 96.390, 1276.0, 35.7211
47.339761632, 96.390, 1229.0, 35.0571
47.392282762, 96.390, 1217.0, 34.8855
47.444803893, 96.390, 1168.0, 34.1760
47.497325024, 96.390, 1190.0, 34.4964
47.549846155, 96.390, 1260.0, 35.4965
47.602367285, 96.390, 1223.0, 34.9714
47.654888416, 96.390, 1214.0, 34.8425
47.707409547, 96.390, 1108.0, 33.2866
47.759930677, 96.390, 1087.0, 32.9697
47.812451808, 96.390, 1058.0, 32.5269
47.864972939, 96.390, 1097.0, 33.1210
47.917494069, 96.390, 1111.0, 33.3317
47.970015200, 96.390, 1197.0, 34.5977
48.022536331, 96.390, 1170.0, 34.2053
48.075057462, 96.390, 1284.0, 35.8329
48.127578592, 96.390, 1309.0, 36.1801
48.180099723, 96.390, 1356.0, 36.8239
48.232620854, 96.390, 1204.0, 34.6987
48.285141984, 96.390, 1257.0, 35.4542
48.337663115, 96.390, 1126.0, 33.5559
48.390184246, 96.390, 1138.0, 33.7343
48.442705377, 96.390, 1227.0, 35.0286
48.495226507, 96.390, 1385.0, 37.2156
48.547747638, 96.390, 1404.0, 37.4700
48.600268769, 96.390, 1398.0, 37.3898
48.652789899, 96.390, 1334.0, 36.5240
48.705311030, 96.390, 1221.0, 34.9428
48.757832161, 96.390, 1153.0, 33.9559
48.810353292, 96.390, 1178.0, 34.3220
48.862874422, 96.390, 1122.0, 33.4963
48.915395553, 96.390, 1107.0, 33.2716
48.967916684, 96.390, 1149.0, 33.8969
49.020437814, 96.390, 1078.0, 32.8329
49.072958945, 96.390, 1090.0, 33.0151
49.125480076, 96.390, 1101.0, 33.1813
49.178001207, 96.390, 1178.0, 34.3220
49.230522337, 96.390, 1038.0, 32.2180
49.283043468, 96.390, 1074.0, 32.7719
49.335564599, 96.390, 1094.0, 33.0757
49.388085729, 96.390, 1118.0, 33.4365
49.440606860, 96.390, 1202.0, 34.6699
49.493127991, 96.390, 1304.0, 36.1109
49.545649121, 96.390, 1151.0, 33.9264
49.598170252, 96.390, 1297.0, 36.0139
49.650691383, 96.390, 1463.0, 38.2492
49.703212514, 96.390, 1876.0, 43.3128
49.755733644, 96.390, 1419.0, 37.6696
49.808254775, 96.390, 1457.0, 38.1707
49.860775906, 96.390, 1322.0, 36.3593
49.913297036, 96.390, 1062.0, 32.5883
49.965818167, 96.390, 950.0, 30.8221
50.018339298, 96.390, 1002.0, 31.6544
50.070860429, 96.390, 910.0, 30.1662
50.123381559, 96.390, 947.0, 30.7734
50.175902690, 96.390, 1039.0, 32.2335
50.228423821, 96.390, 1166.0, 34.1467
50.280944951, 96.390, 1161.0, 34.0735
50.333466082, 96.390, 1215.0, 34.8569
50.385987213, 96.390, 1021.0, 31.9531
50.438508344, 96.390, 1038.0, 32.2180
50.491029474, 96.390, 943.0, 30.7083
50.543550605, 96.390, 922.0, 30.3645
50.596071736, 96.390, 866.0, 29.4279
50.648592866, 96.390, 897.0, 29.9500
50.701113997, 96.390, 867.0, 29.4449
50.753635128, 96.390, 912.0, 30.1993
50.806156258, 96.390, 851.0, 29.1719
50.858677389, 96.390, 913.0, 30.2159
50.911198520, 96.390, 910.0, 30.1662
50.963719651, 96.390, 924.0, 30.3974
51.016240781, 96.390, 1133.0, 33.6601
51.068761912, 96.390, 1346.0, 36.6879
51.121283043, 96.390, 1058.0, 32.5269
51.173804173, 96.390, 1136.0, 33.7046
51.226325304, 96.390, 1132.0, 33.6452
51.278846435, 96.390, 973.0, 31.1929
51.331367566, 96.390, 1021.0, 31.9531
51.383888696, 96.390, 1063.0, 32.6037
51.436409827, 96.390, 988.0, 31.4325
51.488930958, 96.390, 971.0, 31.1609
51.541452088, 96.390, 1033.0, 32.1403
51.593973219, 96.390, 957.0, 30.9354
51.646494350, 96.390, 857.0, 29.2746
51.699015481, 96.390, 867.0, 29.4449
51.751536611, 96.390, 836.0, 28.9137
51.804057742, 96.390, 878.0, 29.6311
51.856578873, 96.390, 914.0, 30.2324
51.909100003, 96.390, 966.0, 31.0805
51.961621134, 96.390, 901.0, 30.0167
52.014142265, 96.390, 889.0, 29.8161
52.066663396, 96.390, 891.0, 29.8496
52.119184526, 96.390, 930.0, 30.4959
52.171705657, 96.390, 1057.0, 32.5115
52.224226788, 96.390, 1107.0, 33.2716
52.276747918, 96.390, 1206.0, 34.7275
52.329269049, 96.390, 1196.0, 34.5832
52.381790180, 96.390, 1279.0, 35.7631
52.434311310, 96.390, 1357.0, 36.8375
52.486832441, 96.390, 1084.0, 32.9242
52.539353572, 96.390, 1294.0, 35.9722
52.591874703, 96.390, 1217.0, 34.8855
52.644395833, 96.390, 1299.0, 36.0416
52.696916964, 96.390, 1145.0, 33.8378
52.749438095, 96.390, 1264.0, 35.5528
52.801959225, 96.390, 1093.0, 33.0606
52.854480356, 96.390, 1093.0, 33.0606
52.907001487, 96.390, 1330.0, 36.4692
52.959522618, 96.390, 1348.0, 36.7151
53.012043748, 96.390, 1076.0, 32.8024
53.064564879, 96.390, 1122.0, 33.4963
53.117086010, 96.390, 1206.0, 34.7275
53.169607140, 96.390, 1365.0, 36.9459
53.222128271, 96.390, 1413.0, 37.5899
53.274649402, 96.390, 1176.0, 34.2929
53.327170533, 96.390, 1137.0, 33.7194
53.379691663, 96.390, 1051.0, 32.4191
53.432212794, 96.390, 898.0, 29.9666
53.484733925, 96.390, 866.0, 29.4279
53.537255055, 96.390, 845.0, 29.0689
53.589776186, 96.390, 869.0, 29.4788
53.642297317, 96.390, 825.0, 28.7228
53.694818448, 96.390, 815.0, 28.5482
53.747339578, 96.390, 847.0, 29.1033
53.799860709, 96.390, 887.0, 29.7825
53.852381840, 96.390, 871.0, 29.5127
53.904902970, 96.390, 1004.0, 31.6860
53.957424101, 96.390, 928.0, 30.4631
54.009945232, 96.390, 944.0, 30.7246
54.062466362, 96.390, 1011.0, 31.7962
54.114987493, 96.390, 1208.0, 34.7563
54.167508624, 96.390, 1326.0, 36.4143
54.220029755, 96.390, 1130.0, 33.6155
54.272550885, 96.390, 1202.0, 34.6699
54.325072016, 96.390, 1166.0, 34.1467
54.377593147, 96.390, 1126.0, 33.5559
54.430114277, 96.390, 990.0, 31.4643
54.482635408, 96.390, 916.0, 30.2655
54.535156539, 96.390, 882.0, 29.6985
54.587677670, 96.390, 922.0, 30.3645
54.640198800, 96.390, 970.0, 31.1448
54.692719931, 96.390, 914.0, 30.2324
54.745241062, 96.390, 924.0, 30.3974
54.797762192, 96.390, 993.0, 31.5119
54.850283323, 96.390, 871.0, 29.5127
54.902804454, 96.390, 941.0, 30.6757
54.955325585, 96.390, 1016.0, 31.8748
55.007846715, 96.390, 976.0, 31.2410
55.060367846, 96.390, 1031.0, 32.1092
55.112888977, 96.390, 1458.0, 38.1838
55.165410107, 96.390, 1176.0, 34.2929
55.217931238, 96.390, 968.0, 31.1127
55.270452369, 96.390, 1066.0, 32.6497
55.322973499, 96.390, 897.0, 29.9500
55.375494630, 96.390, 719.0, 26.8142
55.428015761, 96.390, 793.0, 28.1603
55.480536892, 96.390, 871.0, 29.5127
55.533058022, 96.390, 820.0, 28.6356
55.585579153, 96.390, 826.0, 28.7402
55.638100284, 96.390, 865.0, 29.4109
55.690621414, 96.390, 813.0, 28.5132
55.743142545, 96.390, 836.0, 28.9137
55.795663676, 96.390, 852.0, 29.1890
55.848184807, 96.390, 830.0, 28.8097
55.900705937, 96.390, 763.0, 27.6225
55.953227068, 96.390, 772.0, 27.7849
56.005748199, 96.390, 799.0, 28.2666
56.058269329, 96.390, 814.0, 28.5307
56.110790460, 96.390, 816.0, 28.5657
56.163311591, 96.390, 788.0, 28.0713
56.215832722, 96.390, 815.0, 28.5482
56.268353852, 96.390, 776.0, 27.8568
56.320874983, 96.390, 815.0, 28.5482
56.373396114, 96.390, 759.0, 27.5500
56.425917244, 96.390, 775.0, 27.8388
56.478438375, 96.390, 801.0, 28.3019
56.530959506, 96.390, 769.0, 27.7308
56.583480637, 96.390, 721.0, 26.8514
56.636001767, 96.390, 773.0, 27.8029
56.688522898, 96.390, 802.0, 28.3196
56.741044029, 96.390, 758.0, 27.5318
56.793565159, 96.390, 772.0, 27.7849
56.846086290, 96.390, 734.0, 27.0924
56.898607421, 96.390, 769.0, 27.7308
56.951128551, 96.390, 745.0, 27.2947
57.003649682, 96.390, 753.0, 27.4408
57.056170813, 96.390, 792.0, 28.1425
57.108691944, 96.390, 748.0, 27.3496
57.161213074, 96.390, 748.0, 27.3496
57.213734205, 96.390, 766.0, 27.6767
57.266255336, 96.390, 799.0, 28.2666
57.318776466, 96.390, 741.0, 27.2213
57.371297597, 96.390, 789.0, 28.0891
57.423818728, 96.390, 900.0, 30.0000
57.476339859, 96.390, 1055.0, 32.4808
57.528860989, 96.390, 1085.0, 32.9393
57.581382120, 96.390, 902.0, 30.0333
57.633903251, 96.390, 1009.0, 31.7648
57.686424381, 96.390, 1196.0, 34.5832
57.738945512, 96.390, 1217.0, 34.8855
57.791466643, 96.390, 1180.0, 34.3511
57.843987774, 96.390, 983.0, 31.3528
57.896508904, 96.390, 1001.0, 31.6386
57.949030035, 96.390, 1043.0, 32.2955
58.001551166, 96.390, 869.0, 29.4788
58.054072296, 96.390, 935.0, 30.5778
58.106593427, 96.390, 1047.0, 32.3574
58.159114558, 96.390, 870.0, 29.4958
58.211635689, 96.390, 928.0, 30.4631
58.264156819, 96.390, 883.0, 29.7153
58.316677950, 96.390, 780.0, 27.9285
58.369199081, 96.390, 806.0, 28.3901
58.421720211, 96.390, 757.0, 27.5136
58.474241342, 96.390, 710.0, 26.6458
58.526762473, 96.390, 809.0, 28.4429
58.579283603, 96.390, 816.0, 28.5657
58.631804734, 96.390, 778.0, 27.8927
58.684325865, 96.390, 770.0, 27.7489
58.736846996, 96.390, 735.0, 27.1109
58.789368126, 96.390, 745.0, 27.2947
58.841889257, 96.390, 731.0, 27.0370
58.894410388, 96.390, 684.0, 26.1534
58.946931518, 96.390, 750.0, 27.3861
58.999452649, 96.390, 698.0, 26.4197
59.051973780, 96.390, 745.0, 27.2947
59.104494911, 96.390, 717.0, 26.7769
59.157016041, 96.390, 734.0, 27.0924
59.209537172, 96.390, 694.0, 26.3439
59.262058303, 96.390, 801.0, 28.3019
59.314579433, 96.390, 855.0, 29.2404
59.367100564, 96.390, 872.0, 29.5296
59.419621695, 96.390, 829.0, 28.7924
59.472142826, 96.390, 808.0, 28.4253
59.524663956, 96.390, 900.0, 30.0000
59.577185087, 96.390, 831.0, 28.8271
59.629706218, 96.390, 871.0, 29.5127
59.682227348, 96.390, 848.0, 29.1204
59.734748479, 96.390, 844.0, 29.0517
59.787269610, 96.390, 845.0, 29.0689
59.839790740, 96.390, 860.0, 29.3258
59.892311871, 96.390, 824.0, 28.7054
59.944833002, 96.390, 874.0, 29.5635
59.997354133, 96.390, 894.0, 29.8998
60.049875263, 96.390, 906.0, 30.0998
60.102396394, 96.390, 887.0, 29.7825
60.154917525, 96.390, 859.0, 29.3087
60.207438655, 96.390, 907.0, 30.1164
60.259959786, 96.390, 844.0, 29.0517
60.312480917, 96.390, 920.0, 30.3315
60.365002048, 96.390, 876.0, 29.5973
60.417523178, 96.390, 898.0, 29.9666
60.470044309, 96.390, 988.0, 31.4325
60.522565440, 96.390, 1021.0, 31.9531
60.575086570, 96.390, 1018.0, 31.9061
60.627607701, 96.390, 1054.0, 32.4654
60.680128832, 96.390, 1201.0, 34.6554
60.732649963, 96.390, 1147.0, 33.8674
60.785171093, 96.390, 1194.0, 34.5543
60.837692224, 96.390, 1207.0, 34.7419
60.890213355, 96.390, 1321.0, 36.3456
60.942734485, 96.390, 1283.0, 35.8190
60.995255616, 96.390, 1245.0, 35.2846
61.047776747, 96.390, 1222.0, 34.9571
61.100297878, 96.390, 1156.0, 34.0000
61.152819008, 96.390, 1219.0, 34.9142
61.205340139, 96.390, 1261.0, 35.5106
61.257861270, 96.390, 1152.0, 33.9411
61.310382400, 96.390, 1018.0, 31.9061
61.362903531, 96.390, 1056.0, 32.4962
61.415424662, 96.390, 1041.0, 32.2645
61.467945792, 96.390, 1006.0, 31.7175
61.520466923, 96.390, 978.0, 31.2730
61.572988054, 96.390, 1026.0, 32.0312
61.625509185, 96.390, 1029.0, 32.0780
61.678030315, 96.390, 1056.0, 32.4962
61.730551446, 96.390, 1027.0, 32.0468
61.783072577, 96.390, 1066.0, 32.6497
61.835593707, 96.390, 1061.0, 32.5730
61.888114838, 96.390, 1125.0, 33.5410
61.940635969, 96.390, 1040.0, 32.2490
61.993157100, 96.390, 1034.0, 32.1559
62.045678230, 96.390, 1146.0, 33.8526
62.098199361, 96.390, 1119.0, 33.4515
62.150720492, 96.390, 1067.0, 32.6650
62.203241622, 96.390, 1163.0, 34.1028
62.255762753, 96.390, 1165.0, 34.1321
62.308283884, 96.390, 1053.0, 32.4500
62.360805015, 96.390, 1013.0, 31.8277
62.413326145, 96.390, 1061.0, 32.5730
62.465847276, 96.390, 977.0, 31.2570
62.518368407, 96.390, 982.0, 31.3369
62.570889537, 96.390, 941.0, 30.6757
62.623410668, 96.390, 938.0, 30.6268
62.675931799, 96.390, 944.0, 30.7246
62.728452930, 96.390, 874.0, 29.5635
62.780974060, 96.390, 847.0, 29.1033
62.833495191, 96.390, 854.0, 29.2233
62.886016322, 96.390, 870.0, 29.4958
62.938537452, 96.390, 803.0, 28.3373
62.991058583, 96.390, 731.0, 27.0370
63.043579714, 96.390, 678.0, 26.0384
63.096100844, 96.390, 724.0, 26.9072
63.148621975, 96.390, 724.0, 26.9072
63.201143106, 96.390, 714.0, 26.7208
63.253664237, 96.390, 672.0, 25.9230
63.306185367, 96.390, 671.0, 25.9037
63.358706498, 96.390, 750.0, 27.3861
63.411227629, 96.390, 747.0, 27.3313
63.463748759, 96.390, 751.0, 27.4044
63.516269890, 96.390, 698.0, 26.4197
63.568791021, 96.390, 712.0, 26.6833
63.621312152, 96.390, 703.0, 26.5141
63.673833282, 96.390, 683.0, 26.1343
63.726354413, 96.390, 730.0, 27.0185
63.778875544, 96.390, 695.0, 26.3629
63.831396674, 96.390, 716.0, 26.7582
63.883917805, 96.390, 797.0, 28.2312
63.936438936, 96.390, 781.0, 27.9464
63.988960067, 96.390, 876.0, 29.5973
64.041481197, 96.390, 795.0, 28.1957
64.094002328, 96.390, 824.0, 28.7054
64.146523459, 96.390, 834.0, 28.8791
64.199044589, 96.390, 752.0, 27.4226
64.251565720, 96.390, 749.0, 27.3679
64.304086851, 96.390, 773.0, 27.8029
64.356607981, 96.390, 783.0, 27.9821
64.409129112, 96.390, 682.0, 26.1151
64.461650243, 96.390, 664.0, 25.7682
64.514171374, 96.390, 660.0, 25.6905
64.566692504, 96.390, 686.0, 26.1916
64.619213635, 96.390, 643.0, 25.3574
64.671734766, 96.390, 636.0, 25.2190
64.724255896, 96.390, 698.0, 26.4197
64.776777027, 96.390, 682.0, 26.1151
64.829298158, 96.390, 671.0, 25.9037
64.881819289, 96.390, 642.0, 25.3377
64.934340419, 96.390, 713.0, 26.7021
64.986861550, 96.390, 730.0, 27.0185