File: Files_organized_for_plots/Constant_NaOH_half_mL10M_to_1gPC/XRD_SiAxial12Jan22_Act01Mar22_B1_0385M_NaOH_LS0142_1.csv
[Measurement conditions]
Sample identification,XRD_SiAxial12Jan22_Act01Mar22_B1_0385M_NaOH_LS0142_1
Comment - 1,"Configuration=Stage for Flat Samples/Holders, Owner=User-1, Creation date=7/1/2020 9:53:24 AM"
Comment - 2,"Goniometer=Theta/Theta; Minimum step size 2Theta:0.0001; Minimum step size Omega:0.0001"
Comment - 3,"Sample stage=Stage for flat samples/holders"
Comment - 4,"Diffractometer system=EMPYREAN"
Comment - 5,"Measurement program=C:\Users\ibo5034\OneDrive - The Pennsylvania State University\NEUP - Reed, Titus's files\XRD\Cement\Zerobackground scan.xrdmp, Identifier={98A3B11C-88F9-4AA6-982C-73314A311EF5}"
Anode material,Cu
K-Alpha1 wavelength,1.5405980
K-Alpha2 wavelength,1.5444260
Ratio K-Alpha2/K-Alpha1,0.500
Divergence slit,Fixed,0.25
Monochromator used,NO
Generator voltage, 45
Tube current, 40
File date and time,04/Mar/2022 12:37
Unit cell,
h k l, 0 0 0
Scan axis,Gonio
Scan range,4.994599997,64.999991833
Scan step size,0.0262606
No. of points, 2285
Scan type,CONTINUOUS
Time per step,96.390
[Scan points]
Angle, TimePerStep, Intensity, ESD
5.007730280, 96.390, 5266.0, 72.5672
5.060251411, 96.390, 5085.0, 71.3092
5.112772541, 96.390, 4938.0, 70.2709
5.165293672, 96.390, 4874.0, 69.8140
5.217814803, 96.390, 5048.0, 71.0493
5.270335934, 96.390, 4814.0, 69.3830
5.322857064, 96.390, 4787.0, 69.1881
5.375378195, 96.390, 4583.0, 67.6979
5.427899326, 96.390, 4633.0, 68.0661
5.480420456, 96.390, 4689.0, 68.4763
5.532941587, 96.390, 4686.0, 68.4544
5.585462718, 96.390, 4510.0, 67.1565
5.637983849, 96.390, 4592.0, 67.7643
5.690504979, 96.390, 4540.0, 67.3795
5.743026110, 96.390, 4503.0, 67.1044
5.795547241, 96.390, 4531.0, 67.3127
5.848068371, 96.390, 4418.0, 66.4680
5.900589502, 96.390, 4470.0, 66.8581
5.953110633, 96.390, 4450.0, 66.7083
6.005631763, 96.390, 4324.0, 65.7571
6.058152894, 96.390, 4326.0, 65.7723
6.110674025, 96.390, 4290.0, 65.4981
6.163195156, 96.390, 4373.0, 66.1287
6.215716286, 96.390, 4318.0, 65.7115
6.268237417, 96.390, 4258.0, 65.2534
6.320758548, 96.390, 4204.0, 64.8383
6.373279678, 96.390, 4250.0, 65.1920
6.425800809, 96.390, 4235.0, 65.0769
6.478321940, 96.390, 4151.0, 64.4283
6.530843071, 96.390, 4243.0, 65.1383
6.583364201, 96.390, 4150.0, 64.4205
6.635885332, 96.390, 4094.0, 63.9844
6.688406463, 96.390, 4184.0, 64.6838
6.740927593, 96.390, 4101.0, 64.0391
6.793448724, 96.390, 4185.0, 64.6916
6.845969855, 96.390, 4091.0, 63.9609
6.898490986, 96.390, 4162.0, 64.5136
6.951012116, 96.390, 4071.0, 63.8044
7.003533247, 96.390, 4070.0, 63.7966
7.056054378, 96.390, 4011.0, 63.3325
7.108575508, 96.390, 4158.0, 64.4826
7.161096639, 96.390, 4234.0, 65.0692
7.213617770, 96.390, 3960.0, 62.9285
7.266138900, 96.390, 4080.0, 63.8749
7.318660031, 96.390, 3970.0, 63.0079
7.371181162, 96.390, 4062.0, 63.7338
7.423702293, 96.390, 4054.0, 63.6710
7.476223423, 96.390, 4068.0, 63.7809
7.528744554, 96.390, 3895.0, 62.4099
7.581265685, 96.390, 3975.0, 63.0476
7.633786815, 96.390, 4023.0, 63.4271
7.686307946, 96.390, 3942.0, 62.7853
7.738829077, 96.390, 3945.0, 62.8092
7.791350208, 96.390, 3866.0, 62.1772
7.843871338, 96.390, 3969.0, 63.0000
7.896392469, 96.390, 3755.0, 61.2781
7.948913600, 96.390, 3825.0, 61.8466
8.001434730, 96.390, 3804.0, 61.6766
8.053955861, 96.390, 3918.0, 62.5939
8.106476992, 96.390, 3840.0, 61.9677
8.158998123, 96.390, 3808.0, 61.7090
8.211519253, 96.390, 3873.0, 62.2334
8.264040384, 96.390, 3821.0, 61.8142
8.316561515, 96.390, 3827.0, 61.8628
8.369082645, 96.390, 3856.0, 62.0967
8.421603776, 96.390, 3909.0, 62.5220
8.474124907, 96.390, 3726.0, 61.0410
8.526646038, 96.390, 3763.0, 61.3433
8.579167168, 96.390, 3860.0, 62.1289
8.631688299, 96.390, 3815.0, 61.7657
8.684209430, 96.390, 3751.0, 61.2454
8.736730560, 96.390, 3703.0, 60.8523
8.789251691, 96.390, 3723.0, 61.0164
8.841772822, 96.390, 3803.0, 61.6685
8.894293952, 96.390, 3712.0, 60.9262
8.946815083, 96.390, 3626.0, 60.2163
8.999336214, 96.390, 3805.0, 61.6847
9.051857345, 96.390, 3700.0, 60.8276
9.104378475, 96.390, 3695.0, 60.7865
9.156899606, 96.390, 3699.0, 60.8194
9.209420737, 96.390, 3617.0, 60.1415
9.261941867, 96.390, 3795.0, 61.6036
9.314462998, 96.390, 3483.0, 59.0169
9.366984129, 96.390, 3519.0, 59.3212
9.419505260, 96.390, 3609.0, 60.0750
9.472026390, 96.390, 3560.0, 59.6657
9.524547521, 96.390, 3574.0, 59.7829
9.577068652, 96.390, 3544.0, 59.5315
9.629589782, 96.390, 3542.0, 59.5147
9.682110913, 96.390, 3625.0, 60.2080
9.734632044, 96.390, 3569.0, 59.7411
9.787153175, 96.390, 3425.0, 58.5235
9.839674305, 96.390, 3459.0, 58.8133
9.892195436, 96.390, 3474.0, 58.9406
9.944716567, 96.390, 3379.0, 58.1292
9.997237697, 96.390, 3489.0, 59.0678
10.049758828, 96.390, 3425.0, 58.5235
10.102279959, 96.390, 3296.0, 57.4108
10.154801090, 96.390, 3352.0, 57.8965
10.207322220, 96.390, 3425.0, 58.5235
10.259843351, 96.390, 3295.0, 57.4021
10.312364482, 96.390, 3477.0, 58.9661
10.364885612, 96.390, 3378.0, 58.1206
10.417406743, 96.390, 3230.0, 56.8331
10.469927874, 96.390, 3242.0, 56.9386
10.522449004, 96.390, 3305.0, 57.4891
10.574970135, 96.390, 3318.0, 57.6021
10.627491266, 96.390, 3223.0, 56.7715
10.680012397, 96.390, 3183.0, 56.4181
10.732533527, 96.390, 3242.0, 56.9386
10.785054658, 96.390, 3243.0, 56.9473
10.837575789, 96.390, 3159.0, 56.2050
10.890096919, 96.390, 3299.0, 57.4369
10.942618050, 96.390, 3232.0, 56.8507
10.995139181, 96.390, 3197.0, 56.5420
11.047660312, 96.390, 3214.0, 56.6922
11.100181442, 96.390, 3067.0, 55.3805
11.152702573, 96.390, 3090.0, 55.5878
11.205223704, 96.390, 3178.0, 56.3738
11.257744834, 96.390, 3180.0, 56.3915
11.310265965, 96.390, 3141.0, 56.0446
11.362787096, 96.390, 3039.0, 55.1271
11.415308227, 96.390, 3051.0, 55.2359
11.467829357, 96.390, 3109.0, 55.7584
11.520350488, 96.390, 3002.0, 54.7905
11.572871619, 96.390, 3015.0, 54.9090
11.625392749, 96.390, 3088.0, 55.5698
11.677913880, 96.390, 2984.0, 54.6260
11.730435011, 96.390, 2926.0, 54.0925
11.782956141, 96.390, 2951.0, 54.3231
11.835477272, 96.390, 3034.0, 55.0818
11.887998403, 96.390, 2936.0, 54.1849
11.940519534, 96.390, 2992.0, 54.6992
11.993040664, 96.390, 2788.0, 52.8015
12.045561795, 96.390, 2837.0, 53.2635
12.098082926, 96.390, 2801.0, 52.9245
12.150604056, 96.390, 2995.0, 54.7266
12.203125187, 96.390, 2820.0, 53.1037
12.255646318, 96.390, 2800.0, 52.9150
12.308167449, 96.390, 2815.0, 53.0566
12.360688579, 96.390, 2777.0, 52.6972
12.413209710, 96.390, 2862.0, 53.4977
12.465730841, 96.390, 2824.0, 53.1413
12.518251971, 96.390, 2867.0, 53.5444
12.570773102, 96.390, 2704.0, 52.0000
12.623294233, 96.390, 2762.0, 52.5547
12.675815364, 96.390, 2762.0, 52.5547
12.728336494, 96.390, 2746.0, 52.4023
12.780857625, 96.390, 2872.0, 53.5910
12.833378756, 96.390, 2708.0, 52.0384
12.885899886, 96.390, 2750.0, 52.4404
12.938421017, 96.390, 2792.0, 52.8394
12.990942148, 96.390, 2672.0, 51.6914
13.043463279, 96.390, 2689.0, 51.8556
13.095984409, 96.390, 2674.0, 51.7107
13.148505540, 96.390, 2623.0, 51.2152
13.201026671, 96.390, 2632.0, 51.3030
13.253547801, 96.390, 2645.0, 51.4296
13.306068932, 96.390, 2608.0, 51.0686
13.358590063, 96.390, 2611.0, 51.0979
13.411111193, 96.390, 2604.0, 51.0294
13.463632324, 96.390, 2654.0, 51.5170
13.516153455, 96.390, 2550.0, 50.4975
13.568674586, 96.390, 2645.0, 51.4296
13.621195716, 96.390, 2595.0, 50.9411
13.673716847, 96.390, 2500.0, 50.0000
13.726237978, 96.390, 2582.0, 50.8134
13.778759108, 96.390, 2498.0, 49.9800
13.831280239, 96.390, 2629.0, 51.2738
13.883801370, 96.390, 2491.0, 49.9099
13.936322501, 96.390, 2564.0, 50.6360
13.988843631, 96.390, 2401.0, 49.0000
14.041364762, 96.390, 2602.0, 51.0098
14.093885893, 96.390, 2466.0, 49.6588
14.146407023, 96.390, 2625.0, 51.2348
14.198928154, 96.390, 2510.0, 50.0999
14.251449285, 96.390, 2556.0, 50.5569
14.303970416, 96.390, 2573.0, 50.7247
14.356491546, 96.390, 2404.0, 49.0306
14.409012677, 96.390, 2570.0, 50.6952
14.461533808, 96.390, 2616.0, 51.1468
14.514054938, 96.390, 2526.0, 50.2593
14.566576069, 96.390, 2397.0, 48.9592
14.619097200, 96.390, 2500.0, 50.0000
14.671618331, 96.390, 2487.0, 49.8698
14.724139461, 96.390, 2552.0, 50.5173
14.776660592, 96.390, 2431.0, 49.3052
14.829181723, 96.390, 2491.0, 49.9099
14.881702853, 96.390, 2477.0, 49.7695
14.934223984, 96.390, 2485.0, 49.8498
14.986745115, 96.390, 2426.0, 49.2544
15.039266245, 96.390, 2427.0, 49.2646
15.091787376, 96.390, 2382.0, 48.8057
15.144308507, 96.390, 2467.0, 49.6689
15.196829638, 96.390, 2405.0, 49.0408
15.249350768, 96.390, 2439.0, 49.3862
15.301871899, 96.390, 2498.0, 49.9800
15.354393030, 96.390, 2439.0, 49.3862
15.406914160, 96.390, 2390.0, 48.8876
15.459435291, 96.390, 2510.0, 50.0999
15.511956422, 96.390, 2464.0, 49.6387
15.564477553, 96.390, 2415.0, 49.1426
15.616998683, 96.390, 2459.0, 49.5883
15.669519814, 96.390, 2437.0, 49.3660
15.722040945, 96.390, 2468.0, 49.6790
15.774562075, 96.390, 2476.0, 49.7594
15.827083206, 96.390, 2447.0, 49.4672
15.879604337, 96.390, 2373.0, 48.7134
15.932125468, 96.390, 2485.0, 49.8498
15.984646598, 96.390, 2401.0, 49.0000
16.037167729, 96.390, 2449.0, 49.4874
16.089688860, 96.390, 2491.0, 49.9099
16.142209990, 96.390, 2381.0, 48.7955
16.194731121, 96.390, 2388.0, 48.8672
16.247252252, 96.390, 2496.0, 49.9600
16.299773382, 96.390, 2435.0, 49.3457
16.352294513, 96.390, 2460.0, 49.5984
16.404815644, 96.390, 2478.0, 49.7795
16.457336775, 96.390, 2480.0, 49.7996
16.509857905, 96.390, 2400.0, 48.9898
16.562379036, 96.390, 2433.0, 49.3254
16.614900167, 96.390, 2467.0, 49.6689
16.667421297, 96.390, 2508.0, 50.0799
16.719942428, 96.390, 2525.0, 50.2494
16.772463559, 96.390, 2540.0, 50.3984
16.824984690, 96.390, 2440.0, 49.3964
16.877505820, 96.390, 2426.0, 49.2544
16.930026951, 96.390, 2435.0, 49.3457
16.982548082, 96.390, 2634.0, 51.3225
17.035069212, 96.390, 2578.0, 50.7740
17.087590343, 96.390, 2488.0, 49.8799
17.140111474, 96.390, 2566.0, 50.6557
17.192632605, 96.390, 2404.0, 49.0306
17.245153735, 96.390, 2484.0, 49.8397
17.297674866, 96.390, 2520.0, 50.1996
17.350195997, 96.390, 2569.0, 50.6853
17.402717127, 96.390, 2471.0, 49.7092
17.455238258, 96.390, 2549.0, 50.4876
17.507759389, 96.390, 2560.0, 50.5964
17.560280520, 96.390, 2547.0, 50.4678
17.612801650, 96.390, 2647.0, 51.4490
17.665322781, 96.390, 2628.0, 51.2640
17.717843912, 96.390, 2630.0, 51.2835
17.770365042, 96.390, 2624.0, 51.2250
17.822886173, 96.390, 2625.0, 51.2348
17.875407304, 96.390, 2604.0, 51.0294
17.927928434, 96.390, 2643.0, 51.4101
17.980449565, 96.390, 2571.0, 50.7050
18.032970696, 96.390, 2754.0, 52.4786
18.085491827, 96.390, 2799.0, 52.9056
18.138012957, 96.390, 2697.0, 51.9326
18.190534088, 96.390, 2723.0, 52.1824
18.243055219, 96.390, 2706.0, 52.0192
18.295576349, 96.390, 2637.0, 51.3517
18.348097480, 96.390, 2761.0, 52.5452
18.400618611, 96.390, 2739.0, 52.3355
18.453139742, 96.390, 2817.0, 53.0754
18.505660872, 96.390, 2875.0, 53.6190
18.558182003, 96.390, 2760.0, 52.5357
18.610703134, 96.390, 2741.0, 52.3546
18.663224264, 96.390, 2918.0, 54.0185
18.715745395, 96.390, 2762.0, 52.5547
18.768266526, 96.390, 2886.0, 53.7215
18.820787657, 96.390, 2789.0, 52.8110
18.873308787, 96.390, 2830.0, 53.1977
18.925829918, 96.390, 2826.0, 53.1601
18.978351049, 96.390, 2905.0, 53.8981
19.030872179, 96.390, 2852.0, 53.4041
19.083393310, 96.390, 2881.0, 53.6749
19.135914441, 96.390, 2935.0, 54.1756
19.188435572, 96.390, 2899.0, 53.8424
19.240956702, 96.390, 2789.0, 52.8110
19.293477833, 96.390, 2872.0, 53.5910
19.345998964, 96.390, 2911.0, 53.9537
19.398520094, 96.390, 3050.0, 55.2268
19.451041225, 96.390, 3053.0, 55.2540
19.503562356, 96.390, 2904.0, 53.8888
19.556083486, 96.390, 2999.0, 54.7631
19.608604617, 96.390, 3017.0, 54.9272
19.661125748, 96.390, 3017.0, 54.9272
19.713646879, 96.390, 3036.0, 55.0999
19.766168009, 96.390, 3041.0, 55.1453
19.818689140, 96.390, 3086.0, 55.5518
19.871210271, 96.390, 3061.0, 55.3263
19.923731401, 96.390, 3186.0, 56.4447
19.976252532, 96.390, 3177.0, 56.3649
20.028773663, 96.390, 3142.0, 56.0535
20.081294794, 96.390, 3163.0, 56.2406
20.133815924, 96.390, 3144.0, 56.0714
20.186337055, 96.390, 3219.0, 56.7362
20.238858186, 96.390, 3251.0, 57.0175
20.291379316, 96.390, 3141.0, 56.0446
20.343900447, 96.390, 3256.0, 57.0614
20.396421578, 96.390, 3213.0, 56.6833
20.448942709, 96.390, 3246.0, 56.9737
20.501463839, 96.390, 3280.0, 57.2713
20.553984970, 96.390, 3113.0, 55.7943
20.606506101, 96.390, 3327.0, 57.6802
20.659027231, 96.390, 3292.0, 57.3760
20.711548362, 96.390, 3250.0, 57.0088
20.764069493, 96.390, 3314.0, 57.5674
20.816590623, 96.390, 3413.0, 58.4209
20.869111754, 96.390, 3229.0, 56.8243
20.921632885, 96.390, 3392.0, 58.2409
20.974154016, 96.390, 3268.0, 57.1664
21.026675146, 96.390, 3148.0, 56.1070
21.079196277, 96.390, 3280.0, 57.2713
21.131717408, 96.390, 3218.0, 56.7274
21.184238538, 96.390, 3343.0, 57.8187
21.236759669, 96.390, 3361.0, 57.9741
21.289280800, 96.390, 3340.0, 57.7927
21.341801931, 96.390, 3352.0, 57.8965
21.394323061, 96.390, 3304.0, 57.4804
21.446844192, 96.390, 3268.0, 57.1664
21.499365323, 96.390, 3387.0, 58.1979
21.551886453, 96.390, 3375.0, 58.0948
21.604407584, 96.390, 3262.0, 57.1139
21.656928715, 96.390, 3325.0, 57.6628
21.709449846, 96.390, 3357.0, 57.9396
21.761970976, 96.390, 3376.0, 58.1034
21.814492107, 96.390, 3367.0, 58.0259
21.867013238, 96.390, 3330.0, 57.7062
21.919534368, 96.390, 3478.0, 58.9746
21.972055499, 96.390, 3316.0, 57.5847
22.024576630, 96.390, 3471.0, 58.9152
22.077097761, 96.390, 3353.0, 57.9051
22.129618891, 96.390, 3411.0, 58.4038
22.182140022, 96.390, 3327.0, 57.6802
22.234661153, 96.390, 3287.0, 57.3324
22.287182283, 96.390, 3302.0, 57.4630
22.339703414, 96.390, 3308.0, 57.5152
22.392224545, 96.390, 3414.0, 58.4294
22.444745675, 96.390, 3317.0, 57.5934
22.497266806, 96.390, 3284.0, 57.3062
22.549787937, 96.390, 3434.0, 58.6003
22.602309068, 96.390, 3228.0, 56.8155
22.654830198, 96.390, 3410.0, 58.3952
22.707351329, 96.390, 3266.0, 57.1489
22.759872460, 96.390, 3153.0, 56.1516
22.812393590, 96.390, 3306.0, 57.4978
22.864914721, 96.390, 3265.0, 57.1402
22.917435852, 96.390, 3382.0, 58.1550
22.969956983, 96.390, 3305.0, 57.4891
23.022478113, 96.390, 3372.0, 58.0689
23.074999244, 96.390, 3288.0, 57.3411
23.127520375, 96.390, 3300.0, 57.4456
23.180041505, 96.390, 3052.0, 55.2449
23.232562636, 96.390, 3206.0, 56.6216
23.285083767, 96.390, 3195.0, 56.5243
23.337604898, 96.390, 3198.0, 56.5509
23.390126028, 96.390, 3183.0, 56.4181
23.442647159, 96.390, 3229.0, 56.8243
23.495168290, 96.390, 3101.0, 55.6866
23.547689420, 96.390, 3190.0, 56.4801
23.600210551, 96.390, 3155.0, 56.1694
23.652731682, 96.390, 3254.0, 57.0438
23.705252813, 96.390, 3139.0, 56.0268
23.757773943, 96.390, 3102.0, 55.6956
23.810295074, 96.390, 3092.0, 55.6058
23.862816205, 96.390, 3094.0, 55.6237
23.915337335, 96.390, 3144.0, 56.0714
23.967858466, 96.390, 3071.0, 55.4166
24.020379597, 96.390, 3141.0, 56.0446
24.072900727, 96.390, 3123.0, 55.8838
24.125421858, 96.390, 2935.0, 54.1756
24.177942989, 96.390, 2914.0, 53.9815
24.230464120, 96.390, 2909.0, 53.9351
24.282985250, 96.390, 2957.0, 54.3783
24.335506381, 96.390, 2979.0, 54.5802
24.388027512, 96.390, 2998.0, 54.7540
24.440548642, 96.390, 3010.0, 54.8635
24.493069773, 96.390, 2966.0, 54.4610
24.545590904, 96.390, 2931.0, 54.1387
24.598112035, 96.390, 2859.0, 53.4696
24.650633165, 96.390, 2934.0, 54.1664
24.703154296, 96.390, 2928.0, 54.1110
24.755675427, 96.390, 2777.0, 52.6972
24.808196557, 96.390, 2724.0, 52.1920
24.860717688, 96.390, 2850.0, 53.3854
24.913238819, 96.390, 2822.0, 53.1225
24.965759950, 96.390, 2731.0, 52.2590
25.018281080, 96.390, 2731.0, 52.2590
25.070802211, 96.390, 2847.0, 53.3573
25.123323342, 96.390, 2719.0, 52.1440
25.175844472, 96.390, 2793.0, 52.8488
25.228365603, 96.390, 2682.0, 51.7880
25.280886734, 96.390, 2666.0, 51.6333
25.333407864, 96.390, 2627.0, 51.2543
25.385928995, 96.390, 2661.0, 51.5849
25.438450126, 96.390, 2659.0, 51.5655
25.490971257, 96.390, 2670.0, 51.6720
25.543492387, 96.390, 2613.0, 51.1175
25.596013518, 96.390, 2697.0, 51.9326
25.648534649, 96.390, 2642.0, 51.4004
25.701055779, 96.390, 2645.0, 51.4296
25.753576910, 96.390, 2517.0, 50.1697
25.806098041, 96.390, 2604.0, 51.0294
25.858619172, 96.390, 2454.0, 49.5379
25.911140302, 96.390, 2539.0, 50.3885
25.963661433, 96.390, 2509.0, 50.0899
26.016182564, 96.390, 2507.0, 50.0700
26.068703694, 96.390, 2556.0, 50.5569
26.121224825, 96.390, 2424.0, 49.2341
26.173745956, 96.390, 2530.0, 50.2991
26.226267087, 96.390, 2439.0, 49.3862
26.278788217, 96.390, 2543.0, 50.4282
26.331309348, 96.390, 2507.0, 50.0700
26.383830479, 96.390, 2440.0, 49.3964
26.436351609, 96.390, 2490.0, 49.8999
26.488872740, 96.390, 2467.0, 49.6689
26.541393871, 96.390, 2525.0, 50.2494
26.593915002, 96.390, 2414.0, 49.1325
26.646436132, 96.390, 2346.0, 48.4355
26.698957263, 96.390, 2399.0, 48.9796
26.751478394, 96.390, 2370.0, 48.6826
26.803999524, 96.390, 2464.0, 49.6387
26.856520655, 96.390, 2416.0, 49.1528
26.909041786, 96.390, 2400.0, 48.9898
26.961562916, 96.390, 2346.0, 48.4355
27.014084047, 96.390, 2340.0, 48.3735
27.066605178, 96.390, 2309.0, 48.0521
27.119126309, 96.390, 2338.0, 48.3529
27.171647439, 96.390, 2332.0, 48.2908
27.224168570, 96.390, 2355.0, 48.5283
27.276689701, 96.390, 2328.0, 48.2494
27.329210831, 96.390, 2398.0, 48.9694
27.381731962, 96.390, 2290.0, 47.8539
27.434253093, 96.390, 2306.0, 48.0208
27.486774224, 96.390, 2347.0, 48.4458
27.539295354, 96.390, 2318.0, 48.1456
27.591816485, 96.390, 2330.0, 48.2701
27.644337616, 96.390, 2269.0, 47.6340
27.696858746, 96.390, 2193.0, 46.8295
27.749379877, 96.390, 2260.0, 47.5395
27.801901008, 96.390, 2263.0, 47.5710
27.854422139, 96.390, 2287.0, 47.8226
27.906943269, 96.390, 2143.0, 46.2925
27.959464400, 96.390, 2303.0, 47.9896
28.011985531, 96.390, 2264.0, 47.5815
28.064506661, 96.390, 2175.0, 46.6369
28.117027792, 96.390, 2208.0, 46.9894
28.169548923, 96.390, 2214.0, 47.0532
28.222070054, 96.390, 2291.0, 47.8644
28.274591184, 96.390, 2244.0, 47.3709
28.327112315, 96.390, 2198.0, 46.8828
28.379633446, 96.390, 2291.0, 47.8644
28.432154576, 96.390, 2278.0, 47.7284
28.484675707, 96.390, 2253.0, 47.4658
28.537196838, 96.390, 2164.0, 46.5188
28.589717968, 96.390, 2254.0, 47.4763
28.642239099, 96.390, 2191.0, 46.8081
28.694760230, 96.390, 2135.0, 46.2061
28.747281361, 96.390, 2219.0, 47.1063
28.799802491, 96.390, 2238.0, 47.3075
28.852323622, 96.390, 2234.0, 47.2652
28.904844753, 96.390, 2186.0, 46.7547
28.957365883, 96.390, 2125.0, 46.0977
29.009887014, 96.390, 2127.0, 46.1194
29.062408145, 96.390, 2140.0, 46.2601
29.114929276, 96.390, 2223.0, 47.1487
29.167450406, 96.390, 2091.0, 45.7275
29.219971537, 96.390, 2222.0, 47.1381
29.272492668, 96.390, 2151.0, 46.3789
29.325013798, 96.390, 2165.0, 46.5296
29.377534929, 96.390, 2165.0, 46.5296
29.430056060, 96.390, 2206.0, 46.9681
29.482577191, 96.390, 2080.0, 45.6070
29.535098321, 96.390, 2135.0, 46.2061
29.587619452, 96.390, 2098.0, 45.8039
29.640140583, 96.390, 2164.0, 46.5188
29.692661713, 96.390, 2220.0, 47.1169
29.745182844, 96.390, 2217.0, 47.0850
29.797703975, 96.390, 2186.0, 46.7547
29.850225105, 96.390, 2169.0, 46.5725
29.902746236, 96.390, 2033.0, 45.0888
29.955267367, 96.390, 2151.0, 46.3789
30.007788498, 96.390, 2108.0, 45.9130
30.060309628, 96.390, 2104.0, 45.8694
30.112830759, 96.390, 2194.0, 46.8402
30.165351890, 96.390, 2071.0, 45.5082
30.217873020, 96.390, 2132.0, 46.1736
30.270394151, 96.390, 2075.0, 45.5522
30.322915282, 96.390, 2122.0, 46.0652
30.375436413, 96.390, 2113.0, 45.9674
30.427957543, 96.390, 2134.0, 46.1952
30.480478674, 96.390, 2121.0, 46.0543
30.532999805, 96.390, 2098.0, 45.8039
30.585520935, 96.390, 2167.0, 46.5510
30.638042066, 96.390, 2120.0, 46.0435
30.690563197, 96.390, 2065.0, 45.4423
30.743084328, 96.390, 2090.0, 45.7165
30.795605458, 96.390, 2076.0, 45.5631
30.848126589, 96.390, 2082.0, 45.6289
30.900647720, 96.390, 2130.0, 46.1519
30.953168850, 96.390, 2077.0, 45.5741
31.005689981, 96.390, 2037.0, 45.1331
31.058211112, 96.390, 2077.0, 45.5741
31.110732243, 96.390, 2062.0, 45.4093
31.163253373, 96.390, 2035.0, 45.1110
31.215774504, 96.390, 2024.0, 44.9889
31.268295635, 96.390, 2094.0, 45.7602
31.320816765, 96.390, 2018.0, 44.9222
31.373337896, 96.390, 2055.0, 45.3321
31.425859027, 96.390, 2068.0, 45.4753
31.478380157, 96.390, 1997.0, 44.6878
31.530901288, 96.390, 2087.0, 45.6837
31.583422419, 96.390, 1980.0, 44.4972
31.635943550, 96.390, 2173.0, 46.6154
31.688464680, 96.390, 1985.0, 44.5533
31.740985811, 96.390, 2038.0, 45.1442
31.793506942, 96.390, 1964.0, 44.3170
31.846028072, 96.390, 2036.0, 45.1221
31.898549203, 96.390, 2105.0, 45.8803
31.951070334, 96.390, 2057.0, 45.3542
32.003591465, 96.390, 1988.0, 44.5870
32.056112595, 96.390, 2034.0, 45.0999
32.108633726, 96.390, 1959.0, 44.2606
32.161154857, 96.390, 1870.0, 43.2435
32.213675987, 96.390, 2052.0, 45.2990
32.266197118, 96.390, 1953.0, 44.1928
32.318718249, 96.390, 1989.0, 44.5982
32.371239380, 96.390, 2018.0, 44.9222
32.423760510, 96.390, 2003.0, 44.7549
32.476281641, 96.390, 1959.0, 44.2606
32.528802772, 96.390, 1949.0, 44.1475
32.581323902, 96.390, 1974.0, 44.4297
32.633845033, 96.390, 1970.0, 44.3847
32.686366164, 96.390, 1870.0, 43.2435
32.738887295, 96.390, 2037.0, 45.1331
32.791408425, 96.390, 1893.0, 43.5086
32.843929556, 96.390, 2049.0, 45.2659
32.896450687, 96.390, 1887.0, 43.4396
32.948971817, 96.390, 1943.0, 44.0795
33.001492948, 96.390, 1884.0, 43.4051
33.054014079, 96.390, 1928.0, 43.9090
33.106535209, 96.390, 1926.0, 43.8862
33.159056340, 96.390, 1881.0, 43.3705
33.211577471, 96.390, 1933.0, 43.9659
33.264098602, 96.390, 1880.0, 43.3590
33.316619732, 96.390, 1873.0, 43.2782
33.369140863, 96.390, 1969.0, 44.3734
33.421661994, 96.390, 1922.0, 43.8406
33.474183124, 96.390, 1941.0, 44.0568
33.526704255, 96.390, 1956.0, 44.2267
33.579225386, 96.390, 1908.0, 43.6807
33.631746517, 96.390, 1922.0, 43.8406
33.684267647, 96.390, 1948.0, 44.1362
33.736788778, 96.390, 1955.0, 44.2154
33.789309909, 96.390, 2099.0, 45.8148
33.841831039, 96.390, 1949.0, 44.1475
33.894352170, 96.390, 1998.0, 44.6990
33.946873301, 96.390, 1920.0, 43.8178
33.999394432, 96.390, 1988.0, 44.5870
34.051915562, 96.390, 2107.0, 45.9021
34.104436693, 96.390, 2019.0, 44.9333
34.156957824, 96.390, 2041.0, 45.1774
34.209478954, 96.390, 2028.0, 45.0333
34.262000085, 96.390, 2077.0, 45.5741
34.314521216, 96.390, 2053.0, 45.3100
34.367042346, 96.390, 2095.0, 45.7712
34.419563477, 96.390, 2128.0, 46.1303
34.472084608, 96.390, 2096.0, 45.7821
34.524605739, 96.390, 2033.0, 45.0888
34.577126869, 96.390, 2162.0, 46.4973
34.629648000, 96.390, 2059.0, 45.3762
34.682169131, 96.390, 2079.0, 45.5961
34.734690261, 96.390, 2107.0, 45.9021
34.787211392, 96.390, 2098.0, 45.8039
34.839732523, 96.390, 2042.0, 45.1885
34.892253654, 96.390, 2159.0, 46.4650
34.944774784, 96.390, 2074.0, 45.5412
34.997295915, 96.390, 2026.0, 45.0111
35.049817046, 96.390, 2064.0, 45.4313
35.102338176, 96.390, 1960.0, 44.2719
35.154859307, 96.390, 2062.0, 45.4093
35.207380438, 96.390, 2112.0, 45.9565
35.259901569, 96.390, 2043.0, 45.1996
35.312422699, 96.390, 2120.0, 46.0435
35.364943830, 96.390, 2105.0, 45.8803
35.417464961, 96.390, 2038.0, 45.1442
35.469986091, 96.390, 2103.0, 45.8585
35.522507222, 96.390, 2083.0, 45.6399
35.575028353, 96.390, 2009.0, 44.8219
35.627549484, 96.390, 1969.0, 44.3734
35.680070614, 96.390, 1944.0, 44.0908
35.732591745, 96.390, 2055.0, 45.3321
35.785112876, 96.390, 1996.0, 44.6766
35.837634006, 96.390, 1995.0, 44.6654
35.890155137, 96.390, 2027.0, 45.0222
35.942676268, 96.390, 1982.0, 44.5197
35.995197398, 96.390, 2055.0, 45.3321
36.047718529, 96.390, 1971.0, 44.3959
36.100239660, 96.390, 1960.0, 44.2719
36.152760791, 96.390, 2001.0, 44.7325
36.205281921, 96.390, 1886.0, 43.4281
36.257803052, 96.390, 1881.0, 43.3705
36.310324183, 96.390, 2024.0, 44.9889
36.362845313, 96.390, 1919.0, 43.8064
36.415366444, 96.390, 1865.0, 43.1856
36.467887575, 96.390, 1860.0, 43.1277
36.520408706, 96.390, 1922.0, 43.8406
36.572929836, 96.390, 1844.0, 42.9418
36.625450967, 96.390, 1941.0, 44.0568
36.677972098, 96.390, 1893.0, 43.5086
36.730493228, 96.390, 1773.0, 42.1070
36.783014359, 96.390, 1829.0, 42.7668
36.835535490, 96.390, 1766.0, 42.0238
36.888056621, 96.390, 1834.0, 42.8252
36.940577751, 96.390, 1850.0, 43.0116
36.993098882, 96.390, 1794.0, 42.3556
37.045620013, 96.390, 1793.0, 42.3438
37.098141143, 96.390, 1708.0, 41.3280
37.150662274, 96.390, 1838.0, 42.8719
37.203183405, 96.390, 1732.0, 41.6173
37.255704535, 96.390, 1765.0, 42.0119
37.308225666, 96.390, 1802.0, 42.4500
37.360746797, 96.390, 1764.0, 42.0000
37.413267928, 96.390, 1730.0, 41.5933
37.465789058, 96.390, 1678.0, 40.9634
37.518310189, 96.390, 1701.0, 41.2432
37.570831320, 96.390, 1711.0, 41.3642
37.623352450, 96.390, 1675.0, 40.9268
37.675873581, 96.390, 1648.0, 40.5956
37.728394712, 96.390, 1653.0, 40.6571
37.780915843, 96.390, 1718.0, 41.4488
37.833436973, 96.390, 1704.0, 41.2795
37.885958104, 96.390, 1623.0, 40.2865
37.938479235, 96.390, 1720.0, 41.4729
37.991000365, 96.390, 1595.0, 39.9375
38.043521496, 96.390, 1627.0, 40.3361
38.096042627, 96.390, 1613.0, 40.1622
38.148563758, 96.390, 1669.0, 40.8534
38.201084888, 96.390, 1575.0, 39.6863
38.253606019, 96.390, 1634.0, 40.4228
38.306127150, 96.390, 1568.0, 39.5980
38.358648280, 96.390, 1567.0, 39.5854
38.411169411, 96.390, 1547.0, 39.3319
38.463690542, 96.390, 1560.0, 39.4968
38.516211673, 96.390, 1570.0, 39.6232
38.568732803, 96.390, 1593.0, 39.9124
38.621253934, 96.390, 1524.0, 39.0384
38.673775065, 96.390, 1531.0, 39.1280
38.726296195, 96.390, 1585.0, 39.8121
38.778817326, 96.390, 1640.0, 40.4969
38.831338457, 96.390, 1501.0, 38.7427
38.883859587, 96.390, 1460.0, 38.2099
38.936380718, 96.390, 1480.0, 38.4708
38.988901849, 96.390, 1525.0, 39.0512
39.041422980, 96.390, 1487.0, 38.5616
39.093944110, 96.390, 1469.0, 38.3275
39.146465241, 96.390, 1494.0, 38.6523
39.198986372, 96.390, 1400.0, 37.4166
39.251507502, 96.390, 1491.0, 38.6135
39.304028633, 96.390, 1520.0, 38.9872
39.356549764, 96.390, 1514.0, 38.9102
39.409070895, 96.390, 1482.0, 38.4968
39.461592025, 96.390, 1435.0, 37.8814
39.514113156, 96.390, 1429.0, 37.8021
39.566634287, 96.390, 1403.0, 37.4566
39.619155417, 96.390, 1414.0, 37.6032
39.671676548, 96.390, 1367.0, 36.9730
39.724197679, 96.390, 1443.0, 37.9868
39.776718810, 96.390, 1446.0, 38.0263
39.829239940, 96.390, 1422.0, 37.7094
39.881761071, 96.390, 1440.0, 37.9473
39.934282202, 96.390, 1398.0, 37.3898
39.986803332, 96.390, 1405.0, 37.4833
40.039324463, 96.390, 1427.0, 37.7757
40.091845594, 96.390, 1325.0, 36.4005
40.144366725, 96.390, 1535.0, 39.1791
40.196887855, 96.390, 1399.0, 37.4032
40.249408986, 96.390, 1360.0, 36.8782
40.301930117, 96.390, 1422.0, 37.7094
40.354451247, 96.390, 1315.0, 36.2629
40.406972378, 96.390, 1340.0, 36.6060
40.459493509, 96.390, 1368.0, 36.9865
40.512014639, 96.390, 1349.0, 36.7287
40.564535770, 96.390, 1344.0, 36.6606
40.617056901, 96.390, 1370.0, 37.0135
40.669578032, 96.390, 1387.0, 37.2424
40.722099162, 96.390, 1450.0, 38.0789
40.774620293, 96.390, 1401.0, 37.4299
40.827141424, 96.390, 1381.0, 37.1618
40.879662554, 96.390, 1321.0, 36.3456
40.932183685, 96.390, 1337.0, 36.5650
40.984704816, 96.390, 1351.0, 36.7560
41.037225947, 96.390, 1305.0, 36.1248
41.089747077, 96.390, 1347.0, 36.7015
41.142268208, 96.390, 1294.0, 35.9722
41.194789339, 96.390, 1413.0, 37.5899
41.247310469, 96.390, 1312.0, 36.2215
41.299831600, 96.390, 1292.0, 35.9444
41.352352731, 96.390, 1331.0, 36.4829
41.404873862, 96.390, 1340.0, 36.6060
41.457394992, 96.390, 1291.0, 35.9305
41.509916123, 96.390, 1294.0, 35.9722
41.562437254, 96.390, 1277.0, 35.7351
41.614958384, 96.390, 1335.0, 36.5377
41.667479515, 96.390, 1240.0, 35.2136
41.720000646, 96.390, 1306.0, 36.1386
41.772521776, 96.390, 1261.0, 35.5106
41.825042907, 96.390, 1276.0, 35.7211
41.877564038, 96.390, 1311.0, 36.2077
41.930085169, 96.390, 1348.0, 36.7151
41.982606299, 96.390, 1329.0, 36.4555
42.035127430, 96.390, 1348.0, 36.7151
42.087648561, 96.390, 1290.0, 35.9166
42.140169691, 96.390, 1329.0, 36.4555
42.192690822, 96.390, 1245.0, 35.2846
42.245211953, 96.390, 1309.0, 36.1801
42.297733084, 96.390, 1330.0, 36.4692
42.350254214, 96.390, 1298.0, 36.0278
42.402775345, 96.390, 1221.0, 34.9428
42.455296476, 96.390, 1352.0, 36.7696
42.507817606, 96.390, 1280.0, 35.7771
42.560338737, 96.390, 1285.0, 35.8469
42.612859868, 96.390, 1309.0, 36.1801
42.665380999, 96.390, 1327.0, 36.4280
42.717902129, 96.390, 1292.0, 35.9444
42.770423260, 96.390, 1277.0, 35.7351
42.822944391, 96.390, 1276.0, 35.7211
42.875465521, 96.390, 1336.0, 36.5513
42.927986652, 96.390, 1274.0, 35.6931
42.980507783, 96.390, 1295.0, 35.9861
43.033028914, 96.390, 1222.0, 34.9571
43.085550044, 96.390, 1293.0, 35.9583
43.138071175, 96.390, 1275.0, 35.7071
43.190592306, 96.390, 1259.0, 35.4824
43.243113436, 96.390, 1260.0, 35.4965
43.295634567, 96.390, 1252.0, 35.3836
43.348155698, 96.390, 1250.0, 35.3553
43.400676828, 96.390, 1268.0, 35.6090
43.453197959, 96.390, 1216.0, 34.8712
43.505719090, 96.390, 1273.0, 35.6791
43.558240221, 96.390, 1283.0, 35.8190
43.610761351, 96.390, 1245.0, 35.2846
43.663282482, 96.390, 1284.0, 35.8329
43.715803613, 96.390, 1266.0, 35.5809
43.768324743, 96.390, 1240.0, 35.2136
43.820845874, 96.390, 1317.0, 36.2905
43.873367005, 96.390, 1289.0, 35.9026
43.925888136, 96.390, 1303.0, 36.0971
43.978409266, 96.390, 1369.0, 37.0000
44.030930397, 96.390, 1299.0, 36.0416
44.083451528, 96.390, 1298.0, 36.0278
44.135972658, 96.390, 1361.0, 36.8917
44.188493789, 96.390, 1279.0, 35.7631
44.241014920, 96.390, 1339.0, 36.5923
44.293536051, 96.390, 1299.0, 36.0416
44.346057181, 96.390, 1311.0, 36.2077
44.398578312, 96.390, 1279.0, 35.7631
44.451099443, 96.390, 1211.0, 34.7994
44.503620573, 96.390, 1276.0, 35.7211
44.556141704, 96.390, 1287.0, 35.8748
44.608662835, 96.390, 1381.0, 37.1618
44.661183966, 96.390, 1297.0, 36.0139
44.713705096, 96.390, 1317.0, 36.2905
44.766226227, 96.390, 1296.0, 36.0000
44.818747358, 96.390, 1299.0, 36.0416
44.871268488, 96.390, 1299.0, 36.0416
44.923789619, 96.390, 1243.0, 35.2562
44.976310750, 96.390, 1296.0, 36.0000
45.028831880, 96.390, 1293.0, 35.9583
45.081353011, 96.390, 1289.0, 35.9026
45.133874142, 96.390, 1330.0, 36.4692
45.186395273, 96.390, 1306.0, 36.1386
45.238916403, 96.390, 1313.0, 36.2353
45.291437534, 96.390, 1322.0, 36.3593
45.343958665, 96.390, 1256.0, 35.4401
45.396479795, 96.390, 1261.0, 35.5106
45.449000926, 96.390, 1305.0, 36.1248
45.501522057, 96.390, 1263.0, 35.5387
45.554043188, 96.390, 1238.0, 35.1852
45.606564318, 96.390, 1275.0, 35.7071
45.659085449, 96.390, 1293.0, 35.9583
45.711606580, 96.390, 1304.0, 36.1109
45.764127710, 96.390, 1215.0, 34.8569
45.816648841, 96.390, 1307.0, 36.1525
45.869169972, 96.390, 1287.0, 35.8748
45.921691103, 96.390, 1244.0, 35.2704
45.974212233, 96.390, 1323.0, 36.3731
46.026733364, 96.390, 1255.0, 35.4260
46.079254495, 96.390, 1270.0, 35.6371
46.131775625, 96.390, 1229.0, 35.0571
46.184296756, 96.390, 1326.0, 36.4143
46.236817887, 96.390, 1225.0, 35.0000
46.289339017, 96.390, 1239.0, 35.1994
46.341860148, 96.390, 1271.0, 35.6511
46.394381279, 96.390, 1295.0, 35.9861
46.446902410, 96.390, 1250.0, 35.3553
46.499423540, 96.390, 1303.0, 36.0971
46.551944671, 96.390, 1333.0, 36.5103
46.604465802, 96.390, 1227.0, 35.0286
46.656986932, 96.390, 1245.0, 35.2846
46.709508063, 96.390, 1268.0, 35.6090
46.762029194, 96.390, 1259.0, 35.4824
46.814550325, 96.390, 1313.0, 36.2353
46.867071455, 96.390, 1273.0, 35.6791
46.919592586, 96.390, 1265.0, 35.5668
46.972113717, 96.390, 1308.0, 36.1663
47.024634847, 96.390, 1210.0, 34.7851
47.077155978, 96.390, 1162.0, 34.0881
47.129677109, 96.390, 1271.0, 35.6511
47.182198240, 96.390, 1235.0, 35.1426
47.234719370, 96.390, 1256.0, 35.4401
47.287240501, 96.390, 1208.0, 34.7563
47.339761632, 96.390, 1232.0, 35.0999
47.392282762, 96.390, 1201.0, 34.6554
47.444803893, 96.390, 1233.0, 35.1141
47.497325024, 96.390, 1140.0, 33.7639
47.549846155, 96.390, 1196.0, 34.5832
47.602367285, 96.390, 1138.0, 33.7343
47.654888416, 96.390, 1237.0, 35.1710
47.707409547, 96.390, 1169.0, 34.1906
47.759930677, 96.390, 1227.0, 35.0286
47.812451808, 96.390, 1288.0, 35.8887
47.864972939, 96.390, 1204.0, 34.6987
47.917494069, 96.390, 1286.0, 35.8608
47.970015200, 96.390, 1169.0, 34.1906
48.022536331, 96.390, 1191.0, 34.5109
48.075057462, 96.390, 1132.0, 33.6452
48.127578592, 96.390, 1247.0, 35.3129
48.180099723, 96.390, 1156.0, 34.0000
48.232620854, 96.390, 1216.0, 34.8712
48.285141984, 96.390, 1146.0, 33.8526
48.337663115, 96.390, 1140.0, 33.7639
48.390184246, 96.390, 1202.0, 34.6699
48.442705377, 96.390, 1218.0, 34.8999
48.495226507, 96.390, 1214.0, 34.8425
48.547747638, 96.390, 1148.0, 33.8821
48.600268769, 96.390, 1146.0, 33.8526
48.652789899, 96.390, 1103.0, 33.2114
48.705311030, 96.390, 1193.0, 34.5398
48.757832161, 96.390, 1120.0, 33.4664
48.810353292, 96.390, 1198.0, 34.6121
48.862874422, 96.390, 1156.0, 34.0000
48.915395553, 96.390, 1176.0, 34.2929
48.967916684, 96.390, 1057.0, 32.5115
49.020437814, 96.390, 1176.0, 34.2929
49.072958945, 96.390, 1130.0, 33.6155
49.125480076, 96.390, 1124.0, 33.5261
49.178001207, 96.390, 1116.0, 33.4066
49.230522337, 96.390, 1141.0, 33.7787
49.283043468, 96.390, 1167.0, 34.1614
49.335564599, 96.390, 1127.0, 33.5708
49.388085729, 96.390, 1176.0, 34.2929
49.440606860, 96.390, 1110.0, 33.3167
49.493127991, 96.390, 1180.0, 34.3511
49.545649121, 96.390, 1045.0, 32.3265
49.598170252, 96.390, 1108.0, 33.2866
49.650691383, 96.390, 1132.0, 33.6452
49.703212514, 96.390, 1086.0, 32.9545
49.755733644, 96.390, 1118.0, 33.4365
49.808254775, 96.390, 1094.0, 33.0757
49.860775906, 96.390, 1034.0, 32.1559
49.913297036, 96.390, 1100.0, 33.1662
49.965818167, 96.390, 1080.0, 32.8634
50.018339298, 96.390, 1100.0, 33.1662
50.070860429, 96.390, 1093.0, 33.0606
50.123381559, 96.390, 1052.0, 32.4345
50.175902690, 96.390, 1065.0, 32.6343
50.228423821, 96.390, 1082.0, 32.8938
50.280944951, 96.390, 1095.0, 33.0908
50.333466082, 96.390, 1099.0, 33.1512
50.385987213, 96.390, 1130.0, 33.6155
50.438508344, 96.390, 1089.0, 33.0000
50.491029474, 96.390, 1089.0, 33.0000
50.543550605, 96.390, 1046.0, 32.3419
50.596071736, 96.390, 1094.0, 33.0757
50.648592866, 96.390, 1025.0, 32.0156
50.701113997, 96.390, 1063.0, 32.6037
50.753635128, 96.390, 1020.0, 31.9374
50.806156258, 96.390, 1082.0, 32.8938
50.858677389, 96.390, 1054.0, 32.4654
50.911198520, 96.390, 1102.0, 33.1964
50.963719651, 96.390, 1043.0, 32.2955
51.016240781, 96.390, 1040.0, 32.2490
51.068761912, 96.390, 1042.0, 32.2800
51.121283043, 96.390, 1043.0, 32.2955
51.173804173, 96.390, 1043.0, 32.2955
51.226325304, 96.390, 1032.0, 32.1248
51.278846435, 96.390, 974.0, 31.2090
51.331367566, 96.390, 989.0, 31.4484
51.383888696, 96.390, 1030.0, 32.0936
51.436409827, 96.390, 982.0, 31.3369
51.488930958, 96.390, 1073.0, 32.7567
51.541452088, 96.390, 1021.0, 31.9531
51.593973219, 96.390, 1040.0, 32.2490
51.646494350, 96.390, 1036.0, 32.1870
51.699015481, 96.390, 1032.0, 32.1248
51.751536611, 96.390, 1043.0, 32.2955
51.804057742, 96.390, 1070.0, 32.7109
51.856578873, 96.390, 983.0, 31.3528
51.909100003, 96.390, 970.0, 31.1448
51.961621134, 96.390, 995.0, 31.5436
52.014142265, 96.390, 993.0, 31.5119
52.066663396, 96.390, 995.0, 31.5436
52.119184526, 96.390, 986.0, 31.4006
52.171705657, 96.390, 988.0, 31.4325
52.224226788, 96.390, 1032.0, 32.1248
52.276747918, 96.390, 1040.0, 32.2490
52.329269049, 96.390, 1093.0, 33.0606
52.381790180, 96.390, 1028.0, 32.0624
52.434311310, 96.390, 969.0, 31.1288
52.486832441, 96.390, 1015.0, 31.8591
52.539353572, 96.390, 951.0, 30.8383
52.591874703, 96.390, 1047.0, 32.3574
52.644395833, 96.390, 995.0, 31.5436
52.696916964, 96.390, 1008.0, 31.7490
52.749438095, 96.390, 978.0, 31.2730
52.801959225, 96.390, 1010.0, 31.7805
52.854480356, 96.390, 1019.0, 31.9218
52.907001487, 96.390, 953.0, 30.8707
52.959522618, 96.390, 978.0, 31.2730
53.012043748, 96.390, 1008.0, 31.7490
53.064564879, 96.390, 961.0, 31.0000
53.117086010, 96.390, 1014.0, 31.8434
53.169607140, 96.390, 922.0, 30.3645
53.222128271, 96.390, 955.0, 30.9031
53.274649402, 96.390, 978.0, 31.2730
53.327170533, 96.390, 943.0, 30.7083
53.379691663, 96.390, 959.0, 30.9677
53.432212794, 96.390, 878.0, 29.6311
53.484733925, 96.390, 963.0, 31.0322
53.537255055, 96.390, 935.0, 30.5778
53.589776186, 96.390, 914.0, 30.2324
53.642297317, 96.390, 946.0, 30.7571
53.694818448, 96.390, 940.0, 30.6594
53.747339578, 96.390, 951.0, 30.8383
53.799860709, 96.390, 962.0, 31.0161
53.852381840, 96.390, 997.0, 31.5753
53.904902970, 96.390, 965.0, 31.0644
53.957424101, 96.390, 1002.0, 31.6544
54.009945232, 96.390, 1064.0, 32.6190
54.062466362, 96.390, 915.0, 30.2490
54.114987493, 96.390, 953.0, 30.8707
54.167508624, 96.390, 939.0, 30.6431
54.220029755, 96.390, 936.0, 30.5941
54.272550885, 96.390, 958.0, 30.9516
54.325072016, 96.390, 957.0, 30.9354
54.377593147, 96.390, 970.0, 31.1448
54.430114277, 96.390, 913.0, 30.2159
54.482635408, 96.390, 957.0, 30.9354
54.535156539, 96.390, 938.0, 30.6268
54.587677670, 96.390, 927.0, 30.4467
54.640198800, 96.390, 884.0, 29.7321
54.692719931, 96.390, 954.0, 30.8869
54.745241062, 96.390, 902.0, 30.0333
54.797762192, 96.390, 959.0, 30.9677
54.850283323, 96.390, 955.0, 30.9031
54.902804454, 96.390, 982.0, 31.3369
54.955325585, 96.390, 1026.0, 32.0312
55.007846715, 96.390, 914.0, 30.2324
55.060367846, 96.390, 939.0, 30.6431
55.112888977, 96.390, 939.0, 30.6431
55.165410107, 96.390, 988.0, 31.4325
55.217931238, 96.390, 961.0, 31.0000
55.270452369, 96.390, 977.0, 31.2570
55.322973499, 96.390, 907.0, 30.1164
55.375494630, 96.390, 929.0, 30.4795
55.428015761, 96.390, 886.0, 29.7658
55.480536892, 96.390, 935.0, 30.5778
55.533058022, 96.390, 883.0, 29.7153
55.585579153, 96.390, 944.0, 30.7246
55.638100284, 96.390, 984.0, 31.3688
55.690621414, 96.390, 932.0, 30.5287
55.743142545, 96.390, 916.0, 30.2655
55.795663676, 96.390, 949.0, 30.8058
55.848184807, 96.390, 968.0, 31.1127
55.900705937, 96.390, 946.0, 30.7571
55.953227068, 96.390, 916.0, 30.2655
56.005748199, 96.390, 954.0, 30.8869
56.058269329, 96.390, 918.0, 30.2985
56.110790460, 96.390, 894.0, 29.8998
56.163311591, 96.390, 953.0, 30.8707
56.215832722, 96.390, 912.0, 30.1993
56.268353852, 96.390, 886.0, 29.7658
56.320874983, 96.390, 856.0, 29.2575
56.373396114, 96.390, 901.0, 30.0167
56.425917244, 96.390, 933.0, 30.5450
56.478438375, 96.390, 896.0, 29.9333
56.530959506, 96.390, 900.0, 30.0000
56.583480637, 96.390, 933.0, 30.5450
56.636001767, 96.390, 938.0, 30.6268
56.688522898, 96.390, 867.0, 29.4449
56.741044029, 96.390, 882.0, 29.6985
56.793565159, 96.390, 930.0, 30.4959
56.846086290, 96.390, 965.0, 31.0644
56.898607421, 96.390, 916.0, 30.2655
56.951128551, 96.390, 867.0, 29.4449
57.003649682, 96.390, 882.0, 29.6985
57.056170813, 96.390, 897.0, 29.9500
57.108691944, 96.390, 889.0, 29.8161
57.161213074, 96.390, 906.0, 30.0998
57.213734205, 96.390, 910.0, 30.1662
57.266255336, 96.390, 949.0, 30.8058
57.318776466, 96.390, 894.0, 29.8998
57.371297597, 96.390, 891.0, 29.8496
57.423818728, 96.390, 877.0, 29.6142
57.476339859, 96.390, 888.0, 29.7993
57.528860989, 96.390, 913.0, 30.2159
57.581382120, 96.390, 882.0, 29.6985
57.633903251, 96.390, 890.0, 29.8329
57.686424381, 96.390, 817.0, 28.5832
57.738945512, 96.390, 883.0, 29.7153
57.791466643, 96.390, 915.0, 30.2490
57.843987774, 96.390, 897.0, 29.9500
57.896508904, 96.390, 896.0, 29.9333
57.949030035, 96.390, 901.0, 30.0167
58.001551166, 96.390, 866.0, 29.4279
58.054072296, 96.390, 904.0, 30.0666
58.106593427, 96.390, 900.0, 30.0000
58.159114558, 96.390, 818.0, 28.6007
58.211635689, 96.390, 934.0, 30.5614
58.264156819, 96.390, 877.0, 29.6142
58.316677950, 96.390, 918.0, 30.2985
58.369199081, 96.390, 869.0, 29.4788
58.421720211, 96.390, 887.0, 29.7825
58.474241342, 96.390, 912.0, 30.1993
58.526762473, 96.390, 859.0, 29.3087
58.579283603, 96.390, 828.0, 28.7750
58.631804734, 96.390, 863.0, 29.3769
58.684325865, 96.390, 858.0, 29.2916
58.736846996, 96.390, 884.0, 29.7321
58.789368126, 96.390, 873.0, 29.5466
58.841889257, 96.390, 913.0, 30.2159
58.894410388, 96.390, 912.0, 30.1993
58.946931518, 96.390, 958.0, 30.9516
58.999452649, 96.390, 977.0, 31.2570
59.051973780, 96.390, 910.0, 30.1662
59.104494911, 96.390, 944.0, 30.7246
59.157016041, 96.390, 879.0, 29.6479
59.209537172, 96.390, 887.0, 29.7825
59.262058303, 96.390, 889.0, 29.8161
59.314579433, 96.390, 894.0, 29.8998
59.367100564, 96.390, 911.0, 30.1828
59.419621695, 96.390, 925.0, 30.4138
59.472142826, 96.390, 878.0, 29.6311
59.524663956, 96.390, 887.0, 29.7825
59.577185087, 96.390, 973.0, 31.1929
59.629706218, 96.390, 950.0, 30.8221
59.682227348, 96.390, 937.0, 30.6105
59.734748479, 96.390, 882.0, 29.6985
59.787269610, 96.390, 958.0, 30.9516
59.839790740, 96.390, 923.0, 30.3809
59.892311871, 96.390, 917.0, 30.2820
59.944833002, 96.390, 966.0, 31.0805
59.997354133, 96.390, 980.0, 31.3050
60.049875263, 96.390, 948.0, 30.7896
60.102396394, 96.390, 979.0, 31.2890
60.154917525, 96.390, 925.0, 30.4138
60.207438655, 96.390, 970.0, 31.1448
60.259959786, 96.390, 955.0, 30.9031
60.312480917, 96.390, 1058.0, 32.5269
60.365002048, 96.390, 1037.0, 32.2025
60.417523178, 96.390, 1019.0, 31.9218
60.470044309, 96.390, 1045.0, 32.3265
60.522565440, 96.390, 1058.0, 32.5269
60.575086570, 96.390, 1049.0, 32.3883
60.627607701, 96.390, 1075.0, 32.7872
60.680128832, 96.390, 1120.0, 33.4664
60.732649963, 96.390, 1140.0, 33.7639
60.785171093, 96.390, 1150.0, 33.9116
60.837692224, 96.390, 1120.0, 33.4664
60.890213355, 96.390, 1160.0, 34.0588
60.942734485, 96.390, 1107.0, 33.2716
60.995255616, 96.390, 1185.0, 34.4238
61.047776747, 96.390, 1147.0, 33.8674
61.100297878, 96.390, 1168.0, 34.1760
61.152819008, 96.390, 1199.0, 34.6266
61.205340139, 96.390, 1181.0, 34.3657
61.257861270, 96.390, 1175.0, 34.2783
61.310382400, 96.390, 1183.0, 34.3948
61.362903531, 96.390, 1190.0, 34.4964
61.415424662, 96.390, 1191.0, 34.5109
61.467945792, 96.390, 1242.0, 35.2420
61.520466923, 96.390, 1136.0, 33.7046
61.572988054, 96.390, 1122.0, 33.4963
61.625509185, 96.390, 1157.0, 34.0147
61.678030315, 96.390, 1154.0, 33.9706
61.730551446, 96.390, 1110.0, 33.3167
61.783072577, 96.390, 1152.0, 33.9411
61.835593707, 96.390, 1078.0, 32.8329
61.888114838, 96.390, 1138.0, 33.7343
61.940635969, 96.390, 1127.0, 33.5708
61.993157100, 96.390, 1151.0, 33.9264
62.045678230, 96.390, 1146.0, 33.8526
62.098199361, 96.390, 1115.0, 33.3916
62.150720492, 96.390, 1114.0, 33.3766
62.203241622, 96.390, 1121.0, 33.4813
62.255762753, 96.390, 1091.0, 33.0303
62.308283884, 96.390, 1114.0, 33.3766
62.360805015, 96.390, 1069.0, 32.6956
62.413326145, 96.390, 1121.0, 33.4813
62.465847276, 96.390, 1069.0, 32.6956
62.518368407, 96.390, 1048.0, 32.3728
62.570889537, 96.390, 1033.0, 32.1403
62.623410668, 96.390, 1042.0, 32.2800
62.675931799, 96.390, 1069.0, 32.6956
62.728452930, 96.390, 1015.0, 31.8591
62.780974060, 96.390, 1031.0, 32.1092
62.833495191, 96.390, 1005.0, 31.7017
62.886016322, 96.390, 1016.0, 31.8748
62.938537452, 96.390, 1018.0, 31.9061
62.991058583, 96.390, 1041.0, 32.2645
63.043579714, 96.390, 974.0, 31.2090
63.096100844, 96.390, 953.0, 30.8707
63.148621975, 96.390, 901.0, 30.0167
63.201143106, 96.390, 1020.0, 31.9374
63.253664237, 96.390, 957.0, 30.9354
63.306185367, 96.390, 934.0, 30.5614
63.358706498, 96.390, 934.0, 30.5614
63.411227629, 96.390, 933.0, 30.5450
63.463748759, 96.390, 864.0, 29.3939
63.516269890, 96.390, 963.0, 31.0322
63.568791021, 96.390, 910.0, 30.1662
63.621312152, 96.390, 865.0, 29.4109
63.673833282, 96.390, 975.0, 31.2250
63.726354413, 96.390, 915.0, 30.2490
63.778875544, 96.390, 848.0, 29.1204
63.831396674, 96.390, 948.0, 30.7896
63.883917805, 96.390, 873.0, 29.5466
63.936438936, 96.390, 922.0, 30.3645
63.988960067, 96.390, 907.0, 30.1164
64.041481197, 96.390, 877.0, 29.6142
64.094002328, 96.390, 826.0, 28.7402
64.146523459, 96.390, 884.0, 29.7321
64.199044589, 96.390, 885.0, 29.7489
64.251565720, 96.390, 857.0, 29.2746
64.304086851, 96.390, 824.0, 28.7054
64.356607981, 96.390, 837.0, 28.9310
64.409129112, 96.390, 864.0, 29.3939
64.461650243, 96.390, 872.0, 29.5296
64.514171374, 96.390, 836.0, 28.9137
64.566692504, 96.390, 815.0, 28.5482
64.619213635, 96.390, 886.0, 29.7658
64.671734766, 96.390, 808.0, 28.4253
64.724255896, 96.390, 837.0, 28.9310
64.776777027, 96.390, 832.0, 28.8444
64.829298158, 96.390, 838.0, 28.9482
64.881819289, 96.390, 793.0, 28.1603
64.934340419, 96.390, 799.0, 28.2666
64.986861550, 96.390, 810.0, 28.4605