File: Files_organized_for_plots/Constant_NaOH_half_mL10M_to_1gPC/XRD_MgAxial24Jan22_Act21Feb22_B2_0362M_NaOH_LS0149_1.csv
[Measurement conditions]
Sample identification,XRD_MgAxial24Jan22_Act21Feb22_B2_0362M_NaOH_LS0149_1
Comment - 1,"Configuration=Stage for Flat Samples/Holders, Owner=User-1, Creation date=7/1/2020 9:53:24 AM"
Comment - 2,"Goniometer=Theta/Theta; Minimum step size 2Theta:0.0001; Minimum step size Omega:0.0001"
Comment - 3,"Sample stage=Stage for flat samples/holders"
Comment - 4,"Diffractometer system=EMPYREAN"
Comment - 5,"Measurement program=C:\Users\ibo5034\OneDrive - The Pennsylvania State University\NEUP - Reed, Titus's files\XRD\Cement\Zerobackground scan.xrdmp, Identifier={98A3B11C-88F9-4AA6-982C-73314A311EF5}"
Anode material,Cu
K-Alpha1 wavelength,1.5405980
K-Alpha2 wavelength,1.5444260
Ratio K-Alpha2/K-Alpha1,0.500
Divergence slit,Fixed,0.25
Monochromator used,NO
Generator voltage, 45
Tube current, 40
File date and time,24/Feb/2022 13:10
Unit cell,
h k l, 0 0 0
Scan axis,Gonio
Scan range,4.994599997,64.999991833
Scan step size,0.0262606
No. of points, 2285
Scan type,CONTINUOUS
Time per step,96.390
[Scan points]
Angle, TimePerStep, Intensity, ESD
5.007730280, 96.390, 5314.0, 72.8972
5.060251411, 96.390, 5247.0, 72.4362
5.112772541, 96.390, 5299.0, 72.7942
5.165293672, 96.390, 5026.0, 70.8943
5.217814803, 96.390, 5149.0, 71.7565
5.270335934, 96.390, 4958.0, 70.4131
5.322857064, 96.390, 4973.0, 70.5195
5.375378195, 96.390, 4964.0, 70.4557
5.427899326, 96.390, 4941.0, 70.2922
5.480420456, 96.390, 5038.0, 70.9789
5.532941587, 96.390, 4929.0, 70.2068
5.585462718, 96.390, 4737.0, 68.8259
5.637983849, 96.390, 4759.0, 68.9855
5.690504979, 96.390, 4807.0, 69.3325
5.743026110, 96.390, 4724.0, 68.7314
5.795547241, 96.390, 4651.0, 68.1982
5.848068371, 96.390, 4769.0, 69.0579
5.900589502, 96.390, 4693.0, 68.5055
5.953110633, 96.390, 4666.0, 68.3081
6.005631763, 96.390, 4705.0, 68.5930
6.058152894, 96.390, 4735.0, 68.8113
6.110674025, 96.390, 4713.0, 68.6513
6.163195156, 96.390, 4373.0, 66.1287
6.215716286, 96.390, 4653.0, 68.2129
6.268237417, 96.390, 4693.0, 68.5055
6.320758548, 96.390, 4558.0, 67.5130
6.373279678, 96.390, 4572.0, 67.6166
6.425800809, 96.390, 4488.0, 66.9925
6.478321940, 96.390, 4528.0, 67.2904
6.530843071, 96.390, 4352.0, 65.9697
6.583364201, 96.390, 4309.0, 65.6430
6.635885332, 96.390, 4287.0, 65.4752
6.688406463, 96.390, 4268.0, 65.3299
6.740927593, 96.390, 4357.0, 66.0076
6.793448724, 96.390, 4408.0, 66.3928
6.845969855, 96.390, 4279.0, 65.4141
6.898490986, 96.390, 4256.0, 65.2380
6.951012116, 96.390, 4339.0, 65.8711
7.003533247, 96.390, 4219.0, 64.9538
7.056054378, 96.390, 4262.0, 65.2840
7.108575508, 96.390, 4313.0, 65.6734
7.161096639, 96.390, 4275.0, 65.3835
7.213617770, 96.390, 4218.0, 64.9461
7.266138900, 96.390, 4129.0, 64.2573
7.318660031, 96.390, 4171.0, 64.5833
7.371181162, 96.390, 4225.0, 65.0000
7.423702293, 96.390, 4194.0, 64.7611
7.476223423, 96.390, 4183.0, 64.6761
7.528744554, 96.390, 4036.0, 63.5295
7.581265685, 96.390, 4053.0, 63.6632
7.633786815, 96.390, 3954.0, 62.8808
7.686307946, 96.390, 4023.0, 63.4271
7.738829077, 96.390, 4161.0, 64.5058
7.791350208, 96.390, 4054.0, 63.6710
7.843871338, 96.390, 4093.0, 63.9766
7.896392469, 96.390, 3991.0, 63.1744
7.948913600, 96.390, 4010.0, 63.3246
8.001434730, 96.390, 4057.0, 63.6946
8.053955861, 96.390, 4079.0, 63.8670
8.106476992, 96.390, 3983.0, 63.1110
8.158998123, 96.390, 4005.0, 63.2851
8.211519253, 96.390, 4039.0, 63.5531
8.264040384, 96.390, 3920.0, 62.6099
8.316561515, 96.390, 3972.0, 63.0238
8.369082645, 96.390, 4151.0, 64.4283
8.421603776, 96.390, 3942.0, 62.7853
8.474124907, 96.390, 3998.0, 63.2297
8.526646038, 96.390, 3950.0, 62.8490
8.579167168, 96.390, 3961.0, 62.9365
8.631688299, 96.390, 3903.0, 62.4740
8.684209430, 96.390, 3843.0, 61.9919
8.736730560, 96.390, 3927.0, 62.6658
8.789251691, 96.390, 3774.0, 61.4329
8.841772822, 96.390, 3847.0, 62.0242
8.894293952, 96.390, 3806.0, 61.6928
8.946815083, 96.390, 3820.0, 61.8061
8.999336214, 96.390, 3912.0, 62.5460
9.051857345, 96.390, 3863.0, 62.1530
9.104378475, 96.390, 3819.0, 61.7981
9.156899606, 96.390, 3731.0, 61.0819
9.209420737, 96.390, 3757.0, 61.2944
9.261941867, 96.390, 3911.0, 62.5380
9.314462998, 96.390, 3790.0, 61.5630
9.366984129, 96.390, 3661.0, 60.5062
9.419505260, 96.390, 3857.0, 62.1048
9.472026390, 96.390, 3794.0, 61.5955
9.524547521, 96.390, 3782.0, 61.4980
9.577068652, 96.390, 3909.0, 62.5220
9.629589782, 96.390, 3886.0, 62.3378
9.682110913, 96.390, 3894.0, 62.4019
9.734632044, 96.390, 3790.0, 61.5630
9.787153175, 96.390, 3875.0, 62.2495
9.839674305, 96.390, 3818.0, 61.7900
9.892195436, 96.390, 3879.0, 62.2816
9.944716567, 96.390, 3608.0, 60.0666
9.997237697, 96.390, 3788.0, 61.5467
10.049758828, 96.390, 3943.0, 62.7933
10.102279959, 96.390, 3899.0, 62.4420
10.154801090, 96.390, 3723.0, 61.0164
10.207322220, 96.390, 3825.0, 61.8466
10.259843351, 96.390, 3842.0, 61.9839
10.312364482, 96.390, 3866.0, 62.1772
10.364885612, 96.390, 3682.0, 60.6795
10.417406743, 96.390, 3680.0, 60.6630
10.469927874, 96.390, 3788.0, 61.5467
10.522449004, 96.390, 3829.0, 61.8789
10.574970135, 96.390, 3828.0, 61.8708
10.627491266, 96.390, 3761.0, 61.3270
10.680012397, 96.390, 3848.0, 62.0322
10.732533527, 96.390, 3857.0, 62.1048
10.785054658, 96.390, 3692.0, 60.7618
10.837575789, 96.390, 3757.0, 61.2944
10.890096919, 96.390, 3705.0, 60.8687
10.942618050, 96.390, 3624.0, 60.1997
10.995139181, 96.390, 3800.0, 61.6441
11.047660312, 96.390, 3624.0, 60.1997
11.100181442, 96.390, 3626.0, 60.2163
11.152702573, 96.390, 3648.0, 60.3987
11.205223704, 96.390, 3640.0, 60.3324
11.257744834, 96.390, 3758.0, 61.3025
11.310265965, 96.390, 3669.0, 60.5723
11.362787096, 96.390, 3704.0, 60.8605
11.415308227, 96.390, 3606.0, 60.0500
11.467829357, 96.390, 3706.0, 60.8769
11.520350488, 96.390, 3525.0, 59.3717
11.572871619, 96.390, 3433.0, 58.5918
11.625392749, 96.390, 3585.0, 59.8749
11.677913880, 96.390, 3389.0, 58.2151
11.730435011, 96.390, 3505.0, 59.2030
11.782956141, 96.390, 3530.0, 59.4138
11.835477272, 96.390, 3555.0, 59.6238
11.887998403, 96.390, 3396.0, 58.2752
11.940519534, 96.390, 3297.0, 57.4195
11.993040664, 96.390, 3397.0, 58.2838
12.045561795, 96.390, 3296.0, 57.4108
12.098082926, 96.390, 3266.0, 57.1489
12.150604056, 96.390, 3201.0, 56.5774
12.203125187, 96.390, 3191.0, 56.4889
12.255646318, 96.390, 3226.0, 56.7979
12.308167449, 96.390, 3111.0, 55.7763
12.360688579, 96.390, 3258.0, 57.0789
12.413209710, 96.390, 3178.0, 56.3738
12.465730841, 96.390, 3005.0, 54.8179
12.518251971, 96.390, 3048.0, 55.2087
12.570773102, 96.390, 3068.0, 55.3895
12.623294233, 96.390, 3029.0, 55.0364
12.675815364, 96.390, 2851.0, 53.3948
12.728336494, 96.390, 3037.0, 55.1090
12.780857625, 96.390, 3073.0, 55.4346
12.833378756, 96.390, 2902.0, 53.8702
12.885899886, 96.390, 2910.0, 53.9444
12.938421017, 96.390, 2844.0, 53.3292
12.990942148, 96.390, 2900.0, 53.8516
13.043463279, 96.390, 2857.0, 53.4509
13.095984409, 96.390, 2806.0, 52.9717
13.148505540, 96.390, 2756.0, 52.4976
13.201026671, 96.390, 2745.0, 52.3927
13.253547801, 96.390, 2779.0, 52.7162
13.306068932, 96.390, 2745.0, 52.3927
13.358590063, 96.390, 2726.0, 52.2111
13.411111193, 96.390, 2711.0, 52.0673
13.463632324, 96.390, 2627.0, 51.2543
13.516153455, 96.390, 2629.0, 51.2738
13.568674586, 96.390, 2612.0, 51.1077
13.621195716, 96.390, 2614.0, 51.1273
13.673716847, 96.390, 2676.0, 51.7301
13.726237978, 96.390, 2611.0, 51.0979
13.778759108, 96.390, 2566.0, 50.6557
13.831280239, 96.390, 2565.0, 50.6458
13.883801370, 96.390, 2544.0, 50.4381
13.936322501, 96.390, 2527.0, 50.2693
13.988843631, 96.390, 2500.0, 50.0000
14.041364762, 96.390, 2477.0, 49.7695
14.093885893, 96.390, 2434.0, 49.3356
14.146407023, 96.390, 2532.0, 50.3190
14.198928154, 96.390, 2369.0, 48.6724
14.251449285, 96.390, 2453.0, 49.5278
14.303970416, 96.390, 2467.0, 49.6689
14.356491546, 96.390, 2428.0, 49.2747
14.409012677, 96.390, 2405.0, 49.0408
14.461533808, 96.390, 2383.0, 48.8160
14.514054938, 96.390, 2422.0, 49.2138
14.566576069, 96.390, 2396.0, 48.9490
14.619097200, 96.390, 2360.0, 48.5798
14.671618331, 96.390, 2348.0, 48.4562
14.724139461, 96.390, 2359.0, 48.5695
14.776660592, 96.390, 2350.0, 48.4768
14.829181723, 96.390, 2358.0, 48.5592
14.881702853, 96.390, 2254.0, 47.4763
14.934223984, 96.390, 2400.0, 48.9898
14.986745115, 96.390, 2348.0, 48.4562
15.039266245, 96.390, 2238.0, 47.3075
15.091787376, 96.390, 2247.0, 47.4025
15.144308507, 96.390, 2248.0, 47.4131
15.196829638, 96.390, 2278.0, 47.7284
15.249350768, 96.390, 2327.0, 48.2390
15.301871899, 96.390, 2319.0, 48.1560
15.354393030, 96.390, 2272.0, 47.6655
15.406914160, 96.390, 2248.0, 47.4131
15.459435291, 96.390, 2249.0, 47.4236
15.511956422, 96.390, 2248.0, 47.4131
15.564477553, 96.390, 2327.0, 48.2390
15.616998683, 96.390, 2236.0, 47.2864
15.669519814, 96.390, 2235.0, 47.2758
15.722040945, 96.390, 2229.0, 47.2123
15.774562075, 96.390, 2267.0, 47.6130
15.827083206, 96.390, 2198.0, 46.8828
15.879604337, 96.390, 2204.0, 46.9468
15.932125468, 96.390, 2279.0, 47.7389
15.984646598, 96.390, 2222.0, 47.1381
16.037167729, 96.390, 2180.0, 46.6905
16.089688860, 96.390, 2158.0, 46.4543
16.142209990, 96.390, 2246.0, 47.3920
16.194731121, 96.390, 2210.0, 47.0106
16.247252252, 96.390, 2217.0, 47.0850
16.299773382, 96.390, 2125.0, 46.0977
16.352294513, 96.390, 2230.0, 47.2229
16.404815644, 96.390, 2249.0, 47.4236
16.457336775, 96.390, 2180.0, 46.6905
16.509857905, 96.390, 2175.0, 46.6369
16.562379036, 96.390, 2245.0, 47.3814
16.614900167, 96.390, 2220.0, 47.1169
16.667421297, 96.390, 2143.0, 46.2925
16.719942428, 96.390, 2200.0, 46.9042
16.772463559, 96.390, 2202.0, 46.9255
16.824984690, 96.390, 2173.0, 46.6154
16.877505820, 96.390, 2129.0, 46.1411
16.930026951, 96.390, 2276.0, 47.7074
16.982548082, 96.390, 2167.0, 46.5510
17.035069212, 96.390, 2203.0, 46.9361
17.087590343, 96.390, 2234.0, 47.2652
17.140111474, 96.390, 2202.0, 46.9255
17.192632605, 96.390, 2165.0, 46.5296
17.245153735, 96.390, 2186.0, 46.7547
17.297674866, 96.390, 2208.0, 46.9894
17.350195997, 96.390, 2249.0, 47.4236
17.402717127, 96.390, 2197.0, 46.8722
17.455238258, 96.390, 2259.0, 47.5289
17.507759389, 96.390, 2223.0, 47.1487
17.560280520, 96.390, 2220.0, 47.1169
17.612801650, 96.390, 2296.0, 47.9166
17.665322781, 96.390, 2200.0, 46.9042
17.717843912, 96.390, 2216.0, 47.0744
17.770365042, 96.390, 2303.0, 47.9896
17.822886173, 96.390, 2231.0, 47.2335
17.875407304, 96.390, 2209.0, 47.0000
17.927928434, 96.390, 2233.0, 47.2546
17.980449565, 96.390, 2257.0, 47.5079
18.032970696, 96.390, 2313.0, 48.0937
18.085491827, 96.390, 2278.0, 47.7284
18.138012957, 96.390, 2339.0, 48.3632
18.190534088, 96.390, 2213.0, 47.0425
18.243055219, 96.390, 2277.0, 47.7179
18.295576349, 96.390, 2294.0, 47.8957
18.348097480, 96.390, 2239.0, 47.3181
18.400618611, 96.390, 2331.0, 48.2804
18.453139742, 96.390, 2367.0, 48.6518
18.505660872, 96.390, 2288.0, 47.8330
18.558182003, 96.390, 2384.0, 48.8262
18.610703134, 96.390, 2342.0, 48.3942
18.663224264, 96.390, 2288.0, 47.8330
18.715745395, 96.390, 2300.0, 47.9583
18.768266526, 96.390, 2400.0, 48.9898
18.820787657, 96.390, 2365.0, 48.6313
18.873308787, 96.390, 2423.0, 49.2240
18.925829918, 96.390, 2375.0, 48.7340
18.978351049, 96.390, 2345.0, 48.4252
19.030872179, 96.390, 2325.0, 48.2183
19.083393310, 96.390, 2432.0, 49.3153
19.135914441, 96.390, 2341.0, 48.3839
19.188435572, 96.390, 2436.0, 49.3559
19.240956702, 96.390, 2439.0, 49.3862
19.293477833, 96.390, 2374.0, 48.7237
19.345998964, 96.390, 2425.0, 49.2443
19.398520094, 96.390, 2370.0, 48.6826
19.451041225, 96.390, 2338.0, 48.3529
19.503562356, 96.390, 2412.0, 49.1121
19.556083486, 96.390, 2543.0, 50.4282
19.608604617, 96.390, 2427.0, 49.2646
19.661125748, 96.390, 2492.0, 49.9199
19.713646879, 96.390, 2404.0, 49.0306
19.766168009, 96.390, 2488.0, 49.8799
19.818689140, 96.390, 2510.0, 50.0999
19.871210271, 96.390, 2431.0, 49.3052
19.923731401, 96.390, 2576.0, 50.7543
19.976252532, 96.390, 2555.0, 50.5470
20.028773663, 96.390, 2516.0, 50.1597
20.081294794, 96.390, 2583.0, 50.8232
20.133815924, 96.390, 2624.0, 51.2250
20.186337055, 96.390, 2608.0, 51.0686
20.238858186, 96.390, 2585.0, 50.8429
20.291379316, 96.390, 2537.0, 50.3686
20.343900447, 96.390, 2652.0, 51.4976
20.396421578, 96.390, 2568.0, 50.6754
20.448942709, 96.390, 2571.0, 50.7050
20.501463839, 96.390, 2586.0, 50.8527
20.553984970, 96.390, 2734.0, 52.2877
20.606506101, 96.390, 2593.0, 50.9215
20.659027231, 96.390, 2574.0, 50.7346
20.711548362, 96.390, 2717.0, 52.1249
20.764069493, 96.390, 2621.0, 51.1957
20.816590623, 96.390, 2637.0, 51.3517
20.869111754, 96.390, 2652.0, 51.4976
20.921632885, 96.390, 2707.0, 52.0288
20.974154016, 96.390, 2679.0, 51.7591
21.026675146, 96.390, 2695.0, 51.9134
21.079196277, 96.390, 2677.0, 51.7397
21.131717408, 96.390, 2669.0, 51.6624
21.184238538, 96.390, 2657.0, 51.5461
21.236759669, 96.390, 2678.0, 51.7494
21.289280800, 96.390, 2676.0, 51.7301
21.341801931, 96.390, 2688.0, 51.8459
21.394323061, 96.390, 2832.0, 53.2165
21.446844192, 96.390, 2700.0, 51.9615
21.499365323, 96.390, 2619.0, 51.1762
21.551886453, 96.390, 2927.0, 54.1018
21.604407584, 96.390, 2794.0, 52.8583
21.656928715, 96.390, 2804.0, 52.9528
21.709449846, 96.390, 2823.0, 53.1319
21.761970976, 96.390, 2911.0, 53.9537
21.814492107, 96.390, 2795.0, 52.8678
21.867013238, 96.390, 2757.0, 52.5071
21.919534368, 96.390, 2887.0, 53.7308
21.972055499, 96.390, 2938.0, 54.2033
22.024576630, 96.390, 2808.0, 52.9906
22.077097761, 96.390, 2841.0, 53.3010
22.129618891, 96.390, 2779.0, 52.7162
22.182140022, 96.390, 2808.0, 52.9906
22.234661153, 96.390, 2721.0, 52.1632
22.287182283, 96.390, 2827.0, 53.1695
22.339703414, 96.390, 2868.0, 53.5537
22.392224545, 96.390, 2870.0, 53.5724
22.444745675, 96.390, 3003.0, 54.7996
22.497266806, 96.390, 2872.0, 53.5910
22.549787937, 96.390, 2813.0, 53.0377
22.602309068, 96.390, 2719.0, 52.1440
22.654830198, 96.390, 2807.0, 52.9811
22.707351329, 96.390, 2865.0, 53.5257
22.759872460, 96.390, 2775.0, 52.6783
22.812393590, 96.390, 2702.0, 51.9808
22.864914721, 96.390, 2817.0, 53.0754
22.917435852, 96.390, 2869.0, 53.5630
22.969956983, 96.390, 2823.0, 53.1319
23.022478113, 96.390, 2800.0, 52.9150
23.074999244, 96.390, 2762.0, 52.5547
23.127520375, 96.390, 2832.0, 53.2165
23.180041505, 96.390, 2796.0, 52.8772
23.232562636, 96.390, 2766.0, 52.5928
23.285083767, 96.390, 2826.0, 53.1601
23.337604898, 96.390, 2672.0, 51.6914
23.390126028, 96.390, 2677.0, 51.7397
23.442647159, 96.390, 2634.0, 51.3225
23.495168290, 96.390, 2820.0, 53.1037
23.547689420, 96.390, 2657.0, 51.5461
23.600210551, 96.390, 2616.0, 51.1468
23.652731682, 96.390, 2667.0, 51.6430
23.705252813, 96.390, 2592.0, 50.9117
23.757773943, 96.390, 2559.0, 50.5866
23.810295074, 96.390, 2657.0, 51.5461
23.862816205, 96.390, 2569.0, 50.6853
23.915337335, 96.390, 2484.0, 49.8397
23.967858466, 96.390, 2634.0, 51.3225
24.020379597, 96.390, 2526.0, 50.2593
24.072900727, 96.390, 2527.0, 50.2693
24.125421858, 96.390, 2522.0, 50.2195
24.177942989, 96.390, 2519.0, 50.1896
24.230464120, 96.390, 2533.0, 50.3289
24.282985250, 96.390, 2431.0, 49.3052
24.335506381, 96.390, 2556.0, 50.5569
24.388027512, 96.390, 2474.0, 49.7393
24.440548642, 96.390, 2437.0, 49.3660
24.493069773, 96.390, 2507.0, 50.0700
24.545590904, 96.390, 2416.0, 49.1528
24.598112035, 96.390, 2375.0, 48.7340
24.650633165, 96.390, 2377.0, 48.7545
24.703154296, 96.390, 2470.0, 49.6991
24.755675427, 96.390, 2329.0, 48.2597
24.808196557, 96.390, 2333.0, 48.3011
24.860717688, 96.390, 2337.0, 48.3425
24.913238819, 96.390, 2252.0, 47.4552
24.965759950, 96.390, 2317.0, 48.1352
25.018281080, 96.390, 2226.0, 47.1805
25.070802211, 96.390, 2340.0, 48.3735
25.123323342, 96.390, 2227.0, 47.1911
25.175844472, 96.390, 2279.0, 47.7389
25.228365603, 96.390, 2152.0, 46.3897
25.280886734, 96.390, 2262.0, 47.5605
25.333407864, 96.390, 2283.0, 47.7807
25.385928995, 96.390, 2183.0, 46.7226
25.438450126, 96.390, 2292.0, 47.8748
25.490971257, 96.390, 2274.0, 47.6865
25.543492387, 96.390, 2228.0, 47.2017
25.596013518, 96.390, 2133.0, 46.1844
25.648534649, 96.390, 2268.0, 47.6235
25.701055779, 96.390, 2138.0, 46.2385
25.753576910, 96.390, 2173.0, 46.6154
25.806098041, 96.390, 2208.0, 46.9894
25.858619172, 96.390, 2171.0, 46.5940
25.911140302, 96.390, 2140.0, 46.2601
25.963661433, 96.390, 2210.0, 47.0106
26.016182564, 96.390, 2125.0, 46.0977
26.068703694, 96.390, 2240.0, 47.3286
26.121224825, 96.390, 2099.0, 45.8148
26.173745956, 96.390, 2210.0, 47.0106
26.226267087, 96.390, 2115.0, 45.9891
26.278788217, 96.390, 2060.0, 45.3872
26.331309348, 96.390, 2093.0, 45.7493
26.383830479, 96.390, 2151.0, 46.3789
26.436351609, 96.390, 2146.0, 46.3249
26.488872740, 96.390, 2103.0, 45.8585
26.541393871, 96.390, 2081.0, 45.6180
26.593915002, 96.390, 2074.0, 45.5412
26.646436132, 96.390, 2015.0, 44.8888
26.698957263, 96.390, 2022.0, 44.9667
26.751478394, 96.390, 2084.0, 45.6508
26.803999524, 96.390, 2154.0, 46.4112
26.856520655, 96.390, 2034.0, 45.0999
26.909041786, 96.390, 2098.0, 45.8039
26.961562916, 96.390, 2024.0, 44.9889
27.014084047, 96.390, 1930.0, 43.9318
27.066605178, 96.390, 2123.0, 46.0760
27.119126309, 96.390, 2004.0, 44.7661
27.171647439, 96.390, 2065.0, 45.4423
27.224168570, 96.390, 1990.0, 44.6094
27.276689701, 96.390, 2046.0, 45.2327
27.329210831, 96.390, 2064.0, 45.4313
27.381731962, 96.390, 2030.0, 45.0555
27.434253093, 96.390, 2099.0, 45.8148
27.486774224, 96.390, 2034.0, 45.0999
27.539295354, 96.390, 1990.0, 44.6094
27.591816485, 96.390, 2009.0, 44.8219
27.644337616, 96.390, 2022.0, 44.9667
27.696858746, 96.390, 1944.0, 44.0908
27.749379877, 96.390, 2013.0, 44.8665
27.801901008, 96.390, 2136.0, 46.2169
27.854422139, 96.390, 2038.0, 45.1442
27.906943269, 96.390, 1982.0, 44.5197
27.959464400, 96.390, 2015.0, 44.8888
28.011985531, 96.390, 2023.0, 44.9778
28.064506661, 96.390, 2014.0, 44.8776
28.117027792, 96.390, 2069.0, 45.4863
28.169548923, 96.390, 2029.0, 45.0444
28.222070054, 96.390, 1959.0, 44.2606
28.274591184, 96.390, 2032.0, 45.0777
28.327112315, 96.390, 1990.0, 44.6094
28.379633446, 96.390, 2009.0, 44.8219
28.432154576, 96.390, 2051.0, 45.2880
28.484675707, 96.390, 2107.0, 45.9021
28.537196838, 96.390, 2078.0, 45.5851
28.589717968, 96.390, 1949.0, 44.1475
28.642239099, 96.390, 2063.0, 45.4203
28.694760230, 96.390, 2020.0, 44.9444
28.747281361, 96.390, 1986.0, 44.5646
28.799802491, 96.390, 1953.0, 44.1928
28.852323622, 96.390, 1985.0, 44.5533
28.904844753, 96.390, 2060.0, 45.3872
28.957365883, 96.390, 1952.0, 44.1814
29.009887014, 96.390, 2039.0, 45.1553
29.062408145, 96.390, 2008.0, 44.8107
29.114929276, 96.390, 1964.0, 44.3170
29.167450406, 96.390, 2008.0, 44.8107
29.219971537, 96.390, 2125.0, 46.0977
29.272492668, 96.390, 1996.0, 44.6766
29.325013798, 96.390, 2096.0, 45.7821
29.377534929, 96.390, 2046.0, 45.2327
29.430056060, 96.390, 2115.0, 45.9891
29.482577191, 96.390, 2057.0, 45.3542
29.535098321, 96.390, 2119.0, 46.0326
29.587619452, 96.390, 2047.0, 45.2438
29.640140583, 96.390, 2055.0, 45.3321
29.692661713, 96.390, 2100.0, 45.8258
29.745182844, 96.390, 2077.0, 45.5741
29.797703975, 96.390, 1997.0, 44.6878
29.850225105, 96.390, 2025.0, 45.0000
29.902746236, 96.390, 2037.0, 45.1331
29.955267367, 96.390, 1999.0, 44.7102
30.007788498, 96.390, 2098.0, 45.8039
30.060309628, 96.390, 1993.0, 44.6430
30.112830759, 96.390, 2045.0, 45.2217
30.165351890, 96.390, 2029.0, 45.0444
30.217873020, 96.390, 2083.0, 45.6399
30.270394151, 96.390, 2035.0, 45.1110
30.322915282, 96.390, 2048.0, 45.2548
30.375436413, 96.390, 2020.0, 44.9444
30.427957543, 96.390, 1976.0, 44.4522
30.480478674, 96.390, 1977.0, 44.4635
30.532999805, 96.390, 2004.0, 44.7661
30.585520935, 96.390, 2033.0, 45.0888
30.638042066, 96.390, 1915.0, 43.7607
30.690563197, 96.390, 2009.0, 44.8219
30.743084328, 96.390, 1984.0, 44.5421
30.795605458, 96.390, 1953.0, 44.1928
30.848126589, 96.390, 2021.0, 44.9555
30.900647720, 96.390, 1966.0, 44.3396
30.953168850, 96.390, 2113.0, 45.9674
31.005689981, 96.390, 1982.0, 44.5197
31.058211112, 96.390, 1921.0, 43.8292
31.110732243, 96.390, 1956.0, 44.2267
31.163253373, 96.390, 2005.0, 44.7772
31.215774504, 96.390, 1923.0, 43.8520
31.268295635, 96.390, 1971.0, 44.3959
31.320816765, 96.390, 1920.0, 43.8178
31.373337896, 96.390, 1945.0, 44.1022
31.425859027, 96.390, 1985.0, 44.5533
31.478380157, 96.390, 1964.0, 44.3170
31.530901288, 96.390, 2066.0, 45.4533
31.583422419, 96.390, 1971.0, 44.3959
31.635943550, 96.390, 2043.0, 45.1996
31.688464680, 96.390, 1988.0, 44.5870
31.740985811, 96.390, 1889.0, 43.4626
31.793506942, 96.390, 1951.0, 44.1701
31.846028072, 96.390, 1971.0, 44.3959
31.898549203, 96.390, 1922.0, 43.8406
31.951070334, 96.390, 1980.0, 44.4972
32.003591465, 96.390, 1940.0, 44.0454
32.056112595, 96.390, 1977.0, 44.4635
32.108633726, 96.390, 1985.0, 44.5533
32.161154857, 96.390, 1936.0, 44.0000
32.213675987, 96.390, 1916.0, 43.7721
32.266197118, 96.390, 1867.0, 43.2088
32.318718249, 96.390, 1828.0, 42.7551
32.371239380, 96.390, 1831.0, 42.7902
32.423760510, 96.390, 1888.0, 43.4511
32.476281641, 96.390, 1963.0, 44.3058
32.528802772, 96.390, 1777.0, 42.1545
32.581323902, 96.390, 1949.0, 44.1475
32.633845033, 96.390, 1922.0, 43.8406
32.686366164, 96.390, 1879.0, 43.3474
32.738887295, 96.390, 1919.0, 43.8064
32.791408425, 96.390, 1914.0, 43.7493
32.843929556, 96.390, 1850.0, 43.0116
32.896450687, 96.390, 1827.0, 42.7434
32.948971817, 96.390, 1840.0, 42.8952
33.001492948, 96.390, 1900.0, 43.5890
33.054014079, 96.390, 1808.0, 42.5206
33.106535209, 96.390, 1865.0, 43.1856
33.159056340, 96.390, 1900.0, 43.5890
33.211577471, 96.390, 1857.0, 43.0929
33.264098602, 96.390, 1968.0, 44.3621
33.316619732, 96.390, 1829.0, 42.7668
33.369140863, 96.390, 1935.0, 43.9886
33.421661994, 96.390, 1986.0, 44.5646
33.474183124, 96.390, 1904.0, 43.6348
33.526704255, 96.390, 1936.0, 44.0000
33.579225386, 96.390, 1964.0, 44.3170
33.631746517, 96.390, 1948.0, 44.1362
33.684267647, 96.390, 2007.0, 44.7996
33.736788778, 96.390, 1918.0, 43.7950
33.789309909, 96.390, 1947.0, 44.1248
33.841831039, 96.390, 1965.0, 44.3283
33.894352170, 96.390, 1970.0, 44.3847
33.946873301, 96.390, 1987.0, 44.5758
33.999394432, 96.390, 2061.0, 45.3982
34.051915562, 96.390, 2147.0, 46.3357
34.104436693, 96.390, 2084.0, 45.6508
34.156957824, 96.390, 2074.0, 45.5412
34.209478954, 96.390, 2091.0, 45.7275
34.262000085, 96.390, 2234.0, 47.2652
34.314521216, 96.390, 2244.0, 47.3709
34.367042346, 96.390, 2284.0, 47.7912
34.419563477, 96.390, 2248.0, 47.4131
34.472084608, 96.390, 2293.0, 47.8853
34.524605739, 96.390, 2349.0, 48.4665
34.577126869, 96.390, 2279.0, 47.7389
34.629648000, 96.390, 2412.0, 49.1121
34.682169131, 96.390, 2353.0, 48.5077
34.734690261, 96.390, 2329.0, 48.2597
34.787211392, 96.390, 2462.0, 49.6185
34.839732523, 96.390, 2344.0, 48.4149
34.892253654, 96.390, 2359.0, 48.5695
34.944774784, 96.390, 2366.0, 48.6415
34.997295915, 96.390, 2427.0, 49.2646
35.049817046, 96.390, 2407.0, 49.0612
35.102338176, 96.390, 2358.0, 48.5592
35.154859307, 96.390, 2344.0, 48.4149
35.207380438, 96.390, 2306.0, 48.0208
35.259901569, 96.390, 2339.0, 48.3632
35.312422699, 96.390, 2369.0, 48.6724
35.364943830, 96.390, 2284.0, 47.7912
35.417464961, 96.390, 2313.0, 48.0937
35.469986091, 96.390, 2347.0, 48.4458
35.522507222, 96.390, 2278.0, 47.7284
35.575028353, 96.390, 2293.0, 47.8853
35.627549484, 96.390, 2301.0, 47.9687
35.680070614, 96.390, 2266.0, 47.6025
35.732591745, 96.390, 2212.0, 47.0319
35.785112876, 96.390, 2234.0, 47.2652
35.837634006, 96.390, 2205.0, 46.9574
35.890155137, 96.390, 2158.0, 46.4543
35.942676268, 96.390, 2240.0, 47.3286
35.995197398, 96.390, 2169.0, 46.5725
36.047718529, 96.390, 2162.0, 46.4973
36.100239660, 96.390, 2123.0, 46.0760
36.152760791, 96.390, 2192.0, 46.8188
36.205281921, 96.390, 2145.0, 46.3141
36.257803052, 96.390, 2050.0, 45.2769
36.310324183, 96.390, 2036.0, 45.1221
36.362845313, 96.390, 1985.0, 44.5533
36.415366444, 96.390, 2057.0, 45.3542
36.467887575, 96.390, 1906.0, 43.6578
36.520408706, 96.390, 2027.0, 45.0222
36.572929836, 96.390, 1972.0, 44.4072
36.625450967, 96.390, 1988.0, 44.5870
36.677972098, 96.390, 1952.0, 44.1814
36.730493228, 96.390, 2038.0, 45.1442
36.783014359, 96.390, 1958.0, 44.2493
36.835535490, 96.390, 1932.0, 43.9545
36.888056621, 96.390, 1963.0, 44.3058
36.940577751, 96.390, 1963.0, 44.3058
36.993098882, 96.390, 2046.0, 45.2327
37.045620013, 96.390, 1938.0, 44.0227
37.098141143, 96.390, 1898.0, 43.5660
37.150662274, 96.390, 1877.0, 43.3244
37.203183405, 96.390, 1949.0, 44.1475
37.255704535, 96.390, 1989.0, 44.5982
37.308225666, 96.390, 1914.0, 43.7493
37.360746797, 96.390, 1870.0, 43.2435
37.413267928, 96.390, 1880.0, 43.3590
37.465789058, 96.390, 1786.0, 42.2611
37.518310189, 96.390, 1834.0, 42.8252
37.570831320, 96.390, 1865.0, 43.1856
37.623352450, 96.390, 1815.0, 42.6028
37.675873581, 96.390, 1831.0, 42.7902
37.728394712, 96.390, 1806.0, 42.4971
37.780915843, 96.390, 1790.0, 42.3084
37.833436973, 96.390, 1884.0, 43.4051
37.885958104, 96.390, 1735.0, 41.6533
37.938479235, 96.390, 1847.0, 42.9767
37.991000365, 96.390, 1826.0, 42.7317
38.043521496, 96.390, 1833.0, 42.8135
38.096042627, 96.390, 1802.0, 42.4500
38.148563758, 96.390, 1832.0, 42.8019
38.201084888, 96.390, 1732.0, 41.6173
38.253606019, 96.390, 1740.0, 41.7133
38.306127150, 96.390, 1769.0, 42.0595
38.358648280, 96.390, 1774.0, 42.1189
38.411169411, 96.390, 1732.0, 41.6173
38.463690542, 96.390, 1818.0, 42.6380
38.516211673, 96.390, 1754.0, 41.8808
38.568732803, 96.390, 1752.0, 41.8569
38.621253934, 96.390, 1706.0, 41.3038
38.673775065, 96.390, 1698.0, 41.2068
38.726296195, 96.390, 1761.0, 41.9643
38.778817326, 96.390, 1702.0, 41.2553
38.831338457, 96.390, 1724.0, 41.5211
38.883859587, 96.390, 1704.0, 41.2795
38.936380718, 96.390, 1730.0, 41.5933
38.988901849, 96.390, 1672.0, 40.8901
39.041422980, 96.390, 1664.0, 40.7922
39.093944110, 96.390, 1625.0, 40.3113
39.146465241, 96.390, 1684.0, 41.0366
39.198986372, 96.390, 1696.0, 41.1825
39.251507502, 96.390, 1610.0, 40.1248
39.304028633, 96.390, 1669.0, 40.8534
39.356549764, 96.390, 1604.0, 40.0500
39.409070895, 96.390, 1632.0, 40.3980
39.461592025, 96.390, 1694.0, 41.1582
39.514113156, 96.390, 1621.0, 40.2616
39.566634287, 96.390, 1626.0, 40.3237
39.619155417, 96.390, 1625.0, 40.3113
39.671676548, 96.390, 1644.0, 40.5463
39.724197679, 96.390, 1728.0, 41.5692
39.776718810, 96.390, 1603.0, 40.0375
39.829239940, 96.390, 1642.0, 40.5216
39.881761071, 96.390, 1545.0, 39.3065
39.934282202, 96.390, 1595.0, 39.9375
39.986803332, 96.390, 1572.0, 39.6485
40.039324463, 96.390, 1529.0, 39.1024
40.091845594, 96.390, 1497.0, 38.6911
40.144366725, 96.390, 1583.0, 39.7869
40.196887855, 96.390, 1524.0, 39.0384
40.249408986, 96.390, 1564.0, 39.5474
40.301930117, 96.390, 1520.0, 38.9872
40.354451247, 96.390, 1514.0, 38.9102
40.406972378, 96.390, 1510.0, 38.8587
40.459493509, 96.390, 1547.0, 39.3319
40.512014639, 96.390, 1481.0, 38.4838
40.564535770, 96.390, 1529.0, 39.1024
40.617056901, 96.390, 1491.0, 38.6135
40.669578032, 96.390, 1570.0, 39.6232
40.722099162, 96.390, 1440.0, 37.9473
40.774620293, 96.390, 1512.0, 38.8844
40.827141424, 96.390, 1552.0, 39.3954
40.879662554, 96.390, 1489.0, 38.5876
40.932183685, 96.390, 1522.0, 39.0128
40.984704816, 96.390, 1503.0, 38.7685
41.037225947, 96.390, 1381.0, 37.1618
41.089747077, 96.390, 1420.0, 37.6829
41.142268208, 96.390, 1462.0, 38.2361
41.194789339, 96.390, 1399.0, 37.4032
41.247310469, 96.390, 1435.0, 37.8814
41.299831600, 96.390, 1453.0, 38.1182
41.352352731, 96.390, 1379.0, 37.1349
41.404873862, 96.390, 1372.0, 37.0405
41.457394992, 96.390, 1441.0, 37.9605
41.509916123, 96.390, 1422.0, 37.7094
41.562437254, 96.390, 1378.0, 37.1214
41.614958384, 96.390, 1420.0, 37.6829
41.667479515, 96.390, 1403.0, 37.4566
41.720000646, 96.390, 1391.0, 37.2961
41.772521776, 96.390, 1410.0, 37.5500
41.825042907, 96.390, 1369.0, 37.0000
41.877564038, 96.390, 1336.0, 36.5513
41.930085169, 96.390, 1389.0, 37.2693
41.982606299, 96.390, 1417.0, 37.6431
42.035127430, 96.390, 1359.0, 36.8646
42.087648561, 96.390, 1377.0, 37.1080
42.140169691, 96.390, 1326.0, 36.4143
42.192690822, 96.390, 1386.0, 37.2290
42.245211953, 96.390, 1346.0, 36.6879
42.297733084, 96.390, 1248.0, 35.3270
42.350254214, 96.390, 1326.0, 36.4143
42.402775345, 96.390, 1377.0, 37.1080
42.455296476, 96.390, 1392.0, 37.3095
42.507817606, 96.390, 1400.0, 37.4166
42.560338737, 96.390, 1388.0, 37.2559
42.612859868, 96.390, 1360.0, 36.8782
42.665380999, 96.390, 1372.0, 37.0405
42.717902129, 96.390, 1303.0, 36.0971
42.770423260, 96.390, 1357.0, 36.8375
42.822944391, 96.390, 1276.0, 35.7211
42.875465521, 96.390, 1405.0, 37.4833
42.927986652, 96.390, 1361.0, 36.8917
42.980507783, 96.390, 1373.0, 37.0540
43.033028914, 96.390, 1332.0, 36.4966
43.085550044, 96.390, 1315.0, 36.2629
43.138071175, 96.390, 1318.0, 36.3043
43.190592306, 96.390, 1376.0, 37.0945
43.243113436, 96.390, 1305.0, 36.1248
43.295634567, 96.390, 1343.0, 36.6470
43.348155698, 96.390, 1274.0, 35.6931
43.400676828, 96.390, 1284.0, 35.8329
43.453197959, 96.390, 1253.0, 35.3977
43.505719090, 96.390, 1305.0, 36.1248
43.558240221, 96.390, 1265.0, 35.5668
43.610761351, 96.390, 1353.0, 36.7831
43.663282482, 96.390, 1375.0, 37.0810
43.715803613, 96.390, 1311.0, 36.2077
43.768324743, 96.390, 1320.0, 36.3318
43.820845874, 96.390, 1355.0, 36.8103
43.873367005, 96.390, 1282.0, 35.8050
43.925888136, 96.390, 1377.0, 37.1080
43.978409266, 96.390, 1349.0, 36.7287
44.030930397, 96.390, 1316.0, 36.2767
44.083451528, 96.390, 1359.0, 36.8646
44.135972658, 96.390, 1272.0, 35.6651
44.188493789, 96.390, 1384.0, 37.2022
44.241014920, 96.390, 1309.0, 36.1801
44.293536051, 96.390, 1358.0, 36.8511
44.346057181, 96.390, 1355.0, 36.8103
44.398578312, 96.390, 1310.0, 36.1939
44.451099443, 96.390, 1286.0, 35.8608
44.503620573, 96.390, 1379.0, 37.1349
44.556141704, 96.390, 1314.0, 36.2491
44.608662835, 96.390, 1313.0, 36.2353
44.661183966, 96.390, 1373.0, 37.0540
44.713705096, 96.390, 1334.0, 36.5240
44.766226227, 96.390, 1292.0, 35.9444
44.818747358, 96.390, 1342.0, 36.6333
44.871268488, 96.390, 1338.0, 36.5787
44.923789619, 96.390, 1413.0, 37.5899
44.976310750, 96.390, 1292.0, 35.9444
45.028831880, 96.390, 1395.0, 37.3497
45.081353011, 96.390, 1423.0, 37.7227
45.133874142, 96.390, 1327.0, 36.4280
45.186395273, 96.390, 1318.0, 36.3043
45.238916403, 96.390, 1348.0, 36.7151
45.291437534, 96.390, 1349.0, 36.7287
45.343958665, 96.390, 1305.0, 36.1248
45.396479795, 96.390, 1420.0, 37.6829
45.449000926, 96.390, 1355.0, 36.8103
45.501522057, 96.390, 1323.0, 36.3731
45.554043188, 96.390, 1338.0, 36.5787
45.606564318, 96.390, 1324.0, 36.3868
45.659085449, 96.390, 1348.0, 36.7151
45.711606580, 96.390, 1375.0, 37.0810
45.764127710, 96.390, 1353.0, 36.7831
45.816648841, 96.390, 1376.0, 37.0945
45.869169972, 96.390, 1324.0, 36.3868
45.921691103, 96.390, 1276.0, 35.7211
45.974212233, 96.390, 1338.0, 36.5787
46.026733364, 96.390, 1354.0, 36.7967
46.079254495, 96.390, 1341.0, 36.6197
46.131775625, 96.390, 1314.0, 36.2491
46.184296756, 96.390, 1395.0, 37.3497
46.236817887, 96.390, 1317.0, 36.2905
46.289339017, 96.390, 1364.0, 36.9324
46.341860148, 96.390, 1289.0, 35.9026
46.394381279, 96.390, 1329.0, 36.4555
46.446902410, 96.390, 1274.0, 35.6931
46.499423540, 96.390, 1276.0, 35.7211
46.551944671, 96.390, 1288.0, 35.8887
46.604465802, 96.390, 1301.0, 36.0694
46.656986932, 96.390, 1290.0, 35.9166
46.709508063, 96.390, 1287.0, 35.8748
46.762029194, 96.390, 1322.0, 36.3593
46.814550325, 96.390, 1340.0, 36.6060
46.867071455, 96.390, 1278.0, 35.7491
46.919592586, 96.390, 1324.0, 36.3868
46.972113717, 96.390, 1304.0, 36.1109
47.024634847, 96.390, 1270.0, 35.6371
47.077155978, 96.390, 1281.0, 35.7911
47.129677109, 96.390, 1277.0, 35.7351
47.182198240, 96.390, 1253.0, 35.3977
47.234719370, 96.390, 1287.0, 35.8748
47.287240501, 96.390, 1303.0, 36.0971
47.339761632, 96.390, 1257.0, 35.4542
47.392282762, 96.390, 1289.0, 35.9026
47.444803893, 96.390, 1254.0, 35.4119
47.497325024, 96.390, 1209.0, 34.7707
47.549846155, 96.390, 1235.0, 35.1426
47.602367285, 96.390, 1207.0, 34.7419
47.654888416, 96.390, 1277.0, 35.7351
47.707409547, 96.390, 1228.0, 35.0428
47.759930677, 96.390, 1215.0, 34.8569
47.812451808, 96.390, 1203.0, 34.6843
47.864972939, 96.390, 1194.0, 34.5543
47.917494069, 96.390, 1274.0, 35.6931
47.970015200, 96.390, 1107.0, 33.2716
48.022536331, 96.390, 1133.0, 33.6601
48.075057462, 96.390, 1185.0, 34.4238
48.127578592, 96.390, 1219.0, 34.9142
48.180099723, 96.390, 1217.0, 34.8855
48.232620854, 96.390, 1129.0, 33.6006
48.285141984, 96.390, 1153.0, 33.9559
48.337663115, 96.390, 1216.0, 34.8712
48.390184246, 96.390, 1161.0, 34.0735
48.442705377, 96.390, 1188.0, 34.4674
48.495226507, 96.390, 1165.0, 34.1321
48.547747638, 96.390, 1175.0, 34.2783
48.600268769, 96.390, 1203.0, 34.6843
48.652789899, 96.390, 1150.0, 33.9116
48.705311030, 96.390, 1126.0, 33.5559
48.757832161, 96.390, 1171.0, 34.2199
48.810353292, 96.390, 1147.0, 33.8674
48.862874422, 96.390, 1117.0, 33.4215
48.915395553, 96.390, 1110.0, 33.3167
48.967916684, 96.390, 1170.0, 34.2053
49.020437814, 96.390, 1204.0, 34.6987
49.072958945, 96.390, 1129.0, 33.6006
49.125480076, 96.390, 1154.0, 33.9706
49.178001207, 96.390, 1155.0, 33.9853
49.230522337, 96.390, 1158.0, 34.0294
49.283043468, 96.390, 1088.0, 32.9848
49.335564599, 96.390, 1165.0, 34.1321
49.388085729, 96.390, 1105.0, 33.2415
49.440606860, 96.390, 1167.0, 34.1614
49.493127991, 96.390, 1132.0, 33.6452
49.545649121, 96.390, 1070.0, 32.7109
49.598170252, 96.390, 1142.0, 33.7935
49.650691383, 96.390, 1105.0, 33.2415
49.703212514, 96.390, 1111.0, 33.3317
49.755733644, 96.390, 1094.0, 33.0757
49.808254775, 96.390, 1070.0, 32.7109
49.860775906, 96.390, 1126.0, 33.5559
49.913297036, 96.390, 1074.0, 32.7719
49.965818167, 96.390, 1064.0, 32.6190
50.018339298, 96.390, 1091.0, 33.0303
50.070860429, 96.390, 1102.0, 33.1964
50.123381559, 96.390, 1064.0, 32.6190
50.175902690, 96.390, 1070.0, 32.7109
50.228423821, 96.390, 1102.0, 33.1964
50.280944951, 96.390, 1114.0, 33.3766
50.333466082, 96.390, 1115.0, 33.3916
50.385987213, 96.390, 1004.0, 31.6860
50.438508344, 96.390, 1088.0, 32.9848
50.491029474, 96.390, 1070.0, 32.7109
50.543550605, 96.390, 1043.0, 32.2955
50.596071736, 96.390, 1078.0, 32.8329
50.648592866, 96.390, 1097.0, 33.1210
50.701113997, 96.390, 1012.0, 31.8119
50.753635128, 96.390, 1047.0, 32.3574
50.806156258, 96.390, 1048.0, 32.3728
50.858677389, 96.390, 1035.0, 32.1714
50.911198520, 96.390, 1078.0, 32.8329
50.963719651, 96.390, 1048.0, 32.3728
51.016240781, 96.390, 1030.0, 32.0936
51.068761912, 96.390, 1000.0, 31.6228
51.121283043, 96.390, 991.0, 31.4802
51.173804173, 96.390, 1013.0, 31.8277
51.226325304, 96.390, 1036.0, 32.1870
51.278846435, 96.390, 1010.0, 31.7805
51.331367566, 96.390, 1024.0, 32.0000
51.383888696, 96.390, 995.0, 31.5436
51.436409827, 96.390, 994.0, 31.5278
51.488930958, 96.390, 983.0, 31.3528
51.541452088, 96.390, 966.0, 31.0805
51.593973219, 96.390, 1064.0, 32.6190
51.646494350, 96.390, 989.0, 31.4484
51.699015481, 96.390, 997.0, 31.5753
51.751536611, 96.390, 955.0, 30.9031
51.804057742, 96.390, 992.0, 31.4960
51.856578873, 96.390, 1043.0, 32.2955
51.909100003, 96.390, 964.0, 31.0483
51.961621134, 96.390, 1063.0, 32.6037
52.014142265, 96.390, 949.0, 30.8058
52.066663396, 96.390, 977.0, 31.2570
52.119184526, 96.390, 1004.0, 31.6860
52.171705657, 96.390, 1014.0, 31.8434
52.224226788, 96.390, 960.0, 30.9839
52.276747918, 96.390, 947.0, 30.7734
52.329269049, 96.390, 1002.0, 31.6544
52.381790180, 96.390, 937.0, 30.6105
52.434311310, 96.390, 938.0, 30.6268
52.486832441, 96.390, 991.0, 31.4802
52.539353572, 96.390, 965.0, 31.0644
52.591874703, 96.390, 967.0, 31.0966
52.644395833, 96.390, 1011.0, 31.7962
52.696916964, 96.390, 1028.0, 32.0624
52.749438095, 96.390, 997.0, 31.5753
52.801959225, 96.390, 1001.0, 31.6386
52.854480356, 96.390, 929.0, 30.4795
52.907001487, 96.390, 921.0, 30.3480
52.959522618, 96.390, 978.0, 31.2730
53.012043748, 96.390, 1005.0, 31.7017
53.064564879, 96.390, 977.0, 31.2570
53.117086010, 96.390, 970.0, 31.1448
53.169607140, 96.390, 929.0, 30.4795
53.222128271, 96.390, 948.0, 30.7896
53.274649402, 96.390, 921.0, 30.3480
53.327170533, 96.390, 925.0, 30.4138
53.379691663, 96.390, 960.0, 30.9839
53.432212794, 96.390, 966.0, 31.0805
53.484733925, 96.390, 904.0, 30.0666
53.537255055, 96.390, 969.0, 31.1288
53.589776186, 96.390, 912.0, 30.1993
53.642297317, 96.390, 948.0, 30.7896
53.694818448, 96.390, 928.0, 30.4631
53.747339578, 96.390, 975.0, 31.2250
53.799860709, 96.390, 891.0, 29.8496
53.852381840, 96.390, 889.0, 29.8161
53.904902970, 96.390, 939.0, 30.6431
53.957424101, 96.390, 998.0, 31.5911
54.009945232, 96.390, 955.0, 30.9031
54.062466362, 96.390, 916.0, 30.2655
54.114987493, 96.390, 902.0, 30.0333
54.167508624, 96.390, 879.0, 29.6479
54.220029755, 96.390, 897.0, 29.9500
54.272550885, 96.390, 886.0, 29.7658
54.325072016, 96.390, 904.0, 30.0666
54.377593147, 96.390, 899.0, 29.9833
54.430114277, 96.390, 953.0, 30.8707
54.482635408, 96.390, 963.0, 31.0322
54.535156539, 96.390, 954.0, 30.8869
54.587677670, 96.390, 915.0, 30.2490
54.640198800, 96.390, 912.0, 30.1993
54.692719931, 96.390, 870.0, 29.4958
54.745241062, 96.390, 913.0, 30.2159
54.797762192, 96.390, 848.0, 29.1204
54.850283323, 96.390, 899.0, 29.9833
54.902804454, 96.390, 921.0, 30.3480
54.955325585, 96.390, 893.0, 29.8831
55.007846715, 96.390, 900.0, 30.0000
55.060367846, 96.390, 935.0, 30.5778
55.112888977, 96.390, 832.0, 28.8444
55.165410107, 96.390, 862.0, 29.3598
55.217931238, 96.390, 890.0, 29.8329
55.270452369, 96.390, 923.0, 30.3809
55.322973499, 96.390, 886.0, 29.7658
55.375494630, 96.390, 867.0, 29.4449
55.428015761, 96.390, 925.0, 30.4138
55.480536892, 96.390, 924.0, 30.3974
55.533058022, 96.390, 921.0, 30.3480
55.585579153, 96.390, 951.0, 30.8383
55.638100284, 96.390, 892.0, 29.8664
55.690621414, 96.390, 930.0, 30.4959
55.743142545, 96.390, 889.0, 29.8161
55.795663676, 96.390, 866.0, 29.4279
55.848184807, 96.390, 963.0, 31.0322
55.900705937, 96.390, 862.0, 29.3598
55.953227068, 96.390, 916.0, 30.2655
56.005748199, 96.390, 886.0, 29.7658
56.058269329, 96.390, 909.0, 30.1496
56.110790460, 96.390, 880.0, 29.6648
56.163311591, 96.390, 868.0, 29.4618
56.215832722, 96.390, 892.0, 29.8664
56.268353852, 96.390, 905.0, 30.0832
56.320874983, 96.390, 881.0, 29.6816
56.373396114, 96.390, 845.0, 29.0689
56.425917244, 96.390, 874.0, 29.5635
56.478438375, 96.390, 841.0, 29.0000
56.530959506, 96.390, 826.0, 28.7402
56.583480637, 96.390, 844.0, 29.0517
56.636001767, 96.390, 963.0, 31.0322
56.688522898, 96.390, 876.0, 29.5973
56.741044029, 96.390, 889.0, 29.8161
56.793565159, 96.390, 854.0, 29.2233
56.846086290, 96.390, 862.0, 29.3598
56.898607421, 96.390, 884.0, 29.7321
56.951128551, 96.390, 853.0, 29.2062
57.003649682, 96.390, 904.0, 30.0666
57.056170813, 96.390, 853.0, 29.2062
57.108691944, 96.390, 827.0, 28.7576
57.161213074, 96.390, 924.0, 30.3974
57.213734205, 96.390, 902.0, 30.0333
57.266255336, 96.390, 854.0, 29.2233
57.318776466, 96.390, 895.0, 29.9166
57.371297597, 96.390, 855.0, 29.2404
57.423818728, 96.390, 842.0, 29.0172
57.476339859, 96.390, 859.0, 29.3087
57.528860989, 96.390, 816.0, 28.5657
57.581382120, 96.390, 856.0, 29.2575
57.633903251, 96.390, 851.0, 29.1719
57.686424381, 96.390, 855.0, 29.2404
57.738945512, 96.390, 878.0, 29.6311
57.791466643, 96.390, 864.0, 29.3939
57.843987774, 96.390, 878.0, 29.6311
57.896508904, 96.390, 891.0, 29.8496
57.949030035, 96.390, 884.0, 29.7321
58.001551166, 96.390, 883.0, 29.7153
58.054072296, 96.390, 864.0, 29.3939
58.106593427, 96.390, 907.0, 30.1164
58.159114558, 96.390, 855.0, 29.2404
58.211635689, 96.390, 849.0, 29.1376
58.264156819, 96.390, 878.0, 29.6311
58.316677950, 96.390, 970.0, 31.1448
58.369199081, 96.390, 900.0, 30.0000
58.421720211, 96.390, 800.0, 28.2843
58.474241342, 96.390, 848.0, 29.1204
58.526762473, 96.390, 922.0, 30.3645
58.579283603, 96.390, 906.0, 30.0998
58.631804734, 96.390, 886.0, 29.7658
58.684325865, 96.390, 875.0, 29.5804
58.736846996, 96.390, 895.0, 29.9166
58.789368126, 96.390, 926.0, 30.4302
58.841889257, 96.390, 912.0, 30.1993
58.894410388, 96.390, 886.0, 29.7658
58.946931518, 96.390, 868.0, 29.4618
58.999452649, 96.390, 918.0, 30.2985
59.051973780, 96.390, 861.0, 29.3428
59.104494911, 96.390, 891.0, 29.8496
59.157016041, 96.390, 960.0, 30.9839
59.209537172, 96.390, 859.0, 29.3087
59.262058303, 96.390, 883.0, 29.7153
59.314579433, 96.390, 863.0, 29.3769
59.367100564, 96.390, 930.0, 30.4959
59.419621695, 96.390, 946.0, 30.7571
59.472142826, 96.390, 970.0, 31.1448
59.524663956, 96.390, 879.0, 29.6479
59.577185087, 96.390, 967.0, 31.0966
59.629706218, 96.390, 942.0, 30.6920
59.682227348, 96.390, 928.0, 30.4631
59.734748479, 96.390, 981.0, 31.3209
59.787269610, 96.390, 959.0, 30.9677
59.839790740, 96.390, 952.0, 30.8545
59.892311871, 96.390, 1023.0, 31.9844
59.944833002, 96.390, 1027.0, 32.0468
59.997354133, 96.390, 998.0, 31.5911
60.049875263, 96.390, 1027.0, 32.0468
60.102396394, 96.390, 987.0, 31.4166
60.154917525, 96.390, 1067.0, 32.6650
60.207438655, 96.390, 1090.0, 33.0151
60.259959786, 96.390, 1127.0, 33.5708
60.312480917, 96.390, 1089.0, 33.0000
60.365002048, 96.390, 1198.0, 34.6121
60.417523178, 96.390, 1159.0, 34.0441
60.470044309, 96.390, 1181.0, 34.3657
60.522565440, 96.390, 1196.0, 34.5832
60.575086570, 96.390, 1196.0, 34.5832
60.627607701, 96.390, 1220.0, 34.9285
60.680128832, 96.390, 1282.0, 35.8050
60.732649963, 96.390, 1277.0, 35.7351
60.785171093, 96.390, 1342.0, 36.6333
60.837692224, 96.390, 1270.0, 35.6371
60.890213355, 96.390, 1326.0, 36.4143
60.942734485, 96.390, 1339.0, 36.5923
60.995255616, 96.390, 1466.0, 38.2884
61.047776747, 96.390, 1395.0, 37.3497
61.100297878, 96.390, 1395.0, 37.3497
61.152819008, 96.390, 1300.0, 36.0555
61.205340139, 96.390, 1409.0, 37.5366
61.257861270, 96.390, 1370.0, 37.0135
61.310382400, 96.390, 1359.0, 36.8646
61.362903531, 96.390, 1309.0, 36.1801
61.415424662, 96.390, 1284.0, 35.8329
61.467945792, 96.390, 1323.0, 36.3731
61.520466923, 96.390, 1295.0, 35.9861
61.572988054, 96.390, 1360.0, 36.8782
61.625509185, 96.390, 1321.0, 36.3456
61.678030315, 96.390, 1340.0, 36.6060
61.730551446, 96.390, 1253.0, 35.3977
61.783072577, 96.390, 1276.0, 35.7211
61.835593707, 96.390, 1279.0, 35.7631
61.888114838, 96.390, 1290.0, 35.9166
61.940635969, 96.390, 1298.0, 36.0278
61.993157100, 96.390, 1258.0, 35.4683
62.045678230, 96.390, 1246.0, 35.2987
62.098199361, 96.390, 1298.0, 36.0278
62.150720492, 96.390, 1216.0, 34.8712
62.203241622, 96.390, 1131.0, 33.6303
62.255762753, 96.390, 1210.0, 34.7851
62.308283884, 96.390, 1184.0, 34.4093
62.360805015, 96.390, 1142.0, 33.7935
62.413326145, 96.390, 1093.0, 33.0606
62.465847276, 96.390, 1169.0, 34.1906
62.518368407, 96.390, 1164.0, 34.1174
62.570889537, 96.390, 1077.0, 32.8177
62.623410668, 96.390, 1089.0, 33.0000
62.675931799, 96.390, 1038.0, 32.2180
62.728452930, 96.390, 994.0, 31.5278
62.780974060, 96.390, 1021.0, 31.9531
62.833495191, 96.390, 1004.0, 31.6860
62.886016322, 96.390, 1024.0, 32.0000
62.938537452, 96.390, 987.0, 31.4166
62.991058583, 96.390, 961.0, 31.0000
63.043579714, 96.390, 993.0, 31.5119
63.096100844, 96.390, 954.0, 30.8869
63.148621975, 96.390, 943.0, 30.7083
63.201143106, 96.390, 942.0, 30.6920
63.253664237, 96.390, 909.0, 30.1496
63.306185367, 96.390, 923.0, 30.3809
63.358706498, 96.390, 858.0, 29.2916
63.411227629, 96.390, 844.0, 29.0517
63.463748759, 96.390, 896.0, 29.9333
63.516269890, 96.390, 880.0, 29.6648
63.568791021, 96.390, 856.0, 29.2575
63.621312152, 96.390, 882.0, 29.6985
63.673833282, 96.390, 892.0, 29.8664
63.726354413, 96.390, 894.0, 29.8998
63.778875544, 96.390, 874.0, 29.5635
63.831396674, 96.390, 871.0, 29.5127
63.883917805, 96.390, 860.0, 29.3258
63.936438936, 96.390, 865.0, 29.4109
63.988960067, 96.390, 837.0, 28.9310
64.041481197, 96.390, 822.0, 28.6705
64.094002328, 96.390, 847.0, 29.1033
64.146523459, 96.390, 828.0, 28.7750
64.199044589, 96.390, 861.0, 29.3428
64.251565720, 96.390, 823.0, 28.6880
64.304086851, 96.390, 827.0, 28.7576
64.356607981, 96.390, 749.0, 27.3679
64.409129112, 96.390, 778.0, 27.8927
64.461650243, 96.390, 770.0, 27.7489
64.514171374, 96.390, 758.0, 27.5318
64.566692504, 96.390, 781.0, 27.9464
64.619213635, 96.390, 780.0, 27.9285
64.671734766, 96.390, 796.0, 28.2135
64.724255896, 96.390, 762.0, 27.6043
64.776777027, 96.390, 740.0, 27.2029
64.829298158, 96.390, 723.0, 26.8887
64.881819289, 96.390, 816.0, 28.5657
64.934340419, 96.390, 784.0, 28.0000
64.986861550, 96.390, 779.0, 27.9106