File: Files_organized_for_plots/Constant_NaOH_half_mL10M_to_1gPC/XRD_AlCorner31Jan22_Act15Feb22_B2_0465M_NaOH_LS0120_1.csv
[Measurement conditions]
Sample identification,XRD_AlCorner31Jan22_Act15Feb22_B2_0465M_NaOH_LS0120_1
Comment - 1,"Configuration=Stage for Flat Samples/Holders, Owner=User-1, Creation date=7/1/2020 9:53:24 AM"
Comment - 2,"Goniometer=Theta/Theta; Minimum step size 2Theta:0.0001; Minimum step size Omega:0.0001"
Comment - 3,"Sample stage=Stage for flat samples/holders"
Comment - 4,"Diffractometer system=EMPYREAN"
Comment - 5,"Measurement program=C:\Users\ibo5034\OneDrive - The Pennsylvania State University\NEUP - Reed, Titus's files\XRD\Cement\Zerobackground scan.xrdmp, Identifier={98A3B11C-88F9-4AA6-982C-73314A311EF5}"
Anode material,Cu
K-Alpha1 wavelength,1.5405980
K-Alpha2 wavelength,1.5444260
Ratio K-Alpha2/K-Alpha1,0.500
Divergence slit,Fixed,0.25
Monochromator used,NO
Generator voltage, 45
Tube current, 40
File date and time,18/Feb/2022 12:45
Unit cell,
h k l, 0 0 0
Scan axis,Gonio
Scan range,4.994599997,64.999991833
Scan step size,0.0262606
No. of points, 2285
Scan type,CONTINUOUS
Time per step,96.390
[Scan points]
Angle, TimePerStep, Intensity, ESD
5.007730280, 96.390, 6807.0, 82.5045
5.060251411, 96.390, 6622.0, 81.3757
5.112772541, 96.390, 6557.0, 80.9753
5.165293672, 96.390, 6572.0, 81.0679
5.217814803, 96.390, 6373.0, 79.8311
5.270335934, 96.390, 6352.0, 79.6994
5.322857064, 96.390, 6398.0, 79.9875
5.375378195, 96.390, 6171.0, 78.5557
5.427899326, 96.390, 6142.0, 78.3709
5.480420456, 96.390, 6050.0, 77.7817
5.532941587, 96.390, 6071.0, 77.9166
5.585462718, 96.390, 5926.0, 76.9805
5.637983849, 96.390, 5871.0, 76.6225
5.690504979, 96.390, 5844.0, 76.4461
5.743026110, 96.390, 5769.0, 75.9539
5.795547241, 96.390, 5746.0, 75.8024
5.848068371, 96.390, 5856.0, 76.5245
5.900589502, 96.390, 5696.0, 75.4718
5.953110633, 96.390, 5350.0, 73.1437
6.005631763, 96.390, 5546.0, 74.4715
6.058152894, 96.390, 5536.0, 74.4043
6.110674025, 96.390, 5450.0, 73.8241
6.163195156, 96.390, 5337.0, 73.0548
6.215716286, 96.390, 5361.0, 73.2189
6.268237417, 96.390, 5322.0, 72.9520
6.320758548, 96.390, 5300.0, 72.8011
6.373279678, 96.390, 5185.0, 72.0069
6.425800809, 96.390, 5103.0, 71.4353
6.478321940, 96.390, 5060.0, 71.1337
6.530843071, 96.390, 5153.0, 71.7844
6.583364201, 96.390, 5013.0, 70.8025
6.635885332, 96.390, 5034.0, 70.9507
6.688406463, 96.390, 5101.0, 71.4213
6.740927593, 96.390, 5094.0, 71.3723
6.793448724, 96.390, 4903.0, 70.0214
6.845969855, 96.390, 4947.0, 70.3349
6.898490986, 96.390, 4885.0, 69.8928
6.951012116, 96.390, 4826.0, 69.4694
7.003533247, 96.390, 4962.0, 70.4415
7.056054378, 96.390, 4755.0, 68.9565
7.108575508, 96.390, 4584.0, 67.7052
7.161096639, 96.390, 4692.0, 68.4982
7.213617770, 96.390, 4501.0, 67.0895
7.266138900, 96.390, 4509.0, 67.1491
7.318660031, 96.390, 4660.0, 68.2642
7.371181162, 96.390, 4567.0, 67.5796
7.423702293, 96.390, 4446.0, 66.6783
7.476223423, 96.390, 4482.0, 66.9477
7.528744554, 96.390, 4613.0, 67.9191
7.581265685, 96.390, 4520.0, 67.2309
7.633786815, 96.390, 4525.0, 67.2681
7.686307946, 96.390, 4315.0, 65.6887
7.738829077, 96.390, 4474.0, 66.8880
7.791350208, 96.390, 4348.0, 65.9394
7.843871338, 96.390, 4356.0, 66.0000
7.896392469, 96.390, 4326.0, 65.7723
7.948913600, 96.390, 4258.0, 65.2534
8.001434730, 96.390, 4218.0, 64.9461
8.053955861, 96.390, 4127.0, 64.2417
8.106476992, 96.390, 4213.0, 64.9076
8.158998123, 96.390, 4218.0, 64.9461
8.211519253, 96.390, 4025.0, 63.4429
8.264040384, 96.390, 4187.0, 64.7070
8.316561515, 96.390, 4157.0, 64.4748
8.369082645, 96.390, 4185.0, 64.6916
8.421603776, 96.390, 3973.0, 63.0317
8.474124907, 96.390, 4047.0, 63.6160
8.526646038, 96.390, 3934.0, 62.7216
8.579167168, 96.390, 4017.0, 63.3798
8.631688299, 96.390, 3889.0, 62.3618
8.684209430, 96.390, 3966.0, 62.9762
8.736730560, 96.390, 3983.0, 63.1110
8.789251691, 96.390, 3860.0, 62.1289
8.841772822, 96.390, 3917.0, 62.5859
8.894293952, 96.390, 3987.0, 63.1427
8.946815083, 96.390, 3830.0, 61.8870
8.999336214, 96.390, 3939.0, 62.7615
9.051857345, 96.390, 3856.0, 62.0967
9.104378475, 96.390, 3791.0, 61.5711
9.156899606, 96.390, 3872.0, 62.2254
9.209420737, 96.390, 3716.0, 60.9590
9.261941867, 96.390, 3845.0, 62.0081
9.314462998, 96.390, 3782.0, 61.4980
9.366984129, 96.390, 3699.0, 60.8194
9.419505260, 96.390, 3777.0, 61.4573
9.472026390, 96.390, 3654.0, 60.4483
9.524547521, 96.390, 3678.0, 60.6465
9.577068652, 96.390, 3587.0, 59.8916
9.629589782, 96.390, 3662.0, 60.5145
9.682110913, 96.390, 3684.0, 60.6960
9.734632044, 96.390, 3652.0, 60.4318
9.787153175, 96.390, 3573.0, 59.7746
9.839674305, 96.390, 3553.0, 59.6070
9.892195436, 96.390, 3604.0, 60.0333
9.944716567, 96.390, 3484.0, 59.0254
9.997237697, 96.390, 3588.0, 59.8999
10.049758828, 96.390, 3602.0, 60.0167
10.102279959, 96.390, 3472.0, 58.9237
10.154801090, 96.390, 3481.0, 59.0000
10.207322220, 96.390, 3422.0, 58.4979
10.259843351, 96.390, 3498.0, 59.1439
10.312364482, 96.390, 3462.0, 58.8388
10.364885612, 96.390, 3392.0, 58.2409
10.417406743, 96.390, 3433.0, 58.5918
10.469927874, 96.390, 3389.0, 58.2151
10.522449004, 96.390, 3352.0, 57.8965
10.574970135, 96.390, 3446.0, 58.7026
10.627491266, 96.390, 3398.0, 58.2924
10.680012397, 96.390, 3401.0, 58.3181
10.732533527, 96.390, 3383.0, 58.1636
10.785054658, 96.390, 3288.0, 57.3411
10.837575789, 96.390, 3294.0, 57.3934
10.890096919, 96.390, 3326.0, 57.6715
10.942618050, 96.390, 3308.0, 57.5152
10.995139181, 96.390, 3336.0, 57.7581
11.047660312, 96.390, 3290.0, 57.3585
11.100181442, 96.390, 3237.0, 56.8946
11.152702573, 96.390, 3297.0, 57.4195
11.205223704, 96.390, 3299.0, 57.4369
11.257744834, 96.390, 3270.0, 57.1839
11.310265965, 96.390, 3134.0, 55.9821
11.362787096, 96.390, 3158.0, 56.1961
11.415308227, 96.390, 3218.0, 56.7274
11.467829357, 96.390, 3249.0, 57.0000
11.520350488, 96.390, 3262.0, 57.1139
11.572871619, 96.390, 3320.0, 57.6194
11.625392749, 96.390, 3156.0, 56.1783
11.677913880, 96.390, 3255.0, 57.0526
11.730435011, 96.390, 3070.0, 55.4076
11.782956141, 96.390, 3113.0, 55.7943
11.835477272, 96.390, 3202.0, 56.5862
11.887998403, 96.390, 3132.0, 55.9643
11.940519534, 96.390, 3098.0, 55.6597
11.993040664, 96.390, 3093.0, 55.6147
12.045561795, 96.390, 3127.0, 55.9196
12.098082926, 96.390, 3164.0, 56.2494
12.150604056, 96.390, 3145.0, 56.0803
12.203125187, 96.390, 3020.0, 54.9545
12.255646318, 96.390, 3042.0, 55.1543
12.308167449, 96.390, 3082.0, 55.5158
12.360688579, 96.390, 2980.0, 54.5894
12.413209710, 96.390, 3027.0, 55.0182
12.465730841, 96.390, 3133.0, 55.9732
12.518251971, 96.390, 3077.0, 55.4707
12.570773102, 96.390, 3029.0, 55.0364
12.623294233, 96.390, 3021.0, 54.9636
12.675815364, 96.390, 3020.0, 54.9545
12.728336494, 96.390, 2939.0, 54.2125
12.780857625, 96.390, 2964.0, 54.4426
12.833378756, 96.390, 2977.0, 54.5619
12.885899886, 96.390, 2947.0, 54.2863
12.938421017, 96.390, 3057.0, 55.2901
12.990942148, 96.390, 3021.0, 54.9636
13.043463279, 96.390, 3020.0, 54.9545
13.095984409, 96.390, 3024.0, 54.9909
13.148505540, 96.390, 2951.0, 54.3231
13.201026671, 96.390, 3024.0, 54.9909
13.253547801, 96.390, 2927.0, 54.1018
13.306068932, 96.390, 2876.0, 53.6284
13.358590063, 96.390, 3010.0, 54.8635
13.411111193, 96.390, 2776.0, 52.6878
13.463632324, 96.390, 2885.0, 53.7122
13.516153455, 96.390, 2987.0, 54.6535
13.568674586, 96.390, 2932.0, 54.1479
13.621195716, 96.390, 3010.0, 54.8635
13.673716847, 96.390, 2915.0, 53.9907
13.726237978, 96.390, 2949.0, 54.3047
13.778759108, 96.390, 2942.0, 54.2402
13.831280239, 96.390, 2972.0, 54.5161
13.883801370, 96.390, 2861.0, 53.4883
13.936322501, 96.390, 2942.0, 54.2402
13.988843631, 96.390, 2869.0, 53.5630
14.041364762, 96.390, 2846.0, 53.3479
14.093885893, 96.390, 2736.0, 52.3068
14.146407023, 96.390, 2902.0, 53.8702
14.198928154, 96.390, 2945.0, 54.2679
14.251449285, 96.390, 2982.0, 54.6077
14.303970416, 96.390, 2979.0, 54.5802
14.356491546, 96.390, 2829.0, 53.1883
14.409012677, 96.390, 2823.0, 53.1319
14.461533808, 96.390, 2902.0, 53.8702
14.514054938, 96.390, 2957.0, 54.3783
14.566576069, 96.390, 2765.0, 52.5833
14.619097200, 96.390, 2782.0, 52.7447
14.671618331, 96.390, 2805.0, 52.9623
14.724139461, 96.390, 2774.0, 52.6688
14.776660592, 96.390, 2803.0, 52.9434
14.829181723, 96.390, 2803.0, 52.9434
14.881702853, 96.390, 2734.0, 52.2877
14.934223984, 96.390, 2795.0, 52.8678
14.986745115, 96.390, 2719.0, 52.1440
15.039266245, 96.390, 2729.0, 52.2398
15.091787376, 96.390, 2790.0, 52.8205
15.144308507, 96.390, 2835.0, 53.2447
15.196829638, 96.390, 2776.0, 52.6878
15.249350768, 96.390, 2765.0, 52.5833
15.301871899, 96.390, 2863.0, 53.5070
15.354393030, 96.390, 2755.0, 52.4881
15.406914160, 96.390, 2637.0, 51.3517
15.459435291, 96.390, 2789.0, 52.8110
15.511956422, 96.390, 2720.0, 52.1536
15.564477553, 96.390, 2650.0, 51.4782
15.616998683, 96.390, 2685.0, 51.8170
15.669519814, 96.390, 2646.0, 51.4393
15.722040945, 96.390, 2646.0, 51.4393
15.774562075, 96.390, 2634.0, 51.3225
15.827083206, 96.390, 2691.0, 51.8748
15.879604337, 96.390, 2637.0, 51.3517
15.932125468, 96.390, 2559.0, 50.5866
15.984646598, 96.390, 2634.0, 51.3225
16.037167729, 96.390, 2566.0, 50.6557
16.089688860, 96.390, 2603.0, 51.0196
16.142209990, 96.390, 2628.0, 51.2640
16.194731121, 96.390, 2592.0, 50.9117
16.247252252, 96.390, 2538.0, 50.3786
16.299773382, 96.390, 2561.0, 50.6063
16.352294513, 96.390, 2569.0, 50.6853
16.404815644, 96.390, 2553.0, 50.5272
16.457336775, 96.390, 2603.0, 51.0196
16.509857905, 96.390, 2533.0, 50.3289
16.562379036, 96.390, 2468.0, 49.6790
16.614900167, 96.390, 2594.0, 50.9313
16.667421297, 96.390, 2553.0, 50.5272
16.719942428, 96.390, 2505.0, 50.0500
16.772463559, 96.390, 2428.0, 49.2747
16.824984690, 96.390, 2609.0, 51.0784
16.877505820, 96.390, 2445.0, 49.4469
16.930026951, 96.390, 2527.0, 50.2693
16.982548082, 96.390, 2576.0, 50.7543
17.035069212, 96.390, 2512.0, 50.1199
17.087590343, 96.390, 2456.0, 49.5580
17.140111474, 96.390, 2551.0, 50.5074
17.192632605, 96.390, 2537.0, 50.3686
17.245153735, 96.390, 2510.0, 50.0999
17.297674866, 96.390, 2452.0, 49.5177
17.350195997, 96.390, 2484.0, 49.8397
17.402717127, 96.390, 2407.0, 49.0612
17.455238258, 96.390, 2482.0, 49.8197
17.507759389, 96.390, 2460.0, 49.5984
17.560280520, 96.390, 2425.0, 49.2443
17.612801650, 96.390, 2425.0, 49.2443
17.665322781, 96.390, 2404.0, 49.0306
17.717843912, 96.390, 2392.0, 48.9081
17.770365042, 96.390, 2419.0, 49.1833
17.822886173, 96.390, 2443.0, 49.4267
17.875407304, 96.390, 2379.0, 48.7750
17.927928434, 96.390, 2436.0, 49.3559
17.980449565, 96.390, 2438.0, 49.3761
18.032970696, 96.390, 2450.0, 49.4975
18.085491827, 96.390, 2460.0, 49.5984
18.138012957, 96.390, 2586.0, 50.8527
18.190534088, 96.390, 2599.0, 50.9804
18.243055219, 96.390, 2678.0, 51.7494
18.295576349, 96.390, 2826.0, 53.1601
18.348097480, 96.390, 3057.0, 55.2901
18.400618611, 96.390, 3079.0, 55.4887
18.453139742, 96.390, 3211.0, 56.6657
18.505660872, 96.390, 3402.0, 58.3267
18.558182003, 96.390, 3642.0, 60.3490
18.610703134, 96.390, 3767.0, 61.3759
18.663224264, 96.390, 3870.0, 62.2093
18.715745395, 96.390, 4259.0, 65.2610
18.768266526, 96.390, 5513.0, 74.2496
18.820787657, 96.390, 6005.0, 77.4919
18.873308787, 96.390, 4033.0, 63.5059
18.925829918, 96.390, 2779.0, 52.7162
18.978351049, 96.390, 2591.0, 50.9019
19.030872179, 96.390, 2507.0, 50.0700
19.083393310, 96.390, 2502.0, 50.0200
19.135914441, 96.390, 2462.0, 49.6185
19.188435572, 96.390, 2442.0, 49.4166
19.240956702, 96.390, 2479.0, 49.7896
19.293477833, 96.390, 2488.0, 49.8799
19.345998964, 96.390, 2500.0, 50.0000
19.398520094, 96.390, 2484.0, 49.8397
19.451041225, 96.390, 2453.0, 49.5278
19.503562356, 96.390, 2500.0, 50.0000
19.556083486, 96.390, 2404.0, 49.0306
19.608604617, 96.390, 2462.0, 49.6185
19.661125748, 96.390, 2546.0, 50.4579
19.713646879, 96.390, 2427.0, 49.2646
19.766168009, 96.390, 2529.0, 50.2892
19.818689140, 96.390, 2572.0, 50.7149
19.871210271, 96.390, 2591.0, 50.9019
19.923731401, 96.390, 2540.0, 50.3984
19.976252532, 96.390, 2749.0, 52.4309
20.028773663, 96.390, 2740.0, 52.3450
20.081294794, 96.390, 2692.0, 51.8845
20.133815924, 96.390, 2829.0, 53.1883
20.186337055, 96.390, 3180.0, 56.3915
20.238858186, 96.390, 3823.0, 61.8304
20.291379316, 96.390, 4547.0, 67.4314
20.343900447, 96.390, 4505.0, 67.1193
20.396421578, 96.390, 3952.0, 62.8649
20.448942709, 96.390, 4054.0, 63.6710
20.501463839, 96.390, 3529.0, 59.4054
20.553984970, 96.390, 3205.0, 56.6127
20.606506101, 96.390, 2974.0, 54.5344
20.659027231, 96.390, 2985.0, 54.6352
20.711548362, 96.390, 3223.0, 56.7715
20.764069493, 96.390, 3029.0, 55.0364
20.816590623, 96.390, 2762.0, 52.5547
20.869111754, 96.390, 2682.0, 51.7880
20.921632885, 96.390, 2570.0, 50.6952
20.974154016, 96.390, 2612.0, 51.1077
21.026675146, 96.390, 2582.0, 50.8134
21.079196277, 96.390, 2616.0, 51.1468
21.131717408, 96.390, 2457.0, 49.5681
21.184238538, 96.390, 2455.0, 49.5480
21.236759669, 96.390, 2485.0, 49.8498
21.289280800, 96.390, 2554.0, 50.5371
21.341801931, 96.390, 2471.0, 49.7092
21.394323061, 96.390, 2438.0, 49.3761
21.446844192, 96.390, 2563.0, 50.6261
21.499365323, 96.390, 2564.0, 50.6360
21.551886453, 96.390, 2473.0, 49.7293
21.604407584, 96.390, 2517.0, 50.1697
21.656928715, 96.390, 2436.0, 49.3559
21.709449846, 96.390, 2544.0, 50.4381
21.761970976, 96.390, 2542.0, 50.4183
21.814492107, 96.390, 2418.0, 49.1732
21.867013238, 96.390, 2423.0, 49.2240
21.919534368, 96.390, 2540.0, 50.3984
21.972055499, 96.390, 2321.0, 48.1768
22.024576630, 96.390, 2494.0, 49.9400
22.077097761, 96.390, 2408.0, 49.0714
22.129618891, 96.390, 2512.0, 50.1199
22.182140022, 96.390, 2388.0, 48.8672
22.234661153, 96.390, 2404.0, 49.0306
22.287182283, 96.390, 2308.0, 48.0416
22.339703414, 96.390, 2354.0, 48.5180
22.392224545, 96.390, 2404.0, 49.0306
22.444745675, 96.390, 2404.0, 49.0306
22.497266806, 96.390, 2422.0, 49.2138
22.549787937, 96.390, 2438.0, 49.3761
22.602309068, 96.390, 2478.0, 49.7795
22.654830198, 96.390, 2367.0, 48.6518
22.707351329, 96.390, 2479.0, 49.7896
22.759872460, 96.390, 2376.0, 48.7442
22.812393590, 96.390, 2290.0, 47.8539
22.864914721, 96.390, 2451.0, 49.5076
22.917435852, 96.390, 2341.0, 48.3839
22.969956983, 96.390, 2419.0, 49.1833
23.022478113, 96.390, 2392.0, 48.9081
23.074999244, 96.390, 2394.0, 48.9285
23.127520375, 96.390, 2424.0, 49.2341
23.180041505, 96.390, 2336.0, 48.3322
23.232562636, 96.390, 2333.0, 48.3011
23.285083767, 96.390, 2358.0, 48.5592
23.337604898, 96.390, 2339.0, 48.3632
23.390126028, 96.390, 2474.0, 49.7393
23.442647159, 96.390, 2380.0, 48.7852
23.495168290, 96.390, 2392.0, 48.9081
23.547689420, 96.390, 2264.0, 47.5815
23.600210551, 96.390, 2388.0, 48.8672
23.652731682, 96.390, 2298.0, 47.9375
23.705252813, 96.390, 2333.0, 48.3011
23.757773943, 96.390, 2375.0, 48.7340
23.810295074, 96.390, 2297.0, 47.9270
23.862816205, 96.390, 2334.0, 48.3115
23.915337335, 96.390, 2287.0, 47.8226
23.967858466, 96.390, 2387.0, 48.8569
24.020379597, 96.390, 2271.0, 47.6550
24.072900727, 96.390, 2300.0, 47.9583
24.125421858, 96.390, 2335.0, 48.3218
24.177942989, 96.390, 2282.0, 47.7703
24.230464120, 96.390, 2420.0, 49.1935
24.282985250, 96.390, 2247.0, 47.4025
24.335506381, 96.390, 2221.0, 47.1275
24.388027512, 96.390, 2257.0, 47.5079
24.440548642, 96.390, 2184.0, 46.7333
24.493069773, 96.390, 2204.0, 46.9468
24.545590904, 96.390, 2167.0, 46.5510
24.598112035, 96.390, 2256.0, 47.4974
24.650633165, 96.390, 2220.0, 47.1169
24.703154296, 96.390, 2207.0, 46.9787
24.755675427, 96.390, 2173.0, 46.6154
24.808196557, 96.390, 2194.0, 46.8402
24.860717688, 96.390, 2153.0, 46.4004
24.913238819, 96.390, 2157.0, 46.4435
24.965759950, 96.390, 2185.0, 46.7440
25.018281080, 96.390, 2195.0, 46.8508
25.070802211, 96.390, 2210.0, 47.0106
25.123323342, 96.390, 2129.0, 46.1411
25.175844472, 96.390, 2133.0, 46.1844
25.228365603, 96.390, 2215.0, 47.0638
25.280886734, 96.390, 2216.0, 47.0744
25.333407864, 96.390, 2160.0, 46.4758
25.385928995, 96.390, 2204.0, 46.9468
25.438450126, 96.390, 2287.0, 47.8226
25.490971257, 96.390, 2145.0, 46.3141
25.543492387, 96.390, 2084.0, 45.6508
25.596013518, 96.390, 2184.0, 46.7333
25.648534649, 96.390, 2084.0, 45.6508
25.701055779, 96.390, 2116.0, 46.0000
25.753576910, 96.390, 2165.0, 46.5296
25.806098041, 96.390, 2068.0, 45.4753
25.858619172, 96.390, 2126.0, 46.1086
25.911140302, 96.390, 2138.0, 46.2385
25.963661433, 96.390, 2064.0, 45.4313
26.016182564, 96.390, 2147.0, 46.3357
26.068703694, 96.390, 2045.0, 45.2217
26.121224825, 96.390, 2077.0, 45.5741
26.173745956, 96.390, 1955.0, 44.2154
26.226267087, 96.390, 2049.0, 45.2659
26.278788217, 96.390, 2116.0, 46.0000
26.331309348, 96.390, 2047.0, 45.2438
26.383830479, 96.390, 2063.0, 45.4203
26.436351609, 96.390, 2128.0, 46.1303
26.488872740, 96.390, 2090.0, 45.7165
26.541393871, 96.390, 2146.0, 46.3249
26.593915002, 96.390, 2125.0, 46.0977
26.646436132, 96.390, 2159.0, 46.4650
26.698957263, 96.390, 2050.0, 45.2769
26.751478394, 96.390, 2034.0, 45.0999
26.803999524, 96.390, 2092.0, 45.7384
26.856520655, 96.390, 2142.0, 46.2817
26.909041786, 96.390, 2204.0, 46.9468
26.961562916, 96.390, 2098.0, 45.8039
27.014084047, 96.390, 2180.0, 46.6905
27.066605178, 96.390, 2134.0, 46.1952
27.119126309, 96.390, 2198.0, 46.8828
27.171647439, 96.390, 2159.0, 46.4650
27.224168570, 96.390, 2202.0, 46.9255
27.276689701, 96.390, 2239.0, 47.3181
27.329210831, 96.390, 2161.0, 46.4866
27.381731962, 96.390, 2088.0, 45.6946
27.434253093, 96.390, 2193.0, 46.8295
27.486774224, 96.390, 2108.0, 45.9130
27.539295354, 96.390, 2224.0, 47.1593
27.591816485, 96.390, 2219.0, 47.1063
27.644337616, 96.390, 2217.0, 47.0850
27.696858746, 96.390, 2420.0, 49.1935
27.749379877, 96.390, 2572.0, 50.7149
27.801901008, 96.390, 2662.0, 51.5946
27.854422139, 96.390, 2746.0, 52.4023
27.906943269, 96.390, 2631.0, 51.2933
27.959464400, 96.390, 2492.0, 49.9199
28.011985531, 96.390, 2282.0, 47.7703
28.064506661, 96.390, 2206.0, 46.9681
28.117027792, 96.390, 2118.0, 46.0217
28.169548923, 96.390, 2143.0, 46.2925
28.222070054, 96.390, 2072.0, 45.5192
28.274591184, 96.390, 2140.0, 46.2601
28.327112315, 96.390, 2091.0, 45.7275
28.379633446, 96.390, 2071.0, 45.5082
28.432154576, 96.390, 2040.0, 45.1664
28.484675707, 96.390, 1978.0, 44.4747
28.537196838, 96.390, 2042.0, 45.1885
28.589717968, 96.390, 2028.0, 45.0333
28.642239099, 96.390, 2019.0, 44.9333
28.694760230, 96.390, 2016.0, 44.8999
28.747281361, 96.390, 2008.0, 44.8107
28.799802491, 96.390, 1986.0, 44.5646
28.852323622, 96.390, 1988.0, 44.5870
28.904844753, 96.390, 2033.0, 45.0888
28.957365883, 96.390, 2030.0, 45.0555
29.009887014, 96.390, 1915.0, 43.7607
29.062408145, 96.390, 1996.0, 44.6766
29.114929276, 96.390, 1948.0, 44.1362
29.167450406, 96.390, 2007.0, 44.7996
29.219971537, 96.390, 1915.0, 43.7607
29.272492668, 96.390, 1904.0, 43.6348
29.325013798, 96.390, 1862.0, 43.1509
29.377534929, 96.390, 1907.0, 43.6692
29.430056060, 96.390, 1842.0, 42.9185
29.482577191, 96.390, 2039.0, 45.1553
29.535098321, 96.390, 1915.0, 43.7607
29.587619452, 96.390, 1833.0, 42.8135
29.640140583, 96.390, 1966.0, 44.3396
29.692661713, 96.390, 1920.0, 43.8178
29.745182844, 96.390, 1868.0, 43.2204
29.797703975, 96.390, 1903.0, 43.6234
29.850225105, 96.390, 1859.0, 43.1161
29.902746236, 96.390, 1939.0, 44.0341
29.955267367, 96.390, 1847.0, 42.9767
30.007788498, 96.390, 1844.0, 42.9418
30.060309628, 96.390, 1862.0, 43.1509
30.112830759, 96.390, 1843.0, 42.9302
30.165351890, 96.390, 1866.0, 43.1972
30.217873020, 96.390, 1929.0, 43.9204
30.270394151, 96.390, 1823.0, 42.6966
30.322915282, 96.390, 1833.0, 42.8135
30.375436413, 96.390, 1819.0, 42.6497
30.427957543, 96.390, 1797.0, 42.3910
30.480478674, 96.390, 1840.0, 42.8952
30.532999805, 96.390, 1872.0, 43.2666
30.585520935, 96.390, 1863.0, 43.1625
30.638042066, 96.390, 1802.0, 42.4500
30.690563197, 96.390, 1896.0, 43.5431
30.743084328, 96.390, 1834.0, 42.8252
30.795605458, 96.390, 1916.0, 43.7721
30.848126589, 96.390, 1942.0, 44.0681
30.900647720, 96.390, 1818.0, 42.6380
30.953168850, 96.390, 1816.0, 42.6146
31.005689981, 96.390, 1744.0, 41.7612
31.058211112, 96.390, 1823.0, 42.6966
31.110732243, 96.390, 1780.0, 42.1900
31.163253373, 96.390, 1828.0, 42.7551
31.215774504, 96.390, 1917.0, 43.7836
31.268295635, 96.390, 1858.0, 43.1045
31.320816765, 96.390, 1939.0, 44.0341
31.373337896, 96.390, 1828.0, 42.7551
31.425859027, 96.390, 1881.0, 43.3705
31.478380157, 96.390, 1746.0, 41.7852
31.530901288, 96.390, 1805.0, 42.4853
31.583422419, 96.390, 1735.0, 41.6533
31.635943550, 96.390, 1753.0, 41.8688
31.688464680, 96.390, 1843.0, 42.9302
31.740985811, 96.390, 1786.0, 42.2611
31.793506942, 96.390, 1788.0, 42.2847
31.846028072, 96.390, 1800.0, 42.4264
31.898549203, 96.390, 1748.0, 41.8091
31.951070334, 96.390, 1791.0, 42.3202
32.003591465, 96.390, 1936.0, 44.0000
32.056112595, 96.390, 2111.0, 45.9456
32.108633726, 96.390, 2110.0, 45.9347
32.161154857, 96.390, 1967.0, 44.3509
32.213675987, 96.390, 1856.0, 43.0813
32.266197118, 96.390, 1694.0, 41.1582
32.318718249, 96.390, 1699.0, 41.2189
32.371239380, 96.390, 1759.0, 41.9404
32.423760510, 96.390, 1750.0, 41.8330
32.476281641, 96.390, 1692.0, 41.1339
32.528802772, 96.390, 1685.0, 41.0488
32.581323902, 96.390, 1739.0, 41.7013
32.633845033, 96.390, 1664.0, 40.7922
32.686366164, 96.390, 1681.0, 41.0000
32.738887295, 96.390, 1694.0, 41.1582
32.791408425, 96.390, 1740.0, 41.7133
32.843929556, 96.390, 1778.0, 42.1663
32.896450687, 96.390, 1680.0, 40.9878
32.948971817, 96.390, 1815.0, 42.6028
33.001492948, 96.390, 1689.0, 41.0974
33.054014079, 96.390, 1801.0, 42.4382
33.106535209, 96.390, 1851.0, 43.0232
33.159056340, 96.390, 1854.0, 43.0581
33.211577471, 96.390, 1714.0, 41.4005
33.264098602, 96.390, 1808.0, 42.5206
33.316619732, 96.390, 1770.0, 42.0714
33.369140863, 96.390, 1780.0, 42.1900
33.421661994, 96.390, 1850.0, 43.0116
33.474183124, 96.390, 1744.0, 41.7612
33.526704255, 96.390, 1782.0, 42.2137
33.579225386, 96.390, 1759.0, 41.9404
33.631746517, 96.390, 1771.0, 42.0833
33.684267647, 96.390, 1861.0, 43.1393
33.736788778, 96.390, 1884.0, 43.4051
33.789309909, 96.390, 1824.0, 42.7083
33.841831039, 96.390, 1902.0, 43.6119
33.894352170, 96.390, 1948.0, 44.1362
33.946873301, 96.390, 2053.0, 45.3100
33.999394432, 96.390, 1990.0, 44.6094
34.051915562, 96.390, 2052.0, 45.2990
34.104436693, 96.390, 2018.0, 44.9222
34.156957824, 96.390, 2015.0, 44.8888
34.209478954, 96.390, 2002.0, 44.7437
34.262000085, 96.390, 2008.0, 44.8107
34.314521216, 96.390, 1876.0, 43.3128
34.367042346, 96.390, 1963.0, 44.3058
34.419563477, 96.390, 1957.0, 44.2380
34.472084608, 96.390, 1920.0, 43.8178
34.524605739, 96.390, 1996.0, 44.6766
34.577126869, 96.390, 1964.0, 44.3170
34.629648000, 96.390, 1944.0, 44.0908
34.682169131, 96.390, 1965.0, 44.3283
34.734690261, 96.390, 1880.0, 43.3590
34.787211392, 96.390, 1945.0, 44.1022
34.839732523, 96.390, 1902.0, 43.6119
34.892253654, 96.390, 1962.0, 44.2945
34.944774784, 96.390, 2057.0, 45.3542
34.997295915, 96.390, 1968.0, 44.3621
35.049817046, 96.390, 2002.0, 44.7437
35.102338176, 96.390, 1931.0, 43.9431
35.154859307, 96.390, 1977.0, 44.4635
35.207380438, 96.390, 1896.0, 43.5431
35.259901569, 96.390, 1952.0, 44.1814
35.312422699, 96.390, 1905.0, 43.6463
35.364943830, 96.390, 1913.0, 43.7379
35.417464961, 96.390, 1944.0, 44.0908
35.469986091, 96.390, 1980.0, 44.4972
35.522507222, 96.390, 1945.0, 44.1022
35.575028353, 96.390, 1913.0, 43.7379
35.627549484, 96.390, 1905.0, 43.6463
35.680070614, 96.390, 1904.0, 43.6348
35.732591745, 96.390, 2039.0, 45.1553
35.785112876, 96.390, 1928.0, 43.9090
35.837634006, 96.390, 1948.0, 44.1362
35.890155137, 96.390, 1947.0, 44.1248
35.942676268, 96.390, 1965.0, 44.3283
35.995197398, 96.390, 2001.0, 44.7325
36.047718529, 96.390, 1914.0, 43.7493
36.100239660, 96.390, 1903.0, 43.6234
36.152760791, 96.390, 1893.0, 43.5086
36.205281921, 96.390, 2041.0, 45.1774
36.257803052, 96.390, 1971.0, 44.3959
36.310324183, 96.390, 1908.0, 43.6807
36.362845313, 96.390, 2000.0, 44.7214
36.415366444, 96.390, 2088.0, 45.6946
36.467887575, 96.390, 1989.0, 44.5982
36.520408706, 96.390, 2008.0, 44.8107
36.572929836, 96.390, 1884.0, 43.4051
36.625450967, 96.390, 1980.0, 44.4972
36.677972098, 96.390, 2007.0, 44.7996
36.730493228, 96.390, 2026.0, 45.0111
36.783014359, 96.390, 1922.0, 43.8406
36.835535490, 96.390, 1909.0, 43.6921
36.888056621, 96.390, 1850.0, 43.0116
36.940577751, 96.390, 2028.0, 45.0333
36.993098882, 96.390, 1984.0, 44.5421
37.045620013, 96.390, 1892.0, 43.4971
37.098141143, 96.390, 1917.0, 43.7836
37.150662274, 96.390, 1947.0, 44.1248
37.203183405, 96.390, 1929.0, 43.9204
37.255704535, 96.390, 2093.0, 45.7493
37.308225666, 96.390, 2063.0, 45.4203
37.360746797, 96.390, 1983.0, 44.5309
37.413267928, 96.390, 2008.0, 44.8107
37.465789058, 96.390, 2115.0, 45.9891
37.518310189, 96.390, 2054.0, 45.3211
37.570831320, 96.390, 1970.0, 44.3847
37.623352450, 96.390, 2027.0, 45.0222
37.675873581, 96.390, 2064.0, 45.4313
37.728394712, 96.390, 2012.0, 44.8553
37.780915843, 96.390, 2119.0, 46.0326
37.833436973, 96.390, 2077.0, 45.5741
37.885958104, 96.390, 2085.0, 45.6618
37.938479235, 96.390, 2079.0, 45.5961
37.991000365, 96.390, 1982.0, 44.5197
38.043521496, 96.390, 2023.0, 44.9778
38.096042627, 96.390, 2181.0, 46.7012
38.148563758, 96.390, 2192.0, 46.8188
38.201084888, 96.390, 2132.0, 46.1736
38.253606019, 96.390, 2068.0, 45.4753
38.306127150, 96.390, 2023.0, 44.9778
38.358648280, 96.390, 1933.0, 43.9659
38.411169411, 96.390, 1897.0, 43.5546
38.463690542, 96.390, 1979.0, 44.4860
38.516211673, 96.390, 1919.0, 43.8064
38.568732803, 96.390, 1951.0, 44.1701
38.621253934, 96.390, 2026.0, 45.0111
38.673775065, 96.390, 1953.0, 44.1928
38.726296195, 96.390, 1953.0, 44.1928
38.778817326, 96.390, 1857.0, 43.0929
38.831338457, 96.390, 1951.0, 44.1701
38.883859587, 96.390, 1941.0, 44.0568
38.936380718, 96.390, 1859.0, 43.1161
38.988901849, 96.390, 1866.0, 43.1972
39.041422980, 96.390, 1863.0, 43.1625
39.093944110, 96.390, 1819.0, 42.6497
39.146465241, 96.390, 1828.0, 42.7551
39.198986372, 96.390, 1918.0, 43.7950
39.251507502, 96.390, 1792.0, 42.3320
39.304028633, 96.390, 1790.0, 42.3084
39.356549764, 96.390, 1790.0, 42.3084
39.409070895, 96.390, 1821.0, 42.6732
39.461592025, 96.390, 1845.0, 42.9535
39.514113156, 96.390, 1865.0, 43.1856
39.566634287, 96.390, 1741.0, 41.7253
39.619155417, 96.390, 1775.0, 42.1307
39.671676548, 96.390, 1762.0, 41.9762
39.724197679, 96.390, 1808.0, 42.5206
39.776718810, 96.390, 1703.0, 41.2674
39.829239940, 96.390, 1749.0, 41.8210
39.881761071, 96.390, 1766.0, 42.0238
39.934282202, 96.390, 1741.0, 41.7253
39.986803332, 96.390, 1783.0, 42.2256
40.039324463, 96.390, 1670.0, 40.8656
40.091845594, 96.390, 1738.0, 41.6893
40.144366725, 96.390, 1760.0, 41.9524
40.196887855, 96.390, 1778.0, 42.1663
40.249408986, 96.390, 1792.0, 42.3320
40.301930117, 96.390, 1945.0, 44.1022
40.354451247, 96.390, 2046.0, 45.2327
40.406972378, 96.390, 2331.0, 48.2804
40.459493509, 96.390, 2752.0, 52.4595
40.512014639, 96.390, 2922.0, 54.0555
40.564535770, 96.390, 3186.0, 56.4447
40.617056901, 96.390, 3403.0, 58.3352
40.669578032, 96.390, 3071.0, 55.4166
40.722099162, 96.390, 2657.0, 51.5461
40.774620293, 96.390, 2252.0, 47.4552
40.827141424, 96.390, 1868.0, 43.2204
40.879662554, 96.390, 1722.0, 41.4970
40.932183685, 96.390, 1671.0, 40.8779
40.984704816, 96.390, 1640.0, 40.4969
41.037225947, 96.390, 1533.0, 39.1535
41.089747077, 96.390, 1585.0, 39.8121
41.142268208, 96.390, 1597.0, 39.9625
41.194789339, 96.390, 1506.0, 38.8072
41.247310469, 96.390, 1527.0, 39.0768
41.299831600, 96.390, 1512.0, 38.8844
41.352352731, 96.390, 1454.0, 38.1314
41.404873862, 96.390, 1576.0, 39.6989
41.457394992, 96.390, 1566.0, 39.5727
41.509916123, 96.390, 1514.0, 38.9102
41.562437254, 96.390, 1487.0, 38.5616
41.614958384, 96.390, 1524.0, 39.0384
41.667479515, 96.390, 1430.0, 37.8153
41.720000646, 96.390, 1411.0, 37.5633
41.772521776, 96.390, 1441.0, 37.9605
41.825042907, 96.390, 1465.0, 38.2753
41.877564038, 96.390, 1458.0, 38.1838
41.930085169, 96.390, 1496.0, 38.6782
41.982606299, 96.390, 1430.0, 37.8153
42.035127430, 96.390, 1425.0, 37.7492
42.087648561, 96.390, 1391.0, 37.2961
42.140169691, 96.390, 1408.0, 37.5233
42.192690822, 96.390, 1410.0, 37.5500
42.245211953, 96.390, 1363.0, 36.9188
42.297733084, 96.390, 1436.0, 37.8946
42.350254214, 96.390, 1350.0, 36.7423
42.402775345, 96.390, 1315.0, 36.2629
42.455296476, 96.390, 1374.0, 37.0675
42.507817606, 96.390, 1368.0, 36.9865
42.560338737, 96.390, 1436.0, 37.8946
42.612859868, 96.390, 1400.0, 37.4166
42.665380999, 96.390, 1381.0, 37.1618
42.717902129, 96.390, 1357.0, 36.8375
42.770423260, 96.390, 1397.0, 37.3765
42.822944391, 96.390, 1333.0, 36.5103
42.875465521, 96.390, 1355.0, 36.8103
42.927986652, 96.390, 1369.0, 37.0000
42.980507783, 96.390, 1348.0, 36.7151
43.033028914, 96.390, 1305.0, 36.1248
43.085550044, 96.390, 1341.0, 36.6197
43.138071175, 96.390, 1342.0, 36.6333
43.190592306, 96.390, 1378.0, 37.1214
43.243113436, 96.390, 1406.0, 37.4967
43.295634567, 96.390, 1341.0, 36.6197
43.348155698, 96.390, 1331.0, 36.4829
43.400676828, 96.390, 1323.0, 36.3731
43.453197959, 96.390, 1411.0, 37.5633
43.505719090, 96.390, 1352.0, 36.7696
43.558240221, 96.390, 1351.0, 36.7560
43.610761351, 96.390, 1377.0, 37.1080
43.663282482, 96.390, 1368.0, 36.9865
43.715803613, 96.390, 1497.0, 38.6911
43.768324743, 96.390, 1438.0, 37.9210
43.820845874, 96.390, 1425.0, 37.7492
43.873367005, 96.390, 1475.0, 38.4057
43.925888136, 96.390, 1336.0, 36.5513
43.978409266, 96.390, 1394.0, 37.3363
44.030930397, 96.390, 1347.0, 36.7015
44.083451528, 96.390, 1363.0, 36.9188
44.135972658, 96.390, 1312.0, 36.2215
44.188493789, 96.390, 1329.0, 36.4555
44.241014920, 96.390, 1354.0, 36.7967
44.293536051, 96.390, 1351.0, 36.7560
44.346057181, 96.390, 1373.0, 37.0540
44.398578312, 96.390, 1419.0, 37.6696
44.451099443, 96.390, 1370.0, 37.0135
44.503620573, 96.390, 1294.0, 35.9722
44.556141704, 96.390, 1393.0, 37.3229
44.608662835, 96.390, 1375.0, 37.0810
44.661183966, 96.390, 1332.0, 36.4966
44.713705096, 96.390, 1385.0, 37.2156
44.766226227, 96.390, 1377.0, 37.1080
44.818747358, 96.390, 1375.0, 37.0810
44.871268488, 96.390, 1358.0, 36.8511
44.923789619, 96.390, 1314.0, 36.2491
44.976310750, 96.390, 1418.0, 37.6563
45.028831880, 96.390, 1384.0, 37.2022
45.081353011, 96.390, 1425.0, 37.7492
45.133874142, 96.390, 1376.0, 37.0945
45.186395273, 96.390, 1430.0, 37.8153
45.238916403, 96.390, 1446.0, 38.0263
45.291437534, 96.390, 1312.0, 36.2215
45.343958665, 96.390, 1465.0, 38.2753
45.396479795, 96.390, 1383.0, 37.1887
45.449000926, 96.390, 1435.0, 37.8814
45.501522057, 96.390, 1451.0, 38.0920
45.554043188, 96.390, 1410.0, 37.5500
45.606564318, 96.390, 1437.0, 37.9078
45.659085449, 96.390, 1455.0, 38.1445
45.711606580, 96.390, 1475.0, 38.4057
45.764127710, 96.390, 1496.0, 38.6782
45.816648841, 96.390, 1438.0, 37.9210
45.869169972, 96.390, 1456.0, 38.1576
45.921691103, 96.390, 1432.0, 37.8418
45.974212233, 96.390, 1377.0, 37.1080
46.026733364, 96.390, 1448.0, 38.0526
46.079254495, 96.390, 1412.0, 37.5766
46.131775625, 96.390, 1450.0, 38.0789
46.184296756, 96.390, 1387.0, 37.2424
46.236817887, 96.390, 1455.0, 38.1445
46.289339017, 96.390, 1398.0, 37.3898
46.341860148, 96.390, 1427.0, 37.7757
46.394381279, 96.390, 1437.0, 37.9078
46.446902410, 96.390, 1413.0, 37.5899
46.499423540, 96.390, 1372.0, 37.0405
46.551944671, 96.390, 1422.0, 37.7094
46.604465802, 96.390, 1386.0, 37.2290
46.656986932, 96.390, 1367.0, 36.9730
46.709508063, 96.390, 1352.0, 36.7696
46.762029194, 96.390, 1453.0, 38.1182
46.814550325, 96.390, 1373.0, 37.0540
46.867071455, 96.390, 1378.0, 37.1214
46.919592586, 96.390, 1442.0, 37.9737
46.972113717, 96.390, 1381.0, 37.1618
47.024634847, 96.390, 1467.0, 38.3014
47.077155978, 96.390, 1356.0, 36.8239
47.129677109, 96.390, 1508.0, 38.8330
47.182198240, 96.390, 1418.0, 37.6563
47.234719370, 96.390, 1429.0, 37.8021
47.287240501, 96.390, 1427.0, 37.7757
47.339761632, 96.390, 1421.0, 37.6962
47.392282762, 96.390, 1359.0, 36.8646
47.444803893, 96.390, 1359.0, 36.8646
47.497325024, 96.390, 1436.0, 37.8946
47.549846155, 96.390, 1447.0, 38.0395
47.602367285, 96.390, 1452.0, 38.1051
47.654888416, 96.390, 1461.0, 38.2230
47.707409547, 96.390, 1465.0, 38.2753
47.759930677, 96.390, 1466.0, 38.2884
47.812451808, 96.390, 1429.0, 37.8021
47.864972939, 96.390, 1504.0, 38.7814
47.917494069, 96.390, 1487.0, 38.5616
47.970015200, 96.390, 1440.0, 37.9473
48.022536331, 96.390, 1433.0, 37.8550
48.075057462, 96.390, 1521.0, 39.0000
48.127578592, 96.390, 1490.0, 38.6005
48.180099723, 96.390, 1437.0, 37.9078
48.232620854, 96.390, 1578.0, 39.7240
48.285141984, 96.390, 1449.0, 38.0657
48.337663115, 96.390, 1453.0, 38.1182
48.390184246, 96.390, 1576.0, 39.6989
48.442705377, 96.390, 1542.0, 39.2683
48.495226507, 96.390, 1509.0, 38.8458
48.547747638, 96.390, 1537.0, 39.2046
48.600268769, 96.390, 1550.0, 39.3700
48.652789899, 96.390, 1455.0, 38.1445
48.705311030, 96.390, 1517.0, 38.9487
48.757832161, 96.390, 1505.0, 38.7943
48.810353292, 96.390, 1562.0, 39.5221
48.862874422, 96.390, 1433.0, 37.8550
48.915395553, 96.390, 1510.0, 38.8587
48.967916684, 96.390, 1532.0, 39.1408
49.020437814, 96.390, 1516.0, 38.9358
49.072958945, 96.390, 1481.0, 38.4838
49.125480076, 96.390, 1498.0, 38.7040
49.178001207, 96.390, 1462.0, 38.2361
49.230522337, 96.390, 1464.0, 38.2623
49.283043468, 96.390, 1438.0, 37.9210
49.335564599, 96.390, 1477.0, 38.4318
49.388085729, 96.390, 1410.0, 37.5500
49.440606860, 96.390, 1437.0, 37.9078
49.493127991, 96.390, 1544.0, 39.2938
49.545649121, 96.390, 1478.0, 38.4448
49.598170252, 96.390, 1480.0, 38.4708
49.650691383, 96.390, 1396.0, 37.3631
49.703212514, 96.390, 1435.0, 37.8814
49.755733644, 96.390, 1400.0, 37.4166
49.808254775, 96.390, 1357.0, 36.8375
49.860775906, 96.390, 1371.0, 37.0270
49.913297036, 96.390, 1371.0, 37.0270
49.965818167, 96.390, 1378.0, 37.1214
50.018339298, 96.390, 1329.0, 36.4555
50.070860429, 96.390, 1376.0, 37.0945
50.123381559, 96.390, 1316.0, 36.2767
50.175902690, 96.390, 1398.0, 37.3898
50.228423821, 96.390, 1293.0, 35.9583
50.280944951, 96.390, 1414.0, 37.6032
50.333466082, 96.390, 1283.0, 35.8190
50.385987213, 96.390, 1295.0, 35.9861
50.438508344, 96.390, 1359.0, 36.8646
50.491029474, 96.390, 1192.0, 34.5254
50.543550605, 96.390, 1265.0, 35.5668
50.596071736, 96.390, 1255.0, 35.4260
50.648592866, 96.390, 1267.0, 35.5949
50.701113997, 96.390, 1239.0, 35.1994
50.753635128, 96.390, 1203.0, 34.6843
50.806156258, 96.390, 1224.0, 34.9857
50.858677389, 96.390, 1231.0, 35.0856
50.911198520, 96.390, 1231.0, 35.0856
50.963719651, 96.390, 1178.0, 34.3220
51.016240781, 96.390, 1136.0, 33.7046
51.068761912, 96.390, 1149.0, 33.8969
51.121283043, 96.390, 1193.0, 34.5398
51.173804173, 96.390, 1184.0, 34.4093
51.226325304, 96.390, 1158.0, 34.0294
51.278846435, 96.390, 1191.0, 34.5109
51.331367566, 96.390, 1147.0, 33.8674
51.383888696, 96.390, 1170.0, 34.2053
51.436409827, 96.390, 1180.0, 34.3511
51.488930958, 96.390, 1179.0, 34.3366
51.541452088, 96.390, 1132.0, 33.6452
51.593973219, 96.390, 1174.0, 34.2637
51.646494350, 96.390, 1120.0, 33.4664
51.699015481, 96.390, 1179.0, 34.3366
51.751536611, 96.390, 1131.0, 33.6303
51.804057742, 96.390, 1074.0, 32.7719
51.856578873, 96.390, 1117.0, 33.4215
51.909100003, 96.390, 1090.0, 33.0151
51.961621134, 96.390, 1080.0, 32.8634
52.014142265, 96.390, 1152.0, 33.9411
52.066663396, 96.390, 1084.0, 32.9242
52.119184526, 96.390, 1145.0, 33.8378
52.171705657, 96.390, 1116.0, 33.4066
52.224226788, 96.390, 1131.0, 33.6303
52.276747918, 96.390, 1151.0, 33.9264
52.329269049, 96.390, 1116.0, 33.4066
52.381790180, 96.390, 1078.0, 32.8329
52.434311310, 96.390, 1108.0, 33.2866
52.486832441, 96.390, 1095.0, 33.0908
52.539353572, 96.390, 1070.0, 32.7109
52.591874703, 96.390, 1063.0, 32.6037
52.644395833, 96.390, 1151.0, 33.9264
52.696916964, 96.390, 1035.0, 32.1714
52.749438095, 96.390, 1135.0, 33.6898
52.801959225, 96.390, 1141.0, 33.7787
52.854480356, 96.390, 1167.0, 34.1614
52.907001487, 96.390, 1214.0, 34.8425
52.959522618, 96.390, 1163.0, 34.1028
53.012043748, 96.390, 1332.0, 36.4966
53.064564879, 96.390, 1427.0, 37.7757
53.117086010, 96.390, 1666.0, 40.8167
53.169607140, 96.390, 1754.0, 41.8808
53.222128271, 96.390, 1589.0, 39.8623
53.274649402, 96.390, 1612.0, 40.1497
53.327170533, 96.390, 1490.0, 38.6005
53.379691663, 96.390, 1296.0, 36.0000
53.432212794, 96.390, 1171.0, 34.2199
53.484733925, 96.390, 1200.0, 34.6410
53.537255055, 96.390, 1104.0, 33.2265
53.589776186, 96.390, 1061.0, 32.5730
53.642297317, 96.390, 1086.0, 32.9545
53.694818448, 96.390, 1040.0, 32.2490
53.747339578, 96.390, 1068.0, 32.6803
53.799860709, 96.390, 1051.0, 32.4191
53.852381840, 96.390, 1063.0, 32.6037
53.904902970, 96.390, 983.0, 31.3528
53.957424101, 96.390, 1043.0, 32.2955
54.009945232, 96.390, 992.0, 31.4960
54.062466362, 96.390, 1006.0, 31.7175
54.114987493, 96.390, 943.0, 30.7083
54.167508624, 96.390, 1049.0, 32.3883
54.220029755, 96.390, 1040.0, 32.2490
54.272550885, 96.390, 995.0, 31.5436
54.325072016, 96.390, 1039.0, 32.2335
54.377593147, 96.390, 958.0, 30.9516
54.430114277, 96.390, 949.0, 30.8058
54.482635408, 96.390, 960.0, 30.9839
54.535156539, 96.390, 952.0, 30.8545
54.587677670, 96.390, 1007.0, 31.7333
54.640198800, 96.390, 991.0, 31.4802
54.692719931, 96.390, 963.0, 31.0322
54.745241062, 96.390, 943.0, 30.7083
54.797762192, 96.390, 946.0, 30.7571
54.850283323, 96.390, 884.0, 29.7321
54.902804454, 96.390, 878.0, 29.6311
54.955325585, 96.390, 971.0, 31.1609
55.007846715, 96.390, 941.0, 30.6757
55.060367846, 96.390, 911.0, 30.1828
55.112888977, 96.390, 899.0, 29.9833
55.165410107, 96.390, 895.0, 29.9166
55.217931238, 96.390, 882.0, 29.6985
55.270452369, 96.390, 924.0, 30.3974
55.322973499, 96.390, 954.0, 30.8869
55.375494630, 96.390, 936.0, 30.5941
55.428015761, 96.390, 943.0, 30.7083
55.480536892, 96.390, 967.0, 31.0966
55.533058022, 96.390, 960.0, 30.9839
55.585579153, 96.390, 969.0, 31.1288
55.638100284, 96.390, 950.0, 30.8221
55.690621414, 96.390, 950.0, 30.8221
55.743142545, 96.390, 981.0, 31.3209
55.795663676, 96.390, 953.0, 30.8707
55.848184807, 96.390, 983.0, 31.3528
55.900705937, 96.390, 935.0, 30.5778
55.953227068, 96.390, 981.0, 31.3209
56.005748199, 96.390, 954.0, 30.8869
56.058269329, 96.390, 911.0, 30.1828
56.110790460, 96.390, 935.0, 30.5778
56.163311591, 96.390, 897.0, 29.9500
56.215832722, 96.390, 907.0, 30.1164
56.268353852, 96.390, 922.0, 30.3645
56.320874983, 96.390, 875.0, 29.5804
56.373396114, 96.390, 970.0, 31.1448
56.425917244, 96.390, 919.0, 30.3150
56.478438375, 96.390, 920.0, 30.3315
56.530959506, 96.390, 1011.0, 31.7962
56.583480637, 96.390, 894.0, 29.8998
56.636001767, 96.390, 825.0, 28.7228
56.688522898, 96.390, 904.0, 30.0666
56.741044029, 96.390, 853.0, 29.2062
56.793565159, 96.390, 876.0, 29.5973
56.846086290, 96.390, 880.0, 29.6648
56.898607421, 96.390, 857.0, 29.2746
56.951128551, 96.390, 876.0, 29.5973
57.003649682, 96.390, 927.0, 30.4467
57.056170813, 96.390, 931.0, 30.5123
57.108691944, 96.390, 953.0, 30.8707
57.161213074, 96.390, 883.0, 29.7153
57.213734205, 96.390, 855.0, 29.2404
57.266255336, 96.390, 984.0, 31.3688
57.318776466, 96.390, 883.0, 29.7153
57.371297597, 96.390, 917.0, 30.2820
57.423818728, 96.390, 929.0, 30.4795
57.476339859, 96.390, 956.0, 30.9192
57.528860989, 96.390, 957.0, 30.9354
57.581382120, 96.390, 963.0, 31.0322
57.633903251, 96.390, 954.0, 30.8869
57.686424381, 96.390, 958.0, 30.9516
57.738945512, 96.390, 918.0, 30.2985
57.791466643, 96.390, 949.0, 30.8058
57.843987774, 96.390, 895.0, 29.9166
57.896508904, 96.390, 873.0, 29.5466
57.949030035, 96.390, 895.0, 29.9166
58.001551166, 96.390, 895.0, 29.9166
58.054072296, 96.390, 839.0, 28.9655
58.106593427, 96.390, 933.0, 30.5450
58.159114558, 96.390, 968.0, 31.1127
58.211635689, 96.390, 881.0, 29.6816
58.264156819, 96.390, 905.0, 30.0832
58.316677950, 96.390, 907.0, 30.1164
58.369199081, 96.390, 924.0, 30.3974
58.421720211, 96.390, 862.0, 29.3598
58.474241342, 96.390, 920.0, 30.3315
58.526762473, 96.390, 871.0, 29.5127
58.579283603, 96.390, 891.0, 29.8496
58.631804734, 96.390, 924.0, 30.3974
58.684325865, 96.390, 892.0, 29.8664
58.736846996, 96.390, 901.0, 30.0167
58.789368126, 96.390, 922.0, 30.3645
58.841889257, 96.390, 923.0, 30.3809
58.894410388, 96.390, 892.0, 29.8664
58.946931518, 96.390, 870.0, 29.4958
58.999452649, 96.390, 945.0, 30.7409
59.051973780, 96.390, 911.0, 30.1828
59.104494911, 96.390, 967.0, 31.0966
59.157016041, 96.390, 921.0, 30.3480
59.209537172, 96.390, 930.0, 30.4959
59.262058303, 96.390, 980.0, 31.3050
59.314579433, 96.390, 924.0, 30.3974
59.367100564, 96.390, 924.0, 30.3974
59.419621695, 96.390, 951.0, 30.8383
59.472142826, 96.390, 993.0, 31.5119
59.524663956, 96.390, 970.0, 31.1448
59.577185087, 96.390, 936.0, 30.5941
59.629706218, 96.390, 931.0, 30.5123
59.682227348, 96.390, 954.0, 30.8869
59.734748479, 96.390, 945.0, 30.7409
59.787269610, 96.390, 963.0, 31.0322
59.839790740, 96.390, 952.0, 30.8545
59.892311871, 96.390, 896.0, 29.9333
59.944833002, 96.390, 936.0, 30.5941
59.997354133, 96.390, 965.0, 31.0644
60.049875263, 96.390, 946.0, 30.7571
60.102396394, 96.390, 929.0, 30.4795
60.154917525, 96.390, 917.0, 30.2820
60.207438655, 96.390, 904.0, 30.0666
60.259959786, 96.390, 996.0, 31.5595
60.312480917, 96.390, 955.0, 30.9031
60.365002048, 96.390, 951.0, 30.8383
60.417523178, 96.390, 993.0, 31.5119
60.470044309, 96.390, 944.0, 30.7246
60.522565440, 96.390, 1008.0, 31.7490
60.575086570, 96.390, 1032.0, 32.1248
60.627607701, 96.390, 1003.0, 31.6702
60.680128832, 96.390, 1097.0, 33.1210
60.732649963, 96.390, 1056.0, 32.4962
60.785171093, 96.390, 1049.0, 32.3883
60.837692224, 96.390, 1005.0, 31.7017
60.890213355, 96.390, 1026.0, 32.0312
60.942734485, 96.390, 1036.0, 32.1870
60.995255616, 96.390, 1125.0, 33.5410
61.047776747, 96.390, 1056.0, 32.4962
61.100297878, 96.390, 1032.0, 32.1248
61.152819008, 96.390, 1071.0, 32.7261
61.205340139, 96.390, 1138.0, 33.7343
61.257861270, 96.390, 1131.0, 33.6303
61.310382400, 96.390, 1100.0, 33.1662
61.362903531, 96.390, 1153.0, 33.9559
61.415424662, 96.390, 1144.0, 33.8231
61.467945792, 96.390, 1055.0, 32.4808
61.520466923, 96.390, 1111.0, 33.3317
61.572988054, 96.390, 1145.0, 33.8378
61.625509185, 96.390, 1147.0, 33.8674
61.678030315, 96.390, 1115.0, 33.3916
61.730551446, 96.390, 1051.0, 32.4191
61.783072577, 96.390, 1095.0, 33.0908
61.835593707, 96.390, 1129.0, 33.6006
61.888114838, 96.390, 1160.0, 34.0588
61.940635969, 96.390, 1153.0, 33.9559
61.993157100, 96.390, 1131.0, 33.6303
62.045678230, 96.390, 1132.0, 33.6452
62.098199361, 96.390, 1074.0, 32.7719
62.150720492, 96.390, 1077.0, 32.8177
62.203241622, 96.390, 1148.0, 33.8821
62.255762753, 96.390, 1137.0, 33.7194
62.308283884, 96.390, 1109.0, 33.3017
62.360805015, 96.390, 1107.0, 33.2716
62.413326145, 96.390, 1108.0, 33.2866
62.465847276, 96.390, 1073.0, 32.7567
62.518368407, 96.390, 1102.0, 33.1964
62.570889537, 96.390, 1049.0, 32.3883
62.623410668, 96.390, 1089.0, 33.0000
62.675931799, 96.390, 1108.0, 33.2866
62.728452930, 96.390, 1020.0, 31.9374
62.780974060, 96.390, 1068.0, 32.6803
62.833495191, 96.390, 1086.0, 32.9545
62.886016322, 96.390, 1029.0, 32.0780
62.938537452, 96.390, 1048.0, 32.3728
62.991058583, 96.390, 1058.0, 32.5269
63.043579714, 96.390, 1064.0, 32.6190
63.096100844, 96.390, 1053.0, 32.4500
63.148621975, 96.390, 1082.0, 32.8938
63.201143106, 96.390, 1012.0, 31.8119
63.253664237, 96.390, 1028.0, 32.0624
63.306185367, 96.390, 994.0, 31.5278
63.358706498, 96.390, 1048.0, 32.3728
63.411227629, 96.390, 1088.0, 32.9848
63.463748759, 96.390, 1063.0, 32.6037
63.516269890, 96.390, 1025.0, 32.0156
63.568791021, 96.390, 1058.0, 32.5269
63.621312152, 96.390, 1099.0, 33.1512
63.673833282, 96.390, 1138.0, 33.7343
63.726354413, 96.390, 1194.0, 34.5543
63.778875544, 96.390, 1270.0, 35.6371
63.831396674, 96.390, 1228.0, 35.0428
63.883917805, 96.390, 1245.0, 35.2846
63.936438936, 96.390, 1155.0, 33.9853
63.988960067, 96.390, 1111.0, 33.3317
64.041481197, 96.390, 1102.0, 33.1964
64.094002328, 96.390, 1045.0, 32.3265
64.146523459, 96.390, 1049.0, 32.3883
64.199044589, 96.390, 1070.0, 32.7109
64.251565720, 96.390, 1099.0, 33.1512
64.304086851, 96.390, 1074.0, 32.7719
64.356607981, 96.390, 1108.0, 33.2866
64.409129112, 96.390, 1067.0, 32.6650
64.461650243, 96.390, 1090.0, 33.0151
64.514171374, 96.390, 1072.0, 32.7414
64.566692504, 96.390, 1032.0, 32.1248
64.619213635, 96.390, 996.0, 31.5595
64.671734766, 96.390, 1013.0, 31.8277
64.724255896, 96.390, 1023.0, 31.9844
64.776777027, 96.390, 998.0, 31.5911
64.829298158, 96.390, 937.0, 30.6105
64.881819289, 96.390, 950.0, 30.8221
64.934340419, 96.390, 985.0, 31.3847
64.986861550, 96.390, 952.0, 30.8545