File: Files_organized_for_plots/Constant_NaOH_half_mL10M_to_1gPC/XRD_SiCorner03Feb22_Act01Mar22_B2_0455M_NaOH_LS0122_1.csv
[Measurement conditions]
Sample identification,XRD_Si Corner03Feb22_Act01Mar22_B2_0455M_NaOH_LS0122_1
Comment - 1,"Configuration=Stage for Flat Samples/Holders, Owner=User-1, Creation date=7/1/2020 9:53:24 AM"
Comment - 2,"Goniometer=Theta/Theta; Minimum step size 2Theta:0.0001; Minimum step size Omega:0.0001"
Comment - 3,"Sample stage=Stage for flat samples/holders"
Comment - 4,"Diffractometer system=EMPYREAN"
Comment - 5,"Measurement program=C:\Users\ibo5034\OneDrive - The Pennsylvania State University\NEUP - Reed, Titus's files\XRD\Cement\Zerobackground scan.xrdmp, Identifier={98A3B11C-88F9-4AA6-982C-73314A311EF5}"
Anode material,Cu
K-Alpha1 wavelength,1.5405980
K-Alpha2 wavelength,1.5444260
Ratio K-Alpha2/K-Alpha1,0.500
Divergence slit,Fixed,0.25
Monochromator used,NO
Generator voltage, 45
Tube current, 40
File date and time,04/Mar/2022 12:55
Unit cell,
h k l, 0 0 0
Scan axis,Gonio
Scan range,4.994599997,64.999991833
Scan step size,0.0262606
No. of points, 2285
Scan type,CONTINUOUS
Time per step,96.390
[Scan points]
Angle, TimePerStep, Intensity, ESD
5.007730280, 96.390, 4739.0, 68.8404
5.060251411, 96.390, 4781.0, 69.1448
5.112772541, 96.390, 4670.0, 68.3374
5.165293672, 96.390, 4568.0, 67.5870
5.217814803, 96.390, 4469.0, 66.8506
5.270335934, 96.390, 4412.0, 66.4229
5.322857064, 96.390, 4431.0, 66.5658
5.375378195, 96.390, 4378.0, 66.1665
5.427899326, 96.390, 4224.0, 64.9923
5.480420456, 96.390, 4283.0, 65.4446
5.532941587, 96.390, 4128.0, 64.2495
5.585462718, 96.390, 4112.0, 64.1249
5.637983849, 96.390, 4138.0, 64.3273
5.690504979, 96.390, 3967.0, 62.9841
5.743026110, 96.390, 3929.0, 62.6817
5.795547241, 96.390, 3952.0, 62.8649
5.848068371, 96.390, 4027.0, 63.4586
5.900589502, 96.390, 3864.0, 62.1611
5.953110633, 96.390, 3918.0, 62.5939
6.005631763, 96.390, 3888.0, 62.3538
6.058152894, 96.390, 3866.0, 62.1772
6.110674025, 96.390, 3907.0, 62.5060
6.163195156, 96.390, 3930.0, 62.6897
6.215716286, 96.390, 3851.0, 62.0564
6.268237417, 96.390, 3840.0, 61.9677
6.320758548, 96.390, 3884.0, 62.3217
6.373279678, 96.390, 3763.0, 61.3433
6.425800809, 96.390, 3763.0, 61.3433
6.478321940, 96.390, 3819.0, 61.7981
6.530843071, 96.390, 3679.0, 60.6548
6.583364201, 96.390, 3821.0, 61.8142
6.635885332, 96.390, 3718.0, 60.9754
6.688406463, 96.390, 3751.0, 61.2454
6.740927593, 96.390, 3746.0, 61.2046
6.793448724, 96.390, 3754.0, 61.2699
6.845969855, 96.390, 3758.0, 61.3025
6.898490986, 96.390, 3676.0, 60.6300
6.951012116, 96.390, 3637.0, 60.3075
7.003533247, 96.390, 3622.0, 60.1831
7.056054378, 96.390, 3600.0, 60.0000
7.108575508, 96.390, 3648.0, 60.3987
7.161096639, 96.390, 3619.0, 60.1581
7.213617770, 96.390, 3595.0, 59.9583
7.266138900, 96.390, 3583.0, 59.8582
7.318660031, 96.390, 3563.0, 59.6909
7.371181162, 96.390, 3569.0, 59.7411
7.423702293, 96.390, 3625.0, 60.2080
7.476223423, 96.390, 3582.0, 59.8498
7.528744554, 96.390, 3599.0, 59.9917
7.581265685, 96.390, 3535.0, 59.4559
7.633786815, 96.390, 3505.0, 59.2030
7.686307946, 96.390, 3613.0, 60.1082
7.738829077, 96.390, 3464.0, 58.8558
7.791350208, 96.390, 3453.0, 58.7622
7.843871338, 96.390, 3515.0, 59.2874
7.896392469, 96.390, 3459.0, 58.8133
7.948913600, 96.390, 3405.0, 58.3524
8.001434730, 96.390, 3398.0, 58.2924
8.053955861, 96.390, 3545.0, 59.5399
8.106476992, 96.390, 3588.0, 59.8999
8.158998123, 96.390, 3469.0, 58.8982
8.211519253, 96.390, 3379.0, 58.1292
8.264040384, 96.390, 3461.0, 58.8303
8.316561515, 96.390, 3457.0, 58.7963
8.369082645, 96.390, 3318.0, 57.6021
8.421603776, 96.390, 3390.0, 58.2237
8.474124907, 96.390, 3405.0, 58.3524
8.526646038, 96.390, 3380.0, 58.1378
8.579167168, 96.390, 3411.0, 58.4038
8.631688299, 96.390, 3324.0, 57.6541
8.684209430, 96.390, 3419.0, 58.4722
8.736730560, 96.390, 3275.0, 57.2276
8.789251691, 96.390, 3296.0, 57.4108
8.841772822, 96.390, 3247.0, 56.9825
8.894293952, 96.390, 3305.0, 57.4891
8.946815083, 96.390, 3253.0, 57.0351
8.999336214, 96.390, 3309.0, 57.5239
9.051857345, 96.390, 3235.0, 56.8771
9.104378475, 96.390, 3280.0, 57.2713
9.156899606, 96.390, 3274.0, 57.2189
9.209420737, 96.390, 3274.0, 57.2189
9.261941867, 96.390, 3156.0, 56.1783
9.314462998, 96.390, 3272.0, 57.2014
9.366984129, 96.390, 3080.0, 55.4977
9.419505260, 96.390, 3178.0, 56.3738
9.472026390, 96.390, 3141.0, 56.0446
9.524547521, 96.390, 3088.0, 55.5698
9.577068652, 96.390, 3139.0, 56.0268
9.629589782, 96.390, 3230.0, 56.8331
9.682110913, 96.390, 3015.0, 54.9090
9.734632044, 96.390, 3061.0, 55.3263
9.787153175, 96.390, 3044.0, 55.1725
9.839674305, 96.390, 3065.0, 55.3624
9.892195436, 96.390, 2976.0, 54.5527
9.944716567, 96.390, 3028.0, 55.0273
9.997237697, 96.390, 3078.0, 55.4797
10.049758828, 96.390, 3103.0, 55.7046
10.102279959, 96.390, 3024.0, 54.9909
10.154801090, 96.390, 2988.0, 54.6626
10.207322220, 96.390, 2975.0, 54.5436
10.259843351, 96.390, 2977.0, 54.5619
10.312364482, 96.390, 3005.0, 54.8179
10.364885612, 96.390, 2955.0, 54.3599
10.417406743, 96.390, 2957.0, 54.3783
10.469927874, 96.390, 2890.0, 53.7587
10.522449004, 96.390, 2929.0, 54.1202
10.574970135, 96.390, 2953.0, 54.3415
10.627491266, 96.390, 2946.0, 54.2771
10.680012397, 96.390, 2854.0, 53.4228
10.732533527, 96.390, 2952.0, 54.3323
10.785054658, 96.390, 2864.0, 53.5164
10.837575789, 96.390, 2821.0, 53.1131
10.890096919, 96.390, 2841.0, 53.3010
10.942618050, 96.390, 2845.0, 53.3385
10.995139181, 96.390, 2842.0, 53.3104
11.047660312, 96.390, 2712.0, 52.0769
11.100181442, 96.390, 2829.0, 53.1883
11.152702573, 96.390, 2804.0, 52.9528
11.205223704, 96.390, 2767.0, 52.6023
11.257744834, 96.390, 2671.0, 51.6817
11.310265965, 96.390, 2740.0, 52.3450
11.362787096, 96.390, 2757.0, 52.5071
11.415308227, 96.390, 2742.0, 52.3641
11.467829357, 96.390, 2652.0, 51.4976
11.520350488, 96.390, 2709.0, 52.0481
11.572871619, 96.390, 2680.0, 51.7687
11.625392749, 96.390, 2640.0, 51.3809
11.677913880, 96.390, 2677.0, 51.7397
11.730435011, 96.390, 2649.0, 51.4684
11.782956141, 96.390, 2707.0, 52.0288
11.835477272, 96.390, 2585.0, 50.8429
11.887998403, 96.390, 2713.0, 52.0865
11.940519534, 96.390, 2638.0, 51.3615
11.993040664, 96.390, 2643.0, 51.4101
12.045561795, 96.390, 2542.0, 50.4183
12.098082926, 96.390, 2677.0, 51.7397
12.150604056, 96.390, 2640.0, 51.3809
12.203125187, 96.390, 2644.0, 51.4198
12.255646318, 96.390, 2580.0, 50.7937
12.308167449, 96.390, 2626.0, 51.2445
12.360688579, 96.390, 2610.0, 51.0882
12.413209710, 96.390, 2556.0, 50.5569
12.465730841, 96.390, 2547.0, 50.4678
12.518251971, 96.390, 2608.0, 51.0686
12.570773102, 96.390, 2498.0, 49.9800
12.623294233, 96.390, 2538.0, 50.3786
12.675815364, 96.390, 2457.0, 49.5681
12.728336494, 96.390, 2427.0, 49.2646
12.780857625, 96.390, 2458.0, 49.5782
12.833378756, 96.390, 2605.0, 51.0392
12.885899886, 96.390, 2505.0, 50.0500
12.938421017, 96.390, 2570.0, 50.6952
12.990942148, 96.390, 2525.0, 50.2494
13.043463279, 96.390, 2432.0, 49.3153
13.095984409, 96.390, 2512.0, 50.1199
13.148505540, 96.390, 2492.0, 49.9199
13.201026671, 96.390, 2504.0, 50.0400
13.253547801, 96.390, 2581.0, 50.8035
13.306068932, 96.390, 2546.0, 50.4579
13.358590063, 96.390, 2486.0, 49.8598
13.411111193, 96.390, 2400.0, 48.9898
13.463632324, 96.390, 2394.0, 48.9285
13.516153455, 96.390, 2499.0, 49.9900
13.568674586, 96.390, 2435.0, 49.3457
13.621195716, 96.390, 2488.0, 49.8799
13.673716847, 96.390, 2489.0, 49.8899
13.726237978, 96.390, 2481.0, 49.8096
13.778759108, 96.390, 2536.0, 50.3587
13.831280239, 96.390, 2633.0, 51.3128
13.883801370, 96.390, 2504.0, 50.0400
13.936322501, 96.390, 2467.0, 49.6689
13.988843631, 96.390, 2521.0, 50.2096
14.041364762, 96.390, 2415.0, 49.1426
14.093885893, 96.390, 2397.0, 48.9592
14.146407023, 96.390, 2412.0, 49.1121
14.198928154, 96.390, 2452.0, 49.5177
14.251449285, 96.390, 2680.0, 51.7687
14.303970416, 96.390, 3119.0, 55.8480
14.356491546, 96.390, 2455.0, 49.5480
14.409012677, 96.390, 2515.0, 50.1498
14.461533808, 96.390, 2450.0, 49.4975
14.514054938, 96.390, 2428.0, 49.2747
14.566576069, 96.390, 2420.0, 49.1935
14.619097200, 96.390, 2339.0, 48.3632
14.671618331, 96.390, 2278.0, 47.7284
14.724139461, 96.390, 2400.0, 48.9898
14.776660592, 96.390, 2518.0, 50.1797
14.829181723, 96.390, 2398.0, 48.9694
14.881702853, 96.390, 2408.0, 49.0714
14.934223984, 96.390, 2419.0, 49.1833
14.986745115, 96.390, 2467.0, 49.6689
15.039266245, 96.390, 2405.0, 49.0408
15.091787376, 96.390, 2422.0, 49.2138
15.144308507, 96.390, 2475.0, 49.7494
15.196829638, 96.390, 2412.0, 49.1121
15.249350768, 96.390, 2314.0, 48.1041
15.301871899, 96.390, 2465.0, 49.6488
15.354393030, 96.390, 2323.0, 48.1975
15.406914160, 96.390, 2399.0, 48.9796
15.459435291, 96.390, 2512.0, 50.1199
15.511956422, 96.390, 2462.0, 49.6185
15.564477553, 96.390, 2500.0, 50.0000
15.616998683, 96.390, 2426.0, 49.2544
15.669519814, 96.390, 2415.0, 49.1426
15.722040945, 96.390, 2403.0, 49.0204
15.774562075, 96.390, 2421.0, 49.2037
15.827083206, 96.390, 2433.0, 49.3254
15.879604337, 96.390, 2522.0, 50.2195
15.932125468, 96.390, 2548.0, 50.4777
15.984646598, 96.390, 2442.0, 49.4166
16.037167729, 96.390, 2441.0, 49.4065
16.089688860, 96.390, 2522.0, 50.2195
16.142209990, 96.390, 2505.0, 50.0500
16.194731121, 96.390, 2499.0, 49.9900
16.247252252, 96.390, 2541.0, 50.4083
16.299773382, 96.390, 2434.0, 49.3356
16.352294513, 96.390, 2527.0, 50.2693
16.404815644, 96.390, 2489.0, 49.8899
16.457336775, 96.390, 2463.0, 49.6286
16.509857905, 96.390, 2529.0, 50.2892
16.562379036, 96.390, 2587.0, 50.8626
16.614900167, 96.390, 2539.0, 50.3885
16.667421297, 96.390, 2602.0, 51.0098
16.719942428, 96.390, 2516.0, 50.1597
16.772463559, 96.390, 2558.0, 50.5767
16.824984690, 96.390, 2606.0, 51.0490
16.877505820, 96.390, 2520.0, 50.1996
16.930026951, 96.390, 2667.0, 51.6430
16.982548082, 96.390, 2524.0, 50.2394
17.035069212, 96.390, 2606.0, 51.0490
17.087590343, 96.390, 2562.0, 50.6162
17.140111474, 96.390, 2580.0, 50.7937
17.192632605, 96.390, 2667.0, 51.6430
17.245153735, 96.390, 2646.0, 51.4393
17.297674866, 96.390, 2554.0, 50.5371
17.350195997, 96.390, 2688.0, 51.8459
17.402717127, 96.390, 2728.0, 52.2303
17.455238258, 96.390, 2711.0, 52.0673
17.507759389, 96.390, 2671.0, 51.6817
17.560280520, 96.390, 2802.0, 52.9339
17.612801650, 96.390, 2646.0, 51.4393
17.665322781, 96.390, 2708.0, 52.0384
17.717843912, 96.390, 2657.0, 51.5461
17.770365042, 96.390, 2709.0, 52.0481
17.822886173, 96.390, 2707.0, 52.0288
17.875407304, 96.390, 2626.0, 51.2445
17.927928434, 96.390, 2724.0, 52.1920
17.980449565, 96.390, 2743.0, 52.3737
18.032970696, 96.390, 2707.0, 52.0288
18.085491827, 96.390, 2734.0, 52.2877
18.138012957, 96.390, 2782.0, 52.7447
18.190534088, 96.390, 2762.0, 52.5547
18.243055219, 96.390, 2767.0, 52.6023
18.295576349, 96.390, 2898.0, 53.8331
18.348097480, 96.390, 2880.0, 53.6656
18.400618611, 96.390, 2878.0, 53.6470
18.453139742, 96.390, 2900.0, 53.8516
18.505660872, 96.390, 2926.0, 54.0925
18.558182003, 96.390, 2760.0, 52.5357
18.610703134, 96.390, 2806.0, 52.9717
18.663224264, 96.390, 2923.0, 54.0648
18.715745395, 96.390, 2885.0, 53.7122
18.768266526, 96.390, 2958.0, 54.3875
18.820787657, 96.390, 2878.0, 53.6470
18.873308787, 96.390, 2871.0, 53.5817
18.925829918, 96.390, 2896.0, 53.8145
18.978351049, 96.390, 2960.0, 54.4059
19.030872179, 96.390, 2987.0, 54.6535
19.083393310, 96.390, 2922.0, 54.0555
19.135914441, 96.390, 2998.0, 54.7540
19.188435572, 96.390, 2992.0, 54.6992
19.240956702, 96.390, 3040.0, 55.1362
19.293477833, 96.390, 2998.0, 54.7540
19.345998964, 96.390, 3089.0, 55.5788
19.398520094, 96.390, 3041.0, 55.1453
19.451041225, 96.390, 3123.0, 55.8838
19.503562356, 96.390, 3211.0, 56.6657
19.556083486, 96.390, 3214.0, 56.6922
19.608604617, 96.390, 3125.0, 55.9017
19.661125748, 96.390, 3217.0, 56.7186
19.713646879, 96.390, 3324.0, 57.6541
19.766168009, 96.390, 3371.0, 58.0603
19.818689140, 96.390, 3463.0, 58.8473
19.871210271, 96.390, 3225.0, 56.7891
19.923731401, 96.390, 3243.0, 56.9473
19.976252532, 96.390, 3319.0, 57.6108
20.028773663, 96.390, 3397.0, 58.2838
20.081294794, 96.390, 3333.0, 57.7321
20.133815924, 96.390, 3262.0, 57.1139
20.186337055, 96.390, 3395.0, 58.2666
20.238858186, 96.390, 3324.0, 57.6541
20.291379316, 96.390, 3367.0, 58.0259
20.343900447, 96.390, 3471.0, 58.9152
20.396421578, 96.390, 3626.0, 60.2163
20.448942709, 96.390, 3641.0, 60.3407
20.501463839, 96.390, 3543.0, 59.5231
20.553984970, 96.390, 3546.0, 59.5483
20.606506101, 96.390, 3614.0, 60.1166
20.659027231, 96.390, 3567.0, 59.7244
20.711548362, 96.390, 3609.0, 60.0750
20.764069493, 96.390, 3527.0, 59.3886
20.816590623, 96.390, 3523.0, 59.3549
20.869111754, 96.390, 3536.0, 59.4643
20.921632885, 96.390, 3463.0, 58.8473
20.974154016, 96.390, 3527.0, 59.3886
21.026675146, 96.390, 3492.0, 59.0931
21.079196277, 96.390, 3483.0, 59.0169
21.131717408, 96.390, 3617.0, 60.1415
21.184238538, 96.390, 3651.0, 60.4235
21.236759669, 96.390, 3412.0, 58.4123
21.289280800, 96.390, 3554.0, 59.6154
21.341801931, 96.390, 3501.0, 59.1692
21.394323061, 96.390, 3719.0, 60.9836
21.446844192, 96.390, 3541.0, 59.5063
21.499365323, 96.390, 3556.0, 59.6322
21.551886453, 96.390, 3545.0, 59.5399
21.604407584, 96.390, 3644.0, 60.3656
21.656928715, 96.390, 3748.0, 61.2209
21.709449846, 96.390, 3634.0, 60.2827
21.761970976, 96.390, 3648.0, 60.3987
21.814492107, 96.390, 3600.0, 60.0000
21.867013238, 96.390, 3634.0, 60.2827
21.919534368, 96.390, 3627.0, 60.2246
21.972055499, 96.390, 3507.0, 59.2199
22.024576630, 96.390, 3656.0, 60.4649
22.077097761, 96.390, 3616.0, 60.1332
22.129618891, 96.390, 3637.0, 60.3075
22.182140022, 96.390, 3624.0, 60.1997
22.234661153, 96.390, 3584.0, 59.8665
22.287182283, 96.390, 3586.0, 59.8832
22.339703414, 96.390, 3553.0, 59.6070
22.392224545, 96.390, 3480.0, 58.9915
22.444745675, 96.390, 3630.0, 60.2495
22.497266806, 96.390, 3684.0, 60.6960
22.549787937, 96.390, 3590.0, 59.9166
22.602309068, 96.390, 3698.0, 60.8112
22.654830198, 96.390, 3642.0, 60.3490
22.707351329, 96.390, 3574.0, 59.7829
22.759872460, 96.390, 3586.0, 59.8832
22.812393590, 96.390, 3703.0, 60.8523
22.864914721, 96.390, 3569.0, 59.7411
22.917435852, 96.390, 3442.0, 58.6686
22.969956983, 96.390, 3506.0, 59.2115
23.022478113, 96.390, 3550.0, 59.5819
23.074999244, 96.390, 3541.0, 59.5063
23.127520375, 96.390, 3550.0, 59.5819
23.180041505, 96.390, 3492.0, 59.0931
23.232562636, 96.390, 3493.0, 59.1016
23.285083767, 96.390, 3491.0, 59.0847
23.337604898, 96.390, 3439.0, 58.6430
23.390126028, 96.390, 3332.0, 57.7235
23.442647159, 96.390, 3505.0, 59.2030
23.495168290, 96.390, 3564.0, 59.6992
23.547689420, 96.390, 3511.0, 59.2537
23.600210551, 96.390, 3516.0, 59.2959
23.652731682, 96.390, 3415.0, 58.4380
23.705252813, 96.390, 3328.0, 57.6888
23.757773943, 96.390, 3364.0, 58.0000
23.810295074, 96.390, 3346.0, 57.8446
23.862816205, 96.390, 3449.0, 58.7282
23.915337335, 96.390, 3307.0, 57.5065
23.967858466, 96.390, 3239.0, 56.9122
24.020379597, 96.390, 3342.0, 57.8100
24.072900727, 96.390, 3341.0, 57.8014
24.125421858, 96.390, 3309.0, 57.5239
24.177942989, 96.390, 3404.0, 58.3438
24.230464120, 96.390, 3364.0, 58.0000
24.282985250, 96.390, 3324.0, 57.6541
24.335506381, 96.390, 3312.0, 57.5500
24.388027512, 96.390, 3159.0, 56.2050
24.440548642, 96.390, 3173.0, 56.3294
24.493069773, 96.390, 3243.0, 56.9473
24.545590904, 96.390, 3181.0, 56.4004
24.598112035, 96.390, 3045.0, 55.1815
24.650633165, 96.390, 3060.0, 55.3173
24.703154296, 96.390, 2969.0, 54.4885
24.755675427, 96.390, 3060.0, 55.3173
24.808196557, 96.390, 2976.0, 54.5527
24.860717688, 96.390, 2955.0, 54.3599
24.913238819, 96.390, 2989.0, 54.6717
24.965759950, 96.390, 2960.0, 54.4059
25.018281080, 96.390, 3033.0, 55.0727
25.070802211, 96.390, 2877.0, 53.6377
25.123323342, 96.390, 2786.0, 52.7826
25.175844472, 96.390, 2902.0, 53.8702
25.228365603, 96.390, 2931.0, 54.1387
25.280886734, 96.390, 2841.0, 53.3010
25.333407864, 96.390, 2944.0, 54.2586
25.385928995, 96.390, 2936.0, 54.1849
25.438450126, 96.390, 3004.0, 54.8088
25.490971257, 96.390, 2737.0, 52.3163
25.543492387, 96.390, 2826.0, 53.1601
25.596013518, 96.390, 2736.0, 52.3068
25.648534649, 96.390, 2702.0, 51.9808
25.701055779, 96.390, 2678.0, 51.7494
25.753576910, 96.390, 2809.0, 53.0000
25.806098041, 96.390, 2755.0, 52.4881
25.858619172, 96.390, 2721.0, 52.1632
25.911140302, 96.390, 2665.0, 51.6236
25.963661433, 96.390, 2659.0, 51.5655
26.016182564, 96.390, 2713.0, 52.0865
26.068703694, 96.390, 2683.0, 51.7977
26.121224825, 96.390, 2588.0, 50.8724
26.173745956, 96.390, 2693.0, 51.8941
26.226267087, 96.390, 2625.0, 51.2348
26.278788217, 96.390, 2622.0, 51.2055
26.331309348, 96.390, 2669.0, 51.6624
26.383830479, 96.390, 2638.0, 51.3615
26.436351609, 96.390, 2588.0, 50.8724
26.488872740, 96.390, 2628.0, 51.2640
26.541393871, 96.390, 2596.0, 50.9510
26.593915002, 96.390, 2501.0, 50.0100
26.646436132, 96.390, 2567.0, 50.6656
26.698957263, 96.390, 2425.0, 49.2443
26.751478394, 96.390, 2552.0, 50.5173
26.803999524, 96.390, 2503.0, 50.0300
26.856520655, 96.390, 2520.0, 50.1996
26.909041786, 96.390, 2445.0, 49.4469
26.961562916, 96.390, 2511.0, 50.1099
27.014084047, 96.390, 2500.0, 50.0000
27.066605178, 96.390, 2477.0, 49.7695
27.119126309, 96.390, 2415.0, 49.1426
27.171647439, 96.390, 2354.0, 48.5180
27.224168570, 96.390, 2503.0, 50.0300
27.276689701, 96.390, 2441.0, 49.4065
27.329210831, 96.390, 2428.0, 49.2747
27.381731962, 96.390, 2461.0, 49.6085
27.434253093, 96.390, 2431.0, 49.3052
27.486774224, 96.390, 2458.0, 49.5782
27.539295354, 96.390, 2339.0, 48.3632
27.591816485, 96.390, 2426.0, 49.2544
27.644337616, 96.390, 2403.0, 49.0204
27.696858746, 96.390, 2567.0, 50.6656
27.749379877, 96.390, 2371.0, 48.6929
27.801901008, 96.390, 2366.0, 48.6415
27.854422139, 96.390, 2344.0, 48.4149
27.906943269, 96.390, 2260.0, 47.5395
27.959464400, 96.390, 2314.0, 48.1041
28.011985531, 96.390, 2315.0, 48.1144
28.064506661, 96.390, 2385.0, 48.8365
28.117027792, 96.390, 2330.0, 48.2701
28.169548923, 96.390, 2361.0, 48.5901
28.222070054, 96.390, 2355.0, 48.5283
28.274591184, 96.390, 2267.0, 47.6130
28.327112315, 96.390, 2236.0, 47.2864
28.379633446, 96.390, 2353.0, 48.5077
28.432154576, 96.390, 2256.0, 47.4974
28.484675707, 96.390, 2188.0, 46.7761
28.537196838, 96.390, 2357.0, 48.5489
28.589717968, 96.390, 2295.0, 47.9062
28.642239099, 96.390, 2250.0, 47.4342
28.694760230, 96.390, 2278.0, 47.7284
28.747281361, 96.390, 2361.0, 48.5901
28.799802491, 96.390, 2292.0, 47.8748
28.852323622, 96.390, 2218.0, 47.0956
28.904844753, 96.390, 2190.0, 46.7974
28.957365883, 96.390, 2272.0, 47.6655
29.009887014, 96.390, 2204.0, 46.9468
29.062408145, 96.390, 2231.0, 47.2335
29.114929276, 96.390, 2324.0, 48.2079
29.167450406, 96.390, 2191.0, 46.8081
29.219971537, 96.390, 2231.0, 47.2335
29.272492668, 96.390, 2190.0, 46.7974
29.325013798, 96.390, 2079.0, 45.5961
29.377534929, 96.390, 2208.0, 46.9894
29.430056060, 96.390, 2157.0, 46.4435
29.482577191, 96.390, 2124.0, 46.0869
29.535098321, 96.390, 2227.0, 47.1911
29.587619452, 96.390, 2213.0, 47.0425
29.640140583, 96.390, 2254.0, 47.4763
29.692661713, 96.390, 2219.0, 47.1063
29.745182844, 96.390, 2126.0, 46.1086
29.797703975, 96.390, 2171.0, 46.5940
29.850225105, 96.390, 2151.0, 46.3789
29.902746236, 96.390, 2138.0, 46.2385
29.955267367, 96.390, 2164.0, 46.5188
30.007788498, 96.390, 2085.0, 45.6618
30.060309628, 96.390, 2086.0, 45.6727
30.112830759, 96.390, 2210.0, 47.0106
30.165351890, 96.390, 2224.0, 47.1593
30.217873020, 96.390, 2286.0, 47.8121
30.270394151, 96.390, 2265.0, 47.5920
30.322915282, 96.390, 2153.0, 46.4004
30.375436413, 96.390, 2169.0, 46.5725
30.427957543, 96.390, 2147.0, 46.3357
30.480478674, 96.390, 2145.0, 46.3141
30.532999805, 96.390, 2141.0, 46.2709
30.585520935, 96.390, 2154.0, 46.4112
30.638042066, 96.390, 2106.0, 45.8912
30.690563197, 96.390, 2110.0, 45.9347
30.743084328, 96.390, 2215.0, 47.0638
30.795605458, 96.390, 2197.0, 46.8722
30.848126589, 96.390, 2135.0, 46.2061
30.900647720, 96.390, 2042.0, 45.1885
30.953168850, 96.390, 2084.0, 45.6508
31.005689981, 96.390, 2009.0, 44.8219
31.058211112, 96.390, 2046.0, 45.2327
31.110732243, 96.390, 1987.0, 44.5758
31.163253373, 96.390, 2005.0, 44.7772
31.215774504, 96.390, 2078.0, 45.5851
31.268295635, 96.390, 2029.0, 45.0444
31.320816765, 96.390, 2016.0, 44.8999
31.373337896, 96.390, 1961.0, 44.2832
31.425859027, 96.390, 2058.0, 45.3652
31.478380157, 96.390, 1980.0, 44.4972
31.530901288, 96.390, 2043.0, 45.1996
31.583422419, 96.390, 2058.0, 45.3652
31.635943550, 96.390, 2069.0, 45.4863
31.688464680, 96.390, 2057.0, 45.3542
31.740985811, 96.390, 1997.0, 44.6878
31.793506942, 96.390, 2102.0, 45.8476
31.846028072, 96.390, 2029.0, 45.0444
31.898549203, 96.390, 1911.0, 43.7150
31.951070334, 96.390, 2027.0, 45.0222
32.003591465, 96.390, 2017.0, 44.9110
32.056112595, 96.390, 1959.0, 44.2606
32.108633726, 96.390, 1889.0, 43.4626
32.161154857, 96.390, 1998.0, 44.6990
32.213675987, 96.390, 1922.0, 43.8406
32.266197118, 96.390, 1911.0, 43.7150
32.318718249, 96.390, 1904.0, 43.6348
32.371239380, 96.390, 1928.0, 43.9090
32.423760510, 96.390, 1902.0, 43.6119
32.476281641, 96.390, 1791.0, 42.3202
32.528802772, 96.390, 1795.0, 42.3674
32.581323902, 96.390, 1874.0, 43.2897
32.633845033, 96.390, 1900.0, 43.5890
32.686366164, 96.390, 1956.0, 44.2267
32.738887295, 96.390, 1795.0, 42.3674
32.791408425, 96.390, 1821.0, 42.6732
32.843929556, 96.390, 1827.0, 42.7434
32.896450687, 96.390, 1911.0, 43.7150
32.948971817, 96.390, 1864.0, 43.1741
33.001492948, 96.390, 1934.0, 43.9773
33.054014079, 96.390, 2017.0, 44.9110
33.106535209, 96.390, 2062.0, 45.4093
33.159056340, 96.390, 2028.0, 45.0333
33.211577471, 96.390, 1908.0, 43.6807
33.264098602, 96.390, 1906.0, 43.6578
33.316619732, 96.390, 1793.0, 42.3438
33.369140863, 96.390, 1856.0, 43.0813
33.421661994, 96.390, 1971.0, 44.3959
33.474183124, 96.390, 2003.0, 44.7549
33.526704255, 96.390, 1936.0, 44.0000
33.579225386, 96.390, 1885.0, 43.4166
33.631746517, 96.390, 1911.0, 43.7150
33.684267647, 96.390, 1837.0, 42.8602
33.736788778, 96.390, 1920.0, 43.8178
33.789309909, 96.390, 1879.0, 43.3474
33.841831039, 96.390, 1923.0, 43.8520
33.894352170, 96.390, 1989.0, 44.5982
33.946873301, 96.390, 2110.0, 45.9347
33.999394432, 96.390, 2096.0, 45.7821
34.051915562, 96.390, 2073.0, 45.5302
34.104436693, 96.390, 2082.0, 45.6289
34.156957824, 96.390, 2039.0, 45.1553
34.209478954, 96.390, 2055.0, 45.3321
34.262000085, 96.390, 2082.0, 45.6289
34.314521216, 96.390, 2041.0, 45.1774
34.367042346, 96.390, 2032.0, 45.0777
34.419563477, 96.390, 1889.0, 43.4626
34.472084608, 96.390, 2070.0, 45.4973
34.524605739, 96.390, 1934.0, 43.9773
34.577126869, 96.390, 1995.0, 44.6654
34.629648000, 96.390, 1939.0, 44.0341
34.682169131, 96.390, 2000.0, 44.7214
34.734690261, 96.390, 1912.0, 43.7264
34.787211392, 96.390, 1979.0, 44.4860
34.839732523, 96.390, 1875.0, 43.3013
34.892253654, 96.390, 1984.0, 44.5421
34.944774784, 96.390, 2036.0, 45.1221
34.997295915, 96.390, 2129.0, 46.1411
35.049817046, 96.390, 2076.0, 45.5631
35.102338176, 96.390, 1976.0, 44.4522
35.154859307, 96.390, 1939.0, 44.0341
35.207380438, 96.390, 1994.0, 44.6542
35.259901569, 96.390, 1926.0, 43.8862
35.312422699, 96.390, 1950.0, 44.1588
35.364943830, 96.390, 1989.0, 44.5982
35.417464961, 96.390, 1943.0, 44.0795
35.469986091, 96.390, 1935.0, 43.9886
35.522507222, 96.390, 1921.0, 43.8292
35.575028353, 96.390, 1884.0, 43.4051
35.627549484, 96.390, 1839.0, 42.8836
35.680070614, 96.390, 1873.0, 43.2782
35.732591745, 96.390, 1879.0, 43.3474
35.785112876, 96.390, 1845.0, 42.9535
35.837634006, 96.390, 1767.0, 42.0357
35.890155137, 96.390, 1876.0, 43.3128
35.942676268, 96.390, 1832.0, 42.8019
35.995197398, 96.390, 1809.0, 42.5323
36.047718529, 96.390, 1783.0, 42.2256
36.100239660, 96.390, 1747.0, 41.7971
36.152760791, 96.390, 1725.0, 41.5331
36.205281921, 96.390, 1686.0, 41.0609
36.257803052, 96.390, 1784.0, 42.2374
36.310324183, 96.390, 1736.0, 41.6653
36.362845313, 96.390, 1742.0, 41.7373
36.415366444, 96.390, 1760.0, 41.9524
36.467887575, 96.390, 1749.0, 41.8210
36.520408706, 96.390, 1659.0, 40.7308
36.572929836, 96.390, 1735.0, 41.6533
36.625450967, 96.390, 1654.0, 40.6694
36.677972098, 96.390, 1759.0, 41.9404
36.730493228, 96.390, 1638.0, 40.4722
36.783014359, 96.390, 1604.0, 40.0500
36.835535490, 96.390, 1632.0, 40.3980
36.888056621, 96.390, 1630.0, 40.3733
36.940577751, 96.390, 1581.0, 39.7618
36.993098882, 96.390, 1516.0, 38.9358
37.045620013, 96.390, 1559.0, 39.4842
37.098141143, 96.390, 1511.0, 38.8716
37.150662274, 96.390, 1523.0, 39.0256
37.203183405, 96.390, 1543.0, 39.2810
37.255704535, 96.390, 1463.0, 38.2492
37.308225666, 96.390, 1571.0, 39.6358
37.360746797, 96.390, 1481.0, 38.4838
37.413267928, 96.390, 1484.0, 38.5227
37.465789058, 96.390, 1441.0, 37.9605
37.518310189, 96.390, 1476.0, 38.4187
37.570831320, 96.390, 1561.0, 39.5095
37.623352450, 96.390, 1476.0, 38.4187
37.675873581, 96.390, 1481.0, 38.4838
37.728394712, 96.390, 1508.0, 38.8330
37.780915843, 96.390, 1522.0, 39.0128
37.833436973, 96.390, 1587.0, 39.8372
37.885958104, 96.390, 1430.0, 37.8153
37.938479235, 96.390, 1515.0, 38.9230
37.991000365, 96.390, 1408.0, 37.5233
38.043521496, 96.390, 1503.0, 38.7685
38.096042627, 96.390, 1519.0, 38.9744
38.148563758, 96.390, 1500.0, 38.7298
38.201084888, 96.390, 1444.0, 38.0000
38.253606019, 96.390, 1520.0, 38.9872
38.306127150, 96.390, 1488.0, 38.5746
38.358648280, 96.390, 1535.0, 39.1791
38.411169411, 96.390, 1488.0, 38.5746
38.463690542, 96.390, 1431.0, 37.8286
38.516211673, 96.390, 1327.0, 36.4280
38.568732803, 96.390, 1376.0, 37.0945
38.621253934, 96.390, 1456.0, 38.1576
38.673775065, 96.390, 1422.0, 37.7094
38.726296195, 96.390, 1410.0, 37.5500
38.778817326, 96.390, 1385.0, 37.2156
38.831338457, 96.390, 1412.0, 37.5766
38.883859587, 96.390, 1329.0, 36.4555
38.936380718, 96.390, 1315.0, 36.2629
38.988901849, 96.390, 1321.0, 36.3456
39.041422980, 96.390, 1350.0, 36.7423
39.093944110, 96.390, 1368.0, 36.9865
39.146465241, 96.390, 1349.0, 36.7287
39.198986372, 96.390, 1317.0, 36.2905
39.251507502, 96.390, 1373.0, 37.0540
39.304028633, 96.390, 1345.0, 36.6742
39.356549764, 96.390, 1258.0, 35.4683
39.409070895, 96.390, 1305.0, 36.1248
39.461592025, 96.390, 1361.0, 36.8917
39.514113156, 96.390, 1375.0, 37.0810
39.566634287, 96.390, 1331.0, 36.4829
39.619155417, 96.390, 1359.0, 36.8646
39.671676548, 96.390, 1336.0, 36.5513
39.724197679, 96.390, 1314.0, 36.2491
39.776718810, 96.390, 1309.0, 36.1801
39.829239940, 96.390, 1276.0, 35.7211
39.881761071, 96.390, 1333.0, 36.5103
39.934282202, 96.390, 1298.0, 36.0278
39.986803332, 96.390, 1271.0, 35.6511
40.039324463, 96.390, 1206.0, 34.7275
40.091845594, 96.390, 1232.0, 35.0999
40.144366725, 96.390, 1348.0, 36.7151
40.196887855, 96.390, 1348.0, 36.7151
40.249408986, 96.390, 1328.0, 36.4417
40.301930117, 96.390, 1280.0, 35.7771
40.354451247, 96.390, 1239.0, 35.1994
40.406972378, 96.390, 1268.0, 35.6090
40.459493509, 96.390, 1249.0, 35.3412
40.512014639, 96.390, 1181.0, 34.3657
40.564535770, 96.390, 1292.0, 35.9444
40.617056901, 96.390, 1222.0, 34.9571
40.669578032, 96.390, 1227.0, 35.0286
40.722099162, 96.390, 1229.0, 35.0571
40.774620293, 96.390, 1218.0, 34.8999
40.827141424, 96.390, 1211.0, 34.7994
40.879662554, 96.390, 1268.0, 35.6090
40.932183685, 96.390, 1270.0, 35.6371
40.984704816, 96.390, 1212.0, 34.8138
41.037225947, 96.390, 1211.0, 34.7994
41.089747077, 96.390, 1248.0, 35.3270
41.142268208, 96.390, 1232.0, 35.0999
41.194789339, 96.390, 1135.0, 33.6898
41.247310469, 96.390, 1237.0, 35.1710
41.299831600, 96.390, 1234.0, 35.1283
41.352352731, 96.390, 1226.0, 35.0143
41.404873862, 96.390, 1253.0, 35.3977
41.457394992, 96.390, 1182.0, 34.3802
41.509916123, 96.390, 1174.0, 34.2637
41.562437254, 96.390, 1198.0, 34.6121
41.614958384, 96.390, 1208.0, 34.7563
41.667479515, 96.390, 1227.0, 35.0286
41.720000646, 96.390, 1128.0, 33.5857
41.772521776, 96.390, 1183.0, 34.3948
41.825042907, 96.390, 1220.0, 34.9285
41.877564038, 96.390, 1247.0, 35.3129
41.930085169, 96.390, 1189.0, 34.4819
41.982606299, 96.390, 1178.0, 34.3220
42.035127430, 96.390, 1219.0, 34.9142
42.087648561, 96.390, 1150.0, 33.9116
42.140169691, 96.390, 1207.0, 34.7419
42.192690822, 96.390, 1325.0, 36.4005
42.245211953, 96.390, 1188.0, 34.4674
42.297733084, 96.390, 1240.0, 35.2136
42.350254214, 96.390, 1205.0, 34.7131
42.402775345, 96.390, 1233.0, 35.1141
42.455296476, 96.390, 1190.0, 34.4964
42.507817606, 96.390, 1225.0, 35.0000
42.560338737, 96.390, 1180.0, 34.3511
42.612859868, 96.390, 1191.0, 34.5109
42.665380999, 96.390, 1253.0, 35.3977
42.717902129, 96.390, 1187.0, 34.4529
42.770423260, 96.390, 1147.0, 33.8674
42.822944391, 96.390, 1195.0, 34.5688
42.875465521, 96.390, 1203.0, 34.6843
42.927986652, 96.390, 1214.0, 34.8425
42.980507783, 96.390, 1206.0, 34.7275
43.033028914, 96.390, 1173.0, 34.2491
43.085550044, 96.390, 1205.0, 34.7131
43.138071175, 96.390, 1134.0, 33.6749
43.190592306, 96.390, 1172.0, 34.2345
43.243113436, 96.390, 1235.0, 35.1426
43.295634567, 96.390, 1194.0, 34.5543
43.348155698, 96.390, 1221.0, 34.9428
43.400676828, 96.390, 1204.0, 34.6987
43.453197959, 96.390, 1151.0, 33.9264
43.505719090, 96.390, 1217.0, 34.8855
43.558240221, 96.390, 1204.0, 34.6987
43.610761351, 96.390, 1102.0, 33.1964
43.663282482, 96.390, 1169.0, 34.1906
43.715803613, 96.390, 1225.0, 35.0000
43.768324743, 96.390, 1172.0, 34.2345
43.820845874, 96.390, 1248.0, 35.3270
43.873367005, 96.390, 1169.0, 34.1906
43.925888136, 96.390, 1196.0, 34.5832
43.978409266, 96.390, 1172.0, 34.2345
44.030930397, 96.390, 1190.0, 34.4964
44.083451528, 96.390, 1239.0, 35.1994
44.135972658, 96.390, 1210.0, 34.7851
44.188493789, 96.390, 1188.0, 34.4674
44.241014920, 96.390, 1247.0, 35.3129
44.293536051, 96.390, 1256.0, 35.4401
44.346057181, 96.390, 1232.0, 35.0999
44.398578312, 96.390, 1200.0, 34.6410
44.451099443, 96.390, 1184.0, 34.4093
44.503620573, 96.390, 1229.0, 35.0571
44.556141704, 96.390, 1226.0, 35.0143
44.608662835, 96.390, 1161.0, 34.0735
44.661183966, 96.390, 1226.0, 35.0143
44.713705096, 96.390, 1231.0, 35.0856
44.766226227, 96.390, 1242.0, 35.2420
44.818747358, 96.390, 1264.0, 35.5528
44.871268488, 96.390, 1155.0, 33.9853
44.923789619, 96.390, 1122.0, 33.4963
44.976310750, 96.390, 1232.0, 35.0999
45.028831880, 96.390, 1161.0, 34.0735
45.081353011, 96.390, 1190.0, 34.4964
45.133874142, 96.390, 1252.0, 35.3836
45.186395273, 96.390, 1194.0, 34.5543
45.238916403, 96.390, 1172.0, 34.2345
45.291437534, 96.390, 1251.0, 35.3695
45.343958665, 96.390, 1250.0, 35.3553
45.396479795, 96.390, 1218.0, 34.8999
45.449000926, 96.390, 1231.0, 35.0856
45.501522057, 96.390, 1154.0, 33.9706
45.554043188, 96.390, 1192.0, 34.5254
45.606564318, 96.390, 1239.0, 35.1994
45.659085449, 96.390, 1193.0, 34.5398
45.711606580, 96.390, 1217.0, 34.8855
45.764127710, 96.390, 1176.0, 34.2929
45.816648841, 96.390, 1142.0, 33.7935
45.869169972, 96.390, 1198.0, 34.6121
45.921691103, 96.390, 1258.0, 35.4683
45.974212233, 96.390, 1212.0, 34.8138
46.026733364, 96.390, 1214.0, 34.8425
46.079254495, 96.390, 1186.0, 34.4384
46.131775625, 96.390, 1258.0, 35.4683
46.184296756, 96.390, 1224.0, 34.9857
46.236817887, 96.390, 1244.0, 35.2704
46.289339017, 96.390, 1226.0, 35.0143
46.341860148, 96.390, 1186.0, 34.4384
46.394381279, 96.390, 1249.0, 35.3412
46.446902410, 96.390, 1230.0, 35.0714
46.499423540, 96.390, 1193.0, 34.5398
46.551944671, 96.390, 1141.0, 33.7787
46.604465802, 96.390, 1237.0, 35.1710
46.656986932, 96.390, 1181.0, 34.3657
46.709508063, 96.390, 1143.0, 33.8083
46.762029194, 96.390, 1235.0, 35.1426
46.814550325, 96.390, 1209.0, 34.7707
46.867071455, 96.390, 1143.0, 33.8083
46.919592586, 96.390, 1187.0, 34.4529
46.972113717, 96.390, 1172.0, 34.2345
47.024634847, 96.390, 1104.0, 33.2265
47.077155978, 96.390, 1177.0, 34.3074
47.129677109, 96.390, 1161.0, 34.0735
47.182198240, 96.390, 1125.0, 33.5410
47.234719370, 96.390, 1179.0, 34.3366
47.287240501, 96.390, 1176.0, 34.2929
47.339761632, 96.390, 1124.0, 33.5261
47.392282762, 96.390, 1179.0, 34.3366
47.444803893, 96.390, 1138.0, 33.7343
47.497325024, 96.390, 1078.0, 32.8329
47.549846155, 96.390, 1137.0, 33.7194
47.602367285, 96.390, 1178.0, 34.3220
47.654888416, 96.390, 1148.0, 33.8821
47.707409547, 96.390, 1115.0, 33.3916
47.759930677, 96.390, 1091.0, 33.0303
47.812451808, 96.390, 1101.0, 33.1813
47.864972939, 96.390, 1190.0, 34.4964
47.917494069, 96.390, 1266.0, 35.5809
47.970015200, 96.390, 1127.0, 33.5708
48.022536331, 96.390, 1267.0, 35.5949
48.075057462, 96.390, 1121.0, 33.4813
48.127578592, 96.390, 1131.0, 33.6303
48.180099723, 96.390, 1114.0, 33.3766
48.232620854, 96.390, 1153.0, 33.9559
48.285141984, 96.390, 1109.0, 33.3017
48.337663115, 96.390, 1153.0, 33.9559
48.390184246, 96.390, 1127.0, 33.5708
48.442705377, 96.390, 1114.0, 33.3766
48.495226507, 96.390, 1149.0, 33.8969
48.547747638, 96.390, 1149.0, 33.8969
48.600268769, 96.390, 1093.0, 33.0606
48.652789899, 96.390, 1156.0, 34.0000
48.705311030, 96.390, 1111.0, 33.3317
48.757832161, 96.390, 1065.0, 32.6343
48.810353292, 96.390, 1186.0, 34.4384
48.862874422, 96.390, 1050.0, 32.4037
48.915395553, 96.390, 1100.0, 33.1662
48.967916684, 96.390, 1048.0, 32.3728
49.020437814, 96.390, 1087.0, 32.9697
49.072958945, 96.390, 1110.0, 33.3167
49.125480076, 96.390, 1129.0, 33.6006
49.178001207, 96.390, 1190.0, 34.4964
49.230522337, 96.390, 1085.0, 32.9393
49.283043468, 96.390, 1020.0, 31.9374
49.335564599, 96.390, 1080.0, 32.8634
49.388085729, 96.390, 1174.0, 34.2637
49.440606860, 96.390, 1087.0, 32.9697
49.493127991, 96.390, 1080.0, 32.8634
49.545649121, 96.390, 1041.0, 32.2645
49.598170252, 96.390, 1057.0, 32.5115
49.650691383, 96.390, 1098.0, 33.1361
49.703212514, 96.390, 1055.0, 32.4808
49.755733644, 96.390, 1080.0, 32.8634
49.808254775, 96.390, 1056.0, 32.4962
49.860775906, 96.390, 1013.0, 31.8277
49.913297036, 96.390, 1029.0, 32.0780
49.965818167, 96.390, 1060.0, 32.5576
50.018339298, 96.390, 1021.0, 31.9531
50.070860429, 96.390, 1067.0, 32.6650
50.123381559, 96.390, 1069.0, 32.6956
50.175902690, 96.390, 1104.0, 33.2265
50.228423821, 96.390, 1044.0, 32.3110
50.280944951, 96.390, 1036.0, 32.1870
50.333466082, 96.390, 1066.0, 32.6497
50.385987213, 96.390, 1071.0, 32.7261
50.438508344, 96.390, 1038.0, 32.2180
50.491029474, 96.390, 1036.0, 32.1870
50.543550605, 96.390, 1032.0, 32.1248
50.596071736, 96.390, 1041.0, 32.2645
50.648592866, 96.390, 977.0, 31.2570
50.701113997, 96.390, 999.0, 31.6070
50.753635128, 96.390, 985.0, 31.3847
50.806156258, 96.390, 1047.0, 32.3574
50.858677389, 96.390, 1014.0, 31.8434
50.911198520, 96.390, 1003.0, 31.6702
50.963719651, 96.390, 984.0, 31.3688
51.016240781, 96.390, 983.0, 31.3528
51.068761912, 96.390, 1020.0, 31.9374
51.121283043, 96.390, 1037.0, 32.2025
51.173804173, 96.390, 945.0, 30.7409
51.226325304, 96.390, 1009.0, 31.7648
51.278846435, 96.390, 1039.0, 32.2335
51.331367566, 96.390, 1040.0, 32.2490
51.383888696, 96.390, 1057.0, 32.5115
51.436409827, 96.390, 971.0, 31.1609
51.488930958, 96.390, 1023.0, 31.9844
51.541452088, 96.390, 996.0, 31.5595
51.593973219, 96.390, 992.0, 31.4960
51.646494350, 96.390, 977.0, 31.2570
51.699015481, 96.390, 957.0, 30.9354
51.751536611, 96.390, 966.0, 31.0805
51.804057742, 96.390, 953.0, 30.8707
51.856578873, 96.390, 1020.0, 31.9374
51.909100003, 96.390, 895.0, 29.9166
51.961621134, 96.390, 931.0, 30.5123
52.014142265, 96.390, 1027.0, 32.0468
52.066663396, 96.390, 959.0, 30.9677
52.119184526, 96.390, 909.0, 30.1496
52.171705657, 96.390, 973.0, 31.1929
52.224226788, 96.390, 950.0, 30.8221
52.276747918, 96.390, 933.0, 30.5450
52.329269049, 96.390, 970.0, 31.1448
52.381790180, 96.390, 955.0, 30.9031
52.434311310, 96.390, 1014.0, 31.8434
52.486832441, 96.390, 934.0, 30.5614
52.539353572, 96.390, 947.0, 30.7734
52.591874703, 96.390, 947.0, 30.7734
52.644395833, 96.390, 1011.0, 31.7962
52.696916964, 96.390, 998.0, 31.5911
52.749438095, 96.390, 970.0, 31.1448
52.801959225, 96.390, 1024.0, 32.0000
52.854480356, 96.390, 975.0, 31.2250
52.907001487, 96.390, 943.0, 30.7083
52.959522618, 96.390, 981.0, 31.3209
53.012043748, 96.390, 938.0, 30.6268
53.064564879, 96.390, 960.0, 30.9839
53.117086010, 96.390, 1022.0, 31.9687
53.169607140, 96.390, 1037.0, 32.2025
53.222128271, 96.390, 980.0, 31.3050
53.274649402, 96.390, 932.0, 30.5287
53.327170533, 96.390, 949.0, 30.8058
53.379691663, 96.390, 966.0, 31.0805
53.432212794, 96.390, 948.0, 30.7896
53.484733925, 96.390, 902.0, 30.0333
53.537255055, 96.390, 895.0, 29.9166
53.589776186, 96.390, 926.0, 30.4302
53.642297317, 96.390, 974.0, 31.2090
53.694818448, 96.390, 961.0, 31.0000
53.747339578, 96.390, 934.0, 30.5614
53.799860709, 96.390, 920.0, 30.3315
53.852381840, 96.390, 957.0, 30.9354
53.904902970, 96.390, 920.0, 30.3315
53.957424101, 96.390, 901.0, 30.0167
54.009945232, 96.390, 926.0, 30.4302
54.062466362, 96.390, 921.0, 30.3480
54.114987493, 96.390, 968.0, 31.1127
54.167508624, 96.390, 915.0, 30.2490
54.220029755, 96.390, 912.0, 30.1993
54.272550885, 96.390, 975.0, 31.2250
54.325072016, 96.390, 900.0, 30.0000
54.377593147, 96.390, 920.0, 30.3315
54.430114277, 96.390, 901.0, 30.0167
54.482635408, 96.390, 937.0, 30.6105
54.535156539, 96.390, 925.0, 30.4138
54.587677670, 96.390, 925.0, 30.4138
54.640198800, 96.390, 981.0, 31.3209
54.692719931, 96.390, 894.0, 29.8998
54.745241062, 96.390, 931.0, 30.5123
54.797762192, 96.390, 979.0, 31.2890
54.850283323, 96.390, 891.0, 29.8496
54.902804454, 96.390, 921.0, 30.3480
54.955325585, 96.390, 931.0, 30.5123
55.007846715, 96.390, 920.0, 30.3315
55.060367846, 96.390, 919.0, 30.3150
55.112888977, 96.390, 945.0, 30.7409
55.165410107, 96.390, 840.0, 28.9828
55.217931238, 96.390, 946.0, 30.7571
55.270452369, 96.390, 952.0, 30.8545
55.322973499, 96.390, 885.0, 29.7489
55.375494630, 96.390, 889.0, 29.8161
55.428015761, 96.390, 910.0, 30.1662
55.480536892, 96.390, 910.0, 30.1662
55.533058022, 96.390, 944.0, 30.7246
55.585579153, 96.390, 949.0, 30.8058
55.638100284, 96.390, 904.0, 30.0666
55.690621414, 96.390, 917.0, 30.2820
55.743142545, 96.390, 914.0, 30.2324
55.795663676, 96.390, 967.0, 31.0966
55.848184807, 96.390, 928.0, 30.4631
55.900705937, 96.390, 882.0, 29.6985
55.953227068, 96.390, 887.0, 29.7825
56.005748199, 96.390, 885.0, 29.7489
56.058269329, 96.390, 888.0, 29.7993
56.110790460, 96.390, 911.0, 30.1828
56.163311591, 96.390, 890.0, 29.8329
56.215832722, 96.390, 886.0, 29.7658
56.268353852, 96.390, 906.0, 30.0998
56.320874983, 96.390, 926.0, 30.4302
56.373396114, 96.390, 863.0, 29.3769
56.425917244, 96.390, 893.0, 29.8831
56.478438375, 96.390, 864.0, 29.3939
56.530959506, 96.390, 861.0, 29.3428
56.583480637, 96.390, 803.0, 28.3373
56.636001767, 96.390, 845.0, 29.0689
56.688522898, 96.390, 883.0, 29.7153
56.741044029, 96.390, 917.0, 30.2820
56.793565159, 96.390, 906.0, 30.0998
56.846086290, 96.390, 870.0, 29.4958
56.898607421, 96.390, 852.0, 29.1890
56.951128551, 96.390, 863.0, 29.3769
57.003649682, 96.390, 876.0, 29.5973
57.056170813, 96.390, 817.0, 28.5832
57.108691944, 96.390, 911.0, 30.1828
57.161213074, 96.390, 874.0, 29.5635
57.213734205, 96.390, 902.0, 30.0333
57.266255336, 96.390, 912.0, 30.1993
57.318776466, 96.390, 874.0, 29.5635
57.371297597, 96.390, 863.0, 29.3769
57.423818728, 96.390, 870.0, 29.4958
57.476339859, 96.390, 879.0, 29.6479
57.528860989, 96.390, 906.0, 30.0998
57.581382120, 96.390, 910.0, 30.1662
57.633903251, 96.390, 925.0, 30.4138
57.686424381, 96.390, 867.0, 29.4449
57.738945512, 96.390, 925.0, 30.4138
57.791466643, 96.390, 829.0, 28.7924
57.843987774, 96.390, 822.0, 28.6705
57.896508904, 96.390, 954.0, 30.8869
57.949030035, 96.390, 843.0, 29.0345
58.001551166, 96.390, 880.0, 29.6648
58.054072296, 96.390, 834.0, 28.8791
58.106593427, 96.390, 787.0, 28.0535
58.159114558, 96.390, 835.0, 28.8964
58.211635689, 96.390, 876.0, 29.5973
58.264156819, 96.390, 912.0, 30.1993
58.316677950, 96.390, 902.0, 30.0333
58.369199081, 96.390, 918.0, 30.2985
58.421720211, 96.390, 806.0, 28.3901
58.474241342, 96.390, 846.0, 29.0861
58.526762473, 96.390, 881.0, 29.6816
58.579283603, 96.390, 847.0, 29.1033
58.631804734, 96.390, 889.0, 29.8161
58.684325865, 96.390, 830.0, 28.8097
58.736846996, 96.390, 865.0, 29.4109
58.789368126, 96.390, 882.0, 29.6985
58.841889257, 96.390, 864.0, 29.3939
58.894410388, 96.390, 907.0, 30.1164
58.946931518, 96.390, 778.0, 27.8927
58.999452649, 96.390, 890.0, 29.8329
59.051973780, 96.390, 854.0, 29.2233
59.104494911, 96.390, 858.0, 29.2916
59.157016041, 96.390, 863.0, 29.3769
59.209537172, 96.390, 874.0, 29.5635
59.262058303, 96.390, 870.0, 29.4958
59.314579433, 96.390, 871.0, 29.5127
59.367100564, 96.390, 874.0, 29.5635
59.419621695, 96.390, 912.0, 30.1993
59.472142826, 96.390, 870.0, 29.4958
59.524663956, 96.390, 949.0, 30.8058
59.577185087, 96.390, 911.0, 30.1828
59.629706218, 96.390, 908.0, 30.1330
59.682227348, 96.390, 934.0, 30.5614
59.734748479, 96.390, 880.0, 29.6648
59.787269610, 96.390, 918.0, 30.2985
59.839790740, 96.390, 904.0, 30.0666
59.892311871, 96.390, 933.0, 30.5450
59.944833002, 96.390, 858.0, 29.2916
59.997354133, 96.390, 912.0, 30.1993
60.049875263, 96.390, 950.0, 30.8221
60.102396394, 96.390, 956.0, 30.9192
60.154917525, 96.390, 918.0, 30.2985
60.207438655, 96.390, 955.0, 30.9031
60.259959786, 96.390, 903.0, 30.0500
60.312480917, 96.390, 941.0, 30.6757
60.365002048, 96.390, 912.0, 30.1993
60.417523178, 96.390, 993.0, 31.5119
60.470044309, 96.390, 1062.0, 32.5883
60.522565440, 96.390, 1020.0, 31.9374
60.575086570, 96.390, 1031.0, 32.1092
60.627607701, 96.390, 1035.0, 32.1714
60.680128832, 96.390, 982.0, 31.3369
60.732649963, 96.390, 1126.0, 33.5559
60.785171093, 96.390, 1128.0, 33.5857
60.837692224, 96.390, 1065.0, 32.6343
60.890213355, 96.390, 1149.0, 33.8969
60.942734485, 96.390, 1165.0, 34.1321
60.995255616, 96.390, 1093.0, 33.0606
61.047776747, 96.390, 1177.0, 34.3074
61.100297878, 96.390, 1196.0, 34.5832
61.152819008, 96.390, 1197.0, 34.5977
61.205340139, 96.390, 1156.0, 34.0000
61.257861270, 96.390, 1251.0, 35.3695
61.310382400, 96.390, 1162.0, 34.0881
61.362903531, 96.390, 1083.0, 32.9090
61.415424662, 96.390, 1208.0, 34.7563
61.467945792, 96.390, 1115.0, 33.3916
61.520466923, 96.390, 1099.0, 33.1512
61.572988054, 96.390, 1160.0, 34.0588
61.625509185, 96.390, 1175.0, 34.2783
61.678030315, 96.390, 1166.0, 34.1467
61.730551446, 96.390, 1101.0, 33.1813
61.783072577, 96.390, 1089.0, 33.0000
61.835593707, 96.390, 1068.0, 32.6803
61.888114838, 96.390, 1070.0, 32.7109
61.940635969, 96.390, 1088.0, 32.9848
61.993157100, 96.390, 1030.0, 32.0936
62.045678230, 96.390, 1073.0, 32.7567
62.098199361, 96.390, 1036.0, 32.1870
62.150720492, 96.390, 1044.0, 32.3110
62.203241622, 96.390, 985.0, 31.3847
62.255762753, 96.390, 968.0, 31.1127
62.308283884, 96.390, 1029.0, 32.0780
62.360805015, 96.390, 986.0, 31.4006
62.413326145, 96.390, 941.0, 30.6757
62.465847276, 96.390, 974.0, 31.2090
62.518368407, 96.390, 972.0, 31.1769
62.570889537, 96.390, 991.0, 31.4802
62.623410668, 96.390, 925.0, 30.4138
62.675931799, 96.390, 1021.0, 31.9531
62.728452930, 96.390, 942.0, 30.6920
62.780974060, 96.390, 947.0, 30.7734
62.833495191, 96.390, 1002.0, 31.6544
62.886016322, 96.390, 940.0, 30.6594
62.938537452, 96.390, 929.0, 30.4795
62.991058583, 96.390, 919.0, 30.3150
63.043579714, 96.390, 866.0, 29.4279
63.096100844, 96.390, 934.0, 30.5614
63.148621975, 96.390, 943.0, 30.7083
63.201143106, 96.390, 889.0, 29.8161
63.253664237, 96.390, 905.0, 30.0832
63.306185367, 96.390, 913.0, 30.2159
63.358706498, 96.390, 923.0, 30.3809
63.411227629, 96.390, 889.0, 29.8161
63.463748759, 96.390, 897.0, 29.9500
63.516269890, 96.390, 901.0, 30.0167
63.568791021, 96.390, 853.0, 29.2062
63.621312152, 96.390, 879.0, 29.6479
63.673833282, 96.390, 871.0, 29.5127
63.726354413, 96.390, 885.0, 29.7489
63.778875544, 96.390, 864.0, 29.3939
63.831396674, 96.390, 889.0, 29.8161
63.883917805, 96.390, 856.0, 29.2575
63.936438936, 96.390, 823.0, 28.6880
63.988960067, 96.390, 843.0, 29.0345
64.041481197, 96.390, 814.0, 28.5307
64.094002328, 96.390, 886.0, 29.7658
64.146523459, 96.390, 845.0, 29.0689
64.199044589, 96.390, 880.0, 29.6648
64.251565720, 96.390, 902.0, 30.0333
64.304086851, 96.390, 829.0, 28.7924
64.356607981, 96.390, 850.0, 29.1548
64.409129112, 96.390, 869.0, 29.4788
64.461650243, 96.390, 859.0, 29.3087
64.514171374, 96.390, 795.0, 28.1957
64.566692504, 96.390, 875.0, 29.5804
64.619213635, 96.390, 819.0, 28.6182
64.671734766, 96.390, 823.0, 28.6880
64.724255896, 96.390, 865.0, 29.4109
64.776777027, 96.390, 786.0, 28.0357
64.829298158, 96.390, 789.0, 28.0891
64.881819289, 96.390, 842.0, 29.0172
64.934340419, 96.390, 777.0, 27.8747
64.986861550, 96.390, 851.0, 29.1719