File: Files_organized_for_plots/Constant_NaOH_half_mL10M_to_1gPC/XRD_PAxial04Jan22_Act21Feb22_B2_0455M_NaOH_LS0124_1.csv
[Measurement conditions]
Sample identification,XRD_PAxial04Jan22_Act21Feb22_B2_0455M_NaOH_LS0124_1
Comment - 1,"Configuration=Stage for Flat Samples/Holders, Owner=User-1, Creation date=7/1/2020 9:53:24 AM"
Comment - 2,"Goniometer=Theta/Theta; Minimum step size 2Theta:0.0001; Minimum step size Omega:0.0001"
Comment - 3,"Sample stage=Stage for flat samples/holders"
Comment - 4,"Diffractometer system=EMPYREAN"
Comment - 5,"Measurement program=C:\Users\ibo5034\OneDrive - The Pennsylvania State University\NEUP - Reed, Titus's files\XRD\Cement\Zerobackground scan.xrdmp, Identifier={98A3B11C-88F9-4AA6-982C-73314A311EF5}"
Anode material,Cu
K-Alpha1 wavelength,1.5405980
K-Alpha2 wavelength,1.5444260
Ratio K-Alpha2/K-Alpha1,0.500
Divergence slit,Fixed,0.25
Monochromator used,NO
Generator voltage, 45
Tube current, 40
File date and time,24/Feb/2022 13:31
Unit cell,
h k l, 0 0 0
Scan axis,Gonio
Scan range,4.994599997,64.999991833
Scan step size,0.0262606
No. of points, 2285
Scan type,CONTINUOUS
Time per step,96.390
[Scan points]
Angle, TimePerStep, Intensity, ESD
5.007730280, 96.390, 6636.0, 81.4616
5.060251411, 96.390, 6450.0, 80.3119
5.112772541, 96.390, 6529.0, 80.8022
5.165293672, 96.390, 6192.0, 78.6893
5.217814803, 96.390, 6082.0, 77.9872
5.270335934, 96.390, 6017.0, 77.5693
5.322857064, 96.390, 5912.0, 76.8895
5.375378195, 96.390, 5797.0, 76.1380
5.427899326, 96.390, 5606.0, 74.8732
5.480420456, 96.390, 5539.0, 74.4245
5.532941587, 96.390, 5696.0, 75.4718
5.585462718, 96.390, 5567.0, 74.6123
5.637983849, 96.390, 5538.0, 74.4177
5.690504979, 96.390, 5288.0, 72.7186
5.743026110, 96.390, 5213.0, 72.2011
5.795547241, 96.390, 5313.0, 72.8903
5.848068371, 96.390, 5125.0, 71.5891
5.900589502, 96.390, 5239.0, 72.3809
5.953110633, 96.390, 5228.0, 72.3049
6.005631763, 96.390, 5176.0, 71.9444
6.058152894, 96.390, 4908.0, 70.0571
6.110674025, 96.390, 4997.0, 70.6895
6.163195156, 96.390, 4879.0, 69.8498
6.215716286, 96.390, 4927.0, 70.1926
6.268237417, 96.390, 4978.0, 70.5549
6.320758548, 96.390, 4913.0, 70.0928
6.373279678, 96.390, 4752.0, 68.9348
6.425800809, 96.390, 4824.0, 69.4550
6.478321940, 96.390, 4792.0, 69.2243
6.530843071, 96.390, 4700.0, 68.5565
6.583364201, 96.390, 4684.0, 68.4398
6.635885332, 96.390, 4672.0, 68.3520
6.688406463, 96.390, 4544.0, 67.4092
6.740927593, 96.390, 4592.0, 67.7643
6.793448724, 96.390, 4552.0, 67.4685
6.845969855, 96.390, 4467.0, 66.8356
6.898490986, 96.390, 4516.0, 67.2012
6.951012116, 96.390, 4452.0, 66.7233
7.003533247, 96.390, 4392.0, 66.2722
7.056054378, 96.390, 4410.0, 66.4078
7.108575508, 96.390, 4408.0, 66.3928
7.161096639, 96.390, 4285.0, 65.4599
7.213617770, 96.390, 4381.0, 66.1891
7.266138900, 96.390, 4335.0, 65.8407
7.318660031, 96.390, 4347.0, 65.9318
7.371181162, 96.390, 4325.0, 65.7647
7.423702293, 96.390, 4329.0, 65.7951
7.476223423, 96.390, 4276.0, 65.3911
7.528744554, 96.390, 4280.0, 65.4217
7.581265685, 96.390, 4322.0, 65.7419
7.633786815, 96.390, 4185.0, 64.6916
7.686307946, 96.390, 4310.0, 65.6506
7.738829077, 96.390, 4283.0, 65.4446
7.791350208, 96.390, 4358.0, 66.0151
7.843871338, 96.390, 4446.0, 66.6783
7.896392469, 96.390, 4345.0, 65.9166
7.948913600, 96.390, 4367.0, 66.0833
8.001434730, 96.390, 4468.0, 66.8431
8.053955861, 96.390, 4571.0, 67.6092
8.106476992, 96.390, 4555.0, 67.4907
8.158998123, 96.390, 4416.0, 66.4530
8.211519253, 96.390, 4676.0, 68.3813
8.264040384, 96.390, 4733.0, 68.7968
8.316561515, 96.390, 4769.0, 69.0579
8.369082645, 96.390, 4840.0, 69.5701
8.421603776, 96.390, 4908.0, 70.0571
8.474124907, 96.390, 5014.0, 70.8096
8.526646038, 96.390, 4916.0, 70.1142
8.579167168, 96.390, 5172.0, 71.9166
8.631688299, 96.390, 5161.0, 71.8401
8.684209430, 96.390, 5150.0, 71.7635
8.736730560, 96.390, 5135.0, 71.6589
8.789251691, 96.390, 4939.0, 70.2780
8.841772822, 96.390, 4884.0, 69.8856
8.894293952, 96.390, 4701.0, 68.5638
8.946815083, 96.390, 4718.0, 68.6877
8.999336214, 96.390, 4557.0, 67.5056
9.051857345, 96.390, 4575.0, 67.6387
9.104378475, 96.390, 4279.0, 65.4141
9.156899606, 96.390, 4182.0, 64.6684
9.209420737, 96.390, 4042.0, 63.5767
9.261941867, 96.390, 3980.0, 63.0872
9.314462998, 96.390, 3877.0, 62.2656
9.366984129, 96.390, 3802.0, 61.6604
9.419505260, 96.390, 3760.0, 61.3188
9.472026390, 96.390, 3780.0, 61.4817
9.524547521, 96.390, 3541.0, 59.5063
9.577068652, 96.390, 3600.0, 60.0000
9.629589782, 96.390, 3473.0, 58.9322
9.682110913, 96.390, 3383.0, 58.1636
9.734632044, 96.390, 3323.0, 57.6455
9.787153175, 96.390, 3389.0, 58.2151
9.839674305, 96.390, 3255.0, 57.0526
9.892195436, 96.390, 3280.0, 57.2713
9.944716567, 96.390, 3361.0, 57.9741
9.997237697, 96.390, 3268.0, 57.1664
10.049758828, 96.390, 3254.0, 57.0438
10.102279959, 96.390, 3199.0, 56.5597
10.154801090, 96.390, 3181.0, 56.4004
10.207322220, 96.390, 3207.0, 56.6304
10.259843351, 96.390, 3136.0, 56.0000
10.312364482, 96.390, 3276.0, 57.2364
10.364885612, 96.390, 3163.0, 56.2406
10.417406743, 96.390, 3203.0, 56.5951
10.469927874, 96.390, 3084.0, 55.5338
10.522449004, 96.390, 3197.0, 56.5420
10.574970135, 96.390, 3094.0, 55.6237
10.627491266, 96.390, 3104.0, 55.7136
10.680012397, 96.390, 3087.0, 55.5608
10.732533527, 96.390, 3016.0, 54.9181
10.785054658, 96.390, 3021.0, 54.9636
10.837575789, 96.390, 2962.0, 54.4243
10.890096919, 96.390, 3064.0, 55.3534
10.942618050, 96.390, 2947.0, 54.2863
10.995139181, 96.390, 2917.0, 54.0093
11.047660312, 96.390, 2947.0, 54.2863
11.100181442, 96.390, 2860.0, 53.4790
11.152702573, 96.390, 2993.0, 54.7083
11.205223704, 96.390, 2889.0, 53.7494
11.257744834, 96.390, 3029.0, 55.0364
11.310265965, 96.390, 2844.0, 53.3292
11.362787096, 96.390, 2839.0, 53.2823
11.415308227, 96.390, 2887.0, 53.7308
11.467829357, 96.390, 2874.0, 53.6097
11.520350488, 96.390, 2913.0, 53.9722
11.572871619, 96.390, 2821.0, 53.1131
11.625392749, 96.390, 2756.0, 52.4976
11.677913880, 96.390, 2764.0, 52.5738
11.730435011, 96.390, 2798.0, 52.8961
11.782956141, 96.390, 2850.0, 53.3854
11.835477272, 96.390, 2793.0, 52.8488
11.887998403, 96.390, 2772.0, 52.6498
11.940519534, 96.390, 2829.0, 53.1883
11.993040664, 96.390, 2804.0, 52.9528
12.045561795, 96.390, 2726.0, 52.2111
12.098082926, 96.390, 2823.0, 53.1319
12.150604056, 96.390, 2657.0, 51.5461
12.203125187, 96.390, 2718.0, 52.1344
12.255646318, 96.390, 2734.0, 52.2877
12.308167449, 96.390, 2770.0, 52.6308
12.360688579, 96.390, 2764.0, 52.5738
12.413209710, 96.390, 2692.0, 51.8845
12.465730841, 96.390, 2619.0, 51.1762
12.518251971, 96.390, 2676.0, 51.7301
12.570773102, 96.390, 2671.0, 51.6817
12.623294233, 96.390, 2630.0, 51.2835
12.675815364, 96.390, 2699.0, 51.9519
12.728336494, 96.390, 2622.0, 51.2055
12.780857625, 96.390, 2641.0, 51.3907
12.833378756, 96.390, 2658.0, 51.5558
12.885899886, 96.390, 2621.0, 51.1957
12.938421017, 96.390, 2609.0, 51.0784
12.990942148, 96.390, 2611.0, 51.0979
13.043463279, 96.390, 2557.0, 50.5668
13.095984409, 96.390, 2567.0, 50.6656
13.148505540, 96.390, 2565.0, 50.6458
13.201026671, 96.390, 2632.0, 51.3030
13.253547801, 96.390, 2604.0, 51.0294
13.306068932, 96.390, 2547.0, 50.4678
13.358590063, 96.390, 2627.0, 51.2543
13.411111193, 96.390, 2551.0, 50.5074
13.463632324, 96.390, 2503.0, 50.0300
13.516153455, 96.390, 2456.0, 49.5580
13.568674586, 96.390, 2523.0, 50.2295
13.621195716, 96.390, 2502.0, 50.0200
13.673716847, 96.390, 2467.0, 49.6689
13.726237978, 96.390, 2450.0, 49.4975
13.778759108, 96.390, 2472.0, 49.7192
13.831280239, 96.390, 2531.0, 50.3090
13.883801370, 96.390, 2516.0, 50.1597
13.936322501, 96.390, 2553.0, 50.5272
13.988843631, 96.390, 2441.0, 49.4065
14.041364762, 96.390, 2474.0, 49.7393
14.093885893, 96.390, 2454.0, 49.5379
14.146407023, 96.390, 2535.0, 50.3488
14.198928154, 96.390, 2456.0, 49.5580
14.251449285, 96.390, 2387.0, 48.8569
14.303970416, 96.390, 2497.0, 49.9700
14.356491546, 96.390, 2421.0, 49.2037
14.409012677, 96.390, 2491.0, 49.9099
14.461533808, 96.390, 2382.0, 48.8057
14.514054938, 96.390, 2373.0, 48.7134
14.566576069, 96.390, 2469.0, 49.6890
14.619097200, 96.390, 2555.0, 50.5470
14.671618331, 96.390, 2592.0, 50.9117
14.724139461, 96.390, 2483.0, 49.8297
14.776660592, 96.390, 2459.0, 49.5883
14.829181723, 96.390, 2437.0, 49.3660
14.881702853, 96.390, 2488.0, 49.8799
14.934223984, 96.390, 2484.0, 49.8397
14.986745115, 96.390, 2419.0, 49.1833
15.039266245, 96.390, 2363.0, 48.6107
15.091787376, 96.390, 2423.0, 49.2240
15.144308507, 96.390, 2366.0, 48.6415
15.196829638, 96.390, 2394.0, 48.9285
15.249350768, 96.390, 2341.0, 48.3839
15.301871899, 96.390, 2403.0, 49.0204
15.354393030, 96.390, 2361.0, 48.5901
15.406914160, 96.390, 2387.0, 48.8569
15.459435291, 96.390, 2353.0, 48.5077
15.511956422, 96.390, 2370.0, 48.6826
15.564477553, 96.390, 2370.0, 48.6826
15.616998683, 96.390, 2372.0, 48.7032
15.669519814, 96.390, 2437.0, 49.3660
15.722040945, 96.390, 2437.0, 49.3660
15.774562075, 96.390, 2364.0, 48.6210
15.827083206, 96.390, 2397.0, 48.9592
15.879604337, 96.390, 2409.0, 49.0816
15.932125468, 96.390, 2371.0, 48.6929
15.984646598, 96.390, 2427.0, 49.2646
16.037167729, 96.390, 2448.0, 49.4773
16.089688860, 96.390, 2421.0, 49.2037
16.142209990, 96.390, 2484.0, 49.8397
16.194731121, 96.390, 2418.0, 49.1732
16.247252252, 96.390, 2428.0, 49.2747
16.299773382, 96.390, 2420.0, 49.1935
16.352294513, 96.390, 2459.0, 49.5883
16.404815644, 96.390, 2502.0, 50.0200
16.457336775, 96.390, 2599.0, 50.9804
16.509857905, 96.390, 2585.0, 50.8429
16.562379036, 96.390, 2698.0, 51.9423
16.614900167, 96.390, 2738.0, 52.3259
16.667421297, 96.390, 2738.0, 52.3259
16.719942428, 96.390, 2679.0, 51.7591
16.772463559, 96.390, 2734.0, 52.2877
16.824984690, 96.390, 2613.0, 51.1175
16.877505820, 96.390, 2759.0, 52.5262
16.930026951, 96.390, 2612.0, 51.1077
16.982548082, 96.390, 2761.0, 52.5452
17.035069212, 96.390, 2651.0, 51.4879
17.087590343, 96.390, 2593.0, 50.9215
17.140111474, 96.390, 2686.0, 51.8266
17.192632605, 96.390, 2613.0, 51.1175
17.245153735, 96.390, 2573.0, 50.7247
17.297674866, 96.390, 2546.0, 50.4579
17.350195997, 96.390, 2520.0, 50.1996
17.402717127, 96.390, 2476.0, 49.7594
17.455238258, 96.390, 2548.0, 50.4777
17.507759389, 96.390, 2398.0, 48.9694
17.560280520, 96.390, 2583.0, 50.8232
17.612801650, 96.390, 2469.0, 49.6890
17.665322781, 96.390, 2512.0, 50.1199
17.717843912, 96.390, 2522.0, 50.2195
17.770365042, 96.390, 2468.0, 49.6790
17.822886173, 96.390, 2464.0, 49.6387
17.875407304, 96.390, 2522.0, 50.2195
17.927928434, 96.390, 2346.0, 48.4355
17.980449565, 96.390, 2368.0, 48.6621
18.032970696, 96.390, 2508.0, 50.0799
18.085491827, 96.390, 2456.0, 49.5580
18.138012957, 96.390, 2365.0, 48.6313
18.190534088, 96.390, 2351.0, 48.4871
18.243055219, 96.390, 2402.0, 49.0102
18.295576349, 96.390, 2326.0, 48.2286
18.348097480, 96.390, 2391.0, 48.8979
18.400618611, 96.390, 2335.0, 48.3218
18.453139742, 96.390, 2324.0, 48.2079
18.505660872, 96.390, 2513.0, 50.1298
18.558182003, 96.390, 2246.0, 47.3920
18.610703134, 96.390, 2458.0, 49.5782
18.663224264, 96.390, 2364.0, 48.6210
18.715745395, 96.390, 2332.0, 48.2908
18.768266526, 96.390, 2329.0, 48.2597
18.820787657, 96.390, 2323.0, 48.1975
18.873308787, 96.390, 2318.0, 48.1456
18.925829918, 96.390, 2314.0, 48.1041
18.978351049, 96.390, 2285.0, 47.8017
19.030872179, 96.390, 2395.0, 48.9387
19.083393310, 96.390, 2410.0, 49.0918
19.135914441, 96.390, 2512.0, 50.1199
19.188435572, 96.390, 2563.0, 50.6261
19.240956702, 96.390, 2617.0, 51.1566
19.293477833, 96.390, 2511.0, 50.1099
19.345998964, 96.390, 2487.0, 49.8698
19.398520094, 96.390, 2540.0, 50.3984
19.451041225, 96.390, 2481.0, 49.8096
19.503562356, 96.390, 2448.0, 49.4773
19.556083486, 96.390, 2445.0, 49.4469
19.608604617, 96.390, 2468.0, 49.6790
19.661125748, 96.390, 2447.0, 49.4672
19.713646879, 96.390, 2467.0, 49.6689
19.766168009, 96.390, 2377.0, 48.7545
19.818689140, 96.390, 2474.0, 49.7393
19.871210271, 96.390, 2559.0, 50.5866
19.923731401, 96.390, 2504.0, 50.0400
19.976252532, 96.390, 2444.0, 49.4368
20.028773663, 96.390, 2506.0, 50.0600
20.081294794, 96.390, 2534.0, 50.3389
20.133815924, 96.390, 2629.0, 51.2738
20.186337055, 96.390, 2652.0, 51.4976
20.238858186, 96.390, 2620.0, 51.1859
20.291379316, 96.390, 2617.0, 51.1566
20.343900447, 96.390, 2635.0, 51.3323
20.396421578, 96.390, 2629.0, 51.2738
20.448942709, 96.390, 2637.0, 51.3517
20.501463839, 96.390, 2655.0, 51.5267
20.553984970, 96.390, 2584.0, 50.8331
20.606506101, 96.390, 2534.0, 50.3389
20.659027231, 96.390, 2570.0, 50.6952
20.711548362, 96.390, 2493.0, 49.9300
20.764069493, 96.390, 2489.0, 49.8899
20.816590623, 96.390, 2507.0, 50.0700
20.869111754, 96.390, 2632.0, 51.3030
20.921632885, 96.390, 2583.0, 50.8232
20.974154016, 96.390, 2601.0, 51.0000
21.026675146, 96.390, 2511.0, 50.1099
21.079196277, 96.390, 2557.0, 50.5668
21.131717408, 96.390, 2586.0, 50.8527
21.184238538, 96.390, 2657.0, 51.5461
21.236759669, 96.390, 2615.0, 51.1371
21.289280800, 96.390, 2662.0, 51.5946
21.341801931, 96.390, 2666.0, 51.6333
21.394323061, 96.390, 2686.0, 51.8266
21.446844192, 96.390, 2766.0, 52.5928
21.499365323, 96.390, 2769.0, 52.6213
21.551886453, 96.390, 2587.0, 50.8626
21.604407584, 96.390, 2669.0, 51.6624
21.656928715, 96.390, 2689.0, 51.8556
21.709449846, 96.390, 2699.0, 51.9519
21.761970976, 96.390, 2485.0, 49.8498
21.814492107, 96.390, 2580.0, 50.7937
21.867013238, 96.390, 2548.0, 50.4777
21.919534368, 96.390, 2479.0, 49.7896
21.972055499, 96.390, 2514.0, 50.1398
22.024576630, 96.390, 2522.0, 50.2195
22.077097761, 96.390, 2500.0, 50.0000
22.129618891, 96.390, 2603.0, 51.0196
22.182140022, 96.390, 2441.0, 49.4065
22.234661153, 96.390, 2555.0, 50.5470
22.287182283, 96.390, 2517.0, 50.1697
22.339703414, 96.390, 2504.0, 50.0400
22.392224545, 96.390, 2484.0, 49.8397
22.444745675, 96.390, 2496.0, 49.9600
22.497266806, 96.390, 2515.0, 50.1498
22.549787937, 96.390, 2474.0, 49.7393
22.602309068, 96.390, 2461.0, 49.6085
22.654830198, 96.390, 2529.0, 50.2892
22.707351329, 96.390, 2518.0, 50.1797
22.759872460, 96.390, 2452.0, 49.5177
22.812393590, 96.390, 2424.0, 49.2341
22.864914721, 96.390, 2646.0, 51.4393
22.917435852, 96.390, 2457.0, 49.5681
22.969956983, 96.390, 2436.0, 49.3559
23.022478113, 96.390, 2488.0, 49.8799
23.074999244, 96.390, 2472.0, 49.7192
23.127520375, 96.390, 2556.0, 50.5569
23.180041505, 96.390, 2489.0, 49.8899
23.232562636, 96.390, 2435.0, 49.3457
23.285083767, 96.390, 2504.0, 50.0400
23.337604898, 96.390, 2376.0, 48.7442
23.390126028, 96.390, 2389.0, 48.8774
23.442647159, 96.390, 2355.0, 48.5283
23.495168290, 96.390, 2451.0, 49.5076
23.547689420, 96.390, 2467.0, 49.6689
23.600210551, 96.390, 2501.0, 50.0100
23.652731682, 96.390, 2541.0, 50.4083
23.705252813, 96.390, 2391.0, 48.8979
23.757773943, 96.390, 2474.0, 49.7393
23.810295074, 96.390, 2523.0, 50.2295
23.862816205, 96.390, 2524.0, 50.2394
23.915337335, 96.390, 2477.0, 49.7695
23.967858466, 96.390, 2533.0, 50.3289
24.020379597, 96.390, 2472.0, 49.7192
24.072900727, 96.390, 2415.0, 49.1426
24.125421858, 96.390, 2387.0, 48.8569
24.177942989, 96.390, 2485.0, 49.8498
24.230464120, 96.390, 2400.0, 48.9898
24.282985250, 96.390, 2399.0, 48.9796
24.335506381, 96.390, 2357.0, 48.5489
24.388027512, 96.390, 2440.0, 49.3964
24.440548642, 96.390, 2358.0, 48.5592
24.493069773, 96.390, 2361.0, 48.5901
24.545590904, 96.390, 2456.0, 49.5580
24.598112035, 96.390, 2455.0, 49.5480
24.650633165, 96.390, 2342.0, 48.3942
24.703154296, 96.390, 2337.0, 48.3425
24.755675427, 96.390, 2317.0, 48.1352
24.808196557, 96.390, 2320.0, 48.1664
24.860717688, 96.390, 2355.0, 48.5283
24.913238819, 96.390, 2382.0, 48.8057
24.965759950, 96.390, 2413.0, 49.1223
25.018281080, 96.390, 2304.0, 48.0000
25.070802211, 96.390, 2328.0, 48.2494
25.123323342, 96.390, 2348.0, 48.4562
25.175844472, 96.390, 2369.0, 48.6724
25.228365603, 96.390, 2362.0, 48.6004
25.280886734, 96.390, 2275.0, 47.6970
25.333407864, 96.390, 2329.0, 48.2597
25.385928995, 96.390, 2223.0, 47.1487
25.438450126, 96.390, 2373.0, 48.7134
25.490971257, 96.390, 2297.0, 47.9270
25.543492387, 96.390, 2371.0, 48.6929
25.596013518, 96.390, 2333.0, 48.3011
25.648534649, 96.390, 2306.0, 48.0208
25.701055779, 96.390, 2328.0, 48.2494
25.753576910, 96.390, 2289.0, 47.8435
25.806098041, 96.390, 2428.0, 49.2747
25.858619172, 96.390, 2306.0, 48.0208
25.911140302, 96.390, 2327.0, 48.2390
25.963661433, 96.390, 2292.0, 47.8748
26.016182564, 96.390, 2298.0, 47.9375
26.068703694, 96.390, 2274.0, 47.6865
26.121224825, 96.390, 2360.0, 48.5798
26.173745956, 96.390, 2362.0, 48.6004
26.226267087, 96.390, 2347.0, 48.4458
26.278788217, 96.390, 2378.0, 48.7647
26.331309348, 96.390, 2378.0, 48.7647
26.383830479, 96.390, 2307.0, 48.0312
26.436351609, 96.390, 2366.0, 48.6415
26.488872740, 96.390, 2319.0, 48.1560
26.541393871, 96.390, 2246.0, 47.3920
26.593915002, 96.390, 2395.0, 48.9387
26.646436132, 96.390, 2289.0, 47.8435
26.698957263, 96.390, 2398.0, 48.9694
26.751478394, 96.390, 2347.0, 48.4458
26.803999524, 96.390, 2329.0, 48.2597
26.856520655, 96.390, 2432.0, 49.3153
26.909041786, 96.390, 2313.0, 48.0937
26.961562916, 96.390, 2442.0, 49.4166
27.014084047, 96.390, 2399.0, 48.9796
27.066605178, 96.390, 2508.0, 50.0799
27.119126309, 96.390, 2511.0, 50.1099
27.171647439, 96.390, 2377.0, 48.7545
27.224168570, 96.390, 2467.0, 49.6689
27.276689701, 96.390, 2427.0, 49.2646
27.329210831, 96.390, 2401.0, 49.0000
27.381731962, 96.390, 2432.0, 49.3153
27.434253093, 96.390, 2491.0, 49.9099
27.486774224, 96.390, 2471.0, 49.7092
27.539295354, 96.390, 2398.0, 48.9694
27.591816485, 96.390, 2388.0, 48.8672
27.644337616, 96.390, 2427.0, 49.2646
27.696858746, 96.390, 2539.0, 50.3885
27.749379877, 96.390, 2598.0, 50.9706
27.801901008, 96.390, 2555.0, 50.5470
27.854422139, 96.390, 2553.0, 50.5272
27.906943269, 96.390, 2495.0, 49.9500
27.959464400, 96.390, 2535.0, 50.3488
28.011985531, 96.390, 2557.0, 50.5668
28.064506661, 96.390, 2555.0, 50.5470
28.117027792, 96.390, 2576.0, 50.7543
28.169548923, 96.390, 2600.0, 50.9902
28.222070054, 96.390, 2560.0, 50.5964
28.274591184, 96.390, 2536.0, 50.3587
28.327112315, 96.390, 2629.0, 51.2738
28.379633446, 96.390, 2642.0, 51.4004
28.432154576, 96.390, 2589.0, 50.8822
28.484675707, 96.390, 2561.0, 50.6063
28.537196838, 96.390, 2695.0, 51.9134
28.589717968, 96.390, 2600.0, 50.9902
28.642239099, 96.390, 2680.0, 51.7687
28.694760230, 96.390, 2592.0, 50.9117
28.747281361, 96.390, 2598.0, 50.9706
28.799802491, 96.390, 2637.0, 51.3517
28.852323622, 96.390, 2669.0, 51.6624
28.904844753, 96.390, 2600.0, 50.9902
28.957365883, 96.390, 2609.0, 51.0784
29.009887014, 96.390, 2676.0, 51.7301
29.062408145, 96.390, 2647.0, 51.4490
29.114929276, 96.390, 2541.0, 50.4083
29.167450406, 96.390, 2691.0, 51.8748
29.219971537, 96.390, 2600.0, 50.9902
29.272492668, 96.390, 2678.0, 51.7494
29.325013798, 96.390, 2693.0, 51.8941
29.377534929, 96.390, 2689.0, 51.8556
29.430056060, 96.390, 2788.0, 52.8015
29.482577191, 96.390, 2680.0, 51.7687
29.535098321, 96.390, 2721.0, 52.1632
29.587619452, 96.390, 2769.0, 52.6213
29.640140583, 96.390, 2720.0, 52.1536
29.692661713, 96.390, 2838.0, 53.2729
29.745182844, 96.390, 2905.0, 53.8981
29.797703975, 96.390, 2893.0, 53.7866
29.850225105, 96.390, 2845.0, 53.3385
29.902746236, 96.390, 2860.0, 53.4790
29.955267367, 96.390, 2837.0, 53.2635
30.007788498, 96.390, 2797.0, 52.8867
30.060309628, 96.390, 2844.0, 53.3292
30.112830759, 96.390, 2877.0, 53.6377
30.165351890, 96.390, 2945.0, 54.2679
30.217873020, 96.390, 2958.0, 54.3875
30.270394151, 96.390, 3012.0, 54.8817
30.322915282, 96.390, 2893.0, 53.7866
30.375436413, 96.390, 3013.0, 54.8908
30.427957543, 96.390, 2979.0, 54.5802
30.480478674, 96.390, 2940.0, 54.2218
30.532999805, 96.390, 2853.0, 53.4135
30.585520935, 96.390, 2820.0, 53.1037
30.638042066, 96.390, 2755.0, 52.4881
30.690563197, 96.390, 2717.0, 52.1249
30.743084328, 96.390, 2666.0, 51.6333
30.795605458, 96.390, 2637.0, 51.3517
30.848126589, 96.390, 2639.0, 51.3712
30.900647720, 96.390, 2629.0, 51.2738
30.953168850, 96.390, 2590.0, 50.8920
31.005689981, 96.390, 2647.0, 51.4490
31.058211112, 96.390, 2482.0, 49.8197
31.110732243, 96.390, 2598.0, 50.9706
31.163253373, 96.390, 2588.0, 50.8724
31.215774504, 96.390, 2580.0, 50.7937
31.268295635, 96.390, 2536.0, 50.3587
31.320816765, 96.390, 2563.0, 50.6261
31.373337896, 96.390, 2464.0, 49.6387
31.425859027, 96.390, 2534.0, 50.3389
31.478380157, 96.390, 2488.0, 49.8799
31.530901288, 96.390, 2437.0, 49.3660
31.583422419, 96.390, 2327.0, 48.2390
31.635943550, 96.390, 2417.0, 49.1630
31.688464680, 96.390, 2396.0, 48.9490
31.740985811, 96.390, 2399.0, 48.9796
31.793506942, 96.390, 2313.0, 48.0937
31.846028072, 96.390, 2282.0, 47.7703
31.898549203, 96.390, 2488.0, 49.8799
31.951070334, 96.390, 2275.0, 47.6970
32.003591465, 96.390, 2277.0, 47.7179
32.056112595, 96.390, 2355.0, 48.5283
32.108633726, 96.390, 2383.0, 48.8160
32.161154857, 96.390, 2302.0, 47.9792
32.213675987, 96.390, 2359.0, 48.5695
32.266197118, 96.390, 2283.0, 47.7807
32.318718249, 96.390, 2205.0, 46.9574
32.371239380, 96.390, 2273.0, 47.6760
32.423760510, 96.390, 2309.0, 48.0521
32.476281641, 96.390, 2317.0, 48.1352
32.528802772, 96.390, 2206.0, 46.9681
32.581323902, 96.390, 2272.0, 47.6655
32.633845033, 96.390, 2147.0, 46.3357
32.686366164, 96.390, 2169.0, 46.5725
32.738887295, 96.390, 2152.0, 46.3897
32.791408425, 96.390, 2109.0, 45.9239
32.843929556, 96.390, 2146.0, 46.3249
32.896450687, 96.390, 2144.0, 46.3033
32.948971817, 96.390, 2083.0, 45.6399
33.001492948, 96.390, 2121.0, 46.0543
33.054014079, 96.390, 2158.0, 46.4543
33.106535209, 96.390, 2099.0, 45.8148
33.159056340, 96.390, 2160.0, 46.4758
33.211577471, 96.390, 2110.0, 45.9347
33.264098602, 96.390, 2127.0, 46.1194
33.316619732, 96.390, 2066.0, 45.4533
33.369140863, 96.390, 2126.0, 46.1086
33.421661994, 96.390, 2057.0, 45.3542
33.474183124, 96.390, 2075.0, 45.5522
33.526704255, 96.390, 2170.0, 46.5833
33.579225386, 96.390, 2108.0, 45.9130
33.631746517, 96.390, 2131.0, 46.1628
33.684267647, 96.390, 2172.0, 46.6047
33.736788778, 96.390, 2105.0, 45.8803
33.789309909, 96.390, 2022.0, 44.9667
33.841831039, 96.390, 2120.0, 46.0435
33.894352170, 96.390, 2156.0, 46.4327
33.946873301, 96.390, 2064.0, 45.4313
33.999394432, 96.390, 2014.0, 44.8776
34.051915562, 96.390, 2106.0, 45.8912
34.104436693, 96.390, 2031.0, 45.0666
34.156957824, 96.390, 1971.0, 44.3959
34.209478954, 96.390, 1976.0, 44.4522
34.262000085, 96.390, 2008.0, 44.8107
34.314521216, 96.390, 2048.0, 45.2548
34.367042346, 96.390, 1903.0, 43.6234
34.419563477, 96.390, 1909.0, 43.6921
34.472084608, 96.390, 2007.0, 44.7996
34.524605739, 96.390, 1875.0, 43.3013
34.577126869, 96.390, 1842.0, 42.9185
34.629648000, 96.390, 1919.0, 43.8064
34.682169131, 96.390, 1895.0, 43.5316
34.734690261, 96.390, 1837.0, 42.8602
34.787211392, 96.390, 1901.0, 43.6005
34.839732523, 96.390, 1837.0, 42.8602
34.892253654, 96.390, 1884.0, 43.4051
34.944774784, 96.390, 1857.0, 43.0929
34.997295915, 96.390, 1946.0, 44.1135
35.049817046, 96.390, 1900.0, 43.5890
35.102338176, 96.390, 1843.0, 42.9302
35.154859307, 96.390, 1858.0, 43.1045
35.207380438, 96.390, 1768.0, 42.0476
35.259901569, 96.390, 1759.0, 41.9404
35.312422699, 96.390, 1743.0, 41.7493
35.364943830, 96.390, 1886.0, 43.4281
35.417464961, 96.390, 1766.0, 42.0238
35.469986091, 96.390, 1806.0, 42.4971
35.522507222, 96.390, 1716.0, 41.4246
35.575028353, 96.390, 1774.0, 42.1189
35.627549484, 96.390, 1716.0, 41.4246
35.680070614, 96.390, 1802.0, 42.4500
35.732591745, 96.390, 1758.0, 41.9285
35.785112876, 96.390, 1799.0, 42.4146
35.837634006, 96.390, 1697.0, 41.1947
35.890155137, 96.390, 1715.0, 41.4126
35.942676268, 96.390, 1636.0, 40.4475
35.995197398, 96.390, 1724.0, 41.5211
36.047718529, 96.390, 1697.0, 41.1947
36.100239660, 96.390, 1605.0, 40.0625
36.152760791, 96.390, 1589.0, 39.8623
36.205281921, 96.390, 1656.0, 40.6940
36.257803052, 96.390, 1645.0, 40.5586
36.310324183, 96.390, 1647.0, 40.5832
36.362845313, 96.390, 1703.0, 41.2674
36.415366444, 96.390, 1575.0, 39.6863
36.467887575, 96.390, 1571.0, 39.6358
36.520408706, 96.390, 1622.0, 40.2741
36.572929836, 96.390, 1565.0, 39.5601
36.625450967, 96.390, 1631.0, 40.3856
36.677972098, 96.390, 1676.0, 40.9390
36.730493228, 96.390, 1624.0, 40.2989
36.783014359, 96.390, 1638.0, 40.4722
36.835535490, 96.390, 1622.0, 40.2741
36.888056621, 96.390, 1684.0, 41.0366
36.940577751, 96.390, 1642.0, 40.5216
36.993098882, 96.390, 1556.0, 39.4462
37.045620013, 96.390, 1570.0, 39.6232
37.098141143, 96.390, 1597.0, 39.9625
37.150662274, 96.390, 1553.0, 39.4081
37.203183405, 96.390, 1456.0, 38.1576
37.255704535, 96.390, 1493.0, 38.6394
37.308225666, 96.390, 1508.0, 38.8330
37.360746797, 96.390, 1519.0, 38.9744
37.413267928, 96.390, 1481.0, 38.4838
37.465789058, 96.390, 1451.0, 38.0920
37.518310189, 96.390, 1481.0, 38.4838
37.570831320, 96.390, 1499.0, 38.7169
37.623352450, 96.390, 1461.0, 38.2230
37.675873581, 96.390, 1449.0, 38.0657
37.728394712, 96.390, 1426.0, 37.7624
37.780915843, 96.390, 1382.0, 37.1753
37.833436973, 96.390, 1430.0, 37.8153
37.885958104, 96.390, 1430.0, 37.8153
37.938479235, 96.390, 1438.0, 37.9210
37.991000365, 96.390, 1440.0, 37.9473
38.043521496, 96.390, 1359.0, 36.8646
38.096042627, 96.390, 1418.0, 37.6563
38.148563758, 96.390, 1369.0, 37.0000
38.201084888, 96.390, 1401.0, 37.4299
38.253606019, 96.390, 1419.0, 37.6696
38.306127150, 96.390, 1329.0, 36.4555
38.358648280, 96.390, 1336.0, 36.5513
38.411169411, 96.390, 1304.0, 36.1109
38.463690542, 96.390, 1378.0, 37.1214
38.516211673, 96.390, 1353.0, 36.7831
38.568732803, 96.390, 1419.0, 37.6696
38.621253934, 96.390, 1412.0, 37.5766
38.673775065, 96.390, 1421.0, 37.6962
38.726296195, 96.390, 1537.0, 39.2046
38.778817326, 96.390, 1525.0, 39.0512
38.831338457, 96.390, 1552.0, 39.3954
38.883859587, 96.390, 1587.0, 39.8372
38.936380718, 96.390, 1641.0, 40.5093
38.988901849, 96.390, 1575.0, 39.6863
39.041422980, 96.390, 1535.0, 39.1791
39.093944110, 96.390, 1588.0, 39.8497
39.146465241, 96.390, 1435.0, 37.8814
39.198986372, 96.390, 1510.0, 38.8587
39.251507502, 96.390, 1443.0, 37.9868
39.304028633, 96.390, 1400.0, 37.4166
39.356549764, 96.390, 1434.0, 37.8682
39.409070895, 96.390, 1366.0, 36.9594
39.461592025, 96.390, 1313.0, 36.2353
39.514113156, 96.390, 1417.0, 37.6431
39.566634287, 96.390, 1327.0, 36.4280
39.619155417, 96.390, 1414.0, 37.6032
39.671676548, 96.390, 1406.0, 37.4967
39.724197679, 96.390, 1378.0, 37.1214
39.776718810, 96.390, 1402.0, 37.4433
39.829239940, 96.390, 1367.0, 36.9730
39.881761071, 96.390, 1317.0, 36.2905
39.934282202, 96.390, 1328.0, 36.4417
39.986803332, 96.390, 1319.0, 36.3180
40.039324463, 96.390, 1296.0, 36.0000
40.091845594, 96.390, 1283.0, 35.8190
40.144366725, 96.390, 1361.0, 36.8917
40.196887855, 96.390, 1307.0, 36.1525
40.249408986, 96.390, 1244.0, 35.2704
40.301930117, 96.390, 1267.0, 35.5949
40.354451247, 96.390, 1247.0, 35.3129
40.406972378, 96.390, 1338.0, 36.5787
40.459493509, 96.390, 1322.0, 36.3593
40.512014639, 96.390, 1288.0, 35.8887
40.564535770, 96.390, 1275.0, 35.7071
40.617056901, 96.390, 1261.0, 35.5106
40.669578032, 96.390, 1276.0, 35.7211
40.722099162, 96.390, 1260.0, 35.4965
40.774620293, 96.390, 1282.0, 35.8050
40.827141424, 96.390, 1319.0, 36.3180
40.879662554, 96.390, 1262.0, 35.5246
40.932183685, 96.390, 1305.0, 36.1248
40.984704816, 96.390, 1269.0, 35.6230
41.037225947, 96.390, 1211.0, 34.7994
41.089747077, 96.390, 1233.0, 35.1141
41.142268208, 96.390, 1247.0, 35.3129
41.194789339, 96.390, 1269.0, 35.6230
41.247310469, 96.390, 1212.0, 34.8138
41.299831600, 96.390, 1243.0, 35.2562
41.352352731, 96.390, 1216.0, 34.8712
41.404873862, 96.390, 1208.0, 34.7563
41.457394992, 96.390, 1320.0, 36.3318
41.509916123, 96.390, 1240.0, 35.2136
41.562437254, 96.390, 1204.0, 34.6987
41.614958384, 96.390, 1234.0, 35.1283
41.667479515, 96.390, 1190.0, 34.4964
41.720000646, 96.390, 1247.0, 35.3129
41.772521776, 96.390, 1222.0, 34.9571
41.825042907, 96.390, 1290.0, 35.9166
41.877564038, 96.390, 1209.0, 34.7707
41.930085169, 96.390, 1123.0, 33.5112
41.982606299, 96.390, 1105.0, 33.2415
42.035127430, 96.390, 1242.0, 35.2420
42.087648561, 96.390, 1165.0, 34.1321
42.140169691, 96.390, 1266.0, 35.5809
42.192690822, 96.390, 1240.0, 35.2136
42.245211953, 96.390, 1251.0, 35.3695
42.297733084, 96.390, 1191.0, 34.5109
42.350254214, 96.390, 1204.0, 34.6987
42.402775345, 96.390, 1110.0, 33.3167
42.455296476, 96.390, 1240.0, 35.2136
42.507817606, 96.390, 1158.0, 34.0294
42.560338737, 96.390, 1269.0, 35.6230
42.612859868, 96.390, 1230.0, 35.0714
42.665380999, 96.390, 1188.0, 34.4674
42.717902129, 96.390, 1262.0, 35.5246
42.770423260, 96.390, 1156.0, 34.0000
42.822944391, 96.390, 1175.0, 34.2783
42.875465521, 96.390, 1219.0, 34.9142
42.927986652, 96.390, 1178.0, 34.3220
42.980507783, 96.390, 1168.0, 34.1760
43.033028914, 96.390, 1191.0, 34.5109
43.085550044, 96.390, 1243.0, 35.2562
43.138071175, 96.390, 1175.0, 34.2783
43.190592306, 96.390, 1203.0, 34.6843
43.243113436, 96.390, 1208.0, 34.7563
43.295634567, 96.390, 1193.0, 34.5398
43.348155698, 96.390, 1167.0, 34.1614
43.400676828, 96.390, 1128.0, 33.5857
43.453197959, 96.390, 1185.0, 34.4238
43.505719090, 96.390, 1123.0, 33.5112
43.558240221, 96.390, 1144.0, 33.8231
43.610761351, 96.390, 1182.0, 34.3802
43.663282482, 96.390, 1139.0, 33.7491
43.715803613, 96.390, 1122.0, 33.4963
43.768324743, 96.390, 1152.0, 33.9411
43.820845874, 96.390, 1199.0, 34.6266
43.873367005, 96.390, 1159.0, 34.0441
43.925888136, 96.390, 1156.0, 34.0000
43.978409266, 96.390, 1123.0, 33.5112
44.030930397, 96.390, 1222.0, 34.9571
44.083451528, 96.390, 1199.0, 34.6266
44.135972658, 96.390, 1164.0, 34.1174
44.188493789, 96.390, 1174.0, 34.2637
44.241014920, 96.390, 1147.0, 33.8674
44.293536051, 96.390, 1217.0, 34.8855
44.346057181, 96.390, 1218.0, 34.8999
44.398578312, 96.390, 1223.0, 34.9714
44.451099443, 96.390, 1176.0, 34.2929
44.503620573, 96.390, 1183.0, 34.3948
44.556141704, 96.390, 1198.0, 34.6121
44.608662835, 96.390, 1225.0, 35.0000
44.661183966, 96.390, 1219.0, 34.9142
44.713705096, 96.390, 1243.0, 35.2562
44.766226227, 96.390, 1193.0, 34.5398
44.818747358, 96.390, 1203.0, 34.6843
44.871268488, 96.390, 1175.0, 34.2783
44.923789619, 96.390, 1281.0, 35.7911
44.976310750, 96.390, 1223.0, 34.9714
45.028831880, 96.390, 1270.0, 35.6371
45.081353011, 96.390, 1224.0, 34.9857
45.133874142, 96.390, 1195.0, 34.5688
45.186395273, 96.390, 1199.0, 34.6266
45.238916403, 96.390, 1257.0, 35.4542
45.291437534, 96.390, 1265.0, 35.5668
45.343958665, 96.390, 1246.0, 35.2987
45.396479795, 96.390, 1171.0, 34.2199
45.449000926, 96.390, 1273.0, 35.6791
45.501522057, 96.390, 1257.0, 35.4542
45.554043188, 96.390, 1168.0, 34.1760
45.606564318, 96.390, 1216.0, 34.8712
45.659085449, 96.390, 1183.0, 34.3948
45.711606580, 96.390, 1195.0, 34.5688
45.764127710, 96.390, 1247.0, 35.3129
45.816648841, 96.390, 1180.0, 34.3511
45.869169972, 96.390, 1115.0, 33.3916
45.921691103, 96.390, 1162.0, 34.0881
45.974212233, 96.390, 1235.0, 35.1426
46.026733364, 96.390, 1155.0, 33.9853
46.079254495, 96.390, 1170.0, 34.2053
46.131775625, 96.390, 1190.0, 34.4964
46.184296756, 96.390, 1209.0, 34.7707
46.236817887, 96.390, 1162.0, 34.0881
46.289339017, 96.390, 1189.0, 34.4819
46.341860148, 96.390, 1175.0, 34.2783
46.394381279, 96.390, 1192.0, 34.5254
46.446902410, 96.390, 1177.0, 34.3074
46.499423540, 96.390, 1176.0, 34.2929
46.551944671, 96.390, 1181.0, 34.3657
46.604465802, 96.390, 1157.0, 34.0147
46.656986932, 96.390, 1204.0, 34.6987
46.709508063, 96.390, 1139.0, 33.7491
46.762029194, 96.390, 1174.0, 34.2637
46.814550325, 96.390, 1220.0, 34.9285
46.867071455, 96.390, 1159.0, 34.0441
46.919592586, 96.390, 1193.0, 34.5398
46.972113717, 96.390, 1106.0, 33.2566
47.024634847, 96.390, 1154.0, 33.9706
47.077155978, 96.390, 1145.0, 33.8378
47.129677109, 96.390, 1133.0, 33.6601
47.182198240, 96.390, 1127.0, 33.5708
47.234719370, 96.390, 1090.0, 33.0151
47.287240501, 96.390, 1112.0, 33.3467
47.339761632, 96.390, 1190.0, 34.4964
47.392282762, 96.390, 1112.0, 33.3467
47.444803893, 96.390, 1075.0, 32.7872
47.497325024, 96.390, 1134.0, 33.6749
47.549846155, 96.390, 1057.0, 32.5115
47.602367285, 96.390, 1087.0, 32.9697
47.654888416, 96.390, 1117.0, 33.4215
47.707409547, 96.390, 1101.0, 33.1813
47.759930677, 96.390, 1140.0, 33.7639
47.812451808, 96.390, 1030.0, 32.0936
47.864972939, 96.390, 1053.0, 32.4500
47.917494069, 96.390, 1068.0, 32.6803
47.970015200, 96.390, 1140.0, 33.7639
48.022536331, 96.390, 1052.0, 32.4345
48.075057462, 96.390, 1100.0, 33.1662
48.127578592, 96.390, 1101.0, 33.1813
48.180099723, 96.390, 1062.0, 32.5883
48.232620854, 96.390, 1087.0, 32.9697
48.285141984, 96.390, 1091.0, 33.0303
48.337663115, 96.390, 1058.0, 32.5269
48.390184246, 96.390, 1089.0, 33.0000
48.442705377, 96.390, 1092.0, 33.0454
48.495226507, 96.390, 1073.0, 32.7567
48.547747638, 96.390, 1020.0, 31.9374
48.600268769, 96.390, 1073.0, 32.7567
48.652789899, 96.390, 1057.0, 32.5115
48.705311030, 96.390, 1044.0, 32.3110
48.757832161, 96.390, 1051.0, 32.4191
48.810353292, 96.390, 1031.0, 32.1092
48.862874422, 96.390, 1099.0, 33.1512
48.915395553, 96.390, 1048.0, 32.3728
48.967916684, 96.390, 1009.0, 31.7648
49.020437814, 96.390, 1041.0, 32.2645
49.072958945, 96.390, 1082.0, 32.8938
49.125480076, 96.390, 1017.0, 31.8904
49.178001207, 96.390, 1020.0, 31.9374
49.230522337, 96.390, 1014.0, 31.8434
49.283043468, 96.390, 1022.0, 31.9687
49.335564599, 96.390, 1013.0, 31.8277
49.388085729, 96.390, 1039.0, 32.2335
49.440606860, 96.390, 970.0, 31.1448
49.493127991, 96.390, 1040.0, 32.2490
49.545649121, 96.390, 992.0, 31.4960
49.598170252, 96.390, 987.0, 31.4166
49.650691383, 96.390, 1000.0, 31.6228
49.703212514, 96.390, 978.0, 31.2730
49.755733644, 96.390, 1003.0, 31.6702
49.808254775, 96.390, 1039.0, 32.2335
49.860775906, 96.390, 903.0, 30.0500
49.913297036, 96.390, 948.0, 30.7896
49.965818167, 96.390, 939.0, 30.6431
50.018339298, 96.390, 1036.0, 32.1870
50.070860429, 96.390, 968.0, 31.1127
50.123381559, 96.390, 963.0, 31.0322
50.175902690, 96.390, 983.0, 31.3528
50.228423821, 96.390, 933.0, 30.5450
50.280944951, 96.390, 953.0, 30.8707
50.333466082, 96.390, 988.0, 31.4325
50.385987213, 96.390, 1048.0, 32.3728
50.438508344, 96.390, 958.0, 30.9516
50.491029474, 96.390, 943.0, 30.7083
50.543550605, 96.390, 938.0, 30.6268
50.596071736, 96.390, 920.0, 30.3315
50.648592866, 96.390, 917.0, 30.2820
50.701113997, 96.390, 971.0, 31.1609
50.753635128, 96.390, 979.0, 31.2890
50.806156258, 96.390, 912.0, 30.1993
50.858677389, 96.390, 936.0, 30.5941
50.911198520, 96.390, 934.0, 30.5614
50.963719651, 96.390, 1004.0, 31.6860
51.016240781, 96.390, 998.0, 31.5911
51.068761912, 96.390, 980.0, 31.3050
51.121283043, 96.390, 1006.0, 31.7175
51.173804173, 96.390, 961.0, 31.0000
51.226325304, 96.390, 972.0, 31.1769
51.278846435, 96.390, 1026.0, 32.0312
51.331367566, 96.390, 973.0, 31.1929
51.383888696, 96.390, 941.0, 30.6757
51.436409827, 96.390, 979.0, 31.2890
51.488930958, 96.390, 936.0, 30.5941
51.541452088, 96.390, 934.0, 30.5614
51.593973219, 96.390, 924.0, 30.3974
51.646494350, 96.390, 974.0, 31.2090
51.699015481, 96.390, 895.0, 29.9166
51.751536611, 96.390, 976.0, 31.2410
51.804057742, 96.390, 948.0, 30.7896
51.856578873, 96.390, 929.0, 30.4795
51.909100003, 96.390, 961.0, 31.0000
51.961621134, 96.390, 892.0, 29.8664
52.014142265, 96.390, 985.0, 31.3847
52.066663396, 96.390, 890.0, 29.8329
52.119184526, 96.390, 907.0, 30.1164
52.171705657, 96.390, 909.0, 30.1496
52.224226788, 96.390, 858.0, 29.2916
52.276747918, 96.390, 912.0, 30.1993
52.329269049, 96.390, 894.0, 29.8998
52.381790180, 96.390, 950.0, 30.8221
52.434311310, 96.390, 923.0, 30.3809
52.486832441, 96.390, 864.0, 29.3939
52.539353572, 96.390, 933.0, 30.5450
52.591874703, 96.390, 918.0, 30.2985
52.644395833, 96.390, 908.0, 30.1330
52.696916964, 96.390, 890.0, 29.8329
52.749438095, 96.390, 911.0, 30.1828
52.801959225, 96.390, 858.0, 29.2916
52.854480356, 96.390, 915.0, 30.2490
52.907001487, 96.390, 893.0, 29.8831
52.959522618, 96.390, 868.0, 29.4618
53.012043748, 96.390, 894.0, 29.8998
53.064564879, 96.390, 883.0, 29.7153
53.117086010, 96.390, 909.0, 30.1496
53.169607140, 96.390, 918.0, 30.2985
53.222128271, 96.390, 883.0, 29.7153
53.274649402, 96.390, 852.0, 29.1890
53.327170533, 96.390, 846.0, 29.0861
53.379691663, 96.390, 913.0, 30.2159
53.432212794, 96.390, 861.0, 29.3428
53.484733925, 96.390, 892.0, 29.8664
53.537255055, 96.390, 847.0, 29.1033
53.589776186, 96.390, 927.0, 30.4467
53.642297317, 96.390, 861.0, 29.3428
53.694818448, 96.390, 892.0, 29.8664
53.747339578, 96.390, 877.0, 29.6142
53.799860709, 96.390, 929.0, 30.4795
53.852381840, 96.390, 910.0, 30.1662
53.904902970, 96.390, 902.0, 30.0333
53.957424101, 96.390, 925.0, 30.4138
54.009945232, 96.390, 929.0, 30.4795
54.062466362, 96.390, 881.0, 29.6816
54.114987493, 96.390, 868.0, 29.4618
54.167508624, 96.390, 880.0, 29.6648
54.220029755, 96.390, 909.0, 30.1496
54.272550885, 96.390, 912.0, 30.1993
54.325072016, 96.390, 921.0, 30.3480
54.377593147, 96.390, 889.0, 29.8161
54.430114277, 96.390, 880.0, 29.6648
54.482635408, 96.390, 940.0, 30.6594
54.535156539, 96.390, 899.0, 29.9833
54.587677670, 96.390, 876.0, 29.5973
54.640198800, 96.390, 970.0, 31.1448
54.692719931, 96.390, 926.0, 30.4302
54.745241062, 96.390, 892.0, 29.8664
54.797762192, 96.390, 942.0, 30.6920
54.850283323, 96.390, 957.0, 30.9354
54.902804454, 96.390, 949.0, 30.8058
54.955325585, 96.390, 928.0, 30.4631
55.007846715, 96.390, 935.0, 30.5778
55.060367846, 96.390, 943.0, 30.7083
55.112888977, 96.390, 934.0, 30.5614
55.165410107, 96.390, 900.0, 30.0000
55.217931238, 96.390, 922.0, 30.3645
55.270452369, 96.390, 899.0, 29.9833
55.322973499, 96.390, 902.0, 30.0333
55.375494630, 96.390, 950.0, 30.8221
55.428015761, 96.390, 873.0, 29.5466
55.480536892, 96.390, 892.0, 29.8664
55.533058022, 96.390, 913.0, 30.2159
55.585579153, 96.390, 907.0, 30.1164
55.638100284, 96.390, 918.0, 30.2985
55.690621414, 96.390, 931.0, 30.5123
55.743142545, 96.390, 907.0, 30.1164
55.795663676, 96.390, 897.0, 29.9500
55.848184807, 96.390, 896.0, 29.9333
55.900705937, 96.390, 891.0, 29.8496
55.953227068, 96.390, 896.0, 29.9333
56.005748199, 96.390, 930.0, 30.4959
56.058269329, 96.390, 892.0, 29.8664
56.110790460, 96.390, 893.0, 29.8831
56.163311591, 96.390, 935.0, 30.5778
56.215832722, 96.390, 890.0, 29.8329
56.268353852, 96.390, 908.0, 30.1330
56.320874983, 96.390, 860.0, 29.3258
56.373396114, 96.390, 946.0, 30.7571
56.425917244, 96.390, 850.0, 29.1548
56.478438375, 96.390, 890.0, 29.8329
56.530959506, 96.390, 862.0, 29.3598
56.583480637, 96.390, 864.0, 29.3939
56.636001767, 96.390, 885.0, 29.7489
56.688522898, 96.390, 841.0, 29.0000
56.741044029, 96.390, 942.0, 30.6920
56.793565159, 96.390, 882.0, 29.6985
56.846086290, 96.390, 881.0, 29.6816
56.898607421, 96.390, 868.0, 29.4618
56.951128551, 96.390, 856.0, 29.2575
57.003649682, 96.390, 928.0, 30.4631
57.056170813, 96.390, 918.0, 30.2985
57.108691944, 96.390, 895.0, 29.9166
57.161213074, 96.390, 874.0, 29.5635
57.213734205, 96.390, 900.0, 30.0000
57.266255336, 96.390, 862.0, 29.3598
57.318776466, 96.390, 870.0, 29.4958
57.371297597, 96.390, 947.0, 30.7734
57.423818728, 96.390, 921.0, 30.3480
57.476339859, 96.390, 879.0, 29.6479
57.528860989, 96.390, 878.0, 29.6311
57.581382120, 96.390, 887.0, 29.7825
57.633903251, 96.390, 850.0, 29.1548
57.686424381, 96.390, 881.0, 29.6816
57.738945512, 96.390, 876.0, 29.5973
57.791466643, 96.390, 895.0, 29.9166
57.843987774, 96.390, 843.0, 29.0345
57.896508904, 96.390, 861.0, 29.3428
57.949030035, 96.390, 860.0, 29.3258
58.001551166, 96.390, 858.0, 29.2916
58.054072296, 96.390, 889.0, 29.8161
58.106593427, 96.390, 860.0, 29.3258
58.159114558, 96.390, 893.0, 29.8831
58.211635689, 96.390, 977.0, 31.2570
58.264156819, 96.390, 862.0, 29.3598
58.316677950, 96.390, 873.0, 29.5466
58.369199081, 96.390, 888.0, 29.7993
58.421720211, 96.390, 871.0, 29.5127
58.474241342, 96.390, 906.0, 30.0998
58.526762473, 96.390, 868.0, 29.4618
58.579283603, 96.390, 873.0, 29.5466
58.631804734, 96.390, 841.0, 29.0000
58.684325865, 96.390, 840.0, 28.9828
58.736846996, 96.390, 882.0, 29.6985
58.789368126, 96.390, 819.0, 28.6182
58.841889257, 96.390, 894.0, 29.8998
58.894410388, 96.390, 903.0, 30.0500
58.946931518, 96.390, 860.0, 29.3258
58.999452649, 96.390, 839.0, 28.9655
59.051973780, 96.390, 926.0, 30.4302
59.104494911, 96.390, 842.0, 29.0172
59.157016041, 96.390, 885.0, 29.7489
59.209537172, 96.390, 794.0, 28.1780
59.262058303, 96.390, 867.0, 29.4449
59.314579433, 96.390, 877.0, 29.6142
59.367100564, 96.390, 861.0, 29.3428
59.419621695, 96.390, 873.0, 29.5466
59.472142826, 96.390, 923.0, 30.3809
59.524663956, 96.390, 862.0, 29.3598
59.577185087, 96.390, 887.0, 29.7825
59.629706218, 96.390, 852.0, 29.1890
59.682227348, 96.390, 935.0, 30.5778
59.734748479, 96.390, 820.0, 28.6356
59.787269610, 96.390, 870.0, 29.4958
59.839790740, 96.390, 838.0, 28.9482
59.892311871, 96.390, 876.0, 29.5973
59.944833002, 96.390, 881.0, 29.6816
59.997354133, 96.390, 852.0, 29.1890
60.049875263, 96.390, 900.0, 30.0000
60.102396394, 96.390, 848.0, 29.1204
60.154917525, 96.390, 934.0, 30.5614
60.207438655, 96.390, 863.0, 29.3769
60.259959786, 96.390, 860.0, 29.3258
60.312480917, 96.390, 896.0, 29.9333
60.365002048, 96.390, 915.0, 30.2490
60.417523178, 96.390, 916.0, 30.2655
60.470044309, 96.390, 955.0, 30.9031
60.522565440, 96.390, 976.0, 31.2410
60.575086570, 96.390, 924.0, 30.3974
60.627607701, 96.390, 924.0, 30.3974
60.680128832, 96.390, 1009.0, 31.7648
60.732649963, 96.390, 957.0, 30.9354
60.785171093, 96.390, 962.0, 31.0161
60.837692224, 96.390, 946.0, 30.7571
60.890213355, 96.390, 982.0, 31.3369
60.942734485, 96.390, 926.0, 30.4302
60.995255616, 96.390, 997.0, 31.5753
61.047776747, 96.390, 1023.0, 31.9844
61.100297878, 96.390, 1025.0, 32.0156
61.152819008, 96.390, 1040.0, 32.2490
61.205340139, 96.390, 1012.0, 31.8119
61.257861270, 96.390, 979.0, 31.2890
61.310382400, 96.390, 962.0, 31.0161
61.362903531, 96.390, 995.0, 31.5436
61.415424662, 96.390, 1023.0, 31.9844
61.467945792, 96.390, 936.0, 30.5941
61.520466923, 96.390, 931.0, 30.5123
61.572988054, 96.390, 973.0, 31.1929
61.625509185, 96.390, 951.0, 30.8383
61.678030315, 96.390, 936.0, 30.5941
61.730551446, 96.390, 921.0, 30.3480
61.783072577, 96.390, 1003.0, 31.6702
61.835593707, 96.390, 917.0, 30.2820
61.888114838, 96.390, 945.0, 30.7409
61.940635969, 96.390, 878.0, 29.6311
61.993157100, 96.390, 941.0, 30.6757
62.045678230, 96.390, 888.0, 29.7993
62.098199361, 96.390, 877.0, 29.6142
62.150720492, 96.390, 934.0, 30.5614
62.203241622, 96.390, 893.0, 29.8831
62.255762753, 96.390, 913.0, 30.2159
62.308283884, 96.390, 962.0, 31.0161
62.360805015, 96.390, 926.0, 30.4302
62.413326145, 96.390, 944.0, 30.7246
62.465847276, 96.390, 894.0, 29.8998
62.518368407, 96.390, 889.0, 29.8161
62.570889537, 96.390, 870.0, 29.4958
62.623410668, 96.390, 820.0, 28.6356
62.675931799, 96.390, 884.0, 29.7321
62.728452930, 96.390, 860.0, 29.3258
62.780974060, 96.390, 872.0, 29.5296
62.833495191, 96.390, 830.0, 28.8097
62.886016322, 96.390, 841.0, 29.0000
62.938537452, 96.390, 889.0, 29.8161
62.991058583, 96.390, 847.0, 29.1033
63.043579714, 96.390, 855.0, 29.2404
63.096100844, 96.390, 812.0, 28.4956
63.148621975, 96.390, 856.0, 29.2575
63.201143106, 96.390, 850.0, 29.1548
63.253664237, 96.390, 923.0, 30.3809
63.306185367, 96.390, 885.0, 29.7489
63.358706498, 96.390, 792.0, 28.1425
63.411227629, 96.390, 834.0, 28.8791
63.463748759, 96.390, 864.0, 29.3939
63.516269890, 96.390, 841.0, 29.0000
63.568791021, 96.390, 805.0, 28.3725
63.621312152, 96.390, 853.0, 29.2062
63.673833282, 96.390, 844.0, 29.0517
63.726354413, 96.390, 863.0, 29.3769
63.778875544, 96.390, 795.0, 28.1957
63.831396674, 96.390, 832.0, 28.8444
63.883917805, 96.390, 894.0, 29.8998
63.936438936, 96.390, 830.0, 28.8097
63.988960067, 96.390, 790.0, 28.1069
64.041481197, 96.390, 826.0, 28.7402
64.094002328, 96.390, 832.0, 28.8444
64.146523459, 96.390, 877.0, 29.6142
64.199044589, 96.390, 779.0, 27.9106
64.251565720, 96.390, 852.0, 29.1890
64.304086851, 96.390, 796.0, 28.2135
64.356607981, 96.390, 839.0, 28.9655
64.409129112, 96.390, 789.0, 28.0891
64.461650243, 96.390, 739.0, 27.1846
64.514171374, 96.390, 831.0, 28.8271
64.566692504, 96.390, 805.0, 28.3725
64.619213635, 96.390, 815.0, 28.5482
64.671734766, 96.390, 843.0, 29.0345
64.724255896, 96.390, 794.0, 28.1780
64.776777027, 96.390, 793.0, 28.1603
64.829298158, 96.390, 826.0, 28.7402
64.881819289, 96.390, 758.0, 27.5318
64.934340419, 96.390, 785.0, 28.0179
64.986861550, 96.390, 736.0, 27.1293