File: Files_organized_for_plots/Constant_NaOH_half_mL10M_to_1gPC/XRD_AlAxial27Jan22_Act21Feb22_B4_0617M_NaOH_LS0094_1.csv
[Measurement conditions]
Sample identification,XRD_AlAxial27Jan22_Act21Feb22_B4_0617M_NaOH_LS0094_1
Comment - 1,"Configuration=Stage for Flat Samples/Holders, Owner=User-1, Creation date=7/1/2020 9:53:24 AM"
Comment - 2,"Goniometer=Theta/Theta; Minimum step size 2Theta:0.0001; Minimum step size Omega:0.0001"
Comment - 3,"Sample stage=Stage for flat samples/holders"
Comment - 4,"Diffractometer system=EMPYREAN"
Comment - 5,"Measurement program=C:\Users\ibo5034\OneDrive - The Pennsylvania State University\NEUP - Reed, Titus's files\XRD\Cement\Zerobackground scan.xrdmp, Identifier={98A3B11C-88F9-4AA6-982C-73314A311EF5}"
Anode material,Cu
K-Alpha1 wavelength,1.5405980
K-Alpha2 wavelength,1.5444260
Ratio K-Alpha2/K-Alpha1,0.500
Divergence slit,Fixed,0.25
Monochromator used,NO
Generator voltage, 45
Tube current, 40
File date and time,24/Feb/2022 12:48
Unit cell,
h k l, 0 0 0
Scan axis,Gonio
Scan range,4.994599997,64.999991833
Scan step size,0.0262606
No. of points, 2285
Scan type,CONTINUOUS
Time per step,96.390
[Scan points]
Angle, TimePerStep, Intensity, ESD
5.007730280, 96.390, 4782.0, 69.1520
5.060251411, 96.390, 4792.0, 69.2243
5.112772541, 96.390, 4720.0, 68.7023
5.165293672, 96.390, 4778.0, 69.1231
5.217814803, 96.390, 4754.0, 68.9493
5.270335934, 96.390, 4675.0, 68.3740
5.322857064, 96.390, 4636.0, 68.0882
5.375378195, 96.390, 4602.0, 67.8380
5.427899326, 96.390, 4609.0, 67.8896
5.480420456, 96.390, 4450.0, 66.7083
5.532941587, 96.390, 4579.0, 67.6683
5.585462718, 96.390, 4523.0, 67.2533
5.637983849, 96.390, 4470.0, 66.8581
5.690504979, 96.390, 4526.0, 67.2756
5.743026110, 96.390, 4510.0, 67.1565
5.795547241, 96.390, 4345.0, 65.9166
5.848068371, 96.390, 4495.0, 67.0448
5.900589502, 96.390, 4328.0, 65.7875
5.953110633, 96.390, 4399.0, 66.3250
6.005631763, 96.390, 4368.0, 66.0908
6.058152894, 96.390, 4371.0, 66.1135
6.110674025, 96.390, 4208.0, 64.8691
6.163195156, 96.390, 4358.0, 66.0151
6.215716286, 96.390, 4222.0, 64.9769
6.268237417, 96.390, 4300.0, 65.5744
6.320758548, 96.390, 4324.0, 65.7571
6.373279678, 96.390, 4331.0, 65.8103
6.425800809, 96.390, 4314.0, 65.6810
6.478321940, 96.390, 4295.0, 65.5362
6.530843071, 96.390, 4230.0, 65.0385
6.583364201, 96.390, 4242.0, 65.1306
6.635885332, 96.390, 4174.0, 64.6065
6.688406463, 96.390, 4251.0, 65.1997
6.740927593, 96.390, 4123.0, 64.2106
6.793448724, 96.390, 4215.0, 64.9230
6.845969855, 96.390, 4139.0, 64.3351
6.898490986, 96.390, 4110.0, 64.1093
6.951012116, 96.390, 4169.0, 64.5678
7.003533247, 96.390, 4176.0, 64.6220
7.056054378, 96.390, 4013.0, 63.3482
7.108575508, 96.390, 4103.0, 64.0547
7.161096639, 96.390, 4143.0, 64.3661
7.213617770, 96.390, 4053.0, 63.6632
7.266138900, 96.390, 4093.0, 63.9766
7.318660031, 96.390, 3938.0, 62.7535
7.371181162, 96.390, 4090.0, 63.9531
7.423702293, 96.390, 3989.0, 63.1585
7.476223423, 96.390, 4059.0, 63.7103
7.528744554, 96.390, 3892.0, 62.3859
7.581265685, 96.390, 3891.0, 62.3779
7.633786815, 96.390, 3863.0, 62.1530
7.686307946, 96.390, 3922.0, 62.6259
7.738829077, 96.390, 4014.0, 63.3561
7.791350208, 96.390, 3924.0, 62.6418
7.843871338, 96.390, 3886.0, 62.3378
7.896392469, 96.390, 3896.0, 62.4179
7.948913600, 96.390, 3837.0, 61.9435
8.001434730, 96.390, 3828.0, 61.8708
8.053955861, 96.390, 3812.0, 61.7414
8.106476992, 96.390, 3896.0, 62.4179
8.158998123, 96.390, 3857.0, 62.1048
8.211519253, 96.390, 3881.0, 62.2977
8.264040384, 96.390, 3853.0, 62.0725
8.316561515, 96.390, 3823.0, 61.8304
8.369082645, 96.390, 3754.0, 61.2699
8.421603776, 96.390, 3736.0, 61.1228
8.474124907, 96.390, 3665.0, 60.5392
8.526646038, 96.390, 3689.0, 60.7371
8.579167168, 96.390, 3780.0, 61.4817
8.631688299, 96.390, 3729.0, 61.0655
8.684209430, 96.390, 3673.0, 60.6053
8.736730560, 96.390, 3671.0, 60.5888
8.789251691, 96.390, 3646.0, 60.3821
8.841772822, 96.390, 3633.0, 60.2744
8.894293952, 96.390, 3579.0, 59.8247
8.946815083, 96.390, 3682.0, 60.6795
8.999336214, 96.390, 3677.0, 60.6383
9.051857345, 96.390, 3621.0, 60.1747
9.104378475, 96.390, 3631.0, 60.2578
9.156899606, 96.390, 3556.0, 59.6322
9.209420737, 96.390, 3578.0, 59.8164
9.261941867, 96.390, 3534.0, 59.4475
9.314462998, 96.390, 3520.0, 59.3296
9.366984129, 96.390, 3565.0, 59.7076
9.419505260, 96.390, 3542.0, 59.5147
9.472026390, 96.390, 3431.0, 58.5747
9.524547521, 96.390, 3434.0, 58.6003
9.577068652, 96.390, 3451.0, 58.7452
9.629589782, 96.390, 3518.0, 59.3127
9.682110913, 96.390, 3344.0, 57.8273
9.734632044, 96.390, 3451.0, 58.7452
9.787153175, 96.390, 3431.0, 58.5747
9.839674305, 96.390, 3463.0, 58.8473
9.892195436, 96.390, 3420.0, 58.4808
9.944716567, 96.390, 3405.0, 58.3524
9.997237697, 96.390, 3344.0, 57.8273
10.049758828, 96.390, 3438.0, 58.6345
10.102279959, 96.390, 3324.0, 57.6541
10.154801090, 96.390, 3385.0, 58.1808
10.207322220, 96.390, 3396.0, 58.2752
10.259843351, 96.390, 3425.0, 58.5235
10.312364482, 96.390, 3354.0, 57.9137
10.364885612, 96.390, 3470.0, 58.9067
10.417406743, 96.390, 3363.0, 57.9914
10.469927874, 96.390, 3681.0, 60.6712
10.522449004, 96.390, 3451.0, 58.7452
10.574970135, 96.390, 3305.0, 57.4891
10.627491266, 96.390, 3285.0, 57.3149
10.680012397, 96.390, 3304.0, 57.4804
10.732533527, 96.390, 3247.0, 56.9825
10.785054658, 96.390, 3208.0, 56.6392
10.837575789, 96.390, 3176.0, 56.3560
10.890096919, 96.390, 3216.0, 56.7098
10.942618050, 96.390, 3220.0, 56.7450
10.995139181, 96.390, 3258.0, 57.0789
11.047660312, 96.390, 3206.0, 56.6216
11.100181442, 96.390, 3322.0, 57.6368
11.152702573, 96.390, 3230.0, 56.8331
11.205223704, 96.390, 3084.0, 55.5338
11.257744834, 96.390, 3189.0, 56.4712
11.310265965, 96.390, 3136.0, 56.0000
11.362787096, 96.390, 3031.0, 55.0545
11.415308227, 96.390, 3141.0, 56.0446
11.467829357, 96.390, 3068.0, 55.3895
11.520350488, 96.390, 3052.0, 55.2449
11.572871619, 96.390, 3081.0, 55.5068
11.625392749, 96.390, 2930.0, 54.1295
11.677913880, 96.390, 2986.0, 54.6443
11.730435011, 96.390, 2948.0, 54.2955
11.782956141, 96.390, 3149.0, 56.1160
11.835477272, 96.390, 2996.0, 54.7357
11.887998403, 96.390, 3081.0, 55.5068
11.940519534, 96.390, 3005.0, 54.8179
11.993040664, 96.390, 3014.0, 54.8999
12.045561795, 96.390, 2976.0, 54.5527
12.098082926, 96.390, 2917.0, 54.0093
12.150604056, 96.390, 2920.0, 54.0370
12.203125187, 96.390, 3036.0, 55.0999
12.255646318, 96.390, 2860.0, 53.4790
12.308167449, 96.390, 2929.0, 54.1202
12.360688579, 96.390, 2983.0, 54.6168
12.413209710, 96.390, 2883.0, 53.6936
12.465730841, 96.390, 2861.0, 53.4883
12.518251971, 96.390, 2804.0, 52.9528
12.570773102, 96.390, 2743.0, 52.3737
12.623294233, 96.390, 2862.0, 53.4977
12.675815364, 96.390, 2827.0, 53.1695
12.728336494, 96.390, 2823.0, 53.1319
12.780857625, 96.390, 2735.0, 52.2972
12.833378756, 96.390, 2699.0, 51.9519
12.885899886, 96.390, 2798.0, 52.8961
12.938421017, 96.390, 2803.0, 52.9434
12.990942148, 96.390, 2748.0, 52.4214
13.043463279, 96.390, 2795.0, 52.8678
13.095984409, 96.390, 2661.0, 51.5849
13.148505540, 96.390, 2687.0, 51.8363
13.201026671, 96.390, 2744.0, 52.3832
13.253547801, 96.390, 2659.0, 51.5655
13.306068932, 96.390, 2668.0, 51.6527
13.358590063, 96.390, 2605.0, 51.0392
13.411111193, 96.390, 2708.0, 52.0384
13.463632324, 96.390, 2659.0, 51.5655
13.516153455, 96.390, 2688.0, 51.8459
13.568674586, 96.390, 2588.0, 50.8724
13.621195716, 96.390, 2653.0, 51.5073
13.673716847, 96.390, 2713.0, 52.0865
13.726237978, 96.390, 2753.0, 52.4690
13.778759108, 96.390, 2839.0, 53.2823
13.831280239, 96.390, 3076.0, 55.4617
13.883801370, 96.390, 2783.0, 52.7541
13.936322501, 96.390, 2642.0, 51.4004
13.988843631, 96.390, 2780.0, 52.7257
14.041364762, 96.390, 2599.0, 50.9804
14.093885893, 96.390, 2588.0, 50.8724
14.146407023, 96.390, 2566.0, 50.6557
14.198928154, 96.390, 3050.0, 55.2268
14.251449285, 96.390, 4183.0, 64.6761
14.303970416, 96.390, 4952.0, 70.3704
14.356491546, 96.390, 3526.0, 59.3801
14.409012677, 96.390, 2586.0, 50.8527
14.461533808, 96.390, 2544.0, 50.4381
14.514054938, 96.390, 2617.0, 51.1566
14.566576069, 96.390, 2497.0, 49.9700
14.619097200, 96.390, 2540.0, 50.3984
14.671618331, 96.390, 2582.0, 50.8134
14.724139461, 96.390, 2505.0, 50.0500
14.776660592, 96.390, 2527.0, 50.2693
14.829181723, 96.390, 2506.0, 50.0600
14.881702853, 96.390, 2545.0, 50.4480
14.934223984, 96.390, 2518.0, 50.1797
14.986745115, 96.390, 2497.0, 49.9700
15.039266245, 96.390, 2487.0, 49.8698
15.091787376, 96.390, 2417.0, 49.1630
15.144308507, 96.390, 2458.0, 49.5782
15.196829638, 96.390, 2438.0, 49.3761
15.249350768, 96.390, 2445.0, 49.4469
15.301871899, 96.390, 2462.0, 49.6185
15.354393030, 96.390, 2330.0, 48.2701
15.406914160, 96.390, 2427.0, 49.2646
15.459435291, 96.390, 2330.0, 48.2701
15.511956422, 96.390, 2455.0, 49.5480
15.564477553, 96.390, 2363.0, 48.6107
15.616998683, 96.390, 2389.0, 48.8774
15.669519814, 96.390, 2401.0, 49.0000
15.722040945, 96.390, 2462.0, 49.6185
15.774562075, 96.390, 2363.0, 48.6107
15.827083206, 96.390, 2412.0, 49.1121
15.879604337, 96.390, 2334.0, 48.3115
15.932125468, 96.390, 2421.0, 49.2037
15.984646598, 96.390, 2448.0, 49.4773
16.037167729, 96.390, 2393.0, 48.9183
16.089688860, 96.390, 2357.0, 48.5489
16.142209990, 96.390, 2375.0, 48.7340
16.194731121, 96.390, 2462.0, 49.6185
16.247252252, 96.390, 2359.0, 48.5695
16.299773382, 96.390, 2342.0, 48.3942
16.352294513, 96.390, 2280.0, 47.7493
16.404815644, 96.390, 2404.0, 49.0306
16.457336775, 96.390, 2364.0, 48.6210
16.509857905, 96.390, 2456.0, 49.5580
16.562379036, 96.390, 2371.0, 48.6929
16.614900167, 96.390, 2456.0, 49.5580
16.667421297, 96.390, 2344.0, 48.4149
16.719942428, 96.390, 2351.0, 48.4871
16.772463559, 96.390, 2330.0, 48.2701
16.824984690, 96.390, 2355.0, 48.5283
16.877505820, 96.390, 2374.0, 48.7237
16.930026951, 96.390, 2390.0, 48.8876
16.982548082, 96.390, 2393.0, 48.9183
17.035069212, 96.390, 2342.0, 48.3942
17.087590343, 96.390, 2347.0, 48.4458
17.140111474, 96.390, 2363.0, 48.6107
17.192632605, 96.390, 2479.0, 49.7896
17.245153735, 96.390, 2448.0, 49.4773
17.297674866, 96.390, 2321.0, 48.1768
17.350195997, 96.390, 2347.0, 48.4458
17.402717127, 96.390, 2396.0, 48.9490
17.455238258, 96.390, 2446.0, 49.4571
17.507759389, 96.390, 2397.0, 48.9592
17.560280520, 96.390, 2331.0, 48.2804
17.612801650, 96.390, 2493.0, 49.9300
17.665322781, 96.390, 2328.0, 48.2494
17.717843912, 96.390, 2340.0, 48.3735
17.770365042, 96.390, 2300.0, 47.9583
17.822886173, 96.390, 2330.0, 48.2701
17.875407304, 96.390, 2437.0, 49.3660
17.927928434, 96.390, 2358.0, 48.5592
17.980449565, 96.390, 2359.0, 48.5695
18.032970696, 96.390, 2404.0, 49.0306
18.085491827, 96.390, 2345.0, 48.4252
18.138012957, 96.390, 2458.0, 49.5782
18.190534088, 96.390, 2527.0, 50.2693
18.243055219, 96.390, 2555.0, 50.5470
18.295576349, 96.390, 2666.0, 51.6333
18.348097480, 96.390, 2760.0, 52.5357
18.400618611, 96.390, 2577.0, 50.7642
18.453139742, 96.390, 2844.0, 53.3292
18.505660872, 96.390, 2767.0, 52.6023
18.558182003, 96.390, 2581.0, 50.8035
18.610703134, 96.390, 2518.0, 50.1797
18.663224264, 96.390, 2593.0, 50.9215
18.715745395, 96.390, 2605.0, 51.0392
18.768266526, 96.390, 2675.0, 51.7204
18.820787657, 96.390, 2614.0, 51.1273
18.873308787, 96.390, 2583.0, 50.8232
18.925829918, 96.390, 2510.0, 50.0999
18.978351049, 96.390, 2571.0, 50.7050
19.030872179, 96.390, 2621.0, 51.1957
19.083393310, 96.390, 2573.0, 50.7247
19.135914441, 96.390, 2492.0, 49.9199
19.188435572, 96.390, 2423.0, 49.2240
19.240956702, 96.390, 2471.0, 49.7092
19.293477833, 96.390, 2474.0, 49.7393
19.345998964, 96.390, 2503.0, 50.0300
19.398520094, 96.390, 2531.0, 50.3090
19.451041225, 96.390, 2602.0, 51.0098
19.503562356, 96.390, 2616.0, 51.1468
19.556083486, 96.390, 2489.0, 49.8899
19.608604617, 96.390, 2532.0, 50.3190
19.661125748, 96.390, 2543.0, 50.4282
19.713646879, 96.390, 2611.0, 51.0979
19.766168009, 96.390, 2688.0, 51.8459
19.818689140, 96.390, 2743.0, 52.3737
19.871210271, 96.390, 2612.0, 51.1077
19.923731401, 96.390, 2641.0, 51.3907
19.976252532, 96.390, 2590.0, 50.8920
20.028773663, 96.390, 2605.0, 51.0392
20.081294794, 96.390, 2638.0, 51.3615
20.133815924, 96.390, 2591.0, 50.9019
20.186337055, 96.390, 2647.0, 51.4490
20.238858186, 96.390, 2768.0, 52.6118
20.291379316, 96.390, 2808.0, 52.9906
20.343900447, 96.390, 2951.0, 54.3231
20.396421578, 96.390, 3005.0, 54.8179
20.448942709, 96.390, 3037.0, 55.1090
20.501463839, 96.390, 3035.0, 55.0908
20.553984970, 96.390, 2975.0, 54.5436
20.606506101, 96.390, 3141.0, 56.0446
20.659027231, 96.390, 3456.0, 58.7878
20.711548362, 96.390, 3233.0, 56.8595
20.764069493, 96.390, 3139.0, 56.0268
20.816590623, 96.390, 2855.0, 53.4322
20.869111754, 96.390, 2912.0, 53.9630
20.921632885, 96.390, 2887.0, 53.7308
20.974154016, 96.390, 2795.0, 52.8678
21.026675146, 96.390, 3041.0, 55.1453
21.079196277, 96.390, 2937.0, 54.1941
21.131717408, 96.390, 2749.0, 52.4309
21.184238538, 96.390, 2732.0, 52.2685
21.236759669, 96.390, 2768.0, 52.6118
21.289280800, 96.390, 2659.0, 51.5655
21.341801931, 96.390, 2683.0, 51.7977
21.394323061, 96.390, 2654.0, 51.5170
21.446844192, 96.390, 2690.0, 51.8652
21.499365323, 96.390, 2614.0, 51.1273
21.551886453, 96.390, 2811.0, 53.0189
21.604407584, 96.390, 2741.0, 52.3546
21.656928715, 96.390, 2688.0, 51.8459
21.709449846, 96.390, 2701.0, 51.9711
21.761970976, 96.390, 2675.0, 51.7204
21.814492107, 96.390, 2803.0, 52.9434
21.867013238, 96.390, 2640.0, 51.3809
21.919534368, 96.390, 2663.0, 51.6043
21.972055499, 96.390, 2805.0, 52.9623
22.024576630, 96.390, 2682.0, 51.7880
22.077097761, 96.390, 2603.0, 51.0196
22.129618891, 96.390, 2702.0, 51.9808
22.182140022, 96.390, 2764.0, 52.5738
22.234661153, 96.390, 2767.0, 52.6023
22.287182283, 96.390, 2681.0, 51.7784
22.339703414, 96.390, 2703.0, 51.9904
22.392224545, 96.390, 2693.0, 51.8941
22.444745675, 96.390, 2662.0, 51.5946
22.497266806, 96.390, 2728.0, 52.2303
22.549787937, 96.390, 2725.0, 52.2015
22.602309068, 96.390, 2718.0, 52.1344
22.654830198, 96.390, 2625.0, 51.2348
22.707351329, 96.390, 2680.0, 51.7687
22.759872460, 96.390, 2757.0, 52.5071
22.812393590, 96.390, 2668.0, 51.6527
22.864914721, 96.390, 2673.0, 51.7011
22.917435852, 96.390, 2714.0, 52.0961
22.969956983, 96.390, 2707.0, 52.0288
23.022478113, 96.390, 2645.0, 51.4296
23.074999244, 96.390, 2682.0, 51.7880
23.127520375, 96.390, 2617.0, 51.1566
23.180041505, 96.390, 2639.0, 51.3712
23.232562636, 96.390, 2666.0, 51.6333
23.285083767, 96.390, 2646.0, 51.4393
23.337604898, 96.390, 2730.0, 52.2494
23.390126028, 96.390, 2592.0, 50.9117
23.442647159, 96.390, 2675.0, 51.7204
23.495168290, 96.390, 2723.0, 52.1824
23.547689420, 96.390, 3988.0, 63.1506
23.600210551, 96.390, 3281.0, 57.2800
23.652731682, 96.390, 2739.0, 52.3355
23.705252813, 96.390, 2646.0, 51.4393
23.757773943, 96.390, 2695.0, 51.9134
23.810295074, 96.390, 2576.0, 50.7543
23.862816205, 96.390, 2627.0, 51.2543
23.915337335, 96.390, 2745.0, 52.3927
23.967858466, 96.390, 2677.0, 51.7397
24.020379597, 96.390, 2636.0, 51.3420
24.072900727, 96.390, 2530.0, 50.2991
24.125421858, 96.390, 2750.0, 52.4404
24.177942989, 96.390, 2666.0, 51.6333
24.230464120, 96.390, 2639.0, 51.3712
24.282985250, 96.390, 2637.0, 51.3517
24.335506381, 96.390, 2527.0, 50.2693
24.388027512, 96.390, 2540.0, 50.3984
24.440548642, 96.390, 2508.0, 50.0799
24.493069773, 96.390, 2508.0, 50.0799
24.545590904, 96.390, 2774.0, 52.6688
24.598112035, 96.390, 3487.0, 59.0508
24.650633165, 96.390, 2975.0, 54.5436
24.703154296, 96.390, 2443.0, 49.4267
24.755675427, 96.390, 2327.0, 48.2390
24.808196557, 96.390, 2432.0, 49.3153
24.860717688, 96.390, 2312.0, 48.0833
24.913238819, 96.390, 2371.0, 48.6929
24.965759950, 96.390, 2394.0, 48.9285
25.018281080, 96.390, 2361.0, 48.5901
25.070802211, 96.390, 2376.0, 48.7442
25.123323342, 96.390, 2405.0, 49.0408
25.175844472, 96.390, 2336.0, 48.3322
25.228365603, 96.390, 2399.0, 48.9796
25.280886734, 96.390, 2251.0, 47.4447
25.333407864, 96.390, 2367.0, 48.6518
25.385928995, 96.390, 2413.0, 49.1223
25.438450126, 96.390, 2394.0, 48.9285
25.490971257, 96.390, 2337.0, 48.3425
25.543492387, 96.390, 2337.0, 48.3425
25.596013518, 96.390, 2254.0, 47.4763
25.648534649, 96.390, 2286.0, 47.8121
25.701055779, 96.390, 2237.0, 47.2969
25.753576910, 96.390, 2229.0, 47.2123
25.806098041, 96.390, 2327.0, 48.2390
25.858619172, 96.390, 2197.0, 46.8722
25.911140302, 96.390, 2183.0, 46.7226
25.963661433, 96.390, 2231.0, 47.2335
26.016182564, 96.390, 2198.0, 46.8828
26.068703694, 96.390, 2211.0, 47.0213
26.121224825, 96.390, 2239.0, 47.3181
26.173745956, 96.390, 2214.0, 47.0532
26.226267087, 96.390, 2340.0, 48.3735
26.278788217, 96.390, 2135.0, 46.2061
26.331309348, 96.390, 2255.0, 47.4868
26.383830479, 96.390, 2145.0, 46.3141
26.436351609, 96.390, 2203.0, 46.9361
26.488872740, 96.390, 2243.0, 47.3603
26.541393871, 96.390, 2197.0, 46.8722
26.593915002, 96.390, 2202.0, 46.9255
26.646436132, 96.390, 2192.0, 46.8188
26.698957263, 96.390, 2212.0, 47.0319
26.751478394, 96.390, 2248.0, 47.4131
26.803999524, 96.390, 2129.0, 46.1411
26.856520655, 96.390, 2186.0, 46.7547
26.909041786, 96.390, 2287.0, 47.8226
26.961562916, 96.390, 2203.0, 46.9361
27.014084047, 96.390, 2243.0, 47.3603
27.066605178, 96.390, 2139.0, 46.2493
27.119126309, 96.390, 2149.0, 46.3573
27.171647439, 96.390, 2106.0, 45.8912
27.224168570, 96.390, 2178.0, 46.6690
27.276689701, 96.390, 2129.0, 46.1411
27.329210831, 96.390, 2323.0, 48.1975
27.381731962, 96.390, 2230.0, 47.2229
27.434253093, 96.390, 2148.0, 46.3465
27.486774224, 96.390, 2101.0, 45.8367
27.539295354, 96.390, 2101.0, 45.8367
27.591816485, 96.390, 2127.0, 46.1194
27.644337616, 96.390, 2184.0, 46.7333
27.696858746, 96.390, 2150.0, 46.3681
27.749379877, 96.390, 2088.0, 45.6946
27.801901008, 96.390, 2115.0, 45.9891
27.854422139, 96.390, 2169.0, 46.5725
27.906943269, 96.390, 2125.0, 46.0977
27.959464400, 96.390, 2008.0, 44.8107
28.011985531, 96.390, 2146.0, 46.3249
28.064506661, 96.390, 2035.0, 45.1110
28.117027792, 96.390, 2010.0, 44.8330
28.169548923, 96.390, 2042.0, 45.1885
28.222070054, 96.390, 2139.0, 46.2493
28.274591184, 96.390, 2189.0, 46.7868
28.327112315, 96.390, 2118.0, 46.0217
28.379633446, 96.390, 2144.0, 46.3033
28.432154576, 96.390, 2173.0, 46.6154
28.484675707, 96.390, 2042.0, 45.1885
28.537196838, 96.390, 2067.0, 45.4643
28.589717968, 96.390, 2044.0, 45.2106
28.642239099, 96.390, 2049.0, 45.2659
28.694760230, 96.390, 2031.0, 45.0666
28.747281361, 96.390, 2056.0, 45.3431
28.799802491, 96.390, 2014.0, 44.8776
28.852323622, 96.390, 2087.0, 45.6837
28.904844753, 96.390, 1987.0, 44.5758
28.957365883, 96.390, 1985.0, 44.5533
29.009887014, 96.390, 2023.0, 44.9778
29.062408145, 96.390, 1986.0, 44.5646
29.114929276, 96.390, 1940.0, 44.0454
29.167450406, 96.390, 2043.0, 45.1996
29.219971537, 96.390, 2094.0, 45.7602
29.272492668, 96.390, 2051.0, 45.2880
29.325013798, 96.390, 2109.0, 45.9239
29.377534929, 96.390, 2217.0, 47.0850
29.430056060, 96.390, 2160.0, 46.4758
29.482577191, 96.390, 2046.0, 45.2327
29.535098321, 96.390, 1945.0, 44.1022
29.587619452, 96.390, 1959.0, 44.2606
29.640140583, 96.390, 1910.0, 43.7035
29.692661713, 96.390, 1973.0, 44.4185
29.745182844, 96.390, 1931.0, 43.9431
29.797703975, 96.390, 1855.0, 43.0697
29.850225105, 96.390, 1885.0, 43.4166
29.902746236, 96.390, 1978.0, 44.4747
29.955267367, 96.390, 2057.0, 45.3542
30.007788498, 96.390, 1851.0, 43.0232
30.060309628, 96.390, 1938.0, 44.0227
30.112830759, 96.390, 2035.0, 45.1110
30.165351890, 96.390, 1972.0, 44.4072
30.217873020, 96.390, 1937.0, 44.0114
30.270394151, 96.390, 1861.0, 43.1393
30.322915282, 96.390, 1934.0, 43.9773
30.375436413, 96.390, 1961.0, 44.2832
30.427957543, 96.390, 1921.0, 43.8292
30.480478674, 96.390, 1974.0, 44.4297
30.532999805, 96.390, 2024.0, 44.9889
30.585520935, 96.390, 1961.0, 44.2832
30.638042066, 96.390, 2011.0, 44.8442
30.690563197, 96.390, 2019.0, 44.9333
30.743084328, 96.390, 2360.0, 48.5798
30.795605458, 96.390, 2146.0, 46.3249
30.848126589, 96.390, 2113.0, 45.9674
30.900647720, 96.390, 1982.0, 44.5197
30.953168850, 96.390, 1958.0, 44.2493
31.005689981, 96.390, 1896.0, 43.5431
31.058211112, 96.390, 2021.0, 44.9555
31.110732243, 96.390, 2006.0, 44.7884
31.163253373, 96.390, 1885.0, 43.4166
31.215774504, 96.390, 1964.0, 44.3170
31.268295635, 96.390, 1879.0, 43.3474
31.320816765, 96.390, 1913.0, 43.7379
31.373337896, 96.390, 1962.0, 44.2945
31.425859027, 96.390, 1943.0, 44.0795
31.478380157, 96.390, 1931.0, 43.9431
31.530901288, 96.390, 1936.0, 44.0000
31.583422419, 96.390, 1897.0, 43.5546
31.635943550, 96.390, 1979.0, 44.4860
31.688464680, 96.390, 2163.0, 46.5081
31.740985811, 96.390, 2603.0, 51.0196
31.793506942, 96.390, 2335.0, 48.3218
31.846028072, 96.390, 2303.0, 47.9896
31.898549203, 96.390, 1952.0, 44.1814
31.951070334, 96.390, 1909.0, 43.6921
32.003591465, 96.390, 1942.0, 44.0681
32.056112595, 96.390, 1870.0, 43.2435
32.108633726, 96.390, 1892.0, 43.4971
32.161154857, 96.390, 1872.0, 43.2666
32.213675987, 96.390, 1955.0, 44.2154
32.266197118, 96.390, 1987.0, 44.5758
32.318718249, 96.390, 2057.0, 45.3542
32.371239380, 96.390, 2060.0, 45.3872
32.423760510, 96.390, 1974.0, 44.4297
32.476281641, 96.390, 1962.0, 44.2945
32.528802772, 96.390, 1969.0, 44.3734
32.581323902, 96.390, 1875.0, 43.3013
32.633845033, 96.390, 1844.0, 42.9418
32.686366164, 96.390, 1903.0, 43.6234
32.738887295, 96.390, 1874.0, 43.2897
32.791408425, 96.390, 1908.0, 43.6807
32.843929556, 96.390, 1754.0, 41.8808
32.896450687, 96.390, 1928.0, 43.9090
32.948971817, 96.390, 1900.0, 43.5890
33.001492948, 96.390, 1945.0, 44.1022
33.054014079, 96.390, 1955.0, 44.2154
33.106535209, 96.390, 2069.0, 45.4863
33.159056340, 96.390, 1916.0, 43.7721
33.211577471, 96.390, 1895.0, 43.5316
33.264098602, 96.390, 1903.0, 43.6234
33.316619732, 96.390, 2038.0, 45.1442
33.369140863, 96.390, 2040.0, 45.1664
33.421661994, 96.390, 2179.0, 46.6798
33.474183124, 96.390, 2183.0, 46.7226
33.526704255, 96.390, 2202.0, 46.9255
33.579225386, 96.390, 2192.0, 46.8188
33.631746517, 96.390, 2158.0, 46.4543
33.684267647, 96.390, 2013.0, 44.8665
33.736788778, 96.390, 2110.0, 45.9347
33.789309909, 96.390, 2015.0, 44.8888
33.841831039, 96.390, 2142.0, 46.2817
33.894352170, 96.390, 2290.0, 47.8539
33.946873301, 96.390, 2289.0, 47.8435
33.999394432, 96.390, 2395.0, 48.9387
34.051915562, 96.390, 2436.0, 49.3559
34.104436693, 96.390, 2432.0, 49.3153
34.156957824, 96.390, 2585.0, 50.8429
34.209478954, 96.390, 2530.0, 50.2991
34.262000085, 96.390, 2445.0, 49.4469
34.314521216, 96.390, 2328.0, 48.2494
34.367042346, 96.390, 2334.0, 48.3115
34.419563477, 96.390, 2242.0, 47.3498
34.472084608, 96.390, 2136.0, 46.2169
34.524605739, 96.390, 2066.0, 45.4533
34.577126869, 96.390, 2165.0, 46.5296
34.629648000, 96.390, 2086.0, 45.6727
34.682169131, 96.390, 2202.0, 46.9255
34.734690261, 96.390, 2133.0, 46.1844
34.787211392, 96.390, 2110.0, 45.9347
34.839732523, 96.390, 2040.0, 45.1664
34.892253654, 96.390, 2052.0, 45.2990
34.944774784, 96.390, 1994.0, 44.6542
34.997295915, 96.390, 2070.0, 45.4973
35.049817046, 96.390, 2158.0, 46.4543
35.102338176, 96.390, 2022.0, 44.9667
35.154859307, 96.390, 2050.0, 45.2769
35.207380438, 96.390, 2100.0, 45.8258
35.259901569, 96.390, 2257.0, 47.5079
35.312422699, 96.390, 2034.0, 45.0999
35.364943830, 96.390, 2036.0, 45.1221
35.417464961, 96.390, 1953.0, 44.1928
35.469986091, 96.390, 2022.0, 44.9667
35.522507222, 96.390, 2004.0, 44.7661
35.575028353, 96.390, 1984.0, 44.5421
35.627549484, 96.390, 1928.0, 43.9090
35.680070614, 96.390, 1983.0, 44.5309
35.732591745, 96.390, 1979.0, 44.4860
35.785112876, 96.390, 1962.0, 44.2945
35.837634006, 96.390, 1870.0, 43.2435
35.890155137, 96.390, 1899.0, 43.5775
35.942676268, 96.390, 1932.0, 43.9545
35.995197398, 96.390, 1946.0, 44.1135
36.047718529, 96.390, 1828.0, 42.7551
36.100239660, 96.390, 1927.0, 43.8976
36.152760791, 96.390, 1948.0, 44.1362
36.205281921, 96.390, 1936.0, 44.0000
36.257803052, 96.390, 1930.0, 43.9318
36.310324183, 96.390, 1890.0, 43.4741
36.362845313, 96.390, 1903.0, 43.6234
36.415366444, 96.390, 1955.0, 44.2154
36.467887575, 96.390, 1946.0, 44.1135
36.520408706, 96.390, 1818.0, 42.6380
36.572929836, 96.390, 1858.0, 43.1045
36.625450967, 96.390, 1918.0, 43.7950
36.677972098, 96.390, 1998.0, 44.6990
36.730493228, 96.390, 1924.0, 43.8634
36.783014359, 96.390, 1838.0, 42.8719
36.835535490, 96.390, 1810.0, 42.5441
36.888056621, 96.390, 1881.0, 43.3705
36.940577751, 96.390, 1810.0, 42.5441
36.993098882, 96.390, 1838.0, 42.8719
37.045620013, 96.390, 1794.0, 42.3556
37.098141143, 96.390, 1826.0, 42.7317
37.150662274, 96.390, 1785.0, 42.2493
37.203183405, 96.390, 1824.0, 42.7083
37.255704535, 96.390, 1688.0, 41.0853
37.308225666, 96.390, 1739.0, 41.7013
37.360746797, 96.390, 1792.0, 42.3320
37.413267928, 96.390, 1850.0, 43.0116
37.465789058, 96.390, 1774.0, 42.1189
37.518310189, 96.390, 1797.0, 42.3910
37.570831320, 96.390, 1797.0, 42.3910
37.623352450, 96.390, 1826.0, 42.7317
37.675873581, 96.390, 1800.0, 42.4264
37.728394712, 96.390, 1876.0, 43.3128
37.780915843, 96.390, 1789.0, 42.2966
37.833436973, 96.390, 1853.0, 43.0465
37.885958104, 96.390, 2015.0, 44.8888
37.938479235, 96.390, 2035.0, 45.1110
37.991000365, 96.390, 1879.0, 43.3474
38.043521496, 96.390, 1849.0, 43.0000
38.096042627, 96.390, 1735.0, 41.6533
38.148563758, 96.390, 1783.0, 42.2256
38.201084888, 96.390, 1824.0, 42.7083
38.253606019, 96.390, 1861.0, 43.1393
38.306127150, 96.390, 1813.0, 42.5793
38.358648280, 96.390, 1773.0, 42.1070
38.411169411, 96.390, 1694.0, 41.1582
38.463690542, 96.390, 1753.0, 41.8688
38.516211673, 96.390, 1668.0, 40.8412
38.568732803, 96.390, 1669.0, 40.8534
38.621253934, 96.390, 1683.0, 41.0244
38.673775065, 96.390, 1671.0, 40.8779
38.726296195, 96.390, 1625.0, 40.3113
38.778817326, 96.390, 1638.0, 40.4722
38.831338457, 96.390, 1605.0, 40.0625
38.883859587, 96.390, 1686.0, 41.0609
38.936380718, 96.390, 1698.0, 41.2068
38.988901849, 96.390, 1684.0, 41.0366
39.041422980, 96.390, 1675.0, 40.9268
39.093944110, 96.390, 1594.0, 39.9249
39.146465241, 96.390, 1673.0, 40.9023
39.198986372, 96.390, 1699.0, 41.2189
39.251507502, 96.390, 1685.0, 41.0488
39.304028633, 96.390, 1626.0, 40.3237
39.356549764, 96.390, 1647.0, 40.5832
39.409070895, 96.390, 1603.0, 40.0375
39.461592025, 96.390, 1578.0, 39.7240
39.514113156, 96.390, 1574.0, 39.6737
39.566634287, 96.390, 1631.0, 40.3856
39.619155417, 96.390, 1560.0, 39.4968
39.671676548, 96.390, 1564.0, 39.5474
39.724197679, 96.390, 1617.0, 40.2119
39.776718810, 96.390, 1626.0, 40.3237
39.829239940, 96.390, 1636.0, 40.4475
39.881761071, 96.390, 1590.0, 39.8748
39.934282202, 96.390, 1530.0, 39.1152
39.986803332, 96.390, 1571.0, 39.6358
40.039324463, 96.390, 1513.0, 38.8973
40.091845594, 96.390, 1568.0, 39.5980
40.144366725, 96.390, 1513.0, 38.8973
40.196887855, 96.390, 1631.0, 40.3856
40.249408986, 96.390, 1587.0, 39.8372
40.301930117, 96.390, 1540.0, 39.2428
40.354451247, 96.390, 1506.0, 38.8072
40.406972378, 96.390, 1495.0, 38.6652
40.459493509, 96.390, 1542.0, 39.2683
40.512014639, 96.390, 1589.0, 39.8623
40.564535770, 96.390, 1525.0, 39.0512
40.617056901, 96.390, 1541.0, 39.2556
40.669578032, 96.390, 1576.0, 39.6989
40.722099162, 96.390, 1575.0, 39.6863
40.774620293, 96.390, 1520.0, 38.9872
40.827141424, 96.390, 1496.0, 38.6782
40.879662554, 96.390, 1422.0, 37.7094
40.932183685, 96.390, 1470.0, 38.3406
40.984704816, 96.390, 1460.0, 38.2099
41.037225947, 96.390, 1433.0, 37.8550
41.089747077, 96.390, 1531.0, 39.1280
41.142268208, 96.390, 1433.0, 37.8550
41.194789339, 96.390, 1402.0, 37.4433
41.247310469, 96.390, 1381.0, 37.1618
41.299831600, 96.390, 1467.0, 38.3014
41.352352731, 96.390, 1529.0, 39.1024
41.404873862, 96.390, 1471.0, 38.3536
41.457394992, 96.390, 1405.0, 37.4833
41.509916123, 96.390, 1423.0, 37.7227
41.562437254, 96.390, 1422.0, 37.7094
41.614958384, 96.390, 1386.0, 37.2290
41.667479515, 96.390, 1429.0, 37.8021
41.720000646, 96.390, 1407.0, 37.5100
41.772521776, 96.390, 1445.0, 38.0132
41.825042907, 96.390, 1382.0, 37.1753
41.877564038, 96.390, 1444.0, 38.0000
41.930085169, 96.390, 1440.0, 37.9473
41.982606299, 96.390, 1352.0, 36.7696
42.035127430, 96.390, 1382.0, 37.1753
42.087648561, 96.390, 1381.0, 37.1618
42.140169691, 96.390, 1408.0, 37.5233
42.192690822, 96.390, 1535.0, 39.1791
42.245211953, 96.390, 1432.0, 37.8418
42.297733084, 96.390, 1414.0, 37.6032
42.350254214, 96.390, 1381.0, 37.1618
42.402775345, 96.390, 1332.0, 36.4966
42.455296476, 96.390, 1305.0, 36.1248
42.507817606, 96.390, 1370.0, 37.0135
42.560338737, 96.390, 1371.0, 37.0270
42.612859868, 96.390, 1375.0, 37.0810
42.665380999, 96.390, 1320.0, 36.3318
42.717902129, 96.390, 1336.0, 36.5513
42.770423260, 96.390, 1355.0, 36.8103
42.822944391, 96.390, 1346.0, 36.6879
42.875465521, 96.390, 1322.0, 36.3593
42.927986652, 96.390, 1396.0, 37.3631
42.980507783, 96.390, 1315.0, 36.2629
43.033028914, 96.390, 1344.0, 36.6606
43.085550044, 96.390, 1348.0, 36.7151
43.138071175, 96.390, 1318.0, 36.3043
43.190592306, 96.390, 1262.0, 35.5246
43.243113436, 96.390, 1325.0, 36.4005
43.295634567, 96.390, 1337.0, 36.5650
43.348155698, 96.390, 1302.0, 36.0832
43.400676828, 96.390, 1253.0, 35.3977
43.453197959, 96.390, 1330.0, 36.4692
43.505719090, 96.390, 1386.0, 37.2290
43.558240221, 96.390, 1379.0, 37.1349
43.610761351, 96.390, 1298.0, 36.0278
43.663282482, 96.390, 1277.0, 35.7351
43.715803613, 96.390, 1368.0, 36.9865
43.768324743, 96.390, 1417.0, 37.6431
43.820845874, 96.390, 1384.0, 37.2022
43.873367005, 96.390, 1372.0, 37.0405
43.925888136, 96.390, 1356.0, 36.8239
43.978409266, 96.390, 1360.0, 36.8782
44.030930397, 96.390, 1385.0, 37.2156
44.083451528, 96.390, 1350.0, 36.7423
44.135972658, 96.390, 1276.0, 35.7211
44.188493789, 96.390, 1376.0, 37.0945
44.241014920, 96.390, 1372.0, 37.0405
44.293536051, 96.390, 1517.0, 38.9487
44.346057181, 96.390, 1444.0, 38.0000
44.398578312, 96.390, 1363.0, 36.9188
44.451099443, 96.390, 1411.0, 37.5633
44.503620573, 96.390, 1360.0, 36.8782
44.556141704, 96.390, 1342.0, 36.6333
44.608662835, 96.390, 1337.0, 36.5650
44.661183966, 96.390, 1374.0, 37.0675
44.713705096, 96.390, 1315.0, 36.2629
44.766226227, 96.390, 1371.0, 37.0270
44.818747358, 96.390, 1386.0, 37.2290
44.871268488, 96.390, 1276.0, 35.7211
44.923789619, 96.390, 1333.0, 36.5103
44.976310750, 96.390, 1412.0, 37.5766
45.028831880, 96.390, 1372.0, 37.0405
45.081353011, 96.390, 1381.0, 37.1618
45.133874142, 96.390, 1332.0, 36.4966
45.186395273, 96.390, 1377.0, 37.1080
45.238916403, 96.390, 1377.0, 37.1080
45.291437534, 96.390, 1419.0, 37.6696
45.343958665, 96.390, 1347.0, 36.7015
45.396479795, 96.390, 1421.0, 37.6962
45.449000926, 96.390, 1287.0, 35.8748
45.501522057, 96.390, 1288.0, 35.8887
45.554043188, 96.390, 1370.0, 37.0135
45.606564318, 96.390, 1363.0, 36.9188
45.659085449, 96.390, 1408.0, 37.5233
45.711606580, 96.390, 1323.0, 36.3731
45.764127710, 96.390, 1334.0, 36.5240
45.816648841, 96.390, 1307.0, 36.1525
45.869169972, 96.390, 1248.0, 35.3270
45.921691103, 96.390, 1254.0, 35.4119
45.974212233, 96.390, 1236.0, 35.1568
46.026733364, 96.390, 1360.0, 36.8782
46.079254495, 96.390, 1282.0, 35.8050
46.131775625, 96.390, 1367.0, 36.9730
46.184296756, 96.390, 1334.0, 36.5240
46.236817887, 96.390, 1322.0, 36.3593
46.289339017, 96.390, 1452.0, 38.1051
46.341860148, 96.390, 1380.0, 37.1484
46.394381279, 96.390, 1442.0, 37.9737
46.446902410, 96.390, 1458.0, 38.1838
46.499423540, 96.390, 1416.0, 37.6298
46.551944671, 96.390, 1331.0, 36.4829
46.604465802, 96.390, 1379.0, 37.1349
46.656986932, 96.390, 1346.0, 36.6879
46.709508063, 96.390, 1321.0, 36.3456
46.762029194, 96.390, 1415.0, 37.6165
46.814550325, 96.390, 1271.0, 35.6511
46.867071455, 96.390, 1294.0, 35.9722
46.919592586, 96.390, 1285.0, 35.8469
46.972113717, 96.390, 1327.0, 36.4280
47.024634847, 96.390, 1323.0, 36.3731
47.077155978, 96.390, 1255.0, 35.4260
47.129677109, 96.390, 1331.0, 36.4829
47.182198240, 96.390, 1259.0, 35.4824
47.234719370, 96.390, 1282.0, 35.8050
47.287240501, 96.390, 1316.0, 36.2767
47.339761632, 96.390, 1279.0, 35.7631
47.392282762, 96.390, 1293.0, 35.9583
47.444803893, 96.390, 1280.0, 35.7771
47.497325024, 96.390, 1301.0, 36.0694
47.549846155, 96.390, 1266.0, 35.5809
47.602367285, 96.390, 1281.0, 35.7911
47.654888416, 96.390, 1291.0, 35.9305
47.707409547, 96.390, 1283.0, 35.8190
47.759930677, 96.390, 1324.0, 36.3868
47.812451808, 96.390, 1300.0, 36.0555
47.864972939, 96.390, 1346.0, 36.6879
47.917494069, 96.390, 1341.0, 36.6197
47.970015200, 96.390, 1319.0, 36.3180
48.022536331, 96.390, 1253.0, 35.3977
48.075057462, 96.390, 1300.0, 36.0555
48.127578592, 96.390, 1293.0, 35.9583
48.180099723, 96.390, 1384.0, 37.2022
48.232620854, 96.390, 1354.0, 36.7967
48.285141984, 96.390, 1376.0, 37.0945
48.337663115, 96.390, 1282.0, 35.8050
48.390184246, 96.390, 1335.0, 36.5377
48.442705377, 96.390, 1258.0, 35.4683
48.495226507, 96.390, 1306.0, 36.1386
48.547747638, 96.390, 1382.0, 37.1753
48.600268769, 96.390, 1285.0, 35.8469
48.652789899, 96.390, 1325.0, 36.4005
48.705311030, 96.390, 1453.0, 38.1182
48.757832161, 96.390, 1364.0, 36.9324
48.810353292, 96.390, 1279.0, 35.7631
48.862874422, 96.390, 1336.0, 36.5513
48.915395553, 96.390, 1320.0, 36.3318
48.967916684, 96.390, 1332.0, 36.4966
49.020437814, 96.390, 1309.0, 36.1801
49.072958945, 96.390, 1295.0, 35.9861
49.125480076, 96.390, 1317.0, 36.2905
49.178001207, 96.390, 1280.0, 35.7771
49.230522337, 96.390, 1306.0, 36.1386
49.283043468, 96.390, 1274.0, 35.6931
49.335564599, 96.390, 1284.0, 35.8329
49.388085729, 96.390, 1340.0, 36.6060
49.440606860, 96.390, 1266.0, 35.5809
49.493127991, 96.390, 1290.0, 35.9166
49.545649121, 96.390, 1267.0, 35.5949
49.598170252, 96.390, 1158.0, 34.0294
49.650691383, 96.390, 1245.0, 35.2846
49.703212514, 96.390, 1262.0, 35.5246
49.755733644, 96.390, 1227.0, 35.0286
49.808254775, 96.390, 1286.0, 35.8608
49.860775906, 96.390, 1190.0, 34.4964
49.913297036, 96.390, 1245.0, 35.2846
49.965818167, 96.390, 1160.0, 34.0588
50.018339298, 96.390, 1142.0, 33.7935
50.070860429, 96.390, 1148.0, 33.8821
50.123381559, 96.390, 1207.0, 34.7419
50.175902690, 96.390, 1140.0, 33.7639
50.228423821, 96.390, 1119.0, 33.4515
50.280944951, 96.390, 1164.0, 34.1174
50.333466082, 96.390, 1127.0, 33.5708
50.385987213, 96.390, 1181.0, 34.3657
50.438508344, 96.390, 1145.0, 33.8378
50.491029474, 96.390, 1171.0, 34.2199
50.543550605, 96.390, 1143.0, 33.8083
50.596071736, 96.390, 1119.0, 33.4515
50.648592866, 96.390, 1174.0, 34.2637
50.701113997, 96.390, 1133.0, 33.6601
50.753635128, 96.390, 1131.0, 33.6303
50.806156258, 96.390, 1134.0, 33.6749
50.858677389, 96.390, 1081.0, 32.8786
50.911198520, 96.390, 1082.0, 32.8938
50.963719651, 96.390, 1138.0, 33.7343
51.016240781, 96.390, 1111.0, 33.3317
51.068761912, 96.390, 1139.0, 33.7491
51.121283043, 96.390, 1074.0, 32.7719
51.173804173, 96.390, 1118.0, 33.4365
51.226325304, 96.390, 1124.0, 33.5261
51.278846435, 96.390, 1026.0, 32.0312
51.331367566, 96.390, 1121.0, 33.4813
51.383888696, 96.390, 1084.0, 32.9242
51.436409827, 96.390, 1104.0, 33.2265
51.488930958, 96.390, 1082.0, 32.8938
51.541452088, 96.390, 1085.0, 32.9393
51.593973219, 96.390, 1055.0, 32.4808
51.646494350, 96.390, 1118.0, 33.4365
51.699015481, 96.390, 1050.0, 32.4037
51.751536611, 96.390, 1086.0, 32.9545
51.804057742, 96.390, 993.0, 31.5119
51.856578873, 96.390, 1095.0, 33.0908
51.909100003, 96.390, 1065.0, 32.6343
51.961621134, 96.390, 1053.0, 32.4500
52.014142265, 96.390, 1095.0, 33.0908
52.066663396, 96.390, 1026.0, 32.0312
52.119184526, 96.390, 1050.0, 32.4037
52.171705657, 96.390, 1106.0, 33.2566
52.224226788, 96.390, 1138.0, 33.7343
52.276747918, 96.390, 1038.0, 32.2180
52.329269049, 96.390, 1019.0, 31.9218
52.381790180, 96.390, 1229.0, 35.0571
52.434311310, 96.390, 1129.0, 33.6006
52.486832441, 96.390, 1095.0, 33.0908
52.539353572, 96.390, 1102.0, 33.1964
52.591874703, 96.390, 1097.0, 33.1210
52.644395833, 96.390, 1031.0, 32.1092
52.696916964, 96.390, 1042.0, 32.2800
52.749438095, 96.390, 1015.0, 31.8591
52.801959225, 96.390, 1002.0, 31.6544
52.854480356, 96.390, 1018.0, 31.9061
52.907001487, 96.390, 1043.0, 32.2955
52.959522618, 96.390, 1068.0, 32.6803
53.012043748, 96.390, 1070.0, 32.7109
53.064564879, 96.390, 1100.0, 33.1662
53.117086010, 96.390, 1122.0, 33.4963
53.169607140, 96.390, 1123.0, 33.5112
53.222128271, 96.390, 1206.0, 34.7275
53.274649402, 96.390, 1089.0, 33.0000
53.327170533, 96.390, 1079.0, 32.8481
53.379691663, 96.390, 1039.0, 32.2335
53.432212794, 96.390, 1041.0, 32.2645
53.484733925, 96.390, 959.0, 30.9677
53.537255055, 96.390, 1014.0, 31.8434
53.589776186, 96.390, 966.0, 31.0805
53.642297317, 96.390, 982.0, 31.3369
53.694818448, 96.390, 1022.0, 31.9687
53.747339578, 96.390, 1018.0, 31.9061
53.799860709, 96.390, 1034.0, 32.1559
53.852381840, 96.390, 976.0, 31.2410
53.904902970, 96.390, 1046.0, 32.3419
53.957424101, 96.390, 1027.0, 32.0468
54.009945232, 96.390, 993.0, 31.5119
54.062466362, 96.390, 1070.0, 32.7109
54.114987493, 96.390, 1084.0, 32.9242
54.167508624, 96.390, 1022.0, 31.9687
54.220029755, 96.390, 940.0, 30.6594
54.272550885, 96.390, 1017.0, 31.8904
54.325072016, 96.390, 970.0, 31.1448
54.377593147, 96.390, 1005.0, 31.7017
54.430114277, 96.390, 958.0, 30.9516
54.482635408, 96.390, 1028.0, 32.0624
54.535156539, 96.390, 1024.0, 32.0000
54.587677670, 96.390, 1049.0, 32.3883
54.640198800, 96.390, 969.0, 31.1288
54.692719931, 96.390, 974.0, 31.2090
54.745241062, 96.390, 988.0, 31.4325
54.797762192, 96.390, 938.0, 30.6268
54.850283323, 96.390, 1056.0, 32.4962
54.902804454, 96.390, 970.0, 31.1448
54.955325585, 96.390, 1004.0, 31.6860
55.007846715, 96.390, 958.0, 30.9516
55.060367846, 96.390, 1021.0, 31.9531
55.112888977, 96.390, 1104.0, 33.2265
55.165410107, 96.390, 977.0, 31.2570
55.217931238, 96.390, 946.0, 30.7571
55.270452369, 96.390, 1116.0, 33.4066
55.322973499, 96.390, 959.0, 30.9677
55.375494630, 96.390, 974.0, 31.2090
55.428015761, 96.390, 1011.0, 31.7962
55.480536892, 96.390, 968.0, 31.1127
55.533058022, 96.390, 969.0, 31.1288
55.585579153, 96.390, 999.0, 31.6070
55.638100284, 96.390, 974.0, 31.2090
55.690621414, 96.390, 1011.0, 31.7962
55.743142545, 96.390, 955.0, 30.9031
55.795663676, 96.390, 994.0, 31.5278
55.848184807, 96.390, 958.0, 30.9516
55.900705937, 96.390, 974.0, 31.2090
55.953227068, 96.390, 961.0, 31.0000
56.005748199, 96.390, 924.0, 30.3974
56.058269329, 96.390, 987.0, 31.4166
56.110790460, 96.390, 977.0, 31.2570
56.163311591, 96.390, 904.0, 30.0666
56.215832722, 96.390, 946.0, 30.7571
56.268353852, 96.390, 932.0, 30.5287
56.320874983, 96.390, 963.0, 31.0322
56.373396114, 96.390, 947.0, 30.7734
56.425917244, 96.390, 1008.0, 31.7490
56.478438375, 96.390, 929.0, 30.4795
56.530959506, 96.390, 912.0, 30.1993
56.583480637, 96.390, 905.0, 30.0832
56.636001767, 96.390, 957.0, 30.9354
56.688522898, 96.390, 959.0, 30.9677
56.741044029, 96.390, 950.0, 30.8221
56.793565159, 96.390, 1016.0, 31.8748
56.846086290, 96.390, 978.0, 31.2730
56.898607421, 96.390, 959.0, 30.9677
56.951128551, 96.390, 971.0, 31.1609
57.003649682, 96.390, 973.0, 31.1929
57.056170813, 96.390, 911.0, 30.1828
57.108691944, 96.390, 963.0, 31.0322
57.161213074, 96.390, 993.0, 31.5119
57.213734205, 96.390, 1015.0, 31.8591
57.266255336, 96.390, 1049.0, 32.3883
57.318776466, 96.390, 984.0, 31.3688
57.371297597, 96.390, 947.0, 30.7734
57.423818728, 96.390, 979.0, 31.2890
57.476339859, 96.390, 1061.0, 32.5730
57.528860989, 96.390, 992.0, 31.4960
57.581382120, 96.390, 968.0, 31.1127
57.633903251, 96.390, 1014.0, 31.8434
57.686424381, 96.390, 1000.0, 31.6228
57.738945512, 96.390, 1059.0, 32.5423
57.791466643, 96.390, 1035.0, 32.1714
57.843987774, 96.390, 998.0, 31.5911
57.896508904, 96.390, 1046.0, 32.3419
57.949030035, 96.390, 961.0, 31.0000
58.001551166, 96.390, 956.0, 30.9192
58.054072296, 96.390, 983.0, 31.3528
58.106593427, 96.390, 913.0, 30.2159
58.159114558, 96.390, 937.0, 30.6105
58.211635689, 96.390, 909.0, 30.1496
58.264156819, 96.390, 949.0, 30.8058
58.316677950, 96.390, 922.0, 30.3645
58.369199081, 96.390, 924.0, 30.3974
58.421720211, 96.390, 973.0, 31.1929
58.474241342, 96.390, 916.0, 30.2655
58.526762473, 96.390, 887.0, 29.7825
58.579283603, 96.390, 963.0, 31.0322
58.631804734, 96.390, 930.0, 30.4959
58.684325865, 96.390, 961.0, 31.0000
58.736846996, 96.390, 935.0, 30.5778
58.789368126, 96.390, 910.0, 30.1662
58.841889257, 96.390, 987.0, 31.4166
58.894410388, 96.390, 953.0, 30.8707
58.946931518, 96.390, 944.0, 30.7246
58.999452649, 96.390, 929.0, 30.4795
59.051973780, 96.390, 967.0, 31.0966
59.104494911, 96.390, 947.0, 30.7734
59.157016041, 96.390, 941.0, 30.6757
59.209537172, 96.390, 967.0, 31.0966
59.262058303, 96.390, 930.0, 30.4959
59.314579433, 96.390, 1017.0, 31.8904
59.367100564, 96.390, 978.0, 31.2730
59.419621695, 96.390, 935.0, 30.5778
59.472142826, 96.390, 981.0, 31.3209
59.524663956, 96.390, 946.0, 30.7571
59.577185087, 96.390, 917.0, 30.2820
59.629706218, 96.390, 1011.0, 31.7962
59.682227348, 96.390, 1022.0, 31.9687
59.734748479, 96.390, 1033.0, 32.1403
59.787269610, 96.390, 967.0, 31.0966
59.839790740, 96.390, 989.0, 31.4484
59.892311871, 96.390, 1023.0, 31.9844
59.944833002, 96.390, 984.0, 31.3688
59.997354133, 96.390, 970.0, 31.1448
60.049875263, 96.390, 1052.0, 32.4345
60.102396394, 96.390, 1025.0, 32.0156
60.154917525, 96.390, 986.0, 31.4006
60.207438655, 96.390, 1011.0, 31.7962
60.259959786, 96.390, 1033.0, 32.1403
60.312480917, 96.390, 1038.0, 32.2180
60.365002048, 96.390, 993.0, 31.5119
60.417523178, 96.390, 1034.0, 32.1559
60.470044309, 96.390, 1111.0, 33.3317
60.522565440, 96.390, 1026.0, 32.0312
60.575086570, 96.390, 1087.0, 32.9697
60.627607701, 96.390, 1109.0, 33.3017
60.680128832, 96.390, 1096.0, 33.1059
60.732649963, 96.390, 1116.0, 33.4066
60.785171093, 96.390, 1136.0, 33.7046
60.837692224, 96.390, 1152.0, 33.9411
60.890213355, 96.390, 1115.0, 33.3916
60.942734485, 96.390, 1149.0, 33.8969
60.995255616, 96.390, 1232.0, 35.0999
61.047776747, 96.390, 1204.0, 34.6987
61.100297878, 96.390, 1207.0, 34.7419
61.152819008, 96.390, 1182.0, 34.3802
61.205340139, 96.390, 1180.0, 34.3511
61.257861270, 96.390, 1223.0, 34.9714
61.310382400, 96.390, 1212.0, 34.8138
61.362903531, 96.390, 1132.0, 33.6452
61.415424662, 96.390, 1185.0, 34.4238
61.467945792, 96.390, 1134.0, 33.6749
61.520466923, 96.390, 1121.0, 33.4813
61.572988054, 96.390, 1144.0, 33.8231
61.625509185, 96.390, 1195.0, 34.5688
61.678030315, 96.390, 1191.0, 34.5109
61.730551446, 96.390, 1195.0, 34.5688
61.783072577, 96.390, 1161.0, 34.0735
61.835593707, 96.390, 1142.0, 33.7935
61.888114838, 96.390, 1203.0, 34.6843
61.940635969, 96.390, 1152.0, 33.9411
61.993157100, 96.390, 1093.0, 33.0606
62.045678230, 96.390, 1103.0, 33.2114
62.098199361, 96.390, 1171.0, 34.2199
62.150720492, 96.390, 1114.0, 33.3766
62.203241622, 96.390, 1160.0, 34.0588
62.255762753, 96.390, 1131.0, 33.6303
62.308283884, 96.390, 1140.0, 33.7639
62.360805015, 96.390, 1064.0, 32.6190
62.413326145, 96.390, 1065.0, 32.6343
62.465847276, 96.390, 1094.0, 33.0757
62.518368407, 96.390, 1051.0, 32.4191
62.570889537, 96.390, 1072.0, 32.7414
62.623410668, 96.390, 1065.0, 32.6343
62.675931799, 96.390, 1053.0, 32.4500
62.728452930, 96.390, 1106.0, 33.2566
62.780974060, 96.390, 1041.0, 32.2645
62.833495191, 96.390, 1040.0, 32.2490
62.886016322, 96.390, 1019.0, 31.9218
62.938537452, 96.390, 1050.0, 32.4037
62.991058583, 96.390, 1065.0, 32.6343
63.043579714, 96.390, 1075.0, 32.7872
63.096100844, 96.390, 1032.0, 32.1248
63.148621975, 96.390, 974.0, 31.2090
63.201143106, 96.390, 1078.0, 32.8329
63.253664237, 96.390, 1005.0, 31.7017
63.306185367, 96.390, 1023.0, 31.9844
63.358706498, 96.390, 1022.0, 31.9687
63.411227629, 96.390, 995.0, 31.5436
63.463748759, 96.390, 975.0, 31.2250
63.516269890, 96.390, 1001.0, 31.6386
63.568791021, 96.390, 994.0, 31.5278
63.621312152, 96.390, 1005.0, 31.7017
63.673833282, 96.390, 989.0, 31.4484
63.726354413, 96.390, 1001.0, 31.6386
63.778875544, 96.390, 972.0, 31.1769
63.831396674, 96.390, 962.0, 31.0161
63.883917805, 96.390, 972.0, 31.1769
63.936438936, 96.390, 1025.0, 32.0156
63.988960067, 96.390, 950.0, 30.8221
64.041481197, 96.390, 991.0, 31.4802
64.094002328, 96.390, 1015.0, 31.8591
64.146523459, 96.390, 962.0, 31.0161
64.199044589, 96.390, 1032.0, 32.1248
64.251565720, 96.390, 993.0, 31.5119
64.304086851, 96.390, 972.0, 31.1769
64.356607981, 96.390, 968.0, 31.1127
64.409129112, 96.390, 966.0, 31.0805
64.461650243, 96.390, 941.0, 30.6757
64.514171374, 96.390, 942.0, 30.6920
64.566692504, 96.390, 911.0, 30.1828
64.619213635, 96.390, 968.0, 31.1127
64.671734766, 96.390, 917.0, 30.2820
64.724255896, 96.390, 920.0, 30.3315
64.776777027, 96.390, 905.0, 30.0832
64.829298158, 96.390, 981.0, 31.3209
64.881819289, 96.390, 978.0, 31.2730
64.934340419, 96.390, 934.0, 30.5614
64.986861550, 96.390, 1056.0, 32.4962