File: Files_organized_for_plots/Constant_NaOH_half_mL10M_to_1gPC/zzXRD_Centroid25Oct21_Act23Jan22_B3_0325M_NaOH_LS0134_1.csv
[Measurement conditions]
Sample identification,XRD_Centroid25Oct21_Act23Jan22_B3_0325M_NaOH_LS0134_1
Comment - 1,"Configuration=Stage for Flat Samples/Holders, Owner=User-1, Creation date=7/1/2020 9:53:24 AM"
Comment - 2,"Goniometer=Theta/Theta; Minimum step size 2Theta:0.0001; Minimum step size Omega:0.0001"
Comment - 3,"Sample stage=Stage for flat samples/holders"
Comment - 4,"Diffractometer system=EMPYREAN"
Comment - 5,"Measurement program=C:\Users\ibo5034\OneDrive - The Pennsylvania State University\NEUP\Zerobackground scan.xrdmp, Identifier={98A3B11C-88F9-4AA6-982C-73314A311EF5}"
Anode material,Cu
K-Alpha1 wavelength,1.5405980
K-Alpha2 wavelength,1.5444260
Ratio K-Alpha2/K-Alpha1,0.500
Divergence slit,Fixed,0.25
Monochromator used,NO
Generator voltage, 45
Tube current, 40
File date and time,26/Jan/2022 11:25
Unit cell,
h k l, 0 0 0
Scan axis,Gonio
Scan range,4.994599997,64.999991833
Scan step size,0.0262606
No. of points, 2285
Scan type,CONTINUOUS
Time per step,96.390
[Scan points]
Angle, TimePerStep, Intensity, ESD
5.007730280, 96.390, 5961.0, 77.2075
5.060251411, 96.390, 5816.0, 76.2627
5.112772541, 96.390, 5742.0, 75.7760
5.165293672, 96.390, 5842.0, 76.4330
5.217814803, 96.390, 5764.0, 75.9210
5.270335934, 96.390, 5589.0, 74.7596
5.322857064, 96.390, 5783.0, 76.0460
5.375378195, 96.390, 5489.0, 74.0878
5.427899326, 96.390, 5589.0, 74.7596
5.480420456, 96.390, 5488.0, 74.0810
5.532941587, 96.390, 5517.0, 74.2765
5.585462718, 96.390, 5530.0, 74.3640
5.637983849, 96.390, 5452.0, 73.8377
5.690504979, 96.390, 5223.0, 72.2703
5.743026110, 96.390, 5297.0, 72.7805
5.795547241, 96.390, 5431.0, 73.6953
5.848068371, 96.390, 5235.0, 72.3533
5.900589502, 96.390, 5351.0, 73.1505
5.953110633, 96.390, 5423.0, 73.6410
6.005631763, 96.390, 5305.0, 72.8354
6.058152894, 96.390, 5349.0, 73.1369
6.110674025, 96.390, 5170.0, 71.9027
6.163195156, 96.390, 5192.0, 72.0555
6.215716286, 96.390, 5213.0, 72.2011
6.268237417, 96.390, 5301.0, 72.8080
6.320758548, 96.390, 5140.0, 71.6938
6.373279678, 96.390, 5143.0, 71.7147
6.425800809, 96.390, 5201.0, 72.1180
6.478321940, 96.390, 5149.0, 71.7565
6.530843071, 96.390, 4928.0, 70.1997
6.583364201, 96.390, 4987.0, 70.6187
6.635885332, 96.390, 4963.0, 70.4486
6.688406463, 96.390, 4984.0, 70.5975
6.740927593, 96.390, 4925.0, 70.1783
6.793448724, 96.390, 4877.0, 69.8355
6.845969855, 96.390, 4957.0, 70.4060
6.898490986, 96.390, 4838.0, 69.5557
6.951012116, 96.390, 4777.0, 69.1158
7.003533247, 96.390, 4680.0, 68.4105
7.056054378, 96.390, 4709.0, 68.6222
7.108575508, 96.390, 4718.0, 68.6877
7.161096639, 96.390, 4747.0, 68.8985
7.213617770, 96.390, 4794.0, 69.2387
7.266138900, 96.390, 4805.0, 69.3181
7.318660031, 96.390, 4643.0, 68.1396
7.371181162, 96.390, 4552.0, 67.4685
7.423702293, 96.390, 4535.0, 67.3424
7.476223423, 96.390, 4596.0, 67.7938
7.528744554, 96.390, 4602.0, 67.8380
7.581265685, 96.390, 4558.0, 67.5130
7.633786815, 96.390, 4515.0, 67.1937
7.686307946, 96.390, 4448.0, 66.6933
7.738829077, 96.390, 4490.0, 67.0075
7.791350208, 96.390, 4468.0, 66.8431
7.843871338, 96.390, 4310.0, 65.6506
7.896392469, 96.390, 4351.0, 65.9621
7.948913600, 96.390, 4334.0, 65.8331
8.001434730, 96.390, 4339.0, 65.8711
8.053955861, 96.390, 4402.0, 66.3476
8.106476992, 96.390, 4367.0, 66.0833
8.158998123, 96.390, 4354.0, 65.9848
8.211519253, 96.390, 4373.0, 66.1287
8.264040384, 96.390, 4270.0, 65.3452
8.316561515, 96.390, 4327.0, 65.7799
8.369082645, 96.390, 4189.0, 64.7225
8.421603776, 96.390, 4216.0, 64.9307
8.474124907, 96.390, 4129.0, 64.2573
8.526646038, 96.390, 4196.0, 64.7765
8.579167168, 96.390, 4198.0, 64.7920
8.631688299, 96.390, 4121.0, 64.1950
8.684209430, 96.390, 4115.0, 64.1483
8.736730560, 96.390, 3983.0, 63.1110
8.789251691, 96.390, 4059.0, 63.7103
8.841772822, 96.390, 4011.0, 63.3325
8.894293952, 96.390, 4043.0, 63.5846
8.946815083, 96.390, 3915.0, 62.5700
8.999336214, 96.390, 3883.0, 62.3137
9.051857345, 96.390, 3922.0, 62.6259
9.104378475, 96.390, 3917.0, 62.5859
9.156899606, 96.390, 3893.0, 62.3939
9.209420737, 96.390, 3801.0, 61.6523
9.261941867, 96.390, 3901.0, 62.4580
9.314462998, 96.390, 3802.0, 61.6604
9.366984129, 96.390, 3780.0, 61.4817
9.419505260, 96.390, 3792.0, 61.5792
9.472026390, 96.390, 3758.0, 61.3025
9.524547521, 96.390, 3746.0, 61.2046
9.577068652, 96.390, 3711.0, 60.9180
9.629589782, 96.390, 3681.0, 60.6712
9.682110913, 96.390, 3710.0, 60.9098
9.734632044, 96.390, 3696.0, 60.7947
9.787153175, 96.390, 3581.0, 59.8415
9.839674305, 96.390, 3580.0, 59.8331
9.892195436, 96.390, 3516.0, 59.2959
9.944716567, 96.390, 3561.0, 59.6741
9.997237697, 96.390, 3526.0, 59.3801
10.049758828, 96.390, 3551.0, 59.5903
10.102279959, 96.390, 3572.0, 59.7662
10.154801090, 96.390, 3524.0, 59.3633
10.207322220, 96.390, 3521.0, 59.3380
10.259843351, 96.390, 3389.0, 58.2151
10.312364482, 96.390, 3472.0, 58.9237
10.364885612, 96.390, 3473.0, 58.9322
10.417406743, 96.390, 3451.0, 58.7452
10.469927874, 96.390, 3405.0, 58.3524
10.522449004, 96.390, 3434.0, 58.6003
10.574970135, 96.390, 3295.0, 57.4021
10.627491266, 96.390, 3340.0, 57.7927
10.680012397, 96.390, 3416.0, 58.4466
10.732533527, 96.390, 3309.0, 57.5239
10.785054658, 96.390, 3256.0, 57.0614
10.837575789, 96.390, 3270.0, 57.1839
10.890096919, 96.390, 3369.0, 58.0431
10.942618050, 96.390, 3288.0, 57.3411
10.995139181, 96.390, 3280.0, 57.2713
11.047660312, 96.390, 3277.0, 57.2451
11.100181442, 96.390, 3173.0, 56.3294
11.152702573, 96.390, 3336.0, 57.7581
11.205223704, 96.390, 3111.0, 55.7763
11.257744834, 96.390, 3173.0, 56.3294
11.310265965, 96.390, 3086.0, 55.5518
11.362787096, 96.390, 3061.0, 55.3263
11.415308227, 96.390, 3101.0, 55.6866
11.467829357, 96.390, 3075.0, 55.4527
11.520350488, 96.390, 3074.0, 55.4437
11.572871619, 96.390, 3072.0, 55.4256
11.625392749, 96.390, 3077.0, 55.4707
11.677913880, 96.390, 3039.0, 55.1271
11.730435011, 96.390, 2909.0, 53.9351
11.782956141, 96.390, 3086.0, 55.5518
11.835477272, 96.390, 2994.0, 54.7175
11.887998403, 96.390, 3032.0, 55.0636
11.940519534, 96.390, 3102.0, 55.6956
11.993040664, 96.390, 2902.0, 53.8702
12.045561795, 96.390, 2872.0, 53.5910
12.098082926, 96.390, 2919.0, 54.0278
12.150604056, 96.390, 2914.0, 53.9815
12.203125187, 96.390, 2962.0, 54.4243
12.255646318, 96.390, 2978.0, 54.5711
12.308167449, 96.390, 2862.0, 53.4977
12.360688579, 96.390, 2895.0, 53.8052
12.413209710, 96.390, 2776.0, 52.6878
12.465730841, 96.390, 2799.0, 52.9056
12.518251971, 96.390, 2845.0, 53.3385
12.570773102, 96.390, 2735.0, 52.2972
12.623294233, 96.390, 2787.0, 52.7920
12.675815364, 96.390, 2853.0, 53.4135
12.728336494, 96.390, 2816.0, 53.0660
12.780857625, 96.390, 2635.0, 51.3323
12.833378756, 96.390, 2700.0, 51.9615
12.885899886, 96.390, 2825.0, 53.1507
12.938421017, 96.390, 2731.0, 52.2590
12.990942148, 96.390, 2763.0, 52.5642
13.043463279, 96.390, 2737.0, 52.3163
13.095984409, 96.390, 2654.0, 51.5170
13.148505540, 96.390, 2686.0, 51.8266
13.201026671, 96.390, 2679.0, 51.7591
13.253547801, 96.390, 2685.0, 51.8170
13.306068932, 96.390, 2621.0, 51.1957
13.358590063, 96.390, 2665.0, 51.6236
13.411111193, 96.390, 2705.0, 52.0096
13.463632324, 96.390, 2588.0, 50.8724
13.516153455, 96.390, 2617.0, 51.1566
13.568674586, 96.390, 2597.0, 50.9608
13.621195716, 96.390, 2549.0, 50.4876
13.673716847, 96.390, 2529.0, 50.2892
13.726237978, 96.390, 2530.0, 50.2991
13.778759108, 96.390, 2627.0, 51.2543
13.831280239, 96.390, 2606.0, 51.0490
13.883801370, 96.390, 2483.0, 49.8297
13.936322501, 96.390, 2577.0, 50.7642
13.988843631, 96.390, 2541.0, 50.4083
14.041364762, 96.390, 2527.0, 50.2693
14.093885893, 96.390, 2603.0, 51.0196
14.146407023, 96.390, 2461.0, 49.6085
14.198928154, 96.390, 2474.0, 49.7393
14.251449285, 96.390, 2557.0, 50.5668
14.303970416, 96.390, 2449.0, 49.4874
14.356491546, 96.390, 2488.0, 49.8799
14.409012677, 96.390, 2561.0, 50.6063
14.461533808, 96.390, 2504.0, 50.0400
14.514054938, 96.390, 2408.0, 49.0714
14.566576069, 96.390, 2395.0, 48.9387
14.619097200, 96.390, 2454.0, 49.5379
14.671618331, 96.390, 2509.0, 50.0899
14.724139461, 96.390, 2468.0, 49.6790
14.776660592, 96.390, 2505.0, 50.0500
14.829181723, 96.390, 2456.0, 49.5580
14.881702853, 96.390, 2467.0, 49.6689
14.934223984, 96.390, 2457.0, 49.5681
14.986745115, 96.390, 2494.0, 49.9400
15.039266245, 96.390, 2455.0, 49.5480
15.091787376, 96.390, 2400.0, 48.9898
15.144308507, 96.390, 2446.0, 49.4571
15.196829638, 96.390, 2328.0, 48.2494
15.249350768, 96.390, 2458.0, 49.5782
15.301871899, 96.390, 2407.0, 49.0612
15.354393030, 96.390, 2403.0, 49.0204
15.406914160, 96.390, 2423.0, 49.2240
15.459435291, 96.390, 2418.0, 49.1732
15.511956422, 96.390, 2274.0, 47.6865
15.564477553, 96.390, 2412.0, 49.1121
15.616998683, 96.390, 2347.0, 48.4458
15.669519814, 96.390, 2389.0, 48.8774
15.722040945, 96.390, 2360.0, 48.5798
15.774562075, 96.390, 2313.0, 48.0937
15.827083206, 96.390, 2428.0, 49.2747
15.879604337, 96.390, 2375.0, 48.7340
15.932125468, 96.390, 2359.0, 48.5695
15.984646598, 96.390, 2390.0, 48.8876
16.037167729, 96.390, 2379.0, 48.7750
16.089688860, 96.390, 2479.0, 49.7896
16.142209990, 96.390, 2357.0, 48.5489
16.194731121, 96.390, 2390.0, 48.8876
16.247252252, 96.390, 2373.0, 48.7134
16.299773382, 96.390, 2402.0, 49.0102
16.352294513, 96.390, 2482.0, 49.8197
16.404815644, 96.390, 2333.0, 48.3011
16.457336775, 96.390, 2460.0, 49.5984
16.509857905, 96.390, 2322.0, 48.1871
16.562379036, 96.390, 2487.0, 49.8698
16.614900167, 96.390, 2359.0, 48.5695
16.667421297, 96.390, 2353.0, 48.5077
16.719942428, 96.390, 2337.0, 48.3425
16.772463559, 96.390, 2379.0, 48.7750
16.824984690, 96.390, 2400.0, 48.9898
16.877505820, 96.390, 2405.0, 49.0408
16.930026951, 96.390, 2430.0, 49.2950
16.982548082, 96.390, 2369.0, 48.6724
17.035069212, 96.390, 2408.0, 49.0714
17.087590343, 96.390, 2415.0, 49.1426
17.140111474, 96.390, 2447.0, 49.4672
17.192632605, 96.390, 2487.0, 49.8698
17.245153735, 96.390, 2447.0, 49.4672
17.297674866, 96.390, 2423.0, 49.2240
17.350195997, 96.390, 2455.0, 49.5480
17.402717127, 96.390, 2374.0, 48.7237
17.455238258, 96.390, 2449.0, 49.4874
17.507759389, 96.390, 2449.0, 49.4874
17.560280520, 96.390, 2459.0, 49.5883
17.612801650, 96.390, 2549.0, 50.4876
17.665322781, 96.390, 2450.0, 49.4975
17.717843912, 96.390, 2453.0, 49.5278
17.770365042, 96.390, 2543.0, 50.4282
17.822886173, 96.390, 2513.0, 50.1298
17.875407304, 96.390, 2507.0, 50.0700
17.927928434, 96.390, 2492.0, 49.9199
17.980449565, 96.390, 2396.0, 48.9490
18.032970696, 96.390, 2490.0, 49.8999
18.085491827, 96.390, 2466.0, 49.6588
18.138012957, 96.390, 2490.0, 49.8999
18.190534088, 96.390, 2472.0, 49.7192
18.243055219, 96.390, 2573.0, 50.7247
18.295576349, 96.390, 2521.0, 50.2096
18.348097480, 96.390, 2385.0, 48.8365
18.400618611, 96.390, 2566.0, 50.6557
18.453139742, 96.390, 2592.0, 50.9117
18.505660872, 96.390, 2536.0, 50.3587
18.558182003, 96.390, 2576.0, 50.7543
18.610703134, 96.390, 2556.0, 50.5569
18.663224264, 96.390, 2615.0, 51.1371
18.715745395, 96.390, 2516.0, 50.1597
18.768266526, 96.390, 2565.0, 50.6458
18.820787657, 96.390, 2591.0, 50.9019
18.873308787, 96.390, 2550.0, 50.4975
18.925829918, 96.390, 2672.0, 51.6914
18.978351049, 96.390, 2628.0, 51.2640
19.030872179, 96.390, 2657.0, 51.5461
19.083393310, 96.390, 2716.0, 52.1153
19.135914441, 96.390, 2620.0, 51.1859
19.188435572, 96.390, 2570.0, 50.6952
19.240956702, 96.390, 2636.0, 51.3420
19.293477833, 96.390, 2663.0, 51.6043
19.345998964, 96.390, 2602.0, 51.0098
19.398520094, 96.390, 2733.0, 52.2781
19.451041225, 96.390, 2655.0, 51.5267
19.503562356, 96.390, 2686.0, 51.8266
19.556083486, 96.390, 2764.0, 52.5738
19.608604617, 96.390, 2764.0, 52.5738
19.661125748, 96.390, 2759.0, 52.5262
19.713646879, 96.390, 2753.0, 52.4690
19.766168009, 96.390, 2857.0, 53.4509
19.818689140, 96.390, 2729.0, 52.2398
19.871210271, 96.390, 2676.0, 51.7301
19.923731401, 96.390, 2709.0, 52.0481
19.976252532, 96.390, 2772.0, 52.6498
20.028773663, 96.390, 2747.0, 52.4118
20.081294794, 96.390, 2715.0, 52.1057
20.133815924, 96.390, 2818.0, 53.0848
20.186337055, 96.390, 2896.0, 53.8145
20.238858186, 96.390, 2802.0, 52.9339
20.291379316, 96.390, 2723.0, 52.1824
20.343900447, 96.390, 2814.0, 53.0471
20.396421578, 96.390, 2836.0, 53.2541
20.448942709, 96.390, 2894.0, 53.7959
20.501463839, 96.390, 2988.0, 54.6626
20.553984970, 96.390, 2892.0, 53.7773
20.606506101, 96.390, 2861.0, 53.4883
20.659027231, 96.390, 2826.0, 53.1601
20.711548362, 96.390, 2833.0, 53.2259
20.764069493, 96.390, 2882.0, 53.6843
20.816590623, 96.390, 2849.0, 53.3760
20.869111754, 96.390, 2907.0, 53.9166
20.921632885, 96.390, 2917.0, 54.0093
20.974154016, 96.390, 2902.0, 53.8702
21.026675146, 96.390, 2829.0, 53.1883
21.079196277, 96.390, 2904.0, 53.8888
21.131717408, 96.390, 2879.0, 53.6563
21.184238538, 96.390, 2947.0, 54.2863
21.236759669, 96.390, 2842.0, 53.3104
21.289280800, 96.390, 3000.0, 54.7723
21.341801931, 96.390, 2964.0, 54.4426
21.394323061, 96.390, 2899.0, 53.8424
21.446844192, 96.390, 2967.0, 54.4702
21.499365323, 96.390, 2934.0, 54.1664
21.551886453, 96.390, 2832.0, 53.2165
21.604407584, 96.390, 2896.0, 53.8145
21.656928715, 96.390, 2950.0, 54.3139
21.709449846, 96.390, 2889.0, 53.7494
21.761970976, 96.390, 3061.0, 55.3263
21.814492107, 96.390, 2960.0, 54.4059
21.867013238, 96.390, 2950.0, 54.3139
21.919534368, 96.390, 2981.0, 54.5985
21.972055499, 96.390, 2919.0, 54.0278
22.024576630, 96.390, 2837.0, 53.2635
22.077097761, 96.390, 2902.0, 53.8702
22.129618891, 96.390, 2928.0, 54.1110
22.182140022, 96.390, 2922.0, 54.0555
22.234661153, 96.390, 2862.0, 53.4977
22.287182283, 96.390, 2923.0, 54.0648
22.339703414, 96.390, 2870.0, 53.5724
22.392224545, 96.390, 2893.0, 53.7866
22.444745675, 96.390, 2944.0, 54.2586
22.497266806, 96.390, 2987.0, 54.6535
22.549787937, 96.390, 2977.0, 54.5619
22.602309068, 96.390, 3113.0, 55.7943
22.654830198, 96.390, 2876.0, 53.6284
22.707351329, 96.390, 2954.0, 54.3507
22.759872460, 96.390, 2861.0, 53.4883
22.812393590, 96.390, 2992.0, 54.6992
22.864914721, 96.390, 2920.0, 54.0370
22.917435852, 96.390, 2876.0, 53.6284
22.969956983, 96.390, 2980.0, 54.5894
23.022478113, 96.390, 2890.0, 53.7587
23.074999244, 96.390, 2864.0, 53.5164
23.127520375, 96.390, 2845.0, 53.3385
23.180041505, 96.390, 2898.0, 53.8331
23.232562636, 96.390, 2913.0, 53.9722
23.285083767, 96.390, 2784.0, 52.7636
23.337604898, 96.390, 2847.0, 53.3573
23.390126028, 96.390, 2860.0, 53.4790
23.442647159, 96.390, 2933.0, 54.1572
23.495168290, 96.390, 2889.0, 53.7494
23.547689420, 96.390, 2865.0, 53.5257
23.600210551, 96.390, 2739.0, 52.3355
23.652731682, 96.390, 2738.0, 52.3259
23.705252813, 96.390, 2836.0, 53.2541
23.757773943, 96.390, 2808.0, 52.9906
23.810295074, 96.390, 2720.0, 52.1536
23.862816205, 96.390, 2718.0, 52.1344
23.915337335, 96.390, 2837.0, 53.2635
23.967858466, 96.390, 2700.0, 51.9615
24.020379597, 96.390, 2815.0, 53.0566
24.072900727, 96.390, 2812.0, 53.0283
24.125421858, 96.390, 2680.0, 51.7687
24.177942989, 96.390, 2690.0, 51.8652
24.230464120, 96.390, 2801.0, 52.9245
24.282985250, 96.390, 2719.0, 52.1440
24.335506381, 96.390, 2700.0, 51.9615
24.388027512, 96.390, 2690.0, 51.8652
24.440548642, 96.390, 2679.0, 51.7591
24.493069773, 96.390, 2681.0, 51.7784
24.545590904, 96.390, 2710.0, 52.0577
24.598112035, 96.390, 2666.0, 51.6333
24.650633165, 96.390, 2631.0, 51.2933
24.703154296, 96.390, 2661.0, 51.5849
24.755675427, 96.390, 2609.0, 51.0784
24.808196557, 96.390, 2564.0, 50.6360
24.860717688, 96.390, 2520.0, 50.1996
24.913238819, 96.390, 2688.0, 51.8459
24.965759950, 96.390, 2504.0, 50.0400
25.018281080, 96.390, 2626.0, 51.2445
25.070802211, 96.390, 2612.0, 51.1077
25.123323342, 96.390, 2534.0, 50.3389
25.175844472, 96.390, 2575.0, 50.7445
25.228365603, 96.390, 2563.0, 50.6261
25.280886734, 96.390, 2503.0, 50.0300
25.333407864, 96.390, 2469.0, 49.6890
25.385928995, 96.390, 2573.0, 50.7247
25.438450126, 96.390, 2549.0, 50.4876
25.490971257, 96.390, 2434.0, 49.3356
25.543492387, 96.390, 2456.0, 49.5580
25.596013518, 96.390, 2428.0, 49.2747
25.648534649, 96.390, 2549.0, 50.4876
25.701055779, 96.390, 2408.0, 49.0714
25.753576910, 96.390, 2482.0, 49.8197
25.806098041, 96.390, 2504.0, 50.0400
25.858619172, 96.390, 2393.0, 48.9183
25.911140302, 96.390, 2468.0, 49.6790
25.963661433, 96.390, 2441.0, 49.4065
26.016182564, 96.390, 2451.0, 49.5076
26.068703694, 96.390, 2483.0, 49.8297
26.121224825, 96.390, 2404.0, 49.0306
26.173745956, 96.390, 2421.0, 49.2037
26.226267087, 96.390, 2487.0, 49.8698
26.278788217, 96.390, 2345.0, 48.4252
26.331309348, 96.390, 2447.0, 49.4672
26.383830479, 96.390, 2447.0, 49.4672
26.436351609, 96.390, 2409.0, 49.0816
26.488872740, 96.390, 2436.0, 49.3559
26.541393871, 96.390, 2402.0, 49.0102
26.593915002, 96.390, 2381.0, 48.7955
26.646436132, 96.390, 2363.0, 48.6107
26.698957263, 96.390, 2326.0, 48.2286
26.751478394, 96.390, 2359.0, 48.5695
26.803999524, 96.390, 2394.0, 48.9285
26.856520655, 96.390, 2404.0, 49.0306
26.909041786, 96.390, 2375.0, 48.7340
26.961562916, 96.390, 2361.0, 48.5901
27.014084047, 96.390, 2401.0, 49.0000
27.066605178, 96.390, 2297.0, 47.9270
27.119126309, 96.390, 2440.0, 49.3964
27.171647439, 96.390, 2354.0, 48.5180
27.224168570, 96.390, 2315.0, 48.1144
27.276689701, 96.390, 2257.0, 47.5079
27.329210831, 96.390, 2335.0, 48.3218
27.381731962, 96.390, 2250.0, 47.4342
27.434253093, 96.390, 2348.0, 48.4562
27.486774224, 96.390, 2366.0, 48.6415
27.539295354, 96.390, 2284.0, 47.7912
27.591816485, 96.390, 2298.0, 47.9375
27.644337616, 96.390, 2313.0, 48.0937
27.696858746, 96.390, 2335.0, 48.3218
27.749379877, 96.390, 2332.0, 48.2908
27.801901008, 96.390, 2311.0, 48.0729
27.854422139, 96.390, 2388.0, 48.8672
27.906943269, 96.390, 2288.0, 47.8330
27.959464400, 96.390, 2298.0, 47.9375
28.011985531, 96.390, 2287.0, 47.8226
28.064506661, 96.390, 2305.0, 48.0104
28.117027792, 96.390, 2239.0, 47.3181
28.169548923, 96.390, 2345.0, 48.4252
28.222070054, 96.390, 2293.0, 47.8853
28.274591184, 96.390, 2324.0, 48.2079
28.327112315, 96.390, 2309.0, 48.0521
28.379633446, 96.390, 2291.0, 47.8644
28.432154576, 96.390, 2288.0, 47.8330
28.484675707, 96.390, 2265.0, 47.5920
28.537196838, 96.390, 2245.0, 47.3814
28.589717968, 96.390, 2277.0, 47.7179
28.642239099, 96.390, 2336.0, 48.3322
28.694760230, 96.390, 2297.0, 47.9270
28.747281361, 96.390, 2209.0, 47.0000
28.799802491, 96.390, 2238.0, 47.3075
28.852323622, 96.390, 2306.0, 48.0208
28.904844753, 96.390, 2313.0, 48.0937
28.957365883, 96.390, 2247.0, 47.4025
29.009887014, 96.390, 2248.0, 47.4131
29.062408145, 96.390, 2247.0, 47.4025
29.114929276, 96.390, 2263.0, 47.5710
29.167450406, 96.390, 2281.0, 47.7598
29.219971537, 96.390, 2271.0, 47.6550
29.272492668, 96.390, 2188.0, 46.7761
29.325013798, 96.390, 2187.0, 46.7654
29.377534929, 96.390, 2175.0, 46.6369
29.430056060, 96.390, 2245.0, 47.3814
29.482577191, 96.390, 2342.0, 48.3942
29.535098321, 96.390, 2226.0, 47.1805
29.587619452, 96.390, 2274.0, 47.6865
29.640140583, 96.390, 2299.0, 47.9479
29.692661713, 96.390, 2296.0, 47.9166
29.745182844, 96.390, 2161.0, 46.4866
29.797703975, 96.390, 2185.0, 46.7440
29.850225105, 96.390, 2201.0, 46.9148
29.902746236, 96.390, 2307.0, 48.0312
29.955267367, 96.390, 2285.0, 47.8017
30.007788498, 96.390, 2244.0, 47.3709
30.060309628, 96.390, 2171.0, 46.5940
30.112830759, 96.390, 2251.0, 47.4447
30.165351890, 96.390, 2184.0, 46.7333
30.217873020, 96.390, 2184.0, 46.7333
30.270394151, 96.390, 2230.0, 47.2229
30.322915282, 96.390, 2311.0, 48.0729
30.375436413, 96.390, 2160.0, 46.4758
30.427957543, 96.390, 2266.0, 47.6025
30.480478674, 96.390, 2219.0, 47.1063
30.532999805, 96.390, 2264.0, 47.5815
30.585520935, 96.390, 2201.0, 46.9148
30.638042066, 96.390, 2206.0, 46.9681
30.690563197, 96.390, 2124.0, 46.0869
30.743084328, 96.390, 2110.0, 45.9347
30.795605458, 96.390, 2131.0, 46.1628
30.848126589, 96.390, 2260.0, 47.5395
30.900647720, 96.390, 2238.0, 47.3075
30.953168850, 96.390, 2174.0, 46.6262
31.005689981, 96.390, 2219.0, 47.1063
31.058211112, 96.390, 2200.0, 46.9042
31.110732243, 96.390, 2213.0, 47.0425
31.163253373, 96.390, 2188.0, 46.7761
31.215774504, 96.390, 2161.0, 46.4866
31.268295635, 96.390, 2219.0, 47.1063
31.320816765, 96.390, 2169.0, 46.5725
31.373337896, 96.390, 2152.0, 46.3897
31.425859027, 96.390, 2223.0, 47.1487
31.478380157, 96.390, 2158.0, 46.4543
31.530901288, 96.390, 2213.0, 47.0425
31.583422419, 96.390, 2202.0, 46.9255
31.635943550, 96.390, 2109.0, 45.9239
31.688464680, 96.390, 2244.0, 47.3709
31.740985811, 96.390, 2172.0, 46.6047
31.793506942, 96.390, 2080.0, 45.6070
31.846028072, 96.390, 2125.0, 46.0977
31.898549203, 96.390, 2217.0, 47.0850
31.951070334, 96.390, 2172.0, 46.6047
32.003591465, 96.390, 2151.0, 46.3789
32.056112595, 96.390, 2032.0, 45.0777
32.108633726, 96.390, 2226.0, 47.1805
32.161154857, 96.390, 2212.0, 47.0319
32.213675987, 96.390, 2157.0, 46.4435
32.266197118, 96.390, 2183.0, 46.7226
32.318718249, 96.390, 2102.0, 45.8476
32.371239380, 96.390, 2140.0, 46.2601
32.423760510, 96.390, 2043.0, 45.1996
32.476281641, 96.390, 2117.0, 46.0109
32.528802772, 96.390, 2103.0, 45.8585
32.581323902, 96.390, 1996.0, 44.6766
32.633845033, 96.390, 2103.0, 45.8585
32.686366164, 96.390, 2107.0, 45.9021
32.738887295, 96.390, 2160.0, 46.4758
32.791408425, 96.390, 2043.0, 45.1996
32.843929556, 96.390, 2121.0, 46.0543
32.896450687, 96.390, 2023.0, 44.9778
32.948971817, 96.390, 2230.0, 47.2229
33.001492948, 96.390, 2056.0, 45.3431
33.054014079, 96.390, 2017.0, 44.9110
33.106535209, 96.390, 2029.0, 45.0444
33.159056340, 96.390, 2125.0, 46.0977
33.211577471, 96.390, 1968.0, 44.3621
33.264098602, 96.390, 2084.0, 45.6508
33.316619732, 96.390, 2141.0, 46.2709
33.369140863, 96.390, 2041.0, 45.1774
33.421661994, 96.390, 2019.0, 44.9333
33.474183124, 96.390, 2040.0, 45.1664
33.526704255, 96.390, 2045.0, 45.2217
33.579225386, 96.390, 2086.0, 45.6727
33.631746517, 96.390, 2030.0, 45.0555
33.684267647, 96.390, 1997.0, 44.6878
33.736788778, 96.390, 1985.0, 44.5533
33.789309909, 96.390, 1993.0, 44.6430
33.841831039, 96.390, 2035.0, 45.1110
33.894352170, 96.390, 1953.0, 44.1928
33.946873301, 96.390, 2092.0, 45.7384
33.999394432, 96.390, 2049.0, 45.2659
34.051915562, 96.390, 1985.0, 44.5533
34.104436693, 96.390, 2003.0, 44.7549
34.156957824, 96.390, 2029.0, 45.0444
34.209478954, 96.390, 1926.0, 43.8862
34.262000085, 96.390, 1992.0, 44.6318
34.314521216, 96.390, 2035.0, 45.1110
34.367042346, 96.390, 1993.0, 44.6430
34.419563477, 96.390, 2006.0, 44.7884
34.472084608, 96.390, 2139.0, 46.2493
34.524605739, 96.390, 2036.0, 45.1221
34.577126869, 96.390, 2021.0, 44.9555
34.629648000, 96.390, 1971.0, 44.3959
34.682169131, 96.390, 1984.0, 44.5421
34.734690261, 96.390, 2064.0, 45.4313
34.787211392, 96.390, 2040.0, 45.1664
34.839732523, 96.390, 2040.0, 45.1664
34.892253654, 96.390, 1943.0, 44.0795
34.944774784, 96.390, 2041.0, 45.1774
34.997295915, 96.390, 2022.0, 44.9667
35.049817046, 96.390, 2039.0, 45.1553
35.102338176, 96.390, 1979.0, 44.4860
35.154859307, 96.390, 1953.0, 44.1928
35.207380438, 96.390, 1999.0, 44.7102
35.259901569, 96.390, 2048.0, 45.2548
35.312422699, 96.390, 1942.0, 44.0681
35.364943830, 96.390, 1884.0, 43.4051
35.417464961, 96.390, 1878.0, 43.3359
35.469986091, 96.390, 1943.0, 44.0795
35.522507222, 96.390, 2033.0, 45.0888
35.575028353, 96.390, 1898.0, 43.5660
35.627549484, 96.390, 1927.0, 43.8976
35.680070614, 96.390, 1927.0, 43.8976
35.732591745, 96.390, 1889.0, 43.4626
35.785112876, 96.390, 1977.0, 44.4635
35.837634006, 96.390, 1884.0, 43.4051
35.890155137, 96.390, 1920.0, 43.8178
35.942676268, 96.390, 1903.0, 43.6234
35.995197398, 96.390, 1968.0, 44.3621
36.047718529, 96.390, 1895.0, 43.5316
36.100239660, 96.390, 1852.0, 43.0349
36.152760791, 96.390, 1869.0, 43.2319
36.205281921, 96.390, 1835.0, 42.8369
36.257803052, 96.390, 1830.0, 42.7785
36.310324183, 96.390, 1863.0, 43.1625
36.362845313, 96.390, 1870.0, 43.2435
36.415366444, 96.390, 1737.0, 41.6773
36.467887575, 96.390, 1781.0, 42.2019
36.520408706, 96.390, 1776.0, 42.1426
36.572929836, 96.390, 1766.0, 42.0238
36.625450967, 96.390, 1822.0, 42.6849
36.677972098, 96.390, 1791.0, 42.3202
36.730493228, 96.390, 1724.0, 41.5211
36.783014359, 96.390, 1773.0, 42.1070
36.835535490, 96.390, 1775.0, 42.1307
36.888056621, 96.390, 1768.0, 42.0476
36.940577751, 96.390, 1765.0, 42.0119
36.993098882, 96.390, 1835.0, 42.8369
37.045620013, 96.390, 1709.0, 41.3401
37.098141143, 96.390, 1770.0, 42.0714
37.150662274, 96.390, 1681.0, 41.0000
37.203183405, 96.390, 1770.0, 42.0714
37.255704535, 96.390, 1751.0, 41.8450
37.308225666, 96.390, 1719.0, 41.4608
37.360746797, 96.390, 1706.0, 41.3038
37.413267928, 96.390, 1715.0, 41.4126
37.465789058, 96.390, 1680.0, 40.9878
37.518310189, 96.390, 1708.0, 41.3280
37.570831320, 96.390, 1609.0, 40.1123
37.623352450, 96.390, 1673.0, 40.9023
37.675873581, 96.390, 1626.0, 40.3237
37.728394712, 96.390, 1682.0, 41.0122
37.780915843, 96.390, 1526.0, 39.0640
37.833436973, 96.390, 1643.0, 40.5339
37.885958104, 96.390, 1597.0, 39.9625
37.938479235, 96.390, 1559.0, 39.4842
37.991000365, 96.390, 1626.0, 40.3237
38.043521496, 96.390, 1680.0, 40.9878
38.096042627, 96.390, 1602.0, 40.0250
38.148563758, 96.390, 1533.0, 39.1535
38.201084888, 96.390, 1571.0, 39.6358
38.253606019, 96.390, 1643.0, 40.5339
38.306127150, 96.390, 1580.0, 39.7492
38.358648280, 96.390, 1651.0, 40.6325
38.411169411, 96.390, 1545.0, 39.3065
38.463690542, 96.390, 1610.0, 40.1248
38.516211673, 96.390, 1594.0, 39.9249
38.568732803, 96.390, 1558.0, 39.4715
38.621253934, 96.390, 1483.0, 38.5097
38.673775065, 96.390, 1509.0, 38.8458
38.726296195, 96.390, 1425.0, 37.7492
38.778817326, 96.390, 1524.0, 39.0384
38.831338457, 96.390, 1517.0, 38.9487
38.883859587, 96.390, 1523.0, 39.0256
38.936380718, 96.390, 1497.0, 38.6911
38.988901849, 96.390, 1548.0, 39.3446
39.041422980, 96.390, 1568.0, 39.5980
39.093944110, 96.390, 1433.0, 37.8550
39.146465241, 96.390, 1590.0, 39.8748
39.198986372, 96.390, 1533.0, 39.1535
39.251507502, 96.390, 1586.0, 39.8246
39.304028633, 96.390, 1465.0, 38.2753
39.356549764, 96.390, 1564.0, 39.5474
39.409070895, 96.390, 1531.0, 39.1280
39.461592025, 96.390, 1470.0, 38.3406
39.514113156, 96.390, 1501.0, 38.7427
39.566634287, 96.390, 1503.0, 38.7685
39.619155417, 96.390, 1480.0, 38.4708
39.671676548, 96.390, 1457.0, 38.1707
39.724197679, 96.390, 1502.0, 38.7556
39.776718810, 96.390, 1439.0, 37.9342
39.829239940, 96.390, 1374.0, 37.0675
39.881761071, 96.390, 1407.0, 37.5100
39.934282202, 96.390, 1409.0, 37.5366
39.986803332, 96.390, 1431.0, 37.8286
40.039324463, 96.390, 1423.0, 37.7227
40.091845594, 96.390, 1435.0, 37.8814
40.144366725, 96.390, 1333.0, 36.5103
40.196887855, 96.390, 1477.0, 38.4318
40.249408986, 96.390, 1460.0, 38.2099
40.301930117, 96.390, 1441.0, 37.9605
40.354451247, 96.390, 1391.0, 37.2961
40.406972378, 96.390, 1387.0, 37.2424
40.459493509, 96.390, 1372.0, 37.0405
40.512014639, 96.390, 1432.0, 37.8418
40.564535770, 96.390, 1403.0, 37.4566
40.617056901, 96.390, 1438.0, 37.9210
40.669578032, 96.390, 1417.0, 37.6431
40.722099162, 96.390, 1419.0, 37.6696
40.774620293, 96.390, 1441.0, 37.9605
40.827141424, 96.390, 1390.0, 37.2827
40.879662554, 96.390, 1416.0, 37.6298
40.932183685, 96.390, 1464.0, 38.2623
40.984704816, 96.390, 1348.0, 36.7151
41.037225947, 96.390, 1341.0, 36.6197
41.089747077, 96.390, 1384.0, 37.2022
41.142268208, 96.390, 1418.0, 37.6563
41.194789339, 96.390, 1318.0, 36.3043
41.247310469, 96.390, 1330.0, 36.4692
41.299831600, 96.390, 1433.0, 37.8550
41.352352731, 96.390, 1370.0, 37.0135
41.404873862, 96.390, 1397.0, 37.3765
41.457394992, 96.390, 1365.0, 36.9459
41.509916123, 96.390, 1361.0, 36.8917
41.562437254, 96.390, 1338.0, 36.5787
41.614958384, 96.390, 1426.0, 37.7624
41.667479515, 96.390, 1398.0, 37.3898
41.720000646, 96.390, 1341.0, 36.6197
41.772521776, 96.390, 1295.0, 35.9861
41.825042907, 96.390, 1343.0, 36.6470
41.877564038, 96.390, 1284.0, 35.8329
41.930085169, 96.390, 1359.0, 36.8646
41.982606299, 96.390, 1310.0, 36.1939
42.035127430, 96.390, 1361.0, 36.8917
42.087648561, 96.390, 1301.0, 36.0694
42.140169691, 96.390, 1301.0, 36.0694
42.192690822, 96.390, 1366.0, 36.9594
42.245211953, 96.390, 1289.0, 35.9026
42.297733084, 96.390, 1369.0, 37.0000
42.350254214, 96.390, 1377.0, 37.1080
42.402775345, 96.390, 1357.0, 36.8375
42.455296476, 96.390, 1312.0, 36.2215
42.507817606, 96.390, 1360.0, 36.8782
42.560338737, 96.390, 1317.0, 36.2905
42.612859868, 96.390, 1330.0, 36.4692
42.665380999, 96.390, 1324.0, 36.3868
42.717902129, 96.390, 1375.0, 37.0810
42.770423260, 96.390, 1349.0, 36.7287
42.822944391, 96.390, 1321.0, 36.3456
42.875465521, 96.390, 1323.0, 36.3731
42.927986652, 96.390, 1310.0, 36.1939
42.980507783, 96.390, 1332.0, 36.4966
43.033028914, 96.390, 1249.0, 35.3412
43.085550044, 96.390, 1277.0, 35.7351
43.138071175, 96.390, 1280.0, 35.7771
43.190592306, 96.390, 1285.0, 35.8469
43.243113436, 96.390, 1322.0, 36.3593
43.295634567, 96.390, 1331.0, 36.4829
43.348155698, 96.390, 1374.0, 37.0675
43.400676828, 96.390, 1341.0, 36.6197
43.453197959, 96.390, 1278.0, 35.7491
43.505719090, 96.390, 1287.0, 35.8748
43.558240221, 96.390, 1326.0, 36.4143
43.610761351, 96.390, 1274.0, 35.6931
43.663282482, 96.390, 1324.0, 36.3868
43.715803613, 96.390, 1281.0, 35.7911
43.768324743, 96.390, 1278.0, 35.7491
43.820845874, 96.390, 1249.0, 35.3412
43.873367005, 96.390, 1157.0, 34.0147
43.925888136, 96.390, 1333.0, 36.5103
43.978409266, 96.390, 1376.0, 37.0945
44.030930397, 96.390, 1325.0, 36.4005
44.083451528, 96.390, 1293.0, 35.9583
44.135972658, 96.390, 1301.0, 36.0694
44.188493789, 96.390, 1289.0, 35.9026
44.241014920, 96.390, 1299.0, 36.0416
44.293536051, 96.390, 1359.0, 36.8646
44.346057181, 96.390, 1350.0, 36.7423
44.398578312, 96.390, 1286.0, 35.8608
44.451099443, 96.390, 1299.0, 36.0416
44.503620573, 96.390, 1312.0, 36.2215
44.556141704, 96.390, 1323.0, 36.3731
44.608662835, 96.390, 1340.0, 36.6060
44.661183966, 96.390, 1235.0, 35.1426
44.713705096, 96.390, 1274.0, 35.6931
44.766226227, 96.390, 1332.0, 36.4966
44.818747358, 96.390, 1300.0, 36.0555
44.871268488, 96.390, 1316.0, 36.2767
44.923789619, 96.390, 1259.0, 35.4824
44.976310750, 96.390, 1266.0, 35.5809
45.028831880, 96.390, 1260.0, 35.4965
45.081353011, 96.390, 1294.0, 35.9722
45.133874142, 96.390, 1303.0, 36.0971
45.186395273, 96.390, 1281.0, 35.7911
45.238916403, 96.390, 1306.0, 36.1386
45.291437534, 96.390, 1282.0, 35.8050
45.343958665, 96.390, 1316.0, 36.2767
45.396479795, 96.390, 1250.0, 35.3553
45.449000926, 96.390, 1287.0, 35.8748
45.501522057, 96.390, 1260.0, 35.4965
45.554043188, 96.390, 1259.0, 35.4824
45.606564318, 96.390, 1283.0, 35.8190
45.659085449, 96.390, 1230.0, 35.0714
45.711606580, 96.390, 1234.0, 35.1283
45.764127710, 96.390, 1262.0, 35.5246
45.816648841, 96.390, 1239.0, 35.1994
45.869169972, 96.390, 1313.0, 36.2353
45.921691103, 96.390, 1200.0, 34.6410
45.974212233, 96.390, 1260.0, 35.4965
46.026733364, 96.390, 1241.0, 35.2278
46.079254495, 96.390, 1256.0, 35.4401
46.131775625, 96.390, 1223.0, 34.9714
46.184296756, 96.390, 1281.0, 35.7911
46.236817887, 96.390, 1259.0, 35.4824
46.289339017, 96.390, 1262.0, 35.5246
46.341860148, 96.390, 1209.0, 34.7707
46.394381279, 96.390, 1203.0, 34.6843
46.446902410, 96.390, 1253.0, 35.3977
46.499423540, 96.390, 1309.0, 36.1801
46.551944671, 96.390, 1193.0, 34.5398
46.604465802, 96.390, 1224.0, 34.9857
46.656986932, 96.390, 1241.0, 35.2278
46.709508063, 96.390, 1255.0, 35.4260
46.762029194, 96.390, 1199.0, 34.6266
46.814550325, 96.390, 1286.0, 35.8608
46.867071455, 96.390, 1319.0, 36.3180
46.919592586, 96.390, 1213.0, 34.8281
46.972113717, 96.390, 1223.0, 34.9714
47.024634847, 96.390, 1222.0, 34.9571
47.077155978, 96.390, 1205.0, 34.7131
47.129677109, 96.390, 1248.0, 35.3270
47.182198240, 96.390, 1189.0, 34.4819
47.234719370, 96.390, 1258.0, 35.4683
47.287240501, 96.390, 1268.0, 35.6090
47.339761632, 96.390, 1213.0, 34.8281
47.392282762, 96.390, 1210.0, 34.7851
47.444803893, 96.390, 1154.0, 33.9706
47.497325024, 96.390, 1184.0, 34.4093
47.549846155, 96.390, 1253.0, 35.3977
47.602367285, 96.390, 1142.0, 33.7935
47.654888416, 96.390, 1190.0, 34.4964
47.707409547, 96.390, 1165.0, 34.1321
47.759930677, 96.390, 1126.0, 33.5559
47.812451808, 96.390, 1178.0, 34.3220
47.864972939, 96.390, 1210.0, 34.7851
47.917494069, 96.390, 1139.0, 33.7491
47.970015200, 96.390, 1199.0, 34.6266
48.022536331, 96.390, 1189.0, 34.4819
48.075057462, 96.390, 1174.0, 34.2637
48.127578592, 96.390, 1173.0, 34.2491
48.180099723, 96.390, 1184.0, 34.4093
48.232620854, 96.390, 1144.0, 33.8231
48.285141984, 96.390, 1134.0, 33.6749
48.337663115, 96.390, 1156.0, 34.0000
48.390184246, 96.390, 1206.0, 34.7275
48.442705377, 96.390, 1204.0, 34.6987
48.495226507, 96.390, 1253.0, 35.3977
48.547747638, 96.390, 1114.0, 33.3766
48.600268769, 96.390, 1069.0, 32.6956
48.652789899, 96.390, 1165.0, 34.1321
48.705311030, 96.390, 1132.0, 33.6452
48.757832161, 96.390, 1119.0, 33.4515
48.810353292, 96.390, 1162.0, 34.0881
48.862874422, 96.390, 1175.0, 34.2783
48.915395553, 96.390, 1149.0, 33.8969
48.967916684, 96.390, 1122.0, 33.4963
49.020437814, 96.390, 1094.0, 33.0757
49.072958945, 96.390, 1112.0, 33.3467
49.125480076, 96.390, 1170.0, 34.2053
49.178001207, 96.390, 1097.0, 33.1210
49.230522337, 96.390, 1168.0, 34.1760
49.283043468, 96.390, 1140.0, 33.7639
49.335564599, 96.390, 1133.0, 33.6601
49.388085729, 96.390, 1057.0, 32.5115
49.440606860, 96.390, 1118.0, 33.4365
49.493127991, 96.390, 1091.0, 33.0303
49.545649121, 96.390, 1081.0, 32.8786
49.598170252, 96.390, 1102.0, 33.1964
49.650691383, 96.390, 1146.0, 33.8526
49.703212514, 96.390, 1134.0, 33.6749
49.755733644, 96.390, 1040.0, 32.2490
49.808254775, 96.390, 1129.0, 33.6006
49.860775906, 96.390, 1009.0, 31.7648
49.913297036, 96.390, 1088.0, 32.9848
49.965818167, 96.390, 1066.0, 32.6497
50.018339298, 96.390, 1083.0, 32.9090
50.070860429, 96.390, 1108.0, 33.2866
50.123381559, 96.390, 1062.0, 32.5883
50.175902690, 96.390, 1069.0, 32.6956
50.228423821, 96.390, 1014.0, 31.8434
50.280944951, 96.390, 1057.0, 32.5115
50.333466082, 96.390, 1047.0, 32.3574
50.385987213, 96.390, 1032.0, 32.1248
50.438508344, 96.390, 1039.0, 32.2335
50.491029474, 96.390, 1019.0, 31.9218
50.543550605, 96.390, 1020.0, 31.9374
50.596071736, 96.390, 1016.0, 31.8748
50.648592866, 96.390, 1021.0, 31.9531
50.701113997, 96.390, 1039.0, 32.2335
50.753635128, 96.390, 1053.0, 32.4500
50.806156258, 96.390, 1033.0, 32.1403
50.858677389, 96.390, 1031.0, 32.1092
50.911198520, 96.390, 1073.0, 32.7567
50.963719651, 96.390, 1042.0, 32.2800
51.016240781, 96.390, 1066.0, 32.6497
51.068761912, 96.390, 1022.0, 31.9687
51.121283043, 96.390, 1026.0, 32.0312
51.173804173, 96.390, 1051.0, 32.4191
51.226325304, 96.390, 1036.0, 32.1870
51.278846435, 96.390, 986.0, 31.4006
51.331367566, 96.390, 1051.0, 32.4191
51.383888696, 96.390, 1014.0, 31.8434
51.436409827, 96.390, 1051.0, 32.4191
51.488930958, 96.390, 1025.0, 32.0156
51.541452088, 96.390, 948.0, 30.7896
51.593973219, 96.390, 1028.0, 32.0624
51.646494350, 96.390, 1000.0, 31.6228
51.699015481, 96.390, 1022.0, 31.9687
51.751536611, 96.390, 1005.0, 31.7017
51.804057742, 96.390, 999.0, 31.6070
51.856578873, 96.390, 1002.0, 31.6544
51.909100003, 96.390, 976.0, 31.2410
51.961621134, 96.390, 1026.0, 32.0312
52.014142265, 96.390, 1049.0, 32.3883
52.066663396, 96.390, 950.0, 30.8221
52.119184526, 96.390, 1007.0, 31.7333
52.171705657, 96.390, 995.0, 31.5436
52.224226788, 96.390, 998.0, 31.5911
52.276747918, 96.390, 986.0, 31.4006
52.329269049, 96.390, 995.0, 31.5436
52.381790180, 96.390, 1003.0, 31.6702
52.434311310, 96.390, 938.0, 30.6268
52.486832441, 96.390, 1002.0, 31.6544
52.539353572, 96.390, 1002.0, 31.6544
52.591874703, 96.390, 992.0, 31.4960
52.644395833, 96.390, 987.0, 31.4166
52.696916964, 96.390, 984.0, 31.3688
52.749438095, 96.390, 1003.0, 31.6702
52.801959225, 96.390, 959.0, 30.9677
52.854480356, 96.390, 965.0, 31.0644
52.907001487, 96.390, 977.0, 31.2570
52.959522618, 96.390, 988.0, 31.4325
53.012043748, 96.390, 1010.0, 31.7805
53.064564879, 96.390, 1099.0, 33.1512
53.117086010, 96.390, 1006.0, 31.7175
53.169607140, 96.390, 979.0, 31.2890
53.222128271, 96.390, 975.0, 31.2250
53.274649402, 96.390, 942.0, 30.6920
53.327170533, 96.390, 1009.0, 31.7648
53.379691663, 96.390, 979.0, 31.2890
53.432212794, 96.390, 947.0, 30.7734
53.484733925, 96.390, 962.0, 31.0161
53.537255055, 96.390, 931.0, 30.5123
53.589776186, 96.390, 1059.0, 32.5423
53.642297317, 96.390, 1002.0, 31.6544
53.694818448, 96.390, 948.0, 30.7896
53.747339578, 96.390, 988.0, 31.4325
53.799860709, 96.390, 976.0, 31.2410
53.852381840, 96.390, 969.0, 31.1288
53.904902970, 96.390, 1005.0, 31.7017
53.957424101, 96.390, 991.0, 31.4802
54.009945232, 96.390, 1010.0, 31.7805
54.062466362, 96.390, 920.0, 30.3315
54.114987493, 96.390, 998.0, 31.5911
54.167508624, 96.390, 1005.0, 31.7017
54.220029755, 96.390, 927.0, 30.4467
54.272550885, 96.390, 925.0, 30.4138
54.325072016, 96.390, 939.0, 30.6431
54.377593147, 96.390, 981.0, 31.3209
54.430114277, 96.390, 972.0, 31.1769
54.482635408, 96.390, 1048.0, 32.3728
54.535156539, 96.390, 933.0, 30.5450
54.587677670, 96.390, 985.0, 31.3847
54.640198800, 96.390, 996.0, 31.5595
54.692719931, 96.390, 962.0, 31.0161
54.745241062, 96.390, 954.0, 30.8869
54.797762192, 96.390, 948.0, 30.7896
54.850283323, 96.390, 993.0, 31.5119
54.902804454, 96.390, 1001.0, 31.6386
54.955325585, 96.390, 990.0, 31.4643
55.007846715, 96.390, 934.0, 30.5614
55.060367846, 96.390, 905.0, 30.0832
55.112888977, 96.390, 956.0, 30.9192
55.165410107, 96.390, 973.0, 31.1929
55.217931238, 96.390, 919.0, 30.3150
55.270452369, 96.390, 1017.0, 31.8904
55.322973499, 96.390, 978.0, 31.2730
55.375494630, 96.390, 969.0, 31.1288
55.428015761, 96.390, 972.0, 31.1769
55.480536892, 96.390, 953.0, 30.8707
55.533058022, 96.390, 909.0, 30.1496
55.585579153, 96.390, 981.0, 31.3209
55.638100284, 96.390, 970.0, 31.1448
55.690621414, 96.390, 1009.0, 31.7648
55.743142545, 96.390, 929.0, 30.4795
55.795663676, 96.390, 921.0, 30.3480
55.848184807, 96.390, 909.0, 30.1496
55.900705937, 96.390, 956.0, 30.9192
55.953227068, 96.390, 955.0, 30.9031
56.005748199, 96.390, 969.0, 31.1288
56.058269329, 96.390, 961.0, 31.0000
56.110790460, 96.390, 972.0, 31.1769
56.163311591, 96.390, 1026.0, 32.0312
56.215832722, 96.390, 914.0, 30.2324
56.268353852, 96.390, 943.0, 30.7083
56.320874983, 96.390, 950.0, 30.8221
56.373396114, 96.390, 963.0, 31.0322
56.425917244, 96.390, 928.0, 30.4631
56.478438375, 96.390, 947.0, 30.7734
56.530959506, 96.390, 928.0, 30.4631
56.583480637, 96.390, 923.0, 30.3809
56.636001767, 96.390, 938.0, 30.6268
56.688522898, 96.390, 926.0, 30.4302
56.741044029, 96.390, 923.0, 30.3809
56.793565159, 96.390, 944.0, 30.7246
56.846086290, 96.390, 951.0, 30.8383
56.898607421, 96.390, 929.0, 30.4795
56.951128551, 96.390, 944.0, 30.7246
57.003649682, 96.390, 935.0, 30.5778
57.056170813, 96.390, 986.0, 31.4006
57.108691944, 96.390, 1000.0, 31.6228
57.161213074, 96.390, 962.0, 31.0161
57.213734205, 96.390, 946.0, 30.7571
57.266255336, 96.390, 958.0, 30.9516
57.318776466, 96.390, 977.0, 31.2570
57.371297597, 96.390, 941.0, 30.6757
57.423818728, 96.390, 933.0, 30.5450
57.476339859, 96.390, 1012.0, 31.8119
57.528860989, 96.390, 930.0, 30.4959
57.581382120, 96.390, 926.0, 30.4302
57.633903251, 96.390, 941.0, 30.6757
57.686424381, 96.390, 903.0, 30.0500
57.738945512, 96.390, 950.0, 30.8221
57.791466643, 96.390, 927.0, 30.4467
57.843987774, 96.390, 890.0, 29.8329
57.896508904, 96.390, 959.0, 30.9677
57.949030035, 96.390, 919.0, 30.3150
58.001551166, 96.390, 963.0, 31.0322
58.054072296, 96.390, 931.0, 30.5123
58.106593427, 96.390, 849.0, 29.1376
58.159114558, 96.390, 926.0, 30.4302
58.211635689, 96.390, 945.0, 30.7409
58.264156819, 96.390, 912.0, 30.1993
58.316677950, 96.390, 947.0, 30.7734
58.369199081, 96.390, 912.0, 30.1993
58.421720211, 96.390, 951.0, 30.8383
58.474241342, 96.390, 924.0, 30.3974
58.526762473, 96.390, 895.0, 29.9166
58.579283603, 96.390, 976.0, 31.2410
58.631804734, 96.390, 943.0, 30.7083
58.684325865, 96.390, 916.0, 30.2655
58.736846996, 96.390, 948.0, 30.7896
58.789368126, 96.390, 910.0, 30.1662
58.841889257, 96.390, 881.0, 29.6816
58.894410388, 96.390, 917.0, 30.2820
58.946931518, 96.390, 958.0, 30.9516
58.999452649, 96.390, 965.0, 31.0644
59.051973780, 96.390, 930.0, 30.4959
59.104494911, 96.390, 977.0, 31.2570
59.157016041, 96.390, 972.0, 31.1769
59.209537172, 96.390, 884.0, 29.7321
59.262058303, 96.390, 995.0, 31.5436
59.314579433, 96.390, 977.0, 31.2570
59.367100564, 96.390, 897.0, 29.9500
59.419621695, 96.390, 981.0, 31.3209
59.472142826, 96.390, 1001.0, 31.6386
59.524663956, 96.390, 968.0, 31.1127
59.577185087, 96.390, 867.0, 29.4449
59.629706218, 96.390, 908.0, 30.1330
59.682227348, 96.390, 958.0, 30.9516
59.734748479, 96.390, 961.0, 31.0000
59.787269610, 96.390, 947.0, 30.7734
59.839790740, 96.390, 932.0, 30.5287
59.892311871, 96.390, 916.0, 30.2655
59.944833002, 96.390, 948.0, 30.7896
59.997354133, 96.390, 931.0, 30.5123
60.049875263, 96.390, 981.0, 31.3209
60.102396394, 96.390, 1008.0, 31.7490
60.154917525, 96.390, 921.0, 30.3480
60.207438655, 96.390, 935.0, 30.5778
60.259959786, 96.390, 1008.0, 31.7490
60.312480917, 96.390, 918.0, 30.2985
60.365002048, 96.390, 971.0, 31.1609
60.417523178, 96.390, 977.0, 31.2570
60.470044309, 96.390, 931.0, 30.5123
60.522565440, 96.390, 918.0, 30.2985
60.575086570, 96.390, 959.0, 30.9677
60.627607701, 96.390, 1036.0, 32.1870
60.680128832, 96.390, 927.0, 30.4467
60.732649963, 96.390, 965.0, 31.0644
60.785171093, 96.390, 1003.0, 31.6702
60.837692224, 96.390, 997.0, 31.5753
60.890213355, 96.390, 1021.0, 31.9531
60.942734485, 96.390, 985.0, 31.3847
60.995255616, 96.390, 1040.0, 32.2490
61.047776747, 96.390, 1023.0, 31.9844
61.100297878, 96.390, 963.0, 31.0322
61.152819008, 96.390, 1078.0, 32.8329
61.205340139, 96.390, 1030.0, 32.0936
61.257861270, 96.390, 1049.0, 32.3883
61.310382400, 96.390, 1020.0, 31.9374
61.362903531, 96.390, 1076.0, 32.8024
61.415424662, 96.390, 1006.0, 31.7175
61.467945792, 96.390, 1039.0, 32.2335
61.520466923, 96.390, 1026.0, 32.0312
61.572988054, 96.390, 1008.0, 31.7490
61.625509185, 96.390, 1023.0, 31.9844
61.678030315, 96.390, 1002.0, 31.6544
61.730551446, 96.390, 966.0, 31.0805
61.783072577, 96.390, 1009.0, 31.7648
61.835593707, 96.390, 1045.0, 32.3265
61.888114838, 96.390, 1027.0, 32.0468
61.940635969, 96.390, 1035.0, 32.1714
61.993157100, 96.390, 1010.0, 31.7805
62.045678230, 96.390, 1028.0, 32.0624
62.098199361, 96.390, 1092.0, 33.0454
62.150720492, 96.390, 1024.0, 32.0000
62.203241622, 96.390, 1008.0, 31.7490
62.255762753, 96.390, 1061.0, 32.5730
62.308283884, 96.390, 962.0, 31.0161
62.360805015, 96.390, 1007.0, 31.7333
62.413326145, 96.390, 1017.0, 31.8904
62.465847276, 96.390, 986.0, 31.4006
62.518368407, 96.390, 942.0, 30.6920
62.570889537, 96.390, 991.0, 31.4802
62.623410668, 96.390, 969.0, 31.1288
62.675931799, 96.390, 992.0, 31.4960
62.728452930, 96.390, 978.0, 31.2730
62.780974060, 96.390, 995.0, 31.5436
62.833495191, 96.390, 949.0, 30.8058
62.886016322, 96.390, 979.0, 31.2890
62.938537452, 96.390, 936.0, 30.5941
62.991058583, 96.390, 938.0, 30.6268
63.043579714, 96.390, 988.0, 31.4325
63.096100844, 96.390, 929.0, 30.4795
63.148621975, 96.390, 926.0, 30.4302
63.201143106, 96.390, 948.0, 30.7896
63.253664237, 96.390, 962.0, 31.0161
63.306185367, 96.390, 947.0, 30.7734
63.358706498, 96.390, 932.0, 30.5287
63.411227629, 96.390, 968.0, 31.1127
63.463748759, 96.390, 929.0, 30.4795
63.516269890, 96.390, 896.0, 29.9333
63.568791021, 96.390, 894.0, 29.8998
63.621312152, 96.390, 954.0, 30.8869
63.673833282, 96.390, 930.0, 30.4959
63.726354413, 96.390, 893.0, 29.8831
63.778875544, 96.390, 870.0, 29.4958
63.831396674, 96.390, 914.0, 30.2324
63.883917805, 96.390, 912.0, 30.1993
63.936438936, 96.390, 867.0, 29.4449
63.988960067, 96.390, 934.0, 30.5614
64.041481197, 96.390, 932.0, 30.5287
64.094002328, 96.390, 935.0, 30.5778
64.146523459, 96.390, 877.0, 29.6142
64.199044589, 96.390, 866.0, 29.4279
64.251565720, 96.390, 878.0, 29.6311
64.304086851, 96.390, 894.0, 29.8998
64.356607981, 96.390, 876.0, 29.5973
64.409129112, 96.390, 918.0, 30.2985
64.461650243, 96.390, 898.0, 29.9666
64.514171374, 96.390, 870.0, 29.4958
64.566692504, 96.390, 870.0, 29.4958
64.619213635, 96.390, 881.0, 29.6816
64.671734766, 96.390, 852.0, 29.1890
64.724255896, 96.390, 935.0, 30.5778
64.776777027, 96.390, 866.0, 29.4279
64.829298158, 96.390, 854.0, 29.2233
64.881819289, 96.390, 870.0, 29.4958
64.934340419, 96.390, 841.0, 29.0000
64.986861550, 96.390, 857.0, 29.2746