File: Files_organized_for_plots/Constant_NaOH_1mL10M_to_1gPC_28Day/XRD_P04Free14Apr22_Act03May22_B1_0065M_TSP_LS0111_1.csv
[Measurement conditions]
Sample identification,XRD_P04Free14Apr22_Act03May22_B1_0065M_TSP_LS0111_1
Comment - 1,"Configuration=Stage for Flat Samples/Holders, Owner=User-1, Creation date=7/1/2020 9:53:24 AM"
Comment - 2,"Goniometer=Theta/Theta; Minimum step size 2Theta:0.0001; Minimum step size Omega:0.0001"
Comment - 3,"Sample stage=Stage for flat samples/holders"
Comment - 4,"Diffractometer system=EMPYREAN"
Comment - 5,"Measurement program=C:\Users\ibo5034\OneDrive - The Pennsylvania State University\NEUP\Zerobackground scan.xrdmp, Identifier={98A3B11C-88F9-4AA6-982C-73314A311EF5}"
Anode material,Cu
K-Alpha1 wavelength,1.5405980
K-Alpha2 wavelength,1.5444260
Ratio K-Alpha2/K-Alpha1,0.500
Divergence slit,Fixed,0.25
Monochromator used,NO
Generator voltage, 45
Tube current, 40
File date and time,03/Jun/2022 16:32
Unit cell,
h k l, 0 0 0
Scan axis,Gonio
Scan range,4.994599997,64.999991833
Scan step size,0.0262606
No. of points, 2285
Scan type,CONTINUOUS
Time per step,96.390
[Scan points]
Angle, TimePerStep, Intensity, ESD
5.007730280, 96.390, 5609.0, 74.8933
5.060251411, 96.390, 5465.0, 73.9256
5.112772541, 96.390, 5520.0, 74.2967
5.165293672, 96.390, 5385.0, 73.3826
5.217814803, 96.390, 5204.0, 72.1388
5.270335934, 96.390, 5161.0, 71.8401
5.322857064, 96.390, 5152.0, 71.7774
5.375378195, 96.390, 5192.0, 72.0555
5.427899326, 96.390, 5029.0, 70.9154
5.480420456, 96.390, 5137.0, 71.6729
5.532941587, 96.390, 5020.0, 70.8520
5.585462718, 96.390, 5006.0, 70.7531
5.637983849, 96.390, 4952.0, 70.3704
5.690504979, 96.390, 4794.0, 69.2387
5.743026110, 96.390, 4731.0, 68.7823
5.795547241, 96.390, 4822.0, 69.4406
5.848068371, 96.390, 4782.0, 69.1520
5.900589502, 96.390, 4871.0, 69.7925
5.953110633, 96.390, 4675.0, 68.3740
6.005631763, 96.390, 4742.0, 68.8622
6.058152894, 96.390, 4790.0, 69.2098
6.110674025, 96.390, 4635.0, 68.0808
6.163195156, 96.390, 4501.0, 67.0895
6.215716286, 96.390, 4525.0, 67.2681
6.268237417, 96.390, 4554.0, 67.4833
6.320758548, 96.390, 4514.0, 67.1863
6.373279678, 96.390, 4515.0, 67.1937
6.425800809, 96.390, 4434.0, 66.5883
6.478321940, 96.390, 4500.0, 67.0820
6.530843071, 96.390, 4386.0, 66.2269
6.583364201, 96.390, 4338.0, 65.8635
6.635885332, 96.390, 4162.0, 64.5136
6.688406463, 96.390, 4244.0, 65.1460
6.740927593, 96.390, 4383.0, 66.2042
6.793448724, 96.390, 4288.0, 65.4828
6.845969855, 96.390, 4273.0, 65.3682
6.898490986, 96.390, 4292.0, 65.5134
6.951012116, 96.390, 4188.0, 64.7148
7.003533247, 96.390, 4234.0, 65.0692
7.056054378, 96.390, 4230.0, 65.0385
7.108575508, 96.390, 4202.0, 64.8228
7.161096639, 96.390, 4230.0, 65.0385
7.213617770, 96.390, 4264.0, 65.2993
7.266138900, 96.390, 4208.0, 64.8691
7.318660031, 96.390, 4129.0, 64.2573
7.371181162, 96.390, 4089.0, 63.9453
7.423702293, 96.390, 4142.0, 64.3584
7.476223423, 96.390, 4034.0, 63.5138
7.528744554, 96.390, 4108.0, 64.0937
7.581265685, 96.390, 4003.0, 63.2693
7.633786815, 96.390, 4009.0, 63.3167
7.686307946, 96.390, 4030.0, 63.4823
7.738829077, 96.390, 3949.0, 62.8411
7.791350208, 96.390, 3961.0, 62.9365
7.843871338, 96.390, 4001.0, 63.2535
7.896392469, 96.390, 3853.0, 62.0725
7.948913600, 96.390, 3911.0, 62.5380
8.001434730, 96.390, 4015.0, 63.3640
8.053955861, 96.390, 4021.0, 63.4114
8.106476992, 96.390, 3957.0, 62.9047
8.158998123, 96.390, 3878.0, 62.2736
8.211519253, 96.390, 3760.0, 61.3188
8.264040384, 96.390, 3883.0, 62.3137
8.316561515, 96.390, 3911.0, 62.5380
8.369082645, 96.390, 3880.0, 62.2896
8.421603776, 96.390, 3941.0, 62.7774
8.474124907, 96.390, 3883.0, 62.3137
8.526646038, 96.390, 3911.0, 62.5380
8.579167168, 96.390, 3937.0, 62.7455
8.631688299, 96.390, 3708.0, 60.8933
8.684209430, 96.390, 3913.0, 62.5540
8.736730560, 96.390, 3713.0, 60.9344
8.789251691, 96.390, 3838.0, 61.9516
8.841772822, 96.390, 3875.0, 62.2495
8.894293952, 96.390, 3792.0, 61.5792
8.946815083, 96.390, 3772.0, 61.4166
8.999336214, 96.390, 3761.0, 61.3270
9.051857345, 96.390, 3704.0, 60.8605
9.104378475, 96.390, 3770.0, 61.4003
9.156899606, 96.390, 3807.0, 61.7009
9.209420737, 96.390, 3784.0, 61.5142
9.261941867, 96.390, 3713.0, 60.9344
9.314462998, 96.390, 3762.0, 61.3351
9.366984129, 96.390, 3762.0, 61.3351
9.419505260, 96.390, 3647.0, 60.3904
9.472026390, 96.390, 3793.0, 61.5873
9.524547521, 96.390, 3731.0, 61.0819
9.577068652, 96.390, 3662.0, 60.5145
9.629589782, 96.390, 3639.0, 60.3241
9.682110913, 96.390, 3744.0, 61.1882
9.734632044, 96.390, 3857.0, 62.1048
9.787153175, 96.390, 3706.0, 60.8769
9.839674305, 96.390, 3671.0, 60.5888
9.892195436, 96.390, 3752.0, 61.2536
9.944716567, 96.390, 3612.0, 60.0999
9.997237697, 96.390, 3752.0, 61.2536
10.049758828, 96.390, 3684.0, 60.6960
10.102279959, 96.390, 3730.0, 61.0737
10.154801090, 96.390, 3637.0, 60.3075
10.207322220, 96.390, 3792.0, 61.5792
10.259843351, 96.390, 3658.0, 60.4814
10.312364482, 96.390, 3733.0, 61.0983
10.364885612, 96.390, 3704.0, 60.8605
10.417406743, 96.390, 3711.0, 60.9180
10.469927874, 96.390, 3845.0, 62.0081
10.522449004, 96.390, 3756.0, 61.2862
10.574970135, 96.390, 3694.0, 60.7783
10.627491266, 96.390, 3618.0, 60.1498
10.680012397, 96.390, 3607.0, 60.0583
10.732533527, 96.390, 3717.0, 60.9672
10.785054658, 96.390, 3743.0, 61.1801
10.837575789, 96.390, 3735.0, 61.1146
10.890096919, 96.390, 3796.0, 61.6117
10.942618050, 96.390, 3827.0, 61.8628
10.995139181, 96.390, 3722.0, 61.0082
11.047660312, 96.390, 3805.0, 61.6847
11.100181442, 96.390, 3940.0, 62.7694
11.152702573, 96.390, 3959.0, 62.9206
11.205223704, 96.390, 4050.0, 63.6396
11.257744834, 96.390, 3990.0, 63.1664
11.310265965, 96.390, 3941.0, 62.7774
11.362787096, 96.390, 4071.0, 63.8044
11.415308227, 96.390, 4151.0, 64.4283
11.467829357, 96.390, 4267.0, 65.3223
11.520350488, 96.390, 4275.0, 65.3835
11.572871619, 96.390, 4317.0, 65.7039
11.625392749, 96.390, 4386.0, 66.2269
11.677913880, 96.390, 4363.0, 66.0530
11.730435011, 96.390, 4191.0, 64.7379
11.782956141, 96.390, 4123.0, 64.2106
11.835477272, 96.390, 3923.0, 62.6339
11.887998403, 96.390, 3798.0, 61.6279
11.940519534, 96.390, 3780.0, 61.4817
11.993040664, 96.390, 3530.0, 59.4138
12.045561795, 96.390, 3403.0, 58.3352
12.098082926, 96.390, 3449.0, 58.7282
12.150604056, 96.390, 3358.0, 57.9483
12.203125187, 96.390, 3166.0, 56.2672
12.255646318, 96.390, 3242.0, 56.9386
12.308167449, 96.390, 3183.0, 56.4181
12.360688579, 96.390, 3134.0, 55.9821
12.413209710, 96.390, 3053.0, 55.2540
12.465730841, 96.390, 3135.0, 55.9911
12.518251971, 96.390, 3020.0, 54.9545
12.570773102, 96.390, 3104.0, 55.7136
12.623294233, 96.390, 2933.0, 54.1572
12.675815364, 96.390, 2910.0, 53.9444
12.728336494, 96.390, 2838.0, 53.2729
12.780857625, 96.390, 2891.0, 53.7680
12.833378756, 96.390, 2885.0, 53.7122
12.885899886, 96.390, 2852.0, 53.4041
12.938421017, 96.390, 2853.0, 53.4135
12.990942148, 96.390, 2729.0, 52.2398
13.043463279, 96.390, 2814.0, 53.0471
13.095984409, 96.390, 2728.0, 52.2303
13.148505540, 96.390, 2617.0, 51.1566
13.201026671, 96.390, 2680.0, 51.7687
13.253547801, 96.390, 2713.0, 52.0865
13.306068932, 96.390, 2631.0, 51.2933
13.358590063, 96.390, 2710.0, 52.0577
13.411111193, 96.390, 2690.0, 51.8652
13.463632324, 96.390, 2695.0, 51.9134
13.516153455, 96.390, 2558.0, 50.5767
13.568674586, 96.390, 2529.0, 50.2892
13.621195716, 96.390, 2644.0, 51.4198
13.673716847, 96.390, 2452.0, 49.5177
13.726237978, 96.390, 2606.0, 51.0490
13.778759108, 96.390, 2572.0, 50.7149
13.831280239, 96.390, 2519.0, 50.1896
13.883801370, 96.390, 2454.0, 49.5379
13.936322501, 96.390, 2522.0, 50.2195
13.988843631, 96.390, 2508.0, 50.0799
14.041364762, 96.390, 2497.0, 49.9700
14.093885893, 96.390, 2334.0, 48.3115
14.146407023, 96.390, 2420.0, 49.1935
14.198928154, 96.390, 2410.0, 49.0918
14.251449285, 96.390, 2482.0, 49.8197
14.303970416, 96.390, 2399.0, 48.9796
14.356491546, 96.390, 2381.0, 48.7955
14.409012677, 96.390, 2357.0, 48.5489
14.461533808, 96.390, 2427.0, 49.2646
14.514054938, 96.390, 2361.0, 48.5901
14.566576069, 96.390, 2250.0, 47.4342
14.619097200, 96.390, 2315.0, 48.1144
14.671618331, 96.390, 2261.0, 47.5500
14.724139461, 96.390, 2425.0, 49.2443
14.776660592, 96.390, 2254.0, 47.4763
14.829181723, 96.390, 2265.0, 47.5920
14.881702853, 96.390, 2273.0, 47.6760
14.934223984, 96.390, 2270.0, 47.6445
14.986745115, 96.390, 2343.0, 48.4045
15.039266245, 96.390, 2287.0, 47.8226
15.091787376, 96.390, 2266.0, 47.6025
15.144308507, 96.390, 2261.0, 47.5500
15.196829638, 96.390, 2239.0, 47.3181
15.249350768, 96.390, 2218.0, 47.0956
15.301871899, 96.390, 2284.0, 47.7912
15.354393030, 96.390, 2268.0, 47.6235
15.406914160, 96.390, 2184.0, 46.7333
15.459435291, 96.390, 2246.0, 47.3920
15.511956422, 96.390, 2192.0, 46.8188
15.564477553, 96.390, 2252.0, 47.4552
15.616998683, 96.390, 2155.0, 46.4220
15.669519814, 96.390, 2198.0, 46.8828
15.722040945, 96.390, 2187.0, 46.7654
15.774562075, 96.390, 2223.0, 47.1487
15.827083206, 96.390, 2277.0, 47.7179
15.879604337, 96.390, 2261.0, 47.5500
15.932125468, 96.390, 2064.0, 45.4313
15.984646598, 96.390, 2211.0, 47.0213
16.037167729, 96.390, 2121.0, 46.0543
16.089688860, 96.390, 2074.0, 45.5412
16.142209990, 96.390, 2248.0, 47.4131
16.194731121, 96.390, 2183.0, 46.7226
16.247252252, 96.390, 2234.0, 47.2652
16.299773382, 96.390, 2158.0, 46.4543
16.352294513, 96.390, 2274.0, 47.6865
16.404815644, 96.390, 2181.0, 46.7012
16.457336775, 96.390, 2152.0, 46.3897
16.509857905, 96.390, 2259.0, 47.5289
16.562379036, 96.390, 2168.0, 46.5618
16.614900167, 96.390, 2212.0, 47.0319
16.667421297, 96.390, 2204.0, 46.9468
16.719942428, 96.390, 2156.0, 46.4327
16.772463559, 96.390, 2192.0, 46.8188
16.824984690, 96.390, 2188.0, 46.7761
16.877505820, 96.390, 2216.0, 47.0744
16.930026951, 96.390, 2153.0, 46.4004
16.982548082, 96.390, 2167.0, 46.5510
17.035069212, 96.390, 2247.0, 47.4025
17.087590343, 96.390, 2134.0, 46.1952
17.140111474, 96.390, 2167.0, 46.5510
17.192632605, 96.390, 2242.0, 47.3498
17.245153735, 96.390, 2158.0, 46.4543
17.297674866, 96.390, 2199.0, 46.8935
17.350195997, 96.390, 2208.0, 46.9894
17.402717127, 96.390, 2201.0, 46.9148
17.455238258, 96.390, 2272.0, 47.6655
17.507759389, 96.390, 2272.0, 47.6655
17.560280520, 96.390, 2146.0, 46.3249
17.612801650, 96.390, 2264.0, 47.5815
17.665322781, 96.390, 2266.0, 47.6025
17.717843912, 96.390, 2202.0, 46.9255
17.770365042, 96.390, 2261.0, 47.5500
17.822886173, 96.390, 2228.0, 47.2017
17.875407304, 96.390, 2220.0, 47.1169
17.927928434, 96.390, 2194.0, 46.8402
17.980449565, 96.390, 2235.0, 47.2758
18.032970696, 96.390, 2177.0, 46.6583
18.085491827, 96.390, 2318.0, 48.1456
18.138012957, 96.390, 2256.0, 47.4974
18.190534088, 96.390, 2232.0, 47.2440
18.243055219, 96.390, 2298.0, 47.9375
18.295576349, 96.390, 2259.0, 47.5289
18.348097480, 96.390, 2348.0, 48.4562
18.400618611, 96.390, 2315.0, 48.1144
18.453139742, 96.390, 2244.0, 47.3709
18.505660872, 96.390, 2314.0, 48.1041
18.558182003, 96.390, 2337.0, 48.3425
18.610703134, 96.390, 2330.0, 48.2701
18.663224264, 96.390, 2299.0, 47.9479
18.715745395, 96.390, 2315.0, 48.1144
18.768266526, 96.390, 2162.0, 46.4973
18.820787657, 96.390, 2418.0, 49.1732
18.873308787, 96.390, 2397.0, 48.9592
18.925829918, 96.390, 2421.0, 49.2037
18.978351049, 96.390, 2324.0, 48.2079
19.030872179, 96.390, 2390.0, 48.8876
19.083393310, 96.390, 2442.0, 49.4166
19.135914441, 96.390, 2395.0, 48.9387
19.188435572, 96.390, 2399.0, 48.9796
19.240956702, 96.390, 2434.0, 49.3356
19.293477833, 96.390, 2503.0, 50.0300
19.345998964, 96.390, 2471.0, 49.7092
19.398520094, 96.390, 2493.0, 49.9300
19.451041225, 96.390, 2485.0, 49.8498
19.503562356, 96.390, 2484.0, 49.8397
19.556083486, 96.390, 2481.0, 49.8096
19.608604617, 96.390, 2459.0, 49.5883
19.661125748, 96.390, 2566.0, 50.6557
19.713646879, 96.390, 2541.0, 50.4083
19.766168009, 96.390, 2470.0, 49.6991
19.818689140, 96.390, 2588.0, 50.8724
19.871210271, 96.390, 2568.0, 50.6754
19.923731401, 96.390, 2588.0, 50.8724
19.976252532, 96.390, 2666.0, 51.6333
20.028773663, 96.390, 2540.0, 50.3984
20.081294794, 96.390, 2602.0, 51.0098
20.133815924, 96.390, 2689.0, 51.8556
20.186337055, 96.390, 2561.0, 50.6063
20.238858186, 96.390, 2567.0, 50.6656
20.291379316, 96.390, 2657.0, 51.5461
20.343900447, 96.390, 2718.0, 52.1344
20.396421578, 96.390, 2699.0, 51.9519
20.448942709, 96.390, 2725.0, 52.2015
20.501463839, 96.390, 2640.0, 51.3809
20.553984970, 96.390, 2692.0, 51.8845
20.606506101, 96.390, 2697.0, 51.9326
20.659027231, 96.390, 2727.0, 52.2207
20.711548362, 96.390, 2614.0, 51.1273
20.764069493, 96.390, 2703.0, 51.9904
20.816590623, 96.390, 2728.0, 52.2303
20.869111754, 96.390, 2768.0, 52.6118
20.921632885, 96.390, 2769.0, 52.6213
20.974154016, 96.390, 2810.0, 53.0094
21.026675146, 96.390, 2745.0, 52.3927
21.079196277, 96.390, 2843.0, 53.3198
21.131717408, 96.390, 2831.0, 53.2071
21.184238538, 96.390, 2718.0, 52.1344
21.236759669, 96.390, 2723.0, 52.1824
21.289280800, 96.390, 2761.0, 52.5452
21.341801931, 96.390, 2885.0, 53.7122
21.394323061, 96.390, 2859.0, 53.4696
21.446844192, 96.390, 2811.0, 53.0189
21.499365323, 96.390, 2797.0, 52.8867
21.551886453, 96.390, 2877.0, 53.6377
21.604407584, 96.390, 2918.0, 54.0185
21.656928715, 96.390, 2913.0, 53.9722
21.709449846, 96.390, 2903.0, 53.8795
21.761970976, 96.390, 2938.0, 54.2033
21.814492107, 96.390, 2929.0, 54.1202
21.867013238, 96.390, 2874.0, 53.6097
21.919534368, 96.390, 2933.0, 54.1572
21.972055499, 96.390, 2886.0, 53.7215
22.024576630, 96.390, 2870.0, 53.5724
22.077097761, 96.390, 2861.0, 53.4883
22.129618891, 96.390, 2949.0, 54.3047
22.182140022, 96.390, 2909.0, 53.9351
22.234661153, 96.390, 3031.0, 55.0545
22.287182283, 96.390, 2873.0, 53.6004
22.339703414, 96.390, 3002.0, 54.7905
22.392224545, 96.390, 3007.0, 54.8361
22.444745675, 96.390, 2980.0, 54.5894
22.497266806, 96.390, 2903.0, 53.8795
22.549787937, 96.390, 2989.0, 54.6717
22.602309068, 96.390, 3021.0, 54.9636
22.654830198, 96.390, 2995.0, 54.7266
22.707351329, 96.390, 2897.0, 53.8238
22.759872460, 96.390, 3008.0, 54.8452
22.812393590, 96.390, 2925.0, 54.0833
22.864914721, 96.390, 3016.0, 54.9181
22.917435852, 96.390, 3053.0, 55.2540
22.969956983, 96.390, 3156.0, 56.1783
23.022478113, 96.390, 3112.0, 55.7853
23.074999244, 96.390, 3040.0, 55.1362
23.127520375, 96.390, 3180.0, 56.3915
23.180041505, 96.390, 3216.0, 56.7098
23.232562636, 96.390, 3171.0, 56.3116
23.285083767, 96.390, 3189.0, 56.4712
23.337604898, 96.390, 3179.0, 56.3826
23.390126028, 96.390, 3214.0, 56.6922
23.442647159, 96.390, 3198.0, 56.5509
23.495168290, 96.390, 3156.0, 56.1783
23.547689420, 96.390, 3155.0, 56.1694
23.600210551, 96.390, 3109.0, 55.7584
23.652731682, 96.390, 3032.0, 55.0636
23.705252813, 96.390, 3042.0, 55.1543
23.757773943, 96.390, 2993.0, 54.7083
23.810295074, 96.390, 2871.0, 53.5817
23.862816205, 96.390, 2915.0, 53.9907
23.915337335, 96.390, 2860.0, 53.4790
23.967858466, 96.390, 2816.0, 53.0660
24.020379597, 96.390, 2741.0, 52.3546
24.072900727, 96.390, 2700.0, 51.9615
24.125421858, 96.390, 2784.0, 52.7636
24.177942989, 96.390, 2709.0, 52.0481
24.230464120, 96.390, 2728.0, 52.2303
24.282985250, 96.390, 2687.0, 51.8363
24.335506381, 96.390, 2707.0, 52.0288
24.388027512, 96.390, 2681.0, 51.7784
24.440548642, 96.390, 2632.0, 51.3030
24.493069773, 96.390, 2561.0, 50.6063
24.545590904, 96.390, 2589.0, 50.8822
24.598112035, 96.390, 2605.0, 51.0392
24.650633165, 96.390, 2564.0, 50.6360
24.703154296, 96.390, 2545.0, 50.4480
24.755675427, 96.390, 2588.0, 50.8724
24.808196557, 96.390, 2537.0, 50.3686
24.860717688, 96.390, 2490.0, 49.8999
24.913238819, 96.390, 2569.0, 50.6853
24.965759950, 96.390, 2474.0, 49.7393
25.018281080, 96.390, 2555.0, 50.5470
25.070802211, 96.390, 2467.0, 49.6689
25.123323342, 96.390, 2413.0, 49.1223
25.175844472, 96.390, 2478.0, 49.7795
25.228365603, 96.390, 2496.0, 49.9600
25.280886734, 96.390, 2514.0, 50.1398
25.333407864, 96.390, 2476.0, 49.7594
25.385928995, 96.390, 2487.0, 49.8698
25.438450126, 96.390, 2414.0, 49.1325
25.490971257, 96.390, 2428.0, 49.2747
25.543492387, 96.390, 2396.0, 48.9490
25.596013518, 96.390, 2407.0, 49.0612
25.648534649, 96.390, 2338.0, 48.3529
25.701055779, 96.390, 2413.0, 49.1223
25.753576910, 96.390, 2452.0, 49.5177
25.806098041, 96.390, 2362.0, 48.6004
25.858619172, 96.390, 2238.0, 47.3075
25.911140302, 96.390, 2336.0, 48.3322
25.963661433, 96.390, 2349.0, 48.4665
26.016182564, 96.390, 2293.0, 47.8853
26.068703694, 96.390, 2333.0, 48.3011
26.121224825, 96.390, 2396.0, 48.9490
26.173745956, 96.390, 2337.0, 48.3425
26.226267087, 96.390, 2287.0, 47.8226
26.278788217, 96.390, 2296.0, 47.9166
26.331309348, 96.390, 2288.0, 47.8330
26.383830479, 96.390, 2252.0, 47.4552
26.436351609, 96.390, 2206.0, 46.9681
26.488872740, 96.390, 2302.0, 47.9792
26.541393871, 96.390, 2345.0, 48.4252
26.593915002, 96.390, 2315.0, 48.1144
26.646436132, 96.390, 2175.0, 46.6369
26.698957263, 96.390, 2246.0, 47.3920
26.751478394, 96.390, 2203.0, 46.9361
26.803999524, 96.390, 2245.0, 47.3814
26.856520655, 96.390, 2255.0, 47.4868
26.909041786, 96.390, 2272.0, 47.6655
26.961562916, 96.390, 2251.0, 47.4447
27.014084047, 96.390, 2257.0, 47.5079
27.066605178, 96.390, 2290.0, 47.8539
27.119126309, 96.390, 2300.0, 47.9583
27.171647439, 96.390, 2194.0, 46.8402
27.224168570, 96.390, 2226.0, 47.1805
27.276689701, 96.390, 2111.0, 45.9456
27.329210831, 96.390, 2225.0, 47.1699
27.381731962, 96.390, 2197.0, 46.8722
27.434253093, 96.390, 2241.0, 47.3392
27.486774224, 96.390, 2207.0, 46.9787
27.539295354, 96.390, 2163.0, 46.5081
27.591816485, 96.390, 2160.0, 46.4758
27.644337616, 96.390, 2075.0, 45.5522
27.696858746, 96.390, 2166.0, 46.5403
27.749379877, 96.390, 2223.0, 47.1487
27.801901008, 96.390, 2248.0, 47.4131
27.854422139, 96.390, 2141.0, 46.2709
27.906943269, 96.390, 2147.0, 46.3357
27.959464400, 96.390, 2161.0, 46.4866
28.011985531, 96.390, 2161.0, 46.4866
28.064506661, 96.390, 2151.0, 46.3789
28.117027792, 96.390, 2205.0, 46.9574
28.169548923, 96.390, 2079.0, 45.5961
28.222070054, 96.390, 2145.0, 46.3141
28.274591184, 96.390, 2113.0, 45.9674
28.327112315, 96.390, 2165.0, 46.5296
28.379633446, 96.390, 2177.0, 46.6583
28.432154576, 96.390, 2127.0, 46.1194
28.484675707, 96.390, 2093.0, 45.7493
28.537196838, 96.390, 2097.0, 45.7930
28.589717968, 96.390, 2116.0, 46.0000
28.642239099, 96.390, 2130.0, 46.1519
28.694760230, 96.390, 2145.0, 46.3141
28.747281361, 96.390, 2057.0, 45.3542
28.799802491, 96.390, 2046.0, 45.2327
28.852323622, 96.390, 2072.0, 45.5192
28.904844753, 96.390, 2068.0, 45.4753
28.957365883, 96.390, 2096.0, 45.7821
29.009887014, 96.390, 2071.0, 45.5082
29.062408145, 96.390, 2087.0, 45.6837
29.114929276, 96.390, 2059.0, 45.3762
29.167450406, 96.390, 2077.0, 45.5741
29.219971537, 96.390, 2126.0, 46.1086
29.272492668, 96.390, 2025.0, 45.0000
29.325013798, 96.390, 2079.0, 45.5961
29.377534929, 96.390, 1979.0, 44.4860
29.430056060, 96.390, 2063.0, 45.4203
29.482577191, 96.390, 1951.0, 44.1701
29.535098321, 96.390, 2001.0, 44.7325
29.587619452, 96.390, 2010.0, 44.8330
29.640140583, 96.390, 2068.0, 45.4753
29.692661713, 96.390, 1957.0, 44.2380
29.745182844, 96.390, 2041.0, 45.1774
29.797703975, 96.390, 1989.0, 44.5982
29.850225105, 96.390, 2002.0, 44.7437
29.902746236, 96.390, 1939.0, 44.0341
29.955267367, 96.390, 1918.0, 43.7950
30.007788498, 96.390, 1907.0, 43.6692
30.060309628, 96.390, 1959.0, 44.2606
30.112830759, 96.390, 1950.0, 44.1588
30.165351890, 96.390, 1872.0, 43.2666
30.217873020, 96.390, 1976.0, 44.4522
30.270394151, 96.390, 1947.0, 44.1248
30.322915282, 96.390, 1894.0, 43.5201
30.375436413, 96.390, 1919.0, 43.8064
30.427957543, 96.390, 1809.0, 42.5323
30.480478674, 96.390, 1959.0, 44.2606
30.532999805, 96.390, 1911.0, 43.7150
30.585520935, 96.390, 1888.0, 43.4511
30.638042066, 96.390, 1876.0, 43.3128
30.690563197, 96.390, 1863.0, 43.1625
30.743084328, 96.390, 1829.0, 42.7668
30.795605458, 96.390, 1857.0, 43.0929
30.848126589, 96.390, 1864.0, 43.1741
30.900647720, 96.390, 1803.0, 42.4617
30.953168850, 96.390, 1905.0, 43.6463
31.005689981, 96.390, 1967.0, 44.3509
31.058211112, 96.390, 1820.0, 42.6615
31.110732243, 96.390, 1810.0, 42.5441
31.163253373, 96.390, 1825.0, 42.7200
31.215774504, 96.390, 1856.0, 43.0813
31.268295635, 96.390, 1810.0, 42.5441
31.320816765, 96.390, 1768.0, 42.0476
31.373337896, 96.390, 1820.0, 42.6615
31.425859027, 96.390, 1787.0, 42.2729
31.478380157, 96.390, 1803.0, 42.4617
31.530901288, 96.390, 1813.0, 42.5793
31.583422419, 96.390, 1810.0, 42.5441
31.635943550, 96.390, 1724.0, 41.5211
31.688464680, 96.390, 1776.0, 42.1426
31.740985811, 96.390, 1763.0, 41.9881
31.793506942, 96.390, 1755.0, 41.8927
31.846028072, 96.390, 1668.0, 40.8412
31.898549203, 96.390, 1698.0, 41.2068
31.951070334, 96.390, 1776.0, 42.1426
32.003591465, 96.390, 1725.0, 41.5331
32.056112595, 96.390, 1726.0, 41.5452
32.108633726, 96.390, 1750.0, 41.8330
32.161154857, 96.390, 1804.0, 42.4735
32.213675987, 96.390, 1731.0, 41.6053
32.266197118, 96.390, 1703.0, 41.2674
32.318718249, 96.390, 1667.0, 40.8289
32.371239380, 96.390, 1702.0, 41.2553
32.423760510, 96.390, 1754.0, 41.8808
32.476281641, 96.390, 1733.0, 41.6293
32.528802772, 96.390, 1645.0, 40.5586
32.581323902, 96.390, 1721.0, 41.4849
32.633845033, 96.390, 1718.0, 41.4488
32.686366164, 96.390, 1743.0, 41.7493
32.738887295, 96.390, 1741.0, 41.7253
32.791408425, 96.390, 1697.0, 41.1947
32.843929556, 96.390, 1701.0, 41.2432
32.896450687, 96.390, 1639.0, 40.4846
32.948971817, 96.390, 1707.0, 41.3159
33.001492948, 96.390, 1710.0, 41.3521
33.054014079, 96.390, 1645.0, 40.5586
33.106535209, 96.390, 1702.0, 41.2553
33.159056340, 96.390, 1724.0, 41.5211
33.211577471, 96.390, 1674.0, 40.9145
33.264098602, 96.390, 1812.0, 42.5676
33.316619732, 96.390, 1691.0, 41.1218
33.369140863, 96.390, 1685.0, 41.0488
33.421661994, 96.390, 1669.0, 40.8534
33.474183124, 96.390, 1670.0, 40.8656
33.526704255, 96.390, 1695.0, 41.1704
33.579225386, 96.390, 1605.0, 40.0625
33.631746517, 96.390, 1705.0, 41.2916
33.684267647, 96.390, 1677.0, 40.9512
33.736788778, 96.390, 1786.0, 42.2611
33.789309909, 96.390, 1680.0, 40.9878
33.841831039, 96.390, 1754.0, 41.8808
33.894352170, 96.390, 1768.0, 42.0476
33.946873301, 96.390, 1773.0, 42.1070
33.999394432, 96.390, 1775.0, 42.1307
34.051915562, 96.390, 1865.0, 43.1856
34.104436693, 96.390, 1874.0, 43.2897
34.156957824, 96.390, 1867.0, 43.2088
34.209478954, 96.390, 1906.0, 43.6578
34.262000085, 96.390, 1982.0, 44.5197
34.314521216, 96.390, 1885.0, 43.4166
34.367042346, 96.390, 1998.0, 44.6990
34.419563477, 96.390, 1929.0, 43.9204
34.472084608, 96.390, 1989.0, 44.5982
34.524605739, 96.390, 2009.0, 44.8219
34.577126869, 96.390, 2107.0, 45.9021
34.629648000, 96.390, 2026.0, 45.0111
34.682169131, 96.390, 2009.0, 44.8219
34.734690261, 96.390, 2137.0, 46.2277
34.787211392, 96.390, 2237.0, 47.2969
34.839732523, 96.390, 2338.0, 48.3529
34.892253654, 96.390, 2415.0, 49.1426
34.944774784, 96.390, 2521.0, 50.2096
34.997295915, 96.390, 2520.0, 50.1996
35.049817046, 96.390, 2335.0, 48.3218
35.102338176, 96.390, 2403.0, 49.0204
35.154859307, 96.390, 2320.0, 48.1664
35.207380438, 96.390, 2156.0, 46.4327
35.259901569, 96.390, 2188.0, 46.7761
35.312422699, 96.390, 2115.0, 45.9891
35.364943830, 96.390, 2124.0, 46.0869
35.417464961, 96.390, 1981.0, 44.5084
35.469986091, 96.390, 2091.0, 45.7275
35.522507222, 96.390, 1984.0, 44.5421
35.575028353, 96.390, 2000.0, 44.7214
35.627549484, 96.390, 2020.0, 44.9444
35.680070614, 96.390, 2013.0, 44.8665
35.732591745, 96.390, 1933.0, 43.9659
35.785112876, 96.390, 1970.0, 44.3847
35.837634006, 96.390, 1873.0, 43.2782
35.890155137, 96.390, 1955.0, 44.2154
35.942676268, 96.390, 1955.0, 44.2154
35.995197398, 96.390, 1824.0, 42.7083
36.047718529, 96.390, 1901.0, 43.6005
36.100239660, 96.390, 1847.0, 42.9767
36.152760791, 96.390, 1869.0, 43.2319
36.205281921, 96.390, 1861.0, 43.1393
36.257803052, 96.390, 1828.0, 42.7551
36.310324183, 96.390, 1770.0, 42.0714
36.362845313, 96.390, 1834.0, 42.8252
36.415366444, 96.390, 1858.0, 43.1045
36.467887575, 96.390, 1804.0, 42.4735
36.520408706, 96.390, 1901.0, 43.6005
36.572929836, 96.390, 1812.0, 42.5676
36.625450967, 96.390, 1769.0, 42.0595
36.677972098, 96.390, 1816.0, 42.6146
36.730493228, 96.390, 1759.0, 41.9404
36.783014359, 96.390, 1769.0, 42.0595
36.835535490, 96.390, 1756.0, 41.9047
36.888056621, 96.390, 1760.0, 41.9524
36.940577751, 96.390, 1763.0, 41.9881
36.993098882, 96.390, 1758.0, 41.9285
37.045620013, 96.390, 1684.0, 41.0366
37.098141143, 96.390, 1750.0, 41.8330
37.150662274, 96.390, 1611.0, 40.1373
37.203183405, 96.390, 1706.0, 41.3038
37.255704535, 96.390, 1716.0, 41.4246
37.308225666, 96.390, 1706.0, 41.3038
37.360746797, 96.390, 1595.0, 39.9375
37.413267928, 96.390, 1649.0, 40.6079
37.465789058, 96.390, 1796.0, 42.3792
37.518310189, 96.390, 1658.0, 40.7185
37.570831320, 96.390, 1709.0, 41.3401
37.623352450, 96.390, 1654.0, 40.6694
37.675873581, 96.390, 1626.0, 40.3237
37.728394712, 96.390, 1594.0, 39.9249
37.780915843, 96.390, 1689.0, 41.0974
37.833436973, 96.390, 1715.0, 41.4126
37.885958104, 96.390, 1642.0, 40.5216
37.938479235, 96.390, 1646.0, 40.5709
37.991000365, 96.390, 1677.0, 40.9512
38.043521496, 96.390, 1641.0, 40.5093
38.096042627, 96.390, 1618.0, 40.2244
38.148563758, 96.390, 1603.0, 40.0375
38.201084888, 96.390, 1576.0, 39.6989
38.253606019, 96.390, 1608.0, 40.0999
38.306127150, 96.390, 1609.0, 40.1123
38.358648280, 96.390, 1619.0, 40.2368
38.411169411, 96.390, 1642.0, 40.5216
38.463690542, 96.390, 1626.0, 40.3237
38.516211673, 96.390, 1595.0, 39.9375
38.568732803, 96.390, 1582.0, 39.7744
38.621253934, 96.390, 1612.0, 40.1497
38.673775065, 96.390, 1631.0, 40.3856
38.726296195, 96.390, 1543.0, 39.2810
38.778817326, 96.390, 1612.0, 40.1497
38.831338457, 96.390, 1635.0, 40.4351
38.883859587, 96.390, 1644.0, 40.5463
38.936380718, 96.390, 1527.0, 39.0768
38.988901849, 96.390, 1667.0, 40.8289
39.041422980, 96.390, 1631.0, 40.3856
39.093944110, 96.390, 1612.0, 40.1497
39.146465241, 96.390, 1669.0, 40.8534
39.198986372, 96.390, 1695.0, 41.1704
39.251507502, 96.390, 1684.0, 41.0366
39.304028633, 96.390, 1657.0, 40.7063
39.356549764, 96.390, 1742.0, 41.7373
39.409070895, 96.390, 1806.0, 42.4971
39.461592025, 96.390, 1829.0, 42.7668
39.514113156, 96.390, 1769.0, 42.0595
39.566634287, 96.390, 1770.0, 42.0714
39.619155417, 96.390, 1782.0, 42.2137
39.671676548, 96.390, 1747.0, 41.7971
39.724197679, 96.390, 1753.0, 41.8688
39.776718810, 96.390, 1633.0, 40.4104
39.829239940, 96.390, 1593.0, 39.9124
39.881761071, 96.390, 1570.0, 39.6232
39.934282202, 96.390, 1627.0, 40.3361
39.986803332, 96.390, 1558.0, 39.4715
40.039324463, 96.390, 1490.0, 38.6005
40.091845594, 96.390, 1446.0, 38.0263
40.144366725, 96.390, 1547.0, 39.3319
40.196887855, 96.390, 1496.0, 38.6782
40.249408986, 96.390, 1467.0, 38.3014
40.301930117, 96.390, 1456.0, 38.1576
40.354451247, 96.390, 1487.0, 38.5616
40.406972378, 96.390, 1390.0, 37.2827
40.459493509, 96.390, 1394.0, 37.3363
40.512014639, 96.390, 1424.0, 37.7359
40.564535770, 96.390, 1429.0, 37.8021
40.617056901, 96.390, 1400.0, 37.4166
40.669578032, 96.390, 1446.0, 38.0263
40.722099162, 96.390, 1379.0, 37.1349
40.774620293, 96.390, 1450.0, 38.0789
40.827141424, 96.390, 1429.0, 37.8021
40.879662554, 96.390, 1394.0, 37.3363
40.932183685, 96.390, 1368.0, 36.9865
40.984704816, 96.390, 1347.0, 36.7015
41.037225947, 96.390, 1350.0, 36.7423
41.089747077, 96.390, 1351.0, 36.7560
41.142268208, 96.390, 1334.0, 36.5240
41.194789339, 96.390, 1386.0, 37.2290
41.247310469, 96.390, 1316.0, 36.2767
41.299831600, 96.390, 1360.0, 36.8782
41.352352731, 96.390, 1348.0, 36.7151
41.404873862, 96.390, 1327.0, 36.4280
41.457394992, 96.390, 1347.0, 36.7015
41.509916123, 96.390, 1324.0, 36.3868
41.562437254, 96.390, 1369.0, 37.0000
41.614958384, 96.390, 1415.0, 37.6165
41.667479515, 96.390, 1401.0, 37.4299
41.720000646, 96.390, 1320.0, 36.3318
41.772521776, 96.390, 1378.0, 37.1214
41.825042907, 96.390, 1267.0, 35.5949
41.877564038, 96.390, 1294.0, 35.9722
41.930085169, 96.390, 1212.0, 34.8138
41.982606299, 96.390, 1265.0, 35.5668
42.035127430, 96.390, 1357.0, 36.8375
42.087648561, 96.390, 1259.0, 35.4824
42.140169691, 96.390, 1318.0, 36.3043
42.192690822, 96.390, 1248.0, 35.3270
42.245211953, 96.390, 1285.0, 35.8469
42.297733084, 96.390, 1344.0, 36.6606
42.350254214, 96.390, 1254.0, 35.4119
42.402775345, 96.390, 1378.0, 37.1214
42.455296476, 96.390, 1246.0, 35.2987
42.507817606, 96.390, 1320.0, 36.3318
42.560338737, 96.390, 1291.0, 35.9305
42.612859868, 96.390, 1257.0, 35.4542
42.665380999, 96.390, 1242.0, 35.2420
42.717902129, 96.390, 1388.0, 37.2559
42.770423260, 96.390, 1372.0, 37.0405
42.822944391, 96.390, 1321.0, 36.3456
42.875465521, 96.390, 1345.0, 36.6742
42.927986652, 96.390, 1290.0, 35.9166
42.980507783, 96.390, 1289.0, 35.9026
43.033028914, 96.390, 1357.0, 36.8375
43.085550044, 96.390, 1348.0, 36.7151
43.138071175, 96.390, 1320.0, 36.3318
43.190592306, 96.390, 1262.0, 35.5246
43.243113436, 96.390, 1256.0, 35.4401
43.295634567, 96.390, 1349.0, 36.7287
43.348155698, 96.390, 1267.0, 35.5949
43.400676828, 96.390, 1268.0, 35.6090
43.453197959, 96.390, 1223.0, 34.9714
43.505719090, 96.390, 1282.0, 35.8050
43.558240221, 96.390, 1326.0, 36.4143
43.610761351, 96.390, 1242.0, 35.2420
43.663282482, 96.390, 1279.0, 35.7631
43.715803613, 96.390, 1292.0, 35.9444
43.768324743, 96.390, 1261.0, 35.5106
43.820845874, 96.390, 1239.0, 35.1994
43.873367005, 96.390, 1287.0, 35.8748
43.925888136, 96.390, 1283.0, 35.8190
43.978409266, 96.390, 1351.0, 36.7560
44.030930397, 96.390, 1284.0, 35.8329
44.083451528, 96.390, 1247.0, 35.3129
44.135972658, 96.390, 1312.0, 36.2215
44.188493789, 96.390, 1276.0, 35.7211
44.241014920, 96.390, 1222.0, 34.9571
44.293536051, 96.390, 1278.0, 35.7491
44.346057181, 96.390, 1297.0, 36.0139
44.398578312, 96.390, 1250.0, 35.3553
44.451099443, 96.390, 1267.0, 35.5949
44.503620573, 96.390, 1294.0, 35.9722
44.556141704, 96.390, 1174.0, 34.2637
44.608662835, 96.390, 1254.0, 35.4119
44.661183966, 96.390, 1305.0, 36.1248
44.713705096, 96.390, 1223.0, 34.9714
44.766226227, 96.390, 1209.0, 34.7707
44.818747358, 96.390, 1297.0, 36.0139
44.871268488, 96.390, 1226.0, 35.0143
44.923789619, 96.390, 1237.0, 35.1710
44.976310750, 96.390, 1215.0, 34.8569
45.028831880, 96.390, 1265.0, 35.5668
45.081353011, 96.390, 1215.0, 34.8569
45.133874142, 96.390, 1239.0, 35.1994
45.186395273, 96.390, 1256.0, 35.4401
45.238916403, 96.390, 1226.0, 35.0143
45.291437534, 96.390, 1281.0, 35.7911
45.343958665, 96.390, 1237.0, 35.1710
45.396479795, 96.390, 1278.0, 35.7491
45.449000926, 96.390, 1302.0, 36.0832
45.501522057, 96.390, 1233.0, 35.1141
45.554043188, 96.390, 1248.0, 35.3270
45.606564318, 96.390, 1259.0, 35.4824
45.659085449, 96.390, 1206.0, 34.7275
45.711606580, 96.390, 1227.0, 35.0286
45.764127710, 96.390, 1249.0, 35.3412
45.816648841, 96.390, 1297.0, 36.0139
45.869169972, 96.390, 1257.0, 35.4542
45.921691103, 96.390, 1263.0, 35.5387
45.974212233, 96.390, 1323.0, 36.3731
46.026733364, 96.390, 1256.0, 35.4401
46.079254495, 96.390, 1281.0, 35.7911
46.131775625, 96.390, 1271.0, 35.6511
46.184296756, 96.390, 1214.0, 34.8425
46.236817887, 96.390, 1259.0, 35.4824
46.289339017, 96.390, 1219.0, 34.9142
46.341860148, 96.390, 1337.0, 36.5650
46.394381279, 96.390, 1273.0, 35.6791
46.446902410, 96.390, 1315.0, 36.2629
46.499423540, 96.390, 1306.0, 36.1386
46.551944671, 96.390, 1362.0, 36.9053
46.604465802, 96.390, 1307.0, 36.1525
46.656986932, 96.390, 1353.0, 36.7831
46.709508063, 96.390, 1387.0, 37.2424
46.762029194, 96.390, 1323.0, 36.3731
46.814550325, 96.390, 1395.0, 37.3497
46.867071455, 96.390, 1375.0, 37.0810
46.919592586, 96.390, 1409.0, 37.5366
46.972113717, 96.390, 1412.0, 37.5766
47.024634847, 96.390, 1424.0, 37.7359
47.077155978, 96.390, 1372.0, 37.0405
47.129677109, 96.390, 1356.0, 36.8239
47.182198240, 96.390, 1429.0, 37.8021
47.234719370, 96.390, 1380.0, 37.1484
47.287240501, 96.390, 1386.0, 37.2290
47.339761632, 96.390, 1349.0, 36.7287
47.392282762, 96.390, 1202.0, 34.6699
47.444803893, 96.390, 1215.0, 34.8569
47.497325024, 96.390, 1231.0, 35.0856
47.549846155, 96.390, 1214.0, 34.8425
47.602367285, 96.390, 1172.0, 34.2345
47.654888416, 96.390, 1194.0, 34.5543
47.707409547, 96.390, 1160.0, 34.0588
47.759930677, 96.390, 1218.0, 34.8999
47.812451808, 96.390, 1177.0, 34.3074
47.864972939, 96.390, 1106.0, 33.2566
47.917494069, 96.390, 1145.0, 33.8378
47.970015200, 96.390, 1080.0, 32.8634
48.022536331, 96.390, 1103.0, 33.2114
48.075057462, 96.390, 1148.0, 33.8821
48.127578592, 96.390, 1087.0, 32.9697
48.180099723, 96.390, 1132.0, 33.6452
48.232620854, 96.390, 1101.0, 33.1813
48.285141984, 96.390, 1155.0, 33.9853
48.337663115, 96.390, 1126.0, 33.5559
48.390184246, 96.390, 1120.0, 33.4664
48.442705377, 96.390, 1097.0, 33.1210
48.495226507, 96.390, 1039.0, 32.2335
48.547747638, 96.390, 1131.0, 33.6303
48.600268769, 96.390, 1069.0, 32.6956
48.652789899, 96.390, 1093.0, 33.0606
48.705311030, 96.390, 1096.0, 33.1059
48.757832161, 96.390, 1059.0, 32.5423
48.810353292, 96.390, 1053.0, 32.4500
48.862874422, 96.390, 1069.0, 32.6956
48.915395553, 96.390, 1053.0, 32.4500
48.967916684, 96.390, 1094.0, 33.0757
49.020437814, 96.390, 1050.0, 32.4037
49.072958945, 96.390, 1030.0, 32.0936
49.125480076, 96.390, 1064.0, 32.6190
49.178001207, 96.390, 1078.0, 32.8329
49.230522337, 96.390, 966.0, 31.0805
49.283043468, 96.390, 1092.0, 33.0454
49.335564599, 96.390, 1069.0, 32.6956
49.388085729, 96.390, 1053.0, 32.4500
49.440606860, 96.390, 1037.0, 32.2025
49.493127991, 96.390, 982.0, 31.3369
49.545649121, 96.390, 969.0, 31.1288
49.598170252, 96.390, 1009.0, 31.7648
49.650691383, 96.390, 1026.0, 32.0312
49.703212514, 96.390, 1028.0, 32.0624
49.755733644, 96.390, 1038.0, 32.2180
49.808254775, 96.390, 1023.0, 31.9844
49.860775906, 96.390, 1066.0, 32.6497
49.913297036, 96.390, 1020.0, 31.9374
49.965818167, 96.390, 985.0, 31.3847
50.018339298, 96.390, 962.0, 31.0161
50.070860429, 96.390, 1001.0, 31.6386
50.123381559, 96.390, 1003.0, 31.6702
50.175902690, 96.390, 965.0, 31.0644
50.228423821, 96.390, 1007.0, 31.7333
50.280944951, 96.390, 991.0, 31.4802
50.333466082, 96.390, 1023.0, 31.9844
50.385987213, 96.390, 996.0, 31.5595
50.438508344, 96.390, 1023.0, 31.9844
50.491029474, 96.390, 1051.0, 32.4191
50.543550605, 96.390, 959.0, 30.9677
50.596071736, 96.390, 947.0, 30.7734
50.648592866, 96.390, 1000.0, 31.6228
50.701113997, 96.390, 958.0, 30.9516
50.753635128, 96.390, 1010.0, 31.7805
50.806156258, 96.390, 963.0, 31.0322
50.858677389, 96.390, 917.0, 30.2820
50.911198520, 96.390, 996.0, 31.5595
50.963719651, 96.390, 961.0, 31.0000
51.016240781, 96.390, 971.0, 31.1609
51.068761912, 96.390, 970.0, 31.1448
51.121283043, 96.390, 972.0, 31.1769
51.173804173, 96.390, 968.0, 31.1127
51.226325304, 96.390, 955.0, 30.9031
51.278846435, 96.390, 956.0, 30.9192
51.331367566, 96.390, 987.0, 31.4166
51.383888696, 96.390, 930.0, 30.4959
51.436409827, 96.390, 956.0, 30.9192
51.488930958, 96.390, 970.0, 31.1448
51.541452088, 96.390, 959.0, 30.9677
51.593973219, 96.390, 1015.0, 31.8591
51.646494350, 96.390, 921.0, 30.3480
51.699015481, 96.390, 950.0, 30.8221
51.751536611, 96.390, 977.0, 31.2570
51.804057742, 96.390, 943.0, 30.7083
51.856578873, 96.390, 930.0, 30.4959
51.909100003, 96.390, 966.0, 31.0805
51.961621134, 96.390, 895.0, 29.9166
52.014142265, 96.390, 921.0, 30.3480
52.066663396, 96.390, 1000.0, 31.6228
52.119184526, 96.390, 949.0, 30.8058
52.171705657, 96.390, 925.0, 30.4138
52.224226788, 96.390, 902.0, 30.0333
52.276747918, 96.390, 920.0, 30.3315
52.329269049, 96.390, 962.0, 31.0161
52.381790180, 96.390, 898.0, 29.9666
52.434311310, 96.390, 886.0, 29.7658
52.486832441, 96.390, 969.0, 31.1288
52.539353572, 96.390, 927.0, 30.4467
52.591874703, 96.390, 985.0, 31.3847
52.644395833, 96.390, 971.0, 31.1609
52.696916964, 96.390, 959.0, 30.9677
52.749438095, 96.390, 946.0, 30.7571
52.801959225, 96.390, 927.0, 30.4467
52.854480356, 96.390, 948.0, 30.7896
52.907001487, 96.390, 951.0, 30.8383
52.959522618, 96.390, 918.0, 30.2985
53.012043748, 96.390, 957.0, 30.9354
53.064564879, 96.390, 962.0, 31.0161
53.117086010, 96.390, 977.0, 31.2570
53.169607140, 96.390, 927.0, 30.4467
53.222128271, 96.390, 948.0, 30.7896
53.274649402, 96.390, 938.0, 30.6268
53.327170533, 96.390, 916.0, 30.2655
53.379691663, 96.390, 906.0, 30.0998
53.432212794, 96.390, 958.0, 30.9516
53.484733925, 96.390, 959.0, 30.9677
53.537255055, 96.390, 902.0, 30.0333
53.589776186, 96.390, 846.0, 29.0861
53.642297317, 96.390, 946.0, 30.7571
53.694818448, 96.390, 876.0, 29.5973
53.747339578, 96.390, 908.0, 30.1330
53.799860709, 96.390, 890.0, 29.8329
53.852381840, 96.390, 889.0, 29.8161
53.904902970, 96.390, 849.0, 29.1376
53.957424101, 96.390, 961.0, 31.0000
54.009945232, 96.390, 892.0, 29.8664
54.062466362, 96.390, 883.0, 29.7153
54.114987493, 96.390, 876.0, 29.5973
54.167508624, 96.390, 865.0, 29.4109
54.220029755, 96.390, 892.0, 29.8664
54.272550885, 96.390, 889.0, 29.8161
54.325072016, 96.390, 921.0, 30.3480
54.377593147, 96.390, 882.0, 29.6985
54.430114277, 96.390, 916.0, 30.2655
54.482635408, 96.390, 894.0, 29.8998
54.535156539, 96.390, 802.0, 28.3196
54.587677670, 96.390, 879.0, 29.6479
54.640198800, 96.390, 860.0, 29.3258
54.692719931, 96.390, 868.0, 29.4618
54.745241062, 96.390, 878.0, 29.6311
54.797762192, 96.390, 936.0, 30.5941
54.850283323, 96.390, 850.0, 29.1548
54.902804454, 96.390, 872.0, 29.5296
54.955325585, 96.390, 901.0, 30.0167
55.007846715, 96.390, 863.0, 29.3769
55.060367846, 96.390, 877.0, 29.6142
55.112888977, 96.390, 914.0, 30.2324
55.165410107, 96.390, 862.0, 29.3598
55.217931238, 96.390, 891.0, 29.8496
55.270452369, 96.390, 833.0, 28.8617
55.322973499, 96.390, 906.0, 30.0998
55.375494630, 96.390, 831.0, 28.8271
55.428015761, 96.390, 835.0, 28.8964
55.480536892, 96.390, 868.0, 29.4618
55.533058022, 96.390, 819.0, 28.6182
55.585579153, 96.390, 929.0, 30.4795
55.638100284, 96.390, 930.0, 30.4959
55.690621414, 96.390, 899.0, 29.9833
55.743142545, 96.390, 888.0, 29.7993
55.795663676, 96.390, 832.0, 28.8444
55.848184807, 96.390, 854.0, 29.2233
55.900705937, 96.390, 857.0, 29.2746
55.953227068, 96.390, 881.0, 29.6816
56.005748199, 96.390, 882.0, 29.6985
56.058269329, 96.390, 854.0, 29.2233
56.110790460, 96.390, 882.0, 29.6985
56.163311591, 96.390, 859.0, 29.3087
56.215832722, 96.390, 836.0, 28.9137
56.268353852, 96.390, 879.0, 29.6479
56.320874983, 96.390, 919.0, 30.3150
56.373396114, 96.390, 897.0, 29.9500
56.425917244, 96.390, 821.0, 28.6531
56.478438375, 96.390, 889.0, 29.8161
56.530959506, 96.390, 886.0, 29.7658
56.583480637, 96.390, 910.0, 30.1662
56.636001767, 96.390, 891.0, 29.8496
56.688522898, 96.390, 827.0, 28.7576
56.741044029, 96.390, 924.0, 30.3974
56.793565159, 96.390, 848.0, 29.1204
56.846086290, 96.390, 915.0, 30.2490
56.898607421, 96.390, 920.0, 30.3315
56.951128551, 96.390, 905.0, 30.0832
57.003649682, 96.390, 836.0, 28.9137
57.056170813, 96.390, 872.0, 29.5296
57.108691944, 96.390, 938.0, 30.6268
57.161213074, 96.390, 762.0, 27.6043
57.213734205, 96.390, 823.0, 28.6880
57.266255336, 96.390, 863.0, 29.3769
57.318776466, 96.390, 823.0, 28.6880
57.371297597, 96.390, 829.0, 28.7924
57.423818728, 96.390, 851.0, 29.1719
57.476339859, 96.390, 856.0, 29.2575
57.528860989, 96.390, 906.0, 30.0998
57.581382120, 96.390, 879.0, 29.6479
57.633903251, 96.390, 857.0, 29.2746
57.686424381, 96.390, 873.0, 29.5466
57.738945512, 96.390, 838.0, 28.9482
57.791466643, 96.390, 884.0, 29.7321
57.843987774, 96.390, 909.0, 30.1496
57.896508904, 96.390, 857.0, 29.2746
57.949030035, 96.390, 880.0, 29.6648
58.001551166, 96.390, 901.0, 30.0167
58.054072296, 96.390, 844.0, 29.0517
58.106593427, 96.390, 884.0, 29.7321
58.159114558, 96.390, 869.0, 29.4788
58.211635689, 96.390, 838.0, 28.9482
58.264156819, 96.390, 884.0, 29.7321
58.316677950, 96.390, 857.0, 29.2746
58.369199081, 96.390, 842.0, 29.0172
58.421720211, 96.390, 860.0, 29.3258
58.474241342, 96.390, 874.0, 29.5635
58.526762473, 96.390, 865.0, 29.4109
58.579283603, 96.390, 854.0, 29.2233
58.631804734, 96.390, 917.0, 30.2820
58.684325865, 96.390, 868.0, 29.4618
58.736846996, 96.390, 874.0, 29.5635
58.789368126, 96.390, 885.0, 29.7489
58.841889257, 96.390, 836.0, 28.9137
58.894410388, 96.390, 897.0, 29.9500
58.946931518, 96.390, 859.0, 29.3087
58.999452649, 96.390, 854.0, 29.2233
59.051973780, 96.390, 894.0, 29.8998
59.104494911, 96.390, 899.0, 29.9833
59.157016041, 96.390, 938.0, 30.6268
59.209537172, 96.390, 880.0, 29.6648
59.262058303, 96.390, 860.0, 29.3258
59.314579433, 96.390, 937.0, 30.6105
59.367100564, 96.390, 921.0, 30.3480
59.419621695, 96.390, 954.0, 30.8869
59.472142826, 96.390, 975.0, 31.2250
59.524663956, 96.390, 938.0, 30.6268
59.577185087, 96.390, 975.0, 31.2250
59.629706218, 96.390, 986.0, 31.4006
59.682227348, 96.390, 963.0, 31.0322
59.734748479, 96.390, 930.0, 30.4959
59.787269610, 96.390, 954.0, 30.8869
59.839790740, 96.390, 997.0, 31.5753
59.892311871, 96.390, 975.0, 31.2250
59.944833002, 96.390, 986.0, 31.4006
59.997354133, 96.390, 961.0, 31.0000
60.049875263, 96.390, 1002.0, 31.6544
60.102396394, 96.390, 1079.0, 32.8481
60.154917525, 96.390, 1023.0, 31.9844
60.207438655, 96.390, 1055.0, 32.4808
60.259959786, 96.390, 1019.0, 31.9218
60.312480917, 96.390, 1022.0, 31.9687
60.365002048, 96.390, 1056.0, 32.4962
60.417523178, 96.390, 1199.0, 34.6266
60.470044309, 96.390, 1126.0, 33.5559
60.522565440, 96.390, 1162.0, 34.0881
60.575086570, 96.390, 1187.0, 34.4529
60.627607701, 96.390, 1241.0, 35.2278
60.680128832, 96.390, 1251.0, 35.3695
60.732649963, 96.390, 1243.0, 35.2562
60.785171093, 96.390, 1267.0, 35.5949
60.837692224, 96.390, 1273.0, 35.6791
60.890213355, 96.390, 1357.0, 36.8375
60.942734485, 96.390, 1418.0, 37.6563
60.995255616, 96.390, 1366.0, 36.9594
61.047776747, 96.390, 1379.0, 37.1349
61.100297878, 96.390, 1392.0, 37.3095
61.152819008, 96.390, 1327.0, 36.4280
61.205340139, 96.390, 1268.0, 35.6090
61.257861270, 96.390, 1292.0, 35.9444
61.310382400, 96.390, 1269.0, 35.6230
61.362903531, 96.390, 1236.0, 35.1568
61.415424662, 96.390, 1290.0, 35.9166
61.467945792, 96.390, 1273.0, 35.6791
61.520466923, 96.390, 1202.0, 34.6699
61.572988054, 96.390, 1138.0, 33.7343
61.625509185, 96.390, 1176.0, 34.2929
61.678030315, 96.390, 1228.0, 35.0428
61.730551446, 96.390, 1185.0, 34.4238
61.783072577, 96.390, 1149.0, 33.8969
61.835593707, 96.390, 1197.0, 34.5977
61.888114838, 96.390, 1168.0, 34.1760
61.940635969, 96.390, 1181.0, 34.3657
61.993157100, 96.390, 1170.0, 34.2053
62.045678230, 96.390, 1190.0, 34.4964
62.098199361, 96.390, 1195.0, 34.5688
62.150720492, 96.390, 1209.0, 34.7707
62.203241622, 96.390, 1184.0, 34.4093
62.255762753, 96.390, 1224.0, 34.9857
62.308283884, 96.390, 1324.0, 36.3868
62.360805015, 96.390, 1239.0, 35.1994
62.413326145, 96.390, 1206.0, 34.7275
62.465847276, 96.390, 1226.0, 35.0143
62.518368407, 96.390, 1112.0, 33.3467
62.570889537, 96.390, 1162.0, 34.0881
62.623410668, 96.390, 1138.0, 33.7343
62.675931799, 96.390, 1077.0, 32.8177
62.728452930, 96.390, 1068.0, 32.6803
62.780974060, 96.390, 1017.0, 31.8904
62.833495191, 96.390, 1006.0, 31.7175
62.886016322, 96.390, 944.0, 30.7246
62.938537452, 96.390, 1023.0, 31.9844
62.991058583, 96.390, 993.0, 31.5119
63.043579714, 96.390, 1024.0, 32.0000
63.096100844, 96.390, 924.0, 30.3974
63.148621975, 96.390, 911.0, 30.1828
63.201143106, 96.390, 1027.0, 32.0468
63.253664237, 96.390, 950.0, 30.8221
63.306185367, 96.390, 996.0, 31.5595
63.358706498, 96.390, 941.0, 30.6757
63.411227629, 96.390, 972.0, 31.1769
63.463748759, 96.390, 939.0, 30.6431
63.516269890, 96.390, 930.0, 30.4959
63.568791021, 96.390, 908.0, 30.1330
63.621312152, 96.390, 982.0, 31.3369
63.673833282, 96.390, 903.0, 30.0500
63.726354413, 96.390, 989.0, 31.4484
63.778875544, 96.390, 929.0, 30.4795
63.831396674, 96.390, 950.0, 30.8221
63.883917805, 96.390, 1001.0, 31.6386
63.936438936, 96.390, 981.0, 31.3209
63.988960067, 96.390, 940.0, 30.6594
64.041481197, 96.390, 924.0, 30.3974
64.094002328, 96.390, 951.0, 30.8383
64.146523459, 96.390, 941.0, 30.6757
64.199044589, 96.390, 903.0, 30.0500
64.251565720, 96.390, 897.0, 29.9500
64.304086851, 96.390, 917.0, 30.2820
64.356607981, 96.390, 927.0, 30.4467
64.409129112, 96.390, 936.0, 30.5941
64.461650243, 96.390, 918.0, 30.2985
64.514171374, 96.390, 916.0, 30.2655
64.566692504, 96.390, 841.0, 29.0000
64.619213635, 96.390, 911.0, 30.1828
64.671734766, 96.390, 912.0, 30.1993
64.724255896, 96.390, 908.0, 30.1330
64.776777027, 96.390, 936.0, 30.5941
64.829298158, 96.390, 894.0, 29.8998
64.881819289, 96.390, 919.0, 30.3150
64.934340419, 96.390, 920.0, 30.3315
64.986861550, 96.390, 876.0, 29.5973