File: Files_organized_for_plots/Constant_NaOH_1mL10M_to_1gPC_28Day/XRD_MgAxialnul_Act03May22_B1_0714M_NaOH_LS0172_1.csv
[Measurement conditions]
Sample identification,XRD_MgAxialnul_Act03May22_B1_0714M_NaOH_LS0171_1
Comment - 1,"Configuration=Stage for Flat Samples/Holders, Owner=User-1, Creation date=7/1/2020 9:53:24 AM"
Comment - 2,"Goniometer=Theta/Theta; Minimum step size 2Theta:0.0001; Minimum step size Omega:0.0001"
Comment - 3,"Sample stage=Stage for flat samples/holders"
Comment - 4,"Diffractometer system=EMPYREAN"
Comment - 5,"Measurement program=C:\Users\ibo5034\OneDrive - The Pennsylvania State University\NEUP\Zerobackground scan.xrdmp, Identifier={98A3B11C-88F9-4AA6-982C-73314A311EF5}"
Anode material,Cu
K-Alpha1 wavelength,1.5405980
K-Alpha2 wavelength,1.5444260
Ratio K-Alpha2/K-Alpha1,0.500
Divergence slit,Fixed,0.25
Monochromator used,NO
Generator voltage, 45
Tube current, 40
File date and time,03/Jun/2022 14:26
Unit cell,
h k l, 0 0 0
Scan axis,Gonio
Scan range,4.994599997,64.999991833
Scan step size,0.0262606
No. of points, 2285
Scan type,CONTINUOUS
Time per step,96.390
[Scan points]
Angle, TimePerStep, Intensity, ESD
5.007730280, 96.390, 4691.0, 68.4909
5.060251411, 96.390, 4614.0, 67.9264
5.112772541, 96.390, 4509.0, 67.1491
5.165293672, 96.390, 4458.0, 66.7683
5.217814803, 96.390, 4380.0, 66.1816
5.270335934, 96.390, 4307.0, 65.6277
5.322857064, 96.390, 4336.0, 65.8483
5.375378195, 96.390, 4183.0, 64.6761
5.427899326, 96.390, 4221.0, 64.9692
5.480420456, 96.390, 4274.0, 65.3758
5.532941587, 96.390, 4139.0, 64.3351
5.585462718, 96.390, 4113.0, 64.1327
5.637983849, 96.390, 4067.0, 63.7730
5.690504979, 96.390, 4075.0, 63.8357
5.743026110, 96.390, 4152.0, 64.4360
5.795547241, 96.390, 4104.0, 64.0625
5.848068371, 96.390, 4024.0, 63.4350
5.900589502, 96.390, 3924.0, 62.6418
5.953110633, 96.390, 3905.0, 62.4900
6.005631763, 96.390, 3949.0, 62.8411
6.058152894, 96.390, 3901.0, 62.4580
6.110674025, 96.390, 3866.0, 62.1772
6.163195156, 96.390, 3884.0, 62.3217
6.215716286, 96.390, 3792.0, 61.5792
6.268237417, 96.390, 3784.0, 61.5142
6.320758548, 96.390, 3672.0, 60.5970
6.373279678, 96.390, 3766.0, 61.3677
6.425800809, 96.390, 3802.0, 61.6604
6.478321940, 96.390, 3821.0, 61.8142
6.530843071, 96.390, 3785.0, 61.5224
6.583364201, 96.390, 3707.0, 60.8851
6.635885332, 96.390, 3748.0, 61.2209
6.688406463, 96.390, 3759.0, 61.3107
6.740927593, 96.390, 3572.0, 59.7662
6.793448724, 96.390, 3580.0, 59.8331
6.845969855, 96.390, 3686.0, 60.7124
6.898490986, 96.390, 3479.0, 58.9830
6.951012116, 96.390, 3453.0, 58.7622
7.003533247, 96.390, 3374.0, 58.0861
7.056054378, 96.390, 3514.0, 59.2790
7.108575508, 96.390, 3564.0, 59.6992
7.161096639, 96.390, 3416.0, 58.4466
7.213617770, 96.390, 3501.0, 59.1692
7.266138900, 96.390, 3462.0, 58.8388
7.318660031, 96.390, 3488.0, 59.0593
7.371181162, 96.390, 3553.0, 59.6070
7.423702293, 96.390, 3421.0, 58.4893
7.476223423, 96.390, 3450.0, 58.7367
7.528744554, 96.390, 3397.0, 58.2838
7.581265685, 96.390, 3411.0, 58.4038
7.633786815, 96.390, 3421.0, 58.4893
7.686307946, 96.390, 3243.0, 56.9473
7.738829077, 96.390, 3420.0, 58.4808
7.791350208, 96.390, 3417.0, 58.4551
7.843871338, 96.390, 3452.0, 58.7537
7.896392469, 96.390, 3393.0, 58.2495
7.948913600, 96.390, 3315.0, 57.5760
8.001434730, 96.390, 3270.0, 57.1839
8.053955861, 96.390, 3443.0, 58.6771
8.106476992, 96.390, 3404.0, 58.3438
8.158998123, 96.390, 3357.0, 57.9396
8.211519253, 96.390, 3336.0, 57.7581
8.264040384, 96.390, 3326.0, 57.6715
8.316561515, 96.390, 3364.0, 58.0000
8.369082645, 96.390, 3162.0, 56.2317
8.421603776, 96.390, 3320.0, 57.6194
8.474124907, 96.390, 3273.0, 57.2101
8.526646038, 96.390, 3262.0, 57.1139
8.579167168, 96.390, 3315.0, 57.5760
8.631688299, 96.390, 3334.0, 57.7408
8.684209430, 96.390, 3301.0, 57.4543
8.736730560, 96.390, 3469.0, 58.8982
8.789251691, 96.390, 3219.0, 56.7362
8.841772822, 96.390, 3260.0, 57.0964
8.894293952, 96.390, 3331.0, 57.7148
8.946815083, 96.390, 3360.0, 57.9655
8.999336214, 96.390, 3408.0, 58.3781
9.051857345, 96.390, 3391.0, 58.2323
9.104378475, 96.390, 3419.0, 58.4722
9.156899606, 96.390, 3357.0, 57.9396
9.209420737, 96.390, 3375.0, 58.0948
9.261941867, 96.390, 3485.0, 59.0339
9.314462998, 96.390, 3320.0, 57.6194
9.366984129, 96.390, 3457.0, 58.7963
9.419505260, 96.390, 3501.0, 59.1692
9.472026390, 96.390, 3469.0, 58.8982
9.524547521, 96.390, 3563.0, 59.6909
9.577068652, 96.390, 3503.0, 59.1861
9.629589782, 96.390, 3563.0, 59.6909
9.682110913, 96.390, 3517.0, 59.3043
9.734632044, 96.390, 3688.0, 60.7289
9.787153175, 96.390, 3509.0, 59.2368
9.839674305, 96.390, 3660.0, 60.4979
9.892195436, 96.390, 3650.0, 60.4152
9.944716567, 96.390, 3652.0, 60.4318
9.997237697, 96.390, 3656.0, 60.4649
10.049758828, 96.390, 3709.0, 60.9016
10.102279959, 96.390, 3775.0, 61.4410
10.154801090, 96.390, 3693.0, 60.7701
10.207322220, 96.390, 3804.0, 61.6766
10.259843351, 96.390, 3847.0, 62.0242
10.312364482, 96.390, 3841.0, 61.9758
10.364885612, 96.390, 3882.0, 62.3057
10.417406743, 96.390, 4024.0, 63.4350
10.469927874, 96.390, 4347.0, 65.9318
10.522449004, 96.390, 4140.0, 64.3428
10.574970135, 96.390, 4002.0, 63.2614
10.627491266, 96.390, 3986.0, 63.1348
10.680012397, 96.390, 4069.0, 63.7887
10.732533527, 96.390, 4036.0, 63.5295
10.785054658, 96.390, 4010.0, 63.3246
10.837575789, 96.390, 4154.0, 64.4515
10.890096919, 96.390, 4251.0, 65.1997
10.942618050, 96.390, 4081.0, 63.8827
10.995139181, 96.390, 4310.0, 65.6506
11.047660312, 96.390, 4435.0, 66.5958
11.100181442, 96.390, 4035.0, 63.5216
11.152702573, 96.390, 4104.0, 64.0625
11.205223704, 96.390, 4124.0, 64.2184
11.257744834, 96.390, 3951.0, 62.8570
11.310265965, 96.390, 4046.0, 63.6082
11.362787096, 96.390, 4124.0, 64.2184
11.415308227, 96.390, 4083.0, 63.8984
11.467829357, 96.390, 4000.0, 63.2456
11.520350488, 96.390, 3767.0, 61.3759
11.572871619, 96.390, 3956.0, 62.8967
11.625392749, 96.390, 3866.0, 62.1772
11.677913880, 96.390, 3929.0, 62.6817
11.730435011, 96.390, 3741.0, 61.1637
11.782956141, 96.390, 3786.0, 61.5305
11.835477272, 96.390, 3556.0, 59.6322
11.887998403, 96.390, 3622.0, 60.1831
11.940519534, 96.390, 3618.0, 60.1498
11.993040664, 96.390, 3585.0, 59.8749
12.045561795, 96.390, 3457.0, 58.7963
12.098082926, 96.390, 3490.0, 59.0762
12.150604056, 96.390, 3410.0, 58.3952
12.203125187, 96.390, 3219.0, 56.7362
12.255646318, 96.390, 3325.0, 57.6628
12.308167449, 96.390, 3267.0, 57.1577
12.360688579, 96.390, 3250.0, 57.0088
12.413209710, 96.390, 3147.0, 56.0981
12.465730841, 96.390, 3161.0, 56.2228
12.518251971, 96.390, 3131.0, 55.9553
12.570773102, 96.390, 3121.0, 55.8659
12.623294233, 96.390, 3019.0, 54.9454
12.675815364, 96.390, 2911.0, 53.9537
12.728336494, 96.390, 2922.0, 54.0555
12.780857625, 96.390, 2910.0, 53.9444
12.833378756, 96.390, 2859.0, 53.4696
12.885899886, 96.390, 2787.0, 52.7920
12.938421017, 96.390, 2831.0, 53.2071
12.990942148, 96.390, 2671.0, 51.6817
13.043463279, 96.390, 2736.0, 52.3068
13.095984409, 96.390, 2615.0, 51.1371
13.148505540, 96.390, 2607.0, 51.0588
13.201026671, 96.390, 2680.0, 51.7687
13.253547801, 96.390, 2648.0, 51.4587
13.306068932, 96.390, 2687.0, 51.8363
13.358590063, 96.390, 2712.0, 52.0769
13.411111193, 96.390, 2705.0, 52.0096
13.463632324, 96.390, 2977.0, 54.5619
13.516153455, 96.390, 3244.0, 56.9561
13.568674586, 96.390, 2792.0, 52.8394
13.621195716, 96.390, 2563.0, 50.6261
13.673716847, 96.390, 2568.0, 50.6754
13.726237978, 96.390, 2608.0, 51.0686
13.778759108, 96.390, 2902.0, 53.8702
13.831280239, 96.390, 3406.0, 58.3609
13.883801370, 96.390, 2897.0, 53.8238
13.936322501, 96.390, 2585.0, 50.8429
13.988843631, 96.390, 2411.0, 49.1019
14.041364762, 96.390, 2341.0, 48.3839
14.093885893, 96.390, 2441.0, 49.4065
14.146407023, 96.390, 2659.0, 51.5655
14.198928154, 96.390, 2972.0, 54.5161
14.251449285, 96.390, 3900.0, 62.4500
14.303970416, 96.390, 4745.0, 68.8840
14.356491546, 96.390, 2875.0, 53.6190
14.409012677, 96.390, 2263.0, 47.5710
14.461533808, 96.390, 2219.0, 47.1063
14.514054938, 96.390, 2231.0, 47.2335
14.566576069, 96.390, 2323.0, 48.1975
14.619097200, 96.390, 2162.0, 46.4973
14.671618331, 96.390, 2176.0, 46.6476
14.724139461, 96.390, 2132.0, 46.1736
14.776660592, 96.390, 2117.0, 46.0109
14.829181723, 96.390, 2151.0, 46.3789
14.881702853, 96.390, 2042.0, 45.1885
14.934223984, 96.390, 2066.0, 45.4533
14.986745115, 96.390, 2065.0, 45.4423
15.039266245, 96.390, 2018.0, 44.9222
15.091787376, 96.390, 2181.0, 46.7012
15.144308507, 96.390, 2223.0, 47.1487
15.196829638, 96.390, 2455.0, 49.5480
15.249350768, 96.390, 2970.0, 54.4977
15.301871899, 96.390, 3156.0, 56.1783
15.354393030, 96.390, 2366.0, 48.6415
15.406914160, 96.390, 2134.0, 46.1952
15.459435291, 96.390, 1958.0, 44.2493
15.511956422, 96.390, 1944.0, 44.0908
15.564477553, 96.390, 1999.0, 44.7102
15.616998683, 96.390, 1920.0, 43.8178
15.669519814, 96.390, 1905.0, 43.6463
15.722040945, 96.390, 2033.0, 45.0888
15.774562075, 96.390, 2019.0, 44.9333
15.827083206, 96.390, 1990.0, 44.6094
15.879604337, 96.390, 1958.0, 44.2493
15.932125468, 96.390, 1965.0, 44.3283
15.984646598, 96.390, 1921.0, 43.8292
16.037167729, 96.390, 1934.0, 43.9773
16.089688860, 96.390, 1931.0, 43.9431
16.142209990, 96.390, 1903.0, 43.6234
16.194731121, 96.390, 1977.0, 44.4635
16.247252252, 96.390, 1983.0, 44.5309
16.299773382, 96.390, 1959.0, 44.2606
16.352294513, 96.390, 2033.0, 45.0888
16.404815644, 96.390, 1879.0, 43.3474
16.457336775, 96.390, 1924.0, 43.8634
16.509857905, 96.390, 1943.0, 44.0795
16.562379036, 96.390, 1895.0, 43.5316
16.614900167, 96.390, 1921.0, 43.8292
16.667421297, 96.390, 1904.0, 43.6348
16.719942428, 96.390, 1866.0, 43.1972
16.772463559, 96.390, 1934.0, 43.9773
16.824984690, 96.390, 1900.0, 43.5890
16.877505820, 96.390, 1900.0, 43.5890
16.930026951, 96.390, 1941.0, 44.0568
16.982548082, 96.390, 1963.0, 44.3058
17.035069212, 96.390, 1931.0, 43.9431
17.087590343, 96.390, 1869.0, 43.2319
17.140111474, 96.390, 1880.0, 43.3590
17.192632605, 96.390, 1902.0, 43.6119
17.245153735, 96.390, 1903.0, 43.6234
17.297674866, 96.390, 1951.0, 44.1701
17.350195997, 96.390, 2009.0, 44.8219
17.402717127, 96.390, 1999.0, 44.7102
17.455238258, 96.390, 1978.0, 44.4747
17.507759389, 96.390, 1905.0, 43.6463
17.560280520, 96.390, 1855.0, 43.0697
17.612801650, 96.390, 1888.0, 43.4511
17.665322781, 96.390, 1936.0, 44.0000
17.717843912, 96.390, 1814.0, 42.5911
17.770365042, 96.390, 1837.0, 42.8602
17.822886173, 96.390, 1855.0, 43.0697
17.875407304, 96.390, 1921.0, 43.8292
17.927928434, 96.390, 1824.0, 42.7083
17.980449565, 96.390, 1770.0, 42.0714
18.032970696, 96.390, 1938.0, 44.0227
18.085491827, 96.390, 1950.0, 44.1588
18.138012957, 96.390, 2002.0, 44.7437
18.190534088, 96.390, 1962.0, 44.2945
18.243055219, 96.390, 2037.0, 45.1331
18.295576349, 96.390, 2271.0, 47.6550
18.348097480, 96.390, 2186.0, 46.7547
18.400618611, 96.390, 2171.0, 46.5940
18.453139742, 96.390, 2379.0, 48.7750
18.505660872, 96.390, 2177.0, 46.6583
18.558182003, 96.390, 1878.0, 43.3359
18.610703134, 96.390, 1843.0, 42.9302
18.663224264, 96.390, 1903.0, 43.6234
18.715745395, 96.390, 1894.0, 43.5201
18.768266526, 96.390, 1907.0, 43.6692
18.820787657, 96.390, 1937.0, 44.0114
18.873308787, 96.390, 1961.0, 44.2832
18.925829918, 96.390, 2027.0, 45.0222
18.978351049, 96.390, 2069.0, 45.4863
19.030872179, 96.390, 2169.0, 46.5725
19.083393310, 96.390, 1931.0, 43.9431
19.135914441, 96.390, 1937.0, 44.0114
19.188435572, 96.390, 2049.0, 45.2659
19.240956702, 96.390, 2001.0, 44.7325
19.293477833, 96.390, 2126.0, 46.1086
19.345998964, 96.390, 2187.0, 46.7654
19.398520094, 96.390, 2485.0, 49.8498
19.451041225, 96.390, 2710.0, 52.0577
19.503562356, 96.390, 2393.0, 48.9183
19.556083486, 96.390, 2153.0, 46.4004
19.608604617, 96.390, 2158.0, 46.4543
19.661125748, 96.390, 2316.0, 48.1248
19.713646879, 96.390, 2560.0, 50.5964
19.766168009, 96.390, 2745.0, 52.3927
19.818689140, 96.390, 2892.0, 53.7773
19.871210271, 96.390, 2729.0, 52.2398
19.923731401, 96.390, 3413.0, 58.4209
19.976252532, 96.390, 4159.0, 64.4903
20.028773663, 96.390, 3386.0, 58.1893
20.081294794, 96.390, 2415.0, 49.1426
20.133815924, 96.390, 2190.0, 46.7974
20.186337055, 96.390, 2146.0, 46.3249
20.238858186, 96.390, 2270.0, 47.6445
20.291379316, 96.390, 2245.0, 47.3814
20.343900447, 96.390, 2420.0, 49.1935
20.396421578, 96.390, 2652.0, 51.4976
20.448942709, 96.390, 3039.0, 55.1271
20.501463839, 96.390, 2738.0, 52.3259
20.553984970, 96.390, 2966.0, 54.4610
20.606506101, 96.390, 3957.0, 62.9047
20.659027231, 96.390, 5718.0, 75.6175
20.711548362, 96.390, 8140.0, 90.2219
20.764069493, 96.390, 6179.0, 78.6066
20.816590623, 96.390, 3446.0, 58.7026
20.869111754, 96.390, 2514.0, 50.1398
20.921632885, 96.390, 2436.0, 49.3559
20.974154016, 96.390, 2409.0, 49.0816
21.026675146, 96.390, 2425.0, 49.2443
21.079196277, 96.390, 2297.0, 47.9270
21.131717408, 96.390, 2170.0, 46.5833
21.184238538, 96.390, 2266.0, 47.6025
21.236759669, 96.390, 2232.0, 47.2440
21.289280800, 96.390, 2331.0, 48.2804
21.341801931, 96.390, 2190.0, 46.7974
21.394323061, 96.390, 2269.0, 47.6340
21.446844192, 96.390, 2326.0, 48.2286
21.499365323, 96.390, 2322.0, 48.1871
21.551886453, 96.390, 2303.0, 47.9896
21.604407584, 96.390, 2281.0, 47.7598
21.656928715, 96.390, 2490.0, 49.8999
21.709449846, 96.390, 2428.0, 49.2747
21.761970976, 96.390, 2464.0, 49.6387
21.814492107, 96.390, 2363.0, 48.6107
21.867013238, 96.390, 2414.0, 49.1325
21.919534368, 96.390, 2487.0, 49.8698
21.972055499, 96.390, 2534.0, 50.3389
22.024576630, 96.390, 2446.0, 49.4571
22.077097761, 96.390, 2500.0, 50.0000
22.129618891, 96.390, 2531.0, 50.3090
22.182140022, 96.390, 2568.0, 50.6754
22.234661153, 96.390, 2428.0, 49.2747
22.287182283, 96.390, 2442.0, 49.4166
22.339703414, 96.390, 2541.0, 50.4083
22.392224545, 96.390, 2556.0, 50.5569
22.444745675, 96.390, 2605.0, 51.0392
22.497266806, 96.390, 2624.0, 51.2250
22.549787937, 96.390, 2591.0, 50.9019
22.602309068, 96.390, 2626.0, 51.2445
22.654830198, 96.390, 2555.0, 50.5470
22.707351329, 96.390, 2568.0, 50.6754
22.759872460, 96.390, 2639.0, 51.3712
22.812393590, 96.390, 2669.0, 51.6624
22.864914721, 96.390, 2615.0, 51.1371
22.917435852, 96.390, 2755.0, 52.4881
22.969956983, 96.390, 2487.0, 49.8698
23.022478113, 96.390, 2608.0, 51.0686
23.074999244, 96.390, 2596.0, 50.9510
23.127520375, 96.390, 2591.0, 50.9019
23.180041505, 96.390, 2465.0, 49.6488
23.232562636, 96.390, 2538.0, 50.3786
23.285083767, 96.390, 2579.0, 50.7839
23.337604898, 96.390, 2491.0, 49.9099
23.390126028, 96.390, 2610.0, 51.0882
23.442647159, 96.390, 2647.0, 51.4490
23.495168290, 96.390, 2919.0, 54.0278
23.547689420, 96.390, 3319.0, 57.6108
23.600210551, 96.390, 2823.0, 53.1319
23.652731682, 96.390, 2515.0, 50.1498
23.705252813, 96.390, 2369.0, 48.6724
23.757773943, 96.390, 2463.0, 49.6286
23.810295074, 96.390, 2290.0, 47.8539
23.862816205, 96.390, 2393.0, 48.9183
23.915337335, 96.390, 2293.0, 47.8853
23.967858466, 96.390, 2402.0, 49.0102
24.020379597, 96.390, 2244.0, 47.3709
24.072900727, 96.390, 2428.0, 49.2747
24.125421858, 96.390, 2530.0, 50.2991
24.177942989, 96.390, 2812.0, 53.0283
24.230464120, 96.390, 2820.0, 53.1037
24.282985250, 96.390, 2565.0, 50.6458
24.335506381, 96.390, 2359.0, 48.5695
24.388027512, 96.390, 2189.0, 46.7868
24.440548642, 96.390, 2169.0, 46.5725
24.493069773, 96.390, 2114.0, 45.9783
24.545590904, 96.390, 2401.0, 49.0000
24.598112035, 96.390, 2321.0, 48.1768
24.650633165, 96.390, 2154.0, 46.4112
24.703154296, 96.390, 1954.0, 44.2041
24.755675427, 96.390, 1966.0, 44.3396
24.808196557, 96.390, 1975.0, 44.4410
24.860717688, 96.390, 2008.0, 44.8107
24.913238819, 96.390, 1916.0, 43.7721
24.965759950, 96.390, 2068.0, 45.4753
25.018281080, 96.390, 1954.0, 44.2041
25.070802211, 96.390, 1909.0, 43.6921
25.123323342, 96.390, 1897.0, 43.5546
25.175844472, 96.390, 1932.0, 43.9545
25.228365603, 96.390, 2010.0, 44.8330
25.280886734, 96.390, 2035.0, 45.1110
25.333407864, 96.390, 2221.0, 47.1275
25.385928995, 96.390, 2765.0, 52.5833
25.438450126, 96.390, 3257.0, 57.0701
25.490971257, 96.390, 2945.0, 54.2679
25.543492387, 96.390, 2326.0, 48.2286
25.596013518, 96.390, 1979.0, 44.4860
25.648534649, 96.390, 1929.0, 43.9204
25.701055779, 96.390, 1926.0, 43.8862
25.753576910, 96.390, 1843.0, 42.9302
25.806098041, 96.390, 1866.0, 43.1972
25.858619172, 96.390, 1938.0, 44.0227
25.911140302, 96.390, 1924.0, 43.8634
25.963661433, 96.390, 1869.0, 43.2319
26.016182564, 96.390, 1884.0, 43.4051
26.068703694, 96.390, 1901.0, 43.6005
26.121224825, 96.390, 1834.0, 42.8252
26.173745956, 96.390, 1856.0, 43.0813
26.226267087, 96.390, 1815.0, 42.6028
26.278788217, 96.390, 1804.0, 42.4735
26.331309348, 96.390, 1857.0, 43.0929
26.383830479, 96.390, 1850.0, 43.0116
26.436351609, 96.390, 1855.0, 43.0697
26.488872740, 96.390, 1825.0, 42.7200
26.541393871, 96.390, 1850.0, 43.0116
26.593915002, 96.390, 1775.0, 42.1307
26.646436132, 96.390, 1892.0, 43.4971
26.698957263, 96.390, 1957.0, 44.2380
26.751478394, 96.390, 1918.0, 43.7950
26.803999524, 96.390, 1892.0, 43.4971
26.856520655, 96.390, 1938.0, 44.0227
26.909041786, 96.390, 2030.0, 45.0555
26.961562916, 96.390, 1955.0, 44.2154
27.014084047, 96.390, 2084.0, 45.6508
27.066605178, 96.390, 2255.0, 47.4868
27.119126309, 96.390, 2477.0, 49.7695
27.171647439, 96.390, 3243.0, 56.9473
27.224168570, 96.390, 3269.0, 57.1752
27.276689701, 96.390, 2726.0, 52.2111
27.329210831, 96.390, 2187.0, 46.7654
27.381731962, 96.390, 2059.0, 45.3762
27.434253093, 96.390, 1972.0, 44.4072
27.486774224, 96.390, 1946.0, 44.1135
27.539295354, 96.390, 1940.0, 44.0454
27.591816485, 96.390, 2005.0, 44.7772
27.644337616, 96.390, 2062.0, 45.4093
27.696858746, 96.390, 2035.0, 45.1110
27.749379877, 96.390, 2039.0, 45.1553
27.801901008, 96.390, 1882.0, 43.3820
27.854422139, 96.390, 2019.0, 44.9333
27.906943269, 96.390, 2040.0, 45.1664
27.959464400, 96.390, 1953.0, 44.1928
28.011985531, 96.390, 1940.0, 44.0454
28.064506661, 96.390, 2053.0, 45.3100
28.117027792, 96.390, 2077.0, 45.5741
28.169548923, 96.390, 1964.0, 44.3170
28.222070054, 96.390, 1982.0, 44.5197
28.274591184, 96.390, 2074.0, 45.5412
28.327112315, 96.390, 2028.0, 45.0333
28.379633446, 96.390, 1970.0, 44.3847
28.432154576, 96.390, 1834.0, 42.8252
28.484675707, 96.390, 1945.0, 44.1022
28.537196838, 96.390, 1942.0, 44.0681
28.589717968, 96.390, 1897.0, 43.5546
28.642239099, 96.390, 1980.0, 44.4972
28.694760230, 96.390, 2010.0, 44.8330
28.747281361, 96.390, 2300.0, 47.9583
28.799802491, 96.390, 2326.0, 48.2286
28.852323622, 96.390, 2089.0, 45.7056
28.904844753, 96.390, 2091.0, 45.7275
28.957365883, 96.390, 2095.0, 45.7712
29.009887014, 96.390, 2076.0, 45.5631
29.062408145, 96.390, 2288.0, 47.8330
29.114929276, 96.390, 2575.0, 50.7445
29.167450406, 96.390, 2294.0, 47.8957
29.219971537, 96.390, 2164.0, 46.5188
29.272492668, 96.390, 2024.0, 44.9889
29.325013798, 96.390, 2013.0, 44.8665
29.377534929, 96.390, 1962.0, 44.2945
29.430056060, 96.390, 2072.0, 45.5192
29.482577191, 96.390, 1946.0, 44.1135
29.535098321, 96.390, 2021.0, 44.9555
29.587619452, 96.390, 1975.0, 44.4410
29.640140583, 96.390, 1980.0, 44.4972
29.692661713, 96.390, 1934.0, 43.9773
29.745182844, 96.390, 1842.0, 42.9185
29.797703975, 96.390, 1960.0, 44.2719
29.850225105, 96.390, 1924.0, 43.8634
29.902746236, 96.390, 1865.0, 43.1856
29.955267367, 96.390, 1954.0, 44.2041
30.007788498, 96.390, 1858.0, 43.1045
30.060309628, 96.390, 1935.0, 43.9886
30.112830759, 96.390, 1899.0, 43.5775
30.165351890, 96.390, 1839.0, 42.8836
30.217873020, 96.390, 1867.0, 43.2088
30.270394151, 96.390, 1933.0, 43.9659
30.322915282, 96.390, 1881.0, 43.3705
30.375436413, 96.390, 1906.0, 43.6578
30.427957543, 96.390, 1928.0, 43.9090
30.480478674, 96.390, 2003.0, 44.7549
30.532999805, 96.390, 2051.0, 45.2880
30.585520935, 96.390, 2213.0, 47.0425
30.638042066, 96.390, 2458.0, 49.5782
30.690563197, 96.390, 3003.0, 54.7996
30.743084328, 96.390, 3432.0, 58.5833
30.795605458, 96.390, 2764.0, 52.5738
30.848126589, 96.390, 2632.0, 51.3030
30.900647720, 96.390, 2293.0, 47.8853
30.953168850, 96.390, 2101.0, 45.8367
31.005689981, 96.390, 2029.0, 45.0444
31.058211112, 96.390, 2048.0, 45.2548
31.110732243, 96.390, 2235.0, 47.2758
31.163253373, 96.390, 2603.0, 51.0196
31.215774504, 96.390, 3271.0, 57.1927
31.268295635, 96.390, 2808.0, 52.9906
31.320816765, 96.390, 2643.0, 51.4101
31.373337896, 96.390, 2237.0, 47.2969
31.425859027, 96.390, 2069.0, 45.4863
31.478380157, 96.390, 2221.0, 47.1275
31.530901288, 96.390, 2550.0, 50.4975
31.583422419, 96.390, 2366.0, 48.6415
31.635943550, 96.390, 2580.0, 50.7937
31.688464680, 96.390, 3202.0, 56.5862
31.740985811, 96.390, 4985.0, 70.6045
31.793506942, 96.390, 3388.0, 58.2065
31.846028072, 96.390, 2569.0, 50.6853
31.898549203, 96.390, 2503.0, 50.0300
31.951070334, 96.390, 3071.0, 55.4166
32.003591465, 96.390, 4344.0, 65.9090
32.056112595, 96.390, 6528.0, 80.7960
32.108633726, 96.390, 6160.0, 78.4857
32.161154857, 96.390, 4806.0, 69.3253
32.213675987, 96.390, 2854.0, 53.4228
32.266197118, 96.390, 2236.0, 47.2864
32.318718249, 96.390, 2023.0, 44.9778
32.371239380, 96.390, 1943.0, 44.0795
32.423760510, 96.390, 1952.0, 44.1814
32.476281641, 96.390, 1874.0, 43.2897
32.528802772, 96.390, 1778.0, 42.1663
32.581323902, 96.390, 1750.0, 41.8330
32.633845033, 96.390, 1873.0, 43.2782
32.686366164, 96.390, 2033.0, 45.0888
32.738887295, 96.390, 1892.0, 43.4971
32.791408425, 96.390, 1920.0, 43.8178
32.843929556, 96.390, 1812.0, 42.5676
32.896450687, 96.390, 1864.0, 43.1741
32.948971817, 96.390, 1869.0, 43.2319
33.001492948, 96.390, 1902.0, 43.6119
33.054014079, 96.390, 2108.0, 45.9130
33.106535209, 96.390, 2354.0, 48.5180
33.159056340, 96.390, 2599.0, 50.9804
33.211577471, 96.390, 2220.0, 47.1169
33.264098602, 96.390, 2209.0, 47.0000
33.316619732, 96.390, 2097.0, 45.7930
33.369140863, 96.390, 2202.0, 46.9255
33.421661994, 96.390, 2779.0, 52.7162
33.474183124, 96.390, 3730.0, 61.0737
33.526704255, 96.390, 2782.0, 52.7447
33.579225386, 96.390, 2557.0, 50.5668
33.631746517, 96.390, 1979.0, 44.4860
33.684267647, 96.390, 2088.0, 45.6946
33.736788778, 96.390, 2083.0, 45.6399
33.789309909, 96.390, 2258.0, 47.5184
33.841831039, 96.390, 2402.0, 49.0102
33.894352170, 96.390, 2932.0, 54.1479
33.946873301, 96.390, 3711.0, 60.9180
33.999394432, 96.390, 3925.0, 62.6498
34.051915562, 96.390, 3393.0, 58.2495
34.104436693, 96.390, 2826.0, 53.1601
34.156957824, 96.390, 2691.0, 51.8748
34.209478954, 96.390, 2502.0, 50.0200
34.262000085, 96.390, 2612.0, 51.1077
34.314521216, 96.390, 2902.0, 53.8702
34.367042346, 96.390, 3007.0, 54.8361
34.419563477, 96.390, 2951.0, 54.3231
34.472084608, 96.390, 3189.0, 56.4712
34.524605739, 96.390, 3071.0, 55.4166
34.577126869, 96.390, 3088.0, 55.5698
34.629648000, 96.390, 3094.0, 55.6237
34.682169131, 96.390, 3070.0, 55.4076
34.734690261, 96.390, 3022.0, 54.9727
34.787211392, 96.390, 3189.0, 56.4712
34.839732523, 96.390, 3229.0, 56.8243
34.892253654, 96.390, 3897.0, 62.4260
34.944774784, 96.390, 4492.0, 67.0224
34.997295915, 96.390, 4253.0, 65.2150
35.049817046, 96.390, 3815.0, 61.7657
35.102338176, 96.390, 3180.0, 56.3915
35.154859307, 96.390, 2887.0, 53.7308
35.207380438, 96.390, 2844.0, 53.3292
35.259901569, 96.390, 2776.0, 52.6878
35.312422699, 96.390, 2623.0, 51.2152
35.364943830, 96.390, 2679.0, 51.7591
35.417464961, 96.390, 2446.0, 49.4571
35.469986091, 96.390, 2370.0, 48.6826
35.522507222, 96.390, 2376.0, 48.7442
35.575028353, 96.390, 2445.0, 49.4469
35.627549484, 96.390, 2551.0, 50.5074
35.680070614, 96.390, 2404.0, 49.0306
35.732591745, 96.390, 2448.0, 49.4773
35.785112876, 96.390, 2255.0, 47.4868
35.837634006, 96.390, 2352.0, 48.4974
35.890155137, 96.390, 2290.0, 47.8539
35.942676268, 96.390, 2270.0, 47.6445
35.995197398, 96.390, 2228.0, 47.2017
36.047718529, 96.390, 2205.0, 46.9574
36.100239660, 96.390, 2108.0, 45.9130
36.152760791, 96.390, 2127.0, 46.1194
36.205281921, 96.390, 2076.0, 45.5631
36.257803052, 96.390, 2067.0, 45.4643
36.310324183, 96.390, 2038.0, 45.1442
36.362845313, 96.390, 2182.0, 46.7119
36.415366444, 96.390, 2228.0, 47.2017
36.467887575, 96.390, 2058.0, 45.3652
36.520408706, 96.390, 1986.0, 44.5646
36.572929836, 96.390, 1966.0, 44.3396
36.625450967, 96.390, 1986.0, 44.5646
36.677972098, 96.390, 1843.0, 42.9302
36.730493228, 96.390, 1911.0, 43.7150
36.783014359, 96.390, 1945.0, 44.1022
36.835535490, 96.390, 1877.0, 43.3244
36.888056621, 96.390, 1781.0, 42.2019
36.940577751, 96.390, 1813.0, 42.5793
36.993098882, 96.390, 1809.0, 42.5323
37.045620013, 96.390, 1890.0, 43.4741
37.098141143, 96.390, 1821.0, 42.6732
37.150662274, 96.390, 1813.0, 42.5793
37.203183405, 96.390, 1786.0, 42.2611
37.255704535, 96.390, 1815.0, 42.6028
37.308225666, 96.390, 1765.0, 42.0119
37.360746797, 96.390, 1813.0, 42.5793
37.413267928, 96.390, 1903.0, 43.6234
37.465789058, 96.390, 1848.0, 42.9884
37.518310189, 96.390, 1883.0, 43.3935
37.570831320, 96.390, 1885.0, 43.4166
37.623352450, 96.390, 1971.0, 44.3959
37.675873581, 96.390, 2100.0, 45.8258
37.728394712, 96.390, 2450.0, 49.4975
37.780915843, 96.390, 2454.0, 49.5379
37.833436973, 96.390, 2250.0, 47.4342
37.885958104, 96.390, 2180.0, 46.6905
37.938479235, 96.390, 2071.0, 45.5082
37.991000365, 96.390, 2022.0, 44.9667
38.043521496, 96.390, 1957.0, 44.2380
38.096042627, 96.390, 1907.0, 43.6692
38.148563758, 96.390, 2056.0, 45.3431
38.201084888, 96.390, 2271.0, 47.6550
38.253606019, 96.390, 2109.0, 45.9239
38.306127150, 96.390, 2120.0, 46.0435
38.358648280, 96.390, 1943.0, 44.0795
38.411169411, 96.390, 1935.0, 43.9886
38.463690542, 96.390, 1990.0, 44.6094
38.516211673, 96.390, 1891.0, 43.4856
38.568732803, 96.390, 2028.0, 45.0333
38.621253934, 96.390, 1949.0, 44.1475
38.673775065, 96.390, 1953.0, 44.1928
38.726296195, 96.390, 2204.0, 46.9468
38.778817326, 96.390, 2301.0, 47.9687
38.831338457, 96.390, 2129.0, 46.1411
38.883859587, 96.390, 2103.0, 45.8585
38.936380718, 96.390, 1914.0, 43.7493
38.988901849, 96.390, 1824.0, 42.7083
39.041422980, 96.390, 1800.0, 42.4264
39.093944110, 96.390, 1821.0, 42.6732
39.146465241, 96.390, 1756.0, 41.9047
39.198986372, 96.390, 1928.0, 43.9090
39.251507502, 96.390, 2070.0, 45.4973
39.304028633, 96.390, 2017.0, 44.9110
39.356549764, 96.390, 2163.0, 46.5081
39.409070895, 96.390, 2396.0, 48.9490
39.461592025, 96.390, 2490.0, 49.8999
39.514113156, 96.390, 2188.0, 46.7761
39.566634287, 96.390, 1970.0, 44.3847
39.619155417, 96.390, 1844.0, 42.9418
39.671676548, 96.390, 1751.0, 41.8450
39.724197679, 96.390, 1727.0, 41.5572
39.776718810, 96.390, 1724.0, 41.5211
39.829239940, 96.390, 1748.0, 41.8091
39.881761071, 96.390, 1722.0, 41.4970
39.934282202, 96.390, 1770.0, 42.0714
39.986803332, 96.390, 1760.0, 41.9524
40.039324463, 96.390, 1732.0, 41.6173
40.091845594, 96.390, 1784.0, 42.2374
40.144366725, 96.390, 1894.0, 43.5201
40.196887855, 96.390, 1735.0, 41.6533
40.249408986, 96.390, 1725.0, 41.5331
40.301930117, 96.390, 1615.0, 40.1871
40.354451247, 96.390, 1531.0, 39.1280
40.406972378, 96.390, 1519.0, 38.9744
40.459493509, 96.390, 1530.0, 39.1152
40.512014639, 96.390, 1585.0, 39.8121
40.564535770, 96.390, 1745.0, 41.7732
40.617056901, 96.390, 1782.0, 42.2137
40.669578032, 96.390, 1696.0, 41.1825
40.722099162, 96.390, 1548.0, 39.3446
40.774620293, 96.390, 1512.0, 38.8844
40.827141424, 96.390, 1479.0, 38.4578
40.879662554, 96.390, 1458.0, 38.1838
40.932183685, 96.390, 1545.0, 39.3065
40.984704816, 96.390, 1485.0, 38.5357
41.037225947, 96.390, 1578.0, 39.7240
41.089747077, 96.390, 1489.0, 38.5876
41.142268208, 96.390, 1506.0, 38.8072
41.194789339, 96.390, 1429.0, 37.8021
41.247310469, 96.390, 1553.0, 39.4081
41.299831600, 96.390, 1779.0, 42.1782
41.352352731, 96.390, 2119.0, 46.0326
41.404873862, 96.390, 2364.0, 48.6210
41.457394992, 96.390, 1965.0, 44.3283
41.509916123, 96.390, 1888.0, 43.4511
41.562437254, 96.390, 1596.0, 39.9500
41.614958384, 96.390, 1479.0, 38.4578
41.667479515, 96.390, 1393.0, 37.3229
41.720000646, 96.390, 1359.0, 36.8646
41.772521776, 96.390, 1371.0, 37.0270
41.825042907, 96.390, 1321.0, 36.3456
41.877564038, 96.390, 1375.0, 37.0810
41.930085169, 96.390, 1356.0, 36.8239
41.982606299, 96.390, 1352.0, 36.7696
42.035127430, 96.390, 1432.0, 37.8418
42.087648561, 96.390, 1564.0, 39.5474
42.140169691, 96.390, 1813.0, 42.5793
42.192690822, 96.390, 1827.0, 42.7434
42.245211953, 96.390, 1647.0, 40.5832
42.297733084, 96.390, 1574.0, 39.6737
42.350254214, 96.390, 1368.0, 36.9865
42.402775345, 96.390, 1391.0, 37.2961
42.455296476, 96.390, 1440.0, 37.9473
42.507817606, 96.390, 1547.0, 39.3319
42.560338737, 96.390, 1655.0, 40.6817
42.612859868, 96.390, 1561.0, 39.5095
42.665380999, 96.390, 1526.0, 39.0640
42.717902129, 96.390, 1568.0, 39.5980
42.770423260, 96.390, 1495.0, 38.6652
42.822944391, 96.390, 1297.0, 36.0139
42.875465521, 96.390, 1332.0, 36.4966
42.927986652, 96.390, 1324.0, 36.3868
42.980507783, 96.390, 1304.0, 36.1109
43.033028914, 96.390, 1334.0, 36.5240
43.085550044, 96.390, 1366.0, 36.9594
43.138071175, 96.390, 1320.0, 36.3318
43.190592306, 96.390, 1229.0, 35.0571
43.243113436, 96.390, 1307.0, 36.1525
43.295634567, 96.390, 1260.0, 35.4965
43.348155698, 96.390, 1317.0, 36.2905
43.400676828, 96.390, 1247.0, 35.3129
43.453197959, 96.390, 1301.0, 36.0694
43.505719090, 96.390, 1309.0, 36.1801
43.558240221, 96.390, 1341.0, 36.6197
43.610761351, 96.390, 1329.0, 36.4555
43.663282482, 96.390, 1528.0, 39.0896
43.715803613, 96.390, 1816.0, 42.6146
43.768324743, 96.390, 2159.0, 46.4650
43.820845874, 96.390, 1940.0, 44.0454
43.873367005, 96.390, 1782.0, 42.2137
43.925888136, 96.390, 1683.0, 41.0244
43.978409266, 96.390, 1465.0, 38.2753
44.030930397, 96.390, 1401.0, 37.4299
44.083451528, 96.390, 1312.0, 36.2215
44.135972658, 96.390, 1362.0, 36.9053
44.188493789, 96.390, 1339.0, 36.5923
44.241014920, 96.390, 1402.0, 37.4433
44.293536051, 96.390, 1576.0, 39.6989
44.346057181, 96.390, 1629.0, 40.3609
44.398578312, 96.390, 1767.0, 42.0357
44.451099443, 96.390, 1645.0, 40.5586
44.503620573, 96.390, 1619.0, 40.2368
44.556141704, 96.390, 1486.0, 38.5487
44.608662835, 96.390, 1513.0, 38.8973
44.661183966, 96.390, 1423.0, 37.7227
44.713705096, 96.390, 1409.0, 37.5366
44.766226227, 96.390, 1466.0, 38.2884
44.818747358, 96.390, 1496.0, 38.6782
44.871268488, 96.390, 1559.0, 39.4842
44.923789619, 96.390, 1466.0, 38.2884
44.976310750, 96.390, 1547.0, 39.3319
45.028831880, 96.390, 1583.0, 39.7869
45.081353011, 96.390, 1858.0, 43.1045
45.133874142, 96.390, 1901.0, 43.6005
45.186395273, 96.390, 1868.0, 43.2204
45.238916403, 96.390, 1823.0, 42.6966
45.291437534, 96.390, 1885.0, 43.4166
45.343958665, 96.390, 1902.0, 43.6119
45.396479795, 96.390, 1820.0, 42.6615
45.449000926, 96.390, 1866.0, 43.1972
45.501522057, 96.390, 2069.0, 45.4863
45.554043188, 96.390, 1702.0, 41.2553
45.606564318, 96.390, 1644.0, 40.5463
45.659085449, 96.390, 1625.0, 40.3113
45.711606580, 96.390, 1512.0, 38.8844
45.764127710, 96.390, 1466.0, 38.2884
45.816648841, 96.390, 1525.0, 39.0512
45.869169972, 96.390, 1458.0, 38.1838
45.921691103, 96.390, 1492.0, 38.6264
45.974212233, 96.390, 1485.0, 38.5357
46.026733364, 96.390, 1568.0, 39.5980
46.079254495, 96.390, 1548.0, 39.3446
46.131775625, 96.390, 1643.0, 40.5339
46.184296756, 96.390, 1739.0, 41.7013
46.236817887, 96.390, 1894.0, 43.5201
46.289339017, 96.390, 2045.0, 45.2217
46.341860148, 96.390, 1792.0, 42.3320
46.394381279, 96.390, 1738.0, 41.6893
46.446902410, 96.390, 1847.0, 42.9767
46.499423540, 96.390, 1641.0, 40.5093
46.551944671, 96.390, 1531.0, 39.1280
46.604465802, 96.390, 1556.0, 39.4462
46.656986932, 96.390, 1473.0, 38.3797
46.709508063, 96.390, 1635.0, 40.4351
46.762029194, 96.390, 1561.0, 39.5095
46.814550325, 96.390, 1402.0, 37.4433
46.867071455, 96.390, 1444.0, 38.0000
46.919592586, 96.390, 1477.0, 38.4318
46.972113717, 96.390, 1573.0, 39.6611
47.024634847, 96.390, 1616.0, 40.1995
47.077155978, 96.390, 1459.0, 38.1969
47.129677109, 96.390, 1476.0, 38.4187
47.182198240, 96.390, 1416.0, 37.6298
47.234719370, 96.390, 1356.0, 36.8239
47.287240501, 96.390, 1401.0, 37.4299
47.339761632, 96.390, 1399.0, 37.4032
47.392282762, 96.390, 1415.0, 37.6165
47.444803893, 96.390, 1342.0, 36.6333
47.497325024, 96.390, 1423.0, 37.7227
47.549846155, 96.390, 1426.0, 37.7624
47.602367285, 96.390, 1449.0, 38.0657
47.654888416, 96.390, 1312.0, 36.2215
47.707409547, 96.390, 1306.0, 36.1386
47.759930677, 96.390, 1291.0, 35.9305
47.812451808, 96.390, 1273.0, 35.6791
47.864972939, 96.390, 1272.0, 35.6651
47.917494069, 96.390, 1291.0, 35.9305
47.970015200, 96.390, 1335.0, 36.5377
48.022536331, 96.390, 1330.0, 36.4692
48.075057462, 96.390, 1388.0, 37.2559
48.127578592, 96.390, 1514.0, 38.9102
48.180099723, 96.390, 1501.0, 38.7427
48.232620854, 96.390, 1438.0, 37.9210
48.285141984, 96.390, 1417.0, 37.6431
48.337663115, 96.390, 1320.0, 36.3318
48.390184246, 96.390, 1388.0, 37.2559
48.442705377, 96.390, 1516.0, 38.9358
48.495226507, 96.390, 1575.0, 39.6863
48.547747638, 96.390, 1559.0, 39.4842
48.600268769, 96.390, 1432.0, 37.8418
48.652789899, 96.390, 1412.0, 37.5766
48.705311030, 96.390, 1233.0, 35.1141
48.757832161, 96.390, 1187.0, 34.4529
48.810353292, 96.390, 1166.0, 34.1467
48.862874422, 96.390, 1249.0, 35.3412
48.915395553, 96.390, 1184.0, 34.4093
48.967916684, 96.390, 1201.0, 34.6554
49.020437814, 96.390, 1214.0, 34.8425
49.072958945, 96.390, 1188.0, 34.4674
49.125480076, 96.390, 1134.0, 33.6749
49.178001207, 96.390, 1212.0, 34.8138
49.230522337, 96.390, 1074.0, 32.7719
49.283043468, 96.390, 1200.0, 34.6410
49.335564599, 96.390, 1129.0, 33.6006
49.388085729, 96.390, 1193.0, 34.5398
49.440606860, 96.390, 1288.0, 35.8887
49.493127991, 96.390, 1148.0, 33.8821
49.545649121, 96.390, 1237.0, 35.1710
49.598170252, 96.390, 1139.0, 33.7491
49.650691383, 96.390, 1245.0, 35.2846
49.703212514, 96.390, 1282.0, 35.8050
49.755733644, 96.390, 1220.0, 34.9285
49.808254775, 96.390, 1144.0, 33.8231
49.860775906, 96.390, 1183.0, 34.3948
49.913297036, 96.390, 1123.0, 33.5112
49.965818167, 96.390, 1078.0, 32.8329
50.018339298, 96.390, 1157.0, 34.0147
50.070860429, 96.390, 1134.0, 33.6749
50.123381559, 96.390, 1152.0, 33.9411
50.175902690, 96.390, 1281.0, 35.7911
50.228423821, 96.390, 1334.0, 36.5240
50.280944951, 96.390, 1499.0, 38.7169
50.333466082, 96.390, 1279.0, 35.7631
50.385987213, 96.390, 1353.0, 36.7831
50.438508344, 96.390, 1231.0, 35.0856
50.491029474, 96.390, 1136.0, 33.7046
50.543550605, 96.390, 1150.0, 33.9116
50.596071736, 96.390, 1074.0, 32.7719
50.648592866, 96.390, 1041.0, 32.2645
50.701113997, 96.390, 1065.0, 32.6343
50.753635128, 96.390, 1054.0, 32.4654
50.806156258, 96.390, 983.0, 31.3528
50.858677389, 96.390, 1051.0, 32.4191
50.911198520, 96.390, 1056.0, 32.4962
50.963719651, 96.390, 1046.0, 32.3419
51.016240781, 96.390, 1058.0, 32.5269
51.068761912, 96.390, 1125.0, 33.5410
51.121283043, 96.390, 1164.0, 34.1174
51.173804173, 96.390, 1190.0, 34.4964
51.226325304, 96.390, 1157.0, 34.0147
51.278846435, 96.390, 1154.0, 33.9706
51.331367566, 96.390, 1137.0, 33.7194
51.383888696, 96.390, 1192.0, 34.5254
51.436409827, 96.390, 1088.0, 32.9848
51.488930958, 96.390, 980.0, 31.3050
51.541452088, 96.390, 1003.0, 31.6702
51.593973219, 96.390, 1036.0, 32.1870
51.646494350, 96.390, 962.0, 31.0161
51.699015481, 96.390, 1039.0, 32.2335
51.751536611, 96.390, 1038.0, 32.2180
51.804057742, 96.390, 1080.0, 32.8634
51.856578873, 96.390, 1107.0, 33.2716
51.909100003, 96.390, 1095.0, 33.0908
51.961621134, 96.390, 1119.0, 33.4515
52.014142265, 96.390, 1102.0, 33.1964
52.066663396, 96.390, 1110.0, 33.3167
52.119184526, 96.390, 1185.0, 34.4238
52.171705657, 96.390, 1294.0, 35.9722
52.224226788, 96.390, 1389.0, 37.2693
52.276747918, 96.390, 1410.0, 37.5500
52.329269049, 96.390, 1339.0, 36.5923
52.381790180, 96.390, 1296.0, 36.0000
52.434311310, 96.390, 1212.0, 34.8138
52.486832441, 96.390, 1122.0, 33.4963
52.539353572, 96.390, 1109.0, 33.3017
52.591874703, 96.390, 1178.0, 34.3220
52.644395833, 96.390, 1020.0, 31.9374
52.696916964, 96.390, 1073.0, 32.7567
52.749438095, 96.390, 1086.0, 32.9545
52.801959225, 96.390, 1067.0, 32.6650
52.854480356, 96.390, 1080.0, 32.8634
52.907001487, 96.390, 1154.0, 33.9706
52.959522618, 96.390, 1112.0, 33.3467
53.012043748, 96.390, 1071.0, 32.7261
53.064564879, 96.390, 1046.0, 32.3419
53.117086010, 96.390, 1042.0, 32.2800
53.169607140, 96.390, 1089.0, 33.0000
53.222128271, 96.390, 1081.0, 32.8786
53.274649402, 96.390, 1110.0, 33.3167
53.327170533, 96.390, 1124.0, 33.5261
53.379691663, 96.390, 1087.0, 32.9697
53.432212794, 96.390, 1027.0, 32.0468
53.484733925, 96.390, 1044.0, 32.3110
53.537255055, 96.390, 1037.0, 32.2025
53.589776186, 96.390, 1003.0, 31.6702
53.642297317, 96.390, 1017.0, 31.8904
53.694818448, 96.390, 1024.0, 32.0000
53.747339578, 96.390, 918.0, 30.2985
53.799860709, 96.390, 994.0, 31.5278
53.852381840, 96.390, 990.0, 31.4643
53.904902970, 96.390, 996.0, 31.5595
53.957424101, 96.390, 966.0, 31.0805
54.009945232, 96.390, 1046.0, 32.3419
54.062466362, 96.390, 1134.0, 33.6749
54.114987493, 96.390, 1114.0, 33.3766
54.167508624, 96.390, 1211.0, 34.7994
54.220029755, 96.390, 1140.0, 33.7639
54.272550885, 96.390, 1174.0, 34.2637
54.325072016, 96.390, 1161.0, 34.0735
54.377593147, 96.390, 1210.0, 34.7851
54.430114277, 96.390, 1130.0, 33.6155
54.482635408, 96.390, 1023.0, 31.9844
54.535156539, 96.390, 1047.0, 32.3574
54.587677670, 96.390, 1016.0, 31.8748
54.640198800, 96.390, 1000.0, 31.6228
54.692719931, 96.390, 985.0, 31.3847
54.745241062, 96.390, 968.0, 31.1127
54.797762192, 96.390, 936.0, 30.5941
54.850283323, 96.390, 904.0, 30.0666
54.902804454, 96.390, 1003.0, 31.6702
54.955325585, 96.390, 969.0, 31.1288
55.007846715, 96.390, 969.0, 31.1288
55.060367846, 96.390, 932.0, 30.5287
55.112888977, 96.390, 979.0, 31.2890
55.165410107, 96.390, 953.0, 30.8707
55.217931238, 96.390, 959.0, 30.9677
55.270452369, 96.390, 932.0, 30.5287
55.322973499, 96.390, 878.0, 29.6311
55.375494630, 96.390, 944.0, 30.7246
55.428015761, 96.390, 939.0, 30.6431
55.480536892, 96.390, 956.0, 30.9192
55.533058022, 96.390, 1068.0, 32.6803
55.585579153, 96.390, 1053.0, 32.4500
55.638100284, 96.390, 997.0, 31.5753
55.690621414, 96.390, 1007.0, 31.7333
55.743142545, 96.390, 941.0, 30.6757
55.795663676, 96.390, 1033.0, 32.1403
55.848184807, 96.390, 965.0, 31.0644
55.900705937, 96.390, 890.0, 29.8329
55.953227068, 96.390, 875.0, 29.5804
56.005748199, 96.390, 901.0, 30.0167
56.058269329, 96.390, 971.0, 31.1609
56.110790460, 96.390, 1018.0, 31.9061
56.163311591, 96.390, 929.0, 30.4795
56.215832722, 96.390, 970.0, 31.1448
56.268353852, 96.390, 916.0, 30.2655
56.320874983, 96.390, 899.0, 29.9833
56.373396114, 96.390, 883.0, 29.7153
56.425917244, 96.390, 877.0, 29.6142
56.478438375, 96.390, 927.0, 30.4467
56.530959506, 96.390, 916.0, 30.2655
56.583480637, 96.390, 1005.0, 31.7017
56.636001767, 96.390, 884.0, 29.7321
56.688522898, 96.390, 878.0, 29.6311
56.741044029, 96.390, 855.0, 29.2404
56.793565159, 96.390, 953.0, 30.8707
56.846086290, 96.390, 886.0, 29.7658
56.898607421, 96.390, 904.0, 30.0666
56.951128551, 96.390, 915.0, 30.2490
57.003649682, 96.390, 932.0, 30.5287
57.056170813, 96.390, 879.0, 29.6479
57.108691944, 96.390, 883.0, 29.7153
57.161213074, 96.390, 902.0, 30.0333
57.213734205, 96.390, 846.0, 29.0861
57.266255336, 96.390, 919.0, 30.3150
57.318776466, 96.390, 936.0, 30.5941
57.371297597, 96.390, 987.0, 31.4166
57.423818728, 96.390, 897.0, 29.9500
57.476339859, 96.390, 967.0, 31.0966
57.528860989, 96.390, 1009.0, 31.7648
57.581382120, 96.390, 935.0, 30.5778
57.633903251, 96.390, 981.0, 31.3209
57.686424381, 96.390, 946.0, 30.7571
57.738945512, 96.390, 1017.0, 31.8904
57.791466643, 96.390, 958.0, 30.9516
57.843987774, 96.390, 888.0, 29.7993
57.896508904, 96.390, 1017.0, 31.8904
57.949030035, 96.390, 1046.0, 32.3419
58.001551166, 96.390, 1059.0, 32.5423
58.054072296, 96.390, 1215.0, 34.8569
58.106593427, 96.390, 1204.0, 34.6987
58.159114558, 96.390, 997.0, 31.5753
58.211635689, 96.390, 1036.0, 32.1870
58.264156819, 96.390, 1094.0, 33.0757
58.316677950, 96.390, 955.0, 30.9031
58.369199081, 96.390, 980.0, 31.3050
58.421720211, 96.390, 885.0, 29.7489
58.474241342, 96.390, 864.0, 29.3939
58.526762473, 96.390, 931.0, 30.5123
58.579283603, 96.390, 931.0, 30.5123
58.631804734, 96.390, 927.0, 30.4467
58.684325865, 96.390, 969.0, 31.1288
58.736846996, 96.390, 944.0, 30.7246
58.789368126, 96.390, 941.0, 30.6757
58.841889257, 96.390, 884.0, 29.7321
58.894410388, 96.390, 879.0, 29.6479
58.946931518, 96.390, 946.0, 30.7571
58.999452649, 96.390, 931.0, 30.5123
59.051973780, 96.390, 939.0, 30.6431
59.104494911, 96.390, 902.0, 30.0333
59.157016041, 96.390, 940.0, 30.6594
59.209537172, 96.390, 988.0, 31.4325
59.262058303, 96.390, 1048.0, 32.3728
59.314579433, 96.390, 1040.0, 32.2490
59.367100564, 96.390, 1096.0, 33.1059
59.419621695, 96.390, 1021.0, 31.9531
59.472142826, 96.390, 1066.0, 32.6497
59.524663956, 96.390, 1101.0, 33.1813
59.577185087, 96.390, 1147.0, 33.8674
59.629706218, 96.390, 1024.0, 32.0000
59.682227348, 96.390, 1142.0, 33.7935
59.734748479, 96.390, 1144.0, 33.8231
59.787269610, 96.390, 1135.0, 33.6898
59.839790740, 96.390, 1239.0, 35.1994
59.892311871, 96.390, 1159.0, 34.0441
59.944833002, 96.390, 1247.0, 35.3129
59.997354133, 96.390, 1344.0, 36.6606
60.049875263, 96.390, 1342.0, 36.6333
60.102396394, 96.390, 1328.0, 36.4417
60.154917525, 96.390, 1396.0, 37.3631
60.207438655, 96.390, 1407.0, 37.5100
60.259959786, 96.390, 1429.0, 37.8021
60.312480917, 96.390, 1445.0, 38.0132
60.365002048, 96.390, 1515.0, 38.9230
60.417523178, 96.390, 1537.0, 39.2046
60.470044309, 96.390, 1521.0, 39.0000
60.522565440, 96.390, 1579.0, 39.7366
60.575086570, 96.390, 1579.0, 39.7366
60.627607701, 96.390, 1643.0, 40.5339
60.680128832, 96.390, 1659.0, 40.7308
60.732649963, 96.390, 1638.0, 40.4722
60.785171093, 96.390, 1637.0, 40.4599
60.837692224, 96.390, 1665.0, 40.8044
60.890213355, 96.390, 1630.0, 40.3733
60.942734485, 96.390, 1560.0, 39.4968
60.995255616, 96.390, 1560.0, 39.4968
61.047776747, 96.390, 1594.0, 39.9249
61.100297878, 96.390, 1604.0, 40.0500
61.152819008, 96.390, 1454.0, 38.1314
61.205340139, 96.390, 1535.0, 39.1791
61.257861270, 96.390, 1519.0, 38.9744
61.310382400, 96.390, 1540.0, 39.2428
61.362903531, 96.390, 1522.0, 39.0128
61.415424662, 96.390, 1490.0, 38.6005
61.467945792, 96.390, 1539.0, 39.2301
61.520466923, 96.390, 1626.0, 40.3237
61.572988054, 96.390, 1466.0, 38.2884
61.625509185, 96.390, 1440.0, 37.9473
61.678030315, 96.390, 1485.0, 38.5357
61.730551446, 96.390, 1416.0, 37.6298
61.783072577, 96.390, 1310.0, 36.1939
61.835593707, 96.390, 1369.0, 37.0000
61.888114838, 96.390, 1360.0, 36.8782
61.940635969, 96.390, 1350.0, 36.7423
61.993157100, 96.390, 1356.0, 36.8239
62.045678230, 96.390, 1291.0, 35.9305
62.098199361, 96.390, 1269.0, 35.6230
62.150720492, 96.390, 1230.0, 35.0714
62.203241622, 96.390, 1194.0, 34.5543
62.255762753, 96.390, 1145.0, 33.8378
62.308283884, 96.390, 1166.0, 34.1467
62.360805015, 96.390, 1101.0, 33.1813
62.413326145, 96.390, 1054.0, 32.4654
62.465847276, 96.390, 1122.0, 33.4963
62.518368407, 96.390, 1056.0, 32.4962
62.570889537, 96.390, 1098.0, 33.1361
62.623410668, 96.390, 1086.0, 32.9545
62.675931799, 96.390, 1163.0, 34.1028
62.728452930, 96.390, 1095.0, 33.0908
62.780974060, 96.390, 1013.0, 31.8277
62.833495191, 96.390, 1036.0, 32.1870
62.886016322, 96.390, 1014.0, 31.8434
62.938537452, 96.390, 949.0, 30.8058
62.991058583, 96.390, 886.0, 29.7658
63.043579714, 96.390, 879.0, 29.6479
63.096100844, 96.390, 812.0, 28.4956
63.148621975, 96.390, 878.0, 29.6311
63.201143106, 96.390, 804.0, 28.3549
63.253664237, 96.390, 874.0, 29.5635
63.306185367, 96.390, 830.0, 28.8097
63.358706498, 96.390, 877.0, 29.6142
63.411227629, 96.390, 789.0, 28.0891
63.463748759, 96.390, 851.0, 29.1719
63.516269890, 96.390, 829.0, 28.7924
63.568791021, 96.390, 807.0, 28.4077
63.621312152, 96.390, 827.0, 28.7576
63.673833282, 96.390, 827.0, 28.7576
63.726354413, 96.390, 875.0, 29.5804
63.778875544, 96.390, 906.0, 30.0998
63.831396674, 96.390, 893.0, 29.8831
63.883917805, 96.390, 834.0, 28.8791
63.936438936, 96.390, 855.0, 29.2404
63.988960067, 96.390, 888.0, 29.7993
64.041481197, 96.390, 884.0, 29.7321
64.094002328, 96.390, 888.0, 29.7993
64.146523459, 96.390, 857.0, 29.2746
64.199044589, 96.390, 820.0, 28.6356
64.251565720, 96.390, 875.0, 29.5804
64.304086851, 96.390, 859.0, 29.3087
64.356607981, 96.390, 871.0, 29.5127
64.409129112, 96.390, 775.0, 27.8388
64.461650243, 96.390, 784.0, 28.0000
64.514171374, 96.390, 817.0, 28.5832
64.566692504, 96.390, 764.0, 27.6405
64.619213635, 96.390, 766.0, 27.6767
64.671734766, 96.390, 772.0, 27.7849
64.724255896, 96.390, 770.0, 27.7489
64.776777027, 96.390, 715.0, 26.7395
64.829298158, 96.390, 754.0, 27.4591
64.881819289, 96.390, 725.0, 26.9258
64.934340419, 96.390, 777.0, 27.8747
64.986861550, 96.390, 754.0, 27.4591