File: Files_organized_for_plots/Constant_NaOH_1mL10M_to_1gPC_28Day/XRD_P04Free14Apr22_Act03May22_B1_1000M_NaOH_LS0131_1.csv
[Measurement conditions]
Sample identification,XRD_P04Free14Apr22_Act03May22_B1_1000M_NaOH_LS0131_1
Comment - 1,"Configuration=Stage for Flat Samples/Holders, Owner=User-1, Creation date=7/1/2020 9:53:24 AM"
Comment - 2,"Goniometer=Theta/Theta; Minimum step size 2Theta:0.0001; Minimum step size Omega:0.0001"
Comment - 3,"Sample stage=Stage for flat samples/holders"
Comment - 4,"Diffractometer system=EMPYREAN"
Comment - 5,"Measurement program=C:\Users\ibo5034\OneDrive - The Pennsylvania State University\NEUP\Zerobackground scan.xrdmp, Identifier={98A3B11C-88F9-4AA6-982C-73314A311EF5}"
Anode material,Cu
K-Alpha1 wavelength,1.5405980
K-Alpha2 wavelength,1.5444260
Ratio K-Alpha2/K-Alpha1,0.500
Divergence slit,Fixed,0.25
Monochromator used,NO
Generator voltage, 45
Tube current, 40
File date and time,03/Jun/2022 16:09
Unit cell,
h k l, 0 0 0
Scan axis,Gonio
Scan range,4.994599997,64.999991833
Scan step size,0.0262606
No. of points, 2285
Scan type,CONTINUOUS
Time per step,96.390
[Scan points]
Angle, TimePerStep, Intensity, ESD
5.007730280, 96.390, 4986.0, 70.6116
5.060251411, 96.390, 5012.0, 70.7955
5.112772541, 96.390, 4935.0, 70.2496
5.165293672, 96.390, 5064.0, 71.1618
5.217814803, 96.390, 5074.0, 71.2320
5.270335934, 96.390, 4920.0, 70.1427
5.322857064, 96.390, 5038.0, 70.9789
5.375378195, 96.390, 5283.0, 72.6842
5.427899326, 96.390, 5201.0, 72.1180
5.480420456, 96.390, 5335.0, 73.0411
5.532941587, 96.390, 5736.0, 75.7364
5.585462718, 96.390, 5812.0, 76.2365
5.637983849, 96.390, 6086.0, 78.0128
5.690504979, 96.390, 6414.0, 80.0875
5.743026110, 96.390, 6926.0, 83.2226
5.795547241, 96.390, 6933.0, 83.2646
5.848068371, 96.390, 7388.0, 85.9535
5.900589502, 96.390, 7389.0, 85.9593
5.953110633, 96.390, 7097.0, 84.2437
6.005631763, 96.390, 7307.0, 85.4810
6.058152894, 96.390, 7020.0, 83.7854
6.110674025, 96.390, 7016.0, 83.7616
6.163195156, 96.390, 7098.0, 84.2496
6.215716286, 96.390, 6985.0, 83.5763
6.268237417, 96.390, 6818.0, 82.5712
6.320758548, 96.390, 6709.0, 81.9085
6.373279678, 96.390, 6590.0, 81.1788
6.425800809, 96.390, 6532.0, 80.8208
6.478321940, 96.390, 6469.0, 80.4301
6.530843071, 96.390, 6248.0, 79.0443
6.583364201, 96.390, 6285.0, 79.2780
6.635885332, 96.390, 5960.0, 77.2010
6.688406463, 96.390, 5679.0, 75.3591
6.740927593, 96.390, 5801.0, 76.1643
6.793448724, 96.390, 5398.0, 73.4711
6.845969855, 96.390, 5309.0, 72.8629
6.898490986, 96.390, 5283.0, 72.6842
6.951012116, 96.390, 5182.0, 71.9861
7.003533247, 96.390, 4990.0, 70.6399
7.056054378, 96.390, 5000.0, 70.7107
7.108575508, 96.390, 4756.0, 68.9638
7.161096639, 96.390, 4697.0, 68.5347
7.213617770, 96.390, 4643.0, 68.1396
7.266138900, 96.390, 4566.0, 67.5722
7.318660031, 96.390, 4484.0, 66.9627
7.371181162, 96.390, 4375.0, 66.1438
7.423702293, 96.390, 4286.0, 65.4675
7.476223423, 96.390, 4221.0, 64.9692
7.528744554, 96.390, 4167.0, 64.5523
7.581265685, 96.390, 3974.0, 63.0397
7.633786815, 96.390, 3910.0, 62.5300
7.686307946, 96.390, 3884.0, 62.3217
7.738829077, 96.390, 3789.0, 61.5549
7.791350208, 96.390, 3711.0, 60.9180
7.843871338, 96.390, 3669.0, 60.5723
7.896392469, 96.390, 3700.0, 60.8276
7.948913600, 96.390, 3417.0, 58.4551
8.001434730, 96.390, 3471.0, 58.9152
8.053955861, 96.390, 3375.0, 58.0948
8.106476992, 96.390, 3500.0, 59.1608
8.158998123, 96.390, 3344.0, 57.8273
8.211519253, 96.390, 3348.0, 57.8619
8.264040384, 96.390, 3313.0, 57.5587
8.316561515, 96.390, 3252.0, 57.0263
8.369082645, 96.390, 3250.0, 57.0088
8.421603776, 96.390, 3168.0, 56.2850
8.474124907, 96.390, 3138.0, 56.0179
8.526646038, 96.390, 3140.0, 56.0357
8.579167168, 96.390, 3083.0, 55.5248
8.631688299, 96.390, 3136.0, 56.0000
8.684209430, 96.390, 3124.0, 55.8928
8.736730560, 96.390, 2984.0, 54.6260
8.789251691, 96.390, 3101.0, 55.6866
8.841772822, 96.390, 3087.0, 55.5608
8.894293952, 96.390, 2891.0, 53.7680
8.946815083, 96.390, 3009.0, 54.8544
8.999336214, 96.390, 2960.0, 54.4059
9.051857345, 96.390, 2908.0, 53.9259
9.104378475, 96.390, 2942.0, 54.2402
9.156899606, 96.390, 3013.0, 54.8908
9.209420737, 96.390, 2920.0, 54.0370
9.261941867, 96.390, 2932.0, 54.1479
9.314462998, 96.390, 3001.0, 54.7814
9.366984129, 96.390, 2909.0, 53.9351
9.419505260, 96.390, 2985.0, 54.6352
9.472026390, 96.390, 3066.0, 55.3715
9.524547521, 96.390, 3040.0, 55.1362
9.577068652, 96.390, 2924.0, 54.0740
9.629589782, 96.390, 3027.0, 55.0182
9.682110913, 96.390, 3084.0, 55.5338
9.734632044, 96.390, 3149.0, 56.1160
9.787153175, 96.390, 3182.0, 56.4092
9.839674305, 96.390, 3292.0, 57.3760
9.892195436, 96.390, 3413.0, 58.4209
9.944716567, 96.390, 3471.0, 58.9152
9.997237697, 96.390, 3829.0, 61.8789
10.049758828, 96.390, 3963.0, 62.9524
10.102279959, 96.390, 3853.0, 62.0725
10.154801090, 96.390, 3468.0, 58.8897
10.207322220, 96.390, 3432.0, 58.5833
10.259843351, 96.390, 3406.0, 58.3609
10.312364482, 96.390, 3167.0, 56.2761
10.364885612, 96.390, 3194.0, 56.5155
10.417406743, 96.390, 3293.0, 57.3847
10.469927874, 96.390, 3129.0, 55.9375
10.522449004, 96.390, 3221.0, 56.7539
10.574970135, 96.390, 3319.0, 57.6108
10.627491266, 96.390, 3263.0, 57.1227
10.680012397, 96.390, 3192.0, 56.4978
10.732533527, 96.390, 3366.0, 58.0172
10.785054658, 96.390, 3297.0, 57.4195
10.837575789, 96.390, 3450.0, 58.7367
10.890096919, 96.390, 3260.0, 57.0964
10.942618050, 96.390, 3402.0, 58.3267
10.995139181, 96.390, 3263.0, 57.1227
11.047660312, 96.390, 3372.0, 58.0689
11.100181442, 96.390, 3467.0, 58.8812
11.152702573, 96.390, 3370.0, 58.0517
11.205223704, 96.390, 3481.0, 59.0000
11.257744834, 96.390, 3557.0, 59.6406
11.310265965, 96.390, 3396.0, 58.2752
11.362787096, 96.390, 3410.0, 58.3952
11.415308227, 96.390, 3590.0, 59.9166
11.467829357, 96.390, 3602.0, 60.0167
11.520350488, 96.390, 3510.0, 59.2453
11.572871619, 96.390, 3617.0, 60.1415
11.625392749, 96.390, 3556.0, 59.6322
11.677913880, 96.390, 3644.0, 60.3656
11.730435011, 96.390, 3697.0, 60.8030
11.782956141, 96.390, 3759.0, 61.3107
11.835477272, 96.390, 3667.0, 60.5558
11.887998403, 96.390, 3660.0, 60.4979
11.940519534, 96.390, 3437.0, 58.6259
11.993040664, 96.390, 3512.0, 59.2621
12.045561795, 96.390, 3285.0, 57.3149
12.098082926, 96.390, 3212.0, 56.6745
12.150604056, 96.390, 3093.0, 55.6147
12.203125187, 96.390, 3144.0, 56.0714
12.255646318, 96.390, 2974.0, 54.5344
12.308167449, 96.390, 2896.0, 53.8145
12.360688579, 96.390, 2831.0, 53.2071
12.413209710, 96.390, 2926.0, 54.0925
12.465730841, 96.390, 2768.0, 52.6118
12.518251971, 96.390, 2705.0, 52.0096
12.570773102, 96.390, 2608.0, 51.0686
12.623294233, 96.390, 2583.0, 50.8232
12.675815364, 96.390, 2620.0, 51.1859
12.728336494, 96.390, 2473.0, 49.7293
12.780857625, 96.390, 2357.0, 48.5489
12.833378756, 96.390, 2439.0, 49.3862
12.885899886, 96.390, 2311.0, 48.0729
12.938421017, 96.390, 2376.0, 48.7442
12.990942148, 96.390, 2311.0, 48.0729
13.043463279, 96.390, 2235.0, 47.2758
13.095984409, 96.390, 2245.0, 47.3814
13.148505540, 96.390, 2197.0, 46.8722
13.201026671, 96.390, 2268.0, 47.6235
13.253547801, 96.390, 2129.0, 46.1411
13.306068932, 96.390, 2067.0, 45.4643
13.358590063, 96.390, 2094.0, 45.7602
13.411111193, 96.390, 2121.0, 46.0543
13.463632324, 96.390, 2074.0, 45.5412
13.516153455, 96.390, 2070.0, 45.4973
13.568674586, 96.390, 2104.0, 45.8694
13.621195716, 96.390, 2056.0, 45.3431
13.673716847, 96.390, 2006.0, 44.7884
13.726237978, 96.390, 2029.0, 45.0444
13.778759108, 96.390, 2028.0, 45.0333
13.831280239, 96.390, 2025.0, 45.0000
13.883801370, 96.390, 2155.0, 46.4220
13.936322501, 96.390, 2175.0, 46.6369
13.988843631, 96.390, 2230.0, 47.2229
14.041364762, 96.390, 2469.0, 49.6890
14.093885893, 96.390, 2429.0, 49.2849
14.146407023, 96.390, 2192.0, 46.8188
14.198928154, 96.390, 2058.0, 45.3652
14.251449285, 96.390, 1920.0, 43.8178
14.303970416, 96.390, 1977.0, 44.4635
14.356491546, 96.390, 1971.0, 44.3959
14.409012677, 96.390, 1949.0, 44.1475
14.461533808, 96.390, 1875.0, 43.3013
14.514054938, 96.390, 1849.0, 43.0000
14.566576069, 96.390, 1861.0, 43.1393
14.619097200, 96.390, 1904.0, 43.6348
14.671618331, 96.390, 1821.0, 42.6732
14.724139461, 96.390, 1826.0, 42.7317
14.776660592, 96.390, 1863.0, 43.1625
14.829181723, 96.390, 1881.0, 43.3705
14.881702853, 96.390, 1884.0, 43.4051
14.934223984, 96.390, 1899.0, 43.5775
14.986745115, 96.390, 1967.0, 44.3509
15.039266245, 96.390, 2139.0, 46.2493
15.091787376, 96.390, 2105.0, 45.8803
15.144308507, 96.390, 2191.0, 46.8081
15.196829638, 96.390, 2364.0, 48.6210
15.249350768, 96.390, 2501.0, 50.0100
15.301871899, 96.390, 2670.0, 51.6720
15.354393030, 96.390, 2849.0, 53.3760
15.406914160, 96.390, 2876.0, 53.6284
15.459435291, 96.390, 2795.0, 52.8678
15.511956422, 96.390, 2716.0, 52.1153
15.564477553, 96.390, 2722.0, 52.1728
15.616998683, 96.390, 2448.0, 49.4773
15.669519814, 96.390, 2335.0, 48.3218
15.722040945, 96.390, 2238.0, 47.3075
15.774562075, 96.390, 2200.0, 46.9042
15.827083206, 96.390, 1959.0, 44.2606
15.879604337, 96.390, 1963.0, 44.3058
15.932125468, 96.390, 1906.0, 43.6578
15.984646598, 96.390, 2035.0, 45.1110
16.037167729, 96.390, 1867.0, 43.2088
16.089688860, 96.390, 1839.0, 42.8836
16.142209990, 96.390, 1797.0, 42.3910
16.194731121, 96.390, 1820.0, 42.6615
16.247252252, 96.390, 1726.0, 41.5452
16.299773382, 96.390, 1778.0, 42.1663
16.352294513, 96.390, 1795.0, 42.3674
16.404815644, 96.390, 1833.0, 42.8135
16.457336775, 96.390, 1788.0, 42.2847
16.509857905, 96.390, 1894.0, 43.5201
16.562379036, 96.390, 1904.0, 43.6348
16.614900167, 96.390, 1855.0, 43.0697
16.667421297, 96.390, 1725.0, 41.5331
16.719942428, 96.390, 1735.0, 41.6533
16.772463559, 96.390, 1711.0, 41.3642
16.824984690, 96.390, 1836.0, 42.8486
16.877505820, 96.390, 1862.0, 43.1509
16.930026951, 96.390, 1833.0, 42.8135
16.982548082, 96.390, 1778.0, 42.1663
17.035069212, 96.390, 1717.0, 41.4367
17.087590343, 96.390, 1631.0, 40.3856
17.140111474, 96.390, 1612.0, 40.1497
17.192632605, 96.390, 1663.0, 40.7799
17.245153735, 96.390, 1616.0, 40.1995
17.297674866, 96.390, 1660.0, 40.7431
17.350195997, 96.390, 1621.0, 40.2616
17.402717127, 96.390, 1675.0, 40.9268
17.455238258, 96.390, 1710.0, 41.3521
17.507759389, 96.390, 1581.0, 39.7618
17.560280520, 96.390, 1691.0, 41.1218
17.612801650, 96.390, 1627.0, 40.3361
17.665322781, 96.390, 1680.0, 40.9878
17.717843912, 96.390, 1622.0, 40.2741
17.770365042, 96.390, 1631.0, 40.3856
17.822886173, 96.390, 1542.0, 39.2683
17.875407304, 96.390, 1582.0, 39.7744
17.927928434, 96.390, 1593.0, 39.9124
17.980449565, 96.390, 1706.0, 41.3038
18.032970696, 96.390, 1749.0, 41.8210
18.085491827, 96.390, 1621.0, 40.2616
18.138012957, 96.390, 1638.0, 40.4722
18.190534088, 96.390, 1653.0, 40.6571
18.243055219, 96.390, 1756.0, 41.9047
18.295576349, 96.390, 1723.0, 41.5090
18.348097480, 96.390, 1726.0, 41.5452
18.400618611, 96.390, 1829.0, 42.7668
18.453139742, 96.390, 1819.0, 42.6497
18.505660872, 96.390, 1799.0, 42.4146
18.558182003, 96.390, 1816.0, 42.6146
18.610703134, 96.390, 1764.0, 42.0000
18.663224264, 96.390, 1786.0, 42.2611
18.715745395, 96.390, 1731.0, 41.6053
18.768266526, 96.390, 1828.0, 42.7551
18.820787657, 96.390, 1797.0, 42.3910
18.873308787, 96.390, 1808.0, 42.5206
18.925829918, 96.390, 1760.0, 41.9524
18.978351049, 96.390, 1786.0, 42.2611
19.030872179, 96.390, 1662.0, 40.7676
19.083393310, 96.390, 1717.0, 41.4367
19.135914441, 96.390, 1720.0, 41.4729
19.188435572, 96.390, 1740.0, 41.7133
19.240956702, 96.390, 1811.0, 42.5558
19.293477833, 96.390, 1817.0, 42.6263
19.345998964, 96.390, 1842.0, 42.9185
19.398520094, 96.390, 1874.0, 43.2897
19.451041225, 96.390, 1809.0, 42.5323
19.503562356, 96.390, 1819.0, 42.6497
19.556083486, 96.390, 1860.0, 43.1277
19.608604617, 96.390, 1870.0, 43.2435
19.661125748, 96.390, 1913.0, 43.7379
19.713646879, 96.390, 1953.0, 44.1928
19.766168009, 96.390, 1973.0, 44.4185
19.818689140, 96.390, 2062.0, 45.4093
19.871210271, 96.390, 2054.0, 45.3211
19.923731401, 96.390, 2153.0, 46.4004
19.976252532, 96.390, 2425.0, 49.2443
20.028773663, 96.390, 2483.0, 49.8297
20.081294794, 96.390, 2556.0, 50.5569
20.133815924, 96.390, 2514.0, 50.1398
20.186337055, 96.390, 2473.0, 49.7293
20.238858186, 96.390, 2220.0, 47.1169
20.291379316, 96.390, 2161.0, 46.4866
20.343900447, 96.390, 1954.0, 44.2041
20.396421578, 96.390, 1930.0, 43.9318
20.448942709, 96.390, 1915.0, 43.7607
20.501463839, 96.390, 1792.0, 42.3320
20.553984970, 96.390, 1893.0, 43.5086
20.606506101, 96.390, 1806.0, 42.4971
20.659027231, 96.390, 1862.0, 43.1509
20.711548362, 96.390, 1873.0, 43.2782
20.764069493, 96.390, 1826.0, 42.7317
20.816590623, 96.390, 1857.0, 43.0929
20.869111754, 96.390, 1989.0, 44.5982
20.921632885, 96.390, 1886.0, 43.4281
20.974154016, 96.390, 1982.0, 44.5197
21.026675146, 96.390, 1998.0, 44.6990
21.079196277, 96.390, 1920.0, 43.8178
21.131717408, 96.390, 1971.0, 44.3959
21.184238538, 96.390, 1950.0, 44.1588
21.236759669, 96.390, 1972.0, 44.4072
21.289280800, 96.390, 1862.0, 43.1509
21.341801931, 96.390, 1955.0, 44.2154
21.394323061, 96.390, 1902.0, 43.6119
21.446844192, 96.390, 1982.0, 44.5197
21.499365323, 96.390, 2082.0, 45.6289
21.551886453, 96.390, 1967.0, 44.3509
21.604407584, 96.390, 2022.0, 44.9667
21.656928715, 96.390, 1992.0, 44.6318
21.709449846, 96.390, 1985.0, 44.5533
21.761970976, 96.390, 2002.0, 44.7437
21.814492107, 96.390, 1957.0, 44.2380
21.867013238, 96.390, 2038.0, 45.1442
21.919534368, 96.390, 1970.0, 44.3847
21.972055499, 96.390, 2024.0, 44.9889
22.024576630, 96.390, 2055.0, 45.3321
22.077097761, 96.390, 2156.0, 46.4327
22.129618891, 96.390, 2136.0, 46.2169
22.182140022, 96.390, 2117.0, 46.0109
22.234661153, 96.390, 2136.0, 46.2169
22.287182283, 96.390, 2250.0, 47.4342
22.339703414, 96.390, 2332.0, 48.2908
22.392224545, 96.390, 2233.0, 47.2546
22.444745675, 96.390, 2294.0, 47.8957
22.497266806, 96.390, 2394.0, 48.9285
22.549787937, 96.390, 2420.0, 49.1935
22.602309068, 96.390, 2506.0, 50.0600
22.654830198, 96.390, 2475.0, 49.7494
22.707351329, 96.390, 2680.0, 51.7687
22.759872460, 96.390, 2647.0, 51.4490
22.812393590, 96.390, 2783.0, 52.7541
22.864914721, 96.390, 2968.0, 54.4794
22.917435852, 96.390, 2983.0, 54.6168
22.969956983, 96.390, 3056.0, 55.2811
23.022478113, 96.390, 3299.0, 57.4369
23.074999244, 96.390, 3397.0, 58.2838
23.127520375, 96.390, 3590.0, 59.9166
23.180041505, 96.390, 3896.0, 62.4179
23.232562636, 96.390, 4025.0, 63.4429
23.285083767, 96.390, 4214.0, 64.9153
23.337604898, 96.390, 4269.0, 65.3376
23.390126028, 96.390, 4151.0, 64.4283
23.442647159, 96.390, 3745.0, 61.1964
23.495168290, 96.390, 3689.0, 60.7371
23.547689420, 96.390, 3497.0, 59.1354
23.600210551, 96.390, 3407.0, 58.3695
23.652731682, 96.390, 3068.0, 55.3895
23.705252813, 96.390, 3170.0, 56.3028
23.757773943, 96.390, 2973.0, 54.5252
23.810295074, 96.390, 2888.0, 53.7401
23.862816205, 96.390, 2833.0, 53.2259
23.915337335, 96.390, 2621.0, 51.1957
23.967858466, 96.390, 2788.0, 52.8015
24.020379597, 96.390, 2674.0, 51.7107
24.072900727, 96.390, 2573.0, 50.7247
24.125421858, 96.390, 2594.0, 50.9313
24.177942989, 96.390, 2586.0, 50.8527
24.230464120, 96.390, 2504.0, 50.0400
24.282985250, 96.390, 2527.0, 50.2693
24.335506381, 96.390, 2718.0, 52.1344
24.388027512, 96.390, 2972.0, 54.5161
24.440548642, 96.390, 3002.0, 54.7905
24.493069773, 96.390, 2657.0, 51.5461
24.545590904, 96.390, 2633.0, 51.3128
24.598112035, 96.390, 2370.0, 48.6826
24.650633165, 96.390, 2300.0, 47.9583
24.703154296, 96.390, 2336.0, 48.3322
24.755675427, 96.390, 2254.0, 47.4763
24.808196557, 96.390, 2141.0, 46.2709
24.860717688, 96.390, 2004.0, 44.7661
24.913238819, 96.390, 2091.0, 45.7275
24.965759950, 96.390, 1981.0, 44.5084
25.018281080, 96.390, 1972.0, 44.4072
25.070802211, 96.390, 1912.0, 43.7264
25.123323342, 96.390, 1917.0, 43.7836
25.175844472, 96.390, 1856.0, 43.0813
25.228365603, 96.390, 1921.0, 43.8292
25.280886734, 96.390, 1906.0, 43.6578
25.333407864, 96.390, 1887.0, 43.4396
25.385928995, 96.390, 1884.0, 43.4051
25.438450126, 96.390, 1910.0, 43.7035
25.490971257, 96.390, 1850.0, 43.0116
25.543492387, 96.390, 1911.0, 43.7150
25.596013518, 96.390, 1867.0, 43.2088
25.648534649, 96.390, 1853.0, 43.0465
25.701055779, 96.390, 1837.0, 42.8602
25.753576910, 96.390, 1819.0, 42.6497
25.806098041, 96.390, 1884.0, 43.4051
25.858619172, 96.390, 1969.0, 44.3734
25.911140302, 96.390, 1963.0, 44.3058
25.963661433, 96.390, 1949.0, 44.1475
26.016182564, 96.390, 2027.0, 45.0222
26.068703694, 96.390, 2035.0, 45.1110
26.121224825, 96.390, 2103.0, 45.8585
26.173745956, 96.390, 2096.0, 45.7821
26.226267087, 96.390, 2129.0, 46.1411
26.278788217, 96.390, 2220.0, 47.1169
26.331309348, 96.390, 2210.0, 47.0106
26.383830479, 96.390, 2365.0, 48.6313
26.436351609, 96.390, 2441.0, 49.4065
26.488872740, 96.390, 2648.0, 51.4587
26.541393871, 96.390, 2827.0, 53.1695
26.593915002, 96.390, 3053.0, 55.2540
26.646436132, 96.390, 3291.0, 57.3672
26.698957263, 96.390, 3204.0, 56.6039
26.751478394, 96.390, 3176.0, 56.3560
26.803999524, 96.390, 2875.0, 53.6190
26.856520655, 96.390, 2605.0, 51.0392
26.909041786, 96.390, 2579.0, 50.7839
26.961562916, 96.390, 2394.0, 48.9285
27.014084047, 96.390, 2229.0, 47.2123
27.066605178, 96.390, 2165.0, 46.5296
27.119126309, 96.390, 2164.0, 46.5188
27.171647439, 96.390, 2063.0, 45.4203
27.224168570, 96.390, 2053.0, 45.3100
27.276689701, 96.390, 1985.0, 44.5533
27.329210831, 96.390, 1923.0, 43.8520
27.381731962, 96.390, 1981.0, 44.5084
27.434253093, 96.390, 1917.0, 43.7836
27.486774224, 96.390, 1967.0, 44.3509
27.539295354, 96.390, 1950.0, 44.1588
27.591816485, 96.390, 1888.0, 43.4511
27.644337616, 96.390, 1868.0, 43.2204
27.696858746, 96.390, 1820.0, 42.6615
27.749379877, 96.390, 1897.0, 43.5546
27.801901008, 96.390, 1942.0, 44.0681
27.854422139, 96.390, 1902.0, 43.6119
27.906943269, 96.390, 1853.0, 43.0465
27.959464400, 96.390, 1820.0, 42.6615
28.011985531, 96.390, 1865.0, 43.1856
28.064506661, 96.390, 1908.0, 43.6807
28.117027792, 96.390, 1916.0, 43.7721
28.169548923, 96.390, 1965.0, 44.3283
28.222070054, 96.390, 2000.0, 44.7214
28.274591184, 96.390, 2004.0, 44.7661
28.327112315, 96.390, 2051.0, 45.2880
28.379633446, 96.390, 2015.0, 44.8888
28.432154576, 96.390, 1954.0, 44.2041
28.484675707, 96.390, 1976.0, 44.4522
28.537196838, 96.390, 1970.0, 44.3847
28.589717968, 96.390, 2054.0, 45.3211
28.642239099, 96.390, 1996.0, 44.6766
28.694760230, 96.390, 1965.0, 44.3283
28.747281361, 96.390, 2003.0, 44.7549
28.799802491, 96.390, 2063.0, 45.4203
28.852323622, 96.390, 2101.0, 45.8367
28.904844753, 96.390, 2092.0, 45.7384
28.957365883, 96.390, 2229.0, 47.2123
29.009887014, 96.390, 2319.0, 48.1560
29.062408145, 96.390, 2326.0, 48.2286
29.114929276, 96.390, 2476.0, 49.7594
29.167450406, 96.390, 2584.0, 50.8331
29.219971537, 96.390, 2576.0, 50.7543
29.272492668, 96.390, 2616.0, 51.1468
29.325013798, 96.390, 2538.0, 50.3786
29.377534929, 96.390, 2496.0, 49.9600
29.430056060, 96.390, 2464.0, 49.6387
29.482577191, 96.390, 2366.0, 48.6415
29.535098321, 96.390, 2344.0, 48.4149
29.587619452, 96.390, 2376.0, 48.7442
29.640140583, 96.390, 2229.0, 47.2123
29.692661713, 96.390, 2320.0, 48.1664
29.745182844, 96.390, 2270.0, 47.6445
29.797703975, 96.390, 2214.0, 47.0532
29.850225105, 96.390, 2281.0, 47.7598
29.902746236, 96.390, 2292.0, 47.8748
29.955267367, 96.390, 2311.0, 48.0729
30.007788498, 96.390, 2299.0, 47.9479
30.060309628, 96.390, 2282.0, 47.7703
30.112830759, 96.390, 2315.0, 48.1144
30.165351890, 96.390, 2385.0, 48.8365
30.217873020, 96.390, 2426.0, 49.2544
30.270394151, 96.390, 2566.0, 50.6557
30.322915282, 96.390, 2510.0, 50.0999
30.375436413, 96.390, 2559.0, 50.5866
30.427957543, 96.390, 2553.0, 50.5272
30.480478674, 96.390, 2714.0, 52.0961
30.532999805, 96.390, 2820.0, 53.1037
30.585520935, 96.390, 2848.0, 53.3667
30.638042066, 96.390, 2905.0, 53.8981
30.690563197, 96.390, 3032.0, 55.0636
30.743084328, 96.390, 3169.0, 56.2939
30.795605458, 96.390, 3366.0, 58.0172
30.848126589, 96.390, 3403.0, 58.3352
30.900647720, 96.390, 3536.0, 59.4643
30.953168850, 96.390, 3474.0, 58.9406
31.005689981, 96.390, 3474.0, 58.9406
31.058211112, 96.390, 3358.0, 57.9483
31.110732243, 96.390, 3210.0, 56.6569
31.163253373, 96.390, 3172.0, 56.3205
31.215774504, 96.390, 2977.0, 54.5619
31.268295635, 96.390, 2882.0, 53.6843
31.320816765, 96.390, 2914.0, 53.9815
31.373337896, 96.390, 2830.0, 53.1977
31.425859027, 96.390, 2762.0, 52.5547
31.478380157, 96.390, 2777.0, 52.6972
31.530901288, 96.390, 2716.0, 52.1153
31.583422419, 96.390, 2715.0, 52.1057
31.635943550, 96.390, 2899.0, 53.8424
31.688464680, 96.390, 2858.0, 53.4603
31.740985811, 96.390, 2789.0, 52.8110
31.793506942, 96.390, 2702.0, 51.9808
31.846028072, 96.390, 2687.0, 51.8363
31.898549203, 96.390, 2631.0, 51.2933
31.951070334, 96.390, 2661.0, 51.5849
32.003591465, 96.390, 2539.0, 50.3885
32.056112595, 96.390, 2554.0, 50.5371
32.108633726, 96.390, 2637.0, 51.3517
32.161154857, 96.390, 2485.0, 49.8498
32.213675987, 96.390, 2536.0, 50.3587
32.266197118, 96.390, 2742.0, 52.3641
32.318718249, 96.390, 2748.0, 52.4214
32.371239380, 96.390, 2871.0, 53.5817
32.423760510, 96.390, 2779.0, 52.7162
32.476281641, 96.390, 2686.0, 51.8266
32.528802772, 96.390, 2564.0, 50.6360
32.581323902, 96.390, 2489.0, 49.8899
32.633845033, 96.390, 2357.0, 48.5489
32.686366164, 96.390, 2223.0, 47.1487
32.738887295, 96.390, 2293.0, 47.8853
32.791408425, 96.390, 2199.0, 46.8935
32.843929556, 96.390, 2082.0, 45.6289
32.896450687, 96.390, 2137.0, 46.2277
32.948971817, 96.390, 2158.0, 46.4543
33.001492948, 96.390, 2128.0, 46.1303
33.054014079, 96.390, 2108.0, 45.9130
33.106535209, 96.390, 2184.0, 46.7333
33.159056340, 96.390, 2206.0, 46.9681
33.211577471, 96.390, 2220.0, 47.1169
33.264098602, 96.390, 2265.0, 47.5920
33.316619732, 96.390, 2311.0, 48.0729
33.369140863, 96.390, 2531.0, 50.3090
33.421661994, 96.390, 2545.0, 50.4480
33.474183124, 96.390, 2562.0, 50.6162
33.526704255, 96.390, 2692.0, 51.8845
33.579225386, 96.390, 3598.0, 59.9833
33.631746517, 96.390, 2891.0, 53.7680
33.684267647, 96.390, 2971.0, 54.5069
33.736788778, 96.390, 2479.0, 49.7896
33.789309909, 96.390, 2463.0, 49.6286
33.841831039, 96.390, 2570.0, 50.6952
33.894352170, 96.390, 2456.0, 49.5580
33.946873301, 96.390, 2420.0, 49.1935
33.999394432, 96.390, 2461.0, 49.6085
34.051915562, 96.390, 2377.0, 48.7545
34.104436693, 96.390, 2465.0, 49.6488
34.156957824, 96.390, 2512.0, 50.1199
34.209478954, 96.390, 2575.0, 50.7445
34.262000085, 96.390, 2553.0, 50.5272
34.314521216, 96.390, 2543.0, 50.4282
34.367042346, 96.390, 2621.0, 51.1957
34.419563477, 96.390, 2685.0, 51.8170
34.472084608, 96.390, 2716.0, 52.1153
34.524605739, 96.390, 2711.0, 52.0673
34.577126869, 96.390, 2803.0, 52.9434
34.629648000, 96.390, 2847.0, 53.3573
34.682169131, 96.390, 2921.0, 54.0463
34.734690261, 96.390, 2974.0, 54.5344
34.787211392, 96.390, 3034.0, 55.0818
34.839732523, 96.390, 3047.0, 55.1996
34.892253654, 96.390, 2878.0, 53.6470
34.944774784, 96.390, 2868.0, 53.5537
34.997295915, 96.390, 2887.0, 53.7308
35.049817046, 96.390, 2706.0, 52.0192
35.102338176, 96.390, 2653.0, 51.5073
35.154859307, 96.390, 2656.0, 51.5364
35.207380438, 96.390, 2554.0, 50.5371
35.259901569, 96.390, 2554.0, 50.5371
35.312422699, 96.390, 2467.0, 49.6689
35.364943830, 96.390, 2484.0, 49.8397
35.417464961, 96.390, 2409.0, 49.0816
35.469986091, 96.390, 2502.0, 50.0200
35.522507222, 96.390, 2360.0, 48.5798
35.575028353, 96.390, 2363.0, 48.6107
35.627549484, 96.390, 2286.0, 47.8121
35.680070614, 96.390, 2198.0, 46.8828
35.732591745, 96.390, 2152.0, 46.3897
35.785112876, 96.390, 2220.0, 47.1169
35.837634006, 96.390, 2148.0, 46.3465
35.890155137, 96.390, 2077.0, 45.5741
35.942676268, 96.390, 2173.0, 46.6154
35.995197398, 96.390, 2136.0, 46.2169
36.047718529, 96.390, 2188.0, 46.7761
36.100239660, 96.390, 2124.0, 46.0869
36.152760791, 96.390, 2172.0, 46.6047
36.205281921, 96.390, 2177.0, 46.6583
36.257803052, 96.390, 2233.0, 47.2546
36.310324183, 96.390, 2223.0, 47.1487
36.362845313, 96.390, 2076.0, 45.5631
36.415366444, 96.390, 2169.0, 46.5725
36.467887575, 96.390, 2101.0, 45.8367
36.520408706, 96.390, 2198.0, 46.8828
36.572929836, 96.390, 2154.0, 46.4112
36.625450967, 96.390, 2173.0, 46.6154
36.677972098, 96.390, 2129.0, 46.1411
36.730493228, 96.390, 2180.0, 46.6905
36.783014359, 96.390, 2071.0, 45.5082
36.835535490, 96.390, 2168.0, 46.5618
36.888056621, 96.390, 2021.0, 44.9555
36.940577751, 96.390, 2089.0, 45.7056
36.993098882, 96.390, 2014.0, 44.8776
37.045620013, 96.390, 2054.0, 45.3211
37.098141143, 96.390, 2038.0, 45.1442
37.150662274, 96.390, 2109.0, 45.9239
37.203183405, 96.390, 2095.0, 45.7712
37.255704535, 96.390, 2091.0, 45.7275
37.308225666, 96.390, 2012.0, 44.8553
37.360746797, 96.390, 2075.0, 45.5522
37.413267928, 96.390, 2048.0, 45.2548
37.465789058, 96.390, 2008.0, 44.8107
37.518310189, 96.390, 1956.0, 44.2267
37.570831320, 96.390, 1999.0, 44.7102
37.623352450, 96.390, 2021.0, 44.9555
37.675873581, 96.390, 1971.0, 44.3959
37.728394712, 96.390, 2101.0, 45.8367
37.780915843, 96.390, 2064.0, 45.4313
37.833436973, 96.390, 2077.0, 45.5741
37.885958104, 96.390, 2193.0, 46.8295
37.938479235, 96.390, 2330.0, 48.2701
37.991000365, 96.390, 2318.0, 48.1456
38.043521496, 96.390, 2075.0, 45.5522
38.096042627, 96.390, 2023.0, 44.9778
38.148563758, 96.390, 1917.0, 43.7836
38.201084888, 96.390, 1918.0, 43.7950
38.253606019, 96.390, 1852.0, 43.0349
38.306127150, 96.390, 1839.0, 42.8836
38.358648280, 96.390, 1825.0, 42.7200
38.411169411, 96.390, 1774.0, 42.1189
38.463690542, 96.390, 1817.0, 42.6263
38.516211673, 96.390, 1782.0, 42.2137
38.568732803, 96.390, 1769.0, 42.0595
38.621253934, 96.390, 1827.0, 42.7434
38.673775065, 96.390, 1823.0, 42.6966
38.726296195, 96.390, 1743.0, 41.7493
38.778817326, 96.390, 1755.0, 41.8927
38.831338457, 96.390, 1702.0, 41.2553
38.883859587, 96.390, 1748.0, 41.8091
38.936380718, 96.390, 1681.0, 41.0000
38.988901849, 96.390, 1744.0, 41.7612
39.041422980, 96.390, 1735.0, 41.6533
39.093944110, 96.390, 1683.0, 41.0244
39.146465241, 96.390, 1649.0, 40.6079
39.198986372, 96.390, 1678.0, 40.9634
39.251507502, 96.390, 1706.0, 41.3038
39.304028633, 96.390, 1713.0, 41.3884
39.356549764, 96.390, 1705.0, 41.2916
39.409070895, 96.390, 1638.0, 40.4722
39.461592025, 96.390, 1664.0, 40.7922
39.514113156, 96.390, 1672.0, 40.8901
39.566634287, 96.390, 1662.0, 40.7676
39.619155417, 96.390, 1629.0, 40.3609
39.671676548, 96.390, 1647.0, 40.5832
39.724197679, 96.390, 1698.0, 41.2068
39.776718810, 96.390, 1673.0, 40.9023
39.829239940, 96.390, 1655.0, 40.6817
39.881761071, 96.390, 1620.0, 40.2492
39.934282202, 96.390, 1651.0, 40.6325
39.986803332, 96.390, 1693.0, 41.1461
40.039324463, 96.390, 1629.0, 40.3609
40.091845594, 96.390, 1662.0, 40.7676
40.144366725, 96.390, 1702.0, 41.2553
40.196887855, 96.390, 1767.0, 42.0357
40.249408986, 96.390, 1751.0, 41.8450
40.301930117, 96.390, 1759.0, 41.9404
40.354451247, 96.390, 1759.0, 41.9404
40.406972378, 96.390, 1668.0, 40.8412
40.459493509, 96.390, 1630.0, 40.3733
40.512014639, 96.390, 1625.0, 40.3113
40.564535770, 96.390, 1714.0, 41.4005
40.617056901, 96.390, 1753.0, 41.8688
40.669578032, 96.390, 1822.0, 42.6849
40.722099162, 96.390, 1850.0, 43.0116
40.774620293, 96.390, 1810.0, 42.5441
40.827141424, 96.390, 1908.0, 43.6807
40.879662554, 96.390, 1932.0, 43.9545
40.932183685, 96.390, 1864.0, 43.1741
40.984704816, 96.390, 1834.0, 42.8252
41.037225947, 96.390, 1853.0, 43.0465
41.089747077, 96.390, 1671.0, 40.8779
41.142268208, 96.390, 1793.0, 42.3438
41.194789339, 96.390, 1747.0, 41.7971
41.247310469, 96.390, 1769.0, 42.0595
41.299831600, 96.390, 1747.0, 41.7971
41.352352731, 96.390, 1843.0, 42.9302
41.404873862, 96.390, 1792.0, 42.3320
41.457394992, 96.390, 1688.0, 41.0853
41.509916123, 96.390, 1757.0, 41.9166
41.562437254, 96.390, 1794.0, 42.3556
41.614958384, 96.390, 1699.0, 41.2189
41.667479515, 96.390, 1619.0, 40.2368
41.720000646, 96.390, 1688.0, 41.0853
41.772521776, 96.390, 1642.0, 40.5216
41.825042907, 96.390, 1696.0, 41.1825
41.877564038, 96.390, 1491.0, 38.6135
41.930085169, 96.390, 1536.0, 39.1918
41.982606299, 96.390, 1598.0, 39.9750
42.035127430, 96.390, 1577.0, 39.7115
42.087648561, 96.390, 1579.0, 39.7366
42.140169691, 96.390, 1587.0, 39.8372
42.192690822, 96.390, 1644.0, 40.5463
42.245211953, 96.390, 1602.0, 40.0250
42.297733084, 96.390, 1527.0, 39.0768
42.350254214, 96.390, 1556.0, 39.4462
42.402775345, 96.390, 1521.0, 39.0000
42.455296476, 96.390, 1523.0, 39.0256
42.507817606, 96.390, 1575.0, 39.6863
42.560338737, 96.390, 1517.0, 38.9487
42.612859868, 96.390, 1536.0, 39.1918
42.665380999, 96.390, 1531.0, 39.1280
42.717902129, 96.390, 1527.0, 39.0768
42.770423260, 96.390, 1607.0, 40.0874
42.822944391, 96.390, 1597.0, 39.9625
42.875465521, 96.390, 1663.0, 40.7799
42.927986652, 96.390, 1645.0, 40.5586
42.980507783, 96.390, 1623.0, 40.2865
43.033028914, 96.390, 1626.0, 40.3237
43.085550044, 96.390, 1601.0, 40.0125
43.138071175, 96.390, 1512.0, 38.8844
43.190592306, 96.390, 1446.0, 38.0263
43.243113436, 96.390, 1414.0, 37.6032
43.295634567, 96.390, 1400.0, 37.4166
43.348155698, 96.390, 1467.0, 38.3014
43.400676828, 96.390, 1396.0, 37.3631
43.453197959, 96.390, 1325.0, 36.4005
43.505719090, 96.390, 1388.0, 37.2559
43.558240221, 96.390, 1328.0, 36.4417
43.610761351, 96.390, 1379.0, 37.1349
43.663282482, 96.390, 1359.0, 36.8646
43.715803613, 96.390, 1343.0, 36.6470
43.768324743, 96.390, 1390.0, 37.2827
43.820845874, 96.390, 1322.0, 36.3593
43.873367005, 96.390, 1372.0, 37.0405
43.925888136, 96.390, 1381.0, 37.1618
43.978409266, 96.390, 1394.0, 37.3363
44.030930397, 96.390, 1307.0, 36.1525
44.083451528, 96.390, 1296.0, 36.0000
44.135972658, 96.390, 1306.0, 36.1386
44.188493789, 96.390, 1283.0, 35.8190
44.241014920, 96.390, 1291.0, 35.9305
44.293536051, 96.390, 1362.0, 36.9053
44.346057181, 96.390, 1320.0, 36.3318
44.398578312, 96.390, 1269.0, 35.6230
44.451099443, 96.390, 1286.0, 35.8608
44.503620573, 96.390, 1262.0, 35.5246
44.556141704, 96.390, 1310.0, 36.1939
44.608662835, 96.390, 1317.0, 36.2905
44.661183966, 96.390, 1275.0, 35.7071
44.713705096, 96.390, 1318.0, 36.3043
44.766226227, 96.390, 1357.0, 36.8375
44.818747358, 96.390, 1375.0, 37.0810
44.871268488, 96.390, 1291.0, 35.9305
44.923789619, 96.390, 1332.0, 36.4966
44.976310750, 96.390, 1360.0, 36.8782
45.028831880, 96.390, 1425.0, 37.7492
45.081353011, 96.390, 1489.0, 38.5876
45.133874142, 96.390, 1433.0, 37.8550
45.186395273, 96.390, 1426.0, 37.7624
45.238916403, 96.390, 1501.0, 38.7427
45.291437534, 96.390, 1473.0, 38.3797
45.343958665, 96.390, 1402.0, 37.4433
45.396479795, 96.390, 1438.0, 37.9210
45.449000926, 96.390, 1414.0, 37.6032
45.501522057, 96.390, 1362.0, 36.9053
45.554043188, 96.390, 1373.0, 37.0540
45.606564318, 96.390, 1416.0, 37.6298
45.659085449, 96.390, 1375.0, 37.0810
45.711606580, 96.390, 1393.0, 37.3229
45.764127710, 96.390, 1311.0, 36.2077
45.816648841, 96.390, 1326.0, 36.4143
45.869169972, 96.390, 1310.0, 36.1939
45.921691103, 96.390, 1364.0, 36.9324
45.974212233, 96.390, 1336.0, 36.5513
46.026733364, 96.390, 1359.0, 36.8646
46.079254495, 96.390, 1372.0, 37.0405
46.131775625, 96.390, 1339.0, 36.5923
46.184296756, 96.390, 1475.0, 38.4057
46.236817887, 96.390, 1471.0, 38.3536
46.289339017, 96.390, 1504.0, 38.7814
46.341860148, 96.390, 1369.0, 37.0000
46.394381279, 96.390, 1416.0, 37.6298
46.446902410, 96.390, 1488.0, 38.5746
46.499423540, 96.390, 1444.0, 38.0000
46.551944671, 96.390, 1383.0, 37.1887
46.604465802, 96.390, 1376.0, 37.0945
46.656986932, 96.390, 1454.0, 38.1314
46.709508063, 96.390, 1361.0, 36.8917
46.762029194, 96.390, 1373.0, 37.0540
46.814550325, 96.390, 1362.0, 36.9053
46.867071455, 96.390, 1387.0, 37.2424
46.919592586, 96.390, 1376.0, 37.0945
46.972113717, 96.390, 1372.0, 37.0405
47.024634847, 96.390, 1385.0, 37.2156
47.077155978, 96.390, 1454.0, 38.1314
47.129677109, 96.390, 1420.0, 37.6829
47.182198240, 96.390, 1360.0, 36.8782
47.234719370, 96.390, 1308.0, 36.1663
47.287240501, 96.390, 1351.0, 36.7560
47.339761632, 96.390, 1363.0, 36.9188
47.392282762, 96.390, 1318.0, 36.3043
47.444803893, 96.390, 1305.0, 36.1248
47.497325024, 96.390, 1328.0, 36.4417
47.549846155, 96.390, 1285.0, 35.8469
47.602367285, 96.390, 1272.0, 35.6651
47.654888416, 96.390, 1263.0, 35.5387
47.707409547, 96.390, 1256.0, 35.4401
47.759930677, 96.390, 1333.0, 36.5103
47.812451808, 96.390, 1231.0, 35.0856
47.864972939, 96.390, 1347.0, 36.7015
47.917494069, 96.390, 1421.0, 37.6962
47.970015200, 96.390, 1202.0, 34.6699
48.022536331, 96.390, 1312.0, 36.2215
48.075057462, 96.390, 1238.0, 35.1852
48.127578592, 96.390, 1166.0, 34.1467
48.180099723, 96.390, 1188.0, 34.4674
48.232620854, 96.390, 1152.0, 33.9411
48.285141984, 96.390, 1186.0, 34.4384
48.337663115, 96.390, 1152.0, 33.9411
48.390184246, 96.390, 1191.0, 34.5109
48.442705377, 96.390, 1167.0, 34.1614
48.495226507, 96.390, 1169.0, 34.1906
48.547747638, 96.390, 1190.0, 34.4964
48.600268769, 96.390, 1143.0, 33.8083
48.652789899, 96.390, 1189.0, 34.4819
48.705311030, 96.390, 1152.0, 33.9411
48.757832161, 96.390, 1171.0, 34.2199
48.810353292, 96.390, 1202.0, 34.6699
48.862874422, 96.390, 1196.0, 34.5832
48.915395553, 96.390, 1117.0, 33.4215
48.967916684, 96.390, 1045.0, 32.3265
49.020437814, 96.390, 1126.0, 33.5559
49.072958945, 96.390, 1152.0, 33.9411
49.125480076, 96.390, 1162.0, 34.0881
49.178001207, 96.390, 1036.0, 32.1870
49.230522337, 96.390, 1043.0, 32.2955
49.283043468, 96.390, 1079.0, 32.8481
49.335564599, 96.390, 1084.0, 32.9242
49.388085729, 96.390, 1103.0, 33.2114
49.440606860, 96.390, 1050.0, 32.4037
49.493127991, 96.390, 1122.0, 33.4963
49.545649121, 96.390, 1064.0, 32.6190
49.598170252, 96.390, 1113.0, 33.3617
49.650691383, 96.390, 1060.0, 32.5576
49.703212514, 96.390, 1075.0, 32.7872
49.755733644, 96.390, 1086.0, 32.9545
49.808254775, 96.390, 1082.0, 32.8938
49.860775906, 96.390, 1038.0, 32.2180
49.913297036, 96.390, 1113.0, 33.3617
49.965818167, 96.390, 1090.0, 33.0151
50.018339298, 96.390, 1041.0, 32.2645
50.070860429, 96.390, 1060.0, 32.5576
50.123381559, 96.390, 1105.0, 33.2415
50.175902690, 96.390, 1078.0, 32.8329
50.228423821, 96.390, 1092.0, 33.0454
50.280944951, 96.390, 1055.0, 32.4808
50.333466082, 96.390, 1079.0, 32.8481
50.385987213, 96.390, 1118.0, 33.4365
50.438508344, 96.390, 1060.0, 32.5576
50.491029474, 96.390, 1061.0, 32.5730
50.543550605, 96.390, 1091.0, 33.0303
50.596071736, 96.390, 1059.0, 32.5423
50.648592866, 96.390, 1078.0, 32.8329
50.701113997, 96.390, 1105.0, 33.2415
50.753635128, 96.390, 1075.0, 32.7872
50.806156258, 96.390, 1131.0, 33.6303
50.858677389, 96.390, 1118.0, 33.4365
50.911198520, 96.390, 1250.0, 35.3553
50.963719651, 96.390, 1210.0, 34.7851
51.016240781, 96.390, 1148.0, 33.8821
51.068761912, 96.390, 1119.0, 33.4515
51.121283043, 96.390, 1195.0, 34.5688
51.173804173, 96.390, 1099.0, 33.1512
51.226325304, 96.390, 1072.0, 32.7414
51.278846435, 96.390, 1134.0, 33.6749
51.331367566, 96.390, 1175.0, 34.2783
51.383888696, 96.390, 1171.0, 34.2199
51.436409827, 96.390, 1183.0, 34.3948
51.488930958, 96.390, 1170.0, 34.2053
51.541452088, 96.390, 1223.0, 34.9714
51.593973219, 96.390, 1228.0, 35.0428
51.646494350, 96.390, 1266.0, 35.5809
51.699015481, 96.390, 1174.0, 34.2637
51.751536611, 96.390, 1174.0, 34.2637
51.804057742, 96.390, 1122.0, 33.4963
51.856578873, 96.390, 1120.0, 33.4664
51.909100003, 96.390, 1191.0, 34.5109
51.961621134, 96.390, 1109.0, 33.3017
52.014142265, 96.390, 1094.0, 33.0757
52.066663396, 96.390, 1135.0, 33.6898
52.119184526, 96.390, 1086.0, 32.9545
52.171705657, 96.390, 1140.0, 33.7639
52.224226788, 96.390, 1073.0, 32.7567
52.276747918, 96.390, 1135.0, 33.6898
52.329269049, 96.390, 1137.0, 33.7194
52.381790180, 96.390, 1113.0, 33.3617
52.434311310, 96.390, 1135.0, 33.6898
52.486832441, 96.390, 1117.0, 33.4215
52.539353572, 96.390, 1136.0, 33.7046
52.591874703, 96.390, 1074.0, 32.7719
52.644395833, 96.390, 1194.0, 34.5543
52.696916964, 96.390, 1191.0, 34.5109
52.749438095, 96.390, 1050.0, 32.4037
52.801959225, 96.390, 1189.0, 34.4819
52.854480356, 96.390, 1122.0, 33.4963
52.907001487, 96.390, 1114.0, 33.3766
52.959522618, 96.390, 1203.0, 34.6843
53.012043748, 96.390, 1231.0, 35.0856
53.064564879, 96.390, 1242.0, 35.2420
53.117086010, 96.390, 1230.0, 35.0714
53.169607140, 96.390, 1238.0, 35.1852
53.222128271, 96.390, 1115.0, 33.3916
53.274649402, 96.390, 1102.0, 33.1964
53.327170533, 96.390, 1169.0, 34.1906
53.379691663, 96.390, 1067.0, 32.6650
53.432212794, 96.390, 1108.0, 33.2866
53.484733925, 96.390, 1101.0, 33.1813
53.537255055, 96.390, 1071.0, 32.7261
53.589776186, 96.390, 1074.0, 32.7719
53.642297317, 96.390, 964.0, 31.0483
53.694818448, 96.390, 1069.0, 32.6956
53.747339578, 96.390, 1018.0, 31.9061
53.799860709, 96.390, 1027.0, 32.0468
53.852381840, 96.390, 1021.0, 31.9531
53.904902970, 96.390, 968.0, 31.1127
53.957424101, 96.390, 988.0, 31.4325
54.009945232, 96.390, 991.0, 31.4802
54.062466362, 96.390, 996.0, 31.5595
54.114987493, 96.390, 1010.0, 31.7805
54.167508624, 96.390, 966.0, 31.0805
54.220029755, 96.390, 917.0, 30.2820
54.272550885, 96.390, 989.0, 31.4484
54.325072016, 96.390, 982.0, 31.3369
54.377593147, 96.390, 941.0, 30.6757
54.430114277, 96.390, 944.0, 30.7246
54.482635408, 96.390, 938.0, 30.6268
54.535156539, 96.390, 953.0, 30.8707
54.587677670, 96.390, 967.0, 31.0966
54.640198800, 96.390, 920.0, 30.3315
54.692719931, 96.390, 970.0, 31.1448
54.745241062, 96.390, 953.0, 30.8707
54.797762192, 96.390, 970.0, 31.1448
54.850283323, 96.390, 988.0, 31.4325
54.902804454, 96.390, 1015.0, 31.8591
54.955325585, 96.390, 991.0, 31.4802
55.007846715, 96.390, 1015.0, 31.8591
55.060367846, 96.390, 1030.0, 32.0936
55.112888977, 96.390, 949.0, 30.8058
55.165410107, 96.390, 1007.0, 31.7333
55.217931238, 96.390, 946.0, 30.7571
55.270452369, 96.390, 993.0, 31.5119
55.322973499, 96.390, 901.0, 30.0167
55.375494630, 96.390, 930.0, 30.4959
55.428015761, 96.390, 932.0, 30.5287
55.480536892, 96.390, 978.0, 31.2730
55.533058022, 96.390, 951.0, 30.8383
55.585579153, 96.390, 880.0, 29.6648
55.638100284, 96.390, 931.0, 30.5123
55.690621414, 96.390, 897.0, 29.9500
55.743142545, 96.390, 998.0, 31.5911
55.795663676, 96.390, 894.0, 29.8998
55.848184807, 96.390, 947.0, 30.7734
55.900705937, 96.390, 905.0, 30.0832
55.953227068, 96.390, 922.0, 30.3645
56.005748199, 96.390, 929.0, 30.4795
56.058269329, 96.390, 975.0, 31.2250
56.110790460, 96.390, 938.0, 30.6268
56.163311591, 96.390, 949.0, 30.8058
56.215832722, 96.390, 973.0, 31.1929
56.268353852, 96.390, 946.0, 30.7571
56.320874983, 96.390, 955.0, 30.9031
56.373396114, 96.390, 916.0, 30.2655
56.425917244, 96.390, 912.0, 30.1993
56.478438375, 96.390, 930.0, 30.4959
56.530959506, 96.390, 940.0, 30.6594
56.583480637, 96.390, 939.0, 30.6431
56.636001767, 96.390, 959.0, 30.9677
56.688522898, 96.390, 963.0, 31.0322
56.741044029, 96.390, 943.0, 30.7083
56.793565159, 96.390, 1020.0, 31.9374
56.846086290, 96.390, 971.0, 31.1609
56.898607421, 96.390, 1019.0, 31.9218
56.951128551, 96.390, 1018.0, 31.9061
57.003649682, 96.390, 1029.0, 32.0780
57.056170813, 96.390, 1044.0, 32.3110
57.108691944, 96.390, 1062.0, 32.5883
57.161213074, 96.390, 1112.0, 33.3467
57.213734205, 96.390, 1104.0, 33.2265
57.266255336, 96.390, 1172.0, 34.2345
57.318776466, 96.390, 1168.0, 34.1760
57.371297597, 96.390, 1169.0, 34.1906
57.423818728, 96.390, 1061.0, 32.5730
57.476339859, 96.390, 1141.0, 33.7787
57.528860989, 96.390, 1094.0, 33.0757
57.581382120, 96.390, 1059.0, 32.5423
57.633903251, 96.390, 1046.0, 32.3419
57.686424381, 96.390, 1024.0, 32.0000
57.738945512, 96.390, 1020.0, 31.9374
57.791466643, 96.390, 1021.0, 31.9531
57.843987774, 96.390, 1024.0, 32.0000
57.896508904, 96.390, 972.0, 31.1769
57.949030035, 96.390, 927.0, 30.4467
58.001551166, 96.390, 1027.0, 32.0468
58.054072296, 96.390, 937.0, 30.6105
58.106593427, 96.390, 1013.0, 31.8277
58.159114558, 96.390, 998.0, 31.5911
58.211635689, 96.390, 937.0, 30.6105
58.264156819, 96.390, 1029.0, 32.0780
58.316677950, 96.390, 1021.0, 31.9531
58.369199081, 96.390, 1042.0, 32.2800
58.421720211, 96.390, 1077.0, 32.8177
58.474241342, 96.390, 1104.0, 33.2265
58.526762473, 96.390, 1096.0, 33.1059
58.579283603, 96.390, 1026.0, 32.0312
58.631804734, 96.390, 1051.0, 32.4191
58.684325865, 96.390, 1031.0, 32.1092
58.736846996, 96.390, 1035.0, 32.1714
58.789368126, 96.390, 1062.0, 32.5883
58.841889257, 96.390, 1015.0, 31.8591
58.894410388, 96.390, 1043.0, 32.2955
58.946931518, 96.390, 1014.0, 31.8434
58.999452649, 96.390, 1013.0, 31.8277
59.051973780, 96.390, 1084.0, 32.9242
59.104494911, 96.390, 1086.0, 32.9545
59.157016041, 96.390, 1030.0, 32.0936
59.209537172, 96.390, 1084.0, 32.9242
59.262058303, 96.390, 1126.0, 33.5559
59.314579433, 96.390, 1109.0, 33.3017
59.367100564, 96.390, 1130.0, 33.6155
59.419621695, 96.390, 1197.0, 34.5977
59.472142826, 96.390, 1171.0, 34.2199
59.524663956, 96.390, 1171.0, 34.2199
59.577185087, 96.390, 1240.0, 35.2136
59.629706218, 96.390, 1163.0, 34.1028
59.682227348, 96.390, 1250.0, 35.3553
59.734748479, 96.390, 1313.0, 36.2353
59.787269610, 96.390, 1378.0, 37.1214
59.839790740, 96.390, 1326.0, 36.4143
59.892311871, 96.390, 1345.0, 36.6742
59.944833002, 96.390, 1418.0, 37.6563
59.997354133, 96.390, 1434.0, 37.8682
60.049875263, 96.390, 1373.0, 37.0540
60.102396394, 96.390, 1441.0, 37.9605
60.154917525, 96.390, 1533.0, 39.1535
60.207438655, 96.390, 1460.0, 38.2099
60.259959786, 96.390, 1577.0, 39.7115
60.312480917, 96.390, 1482.0, 38.4968
60.365002048, 96.390, 1636.0, 40.4475
60.417523178, 96.390, 1604.0, 40.0500
60.470044309, 96.390, 1609.0, 40.1123
60.522565440, 96.390, 1709.0, 41.3401
60.575086570, 96.390, 1686.0, 41.0609
60.627607701, 96.390, 1634.0, 40.4228
60.680128832, 96.390, 1611.0, 40.1373
60.732649963, 96.390, 1661.0, 40.7554
60.785171093, 96.390, 1646.0, 40.5709
60.837692224, 96.390, 1607.0, 40.0874
60.890213355, 96.390, 1612.0, 40.1497
60.942734485, 96.390, 1540.0, 39.2428
60.995255616, 96.390, 1543.0, 39.2810
61.047776747, 96.390, 1523.0, 39.0256
61.100297878, 96.390, 1376.0, 37.0945
61.152819008, 96.390, 1357.0, 36.8375
61.205340139, 96.390, 1390.0, 37.2827
61.257861270, 96.390, 1353.0, 36.7831
61.310382400, 96.390, 1299.0, 36.0416
61.362903531, 96.390, 1289.0, 35.9026
61.415424662, 96.390, 1320.0, 36.3318
61.467945792, 96.390, 1274.0, 35.6931
61.520466923, 96.390, 1215.0, 34.8569
61.572988054, 96.390, 1295.0, 35.9861
61.625509185, 96.390, 1177.0, 34.3074
61.678030315, 96.390, 1212.0, 34.8138
61.730551446, 96.390, 1278.0, 35.7491
61.783072577, 96.390, 1275.0, 35.7071
61.835593707, 96.390, 1221.0, 34.9428
61.888114838, 96.390, 1147.0, 33.8674
61.940635969, 96.390, 1116.0, 33.4066
61.993157100, 96.390, 1152.0, 33.9411
62.045678230, 96.390, 1260.0, 35.4965
62.098199361, 96.390, 1218.0, 34.8999
62.150720492, 96.390, 1118.0, 33.4365
62.203241622, 96.390, 1226.0, 35.0143
62.255762753, 96.390, 1167.0, 34.1614
62.308283884, 96.390, 1208.0, 34.7563
62.360805015, 96.390, 1095.0, 33.0908
62.413326145, 96.390, 1039.0, 32.2335
62.465847276, 96.390, 1101.0, 33.1813
62.518368407, 96.390, 1104.0, 33.2265
62.570889537, 96.390, 1073.0, 32.7567
62.623410668, 96.390, 1021.0, 31.9531
62.675931799, 96.390, 1056.0, 32.4962
62.728452930, 96.390, 1071.0, 32.7261
62.780974060, 96.390, 1038.0, 32.2180
62.833495191, 96.390, 956.0, 30.9192
62.886016322, 96.390, 1047.0, 32.3574
62.938537452, 96.390, 1103.0, 33.2114
62.991058583, 96.390, 1052.0, 32.4345
63.043579714, 96.390, 1080.0, 32.8634
63.096100844, 96.390, 992.0, 31.4960
63.148621975, 96.390, 928.0, 30.4631
63.201143106, 96.390, 1004.0, 31.6860
63.253664237, 96.390, 969.0, 31.1288
63.306185367, 96.390, 941.0, 30.6757
63.358706498, 96.390, 942.0, 30.6920
63.411227629, 96.390, 960.0, 30.9839
63.463748759, 96.390, 935.0, 30.5778
63.516269890, 96.390, 917.0, 30.2820
63.568791021, 96.390, 883.0, 29.7153
63.621312152, 96.390, 876.0, 29.5973
63.673833282, 96.390, 857.0, 29.2746
63.726354413, 96.390, 825.0, 28.7228
63.778875544, 96.390, 827.0, 28.7576
63.831396674, 96.390, 845.0, 29.0689
63.883917805, 96.390, 837.0, 28.9310
63.936438936, 96.390, 861.0, 29.3428
63.988960067, 96.390, 918.0, 30.2985
64.041481197, 96.390, 870.0, 29.4958
64.094002328, 96.390, 877.0, 29.6142
64.146523459, 96.390, 823.0, 28.6880
64.199044589, 96.390, 879.0, 29.6479
64.251565720, 96.390, 832.0, 28.8444
64.304086851, 96.390, 849.0, 29.1376
64.356607981, 96.390, 789.0, 28.0891
64.409129112, 96.390, 790.0, 28.1069
64.461650243, 96.390, 811.0, 28.4781
64.514171374, 96.390, 795.0, 28.1957
64.566692504, 96.390, 764.0, 27.6405
64.619213635, 96.390, 790.0, 28.1069
64.671734766, 96.390, 762.0, 27.6043
64.724255896, 96.390, 761.0, 27.5862
64.776777027, 96.390, 741.0, 27.2213
64.829298158, 96.390, 766.0, 27.6767
64.881819289, 96.390, 754.0, 27.4591
64.934340419, 96.390, 767.0, 27.6948
64.986861550, 96.390, 767.0, 27.6948