File: Files_organized_for_plots/Constant_NaOH_1mL10M_to_1gPC_28Day/XRD_PAxialnul_Act03May22_B1_0833M_NaOH_LS0153_1.csv
[Measurement conditions]
Sample identification,XRD_PAxialnul_Act03May22_B1_1000M_NaOH_LS0133_1
Comment - 1,"Configuration=Stage for Flat Samples/Holders, Owner=User-1, Creation date=7/1/2020 9:53:24 AM"
Comment - 2,"Goniometer=Theta/Theta; Minimum step size 2Theta:0.0001; Minimum step size Omega:0.0001"
Comment - 3,"Sample stage=Stage for flat samples/holders"
Comment - 4,"Diffractometer system=EMPYREAN"
Comment - 5,"Measurement program=C:\Users\ibo5034\OneDrive - The Pennsylvania State University\NEUP\Zerobackground scan.xrdmp, Identifier={98A3B11C-88F9-4AA6-982C-73314A311EF5}"
Anode material,Cu
K-Alpha1 wavelength,1.5405980
K-Alpha2 wavelength,1.5444260
Ratio K-Alpha2/K-Alpha1,0.500
Divergence slit,Fixed,0.25
Monochromator used,NO
Generator voltage, 45
Tube current, 40
File date and time,03/Jun/2022 15:46
Unit cell,
h k l, 0 0 0
Scan axis,Gonio
Scan range,4.994599997,64.999991833
Scan step size,0.0262606
No. of points, 2285
Scan type,CONTINUOUS
Time per step,96.390
[Scan points]
Angle, TimePerStep, Intensity, ESD
5.007730280, 96.390, 4287.0, 65.4752
5.060251411, 96.390, 4175.0, 64.6142
5.112772541, 96.390, 4050.0, 63.6396
5.165293672, 96.390, 4033.0, 63.5059
5.217814803, 96.390, 3852.0, 62.0645
5.270335934, 96.390, 3900.0, 62.4500
5.322857064, 96.390, 3909.0, 62.5220
5.375378195, 96.390, 3871.0, 62.2174
5.427899326, 96.390, 3862.0, 62.1450
5.480420456, 96.390, 3788.0, 61.5467
5.532941587, 96.390, 3755.0, 61.2781
5.585462718, 96.390, 3648.0, 60.3987
5.637983849, 96.390, 3679.0, 60.6548
5.690504979, 96.390, 3805.0, 61.6847
5.743026110, 96.390, 3637.0, 60.3075
5.795547241, 96.390, 3618.0, 60.1498
5.848068371, 96.390, 3536.0, 59.4643
5.900589502, 96.390, 3559.0, 59.6574
5.953110633, 96.390, 3656.0, 60.4649
6.005631763, 96.390, 3604.0, 60.0333
6.058152894, 96.390, 3463.0, 58.8473
6.110674025, 96.390, 3481.0, 59.0000
6.163195156, 96.390, 3499.0, 59.1523
6.215716286, 96.390, 3427.0, 58.5406
6.268237417, 96.390, 3420.0, 58.4808
6.320758548, 96.390, 3483.0, 59.0169
6.373279678, 96.390, 3547.0, 59.5567
6.425800809, 96.390, 3569.0, 59.7411
6.478321940, 96.390, 3479.0, 58.9830
6.530843071, 96.390, 3526.0, 59.3801
6.583364201, 96.390, 3424.0, 58.5150
6.635885332, 96.390, 3417.0, 58.4551
6.688406463, 96.390, 3516.0, 59.2959
6.740927593, 96.390, 3415.0, 58.4380
6.793448724, 96.390, 3506.0, 59.2115
6.845969855, 96.390, 3390.0, 58.2237
6.898490986, 96.390, 3464.0, 58.8558
6.951012116, 96.390, 3522.0, 59.3464
7.003533247, 96.390, 3468.0, 58.8897
7.056054378, 96.390, 3350.0, 57.8792
7.108575508, 96.390, 3463.0, 58.8473
7.161096639, 96.390, 3486.0, 59.0424
7.213617770, 96.390, 3376.0, 58.1034
7.266138900, 96.390, 3430.0, 58.5662
7.318660031, 96.390, 3537.0, 59.4727
7.371181162, 96.390, 3597.0, 59.9750
7.423702293, 96.390, 3589.0, 59.9083
7.476223423, 96.390, 3768.0, 61.3840
7.528744554, 96.390, 3704.0, 60.8605
7.581265685, 96.390, 3874.0, 62.2415
7.633786815, 96.390, 3846.0, 62.0161
7.686307946, 96.390, 4060.0, 63.7181
7.738829077, 96.390, 4061.0, 63.7260
7.791350208, 96.390, 4152.0, 64.4360
7.843871338, 96.390, 4441.0, 66.6408
7.896392469, 96.390, 4666.0, 68.3081
7.948913600, 96.390, 4726.0, 68.7459
8.001434730, 96.390, 5194.0, 72.0694
8.053955861, 96.390, 5591.0, 74.7730
8.106476992, 96.390, 6010.0, 77.5242
8.158998123, 96.390, 6645.0, 81.5169
8.211519253, 96.390, 6974.0, 83.5105
8.264040384, 96.390, 7510.0, 86.6603
8.316561515, 96.390, 7997.0, 89.4259
8.369082645, 96.390, 8158.0, 90.3216
8.421603776, 96.390, 8125.0, 90.1388
8.474124907, 96.390, 7863.0, 88.6736
8.526646038, 96.390, 7420.0, 86.1394
8.579167168, 96.390, 6851.0, 82.7708
8.631688299, 96.390, 6436.0, 80.2247
8.684209430, 96.390, 6402.0, 80.0125
8.736730560, 96.390, 6554.0, 80.9568
8.789251691, 96.390, 6132.0, 78.3071
8.841772822, 96.390, 5502.0, 74.1755
8.894293952, 96.390, 5099.0, 71.4073
8.946815083, 96.390, 4818.0, 69.4118
8.999336214, 96.390, 4516.0, 67.2012
9.051857345, 96.390, 4484.0, 66.9627
9.104378475, 96.390, 4281.0, 65.4294
9.156899606, 96.390, 4274.0, 65.3758
9.209420737, 96.390, 4104.0, 64.0625
9.261941867, 96.390, 3944.0, 62.8013
9.314462998, 96.390, 3772.0, 61.4166
9.366984129, 96.390, 3833.0, 61.9112
9.419505260, 96.390, 3658.0, 60.4814
9.472026390, 96.390, 3556.0, 59.6322
9.524547521, 96.390, 3471.0, 58.9152
9.577068652, 96.390, 3528.0, 59.3970
9.629589782, 96.390, 3445.0, 58.6941
9.682110913, 96.390, 3359.0, 57.9569
9.734632044, 96.390, 3236.0, 56.8859
9.787153175, 96.390, 3302.0, 57.4630
9.839674305, 96.390, 3195.0, 56.5243
9.892195436, 96.390, 3188.0, 56.4624
9.944716567, 96.390, 3181.0, 56.4004
9.997237697, 96.390, 3137.0, 56.0089
10.049758828, 96.390, 3105.0, 55.7225
10.102279959, 96.390, 3015.0, 54.9090
10.154801090, 96.390, 3024.0, 54.9909
10.207322220, 96.390, 3035.0, 55.0908
10.259843351, 96.390, 2992.0, 54.6992
10.312364482, 96.390, 2919.0, 54.0278
10.364885612, 96.390, 2892.0, 53.7773
10.417406743, 96.390, 2825.0, 53.1507
10.469927874, 96.390, 2914.0, 53.9815
10.522449004, 96.390, 2851.0, 53.3948
10.574970135, 96.390, 2690.0, 51.8652
10.627491266, 96.390, 2767.0, 52.6023
10.680012397, 96.390, 2697.0, 51.9326
10.732533527, 96.390, 2862.0, 53.4977
10.785054658, 96.390, 2664.0, 51.6140
10.837575789, 96.390, 2674.0, 51.7107
10.890096919, 96.390, 2616.0, 51.1468
10.942618050, 96.390, 2825.0, 53.1507
10.995139181, 96.390, 2689.0, 51.8556
11.047660312, 96.390, 2782.0, 52.7447
11.100181442, 96.390, 2692.0, 51.8845
11.152702573, 96.390, 3555.0, 59.6238
11.205223704, 96.390, 4152.0, 64.4360
11.257744834, 96.390, 4200.0, 64.8074
11.310265965, 96.390, 2691.0, 51.8748
11.362787096, 96.390, 2572.0, 50.7149
11.415308227, 96.390, 2536.0, 50.3587
11.467829357, 96.390, 2519.0, 50.1896
11.520350488, 96.390, 2479.0, 49.7896
11.572871619, 96.390, 2562.0, 50.6162
11.625392749, 96.390, 2521.0, 50.2096
11.677913880, 96.390, 2493.0, 49.9300
11.730435011, 96.390, 2436.0, 49.3559
11.782956141, 96.390, 2408.0, 49.0714
11.835477272, 96.390, 2370.0, 48.6826
11.887998403, 96.390, 2450.0, 49.4975
11.940519534, 96.390, 2406.0, 49.0510
11.993040664, 96.390, 2379.0, 48.7750
12.045561795, 96.390, 2305.0, 48.0104
12.098082926, 96.390, 2321.0, 48.1768
12.150604056, 96.390, 2280.0, 47.7493
12.203125187, 96.390, 2364.0, 48.6210
12.255646318, 96.390, 2378.0, 48.7647
12.308167449, 96.390, 2303.0, 47.9896
12.360688579, 96.390, 2251.0, 47.4447
12.413209710, 96.390, 2291.0, 47.8644
12.465730841, 96.390, 2347.0, 48.4458
12.518251971, 96.390, 2269.0, 47.6340
12.570773102, 96.390, 2237.0, 47.2969
12.623294233, 96.390, 2433.0, 49.3254
12.675815364, 96.390, 2448.0, 49.4773
12.728336494, 96.390, 2788.0, 52.8015
12.780857625, 96.390, 3609.0, 60.0750
12.833378756, 96.390, 3860.0, 62.1289
12.885899886, 96.390, 3444.0, 58.6856
12.938421017, 96.390, 2316.0, 48.1248
12.990942148, 96.390, 2173.0, 46.6154
13.043463279, 96.390, 2161.0, 46.4866
13.095984409, 96.390, 2163.0, 46.5081
13.148505540, 96.390, 2149.0, 46.3573
13.201026671, 96.390, 2125.0, 46.0977
13.253547801, 96.390, 2282.0, 47.7703
13.306068932, 96.390, 2397.0, 48.9592
13.358590063, 96.390, 2568.0, 50.6754
13.411111193, 96.390, 2978.0, 54.5711
13.463632324, 96.390, 4170.0, 64.5755
13.516153455, 96.390, 5469.0, 73.9527
13.568674586, 96.390, 9227.0, 96.0573
13.621195716, 96.390, 4083.0, 63.8984
13.673716847, 96.390, 2293.0, 47.8853
13.726237978, 96.390, 2235.0, 47.2758
13.778759108, 96.390, 2383.0, 48.8160
13.831280239, 96.390, 2590.0, 50.8920
13.883801370, 96.390, 3311.0, 57.5413
13.936322501, 96.390, 3255.0, 57.0526
13.988843631, 96.390, 2272.0, 47.6655
14.041364762, 96.390, 2130.0, 46.1519
14.093885893, 96.390, 2134.0, 46.1952
14.146407023, 96.390, 2153.0, 46.4004
14.198928154, 96.390, 2090.0, 45.7165
14.251449285, 96.390, 2204.0, 46.9468
14.303970416, 96.390, 2539.0, 50.3885
14.356491546, 96.390, 3096.0, 55.6417
14.409012677, 96.390, 4144.0, 64.3739
14.461533808, 96.390, 3292.0, 57.3760
14.514054938, 96.390, 2108.0, 45.9130
14.566576069, 96.390, 2066.0, 45.4533
14.619097200, 96.390, 1887.0, 43.4396
14.671618331, 96.390, 1919.0, 43.8064
14.724139461, 96.390, 1944.0, 44.0908
14.776660592, 96.390, 1878.0, 43.3359
14.829181723, 96.390, 1887.0, 43.4396
14.881702853, 96.390, 1877.0, 43.3244
14.934223984, 96.390, 1983.0, 44.5309
14.986745115, 96.390, 1931.0, 43.9431
15.039266245, 96.390, 1917.0, 43.7836
15.091787376, 96.390, 1977.0, 44.4635
15.144308507, 96.390, 2038.0, 45.1442
15.196829638, 96.390, 2070.0, 45.4973
15.249350768, 96.390, 1999.0, 44.7102
15.301871899, 96.390, 1985.0, 44.5533
15.354393030, 96.390, 1902.0, 43.6119
15.406914160, 96.390, 1993.0, 44.6430
15.459435291, 96.390, 1937.0, 44.0114
15.511956422, 96.390, 1983.0, 44.5309
15.564477553, 96.390, 1954.0, 44.2041
15.616998683, 96.390, 1927.0, 43.8976
15.669519814, 96.390, 1816.0, 42.6146
15.722040945, 96.390, 1939.0, 44.0341
15.774562075, 96.390, 1919.0, 43.8064
15.827083206, 96.390, 2015.0, 44.8888
15.879604337, 96.390, 1980.0, 44.4972
15.932125468, 96.390, 1995.0, 44.6654
15.984646598, 96.390, 2069.0, 45.4863
16.037167729, 96.390, 2384.0, 48.8262
16.089688860, 96.390, 2937.0, 54.1941
16.142209990, 96.390, 4308.0, 65.6354
16.194731121, 96.390, 5686.0, 75.4056
16.247252252, 96.390, 3403.0, 58.3352
16.299773382, 96.390, 2064.0, 45.4313
16.352294513, 96.390, 1989.0, 44.5982
16.404815644, 96.390, 2100.0, 45.8258
16.457336775, 96.390, 1960.0, 44.2719
16.509857905, 96.390, 2109.0, 45.9239
16.562379036, 96.390, 1982.0, 44.5197
16.614900167, 96.390, 2043.0, 45.1996
16.667421297, 96.390, 2073.0, 45.5302
16.719942428, 96.390, 1976.0, 44.4522
16.772463559, 96.390, 2109.0, 45.9239
16.824984690, 96.390, 2074.0, 45.5412
16.877505820, 96.390, 2092.0, 45.7384
16.930026951, 96.390, 2147.0, 46.3357
16.982548082, 96.390, 2129.0, 46.1411
17.035069212, 96.390, 2136.0, 46.2169
17.087590343, 96.390, 2187.0, 46.7654
17.140111474, 96.390, 2238.0, 47.3075
17.192632605, 96.390, 2186.0, 46.7547
17.245153735, 96.390, 2217.0, 47.0850
17.297674866, 96.390, 2251.0, 47.4447
17.350195997, 96.390, 2271.0, 47.6550
17.402717127, 96.390, 2418.0, 49.1732
17.455238258, 96.390, 2468.0, 49.6790
17.507759389, 96.390, 2567.0, 50.6656
17.560280520, 96.390, 2509.0, 50.0899
17.612801650, 96.390, 2574.0, 50.7346
17.665322781, 96.390, 2440.0, 49.3964
17.717843912, 96.390, 2363.0, 48.6107
17.770365042, 96.390, 2307.0, 48.0312
17.822886173, 96.390, 2295.0, 47.9062
17.875407304, 96.390, 2166.0, 46.5403
17.927928434, 96.390, 2232.0, 47.2440
17.980449565, 96.390, 2178.0, 46.6690
18.032970696, 96.390, 2187.0, 46.7654
18.085491827, 96.390, 2159.0, 46.4650
18.138012957, 96.390, 2083.0, 45.6399
18.190534088, 96.390, 2136.0, 46.2169
18.243055219, 96.390, 2128.0, 46.1303
18.295576349, 96.390, 2178.0, 46.6690
18.348097480, 96.390, 2047.0, 45.2438
18.400618611, 96.390, 2012.0, 44.8553
18.453139742, 96.390, 2092.0, 45.7384
18.505660872, 96.390, 2080.0, 45.6070
18.558182003, 96.390, 2069.0, 45.4863
18.610703134, 96.390, 2061.0, 45.3982
18.663224264, 96.390, 2065.0, 45.4423
18.715745395, 96.390, 1975.0, 44.4410
18.768266526, 96.390, 1930.0, 43.9318
18.820787657, 96.390, 2043.0, 45.1996
18.873308787, 96.390, 2079.0, 45.5961
18.925829918, 96.390, 2037.0, 45.1331
18.978351049, 96.390, 2123.0, 46.0760
19.030872179, 96.390, 2048.0, 45.2548
19.083393310, 96.390, 2062.0, 45.4093
19.135914441, 96.390, 2025.0, 45.0000
19.188435572, 96.390, 2015.0, 44.8888
19.240956702, 96.390, 2100.0, 45.8258
19.293477833, 96.390, 2052.0, 45.2990
19.345998964, 96.390, 2019.0, 44.9333
19.398520094, 96.390, 2085.0, 45.6618
19.451041225, 96.390, 2069.0, 45.4863
19.503562356, 96.390, 2115.0, 45.9891
19.556083486, 96.390, 2131.0, 46.1628
19.608604617, 96.390, 2025.0, 45.0000
19.661125748, 96.390, 2163.0, 46.5081
19.713646879, 96.390, 2083.0, 45.6399
19.766168009, 96.390, 2083.0, 45.6399
19.818689140, 96.390, 2082.0, 45.6289
19.871210271, 96.390, 2239.0, 47.3181
19.923731401, 96.390, 2333.0, 48.3011
19.976252532, 96.390, 2816.0, 53.0660
20.028773663, 96.390, 3370.0, 58.0517
20.081294794, 96.390, 3994.0, 63.1981
20.133815924, 96.390, 4842.0, 69.5845
20.186337055, 96.390, 7359.0, 85.7846
20.238858186, 96.390, 8181.0, 90.4489
20.291379316, 96.390, 4802.0, 69.2965
20.343900447, 96.390, 2885.0, 53.7122
20.396421578, 96.390, 2526.0, 50.2593
20.448942709, 96.390, 2205.0, 46.9574
20.501463839, 96.390, 2034.0, 45.0999
20.553984970, 96.390, 2043.0, 45.1996
20.606506101, 96.390, 2126.0, 46.1086
20.659027231, 96.390, 2014.0, 44.8776
20.711548362, 96.390, 2039.0, 45.1553
20.764069493, 96.390, 1986.0, 44.5646
20.816590623, 96.390, 1892.0, 43.4971
20.869111754, 96.390, 2062.0, 45.4093
20.921632885, 96.390, 2072.0, 45.5192
20.974154016, 96.390, 1973.0, 44.4185
21.026675146, 96.390, 1895.0, 43.5316
21.079196277, 96.390, 2034.0, 45.0999
21.131717408, 96.390, 1948.0, 44.1362
21.184238538, 96.390, 2064.0, 45.4313
21.236759669, 96.390, 2037.0, 45.1331
21.289280800, 96.390, 2144.0, 46.3033
21.341801931, 96.390, 2282.0, 47.7703
21.394323061, 96.390, 2372.0, 48.7032
21.446844192, 96.390, 2286.0, 47.8121
21.499365323, 96.390, 2152.0, 46.3897
21.551886453, 96.390, 2061.0, 45.3982
21.604407584, 96.390, 2045.0, 45.2217
21.656928715, 96.390, 2081.0, 45.6180
21.709449846, 96.390, 1915.0, 43.7607
21.761970976, 96.390, 2054.0, 45.3211
21.814492107, 96.390, 2092.0, 45.7384
21.867013238, 96.390, 2082.0, 45.6289
21.919534368, 96.390, 2073.0, 45.5302
21.972055499, 96.390, 1975.0, 44.4410
22.024576630, 96.390, 2094.0, 45.7602
22.077097761, 96.390, 2076.0, 45.5631
22.129618891, 96.390, 2070.0, 45.4973
22.182140022, 96.390, 2055.0, 45.3321
22.234661153, 96.390, 2112.0, 45.9565
22.287182283, 96.390, 2074.0, 45.5412
22.339703414, 96.390, 2111.0, 45.9456
22.392224545, 96.390, 2081.0, 45.6180
22.444745675, 96.390, 2096.0, 45.7821
22.497266806, 96.390, 2176.0, 46.6476
22.549787937, 96.390, 2155.0, 46.4220
22.602309068, 96.390, 2167.0, 46.5510
22.654830198, 96.390, 2129.0, 46.1411
22.707351329, 96.390, 2140.0, 46.2601
22.759872460, 96.390, 2036.0, 45.1221
22.812393590, 96.390, 2156.0, 46.4327
22.864914721, 96.390, 2108.0, 45.9130
22.917435852, 96.390, 2074.0, 45.5412
22.969956983, 96.390, 2103.0, 45.8585
23.022478113, 96.390, 2090.0, 45.7165
23.074999244, 96.390, 2050.0, 45.2769
23.127520375, 96.390, 2121.0, 46.0543
23.180041505, 96.390, 2065.0, 45.4423
23.232562636, 96.390, 2103.0, 45.8585
23.285083767, 96.390, 2070.0, 45.4973
23.337604898, 96.390, 2071.0, 45.5082
23.390126028, 96.390, 2046.0, 45.2327
23.442647159, 96.390, 2153.0, 46.4004
23.495168290, 96.390, 2070.0, 45.4973
23.547689420, 96.390, 2063.0, 45.4203
23.600210551, 96.390, 1976.0, 44.4522
23.652731682, 96.390, 2044.0, 45.2106
23.705252813, 96.390, 2115.0, 45.9891
23.757773943, 96.390, 2119.0, 46.0326
23.810295074, 96.390, 2228.0, 47.2017
23.862816205, 96.390, 2642.0, 51.4004
23.915337335, 96.390, 3303.0, 57.4717
23.967858466, 96.390, 3687.0, 60.7207
24.020379597, 96.390, 3772.0, 61.4166
24.072900727, 96.390, 4717.0, 68.6804
24.125421858, 96.390, 5588.0, 74.7529
24.177942989, 96.390, 3733.0, 61.0983
24.230464120, 96.390, 2276.0, 47.7074
24.282985250, 96.390, 2043.0, 45.1996
24.335506381, 96.390, 1905.0, 43.6463
24.388027512, 96.390, 2061.0, 45.3982
24.440548642, 96.390, 2137.0, 46.2277
24.493069773, 96.390, 2065.0, 45.4423
24.545590904, 96.390, 2023.0, 44.9778
24.598112035, 96.390, 1963.0, 44.3058
24.650633165, 96.390, 1999.0, 44.7102
24.703154296, 96.390, 2018.0, 44.9222
24.755675427, 96.390, 2020.0, 44.9444
24.808196557, 96.390, 1932.0, 43.9545
24.860717688, 96.390, 1956.0, 44.2267
24.913238819, 96.390, 1944.0, 44.0908
24.965759950, 96.390, 1937.0, 44.0114
25.018281080, 96.390, 1957.0, 44.2380
25.070802211, 96.390, 1964.0, 44.3170
25.123323342, 96.390, 1899.0, 43.5775
25.175844472, 96.390, 1888.0, 43.4511
25.228365603, 96.390, 1861.0, 43.1393
25.280886734, 96.390, 1820.0, 42.6615
25.333407864, 96.390, 1827.0, 42.7434
25.385928995, 96.390, 1939.0, 44.0341
25.438450126, 96.390, 2097.0, 45.7930
25.490971257, 96.390, 2694.0, 51.9038
25.543492387, 96.390, 3494.0, 59.1101
25.596013518, 96.390, 3243.0, 56.9473
25.648534649, 96.390, 2533.0, 50.3289
25.701055779, 96.390, 2073.0, 45.5302
25.753576910, 96.390, 2136.0, 46.2169
25.806098041, 96.390, 2605.0, 51.0392
25.858619172, 96.390, 2886.0, 53.7215
25.911140302, 96.390, 2291.0, 47.8644
25.963661433, 96.390, 1928.0, 43.9090
26.016182564, 96.390, 1826.0, 42.7317
26.068703694, 96.390, 1812.0, 42.5676
26.121224825, 96.390, 1795.0, 42.3674
26.173745956, 96.390, 1793.0, 42.3438
26.226267087, 96.390, 1909.0, 43.6921
26.278788217, 96.390, 2018.0, 44.9222
26.331309348, 96.390, 2158.0, 46.4543
26.383830479, 96.390, 2220.0, 47.1169
26.436351609, 96.390, 2385.0, 48.8365
26.488872740, 96.390, 2205.0, 46.9574
26.541393871, 96.390, 2215.0, 47.0638
26.593915002, 96.390, 2092.0, 45.7384
26.646436132, 96.390, 2103.0, 45.8585
26.698957263, 96.390, 2083.0, 45.6399
26.751478394, 96.390, 2030.0, 45.0555
26.803999524, 96.390, 2002.0, 44.7437
26.856520655, 96.390, 1987.0, 44.5758
26.909041786, 96.390, 2002.0, 44.7437
26.961562916, 96.390, 2010.0, 44.8330
27.014084047, 96.390, 2036.0, 45.1221
27.066605178, 96.390, 1937.0, 44.0114
27.119126309, 96.390, 1954.0, 44.2041
27.171647439, 96.390, 1959.0, 44.2606
27.224168570, 96.390, 2104.0, 45.8694
27.276689701, 96.390, 2373.0, 48.7134
27.329210831, 96.390, 2615.0, 51.1371
27.381731962, 96.390, 2192.0, 46.8188
27.434253093, 96.390, 1947.0, 44.1248
27.486774224, 96.390, 1871.0, 43.2551
27.539295354, 96.390, 1761.0, 41.9643
27.591816485, 96.390, 1812.0, 42.5676
27.644337616, 96.390, 1686.0, 41.0609
27.696858746, 96.390, 1689.0, 41.0974
27.749379877, 96.390, 1836.0, 42.8486
27.801901008, 96.390, 1801.0, 42.4382
27.854422139, 96.390, 1790.0, 42.3084
27.906943269, 96.390, 1824.0, 42.7083
27.959464400, 96.390, 1816.0, 42.6146
28.011985531, 96.390, 1939.0, 44.0341
28.064506661, 96.390, 1876.0, 43.3128
28.117027792, 96.390, 1776.0, 42.1426
28.169548923, 96.390, 1763.0, 41.9881
28.222070054, 96.390, 1787.0, 42.2729
28.274591184, 96.390, 1785.0, 42.2493
28.327112315, 96.390, 1680.0, 40.9878
28.379633446, 96.390, 1773.0, 42.1070
28.432154576, 96.390, 1734.0, 41.6413
28.484675707, 96.390, 1738.0, 41.6893
28.537196838, 96.390, 1730.0, 41.5933
28.589717968, 96.390, 1910.0, 43.7035
28.642239099, 96.390, 2105.0, 45.8803
28.694760230, 96.390, 2366.0, 48.6415
28.747281361, 96.390, 2325.0, 48.2183
28.799802491, 96.390, 2064.0, 45.4313
28.852323622, 96.390, 1930.0, 43.9318
28.904844753, 96.390, 1924.0, 43.8634
28.957365883, 96.390, 2102.0, 45.8476
29.009887014, 96.390, 2855.0, 53.4322
29.062408145, 96.390, 3487.0, 59.0508
29.114929276, 96.390, 2958.0, 54.3875
29.167450406, 96.390, 2238.0, 47.3075
29.219971537, 96.390, 1920.0, 43.8178
29.272492668, 96.390, 1779.0, 42.1782
29.325013798, 96.390, 1791.0, 42.3202
29.377534929, 96.390, 1831.0, 42.7902
29.430056060, 96.390, 1889.0, 43.4626
29.482577191, 96.390, 2296.0, 47.9166
29.535098321, 96.390, 2584.0, 50.8331
29.587619452, 96.390, 2330.0, 48.2701
29.640140583, 96.390, 2272.0, 47.6655
29.692661713, 96.390, 2254.0, 47.4763
29.745182844, 96.390, 2283.0, 47.7807
29.797703975, 96.390, 2067.0, 45.4643
29.850225105, 96.390, 1972.0, 44.4072
29.902746236, 96.390, 2038.0, 45.1442
29.955267367, 96.390, 2318.0, 48.1456
30.007788498, 96.390, 2490.0, 49.8999
30.060309628, 96.390, 2338.0, 48.3529
30.112830759, 96.390, 2126.0, 46.1086
30.165351890, 96.390, 1858.0, 43.1045
30.217873020, 96.390, 1854.0, 43.0581
30.270394151, 96.390, 1797.0, 42.3910
30.322915282, 96.390, 1850.0, 43.0116
30.375436413, 96.390, 1881.0, 43.3705
30.427957543, 96.390, 1916.0, 43.7721
30.480478674, 96.390, 1899.0, 43.5775
30.532999805, 96.390, 2207.0, 46.9787
30.585520935, 96.390, 2533.0, 50.3289
30.638042066, 96.390, 2293.0, 47.8853
30.690563197, 96.390, 2113.0, 45.9674
30.743084328, 96.390, 1920.0, 43.8178
30.795605458, 96.390, 1880.0, 43.3590
30.848126589, 96.390, 1824.0, 42.7083
30.900647720, 96.390, 1775.0, 42.1307
30.953168850, 96.390, 1823.0, 42.6966
31.005689981, 96.390, 1933.0, 43.9659
31.058211112, 96.390, 1921.0, 43.8292
31.110732243, 96.390, 2013.0, 44.8665
31.163253373, 96.390, 2042.0, 45.1885
31.215774504, 96.390, 1937.0, 44.0114
31.268295635, 96.390, 1866.0, 43.1972
31.320816765, 96.390, 1864.0, 43.1741
31.373337896, 96.390, 1875.0, 43.3013
31.425859027, 96.390, 1854.0, 43.0581
31.478380157, 96.390, 1974.0, 44.4297
31.530901288, 96.390, 2238.0, 47.3075
31.583422419, 96.390, 2877.0, 53.6377
31.635943550, 96.390, 3447.0, 58.7112
31.688464680, 96.390, 3714.0, 60.9426
31.740985811, 96.390, 3004.0, 54.8088
31.793506942, 96.390, 2595.0, 50.9411
31.846028072, 96.390, 2454.0, 49.5379
31.898549203, 96.390, 2993.0, 54.7083
31.951070334, 96.390, 4218.0, 64.9461
32.003591465, 96.390, 4462.0, 66.7982
32.056112595, 96.390, 3292.0, 57.3760
32.108633726, 96.390, 2538.0, 50.3786
32.161154857, 96.390, 2569.0, 50.6853
32.213675987, 96.390, 3318.0, 57.6021
32.266197118, 96.390, 4183.0, 64.6761
32.318718249, 96.390, 2990.0, 54.6809
32.371239380, 96.390, 2416.0, 49.1528
32.423760510, 96.390, 2085.0, 45.6618
32.476281641, 96.390, 1982.0, 44.5197
32.528802772, 96.390, 1921.0, 43.8292
32.581323902, 96.390, 2196.0, 46.8615
32.633845033, 96.390, 2553.0, 50.5272
32.686366164, 96.390, 3072.0, 55.4256
32.738887295, 96.390, 2938.0, 54.2033
32.791408425, 96.390, 2813.0, 53.0377
32.843929556, 96.390, 2591.0, 50.9019
32.896450687, 96.390, 2905.0, 53.8981
32.948971817, 96.390, 2757.0, 52.5071
33.001492948, 96.390, 2651.0, 51.4879
33.054014079, 96.390, 2730.0, 52.2494
33.106535209, 96.390, 3862.0, 62.1450
33.159056340, 96.390, 4775.0, 69.1014
33.211577471, 96.390, 3782.0, 61.4980
33.264098602, 96.390, 3206.0, 56.6216
33.316619732, 96.390, 2721.0, 52.1632
33.369140863, 96.390, 2598.0, 50.9706
33.421661994, 96.390, 2403.0, 49.0204
33.474183124, 96.390, 2130.0, 46.1519
33.526704255, 96.390, 2037.0, 45.1331
33.579225386, 96.390, 2149.0, 46.3573
33.631746517, 96.390, 2123.0, 46.0760
33.684267647, 96.390, 2007.0, 44.7996
33.736788778, 96.390, 2034.0, 45.0999
33.789309909, 96.390, 1997.0, 44.6878
33.841831039, 96.390, 2040.0, 45.1664
33.894352170, 96.390, 2203.0, 46.9361
33.946873301, 96.390, 2283.0, 47.7807
33.999394432, 96.390, 2760.0, 52.5357
34.051915562, 96.390, 3968.0, 62.9921
34.104436693, 96.390, 5179.0, 71.9653
34.156957824, 96.390, 4432.0, 66.5733
34.209478954, 96.390, 3801.0, 61.6523
34.262000085, 96.390, 2700.0, 51.9615
34.314521216, 96.390, 2340.0, 48.3735
34.367042346, 96.390, 2557.0, 50.5668
34.419563477, 96.390, 2321.0, 48.1768
34.472084608, 96.390, 2093.0, 45.7493
34.524605739, 96.390, 1956.0, 44.2267
34.577126869, 96.390, 1887.0, 43.4396
34.629648000, 96.390, 1840.0, 42.8952
34.682169131, 96.390, 1896.0, 43.5431
34.734690261, 96.390, 1873.0, 43.2782
34.787211392, 96.390, 1866.0, 43.1972
34.839732523, 96.390, 1823.0, 42.6966
34.892253654, 96.390, 1808.0, 42.5206
34.944774784, 96.390, 1802.0, 42.4500
34.997295915, 96.390, 1898.0, 43.5660
35.049817046, 96.390, 1699.0, 41.2189
35.102338176, 96.390, 1809.0, 42.5323
35.154859307, 96.390, 1801.0, 42.4382
35.207380438, 96.390, 1889.0, 43.4626
35.259901569, 96.390, 2175.0, 46.6369
35.312422699, 96.390, 3340.0, 57.7927
35.364943830, 96.390, 4238.0, 65.0999
35.417464961, 96.390, 4822.0, 69.4406
35.469986091, 96.390, 3229.0, 56.8243
35.522507222, 96.390, 2343.0, 48.4045
35.575028353, 96.390, 1805.0, 42.4853
35.627549484, 96.390, 1722.0, 41.4970
35.680070614, 96.390, 1720.0, 41.4729
35.732591745, 96.390, 1765.0, 42.0119
35.785112876, 96.390, 1699.0, 41.2189
35.837634006, 96.390, 1595.0, 39.9375
35.890155137, 96.390, 1605.0, 40.0625
35.942676268, 96.390, 1586.0, 39.8246
35.995197398, 96.390, 1517.0, 38.9487
36.047718529, 96.390, 1568.0, 39.5980
36.100239660, 96.390, 1651.0, 40.6325
36.152760791, 96.390, 1606.0, 40.0749
36.205281921, 96.390, 1549.0, 39.3573
36.257803052, 96.390, 1609.0, 40.1123
36.310324183, 96.390, 1555.0, 39.4335
36.362845313, 96.390, 1706.0, 41.3038
36.415366444, 96.390, 1882.0, 43.3820
36.467887575, 96.390, 1706.0, 41.3038
36.520408706, 96.390, 1761.0, 41.9643
36.572929836, 96.390, 1867.0, 43.2088
36.625450967, 96.390, 2312.0, 48.0833
36.677972098, 96.390, 2484.0, 49.8397
36.730493228, 96.390, 2322.0, 48.1871
36.783014359, 96.390, 1978.0, 44.4747
36.835535490, 96.390, 1691.0, 41.1218
36.888056621, 96.390, 1548.0, 39.3446
36.940577751, 96.390, 1440.0, 37.9473
36.993098882, 96.390, 1324.0, 36.3868
37.045620013, 96.390, 1328.0, 36.4417
37.098141143, 96.390, 1350.0, 36.7423
37.150662274, 96.390, 1351.0, 36.7560
37.203183405, 96.390, 1397.0, 37.3765
37.255704535, 96.390, 1411.0, 37.5633
37.308225666, 96.390, 1417.0, 37.6431
37.360746797, 96.390, 1420.0, 37.6829
37.413267928, 96.390, 1457.0, 38.1707
37.465789058, 96.390, 1352.0, 36.7696
37.518310189, 96.390, 1295.0, 35.9861
37.570831320, 96.390, 1325.0, 36.4005
37.623352450, 96.390, 1248.0, 35.3270
37.675873581, 96.390, 1359.0, 36.8646
37.728394712, 96.390, 1546.0, 39.3192
37.780915843, 96.390, 1591.0, 39.8873
37.833436973, 96.390, 1552.0, 39.3954
37.885958104, 96.390, 1516.0, 38.9358
37.938479235, 96.390, 1287.0, 35.8748
37.991000365, 96.390, 1294.0, 35.9722
38.043521496, 96.390, 1317.0, 36.2905
38.096042627, 96.390, 1267.0, 35.5949
38.148563758, 96.390, 1228.0, 35.0428
38.201084888, 96.390, 1219.0, 34.9142
38.253606019, 96.390, 1184.0, 34.4093
38.306127150, 96.390, 1211.0, 34.7994
38.358648280, 96.390, 1443.0, 37.9868
38.411169411, 96.390, 1525.0, 39.0512
38.463690542, 96.390, 1490.0, 38.6005
38.516211673, 96.390, 1520.0, 38.9872
38.568732803, 96.390, 1715.0, 41.4126
38.621253934, 96.390, 2188.0, 46.7761
38.673775065, 96.390, 2603.0, 51.0196
38.726296195, 96.390, 2003.0, 44.7549
38.778817326, 96.390, 1929.0, 43.9204
38.831338457, 96.390, 1578.0, 39.7240
38.883859587, 96.390, 1398.0, 37.3898
38.936380718, 96.390, 1310.0, 36.1939
38.988901849, 96.390, 1270.0, 35.6371
39.041422980, 96.390, 1301.0, 36.0694
39.093944110, 96.390, 1229.0, 35.0571
39.146465241, 96.390, 1254.0, 35.4119
39.198986372, 96.390, 1258.0, 35.4683
39.251507502, 96.390, 1272.0, 35.6651
39.304028633, 96.390, 1504.0, 38.7814
39.356549764, 96.390, 1676.0, 40.9390
39.409070895, 96.390, 1483.0, 38.5097
39.461592025, 96.390, 1419.0, 37.6696
39.514113156, 96.390, 1401.0, 37.4299
39.566634287, 96.390, 1625.0, 40.3113
39.619155417, 96.390, 2020.0, 44.9444
39.671676548, 96.390, 1718.0, 41.4488
39.724197679, 96.390, 1715.0, 41.4126
39.776718810, 96.390, 1541.0, 39.2556
39.829239940, 96.390, 1755.0, 41.8927
39.881761071, 96.390, 1833.0, 42.8135
39.934282202, 96.390, 1746.0, 41.7852
39.986803332, 96.390, 1548.0, 39.3446
40.039324463, 96.390, 1337.0, 36.5650
40.091845594, 96.390, 1205.0, 34.7131
40.144366725, 96.390, 1289.0, 35.9026
40.196887855, 96.390, 1222.0, 34.9571
40.249408986, 96.390, 1237.0, 35.1710
40.301930117, 96.390, 1113.0, 33.3617
40.354451247, 96.390, 1036.0, 32.1870
40.406972378, 96.390, 1127.0, 33.5708
40.459493509, 96.390, 1113.0, 33.3617
40.512014639, 96.390, 1043.0, 32.2955
40.564535770, 96.390, 1069.0, 32.6956
40.617056901, 96.390, 1055.0, 32.4808
40.669578032, 96.390, 1118.0, 33.4365
40.722099162, 96.390, 1214.0, 34.8425
40.774620293, 96.390, 1078.0, 32.8329
40.827141424, 96.390, 1136.0, 33.7046
40.879662554, 96.390, 1122.0, 33.4963
40.932183685, 96.390, 1148.0, 33.8821
40.984704816, 96.390, 1170.0, 34.2053
41.037225947, 96.390, 1208.0, 34.7563
41.089747077, 96.390, 1315.0, 36.2629
41.142268208, 96.390, 1259.0, 35.4824
41.194789339, 96.390, 1255.0, 35.4260
41.247310469, 96.390, 1103.0, 33.2114
41.299831600, 96.390, 1056.0, 32.4962
41.352352731, 96.390, 1027.0, 32.0468
41.404873862, 96.390, 1069.0, 32.6956
41.457394992, 96.390, 1103.0, 33.2114
41.509916123, 96.390, 1078.0, 32.8329
41.562437254, 96.390, 1093.0, 33.0606
41.614958384, 96.390, 1072.0, 32.7414
41.667479515, 96.390, 1145.0, 33.8378
41.720000646, 96.390, 1371.0, 37.0270
41.772521776, 96.390, 1513.0, 38.8973
41.825042907, 96.390, 1326.0, 36.4143
41.877564038, 96.390, 1310.0, 36.1939
41.930085169, 96.390, 1174.0, 34.2637
41.982606299, 96.390, 1097.0, 33.1210
42.035127430, 96.390, 1091.0, 33.0303
42.087648561, 96.390, 1220.0, 34.9285
42.140169691, 96.390, 1405.0, 37.4833
42.192690822, 96.390, 1580.0, 39.7492
42.245211953, 96.390, 1224.0, 34.9857
42.297733084, 96.390, 1262.0, 35.5246
42.350254214, 96.390, 1149.0, 33.8969
42.402775345, 96.390, 1125.0, 33.5410
42.455296476, 96.390, 1119.0, 33.4515
42.507817606, 96.390, 1118.0, 33.4365
42.560338737, 96.390, 1239.0, 35.1994
42.612859868, 96.390, 1180.0, 34.3511
42.665380999, 96.390, 1235.0, 35.1426
42.717902129, 96.390, 1334.0, 36.5240
42.770423260, 96.390, 1560.0, 39.4968
42.822944391, 96.390, 1338.0, 36.5787
42.875465521, 96.390, 1258.0, 35.4683
42.927986652, 96.390, 1168.0, 34.1760
42.980507783, 96.390, 998.0, 31.5911
43.033028914, 96.390, 1081.0, 32.8786
43.085550044, 96.390, 1123.0, 33.5112
43.138071175, 96.390, 1055.0, 32.4808
43.190592306, 96.390, 1140.0, 33.7639
43.243113436, 96.390, 1194.0, 34.5543
43.295634567, 96.390, 1348.0, 36.7151
43.348155698, 96.390, 1377.0, 37.1080
43.400676828, 96.390, 1231.0, 35.0856
43.453197959, 96.390, 1249.0, 35.3412
43.505719090, 96.390, 1178.0, 34.3220
43.558240221, 96.390, 1196.0, 34.5832
43.610761351, 96.390, 1214.0, 34.8425
43.663282482, 96.390, 1169.0, 34.1906
43.715803613, 96.390, 1158.0, 34.0294
43.768324743, 96.390, 1146.0, 33.8526
43.820845874, 96.390, 1162.0, 34.0881
43.873367005, 96.390, 1240.0, 35.2136
43.925888136, 96.390, 1150.0, 33.9116
43.978409266, 96.390, 1145.0, 33.8378
44.030930397, 96.390, 1177.0, 34.3074
44.083451528, 96.390, 1048.0, 32.3728
44.135972658, 96.390, 1084.0, 32.9242
44.188493789, 96.390, 1018.0, 31.9061
44.241014920, 96.390, 1048.0, 32.3728
44.293536051, 96.390, 1082.0, 32.8938
44.346057181, 96.390, 1106.0, 33.2566
44.398578312, 96.390, 1069.0, 32.6956
44.451099443, 96.390, 1069.0, 32.6956
44.503620573, 96.390, 1042.0, 32.2800
44.556141704, 96.390, 1047.0, 32.3574
44.608662835, 96.390, 1076.0, 32.8024
44.661183966, 96.390, 1111.0, 33.3317
44.713705096, 96.390, 1137.0, 33.7194
44.766226227, 96.390, 1092.0, 33.0454
44.818747358, 96.390, 1057.0, 32.5115
44.871268488, 96.390, 1107.0, 33.2716
44.923789619, 96.390, 1166.0, 34.1467
44.976310750, 96.390, 1309.0, 36.1801
45.028831880, 96.390, 1678.0, 40.9634
45.081353011, 96.390, 1635.0, 40.4351
45.133874142, 96.390, 1428.0, 37.7889
45.186395273, 96.390, 1333.0, 36.5103
45.238916403, 96.390, 1183.0, 34.3948
45.291437534, 96.390, 1036.0, 32.1870
45.343958665, 96.390, 1017.0, 31.8904
45.396479795, 96.390, 1042.0, 32.2800
45.449000926, 96.390, 1038.0, 32.2180
45.501522057, 96.390, 1023.0, 31.9844
45.554043188, 96.390, 919.0, 30.3150
45.606564318, 96.390, 1059.0, 32.5423
45.659085449, 96.390, 1074.0, 32.7719
45.711606580, 96.390, 1218.0, 34.8999
45.764127710, 96.390, 1144.0, 33.8231
45.816648841, 96.390, 1133.0, 33.6601
45.869169972, 96.390, 1073.0, 32.7567
45.921691103, 96.390, 1069.0, 32.6956
45.974212233, 96.390, 1044.0, 32.3110
46.026733364, 96.390, 1139.0, 33.7491
46.079254495, 96.390, 1163.0, 34.1028
46.131775625, 96.390, 1143.0, 33.8083
46.184296756, 96.390, 1138.0, 33.7343
46.236817887, 96.390, 1057.0, 32.5115
46.289339017, 96.390, 1130.0, 33.6155
46.341860148, 96.390, 1082.0, 32.8938
46.394381279, 96.390, 1140.0, 33.7639
46.446902410, 96.390, 1096.0, 33.1059
46.499423540, 96.390, 1122.0, 33.4963
46.551944671, 96.390, 1224.0, 34.9857
46.604465802, 96.390, 1413.0, 37.5899
46.656986932, 96.390, 1545.0, 39.3065
46.709508063, 96.390, 1532.0, 39.1408
46.762029194, 96.390, 1430.0, 37.8153
46.814550325, 96.390, 1351.0, 36.7560
46.867071455, 96.390, 1250.0, 35.3553
46.919592586, 96.390, 1094.0, 33.0757
46.972113717, 96.390, 1082.0, 32.8938
47.024634847, 96.390, 1090.0, 33.0151
47.077155978, 96.390, 1029.0, 32.0780
47.129677109, 96.390, 1118.0, 33.4365
47.182198240, 96.390, 1105.0, 33.2415
47.234719370, 96.390, 1144.0, 33.8231
47.287240501, 96.390, 1205.0, 34.7131
47.339761632, 96.390, 1165.0, 34.1321
47.392282762, 96.390, 1227.0, 35.0286
47.444803893, 96.390, 1280.0, 35.7771
47.497325024, 96.390, 1358.0, 36.8511
47.549846155, 96.390, 1473.0, 38.3797
47.602367285, 96.390, 1502.0, 38.7556
47.654888416, 96.390, 1359.0, 36.8646
47.707409547, 96.390, 1246.0, 35.2987
47.759930677, 96.390, 1131.0, 33.6303
47.812451808, 96.390, 1062.0, 32.5883
47.864972939, 96.390, 1042.0, 32.2800
47.917494069, 96.390, 1022.0, 31.9687
47.970015200, 96.390, 980.0, 31.3050
48.022536331, 96.390, 1039.0, 32.2335
48.075057462, 96.390, 1000.0, 31.6228
48.127578592, 96.390, 1032.0, 32.1248
48.180099723, 96.390, 1006.0, 31.7175
48.232620854, 96.390, 983.0, 31.3528
48.285141984, 96.390, 1019.0, 31.9218
48.337663115, 96.390, 976.0, 31.2410
48.390184246, 96.390, 960.0, 30.9839
48.442705377, 96.390, 1007.0, 31.7333
48.495226507, 96.390, 1052.0, 32.4345
48.547747638, 96.390, 963.0, 31.0322
48.600268769, 96.390, 990.0, 31.4643
48.652789899, 96.390, 1033.0, 32.1403
48.705311030, 96.390, 1126.0, 33.5559
48.757832161, 96.390, 1128.0, 33.5857
48.810353292, 96.390, 1172.0, 34.2345
48.862874422, 96.390, 1046.0, 32.3419
48.915395553, 96.390, 1069.0, 32.6956
48.967916684, 96.390, 1037.0, 32.2025
49.020437814, 96.390, 892.0, 29.8664
49.072958945, 96.390, 1000.0, 31.6228
49.125480076, 96.390, 1068.0, 32.6803
49.178001207, 96.390, 1813.0, 42.5793
49.230522337, 96.390, 1252.0, 35.3836
49.283043468, 96.390, 1109.0, 33.3017
49.335564599, 96.390, 1322.0, 36.3593
49.388085729, 96.390, 927.0, 30.4467
49.440606860, 96.390, 912.0, 30.1993
49.493127991, 96.390, 872.0, 29.5296
49.545649121, 96.390, 912.0, 30.1993
49.598170252, 96.390, 904.0, 30.0666
49.650691383, 96.390, 924.0, 30.3974
49.703212514, 96.390, 927.0, 30.4467
49.755733644, 96.390, 952.0, 30.8545
49.808254775, 96.390, 1007.0, 31.7333
49.860775906, 96.390, 913.0, 30.2159
49.913297036, 96.390, 862.0, 29.3598
49.965818167, 96.390, 882.0, 29.6985
50.018339298, 96.390, 898.0, 29.9666
50.070860429, 96.390, 847.0, 29.1033
50.123381559, 96.390, 892.0, 29.8664
50.175902690, 96.390, 878.0, 29.6311
50.228423821, 96.390, 923.0, 30.3809
50.280944951, 96.390, 936.0, 30.5941
50.333466082, 96.390, 978.0, 31.2730
50.385987213, 96.390, 965.0, 31.0644
50.438508344, 96.390, 949.0, 30.8058
50.491029474, 96.390, 996.0, 31.5595
50.543550605, 96.390, 1064.0, 32.6190
50.596071736, 96.390, 1265.0, 35.5668
50.648592866, 96.390, 1315.0, 36.2629
50.701113997, 96.390, 1218.0, 34.8999
50.753635128, 96.390, 1132.0, 33.6452
50.806156258, 96.390, 1045.0, 32.3265
50.858677389, 96.390, 1016.0, 31.8748
50.911198520, 96.390, 923.0, 30.3809
50.963719651, 96.390, 934.0, 30.5614
51.016240781, 96.390, 925.0, 30.4138
51.068761912, 96.390, 889.0, 29.8161
51.121283043, 96.390, 855.0, 29.2404
51.173804173, 96.390, 855.0, 29.2404
51.226325304, 96.390, 788.0, 28.0713
51.278846435, 96.390, 817.0, 28.5832
51.331367566, 96.390, 840.0, 28.9828
51.383888696, 96.390, 829.0, 28.7924
51.436409827, 96.390, 831.0, 28.8271
51.488930958, 96.390, 846.0, 29.0861
51.541452088, 96.390, 821.0, 28.6531
51.593973219, 96.390, 843.0, 29.0345
51.646494350, 96.390, 894.0, 29.8998
51.699015481, 96.390, 867.0, 29.4449
51.751536611, 96.390, 986.0, 31.4006
51.804057742, 96.390, 987.0, 31.4166
51.856578873, 96.390, 958.0, 30.9516
51.909100003, 96.390, 989.0, 31.4484
51.961621134, 96.390, 1108.0, 33.2866
52.014142265, 96.390, 1502.0, 38.7556
52.066663396, 96.390, 1571.0, 39.6358
52.119184526, 96.390, 1145.0, 33.8378
52.171705657, 96.390, 1263.0, 35.5387
52.224226788, 96.390, 1095.0, 33.0908
52.276747918, 96.390, 915.0, 30.2490
52.329269049, 96.390, 784.0, 28.0000
52.381790180, 96.390, 856.0, 29.2575
52.434311310, 96.390, 887.0, 29.7825
52.486832441, 96.390, 882.0, 29.6985
52.539353572, 96.390, 886.0, 29.7658
52.591874703, 96.390, 818.0, 28.6007
52.644395833, 96.390, 883.0, 29.7153
52.696916964, 96.390, 954.0, 30.8869
52.749438095, 96.390, 1089.0, 33.0000
52.801959225, 96.390, 1069.0, 32.6956
52.854480356, 96.390, 1046.0, 32.3419
52.907001487, 96.390, 1139.0, 33.7491
52.959522618, 96.390, 1085.0, 32.9393
53.012043748, 96.390, 1390.0, 37.2827
53.064564879, 96.390, 1389.0, 37.2693
53.117086010, 96.390, 1250.0, 35.3553
53.169607140, 96.390, 1140.0, 33.7639
53.222128271, 96.390, 1012.0, 31.8119
53.274649402, 96.390, 932.0, 30.5287
53.327170533, 96.390, 876.0, 29.5973
53.379691663, 96.390, 890.0, 29.8329
53.432212794, 96.390, 876.0, 29.5973
53.484733925, 96.390, 900.0, 30.0000
53.537255055, 96.390, 932.0, 30.5287
53.589776186, 96.390, 878.0, 29.6311
53.642297317, 96.390, 878.0, 29.6311
53.694818448, 96.390, 924.0, 30.3974
53.747339578, 96.390, 814.0, 28.5307
53.799860709, 96.390, 862.0, 29.3598
53.852381840, 96.390, 811.0, 28.4781
53.904902970, 96.390, 883.0, 29.7153
53.957424101, 96.390, 928.0, 30.4631
54.009945232, 96.390, 931.0, 30.5123
54.062466362, 96.390, 912.0, 30.1993
54.114987493, 96.390, 887.0, 29.7825
54.167508624, 96.390, 961.0, 31.0000
54.220029755, 96.390, 912.0, 30.1993
54.272550885, 96.390, 930.0, 30.4959
54.325072016, 96.390, 904.0, 30.0666
54.377593147, 96.390, 921.0, 30.3480
54.430114277, 96.390, 878.0, 29.6311
54.482635408, 96.390, 1052.0, 32.4345
54.535156539, 96.390, 1126.0, 33.5559
54.587677670, 96.390, 1072.0, 32.7414
54.640198800, 96.390, 991.0, 31.4802
54.692719931, 96.390, 1004.0, 31.6860
54.745241062, 96.390, 896.0, 29.9333
54.797762192, 96.390, 897.0, 29.9500
54.850283323, 96.390, 969.0, 31.1288
54.902804454, 96.390, 1075.0, 32.7872
54.955325585, 96.390, 1221.0, 34.9428
55.007846715, 96.390, 1068.0, 32.6803
55.060367846, 96.390, 1007.0, 31.7333
55.112888977, 96.390, 1040.0, 32.2490
55.165410107, 96.390, 869.0, 29.4788
55.217931238, 96.390, 850.0, 29.1548
55.270452369, 96.390, 835.0, 28.8964
55.322973499, 96.390, 816.0, 28.5657
55.375494630, 96.390, 768.0, 27.7128
55.428015761, 96.390, 797.0, 28.2312
55.480536892, 96.390, 896.0, 29.9333
55.533058022, 96.390, 819.0, 28.6182
55.585579153, 96.390, 853.0, 29.2062
55.638100284, 96.390, 786.0, 28.0357
55.690621414, 96.390, 736.0, 27.1293
55.743142545, 96.390, 697.0, 26.4008
55.795663676, 96.390, 732.0, 27.0555
55.848184807, 96.390, 805.0, 28.3725
55.900705937, 96.390, 735.0, 27.1109
55.953227068, 96.390, 729.0, 27.0000
56.005748199, 96.390, 763.0, 27.6225
56.058269329, 96.390, 776.0, 27.8568
56.110790460, 96.390, 856.0, 29.2575
56.163311591, 96.390, 934.0, 30.5614
56.215832722, 96.390, 865.0, 29.4109
56.268353852, 96.390, 818.0, 28.6007
56.320874983, 96.390, 797.0, 28.2312
56.373396114, 96.390, 724.0, 26.9072
56.425917244, 96.390, 760.0, 27.5681
56.478438375, 96.390, 770.0, 27.7489
56.530959506, 96.390, 667.0, 25.8263
56.583480637, 96.390, 727.0, 26.9629
56.636001767, 96.390, 767.0, 27.6948
56.688522898, 96.390, 760.0, 27.5681
56.741044029, 96.390, 752.0, 27.4226
56.793565159, 96.390, 764.0, 27.6405
56.846086290, 96.390, 761.0, 27.5862
56.898607421, 96.390, 767.0, 27.6948
56.951128551, 96.390, 732.0, 27.0555
57.003649682, 96.390, 756.0, 27.4955
57.056170813, 96.390, 738.0, 27.1662
57.108691944, 96.390, 810.0, 28.4605
57.161213074, 96.390, 814.0, 28.5307
57.213734205, 96.390, 727.0, 26.9629
57.266255336, 96.390, 790.0, 28.1069
57.318776466, 96.390, 817.0, 28.5832
57.371297597, 96.390, 829.0, 28.7924
57.423818728, 96.390, 938.0, 30.6268
57.476339859, 96.390, 851.0, 29.1719
57.528860989, 96.390, 809.0, 28.4429
57.581382120, 96.390, 838.0, 28.9482
57.633903251, 96.390, 789.0, 28.0891
57.686424381, 96.390, 811.0, 28.4781
57.738945512, 96.390, 791.0, 28.1247
57.791466643, 96.390, 948.0, 30.7896
57.843987774, 96.390, 1293.0, 35.9583
57.896508904, 96.390, 1281.0, 35.7911
57.949030035, 96.390, 1136.0, 33.7046
58.001551166, 96.390, 1009.0, 31.7648
58.054072296, 96.390, 1064.0, 32.6190
58.106593427, 96.390, 822.0, 28.6705
58.159114558, 96.390, 783.0, 27.9821
58.211635689, 96.390, 769.0, 27.7308
58.264156819, 96.390, 706.0, 26.5707
58.316677950, 96.390, 740.0, 27.2029
58.369199081, 96.390, 751.0, 27.4044
58.421720211, 96.390, 722.0, 26.8701
58.474241342, 96.390, 693.0, 26.3249
58.526762473, 96.390, 710.0, 26.6458
58.579283603, 96.390, 730.0, 27.0185
58.631804734, 96.390, 704.0, 26.5330
58.684325865, 96.390, 658.0, 25.6515
58.736846996, 96.390, 683.0, 26.1343
58.789368126, 96.390, 699.0, 26.4386
58.841889257, 96.390, 715.0, 26.7395
58.894410388, 96.390, 802.0, 28.3196
58.946931518, 96.390, 795.0, 28.1957
58.999452649, 96.390, 809.0, 28.4429
59.051973780, 96.390, 736.0, 27.1293
59.104494911, 96.390, 783.0, 27.9821
59.157016041, 96.390, 769.0, 27.7308
59.209537172, 96.390, 767.0, 27.6948
59.262058303, 96.390, 749.0, 27.3679
59.314579433, 96.390, 771.0, 27.7669
59.367100564, 96.390, 719.0, 26.8142
59.419621695, 96.390, 832.0, 28.8444
59.472142826, 96.390, 741.0, 27.2213
59.524663956, 96.390, 730.0, 27.0185
59.577185087, 96.390, 723.0, 26.8887
59.629706218, 96.390, 766.0, 27.6767
59.682227348, 96.390, 771.0, 27.7669
59.734748479, 96.390, 809.0, 28.4429
59.787269610, 96.390, 851.0, 29.1719
59.839790740, 96.390, 803.0, 28.3373
59.892311871, 96.390, 784.0, 28.0000
59.944833002, 96.390, 759.0, 27.5500
59.997354133, 96.390, 798.0, 28.2489
60.049875263, 96.390, 787.0, 28.0535
60.102396394, 96.390, 755.0, 27.4773
60.154917525, 96.390, 759.0, 27.5500
60.207438655, 96.390, 761.0, 27.5862
60.259959786, 96.390, 793.0, 28.1603
60.312480917, 96.390, 750.0, 27.3861
60.365002048, 96.390, 743.0, 27.2580
60.417523178, 96.390, 722.0, 26.8701
60.470044309, 96.390, 789.0, 28.0891
60.522565440, 96.390, 769.0, 27.7308
60.575086570, 96.390, 788.0, 28.0713
60.627607701, 96.390, 779.0, 27.9106
60.680128832, 96.390, 763.0, 27.6225
60.732649963, 96.390, 796.0, 28.2135
60.785171093, 96.390, 782.0, 27.9643
60.837692224, 96.390, 814.0, 28.5307
60.890213355, 96.390, 866.0, 29.4279
60.942734485, 96.390, 825.0, 28.7228
60.995255616, 96.390, 795.0, 28.1957
61.047776747, 96.390, 801.0, 28.3019
61.100297878, 96.390, 860.0, 29.3258
61.152819008, 96.390, 845.0, 29.0689
61.205340139, 96.390, 881.0, 29.6816
61.257861270, 96.390, 1061.0, 32.5730
61.310382400, 96.390, 918.0, 30.2985
61.362903531, 96.390, 845.0, 29.0689
61.415424662, 96.390, 971.0, 31.1609
61.467945792, 96.390, 885.0, 29.7489
61.520466923, 96.390, 811.0, 28.4781
61.572988054, 96.390, 809.0, 28.4429
61.625509185, 96.390, 881.0, 29.6816
61.678030315, 96.390, 990.0, 31.4643
61.730551446, 96.390, 893.0, 29.8831
61.783072577, 96.390, 872.0, 29.5296
61.835593707, 96.390, 852.0, 29.1890
61.888114838, 96.390, 852.0, 29.1890
61.940635969, 96.390, 884.0, 29.7321
61.993157100, 96.390, 785.0, 28.0179
62.045678230, 96.390, 788.0, 28.0713
62.098199361, 96.390, 761.0, 27.5862
62.150720492, 96.390, 755.0, 27.4773
62.203241622, 96.390, 827.0, 28.7576
62.255762753, 96.390, 731.0, 27.0370
62.308283884, 96.390, 825.0, 28.7228
62.360805015, 96.390, 775.0, 27.8388
62.413326145, 96.390, 777.0, 27.8747
62.465847276, 96.390, 725.0, 26.9258
62.518368407, 96.390, 727.0, 26.9629
62.570889537, 96.390, 762.0, 27.6043
62.623410668, 96.390, 708.0, 26.6083
62.675931799, 96.390, 678.0, 26.0384
62.728452930, 96.390, 722.0, 26.8701
62.780974060, 96.390, 746.0, 27.3130
62.833495191, 96.390, 796.0, 28.2135
62.886016322, 96.390, 736.0, 27.1293
62.938537452, 96.390, 749.0, 27.3679
62.991058583, 96.390, 762.0, 27.6043
63.043579714, 96.390, 783.0, 27.9821
63.096100844, 96.390, 762.0, 27.6043
63.148621975, 96.390, 752.0, 27.4226
63.201143106, 96.390, 753.0, 27.4408
63.253664237, 96.390, 732.0, 27.0555
63.306185367, 96.390, 730.0, 27.0185
63.358706498, 96.390, 677.0, 26.0192
63.411227629, 96.390, 664.0, 25.7682
63.463748759, 96.390, 708.0, 26.6083
63.516269890, 96.390, 692.0, 26.3059
63.568791021, 96.390, 718.0, 26.7955
63.621312152, 96.390, 771.0, 27.7669
63.673833282, 96.390, 742.0, 27.2397
63.726354413, 96.390, 814.0, 28.5307
63.778875544, 96.390, 773.0, 27.8029
63.831396674, 96.390, 836.0, 28.9137
63.883917805, 96.390, 799.0, 28.2666
63.936438936, 96.390, 764.0, 27.6405
63.988960067, 96.390, 699.0, 26.4386
64.041481197, 96.390, 717.0, 26.7769
64.094002328, 96.390, 721.0, 26.8514
64.146523459, 96.390, 739.0, 27.1846
64.199044589, 96.390, 731.0, 27.0370
64.251565720, 96.390, 693.0, 26.3249
64.304086851, 96.390, 730.0, 27.0185
64.356607981, 96.390, 700.0, 26.4575
64.409129112, 96.390, 659.0, 25.6710
64.461650243, 96.390, 655.0, 25.5930
64.514171374, 96.390, 664.0, 25.7682
64.566692504, 96.390, 707.0, 26.5895
64.619213635, 96.390, 717.0, 26.7769
64.671734766, 96.390, 741.0, 27.2213
64.724255896, 96.390, 683.0, 26.1343
64.776777027, 96.390, 724.0, 26.9072
64.829298158, 96.390, 719.0, 26.8142
64.881819289, 96.390, 710.0, 26.6458
64.934340419, 96.390, 690.0, 26.2679
64.986861550, 96.390, 655.0, 25.5930