File: Files_organized_for_plots/Constant_NaOH_1mL10M_to_1gPC_28Day/XRD_AlCornernul_Act03May22_B1_0833M_NaOH_LS0152_1.csv
[Measurement conditions]
Sample identification,XRD_AlCornernul_Act03May22_B1_0714M_NaOH_LS0172_1
Comment - 1,"Configuration=Stage for Flat Samples/Holders, Owner=User-1, Creation date=7/1/2020 9:53:24 AM"
Comment - 2,"Goniometer=Theta/Theta; Minimum step size 2Theta:0.0001; Minimum step size Omega:0.0001"
Comment - 3,"Sample stage=Stage for flat samples/holders"
Comment - 4,"Diffractometer system=EMPYREAN"
Comment - 5,"Measurement program=C:\Users\ibo5034\OneDrive - The Pennsylvania State University\NEUP\Zerobackground scan.xrdmp, Identifier={98A3B11C-88F9-4AA6-982C-73314A311EF5}"
Anode material,Cu
K-Alpha1 wavelength,1.5405980
K-Alpha2 wavelength,1.5444260
Ratio K-Alpha2/K-Alpha1,0.500
Divergence slit,Fixed,0.25
Monochromator used,NO
Generator voltage, 45
Tube current, 40
File date and time,03/Jun/2022 14:45
Unit cell,
h k l, 0 0 0
Scan axis,Gonio
Scan range,4.994599997,64.999991833
Scan step size,0.0262606
No. of points, 2285
Scan type,CONTINUOUS
Time per step,96.390
[Scan points]
Angle, TimePerStep, Intensity, ESD
5.007730280, 96.390, 3373.0, 58.0775
5.060251411, 96.390, 3521.0, 59.3380
5.112772541, 96.390, 3439.0, 58.6430
5.165293672, 96.390, 3451.0, 58.7452
5.217814803, 96.390, 3359.0, 57.9569
5.270335934, 96.390, 3266.0, 57.1489
5.322857064, 96.390, 3205.0, 56.6127
5.375378195, 96.390, 3102.0, 55.6956
5.427899326, 96.390, 3100.0, 55.6776
5.480420456, 96.390, 3211.0, 56.6657
5.532941587, 96.390, 3116.0, 55.8211
5.585462718, 96.390, 3073.0, 55.4346
5.637983849, 96.390, 3029.0, 55.0364
5.690504979, 96.390, 3034.0, 55.0818
5.743026110, 96.390, 3021.0, 54.9636
5.795547241, 96.390, 3022.0, 54.9727
5.848068371, 96.390, 2975.0, 54.5436
5.900589502, 96.390, 2910.0, 53.9444
5.953110633, 96.390, 2952.0, 54.3323
6.005631763, 96.390, 2935.0, 54.1756
6.058152894, 96.390, 2943.0, 54.2494
6.110674025, 96.390, 2947.0, 54.2863
6.163195156, 96.390, 2926.0, 54.0925
6.215716286, 96.390, 2929.0, 54.1202
6.268237417, 96.390, 2930.0, 54.1295
6.320758548, 96.390, 2826.0, 53.1601
6.373279678, 96.390, 2980.0, 54.5894
6.425800809, 96.390, 2872.0, 53.5910
6.478321940, 96.390, 2901.0, 53.8609
6.530843071, 96.390, 2939.0, 54.2125
6.583364201, 96.390, 2933.0, 54.1572
6.635885332, 96.390, 2892.0, 53.7773
6.688406463, 96.390, 3044.0, 55.1725
6.740927593, 96.390, 3073.0, 55.4346
6.793448724, 96.390, 3290.0, 57.3585
6.845969855, 96.390, 3478.0, 58.9746
6.898490986, 96.390, 3757.0, 61.2944
6.951012116, 96.390, 3990.0, 63.1664
7.003533247, 96.390, 4483.0, 66.9552
7.056054378, 96.390, 5371.0, 73.2871
7.108575508, 96.390, 6618.0, 81.3511
7.161096639, 96.390, 8754.0, 93.5628
7.213617770, 96.390, 12381.0, 111.2699
7.266138900, 96.390, 9749.0, 98.7370
7.318660031, 96.390, 4363.0, 66.0530
7.371181162, 96.390, 3302.0, 57.4630
7.423702293, 96.390, 2955.0, 54.3599
7.476223423, 96.390, 2811.0, 53.0189
7.528744554, 96.390, 2709.0, 52.0481
7.581265685, 96.390, 2746.0, 52.4023
7.633786815, 96.390, 2692.0, 51.8845
7.686307946, 96.390, 2658.0, 51.5558
7.738829077, 96.390, 2670.0, 51.6720
7.791350208, 96.390, 2530.0, 50.2991
7.843871338, 96.390, 2478.0, 49.7795
7.896392469, 96.390, 2506.0, 50.0600
7.948913600, 96.390, 2436.0, 49.3559
8.001434730, 96.390, 2478.0, 49.7795
8.053955861, 96.390, 2482.0, 49.8197
8.106476992, 96.390, 2454.0, 49.5379
8.158998123, 96.390, 2520.0, 50.1996
8.211519253, 96.390, 2527.0, 50.2693
8.264040384, 96.390, 2458.0, 49.5782
8.316561515, 96.390, 2419.0, 49.1833
8.369082645, 96.390, 2439.0, 49.3862
8.421603776, 96.390, 2371.0, 48.6929
8.474124907, 96.390, 2444.0, 49.4368
8.526646038, 96.390, 2522.0, 50.2195
8.579167168, 96.390, 2658.0, 51.5558
8.631688299, 96.390, 2631.0, 51.2933
8.684209430, 96.390, 2387.0, 48.8569
8.736730560, 96.390, 2280.0, 47.7493
8.789251691, 96.390, 2378.0, 48.7647
8.841772822, 96.390, 2295.0, 47.9062
8.894293952, 96.390, 2355.0, 48.5283
8.946815083, 96.390, 2365.0, 48.6313
8.999336214, 96.390, 2197.0, 46.8722
9.051857345, 96.390, 2248.0, 47.4131
9.104378475, 96.390, 2330.0, 48.2701
9.156899606, 96.390, 2327.0, 48.2390
9.209420737, 96.390, 2369.0, 48.6724
9.261941867, 96.390, 2228.0, 47.2017
9.314462998, 96.390, 2288.0, 47.8330
9.366984129, 96.390, 2332.0, 48.2908
9.419505260, 96.390, 2286.0, 47.8121
9.472026390, 96.390, 2297.0, 47.9270
9.524547521, 96.390, 2281.0, 47.7598
9.577068652, 96.390, 2310.0, 48.0625
9.629589782, 96.390, 2355.0, 48.5283
9.682110913, 96.390, 2439.0, 49.3862
9.734632044, 96.390, 2418.0, 49.1732
9.787153175, 96.390, 2509.0, 50.0899
9.839674305, 96.390, 2565.0, 50.6458
9.892195436, 96.390, 2888.0, 53.7401
9.944716567, 96.390, 2972.0, 54.5161
9.997237697, 96.390, 3291.0, 57.3672
10.049758828, 96.390, 3797.0, 61.6198
10.102279959, 96.390, 4885.0, 69.8928
10.154801090, 96.390, 6394.0, 79.9625
10.207322220, 96.390, 8715.0, 93.3542
10.259843351, 96.390, 6399.0, 79.9937
10.312364482, 96.390, 3626.0, 60.2163
10.364885612, 96.390, 3025.0, 55.0000
10.417406743, 96.390, 2748.0, 52.4214
10.469927874, 96.390, 2860.0, 53.4790
10.522449004, 96.390, 2743.0, 52.3737
10.574970135, 96.390, 2800.0, 52.9150
10.627491266, 96.390, 2785.0, 52.7731
10.680012397, 96.390, 2779.0, 52.7162
10.732533527, 96.390, 2825.0, 53.1507
10.785054658, 96.390, 2734.0, 52.2877
10.837575789, 96.390, 2926.0, 54.0925
10.890096919, 96.390, 2955.0, 54.3599
10.942618050, 96.390, 2994.0, 54.7175
10.995139181, 96.390, 3015.0, 54.9090
11.047660312, 96.390, 3036.0, 55.0999
11.100181442, 96.390, 3054.0, 55.2630
11.152702573, 96.390, 3102.0, 55.6956
11.205223704, 96.390, 3304.0, 57.4804
11.257744834, 96.390, 3298.0, 57.4282
11.310265965, 96.390, 3481.0, 59.0000
11.362787096, 96.390, 3441.0, 58.6600
11.415308227, 96.390, 3439.0, 58.6430
11.467829357, 96.390, 3502.0, 59.1777
11.520350488, 96.390, 3793.0, 61.5873
11.572871619, 96.390, 3794.0, 61.5955
11.625392749, 96.390, 3716.0, 60.9590
11.677913880, 96.390, 3688.0, 60.7289
11.730435011, 96.390, 3757.0, 61.2944
11.782956141, 96.390, 3671.0, 60.5888
11.835477272, 96.390, 3398.0, 58.2924
11.887998403, 96.390, 3388.0, 58.2065
11.940519534, 96.390, 3349.0, 57.8705
11.993040664, 96.390, 3185.0, 56.4358
12.045561795, 96.390, 3093.0, 55.6147
12.098082926, 96.390, 2956.0, 54.3691
12.150604056, 96.390, 3004.0, 54.8088
12.203125187, 96.390, 3165.0, 56.2583
12.255646318, 96.390, 3133.0, 55.9732
12.308167449, 96.390, 3196.0, 56.5332
12.360688579, 96.390, 3651.0, 60.4235
12.413209710, 96.390, 4286.0, 65.4675
12.465730841, 96.390, 5706.0, 75.5381
12.518251971, 96.390, 6888.0, 82.9940
12.570773102, 96.390, 4195.0, 64.7688
12.623294233, 96.390, 2786.0, 52.7826
12.675815364, 96.390, 2518.0, 50.1797
12.728336494, 96.390, 2410.0, 49.0918
12.780857625, 96.390, 2252.0, 47.4552
12.833378756, 96.390, 2166.0, 46.5403
12.885899886, 96.390, 2119.0, 46.0326
12.938421017, 96.390, 2157.0, 46.4435
12.990942148, 96.390, 2027.0, 45.0222
13.043463279, 96.390, 1929.0, 43.9204
13.095984409, 96.390, 1992.0, 44.6318
13.148505540, 96.390, 1944.0, 44.0908
13.201026671, 96.390, 1940.0, 44.0454
13.253547801, 96.390, 1966.0, 44.3396
13.306068932, 96.390, 1936.0, 44.0000
13.358590063, 96.390, 2123.0, 46.0760
13.411111193, 96.390, 2103.0, 45.8585
13.463632324, 96.390, 2483.0, 49.8297
13.516153455, 96.390, 3108.0, 55.7494
13.568674586, 96.390, 2813.0, 53.0377
13.621195716, 96.390, 2003.0, 44.7549
13.673716847, 96.390, 1773.0, 42.1070
13.726237978, 96.390, 1839.0, 42.8836
13.778759108, 96.390, 1735.0, 41.6533
13.831280239, 96.390, 1920.0, 43.8178
13.883801370, 96.390, 1995.0, 44.6654
13.936322501, 96.390, 2287.0, 47.8226
13.988843631, 96.390, 2057.0, 45.3542
14.041364762, 96.390, 1742.0, 41.7373
14.093885893, 96.390, 1844.0, 42.9418
14.146407023, 96.390, 1905.0, 43.6463
14.198928154, 96.390, 2130.0, 46.1519
14.251449285, 96.390, 2673.0, 51.7011
14.303970416, 96.390, 3594.0, 59.9500
14.356491546, 96.390, 2627.0, 51.2543
14.409012677, 96.390, 1726.0, 41.5452
14.461533808, 96.390, 1618.0, 40.2244
14.514054938, 96.390, 1512.0, 38.8844
14.566576069, 96.390, 1485.0, 38.5357
14.619097200, 96.390, 1498.0, 38.7040
14.671618331, 96.390, 1472.0, 38.3667
14.724139461, 96.390, 1557.0, 39.4588
14.776660592, 96.390, 1568.0, 39.5980
14.829181723, 96.390, 1556.0, 39.4462
14.881702853, 96.390, 1520.0, 38.9872
14.934223984, 96.390, 1596.0, 39.9500
14.986745115, 96.390, 1525.0, 39.0512
15.039266245, 96.390, 1571.0, 39.6358
15.091787376, 96.390, 1594.0, 39.9249
15.144308507, 96.390, 1815.0, 42.6028
15.196829638, 96.390, 2037.0, 45.1331
15.249350768, 96.390, 2680.0, 51.7687
15.301871899, 96.390, 3725.0, 61.0328
15.354393030, 96.390, 3179.0, 56.3826
15.406914160, 96.390, 1757.0, 41.9166
15.459435291, 96.390, 1594.0, 39.9249
15.511956422, 96.390, 1486.0, 38.5487
15.564477553, 96.390, 1407.0, 37.5100
15.616998683, 96.390, 1393.0, 37.3229
15.669519814, 96.390, 1382.0, 37.1753
15.722040945, 96.390, 1408.0, 37.5233
15.774562075, 96.390, 1499.0, 38.7169
15.827083206, 96.390, 1507.0, 38.8201
15.879604337, 96.390, 1560.0, 39.4968
15.932125468, 96.390, 1630.0, 40.3733
15.984646598, 96.390, 1855.0, 43.0697
16.037167729, 96.390, 2157.0, 46.4435
16.089688860, 96.390, 2937.0, 54.1941
16.142209990, 96.390, 4159.0, 64.4903
16.194731121, 96.390, 3764.0, 61.3514
16.247252252, 96.390, 2168.0, 46.5618
16.299773382, 96.390, 1647.0, 40.5832
16.352294513, 96.390, 1532.0, 39.1408
16.404815644, 96.390, 1514.0, 38.9102
16.457336775, 96.390, 1581.0, 39.7618
16.509857905, 96.390, 1447.0, 38.0395
16.562379036, 96.390, 1312.0, 36.2215
16.614900167, 96.390, 1314.0, 36.2491
16.667421297, 96.390, 1286.0, 35.8608
16.719942428, 96.390, 1335.0, 36.5377
16.772463559, 96.390, 1312.0, 36.2215
16.824984690, 96.390, 1340.0, 36.6060
16.877505820, 96.390, 1380.0, 37.1484
16.930026951, 96.390, 1359.0, 36.8646
16.982548082, 96.390, 1276.0, 35.7211
17.035069212, 96.390, 1321.0, 36.3456
17.087590343, 96.390, 1285.0, 35.8469
17.140111474, 96.390, 1307.0, 36.1525
17.192632605, 96.390, 1319.0, 36.3180
17.245153735, 96.390, 1280.0, 35.7771
17.297674866, 96.390, 1285.0, 35.8469
17.350195997, 96.390, 1320.0, 36.3318
17.402717127, 96.390, 1350.0, 36.7423
17.455238258, 96.390, 1308.0, 36.1663
17.507759389, 96.390, 1301.0, 36.0694
17.560280520, 96.390, 1366.0, 36.9594
17.612801650, 96.390, 1440.0, 37.9473
17.665322781, 96.390, 1456.0, 38.1576
17.717843912, 96.390, 1602.0, 40.0250
17.770365042, 96.390, 1438.0, 37.9210
17.822886173, 96.390, 1352.0, 36.7696
17.875407304, 96.390, 1392.0, 37.3095
17.927928434, 96.390, 1387.0, 37.2424
17.980449565, 96.390, 1464.0, 38.2623
18.032970696, 96.390, 1548.0, 39.3446
18.085491827, 96.390, 1582.0, 39.7744
18.138012957, 96.390, 1804.0, 42.4735
18.190534088, 96.390, 2075.0, 45.5522
18.243055219, 96.390, 2477.0, 49.7695
18.295576349, 96.390, 3336.0, 57.7581
18.348097480, 96.390, 4225.0, 65.0000
18.400618611, 96.390, 5704.0, 75.5248
18.453139742, 96.390, 7093.0, 84.2200
18.505660872, 96.390, 7916.0, 88.9719
18.558182003, 96.390, 7436.0, 86.2322
18.610703134, 96.390, 6763.0, 82.2375
18.663224264, 96.390, 6119.0, 78.2240
18.715745395, 96.390, 6142.0, 78.3709
18.768266526, 96.390, 6723.0, 81.9939
18.820787657, 96.390, 6540.0, 80.8703
18.873308787, 96.390, 4293.0, 65.5210
18.925829918, 96.390, 2371.0, 48.6929
18.978351049, 96.390, 1880.0, 43.3590
19.030872179, 96.390, 1673.0, 40.9023
19.083393310, 96.390, 1601.0, 40.0125
19.135914441, 96.390, 1444.0, 38.0000
19.188435572, 96.390, 1430.0, 37.8153
19.240956702, 96.390, 1421.0, 37.6962
19.293477833, 96.390, 1487.0, 38.5616
19.345998964, 96.390, 1631.0, 40.3856
19.398520094, 96.390, 2007.0, 44.7996
19.451041225, 96.390, 2490.0, 49.8999
19.503562356, 96.390, 2346.0, 48.4355
19.556083486, 96.390, 1648.0, 40.5956
19.608604617, 96.390, 1498.0, 38.7040
19.661125748, 96.390, 1626.0, 40.3237
19.713646879, 96.390, 1989.0, 44.5982
19.766168009, 96.390, 1898.0, 43.5660
19.818689140, 96.390, 1776.0, 42.1426
19.871210271, 96.390, 2162.0, 46.4973
19.923731401, 96.390, 2983.0, 54.6168
19.976252532, 96.390, 5077.0, 71.2531
20.028773663, 96.390, 6107.0, 78.1473
20.081294794, 96.390, 3698.0, 60.8112
20.133815924, 96.390, 2506.0, 50.0600
20.186337055, 96.390, 3134.0, 55.9821
20.238858186, 96.390, 4485.0, 66.9701
20.291379316, 96.390, 6988.0, 83.5943
20.343900447, 96.390, 8440.0, 91.8695
20.396421578, 96.390, 7711.0, 87.8123
20.448942709, 96.390, 6787.0, 82.3833
20.501463839, 96.390, 5908.0, 76.8635
20.553984970, 96.390, 4622.0, 67.9853
20.606506101, 96.390, 4330.0, 65.8027
20.659027231, 96.390, 5977.0, 77.3111
20.711548362, 96.390, 10833.0, 104.0817
20.764069493, 96.390, 14395.0, 119.9792
20.816590623, 96.390, 7383.0, 85.9244
20.869111754, 96.390, 2458.0, 49.5782
20.921632885, 96.390, 1850.0, 43.0116
20.974154016, 96.390, 1586.0, 39.8246
21.026675146, 96.390, 1464.0, 38.2623
21.079196277, 96.390, 1325.0, 36.4005
21.131717408, 96.390, 1365.0, 36.9459
21.184238538, 96.390, 1277.0, 35.7351
21.236759669, 96.390, 1362.0, 36.9053
21.289280800, 96.390, 1395.0, 37.3497
21.341801931, 96.390, 1466.0, 38.2884
21.394323061, 96.390, 1670.0, 40.8656
21.446844192, 96.390, 1688.0, 41.0853
21.499365323, 96.390, 1581.0, 39.7618
21.551886453, 96.390, 1759.0, 41.9404
21.604407584, 96.390, 2344.0, 48.4149
21.656928715, 96.390, 3502.0, 59.1777
21.709449846, 96.390, 5281.0, 72.6705
21.761970976, 96.390, 4516.0, 67.2012
21.814492107, 96.390, 2612.0, 51.1077
21.867013238, 96.390, 1670.0, 40.8656
21.919534368, 96.390, 1414.0, 37.6032
21.972055499, 96.390, 1374.0, 37.0675
22.024576630, 96.390, 1346.0, 36.6879
22.077097761, 96.390, 1346.0, 36.6879
22.129618891, 96.390, 1287.0, 35.8748
22.182140022, 96.390, 1302.0, 36.0832
22.234661153, 96.390, 1308.0, 36.1663
22.287182283, 96.390, 1292.0, 35.9444
22.339703414, 96.390, 1238.0, 35.1852
22.392224545, 96.390, 1273.0, 35.6791
22.444745675, 96.390, 1239.0, 35.1994
22.497266806, 96.390, 1276.0, 35.7211
22.549787937, 96.390, 1305.0, 36.1248
22.602309068, 96.390, 1386.0, 37.2290
22.654830198, 96.390, 1337.0, 36.5650
22.707351329, 96.390, 1442.0, 37.9737
22.759872460, 96.390, 1447.0, 38.0395
22.812393590, 96.390, 1545.0, 39.3065
22.864914721, 96.390, 1670.0, 40.8656
22.917435852, 96.390, 1872.0, 43.2666
22.969956983, 96.390, 1725.0, 41.5331
23.022478113, 96.390, 1641.0, 40.5093
23.074999244, 96.390, 1642.0, 40.5216
23.127520375, 96.390, 1666.0, 40.8167
23.180041505, 96.390, 1638.0, 40.4722
23.232562636, 96.390, 1778.0, 42.1663
23.285083767, 96.390, 1696.0, 41.1825
23.337604898, 96.390, 1830.0, 42.7785
23.390126028, 96.390, 1875.0, 43.3013
23.442647159, 96.390, 1920.0, 43.8178
23.495168290, 96.390, 2027.0, 45.0222
23.547689420, 96.390, 2074.0, 45.5412
23.600210551, 96.390, 2031.0, 45.0666
23.652731682, 96.390, 2084.0, 45.6508
23.705252813, 96.390, 2140.0, 46.2601
23.757773943, 96.390, 2063.0, 45.4203
23.810295074, 96.390, 2252.0, 47.4552
23.862816205, 96.390, 2551.0, 50.5074
23.915337335, 96.390, 3363.0, 57.9914
23.967858466, 96.390, 4777.0, 69.1158
24.020379597, 96.390, 7506.0, 86.6372
24.072900727, 96.390, 7531.0, 86.7813
24.125421858, 96.390, 4852.0, 69.6563
24.177942989, 96.390, 3297.0, 57.4195
24.230464120, 96.390, 2972.0, 54.5161
24.282985250, 96.390, 2255.0, 47.4868
24.335506381, 96.390, 1649.0, 40.6079
24.388027512, 96.390, 1427.0, 37.7757
24.440548642, 96.390, 1370.0, 37.0135
24.493069773, 96.390, 1274.0, 35.6931
24.545590904, 96.390, 1255.0, 35.4260
24.598112035, 96.390, 1195.0, 34.5688
24.650633165, 96.390, 1137.0, 33.7194
24.703154296, 96.390, 1135.0, 33.6898
24.755675427, 96.390, 1096.0, 33.1059
24.808196557, 96.390, 1091.0, 33.0303
24.860717688, 96.390, 1073.0, 32.7567
24.913238819, 96.390, 1090.0, 33.0151
24.965759950, 96.390, 1100.0, 33.1662
25.018281080, 96.390, 1086.0, 32.9545
25.070802211, 96.390, 1111.0, 33.3317
25.123323342, 96.390, 1079.0, 32.8481
25.175844472, 96.390, 1074.0, 32.7719
25.228365603, 96.390, 1088.0, 32.9848
25.280886734, 96.390, 1156.0, 34.0000
25.333407864, 96.390, 1338.0, 36.5787
25.385928995, 96.390, 1743.0, 41.7493
25.438450126, 96.390, 2707.0, 52.0288
25.490971257, 96.390, 3871.0, 62.2174
25.543492387, 96.390, 2556.0, 50.5569
25.596013518, 96.390, 1553.0, 39.4081
25.648534649, 96.390, 1088.0, 32.9848
25.701055779, 96.390, 1069.0, 32.6956
25.753576910, 96.390, 1110.0, 33.3167
25.806098041, 96.390, 1066.0, 32.6497
25.858619172, 96.390, 1096.0, 33.1059
25.911140302, 96.390, 1171.0, 34.2199
25.963661433, 96.390, 1315.0, 36.2629
26.016182564, 96.390, 1451.0, 38.0920
26.068703694, 96.390, 1836.0, 42.8486
26.121224825, 96.390, 2344.0, 48.4149
26.173745956, 96.390, 3020.0, 54.9545
26.226267087, 96.390, 2412.0, 49.1121
26.278788217, 96.390, 1733.0, 41.6293
26.331309348, 96.390, 1282.0, 35.8050
26.383830479, 96.390, 1161.0, 34.0735
26.436351609, 96.390, 1246.0, 35.2987
26.488872740, 96.390, 1246.0, 35.2987
26.541393871, 96.390, 1193.0, 34.5398
26.593915002, 96.390, 1274.0, 35.6931
26.646436132, 96.390, 1176.0, 34.2929
26.698957263, 96.390, 1295.0, 35.9861
26.751478394, 96.390, 1315.0, 36.2629
26.803999524, 96.390, 1300.0, 36.0555
26.856520655, 96.390, 1502.0, 38.7556
26.909041786, 96.390, 1671.0, 40.8779
26.961562916, 96.390, 1849.0, 43.0000
27.014084047, 96.390, 2403.0, 49.0204
27.066605178, 96.390, 3338.0, 57.7754
27.119126309, 96.390, 5564.0, 74.5922
27.171647439, 96.390, 8850.0, 94.0744
27.224168570, 96.390, 8805.0, 93.8350
27.276689701, 96.390, 5578.0, 74.6860
27.329210831, 96.390, 3014.0, 54.8999
27.381731962, 96.390, 1929.0, 43.9204
27.434253093, 96.390, 1777.0, 42.1545
27.486774224, 96.390, 1690.0, 41.1096
27.539295354, 96.390, 1639.0, 40.4846
27.591816485, 96.390, 1745.0, 41.7732
27.644337616, 96.390, 1915.0, 43.7607
27.696858746, 96.390, 1924.0, 43.8634
27.749379877, 96.390, 2218.0, 47.0956
27.801901008, 96.390, 2354.0, 48.5180
27.854422139, 96.390, 2379.0, 48.7750
27.906943269, 96.390, 2326.0, 48.2286
27.959464400, 96.390, 2018.0, 44.9222
28.011985531, 96.390, 1840.0, 42.8952
28.064506661, 96.390, 1808.0, 42.5206
28.117027792, 96.390, 1604.0, 40.0500
28.169548923, 96.390, 1555.0, 39.4335
28.222070054, 96.390, 1414.0, 37.6032
28.274591184, 96.390, 1307.0, 36.1525
28.327112315, 96.390, 1233.0, 35.1141
28.379633446, 96.390, 1156.0, 34.0000
28.432154576, 96.390, 1230.0, 35.0714
28.484675707, 96.390, 1094.0, 33.0757
28.537196838, 96.390, 1166.0, 34.1467
28.589717968, 96.390, 1154.0, 33.9706
28.642239099, 96.390, 1213.0, 34.8281
28.694760230, 96.390, 1353.0, 36.7831
28.747281361, 96.390, 1681.0, 41.0000
28.799802491, 96.390, 2013.0, 44.8665
28.852323622, 96.390, 1650.0, 40.6202
28.904844753, 96.390, 1496.0, 38.6782
28.957365883, 96.390, 1234.0, 35.1283
29.009887014, 96.390, 1298.0, 36.0278
29.062408145, 96.390, 1664.0, 40.7922
29.114929276, 96.390, 2209.0, 47.0000
29.167450406, 96.390, 2489.0, 49.8899
29.219971537, 96.390, 1920.0, 43.8178
29.272492668, 96.390, 1337.0, 36.5650
29.325013798, 96.390, 1160.0, 34.0588
29.377534929, 96.390, 1125.0, 33.5410
29.430056060, 96.390, 1220.0, 34.9285
29.482577191, 96.390, 1140.0, 33.7639
29.535098321, 96.390, 1111.0, 33.3317
29.587619452, 96.390, 1196.0, 34.5832
29.640140583, 96.390, 1277.0, 35.7351
29.692661713, 96.390, 1347.0, 36.7015
29.745182844, 96.390, 1486.0, 38.5487
29.797703975, 96.390, 1763.0, 41.9881
29.850225105, 96.390, 2416.0, 49.1528
29.902746236, 96.390, 3752.0, 61.2536
29.955267367, 96.390, 6276.0, 79.2212
30.007788498, 96.390, 8315.0, 91.1866
30.060309628, 96.390, 6040.0, 77.7174
30.112830759, 96.390, 3879.0, 62.2816
30.165351890, 96.390, 2133.0, 46.1844
30.217873020, 96.390, 1533.0, 39.1535
30.270394151, 96.390, 1372.0, 37.0405
30.322915282, 96.390, 1270.0, 35.6371
30.375436413, 96.390, 1224.0, 34.9857
30.427957543, 96.390, 1151.0, 33.9264
30.480478674, 96.390, 1120.0, 33.4664
30.532999805, 96.390, 1175.0, 34.2783
30.585520935, 96.390, 1300.0, 36.0555
30.638042066, 96.390, 1686.0, 41.0609
30.690563197, 96.390, 2204.0, 46.9468
30.743084328, 96.390, 2048.0, 45.2548
30.795605458, 96.390, 2156.0, 46.4327
30.848126589, 96.390, 2647.0, 51.4490
30.900647720, 96.390, 2832.0, 53.2165
30.953168850, 96.390, 2306.0, 48.0208
31.005689981, 96.390, 1666.0, 40.8167
31.058211112, 96.390, 1441.0, 37.9605
31.110732243, 96.390, 1471.0, 38.3536
31.163253373, 96.390, 2009.0, 44.8219
31.215774504, 96.390, 3391.0, 58.2323
31.268295635, 96.390, 3916.0, 62.5780
31.320816765, 96.390, 2911.0, 53.9537
31.373337896, 96.390, 1915.0, 43.7607
31.425859027, 96.390, 1437.0, 37.9078
31.478380157, 96.390, 1500.0, 38.7298
31.530901288, 96.390, 1795.0, 42.3674
31.583422419, 96.390, 1834.0, 42.8252
31.635943550, 96.390, 1996.0, 44.6766
31.688464680, 96.390, 1984.0, 44.5421
31.740985811, 96.390, 1610.0, 40.1248
31.793506942, 96.390, 1527.0, 39.0768
31.846028072, 96.390, 1366.0, 36.9594
31.898549203, 96.390, 1756.0, 41.9047
31.951070334, 96.390, 2299.0, 47.9479
32.003591465, 96.390, 4258.0, 65.2534
32.056112595, 96.390, 8516.0, 92.2822
32.108633726, 96.390, 12739.0, 112.8672
32.161154857, 96.390, 8465.0, 92.0054
32.213675987, 96.390, 5405.0, 73.5187
32.266197118, 96.390, 2172.0, 46.6047
32.318718249, 96.390, 1564.0, 39.5474
32.371239380, 96.390, 1446.0, 38.0263
32.423760510, 96.390, 1407.0, 37.5100
32.476281641, 96.390, 1532.0, 39.1408
32.528802772, 96.390, 1797.0, 42.3910
32.581323902, 96.390, 2348.0, 48.4562
32.633845033, 96.390, 2279.0, 47.7389
32.686366164, 96.390, 1924.0, 43.8634
32.738887295, 96.390, 1613.0, 40.1622
32.791408425, 96.390, 1276.0, 35.7211
32.843929556, 96.390, 1188.0, 34.4674
32.896450687, 96.390, 1106.0, 33.2566
32.948971817, 96.390, 1143.0, 33.8083
33.001492948, 96.390, 1165.0, 34.1321
33.054014079, 96.390, 1166.0, 34.1467
33.106535209, 96.390, 1259.0, 35.4824
33.159056340, 96.390, 1293.0, 35.9583
33.211577471, 96.390, 1358.0, 36.8511
33.264098602, 96.390, 1323.0, 36.3731
33.316619732, 96.390, 1271.0, 35.6511
33.369140863, 96.390, 1351.0, 36.7560
33.421661994, 96.390, 1496.0, 38.6782
33.474183124, 96.390, 1572.0, 39.6485
33.526704255, 96.390, 1290.0, 35.9166
33.579225386, 96.390, 1236.0, 35.1568
33.631746517, 96.390, 1163.0, 34.1028
33.684267647, 96.390, 1147.0, 33.8674
33.736788778, 96.390, 1151.0, 33.9264
33.789309909, 96.390, 1282.0, 35.8050
33.841831039, 96.390, 1459.0, 38.1969
33.894352170, 96.390, 2053.0, 45.3100
33.946873301, 96.390, 3396.0, 58.2752
33.999394432, 96.390, 5399.0, 73.4779
34.051915562, 96.390, 3953.0, 62.8729
34.104436693, 96.390, 3876.0, 62.2575
34.156957824, 96.390, 3462.0, 58.8388
34.209478954, 96.390, 5079.0, 71.2671
34.262000085, 96.390, 5223.0, 72.2703
34.314521216, 96.390, 4241.0, 65.1230
34.367042346, 96.390, 3085.0, 55.5428
34.419563477, 96.390, 2495.0, 49.9500
34.472084608, 96.390, 2490.0, 49.8999
34.524605739, 96.390, 2705.0, 52.0096
34.577126869, 96.390, 2410.0, 49.0918
34.629648000, 96.390, 2254.0, 47.4763
34.682169131, 96.390, 2058.0, 45.3652
34.734690261, 96.390, 2058.0, 45.3652
34.787211392, 96.390, 2207.0, 46.9787
34.839732523, 96.390, 2572.0, 50.7149
34.892253654, 96.390, 3534.0, 59.4475
34.944774784, 96.390, 5030.0, 70.9225
34.997295915, 96.390, 5117.0, 71.5332
35.049817046, 96.390, 3728.0, 61.0574
35.102338176, 96.390, 2743.0, 52.3737
35.154859307, 96.390, 1924.0, 43.8634
35.207380438, 96.390, 1602.0, 40.0250
35.259901569, 96.390, 1557.0, 39.4588
35.312422699, 96.390, 1563.0, 39.5348
35.364943830, 96.390, 1488.0, 38.5746
35.417464961, 96.390, 1527.0, 39.0768
35.469986091, 96.390, 1484.0, 38.5227
35.522507222, 96.390, 1462.0, 38.2361
35.575028353, 96.390, 1432.0, 37.8418
35.627549484, 96.390, 1709.0, 41.3401
35.680070614, 96.390, 1867.0, 43.2088
35.732591745, 96.390, 1845.0, 42.9535
35.785112876, 96.390, 2069.0, 45.4863
35.837634006, 96.390, 1926.0, 43.8862
35.890155137, 96.390, 1938.0, 44.0227
35.942676268, 96.390, 1605.0, 40.0625
35.995197398, 96.390, 1407.0, 37.5100
36.047718529, 96.390, 1355.0, 36.8103
36.100239660, 96.390, 1352.0, 36.7696
36.152760791, 96.390, 1338.0, 36.5787
36.205281921, 96.390, 1360.0, 36.8782
36.257803052, 96.390, 1334.0, 36.5240
36.310324183, 96.390, 1376.0, 37.0945
36.362845313, 96.390, 1392.0, 37.3095
36.415366444, 96.390, 1454.0, 38.1314
36.467887575, 96.390, 1491.0, 38.6135
36.520408706, 96.390, 1659.0, 40.7308
36.572929836, 96.390, 1718.0, 41.4488
36.625450967, 96.390, 1687.0, 41.0731
36.677972098, 96.390, 1476.0, 38.4187
36.730493228, 96.390, 1316.0, 36.2767
36.783014359, 96.390, 1204.0, 34.6987
36.835535490, 96.390, 1184.0, 34.4093
36.888056621, 96.390, 1176.0, 34.2929
36.940577751, 96.390, 1150.0, 33.9116
36.993098882, 96.390, 1147.0, 33.8674
37.045620013, 96.390, 1175.0, 34.2783
37.098141143, 96.390, 1183.0, 34.3948
37.150662274, 96.390, 1142.0, 33.7935
37.203183405, 96.390, 1245.0, 35.2846
37.255704535, 96.390, 1194.0, 34.5543
37.308225666, 96.390, 1341.0, 36.6197
37.360746797, 96.390, 1388.0, 37.2559
37.413267928, 96.390, 1332.0, 36.4966
37.465789058, 96.390, 1420.0, 37.6829
37.518310189, 96.390, 1490.0, 38.6005
37.570831320, 96.390, 1538.0, 39.2173
37.623352450, 96.390, 1717.0, 41.4367
37.675873581, 96.390, 2064.0, 45.4313
37.728394712, 96.390, 2427.0, 49.2646
37.780915843, 96.390, 2996.0, 54.7357
37.833436973, 96.390, 2288.0, 47.8330
37.885958104, 96.390, 2188.0, 46.7761
37.938479235, 96.390, 1814.0, 42.5911
37.991000365, 96.390, 1744.0, 41.7612
38.043521496, 96.390, 1869.0, 43.2319
38.096042627, 96.390, 1895.0, 43.5316
38.148563758, 96.390, 1920.0, 43.8178
38.201084888, 96.390, 2046.0, 45.2327
38.253606019, 96.390, 1919.0, 43.8064
38.306127150, 96.390, 1696.0, 41.1825
38.358648280, 96.390, 1668.0, 40.8412
38.411169411, 96.390, 1433.0, 37.8550
38.463690542, 96.390, 1522.0, 39.0128
38.516211673, 96.390, 1590.0, 39.8748
38.568732803, 96.390, 1551.0, 39.3827
38.621253934, 96.390, 1647.0, 40.5832
38.673775065, 96.390, 1728.0, 41.5692
38.726296195, 96.390, 1907.0, 43.6692
38.778817326, 96.390, 2365.0, 48.6313
38.831338457, 96.390, 2549.0, 50.4876
38.883859587, 96.390, 2021.0, 44.9555
38.936380718, 96.390, 1865.0, 43.1856
38.988901849, 96.390, 1563.0, 39.5348
39.041422980, 96.390, 1406.0, 37.4967
39.093944110, 96.390, 1372.0, 37.0405
39.146465241, 96.390, 1472.0, 38.3667
39.198986372, 96.390, 1421.0, 37.6962
39.251507502, 96.390, 1537.0, 39.2046
39.304028633, 96.390, 1705.0, 41.2916
39.356549764, 96.390, 1983.0, 44.5309
39.409070895, 96.390, 2605.0, 51.0392
39.461592025, 96.390, 3455.0, 58.7792
39.514113156, 96.390, 2981.0, 54.5985
39.566634287, 96.390, 2644.0, 51.4198
39.619155417, 96.390, 2016.0, 44.8999
39.671676548, 96.390, 1663.0, 40.7799
39.724197679, 96.390, 1601.0, 40.0125
39.776718810, 96.390, 1526.0, 39.0640
39.829239940, 96.390, 1577.0, 39.7115
39.881761071, 96.390, 1551.0, 39.3827
39.934282202, 96.390, 1627.0, 40.3361
39.986803332, 96.390, 1701.0, 41.2432
40.039324463, 96.390, 1889.0, 43.4626
40.091845594, 96.390, 2106.0, 45.8912
40.144366725, 96.390, 2421.0, 49.2037
40.196887855, 96.390, 2504.0, 50.0400
40.249408986, 96.390, 2456.0, 49.5580
40.301930117, 96.390, 2498.0, 49.9800
40.354451247, 96.390, 2700.0, 51.9615
40.406972378, 96.390, 2889.0, 53.7494
40.459493509, 96.390, 3301.0, 57.4543
40.512014639, 96.390, 3767.0, 61.3759
40.564535770, 96.390, 4305.0, 65.6125
40.617056901, 96.390, 4712.0, 68.6440
40.669578032, 96.390, 4273.0, 65.3682
40.722099162, 96.390, 3756.0, 61.2862
40.774620293, 96.390, 2773.0, 52.6593
40.827141424, 96.390, 2183.0, 46.7226
40.879662554, 96.390, 1783.0, 42.2256
40.932183685, 96.390, 1627.0, 40.3361
40.984704816, 96.390, 1490.0, 38.6005
41.037225947, 96.390, 1563.0, 39.5348
41.089747077, 96.390, 1425.0, 37.7492
41.142268208, 96.390, 1426.0, 37.7624
41.194789339, 96.390, 1438.0, 37.9210
41.247310469, 96.390, 1481.0, 38.4838
41.299831600, 96.390, 1699.0, 41.2189
41.352352731, 96.390, 2335.0, 48.3218
41.404873862, 96.390, 3168.0, 56.2850
41.457394992, 96.390, 3058.0, 55.2992
41.509916123, 96.390, 2693.0, 51.8941
41.562437254, 96.390, 2646.0, 51.4393
41.614958384, 96.390, 2026.0, 45.0111
41.667479515, 96.390, 1866.0, 43.1972
41.720000646, 96.390, 1556.0, 39.4462
41.772521776, 96.390, 1372.0, 37.0405
41.825042907, 96.390, 1339.0, 36.5923
41.877564038, 96.390, 1339.0, 36.5923
41.930085169, 96.390, 1260.0, 35.4965
41.982606299, 96.390, 1262.0, 35.5246
42.035127430, 96.390, 1337.0, 36.5650
42.087648561, 96.390, 1369.0, 37.0000
42.140169691, 96.390, 1668.0, 40.8412
42.192690822, 96.390, 1989.0, 44.5982
42.245211953, 96.390, 2035.0, 45.1110
42.297733084, 96.390, 1795.0, 42.3674
42.350254214, 96.390, 1493.0, 38.6394
42.402775345, 96.390, 1361.0, 36.8917
42.455296476, 96.390, 1278.0, 35.7491
42.507817606, 96.390, 1351.0, 36.7560
42.560338737, 96.390, 1629.0, 40.3609
42.612859868, 96.390, 1726.0, 41.5452
42.665380999, 96.390, 1518.0, 38.9615
42.717902129, 96.390, 1334.0, 36.5240
42.770423260, 96.390, 1205.0, 34.7131
42.822944391, 96.390, 1173.0, 34.2491
42.875465521, 96.390, 1242.0, 35.2420
42.927986652, 96.390, 1346.0, 36.6879
42.980507783, 96.390, 1186.0, 34.4384
43.033028914, 96.390, 1186.0, 34.4384
43.085550044, 96.390, 1107.0, 33.2716
43.138071175, 96.390, 1109.0, 33.3017
43.190592306, 96.390, 1071.0, 32.7261
43.243113436, 96.390, 1000.0, 31.6228
43.295634567, 96.390, 1069.0, 32.6956
43.348155698, 96.390, 1111.0, 33.3317
43.400676828, 96.390, 1098.0, 33.1361
43.453197959, 96.390, 1122.0, 33.4963
43.505719090, 96.390, 1272.0, 35.6651
43.558240221, 96.390, 1428.0, 37.7889
43.610761351, 96.390, 1500.0, 38.7298
43.663282482, 96.390, 1581.0, 39.7618
43.715803613, 96.390, 2010.0, 44.8330
43.768324743, 96.390, 2650.0, 51.4782
43.820845874, 96.390, 2840.0, 53.2917
43.873367005, 96.390, 2174.0, 46.6262
43.925888136, 96.390, 2250.0, 47.4342
43.978409266, 96.390, 1654.0, 40.6694
44.030930397, 96.390, 1506.0, 38.8072
44.083451528, 96.390, 1469.0, 38.3275
44.135972658, 96.390, 1516.0, 38.9358
44.188493789, 96.390, 1893.0, 43.5086
44.241014920, 96.390, 1911.0, 43.7150
44.293536051, 96.390, 1836.0, 42.8486
44.346057181, 96.390, 2026.0, 45.0111
44.398578312, 96.390, 2181.0, 46.7012
44.451099443, 96.390, 2199.0, 46.8935
44.503620573, 96.390, 1729.0, 41.5812
44.556141704, 96.390, 1552.0, 39.3954
44.608662835, 96.390, 1222.0, 34.9571
44.661183966, 96.390, 1127.0, 33.5708
44.713705096, 96.390, 1065.0, 32.6343
44.766226227, 96.390, 1103.0, 33.2114
44.818747358, 96.390, 1234.0, 35.1283
44.871268488, 96.390, 1343.0, 36.6470
44.923789619, 96.390, 1453.0, 38.1182
44.976310750, 96.390, 1275.0, 35.7071
45.028831880, 96.390, 1381.0, 37.1618
45.081353011, 96.390, 1494.0, 38.6523
45.133874142, 96.390, 1927.0, 43.8976
45.186395273, 96.390, 2108.0, 45.9130
45.238916403, 96.390, 1638.0, 40.4722
45.291437534, 96.390, 1998.0, 44.6990
45.343958665, 96.390, 2018.0, 44.9222
45.396479795, 96.390, 2058.0, 45.3652
45.449000926, 96.390, 2024.0, 44.9889
45.501522057, 96.390, 2397.0, 48.9592
45.554043188, 96.390, 2032.0, 45.0777
45.606564318, 96.390, 1761.0, 41.9643
45.659085449, 96.390, 1714.0, 41.4005
45.711606580, 96.390, 1445.0, 38.0132
45.764127710, 96.390, 1281.0, 35.7911
45.816648841, 96.390, 1328.0, 36.4417
45.869169972, 96.390, 1446.0, 38.0263
45.921691103, 96.390, 1342.0, 36.6333
45.974212233, 96.390, 1291.0, 35.9305
46.026733364, 96.390, 1326.0, 36.4143
46.079254495, 96.390, 1287.0, 35.8748
46.131775625, 96.390, 1276.0, 35.7211
46.184296756, 96.390, 1433.0, 37.8550
46.236817887, 96.390, 1514.0, 38.9102
46.289339017, 96.390, 1790.0, 42.3084
46.341860148, 96.390, 1621.0, 40.2616
46.394381279, 96.390, 1510.0, 38.8587
46.446902410, 96.390, 1575.0, 39.6863
46.499423540, 96.390, 1254.0, 35.4119
46.551944671, 96.390, 1184.0, 34.4093
46.604465802, 96.390, 1173.0, 34.2491
46.656986932, 96.390, 1151.0, 33.9264
46.709508063, 96.390, 1121.0, 33.4813
46.762029194, 96.390, 1143.0, 33.8083
46.814550325, 96.390, 1168.0, 34.1760
46.867071455, 96.390, 1168.0, 34.1760
46.919592586, 96.390, 1250.0, 35.3553
46.972113717, 96.390, 1506.0, 38.8072
47.024634847, 96.390, 1742.0, 41.7373
47.077155978, 96.390, 1536.0, 39.1918
47.129677109, 96.390, 1475.0, 38.4057
47.182198240, 96.390, 1501.0, 38.7427
47.234719370, 96.390, 1313.0, 36.2353
47.287240501, 96.390, 1500.0, 38.7298
47.339761632, 96.390, 1830.0, 42.7785
47.392282762, 96.390, 1784.0, 42.2374
47.444803893, 96.390, 1615.0, 40.1871
47.497325024, 96.390, 1555.0, 39.4335
47.549846155, 96.390, 1381.0, 37.1618
47.602367285, 96.390, 1268.0, 35.6090
47.654888416, 96.390, 1169.0, 34.1906
47.707409547, 96.390, 1118.0, 33.4365
47.759930677, 96.390, 1015.0, 31.8591
47.812451808, 96.390, 1045.0, 32.3265
47.864972939, 96.390, 1125.0, 33.5410
47.917494069, 96.390, 1291.0, 35.9305
47.970015200, 96.390, 1373.0, 37.0540
48.022536331, 96.390, 1373.0, 37.0540
48.075057462, 96.390, 1436.0, 37.8946
48.127578592, 96.390, 1547.0, 39.3319
48.180099723, 96.390, 1645.0, 40.5586
48.232620854, 96.390, 1287.0, 35.8748
48.285141984, 96.390, 1391.0, 37.2961
48.337663115, 96.390, 1207.0, 34.7419
48.390184246, 96.390, 1042.0, 32.2800
48.442705377, 96.390, 1215.0, 34.8569
48.495226507, 96.390, 1404.0, 37.4700
48.547747638, 96.390, 1674.0, 40.9145
48.600268769, 96.390, 1381.0, 37.1618
48.652789899, 96.390, 1316.0, 36.2767
48.705311030, 96.390, 1233.0, 35.1141
48.757832161, 96.390, 948.0, 30.7896
48.810353292, 96.390, 861.0, 29.3428
48.862874422, 96.390, 909.0, 30.1496
48.915395553, 96.390, 938.0, 30.6268
48.967916684, 96.390, 886.0, 29.7658
49.020437814, 96.390, 902.0, 30.0333
49.072958945, 96.390, 944.0, 30.7246
49.125480076, 96.390, 965.0, 31.0644
49.178001207, 96.390, 1046.0, 32.3419
49.230522337, 96.390, 1027.0, 32.0468
49.283043468, 96.390, 997.0, 31.5753
49.335564599, 96.390, 989.0, 31.4484
49.388085729, 96.390, 924.0, 30.3974
49.440606860, 96.390, 933.0, 30.5450
49.493127991, 96.390, 984.0, 31.3688
49.545649121, 96.390, 973.0, 31.1929
49.598170252, 96.390, 1051.0, 32.4191
49.650691383, 96.390, 948.0, 30.7896
49.703212514, 96.390, 1075.0, 32.7872
49.755733644, 96.390, 1204.0, 34.6987
49.808254775, 96.390, 1060.0, 32.5576
49.860775906, 96.390, 1090.0, 33.0151
49.913297036, 96.390, 1020.0, 31.9374
49.965818167, 96.390, 944.0, 30.7246
50.018339298, 96.390, 890.0, 29.8329
50.070860429, 96.390, 914.0, 30.2324
50.123381559, 96.390, 947.0, 30.7734
50.175902690, 96.390, 988.0, 31.4325
50.228423821, 96.390, 1397.0, 37.3765
50.280944951, 96.390, 1736.0, 41.6653
50.333466082, 96.390, 1438.0, 37.9210
50.385987213, 96.390, 1302.0, 36.0832
50.438508344, 96.390, 1291.0, 35.9305
50.491029474, 96.390, 1001.0, 31.6386
50.543550605, 96.390, 870.0, 29.4958
50.596071736, 96.390, 848.0, 29.1204
50.648592866, 96.390, 902.0, 30.0333
50.701113997, 96.390, 864.0, 29.3939
50.753635128, 96.390, 829.0, 28.7924
50.806156258, 96.390, 872.0, 29.5296
50.858677389, 96.390, 814.0, 28.5307
50.911198520, 96.390, 889.0, 29.8161
50.963719651, 96.390, 858.0, 29.2916
51.016240781, 96.390, 867.0, 29.4449
51.068761912, 96.390, 874.0, 29.5635
51.121283043, 96.390, 924.0, 30.3974
51.173804173, 96.390, 1061.0, 32.5730
51.226325304, 96.390, 1252.0, 35.3836
51.278846435, 96.390, 1277.0, 35.7351
51.331367566, 96.390, 1110.0, 33.3167
51.383888696, 96.390, 1110.0, 33.3167
51.436409827, 96.390, 1095.0, 33.0908
51.488930958, 96.390, 920.0, 30.3315
51.541452088, 96.390, 931.0, 30.5123
51.593973219, 96.390, 956.0, 30.9192
51.646494350, 96.390, 946.0, 30.7571
51.699015481, 96.390, 905.0, 30.0832
51.751536611, 96.390, 945.0, 30.7409
51.804057742, 96.390, 1054.0, 32.4654
51.856578873, 96.390, 1142.0, 33.7935
51.909100003, 96.390, 1090.0, 33.0151
51.961621134, 96.390, 1188.0, 34.4674
52.014142265, 96.390, 1236.0, 35.1568
52.066663396, 96.390, 1310.0, 36.1939
52.119184526, 96.390, 1387.0, 37.2424
52.171705657, 96.390, 1669.0, 40.8534
52.224226788, 96.390, 2031.0, 45.0666
52.276747918, 96.390, 2080.0, 45.6070
52.329269049, 96.390, 2020.0, 44.9444
52.381790180, 96.390, 1858.0, 43.1045
52.434311310, 96.390, 1789.0, 42.2966
52.486832441, 96.390, 1613.0, 40.1622
52.539353572, 96.390, 1666.0, 40.8167
52.591874703, 96.390, 1994.0, 44.6542
52.644395833, 96.390, 2374.0, 48.7237
52.696916964, 96.390, 2351.0, 48.4871
52.749438095, 96.390, 2150.0, 46.3681
52.801959225, 96.390, 2118.0, 46.0217
52.854480356, 96.390, 1931.0, 43.9431
52.907001487, 96.390, 1808.0, 42.5206
52.959522618, 96.390, 1741.0, 41.7253
53.012043748, 96.390, 1939.0, 44.0341
53.064564879, 96.390, 1979.0, 44.4860
53.117086010, 96.390, 2065.0, 45.4423
53.169607140, 96.390, 2214.0, 47.0532
53.222128271, 96.390, 2202.0, 46.9255
53.274649402, 96.390, 2171.0, 46.5940
53.327170533, 96.390, 1892.0, 43.4971
53.379691663, 96.390, 1670.0, 40.8656
53.432212794, 96.390, 1511.0, 38.8716
53.484733925, 96.390, 1385.0, 37.2156
53.537255055, 96.390, 1225.0, 35.0000
53.589776186, 96.390, 1090.0, 33.0151
53.642297317, 96.390, 1029.0, 32.0780
53.694818448, 96.390, 972.0, 31.1769
53.747339578, 96.390, 908.0, 30.1330
53.799860709, 96.390, 904.0, 30.0666
53.852381840, 96.390, 885.0, 29.7489
53.904902970, 96.390, 928.0, 30.4631
53.957424101, 96.390, 860.0, 29.3258
54.009945232, 96.390, 911.0, 30.1828
54.062466362, 96.390, 967.0, 31.0966
54.114987493, 96.390, 1150.0, 33.9116
54.167508624, 96.390, 1379.0, 37.1349
54.220029755, 96.390, 1574.0, 39.6737
54.272550885, 96.390, 1590.0, 39.8748
54.325072016, 96.390, 1790.0, 42.3084
54.377593147, 96.390, 1847.0, 42.9767
54.430114277, 96.390, 1472.0, 38.3667
54.482635408, 96.390, 1356.0, 36.8239
54.535156539, 96.390, 1253.0, 35.3977
54.587677670, 96.390, 1075.0, 32.7872
54.640198800, 96.390, 862.0, 29.3598
54.692719931, 96.390, 803.0, 28.3373
54.745241062, 96.390, 857.0, 29.2746
54.797762192, 96.390, 855.0, 29.2404
54.850283323, 96.390, 872.0, 29.5296
54.902804454, 96.390, 850.0, 29.1548
54.955325585, 96.390, 823.0, 28.6880
55.007846715, 96.390, 776.0, 27.8568
55.060367846, 96.390, 793.0, 28.1603
55.112888977, 96.390, 724.0, 26.9072
55.165410107, 96.390, 709.0, 26.6271
55.217931238, 96.390, 687.0, 26.2107
55.270452369, 96.390, 705.0, 26.5518
55.322973499, 96.390, 726.0, 26.9444
55.375494630, 96.390, 785.0, 28.0179
55.428015761, 96.390, 778.0, 27.8927
55.480536892, 96.390, 760.0, 27.5681
55.533058022, 96.390, 843.0, 29.0345
55.585579153, 96.390, 970.0, 31.1448
55.638100284, 96.390, 1038.0, 32.2180
55.690621414, 96.390, 896.0, 29.9333
55.743142545, 96.390, 948.0, 30.7896
55.795663676, 96.390, 1049.0, 32.3883
55.848184807, 96.390, 924.0, 30.3974
55.900705937, 96.390, 860.0, 29.3258
55.953227068, 96.390, 894.0, 29.8998
56.005748199, 96.390, 879.0, 29.6479
56.058269329, 96.390, 831.0, 28.8271
56.110790460, 96.390, 919.0, 30.3150
56.163311591, 96.390, 834.0, 28.8791
56.215832722, 96.390, 766.0, 27.6767
56.268353852, 96.390, 739.0, 27.1846
56.320874983, 96.390, 737.0, 27.1477
56.373396114, 96.390, 771.0, 27.7669
56.425917244, 96.390, 854.0, 29.2233
56.478438375, 96.390, 901.0, 30.0167
56.530959506, 96.390, 1050.0, 32.4037
56.583480637, 96.390, 948.0, 30.7896
56.636001767, 96.390, 927.0, 30.4467
56.688522898, 96.390, 857.0, 29.2746
56.741044029, 96.390, 814.0, 28.5307
56.793565159, 96.390, 765.0, 27.6586
56.846086290, 96.390, 791.0, 28.1247
56.898607421, 96.390, 764.0, 27.6405
56.951128551, 96.390, 837.0, 28.9310
57.003649682, 96.390, 803.0, 28.3373
57.056170813, 96.390, 795.0, 28.1957
57.108691944, 96.390, 805.0, 28.3725
57.161213074, 96.390, 773.0, 27.8029
57.213734205, 96.390, 844.0, 29.0517
57.266255336, 96.390, 830.0, 28.8097
57.318776466, 96.390, 846.0, 29.0861
57.371297597, 96.390, 915.0, 30.2490
57.423818728, 96.390, 955.0, 30.9031
57.476339859, 96.390, 1034.0, 32.1559
57.528860989, 96.390, 1174.0, 34.2637
57.581382120, 96.390, 1285.0, 35.8469
57.633903251, 96.390, 1286.0, 35.8608
57.686424381, 96.390, 1188.0, 34.4674
57.738945512, 96.390, 1054.0, 32.4654
57.791466643, 96.390, 963.0, 31.0322
57.843987774, 96.390, 870.0, 29.4958
57.896508904, 96.390, 846.0, 29.0861
57.949030035, 96.390, 813.0, 28.5132
58.001551166, 96.390, 939.0, 30.6431
58.054072296, 96.390, 1199.0, 34.6266
58.106593427, 96.390, 1407.0, 37.5100
58.159114558, 96.390, 1131.0, 33.6303
58.211635689, 96.390, 1054.0, 32.4654
58.264156819, 96.390, 1043.0, 32.2955
58.316677950, 96.390, 916.0, 30.2655
58.369199081, 96.390, 751.0, 27.4044
58.421720211, 96.390, 781.0, 27.9464
58.474241342, 96.390, 812.0, 28.4956
58.526762473, 96.390, 862.0, 29.3598
58.579283603, 96.390, 1103.0, 33.2114
58.631804734, 96.390, 1389.0, 37.2693
58.684325865, 96.390, 1232.0, 35.0999
58.736846996, 96.390, 1149.0, 33.8969
58.789368126, 96.390, 1149.0, 33.8969
58.841889257, 96.390, 1058.0, 32.5269
58.894410388, 96.390, 904.0, 30.0666
58.946931518, 96.390, 871.0, 29.5127
58.999452649, 96.390, 830.0, 28.8097
59.051973780, 96.390, 770.0, 27.7489
59.104494911, 96.390, 852.0, 29.1890
59.157016041, 96.390, 882.0, 29.6985
59.209537172, 96.390, 886.0, 29.7658
59.262058303, 96.390, 1018.0, 31.9061
59.314579433, 96.390, 1144.0, 33.8231
59.367100564, 96.390, 951.0, 30.8383
59.419621695, 96.390, 938.0, 30.6268
59.472142826, 96.390, 888.0, 29.7993
59.524663956, 96.390, 875.0, 29.5804
59.577185087, 96.390, 914.0, 30.2324
59.629706218, 96.390, 840.0, 28.9828
59.682227348, 96.390, 850.0, 29.1548
59.734748479, 96.390, 807.0, 28.4077
59.787269610, 96.390, 886.0, 29.7658
59.839790740, 96.390, 910.0, 30.1662
59.892311871, 96.390, 926.0, 30.4302
59.944833002, 96.390, 915.0, 30.2490
59.997354133, 96.390, 987.0, 31.4166
60.049875263, 96.390, 910.0, 30.1662
60.102396394, 96.390, 931.0, 30.5123
60.154917525, 96.390, 1023.0, 31.9844
60.207438655, 96.390, 1009.0, 31.7648
60.259959786, 96.390, 1026.0, 32.0312
60.312480917, 96.390, 1019.0, 31.9218
60.365002048, 96.390, 854.0, 29.2233
60.417523178, 96.390, 921.0, 30.3480
60.470044309, 96.390, 859.0, 29.3087
60.522565440, 96.390, 878.0, 29.6311
60.575086570, 96.390, 907.0, 30.1164
60.627607701, 96.390, 886.0, 29.7658
60.680128832, 96.390, 1069.0, 32.6956
60.732649963, 96.390, 1268.0, 35.6090
60.785171093, 96.390, 1356.0, 36.8239
60.837692224, 96.390, 1377.0, 37.1080
60.890213355, 96.390, 1477.0, 38.4318
60.942734485, 96.390, 1490.0, 38.6005
60.995255616, 96.390, 1274.0, 35.6931
61.047776747, 96.390, 1186.0, 34.4384
61.100297878, 96.390, 1044.0, 32.3110
61.152819008, 96.390, 969.0, 31.1288
61.205340139, 96.390, 971.0, 31.1609
61.257861270, 96.390, 969.0, 31.1288
61.310382400, 96.390, 916.0, 30.2655
61.362903531, 96.390, 907.0, 30.1164
61.415424662, 96.390, 923.0, 30.3809
61.467945792, 96.390, 1044.0, 32.3110
61.520466923, 96.390, 1145.0, 33.8378
61.572988054, 96.390, 998.0, 31.5911
61.625509185, 96.390, 899.0, 29.9833
61.678030315, 96.390, 901.0, 30.0167
61.730551446, 96.390, 950.0, 30.8221
61.783072577, 96.390, 903.0, 30.0500
61.835593707, 96.390, 904.0, 30.0666
61.888114838, 96.390, 875.0, 29.5804
61.940635969, 96.390, 976.0, 31.2410
61.993157100, 96.390, 1038.0, 32.2180
62.045678230, 96.390, 1010.0, 31.7805
62.098199361, 96.390, 1045.0, 32.3265
62.150720492, 96.390, 1160.0, 34.0588
62.203241622, 96.390, 1184.0, 34.4093
62.255762753, 96.390, 1226.0, 35.0143
62.308283884, 96.390, 1263.0, 35.5387
62.360805015, 96.390, 1127.0, 33.5708
62.413326145, 96.390, 1086.0, 32.9545
62.465847276, 96.390, 1036.0, 32.1870
62.518368407, 96.390, 983.0, 31.3528
62.570889537, 96.390, 914.0, 30.2324
62.623410668, 96.390, 975.0, 31.2250
62.675931799, 96.390, 1048.0, 32.3728
62.728452930, 96.390, 1283.0, 35.8190
62.780974060, 96.390, 1107.0, 33.2716
62.833495191, 96.390, 1101.0, 33.1813
62.886016322, 96.390, 1028.0, 32.0624
62.938537452, 96.390, 898.0, 29.9666
62.991058583, 96.390, 827.0, 28.7576
63.043579714, 96.390, 686.0, 26.1916
63.096100844, 96.390, 639.0, 25.2784
63.148621975, 96.390, 670.0, 25.8844
63.201143106, 96.390, 704.0, 26.5330
63.253664237, 96.390, 703.0, 26.5141
63.306185367, 96.390, 727.0, 26.9629
63.358706498, 96.390, 729.0, 27.0000
63.411227629, 96.390, 730.0, 27.0185
63.463748759, 96.390, 774.0, 27.8209
63.516269890, 96.390, 718.0, 26.7955
63.568791021, 96.390, 800.0, 28.2843
63.621312152, 96.390, 885.0, 29.7489
63.673833282, 96.390, 1029.0, 32.0780
63.726354413, 96.390, 1193.0, 34.5398
63.778875544, 96.390, 1422.0, 37.7094
63.831396674, 96.390, 1643.0, 40.5339
63.883917805, 96.390, 1545.0, 39.3065
63.936438936, 96.390, 1322.0, 36.3593
63.988960067, 96.390, 1327.0, 36.4280
64.041481197, 96.390, 1231.0, 35.0856
64.094002328, 96.390, 1073.0, 32.7567
64.146523459, 96.390, 1048.0, 32.3728
64.199044589, 96.390, 1056.0, 32.4962
64.251565720, 96.390, 1290.0, 35.9166
64.304086851, 96.390, 1258.0, 35.4683
64.356607981, 96.390, 1152.0, 33.9411
64.409129112, 96.390, 1131.0, 33.6303
64.461650243, 96.390, 1100.0, 33.1662
64.514171374, 96.390, 1017.0, 31.8904
64.566692504, 96.390, 949.0, 30.8058
64.619213635, 96.390, 857.0, 29.2746
64.671734766, 96.390, 836.0, 28.9137
64.724255896, 96.390, 768.0, 27.7128
64.776777027, 96.390, 805.0, 28.3725
64.829298158, 96.390, 777.0, 27.8747
64.881819289, 96.390, 713.0, 26.7021
64.934340419, 96.390, 729.0, 27.0000
64.986861550, 96.390, 700.0, 26.4575