File: Files_organized_for_plots/Constant_NaOH_1mL10M_to_1gPC_28Day/XRD_PCornernul_Act03May22_B1_1000M_NaOH_LS0133_1.csv
[Measurement conditions]
Sample identification,XRD_PCornernul_Act03May22_B1_1000M_NaOH_LS0133_1
Comment - 1,"Configuration=Stage for Flat Samples/Holders, Owner=User-1, Creation date=7/1/2020 9:53:24 AM"
Comment - 2,"Goniometer=Theta/Theta; Minimum step size 2Theta:0.0001; Minimum step size Omega:0.0001"
Comment - 3,"Sample stage=Stage for flat samples/holders"
Comment - 4,"Diffractometer system=EMPYREAN"
Comment - 5,"Measurement program=C:\Users\ibo5034\OneDrive - The Pennsylvania State University\NEUP\Zerobackground scan.xrdmp, Identifier={98A3B11C-88F9-4AA6-982C-73314A311EF5}"
Anode material,Cu
K-Alpha1 wavelength,1.5405980
K-Alpha2 wavelength,1.5444260
Ratio K-Alpha2/K-Alpha1,0.500
Divergence slit,Fixed,0.25
Monochromator used,NO
Generator voltage, 45
Tube current, 40
File date and time,03/Jun/2022 15:26
Unit cell,
h k l, 0 0 0
Scan axis,Gonio
Scan range,4.994599997,64.999991833
Scan step size,0.0262606
No. of points, 2285
Scan type,CONTINUOUS
Time per step,96.390
[Scan points]
Angle, TimePerStep, Intensity, ESD
5.007730280, 96.390, 5764.0, 75.9210
5.060251411, 96.390, 5668.0, 75.2861
5.112772541, 96.390, 5511.0, 74.2361
5.165293672, 96.390, 5426.0, 73.6614
5.217814803, 96.390, 5301.0, 72.8080
5.270335934, 96.390, 5145.0, 71.7287
5.322857064, 96.390, 5248.0, 72.4431
5.375378195, 96.390, 5076.0, 71.2461
5.427899326, 96.390, 4818.0, 69.4118
5.480420456, 96.390, 4893.0, 69.9500
5.532941587, 96.390, 4938.0, 70.2709
5.585462718, 96.390, 4969.0, 70.4911
5.637983849, 96.390, 4949.0, 70.3491
5.690504979, 96.390, 4744.0, 68.8767
5.743026110, 96.390, 4723.0, 68.7241
5.795547241, 96.390, 4672.0, 68.3520
5.848068371, 96.390, 4565.0, 67.5648
5.900589502, 96.390, 4488.0, 66.9925
5.953110633, 96.390, 4524.0, 67.2607
6.005631763, 96.390, 4441.0, 66.6408
6.058152894, 96.390, 4433.0, 66.5808
6.110674025, 96.390, 4424.0, 66.5132
6.163195156, 96.390, 4269.0, 65.3376
6.215716286, 96.390, 4326.0, 65.7723
6.268237417, 96.390, 4348.0, 65.9394
6.320758548, 96.390, 4254.0, 65.2227
6.373279678, 96.390, 4157.0, 64.4748
6.425800809, 96.390, 4095.0, 63.9922
6.478321940, 96.390, 4162.0, 64.5136
6.530843071, 96.390, 4106.0, 64.0781
6.583364201, 96.390, 4142.0, 64.3584
6.635885332, 96.390, 4080.0, 63.8749
6.688406463, 96.390, 4156.0, 64.4670
6.740927593, 96.390, 3951.0, 62.8570
6.793448724, 96.390, 4066.0, 63.7652
6.845969855, 96.390, 4086.0, 63.9218
6.898490986, 96.390, 4008.0, 63.3088
6.951012116, 96.390, 4125.0, 64.2262
7.003533247, 96.390, 4157.0, 64.4748
7.056054378, 96.390, 4333.0, 65.8255
7.108575508, 96.390, 4381.0, 66.1891
7.161096639, 96.390, 4479.0, 66.9253
7.213617770, 96.390, 4575.0, 67.6387
7.266138900, 96.390, 4738.0, 68.8331
7.318660031, 96.390, 5077.0, 71.2531
7.371181162, 96.390, 5151.0, 71.7705
7.423702293, 96.390, 5117.0, 71.5332
7.476223423, 96.390, 5529.0, 74.3572
7.528744554, 96.390, 5906.0, 76.8505
7.581265685, 96.390, 6304.0, 79.3977
7.633786815, 96.390, 6636.0, 81.4616
7.686307946, 96.390, 6493.0, 80.5792
7.738829077, 96.390, 6564.0, 81.0185
7.791350208, 96.390, 6384.0, 79.8999
7.843871338, 96.390, 5773.0, 75.9803
7.896392469, 96.390, 5314.0, 72.8972
7.948913600, 96.390, 4659.0, 68.2569
8.001434730, 96.390, 4279.0, 65.4141
8.053955861, 96.390, 3855.0, 62.0886
8.106476992, 96.390, 3743.0, 61.1801
8.158998123, 96.390, 3660.0, 60.4979
8.211519253, 96.390, 3589.0, 59.9083
8.264040384, 96.390, 3364.0, 58.0000
8.316561515, 96.390, 3413.0, 58.4209
8.369082645, 96.390, 3400.0, 58.3095
8.421603776, 96.390, 3299.0, 57.4369
8.474124907, 96.390, 3166.0, 56.2672
8.526646038, 96.390, 3160.0, 56.2139
8.579167168, 96.390, 3219.0, 56.7362
8.631688299, 96.390, 3209.0, 56.6480
8.684209430, 96.390, 3163.0, 56.2406
8.736730560, 96.390, 3159.0, 56.2050
8.789251691, 96.390, 3111.0, 55.7763
8.841772822, 96.390, 3193.0, 56.5066
8.894293952, 96.390, 3111.0, 55.7763
8.946815083, 96.390, 3121.0, 55.8659
8.999336214, 96.390, 3064.0, 55.3534
9.051857345, 96.390, 3263.0, 57.1227
9.104378475, 96.390, 3192.0, 56.4978
9.156899606, 96.390, 3259.0, 57.0877
9.209420737, 96.390, 3215.0, 56.7010
9.261941867, 96.390, 3403.0, 58.3352
9.314462998, 96.390, 3488.0, 59.0593
9.366984129, 96.390, 3614.0, 60.1166
9.419505260, 96.390, 3904.0, 62.4820
9.472026390, 96.390, 4519.0, 67.2235
9.524547521, 96.390, 4906.0, 70.0428
9.577068652, 96.390, 4715.0, 68.6659
9.629589782, 96.390, 3896.0, 62.4179
9.682110913, 96.390, 3256.0, 57.0614
9.734632044, 96.390, 2969.0, 54.4885
9.787153175, 96.390, 2897.0, 53.8238
9.839674305, 96.390, 2874.0, 53.6097
9.892195436, 96.390, 2862.0, 53.4977
9.944716567, 96.390, 2804.0, 52.9528
9.997237697, 96.390, 2703.0, 51.9904
10.049758828, 96.390, 2640.0, 51.3809
10.102279959, 96.390, 2660.0, 51.5752
10.154801090, 96.390, 2738.0, 52.3259
10.207322220, 96.390, 2689.0, 51.8556
10.259843351, 96.390, 2693.0, 51.8941
10.312364482, 96.390, 2654.0, 51.5170
10.364885612, 96.390, 2668.0, 51.6527
10.417406743, 96.390, 2698.0, 51.9423
10.469927874, 96.390, 2683.0, 51.7977
10.522449004, 96.390, 2627.0, 51.2543
10.574970135, 96.390, 2568.0, 50.6754
10.627491266, 96.390, 2611.0, 51.0979
10.680012397, 96.390, 2587.0, 50.8626
10.732533527, 96.390, 2561.0, 50.6063
10.785054658, 96.390, 2505.0, 50.0500
10.837575789, 96.390, 2554.0, 50.5371
10.890096919, 96.390, 2662.0, 51.5946
10.942618050, 96.390, 2521.0, 50.2096
10.995139181, 96.390, 2683.0, 51.7977
11.047660312, 96.390, 2600.0, 50.9902
11.100181442, 96.390, 2641.0, 51.3907
11.152702573, 96.390, 2760.0, 52.5357
11.205223704, 96.390, 2722.0, 52.1728
11.257744834, 96.390, 2731.0, 52.2590
11.310265965, 96.390, 2755.0, 52.4881
11.362787096, 96.390, 2658.0, 51.5558
11.415308227, 96.390, 2520.0, 50.1996
11.467829357, 96.390, 2542.0, 50.4183
11.520350488, 96.390, 2518.0, 50.1797
11.572871619, 96.390, 2533.0, 50.3289
11.625392749, 96.390, 2580.0, 50.7937
11.677913880, 96.390, 2631.0, 51.2933
11.730435011, 96.390, 2654.0, 51.5170
11.782956141, 96.390, 2745.0, 52.3927
11.835477272, 96.390, 2737.0, 52.3163
11.887998403, 96.390, 2831.0, 53.2071
11.940519534, 96.390, 2806.0, 52.9717
11.993040664, 96.390, 2645.0, 51.4296
12.045561795, 96.390, 2501.0, 50.0100
12.098082926, 96.390, 2446.0, 49.4571
12.150604056, 96.390, 2469.0, 49.6890
12.203125187, 96.390, 2420.0, 49.1935
12.255646318, 96.390, 2467.0, 49.6689
12.308167449, 96.390, 2432.0, 49.3153
12.360688579, 96.390, 2325.0, 48.2183
12.413209710, 96.390, 2330.0, 48.2701
12.465730841, 96.390, 2321.0, 48.1768
12.518251971, 96.390, 2387.0, 48.8569
12.570773102, 96.390, 2399.0, 48.9796
12.623294233, 96.390, 2393.0, 48.9183
12.675815364, 96.390, 2468.0, 49.6790
12.728336494, 96.390, 2492.0, 49.9199
12.780857625, 96.390, 2681.0, 51.7784
12.833378756, 96.390, 2606.0, 51.0490
12.885899886, 96.390, 2625.0, 51.2348
12.938421017, 96.390, 2564.0, 50.6360
12.990942148, 96.390, 2509.0, 50.0899
13.043463279, 96.390, 2466.0, 49.6588
13.095984409, 96.390, 2384.0, 48.8262
13.148505540, 96.390, 2517.0, 50.1697
13.201026671, 96.390, 2511.0, 50.1099
13.253547801, 96.390, 2481.0, 49.8096
13.306068932, 96.390, 2569.0, 50.6853
13.358590063, 96.390, 2519.0, 50.1896
13.411111193, 96.390, 2476.0, 49.7594
13.463632324, 96.390, 2306.0, 48.0208
13.516153455, 96.390, 2283.0, 47.7807
13.568674586, 96.390, 2190.0, 46.7974
13.621195716, 96.390, 2284.0, 47.7912
13.673716847, 96.390, 2230.0, 47.2229
13.726237978, 96.390, 2188.0, 46.7761
13.778759108, 96.390, 2101.0, 45.8367
13.831280239, 96.390, 2265.0, 47.5920
13.883801370, 96.390, 2263.0, 47.5710
13.936322501, 96.390, 2165.0, 46.5296
13.988843631, 96.390, 2195.0, 46.8508
14.041364762, 96.390, 2147.0, 46.3357
14.093885893, 96.390, 2136.0, 46.2169
14.146407023, 96.390, 2181.0, 46.7012
14.198928154, 96.390, 2216.0, 47.0744
14.251449285, 96.390, 2323.0, 48.1975
14.303970416, 96.390, 2355.0, 48.5283
14.356491546, 96.390, 2345.0, 48.4252
14.409012677, 96.390, 2368.0, 48.6621
14.461533808, 96.390, 2358.0, 48.5592
14.514054938, 96.390, 2381.0, 48.7955
14.566576069, 96.390, 2402.0, 49.0102
14.619097200, 96.390, 2367.0, 48.6518
14.671618331, 96.390, 2492.0, 49.9199
14.724139461, 96.390, 2387.0, 48.8569
14.776660592, 96.390, 2428.0, 49.2747
14.829181723, 96.390, 2316.0, 48.1248
14.881702853, 96.390, 2369.0, 48.6724
14.934223984, 96.390, 2354.0, 48.5180
14.986745115, 96.390, 2351.0, 48.4871
15.039266245, 96.390, 2482.0, 49.8197
15.091787376, 96.390, 2446.0, 49.4571
15.144308507, 96.390, 2584.0, 50.8331
15.196829638, 96.390, 2583.0, 50.8232
15.249350768, 96.390, 2452.0, 49.5177
15.301871899, 96.390, 2425.0, 49.2443
15.354393030, 96.390, 2178.0, 46.6690
15.406914160, 96.390, 2176.0, 46.6476
15.459435291, 96.390, 2125.0, 46.0977
15.511956422, 96.390, 2060.0, 45.3872
15.564477553, 96.390, 2089.0, 45.7056
15.616998683, 96.390, 2099.0, 45.8148
15.669519814, 96.390, 2135.0, 46.2061
15.722040945, 96.390, 2066.0, 45.4533
15.774562075, 96.390, 2106.0, 45.8912
15.827083206, 96.390, 2111.0, 45.9456
15.879604337, 96.390, 2123.0, 46.0760
15.932125468, 96.390, 2053.0, 45.3100
15.984646598, 96.390, 2077.0, 45.5741
16.037167729, 96.390, 2014.0, 44.8776
16.089688860, 96.390, 2059.0, 45.3762
16.142209990, 96.390, 2084.0, 45.6508
16.194731121, 96.390, 2006.0, 44.7884
16.247252252, 96.390, 1980.0, 44.4972
16.299773382, 96.390, 1957.0, 44.2380
16.352294513, 96.390, 1975.0, 44.4410
16.404815644, 96.390, 1963.0, 44.3058
16.457336775, 96.390, 1938.0, 44.0227
16.509857905, 96.390, 2043.0, 45.1996
16.562379036, 96.390, 1973.0, 44.4185
16.614900167, 96.390, 1961.0, 44.2832
16.667421297, 96.390, 2010.0, 44.8330
16.719942428, 96.390, 1977.0, 44.4635
16.772463559, 96.390, 2062.0, 45.4093
16.824984690, 96.390, 1951.0, 44.1701
16.877505820, 96.390, 1939.0, 44.0341
16.930026951, 96.390, 1942.0, 44.0681
16.982548082, 96.390, 1960.0, 44.2719
17.035069212, 96.390, 1968.0, 44.3621
17.087590343, 96.390, 1901.0, 43.6005
17.140111474, 96.390, 1946.0, 44.1135
17.192632605, 96.390, 1864.0, 43.1741
17.245153735, 96.390, 1921.0, 43.8292
17.297674866, 96.390, 1917.0, 43.7836
17.350195997, 96.390, 1928.0, 43.9090
17.402717127, 96.390, 1954.0, 44.2041
17.455238258, 96.390, 1824.0, 42.7083
17.507759389, 96.390, 1967.0, 44.3509
17.560280520, 96.390, 1908.0, 43.6807
17.612801650, 96.390, 1904.0, 43.6348
17.665322781, 96.390, 1953.0, 44.1928
17.717843912, 96.390, 1967.0, 44.3509
17.770365042, 96.390, 1890.0, 43.4741
17.822886173, 96.390, 2003.0, 44.7549
17.875407304, 96.390, 1868.0, 43.2204
17.927928434, 96.390, 2097.0, 45.7930
17.980449565, 96.390, 1996.0, 44.6766
18.032970696, 96.390, 2003.0, 44.7549
18.085491827, 96.390, 2139.0, 46.2493
18.138012957, 96.390, 2177.0, 46.6583
18.190534088, 96.390, 2202.0, 46.9255
18.243055219, 96.390, 2164.0, 46.5188
18.295576349, 96.390, 2141.0, 46.2709
18.348097480, 96.390, 1977.0, 44.4635
18.400618611, 96.390, 1996.0, 44.6766
18.453139742, 96.390, 1998.0, 44.6990
18.505660872, 96.390, 2003.0, 44.7549
18.558182003, 96.390, 1922.0, 43.8406
18.610703134, 96.390, 1929.0, 43.9204
18.663224264, 96.390, 1889.0, 43.4626
18.715745395, 96.390, 1939.0, 44.0341
18.768266526, 96.390, 1917.0, 43.7836
18.820787657, 96.390, 1873.0, 43.2782
18.873308787, 96.390, 1917.0, 43.7836
18.925829918, 96.390, 1936.0, 44.0000
18.978351049, 96.390, 1978.0, 44.4747
19.030872179, 96.390, 1985.0, 44.5533
19.083393310, 96.390, 2040.0, 45.1664
19.135914441, 96.390, 2094.0, 45.7602
19.188435572, 96.390, 1981.0, 44.5084
19.240956702, 96.390, 1967.0, 44.3509
19.293477833, 96.390, 2086.0, 45.6727
19.345998964, 96.390, 1938.0, 44.0227
19.398520094, 96.390, 2051.0, 45.2880
19.451041225, 96.390, 2061.0, 45.3982
19.503562356, 96.390, 2104.0, 45.8694
19.556083486, 96.390, 2104.0, 45.8694
19.608604617, 96.390, 2047.0, 45.2438
19.661125748, 96.390, 2042.0, 45.1885
19.713646879, 96.390, 2016.0, 44.8999
19.766168009, 96.390, 1988.0, 44.5870
19.818689140, 96.390, 2060.0, 45.3872
19.871210271, 96.390, 2034.0, 45.0999
19.923731401, 96.390, 2079.0, 45.5961
19.976252532, 96.390, 2080.0, 45.6070
20.028773663, 96.390, 2120.0, 46.0435
20.081294794, 96.390, 2192.0, 46.8188
20.133815924, 96.390, 2208.0, 46.9894
20.186337055, 96.390, 2181.0, 46.7012
20.238858186, 96.390, 2154.0, 46.4112
20.291379316, 96.390, 2205.0, 46.9574
20.343900447, 96.390, 2223.0, 47.1487
20.396421578, 96.390, 2150.0, 46.3681
20.448942709, 96.390, 2195.0, 46.8508
20.501463839, 96.390, 2215.0, 47.0638
20.553984970, 96.390, 2182.0, 46.7119
20.606506101, 96.390, 2221.0, 47.1275
20.659027231, 96.390, 2248.0, 47.4131
20.711548362, 96.390, 2183.0, 46.7226
20.764069493, 96.390, 2276.0, 47.7074
20.816590623, 96.390, 2163.0, 46.5081
20.869111754, 96.390, 2169.0, 46.5725
20.921632885, 96.390, 2192.0, 46.8188
20.974154016, 96.390, 2129.0, 46.1411
21.026675146, 96.390, 2107.0, 45.9021
21.079196277, 96.390, 2159.0, 46.4650
21.131717408, 96.390, 2187.0, 46.7654
21.184238538, 96.390, 2167.0, 46.5510
21.236759669, 96.390, 2223.0, 47.1487
21.289280800, 96.390, 2297.0, 47.9270
21.341801931, 96.390, 2317.0, 48.1352
21.394323061, 96.390, 2413.0, 49.1223
21.446844192, 96.390, 2518.0, 50.1797
21.499365323, 96.390, 2552.0, 50.5173
21.551886453, 96.390, 2557.0, 50.5668
21.604407584, 96.390, 2509.0, 50.0899
21.656928715, 96.390, 2186.0, 46.7547
21.709449846, 96.390, 2200.0, 46.9042
21.761970976, 96.390, 2166.0, 46.5403
21.814492107, 96.390, 2286.0, 47.8121
21.867013238, 96.390, 2187.0, 46.7654
21.919534368, 96.390, 2140.0, 46.2601
21.972055499, 96.390, 2177.0, 46.6583
22.024576630, 96.390, 2159.0, 46.4650
22.077097761, 96.390, 2086.0, 45.6727
22.129618891, 96.390, 2076.0, 45.5631
22.182140022, 96.390, 2044.0, 45.2106
22.234661153, 96.390, 2030.0, 45.0555
22.287182283, 96.390, 2002.0, 44.7437
22.339703414, 96.390, 1961.0, 44.2832
22.392224545, 96.390, 1998.0, 44.6990
22.444745675, 96.390, 1872.0, 43.2666
22.497266806, 96.390, 2018.0, 44.9222
22.549787937, 96.390, 1916.0, 43.7721
22.602309068, 96.390, 1973.0, 44.4185
22.654830198, 96.390, 2077.0, 45.5741
22.707351329, 96.390, 2084.0, 45.6508
22.759872460, 96.390, 2085.0, 45.6618
22.812393590, 96.390, 2023.0, 44.9778
22.864914721, 96.390, 2114.0, 45.9783
22.917435852, 96.390, 2065.0, 45.4423
22.969956983, 96.390, 2025.0, 45.0000
23.022478113, 96.390, 2030.0, 45.0555
23.074999244, 96.390, 2128.0, 46.1303
23.127520375, 96.390, 2059.0, 45.3762
23.180041505, 96.390, 2157.0, 46.4435
23.232562636, 96.390, 2098.0, 45.8039
23.285083767, 96.390, 2237.0, 47.2969
23.337604898, 96.390, 2221.0, 47.1275
23.390126028, 96.390, 2125.0, 46.0977
23.442647159, 96.390, 2247.0, 47.4025
23.495168290, 96.390, 2256.0, 47.4974
23.547689420, 96.390, 2298.0, 47.9375
23.600210551, 96.390, 2276.0, 47.7074
23.652731682, 96.390, 2246.0, 47.3920
23.705252813, 96.390, 2171.0, 46.5940
23.757773943, 96.390, 2161.0, 46.4866
23.810295074, 96.390, 2129.0, 46.1411
23.862816205, 96.390, 2071.0, 45.5082
23.915337335, 96.390, 2064.0, 45.4313
23.967858466, 96.390, 1982.0, 44.5197
24.020379597, 96.390, 2081.0, 45.6180
24.072900727, 96.390, 2012.0, 44.8553
24.125421858, 96.390, 1945.0, 44.1022
24.177942989, 96.390, 2001.0, 44.7325
24.230464120, 96.390, 1918.0, 43.7950
24.282985250, 96.390, 1935.0, 43.9886
24.335506381, 96.390, 1955.0, 44.2154
24.388027512, 96.390, 1911.0, 43.7150
24.440548642, 96.390, 1881.0, 43.3705
24.493069773, 96.390, 1852.0, 43.0349
24.545590904, 96.390, 1903.0, 43.6234
24.598112035, 96.390, 1869.0, 43.2319
24.650633165, 96.390, 1912.0, 43.7264
24.703154296, 96.390, 1883.0, 43.3935
24.755675427, 96.390, 1892.0, 43.4971
24.808196557, 96.390, 1936.0, 44.0000
24.860717688, 96.390, 1916.0, 43.7721
24.913238819, 96.390, 1995.0, 44.6654
24.965759950, 96.390, 2048.0, 45.2548
25.018281080, 96.390, 1950.0, 44.1588
25.070802211, 96.390, 1972.0, 44.4072
25.123323342, 96.390, 1976.0, 44.4522
25.175844472, 96.390, 1996.0, 44.6766
25.228365603, 96.390, 2092.0, 45.7384
25.280886734, 96.390, 2047.0, 45.2438
25.333407864, 96.390, 2093.0, 45.7493
25.385928995, 96.390, 1990.0, 44.6094
25.438450126, 96.390, 2075.0, 45.5522
25.490971257, 96.390, 2094.0, 45.7602
25.543492387, 96.390, 2012.0, 44.8553
25.596013518, 96.390, 2089.0, 45.7056
25.648534649, 96.390, 2130.0, 46.1519
25.701055779, 96.390, 2181.0, 46.7012
25.753576910, 96.390, 2321.0, 48.1768
25.806098041, 96.390, 2426.0, 49.2544
25.858619172, 96.390, 2388.0, 48.8672
25.911140302, 96.390, 2355.0, 48.5283
25.963661433, 96.390, 2427.0, 49.2646
26.016182564, 96.390, 2360.0, 48.5798
26.068703694, 96.390, 2286.0, 47.8121
26.121224825, 96.390, 2227.0, 47.1911
26.173745956, 96.390, 2172.0, 46.6047
26.226267087, 96.390, 2129.0, 46.1411
26.278788217, 96.390, 2140.0, 46.2601
26.331309348, 96.390, 2048.0, 45.2548
26.383830479, 96.390, 2214.0, 47.0532
26.436351609, 96.390, 2216.0, 47.0744
26.488872740, 96.390, 2246.0, 47.3920
26.541393871, 96.390, 2249.0, 47.4236
26.593915002, 96.390, 2291.0, 47.8644
26.646436132, 96.390, 2328.0, 48.2494
26.698957263, 96.390, 2238.0, 47.3075
26.751478394, 96.390, 2264.0, 47.5815
26.803999524, 96.390, 2337.0, 48.3425
26.856520655, 96.390, 2340.0, 48.3735
26.909041786, 96.390, 2183.0, 46.7226
26.961562916, 96.390, 2241.0, 47.3392
27.014084047, 96.390, 2256.0, 47.4974
27.066605178, 96.390, 2360.0, 48.5798
27.119126309, 96.390, 2214.0, 47.0532
27.171647439, 96.390, 2376.0, 48.7442
27.224168570, 96.390, 2241.0, 47.3392
27.276689701, 96.390, 2305.0, 48.0104
27.329210831, 96.390, 2251.0, 47.4447
27.381731962, 96.390, 2340.0, 48.3735
27.434253093, 96.390, 2149.0, 46.3573
27.486774224, 96.390, 2229.0, 47.2123
27.539295354, 96.390, 2199.0, 46.8935
27.591816485, 96.390, 2244.0, 47.3709
27.644337616, 96.390, 2196.0, 46.8615
27.696858746, 96.390, 2214.0, 47.0532
27.749379877, 96.390, 2211.0, 47.0213
27.801901008, 96.390, 2242.0, 47.3498
27.854422139, 96.390, 2339.0, 48.3632
27.906943269, 96.390, 2237.0, 47.2969
27.959464400, 96.390, 2341.0, 48.3839
28.011985531, 96.390, 2282.0, 47.7703
28.064506661, 96.390, 2289.0, 47.8435
28.117027792, 96.390, 2305.0, 48.0104
28.169548923, 96.390, 2426.0, 49.2544
28.222070054, 96.390, 2419.0, 49.1833
28.274591184, 96.390, 2529.0, 50.2892
28.327112315, 96.390, 2462.0, 49.6185
28.379633446, 96.390, 2448.0, 49.4773
28.432154576, 96.390, 2570.0, 50.6952
28.484675707, 96.390, 2522.0, 50.2195
28.537196838, 96.390, 2527.0, 50.2693
28.589717968, 96.390, 2532.0, 50.3190
28.642239099, 96.390, 2619.0, 51.1762
28.694760230, 96.390, 2593.0, 50.9215
28.747281361, 96.390, 2639.0, 51.3712
28.799802491, 96.390, 2742.0, 52.3641
28.852323622, 96.390, 2802.0, 52.9339
28.904844753, 96.390, 2634.0, 51.3225
28.957365883, 96.390, 2742.0, 52.3641
29.009887014, 96.390, 2829.0, 53.1883
29.062408145, 96.390, 2801.0, 52.9245
29.114929276, 96.390, 2747.0, 52.4118
29.167450406, 96.390, 2764.0, 52.5738
29.219971537, 96.390, 2829.0, 53.1883
29.272492668, 96.390, 2962.0, 54.4243
29.325013798, 96.390, 2975.0, 54.5436
29.377534929, 96.390, 2974.0, 54.5344
29.430056060, 96.390, 2976.0, 54.5527
29.482577191, 96.390, 2918.0, 54.0185
29.535098321, 96.390, 3233.0, 56.8595
29.587619452, 96.390, 3295.0, 57.4021
29.640140583, 96.390, 3336.0, 57.7581
29.692661713, 96.390, 3331.0, 57.7148
29.745182844, 96.390, 3176.0, 56.3560
29.797703975, 96.390, 3133.0, 55.9732
29.850225105, 96.390, 3035.0, 55.0908
29.902746236, 96.390, 2991.0, 54.6900
29.955267367, 96.390, 2848.0, 53.3667
30.007788498, 96.390, 2848.0, 53.3667
30.060309628, 96.390, 2879.0, 53.6563
30.112830759, 96.390, 2824.0, 53.1413
30.165351890, 96.390, 2891.0, 53.7680
30.217873020, 96.390, 2769.0, 52.6213
30.270394151, 96.390, 2884.0, 53.7029
30.322915282, 96.390, 2864.0, 53.5164
30.375436413, 96.390, 2833.0, 53.2259
30.427957543, 96.390, 2933.0, 54.1572
30.480478674, 96.390, 2806.0, 52.9717
30.532999805, 96.390, 3021.0, 54.9636
30.585520935, 96.390, 3146.0, 56.0892
30.638042066, 96.390, 3051.0, 55.2359
30.690563197, 96.390, 3015.0, 54.9090
30.743084328, 96.390, 2984.0, 54.6260
30.795605458, 96.390, 2848.0, 53.3667
30.848126589, 96.390, 2814.0, 53.0471
30.900647720, 96.390, 2744.0, 52.3832
30.953168850, 96.390, 2814.0, 53.0471
31.005689981, 96.390, 2789.0, 52.8110
31.058211112, 96.390, 2827.0, 53.1695
31.110732243, 96.390, 2778.0, 52.7067
31.163253373, 96.390, 2727.0, 52.2207
31.215774504, 96.390, 2831.0, 53.2071
31.268295635, 96.390, 2861.0, 53.4883
31.320816765, 96.390, 2827.0, 53.1695
31.373337896, 96.390, 2847.0, 53.3573
31.425859027, 96.390, 2758.0, 52.5167
31.478380157, 96.390, 2808.0, 52.9906
31.530901288, 96.390, 2647.0, 51.4490
31.583422419, 96.390, 2662.0, 51.5946
31.635943550, 96.390, 2675.0, 51.7204
31.688464680, 96.390, 2628.0, 51.2640
31.740985811, 96.390, 2546.0, 50.4579
31.793506942, 96.390, 2643.0, 51.4101
31.846028072, 96.390, 2503.0, 50.0300
31.898549203, 96.390, 2450.0, 49.4975
31.951070334, 96.390, 2503.0, 50.0300
32.003591465, 96.390, 2586.0, 50.8527
32.056112595, 96.390, 2589.0, 50.8822
32.108633726, 96.390, 2660.0, 51.5752
32.161154857, 96.390, 2770.0, 52.6308
32.213675987, 96.390, 2794.0, 52.8583
32.266197118, 96.390, 2781.0, 52.7352
32.318718249, 96.390, 2707.0, 52.0288
32.371239380, 96.390, 2785.0, 52.7731
32.423760510, 96.390, 2714.0, 52.0961
32.476281641, 96.390, 2753.0, 52.4690
32.528802772, 96.390, 2646.0, 51.4393
32.581323902, 96.390, 2559.0, 50.5866
32.633845033, 96.390, 2484.0, 49.8397
32.686366164, 96.390, 2463.0, 49.6286
32.738887295, 96.390, 2396.0, 48.9490
32.791408425, 96.390, 2352.0, 48.4974
32.843929556, 96.390, 2446.0, 49.4571
32.896450687, 96.390, 2437.0, 49.3660
32.948971817, 96.390, 2473.0, 49.7293
33.001492948, 96.390, 2436.0, 49.3559
33.054014079, 96.390, 2305.0, 48.0104
33.106535209, 96.390, 2405.0, 49.0408
33.159056340, 96.390, 2400.0, 48.9898
33.211577471, 96.390, 2364.0, 48.6210
33.264098602, 96.390, 2388.0, 48.8672
33.316619732, 96.390, 2313.0, 48.0937
33.369140863, 96.390, 2253.0, 47.4658
33.421661994, 96.390, 2348.0, 48.4562
33.474183124, 96.390, 2293.0, 47.8853
33.526704255, 96.390, 2305.0, 48.0104
33.579225386, 96.390, 2326.0, 48.2286
33.631746517, 96.390, 2420.0, 49.1935
33.684267647, 96.390, 2471.0, 49.7092
33.736788778, 96.390, 2543.0, 50.4282
33.789309909, 96.390, 2482.0, 49.8197
33.841831039, 96.390, 2541.0, 50.4083
33.894352170, 96.390, 2439.0, 49.3862
33.946873301, 96.390, 2520.0, 50.1996
33.999394432, 96.390, 2456.0, 49.5580
34.051915562, 96.390, 2484.0, 49.8397
34.104436693, 96.390, 2383.0, 48.8160
34.156957824, 96.390, 2368.0, 48.6621
34.209478954, 96.390, 2348.0, 48.4562
34.262000085, 96.390, 2165.0, 46.5296
34.314521216, 96.390, 2136.0, 46.2169
34.367042346, 96.390, 2140.0, 46.2601
34.419563477, 96.390, 2118.0, 46.0217
34.472084608, 96.390, 2058.0, 45.3652
34.524605739, 96.390, 2116.0, 46.0000
34.577126869, 96.390, 2162.0, 46.4973
34.629648000, 96.390, 2082.0, 45.6289
34.682169131, 96.390, 2147.0, 46.3357
34.734690261, 96.390, 2254.0, 47.4763
34.787211392, 96.390, 2143.0, 46.2925
34.839732523, 96.390, 2268.0, 47.6235
34.892253654, 96.390, 2217.0, 47.0850
34.944774784, 96.390, 2242.0, 47.3498
34.997295915, 96.390, 2155.0, 46.4220
35.049817046, 96.390, 2054.0, 45.3211
35.102338176, 96.390, 2062.0, 45.4093
35.154859307, 96.390, 1969.0, 44.3734
35.207380438, 96.390, 1978.0, 44.4747
35.259901569, 96.390, 1881.0, 43.3705
35.312422699, 96.390, 1900.0, 43.5890
35.364943830, 96.390, 1795.0, 42.3674
35.417464961, 96.390, 1788.0, 42.2847
35.469986091, 96.390, 1699.0, 41.2189
35.522507222, 96.390, 1668.0, 40.8412
35.575028353, 96.390, 1667.0, 40.8289
35.627549484, 96.390, 1621.0, 40.2616
35.680070614, 96.390, 1621.0, 40.2616
35.732591745, 96.390, 1541.0, 39.2556
35.785112876, 96.390, 1626.0, 40.3237
35.837634006, 96.390, 1645.0, 40.5586
35.890155137, 96.390, 1556.0, 39.4462
35.942676268, 96.390, 1492.0, 38.6264
35.995197398, 96.390, 1538.0, 39.2173
36.047718529, 96.390, 1529.0, 39.1024
36.100239660, 96.390, 1458.0, 38.1838
36.152760791, 96.390, 1531.0, 39.1280
36.205281921, 96.390, 1456.0, 38.1576
36.257803052, 96.390, 1505.0, 38.7943
36.310324183, 96.390, 1528.0, 39.0896
36.362845313, 96.390, 1507.0, 38.8201
36.415366444, 96.390, 1553.0, 39.4081
36.467887575, 96.390, 1471.0, 38.3536
36.520408706, 96.390, 1536.0, 39.1918
36.572929836, 96.390, 1520.0, 38.9872
36.625450967, 96.390, 1451.0, 38.0920
36.677972098, 96.390, 1524.0, 39.0384
36.730493228, 96.390, 1459.0, 38.1969
36.783014359, 96.390, 1501.0, 38.7427
36.835535490, 96.390, 1462.0, 38.2361
36.888056621, 96.390, 1566.0, 39.5727
36.940577751, 96.390, 1471.0, 38.3536
36.993098882, 96.390, 1600.0, 40.0000
37.045620013, 96.390, 1516.0, 38.9358
37.098141143, 96.390, 1489.0, 38.5876
37.150662274, 96.390, 1466.0, 38.2884
37.203183405, 96.390, 1493.0, 38.6394
37.255704535, 96.390, 1428.0, 37.7889
37.308225666, 96.390, 1413.0, 37.5899
37.360746797, 96.390, 1430.0, 37.8153
37.413267928, 96.390, 1387.0, 37.2424
37.465789058, 96.390, 1459.0, 38.1969
37.518310189, 96.390, 1380.0, 37.1484
37.570831320, 96.390, 1335.0, 36.5377
37.623352450, 96.390, 1337.0, 36.5650
37.675873581, 96.390, 1379.0, 37.1349
37.728394712, 96.390, 1370.0, 37.0135
37.780915843, 96.390, 1424.0, 37.7359
37.833436973, 96.390, 1421.0, 37.6962
37.885958104, 96.390, 1377.0, 37.1080
37.938479235, 96.390, 1442.0, 37.9737
37.991000365, 96.390, 1452.0, 38.1051
38.043521496, 96.390, 1406.0, 37.4967
38.096042627, 96.390, 1424.0, 37.7359
38.148563758, 96.390, 1396.0, 37.3631
38.201084888, 96.390, 1463.0, 38.2492
38.253606019, 96.390, 1450.0, 38.0789
38.306127150, 96.390, 1411.0, 37.5633
38.358648280, 96.390, 1378.0, 37.1214
38.411169411, 96.390, 1403.0, 37.4566
38.463690542, 96.390, 1351.0, 36.7560
38.516211673, 96.390, 1358.0, 36.8511
38.568732803, 96.390, 1385.0, 37.2156
38.621253934, 96.390, 1388.0, 37.2559
38.673775065, 96.390, 1394.0, 37.3363
38.726296195, 96.390, 1419.0, 37.6696
38.778817326, 96.390, 1348.0, 36.7151
38.831338457, 96.390, 1265.0, 35.5668
38.883859587, 96.390, 1389.0, 37.2693
38.936380718, 96.390, 1348.0, 36.7151
38.988901849, 96.390, 1273.0, 35.6791
39.041422980, 96.390, 1315.0, 36.2629
39.093944110, 96.390, 1357.0, 36.8375
39.146465241, 96.390, 1256.0, 35.4401
39.198986372, 96.390, 1282.0, 35.8050
39.251507502, 96.390, 1266.0, 35.5809
39.304028633, 96.390, 1317.0, 36.2905
39.356549764, 96.390, 1267.0, 35.5949
39.409070895, 96.390, 1302.0, 36.0832
39.461592025, 96.390, 1217.0, 34.8855
39.514113156, 96.390, 1338.0, 36.5787
39.566634287, 96.390, 1230.0, 35.0714
39.619155417, 96.390, 1256.0, 35.4401
39.671676548, 96.390, 1263.0, 35.5387
39.724197679, 96.390, 1242.0, 35.2420
39.776718810, 96.390, 1304.0, 36.1109
39.829239940, 96.390, 1264.0, 35.5528
39.881761071, 96.390, 1269.0, 35.6230
39.934282202, 96.390, 1293.0, 35.9583
39.986803332, 96.390, 1293.0, 35.9583
40.039324463, 96.390, 1293.0, 35.9583
40.091845594, 96.390, 1286.0, 35.8608
40.144366725, 96.390, 1218.0, 34.8999
40.196887855, 96.390, 1255.0, 35.4260
40.249408986, 96.390, 1254.0, 35.4119
40.301930117, 96.390, 1258.0, 35.4683
40.354451247, 96.390, 1231.0, 35.0856
40.406972378, 96.390, 1205.0, 34.7131
40.459493509, 96.390, 1280.0, 35.7771
40.512014639, 96.390, 1277.0, 35.7351
40.564535770, 96.390, 1236.0, 35.1568
40.617056901, 96.390, 1269.0, 35.6230
40.669578032, 96.390, 1232.0, 35.0999
40.722099162, 96.390, 1192.0, 34.5254
40.774620293, 96.390, 1180.0, 34.3511
40.827141424, 96.390, 1224.0, 34.9857
40.879662554, 96.390, 1161.0, 34.0735
40.932183685, 96.390, 1177.0, 34.3074
40.984704816, 96.390, 1192.0, 34.5254
41.037225947, 96.390, 1200.0, 34.6410
41.089747077, 96.390, 1223.0, 34.9714
41.142268208, 96.390, 1202.0, 34.6699
41.194789339, 96.390, 1135.0, 33.6898
41.247310469, 96.390, 1141.0, 33.7787
41.299831600, 96.390, 1174.0, 34.2637
41.352352731, 96.390, 1190.0, 34.4964
41.404873862, 96.390, 1255.0, 35.4260
41.457394992, 96.390, 1265.0, 35.5668
41.509916123, 96.390, 1218.0, 34.8999
41.562437254, 96.390, 1213.0, 34.8281
41.614958384, 96.390, 1231.0, 35.0856
41.667479515, 96.390, 1287.0, 35.8748
41.720000646, 96.390, 1207.0, 34.7419
41.772521776, 96.390, 1259.0, 35.4824
41.825042907, 96.390, 1278.0, 35.7491
41.877564038, 96.390, 1279.0, 35.7631
41.930085169, 96.390, 1240.0, 35.2136
41.982606299, 96.390, 1254.0, 35.4119
42.035127430, 96.390, 1294.0, 35.9722
42.087648561, 96.390, 1231.0, 35.0856
42.140169691, 96.390, 1241.0, 35.2278
42.192690822, 96.390, 1253.0, 35.3977
42.245211953, 96.390, 1203.0, 34.6843
42.297733084, 96.390, 1234.0, 35.1283
42.350254214, 96.390, 1256.0, 35.4401
42.402775345, 96.390, 1262.0, 35.5246
42.455296476, 96.390, 1263.0, 35.5387
42.507817606, 96.390, 1298.0, 36.0278
42.560338737, 96.390, 1257.0, 35.4542
42.612859868, 96.390, 1270.0, 35.6371
42.665380999, 96.390, 1266.0, 35.5809
42.717902129, 96.390, 1248.0, 35.3270
42.770423260, 96.390, 1291.0, 35.9305
42.822944391, 96.390, 1278.0, 35.7491
42.875465521, 96.390, 1271.0, 35.6511
42.927986652, 96.390, 1256.0, 35.4401
42.980507783, 96.390, 1218.0, 34.8999
43.033028914, 96.390, 1279.0, 35.7631
43.085550044, 96.390, 1194.0, 34.5543
43.138071175, 96.390, 1205.0, 34.7131
43.190592306, 96.390, 1197.0, 34.5977
43.243113436, 96.390, 1134.0, 33.6749
43.295634567, 96.390, 1215.0, 34.8569
43.348155698, 96.390, 1103.0, 33.2114
43.400676828, 96.390, 1184.0, 34.4093
43.453197959, 96.390, 1194.0, 34.5543
43.505719090, 96.390, 1208.0, 34.7563
43.558240221, 96.390, 1226.0, 35.0143
43.610761351, 96.390, 1182.0, 34.3802
43.663282482, 96.390, 1199.0, 34.6266
43.715803613, 96.390, 1255.0, 35.4260
43.768324743, 96.390, 1260.0, 35.4965
43.820845874, 96.390, 1288.0, 35.8887
43.873367005, 96.390, 1251.0, 35.3695
43.925888136, 96.390, 1174.0, 34.2637
43.978409266, 96.390, 1213.0, 34.8281
44.030930397, 96.390, 1198.0, 34.6121
44.083451528, 96.390, 1221.0, 34.9428
44.135972658, 96.390, 1262.0, 35.5246
44.188493789, 96.390, 1240.0, 35.2136
44.241014920, 96.390, 1204.0, 34.6987
44.293536051, 96.390, 1212.0, 34.8138
44.346057181, 96.390, 1249.0, 35.3412
44.398578312, 96.390, 1240.0, 35.2136
44.451099443, 96.390, 1216.0, 34.8712
44.503620573, 96.390, 1224.0, 34.9857
44.556141704, 96.390, 1170.0, 34.2053
44.608662835, 96.390, 1296.0, 36.0000
44.661183966, 96.390, 1256.0, 35.4401
44.713705096, 96.390, 1259.0, 35.4824
44.766226227, 96.390, 1287.0, 35.8748
44.818747358, 96.390, 1347.0, 36.7015
44.871268488, 96.390, 1278.0, 35.7491
44.923789619, 96.390, 1229.0, 35.0571
44.976310750, 96.390, 1269.0, 35.6230
45.028831880, 96.390, 1154.0, 33.9706
45.081353011, 96.390, 1235.0, 35.1426
45.133874142, 96.390, 1244.0, 35.2704
45.186395273, 96.390, 1257.0, 35.4542
45.238916403, 96.390, 1189.0, 34.4819
45.291437534, 96.390, 1133.0, 33.6601
45.343958665, 96.390, 1140.0, 33.7639
45.396479795, 96.390, 1155.0, 33.9853
45.449000926, 96.390, 1158.0, 34.0294
45.501522057, 96.390, 1154.0, 33.9706
45.554043188, 96.390, 1108.0, 33.2866
45.606564318, 96.390, 1124.0, 33.5261
45.659085449, 96.390, 1097.0, 33.1210
45.711606580, 96.390, 1083.0, 32.9090
45.764127710, 96.390, 1157.0, 34.0147
45.816648841, 96.390, 1141.0, 33.7787
45.869169972, 96.390, 1125.0, 33.5410
45.921691103, 96.390, 1084.0, 32.9242
45.974212233, 96.390, 1111.0, 33.3317
46.026733364, 96.390, 1141.0, 33.7787
46.079254495, 96.390, 1102.0, 33.1964
46.131775625, 96.390, 1134.0, 33.6749
46.184296756, 96.390, 1129.0, 33.6006
46.236817887, 96.390, 1069.0, 32.6956
46.289339017, 96.390, 1046.0, 32.3419
46.341860148, 96.390, 1109.0, 33.3017
46.394381279, 96.390, 1062.0, 32.5883
46.446902410, 96.390, 1074.0, 32.7719
46.499423540, 96.390, 1134.0, 33.6749
46.551944671, 96.390, 1094.0, 33.0757
46.604465802, 96.390, 1100.0, 33.1662
46.656986932, 96.390, 1090.0, 33.0151
46.709508063, 96.390, 1121.0, 33.4813
46.762029194, 96.390, 1048.0, 32.3728
46.814550325, 96.390, 1053.0, 32.4500
46.867071455, 96.390, 1055.0, 32.4808
46.919592586, 96.390, 1050.0, 32.4037
46.972113717, 96.390, 998.0, 31.5911
47.024634847, 96.390, 1048.0, 32.3728
47.077155978, 96.390, 1044.0, 32.3110
47.129677109, 96.390, 1028.0, 32.0624
47.182198240, 96.390, 1020.0, 31.9374
47.234719370, 96.390, 1073.0, 32.7567
47.287240501, 96.390, 1020.0, 31.9374
47.339761632, 96.390, 1030.0, 32.0936
47.392282762, 96.390, 1014.0, 31.8434
47.444803893, 96.390, 982.0, 31.3369
47.497325024, 96.390, 1026.0, 32.0312
47.549846155, 96.390, 1018.0, 31.9061
47.602367285, 96.390, 1032.0, 32.1248
47.654888416, 96.390, 1027.0, 32.0468
47.707409547, 96.390, 1004.0, 31.6860
47.759930677, 96.390, 1083.0, 32.9090
47.812451808, 96.390, 1026.0, 32.0312
47.864972939, 96.390, 1049.0, 32.3883
47.917494069, 96.390, 1063.0, 32.6037
47.970015200, 96.390, 1025.0, 32.0156
48.022536331, 96.390, 1011.0, 31.7962
48.075057462, 96.390, 1018.0, 31.9061
48.127578592, 96.390, 1123.0, 33.5112
48.180099723, 96.390, 986.0, 31.4006
48.232620854, 96.390, 1068.0, 32.6803
48.285141984, 96.390, 986.0, 31.4006
48.337663115, 96.390, 1070.0, 32.7109
48.390184246, 96.390, 1039.0, 32.2335
48.442705377, 96.390, 1010.0, 31.7805
48.495226507, 96.390, 1024.0, 32.0000
48.547747638, 96.390, 1044.0, 32.3110
48.600268769, 96.390, 1011.0, 31.7962
48.652789899, 96.390, 1073.0, 32.7567
48.705311030, 96.390, 1088.0, 32.9848
48.757832161, 96.390, 1098.0, 33.1361
48.810353292, 96.390, 1102.0, 33.1964
48.862874422, 96.390, 1148.0, 33.8821
48.915395553, 96.390, 1061.0, 32.5730
48.967916684, 96.390, 1089.0, 33.0000
49.020437814, 96.390, 1096.0, 33.1059
49.072958945, 96.390, 1102.0, 33.1964
49.125480076, 96.390, 1105.0, 33.2415
49.178001207, 96.390, 1117.0, 33.4215
49.230522337, 96.390, 1062.0, 32.5883
49.283043468, 96.390, 1145.0, 33.8378
49.335564599, 96.390, 1114.0, 33.3766
49.388085729, 96.390, 1070.0, 32.7109
49.440606860, 96.390, 1032.0, 32.1248
49.493127991, 96.390, 1057.0, 32.5115
49.545649121, 96.390, 1087.0, 32.9697
49.598170252, 96.390, 1040.0, 32.2490
49.650691383, 96.390, 1079.0, 32.8481
49.703212514, 96.390, 1102.0, 33.1964
49.755733644, 96.390, 1032.0, 32.1248
49.808254775, 96.390, 1017.0, 31.8904
49.860775906, 96.390, 958.0, 30.9516
49.913297036, 96.390, 1022.0, 31.9687
49.965818167, 96.390, 946.0, 30.7571
50.018339298, 96.390, 1009.0, 31.7648
50.070860429, 96.390, 960.0, 30.9839
50.123381559, 96.390, 996.0, 31.5595
50.175902690, 96.390, 1048.0, 32.3728
50.228423821, 96.390, 977.0, 31.2570
50.280944951, 96.390, 1019.0, 31.9218
50.333466082, 96.390, 999.0, 31.6070
50.385987213, 96.390, 1036.0, 32.1870
50.438508344, 96.390, 997.0, 31.5753
50.491029474, 96.390, 1057.0, 32.5115
50.543550605, 96.390, 1101.0, 33.1813
50.596071736, 96.390, 1040.0, 32.2490
50.648592866, 96.390, 1044.0, 32.3110
50.701113997, 96.390, 1113.0, 33.3617
50.753635128, 96.390, 1061.0, 32.5730
50.806156258, 96.390, 1101.0, 33.1813
50.858677389, 96.390, 1058.0, 32.5269
50.911198520, 96.390, 1107.0, 33.2716
50.963719651, 96.390, 1082.0, 32.8938
51.016240781, 96.390, 1065.0, 32.6343
51.068761912, 96.390, 1034.0, 32.1559
51.121283043, 96.390, 1065.0, 32.6343
51.173804173, 96.390, 971.0, 31.1609
51.226325304, 96.390, 981.0, 31.3209
51.278846435, 96.390, 983.0, 31.3528
51.331367566, 96.390, 960.0, 30.9839
51.383888696, 96.390, 1032.0, 32.1248
51.436409827, 96.390, 967.0, 31.0966
51.488930958, 96.390, 925.0, 30.4138
51.541452088, 96.390, 940.0, 30.6594
51.593973219, 96.390, 925.0, 30.4138
51.646494350, 96.390, 946.0, 30.7571
51.699015481, 96.390, 963.0, 31.0322
51.751536611, 96.390, 961.0, 31.0000
51.804057742, 96.390, 885.0, 29.7489
51.856578873, 96.390, 918.0, 30.2985
51.909100003, 96.390, 912.0, 30.1993
51.961621134, 96.390, 885.0, 29.7489
52.014142265, 96.390, 986.0, 31.4006
52.066663396, 96.390, 919.0, 30.3150
52.119184526, 96.390, 948.0, 30.7896
52.171705657, 96.390, 921.0, 30.3480
52.224226788, 96.390, 917.0, 30.2820
52.276747918, 96.390, 884.0, 29.7321
52.329269049, 96.390, 900.0, 30.0000
52.381790180, 96.390, 976.0, 31.2410
52.434311310, 96.390, 975.0, 31.2250
52.486832441, 96.390, 989.0, 31.4484
52.539353572, 96.390, 1006.0, 31.7175
52.591874703, 96.390, 983.0, 31.3528
52.644395833, 96.390, 934.0, 30.5614
52.696916964, 96.390, 922.0, 30.3645
52.749438095, 96.390, 967.0, 31.0966
52.801959225, 96.390, 905.0, 30.0832
52.854480356, 96.390, 967.0, 31.0966
52.907001487, 96.390, 872.0, 29.5296
52.959522618, 96.390, 952.0, 30.8545
53.012043748, 96.390, 931.0, 30.5123
53.064564879, 96.390, 960.0, 30.9839
53.117086010, 96.390, 971.0, 31.1609
53.169607140, 96.390, 1004.0, 31.6860
53.222128271, 96.390, 1024.0, 32.0000
53.274649402, 96.390, 963.0, 31.0322
53.327170533, 96.390, 1013.0, 31.8277
53.379691663, 96.390, 1011.0, 31.7962
53.432212794, 96.390, 1003.0, 31.6702
53.484733925, 96.390, 963.0, 31.0322
53.537255055, 96.390, 966.0, 31.0805
53.589776186, 96.390, 959.0, 30.9677
53.642297317, 96.390, 964.0, 31.0483
53.694818448, 96.390, 931.0, 30.5123
53.747339578, 96.390, 1016.0, 31.8748
53.799860709, 96.390, 984.0, 31.3688
53.852381840, 96.390, 972.0, 31.1769
53.904902970, 96.390, 983.0, 31.3528
53.957424101, 96.390, 944.0, 30.7246
54.009945232, 96.390, 937.0, 30.6105
54.062466362, 96.390, 941.0, 30.6757
54.114987493, 96.390, 925.0, 30.4138
54.167508624, 96.390, 1033.0, 32.1403
54.220029755, 96.390, 943.0, 30.7083
54.272550885, 96.390, 1005.0, 31.7017
54.325072016, 96.390, 964.0, 31.0483
54.377593147, 96.390, 958.0, 30.9516
54.430114277, 96.390, 991.0, 31.4802
54.482635408, 96.390, 982.0, 31.3369
54.535156539, 96.390, 996.0, 31.5595
54.587677670, 96.390, 938.0, 30.6268
54.640198800, 96.390, 922.0, 30.3645
54.692719931, 96.390, 944.0, 30.7246
54.745241062, 96.390, 958.0, 30.9516
54.797762192, 96.390, 955.0, 30.9031
54.850283323, 96.390, 891.0, 29.8496
54.902804454, 96.390, 923.0, 30.3809
54.955325585, 96.390, 956.0, 30.9192
55.007846715, 96.390, 905.0, 30.0832
55.060367846, 96.390, 949.0, 30.8058
55.112888977, 96.390, 911.0, 30.1828
55.165410107, 96.390, 952.0, 30.8545
55.217931238, 96.390, 942.0, 30.6920
55.270452369, 96.390, 916.0, 30.2655
55.322973499, 96.390, 939.0, 30.6431
55.375494630, 96.390, 952.0, 30.8545
55.428015761, 96.390, 935.0, 30.5778
55.480536892, 96.390, 986.0, 31.4006
55.533058022, 96.390, 981.0, 31.3209
55.585579153, 96.390, 946.0, 30.7571
55.638100284, 96.390, 965.0, 31.0644
55.690621414, 96.390, 979.0, 31.2890
55.743142545, 96.390, 1053.0, 32.4500
55.795663676, 96.390, 993.0, 31.5119
55.848184807, 96.390, 929.0, 30.4795
55.900705937, 96.390, 1008.0, 31.7490
55.953227068, 96.390, 965.0, 31.0644
56.005748199, 96.390, 974.0, 31.2090
56.058269329, 96.390, 969.0, 31.1288
56.110790460, 96.390, 886.0, 29.7658
56.163311591, 96.390, 903.0, 30.0500
56.215832722, 96.390, 919.0, 30.3150
56.268353852, 96.390, 906.0, 30.0998
56.320874983, 96.390, 878.0, 29.6311
56.373396114, 96.390, 873.0, 29.5466
56.425917244, 96.390, 881.0, 29.6816
56.478438375, 96.390, 888.0, 29.7993
56.530959506, 96.390, 829.0, 28.7924
56.583480637, 96.390, 898.0, 29.9666
56.636001767, 96.390, 893.0, 29.8831
56.688522898, 96.390, 836.0, 28.9137
56.741044029, 96.390, 921.0, 30.3480
56.793565159, 96.390, 907.0, 30.1164
56.846086290, 96.390, 915.0, 30.2490
56.898607421, 96.390, 857.0, 29.2746
56.951128551, 96.390, 914.0, 30.2324
57.003649682, 96.390, 930.0, 30.4959
57.056170813, 96.390, 943.0, 30.7083
57.108691944, 96.390, 963.0, 31.0322
57.161213074, 96.390, 947.0, 30.7734
57.213734205, 96.390, 905.0, 30.0832
57.266255336, 96.390, 930.0, 30.4959
57.318776466, 96.390, 927.0, 30.4467
57.371297597, 96.390, 950.0, 30.8221
57.423818728, 96.390, 956.0, 30.9192
57.476339859, 96.390, 876.0, 29.5973
57.528860989, 96.390, 888.0, 29.7993
57.581382120, 96.390, 943.0, 30.7083
57.633903251, 96.390, 977.0, 31.2570
57.686424381, 96.390, 958.0, 30.9516
57.738945512, 96.390, 914.0, 30.2324
57.791466643, 96.390, 957.0, 30.9354
57.843987774, 96.390, 958.0, 30.9516
57.896508904, 96.390, 924.0, 30.3974
57.949030035, 96.390, 954.0, 30.8869
58.001551166, 96.390, 940.0, 30.6594
58.054072296, 96.390, 945.0, 30.7409
58.106593427, 96.390, 985.0, 31.3847
58.159114558, 96.390, 904.0, 30.0666
58.211635689, 96.390, 930.0, 30.4959
58.264156819, 96.390, 944.0, 30.7246
58.316677950, 96.390, 919.0, 30.3150
58.369199081, 96.390, 888.0, 29.7993
58.421720211, 96.390, 910.0, 30.1662
58.474241342, 96.390, 828.0, 28.7750
58.526762473, 96.390, 932.0, 30.5287
58.579283603, 96.390, 831.0, 28.8271
58.631804734, 96.390, 875.0, 29.5804
58.684325865, 96.390, 874.0, 29.5635
58.736846996, 96.390, 921.0, 30.3480
58.789368126, 96.390, 895.0, 29.9166
58.841889257, 96.390, 880.0, 29.6648
58.894410388, 96.390, 816.0, 28.5657
58.946931518, 96.390, 903.0, 30.0500
58.999452649, 96.390, 865.0, 29.4109
59.051973780, 96.390, 864.0, 29.3939
59.104494911, 96.390, 875.0, 29.5804
59.157016041, 96.390, 879.0, 29.6479
59.209537172, 96.390, 891.0, 29.8496
59.262058303, 96.390, 962.0, 31.0161
59.314579433, 96.390, 880.0, 29.6648
59.367100564, 96.390, 888.0, 29.7993
59.419621695, 96.390, 798.0, 28.2489
59.472142826, 96.390, 884.0, 29.7321
59.524663956, 96.390, 860.0, 29.3258
59.577185087, 96.390, 833.0, 28.8617
59.629706218, 96.390, 891.0, 29.8496
59.682227348, 96.390, 862.0, 29.3598
59.734748479, 96.390, 881.0, 29.6816
59.787269610, 96.390, 892.0, 29.8664
59.839790740, 96.390, 881.0, 29.6816
59.892311871, 96.390, 880.0, 29.6648
59.944833002, 96.390, 859.0, 29.3087
59.997354133, 96.390, 890.0, 29.8329
60.049875263, 96.390, 798.0, 28.2489
60.102396394, 96.390, 895.0, 29.9166
60.154917525, 96.390, 880.0, 29.6648
60.207438655, 96.390, 846.0, 29.0861
60.259959786, 96.390, 871.0, 29.5127
60.312480917, 96.390, 881.0, 29.6816
60.365002048, 96.390, 896.0, 29.9333
60.417523178, 96.390, 916.0, 30.2655
60.470044309, 96.390, 893.0, 29.8831
60.522565440, 96.390, 941.0, 30.6757
60.575086570, 96.390, 838.0, 28.9482
60.627607701, 96.390, 905.0, 30.0832
60.680128832, 96.390, 888.0, 29.7993
60.732649963, 96.390, 913.0, 30.2159
60.785171093, 96.390, 834.0, 28.8791
60.837692224, 96.390, 889.0, 29.8161
60.890213355, 96.390, 826.0, 28.7402
60.942734485, 96.390, 928.0, 30.4631
60.995255616, 96.390, 885.0, 29.7489
61.047776747, 96.390, 903.0, 30.0500
61.100297878, 96.390, 856.0, 29.2575
61.152819008, 96.390, 855.0, 29.2404
61.205340139, 96.390, 919.0, 30.3150
61.257861270, 96.390, 880.0, 29.6648
61.310382400, 96.390, 835.0, 28.8964
61.362903531, 96.390, 854.0, 29.2233
61.415424662, 96.390, 883.0, 29.7153
61.467945792, 96.390, 859.0, 29.3087
61.520466923, 96.390, 862.0, 29.3598
61.572988054, 96.390, 837.0, 28.9310
61.625509185, 96.390, 891.0, 29.8496
61.678030315, 96.390, 883.0, 29.7153
61.730551446, 96.390, 835.0, 28.8964
61.783072577, 96.390, 805.0, 28.3725
61.835593707, 96.390, 888.0, 29.7993
61.888114838, 96.390, 870.0, 29.4958
61.940635969, 96.390, 805.0, 28.3725
61.993157100, 96.390, 806.0, 28.3901
62.045678230, 96.390, 886.0, 29.7658
62.098199361, 96.390, 823.0, 28.6880
62.150720492, 96.390, 855.0, 29.2404
62.203241622, 96.390, 791.0, 28.1247
62.255762753, 96.390, 795.0, 28.1957
62.308283884, 96.390, 921.0, 30.3480
62.360805015, 96.390, 919.0, 30.3150
62.413326145, 96.390, 906.0, 30.0998
62.465847276, 96.390, 872.0, 29.5296
62.518368407, 96.390, 843.0, 29.0345
62.570889537, 96.390, 893.0, 29.8831
62.623410668, 96.390, 824.0, 28.7054
62.675931799, 96.390, 889.0, 29.8161
62.728452930, 96.390, 859.0, 29.3087
62.780974060, 96.390, 769.0, 27.7308
62.833495191, 96.390, 828.0, 28.7750
62.886016322, 96.390, 821.0, 28.6531
62.938537452, 96.390, 841.0, 29.0000
62.991058583, 96.390, 794.0, 28.1780
63.043579714, 96.390, 849.0, 29.1376
63.096100844, 96.390, 793.0, 28.1603
63.148621975, 96.390, 823.0, 28.6880
63.201143106, 96.390, 868.0, 29.4618
63.253664237, 96.390, 817.0, 28.5832
63.306185367, 96.390, 836.0, 28.9137
63.358706498, 96.390, 797.0, 28.2312
63.411227629, 96.390, 820.0, 28.6356
63.463748759, 96.390, 763.0, 27.6225
63.516269890, 96.390, 851.0, 29.1719
63.568791021, 96.390, 826.0, 28.7402
63.621312152, 96.390, 827.0, 28.7576
63.673833282, 96.390, 795.0, 28.1957
63.726354413, 96.390, 789.0, 28.0891
63.778875544, 96.390, 836.0, 28.9137
63.831396674, 96.390, 792.0, 28.1425
63.883917805, 96.390, 787.0, 28.0535
63.936438936, 96.390, 794.0, 28.1780
63.988960067, 96.390, 838.0, 28.9482
64.041481197, 96.390, 776.0, 27.8568
64.094002328, 96.390, 834.0, 28.8791
64.146523459, 96.390, 756.0, 27.4955
64.199044589, 96.390, 820.0, 28.6356
64.251565720, 96.390, 784.0, 28.0000
64.304086851, 96.390, 769.0, 27.7308
64.356607981, 96.390, 741.0, 27.2213
64.409129112, 96.390, 776.0, 27.8568
64.461650243, 96.390, 732.0, 27.0555
64.514171374, 96.390, 781.0, 27.9464
64.566692504, 96.390, 765.0, 27.6586
64.619213635, 96.390, 725.0, 26.9258
64.671734766, 96.390, 741.0, 27.2213
64.724255896, 96.390, 787.0, 28.0535
64.776777027, 96.390, 757.0, 27.5136
64.829298158, 96.390, 787.0, 28.0535
64.881819289, 96.390, 747.0, 27.3313
64.934340419, 96.390, 751.0, 27.4044
64.986861550, 96.390, 778.0, 27.8927