File: Files_organized_for_plots/Constant_NaOH_1mL10M_to_1gPC_28Day/XRD_SiAxialnul_Act03May22_B1_0714M_NaOH_LS0172_1.csv
[Measurement conditions]
Sample identification,XRD_SiAxialnul_Act03May22_B1_0833M_NaOH_LS0152_1
Comment - 1,"Configuration=Stage for Flat Samples/Holders, Owner=User-1, Creation date=7/1/2020 9:53:24 AM"
Comment - 2,"Goniometer=Theta/Theta; Minimum step size 2Theta:0.0001; Minimum step size Omega:0.0001"
Comment - 3,"Sample stage=Stage for flat samples/holders"
Comment - 4,"Diffractometer system=EMPYREAN"
Comment - 5,"Measurement program=C:\Users\ibo5034\OneDrive - The Pennsylvania State University\NEUP\Zerobackground scan.xrdmp, Identifier={98A3B11C-88F9-4AA6-982C-73314A311EF5}"
Anode material,Cu
K-Alpha1 wavelength,1.5405980
K-Alpha2 wavelength,1.5444260
Ratio K-Alpha2/K-Alpha1,0.500
Divergence slit,Fixed,0.25
Monochromator used,NO
Generator voltage, 45
Tube current, 40
File date and time,03/Jun/2022 13:49
Unit cell,
h k l, 0 0 0
Scan axis,Gonio
Scan range,4.994599997,64.999991833
Scan step size,0.0262606
No. of points, 2285
Scan type,CONTINUOUS
Time per step,96.390
[Scan points]
Angle, TimePerStep, Intensity, ESD
5.007730280, 96.390, 4115.0, 64.1483
5.060251411, 96.390, 4058.0, 63.7024
5.112772541, 96.390, 4026.0, 63.4508
5.165293672, 96.390, 3853.0, 62.0725
5.217814803, 96.390, 3776.0, 61.4492
5.270335934, 96.390, 3881.0, 62.2977
5.322857064, 96.390, 3995.0, 63.2060
5.375378195, 96.390, 3862.0, 62.1450
5.427899326, 96.390, 3921.0, 62.6179
5.480420456, 96.390, 3729.0, 61.0655
5.532941587, 96.390, 3815.0, 61.7657
5.585462718, 96.390, 3635.0, 60.2910
5.637983849, 96.390, 3765.0, 61.3596
5.690504979, 96.390, 3688.0, 60.7289
5.743026110, 96.390, 3802.0, 61.6604
5.795547241, 96.390, 3599.0, 59.9917
5.848068371, 96.390, 3660.0, 60.4979
5.900589502, 96.390, 3650.0, 60.4152
5.953110633, 96.390, 3577.0, 59.8080
6.005631763, 96.390, 3538.0, 59.4811
6.058152894, 96.390, 3558.0, 59.6490
6.110674025, 96.390, 3518.0, 59.3127
6.163195156, 96.390, 3562.0, 59.6825
6.215716286, 96.390, 3522.0, 59.3464
6.268237417, 96.390, 3563.0, 59.6909
6.320758548, 96.390, 3494.0, 59.1101
6.373279678, 96.390, 3547.0, 59.5567
6.425800809, 96.390, 3478.0, 58.9746
6.478321940, 96.390, 3517.0, 59.3043
6.530843071, 96.390, 3530.0, 59.4138
6.583364201, 96.390, 3473.0, 58.9322
6.635885332, 96.390, 3447.0, 58.7112
6.688406463, 96.390, 3464.0, 58.8558
6.740927593, 96.390, 3554.0, 59.6154
6.793448724, 96.390, 3358.0, 57.9483
6.845969855, 96.390, 3431.0, 58.5747
6.898490986, 96.390, 3476.0, 58.9576
6.951012116, 96.390, 3466.0, 58.8727
7.003533247, 96.390, 3457.0, 58.7963
7.056054378, 96.390, 3449.0, 58.7282
7.108575508, 96.390, 3412.0, 58.4123
7.161096639, 96.390, 3407.0, 58.3695
7.213617770, 96.390, 3449.0, 58.7282
7.266138900, 96.390, 3457.0, 58.7963
7.318660031, 96.390, 3443.0, 58.6771
7.371181162, 96.390, 3361.0, 57.9741
7.423702293, 96.390, 3455.0, 58.7792
7.476223423, 96.390, 3386.0, 58.1893
7.528744554, 96.390, 3461.0, 58.8303
7.581265685, 96.390, 3454.0, 58.7707
7.633786815, 96.390, 3477.0, 58.9661
7.686307946, 96.390, 3382.0, 58.1550
7.738829077, 96.390, 3466.0, 58.8727
7.791350208, 96.390, 3421.0, 58.4893
7.843871338, 96.390, 3381.0, 58.1464
7.896392469, 96.390, 3394.0, 58.2580
7.948913600, 96.390, 3542.0, 59.5147
8.001434730, 96.390, 3380.0, 58.1378
8.053955861, 96.390, 3479.0, 58.9830
8.106476992, 96.390, 3461.0, 58.8303
8.158998123, 96.390, 3539.0, 59.4895
8.211519253, 96.390, 3451.0, 58.7452
8.264040384, 96.390, 3372.0, 58.0689
8.316561515, 96.390, 3439.0, 58.6430
8.369082645, 96.390, 3532.0, 59.4306
8.421603776, 96.390, 3402.0, 58.3267
8.474124907, 96.390, 3363.0, 57.9914
8.526646038, 96.390, 3578.0, 59.8164
8.579167168, 96.390, 3442.0, 58.6686
8.631688299, 96.390, 3351.0, 57.8878
8.684209430, 96.390, 3459.0, 58.8133
8.736730560, 96.390, 3469.0, 58.8982
8.789251691, 96.390, 3303.0, 57.4717
8.841772822, 96.390, 3340.0, 57.7927
8.894293952, 96.390, 3369.0, 58.0431
8.946815083, 96.390, 3283.0, 57.2975
8.999336214, 96.390, 3326.0, 57.6715
9.051857345, 96.390, 3340.0, 57.7927
9.104378475, 96.390, 3332.0, 57.7235
9.156899606, 96.390, 3228.0, 56.8155
9.209420737, 96.390, 3199.0, 56.5597
9.261941867, 96.390, 3141.0, 56.0446
9.314462998, 96.390, 3169.0, 56.2939
9.366984129, 96.390, 3160.0, 56.2139
9.419505260, 96.390, 3094.0, 55.6237
9.472026390, 96.390, 3073.0, 55.4346
9.524547521, 96.390, 3139.0, 56.0268
9.577068652, 96.390, 3087.0, 55.5608
9.629589782, 96.390, 3126.0, 55.9106
9.682110913, 96.390, 2982.0, 54.6077
9.734632044, 96.390, 3112.0, 55.7853
9.787153175, 96.390, 3035.0, 55.0908
9.839674305, 96.390, 2945.0, 54.2679
9.892195436, 96.390, 3147.0, 56.0981
9.944716567, 96.390, 3070.0, 55.4076
9.997237697, 96.390, 3142.0, 56.0535
10.049758828, 96.390, 3070.0, 55.4076
10.102279959, 96.390, 3063.0, 55.3444
10.154801090, 96.390, 2995.0, 54.7266
10.207322220, 96.390, 2957.0, 54.3783
10.259843351, 96.390, 3095.0, 55.6327
10.312364482, 96.390, 2925.0, 54.0833
10.364885612, 96.390, 3053.0, 55.2540
10.417406743, 96.390, 3439.0, 58.6430
10.469927874, 96.390, 3453.0, 58.7622
10.522449004, 96.390, 2949.0, 54.3047
10.574970135, 96.390, 2848.0, 53.3667
10.627491266, 96.390, 2968.0, 54.4794
10.680012397, 96.390, 2816.0, 53.0660
10.732533527, 96.390, 2831.0, 53.2071
10.785054658, 96.390, 2896.0, 53.8145
10.837575789, 96.390, 2772.0, 52.6498
10.890096919, 96.390, 3010.0, 54.8635
10.942618050, 96.390, 3108.0, 55.7494
10.995139181, 96.390, 3759.0, 61.3107
11.047660312, 96.390, 3267.0, 57.1577
11.100181442, 96.390, 2777.0, 52.6972
11.152702573, 96.390, 2734.0, 52.2877
11.205223704, 96.390, 2730.0, 52.2494
11.257744834, 96.390, 2700.0, 51.9615
11.310265965, 96.390, 2732.0, 52.2685
11.362787096, 96.390, 2753.0, 52.4690
11.415308227, 96.390, 2651.0, 51.4879
11.467829357, 96.390, 2716.0, 52.1153
11.520350488, 96.390, 2692.0, 51.8845
11.572871619, 96.390, 2701.0, 51.9711
11.625392749, 96.390, 2604.0, 51.0294
11.677913880, 96.390, 2716.0, 52.1153
11.730435011, 96.390, 2583.0, 50.8232
11.782956141, 96.390, 2604.0, 51.0294
11.835477272, 96.390, 2677.0, 51.7397
11.887998403, 96.390, 2606.0, 51.0490
11.940519534, 96.390, 2645.0, 51.4296
11.993040664, 96.390, 2612.0, 51.1077
12.045561795, 96.390, 2526.0, 50.2593
12.098082926, 96.390, 2511.0, 50.1099
12.150604056, 96.390, 2562.0, 50.6162
12.203125187, 96.390, 2573.0, 50.7247
12.255646318, 96.390, 2551.0, 50.5074
12.308167449, 96.390, 2463.0, 49.6286
12.360688579, 96.390, 2491.0, 49.9099
12.413209710, 96.390, 2519.0, 50.1896
12.465730841, 96.390, 2523.0, 50.2295
12.518251971, 96.390, 2501.0, 50.0100
12.570773102, 96.390, 2421.0, 49.2037
12.623294233, 96.390, 2306.0, 48.0208
12.675815364, 96.390, 2493.0, 49.9300
12.728336494, 96.390, 2447.0, 49.4672
12.780857625, 96.390, 2409.0, 49.0816
12.833378756, 96.390, 2397.0, 48.9592
12.885899886, 96.390, 2504.0, 50.0400
12.938421017, 96.390, 2452.0, 49.5177
12.990942148, 96.390, 2378.0, 48.7647
13.043463279, 96.390, 2420.0, 49.1935
13.095984409, 96.390, 2242.0, 47.3498
13.148505540, 96.390, 2389.0, 48.8774
13.201026671, 96.390, 2322.0, 48.1871
13.253547801, 96.390, 2260.0, 47.5395
13.306068932, 96.390, 2382.0, 48.8057
13.358590063, 96.390, 2368.0, 48.6621
13.411111193, 96.390, 2348.0, 48.4562
13.463632324, 96.390, 2316.0, 48.1248
13.516153455, 96.390, 2414.0, 49.1325
13.568674586, 96.390, 2357.0, 48.5489
13.621195716, 96.390, 2385.0, 48.8365
13.673716847, 96.390, 2547.0, 50.4678
13.726237978, 96.390, 2699.0, 51.9519
13.778759108, 96.390, 3287.0, 57.3324
13.831280239, 96.390, 3076.0, 55.4617
13.883801370, 96.390, 2342.0, 48.3942
13.936322501, 96.390, 2364.0, 48.6210
13.988843631, 96.390, 2320.0, 48.1664
14.041364762, 96.390, 2317.0, 48.1352
14.093885893, 96.390, 2498.0, 49.9800
14.146407023, 96.390, 2445.0, 49.4469
14.198928154, 96.390, 2797.0, 52.8867
14.251449285, 96.390, 4197.0, 64.7843
14.303970416, 96.390, 6457.0, 80.3555
14.356491546, 96.390, 2733.0, 52.2781
14.409012677, 96.390, 2356.0, 48.5386
14.461533808, 96.390, 2351.0, 48.4871
14.514054938, 96.390, 2376.0, 48.7442
14.566576069, 96.390, 2373.0, 48.7134
14.619097200, 96.390, 2234.0, 47.2652
14.671618331, 96.390, 2263.0, 47.5710
14.724139461, 96.390, 2187.0, 46.7654
14.776660592, 96.390, 2173.0, 46.6154
14.829181723, 96.390, 2183.0, 46.7226
14.881702853, 96.390, 2334.0, 48.3115
14.934223984, 96.390, 2236.0, 47.2864
14.986745115, 96.390, 2187.0, 46.7654
15.039266245, 96.390, 2281.0, 47.7598
15.091787376, 96.390, 2178.0, 46.6690
15.144308507, 96.390, 2299.0, 47.9479
15.196829638, 96.390, 2386.0, 48.8467
15.249350768, 96.390, 2321.0, 48.1768
15.301871899, 96.390, 2215.0, 47.0638
15.354393030, 96.390, 2246.0, 47.3920
15.406914160, 96.390, 2245.0, 47.3814
15.459435291, 96.390, 2277.0, 47.7179
15.511956422, 96.390, 2151.0, 46.3789
15.564477553, 96.390, 2263.0, 47.5710
15.616998683, 96.390, 2254.0, 47.4763
15.669519814, 96.390, 2236.0, 47.2864
15.722040945, 96.390, 2330.0, 48.2701
15.774562075, 96.390, 2203.0, 46.9361
15.827083206, 96.390, 2369.0, 48.6724
15.879604337, 96.390, 2278.0, 47.7284
15.932125468, 96.390, 2245.0, 47.3814
15.984646598, 96.390, 2372.0, 48.7032
16.037167729, 96.390, 2334.0, 48.3115
16.089688860, 96.390, 2320.0, 48.1664
16.142209990, 96.390, 2205.0, 46.9574
16.194731121, 96.390, 2285.0, 47.8017
16.247252252, 96.390, 2441.0, 49.4065
16.299773382, 96.390, 2468.0, 49.6790
16.352294513, 96.390, 2400.0, 48.9898
16.404815644, 96.390, 2289.0, 47.8435
16.457336775, 96.390, 2325.0, 48.2183
16.509857905, 96.390, 2291.0, 47.8644
16.562379036, 96.390, 2369.0, 48.6724
16.614900167, 96.390, 2286.0, 47.8121
16.667421297, 96.390, 2320.0, 48.1664
16.719942428, 96.390, 2267.0, 47.6130
16.772463559, 96.390, 2439.0, 49.3862
16.824984690, 96.390, 2296.0, 47.9166
16.877505820, 96.390, 2358.0, 48.5592
16.930026951, 96.390, 2560.0, 50.5964
16.982548082, 96.390, 2395.0, 48.9387
17.035069212, 96.390, 2231.0, 47.2335
17.087590343, 96.390, 2310.0, 48.0625
17.140111474, 96.390, 2355.0, 48.5283
17.192632605, 96.390, 2278.0, 47.7284
17.245153735, 96.390, 2259.0, 47.5289
17.297674866, 96.390, 2402.0, 49.0102
17.350195997, 96.390, 2462.0, 49.6185
17.402717127, 96.390, 2630.0, 51.2835
17.455238258, 96.390, 2453.0, 49.5278
17.507759389, 96.390, 2308.0, 48.0416
17.560280520, 96.390, 2229.0, 47.2123
17.612801650, 96.390, 2262.0, 47.5605
17.665322781, 96.390, 2214.0, 47.0532
17.717843912, 96.390, 2257.0, 47.5079
17.770365042, 96.390, 2196.0, 46.8615
17.822886173, 96.390, 2153.0, 46.4004
17.875407304, 96.390, 2110.0, 45.9347
17.927928434, 96.390, 2101.0, 45.8367
17.980449565, 96.390, 2135.0, 46.2061
18.032970696, 96.390, 2226.0, 47.1805
18.085491827, 96.390, 2370.0, 48.6826
18.138012957, 96.390, 2364.0, 48.6210
18.190534088, 96.390, 2281.0, 47.7598
18.243055219, 96.390, 2591.0, 50.9019
18.295576349, 96.390, 2850.0, 53.3854
18.348097480, 96.390, 2551.0, 50.5074
18.400618611, 96.390, 2603.0, 51.0196
18.453139742, 96.390, 2874.0, 53.6097
18.505660872, 96.390, 2445.0, 49.4469
18.558182003, 96.390, 2132.0, 46.1736
18.610703134, 96.390, 2181.0, 46.7012
18.663224264, 96.390, 2084.0, 45.6508
18.715745395, 96.390, 2091.0, 45.7275
18.768266526, 96.390, 2221.0, 47.1275
18.820787657, 96.390, 2211.0, 47.0213
18.873308787, 96.390, 2396.0, 48.9490
18.925829918, 96.390, 2594.0, 50.9313
18.978351049, 96.390, 2726.0, 52.2111
19.030872179, 96.390, 2589.0, 50.8822
19.083393310, 96.390, 2207.0, 46.9787
19.135914441, 96.390, 2334.0, 48.3115
19.188435572, 96.390, 2191.0, 46.8081
19.240956702, 96.390, 2182.0, 46.7119
19.293477833, 96.390, 2234.0, 47.2652
19.345998964, 96.390, 2236.0, 47.2864
19.398520094, 96.390, 2336.0, 48.3322
19.451041225, 96.390, 2546.0, 50.4579
19.503562356, 96.390, 2697.0, 51.9326
19.556083486, 96.390, 2388.0, 48.8672
19.608604617, 96.390, 2227.0, 47.1911
19.661125748, 96.390, 2445.0, 49.4469
19.713646879, 96.390, 2675.0, 51.7204
19.766168009, 96.390, 3289.0, 57.3498
19.818689140, 96.390, 2881.0, 53.6749
19.871210271, 96.390, 2445.0, 49.4469
19.923731401, 96.390, 2273.0, 47.6760
19.976252532, 96.390, 2398.0, 48.9694
20.028773663, 96.390, 2319.0, 48.1560
20.081294794, 96.390, 2268.0, 47.6235
20.133815924, 96.390, 2229.0, 47.2123
20.186337055, 96.390, 2378.0, 48.7647
20.238858186, 96.390, 2372.0, 48.7032
20.291379316, 96.390, 2479.0, 49.7896
20.343900447, 96.390, 2782.0, 52.7447
20.396421578, 96.390, 3606.0, 60.0500
20.448942709, 96.390, 4080.0, 63.8749
20.501463839, 96.390, 3169.0, 56.2939
20.553984970, 96.390, 2702.0, 51.9808
20.606506101, 96.390, 3185.0, 56.4358
20.659027231, 96.390, 2900.0, 53.8516
20.711548362, 96.390, 2601.0, 51.0000
20.764069493, 96.390, 2454.0, 49.5379
20.816590623, 96.390, 2447.0, 49.4672
20.869111754, 96.390, 2333.0, 48.3011
20.921632885, 96.390, 2429.0, 49.2849
20.974154016, 96.390, 2646.0, 51.4393
21.026675146, 96.390, 2574.0, 50.7346
21.079196277, 96.390, 2386.0, 48.8467
21.131717408, 96.390, 2335.0, 48.3218
21.184238538, 96.390, 2365.0, 48.6313
21.236759669, 96.390, 2312.0, 48.0833
21.289280800, 96.390, 2434.0, 49.3356
21.341801931, 96.390, 2384.0, 48.8262
21.394323061, 96.390, 2401.0, 49.0000
21.446844192, 96.390, 2345.0, 48.4252
21.499365323, 96.390, 2449.0, 49.4874
21.551886453, 96.390, 2351.0, 48.4871
21.604407584, 96.390, 2448.0, 49.4773
21.656928715, 96.390, 2597.0, 50.9608
21.709449846, 96.390, 2793.0, 52.8488
21.761970976, 96.390, 2697.0, 51.9326
21.814492107, 96.390, 2417.0, 49.1630
21.867013238, 96.390, 2364.0, 48.6210
21.919534368, 96.390, 2357.0, 48.5489
21.972055499, 96.390, 2383.0, 48.8160
22.024576630, 96.390, 2355.0, 48.5283
22.077097761, 96.390, 2502.0, 50.0200
22.129618891, 96.390, 2450.0, 49.4975
22.182140022, 96.390, 2423.0, 49.2240
22.234661153, 96.390, 2395.0, 48.9387
22.287182283, 96.390, 2424.0, 49.2341
22.339703414, 96.390, 2466.0, 49.6588
22.392224545, 96.390, 2496.0, 49.9600
22.444745675, 96.390, 2522.0, 50.2195
22.497266806, 96.390, 2453.0, 49.5278
22.549787937, 96.390, 2610.0, 51.0882
22.602309068, 96.390, 2614.0, 51.1273
22.654830198, 96.390, 2434.0, 49.3356
22.707351329, 96.390, 2493.0, 49.9300
22.759872460, 96.390, 2451.0, 49.5076
22.812393590, 96.390, 2609.0, 51.0784
22.864914721, 96.390, 2713.0, 52.0865
22.917435852, 96.390, 2613.0, 51.1175
22.969956983, 96.390, 2535.0, 50.3488
23.022478113, 96.390, 2585.0, 50.8429
23.074999244, 96.390, 2712.0, 52.0769
23.127520375, 96.390, 2556.0, 50.5569
23.180041505, 96.390, 2722.0, 52.1728
23.232562636, 96.390, 2674.0, 51.7107
23.285083767, 96.390, 2595.0, 50.9411
23.337604898, 96.390, 2570.0, 50.6952
23.390126028, 96.390, 2729.0, 52.2398
23.442647159, 96.390, 2889.0, 53.7494
23.495168290, 96.390, 3818.0, 61.7900
23.547689420, 96.390, 3549.0, 59.5735
23.600210551, 96.390, 2827.0, 53.1695
23.652731682, 96.390, 2593.0, 50.9215
23.705252813, 96.390, 2517.0, 50.1697
23.757773943, 96.390, 2509.0, 50.0899
23.810295074, 96.390, 2490.0, 49.8999
23.862816205, 96.390, 2447.0, 49.4672
23.915337335, 96.390, 2453.0, 49.5278
23.967858466, 96.390, 2498.0, 49.9800
24.020379597, 96.390, 2575.0, 50.7445
24.072900727, 96.390, 2749.0, 52.4309
24.125421858, 96.390, 2771.0, 52.6403
24.177942989, 96.390, 3076.0, 55.4617
24.230464120, 96.390, 3368.0, 58.0345
24.282985250, 96.390, 3435.0, 58.6089
24.335506381, 96.390, 3123.0, 55.8838
24.388027512, 96.390, 2660.0, 51.5752
24.440548642, 96.390, 2601.0, 51.0000
24.493069773, 96.390, 2650.0, 51.4782
24.545590904, 96.390, 3214.0, 56.6922
24.598112035, 96.390, 2997.0, 54.7449
24.650633165, 96.390, 2793.0, 52.8488
24.703154296, 96.390, 2476.0, 49.7594
24.755675427, 96.390, 2517.0, 50.1697
24.808196557, 96.390, 2462.0, 49.6185
24.860717688, 96.390, 2542.0, 50.4183
24.913238819, 96.390, 2406.0, 49.0510
24.965759950, 96.390, 2487.0, 49.8698
25.018281080, 96.390, 2558.0, 50.5767
25.070802211, 96.390, 2495.0, 49.9500
25.123323342, 96.390, 2452.0, 49.5177
25.175844472, 96.390, 2558.0, 50.5767
25.228365603, 96.390, 2410.0, 49.0918
25.280886734, 96.390, 2543.0, 50.4282
25.333407864, 96.390, 2551.0, 50.5074
25.385928995, 96.390, 2678.0, 51.7494
25.438450126, 96.390, 2779.0, 52.7162
25.490971257, 96.390, 2541.0, 50.4083
25.543492387, 96.390, 2340.0, 48.3735
25.596013518, 96.390, 2343.0, 48.4045
25.648534649, 96.390, 2380.0, 48.7852
25.701055779, 96.390, 2449.0, 49.4874
25.753576910, 96.390, 2452.0, 49.5177
25.806098041, 96.390, 2584.0, 50.8331
25.858619172, 96.390, 3523.0, 59.3549
25.911140302, 96.390, 2756.0, 52.4976
25.963661433, 96.390, 2487.0, 49.8698
26.016182564, 96.390, 2398.0, 48.9694
26.068703694, 96.390, 2292.0, 47.8748
26.121224825, 96.390, 2264.0, 47.5815
26.173745956, 96.390, 2345.0, 48.4252
26.226267087, 96.390, 2284.0, 47.7912
26.278788217, 96.390, 2361.0, 48.5901
26.331309348, 96.390, 2367.0, 48.6518
26.383830479, 96.390, 2407.0, 49.0612
26.436351609, 96.390, 2208.0, 46.9894
26.488872740, 96.390, 2355.0, 48.5283
26.541393871, 96.390, 2330.0, 48.2701
26.593915002, 96.390, 2254.0, 47.4763
26.646436132, 96.390, 2302.0, 47.9792
26.698957263, 96.390, 2346.0, 48.4355
26.751478394, 96.390, 2459.0, 49.5883
26.803999524, 96.390, 2430.0, 49.2950
26.856520655, 96.390, 2486.0, 49.8598
26.909041786, 96.390, 2445.0, 49.4469
26.961562916, 96.390, 2489.0, 49.8899
27.014084047, 96.390, 2562.0, 50.6162
27.066605178, 96.390, 2357.0, 48.5489
27.119126309, 96.390, 2446.0, 49.4571
27.171647439, 96.390, 2617.0, 51.1566
27.224168570, 96.390, 2656.0, 51.5364
27.276689701, 96.390, 2620.0, 51.1859
27.329210831, 96.390, 2568.0, 50.6754
27.381731962, 96.390, 2444.0, 49.4368
27.434253093, 96.390, 2389.0, 48.8774
27.486774224, 96.390, 2311.0, 48.0729
27.539295354, 96.390, 2305.0, 48.0104
27.591816485, 96.390, 2381.0, 48.7955
27.644337616, 96.390, 2525.0, 50.2494
27.696858746, 96.390, 2608.0, 51.0686
27.749379877, 96.390, 2471.0, 49.7092
27.801901008, 96.390, 2394.0, 48.9285
27.854422139, 96.390, 2408.0, 49.0714
27.906943269, 96.390, 2423.0, 49.2240
27.959464400, 96.390, 2175.0, 46.6369
28.011985531, 96.390, 2304.0, 48.0000
28.064506661, 96.390, 2280.0, 47.7493
28.117027792, 96.390, 2375.0, 48.7340
28.169548923, 96.390, 2367.0, 48.6518
28.222070054, 96.390, 2386.0, 48.8467
28.274591184, 96.390, 2558.0, 50.5767
28.327112315, 96.390, 2377.0, 48.7545
28.379633446, 96.390, 2350.0, 48.4768
28.432154576, 96.390, 2481.0, 49.8096
28.484675707, 96.390, 2374.0, 48.7237
28.537196838, 96.390, 2348.0, 48.4562
28.589717968, 96.390, 2278.0, 47.7284
28.642239099, 96.390, 2258.0, 47.5184
28.694760230, 96.390, 2262.0, 47.5605
28.747281361, 96.390, 2226.0, 47.1805
28.799802491, 96.390, 2325.0, 48.2183
28.852323622, 96.390, 2309.0, 48.0521
28.904844753, 96.390, 2298.0, 47.9375
28.957365883, 96.390, 2267.0, 47.6130
29.009887014, 96.390, 2325.0, 48.2183
29.062408145, 96.390, 2233.0, 47.2546
29.114929276, 96.390, 2496.0, 49.9600
29.167450406, 96.390, 2406.0, 49.0510
29.219971537, 96.390, 2417.0, 49.1630
29.272492668, 96.390, 2346.0, 48.4355
29.325013798, 96.390, 2430.0, 49.2950
29.377534929, 96.390, 2476.0, 49.7594
29.430056060, 96.390, 2352.0, 48.4974
29.482577191, 96.390, 2419.0, 49.1833
29.535098321, 96.390, 2273.0, 47.6760
29.587619452, 96.390, 2372.0, 48.7032
29.640140583, 96.390, 2416.0, 49.1528
29.692661713, 96.390, 2289.0, 47.8435
29.745182844, 96.390, 2307.0, 48.0312
29.797703975, 96.390, 2097.0, 45.7930
29.850225105, 96.390, 2273.0, 47.6760
29.902746236, 96.390, 2239.0, 47.3181
29.955267367, 96.390, 2149.0, 46.3573
30.007788498, 96.390, 2176.0, 46.6476
30.060309628, 96.390, 2111.0, 45.9456
30.112830759, 96.390, 2253.0, 47.4658
30.165351890, 96.390, 2191.0, 46.8081
30.217873020, 96.390, 2199.0, 46.8935
30.270394151, 96.390, 2101.0, 45.8367
30.322915282, 96.390, 2076.0, 45.5631
30.375436413, 96.390, 2197.0, 46.8722
30.427957543, 96.390, 2320.0, 48.1664
30.480478674, 96.390, 2549.0, 50.4876
30.532999805, 96.390, 2656.0, 51.5364
30.585520935, 96.390, 2594.0, 50.9313
30.638042066, 96.390, 2932.0, 54.1479
30.690563197, 96.390, 3729.0, 61.0655
30.743084328, 96.390, 3383.0, 58.1636
30.795605458, 96.390, 2616.0, 51.1468
30.848126589, 96.390, 2300.0, 47.9583
30.900647720, 96.390, 2302.0, 47.9792
30.953168850, 96.390, 2683.0, 51.7977
31.005689981, 96.390, 2602.0, 51.0098
31.058211112, 96.390, 2428.0, 49.2747
31.110732243, 96.390, 2357.0, 48.5489
31.163253373, 96.390, 2180.0, 46.6905
31.215774504, 96.390, 2238.0, 47.3075
31.268295635, 96.390, 2219.0, 47.1063
31.320816765, 96.390, 2390.0, 48.8876
31.373337896, 96.390, 2504.0, 50.0400
31.425859027, 96.390, 2314.0, 48.1041
31.478380157, 96.390, 2323.0, 48.1975
31.530901288, 96.390, 2339.0, 48.3632
31.583422419, 96.390, 2371.0, 48.6929
31.635943550, 96.390, 2536.0, 50.3587
31.688464680, 96.390, 2952.0, 54.3323
31.740985811, 96.390, 4362.0, 66.0454
31.793506942, 96.390, 2933.0, 54.1572
31.846028072, 96.390, 2527.0, 50.2693
31.898549203, 96.390, 2431.0, 49.3052
31.951070334, 96.390, 2664.0, 51.6140
32.003591465, 96.390, 2566.0, 50.6557
32.056112595, 96.390, 2381.0, 48.7955
32.108633726, 96.390, 2284.0, 47.7912
32.161154857, 96.390, 2134.0, 46.1952
32.213675987, 96.390, 2152.0, 46.3897
32.266197118, 96.390, 2095.0, 45.7712
32.318718249, 96.390, 2179.0, 46.6798
32.371239380, 96.390, 2188.0, 46.7761
32.423760510, 96.390, 2002.0, 44.7437
32.476281641, 96.390, 1945.0, 44.1022
32.528802772, 96.390, 1840.0, 42.8952
32.581323902, 96.390, 1967.0, 44.3509
32.633845033, 96.390, 2231.0, 47.2335
32.686366164, 96.390, 2193.0, 46.8295
32.738887295, 96.390, 2116.0, 46.0000
32.791408425, 96.390, 2018.0, 44.9222
32.843929556, 96.390, 2037.0, 45.1331
32.896450687, 96.390, 2041.0, 45.1774
32.948971817, 96.390, 2481.0, 49.8096
33.001492948, 96.390, 2442.0, 49.4166
33.054014079, 96.390, 2505.0, 50.0500
33.106535209, 96.390, 2564.0, 50.6360
33.159056340, 96.390, 2732.0, 52.2685
33.211577471, 96.390, 2510.0, 50.0999
33.264098602, 96.390, 2336.0, 48.3322
33.316619732, 96.390, 2389.0, 48.8774
33.369140863, 96.390, 2800.0, 52.9150
33.421661994, 96.390, 4718.0, 68.6877
33.474183124, 96.390, 6791.0, 82.4075
33.526704255, 96.390, 5524.0, 74.3236
33.579225386, 96.390, 2751.0, 52.4500
33.631746517, 96.390, 1989.0, 44.5982
33.684267647, 96.390, 1879.0, 43.3474
33.736788778, 96.390, 1942.0, 44.0681
33.789309909, 96.390, 1928.0, 43.9090
33.841831039, 96.390, 2217.0, 47.0850
33.894352170, 96.390, 2373.0, 48.7134
33.946873301, 96.390, 2736.0, 52.3068
33.999394432, 96.390, 2337.0, 48.3425
34.051915562, 96.390, 2368.0, 48.6621
34.104436693, 96.390, 1965.0, 44.3283
34.156957824, 96.390, 1833.0, 42.8135
34.209478954, 96.390, 2054.0, 45.3211
34.262000085, 96.390, 2260.0, 47.5395
34.314521216, 96.390, 2635.0, 51.3323
34.367042346, 96.390, 2358.0, 48.5592
34.419563477, 96.390, 2444.0, 49.4368
34.472084608, 96.390, 2292.0, 47.8748
34.524605739, 96.390, 2303.0, 47.9896
34.577126869, 96.390, 2360.0, 48.5798
34.629648000, 96.390, 2300.0, 47.9583
34.682169131, 96.390, 2486.0, 49.8598
34.734690261, 96.390, 2304.0, 48.0000
34.787211392, 96.390, 2210.0, 47.0106
34.839732523, 96.390, 2226.0, 47.1805
34.892253654, 96.390, 2255.0, 47.4868
34.944774784, 96.390, 2535.0, 50.3488
34.997295915, 96.390, 2877.0, 53.6377
35.049817046, 96.390, 2936.0, 54.1849
35.102338176, 96.390, 2654.0, 51.5170
35.154859307, 96.390, 2344.0, 48.4149
35.207380438, 96.390, 2476.0, 49.7594
35.259901569, 96.390, 2225.0, 47.1699
35.312422699, 96.390, 2164.0, 46.5188
35.364943830, 96.390, 2035.0, 45.1110
35.417464961, 96.390, 1995.0, 44.6654
35.469986091, 96.390, 2016.0, 44.8999
35.522507222, 96.390, 2037.0, 45.1331
35.575028353, 96.390, 2010.0, 44.8330
35.627549484, 96.390, 2011.0, 44.8442
35.680070614, 96.390, 2043.0, 45.1996
35.732591745, 96.390, 1971.0, 44.3959
35.785112876, 96.390, 1986.0, 44.5646
35.837634006, 96.390, 2081.0, 45.6180
35.890155137, 96.390, 1990.0, 44.6094
35.942676268, 96.390, 2155.0, 46.4220
35.995197398, 96.390, 2253.0, 47.4658
36.047718529, 96.390, 1991.0, 44.6206
36.100239660, 96.390, 2035.0, 45.1110
36.152760791, 96.390, 1798.0, 42.4028
36.205281921, 96.390, 1893.0, 43.5086
36.257803052, 96.390, 1885.0, 43.4166
36.310324183, 96.390, 1920.0, 43.8178
36.362845313, 96.390, 2195.0, 46.8508
36.415366444, 96.390, 1912.0, 43.7264
36.467887575, 96.390, 1915.0, 43.7607
36.520408706, 96.390, 1631.0, 40.3856
36.572929836, 96.390, 1751.0, 41.8450
36.625450967, 96.390, 1736.0, 41.6653
36.677972098, 96.390, 1821.0, 42.6732
36.730493228, 96.390, 1718.0, 41.4488
36.783014359, 96.390, 1739.0, 41.7013
36.835535490, 96.390, 1535.0, 39.1791
36.888056621, 96.390, 1611.0, 40.1373
36.940577751, 96.390, 1625.0, 40.3113
36.993098882, 96.390, 1544.0, 39.2938
37.045620013, 96.390, 1629.0, 40.3609
37.098141143, 96.390, 1659.0, 40.7308
37.150662274, 96.390, 1532.0, 39.1408
37.203183405, 96.390, 1596.0, 39.9500
37.255704535, 96.390, 1621.0, 40.2616
37.308225666, 96.390, 1543.0, 39.2810
37.360746797, 96.390, 1550.0, 39.3700
37.413267928, 96.390, 1708.0, 41.3280
37.465789058, 96.390, 1535.0, 39.1791
37.518310189, 96.390, 1544.0, 39.2938
37.570831320, 96.390, 1546.0, 39.3192
37.623352450, 96.390, 1615.0, 40.1871
37.675873581, 96.390, 1560.0, 39.4968
37.728394712, 96.390, 1629.0, 40.3609
37.780915843, 96.390, 1702.0, 41.2553
37.833436973, 96.390, 2075.0, 45.5522
37.885958104, 96.390, 1907.0, 43.6692
37.938479235, 96.390, 1766.0, 42.0238
37.991000365, 96.390, 1583.0, 39.7869
38.043521496, 96.390, 1580.0, 39.7492
38.096042627, 96.390, 1539.0, 39.2301
38.148563758, 96.390, 1776.0, 42.1426
38.201084888, 96.390, 1963.0, 44.3058
38.253606019, 96.390, 1918.0, 43.7950
38.306127150, 96.390, 2015.0, 44.8888
38.358648280, 96.390, 1648.0, 40.5956
38.411169411, 96.390, 1627.0, 40.3361
38.463690542, 96.390, 1561.0, 39.5095
38.516211673, 96.390, 1449.0, 38.0657
38.568732803, 96.390, 1453.0, 38.1182
38.621253934, 96.390, 1433.0, 37.8550
38.673775065, 96.390, 1446.0, 38.0263
38.726296195, 96.390, 1504.0, 38.7814
38.778817326, 96.390, 1435.0, 37.8814
38.831338457, 96.390, 1380.0, 37.1484
38.883859587, 96.390, 1466.0, 38.2884
38.936380718, 96.390, 1412.0, 37.5766
38.988901849, 96.390, 1516.0, 38.9358
39.041422980, 96.390, 1386.0, 37.2290
39.093944110, 96.390, 1495.0, 38.6652
39.146465241, 96.390, 1644.0, 40.5463
39.198986372, 96.390, 2244.0, 47.3709
39.251507502, 96.390, 2337.0, 48.3425
39.304028633, 96.390, 1873.0, 43.2782
39.356549764, 96.390, 1827.0, 42.7434
39.409070895, 96.390, 1462.0, 38.2361
39.461592025, 96.390, 1455.0, 38.1445
39.514113156, 96.390, 1395.0, 37.3497
39.566634287, 96.390, 1461.0, 38.2230
39.619155417, 96.390, 1386.0, 37.2290
39.671676548, 96.390, 1463.0, 38.2492
39.724197679, 96.390, 1435.0, 37.8814
39.776718810, 96.390, 1709.0, 41.3401
39.829239940, 96.390, 1594.0, 39.9249
39.881761071, 96.390, 1545.0, 39.3065
39.934282202, 96.390, 1504.0, 38.7814
39.986803332, 96.390, 1313.0, 36.2353
40.039324463, 96.390, 1409.0, 37.5366
40.091845594, 96.390, 1502.0, 38.7556
40.144366725, 96.390, 1554.0, 39.4208
40.196887855, 96.390, 1531.0, 39.1280
40.249408986, 96.390, 1419.0, 37.6696
40.301930117, 96.390, 1392.0, 37.3095
40.354451247, 96.390, 1252.0, 35.3836
40.406972378, 96.390, 1333.0, 36.5103
40.459493509, 96.390, 1265.0, 35.5668
40.512014639, 96.390, 1266.0, 35.5809
40.564535770, 96.390, 1356.0, 36.8239
40.617056901, 96.390, 1322.0, 36.3593
40.669578032, 96.390, 1322.0, 36.3593
40.722099162, 96.390, 1322.0, 36.3593
40.774620293, 96.390, 1254.0, 35.4119
40.827141424, 96.390, 1263.0, 35.5387
40.879662554, 96.390, 1235.0, 35.1426
40.932183685, 96.390, 1201.0, 34.6554
40.984704816, 96.390, 1315.0, 36.2629
41.037225947, 96.390, 1265.0, 35.5668
41.089747077, 96.390, 1263.0, 35.5387
41.142268208, 96.390, 1286.0, 35.8608
41.194789339, 96.390, 1228.0, 35.0428
41.247310469, 96.390, 1248.0, 35.3270
41.299831600, 96.390, 1352.0, 36.7696
41.352352731, 96.390, 1429.0, 37.8021
41.404873862, 96.390, 1302.0, 36.0832
41.457394992, 96.390, 1372.0, 37.0405
41.509916123, 96.390, 1332.0, 36.4966
41.562437254, 96.390, 1264.0, 35.5528
41.614958384, 96.390, 1235.0, 35.1426
41.667479515, 96.390, 1208.0, 34.7563
41.720000646, 96.390, 1283.0, 35.8190
41.772521776, 96.390, 1178.0, 34.3220
41.825042907, 96.390, 1182.0, 34.3802
41.877564038, 96.390, 1235.0, 35.1426
41.930085169, 96.390, 1234.0, 35.1283
41.982606299, 96.390, 1162.0, 34.0881
42.035127430, 96.390, 1268.0, 35.6090
42.087648561, 96.390, 1372.0, 37.0405
42.140169691, 96.390, 1670.0, 40.8656
42.192690822, 96.390, 1636.0, 40.4475
42.245211953, 96.390, 1590.0, 39.8748
42.297733084, 96.390, 1500.0, 38.7298
42.350254214, 96.390, 1270.0, 35.6371
42.402775345, 96.390, 1260.0, 35.4965
42.455296476, 96.390, 1232.0, 35.0999
42.507817606, 96.390, 1162.0, 34.0881
42.560338737, 96.390, 1222.0, 34.9571
42.612859868, 96.390, 1225.0, 35.0000
42.665380999, 96.390, 1306.0, 36.1386
42.717902129, 96.390, 1367.0, 36.9730
42.770423260, 96.390, 1346.0, 36.6879
42.822944391, 96.390, 1279.0, 35.7631
42.875465521, 96.390, 1268.0, 35.6090
42.927986652, 96.390, 1181.0, 34.3657
42.980507783, 96.390, 1190.0, 34.4964
43.033028914, 96.390, 1270.0, 35.6371
43.085550044, 96.390, 1211.0, 34.7994
43.138071175, 96.390, 1220.0, 34.9285
43.190592306, 96.390, 1148.0, 33.8821
43.243113436, 96.390, 1134.0, 33.6749
43.295634567, 96.390, 1221.0, 34.9428
43.348155698, 96.390, 1160.0, 34.0588
43.400676828, 96.390, 1157.0, 34.0147
43.453197959, 96.390, 1271.0, 35.6511
43.505719090, 96.390, 1197.0, 34.5977
43.558240221, 96.390, 1219.0, 34.9142
43.610761351, 96.390, 1173.0, 34.2491
43.663282482, 96.390, 1200.0, 34.6410
43.715803613, 96.390, 1186.0, 34.4384
43.768324743, 96.390, 1254.0, 35.4119
43.820845874, 96.390, 1242.0, 35.2420
43.873367005, 96.390, 1163.0, 34.1028
43.925888136, 96.390, 1187.0, 34.4529
43.978409266, 96.390, 1202.0, 34.6699
44.030930397, 96.390, 1191.0, 34.5109
44.083451528, 96.390, 1161.0, 34.0735
44.135972658, 96.390, 1265.0, 35.5668
44.188493789, 96.390, 1295.0, 35.9861
44.241014920, 96.390, 1339.0, 36.5923
44.293536051, 96.390, 1286.0, 35.8608
44.346057181, 96.390, 1293.0, 35.9583
44.398578312, 96.390, 1274.0, 35.6931
44.451099443, 96.390, 1152.0, 33.9411
44.503620573, 96.390, 1255.0, 35.4260
44.556141704, 96.390, 1235.0, 35.1426
44.608662835, 96.390, 1166.0, 34.1467
44.661183966, 96.390, 1187.0, 34.4529
44.713705096, 96.390, 1335.0, 36.5377
44.766226227, 96.390, 1369.0, 37.0000
44.818747358, 96.390, 1466.0, 38.2884
44.871268488, 96.390, 1335.0, 36.5377
44.923789619, 96.390, 1288.0, 35.8887
44.976310750, 96.390, 1231.0, 35.0856
45.028831880, 96.390, 1264.0, 35.5528
45.081353011, 96.390, 1227.0, 35.0286
45.133874142, 96.390, 2200.0, 46.9042
45.186395273, 96.390, 1381.0, 37.1618
45.238916403, 96.390, 1659.0, 40.7308
45.291437534, 96.390, 1386.0, 37.2290
45.343958665, 96.390, 1261.0, 35.5106
45.396479795, 96.390, 1318.0, 36.3043
45.449000926, 96.390, 1296.0, 36.0000
45.501522057, 96.390, 1195.0, 34.5688
45.554043188, 96.390, 1291.0, 35.9305
45.606564318, 96.390, 1380.0, 37.1484
45.659085449, 96.390, 1384.0, 37.2022
45.711606580, 96.390, 1202.0, 34.6699
45.764127710, 96.390, 1295.0, 35.9861
45.816648841, 96.390, 1310.0, 36.1939
45.869169972, 96.390, 1219.0, 34.9142
45.921691103, 96.390, 1196.0, 34.5832
45.974212233, 96.390, 1247.0, 35.3129
46.026733364, 96.390, 1197.0, 34.5977
46.079254495, 96.390, 1391.0, 37.2961
46.131775625, 96.390, 1569.0, 39.6106
46.184296756, 96.390, 1744.0, 41.7612
46.236817887, 96.390, 1799.0, 42.4146
46.289339017, 96.390, 1723.0, 41.5090
46.341860148, 96.390, 1735.0, 41.6533
46.394381279, 96.390, 1626.0, 40.3237
46.446902410, 96.390, 1574.0, 39.6737
46.499423540, 96.390, 1493.0, 38.6394
46.551944671, 96.390, 1410.0, 37.5500
46.604465802, 96.390, 1359.0, 36.8646
46.656986932, 96.390, 1657.0, 40.7063
46.709508063, 96.390, 1555.0, 39.4335
46.762029194, 96.390, 1414.0, 37.6032
46.814550325, 96.390, 1347.0, 36.7015
46.867071455, 96.390, 1244.0, 35.2704
46.919592586, 96.390, 1141.0, 33.7787
46.972113717, 96.390, 1189.0, 34.4819
47.024634847, 96.390, 1140.0, 33.7639
47.077155978, 96.390, 1148.0, 33.8821
47.129677109, 96.390, 1157.0, 34.0147
47.182198240, 96.390, 1169.0, 34.1906
47.234719370, 96.390, 1130.0, 33.6155
47.287240501, 96.390, 1269.0, 35.6230
47.339761632, 96.390, 1220.0, 34.9285
47.392282762, 96.390, 1204.0, 34.6987
47.444803893, 96.390, 1154.0, 33.9706
47.497325024, 96.390, 1179.0, 34.3366
47.549846155, 96.390, 1214.0, 34.8425
47.602367285, 96.390, 1121.0, 33.4813
47.654888416, 96.390, 1127.0, 33.5708
47.707409547, 96.390, 1130.0, 33.6155
47.759930677, 96.390, 1106.0, 33.2566
47.812451808, 96.390, 1143.0, 33.8083
47.864972939, 96.390, 1231.0, 35.0856
47.917494069, 96.390, 1223.0, 34.9714
47.970015200, 96.390, 1076.0, 32.8024
48.022536331, 96.390, 1159.0, 34.0441
48.075057462, 96.390, 1185.0, 34.4238
48.127578592, 96.390, 1387.0, 37.2424
48.180099723, 96.390, 1181.0, 34.3657
48.232620854, 96.390, 1174.0, 34.2637
48.285141984, 96.390, 1227.0, 35.0286
48.337663115, 96.390, 1118.0, 33.4365
48.390184246, 96.390, 1129.0, 33.6006
48.442705377, 96.390, 1304.0, 36.1109
48.495226507, 96.390, 1235.0, 35.1426
48.547747638, 96.390, 1163.0, 34.1028
48.600268769, 96.390, 1273.0, 35.6791
48.652789899, 96.390, 1148.0, 33.8821
48.705311030, 96.390, 1119.0, 33.4515
48.757832161, 96.390, 1098.0, 33.1361
48.810353292, 96.390, 1150.0, 33.9116
48.862874422, 96.390, 1123.0, 33.5112
48.915395553, 96.390, 1112.0, 33.3467
48.967916684, 96.390, 1125.0, 33.5410
49.020437814, 96.390, 1084.0, 32.9242
49.072958945, 96.390, 1101.0, 33.1813
49.125480076, 96.390, 1101.0, 33.1813
49.178001207, 96.390, 1235.0, 35.1426
49.230522337, 96.390, 1155.0, 33.9853
49.283043468, 96.390, 1097.0, 33.1210
49.335564599, 96.390, 1084.0, 32.9242
49.388085729, 96.390, 1176.0, 34.2929
49.440606860, 96.390, 1134.0, 33.6749
49.493127991, 96.390, 1078.0, 32.8329
49.545649121, 96.390, 1085.0, 32.9393
49.598170252, 96.390, 1213.0, 34.8281
49.650691383, 96.390, 1457.0, 38.1707
49.703212514, 96.390, 1489.0, 38.5876
49.755733644, 96.390, 1313.0, 36.2353
49.808254775, 96.390, 1282.0, 35.8050
49.860775906, 96.390, 1195.0, 34.5688
49.913297036, 96.390, 1028.0, 32.0624
49.965818167, 96.390, 1046.0, 32.3419
50.018339298, 96.390, 1007.0, 31.7333
50.070860429, 96.390, 996.0, 31.5595
50.123381559, 96.390, 928.0, 30.4631
50.175902690, 96.390, 1046.0, 32.3419
50.228423821, 96.390, 1083.0, 32.9090
50.280944951, 96.390, 1091.0, 33.0303
50.333466082, 96.390, 1034.0, 32.1559
50.385987213, 96.390, 1081.0, 32.8786
50.438508344, 96.390, 1080.0, 32.8634
50.491029474, 96.390, 1058.0, 32.5269
50.543550605, 96.390, 1032.0, 32.1248
50.596071736, 96.390, 1041.0, 32.2645
50.648592866, 96.390, 992.0, 31.4960
50.701113997, 96.390, 1029.0, 32.0780
50.753635128, 96.390, 931.0, 30.5123
50.806156258, 96.390, 1014.0, 31.8434
50.858677389, 96.390, 996.0, 31.5595
50.911198520, 96.390, 999.0, 31.6070
50.963719651, 96.390, 1034.0, 32.1559
51.016240781, 96.390, 1237.0, 35.1710
51.068761912, 96.390, 1202.0, 34.6699
51.121283043, 96.390, 1067.0, 32.6650
51.173804173, 96.390, 1246.0, 35.2987
51.226325304, 96.390, 1055.0, 32.4808
51.278846435, 96.390, 997.0, 31.5753
51.331367566, 96.390, 1010.0, 31.7805
51.383888696, 96.390, 1013.0, 31.8277
51.436409827, 96.390, 1330.0, 36.4692
51.488930958, 96.390, 1007.0, 31.7333
51.541452088, 96.390, 1032.0, 32.1248
51.593973219, 96.390, 1069.0, 32.6956
51.646494350, 96.390, 927.0, 30.4467
51.699015481, 96.390, 1026.0, 32.0312
51.751536611, 96.390, 988.0, 31.4325
51.804057742, 96.390, 953.0, 30.8707
51.856578873, 96.390, 988.0, 31.4325
51.909100003, 96.390, 966.0, 31.0805
51.961621134, 96.390, 987.0, 31.4166
52.014142265, 96.390, 919.0, 30.3150
52.066663396, 96.390, 935.0, 30.5778
52.119184526, 96.390, 989.0, 31.4484
52.171705657, 96.390, 997.0, 31.5753
52.224226788, 96.390, 963.0, 31.0322
52.276747918, 96.390, 1085.0, 32.9393
52.329269049, 96.390, 1160.0, 34.0588
52.381790180, 96.390, 1228.0, 35.0428
52.434311310, 96.390, 1170.0, 34.2053
52.486832441, 96.390, 1071.0, 32.7261
52.539353572, 96.390, 1117.0, 33.4215
52.591874703, 96.390, 1114.0, 33.3766
52.644395833, 96.390, 977.0, 31.2570
52.696916964, 96.390, 1070.0, 32.7109
52.749438095, 96.390, 1058.0, 32.5269
52.801959225, 96.390, 961.0, 31.0000
52.854480356, 96.390, 1053.0, 32.4500
52.907001487, 96.390, 1148.0, 33.8821
52.959522618, 96.390, 1087.0, 32.9697
53.012043748, 96.390, 973.0, 31.1929
53.064564879, 96.390, 1123.0, 33.5112
53.117086010, 96.390, 1097.0, 33.1210
53.169607140, 96.390, 1524.0, 39.0384
53.222128271, 96.390, 1146.0, 33.8526
53.274649402, 96.390, 1062.0, 32.5883
53.327170533, 96.390, 1237.0, 35.1710
53.379691663, 96.390, 1031.0, 32.1092
53.432212794, 96.390, 961.0, 31.0000
53.484733925, 96.390, 1017.0, 31.8904
53.537255055, 96.390, 893.0, 29.8831
53.589776186, 96.390, 888.0, 29.7993
53.642297317, 96.390, 891.0, 29.8496
53.694818448, 96.390, 864.0, 29.3939
53.747339578, 96.390, 986.0, 31.4006
53.799860709, 96.390, 908.0, 30.1330
53.852381840, 96.390, 990.0, 31.4643
53.904902970, 96.390, 985.0, 31.3847
53.957424101, 96.390, 1023.0, 31.9844
54.009945232, 96.390, 1046.0, 32.3419
54.062466362, 96.390, 1029.0, 32.0780
54.114987493, 96.390, 1167.0, 34.1614
54.167508624, 96.390, 1123.0, 33.5112
54.220029755, 96.390, 969.0, 31.1288
54.272550885, 96.390, 1069.0, 32.6956
54.325072016, 96.390, 1014.0, 31.8434
54.377593147, 96.390, 969.0, 31.1288
54.430114277, 96.390, 909.0, 30.1496
54.482635408, 96.390, 907.0, 30.1164
54.535156539, 96.390, 976.0, 31.2410
54.587677670, 96.390, 940.0, 30.6594
54.640198800, 96.390, 951.0, 30.8383
54.692719931, 96.390, 919.0, 30.3150
54.745241062, 96.390, 914.0, 30.2324
54.797762192, 96.390, 953.0, 30.8707
54.850283323, 96.390, 938.0, 30.6268
54.902804454, 96.390, 909.0, 30.1496
54.955325585, 96.390, 936.0, 30.5941
55.007846715, 96.390, 990.0, 31.4643
55.060367846, 96.390, 1059.0, 32.5423
55.112888977, 96.390, 1420.0, 37.6829
55.165410107, 96.390, 959.0, 30.9677
55.217931238, 96.390, 919.0, 30.3150
55.270452369, 96.390, 1112.0, 33.3467
55.322973499, 96.390, 935.0, 30.5778
55.375494630, 96.390, 880.0, 29.6648
55.428015761, 96.390, 908.0, 30.1330
55.480536892, 96.390, 872.0, 29.5296
55.533058022, 96.390, 844.0, 29.0517
55.585579153, 96.390, 886.0, 29.7658
55.638100284, 96.390, 909.0, 30.1496
55.690621414, 96.390, 854.0, 29.2233
55.743142545, 96.390, 872.0, 29.5296
55.795663676, 96.390, 911.0, 30.1828
55.848184807, 96.390, 818.0, 28.6007
55.900705937, 96.390, 854.0, 29.2233
55.953227068, 96.390, 859.0, 29.3087
56.005748199, 96.390, 844.0, 29.0517
56.058269329, 96.390, 886.0, 29.7658
56.110790460, 96.390, 881.0, 29.6816
56.163311591, 96.390, 909.0, 30.1496
56.215832722, 96.390, 857.0, 29.2746
56.268353852, 96.390, 847.0, 29.1033
56.320874983, 96.390, 933.0, 30.5450
56.373396114, 96.390, 838.0, 28.9482
56.425917244, 96.390, 791.0, 28.1247
56.478438375, 96.390, 834.0, 28.8791
56.530959506, 96.390, 823.0, 28.6880
56.583480637, 96.390, 878.0, 29.6311
56.636001767, 96.390, 881.0, 29.6816
56.688522898, 96.390, 859.0, 29.3087
56.741044029, 96.390, 841.0, 29.0000
56.793565159, 96.390, 870.0, 29.4958
56.846086290, 96.390, 793.0, 28.1603
56.898607421, 96.390, 896.0, 29.9333
56.951128551, 96.390, 795.0, 28.1957
57.003649682, 96.390, 765.0, 27.6586
57.056170813, 96.390, 872.0, 29.5296
57.108691944, 96.390, 844.0, 29.0517
57.161213074, 96.390, 789.0, 28.0891
57.213734205, 96.390, 847.0, 29.1033
57.266255336, 96.390, 889.0, 29.8161
57.318776466, 96.390, 1070.0, 32.7109
57.371297597, 96.390, 987.0, 31.4166
57.423818728, 96.390, 1008.0, 31.7490
57.476339859, 96.390, 1247.0, 35.3129
57.528860989, 96.390, 956.0, 30.9192
57.581382120, 96.390, 872.0, 29.5296
57.633903251, 96.390, 1053.0, 32.4500
57.686424381, 96.390, 1034.0, 32.1559
57.738945512, 96.390, 1018.0, 31.9061
57.791466643, 96.390, 925.0, 30.4138
57.843987774, 96.390, 1037.0, 32.2025
57.896508904, 96.390, 1037.0, 32.2025
57.949030035, 96.390, 943.0, 30.7083
58.001551166, 96.390, 870.0, 29.4958
58.054072296, 96.390, 915.0, 30.2490
58.106593427, 96.390, 858.0, 29.2916
58.159114558, 96.390, 860.0, 29.3258
58.211635689, 96.390, 825.0, 28.7228
58.264156819, 96.390, 843.0, 29.0345
58.316677950, 96.390, 835.0, 28.8964
58.369199081, 96.390, 830.0, 28.8097
58.421720211, 96.390, 781.0, 27.9464
58.474241342, 96.390, 893.0, 29.8831
58.526762473, 96.390, 846.0, 29.0861
58.579283603, 96.390, 835.0, 28.8964
58.631804734, 96.390, 818.0, 28.6007
58.684325865, 96.390, 835.0, 28.8964
58.736846996, 96.390, 828.0, 28.7750
58.789368126, 96.390, 762.0, 27.6043
58.841889257, 96.390, 787.0, 28.0535
58.894410388, 96.390, 821.0, 28.6531
58.946931518, 96.390, 843.0, 29.0345
58.999452649, 96.390, 851.0, 29.1719
59.051973780, 96.390, 813.0, 28.5132
59.104494911, 96.390, 804.0, 28.3549
59.157016041, 96.390, 776.0, 27.8568
59.209537172, 96.390, 884.0, 29.7321
59.262058303, 96.390, 857.0, 29.2746
59.314579433, 96.390, 902.0, 30.0333
59.367100564, 96.390, 901.0, 30.0167
59.419621695, 96.390, 844.0, 29.0517
59.472142826, 96.390, 793.0, 28.1603
59.524663956, 96.390, 928.0, 30.4631
59.577185087, 96.390, 832.0, 28.8444
59.629706218, 96.390, 838.0, 28.9482
59.682227348, 96.390, 838.0, 28.9482
59.734748479, 96.390, 848.0, 29.1204
59.787269610, 96.390, 871.0, 29.5127
59.839790740, 96.390, 847.0, 29.1033
59.892311871, 96.390, 800.0, 28.2843
59.944833002, 96.390, 826.0, 28.7402
59.997354133, 96.390, 888.0, 29.7993
60.049875263, 96.390, 872.0, 29.5296
60.102396394, 96.390, 900.0, 30.0000
60.154917525, 96.390, 814.0, 28.5307
60.207438655, 96.390, 867.0, 29.4449
60.259959786, 96.390, 892.0, 29.8664
60.312480917, 96.390, 912.0, 30.1993
60.365002048, 96.390, 914.0, 30.2324
60.417523178, 96.390, 1013.0, 31.8277
60.470044309, 96.390, 983.0, 31.3528
60.522565440, 96.390, 961.0, 31.0000
60.575086570, 96.390, 1079.0, 32.8481
60.627607701, 96.390, 1083.0, 32.9090
60.680128832, 96.390, 1149.0, 33.8969
60.732649963, 96.390, 1123.0, 33.5112
60.785171093, 96.390, 1146.0, 33.8526
60.837692224, 96.390, 1215.0, 34.8569
60.890213355, 96.390, 1262.0, 35.5246
60.942734485, 96.390, 1265.0, 35.5668
60.995255616, 96.390, 1315.0, 36.2629
61.047776747, 96.390, 1294.0, 35.9722
61.100297878, 96.390, 1333.0, 36.5103
61.152819008, 96.390, 1356.0, 36.8239
61.205340139, 96.390, 1482.0, 38.4968
61.257861270, 96.390, 1239.0, 35.1994
61.310382400, 96.390, 1206.0, 34.7275
61.362903531, 96.390, 1219.0, 34.9142
61.415424662, 96.390, 1183.0, 34.3948
61.467945792, 96.390, 1155.0, 33.9853
61.520466923, 96.390, 1043.0, 32.2955
61.572988054, 96.390, 1178.0, 34.3220
61.625509185, 96.390, 1150.0, 33.9116
61.678030315, 96.390, 1075.0, 32.7872
61.730551446, 96.390, 1067.0, 32.6650
61.783072577, 96.390, 1093.0, 33.0606
61.835593707, 96.390, 1028.0, 32.0624
61.888114838, 96.390, 996.0, 31.5595
61.940635969, 96.390, 1031.0, 32.1092
61.993157100, 96.390, 1026.0, 32.0312
62.045678230, 96.390, 961.0, 31.0000
62.098199361, 96.390, 953.0, 30.8707
62.150720492, 96.390, 955.0, 30.9031
62.203241622, 96.390, 1016.0, 31.8748
62.255762753, 96.390, 985.0, 31.3847
62.308283884, 96.390, 943.0, 30.7083
62.360805015, 96.390, 943.0, 30.7083
62.413326145, 96.390, 915.0, 30.2490
62.465847276, 96.390, 935.0, 30.5778
62.518368407, 96.390, 896.0, 29.9333
62.570889537, 96.390, 868.0, 29.4618
62.623410668, 96.390, 898.0, 29.9666
62.675931799, 96.390, 862.0, 29.3598
62.728452930, 96.390, 841.0, 29.0000
62.780974060, 96.390, 848.0, 29.1204
62.833495191, 96.390, 820.0, 28.6356
62.886016322, 96.390, 820.0, 28.6356
62.938537452, 96.390, 819.0, 28.6182
62.991058583, 96.390, 853.0, 29.2062
63.043579714, 96.390, 813.0, 28.5132
63.096100844, 96.390, 776.0, 27.8568
63.148621975, 96.390, 791.0, 28.1247
63.201143106, 96.390, 742.0, 27.2397
63.253664237, 96.390, 828.0, 28.7750
63.306185367, 96.390, 770.0, 27.7489
63.358706498, 96.390, 824.0, 28.7054
63.411227629, 96.390, 740.0, 27.2029
63.463748759, 96.390, 826.0, 28.7402
63.516269890, 96.390, 755.0, 27.4773
63.568791021, 96.390, 786.0, 28.0357
63.621312152, 96.390, 819.0, 28.6182
63.673833282, 96.390, 795.0, 28.1957
63.726354413, 96.390, 729.0, 27.0000
63.778875544, 96.390, 763.0, 27.6225
63.831396674, 96.390, 768.0, 27.7128
63.883917805, 96.390, 809.0, 28.4429
63.936438936, 96.390, 895.0, 29.9166
63.988960067, 96.390, 915.0, 30.2490
64.041481197, 96.390, 741.0, 27.2213
64.094002328, 96.390, 830.0, 28.8097
64.146523459, 96.390, 910.0, 30.1662
64.199044589, 96.390, 807.0, 28.4077
64.251565720, 96.390, 791.0, 28.1247
64.304086851, 96.390, 771.0, 27.7669
64.356607981, 96.390, 792.0, 28.1425
64.409129112, 96.390, 688.0, 26.2298
64.461650243, 96.390, 690.0, 26.2679
64.514171374, 96.390, 727.0, 26.9629
64.566692504, 96.390, 715.0, 26.7395
64.619213635, 96.390, 748.0, 27.3496
64.671734766, 96.390, 755.0, 27.4773
64.724255896, 96.390, 775.0, 27.8388
64.776777027, 96.390, 770.0, 27.7489
64.829298158, 96.390, 761.0, 27.5862
64.881819289, 96.390, 822.0, 28.6705
64.934340419, 96.390, 747.0, 27.3313
64.986861550, 96.390, 732.0, 27.0555