File: Files_organized_for_plots/Constant_NaOH_1mL10M_to_1gPC_28Day/XRD_SiCornernul_Act03May22_B1_0833M_NaOH_LS0152_1.csv
[Measurement conditions]
Sample identification,XRD_SiCornernul_Act03May22_B1_0714M_NaOH_LS0173_1
Comment - 1,"Configuration=Stage for Flat Samples/Holders, Owner=User-1, Creation date=7/1/2020 9:53:24 AM"
Comment - 2,"Goniometer=Theta/Theta; Minimum step size 2Theta:0.0001; Minimum step size Omega:0.0001"
Comment - 3,"Sample stage=Stage for flat samples/holders"
Comment - 4,"Diffractometer system=EMPYREAN"
Comment - 5,"Measurement program=C:\Users\ibo5034\OneDrive - The Pennsylvania State University\NEUP\Zerobackground scan.xrdmp, Identifier={98A3B11C-88F9-4AA6-982C-73314A311EF5}"
Anode material,Cu
K-Alpha1 wavelength,1.5405980
K-Alpha2 wavelength,1.5444260
Ratio K-Alpha2/K-Alpha1,0.500
Divergence slit,Fixed,0.25
Monochromator used,NO
Generator voltage, 45
Tube current, 40
File date and time,03/Jun/2022 13:31
Unit cell,
h k l, 0 0 0
Scan axis,Gonio
Scan range,4.994599997,64.999991833
Scan step size,0.0262606
No. of points, 2285
Scan type,CONTINUOUS
Time per step,96.390
[Scan points]
Angle, TimePerStep, Intensity, ESD
5.007730280, 96.390, 3846.0, 62.0161
5.060251411, 96.390, 4066.0, 63.7652
5.112772541, 96.390, 3775.0, 61.4410
5.165293672, 96.390, 3795.0, 61.6036
5.217814803, 96.390, 3836.0, 61.9355
5.270335934, 96.390, 3708.0, 60.8933
5.322857064, 96.390, 3634.0, 60.2827
5.375378195, 96.390, 3723.0, 61.0164
5.427899326, 96.390, 3637.0, 60.3075
5.480420456, 96.390, 3672.0, 60.5970
5.532941587, 96.390, 3723.0, 61.0164
5.585462718, 96.390, 3543.0, 59.5231
5.637983849, 96.390, 3615.0, 60.1249
5.690504979, 96.390, 3631.0, 60.2578
5.743026110, 96.390, 3525.0, 59.3717
5.795547241, 96.390, 3455.0, 58.7792
5.848068371, 96.390, 3670.0, 60.5805
5.900589502, 96.390, 3514.0, 59.2790
5.953110633, 96.390, 3524.0, 59.3633
6.005631763, 96.390, 3451.0, 58.7452
6.058152894, 96.390, 3464.0, 58.8558
6.110674025, 96.390, 3485.0, 59.0339
6.163195156, 96.390, 3475.0, 58.9491
6.215716286, 96.390, 3407.0, 58.3695
6.268237417, 96.390, 3517.0, 59.3043
6.320758548, 96.390, 3467.0, 58.8812
6.373279678, 96.390, 3328.0, 57.6888
6.425800809, 96.390, 3475.0, 58.9491
6.478321940, 96.390, 3390.0, 58.2237
6.530843071, 96.390, 3460.0, 58.8218
6.583364201, 96.390, 3356.0, 57.9310
6.635885332, 96.390, 3515.0, 59.2874
6.688406463, 96.390, 3356.0, 57.9310
6.740927593, 96.390, 3383.0, 58.1636
6.793448724, 96.390, 3436.0, 58.6174
6.845969855, 96.390, 3330.0, 57.7062
6.898490986, 96.390, 3415.0, 58.4380
6.951012116, 96.390, 3362.0, 57.9828
7.003533247, 96.390, 3467.0, 58.8812
7.056054378, 96.390, 3390.0, 58.2237
7.108575508, 96.390, 3329.0, 57.6975
7.161096639, 96.390, 3431.0, 58.5747
7.213617770, 96.390, 3499.0, 59.1523
7.266138900, 96.390, 3428.0, 58.5491
7.318660031, 96.390, 3412.0, 58.4123
7.371181162, 96.390, 3387.0, 58.1979
7.423702293, 96.390, 3336.0, 57.7581
7.476223423, 96.390, 3429.0, 58.5577
7.528744554, 96.390, 3373.0, 58.0775
7.581265685, 96.390, 3416.0, 58.4466
7.633786815, 96.390, 3470.0, 58.9067
7.686307946, 96.390, 3469.0, 58.8982
7.738829077, 96.390, 3371.0, 58.0603
7.791350208, 96.390, 3323.0, 57.6455
7.843871338, 96.390, 3393.0, 58.2495
7.896392469, 96.390, 3423.0, 58.5064
7.948913600, 96.390, 3385.0, 58.1808
8.001434730, 96.390, 3430.0, 58.5662
8.053955861, 96.390, 3400.0, 58.3095
8.106476992, 96.390, 3425.0, 58.5235
8.158998123, 96.390, 3327.0, 57.6802
8.211519253, 96.390, 3313.0, 57.5587
8.264040384, 96.390, 3362.0, 57.9828
8.316561515, 96.390, 3389.0, 58.2151
8.369082645, 96.390, 3423.0, 58.5064
8.421603776, 96.390, 3342.0, 57.8100
8.474124907, 96.390, 3374.0, 58.0861
8.526646038, 96.390, 3507.0, 59.2199
8.579167168, 96.390, 3569.0, 59.7411
8.631688299, 96.390, 3547.0, 59.5567
8.684209430, 96.390, 3339.0, 57.7841
8.736730560, 96.390, 3313.0, 57.5587
8.789251691, 96.390, 3333.0, 57.7321
8.841772822, 96.390, 3325.0, 57.6628
8.894293952, 96.390, 3280.0, 57.2713
8.946815083, 96.390, 3250.0, 57.0088
8.999336214, 96.390, 3230.0, 56.8331
9.051857345, 96.390, 3249.0, 57.0000
9.104378475, 96.390, 3247.0, 56.9825
9.156899606, 96.390, 3269.0, 57.1752
9.209420737, 96.390, 3306.0, 57.4978
9.261941867, 96.390, 3184.0, 56.4269
9.314462998, 96.390, 3232.0, 56.8507
9.366984129, 96.390, 3351.0, 57.8878
9.419505260, 96.390, 3182.0, 56.4092
9.472026390, 96.390, 3232.0, 56.8507
9.524547521, 96.390, 3219.0, 56.7362
9.577068652, 96.390, 3096.0, 55.6417
9.629589782, 96.390, 3117.0, 55.8301
9.682110913, 96.390, 3108.0, 55.7494
9.734632044, 96.390, 3178.0, 56.3738
9.787153175, 96.390, 3122.0, 55.8749
9.839674305, 96.390, 3198.0, 56.5509
9.892195436, 96.390, 3058.0, 55.2992
9.944716567, 96.390, 3127.0, 55.9196
9.997237697, 96.390, 3127.0, 55.9196
10.049758828, 96.390, 3121.0, 55.8659
10.102279959, 96.390, 3041.0, 55.1453
10.154801090, 96.390, 3021.0, 54.9636
10.207322220, 96.390, 3228.0, 56.8155
10.259843351, 96.390, 3110.0, 55.7674
10.312364482, 96.390, 3070.0, 55.4076
10.364885612, 96.390, 3010.0, 54.8635
10.417406743, 96.390, 3068.0, 55.3895
10.469927874, 96.390, 3190.0, 56.4801
10.522449004, 96.390, 3313.0, 57.5587
10.574970135, 96.390, 3043.0, 55.1634
10.627491266, 96.390, 2891.0, 53.7680
10.680012397, 96.390, 2910.0, 53.9444
10.732533527, 96.390, 2927.0, 54.1018
10.785054658, 96.390, 3033.0, 55.0727
10.837575789, 96.390, 2903.0, 53.8795
10.890096919, 96.390, 2898.0, 53.8331
10.942618050, 96.390, 2920.0, 54.0370
10.995139181, 96.390, 2846.0, 53.3479
11.047660312, 96.390, 2877.0, 53.6377
11.100181442, 96.390, 2901.0, 53.8609
11.152702573, 96.390, 2787.0, 52.7920
11.205223704, 96.390, 2767.0, 52.6023
11.257744834, 96.390, 2864.0, 53.5164
11.310265965, 96.390, 2774.0, 52.6688
11.362787096, 96.390, 2816.0, 53.0660
11.415308227, 96.390, 2701.0, 51.9711
11.467829357, 96.390, 2760.0, 52.5357
11.520350488, 96.390, 2684.0, 51.8073
11.572871619, 96.390, 2625.0, 51.2348
11.625392749, 96.390, 2728.0, 52.2303
11.677913880, 96.390, 2712.0, 52.0769
11.730435011, 96.390, 2670.0, 51.6720
11.782956141, 96.390, 2560.0, 50.5964
11.835477272, 96.390, 2528.0, 50.2792
11.887998403, 96.390, 2580.0, 50.7937
11.940519534, 96.390, 2709.0, 52.0481
11.993040664, 96.390, 2652.0, 51.4976
12.045561795, 96.390, 2638.0, 51.3615
12.098082926, 96.390, 2556.0, 50.5569
12.150604056, 96.390, 2583.0, 50.8232
12.203125187, 96.390, 2532.0, 50.3190
12.255646318, 96.390, 2514.0, 50.1398
12.308167449, 96.390, 2576.0, 50.7543
12.360688579, 96.390, 2536.0, 50.3587
12.413209710, 96.390, 2543.0, 50.4282
12.465730841, 96.390, 2463.0, 49.6286
12.518251971, 96.390, 2436.0, 49.3559
12.570773102, 96.390, 2478.0, 49.7795
12.623294233, 96.390, 2571.0, 50.7050
12.675815364, 96.390, 2530.0, 50.2991
12.728336494, 96.390, 2652.0, 51.4976
12.780857625, 96.390, 2566.0, 50.6557
12.833378756, 96.390, 2475.0, 49.7494
12.885899886, 96.390, 2472.0, 49.7192
12.938421017, 96.390, 2397.0, 48.9592
12.990942148, 96.390, 2410.0, 49.0918
13.043463279, 96.390, 2325.0, 48.2183
13.095984409, 96.390, 2436.0, 49.3559
13.148505540, 96.390, 2368.0, 48.6621
13.201026671, 96.390, 2405.0, 49.0408
13.253547801, 96.390, 2256.0, 47.4974
13.306068932, 96.390, 2310.0, 48.0625
13.358590063, 96.390, 2320.0, 48.1664
13.411111193, 96.390, 2407.0, 49.0612
13.463632324, 96.390, 2655.0, 51.5267
13.516153455, 96.390, 2898.0, 53.8331
13.568674586, 96.390, 2782.0, 52.7447
13.621195716, 96.390, 2412.0, 49.1121
13.673716847, 96.390, 2299.0, 47.9479
13.726237978, 96.390, 2316.0, 48.1248
13.778759108, 96.390, 2530.0, 50.2991
13.831280239, 96.390, 2917.0, 54.0093
13.883801370, 96.390, 2819.0, 53.0943
13.936322501, 96.390, 2560.0, 50.5964
13.988843631, 96.390, 2443.0, 49.4267
14.041364762, 96.390, 2330.0, 48.2701
14.093885893, 96.390, 2298.0, 47.9375
14.146407023, 96.390, 2434.0, 49.3356
14.198928154, 96.390, 2527.0, 50.2693
14.251449285, 96.390, 3111.0, 55.7763
14.303970416, 96.390, 3724.0, 61.0246
14.356491546, 96.390, 2947.0, 54.2863
14.409012677, 96.390, 2262.0, 47.5605
14.461533808, 96.390, 2265.0, 47.5920
14.514054938, 96.390, 2204.0, 46.9468
14.566576069, 96.390, 2131.0, 46.1628
14.619097200, 96.390, 2147.0, 46.3357
14.671618331, 96.390, 2104.0, 45.8694
14.724139461, 96.390, 2122.0, 46.0652
14.776660592, 96.390, 2084.0, 45.6508
14.829181723, 96.390, 2144.0, 46.3033
14.881702853, 96.390, 2198.0, 46.8828
14.934223984, 96.390, 2108.0, 45.9130
14.986745115, 96.390, 2109.0, 45.9239
15.039266245, 96.390, 2259.0, 47.5289
15.091787376, 96.390, 2149.0, 46.3573
15.144308507, 96.390, 2312.0, 48.0833
15.196829638, 96.390, 2413.0, 49.1223
15.249350768, 96.390, 2753.0, 52.4690
15.301871899, 96.390, 3229.0, 56.8243
15.354393030, 96.390, 2952.0, 54.3323
15.406914160, 96.390, 2425.0, 49.2443
15.459435291, 96.390, 2261.0, 47.5500
15.511956422, 96.390, 2062.0, 45.4093
15.564477553, 96.390, 2175.0, 46.6369
15.616998683, 96.390, 1958.0, 44.2493
15.669519814, 96.390, 2085.0, 45.6618
15.722040945, 96.390, 2100.0, 45.8258
15.774562075, 96.390, 2022.0, 44.9667
15.827083206, 96.390, 1952.0, 44.1814
15.879604337, 96.390, 1990.0, 44.6094
15.932125468, 96.390, 1986.0, 44.5646
15.984646598, 96.390, 1987.0, 44.5758
16.037167729, 96.390, 2067.0, 45.4643
16.089688860, 96.390, 2006.0, 44.7884
16.142209990, 96.390, 2090.0, 45.7165
16.194731121, 96.390, 2027.0, 45.0222
16.247252252, 96.390, 1968.0, 44.3621
16.299773382, 96.390, 1954.0, 44.2041
16.352294513, 96.390, 1884.0, 43.4051
16.404815644, 96.390, 1923.0, 43.8520
16.457336775, 96.390, 1956.0, 44.2267
16.509857905, 96.390, 2000.0, 44.7214
16.562379036, 96.390, 1900.0, 43.5890
16.614900167, 96.390, 1940.0, 44.0454
16.667421297, 96.390, 1956.0, 44.2267
16.719942428, 96.390, 1976.0, 44.4522
16.772463559, 96.390, 1907.0, 43.6692
16.824984690, 96.390, 2043.0, 45.1996
16.877505820, 96.390, 2005.0, 44.7772
16.930026951, 96.390, 2029.0, 45.0444
16.982548082, 96.390, 2020.0, 44.9444
17.035069212, 96.390, 1982.0, 44.5197
17.087590343, 96.390, 1921.0, 43.8292
17.140111474, 96.390, 1930.0, 43.9318
17.192632605, 96.390, 2011.0, 44.8442
17.245153735, 96.390, 1907.0, 43.6692
17.297674866, 96.390, 2013.0, 44.8665
17.350195997, 96.390, 2081.0, 45.6180
17.402717127, 96.390, 2137.0, 46.2277
17.455238258, 96.390, 2245.0, 47.3814
17.507759389, 96.390, 2019.0, 44.9333
17.560280520, 96.390, 1950.0, 44.1588
17.612801650, 96.390, 1870.0, 43.2435
17.665322781, 96.390, 1905.0, 43.6463
17.717843912, 96.390, 1859.0, 43.1161
17.770365042, 96.390, 1893.0, 43.5086
17.822886173, 96.390, 1816.0, 42.6146
17.875407304, 96.390, 1897.0, 43.5546
17.927928434, 96.390, 1940.0, 44.0454
17.980449565, 96.390, 1907.0, 43.6692
18.032970696, 96.390, 1931.0, 43.9431
18.085491827, 96.390, 1994.0, 44.6542
18.138012957, 96.390, 2011.0, 44.8442
18.190534088, 96.390, 1990.0, 44.6094
18.243055219, 96.390, 2054.0, 45.3211
18.295576349, 96.390, 2307.0, 48.0312
18.348097480, 96.390, 2506.0, 50.0600
18.400618611, 96.390, 2254.0, 47.4763
18.453139742, 96.390, 2271.0, 47.6550
18.505660872, 96.390, 2441.0, 49.4065
18.558182003, 96.390, 2149.0, 46.3573
18.610703134, 96.390, 1991.0, 44.6206
18.663224264, 96.390, 2013.0, 44.8665
18.715745395, 96.390, 1997.0, 44.6878
18.768266526, 96.390, 2015.0, 44.8888
18.820787657, 96.390, 2018.0, 44.9222
18.873308787, 96.390, 2130.0, 46.1519
18.925829918, 96.390, 2081.0, 45.6180
18.978351049, 96.390, 2116.0, 46.0000
19.030872179, 96.390, 2264.0, 47.5815
19.083393310, 96.390, 2283.0, 47.7807
19.135914441, 96.390, 2155.0, 46.4220
19.188435572, 96.390, 2059.0, 45.3762
19.240956702, 96.390, 2001.0, 44.7325
19.293477833, 96.390, 2083.0, 45.6399
19.345998964, 96.390, 2205.0, 46.9574
19.398520094, 96.390, 2390.0, 48.8876
19.451041225, 96.390, 2664.0, 51.6140
19.503562356, 96.390, 2618.0, 51.1664
19.556083486, 96.390, 2450.0, 49.4975
19.608604617, 96.390, 2288.0, 47.8330
19.661125748, 96.390, 2271.0, 47.6550
19.713646879, 96.390, 2458.0, 49.5782
19.766168009, 96.390, 2730.0, 52.2494
19.818689140, 96.390, 2905.0, 53.8981
19.871210271, 96.390, 2929.0, 54.1202
19.923731401, 96.390, 3041.0, 55.1453
19.976252532, 96.390, 3837.0, 61.9435
20.028773663, 96.390, 4258.0, 65.2534
20.081294794, 96.390, 3082.0, 55.5158
20.133815924, 96.390, 2264.0, 47.5815
20.186337055, 96.390, 2177.0, 46.6583
20.238858186, 96.390, 2193.0, 46.8295
20.291379316, 96.390, 2292.0, 47.8748
20.343900447, 96.390, 2330.0, 48.2701
20.396421578, 96.390, 2739.0, 52.3355
20.448942709, 96.390, 3895.0, 62.4099
20.501463839, 96.390, 3453.0, 58.7622
20.553984970, 96.390, 3019.0, 54.9454
20.606506101, 96.390, 3672.0, 60.5970
20.659027231, 96.390, 4549.0, 67.4463
20.711548362, 96.390, 6577.0, 81.0987
20.764069493, 96.390, 7497.0, 86.5852
20.816590623, 96.390, 4568.0, 67.5870
20.869111754, 96.390, 2644.0, 51.4198
20.921632885, 96.390, 2524.0, 50.2394
20.974154016, 96.390, 2407.0, 49.0612
21.026675146, 96.390, 2376.0, 48.7442
21.079196277, 96.390, 2371.0, 48.6929
21.131717408, 96.390, 2313.0, 48.0937
21.184238538, 96.390, 2266.0, 47.6025
21.236759669, 96.390, 2363.0, 48.6107
21.289280800, 96.390, 2355.0, 48.5283
21.341801931, 96.390, 2365.0, 48.6313
21.394323061, 96.390, 2243.0, 47.3603
21.446844192, 96.390, 2234.0, 47.2652
21.499365323, 96.390, 2301.0, 47.9687
21.551886453, 96.390, 2300.0, 47.9583
21.604407584, 96.390, 2316.0, 48.1248
21.656928715, 96.390, 2355.0, 48.5283
21.709449846, 96.390, 2533.0, 50.3289
21.761970976, 96.390, 2594.0, 50.9313
21.814492107, 96.390, 2492.0, 49.9199
21.867013238, 96.390, 2297.0, 47.9270
21.919534368, 96.390, 2405.0, 49.0408
21.972055499, 96.390, 2494.0, 49.9400
22.024576630, 96.390, 2416.0, 49.1528
22.077097761, 96.390, 2517.0, 50.1697
22.129618891, 96.390, 2450.0, 49.4975
22.182140022, 96.390, 2611.0, 51.0979
22.234661153, 96.390, 2527.0, 50.2693
22.287182283, 96.390, 2468.0, 49.6790
22.339703414, 96.390, 2505.0, 50.0500
22.392224545, 96.390, 2427.0, 49.2646
22.444745675, 96.390, 2419.0, 49.1833
22.497266806, 96.390, 2392.0, 48.9081
22.549787937, 96.390, 2402.0, 49.0102
22.602309068, 96.390, 2483.0, 49.8297
22.654830198, 96.390, 2594.0, 50.9313
22.707351329, 96.390, 2470.0, 49.6991
22.759872460, 96.390, 2394.0, 48.9285
22.812393590, 96.390, 2452.0, 49.5177
22.864914721, 96.390, 2545.0, 50.4480
22.917435852, 96.390, 2592.0, 50.9117
22.969956983, 96.390, 2506.0, 50.0600
23.022478113, 96.390, 2546.0, 50.4579
23.074999244, 96.390, 2599.0, 50.9804
23.127520375, 96.390, 2445.0, 49.4469
23.180041505, 96.390, 2387.0, 48.8569
23.232562636, 96.390, 2419.0, 49.1833
23.285083767, 96.390, 2508.0, 50.0799
23.337604898, 96.390, 2449.0, 49.4874
23.390126028, 96.390, 2502.0, 50.0200
23.442647159, 96.390, 2571.0, 50.7050
23.495168290, 96.390, 2632.0, 51.3030
23.547689420, 96.390, 2935.0, 54.1756
23.600210551, 96.390, 2985.0, 54.6352
23.652731682, 96.390, 2838.0, 53.2729
23.705252813, 96.390, 2495.0, 49.9500
23.757773943, 96.390, 2457.0, 49.5681
23.810295074, 96.390, 2413.0, 49.1223
23.862816205, 96.390, 2434.0, 49.3356
23.915337335, 96.390, 2453.0, 49.5278
23.967858466, 96.390, 2461.0, 49.6085
24.020379597, 96.390, 2542.0, 50.4183
24.072900727, 96.390, 2576.0, 50.7543
24.125421858, 96.390, 2616.0, 51.1468
24.177942989, 96.390, 2919.0, 54.0278
24.230464120, 96.390, 3175.0, 56.3471
24.282985250, 96.390, 3127.0, 55.9196
24.335506381, 96.390, 2945.0, 54.2679
24.388027512, 96.390, 2795.0, 52.8678
24.440548642, 96.390, 2664.0, 51.6140
24.493069773, 96.390, 2662.0, 51.5946
24.545590904, 96.390, 2674.0, 51.7107
24.598112035, 96.390, 2607.0, 51.0588
24.650633165, 96.390, 2534.0, 50.3389
24.703154296, 96.390, 2494.0, 49.9400
24.755675427, 96.390, 2508.0, 50.0799
24.808196557, 96.390, 2524.0, 50.2394
24.860717688, 96.390, 2532.0, 50.3190
24.913238819, 96.390, 2506.0, 50.0600
24.965759950, 96.390, 2477.0, 49.7695
25.018281080, 96.390, 2562.0, 50.6162
25.070802211, 96.390, 2648.0, 51.4587
25.123323342, 96.390, 2550.0, 50.4975
25.175844472, 96.390, 2531.0, 50.3090
25.228365603, 96.390, 2542.0, 50.4183
25.280886734, 96.390, 2677.0, 51.7397
25.333407864, 96.390, 2811.0, 53.0189
25.385928995, 96.390, 3099.0, 55.6687
25.438450126, 96.390, 3432.0, 58.5833
25.490971257, 96.390, 3890.0, 62.3699
25.543492387, 96.390, 3413.0, 58.4209
25.596013518, 96.390, 2757.0, 52.5071
25.648534649, 96.390, 2586.0, 50.8527
25.701055779, 96.390, 2584.0, 50.8331
25.753576910, 96.390, 2684.0, 51.8073
25.806098041, 96.390, 2620.0, 51.1859
25.858619172, 96.390, 2657.0, 51.5461
25.911140302, 96.390, 2902.0, 53.8702
25.963661433, 96.390, 2880.0, 53.6656
26.016182564, 96.390, 2718.0, 52.1344
26.068703694, 96.390, 2672.0, 51.6914
26.121224825, 96.390, 2564.0, 50.6360
26.173745956, 96.390, 2520.0, 50.1996
26.226267087, 96.390, 2600.0, 50.9902
26.278788217, 96.390, 2658.0, 51.5558
26.331309348, 96.390, 2679.0, 51.7591
26.383830479, 96.390, 2692.0, 51.8845
26.436351609, 96.390, 2814.0, 53.0471
26.488872740, 96.390, 2746.0, 52.4023
26.541393871, 96.390, 2693.0, 51.8941
26.593915002, 96.390, 2659.0, 51.5655
26.646436132, 96.390, 2689.0, 51.8556
26.698957263, 96.390, 2623.0, 51.2152
26.751478394, 96.390, 2598.0, 50.9706
26.803999524, 96.390, 2684.0, 51.8073
26.856520655, 96.390, 2633.0, 51.3128
26.909041786, 96.390, 2622.0, 51.2055
26.961562916, 96.390, 2711.0, 52.0673
27.014084047, 96.390, 2889.0, 53.7494
27.066605178, 96.390, 2787.0, 52.7920
27.119126309, 96.390, 3032.0, 55.0636
27.171647439, 96.390, 3635.0, 60.2910
27.224168570, 96.390, 4103.0, 64.0547
27.276689701, 96.390, 3656.0, 60.4649
27.329210831, 96.390, 3196.0, 56.5332
27.381731962, 96.390, 2826.0, 53.1601
27.434253093, 96.390, 2702.0, 51.9808
27.486774224, 96.390, 2568.0, 50.6754
27.539295354, 96.390, 2575.0, 50.7445
27.591816485, 96.390, 2618.0, 51.1664
27.644337616, 96.390, 2551.0, 50.5074
27.696858746, 96.390, 2639.0, 51.3712
27.749379877, 96.390, 2702.0, 51.9808
27.801901008, 96.390, 2728.0, 52.2303
27.854422139, 96.390, 2552.0, 50.5173
27.906943269, 96.390, 2790.0, 52.8205
27.959464400, 96.390, 2683.0, 51.7977
28.011985531, 96.390, 2708.0, 52.0384
28.064506661, 96.390, 2665.0, 51.6236
28.117027792, 96.390, 2604.0, 51.0294
28.169548923, 96.390, 2690.0, 51.8652
28.222070054, 96.390, 2707.0, 52.0288
28.274591184, 96.390, 2749.0, 52.4309
28.327112315, 96.390, 2677.0, 51.7397
28.379633446, 96.390, 2531.0, 50.3090
28.432154576, 96.390, 2578.0, 50.7740
28.484675707, 96.390, 2454.0, 49.5379
28.537196838, 96.390, 2580.0, 50.7937
28.589717968, 96.390, 2507.0, 50.0700
28.642239099, 96.390, 2564.0, 50.6360
28.694760230, 96.390, 2559.0, 50.5866
28.747281361, 96.390, 2708.0, 52.0384
28.799802491, 96.390, 2894.0, 53.7959
28.852323622, 96.390, 2769.0, 52.6213
28.904844753, 96.390, 2649.0, 51.4684
28.957365883, 96.390, 2517.0, 50.1697
29.009887014, 96.390, 2604.0, 51.0294
29.062408145, 96.390, 2667.0, 51.6430
29.114929276, 96.390, 2880.0, 53.6656
29.167450406, 96.390, 2874.0, 53.6097
29.219971537, 96.390, 2783.0, 52.7541
29.272492668, 96.390, 2433.0, 49.3254
29.325013798, 96.390, 2381.0, 48.7955
29.377534929, 96.390, 2418.0, 49.1732
29.430056060, 96.390, 2340.0, 48.3735
29.482577191, 96.390, 2423.0, 49.2240
29.535098321, 96.390, 2340.0, 48.3735
29.587619452, 96.390, 2328.0, 48.2494
29.640140583, 96.390, 2297.0, 47.9270
29.692661713, 96.390, 2377.0, 48.7545
29.745182844, 96.390, 2315.0, 48.1144
29.797703975, 96.390, 2300.0, 47.9583
29.850225105, 96.390, 2272.0, 47.6655
29.902746236, 96.390, 2369.0, 48.6724
29.955267367, 96.390, 2272.0, 47.6655
30.007788498, 96.390, 2239.0, 47.3181
30.060309628, 96.390, 2327.0, 48.2390
30.112830759, 96.390, 2309.0, 48.0521
30.165351890, 96.390, 2257.0, 47.5079
30.217873020, 96.390, 2267.0, 47.6130
30.270394151, 96.390, 2301.0, 47.9687
30.322915282, 96.390, 2411.0, 49.1019
30.375436413, 96.390, 2318.0, 48.1456
30.427957543, 96.390, 2269.0, 47.6340
30.480478674, 96.390, 2265.0, 47.5920
30.532999805, 96.390, 2338.0, 48.3529
30.585520935, 96.390, 2483.0, 49.8297
30.638042066, 96.390, 2668.0, 51.6527
30.690563197, 96.390, 2904.0, 53.8888
30.743084328, 96.390, 3197.0, 56.5420
30.795605458, 96.390, 2998.0, 54.7540
30.848126589, 96.390, 2929.0, 54.1202
30.900647720, 96.390, 2610.0, 51.0882
30.953168850, 96.390, 2484.0, 49.8397
31.005689981, 96.390, 2355.0, 48.5283
31.058211112, 96.390, 2348.0, 48.4562
31.110732243, 96.390, 2453.0, 49.5278
31.163253373, 96.390, 2695.0, 51.9134
31.215774504, 96.390, 3332.0, 57.7235
31.268295635, 96.390, 3568.0, 59.7327
31.320816765, 96.390, 2893.0, 53.7866
31.373337896, 96.390, 2581.0, 50.8035
31.425859027, 96.390, 2452.0, 49.5177
31.478380157, 96.390, 2535.0, 50.3488
31.530901288, 96.390, 2831.0, 53.2071
31.583422419, 96.390, 2641.0, 51.3907
31.635943550, 96.390, 2633.0, 51.3128
31.688464680, 96.390, 2693.0, 51.8941
31.740985811, 96.390, 3468.0, 58.8897
31.793506942, 96.390, 3489.0, 59.0678
31.846028072, 96.390, 2946.0, 54.2771
31.898549203, 96.390, 2399.0, 48.9796
31.951070334, 96.390, 2692.0, 51.8845
32.003591465, 96.390, 3654.0, 60.4483
32.056112595, 96.390, 5353.0, 73.1642
32.108633726, 96.390, 7018.0, 83.7735
32.161154857, 96.390, 5027.0, 70.9013
32.213675987, 96.390, 3709.0, 60.9016
32.266197118, 96.390, 2392.0, 48.9081
32.318718249, 96.390, 2071.0, 45.5082
32.371239380, 96.390, 2081.0, 45.6180
32.423760510, 96.390, 2015.0, 44.8888
32.476281641, 96.390, 1977.0, 44.4635
32.528802772, 96.390, 1946.0, 44.1135
32.581323902, 96.390, 1982.0, 44.5197
32.633845033, 96.390, 1945.0, 44.1022
32.686366164, 96.390, 2265.0, 47.5920
32.738887295, 96.390, 2241.0, 47.3392
32.791408425, 96.390, 2089.0, 45.7056
32.843929556, 96.390, 2031.0, 45.0666
32.896450687, 96.390, 1894.0, 43.5201
32.948971817, 96.390, 1945.0, 44.1022
33.001492948, 96.390, 2158.0, 46.4543
33.054014079, 96.390, 2173.0, 46.6154
33.106535209, 96.390, 2343.0, 48.4045
33.159056340, 96.390, 2360.0, 48.5798
33.211577471, 96.390, 2353.0, 48.5077
33.264098602, 96.390, 2322.0, 48.1871
33.316619732, 96.390, 2791.0, 52.8299
33.369140863, 96.390, 2360.0, 48.5798
33.421661994, 96.390, 2630.0, 51.2835
33.474183124, 96.390, 2528.0, 50.2792
33.526704255, 96.390, 2481.0, 49.8096
33.579225386, 96.390, 2221.0, 47.1275
33.631746517, 96.390, 1873.0, 43.2782
33.684267647, 96.390, 1796.0, 42.3792
33.736788778, 96.390, 1730.0, 41.5933
33.789309909, 96.390, 1803.0, 42.4617
33.841831039, 96.390, 1955.0, 44.2154
33.894352170, 96.390, 2131.0, 46.1628
33.946873301, 96.390, 2852.0, 53.4041
33.999394432, 96.390, 3508.0, 59.2284
34.051915562, 96.390, 2861.0, 53.4883
34.104436693, 96.390, 2520.0, 50.1996
34.156957824, 96.390, 1936.0, 44.0000
34.209478954, 96.390, 1848.0, 42.9884
34.262000085, 96.390, 1881.0, 43.3705
34.314521216, 96.390, 1998.0, 44.6990
34.367042346, 96.390, 1969.0, 44.3734
34.419563477, 96.390, 2136.0, 46.2169
34.472084608, 96.390, 2126.0, 46.1086
34.524605739, 96.390, 2226.0, 47.1805
34.577126869, 96.390, 2098.0, 45.8039
34.629648000, 96.390, 2136.0, 46.2169
34.682169131, 96.390, 2114.0, 45.9783
34.734690261, 96.390, 2136.0, 46.2169
34.787211392, 96.390, 2183.0, 46.7226
34.839732523, 96.390, 2321.0, 48.1768
34.892253654, 96.390, 2780.0, 52.7257
34.944774784, 96.390, 3379.0, 58.1292
34.997295915, 96.390, 3560.0, 59.6657
35.049817046, 96.390, 3200.0, 56.5685
35.102338176, 96.390, 2620.0, 51.1859
35.154859307, 96.390, 2223.0, 47.1487
35.207380438, 96.390, 2003.0, 44.7549
35.259901569, 96.390, 2185.0, 46.7440
35.312422699, 96.390, 2085.0, 45.6618
35.364943830, 96.390, 1994.0, 44.6542
35.417464961, 96.390, 1786.0, 42.2611
35.469986091, 96.390, 1744.0, 41.7612
35.522507222, 96.390, 1721.0, 41.4849
35.575028353, 96.390, 1729.0, 41.5812
35.627549484, 96.390, 1737.0, 41.6773
35.680070614, 96.390, 1886.0, 43.4281
35.732591745, 96.390, 1851.0, 43.0232
35.785112876, 96.390, 1800.0, 42.4264
35.837634006, 96.390, 1817.0, 42.6263
35.890155137, 96.390, 1708.0, 41.3280
35.942676268, 96.390, 1699.0, 41.2189
35.995197398, 96.390, 1834.0, 42.8252
36.047718529, 96.390, 1769.0, 42.0595
36.100239660, 96.390, 1682.0, 41.0122
36.152760791, 96.390, 1695.0, 41.1704
36.205281921, 96.390, 1596.0, 39.9500
36.257803052, 96.390, 1609.0, 40.1123
36.310324183, 96.390, 1527.0, 39.0768
36.362845313, 96.390, 1782.0, 42.2137
36.415366444, 96.390, 1912.0, 43.7264
36.467887575, 96.390, 1742.0, 41.7373
36.520408706, 96.390, 1604.0, 40.0500
36.572929836, 96.390, 1525.0, 39.0512
36.625450967, 96.390, 1428.0, 37.7889
36.677972098, 96.390, 1585.0, 39.8121
36.730493228, 96.390, 1611.0, 40.1373
36.783014359, 96.390, 1516.0, 38.9358
36.835535490, 96.390, 1581.0, 39.7618
36.888056621, 96.390, 1530.0, 39.1152
36.940577751, 96.390, 1578.0, 39.7240
36.993098882, 96.390, 1562.0, 39.5221
37.045620013, 96.390, 1412.0, 37.5766
37.098141143, 96.390, 1460.0, 38.2099
37.150662274, 96.390, 1379.0, 37.1349
37.203183405, 96.390, 1447.0, 38.0395
37.255704535, 96.390, 1482.0, 38.4968
37.308225666, 96.390, 1583.0, 39.7869
37.360746797, 96.390, 1536.0, 39.1918
37.413267928, 96.390, 1455.0, 38.1445
37.465789058, 96.390, 1500.0, 38.7298
37.518310189, 96.390, 1451.0, 38.0920
37.570831320, 96.390, 1458.0, 38.1838
37.623352450, 96.390, 1557.0, 39.4588
37.675873581, 96.390, 1606.0, 40.0749
37.728394712, 96.390, 1795.0, 42.3674
37.780915843, 96.390, 2149.0, 46.3573
37.833436973, 96.390, 1977.0, 44.4635
37.885958104, 96.390, 1837.0, 42.8602
37.938479235, 96.390, 1643.0, 40.5339
37.991000365, 96.390, 1516.0, 38.9358
38.043521496, 96.390, 1405.0, 37.4833
38.096042627, 96.390, 1508.0, 38.8330
38.148563758, 96.390, 1480.0, 38.4708
38.201084888, 96.390, 1689.0, 41.0974
38.253606019, 96.390, 1706.0, 41.3038
38.306127150, 96.390, 1770.0, 42.0714
38.358648280, 96.390, 1768.0, 42.0476
38.411169411, 96.390, 1572.0, 39.6485
38.463690542, 96.390, 1535.0, 39.1791
38.516211673, 96.390, 1417.0, 37.6431
38.568732803, 96.390, 1502.0, 38.7556
38.621253934, 96.390, 1434.0, 37.8682
38.673775065, 96.390, 1437.0, 37.9078
38.726296195, 96.390, 1579.0, 39.7366
38.778817326, 96.390, 1817.0, 42.6263
38.831338457, 96.390, 1876.0, 43.3128
38.883859587, 96.390, 1613.0, 40.1622
38.936380718, 96.390, 1572.0, 39.6485
38.988901849, 96.390, 1479.0, 38.4578
39.041422980, 96.390, 1356.0, 36.8239
39.093944110, 96.390, 1362.0, 36.9053
39.146465241, 96.390, 1362.0, 36.9053
39.198986372, 96.390, 1385.0, 37.2156
39.251507502, 96.390, 1470.0, 38.3406
39.304028633, 96.390, 1470.0, 38.3406
39.356549764, 96.390, 1541.0, 39.2556
39.409070895, 96.390, 1772.0, 42.0951
39.461592025, 96.390, 2128.0, 46.1303
39.514113156, 96.390, 1877.0, 43.3244
39.566634287, 96.390, 1753.0, 41.8688
39.619155417, 96.390, 1485.0, 38.5357
39.671676548, 96.390, 1460.0, 38.2099
39.724197679, 96.390, 1431.0, 37.8286
39.776718810, 96.390, 1373.0, 37.0540
39.829239940, 96.390, 1468.0, 38.3145
39.881761071, 96.390, 1494.0, 38.6523
39.934282202, 96.390, 1435.0, 37.8814
39.986803332, 96.390, 1511.0, 38.8716
40.039324463, 96.390, 1432.0, 37.8418
40.091845594, 96.390, 1448.0, 38.0526
40.144366725, 96.390, 1554.0, 39.4208
40.196887855, 96.390, 1458.0, 38.1838
40.249408986, 96.390, 1481.0, 38.4838
40.301930117, 96.390, 1393.0, 37.3229
40.354451247, 96.390, 1298.0, 36.0278
40.406972378, 96.390, 1331.0, 36.4829
40.459493509, 96.390, 1248.0, 35.3270
40.512014639, 96.390, 1306.0, 36.1386
40.564535770, 96.390, 1387.0, 37.2424
40.617056901, 96.390, 1486.0, 38.5487
40.669578032, 96.390, 1455.0, 38.1445
40.722099162, 96.390, 1380.0, 37.1484
40.774620293, 96.390, 1279.0, 35.7631
40.827141424, 96.390, 1278.0, 35.7491
40.879662554, 96.390, 1213.0, 34.8281
40.932183685, 96.390, 1227.0, 35.0286
40.984704816, 96.390, 1221.0, 34.9428
41.037225947, 96.390, 1305.0, 36.1248
41.089747077, 96.390, 1256.0, 35.4401
41.142268208, 96.390, 1263.0, 35.5387
41.194789339, 96.390, 1272.0, 35.6651
41.247310469, 96.390, 1310.0, 36.1939
41.299831600, 96.390, 1344.0, 36.6606
41.352352731, 96.390, 1621.0, 40.2616
41.404873862, 96.390, 2008.0, 44.8107
41.457394992, 96.390, 1952.0, 44.1814
41.509916123, 96.390, 1727.0, 41.5572
41.562437254, 96.390, 1563.0, 39.5348
41.614958384, 96.390, 1352.0, 36.7696
41.667479515, 96.390, 1235.0, 35.1426
41.720000646, 96.390, 1235.0, 35.1426
41.772521776, 96.390, 1214.0, 34.8425
41.825042907, 96.390, 1147.0, 33.8674
41.877564038, 96.390, 1237.0, 35.1710
41.930085169, 96.390, 1181.0, 34.3657
41.982606299, 96.390, 1259.0, 35.4824
42.035127430, 96.390, 1192.0, 34.5254
42.087648561, 96.390, 1346.0, 36.6879
42.140169691, 96.390, 1517.0, 38.9487
42.192690822, 96.390, 1549.0, 39.3573
42.245211953, 96.390, 1479.0, 38.4578
42.297733084, 96.390, 1490.0, 38.6005
42.350254214, 96.390, 1386.0, 37.2290
42.402775345, 96.390, 1247.0, 35.3129
42.455296476, 96.390, 1263.0, 35.5387
42.507817606, 96.390, 1281.0, 35.7911
42.560338737, 96.390, 1472.0, 38.3667
42.612859868, 96.390, 1496.0, 38.6782
42.665380999, 96.390, 1418.0, 37.6563
42.717902129, 96.390, 1363.0, 36.9188
42.770423260, 96.390, 1346.0, 36.6879
42.822944391, 96.390, 1232.0, 35.0999
42.875465521, 96.390, 1274.0, 35.6931
42.927986652, 96.390, 1281.0, 35.7911
42.980507783, 96.390, 1230.0, 35.0714
43.033028914, 96.390, 1274.0, 35.6931
43.085550044, 96.390, 1194.0, 34.5543
43.138071175, 96.390, 1213.0, 34.8281
43.190592306, 96.390, 1201.0, 34.6554
43.243113436, 96.390, 1141.0, 33.7787
43.295634567, 96.390, 1196.0, 34.5832
43.348155698, 96.390, 1239.0, 35.1994
43.400676828, 96.390, 1224.0, 34.9857
43.453197959, 96.390, 1209.0, 34.7707
43.505719090, 96.390, 1144.0, 33.8231
43.558240221, 96.390, 1168.0, 34.1760
43.610761351, 96.390, 1238.0, 35.1852
43.663282482, 96.390, 1307.0, 36.1525
43.715803613, 96.390, 1498.0, 38.7040
43.768324743, 96.390, 1856.0, 43.0813
43.820845874, 96.390, 1916.0, 43.7721
43.873367005, 96.390, 1708.0, 41.3280
43.925888136, 96.390, 1677.0, 40.9512
43.978409266, 96.390, 1367.0, 36.9730
44.030930397, 96.390, 1230.0, 35.0714
44.083451528, 96.390, 1323.0, 36.3731
44.135972658, 96.390, 1189.0, 34.4819
44.188493789, 96.390, 1245.0, 35.2846
44.241014920, 96.390, 1334.0, 36.5240
44.293536051, 96.390, 1407.0, 37.5100
44.346057181, 96.390, 1393.0, 37.3229
44.398578312, 96.390, 1636.0, 40.4475
44.451099443, 96.390, 1693.0, 41.1461
44.503620573, 96.390, 1555.0, 39.4335
44.556141704, 96.390, 1402.0, 37.4433
44.608662835, 96.390, 1408.0, 37.5233
44.661183966, 96.390, 1242.0, 35.2420
44.713705096, 96.390, 1253.0, 35.3977
44.766226227, 96.390, 1330.0, 36.4692
44.818747358, 96.390, 1368.0, 36.9865
44.871268488, 96.390, 1348.0, 36.7151
44.923789619, 96.390, 1344.0, 36.6606
44.976310750, 96.390, 1365.0, 36.9459
45.028831880, 96.390, 1314.0, 36.2491
45.081353011, 96.390, 1435.0, 37.8814
45.133874142, 96.390, 1668.0, 40.8412
45.186395273, 96.390, 1673.0, 40.9023
45.238916403, 96.390, 1602.0, 40.0250
45.291437534, 96.390, 1527.0, 39.0768
45.343958665, 96.390, 1607.0, 40.0874
45.396479795, 96.390, 1525.0, 39.0512
45.449000926, 96.390, 1581.0, 39.7618
45.501522057, 96.390, 1729.0, 41.5812
45.554043188, 96.390, 1558.0, 39.4715
45.606564318, 96.390, 1456.0, 38.1576
45.659085449, 96.390, 1330.0, 36.4692
45.711606580, 96.390, 1358.0, 36.8511
45.764127710, 96.390, 1357.0, 36.8375
45.816648841, 96.390, 1268.0, 35.6090
45.869169972, 96.390, 1248.0, 35.3270
45.921691103, 96.390, 1202.0, 34.6699
45.974212233, 96.390, 1199.0, 34.6266
46.026733364, 96.390, 1279.0, 35.7631
46.079254495, 96.390, 1235.0, 35.1426
46.131775625, 96.390, 1293.0, 35.9583
46.184296756, 96.390, 1405.0, 37.4833
46.236817887, 96.390, 1501.0, 38.7427
46.289339017, 96.390, 1584.0, 39.7995
46.341860148, 96.390, 1610.0, 40.1248
46.394381279, 96.390, 1430.0, 37.8153
46.446902410, 96.390, 1542.0, 39.2683
46.499423540, 96.390, 1391.0, 37.2961
46.551944671, 96.390, 1272.0, 35.6651
46.604465802, 96.390, 1305.0, 36.1248
46.656986932, 96.390, 1241.0, 35.2278
46.709508063, 96.390, 1345.0, 36.6742
46.762029194, 96.390, 1292.0, 35.9444
46.814550325, 96.390, 1296.0, 36.0000
46.867071455, 96.390, 1279.0, 35.7631
46.919592586, 96.390, 1273.0, 35.6791
46.972113717, 96.390, 1404.0, 37.4700
47.024634847, 96.390, 1420.0, 37.6829
47.077155978, 96.390, 1417.0, 37.6431
47.129677109, 96.390, 1277.0, 35.7351
47.182198240, 96.390, 1321.0, 36.3456
47.234719370, 96.390, 1201.0, 34.6554
47.287240501, 96.390, 1232.0, 35.0999
47.339761632, 96.390, 1248.0, 35.3270
47.392282762, 96.390, 1134.0, 33.6749
47.444803893, 96.390, 1159.0, 34.0441
47.497325024, 96.390, 1211.0, 34.7994
47.549846155, 96.390, 1199.0, 34.6266
47.602367285, 96.390, 1241.0, 35.2278
47.654888416, 96.390, 1153.0, 33.9559
47.707409547, 96.390, 1129.0, 33.6006
47.759930677, 96.390, 1215.0, 34.8569
47.812451808, 96.390, 1121.0, 33.4813
47.864972939, 96.390, 1103.0, 33.2114
47.917494069, 96.390, 1122.0, 33.4963
47.970015200, 96.390, 1165.0, 34.1321
48.022536331, 96.390, 1231.0, 35.0856
48.075057462, 96.390, 1268.0, 35.6090
48.127578592, 96.390, 1314.0, 36.2491
48.180099723, 96.390, 1434.0, 37.8682
48.232620854, 96.390, 1288.0, 35.8887
48.285141984, 96.390, 1277.0, 35.7351
48.337663115, 96.390, 1189.0, 34.4819
48.390184246, 96.390, 1156.0, 34.0000
48.442705377, 96.390, 1198.0, 34.6121
48.495226507, 96.390, 1360.0, 36.8782
48.547747638, 96.390, 1410.0, 37.5500
48.600268769, 96.390, 1341.0, 36.6197
48.652789899, 96.390, 1326.0, 36.4143
48.705311030, 96.390, 1251.0, 35.3695
48.757832161, 96.390, 1191.0, 34.5109
48.810353292, 96.390, 1093.0, 33.0606
48.862874422, 96.390, 1125.0, 33.5410
48.915395553, 96.390, 1113.0, 33.3617
48.967916684, 96.390, 1065.0, 32.6343
49.020437814, 96.390, 1018.0, 31.9061
49.072958945, 96.390, 1090.0, 33.0151
49.125480076, 96.390, 1067.0, 32.6650
49.178001207, 96.390, 1058.0, 32.5269
49.230522337, 96.390, 1116.0, 33.4066
49.283043468, 96.390, 1108.0, 33.2866
49.335564599, 96.390, 1082.0, 32.8938
49.388085729, 96.390, 1054.0, 32.4654
49.440606860, 96.390, 1109.0, 33.3017
49.493127991, 96.390, 1063.0, 32.6037
49.545649121, 96.390, 1158.0, 34.0294
49.598170252, 96.390, 1166.0, 34.1467
49.650691383, 96.390, 1160.0, 34.0588
49.703212514, 96.390, 1140.0, 33.7639
49.755733644, 96.390, 1097.0, 33.1210
49.808254775, 96.390, 1129.0, 33.6006
49.860775906, 96.390, 1112.0, 33.3467
49.913297036, 96.390, 1066.0, 32.6497
49.965818167, 96.390, 1032.0, 32.1248
50.018339298, 96.390, 1012.0, 31.8119
50.070860429, 96.390, 1051.0, 32.4191
50.123381559, 96.390, 1065.0, 32.6343
50.175902690, 96.390, 1097.0, 33.1210
50.228423821, 96.390, 1247.0, 35.3129
50.280944951, 96.390, 1380.0, 37.1484
50.333466082, 96.390, 1210.0, 34.7851
50.385987213, 96.390, 1202.0, 34.6699
50.438508344, 96.390, 1162.0, 34.0881
50.491029474, 96.390, 1072.0, 32.7414
50.543550605, 96.390, 1083.0, 32.9090
50.596071736, 96.390, 1036.0, 32.1870
50.648592866, 96.390, 1001.0, 31.6386
50.701113997, 96.390, 1021.0, 31.9531
50.753635128, 96.390, 1009.0, 31.7648
50.806156258, 96.390, 1007.0, 31.7333
50.858677389, 96.390, 1027.0, 32.0468
50.911198520, 96.390, 1031.0, 32.1092
50.963719651, 96.390, 994.0, 31.5278
51.016240781, 96.390, 1075.0, 32.7872
51.068761912, 96.390, 1074.0, 32.7719
51.121283043, 96.390, 1094.0, 33.0757
51.173804173, 96.390, 1086.0, 32.9545
51.226325304, 96.390, 1182.0, 34.3802
51.278846435, 96.390, 1170.0, 34.2053
51.331367566, 96.390, 1118.0, 33.4365
51.383888696, 96.390, 1113.0, 33.3617
51.436409827, 96.390, 1080.0, 32.8634
51.488930958, 96.390, 1064.0, 32.6190
51.541452088, 96.390, 988.0, 31.4325
51.593973219, 96.390, 971.0, 31.1609
51.646494350, 96.390, 964.0, 31.0483
51.699015481, 96.390, 969.0, 31.1288
51.751536611, 96.390, 1001.0, 31.6386
51.804057742, 96.390, 1062.0, 32.5883
51.856578873, 96.390, 1011.0, 31.7962
51.909100003, 96.390, 1009.0, 31.7648
51.961621134, 96.390, 1015.0, 31.8591
52.014142265, 96.390, 1100.0, 33.1662
52.066663396, 96.390, 1013.0, 31.8277
52.119184526, 96.390, 1052.0, 32.4345
52.171705657, 96.390, 1173.0, 34.2491
52.224226788, 96.390, 1313.0, 36.2353
52.276747918, 96.390, 1318.0, 36.3043
52.329269049, 96.390, 1331.0, 36.4829
52.381790180, 96.390, 1237.0, 35.1710
52.434311310, 96.390, 1212.0, 34.8138
52.486832441, 96.390, 1092.0, 33.0454
52.539353572, 96.390, 1020.0, 31.9374
52.591874703, 96.390, 973.0, 31.1929
52.644395833, 96.390, 1007.0, 31.7333
52.696916964, 96.390, 1073.0, 32.7567
52.749438095, 96.390, 1138.0, 33.7343
52.801959225, 96.390, 1105.0, 33.2415
52.854480356, 96.390, 1185.0, 34.4238
52.907001487, 96.390, 1183.0, 34.3948
52.959522618, 96.390, 1121.0, 33.4813
53.012043748, 96.390, 1041.0, 32.2645
53.064564879, 96.390, 1038.0, 32.2180
53.117086010, 96.390, 1039.0, 32.2335
53.169607140, 96.390, 1124.0, 33.5261
53.222128271, 96.390, 1141.0, 33.7787
53.274649402, 96.390, 1187.0, 34.4529
53.327170533, 96.390, 1114.0, 33.3766
53.379691663, 96.390, 1107.0, 33.2716
53.432212794, 96.390, 1034.0, 32.1559
53.484733925, 96.390, 1047.0, 32.3574
53.537255055, 96.390, 1066.0, 32.6497
53.589776186, 96.390, 958.0, 30.9516
53.642297317, 96.390, 944.0, 30.7246
53.694818448, 96.390, 917.0, 30.2820
53.747339578, 96.390, 952.0, 30.8545
53.799860709, 96.390, 947.0, 30.7734
53.852381840, 96.390, 955.0, 30.9031
53.904902970, 96.390, 973.0, 31.1929
53.957424101, 96.390, 946.0, 30.7571
54.009945232, 96.390, 971.0, 31.1609
54.062466362, 96.390, 1019.0, 31.9218
54.114987493, 96.390, 1089.0, 33.0000
54.167508624, 96.390, 1177.0, 34.3074
54.220029755, 96.390, 1162.0, 34.0881
54.272550885, 96.390, 1092.0, 33.0454
54.325072016, 96.390, 1122.0, 33.4963
54.377593147, 96.390, 1149.0, 33.8969
54.430114277, 96.390, 1031.0, 32.1092
54.482635408, 96.390, 990.0, 31.4643
54.535156539, 96.390, 1026.0, 32.0312
54.587677670, 96.390, 1036.0, 32.1870
54.640198800, 96.390, 999.0, 31.6070
54.692719931, 96.390, 938.0, 30.6268
54.745241062, 96.390, 944.0, 30.7246
54.797762192, 96.390, 965.0, 31.0644
54.850283323, 96.390, 902.0, 30.0333
54.902804454, 96.390, 943.0, 30.7083
54.955325585, 96.390, 907.0, 30.1164
55.007846715, 96.390, 965.0, 31.0644
55.060367846, 96.390, 948.0, 30.7896
55.112888977, 96.390, 884.0, 29.7321
55.165410107, 96.390, 918.0, 30.2985
55.217931238, 96.390, 852.0, 29.1890
55.270452369, 96.390, 911.0, 30.1828
55.322973499, 96.390, 874.0, 29.5635
55.375494630, 96.390, 869.0, 29.4788
55.428015761, 96.390, 908.0, 30.1330
55.480536892, 96.390, 1018.0, 31.9061
55.533058022, 96.390, 905.0, 30.0832
55.585579153, 96.390, 964.0, 31.0483
55.638100284, 96.390, 1055.0, 32.4808
55.690621414, 96.390, 1016.0, 31.8748
55.743142545, 96.390, 917.0, 30.2820
55.795663676, 96.390, 916.0, 30.2655
55.848184807, 96.390, 956.0, 30.9192
55.900705937, 96.390, 862.0, 29.3598
55.953227068, 96.390, 824.0, 28.7054
56.005748199, 96.390, 933.0, 30.5450
56.058269329, 96.390, 875.0, 29.5804
56.110790460, 96.390, 890.0, 29.8329
56.163311591, 96.390, 897.0, 29.9500
56.215832722, 96.390, 907.0, 30.1164
56.268353852, 96.390, 929.0, 30.4795
56.320874983, 96.390, 882.0, 29.6985
56.373396114, 96.390, 818.0, 28.6007
56.425917244, 96.390, 894.0, 29.8998
56.478438375, 96.390, 852.0, 29.1890
56.530959506, 96.390, 838.0, 28.9482
56.583480637, 96.390, 843.0, 29.0345
56.636001767, 96.390, 872.0, 29.5296
56.688522898, 96.390, 827.0, 28.7576
56.741044029, 96.390, 790.0, 28.1069
56.793565159, 96.390, 815.0, 28.5482
56.846086290, 96.390, 854.0, 29.2233
56.898607421, 96.390, 884.0, 29.7321
56.951128551, 96.390, 864.0, 29.3939
57.003649682, 96.390, 866.0, 29.4279
57.056170813, 96.390, 851.0, 29.1719
57.108691944, 96.390, 858.0, 29.2916
57.161213074, 96.390, 849.0, 29.1376
57.213734205, 96.390, 826.0, 28.7402
57.266255336, 96.390, 835.0, 28.8964
57.318776466, 96.390, 848.0, 29.1204
57.371297597, 96.390, 886.0, 29.7658
57.423818728, 96.390, 893.0, 29.8831
57.476339859, 96.390, 847.0, 29.1033
57.528860989, 96.390, 893.0, 29.8831
57.581382120, 96.390, 814.0, 28.5307
57.633903251, 96.390, 886.0, 29.7658
57.686424381, 96.390, 931.0, 30.5123
57.738945512, 96.390, 851.0, 29.1719
57.791466643, 96.390, 896.0, 29.9333
57.843987774, 96.390, 904.0, 30.0666
57.896508904, 96.390, 914.0, 30.2324
57.949030035, 96.390, 887.0, 29.7825
58.001551166, 96.390, 950.0, 30.8221
58.054072296, 96.390, 1008.0, 31.7490
58.106593427, 96.390, 1146.0, 33.8526
58.159114558, 96.390, 1128.0, 33.5857
58.211635689, 96.390, 995.0, 31.5436
58.264156819, 96.390, 1035.0, 32.1714
58.316677950, 96.390, 934.0, 30.5614
58.369199081, 96.390, 891.0, 29.8496
58.421720211, 96.390, 871.0, 29.5127
58.474241342, 96.390, 862.0, 29.3598
58.526762473, 96.390, 883.0, 29.7153
58.579283603, 96.390, 873.0, 29.5466
58.631804734, 96.390, 857.0, 29.2746
58.684325865, 96.390, 795.0, 28.1957
58.736846996, 96.390, 826.0, 28.7402
58.789368126, 96.390, 838.0, 28.9482
58.841889257, 96.390, 864.0, 29.3939
58.894410388, 96.390, 791.0, 28.1247
58.946931518, 96.390, 781.0, 27.9464
58.999452649, 96.390, 754.0, 27.4591
59.051973780, 96.390, 836.0, 28.9137
59.104494911, 96.390, 826.0, 28.7402
59.157016041, 96.390, 851.0, 29.1719
59.209537172, 96.390, 875.0, 29.5804
59.262058303, 96.390, 902.0, 30.0333
59.314579433, 96.390, 928.0, 30.4631
59.367100564, 96.390, 902.0, 30.0333
59.419621695, 96.390, 888.0, 29.7993
59.472142826, 96.390, 877.0, 29.6142
59.524663956, 96.390, 861.0, 29.3428
59.577185087, 96.390, 862.0, 29.3598
59.629706218, 96.390, 954.0, 30.8869
59.682227348, 96.390, 880.0, 29.6648
59.734748479, 96.390, 861.0, 29.3428
59.787269610, 96.390, 944.0, 30.7246
59.839790740, 96.390, 938.0, 30.6268
59.892311871, 96.390, 928.0, 30.4631
59.944833002, 96.390, 985.0, 31.3847
59.997354133, 96.390, 1044.0, 32.3110
60.049875263, 96.390, 942.0, 30.6920
60.102396394, 96.390, 960.0, 30.9839
60.154917525, 96.390, 979.0, 31.2890
60.207438655, 96.390, 982.0, 31.3369
60.259959786, 96.390, 978.0, 31.2730
60.312480917, 96.390, 997.0, 31.5753
60.365002048, 96.390, 1011.0, 31.7962
60.417523178, 96.390, 991.0, 31.4802
60.470044309, 96.390, 1002.0, 31.6544
60.522565440, 96.390, 1018.0, 31.9061
60.575086570, 96.390, 1003.0, 31.6702
60.627607701, 96.390, 991.0, 31.4802
60.680128832, 96.390, 1083.0, 32.9090
60.732649963, 96.390, 1111.0, 33.3317
60.785171093, 96.390, 1060.0, 32.5576
60.837692224, 96.390, 1039.0, 32.2335
60.890213355, 96.390, 1104.0, 33.2265
60.942734485, 96.390, 1067.0, 32.6650
60.995255616, 96.390, 1030.0, 32.0936
61.047776747, 96.390, 1059.0, 32.5423
61.100297878, 96.390, 1064.0, 32.6190
61.152819008, 96.390, 1170.0, 34.2053
61.205340139, 96.390, 1192.0, 34.5254
61.257861270, 96.390, 1108.0, 33.2866
61.310382400, 96.390, 1098.0, 33.1361
61.362903531, 96.390, 1077.0, 32.8177
61.415424662, 96.390, 1079.0, 32.8481
61.467945792, 96.390, 1144.0, 33.8231
61.520466923, 96.390, 1184.0, 34.4093
61.572988054, 96.390, 1165.0, 34.1321
61.625509185, 96.390, 1096.0, 33.1059
61.678030315, 96.390, 1092.0, 33.0454
61.730551446, 96.390, 1062.0, 32.5883
61.783072577, 96.390, 1040.0, 32.2490
61.835593707, 96.390, 927.0, 30.4467
61.888114838, 96.390, 1013.0, 31.8277
61.940635969, 96.390, 989.0, 31.4484
61.993157100, 96.390, 946.0, 30.7571
62.045678230, 96.390, 949.0, 30.8058
62.098199361, 96.390, 915.0, 30.2490
62.150720492, 96.390, 938.0, 30.6268
62.203241622, 96.390, 965.0, 31.0644
62.255762753, 96.390, 920.0, 30.3315
62.308283884, 96.390, 896.0, 29.9333
62.360805015, 96.390, 902.0, 30.0333
62.413326145, 96.390, 889.0, 29.8161
62.465847276, 96.390, 850.0, 29.1548
62.518368407, 96.390, 853.0, 29.2062
62.570889537, 96.390, 846.0, 29.0861
62.623410668, 96.390, 870.0, 29.4958
62.675931799, 96.390, 912.0, 30.1993
62.728452930, 96.390, 971.0, 31.1609
62.780974060, 96.390, 887.0, 29.7825
62.833495191, 96.390, 867.0, 29.4449
62.886016322, 96.390, 873.0, 29.5466
62.938537452, 96.390, 883.0, 29.7153
62.991058583, 96.390, 812.0, 28.4956
63.043579714, 96.390, 809.0, 28.4429
63.096100844, 96.390, 795.0, 28.1957
63.148621975, 96.390, 759.0, 27.5500
63.201143106, 96.390, 759.0, 27.5500
63.253664237, 96.390, 770.0, 27.7489
63.306185367, 96.390, 756.0, 27.4955
63.358706498, 96.390, 782.0, 27.9643
63.411227629, 96.390, 712.0, 26.6833
63.463748759, 96.390, 757.0, 27.5136
63.516269890, 96.390, 761.0, 27.5862
63.568791021, 96.390, 785.0, 28.0179
63.621312152, 96.390, 783.0, 27.9821
63.673833282, 96.390, 778.0, 27.8927
63.726354413, 96.390, 778.0, 27.8927
63.778875544, 96.390, 794.0, 28.1780
63.831396674, 96.390, 828.0, 28.7750
63.883917805, 96.390, 866.0, 29.4279
63.936438936, 96.390, 830.0, 28.8097
63.988960067, 96.390, 938.0, 30.6268
64.041481197, 96.390, 835.0, 28.8964
64.094002328, 96.390, 853.0, 29.2062
64.146523459, 96.390, 844.0, 29.0517
64.199044589, 96.390, 862.0, 29.3598
64.251565720, 96.390, 806.0, 28.3901
64.304086851, 96.390, 852.0, 29.1890
64.356607981, 96.390, 786.0, 28.0357
64.409129112, 96.390, 759.0, 27.5500
64.461650243, 96.390, 790.0, 28.1069
64.514171374, 96.390, 751.0, 27.4044
64.566692504, 96.390, 841.0, 29.0000
64.619213635, 96.390, 736.0, 27.1293
64.671734766, 96.390, 740.0, 27.2029
64.724255896, 96.390, 733.0, 27.0740
64.776777027, 96.390, 732.0, 27.0555
64.829298158, 96.390, 707.0, 26.5895
64.881819289, 96.390, 717.0, 26.7769
64.934340419, 96.390, 755.0, 27.4773
64.986861550, 96.390, 695.0, 26.3629