File: Files_organized_for_plots/PC/XRD_PC_PcornerPC10nov21.csv
[Measurement conditions]
Sample identification,MNASPH_PcornerPC10nov21
Comment - 1,"Configuration=Stage for Flat Samples/Holders, Owner=User-1, Creation date=7/1/2020 9:53:24 AM"
Comment - 2,"Goniometer=Theta/Theta; Minimum step size 2Theta:0.0001; Minimum step size Omega:0.0001"
Comment - 3,"Sample stage=Stage for flat samples/holders"
Comment - 4,"Diffractometer system=EMPYREAN"
Comment - 5,"Measurement program=C:\Users\ibo5034\OneDrive - The Pennsylvania State University\NEUP\Zerobackground scan.xrdmp, Identifier={98A3B11C-88F9-4AA6-982C-73314A311EF5}"
Anode material,Cu
K-Alpha1 wavelength,1.5405980
K-Alpha2 wavelength,1.5444260
Ratio K-Alpha2/K-Alpha1,0.500
Divergence slit,Fixed,0.25
Monochromator used,NO
Generator voltage, 45
Tube current, 40
File date and time,03/Dec/2021 09:57
Unit cell,
h k l, 0 0 0
Scan axis,Gonio
Scan range,4.994599997,64.999991833
Scan step size,0.0262606
No. of points, 2285
Scan type,CONTINUOUS
Time per step,96.390
[Scan points]
Angle, TimePerStep, Intensity, ESD
5.007730280, 96.390, 3649.0, 60.4070
5.060251411, 96.390, 3618.0, 60.1498
5.112772541, 96.390, 3619.0, 60.1581
5.165293672, 96.390, 3575.0, 59.7913
5.217814803, 96.390, 3440.0, 58.6515
5.270335934, 96.390, 3442.0, 58.6686
5.322857064, 96.390, 3511.0, 59.2537
5.375378195, 96.390, 3392.0, 58.2409
5.427899326, 96.390, 3463.0, 58.8473
5.480420456, 96.390, 3431.0, 58.5747
5.532941587, 96.390, 3385.0, 58.1808
5.585462718, 96.390, 3402.0, 58.3267
5.637983849, 96.390, 3447.0, 58.7112
5.690504979, 96.390, 3284.0, 57.3062
5.743026110, 96.390, 3316.0, 57.5847
5.795547241, 96.390, 3290.0, 57.3585
5.848068371, 96.390, 3366.0, 58.0172
5.900589502, 96.390, 3230.0, 56.8331
5.953110633, 96.390, 3197.0, 56.5420
6.005631763, 96.390, 3275.0, 57.2276
6.058152894, 96.390, 3292.0, 57.3760
6.110674025, 96.390, 3275.0, 57.2276
6.163195156, 96.390, 3132.0, 55.9643
6.215716286, 96.390, 3232.0, 56.8507
6.268237417, 96.390, 3315.0, 57.5760
6.320758548, 96.390, 3157.0, 56.1872
6.373279678, 96.390, 3182.0, 56.4092
6.425800809, 96.390, 3227.0, 56.8067
6.478321940, 96.390, 3193.0, 56.5066
6.530843071, 96.390, 3188.0, 56.4624
6.583364201, 96.390, 3063.0, 55.3444
6.635885332, 96.390, 3026.0, 55.0091
6.688406463, 96.390, 3209.0, 56.6480
6.740927593, 96.390, 3156.0, 56.1783
6.793448724, 96.390, 3146.0, 56.0892
6.845969855, 96.390, 3131.0, 55.9553
6.898490986, 96.390, 3076.0, 55.4617
6.951012116, 96.390, 3199.0, 56.5597
7.003533247, 96.390, 3026.0, 55.0091
7.056054378, 96.390, 3082.0, 55.5158
7.108575508, 96.390, 3039.0, 55.1271
7.161096639, 96.390, 3035.0, 55.0908
7.213617770, 96.390, 3045.0, 55.1815
7.266138900, 96.390, 3026.0, 55.0091
7.318660031, 96.390, 3053.0, 55.2540
7.371181162, 96.390, 3154.0, 56.1605
7.423702293, 96.390, 3105.0, 55.7225
7.476223423, 96.390, 2974.0, 54.5344
7.528744554, 96.390, 2963.0, 54.4334
7.581265685, 96.390, 3043.0, 55.1634
7.633786815, 96.390, 2971.0, 54.5069
7.686307946, 96.390, 2992.0, 54.6992
7.738829077, 96.390, 2931.0, 54.1387
7.791350208, 96.390, 2932.0, 54.1479
7.843871338, 96.390, 2835.0, 53.2447
7.896392469, 96.390, 3080.0, 55.4977
7.948913600, 96.390, 2896.0, 53.8145
8.001434730, 96.390, 2786.0, 52.7826
8.053955861, 96.390, 2998.0, 54.7540
8.106476992, 96.390, 2945.0, 54.2679
8.158998123, 96.390, 2857.0, 53.4509
8.211519253, 96.390, 2944.0, 54.2586
8.264040384, 96.390, 2965.0, 54.4518
8.316561515, 96.390, 2875.0, 53.6190
8.369082645, 96.390, 2811.0, 53.0189
8.421603776, 96.390, 2868.0, 53.5537
8.474124907, 96.390, 2856.0, 53.4416
8.526646038, 96.390, 2832.0, 53.2165
8.579167168, 96.390, 2859.0, 53.4696
8.631688299, 96.390, 2805.0, 52.9623
8.684209430, 96.390, 2801.0, 52.9245
8.736730560, 96.390, 2769.0, 52.6213
8.789251691, 96.390, 2804.0, 52.9528
8.841772822, 96.390, 2858.0, 53.4603
8.894293952, 96.390, 2750.0, 52.4404
8.946815083, 96.390, 2869.0, 53.5630
8.999336214, 96.390, 2794.0, 52.8583
9.051857345, 96.390, 2834.0, 53.2353
9.104378475, 96.390, 2810.0, 53.0094
9.156899606, 96.390, 2825.0, 53.1507
9.209420737, 96.390, 2695.0, 51.9134
9.261941867, 96.390, 2880.0, 53.6656
9.314462998, 96.390, 2750.0, 52.4404
9.366984129, 96.390, 2841.0, 53.3010
9.419505260, 96.390, 2628.0, 51.2640
9.472026390, 96.390, 2831.0, 53.2071
9.524547521, 96.390, 2729.0, 52.2398
9.577068652, 96.390, 2732.0, 52.2685
9.629589782, 96.390, 2573.0, 50.7247
9.682110913, 96.390, 2678.0, 51.7494
9.734632044, 96.390, 2729.0, 52.2398
9.787153175, 96.390, 2645.0, 51.4296
9.839674305, 96.390, 2661.0, 51.5849
9.892195436, 96.390, 2619.0, 51.1762
9.944716567, 96.390, 2652.0, 51.4976
9.997237697, 96.390, 2672.0, 51.6914
10.049758828, 96.390, 2629.0, 51.2738
10.102279959, 96.390, 2682.0, 51.7880
10.154801090, 96.390, 2579.0, 50.7839
10.207322220, 96.390, 2628.0, 51.2640
10.259843351, 96.390, 2693.0, 51.8941
10.312364482, 96.390, 2649.0, 51.4684
10.364885612, 96.390, 2548.0, 50.4777
10.417406743, 96.390, 2595.0, 50.9411
10.469927874, 96.390, 2601.0, 51.0000
10.522449004, 96.390, 2622.0, 51.2055
10.574970135, 96.390, 2617.0, 51.1566
10.627491266, 96.390, 2674.0, 51.7107
10.680012397, 96.390, 2623.0, 51.2152
10.732533527, 96.390, 2546.0, 50.4579
10.785054658, 96.390, 2502.0, 50.0200
10.837575789, 96.390, 2511.0, 50.1099
10.890096919, 96.390, 2613.0, 51.1175
10.942618050, 96.390, 2669.0, 51.6624
10.995139181, 96.390, 2580.0, 50.7937
11.047660312, 96.390, 2601.0, 51.0000
11.100181442, 96.390, 2493.0, 49.9300
11.152702573, 96.390, 2544.0, 50.4381
11.205223704, 96.390, 2563.0, 50.6261
11.257744834, 96.390, 2583.0, 50.8232
11.310265965, 96.390, 2596.0, 50.9510
11.362787096, 96.390, 2484.0, 49.8397
11.415308227, 96.390, 2427.0, 49.2646
11.467829357, 96.390, 2598.0, 50.9706
11.520350488, 96.390, 2504.0, 50.0400
11.572871619, 96.390, 2580.0, 50.7937
11.625392749, 96.390, 2382.0, 48.8057
11.677913880, 96.390, 2432.0, 49.3153
11.730435011, 96.390, 2397.0, 48.9592
11.782956141, 96.390, 2440.0, 49.3964
11.835477272, 96.390, 2547.0, 50.4678
11.887998403, 96.390, 2422.0, 49.2138
11.940519534, 96.390, 2445.0, 49.4469
11.993040664, 96.390, 2362.0, 48.6004
12.045561795, 96.390, 2396.0, 48.9490
12.098082926, 96.390, 2441.0, 49.4065
12.150604056, 96.390, 2381.0, 48.7955
12.203125187, 96.390, 2496.0, 49.9600
12.255646318, 96.390, 2378.0, 48.7647
12.308167449, 96.390, 2428.0, 49.2747
12.360688579, 96.390, 2411.0, 49.1019
12.413209710, 96.390, 2402.0, 49.0102
12.465730841, 96.390, 2392.0, 48.9081
12.518251971, 96.390, 2399.0, 48.9796
12.570773102, 96.390, 2438.0, 49.3761
12.623294233, 96.390, 2430.0, 49.2950
12.675815364, 96.390, 2301.0, 47.9687
12.728336494, 96.390, 2282.0, 47.7703
12.780857625, 96.390, 2392.0, 48.9081
12.833378756, 96.390, 2373.0, 48.7134
12.885899886, 96.390, 2471.0, 49.7092
12.938421017, 96.390, 2286.0, 47.8121
12.990942148, 96.390, 2334.0, 48.3115
13.043463279, 96.390, 2394.0, 48.9285
13.095984409, 96.390, 2365.0, 48.6313
13.148505540, 96.390, 2348.0, 48.4562
13.201026671, 96.390, 2360.0, 48.5798
13.253547801, 96.390, 2351.0, 48.4871
13.306068932, 96.390, 2433.0, 49.3254
13.358590063, 96.390, 2375.0, 48.7340
13.411111193, 96.390, 2387.0, 48.8569
13.463632324, 96.390, 2419.0, 49.1833
13.516153455, 96.390, 2415.0, 49.1426
13.568674586, 96.390, 2300.0, 47.9583
13.621195716, 96.390, 2315.0, 48.1144
13.673716847, 96.390, 2372.0, 48.7032
13.726237978, 96.390, 2315.0, 48.1144
13.778759108, 96.390, 2396.0, 48.9490
13.831280239, 96.390, 2282.0, 47.7703
13.883801370, 96.390, 2351.0, 48.4871
13.936322501, 96.390, 2379.0, 48.7750
13.988843631, 96.390, 2361.0, 48.5901
14.041364762, 96.390, 2377.0, 48.7545
14.093885893, 96.390, 2312.0, 48.0833
14.146407023, 96.390, 2356.0, 48.5386
14.198928154, 96.390, 2292.0, 47.8748
14.251449285, 96.390, 2228.0, 47.2017
14.303970416, 96.390, 2320.0, 48.1664
14.356491546, 96.390, 2341.0, 48.3839
14.409012677, 96.390, 2368.0, 48.6621
14.461533808, 96.390, 2343.0, 48.4045
14.514054938, 96.390, 2370.0, 48.6826
14.566576069, 96.390, 2396.0, 48.9490
14.619097200, 96.390, 2377.0, 48.7545
14.671618331, 96.390, 2364.0, 48.6210
14.724139461, 96.390, 2363.0, 48.6107
14.776660592, 96.390, 2325.0, 48.2183
14.829181723, 96.390, 2320.0, 48.1664
14.881702853, 96.390, 2419.0, 49.1833
14.934223984, 96.390, 2444.0, 49.4368
14.986745115, 96.390, 2356.0, 48.5386
15.039266245, 96.390, 2445.0, 49.4469
15.091787376, 96.390, 2373.0, 48.7134
15.144308507, 96.390, 2445.0, 49.4469
15.196829638, 96.390, 2276.0, 47.7074
15.249350768, 96.390, 2356.0, 48.5386
15.301871899, 96.390, 2384.0, 48.8262
15.354393030, 96.390, 2405.0, 49.0408
15.406914160, 96.390, 2397.0, 48.9592
15.459435291, 96.390, 2479.0, 49.7896
15.511956422, 96.390, 2387.0, 48.8569
15.564477553, 96.390, 2335.0, 48.3218
15.616998683, 96.390, 2437.0, 49.3660
15.669519814, 96.390, 2506.0, 50.0600
15.722040945, 96.390, 2486.0, 49.8598
15.774562075, 96.390, 2514.0, 50.1398
15.827083206, 96.390, 2557.0, 50.5668
15.879604337, 96.390, 2466.0, 49.6588
15.932125468, 96.390, 2573.0, 50.7247
15.984646598, 96.390, 2568.0, 50.6754
16.037167729, 96.390, 2681.0, 51.7784
16.089688860, 96.390, 2713.0, 52.0865
16.142209990, 96.390, 2664.0, 51.6140
16.194731121, 96.390, 2646.0, 51.4393
16.247252252, 96.390, 2603.0, 51.0196
16.299773382, 96.390, 2490.0, 49.8999
16.352294513, 96.390, 2489.0, 49.8899
16.404815644, 96.390, 2507.0, 50.0700
16.457336775, 96.390, 2517.0, 50.1697
16.509857905, 96.390, 2539.0, 50.3885
16.562379036, 96.390, 2545.0, 50.4480
16.614900167, 96.390, 2499.0, 49.9900
16.667421297, 96.390, 2600.0, 50.9902
16.719942428, 96.390, 2524.0, 50.2394
16.772463559, 96.390, 2498.0, 49.9800
16.824984690, 96.390, 2520.0, 50.1996
16.877505820, 96.390, 2560.0, 50.5964
16.930026951, 96.390, 2525.0, 50.2494
16.982548082, 96.390, 2591.0, 50.9019
17.035069212, 96.390, 2597.0, 50.9608
17.087590343, 96.390, 2613.0, 51.1175
17.140111474, 96.390, 2562.0, 50.6162
17.192632605, 96.390, 2637.0, 51.3517
17.245153735, 96.390, 2709.0, 52.0481
17.297674866, 96.390, 2632.0, 51.3030
17.350195997, 96.390, 2708.0, 52.0384
17.402717127, 96.390, 2676.0, 51.7301
17.455238258, 96.390, 2671.0, 51.6817
17.507759389, 96.390, 2747.0, 52.4118
17.560280520, 96.390, 2707.0, 52.0288
17.612801650, 96.390, 2638.0, 51.3615
17.665322781, 96.390, 2694.0, 51.9038
17.717843912, 96.390, 2773.0, 52.6593
17.770365042, 96.390, 2751.0, 52.4500
17.822886173, 96.390, 2762.0, 52.5547
17.875407304, 96.390, 2757.0, 52.5071
17.927928434, 96.390, 2806.0, 52.9717
17.980449565, 96.390, 2796.0, 52.8772
18.032970696, 96.390, 2865.0, 53.5257
18.085491827, 96.390, 2972.0, 54.5161
18.138012957, 96.390, 2861.0, 53.4883
18.190534088, 96.390, 2965.0, 54.4518
18.243055219, 96.390, 2887.0, 53.7308
18.295576349, 96.390, 2981.0, 54.5985
18.348097480, 96.390, 2814.0, 53.0471
18.400618611, 96.390, 2933.0, 54.1572
18.453139742, 96.390, 2956.0, 54.3691
18.505660872, 96.390, 3057.0, 55.2901
18.558182003, 96.390, 2938.0, 54.2033
18.610703134, 96.390, 2974.0, 54.5344
18.663224264, 96.390, 2957.0, 54.3783
18.715745395, 96.390, 2944.0, 54.2586
18.768266526, 96.390, 3068.0, 55.3895
18.820787657, 96.390, 3050.0, 55.2268
18.873308787, 96.390, 3030.0, 55.0454
18.925829918, 96.390, 3053.0, 55.2540
18.978351049, 96.390, 3146.0, 56.0892
19.030872179, 96.390, 3102.0, 55.6956
19.083393310, 96.390, 3057.0, 55.2901
19.135914441, 96.390, 3148.0, 56.1070
19.188435572, 96.390, 3131.0, 55.9553
19.240956702, 96.390, 3323.0, 57.6455
19.293477833, 96.390, 3142.0, 56.0535
19.345998964, 96.390, 3110.0, 55.7674
19.398520094, 96.390, 3235.0, 56.8771
19.451041225, 96.390, 3262.0, 57.1139
19.503562356, 96.390, 3191.0, 56.4889
19.556083486, 96.390, 3360.0, 57.9655
19.608604617, 96.390, 3230.0, 56.8331
19.661125748, 96.390, 3229.0, 56.8243
19.713646879, 96.390, 3290.0, 57.3585
19.766168009, 96.390, 3344.0, 57.8273
19.818689140, 96.390, 3374.0, 58.0861
19.871210271, 96.390, 3427.0, 58.5406
19.923731401, 96.390, 3531.0, 59.4222
19.976252532, 96.390, 3409.0, 58.3866
20.028773663, 96.390, 3538.0, 59.4811
20.081294794, 96.390, 3751.0, 61.2454
20.133815924, 96.390, 3883.0, 62.3137
20.186337055, 96.390, 4076.0, 63.8436
20.238858186, 96.390, 4034.0, 63.5138
20.291379316, 96.390, 3956.0, 62.8967
20.343900447, 96.390, 3926.0, 62.6578
20.396421578, 96.390, 3784.0, 61.5142
20.448942709, 96.390, 3640.0, 60.3324
20.501463839, 96.390, 3684.0, 60.6960
20.553984970, 96.390, 3570.0, 59.7495
20.606506101, 96.390, 3615.0, 60.1249
20.659027231, 96.390, 3651.0, 60.4235
20.711548362, 96.390, 3728.0, 61.0574
20.764069493, 96.390, 3692.0, 60.7618
20.816590623, 96.390, 3716.0, 60.9590
20.869111754, 96.390, 3672.0, 60.5970
20.921632885, 96.390, 3813.0, 61.7495
20.974154016, 96.390, 3727.0, 61.0492
21.026675146, 96.390, 3786.0, 61.5305
21.079196277, 96.390, 3814.0, 61.7576
21.131717408, 96.390, 3873.0, 62.2334
21.184238538, 96.390, 3981.0, 63.0952
21.236759669, 96.390, 4114.0, 64.1405
21.289280800, 96.390, 4054.0, 63.6710
21.341801931, 96.390, 4261.0, 65.2763
21.394323061, 96.390, 4374.0, 66.1362
21.446844192, 96.390, 4489.0, 67.0000
21.499365323, 96.390, 4205.0, 64.8460
21.551886453, 96.390, 4121.0, 64.1950
21.604407584, 96.390, 4113.0, 64.1327
21.656928715, 96.390, 4034.0, 63.5138
21.709449846, 96.390, 3981.0, 63.0952
21.761970976, 96.390, 3978.0, 63.0714
21.814492107, 96.390, 3948.0, 62.8331
21.867013238, 96.390, 3877.0, 62.2656
21.919534368, 96.390, 3928.0, 62.6738
21.972055499, 96.390, 3911.0, 62.5380
22.024576630, 96.390, 3905.0, 62.4900
22.077097761, 96.390, 3962.0, 62.9444
22.129618891, 96.390, 3957.0, 62.9047
22.182140022, 96.390, 3911.0, 62.5380
22.234661153, 96.390, 3938.0, 62.7535
22.287182283, 96.390, 3922.0, 62.6259
22.339703414, 96.390, 3954.0, 62.8808
22.392224545, 96.390, 3888.0, 62.3538
22.444745675, 96.390, 3938.0, 62.7535
22.497266806, 96.390, 3990.0, 63.1664
22.549787937, 96.390, 3929.0, 62.6817
22.602309068, 96.390, 3990.0, 63.1664
22.654830198, 96.390, 4026.0, 63.4508
22.707351329, 96.390, 3993.0, 63.1902
22.759872460, 96.390, 4116.0, 64.1561
22.812393590, 96.390, 4047.0, 63.6160
22.864914721, 96.390, 4183.0, 64.6761
22.917435852, 96.390, 4146.0, 64.3894
22.969956983, 96.390, 4053.0, 63.6632
23.022478113, 96.390, 3975.0, 63.0476
23.074999244, 96.390, 3947.0, 62.8252
23.127520375, 96.390, 3938.0, 62.7535
23.180041505, 96.390, 3899.0, 62.4420
23.232562636, 96.390, 3915.0, 62.5700
23.285083767, 96.390, 3898.0, 62.4340
23.337604898, 96.390, 3816.0, 61.7738
23.390126028, 96.390, 3781.0, 61.4898
23.442647159, 96.390, 3809.0, 61.7171
23.495168290, 96.390, 3652.0, 60.4318
23.547689420, 96.390, 3797.0, 61.6198
23.600210551, 96.390, 3963.0, 62.9524
23.652731682, 96.390, 3732.0, 61.0901
23.705252813, 96.390, 3820.0, 61.8061
23.757773943, 96.390, 3711.0, 60.9180
23.810295074, 96.390, 3853.0, 62.0725
23.862816205, 96.390, 3663.0, 60.5227
23.915337335, 96.390, 3777.0, 61.4573
23.967858466, 96.390, 3727.0, 61.0492
24.020379597, 96.390, 3620.0, 60.1664
24.072900727, 96.390, 3632.0, 60.2661
24.125421858, 96.390, 3649.0, 60.4070
24.177942989, 96.390, 3642.0, 60.3490
24.230464120, 96.390, 3511.0, 59.2537
24.282985250, 96.390, 3596.0, 59.9667
24.335506381, 96.390, 3583.0, 59.8582
24.388027512, 96.390, 3562.0, 59.6825
24.440548642, 96.390, 3428.0, 58.5491
24.493069773, 96.390, 3486.0, 59.0424
24.545590904, 96.390, 3415.0, 58.4380
24.598112035, 96.390, 3385.0, 58.1808
24.650633165, 96.390, 3534.0, 59.4475
24.703154296, 96.390, 3389.0, 58.2151
24.755675427, 96.390, 3391.0, 58.2323
24.808196557, 96.390, 3396.0, 58.2752
24.860717688, 96.390, 3374.0, 58.0861
24.913238819, 96.390, 3425.0, 58.5235
24.965759950, 96.390, 3372.0, 58.0689
25.018281080, 96.390, 3364.0, 58.0000
25.070802211, 96.390, 3399.0, 58.3009
25.123323342, 96.390, 3408.0, 58.3781
25.175844472, 96.390, 3301.0, 57.4543
25.228365603, 96.390, 3315.0, 57.5760
25.280886734, 96.390, 3243.0, 56.9473
25.333407864, 96.390, 3418.0, 58.4637
25.385928995, 96.390, 3305.0, 57.4891
25.438450126, 96.390, 3181.0, 56.4004
25.490971257, 96.390, 3208.0, 56.6392
25.543492387, 96.390, 3184.0, 56.4269
25.596013518, 96.390, 3108.0, 55.7494
25.648534649, 96.390, 3152.0, 56.1427
25.701055779, 96.390, 3248.0, 56.9912
25.753576910, 96.390, 3112.0, 55.7853
25.806098041, 96.390, 3080.0, 55.4977
25.858619172, 96.390, 2990.0, 54.6809
25.911140302, 96.390, 2978.0, 54.5711
25.963661433, 96.390, 3016.0, 54.9181
26.016182564, 96.390, 3082.0, 55.5158
26.068703694, 96.390, 3061.0, 55.3263
26.121224825, 96.390, 2886.0, 53.7215
26.173745956, 96.390, 2927.0, 54.1018
26.226267087, 96.390, 2862.0, 53.4977
26.278788217, 96.390, 2823.0, 53.1319
26.331309348, 96.390, 2935.0, 54.1756
26.383830479, 96.390, 2872.0, 53.5910
26.436351609, 96.390, 2897.0, 53.8238
26.488872740, 96.390, 2814.0, 53.0471
26.541393871, 96.390, 2895.0, 53.8052
26.593915002, 96.390, 2873.0, 53.6004
26.646436132, 96.390, 2803.0, 52.9434
26.698957263, 96.390, 2792.0, 52.8394
26.751478394, 96.390, 2745.0, 52.3927
26.803999524, 96.390, 2705.0, 52.0096
26.856520655, 96.390, 2658.0, 51.5558
26.909041786, 96.390, 2673.0, 51.7011
26.961562916, 96.390, 2673.0, 51.7011
27.014084047, 96.390, 2665.0, 51.6236
27.066605178, 96.390, 2701.0, 51.9711
27.119126309, 96.390, 2593.0, 50.9215
27.171647439, 96.390, 2629.0, 51.2738
27.224168570, 96.390, 2642.0, 51.4004
27.276689701, 96.390, 2501.0, 50.0100
27.329210831, 96.390, 2630.0, 51.2835
27.381731962, 96.390, 2514.0, 50.1398
27.434253093, 96.390, 2568.0, 50.6754
27.486774224, 96.390, 2510.0, 50.0999
27.539295354, 96.390, 2486.0, 49.8598
27.591816485, 96.390, 2462.0, 49.6185
27.644337616, 96.390, 2489.0, 49.8899
27.696858746, 96.390, 2501.0, 50.0100
27.749379877, 96.390, 2464.0, 49.6387
27.801901008, 96.390, 2576.0, 50.7543
27.854422139, 96.390, 2498.0, 49.9800
27.906943269, 96.390, 2395.0, 48.9387
27.959464400, 96.390, 2344.0, 48.4149
28.011985531, 96.390, 2459.0, 49.5883
28.064506661, 96.390, 2394.0, 48.9285
28.117027792, 96.390, 2306.0, 48.0208
28.169548923, 96.390, 2400.0, 48.9898
28.222070054, 96.390, 2381.0, 48.7955
28.274591184, 96.390, 2342.0, 48.3942
28.327112315, 96.390, 2345.0, 48.4252
28.379633446, 96.390, 2325.0, 48.2183
28.432154576, 96.390, 2226.0, 47.1805
28.484675707, 96.390, 2304.0, 48.0000
28.537196838, 96.390, 2322.0, 48.1871
28.589717968, 96.390, 2312.0, 48.0833
28.642239099, 96.390, 2310.0, 48.0625
28.694760230, 96.390, 2262.0, 47.5605
28.747281361, 96.390, 2224.0, 47.1593
28.799802491, 96.390, 2222.0, 47.1381
28.852323622, 96.390, 2138.0, 46.2385
28.904844753, 96.390, 2093.0, 45.7493
28.957365883, 96.390, 2245.0, 47.3814
29.009887014, 96.390, 2208.0, 46.9894
29.062408145, 96.390, 2212.0, 47.0319
29.114929276, 96.390, 2228.0, 47.2017
29.167450406, 96.390, 2249.0, 47.4236
29.219971537, 96.390, 2234.0, 47.2652
29.272492668, 96.390, 2234.0, 47.2652
29.325013798, 96.390, 2299.0, 47.9479
29.377534929, 96.390, 2254.0, 47.4763
29.430056060, 96.390, 2488.0, 49.8799
29.482577191, 96.390, 2496.0, 49.9600
29.535098321, 96.390, 2629.0, 51.2738
29.587619452, 96.390, 2820.0, 53.1037
29.640140583, 96.390, 3084.0, 55.5338
29.692661713, 96.390, 3027.0, 55.0182
29.745182844, 96.390, 3004.0, 54.8088
29.797703975, 96.390, 2951.0, 54.3231
29.850225105, 96.390, 2761.0, 52.5452
29.902746236, 96.390, 2507.0, 50.0700
29.955267367, 96.390, 2440.0, 49.3964
30.007788498, 96.390, 2260.0, 47.5395
30.060309628, 96.390, 2222.0, 47.1381
30.112830759, 96.390, 2188.0, 46.7761
30.165351890, 96.390, 2177.0, 46.6583
30.217873020, 96.390, 2222.0, 47.1381
30.270394151, 96.390, 2267.0, 47.6130
30.322915282, 96.390, 2264.0, 47.5815
30.375436413, 96.390, 2210.0, 47.0106
30.427957543, 96.390, 2188.0, 46.7761
30.480478674, 96.390, 2201.0, 46.9148
30.532999805, 96.390, 2161.0, 46.4866
30.585520935, 96.390, 2083.0, 45.6399
30.638042066, 96.390, 1972.0, 44.4072
30.690563197, 96.390, 1984.0, 44.5421
30.743084328, 96.390, 1957.0, 44.2380
30.795605458, 96.390, 1930.0, 43.9318
30.848126589, 96.390, 1882.0, 43.3820
30.900647720, 96.390, 1929.0, 43.9204
30.953168850, 96.390, 1902.0, 43.6119
31.005689981, 96.390, 1911.0, 43.7150
31.058211112, 96.390, 1777.0, 42.1545
31.110732243, 96.390, 1807.0, 42.5088
31.163253373, 96.390, 1815.0, 42.6028
31.215774504, 96.390, 1783.0, 42.2256
31.268295635, 96.390, 1735.0, 41.6533
31.320816765, 96.390, 1721.0, 41.4849
31.373337896, 96.390, 1745.0, 41.7732
31.425859027, 96.390, 1721.0, 41.4849
31.478380157, 96.390, 1703.0, 41.2674
31.530901288, 96.390, 1672.0, 40.8901
31.583422419, 96.390, 1712.0, 41.3763
31.635943550, 96.390, 1783.0, 42.2256
31.688464680, 96.390, 1687.0, 41.0731
31.740985811, 96.390, 1755.0, 41.8927
31.793506942, 96.390, 1688.0, 41.0853
31.846028072, 96.390, 1686.0, 41.0609
31.898549203, 96.390, 1690.0, 41.1096
31.951070334, 96.390, 1620.0, 40.2492
32.003591465, 96.390, 1592.0, 39.8999
32.056112595, 96.390, 1606.0, 40.0749
32.108633726, 96.390, 1596.0, 39.9500
32.161154857, 96.390, 1608.0, 40.0999
32.213675987, 96.390, 1561.0, 39.5095
32.266197118, 96.390, 1608.0, 40.0999
32.318718249, 96.390, 1590.0, 39.8748
32.371239380, 96.390, 1572.0, 39.6485
32.423760510, 96.390, 1634.0, 40.4228
32.476281641, 96.390, 1538.0, 39.2173
32.528802772, 96.390, 1591.0, 39.8873
32.581323902, 96.390, 1592.0, 39.8999
32.633845033, 96.390, 1530.0, 39.1152
32.686366164, 96.390, 1548.0, 39.3446
32.738887295, 96.390, 1500.0, 38.7298
32.791408425, 96.390, 1518.0, 38.9615
32.843929556, 96.390, 1467.0, 38.3014
32.896450687, 96.390, 1475.0, 38.4057
32.948971817, 96.390, 1498.0, 38.7040
33.001492948, 96.390, 1437.0, 37.9078
33.054014079, 96.390, 1488.0, 38.5746
33.106535209, 96.390, 1507.0, 38.8201
33.159056340, 96.390, 1486.0, 38.5487
33.211577471, 96.390, 1413.0, 37.5899
33.264098602, 96.390, 1406.0, 37.4967
33.316619732, 96.390, 1351.0, 36.7560
33.369140863, 96.390, 1417.0, 37.6431
33.421661994, 96.390, 1485.0, 38.5357
33.474183124, 96.390, 1408.0, 37.5233
33.526704255, 96.390, 1496.0, 38.6782
33.579225386, 96.390, 1431.0, 37.8286
33.631746517, 96.390, 1445.0, 38.0132
33.684267647, 96.390, 1449.0, 38.0657
33.736788778, 96.390, 1349.0, 36.7287
33.789309909, 96.390, 1415.0, 37.6165
33.841831039, 96.390, 1379.0, 37.1349
33.894352170, 96.390, 1375.0, 37.0810
33.946873301, 96.390, 1370.0, 37.0135
33.999394432, 96.390, 1394.0, 37.3363
34.051915562, 96.390, 1422.0, 37.7094
34.104436693, 96.390, 1385.0, 37.2156
34.156957824, 96.390, 1380.0, 37.1484
34.209478954, 96.390, 1381.0, 37.1618
34.262000085, 96.390, 1305.0, 36.1248
34.314521216, 96.390, 1399.0, 37.4032
34.367042346, 96.390, 1324.0, 36.3868
34.419563477, 96.390, 1380.0, 37.1484
34.472084608, 96.390, 1418.0, 37.6563
34.524605739, 96.390, 1337.0, 36.5650
34.577126869, 96.390, 1340.0, 36.6060
34.629648000, 96.390, 1374.0, 37.0675
34.682169131, 96.390, 1294.0, 35.9722
34.734690261, 96.390, 1329.0, 36.4555
34.787211392, 96.390, 1339.0, 36.5923
34.839732523, 96.390, 1291.0, 35.9305
34.892253654, 96.390, 1298.0, 36.0278
34.944774784, 96.390, 1325.0, 36.4005
34.997295915, 96.390, 1385.0, 37.2156
35.049817046, 96.390, 1244.0, 35.2704
35.102338176, 96.390, 1290.0, 35.9166
35.154859307, 96.390, 1343.0, 36.6470
35.207380438, 96.390, 1280.0, 35.7771
35.259901569, 96.390, 1346.0, 36.6879
35.312422699, 96.390, 1386.0, 37.2290
35.364943830, 96.390, 1400.0, 37.4166
35.417464961, 96.390, 1423.0, 37.7227
35.469986091, 96.390, 1383.0, 37.1887
35.522507222, 96.390, 1396.0, 37.3631
35.575028353, 96.390, 1350.0, 36.7423
35.627549484, 96.390, 1325.0, 36.4005
35.680070614, 96.390, 1332.0, 36.4966
35.732591745, 96.390, 1338.0, 36.5787
35.785112876, 96.390, 1347.0, 36.7015
35.837634006, 96.390, 1324.0, 36.3868
35.890155137, 96.390, 1299.0, 36.0416
35.942676268, 96.390, 1285.0, 35.8469
35.995197398, 96.390, 1246.0, 35.2987
36.047718529, 96.390, 1260.0, 35.4965
36.100239660, 96.390, 1217.0, 34.8855
36.152760791, 96.390, 1198.0, 34.6121
36.205281921, 96.390, 1219.0, 34.9142
36.257803052, 96.390, 1195.0, 34.5688
36.310324183, 96.390, 1218.0, 34.8999
36.362845313, 96.390, 1179.0, 34.3366
36.415366444, 96.390, 1156.0, 34.0000
36.467887575, 96.390, 1210.0, 34.7851
36.520408706, 96.390, 1190.0, 34.4964
36.572929836, 96.390, 1165.0, 34.1321
36.625450967, 96.390, 1244.0, 35.2704
36.677972098, 96.390, 1165.0, 34.1321
36.730493228, 96.390, 1187.0, 34.4529
36.783014359, 96.390, 1140.0, 33.7639
36.835535490, 96.390, 1218.0, 34.8999
36.888056621, 96.390, 1151.0, 33.9264
36.940577751, 96.390, 1113.0, 33.3617
36.993098882, 96.390, 1133.0, 33.6601
37.045620013, 96.390, 1178.0, 34.3220
37.098141143, 96.390, 1124.0, 33.5261
37.150662274, 96.390, 1193.0, 34.5398
37.203183405, 96.390, 1183.0, 34.3948
37.255704535, 96.390, 1099.0, 33.1512
37.308225666, 96.390, 1166.0, 34.1467
37.360746797, 96.390, 1115.0, 33.3916
37.413267928, 96.390, 1111.0, 33.3317
37.465789058, 96.390, 1151.0, 33.9264
37.518310189, 96.390, 1173.0, 34.2491
37.570831320, 96.390, 1122.0, 33.4963
37.623352450, 96.390, 1180.0, 34.3511
37.675873581, 96.390, 1121.0, 33.4813
37.728394712, 96.390, 1139.0, 33.7491
37.780915843, 96.390, 1050.0, 32.4037
37.833436973, 96.390, 1090.0, 33.0151
37.885958104, 96.390, 1068.0, 32.6803
37.938479235, 96.390, 1086.0, 32.9545
37.991000365, 96.390, 1035.0, 32.1714
38.043521496, 96.390, 1134.0, 33.6749
38.096042627, 96.390, 1062.0, 32.5883
38.148563758, 96.390, 1074.0, 32.7719
38.201084888, 96.390, 1081.0, 32.8786
38.253606019, 96.390, 1119.0, 33.4515
38.306127150, 96.390, 1061.0, 32.5730
38.358648280, 96.390, 1044.0, 32.3110
38.411169411, 96.390, 1065.0, 32.6343
38.463690542, 96.390, 1133.0, 33.6601
38.516211673, 96.390, 1046.0, 32.3419
38.568732803, 96.390, 1075.0, 32.7872
38.621253934, 96.390, 1004.0, 31.6860
38.673775065, 96.390, 1024.0, 32.0000
38.726296195, 96.390, 1067.0, 32.6650
38.778817326, 96.390, 954.0, 30.8869
38.831338457, 96.390, 958.0, 30.9516
38.883859587, 96.390, 1013.0, 31.8277
38.936380718, 96.390, 1003.0, 31.6702
38.988901849, 96.390, 1022.0, 31.9687
39.041422980, 96.390, 936.0, 30.5941
39.093944110, 96.390, 972.0, 31.1769
39.146465241, 96.390, 1009.0, 31.7648
39.198986372, 96.390, 980.0, 31.3050
39.251507502, 96.390, 1013.0, 31.8277
39.304028633, 96.390, 1004.0, 31.6860
39.356549764, 96.390, 957.0, 30.9354
39.409070895, 96.390, 954.0, 30.8869
39.461592025, 96.390, 966.0, 31.0805
39.514113156, 96.390, 990.0, 31.4643
39.566634287, 96.390, 959.0, 30.9677
39.619155417, 96.390, 957.0, 30.9354
39.671676548, 96.390, 1005.0, 31.7017
39.724197679, 96.390, 994.0, 31.5278
39.776718810, 96.390, 969.0, 31.1288
39.829239940, 96.390, 990.0, 31.4643
39.881761071, 96.390, 912.0, 30.1993
39.934282202, 96.390, 961.0, 31.0000
39.986803332, 96.390, 926.0, 30.4302
40.039324463, 96.390, 908.0, 30.1330
40.091845594, 96.390, 944.0, 30.7246
40.144366725, 96.390, 927.0, 30.4467
40.196887855, 96.390, 942.0, 30.6920
40.249408986, 96.390, 941.0, 30.6757
40.301930117, 96.390, 957.0, 30.9354
40.354451247, 96.390, 988.0, 31.4325
40.406972378, 96.390, 1003.0, 31.6702
40.459493509, 96.390, 980.0, 31.3050
40.512014639, 96.390, 920.0, 30.3315
40.564535770, 96.390, 976.0, 31.2410
40.617056901, 96.390, 963.0, 31.0322
40.669578032, 96.390, 951.0, 30.8383
40.722099162, 96.390, 953.0, 30.8707
40.774620293, 96.390, 976.0, 31.2410
40.827141424, 96.390, 954.0, 30.8869
40.879662554, 96.390, 928.0, 30.4631
40.932183685, 96.390, 931.0, 30.5123
40.984704816, 96.390, 932.0, 30.5287
41.037225947, 96.390, 917.0, 30.2820
41.089747077, 96.390, 918.0, 30.2985
41.142268208, 96.390, 908.0, 30.1330
41.194789339, 96.390, 881.0, 29.6816
41.247310469, 96.390, 904.0, 30.0666
41.299831600, 96.390, 970.0, 31.1448
41.352352731, 96.390, 948.0, 30.7896
41.404873862, 96.390, 969.0, 31.1288
41.457394992, 96.390, 897.0, 29.9500
41.509916123, 96.390, 939.0, 30.6431
41.562437254, 96.390, 883.0, 29.7153
41.614958384, 96.390, 890.0, 29.8329
41.667479515, 96.390, 956.0, 30.9192
41.720000646, 96.390, 921.0, 30.3480
41.772521776, 96.390, 910.0, 30.1662
41.825042907, 96.390, 887.0, 29.7825
41.877564038, 96.390, 926.0, 30.4302
41.930085169, 96.390, 905.0, 30.0832
41.982606299, 96.390, 885.0, 29.7489
42.035127430, 96.390, 925.0, 30.4138
42.087648561, 96.390, 876.0, 29.5973
42.140169691, 96.390, 959.0, 30.9677
42.192690822, 96.390, 926.0, 30.4302
42.245211953, 96.390, 924.0, 30.3974
42.297733084, 96.390, 913.0, 30.2159
42.350254214, 96.390, 905.0, 30.0832
42.402775345, 96.390, 936.0, 30.5941
42.455296476, 96.390, 905.0, 30.0832
42.507817606, 96.390, 953.0, 30.8707
42.560338737, 96.390, 949.0, 30.8058
42.612859868, 96.390, 923.0, 30.3809
42.665380999, 96.390, 954.0, 30.8869
42.717902129, 96.390, 946.0, 30.7571
42.770423260, 96.390, 975.0, 31.2250
42.822944391, 96.390, 930.0, 30.4959
42.875465521, 96.390, 970.0, 31.1448
42.927986652, 96.390, 925.0, 30.4138
42.980507783, 96.390, 1038.0, 32.2180
43.033028914, 96.390, 987.0, 31.4166
43.085550044, 96.390, 1030.0, 32.0936
43.138071175, 96.390, 995.0, 31.5436
43.190592306, 96.390, 1023.0, 31.9844
43.243113436, 96.390, 962.0, 31.0161
43.295634567, 96.390, 913.0, 30.2159
43.348155698, 96.390, 980.0, 31.3050
43.400676828, 96.390, 967.0, 31.0966
43.453197959, 96.390, 948.0, 30.7896
43.505719090, 96.390, 939.0, 30.6431
43.558240221, 96.390, 948.0, 30.7896
43.610761351, 96.390, 965.0, 31.0644
43.663282482, 96.390, 928.0, 30.4631
43.715803613, 96.390, 949.0, 30.8058
43.768324743, 96.390, 927.0, 30.4467
43.820845874, 96.390, 879.0, 29.6479
43.873367005, 96.390, 976.0, 31.2410
43.925888136, 96.390, 929.0, 30.4795
43.978409266, 96.390, 951.0, 30.8383
44.030930397, 96.390, 1018.0, 31.9061
44.083451528, 96.390, 957.0, 30.9354
44.135972658, 96.390, 982.0, 31.3369
44.188493789, 96.390, 970.0, 31.1448
44.241014920, 96.390, 1020.0, 31.9374
44.293536051, 96.390, 953.0, 30.8707
44.346057181, 96.390, 978.0, 31.2730
44.398578312, 96.390, 948.0, 30.7896
44.451099443, 96.390, 950.0, 30.8221
44.503620573, 96.390, 918.0, 30.2985
44.556141704, 96.390, 891.0, 29.8496
44.608662835, 96.390, 949.0, 30.8058
44.661183966, 96.390, 917.0, 30.2820
44.713705096, 96.390, 910.0, 30.1662
44.766226227, 96.390, 914.0, 30.2324
44.818747358, 96.390, 862.0, 29.3598
44.871268488, 96.390, 944.0, 30.7246
44.923789619, 96.390, 910.0, 30.1662
44.976310750, 96.390, 902.0, 30.0333
45.028831880, 96.390, 919.0, 30.3150
45.081353011, 96.390, 957.0, 30.9354
45.133874142, 96.390, 922.0, 30.3645
45.186395273, 96.390, 958.0, 30.9516
45.238916403, 96.390, 835.0, 28.8964
45.291437534, 96.390, 896.0, 29.9333
45.343958665, 96.390, 900.0, 30.0000
45.396479795, 96.390, 879.0, 29.6479
45.449000926, 96.390, 848.0, 29.1204
45.501522057, 96.390, 875.0, 29.5804
45.554043188, 96.390, 846.0, 29.0861
45.606564318, 96.390, 927.0, 30.4467
45.659085449, 96.390, 908.0, 30.1330
45.711606580, 96.390, 880.0, 29.6648
45.764127710, 96.390, 899.0, 29.9833
45.816648841, 96.390, 924.0, 30.3974
45.869169972, 96.390, 916.0, 30.2655
45.921691103, 96.390, 881.0, 29.6816
45.974212233, 96.390, 903.0, 30.0500
46.026733364, 96.390, 860.0, 29.3258
46.079254495, 96.390, 880.0, 29.6648
46.131775625, 96.390, 869.0, 29.4788
46.184296756, 96.390, 877.0, 29.6142
46.236817887, 96.390, 875.0, 29.5804
46.289339017, 96.390, 902.0, 30.0333
46.341860148, 96.390, 952.0, 30.8545
46.394381279, 96.390, 853.0, 29.2062
46.446902410, 96.390, 876.0, 29.5973
46.499423540, 96.390, 904.0, 30.0666
46.551944671, 96.390, 912.0, 30.1993
46.604465802, 96.390, 857.0, 29.2746
46.656986932, 96.390, 859.0, 29.3087
46.709508063, 96.390, 888.0, 29.7993
46.762029194, 96.390, 851.0, 29.1719
46.814550325, 96.390, 870.0, 29.4958
46.867071455, 96.390, 858.0, 29.2916
46.919592586, 96.390, 820.0, 28.6356
46.972113717, 96.390, 844.0, 29.0517
47.024634847, 96.390, 882.0, 29.6985
47.077155978, 96.390, 840.0, 28.9828
47.129677109, 96.390, 844.0, 29.0517
47.182198240, 96.390, 841.0, 29.0000
47.234719370, 96.390, 821.0, 28.6531
47.287240501, 96.390, 835.0, 28.8964
47.339761632, 96.390, 872.0, 29.5296
47.392282762, 96.390, 922.0, 30.3645
47.444803893, 96.390, 860.0, 29.3258
47.497325024, 96.390, 852.0, 29.1890
47.549846155, 96.390, 881.0, 29.6816
47.602367285, 96.390, 882.0, 29.6985
47.654888416, 96.390, 842.0, 29.0172
47.707409547, 96.390, 869.0, 29.4788
47.759930677, 96.390, 825.0, 28.7228
47.812451808, 96.390, 847.0, 29.1033
47.864972939, 96.390, 888.0, 29.7993
47.917494069, 96.390, 862.0, 29.3598
47.970015200, 96.390, 854.0, 29.2233
48.022536331, 96.390, 876.0, 29.5973
48.075057462, 96.390, 867.0, 29.4449
48.127578592, 96.390, 863.0, 29.3769
48.180099723, 96.390, 848.0, 29.1204
48.232620854, 96.390, 860.0, 29.3258
48.285141984, 96.390, 880.0, 29.6648
48.337663115, 96.390, 865.0, 29.4109
48.390184246, 96.390, 856.0, 29.2575
48.442705377, 96.390, 918.0, 30.2985
48.495226507, 96.390, 913.0, 30.2159
48.547747638, 96.390, 903.0, 30.0500
48.600268769, 96.390, 861.0, 29.3428
48.652789899, 96.390, 884.0, 29.7321
48.705311030, 96.390, 884.0, 29.7321
48.757832161, 96.390, 901.0, 30.0167
48.810353292, 96.390, 898.0, 29.9666
48.862874422, 96.390, 891.0, 29.8496
48.915395553, 96.390, 884.0, 29.7321
48.967916684, 96.390, 874.0, 29.5635
49.020437814, 96.390, 795.0, 28.1957
49.072958945, 96.390, 862.0, 29.3598
49.125480076, 96.390, 889.0, 29.8161
49.178001207, 96.390, 868.0, 29.4618
49.230522337, 96.390, 902.0, 30.0333
49.283043468, 96.390, 850.0, 29.1548
49.335564599, 96.390, 910.0, 30.1662
49.388085729, 96.390, 854.0, 29.2233
49.440606860, 96.390, 907.0, 30.1164
49.493127991, 96.390, 895.0, 29.9166
49.545649121, 96.390, 871.0, 29.5127
49.598170252, 96.390, 866.0, 29.4279
49.650691383, 96.390, 921.0, 30.3480
49.703212514, 96.390, 866.0, 29.4279
49.755733644, 96.390, 853.0, 29.2062
49.808254775, 96.390, 855.0, 29.2404
49.860775906, 96.390, 884.0, 29.7321
49.913297036, 96.390, 880.0, 29.6648
49.965818167, 96.390, 836.0, 28.9137
50.018339298, 96.390, 881.0, 29.6816
50.070860429, 96.390, 806.0, 28.3901
50.123381559, 96.390, 880.0, 29.6648
50.175902690, 96.390, 830.0, 28.8097
50.228423821, 96.390, 901.0, 30.0167
50.280944951, 96.390, 757.0, 27.5136
50.333466082, 96.390, 795.0, 28.1957
50.385987213, 96.390, 779.0, 27.9106
50.438508344, 96.390, 758.0, 27.5318
50.491029474, 96.390, 812.0, 28.4956
50.543550605, 96.390, 827.0, 28.7576
50.596071736, 96.390, 841.0, 29.0000
50.648592866, 96.390, 809.0, 28.4429
50.701113997, 96.390, 846.0, 29.0861
50.753635128, 96.390, 803.0, 28.3373
50.806156258, 96.390, 810.0, 28.4605
50.858677389, 96.390, 830.0, 28.8097
50.911198520, 96.390, 810.0, 28.4605
50.963719651, 96.390, 756.0, 27.4955
51.016240781, 96.390, 786.0, 28.0357
51.068761912, 96.390, 816.0, 28.5657
51.121283043, 96.390, 738.0, 27.1662
51.173804173, 96.390, 775.0, 27.8388
51.226325304, 96.390, 815.0, 28.5482
51.278846435, 96.390, 802.0, 28.3196
51.331367566, 96.390, 803.0, 28.3373
51.383888696, 96.390, 739.0, 27.1846
51.436409827, 96.390, 745.0, 27.2947
51.488930958, 96.390, 800.0, 28.2843
51.541452088, 96.390, 733.0, 27.0740
51.593973219, 96.390, 771.0, 27.7669
51.646494350, 96.390, 792.0, 28.1425
51.699015481, 96.390, 823.0, 28.6880
51.751536611, 96.390, 811.0, 28.4781
51.804057742, 96.390, 754.0, 27.4591
51.856578873, 96.390, 820.0, 28.6356
51.909100003, 96.390, 758.0, 27.5318
51.961621134, 96.390, 829.0, 28.7924
52.014142265, 96.390, 770.0, 27.7489
52.066663396, 96.390, 748.0, 27.3496
52.119184526, 96.390, 759.0, 27.5500
52.171705657, 96.390, 748.0, 27.3496
52.224226788, 96.390, 813.0, 28.5132
52.276747918, 96.390, 801.0, 28.3019
52.329269049, 96.390, 845.0, 29.0689
52.381790180, 96.390, 825.0, 28.7228
52.434311310, 96.390, 786.0, 28.0357
52.486832441, 96.390, 813.0, 28.5132
52.539353572, 96.390, 784.0, 28.0000
52.591874703, 96.390, 778.0, 27.8927
52.644395833, 96.390, 728.0, 26.9815
52.696916964, 96.390, 736.0, 27.1293
52.749438095, 96.390, 795.0, 28.1957
52.801959225, 96.390, 826.0, 28.7402
52.854480356, 96.390, 759.0, 27.5500
52.907001487, 96.390, 834.0, 28.8791
52.959522618, 96.390, 798.0, 28.2489
53.012043748, 96.390, 756.0, 27.4955
53.064564879, 96.390, 741.0, 27.2213
53.117086010, 96.390, 738.0, 27.1662
53.169607140, 96.390, 771.0, 27.7669
53.222128271, 96.390, 821.0, 28.6531
53.274649402, 96.390, 766.0, 27.6767
53.327170533, 96.390, 814.0, 28.5307
53.379691663, 96.390, 792.0, 28.1425
53.432212794, 96.390, 808.0, 28.4253
53.484733925, 96.390, 801.0, 28.3019
53.537255055, 96.390, 782.0, 27.9643
53.589776186, 96.390, 798.0, 28.2489
53.642297317, 96.390, 799.0, 28.2666
53.694818448, 96.390, 747.0, 27.3313
53.747339578, 96.390, 767.0, 27.6948
53.799860709, 96.390, 793.0, 28.1603
53.852381840, 96.390, 814.0, 28.5307
53.904902970, 96.390, 788.0, 28.0713
53.957424101, 96.390, 792.0, 28.1425
54.009945232, 96.390, 790.0, 28.1069
54.062466362, 96.390, 808.0, 28.4253
54.114987493, 96.390, 774.0, 27.8209
54.167508624, 96.390, 788.0, 28.0713
54.220029755, 96.390, 830.0, 28.8097
54.272550885, 96.390, 810.0, 28.4605
54.325072016, 96.390, 799.0, 28.2666
54.377593147, 96.390, 802.0, 28.3196
54.430114277, 96.390, 853.0, 29.2062
54.482635408, 96.390, 811.0, 28.4781
54.535156539, 96.390, 805.0, 28.3725
54.587677670, 96.390, 841.0, 29.0000
54.640198800, 96.390, 800.0, 28.2843
54.692719931, 96.390, 798.0, 28.2489
54.745241062, 96.390, 792.0, 28.1425
54.797762192, 96.390, 819.0, 28.6182
54.850283323, 96.390, 837.0, 28.9310
54.902804454, 96.390, 806.0, 28.3901
54.955325585, 96.390, 775.0, 27.8388
55.007846715, 96.390, 818.0, 28.6007
55.060367846, 96.390, 743.0, 27.2580
55.112888977, 96.390, 768.0, 27.7128
55.165410107, 96.390, 770.0, 27.7489
55.217931238, 96.390, 828.0, 28.7750
55.270452369, 96.390, 785.0, 28.0179
55.322973499, 96.390, 724.0, 26.9072
55.375494630, 96.390, 808.0, 28.4253
55.428015761, 96.390, 772.0, 27.7849
55.480536892, 96.390, 769.0, 27.7308
55.533058022, 96.390, 844.0, 29.0517
55.585579153, 96.390, 805.0, 28.3725
55.638100284, 96.390, 813.0, 28.5132
55.690621414, 96.390, 726.0, 26.9444
55.743142545, 96.390, 784.0, 28.0000
55.795663676, 96.390, 770.0, 27.7489
55.848184807, 96.390, 752.0, 27.4226
55.900705937, 96.390, 776.0, 27.8568
55.953227068, 96.390, 777.0, 27.8747
56.005748199, 96.390, 772.0, 27.7849
56.058269329, 96.390, 740.0, 27.2029
56.110790460, 96.390, 811.0, 28.4781
56.163311591, 96.390, 786.0, 28.0357
56.215832722, 96.390, 742.0, 27.2397
56.268353852, 96.390, 766.0, 27.6767
56.320874983, 96.390, 834.0, 28.8791
56.373396114, 96.390, 825.0, 28.7228
56.425917244, 96.390, 800.0, 28.2843
56.478438375, 96.390, 804.0, 28.3549
56.530959506, 96.390, 780.0, 27.9285
56.583480637, 96.390, 813.0, 28.5132
56.636001767, 96.390, 771.0, 27.7669
56.688522898, 96.390, 786.0, 28.0357
56.741044029, 96.390, 824.0, 28.7054
56.793565159, 96.390, 861.0, 29.3428
56.846086290, 96.390, 804.0, 28.3549
56.898607421, 96.390, 797.0, 28.2312
56.951128551, 96.390, 787.0, 28.0535
57.003649682, 96.390, 777.0, 27.8747
57.056170813, 96.390, 816.0, 28.5657
57.108691944, 96.390, 846.0, 29.0861
57.161213074, 96.390, 790.0, 28.1069
57.213734205, 96.390, 806.0, 28.3901
57.266255336, 96.390, 757.0, 27.5136
57.318776466, 96.390, 731.0, 27.0370
57.371297597, 96.390, 801.0, 28.3019
57.423818728, 96.390, 811.0, 28.4781
57.476339859, 96.390, 845.0, 29.0689
57.528860989, 96.390, 747.0, 27.3313
57.581382120, 96.390, 828.0, 28.7750
57.633903251, 96.390, 754.0, 27.4591
57.686424381, 96.390, 783.0, 27.9821
57.738945512, 96.390, 775.0, 27.8388
57.791466643, 96.390, 795.0, 28.1957
57.843987774, 96.390, 745.0, 27.2947
57.896508904, 96.390, 815.0, 28.5482
57.949030035, 96.390, 795.0, 28.1957
58.001551166, 96.390, 783.0, 27.9821
58.054072296, 96.390, 765.0, 27.6586
58.106593427, 96.390, 784.0, 28.0000
58.159114558, 96.390, 849.0, 29.1376
58.211635689, 96.390, 813.0, 28.5132
58.264156819, 96.390, 824.0, 28.7054
58.316677950, 96.390, 843.0, 29.0345
58.369199081, 96.390, 853.0, 29.2062
58.421720211, 96.390, 896.0, 29.9333
58.474241342, 96.390, 890.0, 29.8329
58.526762473, 96.390, 885.0, 29.7489
58.579283603, 96.390, 877.0, 29.6142
58.631804734, 96.390, 913.0, 30.2159
58.684325865, 96.390, 882.0, 29.6985
58.736846996, 96.390, 903.0, 30.0500
58.789368126, 96.390, 840.0, 28.9828
58.841889257, 96.390, 801.0, 28.3019
58.894410388, 96.390, 807.0, 28.4077
58.946931518, 96.390, 837.0, 28.9310
58.999452649, 96.390, 756.0, 27.4955
59.051973780, 96.390, 787.0, 28.0535
59.104494911, 96.390, 840.0, 28.9828
59.157016041, 96.390, 810.0, 28.4605
59.209537172, 96.390, 789.0, 28.0891
59.262058303, 96.390, 772.0, 27.7849
59.314579433, 96.390, 730.0, 27.0185
59.367100564, 96.390, 795.0, 28.1957
59.419621695, 96.390, 794.0, 28.1780
59.472142826, 96.390, 792.0, 28.1425
59.524663956, 96.390, 854.0, 29.2233
59.577185087, 96.390, 800.0, 28.2843
59.629706218, 96.390, 819.0, 28.6182
59.682227348, 96.390, 822.0, 28.6705
59.734748479, 96.390, 830.0, 28.8097
59.787269610, 96.390, 779.0, 27.9106
59.839790740, 96.390, 772.0, 27.7849
59.892311871, 96.390, 740.0, 27.2029
59.944833002, 96.390, 789.0, 28.0891
59.997354133, 96.390, 756.0, 27.4955
60.049875263, 96.390, 792.0, 28.1425
60.102396394, 96.390, 793.0, 28.1603
60.154917525, 96.390, 727.0, 26.9629
60.207438655, 96.390, 787.0, 28.0535
60.259959786, 96.390, 813.0, 28.5132
60.312480917, 96.390, 822.0, 28.6705
60.365002048, 96.390, 772.0, 27.7849
60.417523178, 96.390, 756.0, 27.4955
60.470044309, 96.390, 844.0, 29.0517
60.522565440, 96.390, 798.0, 28.2489
60.575086570, 96.390, 779.0, 27.9106
60.627607701, 96.390, 772.0, 27.7849
60.680128832, 96.390, 754.0, 27.4591
60.732649963, 96.390, 784.0, 28.0000
60.785171093, 96.390, 808.0, 28.4253
60.837692224, 96.390, 791.0, 28.1247
60.890213355, 96.390, 788.0, 28.0713
60.942734485, 96.390, 784.0, 28.0000
60.995255616, 96.390, 789.0, 28.0891
61.047776747, 96.390, 831.0, 28.8271
61.100297878, 96.390, 828.0, 28.7750
61.152819008, 96.390, 785.0, 28.0179
61.205340139, 96.390, 804.0, 28.3549
61.257861270, 96.390, 793.0, 28.1603
61.310382400, 96.390, 852.0, 29.1890
61.362903531, 96.390, 804.0, 28.3549
61.415424662, 96.390, 789.0, 28.0891
61.467945792, 96.390, 787.0, 28.0535
61.520466923, 96.390, 840.0, 28.9828
61.572988054, 96.390, 798.0, 28.2489
61.625509185, 96.390, 837.0, 28.9310
61.678030315, 96.390, 792.0, 28.1425
61.730551446, 96.390, 807.0, 28.4077
61.783072577, 96.390, 841.0, 29.0000
61.835593707, 96.390, 822.0, 28.6705
61.888114838, 96.390, 841.0, 29.0000
61.940635969, 96.390, 858.0, 29.2916
61.993157100, 96.390, 777.0, 27.8747
62.045678230, 96.390, 789.0, 28.0891
62.098199361, 96.390, 808.0, 28.4253
62.150720492, 96.390, 831.0, 28.8271
62.203241622, 96.390, 752.0, 27.4226
62.255762753, 96.390, 821.0, 28.6531
62.308283884, 96.390, 850.0, 29.1548
62.360805015, 96.390, 822.0, 28.6705
62.413326145, 96.390, 800.0, 28.2843
62.465847276, 96.390, 790.0, 28.1069
62.518368407, 96.390, 789.0, 28.0891
62.570889537, 96.390, 826.0, 28.7402
62.623410668, 96.390, 804.0, 28.3549
62.675931799, 96.390, 841.0, 29.0000
62.728452930, 96.390, 805.0, 28.3725
62.780974060, 96.390, 850.0, 29.1548
62.833495191, 96.390, 821.0, 28.6531
62.886016322, 96.390, 850.0, 29.1548
62.938537452, 96.390, 842.0, 29.0172
62.991058583, 96.390, 802.0, 28.3196
63.043579714, 96.390, 888.0, 29.7993
63.096100844, 96.390, 844.0, 29.0517
63.148621975, 96.390, 854.0, 29.2233
63.201143106, 96.390, 811.0, 28.4781
63.253664237, 96.390, 865.0, 29.4109
63.306185367, 96.390, 904.0, 30.0666
63.358706498, 96.390, 855.0, 29.2404
63.411227629, 96.390, 838.0, 28.9482
63.463748759, 96.390, 876.0, 29.5973
63.516269890, 96.390, 788.0, 28.0713
63.568791021, 96.390, 789.0, 28.0891
63.621312152, 96.390, 848.0, 29.1204
63.673833282, 96.390, 792.0, 28.1425
63.726354413, 96.390, 855.0, 29.2404
63.778875544, 96.390, 899.0, 29.9833
63.831396674, 96.390, 759.0, 27.5500
63.883917805, 96.390, 779.0, 27.9106
63.936438936, 96.390, 844.0, 29.0517
63.988960067, 96.390, 821.0, 28.6531
64.041481197, 96.390, 792.0, 28.1425
64.094002328, 96.390, 822.0, 28.6705
64.146523459, 96.390, 816.0, 28.5657
64.199044589, 96.390, 813.0, 28.5132
64.251565720, 96.390, 797.0, 28.2312
64.304086851, 96.390, 731.0, 27.0370
64.356607981, 96.390, 825.0, 28.7228
64.409129112, 96.390, 810.0, 28.4605
64.461650243, 96.390, 763.0, 27.6225
64.514171374, 96.390, 801.0, 28.3019
64.566692504, 96.390, 789.0, 28.0891
64.619213635, 96.390, 831.0, 28.8271
64.671734766, 96.390, 822.0, 28.6705
64.724255896, 96.390, 762.0, 27.6043
64.776777027, 96.390, 792.0, 28.1425
64.829298158, 96.390, 760.0, 27.5681
64.881819289, 96.390, 824.0, 28.7054
64.934340419, 96.390, 822.0, 28.6705
64.986861550, 96.390, 813.0, 28.5132