File: Files_organized_for_plots/PC/XRD_PC_SiAxialPrecursor12Jan22_B2_1.csv
[Measurement conditions]
Sample identification,XRD_SiAxialPrecursor12Jan22_B2_1
Comment - 1,"Configuration=Stage for Flat Samples/Holders, Owner=User-1, Creation date=7/1/2020 9:53:24 AM"
Comment - 2,"Goniometer=Theta/Theta; Minimum step size 2Theta:0.0001; Minimum step size Omega:0.0001"
Comment - 3,"Sample stage=Stage for flat samples/holders"
Comment - 4,"Diffractometer system=EMPYREAN"
Comment - 5,"Measurement program=C:\Users\ibo5034\OneDrive - The Pennsylvania State University\NEUP\Zerobackground scan.xrdmp, Identifier={98A3B11C-88F9-4AA6-982C-73314A311EF5}"
Anode material,Cu
K-Alpha1 wavelength,1.5405980
K-Alpha2 wavelength,1.5444260
Ratio K-Alpha2/K-Alpha1,0.500
Divergence slit,Fixed,0.25
Monochromator used,NO
Generator voltage, 45
Tube current, 40
File date and time,11/Mar/2022 12:07
Unit cell,
h k l, 0 0 0
Scan axis,Gonio
Scan range,4.994599997,64.999991833
Scan step size,0.0262606
No. of points, 2285
Scan type,CONTINUOUS
Time per step,96.390
[Scan points]
Angle, TimePerStep, Intensity, ESD
5.007730280, 96.390, 5193.0, 72.0625
5.060251411, 96.390, 4936.0, 70.2567
5.112772541, 96.390, 4922.0, 70.1570
5.165293672, 96.390, 4841.0, 69.5773
5.217814803, 96.390, 4838.0, 69.5557
5.270335934, 96.390, 4614.0, 67.9264
5.322857064, 96.390, 4446.0, 66.6783
5.375378195, 96.390, 4456.0, 66.7533
5.427899326, 96.390, 4362.0, 66.0454
5.480420456, 96.390, 4324.0, 65.7571
5.532941587, 96.390, 4269.0, 65.3376
5.585462718, 96.390, 4285.0, 65.4599
5.637983849, 96.390, 4233.0, 65.0615
5.690504979, 96.390, 4176.0, 64.6220
5.743026110, 96.390, 4111.0, 64.1171
5.795547241, 96.390, 4118.0, 64.1716
5.848068371, 96.390, 4100.0, 64.0312
5.900589502, 96.390, 4009.0, 63.3167
5.953110633, 96.390, 4034.0, 63.5138
6.005631763, 96.390, 4001.0, 63.2535
6.058152894, 96.390, 3899.0, 62.4420
6.110674025, 96.390, 3905.0, 62.4900
6.163195156, 96.390, 3785.0, 61.5224
6.215716286, 96.390, 3685.0, 60.7042
6.268237417, 96.390, 3711.0, 60.9180
6.320758548, 96.390, 3629.0, 60.2412
6.373279678, 96.390, 3705.0, 60.8687
6.425800809, 96.390, 3736.0, 61.1228
6.478321940, 96.390, 3633.0, 60.2744
6.530843071, 96.390, 3537.0, 59.4727
6.583364201, 96.390, 3591.0, 59.9250
6.635885332, 96.390, 3451.0, 58.7452
6.688406463, 96.390, 3535.0, 59.4559
6.740927593, 96.390, 3589.0, 59.9083
6.793448724, 96.390, 3486.0, 59.0424
6.845969855, 96.390, 3508.0, 59.2284
6.898490986, 96.390, 3410.0, 58.3952
6.951012116, 96.390, 3313.0, 57.5587
7.003533247, 96.390, 3398.0, 58.2924
7.056054378, 96.390, 3352.0, 57.8965
7.108575508, 96.390, 3363.0, 57.9914
7.161096639, 96.390, 3334.0, 57.7408
7.213617770, 96.390, 3324.0, 57.6541
7.266138900, 96.390, 3296.0, 57.4108
7.318660031, 96.390, 3250.0, 57.0088
7.371181162, 96.390, 3254.0, 57.0438
7.423702293, 96.390, 3182.0, 56.4092
7.476223423, 96.390, 3362.0, 57.9828
7.528744554, 96.390, 3151.0, 56.1338
7.581265685, 96.390, 3219.0, 56.7362
7.633786815, 96.390, 3090.0, 55.5878
7.686307946, 96.390, 3304.0, 57.4804
7.738829077, 96.390, 3211.0, 56.6657
7.791350208, 96.390, 3156.0, 56.1783
7.843871338, 96.390, 3105.0, 55.7225
7.896392469, 96.390, 3124.0, 55.8928
7.948913600, 96.390, 2982.0, 54.6077
8.001434730, 96.390, 3212.0, 56.6745
8.053955861, 96.390, 3040.0, 55.1362
8.106476992, 96.390, 3153.0, 56.1516
8.158998123, 96.390, 2953.0, 54.3415
8.211519253, 96.390, 3063.0, 55.3444
8.264040384, 96.390, 2971.0, 54.5069
8.316561515, 96.390, 2907.0, 53.9166
8.369082645, 96.390, 2885.0, 53.7122
8.421603776, 96.390, 2936.0, 54.1849
8.474124907, 96.390, 2973.0, 54.5252
8.526646038, 96.390, 2926.0, 54.0925
8.579167168, 96.390, 2920.0, 54.0370
8.631688299, 96.390, 2959.0, 54.3967
8.684209430, 96.390, 2972.0, 54.5161
8.736730560, 96.390, 2915.0, 53.9907
8.789251691, 96.390, 2772.0, 52.6498
8.841772822, 96.390, 2850.0, 53.3854
8.894293952, 96.390, 2804.0, 52.9528
8.946815083, 96.390, 2758.0, 52.5167
8.999336214, 96.390, 2819.0, 53.0943
9.051857345, 96.390, 2783.0, 52.7541
9.104378475, 96.390, 2835.0, 53.2447
9.156899606, 96.390, 2799.0, 52.9056
9.209420737, 96.390, 2885.0, 53.7122
9.261941867, 96.390, 2823.0, 53.1319
9.314462998, 96.390, 2697.0, 51.9326
9.366984129, 96.390, 2799.0, 52.9056
9.419505260, 96.390, 2761.0, 52.5452
9.472026390, 96.390, 2731.0, 52.2590
9.524547521, 96.390, 2816.0, 53.0660
9.577068652, 96.390, 2654.0, 51.5170
9.629589782, 96.390, 2722.0, 52.1728
9.682110913, 96.390, 2641.0, 51.3907
9.734632044, 96.390, 2694.0, 51.9038
9.787153175, 96.390, 2599.0, 50.9804
9.839674305, 96.390, 2643.0, 51.4101
9.892195436, 96.390, 2641.0, 51.3907
9.944716567, 96.390, 2640.0, 51.3809
9.997237697, 96.390, 2506.0, 50.0600
10.049758828, 96.390, 2638.0, 51.3615
10.102279959, 96.390, 2498.0, 49.9800
10.154801090, 96.390, 2562.0, 50.6162
10.207322220, 96.390, 2584.0, 50.8331
10.259843351, 96.390, 2540.0, 50.3984
10.312364482, 96.390, 2605.0, 51.0392
10.364885612, 96.390, 2459.0, 49.5883
10.417406743, 96.390, 2555.0, 50.5470
10.469927874, 96.390, 2437.0, 49.3660
10.522449004, 96.390, 2533.0, 50.3289
10.574970135, 96.390, 2605.0, 51.0392
10.627491266, 96.390, 2468.0, 49.6790
10.680012397, 96.390, 2500.0, 50.0000
10.732533527, 96.390, 2495.0, 49.9500
10.785054658, 96.390, 2396.0, 48.9490
10.837575789, 96.390, 2508.0, 50.0799
10.890096919, 96.390, 2434.0, 49.3356
10.942618050, 96.390, 2402.0, 49.0102
10.995139181, 96.390, 2483.0, 49.8297
11.047660312, 96.390, 2357.0, 48.5489
11.100181442, 96.390, 2397.0, 48.9592
11.152702573, 96.390, 2474.0, 49.7393
11.205223704, 96.390, 2424.0, 49.2341
11.257744834, 96.390, 2352.0, 48.4974
11.310265965, 96.390, 2364.0, 48.6210
11.362787096, 96.390, 2353.0, 48.5077
11.415308227, 96.390, 2365.0, 48.6313
11.467829357, 96.390, 2410.0, 49.0918
11.520350488, 96.390, 2348.0, 48.4562
11.572871619, 96.390, 2330.0, 48.2701
11.625392749, 96.390, 2338.0, 48.3529
11.677913880, 96.390, 2298.0, 47.9375
11.730435011, 96.390, 2271.0, 47.6550
11.782956141, 96.390, 2357.0, 48.5489
11.835477272, 96.390, 2275.0, 47.6970
11.887998403, 96.390, 2291.0, 47.8644
11.940519534, 96.390, 2208.0, 46.9894
11.993040664, 96.390, 2141.0, 46.2709
12.045561795, 96.390, 2346.0, 48.4355
12.098082926, 96.390, 2268.0, 47.6235
12.150604056, 96.390, 2243.0, 47.3603
12.203125187, 96.390, 2305.0, 48.0104
12.255646318, 96.390, 2278.0, 47.7284
12.308167449, 96.390, 2257.0, 47.5079
12.360688579, 96.390, 2238.0, 47.3075
12.413209710, 96.390, 2151.0, 46.3789
12.465730841, 96.390, 2206.0, 46.9681
12.518251971, 96.390, 2291.0, 47.8644
12.570773102, 96.390, 2225.0, 47.1699
12.623294233, 96.390, 2175.0, 46.6369
12.675815364, 96.390, 2207.0, 46.9787
12.728336494, 96.390, 2155.0, 46.4220
12.780857625, 96.390, 2240.0, 47.3286
12.833378756, 96.390, 2187.0, 46.7654
12.885899886, 96.390, 2194.0, 46.8402
12.938421017, 96.390, 2070.0, 45.4973
12.990942148, 96.390, 2138.0, 46.2385
13.043463279, 96.390, 2109.0, 45.9239
13.095984409, 96.390, 2247.0, 47.4025
13.148505540, 96.390, 2130.0, 46.1519
13.201026671, 96.390, 2192.0, 46.8188
13.253547801, 96.390, 2221.0, 47.1275
13.306068932, 96.390, 2121.0, 46.0543
13.358590063, 96.390, 2136.0, 46.2169
13.411111193, 96.390, 2112.0, 45.9565
13.463632324, 96.390, 2172.0, 46.6047
13.516153455, 96.390, 2135.0, 46.2061
13.568674586, 96.390, 2075.0, 45.5522
13.621195716, 96.390, 2155.0, 46.4220
13.673716847, 96.390, 2083.0, 45.6399
13.726237978, 96.390, 2166.0, 46.5403
13.778759108, 96.390, 2115.0, 45.9891
13.831280239, 96.390, 2058.0, 45.3652
13.883801370, 96.390, 2006.0, 44.7884
13.936322501, 96.390, 1973.0, 44.4185
13.988843631, 96.390, 2036.0, 45.1221
14.041364762, 96.390, 2073.0, 45.5302
14.093885893, 96.390, 2094.0, 45.7602
14.146407023, 96.390, 2027.0, 45.0222
14.198928154, 96.390, 2093.0, 45.7493
14.251449285, 96.390, 2061.0, 45.3982
14.303970416, 96.390, 2031.0, 45.0666
14.356491546, 96.390, 2067.0, 45.4643
14.409012677, 96.390, 2038.0, 45.1442
14.461533808, 96.390, 2039.0, 45.1553
14.514054938, 96.390, 1957.0, 44.2380
14.566576069, 96.390, 2112.0, 45.9565
14.619097200, 96.390, 1971.0, 44.3959
14.671618331, 96.390, 1990.0, 44.6094
14.724139461, 96.390, 1994.0, 44.6542
14.776660592, 96.390, 2021.0, 44.9555
14.829181723, 96.390, 2081.0, 45.6180
14.881702853, 96.390, 1991.0, 44.6206
14.934223984, 96.390, 1982.0, 44.5197
14.986745115, 96.390, 2001.0, 44.7325
15.039266245, 96.390, 1956.0, 44.2267
15.091787376, 96.390, 1945.0, 44.1022
15.144308507, 96.390, 1971.0, 44.3959
15.196829638, 96.390, 1975.0, 44.4410
15.249350768, 96.390, 2005.0, 44.7772
15.301871899, 96.390, 1999.0, 44.7102
15.354393030, 96.390, 2046.0, 45.2327
15.406914160, 96.390, 1985.0, 44.5533
15.459435291, 96.390, 2148.0, 46.3465
15.511956422, 96.390, 2012.0, 44.8553
15.564477553, 96.390, 2057.0, 45.3542
15.616998683, 96.390, 2064.0, 45.4313
15.669519814, 96.390, 1998.0, 44.6990
15.722040945, 96.390, 1963.0, 44.3058
15.774562075, 96.390, 1936.0, 44.0000
15.827083206, 96.390, 2007.0, 44.7996
15.879604337, 96.390, 2111.0, 45.9456
15.932125468, 96.390, 2093.0, 45.7493
15.984646598, 96.390, 2072.0, 45.5192
16.037167729, 96.390, 2050.0, 45.2769
16.089688860, 96.390, 1943.0, 44.0795
16.142209990, 96.390, 2066.0, 45.4533
16.194731121, 96.390, 1990.0, 44.6094
16.247252252, 96.390, 2074.0, 45.5412
16.299773382, 96.390, 2096.0, 45.7821
16.352294513, 96.390, 2068.0, 45.4753
16.404815644, 96.390, 2122.0, 46.0652
16.457336775, 96.390, 2019.0, 44.9333
16.509857905, 96.390, 2133.0, 46.1844
16.562379036, 96.390, 2096.0, 45.7821
16.614900167, 96.390, 1973.0, 44.4185
16.667421297, 96.390, 2118.0, 46.0217
16.719942428, 96.390, 2093.0, 45.7493
16.772463559, 96.390, 2048.0, 45.2548
16.824984690, 96.390, 2057.0, 45.3542
16.877505820, 96.390, 2080.0, 45.6070
16.930026951, 96.390, 2050.0, 45.2769
16.982548082, 96.390, 2090.0, 45.7165
17.035069212, 96.390, 2162.0, 46.4973
17.087590343, 96.390, 2033.0, 45.0888
17.140111474, 96.390, 2130.0, 46.1519
17.192632605, 96.390, 2052.0, 45.2990
17.245153735, 96.390, 2075.0, 45.5522
17.297674866, 96.390, 2076.0, 45.5631
17.350195997, 96.390, 2182.0, 46.7119
17.402717127, 96.390, 2273.0, 47.6760
17.455238258, 96.390, 2228.0, 47.2017
17.507759389, 96.390, 2178.0, 46.6690
17.560280520, 96.390, 2182.0, 46.7119
17.612801650, 96.390, 2216.0, 47.0744
17.665322781, 96.390, 2218.0, 47.0956
17.717843912, 96.390, 2219.0, 47.1063
17.770365042, 96.390, 2238.0, 47.3075
17.822886173, 96.390, 2153.0, 46.4004
17.875407304, 96.390, 2324.0, 48.2079
17.927928434, 96.390, 2255.0, 47.4868
17.980449565, 96.390, 2227.0, 47.1911
18.032970696, 96.390, 2356.0, 48.5386
18.085491827, 96.390, 2268.0, 47.6235
18.138012957, 96.390, 2340.0, 48.3735
18.190534088, 96.390, 2340.0, 48.3735
18.243055219, 96.390, 2271.0, 47.6550
18.295576349, 96.390, 2345.0, 48.4252
18.348097480, 96.390, 2315.0, 48.1144
18.400618611, 96.390, 2362.0, 48.6004
18.453139742, 96.390, 2351.0, 48.4871
18.505660872, 96.390, 2399.0, 48.9796
18.558182003, 96.390, 2402.0, 49.0102
18.610703134, 96.390, 2333.0, 48.3011
18.663224264, 96.390, 2459.0, 49.5883
18.715745395, 96.390, 2402.0, 49.0102
18.768266526, 96.390, 2407.0, 49.0612
18.820787657, 96.390, 2422.0, 49.2138
18.873308787, 96.390, 2507.0, 50.0700
18.925829918, 96.390, 2437.0, 49.3660
18.978351049, 96.390, 2560.0, 50.5964
19.030872179, 96.390, 2548.0, 50.4777
19.083393310, 96.390, 2497.0, 49.9700
19.135914441, 96.390, 2544.0, 50.4381
19.188435572, 96.390, 2521.0, 50.2096
19.240956702, 96.390, 2681.0, 51.7784
19.293477833, 96.390, 2553.0, 50.5272
19.345998964, 96.390, 2644.0, 51.4198
19.398520094, 96.390, 2557.0, 50.5668
19.451041225, 96.390, 2698.0, 51.9423
19.503562356, 96.390, 2720.0, 52.1536
19.556083486, 96.390, 2747.0, 52.4118
19.608604617, 96.390, 2750.0, 52.4404
19.661125748, 96.390, 2616.0, 51.1468
19.713646879, 96.390, 2704.0, 52.0000
19.766168009, 96.390, 2712.0, 52.0769
19.818689140, 96.390, 2792.0, 52.8394
19.871210271, 96.390, 2880.0, 53.6656
19.923731401, 96.390, 2862.0, 53.4977
19.976252532, 96.390, 2812.0, 53.0283
20.028773663, 96.390, 2844.0, 53.3292
20.081294794, 96.390, 2878.0, 53.6470
20.133815924, 96.390, 2978.0, 54.5711
20.186337055, 96.390, 2898.0, 53.8331
20.238858186, 96.390, 2928.0, 54.1110
20.291379316, 96.390, 2968.0, 54.4794
20.343900447, 96.390, 2993.0, 54.7083
20.396421578, 96.390, 2945.0, 54.2679
20.448942709, 96.390, 3057.0, 55.2901
20.501463839, 96.390, 3065.0, 55.3624
20.553984970, 96.390, 3081.0, 55.5068
20.606506101, 96.390, 3023.0, 54.9818
20.659027231, 96.390, 3050.0, 55.2268
20.711548362, 96.390, 3026.0, 55.0091
20.764069493, 96.390, 2998.0, 54.7540
20.816590623, 96.390, 3090.0, 55.5878
20.869111754, 96.390, 3242.0, 56.9386
20.921632885, 96.390, 3069.0, 55.3986
20.974154016, 96.390, 3080.0, 55.4977
21.026675146, 96.390, 3181.0, 56.4004
21.079196277, 96.390, 3198.0, 56.5509
21.131717408, 96.390, 3171.0, 56.3116
21.184238538, 96.390, 3154.0, 56.1605
21.236759669, 96.390, 3248.0, 56.9912
21.289280800, 96.390, 3167.0, 56.2761
21.341801931, 96.390, 3338.0, 57.7754
21.394323061, 96.390, 2996.0, 54.7357
21.446844192, 96.390, 3205.0, 56.6127
21.499365323, 96.390, 3337.0, 57.7668
21.551886453, 96.390, 3275.0, 57.2276
21.604407584, 96.390, 3335.0, 57.7495
21.656928715, 96.390, 3189.0, 56.4712
21.709449846, 96.390, 3223.0, 56.7715
21.761970976, 96.390, 3200.0, 56.5685
21.814492107, 96.390, 3328.0, 57.6888
21.867013238, 96.390, 3406.0, 58.3609
21.919534368, 96.390, 3430.0, 58.5662
21.972055499, 96.390, 3345.0, 57.8360
22.024576630, 96.390, 3329.0, 57.6975
22.077097761, 96.390, 3294.0, 57.3934
22.129618891, 96.390, 3353.0, 57.9051
22.182140022, 96.390, 3371.0, 58.0603
22.234661153, 96.390, 3401.0, 58.3181
22.287182283, 96.390, 3406.0, 58.3609
22.339703414, 96.390, 3242.0, 56.9386
22.392224545, 96.390, 3405.0, 58.3524
22.444745675, 96.390, 3316.0, 57.5847
22.497266806, 96.390, 3336.0, 57.7581
22.549787937, 96.390, 3375.0, 58.0948
22.602309068, 96.390, 3376.0, 58.1034
22.654830198, 96.390, 3355.0, 57.9224
22.707351329, 96.390, 3382.0, 58.1550
22.759872460, 96.390, 3382.0, 58.1550
22.812393590, 96.390, 3292.0, 57.3760
22.864914721, 96.390, 3316.0, 57.5847
22.917435852, 96.390, 3312.0, 57.5500
22.969956983, 96.390, 3328.0, 57.6888
23.022478113, 96.390, 3384.0, 58.1722
23.074999244, 96.390, 3305.0, 57.4891
23.127520375, 96.390, 3241.0, 56.9298
23.180041505, 96.390, 3252.0, 57.0263
23.232562636, 96.390, 3365.0, 58.0086
23.285083767, 96.390, 3217.0, 56.7186
23.337604898, 96.390, 3255.0, 57.0526
23.390126028, 96.390, 3196.0, 56.5332
23.442647159, 96.390, 3284.0, 57.3062
23.495168290, 96.390, 3238.0, 56.9034
23.547689420, 96.390, 3196.0, 56.5332
23.600210551, 96.390, 3198.0, 56.5509
23.652731682, 96.390, 3054.0, 55.2630
23.705252813, 96.390, 3161.0, 56.2228
23.757773943, 96.390, 3122.0, 55.8749
23.810295074, 96.390, 3128.0, 55.9285
23.862816205, 96.390, 3155.0, 56.1694
23.915337335, 96.390, 3102.0, 55.6956
23.967858466, 96.390, 3109.0, 55.7584
24.020379597, 96.390, 3120.0, 55.8570
24.072900727, 96.390, 3068.0, 55.3895
24.125421858, 96.390, 3044.0, 55.1725
24.177942989, 96.390, 3076.0, 55.4617
24.230464120, 96.390, 3103.0, 55.7046
24.282985250, 96.390, 2960.0, 54.4059
24.335506381, 96.390, 3087.0, 55.5608
24.388027512, 96.390, 3025.0, 55.0000
24.440548642, 96.390, 2973.0, 54.5252
24.493069773, 96.390, 2970.0, 54.4977
24.545590904, 96.390, 2953.0, 54.3415
24.598112035, 96.390, 2998.0, 54.7540
24.650633165, 96.390, 2865.0, 53.5257
24.703154296, 96.390, 2895.0, 53.8052
24.755675427, 96.390, 2893.0, 53.7866
24.808196557, 96.390, 3025.0, 55.0000
24.860717688, 96.390, 2908.0, 53.9259
24.913238819, 96.390, 2936.0, 54.1849
24.965759950, 96.390, 2809.0, 53.0000
25.018281080, 96.390, 2839.0, 53.2823
25.070802211, 96.390, 2969.0, 54.4885
25.123323342, 96.390, 2876.0, 53.6284
25.175844472, 96.390, 2831.0, 53.2071
25.228365603, 96.390, 2794.0, 52.8583
25.280886734, 96.390, 2808.0, 52.9906
25.333407864, 96.390, 2674.0, 51.7107
25.385928995, 96.390, 2727.0, 52.2207
25.438450126, 96.390, 2696.0, 51.9230
25.490971257, 96.390, 2698.0, 51.9423
25.543492387, 96.390, 2649.0, 51.4684
25.596013518, 96.390, 2707.0, 52.0288
25.648534649, 96.390, 2732.0, 52.2685
25.701055779, 96.390, 2648.0, 51.4587
25.753576910, 96.390, 2681.0, 51.7784
25.806098041, 96.390, 2581.0, 50.8035
25.858619172, 96.390, 2623.0, 51.2152
25.911140302, 96.390, 2550.0, 50.4975
25.963661433, 96.390, 2638.0, 51.3615
26.016182564, 96.390, 2584.0, 50.8331
26.068703694, 96.390, 2588.0, 50.8724
26.121224825, 96.390, 2540.0, 50.3984
26.173745956, 96.390, 2573.0, 50.7247
26.226267087, 96.390, 2507.0, 50.0700
26.278788217, 96.390, 2598.0, 50.9706
26.331309348, 96.390, 2470.0, 49.6991
26.383830479, 96.390, 2706.0, 52.0192
26.436351609, 96.390, 2554.0, 50.5371
26.488872740, 96.390, 2437.0, 49.3660
26.541393871, 96.390, 2459.0, 49.5883
26.593915002, 96.390, 2390.0, 48.8876
26.646436132, 96.390, 2477.0, 49.7695
26.698957263, 96.390, 2439.0, 49.3862
26.751478394, 96.390, 2464.0, 49.6387
26.803999524, 96.390, 2410.0, 49.0918
26.856520655, 96.390, 2368.0, 48.6621
26.909041786, 96.390, 2415.0, 49.1426
26.961562916, 96.390, 2416.0, 49.1528
27.014084047, 96.390, 2311.0, 48.0729
27.066605178, 96.390, 2386.0, 48.8467
27.119126309, 96.390, 2344.0, 48.4149
27.171647439, 96.390, 2296.0, 47.9166
27.224168570, 96.390, 2320.0, 48.1664
27.276689701, 96.390, 2292.0, 47.8748
27.329210831, 96.390, 2395.0, 48.9387
27.381731962, 96.390, 2322.0, 48.1871
27.434253093, 96.390, 2287.0, 47.8226
27.486774224, 96.390, 2291.0, 47.8644
27.539295354, 96.390, 2299.0, 47.9479
27.591816485, 96.390, 2247.0, 47.4025
27.644337616, 96.390, 2230.0, 47.2229
27.696858746, 96.390, 2236.0, 47.2864
27.749379877, 96.390, 2234.0, 47.2652
27.801901008, 96.390, 2308.0, 48.0416
27.854422139, 96.390, 2160.0, 46.4758
27.906943269, 96.390, 2178.0, 46.6690
27.959464400, 96.390, 2211.0, 47.0213
28.011985531, 96.390, 2061.0, 45.3982
28.064506661, 96.390, 2032.0, 45.0777
28.117027792, 96.390, 2255.0, 47.4868
28.169548923, 96.390, 2193.0, 46.8295
28.222070054, 96.390, 2142.0, 46.2817
28.274591184, 96.390, 2107.0, 45.9021
28.327112315, 96.390, 2181.0, 46.7012
28.379633446, 96.390, 2106.0, 45.8912
28.432154576, 96.390, 2075.0, 45.5522
28.484675707, 96.390, 2019.0, 44.9333
28.537196838, 96.390, 2116.0, 46.0000
28.589717968, 96.390, 1999.0, 44.7102
28.642239099, 96.390, 2127.0, 46.1194
28.694760230, 96.390, 1940.0, 44.0454
28.747281361, 96.390, 2084.0, 45.6508
28.799802491, 96.390, 2012.0, 44.8553
28.852323622, 96.390, 2035.0, 45.1110
28.904844753, 96.390, 2039.0, 45.1553
28.957365883, 96.390, 1911.0, 43.7150
29.009887014, 96.390, 1994.0, 44.6542
29.062408145, 96.390, 2036.0, 45.1221
29.114929276, 96.390, 2024.0, 44.9889
29.167450406, 96.390, 1980.0, 44.4972
29.219971537, 96.390, 2035.0, 45.1110
29.272492668, 96.390, 1989.0, 44.5982
29.325013798, 96.390, 1952.0, 44.1814
29.377534929, 96.390, 1952.0, 44.1814
29.430056060, 96.390, 2001.0, 44.7325
29.482577191, 96.390, 1940.0, 44.0454
29.535098321, 96.390, 1899.0, 43.5775
29.587619452, 96.390, 1874.0, 43.2897
29.640140583, 96.390, 1906.0, 43.6578
29.692661713, 96.390, 1839.0, 42.8836
29.745182844, 96.390, 1905.0, 43.6463
29.797703975, 96.390, 1929.0, 43.9204
29.850225105, 96.390, 1893.0, 43.5086
29.902746236, 96.390, 1839.0, 42.8836
29.955267367, 96.390, 1788.0, 42.2847
30.007788498, 96.390, 1853.0, 43.0465
30.060309628, 96.390, 1812.0, 42.5676
30.112830759, 96.390, 1781.0, 42.2019
30.165351890, 96.390, 1717.0, 41.4367
30.217873020, 96.390, 1807.0, 42.5088
30.270394151, 96.390, 1820.0, 42.6615
30.322915282, 96.390, 1785.0, 42.2493
30.375436413, 96.390, 1832.0, 42.8019
30.427957543, 96.390, 1881.0, 43.3705
30.480478674, 96.390, 1840.0, 42.8952
30.532999805, 96.390, 1703.0, 41.2674
30.585520935, 96.390, 1754.0, 41.8808
30.638042066, 96.390, 1708.0, 41.3280
30.690563197, 96.390, 1819.0, 42.6497
30.743084328, 96.390, 1702.0, 41.2553
30.795605458, 96.390, 1771.0, 42.0833
30.848126589, 96.390, 1726.0, 41.5452
30.900647720, 96.390, 1692.0, 41.1339
30.953168850, 96.390, 1696.0, 41.1825
31.005689981, 96.390, 1698.0, 41.2068
31.058211112, 96.390, 1633.0, 40.4104
31.110732243, 96.390, 1753.0, 41.8688
31.163253373, 96.390, 1757.0, 41.9166
31.215774504, 96.390, 1668.0, 40.8412
31.268295635, 96.390, 1616.0, 40.1995
31.320816765, 96.390, 1675.0, 40.9268
31.373337896, 96.390, 1611.0, 40.1373
31.425859027, 96.390, 1643.0, 40.5339
31.478380157, 96.390, 1626.0, 40.3237
31.530901288, 96.390, 1683.0, 41.0244
31.583422419, 96.390, 1561.0, 39.5095
31.635943550, 96.390, 1565.0, 39.5601
31.688464680, 96.390, 1616.0, 40.1995
31.740985811, 96.390, 1602.0, 40.0250
31.793506942, 96.390, 1523.0, 39.0256
31.846028072, 96.390, 1549.0, 39.3573
31.898549203, 96.390, 1531.0, 39.1280
31.951070334, 96.390, 1518.0, 38.9615
32.003591465, 96.390, 1611.0, 40.1373
32.056112595, 96.390, 1507.0, 38.8201
32.108633726, 96.390, 1554.0, 39.4208
32.161154857, 96.390, 1549.0, 39.3573
32.213675987, 96.390, 1573.0, 39.6611
32.266197118, 96.390, 1445.0, 38.0132
32.318718249, 96.390, 1537.0, 39.2046
32.371239380, 96.390, 1494.0, 38.6523
32.423760510, 96.390, 1517.0, 38.9487
32.476281641, 96.390, 1473.0, 38.3797
32.528802772, 96.390, 1557.0, 39.4588
32.581323902, 96.390, 1459.0, 38.1969
32.633845033, 96.390, 1473.0, 38.3797
32.686366164, 96.390, 1398.0, 37.3898
32.738887295, 96.390, 1469.0, 38.3275
32.791408425, 96.390, 1473.0, 38.3797
32.843929556, 96.390, 1429.0, 37.8021
32.896450687, 96.390, 1436.0, 37.8946
32.948971817, 96.390, 1417.0, 37.6431
33.001492948, 96.390, 1416.0, 37.6298
33.054014079, 96.390, 1449.0, 38.0657
33.106535209, 96.390, 1417.0, 37.6431
33.159056340, 96.390, 1422.0, 37.7094
33.211577471, 96.390, 1421.0, 37.6962
33.264098602, 96.390, 1443.0, 37.9868
33.316619732, 96.390, 1373.0, 37.0540
33.369140863, 96.390, 1314.0, 36.2491
33.421661994, 96.390, 1352.0, 36.7696
33.474183124, 96.390, 1316.0, 36.2767
33.526704255, 96.390, 1372.0, 37.0405
33.579225386, 96.390, 1358.0, 36.8511
33.631746517, 96.390, 1392.0, 37.3095
33.684267647, 96.390, 1284.0, 35.8329
33.736788778, 96.390, 1377.0, 37.1080
33.789309909, 96.390, 1337.0, 36.5650
33.841831039, 96.390, 1317.0, 36.2905
33.894352170, 96.390, 1264.0, 35.5528
33.946873301, 96.390, 1309.0, 36.1801
33.999394432, 96.390, 1327.0, 36.4280
34.051915562, 96.390, 1309.0, 36.1801
34.104436693, 96.390, 1322.0, 36.3593
34.156957824, 96.390, 1259.0, 35.4824
34.209478954, 96.390, 1283.0, 35.8190
34.262000085, 96.390, 1278.0, 35.7491
34.314521216, 96.390, 1304.0, 36.1109
34.367042346, 96.390, 1235.0, 35.1426
34.419563477, 96.390, 1340.0, 36.6060
34.472084608, 96.390, 1255.0, 35.4260
34.524605739, 96.390, 1281.0, 35.7911
34.577126869, 96.390, 1299.0, 36.0416
34.629648000, 96.390, 1232.0, 35.0999
34.682169131, 96.390, 1221.0, 34.9428
34.734690261, 96.390, 1258.0, 35.4683
34.787211392, 96.390, 1200.0, 34.6410
34.839732523, 96.390, 1250.0, 35.3553
34.892253654, 96.390, 1242.0, 35.2420
34.944774784, 96.390, 1211.0, 34.7994
34.997295915, 96.390, 1231.0, 35.0856
35.049817046, 96.390, 1186.0, 34.4384
35.102338176, 96.390, 1215.0, 34.8569
35.154859307, 96.390, 1237.0, 35.1710
35.207380438, 96.390, 1194.0, 34.5543
35.259901569, 96.390, 1211.0, 34.7994
35.312422699, 96.390, 1167.0, 34.1614
35.364943830, 96.390, 1163.0, 34.1028
35.417464961, 96.390, 1148.0, 33.8821
35.469986091, 96.390, 1167.0, 34.1614
35.522507222, 96.390, 1154.0, 33.9706
35.575028353, 96.390, 1164.0, 34.1174
35.627549484, 96.390, 1142.0, 33.7935
35.680070614, 96.390, 1169.0, 34.1906
35.732591745, 96.390, 1109.0, 33.3017
35.785112876, 96.390, 1193.0, 34.5398
35.837634006, 96.390, 1084.0, 32.9242
35.890155137, 96.390, 1130.0, 33.6155
35.942676268, 96.390, 1075.0, 32.7872
35.995197398, 96.390, 1121.0, 33.4813
36.047718529, 96.390, 1110.0, 33.3167
36.100239660, 96.390, 1079.0, 32.8481
36.152760791, 96.390, 1117.0, 33.4215
36.205281921, 96.390, 1139.0, 33.7491
36.257803052, 96.390, 1169.0, 34.1906
36.310324183, 96.390, 1108.0, 33.2866
36.362845313, 96.390, 1090.0, 33.0151
36.415366444, 96.390, 1101.0, 33.1813
36.467887575, 96.390, 1069.0, 32.6956
36.520408706, 96.390, 1119.0, 33.4515
36.572929836, 96.390, 1077.0, 32.8177
36.625450967, 96.390, 1044.0, 32.3110
36.677972098, 96.390, 1085.0, 32.9393
36.730493228, 96.390, 1084.0, 32.9242
36.783014359, 96.390, 1149.0, 33.8969
36.835535490, 96.390, 1016.0, 31.8748
36.888056621, 96.390, 1071.0, 32.7261
36.940577751, 96.390, 1052.0, 32.4345
36.993098882, 96.390, 994.0, 31.5278
37.045620013, 96.390, 1065.0, 32.6343
37.098141143, 96.390, 1002.0, 31.6544
37.150662274, 96.390, 1046.0, 32.3419
37.203183405, 96.390, 1024.0, 32.0000
37.255704535, 96.390, 1031.0, 32.1092
37.308225666, 96.390, 1019.0, 31.9218
37.360746797, 96.390, 994.0, 31.5278
37.413267928, 96.390, 1056.0, 32.4962
37.465789058, 96.390, 1026.0, 32.0312
37.518310189, 96.390, 991.0, 31.4802
37.570831320, 96.390, 1062.0, 32.5883
37.623352450, 96.390, 1037.0, 32.2025
37.675873581, 96.390, 950.0, 30.8221
37.728394712, 96.390, 978.0, 31.2730
37.780915843, 96.390, 1031.0, 32.1092
37.833436973, 96.390, 1010.0, 31.7805
37.885958104, 96.390, 1051.0, 32.4191
37.938479235, 96.390, 956.0, 30.9192
37.991000365, 96.390, 922.0, 30.3645
38.043521496, 96.390, 996.0, 31.5595
38.096042627, 96.390, 945.0, 30.7409
38.148563758, 96.390, 979.0, 31.2890
38.201084888, 96.390, 905.0, 30.0832
38.253606019, 96.390, 916.0, 30.2655
38.306127150, 96.390, 1018.0, 31.9061
38.358648280, 96.390, 967.0, 31.0966
38.411169411, 96.390, 946.0, 30.7571
38.463690542, 96.390, 938.0, 30.6268
38.516211673, 96.390, 962.0, 31.0161
38.568732803, 96.390, 957.0, 30.9354
38.621253934, 96.390, 929.0, 30.4795
38.673775065, 96.390, 859.0, 29.3087
38.726296195, 96.390, 950.0, 30.8221
38.778817326, 96.390, 956.0, 30.9192
38.831338457, 96.390, 951.0, 30.8383
38.883859587, 96.390, 898.0, 29.9666
38.936380718, 96.390, 891.0, 29.8496
38.988901849, 96.390, 949.0, 30.8058
39.041422980, 96.390, 917.0, 30.2820
39.093944110, 96.390, 911.0, 30.1828
39.146465241, 96.390, 918.0, 30.2985
39.198986372, 96.390, 878.0, 29.6311
39.251507502, 96.390, 952.0, 30.8545
39.304028633, 96.390, 911.0, 30.1828
39.356549764, 96.390, 945.0, 30.7409
39.409070895, 96.390, 846.0, 29.0861
39.461592025, 96.390, 927.0, 30.4467
39.514113156, 96.390, 950.0, 30.8221
39.566634287, 96.390, 923.0, 30.3809
39.619155417, 96.390, 895.0, 29.9166
39.671676548, 96.390, 872.0, 29.5296
39.724197679, 96.390, 881.0, 29.6816
39.776718810, 96.390, 906.0, 30.0998
39.829239940, 96.390, 958.0, 30.9516
39.881761071, 96.390, 917.0, 30.2820
39.934282202, 96.390, 931.0, 30.5123
39.986803332, 96.390, 913.0, 30.2159
40.039324463, 96.390, 907.0, 30.1164
40.091845594, 96.390, 796.0, 28.2135
40.144366725, 96.390, 845.0, 29.0689
40.196887855, 96.390, 847.0, 29.1033
40.249408986, 96.390, 924.0, 30.3974
40.301930117, 96.390, 870.0, 29.4958
40.354451247, 96.390, 857.0, 29.2746
40.406972378, 96.390, 854.0, 29.2233
40.459493509, 96.390, 897.0, 29.9500
40.512014639, 96.390, 905.0, 30.0832
40.564535770, 96.390, 893.0, 29.8831
40.617056901, 96.390, 849.0, 29.1376
40.669578032, 96.390, 893.0, 29.8831
40.722099162, 96.390, 921.0, 30.3480
40.774620293, 96.390, 887.0, 29.7825
40.827141424, 96.390, 869.0, 29.4788
40.879662554, 96.390, 840.0, 28.9828
40.932183685, 96.390, 846.0, 29.0861
40.984704816, 96.390, 891.0, 29.8496
41.037225947, 96.390, 875.0, 29.5804
41.089747077, 96.390, 920.0, 30.3315
41.142268208, 96.390, 913.0, 30.2159
41.194789339, 96.390, 866.0, 29.4279
41.247310469, 96.390, 861.0, 29.3428
41.299831600, 96.390, 875.0, 29.5804
41.352352731, 96.390, 875.0, 29.5804
41.404873862, 96.390, 833.0, 28.8617
41.457394992, 96.390, 890.0, 29.8329
41.509916123, 96.390, 889.0, 29.8161
41.562437254, 96.390, 885.0, 29.7489
41.614958384, 96.390, 867.0, 29.4449
41.667479515, 96.390, 881.0, 29.6816
41.720000646, 96.390, 848.0, 29.1204
41.772521776, 96.390, 841.0, 29.0000
41.825042907, 96.390, 879.0, 29.6479
41.877564038, 96.390, 854.0, 29.2233
41.930085169, 96.390, 847.0, 29.1033
41.982606299, 96.390, 894.0, 29.8998
42.035127430, 96.390, 841.0, 29.0000
42.087648561, 96.390, 866.0, 29.4279
42.140169691, 96.390, 826.0, 28.7402
42.192690822, 96.390, 811.0, 28.4781
42.245211953, 96.390, 865.0, 29.4109
42.297733084, 96.390, 852.0, 29.1890
42.350254214, 96.390, 849.0, 29.1376
42.402775345, 96.390, 859.0, 29.3087
42.455296476, 96.390, 834.0, 28.8791
42.507817606, 96.390, 853.0, 29.2062
42.560338737, 96.390, 822.0, 28.6705
42.612859868, 96.390, 844.0, 29.0517
42.665380999, 96.390, 838.0, 28.9482
42.717902129, 96.390, 862.0, 29.3598
42.770423260, 96.390, 844.0, 29.0517
42.822944391, 96.390, 875.0, 29.5804
42.875465521, 96.390, 867.0, 29.4449
42.927986652, 96.390, 847.0, 29.1033
42.980507783, 96.390, 883.0, 29.7153
43.033028914, 96.390, 850.0, 29.1548
43.085550044, 96.390, 818.0, 28.6007
43.138071175, 96.390, 821.0, 28.6531
43.190592306, 96.390, 791.0, 28.1247
43.243113436, 96.390, 818.0, 28.6007
43.295634567, 96.390, 862.0, 29.3598
43.348155698, 96.390, 831.0, 28.8271
43.400676828, 96.390, 896.0, 29.9333
43.453197959, 96.390, 836.0, 28.9137
43.505719090, 96.390, 826.0, 28.7402
43.558240221, 96.390, 844.0, 29.0517
43.610761351, 96.390, 786.0, 28.0357
43.663282482, 96.390, 789.0, 28.0891
43.715803613, 96.390, 831.0, 28.8271
43.768324743, 96.390, 826.0, 28.7402
43.820845874, 96.390, 862.0, 29.3598
43.873367005, 96.390, 778.0, 27.8927
43.925888136, 96.390, 828.0, 28.7750
43.978409266, 96.390, 774.0, 27.8209
44.030930397, 96.390, 881.0, 29.6816
44.083451528, 96.390, 840.0, 28.9828
44.135972658, 96.390, 860.0, 29.3258
44.188493789, 96.390, 818.0, 28.6007
44.241014920, 96.390, 776.0, 27.8568
44.293536051, 96.390, 792.0, 28.1425
44.346057181, 96.390, 818.0, 28.6007
44.398578312, 96.390, 803.0, 28.3373
44.451099443, 96.390, 819.0, 28.6182
44.503620573, 96.390, 804.0, 28.3549
44.556141704, 96.390, 800.0, 28.2843
44.608662835, 96.390, 838.0, 28.9482
44.661183966, 96.390, 811.0, 28.4781
44.713705096, 96.390, 809.0, 28.4429
44.766226227, 96.390, 783.0, 27.9821
44.818747358, 96.390, 790.0, 28.1069
44.871268488, 96.390, 818.0, 28.6007
44.923789619, 96.390, 792.0, 28.1425
44.976310750, 96.390, 754.0, 27.4591
45.028831880, 96.390, 794.0, 28.1780
45.081353011, 96.390, 803.0, 28.3373
45.133874142, 96.390, 778.0, 27.8927
45.186395273, 96.390, 818.0, 28.6007
45.238916403, 96.390, 784.0, 28.0000
45.291437534, 96.390, 773.0, 27.8029
45.343958665, 96.390, 769.0, 27.7308
45.396479795, 96.390, 813.0, 28.5132
45.449000926, 96.390, 751.0, 27.4044
45.501522057, 96.390, 763.0, 27.6225
45.554043188, 96.390, 811.0, 28.4781
45.606564318, 96.390, 780.0, 27.9285
45.659085449, 96.390, 842.0, 29.0172
45.711606580, 96.390, 767.0, 27.6948
45.764127710, 96.390, 783.0, 27.9821
45.816648841, 96.390, 783.0, 27.9821
45.869169972, 96.390, 782.0, 27.9643
45.921691103, 96.390, 755.0, 27.4773
45.974212233, 96.390, 767.0, 27.6948
46.026733364, 96.390, 753.0, 27.4408
46.079254495, 96.390, 733.0, 27.0740
46.131775625, 96.390, 779.0, 27.9106
46.184296756, 96.390, 759.0, 27.5500
46.236817887, 96.390, 803.0, 28.3373
46.289339017, 96.390, 821.0, 28.6531
46.341860148, 96.390, 741.0, 27.2213
46.394381279, 96.390, 780.0, 27.9285
46.446902410, 96.390, 806.0, 28.3901
46.499423540, 96.390, 728.0, 26.9815
46.551944671, 96.390, 758.0, 27.5318
46.604465802, 96.390, 826.0, 28.7402
46.656986932, 96.390, 770.0, 27.7489
46.709508063, 96.390, 788.0, 28.0713
46.762029194, 96.390, 767.0, 27.6948
46.814550325, 96.390, 760.0, 27.5681
46.867071455, 96.390, 769.0, 27.7308
46.919592586, 96.390, 780.0, 27.9285
46.972113717, 96.390, 722.0, 26.8701
47.024634847, 96.390, 765.0, 27.6586
47.077155978, 96.390, 815.0, 28.5482
47.129677109, 96.390, 817.0, 28.5832
47.182198240, 96.390, 796.0, 28.2135
47.234719370, 96.390, 751.0, 27.4044
47.287240501, 96.390, 770.0, 27.7489
47.339761632, 96.390, 765.0, 27.6586
47.392282762, 96.390, 769.0, 27.7308
47.444803893, 96.390, 744.0, 27.2764
47.497325024, 96.390, 772.0, 27.7849
47.549846155, 96.390, 773.0, 27.8029
47.602367285, 96.390, 731.0, 27.0370
47.654888416, 96.390, 718.0, 26.7955
47.707409547, 96.390, 770.0, 27.7489
47.759930677, 96.390, 805.0, 28.3725
47.812451808, 96.390, 744.0, 27.2764
47.864972939, 96.390, 728.0, 26.9815
47.917494069, 96.390, 730.0, 27.0185
47.970015200, 96.390, 730.0, 27.0185
48.022536331, 96.390, 736.0, 27.1293
48.075057462, 96.390, 758.0, 27.5318
48.127578592, 96.390, 718.0, 26.7955
48.180099723, 96.390, 775.0, 27.8388
48.232620854, 96.390, 764.0, 27.6405
48.285141984, 96.390, 741.0, 27.2213
48.337663115, 96.390, 754.0, 27.4591
48.390184246, 96.390, 763.0, 27.6225
48.442705377, 96.390, 748.0, 27.3496
48.495226507, 96.390, 713.0, 26.7021
48.547747638, 96.390, 691.0, 26.2869
48.600268769, 96.390, 721.0, 26.8514
48.652789899, 96.390, 726.0, 26.9444
48.705311030, 96.390, 745.0, 27.2947
48.757832161, 96.390, 782.0, 27.9643
48.810353292, 96.390, 699.0, 26.4386
48.862874422, 96.390, 794.0, 28.1780
48.915395553, 96.390, 709.0, 26.6271
48.967916684, 96.390, 747.0, 27.3313
49.020437814, 96.390, 767.0, 27.6948
49.072958945, 96.390, 721.0, 26.8514
49.125480076, 96.390, 731.0, 27.0370
49.178001207, 96.390, 710.0, 26.6458
49.230522337, 96.390, 795.0, 28.1957
49.283043468, 96.390, 714.0, 26.7208
49.335564599, 96.390, 725.0, 26.9258
49.388085729, 96.390, 722.0, 26.8701
49.440606860, 96.390, 714.0, 26.7208
49.493127991, 96.390, 759.0, 27.5500
49.545649121, 96.390, 689.0, 26.2488
49.598170252, 96.390, 701.0, 26.4764
49.650691383, 96.390, 777.0, 27.8747
49.703212514, 96.390, 697.0, 26.4008
49.755733644, 96.390, 734.0, 27.0924
49.808254775, 96.390, 777.0, 27.8747
49.860775906, 96.390, 743.0, 27.2580
49.913297036, 96.390, 728.0, 26.9815
49.965818167, 96.390, 748.0, 27.3496
50.018339298, 96.390, 679.0, 26.0576
50.070860429, 96.390, 704.0, 26.5330
50.123381559, 96.390, 732.0, 27.0555
50.175902690, 96.390, 671.0, 25.9037
50.228423821, 96.390, 744.0, 27.2764
50.280944951, 96.390, 696.0, 26.3818
50.333466082, 96.390, 691.0, 26.2869
50.385987213, 96.390, 731.0, 27.0370
50.438508344, 96.390, 706.0, 26.5707
50.491029474, 96.390, 707.0, 26.5895
50.543550605, 96.390, 752.0, 27.4226
50.596071736, 96.390, 725.0, 26.9258
50.648592866, 96.390, 710.0, 26.6458
50.701113997, 96.390, 767.0, 27.6948
50.753635128, 96.390, 732.0, 27.0555
50.806156258, 96.390, 703.0, 26.5141
50.858677389, 96.390, 697.0, 26.4008
50.911198520, 96.390, 722.0, 26.8701
50.963719651, 96.390, 762.0, 27.6043
51.016240781, 96.390, 719.0, 26.8142
51.068761912, 96.390, 748.0, 27.3496
51.121283043, 96.390, 709.0, 26.6271
51.173804173, 96.390, 738.0, 27.1662
51.226325304, 96.390, 702.0, 26.4953
51.278846435, 96.390, 640.0, 25.2982
51.331367566, 96.390, 744.0, 27.2764
51.383888696, 96.390, 685.0, 26.1725
51.436409827, 96.390, 707.0, 26.5895
51.488930958, 96.390, 724.0, 26.9072
51.541452088, 96.390, 717.0, 26.7769
51.593973219, 96.390, 729.0, 27.0000
51.646494350, 96.390, 694.0, 26.3439
51.699015481, 96.390, 707.0, 26.5895
51.751536611, 96.390, 720.0, 26.8328
51.804057742, 96.390, 709.0, 26.6271
51.856578873, 96.390, 704.0, 26.5330
51.909100003, 96.390, 754.0, 27.4591
51.961621134, 96.390, 691.0, 26.2869
52.014142265, 96.390, 642.0, 25.3377
52.066663396, 96.390, 736.0, 27.1293
52.119184526, 96.390, 680.0, 26.0768
52.171705657, 96.390, 689.0, 26.2488
52.224226788, 96.390, 694.0, 26.3439
52.276747918, 96.390, 682.0, 26.1151
52.329269049, 96.390, 693.0, 26.3249
52.381790180, 96.390, 699.0, 26.4386
52.434311310, 96.390, 719.0, 26.8142
52.486832441, 96.390, 684.0, 26.1534
52.539353572, 96.390, 682.0, 26.1151
52.591874703, 96.390, 678.0, 26.0384
52.644395833, 96.390, 692.0, 26.3059
52.696916964, 96.390, 714.0, 26.7208
52.749438095, 96.390, 688.0, 26.2298
52.801959225, 96.390, 667.0, 25.8263
52.854480356, 96.390, 716.0, 26.7582
52.907001487, 96.390, 726.0, 26.9444
52.959522618, 96.390, 734.0, 27.0924
53.012043748, 96.390, 705.0, 26.5518
53.064564879, 96.390, 697.0, 26.4008
53.117086010, 96.390, 674.0, 25.9615
53.169607140, 96.390, 654.0, 25.5734
53.222128271, 96.390, 728.0, 26.9815
53.274649402, 96.390, 651.0, 25.5147
53.327170533, 96.390, 670.0, 25.8844
53.379691663, 96.390, 684.0, 26.1534
53.432212794, 96.390, 723.0, 26.8887
53.484733925, 96.390, 704.0, 26.5330
53.537255055, 96.390, 664.0, 25.7682
53.589776186, 96.390, 664.0, 25.7682
53.642297317, 96.390, 754.0, 27.4591
53.694818448, 96.390, 689.0, 26.2488
53.747339578, 96.390, 702.0, 26.4953
53.799860709, 96.390, 672.0, 25.9230
53.852381840, 96.390, 651.0, 25.5147
53.904902970, 96.390, 635.0, 25.1992
53.957424101, 96.390, 675.0, 25.9808
54.009945232, 96.390, 683.0, 26.1343
54.062466362, 96.390, 720.0, 26.8328
54.114987493, 96.390, 716.0, 26.7582
54.167508624, 96.390, 680.0, 26.0768
54.220029755, 96.390, 695.0, 26.3629
54.272550885, 96.390, 710.0, 26.6458
54.325072016, 96.390, 662.0, 25.7294
54.377593147, 96.390, 682.0, 26.1151
54.430114277, 96.390, 636.0, 25.2190
54.482635408, 96.390, 675.0, 25.9808
54.535156539, 96.390, 638.0, 25.2587
54.587677670, 96.390, 664.0, 25.7682
54.640198800, 96.390, 728.0, 26.9815
54.692719931, 96.390, 737.0, 27.1477
54.745241062, 96.390, 664.0, 25.7682
54.797762192, 96.390, 724.0, 26.9072
54.850283323, 96.390, 673.0, 25.9422
54.902804454, 96.390, 648.0, 25.4558
54.955325585, 96.390, 702.0, 26.4953
55.007846715, 96.390, 674.0, 25.9615
55.060367846, 96.390, 669.0, 25.8650
55.112888977, 96.390, 724.0, 26.9072
55.165410107, 96.390, 703.0, 26.5141
55.217931238, 96.390, 684.0, 26.1534
55.270452369, 96.390, 660.0, 25.6905
55.322973499, 96.390, 675.0, 25.9808
55.375494630, 96.390, 701.0, 26.4764
55.428015761, 96.390, 681.0, 26.0960
55.480536892, 96.390, 707.0, 26.5895
55.533058022, 96.390, 661.0, 25.7099
55.585579153, 96.390, 660.0, 25.6905
55.638100284, 96.390, 696.0, 26.3818
55.690621414, 96.390, 688.0, 26.2298
55.743142545, 96.390, 686.0, 26.1916
55.795663676, 96.390, 656.0, 25.6125
55.848184807, 96.390, 703.0, 26.5141
55.900705937, 96.390, 635.0, 25.1992
55.953227068, 96.390, 649.0, 25.4755
56.005748199, 96.390, 720.0, 26.8328
56.058269329, 96.390, 700.0, 26.4575
56.110790460, 96.390, 694.0, 26.3439
56.163311591, 96.390, 734.0, 27.0924
56.215832722, 96.390, 728.0, 26.9815
56.268353852, 96.390, 704.0, 26.5330
56.320874983, 96.390, 669.0, 25.8650
56.373396114, 96.390, 691.0, 26.2869
56.425917244, 96.390, 687.0, 26.2107
56.478438375, 96.390, 665.0, 25.7876
56.530959506, 96.390, 692.0, 26.3059
56.583480637, 96.390, 689.0, 26.2488
56.636001767, 96.390, 704.0, 26.5330
56.688522898, 96.390, 678.0, 26.0384
56.741044029, 96.390, 691.0, 26.2869
56.793565159, 96.390, 728.0, 26.9815
56.846086290, 96.390, 697.0, 26.4008
56.898607421, 96.390, 716.0, 26.7582
56.951128551, 96.390, 693.0, 26.3249
57.003649682, 96.390, 732.0, 27.0555
57.056170813, 96.390, 641.0, 25.3180
57.108691944, 96.390, 705.0, 26.5518
57.161213074, 96.390, 672.0, 25.9230
57.213734205, 96.390, 695.0, 26.3629
57.266255336, 96.390, 657.0, 25.6320
57.318776466, 96.390, 693.0, 26.3249
57.371297597, 96.390, 697.0, 26.4008
57.423818728, 96.390, 664.0, 25.7682
57.476339859, 96.390, 685.0, 26.1725
57.528860989, 96.390, 675.0, 25.9808
57.581382120, 96.390, 656.0, 25.6125
57.633903251, 96.390, 721.0, 26.8514
57.686424381, 96.390, 685.0, 26.1725
57.738945512, 96.390, 710.0, 26.6458
57.791466643, 96.390, 663.0, 25.7488
57.843987774, 96.390, 695.0, 26.3629
57.896508904, 96.390, 671.0, 25.9037
57.949030035, 96.390, 674.0, 25.9615
58.001551166, 96.390, 662.0, 25.7294
58.054072296, 96.390, 659.0, 25.6710
58.106593427, 96.390, 689.0, 26.2488
58.159114558, 96.390, 680.0, 26.0768
58.211635689, 96.390, 663.0, 25.7488
58.264156819, 96.390, 648.0, 25.4558
58.316677950, 96.390, 686.0, 26.1916
58.369199081, 96.390, 686.0, 26.1916
58.421720211, 96.390, 710.0, 26.6458
58.474241342, 96.390, 647.0, 25.4362
58.526762473, 96.390, 610.0, 24.6982
58.579283603, 96.390, 706.0, 26.5707
58.631804734, 96.390, 661.0, 25.7099
58.684325865, 96.390, 719.0, 26.8142
58.736846996, 96.390, 637.0, 25.2389
58.789368126, 96.390, 650.0, 25.4951
58.841889257, 96.390, 685.0, 26.1725
58.894410388, 96.390, 640.0, 25.2982
58.946931518, 96.390, 679.0, 26.0576
58.999452649, 96.390, 653.0, 25.5539
59.051973780, 96.390, 645.0, 25.3969
59.104494911, 96.390, 674.0, 25.9615
59.157016041, 96.390, 669.0, 25.8650
59.209537172, 96.390, 656.0, 25.6125
59.262058303, 96.390, 681.0, 26.0960
59.314579433, 96.390, 711.0, 26.6646
59.367100564, 96.390, 667.0, 25.8263
59.419621695, 96.390, 699.0, 26.4386
59.472142826, 96.390, 676.0, 26.0000
59.524663956, 96.390, 685.0, 26.1725
59.577185087, 96.390, 671.0, 25.9037
59.629706218, 96.390, 616.0, 24.8193
59.682227348, 96.390, 673.0, 25.9422
59.734748479, 96.390, 705.0, 26.5518
59.787269610, 96.390, 702.0, 26.4953
59.839790740, 96.390, 715.0, 26.7395
59.892311871, 96.390, 658.0, 25.6515
59.944833002, 96.390, 658.0, 25.6515
59.997354133, 96.390, 681.0, 26.0960
60.049875263, 96.390, 632.0, 25.1396
60.102396394, 96.390, 738.0, 27.1662
60.154917525, 96.390, 732.0, 27.0555
60.207438655, 96.390, 667.0, 25.8263
60.259959786, 96.390, 710.0, 26.6458
60.312480917, 96.390, 714.0, 26.7208
60.365002048, 96.390, 694.0, 26.3439
60.417523178, 96.390, 688.0, 26.2298
60.470044309, 96.390, 592.0, 24.3311
60.522565440, 96.390, 670.0, 25.8844
60.575086570, 96.390, 679.0, 26.0576
60.627607701, 96.390, 713.0, 26.7021
60.680128832, 96.390, 683.0, 26.1343
60.732649963, 96.390, 683.0, 26.1343
60.785171093, 96.390, 694.0, 26.3439
60.837692224, 96.390, 665.0, 25.7876
60.890213355, 96.390, 672.0, 25.9230
60.942734485, 96.390, 670.0, 25.8844
60.995255616, 96.390, 655.0, 25.5930
61.047776747, 96.390, 662.0, 25.7294
61.100297878, 96.390, 671.0, 25.9037
61.152819008, 96.390, 698.0, 26.4197
61.205340139, 96.390, 696.0, 26.3818
61.257861270, 96.390, 665.0, 25.7876
61.310382400, 96.390, 690.0, 26.2679
61.362903531, 96.390, 711.0, 26.6646
61.415424662, 96.390, 698.0, 26.4197
61.467945792, 96.390, 702.0, 26.4953
61.520466923, 96.390, 695.0, 26.3629
61.572988054, 96.390, 672.0, 25.9230
61.625509185, 96.390, 691.0, 26.2869
61.678030315, 96.390, 676.0, 26.0000
61.730551446, 96.390, 657.0, 25.6320
61.783072577, 96.390, 721.0, 26.8514
61.835593707, 96.390, 689.0, 26.2488
61.888114838, 96.390, 694.0, 26.3439
61.940635969, 96.390, 714.0, 26.7208
61.993157100, 96.390, 671.0, 25.9037
62.045678230, 96.390, 705.0, 26.5518
62.098199361, 96.390, 730.0, 27.0185
62.150720492, 96.390, 715.0, 26.7395
62.203241622, 96.390, 658.0, 25.6515
62.255762753, 96.390, 697.0, 26.4008
62.308283884, 96.390, 687.0, 26.2107
62.360805015, 96.390, 703.0, 26.5141
62.413326145, 96.390, 690.0, 26.2679
62.465847276, 96.390, 663.0, 25.7488
62.518368407, 96.390, 654.0, 25.5734
62.570889537, 96.390, 652.0, 25.5343
62.623410668, 96.390, 687.0, 26.2107
62.675931799, 96.390, 694.0, 26.3439
62.728452930, 96.390, 700.0, 26.4575
62.780974060, 96.390, 677.0, 26.0192
62.833495191, 96.390, 685.0, 26.1725
62.886016322, 96.390, 725.0, 26.9258
62.938537452, 96.390, 691.0, 26.2869
62.991058583, 96.390, 716.0, 26.7582
63.043579714, 96.390, 672.0, 25.9230
63.096100844, 96.390, 660.0, 25.6905
63.148621975, 96.390, 708.0, 26.6083
63.201143106, 96.390, 647.0, 25.4362
63.253664237, 96.390, 671.0, 25.9037
63.306185367, 96.390, 660.0, 25.6905
63.358706498, 96.390, 699.0, 26.4386
63.411227629, 96.390, 695.0, 26.3629
63.463748759, 96.390, 657.0, 25.6320
63.516269890, 96.390, 711.0, 26.6646
63.568791021, 96.390, 668.0, 25.8457
63.621312152, 96.390, 695.0, 26.3629
63.673833282, 96.390, 759.0, 27.5500
63.726354413, 96.390, 655.0, 25.5930
63.778875544, 96.390, 714.0, 26.7208
63.831396674, 96.390, 655.0, 25.5930
63.883917805, 96.390, 700.0, 26.4575
63.936438936, 96.390, 645.0, 25.3969
63.988960067, 96.390, 683.0, 26.1343
64.041481197, 96.390, 662.0, 25.7294
64.094002328, 96.390, 678.0, 26.0384
64.146523459, 96.390, 682.0, 26.1151
64.199044589, 96.390, 705.0, 26.5518
64.251565720, 96.390, 704.0, 26.5330
64.304086851, 96.390, 634.0, 25.1794
64.356607981, 96.390, 699.0, 26.4386
64.409129112, 96.390, 687.0, 26.2107
64.461650243, 96.390, 674.0, 25.9615
64.514171374, 96.390, 704.0, 26.5330
64.566692504, 96.390, 650.0, 25.4951
64.619213635, 96.390, 668.0, 25.8457
64.671734766, 96.390, 663.0, 25.7488
64.724255896, 96.390, 677.0, 26.0192
64.776777027, 96.390, 689.0, 26.2488
64.829298158, 96.390, 647.0, 25.4362
64.881819289, 96.390, 668.0, 25.8457
64.934340419, 96.390, 691.0, 26.2869
64.986861550, 96.390, 649.0, 25.4755