File: Files_organized_for_plots/PC/XRD_PC_SicornerPC03nov21.csv
[Measurement conditions]
Sample identification,MNASPH_sicornerPC03nov21
Comment - 1,"Configuration=Stage for Flat Samples/Holders, Owner=User-1, Creation date=7/1/2020 9:53:24 AM"
Comment - 2,"Goniometer=Theta/Theta; Minimum step size 2Theta:0.0001; Minimum step size Omega:0.0001"
Comment - 3,"Sample stage=Stage for flat samples/holders"
Comment - 4,"Diffractometer system=EMPYREAN"
Comment - 5,"Measurement program=C:\Users\ibo5034\OneDrive - The Pennsylvania State University\NEUP\Zerobackground scan.xrdmp, Identifier={98A3B11C-88F9-4AA6-982C-73314A311EF5}"
Anode material,Cu
K-Alpha1 wavelength,1.5405980
K-Alpha2 wavelength,1.5444260
Ratio K-Alpha2/K-Alpha1,0.500
Divergence slit,Fixed,0.25
Monochromator used,NO
Generator voltage, 45
Tube current, 40
File date and time,03/Dec/2021 10:43
Unit cell,
h k l, 0 0 0
Scan axis,Gonio
Scan range,4.994599997,64.999991833
Scan step size,0.0262606
No. of points, 2285
Scan type,CONTINUOUS
Time per step,96.390
[Scan points]
Angle, TimePerStep, Intensity, ESD
5.007730280, 96.390, 5567.0, 74.6123
5.060251411, 96.390, 5614.0, 74.9266
5.112772541, 96.390, 5391.0, 73.4234
5.165293672, 96.390, 5335.0, 73.0411
5.217814803, 96.390, 5308.0, 72.8560
5.270335934, 96.390, 5185.0, 72.0069
5.322857064, 96.390, 5114.0, 71.5122
5.375378195, 96.390, 5004.0, 70.7390
5.427899326, 96.390, 4860.0, 69.7137
5.480420456, 96.390, 4874.0, 69.8140
5.532941587, 96.390, 4648.0, 68.1762
5.585462718, 96.390, 4752.0, 68.9348
5.637983849, 96.390, 4713.0, 68.6513
5.690504979, 96.390, 4606.0, 67.8675
5.743026110, 96.390, 4595.0, 67.7864
5.795547241, 96.390, 4533.0, 67.3276
5.848068371, 96.390, 4579.0, 67.6683
5.900589502, 96.390, 4381.0, 66.1891
5.953110633, 96.390, 4365.0, 66.0681
6.005631763, 96.390, 4298.0, 65.5591
6.058152894, 96.390, 4240.0, 65.1153
6.110674025, 96.390, 4339.0, 65.8711
6.163195156, 96.390, 4170.0, 64.5755
6.215716286, 96.390, 4251.0, 65.1997
6.268237417, 96.390, 4107.0, 64.0859
6.320758548, 96.390, 4185.0, 64.6916
6.373279678, 96.390, 4085.0, 63.9140
6.425800809, 96.390, 4131.0, 64.2729
6.478321940, 96.390, 3948.0, 62.8331
6.530843071, 96.390, 4062.0, 63.7338
6.583364201, 96.390, 4060.0, 63.7181
6.635885332, 96.390, 4032.0, 63.4980
6.688406463, 96.390, 3911.0, 62.5380
6.740927593, 96.390, 3875.0, 62.2495
6.793448724, 96.390, 3884.0, 62.3217
6.845969855, 96.390, 3812.0, 61.7414
6.898490986, 96.390, 3829.0, 61.8789
6.951012116, 96.390, 3787.0, 61.5386
7.003533247, 96.390, 3761.0, 61.3270
7.056054378, 96.390, 3640.0, 60.3324
7.108575508, 96.390, 3730.0, 61.0737
7.161096639, 96.390, 3604.0, 60.0333
7.213617770, 96.390, 3720.0, 60.9918
7.266138900, 96.390, 3715.0, 60.9508
7.318660031, 96.390, 3655.0, 60.4566
7.371181162, 96.390, 3748.0, 61.2209
7.423702293, 96.390, 3618.0, 60.1498
7.476223423, 96.390, 3675.0, 60.6218
7.528744554, 96.390, 3614.0, 60.1166
7.581265685, 96.390, 3469.0, 58.8982
7.633786815, 96.390, 3512.0, 59.2621
7.686307946, 96.390, 3558.0, 59.6490
7.738829077, 96.390, 3486.0, 59.0424
7.791350208, 96.390, 3546.0, 59.5483
7.843871338, 96.390, 3430.0, 58.5662
7.896392469, 96.390, 3450.0, 58.7367
7.948913600, 96.390, 3446.0, 58.7026
8.001434730, 96.390, 3453.0, 58.7622
8.053955861, 96.390, 3405.0, 58.3524
8.106476992, 96.390, 3426.0, 58.5320
8.158998123, 96.390, 3493.0, 59.1016
8.211519253, 96.390, 3442.0, 58.6686
8.264040384, 96.390, 3305.0, 57.4891
8.316561515, 96.390, 3303.0, 57.4717
8.369082645, 96.390, 3266.0, 57.1489
8.421603776, 96.390, 3242.0, 56.9386
8.474124907, 96.390, 3236.0, 56.8859
8.526646038, 96.390, 3237.0, 56.8946
8.579167168, 96.390, 3292.0, 57.3760
8.631688299, 96.390, 3357.0, 57.9396
8.684209430, 96.390, 3192.0, 56.4978
8.736730560, 96.390, 3174.0, 56.3383
8.789251691, 96.390, 3253.0, 57.0351
8.841772822, 96.390, 3218.0, 56.7274
8.894293952, 96.390, 3163.0, 56.2406
8.946815083, 96.390, 3077.0, 55.4707
8.999336214, 96.390, 3228.0, 56.8155
9.051857345, 96.390, 3132.0, 55.9643
9.104378475, 96.390, 3257.0, 57.0701
9.156899606, 96.390, 3043.0, 55.1634
9.209420737, 96.390, 3210.0, 56.6569
9.261941867, 96.390, 3140.0, 56.0357
9.314462998, 96.390, 3089.0, 55.5788
9.366984129, 96.390, 3113.0, 55.7943
9.419505260, 96.390, 3196.0, 56.5332
9.472026390, 96.390, 3084.0, 55.5338
9.524547521, 96.390, 3048.0, 55.2087
9.577068652, 96.390, 3120.0, 55.8570
9.629589782, 96.390, 3105.0, 55.7225
9.682110913, 96.390, 3146.0, 56.0892
9.734632044, 96.390, 3089.0, 55.5788
9.787153175, 96.390, 3012.0, 54.8817
9.839674305, 96.390, 3005.0, 54.8179
9.892195436, 96.390, 3042.0, 55.1543
9.944716567, 96.390, 3015.0, 54.9090
9.997237697, 96.390, 3057.0, 55.2901
10.049758828, 96.390, 2921.0, 54.0463
10.102279959, 96.390, 2966.0, 54.4610
10.154801090, 96.390, 2924.0, 54.0740
10.207322220, 96.390, 2883.0, 53.6936
10.259843351, 96.390, 3004.0, 54.8088
10.312364482, 96.390, 2897.0, 53.8238
10.364885612, 96.390, 2870.0, 53.5724
10.417406743, 96.390, 2926.0, 54.0925
10.469927874, 96.390, 2901.0, 53.8609
10.522449004, 96.390, 2906.0, 53.9073
10.574970135, 96.390, 2802.0, 52.9339
10.627491266, 96.390, 2851.0, 53.3948
10.680012397, 96.390, 2933.0, 54.1572
10.732533527, 96.390, 2799.0, 52.9056
10.785054658, 96.390, 2901.0, 53.8609
10.837575789, 96.390, 2869.0, 53.5630
10.890096919, 96.390, 2939.0, 54.2125
10.942618050, 96.390, 2721.0, 52.1632
10.995139181, 96.390, 2869.0, 53.5630
11.047660312, 96.390, 2744.0, 52.3832
11.100181442, 96.390, 2782.0, 52.7447
11.152702573, 96.390, 2672.0, 51.6914
11.205223704, 96.390, 2710.0, 52.0577
11.257744834, 96.390, 2779.0, 52.7162
11.310265965, 96.390, 2878.0, 53.6470
11.362787096, 96.390, 2679.0, 51.7591
11.415308227, 96.390, 2716.0, 52.1153
11.467829357, 96.390, 2717.0, 52.1249
11.520350488, 96.390, 2747.0, 52.4118
11.572871619, 96.390, 2664.0, 51.6140
11.625392749, 96.390, 2551.0, 50.5074
11.677913880, 96.390, 2661.0, 51.5849
11.730435011, 96.390, 2651.0, 51.4879
11.782956141, 96.390, 2691.0, 51.8748
11.835477272, 96.390, 2660.0, 51.5752
11.887998403, 96.390, 2606.0, 51.0490
11.940519534, 96.390, 2588.0, 50.8724
11.993040664, 96.390, 2695.0, 51.9134
12.045561795, 96.390, 2650.0, 51.4782
12.098082926, 96.390, 2533.0, 50.3289
12.150604056, 96.390, 2647.0, 51.4490
12.203125187, 96.390, 2637.0, 51.3517
12.255646318, 96.390, 2624.0, 51.2250
12.308167449, 96.390, 2523.0, 50.2295
12.360688579, 96.390, 2616.0, 51.1468
12.413209710, 96.390, 2461.0, 49.6085
12.465730841, 96.390, 2554.0, 50.5371
12.518251971, 96.390, 2549.0, 50.4876
12.570773102, 96.390, 2553.0, 50.5272
12.623294233, 96.390, 2563.0, 50.6261
12.675815364, 96.390, 2570.0, 50.6952
12.728336494, 96.390, 2529.0, 50.2892
12.780857625, 96.390, 2461.0, 49.6085
12.833378756, 96.390, 2493.0, 49.9300
12.885899886, 96.390, 2386.0, 48.8467
12.938421017, 96.390, 2396.0, 48.9490
12.990942148, 96.390, 2489.0, 49.8899
13.043463279, 96.390, 2452.0, 49.5177
13.095984409, 96.390, 2517.0, 50.1697
13.148505540, 96.390, 2520.0, 50.1996
13.201026671, 96.390, 2483.0, 49.8297
13.253547801, 96.390, 2505.0, 50.0500
13.306068932, 96.390, 2354.0, 48.5180
13.358590063, 96.390, 2412.0, 49.1121
13.411111193, 96.390, 2466.0, 49.6588
13.463632324, 96.390, 2390.0, 48.8876
13.516153455, 96.390, 2460.0, 49.5984
13.568674586, 96.390, 2421.0, 49.2037
13.621195716, 96.390, 2378.0, 48.7647
13.673716847, 96.390, 2430.0, 49.2950
13.726237978, 96.390, 2493.0, 49.9300
13.778759108, 96.390, 2281.0, 47.7598
13.831280239, 96.390, 2384.0, 48.8262
13.883801370, 96.390, 2393.0, 48.9183
13.936322501, 96.390, 2522.0, 50.2195
13.988843631, 96.390, 2416.0, 49.1528
14.041364762, 96.390, 2416.0, 49.1528
14.093885893, 96.390, 2443.0, 49.4267
14.146407023, 96.390, 2391.0, 48.8979
14.198928154, 96.390, 2337.0, 48.3425
14.251449285, 96.390, 2286.0, 47.8121
14.303970416, 96.390, 2362.0, 48.6004
14.356491546, 96.390, 2452.0, 49.5177
14.409012677, 96.390, 2493.0, 49.9300
14.461533808, 96.390, 2288.0, 47.8330
14.514054938, 96.390, 2320.0, 48.1664
14.566576069, 96.390, 2353.0, 48.5077
14.619097200, 96.390, 2410.0, 49.0918
14.671618331, 96.390, 2421.0, 49.2037
14.724139461, 96.390, 2398.0, 48.9694
14.776660592, 96.390, 2417.0, 49.1630
14.829181723, 96.390, 2322.0, 48.1871
14.881702853, 96.390, 2293.0, 47.8853
14.934223984, 96.390, 2421.0, 49.2037
14.986745115, 96.390, 2358.0, 48.5592
15.039266245, 96.390, 2480.0, 49.7996
15.091787376, 96.390, 2346.0, 48.4355
15.144308507, 96.390, 2394.0, 48.9285
15.196829638, 96.390, 2333.0, 48.3011
15.249350768, 96.390, 2426.0, 49.2544
15.301871899, 96.390, 2468.0, 49.6790
15.354393030, 96.390, 2440.0, 49.3964
15.406914160, 96.390, 2273.0, 47.6760
15.459435291, 96.390, 2394.0, 48.9285
15.511956422, 96.390, 2418.0, 49.1732
15.564477553, 96.390, 2445.0, 49.4469
15.616998683, 96.390, 2421.0, 49.2037
15.669519814, 96.390, 2385.0, 48.8365
15.722040945, 96.390, 2463.0, 49.6286
15.774562075, 96.390, 2373.0, 48.7134
15.827083206, 96.390, 2419.0, 49.1833
15.879604337, 96.390, 2362.0, 48.6004
15.932125468, 96.390, 2372.0, 48.7032
15.984646598, 96.390, 2403.0, 49.0204
16.037167729, 96.390, 2376.0, 48.7442
16.089688860, 96.390, 2482.0, 49.8197
16.142209990, 96.390, 2419.0, 49.1833
16.194731121, 96.390, 2408.0, 49.0714
16.247252252, 96.390, 2452.0, 49.5177
16.299773382, 96.390, 2454.0, 49.5379
16.352294513, 96.390, 2452.0, 49.5177
16.404815644, 96.390, 2545.0, 50.4480
16.457336775, 96.390, 2436.0, 49.3559
16.509857905, 96.390, 2468.0, 49.6790
16.562379036, 96.390, 2460.0, 49.5984
16.614900167, 96.390, 2410.0, 49.0918
16.667421297, 96.390, 2540.0, 50.3984
16.719942428, 96.390, 2491.0, 49.9099
16.772463559, 96.390, 2431.0, 49.3052
16.824984690, 96.390, 2534.0, 50.3389
16.877505820, 96.390, 2496.0, 49.9600
16.930026951, 96.390, 2502.0, 50.0200
16.982548082, 96.390, 2573.0, 50.7247
17.035069212, 96.390, 2509.0, 50.0899
17.087590343, 96.390, 2575.0, 50.7445
17.140111474, 96.390, 2566.0, 50.6557
17.192632605, 96.390, 2628.0, 51.2640
17.245153735, 96.390, 2579.0, 50.7839
17.297674866, 96.390, 2633.0, 51.3128
17.350195997, 96.390, 2531.0, 50.3090
17.402717127, 96.390, 2615.0, 51.1371
17.455238258, 96.390, 2705.0, 52.0096
17.507759389, 96.390, 2731.0, 52.2590
17.560280520, 96.390, 2644.0, 51.4198
17.612801650, 96.390, 2664.0, 51.6140
17.665322781, 96.390, 2763.0, 52.5642
17.717843912, 96.390, 2735.0, 52.2972
17.770365042, 96.390, 2759.0, 52.5262
17.822886173, 96.390, 2796.0, 52.8772
17.875407304, 96.390, 2675.0, 51.7204
17.927928434, 96.390, 2788.0, 52.8015
17.980449565, 96.390, 2781.0, 52.7352
18.032970696, 96.390, 2789.0, 52.8110
18.085491827, 96.390, 2876.0, 53.6284
18.138012957, 96.390, 2812.0, 53.0283
18.190534088, 96.390, 2857.0, 53.4509
18.243055219, 96.390, 2911.0, 53.9537
18.295576349, 96.390, 2966.0, 54.4610
18.348097480, 96.390, 2927.0, 54.1018
18.400618611, 96.390, 3043.0, 55.1634
18.453139742, 96.390, 2894.0, 53.7959
18.505660872, 96.390, 3023.0, 54.9818
18.558182003, 96.390, 3033.0, 55.0727
18.610703134, 96.390, 3027.0, 55.0182
18.663224264, 96.390, 2993.0, 54.7083
18.715745395, 96.390, 3194.0, 56.5155
18.768266526, 96.390, 3073.0, 55.4346
18.820787657, 96.390, 2999.0, 54.7631
18.873308787, 96.390, 3054.0, 55.2630
18.925829918, 96.390, 3168.0, 56.2850
18.978351049, 96.390, 3131.0, 55.9553
19.030872179, 96.390, 3191.0, 56.4889
19.083393310, 96.390, 3167.0, 56.2761
19.135914441, 96.390, 3210.0, 56.6569
19.188435572, 96.390, 3195.0, 56.5243
19.240956702, 96.390, 3222.0, 56.7627
19.293477833, 96.390, 3285.0, 57.3149
19.345998964, 96.390, 3387.0, 58.1979
19.398520094, 96.390, 3363.0, 57.9914
19.451041225, 96.390, 3433.0, 58.5918
19.503562356, 96.390, 3420.0, 58.4808
19.556083486, 96.390, 3340.0, 57.7927
19.608604617, 96.390, 3402.0, 58.3267
19.661125748, 96.390, 3478.0, 58.9746
19.713646879, 96.390, 3536.0, 59.4643
19.766168009, 96.390, 3536.0, 59.4643
19.818689140, 96.390, 3496.0, 59.1270
19.871210271, 96.390, 3592.0, 59.9333
19.923731401, 96.390, 3531.0, 59.4222
19.976252532, 96.390, 3657.0, 60.4731
20.028773663, 96.390, 3711.0, 60.9180
20.081294794, 96.390, 3728.0, 61.0574
20.133815924, 96.390, 3721.0, 61.0000
20.186337055, 96.390, 3680.0, 60.6630
20.238858186, 96.390, 3662.0, 60.5145
20.291379316, 96.390, 3781.0, 61.4898
20.343900447, 96.390, 3852.0, 62.0645
20.396421578, 96.390, 3838.0, 61.9516
20.448942709, 96.390, 3952.0, 62.8649
20.501463839, 96.390, 3782.0, 61.4980
20.553984970, 96.390, 3863.0, 62.1530
20.606506101, 96.390, 3964.0, 62.9603
20.659027231, 96.390, 3892.0, 62.3859
20.711548362, 96.390, 3954.0, 62.8808
20.764069493, 96.390, 4089.0, 63.9453
20.816590623, 96.390, 3860.0, 62.1289
20.869111754, 96.390, 4081.0, 63.8827
20.921632885, 96.390, 4087.0, 63.9296
20.974154016, 96.390, 4138.0, 64.3273
21.026675146, 96.390, 4015.0, 63.3640
21.079196277, 96.390, 4144.0, 64.3739
21.131717408, 96.390, 4140.0, 64.3428
21.184238538, 96.390, 4134.0, 64.2962
21.236759669, 96.390, 4178.0, 64.6375
21.289280800, 96.390, 4204.0, 64.8383
21.341801931, 96.390, 4165.0, 64.5368
21.394323061, 96.390, 4192.0, 64.7457
21.446844192, 96.390, 4216.0, 64.9307
21.499365323, 96.390, 4103.0, 64.0547
21.551886453, 96.390, 4248.0, 65.1767
21.604407584, 96.390, 4335.0, 65.8407
21.656928715, 96.390, 4243.0, 65.1383
21.709449846, 96.390, 4217.0, 64.9384
21.761970976, 96.390, 4249.0, 65.1844
21.814492107, 96.390, 4321.0, 65.7343
21.867013238, 96.390, 4296.0, 65.5439
21.919534368, 96.390, 4292.0, 65.5134
21.972055499, 96.390, 4269.0, 65.3376
22.024576630, 96.390, 4392.0, 66.2722
22.077097761, 96.390, 4144.0, 64.3739
22.129618891, 96.390, 4311.0, 65.6582
22.182140022, 96.390, 4301.0, 65.5820
22.234661153, 96.390, 4220.0, 64.9615
22.287182283, 96.390, 4242.0, 65.1306
22.339703414, 96.390, 4371.0, 66.1135
22.392224545, 96.390, 4362.0, 66.0454
22.444745675, 96.390, 4212.0, 64.8999
22.497266806, 96.390, 4131.0, 64.2729
22.549787937, 96.390, 4269.0, 65.3376
22.602309068, 96.390, 4275.0, 65.3835
22.654830198, 96.390, 4267.0, 65.3223
22.707351329, 96.390, 4274.0, 65.3758
22.759872460, 96.390, 4251.0, 65.1997
22.812393590, 96.390, 4151.0, 64.4283
22.864914721, 96.390, 4148.0, 64.4050
22.917435852, 96.390, 4182.0, 64.6684
22.969956983, 96.390, 4088.0, 63.9375
23.022478113, 96.390, 4215.0, 64.9230
23.074999244, 96.390, 4222.0, 64.9769
23.127520375, 96.390, 4006.0, 63.2930
23.180041505, 96.390, 4062.0, 63.7338
23.232562636, 96.390, 4186.0, 64.6993
23.285083767, 96.390, 4143.0, 64.3661
23.337604898, 96.390, 4052.0, 63.6553
23.390126028, 96.390, 4081.0, 63.8827
23.442647159, 96.390, 3945.0, 62.8092
23.495168290, 96.390, 4057.0, 63.6946
23.547689420, 96.390, 4036.0, 63.5295
23.600210551, 96.390, 4041.0, 63.5689
23.652731682, 96.390, 3887.0, 62.3458
23.705252813, 96.390, 3993.0, 63.1902
23.757773943, 96.390, 4083.0, 63.8984
23.810295074, 96.390, 3882.0, 62.3057
23.862816205, 96.390, 3899.0, 62.4420
23.915337335, 96.390, 3739.0, 61.1474
23.967858466, 96.390, 3906.0, 62.4980
24.020379597, 96.390, 3830.0, 61.8870
24.072900727, 96.390, 3735.0, 61.1146
24.125421858, 96.390, 3862.0, 62.1450
24.177942989, 96.390, 3848.0, 62.0322
24.230464120, 96.390, 3753.0, 61.2617
24.282985250, 96.390, 3841.0, 61.9758
24.335506381, 96.390, 3643.0, 60.3573
24.388027512, 96.390, 3679.0, 60.6548
24.440548642, 96.390, 3617.0, 60.1415
24.493069773, 96.390, 3634.0, 60.2827
24.545590904, 96.390, 3645.0, 60.3738
24.598112035, 96.390, 3566.0, 59.7160
24.650633165, 96.390, 3644.0, 60.3656
24.703154296, 96.390, 3636.0, 60.2993
24.755675427, 96.390, 3553.0, 59.6070
24.808196557, 96.390, 3492.0, 59.0931
24.860717688, 96.390, 3650.0, 60.4152
24.913238819, 96.390, 3481.0, 59.0000
24.965759950, 96.390, 3523.0, 59.3549
25.018281080, 96.390, 3519.0, 59.3212
25.070802211, 96.390, 3406.0, 58.3609
25.123323342, 96.390, 3344.0, 57.8273
25.175844472, 96.390, 3381.0, 58.1464
25.228365603, 96.390, 3378.0, 58.1206
25.280886734, 96.390, 3371.0, 58.0603
25.333407864, 96.390, 3321.0, 57.6281
25.385928995, 96.390, 3262.0, 57.1139
25.438450126, 96.390, 3269.0, 57.1752
25.490971257, 96.390, 3251.0, 57.0175
25.543492387, 96.390, 3202.0, 56.5862
25.596013518, 96.390, 3304.0, 57.4804
25.648534649, 96.390, 3159.0, 56.2050
25.701055779, 96.390, 3217.0, 56.7186
25.753576910, 96.390, 3190.0, 56.4801
25.806098041, 96.390, 3146.0, 56.0892
25.858619172, 96.390, 3171.0, 56.3116
25.911140302, 96.390, 3187.0, 56.4535
25.963661433, 96.390, 3130.0, 55.9464
26.016182564, 96.390, 3115.0, 55.8122
26.068703694, 96.390, 3008.0, 54.8452
26.121224825, 96.390, 3107.0, 55.7405
26.173745956, 96.390, 2970.0, 54.4977
26.226267087, 96.390, 3051.0, 55.2359
26.278788217, 96.390, 3009.0, 54.8544
26.331309348, 96.390, 2962.0, 54.4243
26.383830479, 96.390, 2942.0, 54.2402
26.436351609, 96.390, 2934.0, 54.1664
26.488872740, 96.390, 3051.0, 55.2359
26.541393871, 96.390, 2893.0, 53.7866
26.593915002, 96.390, 2884.0, 53.7029
26.646436132, 96.390, 2887.0, 53.7308
26.698957263, 96.390, 2913.0, 53.9722
26.751478394, 96.390, 2868.0, 53.5537
26.803999524, 96.390, 2903.0, 53.8795
26.856520655, 96.390, 2954.0, 54.3507
26.909041786, 96.390, 2843.0, 53.3198
26.961562916, 96.390, 2744.0, 52.3832
27.014084047, 96.390, 2744.0, 52.3832
27.066605178, 96.390, 2700.0, 51.9615
27.119126309, 96.390, 2813.0, 53.0377
27.171647439, 96.390, 2741.0, 52.3546
27.224168570, 96.390, 2674.0, 51.7107
27.276689701, 96.390, 2722.0, 52.1728
27.329210831, 96.390, 2652.0, 51.4976
27.381731962, 96.390, 2724.0, 52.1920
27.434253093, 96.390, 2552.0, 50.5173
27.486774224, 96.390, 2653.0, 51.5073
27.539295354, 96.390, 2647.0, 51.4490
27.591816485, 96.390, 2712.0, 52.0769
27.644337616, 96.390, 2463.0, 49.6286
27.696858746, 96.390, 2608.0, 51.0686
27.749379877, 96.390, 2527.0, 50.2693
27.801901008, 96.390, 2546.0, 50.4579
27.854422139, 96.390, 2494.0, 49.9400
27.906943269, 96.390, 2560.0, 50.5964
27.959464400, 96.390, 2608.0, 51.0686
28.011985531, 96.390, 2541.0, 50.4083
28.064506661, 96.390, 2532.0, 50.3190
28.117027792, 96.390, 2518.0, 50.1797
28.169548923, 96.390, 2550.0, 50.4975
28.222070054, 96.390, 2455.0, 49.5480
28.274591184, 96.390, 2494.0, 49.9400
28.327112315, 96.390, 2432.0, 49.3153
28.379633446, 96.390, 2430.0, 49.2950
28.432154576, 96.390, 2457.0, 49.5681
28.484675707, 96.390, 2367.0, 48.6518
28.537196838, 96.390, 2372.0, 48.7032
28.589717968, 96.390, 2365.0, 48.6313
28.642239099, 96.390, 2321.0, 48.1768
28.694760230, 96.390, 2396.0, 48.9490
28.747281361, 96.390, 2409.0, 49.0816
28.799802491, 96.390, 2296.0, 47.9166
28.852323622, 96.390, 2343.0, 48.4045
28.904844753, 96.390, 2419.0, 49.1833
28.957365883, 96.390, 2252.0, 47.4552
29.009887014, 96.390, 2259.0, 47.5289
29.062408145, 96.390, 2343.0, 48.4045
29.114929276, 96.390, 2267.0, 47.6130
29.167450406, 96.390, 2206.0, 46.9681
29.219971537, 96.390, 2161.0, 46.4866
29.272492668, 96.390, 2208.0, 46.9894
29.325013798, 96.390, 2196.0, 46.8615
29.377534929, 96.390, 2134.0, 46.1952
29.430056060, 96.390, 2227.0, 47.1911
29.482577191, 96.390, 2129.0, 46.1411
29.535098321, 96.390, 2243.0, 47.3603
29.587619452, 96.390, 2147.0, 46.3357
29.640140583, 96.390, 2170.0, 46.5833
29.692661713, 96.390, 2118.0, 46.0217
29.745182844, 96.390, 2214.0, 47.0532
29.797703975, 96.390, 2162.0, 46.4973
29.850225105, 96.390, 2180.0, 46.6905
29.902746236, 96.390, 2089.0, 45.7056
29.955267367, 96.390, 2097.0, 45.7930
30.007788498, 96.390, 2064.0, 45.4313
30.060309628, 96.390, 2106.0, 45.8912
30.112830759, 96.390, 2104.0, 45.8694
30.165351890, 96.390, 2038.0, 45.1442
30.217873020, 96.390, 2017.0, 44.9110
30.270394151, 96.390, 2084.0, 45.6508
30.322915282, 96.390, 2041.0, 45.1774
30.375436413, 96.390, 2073.0, 45.5302
30.427957543, 96.390, 2076.0, 45.5631
30.480478674, 96.390, 2051.0, 45.2880
30.532999805, 96.390, 2036.0, 45.1221
30.585520935, 96.390, 2051.0, 45.2880
30.638042066, 96.390, 1967.0, 44.3509
30.690563197, 96.390, 1969.0, 44.3734
30.743084328, 96.390, 2005.0, 44.7772
30.795605458, 96.390, 1857.0, 43.0929
30.848126589, 96.390, 2011.0, 44.8442
30.900647720, 96.390, 1888.0, 43.4511
30.953168850, 96.390, 1909.0, 43.6921
31.005689981, 96.390, 1918.0, 43.7950
31.058211112, 96.390, 1945.0, 44.1022
31.110732243, 96.390, 2026.0, 45.0111
31.163253373, 96.390, 1887.0, 43.4396
31.215774504, 96.390, 1887.0, 43.4396
31.268295635, 96.390, 1952.0, 44.1814
31.320816765, 96.390, 1973.0, 44.4185
31.373337896, 96.390, 1883.0, 43.3935
31.425859027, 96.390, 1864.0, 43.1741
31.478380157, 96.390, 1866.0, 43.1972
31.530901288, 96.390, 1841.0, 42.9069
31.583422419, 96.390, 1854.0, 43.0581
31.635943550, 96.390, 1968.0, 44.3621
31.688464680, 96.390, 1822.0, 42.6849
31.740985811, 96.390, 1848.0, 42.9884
31.793506942, 96.390, 1904.0, 43.6348
31.846028072, 96.390, 1724.0, 41.5211
31.898549203, 96.390, 1774.0, 42.1189
31.951070334, 96.390, 1813.0, 42.5793
32.003591465, 96.390, 1857.0, 43.0929
32.056112595, 96.390, 1791.0, 42.3202
32.108633726, 96.390, 1743.0, 41.7493
32.161154857, 96.390, 1767.0, 42.0357
32.213675987, 96.390, 1686.0, 41.0609
32.266197118, 96.390, 1718.0, 41.4488
32.318718249, 96.390, 1705.0, 41.2916
32.371239380, 96.390, 1788.0, 42.2847
32.423760510, 96.390, 1724.0, 41.5211
32.476281641, 96.390, 1721.0, 41.4849
32.528802772, 96.390, 1781.0, 42.2019
32.581323902, 96.390, 1698.0, 41.2068
32.633845033, 96.390, 1672.0, 40.8901
32.686366164, 96.390, 1663.0, 40.7799
32.738887295, 96.390, 1637.0, 40.4599
32.791408425, 96.390, 1632.0, 40.3980
32.843929556, 96.390, 1704.0, 41.2795
32.896450687, 96.390, 1631.0, 40.3856
32.948971817, 96.390, 1691.0, 41.1218
33.001492948, 96.390, 1675.0, 40.9268
33.054014079, 96.390, 1640.0, 40.4969
33.106535209, 96.390, 1632.0, 40.3980
33.159056340, 96.390, 1627.0, 40.3361
33.211577471, 96.390, 1671.0, 40.8779
33.264098602, 96.390, 1592.0, 39.8999
33.316619732, 96.390, 1696.0, 41.1825
33.369140863, 96.390, 1595.0, 39.9375
33.421661994, 96.390, 1586.0, 39.8246
33.474183124, 96.390, 1586.0, 39.8246
33.526704255, 96.390, 1590.0, 39.8748
33.579225386, 96.390, 1606.0, 40.0749
33.631746517, 96.390, 1603.0, 40.0375
33.684267647, 96.390, 1519.0, 38.9744
33.736788778, 96.390, 1542.0, 39.2683
33.789309909, 96.390, 1639.0, 40.4846
33.841831039, 96.390, 1550.0, 39.3700
33.894352170, 96.390, 1543.0, 39.2810
33.946873301, 96.390, 1551.0, 39.3827
33.999394432, 96.390, 1504.0, 38.7814
34.051915562, 96.390, 1517.0, 38.9487
34.104436693, 96.390, 1608.0, 40.0999
34.156957824, 96.390, 1505.0, 38.7943
34.209478954, 96.390, 1527.0, 39.0768
34.262000085, 96.390, 1593.0, 39.9124
34.314521216, 96.390, 1467.0, 38.3014
34.367042346, 96.390, 1517.0, 38.9487
34.419563477, 96.390, 1438.0, 37.9210
34.472084608, 96.390, 1506.0, 38.8072
34.524605739, 96.390, 1489.0, 38.5876
34.577126869, 96.390, 1513.0, 38.8973
34.629648000, 96.390, 1468.0, 38.3145
34.682169131, 96.390, 1478.0, 38.4448
34.734690261, 96.390, 1435.0, 37.8814
34.787211392, 96.390, 1412.0, 37.5766
34.839732523, 96.390, 1414.0, 37.6032
34.892253654, 96.390, 1408.0, 37.5233
34.944774784, 96.390, 1428.0, 37.7889
34.997295915, 96.390, 1384.0, 37.2022
35.049817046, 96.390, 1460.0, 38.2099
35.102338176, 96.390, 1429.0, 37.8021
35.154859307, 96.390, 1418.0, 37.6563
35.207380438, 96.390, 1386.0, 37.2290
35.259901569, 96.390, 1431.0, 37.8286
35.312422699, 96.390, 1401.0, 37.4299
35.364943830, 96.390, 1350.0, 36.7423
35.417464961, 96.390, 1400.0, 37.4166
35.469986091, 96.390, 1406.0, 37.4967
35.522507222, 96.390, 1403.0, 37.4566
35.575028353, 96.390, 1328.0, 36.4417
35.627549484, 96.390, 1360.0, 36.8782
35.680070614, 96.390, 1291.0, 35.9305
35.732591745, 96.390, 1342.0, 36.6333
35.785112876, 96.390, 1325.0, 36.4005
35.837634006, 96.390, 1399.0, 37.4032
35.890155137, 96.390, 1375.0, 37.0810
35.942676268, 96.390, 1340.0, 36.6060
35.995197398, 96.390, 1353.0, 36.7831
36.047718529, 96.390, 1351.0, 36.7560
36.100239660, 96.390, 1311.0, 36.2077
36.152760791, 96.390, 1259.0, 35.4824
36.205281921, 96.390, 1318.0, 36.3043
36.257803052, 96.390, 1286.0, 35.8608
36.310324183, 96.390, 1274.0, 35.6931
36.362845313, 96.390, 1279.0, 35.7631
36.415366444, 96.390, 1232.0, 35.0999
36.467887575, 96.390, 1242.0, 35.2420
36.520408706, 96.390, 1251.0, 35.3695
36.572929836, 96.390, 1309.0, 36.1801
36.625450967, 96.390, 1277.0, 35.7351
36.677972098, 96.390, 1273.0, 35.6791
36.730493228, 96.390, 1318.0, 36.3043
36.783014359, 96.390, 1304.0, 36.1109
36.835535490, 96.390, 1196.0, 34.5832
36.888056621, 96.390, 1203.0, 34.6843
36.940577751, 96.390, 1272.0, 35.6651
36.993098882, 96.390, 1288.0, 35.8887
37.045620013, 96.390, 1182.0, 34.3802
37.098141143, 96.390, 1278.0, 35.7491
37.150662274, 96.390, 1177.0, 34.3074
37.203183405, 96.390, 1246.0, 35.2987
37.255704535, 96.390, 1251.0, 35.3695
37.308225666, 96.390, 1212.0, 34.8138
37.360746797, 96.390, 1212.0, 34.8138
37.413267928, 96.390, 1224.0, 34.9857
37.465789058, 96.390, 1205.0, 34.7131
37.518310189, 96.390, 1226.0, 35.0143
37.570831320, 96.390, 1229.0, 35.0571
37.623352450, 96.390, 1164.0, 34.1174
37.675873581, 96.390, 1140.0, 33.7639
37.728394712, 96.390, 1238.0, 35.1852
37.780915843, 96.390, 1165.0, 34.1321
37.833436973, 96.390, 1219.0, 34.9142
37.885958104, 96.390, 1182.0, 34.3802
37.938479235, 96.390, 1193.0, 34.5398
37.991000365, 96.390, 1139.0, 33.7491
38.043521496, 96.390, 1183.0, 34.3948
38.096042627, 96.390, 1182.0, 34.3802
38.148563758, 96.390, 1195.0, 34.5688
38.201084888, 96.390, 1149.0, 33.8969
38.253606019, 96.390, 1095.0, 33.0908
38.306127150, 96.390, 1139.0, 33.7491
38.358648280, 96.390, 1209.0, 34.7707
38.411169411, 96.390, 1127.0, 33.5708
38.463690542, 96.390, 1165.0, 34.1321
38.516211673, 96.390, 1113.0, 33.3617
38.568732803, 96.390, 1060.0, 32.5576
38.621253934, 96.390, 1141.0, 33.7787
38.673775065, 96.390, 1158.0, 34.0294
38.726296195, 96.390, 1153.0, 33.9559
38.778817326, 96.390, 1121.0, 33.4813
38.831338457, 96.390, 1110.0, 33.3167
38.883859587, 96.390, 1141.0, 33.7787
38.936380718, 96.390, 1092.0, 33.0454
38.988901849, 96.390, 1070.0, 32.7109
39.041422980, 96.390, 1070.0, 32.7109
39.093944110, 96.390, 1110.0, 33.3167
39.146465241, 96.390, 1141.0, 33.7787
39.198986372, 96.390, 1071.0, 32.7261
39.251507502, 96.390, 1072.0, 32.7414
39.304028633, 96.390, 1115.0, 33.3916
39.356549764, 96.390, 1044.0, 32.3110
39.409070895, 96.390, 1062.0, 32.5883
39.461592025, 96.390, 1076.0, 32.8024
39.514113156, 96.390, 1104.0, 33.2265
39.566634287, 96.390, 1050.0, 32.4037
39.619155417, 96.390, 1048.0, 32.3728
39.671676548, 96.390, 1040.0, 32.2490
39.724197679, 96.390, 1084.0, 32.9242
39.776718810, 96.390, 1009.0, 31.7648
39.829239940, 96.390, 1082.0, 32.8938
39.881761071, 96.390, 1064.0, 32.6190
39.934282202, 96.390, 1035.0, 32.1714
39.986803332, 96.390, 1073.0, 32.7567
40.039324463, 96.390, 1058.0, 32.5269
40.091845594, 96.390, 1018.0, 31.9061
40.144366725, 96.390, 1030.0, 32.0936
40.196887855, 96.390, 1128.0, 33.5857
40.249408986, 96.390, 1118.0, 33.4365
40.301930117, 96.390, 1031.0, 32.1092
40.354451247, 96.390, 1091.0, 33.0303
40.406972378, 96.390, 1053.0, 32.4500
40.459493509, 96.390, 1135.0, 33.6898
40.512014639, 96.390, 1019.0, 31.9218
40.564535770, 96.390, 1078.0, 32.8329
40.617056901, 96.390, 1103.0, 33.2114
40.669578032, 96.390, 1011.0, 31.7962
40.722099162, 96.390, 1025.0, 32.0156
40.774620293, 96.390, 1038.0, 32.2180
40.827141424, 96.390, 1047.0, 32.3574
40.879662554, 96.390, 1056.0, 32.4962
40.932183685, 96.390, 1036.0, 32.1870
40.984704816, 96.390, 1078.0, 32.8329
41.037225947, 96.390, 1015.0, 31.8591
41.089747077, 96.390, 1041.0, 32.2645
41.142268208, 96.390, 1030.0, 32.0936
41.194789339, 96.390, 1059.0, 32.5423
41.247310469, 96.390, 1072.0, 32.7414
41.299831600, 96.390, 1000.0, 31.6228
41.352352731, 96.390, 987.0, 31.4166
41.404873862, 96.390, 1040.0, 32.2490
41.457394992, 96.390, 1006.0, 31.7175
41.509916123, 96.390, 1062.0, 32.5883
41.562437254, 96.390, 1018.0, 31.9061
41.614958384, 96.390, 1002.0, 31.6544
41.667479515, 96.390, 1032.0, 32.1248
41.720000646, 96.390, 1016.0, 31.8748
41.772521776, 96.390, 993.0, 31.5119
41.825042907, 96.390, 989.0, 31.4484
41.877564038, 96.390, 1029.0, 32.0780
41.930085169, 96.390, 1018.0, 31.9061
41.982606299, 96.390, 1082.0, 32.8938
42.035127430, 96.390, 1021.0, 31.9531
42.087648561, 96.390, 1000.0, 31.6228
42.140169691, 96.390, 999.0, 31.6070
42.192690822, 96.390, 974.0, 31.2090
42.245211953, 96.390, 1043.0, 32.2955
42.297733084, 96.390, 1012.0, 31.8119
42.350254214, 96.390, 960.0, 30.9839
42.402775345, 96.390, 1053.0, 32.4500
42.455296476, 96.390, 962.0, 31.0161
42.507817606, 96.390, 1009.0, 31.7648
42.560338737, 96.390, 977.0, 31.2570
42.612859868, 96.390, 956.0, 30.9192
42.665380999, 96.390, 1037.0, 32.2025
42.717902129, 96.390, 1054.0, 32.4654
42.770423260, 96.390, 1031.0, 32.1092
42.822944391, 96.390, 1022.0, 31.9687
42.875465521, 96.390, 986.0, 31.4006
42.927986652, 96.390, 1026.0, 32.0312
42.980507783, 96.390, 1009.0, 31.7648
43.033028914, 96.390, 993.0, 31.5119
43.085550044, 96.390, 1011.0, 31.7962
43.138071175, 96.390, 1054.0, 32.4654
43.190592306, 96.390, 1040.0, 32.2490
43.243113436, 96.390, 1028.0, 32.0624
43.295634567, 96.390, 1040.0, 32.2490
43.348155698, 96.390, 1007.0, 31.7333
43.400676828, 96.390, 1010.0, 31.7805
43.453197959, 96.390, 1029.0, 32.0780
43.505719090, 96.390, 1019.0, 31.9218
43.558240221, 96.390, 1033.0, 32.1403
43.610761351, 96.390, 942.0, 30.6920
43.663282482, 96.390, 974.0, 31.2090
43.715803613, 96.390, 959.0, 30.9677
43.768324743, 96.390, 1013.0, 31.8277
43.820845874, 96.390, 994.0, 31.5278
43.873367005, 96.390, 1090.0, 33.0151
43.925888136, 96.390, 998.0, 31.5911
43.978409266, 96.390, 975.0, 31.2250
44.030930397, 96.390, 960.0, 30.9839
44.083451528, 96.390, 962.0, 31.0161
44.135972658, 96.390, 1003.0, 31.6702
44.188493789, 96.390, 955.0, 30.9031
44.241014920, 96.390, 982.0, 31.3369
44.293536051, 96.390, 983.0, 31.3528
44.346057181, 96.390, 959.0, 30.9677
44.398578312, 96.390, 979.0, 31.2890
44.451099443, 96.390, 973.0, 31.1929
44.503620573, 96.390, 999.0, 31.6070
44.556141704, 96.390, 1005.0, 31.7017
44.608662835, 96.390, 983.0, 31.3528
44.661183966, 96.390, 966.0, 31.0805
44.713705096, 96.390, 1000.0, 31.6228
44.766226227, 96.390, 1022.0, 31.9687
44.818747358, 96.390, 1015.0, 31.8591
44.871268488, 96.390, 1025.0, 32.0156
44.923789619, 96.390, 980.0, 31.3050
44.976310750, 96.390, 999.0, 31.6070
45.028831880, 96.390, 995.0, 31.5436
45.081353011, 96.390, 962.0, 31.0161
45.133874142, 96.390, 910.0, 30.1662
45.186395273, 96.390, 923.0, 30.3809
45.238916403, 96.390, 991.0, 31.4802
45.291437534, 96.390, 960.0, 30.9839
45.343958665, 96.390, 1028.0, 32.0624
45.396479795, 96.390, 967.0, 31.0966
45.449000926, 96.390, 1027.0, 32.0468
45.501522057, 96.390, 935.0, 30.5778
45.554043188, 96.390, 974.0, 31.2090
45.606564318, 96.390, 1082.0, 32.8938
45.659085449, 96.390, 991.0, 31.4802
45.711606580, 96.390, 983.0, 31.3528
45.764127710, 96.390, 946.0, 30.7571
45.816648841, 96.390, 966.0, 31.0805
45.869169972, 96.390, 983.0, 31.3528
45.921691103, 96.390, 1017.0, 31.8904
45.974212233, 96.390, 965.0, 31.0644
46.026733364, 96.390, 880.0, 29.6648
46.079254495, 96.390, 905.0, 30.0832
46.131775625, 96.390, 914.0, 30.2324
46.184296756, 96.390, 912.0, 30.1993
46.236817887, 96.390, 973.0, 31.1929
46.289339017, 96.390, 897.0, 29.9500
46.341860148, 96.390, 953.0, 30.8707
46.394381279, 96.390, 950.0, 30.8221
46.446902410, 96.390, 937.0, 30.6105
46.499423540, 96.390, 962.0, 31.0161
46.551944671, 96.390, 955.0, 30.9031
46.604465802, 96.390, 937.0, 30.6105
46.656986932, 96.390, 1030.0, 32.0936
46.709508063, 96.390, 934.0, 30.5614
46.762029194, 96.390, 986.0, 31.4006
46.814550325, 96.390, 963.0, 31.0322
46.867071455, 96.390, 933.0, 30.5450
46.919592586, 96.390, 945.0, 30.7409
46.972113717, 96.390, 1015.0, 31.8591
47.024634847, 96.390, 1007.0, 31.7333
47.077155978, 96.390, 927.0, 30.4467
47.129677109, 96.390, 978.0, 31.2730
47.182198240, 96.390, 935.0, 30.5778
47.234719370, 96.390, 929.0, 30.4795
47.287240501, 96.390, 971.0, 31.1609
47.339761632, 96.390, 953.0, 30.8707
47.392282762, 96.390, 887.0, 29.7825
47.444803893, 96.390, 934.0, 30.5614
47.497325024, 96.390, 963.0, 31.0322
47.549846155, 96.390, 907.0, 30.1164
47.602367285, 96.390, 925.0, 30.4138
47.654888416, 96.390, 874.0, 29.5635
47.707409547, 96.390, 922.0, 30.3645
47.759930677, 96.390, 976.0, 31.2410
47.812451808, 96.390, 908.0, 30.1330
47.864972939, 96.390, 894.0, 29.8998
47.917494069, 96.390, 926.0, 30.4302
47.970015200, 96.390, 897.0, 29.9500
48.022536331, 96.390, 1008.0, 31.7490
48.075057462, 96.390, 935.0, 30.5778
48.127578592, 96.390, 899.0, 29.9833
48.180099723, 96.390, 955.0, 30.9031
48.232620854, 96.390, 957.0, 30.9354
48.285141984, 96.390, 895.0, 29.9166
48.337663115, 96.390, 929.0, 30.4795
48.390184246, 96.390, 952.0, 30.8545
48.442705377, 96.390, 962.0, 31.0161
48.495226507, 96.390, 861.0, 29.3428
48.547747638, 96.390, 897.0, 29.9500
48.600268769, 96.390, 911.0, 30.1828
48.652789899, 96.390, 922.0, 30.3645
48.705311030, 96.390, 915.0, 30.2490
48.757832161, 96.390, 943.0, 30.7083
48.810353292, 96.390, 918.0, 30.2985
48.862874422, 96.390, 832.0, 28.8444
48.915395553, 96.390, 951.0, 30.8383
48.967916684, 96.390, 917.0, 30.2820
49.020437814, 96.390, 900.0, 30.0000
49.072958945, 96.390, 892.0, 29.8664
49.125480076, 96.390, 898.0, 29.9666
49.178001207, 96.390, 895.0, 29.9166
49.230522337, 96.390, 892.0, 29.8664
49.283043468, 96.390, 898.0, 29.9666
49.335564599, 96.390, 915.0, 30.2490
49.388085729, 96.390, 960.0, 30.9839
49.440606860, 96.390, 923.0, 30.3809
49.493127991, 96.390, 912.0, 30.1993
49.545649121, 96.390, 881.0, 29.6816
49.598170252, 96.390, 893.0, 29.8831
49.650691383, 96.390, 899.0, 29.9833
49.703212514, 96.390, 899.0, 29.9833
49.755733644, 96.390, 920.0, 30.3315
49.808254775, 96.390, 933.0, 30.5450
49.860775906, 96.390, 873.0, 29.5466
49.913297036, 96.390, 893.0, 29.8831
49.965818167, 96.390, 860.0, 29.3258
50.018339298, 96.390, 871.0, 29.5127
50.070860429, 96.390, 899.0, 29.9833
50.123381559, 96.390, 875.0, 29.5804
50.175902690, 96.390, 869.0, 29.4788
50.228423821, 96.390, 887.0, 29.7825
50.280944951, 96.390, 889.0, 29.8161
50.333466082, 96.390, 845.0, 29.0689
50.385987213, 96.390, 845.0, 29.0689
50.438508344, 96.390, 896.0, 29.9333
50.491029474, 96.390, 915.0, 30.2490
50.543550605, 96.390, 890.0, 29.8329
50.596071736, 96.390, 878.0, 29.6311
50.648592866, 96.390, 946.0, 30.7571
50.701113997, 96.390, 855.0, 29.2404
50.753635128, 96.390, 880.0, 29.6648
50.806156258, 96.390, 861.0, 29.3428
50.858677389, 96.390, 908.0, 30.1330
50.911198520, 96.390, 895.0, 29.9166
50.963719651, 96.390, 883.0, 29.7153
51.016240781, 96.390, 894.0, 29.8998
51.068761912, 96.390, 832.0, 28.8444
51.121283043, 96.390, 874.0, 29.5635
51.173804173, 96.390, 869.0, 29.4788
51.226325304, 96.390, 885.0, 29.7489
51.278846435, 96.390, 897.0, 29.9500
51.331367566, 96.390, 861.0, 29.3428
51.383888696, 96.390, 844.0, 29.0517
51.436409827, 96.390, 834.0, 28.8791
51.488930958, 96.390, 893.0, 29.8831
51.541452088, 96.390, 881.0, 29.6816
51.593973219, 96.390, 825.0, 28.7228
51.646494350, 96.390, 806.0, 28.3901
51.699015481, 96.390, 823.0, 28.6880
51.751536611, 96.390, 884.0, 29.7321
51.804057742, 96.390, 887.0, 29.7825
51.856578873, 96.390, 930.0, 30.4959
51.909100003, 96.390, 883.0, 29.7153
51.961621134, 96.390, 832.0, 28.8444
52.014142265, 96.390, 864.0, 29.3939
52.066663396, 96.390, 880.0, 29.6648
52.119184526, 96.390, 867.0, 29.4449
52.171705657, 96.390, 841.0, 29.0000
52.224226788, 96.390, 858.0, 29.2916
52.276747918, 96.390, 850.0, 29.1548
52.329269049, 96.390, 834.0, 28.8791
52.381790180, 96.390, 859.0, 29.3087
52.434311310, 96.390, 850.0, 29.1548
52.486832441, 96.390, 848.0, 29.1204
52.539353572, 96.390, 919.0, 30.3150
52.591874703, 96.390, 890.0, 29.8329
52.644395833, 96.390, 867.0, 29.4449
52.696916964, 96.390, 843.0, 29.0345
52.749438095, 96.390, 837.0, 28.9310
52.801959225, 96.390, 812.0, 28.4956
52.854480356, 96.390, 864.0, 29.3939
52.907001487, 96.390, 821.0, 28.6531
52.959522618, 96.390, 851.0, 29.1719
53.012043748, 96.390, 845.0, 29.0689
53.064564879, 96.390, 878.0, 29.6311
53.117086010, 96.390, 810.0, 28.4605
53.169607140, 96.390, 866.0, 29.4279
53.222128271, 96.390, 852.0, 29.1890
53.274649402, 96.390, 885.0, 29.7489
53.327170533, 96.390, 835.0, 28.8964
53.379691663, 96.390, 849.0, 29.1376
53.432212794, 96.390, 865.0, 29.4109
53.484733925, 96.390, 835.0, 28.8964
53.537255055, 96.390, 830.0, 28.8097
53.589776186, 96.390, 825.0, 28.7228
53.642297317, 96.390, 803.0, 28.3373
53.694818448, 96.390, 852.0, 29.1890
53.747339578, 96.390, 793.0, 28.1603
53.799860709, 96.390, 863.0, 29.3769
53.852381840, 96.390, 846.0, 29.0861
53.904902970, 96.390, 875.0, 29.5804
53.957424101, 96.390, 880.0, 29.6648
54.009945232, 96.390, 815.0, 28.5482
54.062466362, 96.390, 848.0, 29.1204
54.114987493, 96.390, 812.0, 28.4956
54.167508624, 96.390, 863.0, 29.3769
54.220029755, 96.390, 866.0, 29.4279
54.272550885, 96.390, 881.0, 29.6816
54.325072016, 96.390, 855.0, 29.2404
54.377593147, 96.390, 843.0, 29.0345
54.430114277, 96.390, 826.0, 28.7402
54.482635408, 96.390, 879.0, 29.6479
54.535156539, 96.390, 817.0, 28.5832
54.587677670, 96.390, 914.0, 30.2324
54.640198800, 96.390, 796.0, 28.2135
54.692719931, 96.390, 816.0, 28.5657
54.745241062, 96.390, 911.0, 30.1828
54.797762192, 96.390, 865.0, 29.4109
54.850283323, 96.390, 764.0, 27.6405
54.902804454, 96.390, 892.0, 29.8664
54.955325585, 96.390, 865.0, 29.4109
55.007846715, 96.390, 793.0, 28.1603
55.060367846, 96.390, 820.0, 28.6356
55.112888977, 96.390, 840.0, 28.9828
55.165410107, 96.390, 855.0, 29.2404
55.217931238, 96.390, 886.0, 29.7658
55.270452369, 96.390, 907.0, 30.1164
55.322973499, 96.390, 838.0, 28.9482
55.375494630, 96.390, 809.0, 28.4429
55.428015761, 96.390, 882.0, 29.6985
55.480536892, 96.390, 850.0, 29.1548
55.533058022, 96.390, 847.0, 29.1033
55.585579153, 96.390, 848.0, 29.1204
55.638100284, 96.390, 823.0, 28.6880
55.690621414, 96.390, 872.0, 29.5296
55.743142545, 96.390, 812.0, 28.4956
55.795663676, 96.390, 898.0, 29.9666
55.848184807, 96.390, 777.0, 27.8747
55.900705937, 96.390, 820.0, 28.6356
55.953227068, 96.390, 831.0, 28.8271
56.005748199, 96.390, 831.0, 28.8271
56.058269329, 96.390, 875.0, 29.5804
56.110790460, 96.390, 883.0, 29.7153
56.163311591, 96.390, 897.0, 29.9500
56.215832722, 96.390, 865.0, 29.4109
56.268353852, 96.390, 797.0, 28.2312
56.320874983, 96.390, 820.0, 28.6356
56.373396114, 96.390, 870.0, 29.4958
56.425917244, 96.390, 870.0, 29.4958
56.478438375, 96.390, 832.0, 28.8444
56.530959506, 96.390, 846.0, 29.0861
56.583480637, 96.390, 798.0, 28.2489
56.636001767, 96.390, 835.0, 28.8964
56.688522898, 96.390, 844.0, 29.0517
56.741044029, 96.390, 844.0, 29.0517
56.793565159, 96.390, 849.0, 29.1376
56.846086290, 96.390, 785.0, 28.0179
56.898607421, 96.390, 826.0, 28.7402
56.951128551, 96.390, 845.0, 29.0689
57.003649682, 96.390, 819.0, 28.6182
57.056170813, 96.390, 878.0, 29.6311
57.108691944, 96.390, 824.0, 28.7054
57.161213074, 96.390, 907.0, 30.1164
57.213734205, 96.390, 801.0, 28.3019
57.266255336, 96.390, 770.0, 27.7489
57.318776466, 96.390, 876.0, 29.5973
57.371297597, 96.390, 880.0, 29.6648
57.423818728, 96.390, 791.0, 28.1247
57.476339859, 96.390, 867.0, 29.4449
57.528860989, 96.390, 854.0, 29.2233
57.581382120, 96.390, 795.0, 28.1957
57.633903251, 96.390, 838.0, 28.9482
57.686424381, 96.390, 814.0, 28.5307
57.738945512, 96.390, 890.0, 29.8329
57.791466643, 96.390, 846.0, 29.0861
57.843987774, 96.390, 841.0, 29.0000
57.896508904, 96.390, 891.0, 29.8496
57.949030035, 96.390, 880.0, 29.6648
58.001551166, 96.390, 822.0, 28.6705
58.054072296, 96.390, 856.0, 29.2575
58.106593427, 96.390, 882.0, 29.6985
58.159114558, 96.390, 851.0, 29.1719
58.211635689, 96.390, 890.0, 29.8329
58.264156819, 96.390, 882.0, 29.6985
58.316677950, 96.390, 844.0, 29.0517
58.369199081, 96.390, 819.0, 28.6182
58.421720211, 96.390, 756.0, 27.4955
58.474241342, 96.390, 825.0, 28.7228
58.526762473, 96.390, 840.0, 28.9828
58.579283603, 96.390, 853.0, 29.2062
58.631804734, 96.390, 855.0, 29.2404
58.684325865, 96.390, 793.0, 28.1603
58.736846996, 96.390, 868.0, 29.4618
58.789368126, 96.390, 870.0, 29.4958
58.841889257, 96.390, 799.0, 28.2666
58.894410388, 96.390, 818.0, 28.6007
58.946931518, 96.390, 821.0, 28.6531
58.999452649, 96.390, 814.0, 28.5307
59.051973780, 96.390, 897.0, 29.9500
59.104494911, 96.390, 845.0, 29.0689
59.157016041, 96.390, 835.0, 28.8964
59.209537172, 96.390, 902.0, 30.0333
59.262058303, 96.390, 880.0, 29.6648
59.314579433, 96.390, 865.0, 29.4109
59.367100564, 96.390, 893.0, 29.8831
59.419621695, 96.390, 870.0, 29.4958
59.472142826, 96.390, 802.0, 28.3196
59.524663956, 96.390, 861.0, 29.3428
59.577185087, 96.390, 852.0, 29.1890
59.629706218, 96.390, 881.0, 29.6816
59.682227348, 96.390, 921.0, 30.3480
59.734748479, 96.390, 849.0, 29.1376
59.787269610, 96.390, 898.0, 29.9666
59.839790740, 96.390, 876.0, 29.5973
59.892311871, 96.390, 841.0, 29.0000
59.944833002, 96.390, 819.0, 28.6182
59.997354133, 96.390, 906.0, 30.0998
60.049875263, 96.390, 842.0, 29.0172
60.102396394, 96.390, 852.0, 29.1890
60.154917525, 96.390, 821.0, 28.6531
60.207438655, 96.390, 874.0, 29.5635
60.259959786, 96.390, 850.0, 29.1548
60.312480917, 96.390, 885.0, 29.7489
60.365002048, 96.390, 841.0, 29.0000
60.417523178, 96.390, 844.0, 29.0517
60.470044309, 96.390, 869.0, 29.4788
60.522565440, 96.390, 846.0, 29.0861
60.575086570, 96.390, 823.0, 28.6880
60.627607701, 96.390, 829.0, 28.7924
60.680128832, 96.390, 848.0, 29.1204
60.732649963, 96.390, 812.0, 28.4956
60.785171093, 96.390, 854.0, 29.2233
60.837692224, 96.390, 832.0, 28.8444
60.890213355, 96.390, 856.0, 29.2575
60.942734485, 96.390, 830.0, 28.8097
60.995255616, 96.390, 853.0, 29.2062
61.047776747, 96.390, 862.0, 29.3598
61.100297878, 96.390, 864.0, 29.3939
61.152819008, 96.390, 846.0, 29.0861
61.205340139, 96.390, 788.0, 28.0713
61.257861270, 96.390, 880.0, 29.6648
61.310382400, 96.390, 816.0, 28.5657
61.362903531, 96.390, 849.0, 29.1376
61.415424662, 96.390, 844.0, 29.0517
61.467945792, 96.390, 931.0, 30.5123
61.520466923, 96.390, 868.0, 29.4618
61.572988054, 96.390, 856.0, 29.2575
61.625509185, 96.390, 835.0, 28.8964
61.678030315, 96.390, 870.0, 29.4958
61.730551446, 96.390, 832.0, 28.8444
61.783072577, 96.390, 860.0, 29.3258
61.835593707, 96.390, 865.0, 29.4109
61.888114838, 96.390, 847.0, 29.1033
61.940635969, 96.390, 860.0, 29.3258
61.993157100, 96.390, 823.0, 28.6880
62.045678230, 96.390, 833.0, 28.8617
62.098199361, 96.390, 853.0, 29.2062
62.150720492, 96.390, 816.0, 28.5657
62.203241622, 96.390, 881.0, 29.6816
62.255762753, 96.390, 837.0, 28.9310
62.308283884, 96.390, 877.0, 29.6142
62.360805015, 96.390, 874.0, 29.5635
62.413326145, 96.390, 895.0, 29.9166
62.465847276, 96.390, 849.0, 29.1376
62.518368407, 96.390, 906.0, 30.0998
62.570889537, 96.390, 875.0, 29.5804
62.623410668, 96.390, 872.0, 29.5296
62.675931799, 96.390, 886.0, 29.7658
62.728452930, 96.390, 860.0, 29.3258
62.780974060, 96.390, 864.0, 29.3939
62.833495191, 96.390, 811.0, 28.4781
62.886016322, 96.390, 805.0, 28.3725
62.938537452, 96.390, 935.0, 30.5778
62.991058583, 96.390, 833.0, 28.8617
63.043579714, 96.390, 854.0, 29.2233
63.096100844, 96.390, 825.0, 28.7228
63.148621975, 96.390, 853.0, 29.2062
63.201143106, 96.390, 891.0, 29.8496
63.253664237, 96.390, 865.0, 29.4109
63.306185367, 96.390, 867.0, 29.4449
63.358706498, 96.390, 865.0, 29.4109
63.411227629, 96.390, 818.0, 28.6007
63.463748759, 96.390, 858.0, 29.2916
63.516269890, 96.390, 804.0, 28.3549
63.568791021, 96.390, 862.0, 29.3598
63.621312152, 96.390, 859.0, 29.3087
63.673833282, 96.390, 821.0, 28.6531
63.726354413, 96.390, 833.0, 28.8617
63.778875544, 96.390, 893.0, 29.8831
63.831396674, 96.390, 794.0, 28.1780
63.883917805, 96.390, 849.0, 29.1376
63.936438936, 96.390, 856.0, 29.2575
63.988960067, 96.390, 801.0, 28.3019
64.041481197, 96.390, 847.0, 29.1033
64.094002328, 96.390, 812.0, 28.4956
64.146523459, 96.390, 875.0, 29.5804
64.199044589, 96.390, 905.0, 30.0832
64.251565720, 96.390, 848.0, 29.1204
64.304086851, 96.390, 878.0, 29.6311
64.356607981, 96.390, 898.0, 29.9666
64.409129112, 96.390, 911.0, 30.1828
64.461650243, 96.390, 884.0, 29.7321
64.514171374, 96.390, 860.0, 29.3258
64.566692504, 96.390, 819.0, 28.6182
64.619213635, 96.390, 836.0, 28.9137
64.671734766, 96.390, 831.0, 28.8271
64.724255896, 96.390, 851.0, 29.1719
64.776777027, 96.390, 872.0, 29.5296
64.829298158, 96.390, 833.0, 28.8617
64.881819289, 96.390, 815.0, 28.5482
64.934340419, 96.390, 806.0, 28.3901
64.986861550, 96.390, 852.0, 29.1890