File: Files_organized_for_plots/PC/XRD_xPO4-Free_07Mar23.csv
[Measurement conditions]
Sample identification,PO4-Free_07Mar23
Comment - 1,"Configuration=Stage for Flat Samples/Holders, Owner=User-1, Creation date=7/1/2020 9:53:24 AM"
Comment - 2,"Goniometer=Theta/Theta; Minimum step size 2Theta:0.0001; Minimum step size Omega:0.0001"
Comment - 3,"Sample stage=Stage for flat samples/holders"
Comment - 4,"Diffractometer system=EMPYREAN"
Comment - 5,"Measurement program=C:\Users\tmr79\OneDrive - The Pennsylvania State University\Documents\NEUP\XRD\Cement\Zerobackground scan.xrdmp, Identifier={98A3B11C-88F9-4AA6-982C-73314A311EF5}"
Anode material,Cu
K-Alpha1 wavelength,1.5405980
K-Alpha2 wavelength,1.5444260
Ratio K-Alpha2/K-Alpha1,0.500
Divergence slit,Fixed,0.25
Monochromator used,NO
Generator voltage, 45
Tube current, 40
File date and time,23/May/2023 09:43
Unit cell,
h k l, 0 0 0
Scan axis,Gonio
Scan range,4.994599997,64.999991833
Scan step size,0.0262606
No. of points, 2285
Scan type,CONTINUOUS
Time per step,96.390
[Scan points]
Angle, TimePerStep, Intensity, ESD
5.007730280, 96.390, 5106.0, 71.4563
5.060251411, 96.390, 4926.0, 70.1855
5.112772541, 96.390, 4855.0, 69.6778
5.165293672, 96.390, 4803.0, 69.3037
5.217814803, 96.390, 4692.0, 68.4982
5.270335934, 96.390, 4509.0, 67.1491
5.322857064, 96.390, 4533.0, 67.3276
5.375378195, 96.390, 4484.0, 66.9627
5.427899326, 96.390, 4349.0, 65.9469
5.480420456, 96.390, 4302.0, 65.5896
5.532941587, 96.390, 4212.0, 64.8999
5.585462718, 96.390, 4134.0, 64.2962
5.637983849, 96.390, 4172.0, 64.5910
5.690504979, 96.390, 4036.0, 63.5295
5.743026110, 96.390, 3938.0, 62.7535
5.795547241, 96.390, 3924.0, 62.6418
5.848068371, 96.390, 3766.0, 61.3677
5.900589502, 96.390, 3905.0, 62.4900
5.953110633, 96.390, 3785.0, 61.5224
6.005631763, 96.390, 3814.0, 61.7576
6.058152894, 96.390, 3694.0, 60.7783
6.110674025, 96.390, 3683.0, 60.6877
6.163195156, 96.390, 3518.0, 59.3127
6.215716286, 96.390, 3633.0, 60.2744
6.268237417, 96.390, 3529.0, 59.4054
6.320758548, 96.390, 3379.0, 58.1292
6.373279678, 96.390, 3509.0, 59.2368
6.425800809, 96.390, 3323.0, 57.6455
6.478321940, 96.390, 3426.0, 58.5320
6.530843071, 96.390, 3322.0, 57.6368
6.583364201, 96.390, 3444.0, 58.6856
6.635885332, 96.390, 3282.0, 57.2887
6.688406463, 96.390, 3246.0, 56.9737
6.740927593, 96.390, 3239.0, 56.9122
6.793448724, 96.390, 3257.0, 57.0701
6.845969855, 96.390, 3099.0, 55.6687
6.898490986, 96.390, 3087.0, 55.5608
6.951012116, 96.390, 2995.0, 54.7266
7.003533247, 96.390, 3116.0, 55.8211
7.056054378, 96.390, 3027.0, 55.0182
7.108575508, 96.390, 3077.0, 55.4707
7.161096639, 96.390, 3093.0, 55.6147
7.213617770, 96.390, 2993.0, 54.7083
7.266138900, 96.390, 3011.0, 54.8726
7.318660031, 96.390, 2864.0, 53.5164
7.371181162, 96.390, 3001.0, 54.7814
7.423702293, 96.390, 2997.0, 54.7449
7.476223423, 96.390, 2929.0, 54.1202
7.528744554, 96.390, 2792.0, 52.8394
7.581265685, 96.390, 2843.0, 53.3198
7.633786815, 96.390, 2806.0, 52.9717
7.686307946, 96.390, 2837.0, 53.2635
7.738829077, 96.390, 2779.0, 52.7162
7.791350208, 96.390, 2760.0, 52.5357
7.843871338, 96.390, 2829.0, 53.1883
7.896392469, 96.390, 2701.0, 51.9711
7.948913600, 96.390, 2844.0, 53.3292
8.001434730, 96.390, 2760.0, 52.5357
8.053955861, 96.390, 2744.0, 52.3832
8.106476992, 96.390, 2746.0, 52.4023
8.158998123, 96.390, 2583.0, 50.8232
8.211519253, 96.390, 2666.0, 51.6333
8.264040384, 96.390, 2808.0, 52.9906
8.316561515, 96.390, 2624.0, 51.2250
8.369082645, 96.390, 2593.0, 50.9215
8.421603776, 96.390, 2616.0, 51.1468
8.474124907, 96.390, 2659.0, 51.5655
8.526646038, 96.390, 2571.0, 50.7050
8.579167168, 96.390, 2618.0, 51.1664
8.631688299, 96.390, 2519.0, 50.1896
8.684209430, 96.390, 2498.0, 49.9800
8.736730560, 96.390, 2532.0, 50.3190
8.789251691, 96.390, 2526.0, 50.2593
8.841772822, 96.390, 2560.0, 50.5964
8.894293952, 96.390, 2566.0, 50.6557
8.946815083, 96.390, 2390.0, 48.8876
8.999336214, 96.390, 2502.0, 50.0200
9.051857345, 96.390, 2512.0, 50.1199
9.104378475, 96.390, 2375.0, 48.7340
9.156899606, 96.390, 2493.0, 49.9300
9.209420737, 96.390, 2455.0, 49.5480
9.261941867, 96.390, 2422.0, 49.2138
9.314462998, 96.390, 2439.0, 49.3862
9.366984129, 96.390, 2464.0, 49.6387
9.419505260, 96.390, 2421.0, 49.2037
9.472026390, 96.390, 2461.0, 49.6085
9.524547521, 96.390, 2330.0, 48.2701
9.577068652, 96.390, 2321.0, 48.1768
9.629589782, 96.390, 2341.0, 48.3839
9.682110913, 96.390, 2282.0, 47.7703
9.734632044, 96.390, 2320.0, 48.1664
9.787153175, 96.390, 2267.0, 47.6130
9.839674305, 96.390, 2293.0, 47.8853
9.892195436, 96.390, 2367.0, 48.6518
9.944716567, 96.390, 2329.0, 48.2597
9.997237697, 96.390, 2255.0, 47.4868
10.049758828, 96.390, 2336.0, 48.3322
10.102279959, 96.390, 2302.0, 47.9792
10.154801090, 96.390, 2248.0, 47.4131
10.207322220, 96.390, 2252.0, 47.4552
10.259843351, 96.390, 2254.0, 47.4763
10.312364482, 96.390, 2293.0, 47.8853
10.364885612, 96.390, 2204.0, 46.9468
10.417406743, 96.390, 2257.0, 47.5079
10.469927874, 96.390, 2214.0, 47.0532
10.522449004, 96.390, 2197.0, 46.8722
10.574970135, 96.390, 2200.0, 46.9042
10.627491266, 96.390, 2218.0, 47.0956
10.680012397, 96.390, 2212.0, 47.0319
10.732533527, 96.390, 2205.0, 46.9574
10.785054658, 96.390, 2159.0, 46.4650
10.837575789, 96.390, 2120.0, 46.0435
10.890096919, 96.390, 2149.0, 46.3573
10.942618050, 96.390, 2159.0, 46.4650
10.995139181, 96.390, 2100.0, 45.8258
11.047660312, 96.390, 2182.0, 46.7119
11.100181442, 96.390, 2103.0, 45.8585
11.152702573, 96.390, 2190.0, 46.7974
11.205223704, 96.390, 2099.0, 45.8148
11.257744834, 96.390, 2046.0, 45.2327
11.310265965, 96.390, 2132.0, 46.1736
11.362787096, 96.390, 2008.0, 44.8107
11.415308227, 96.390, 2026.0, 45.0111
11.467829357, 96.390, 2123.0, 46.0760
11.520350488, 96.390, 2114.0, 45.9783
11.572871619, 96.390, 2032.0, 45.0777
11.625392749, 96.390, 2038.0, 45.1442
11.677913880, 96.390, 2051.0, 45.2880
11.730435011, 96.390, 2006.0, 44.7884
11.782956141, 96.390, 2039.0, 45.1553
11.835477272, 96.390, 1980.0, 44.4972
11.887998403, 96.390, 1946.0, 44.1135
11.940519534, 96.390, 1965.0, 44.3283
11.993040664, 96.390, 2022.0, 44.9667
12.045561795, 96.390, 1931.0, 43.9431
12.098082926, 96.390, 1987.0, 44.5758
12.150604056, 96.390, 1913.0, 43.7379
12.203125187, 96.390, 2045.0, 45.2217
12.255646318, 96.390, 1962.0, 44.2945
12.308167449, 96.390, 1969.0, 44.3734
12.360688579, 96.390, 1930.0, 43.9318
12.413209710, 96.390, 1857.0, 43.0929
12.465730841, 96.390, 1936.0, 44.0000
12.518251971, 96.390, 1897.0, 43.5546
12.570773102, 96.390, 1868.0, 43.2204
12.623294233, 96.390, 1954.0, 44.2041
12.675815364, 96.390, 1954.0, 44.2041
12.728336494, 96.390, 1920.0, 43.8178
12.780857625, 96.390, 1907.0, 43.6692
12.833378756, 96.390, 1872.0, 43.2666
12.885899886, 96.390, 1847.0, 42.9767
12.938421017, 96.390, 1929.0, 43.9204
12.990942148, 96.390, 1828.0, 42.7551
13.043463279, 96.390, 1807.0, 42.5088
13.095984409, 96.390, 1879.0, 43.3474
13.148505540, 96.390, 1826.0, 42.7317
13.201026671, 96.390, 1847.0, 42.9767
13.253547801, 96.390, 1841.0, 42.9069
13.306068932, 96.390, 1778.0, 42.1663
13.358590063, 96.390, 1924.0, 43.8634
13.411111193, 96.390, 1823.0, 42.6966
13.463632324, 96.390, 1902.0, 43.6119
13.516153455, 96.390, 1889.0, 43.4626
13.568674586, 96.390, 1809.0, 42.5323
13.621195716, 96.390, 1852.0, 43.0349
13.673716847, 96.390, 1777.0, 42.1545
13.726237978, 96.390, 1771.0, 42.0833
13.778759108, 96.390, 1769.0, 42.0595
13.831280239, 96.390, 1837.0, 42.8602
13.883801370, 96.390, 1851.0, 43.0232
13.936322501, 96.390, 1900.0, 43.5890
13.988843631, 96.390, 1756.0, 41.9047
14.041364762, 96.390, 1791.0, 42.3202
14.093885893, 96.390, 1766.0, 42.0238
14.146407023, 96.390, 1744.0, 41.7612
14.198928154, 96.390, 1744.0, 41.7612
14.251449285, 96.390, 1742.0, 41.7373
14.303970416, 96.390, 1761.0, 41.9643
14.356491546, 96.390, 1759.0, 41.9404
14.409012677, 96.390, 1714.0, 41.4005
14.461533808, 96.390, 1680.0, 40.9878
14.514054938, 96.390, 1723.0, 41.5090
14.566576069, 96.390, 1810.0, 42.5441
14.619097200, 96.390, 1670.0, 40.8656
14.671618331, 96.390, 1740.0, 41.7133
14.724139461, 96.390, 1796.0, 42.3792
14.776660592, 96.390, 1671.0, 40.8779
14.829181723, 96.390, 1707.0, 41.3159
14.881702853, 96.390, 1792.0, 42.3320
14.934223984, 96.390, 1733.0, 41.6293
14.986745115, 96.390, 1742.0, 41.7373
15.039266245, 96.390, 1619.0, 40.2368
15.091787376, 96.390, 1733.0, 41.6293
15.144308507, 96.390, 1724.0, 41.5211
15.196829638, 96.390, 1700.0, 41.2311
15.249350768, 96.390, 1725.0, 41.5331
15.301871899, 96.390, 1709.0, 41.3401
15.354393030, 96.390, 1672.0, 40.8901
15.406914160, 96.390, 1765.0, 42.0119
15.459435291, 96.390, 1642.0, 40.5216
15.511956422, 96.390, 1666.0, 40.8167
15.564477553, 96.390, 1713.0, 41.3884
15.616998683, 96.390, 1710.0, 41.3521
15.669519814, 96.390, 1709.0, 41.3401
15.722040945, 96.390, 1658.0, 40.7185
15.774562075, 96.390, 1669.0, 40.8534
15.827083206, 96.390, 1700.0, 41.2311
15.879604337, 96.390, 1740.0, 41.7133
15.932125468, 96.390, 1708.0, 41.3280
15.984646598, 96.390, 1662.0, 40.7676
16.037167729, 96.390, 1659.0, 40.7308
16.089688860, 96.390, 1769.0, 42.0595
16.142209990, 96.390, 1747.0, 41.7971
16.194731121, 96.390, 1745.0, 41.7732
16.247252252, 96.390, 1635.0, 40.4351
16.299773382, 96.390, 1756.0, 41.9047
16.352294513, 96.390, 1718.0, 41.4488
16.404815644, 96.390, 1668.0, 40.8412
16.457336775, 96.390, 1745.0, 41.7732
16.509857905, 96.390, 1755.0, 41.8927
16.562379036, 96.390, 1700.0, 41.2311
16.614900167, 96.390, 1655.0, 40.6817
16.667421297, 96.390, 1727.0, 41.5572
16.719942428, 96.390, 1701.0, 41.2432
16.772463559, 96.390, 1719.0, 41.4608
16.824984690, 96.390, 1644.0, 40.5463
16.877505820, 96.390, 1747.0, 41.7971
16.930026951, 96.390, 1730.0, 41.5933
16.982548082, 96.390, 1738.0, 41.6893
17.035069212, 96.390, 1768.0, 42.0476
17.087590343, 96.390, 1746.0, 41.7852
17.140111474, 96.390, 1688.0, 41.0853
17.192632605, 96.390, 1643.0, 40.5339
17.245153735, 96.390, 1791.0, 42.3202
17.297674866, 96.390, 1806.0, 42.4971
17.350195997, 96.390, 1711.0, 41.3642
17.402717127, 96.390, 1741.0, 41.7253
17.455238258, 96.390, 1788.0, 42.2847
17.507759389, 96.390, 1741.0, 41.7253
17.560280520, 96.390, 1810.0, 42.5441
17.612801650, 96.390, 1750.0, 41.8330
17.665322781, 96.390, 1727.0, 41.5572
17.717843912, 96.390, 1719.0, 41.4608
17.770365042, 96.390, 1757.0, 41.9166
17.822886173, 96.390, 1803.0, 42.4617
17.875407304, 96.390, 1779.0, 42.1782
17.927928434, 96.390, 1763.0, 41.9881
17.980449565, 96.390, 1854.0, 43.0581
18.032970696, 96.390, 1784.0, 42.2374
18.085491827, 96.390, 1891.0, 43.4856
18.138012957, 96.390, 1797.0, 42.3910
18.190534088, 96.390, 1817.0, 42.6263
18.243055219, 96.390, 1777.0, 42.1545
18.295576349, 96.390, 1800.0, 42.4264
18.348097480, 96.390, 1816.0, 42.6146
18.400618611, 96.390, 1903.0, 43.6234
18.453139742, 96.390, 1837.0, 42.8602
18.505660872, 96.390, 1782.0, 42.2137
18.558182003, 96.390, 1793.0, 42.3438
18.610703134, 96.390, 1834.0, 42.8252
18.663224264, 96.390, 1881.0, 43.3705
18.715745395, 96.390, 1818.0, 42.6380
18.768266526, 96.390, 1899.0, 43.5775
18.820787657, 96.390, 1998.0, 44.6990
18.873308787, 96.390, 1877.0, 43.3244
18.925829918, 96.390, 1993.0, 44.6430
18.978351049, 96.390, 1933.0, 43.9659
19.030872179, 96.390, 1942.0, 44.0681
19.083393310, 96.390, 1929.0, 43.9204
19.135914441, 96.390, 2006.0, 44.7884
19.188435572, 96.390, 1963.0, 44.3058
19.240956702, 96.390, 1991.0, 44.6206
19.293477833, 96.390, 1913.0, 43.7379
19.345998964, 96.390, 2022.0, 44.9667
19.398520094, 96.390, 2007.0, 44.7996
19.451041225, 96.390, 1972.0, 44.4072
19.503562356, 96.390, 2144.0, 46.3033
19.556083486, 96.390, 1936.0, 44.0000
19.608604617, 96.390, 2093.0, 45.7493
19.661125748, 96.390, 2079.0, 45.5961
19.713646879, 96.390, 2107.0, 45.9021
19.766168009, 96.390, 2163.0, 46.5081
19.818689140, 96.390, 2110.0, 45.9347
19.871210271, 96.390, 2121.0, 46.0543
19.923731401, 96.390, 2141.0, 46.2709
19.976252532, 96.390, 2128.0, 46.1303
20.028773663, 96.390, 2099.0, 45.8148
20.081294794, 96.390, 2244.0, 47.3709
20.133815924, 96.390, 2141.0, 46.2709
20.186337055, 96.390, 2163.0, 46.5081
20.238858186, 96.390, 2148.0, 46.3465
20.291379316, 96.390, 2142.0, 46.2817
20.343900447, 96.390, 2197.0, 46.8722
20.396421578, 96.390, 2182.0, 46.7119
20.448942709, 96.390, 2149.0, 46.3573
20.501463839, 96.390, 2250.0, 47.4342
20.553984970, 96.390, 2161.0, 46.4866
20.606506101, 96.390, 2290.0, 47.8539
20.659027231, 96.390, 2203.0, 46.9361
20.711548362, 96.390, 2181.0, 46.7012
20.764069493, 96.390, 2162.0, 46.4973
20.816590623, 96.390, 2217.0, 47.0850
20.869111754, 96.390, 2272.0, 47.6655
20.921632885, 96.390, 2285.0, 47.8017
20.974154016, 96.390, 2279.0, 47.7389
21.026675146, 96.390, 2278.0, 47.7284
21.079196277, 96.390, 2350.0, 48.4768
21.131717408, 96.390, 2284.0, 47.7912
21.184238538, 96.390, 2307.0, 48.0312
21.236759669, 96.390, 2412.0, 49.1121
21.289280800, 96.390, 2367.0, 48.6518
21.341801931, 96.390, 2392.0, 48.9081
21.394323061, 96.390, 2290.0, 47.8539
21.446844192, 96.390, 2408.0, 49.0714
21.499365323, 96.390, 2434.0, 49.3356
21.551886453, 96.390, 2322.0, 48.1871
21.604407584, 96.390, 2287.0, 47.8226
21.656928715, 96.390, 2397.0, 48.9592
21.709449846, 96.390, 2467.0, 49.6689
21.761970976, 96.390, 2500.0, 50.0000
21.814492107, 96.390, 2446.0, 49.4571
21.867013238, 96.390, 2453.0, 49.5278
21.919534368, 96.390, 2428.0, 49.2747
21.972055499, 96.390, 2353.0, 48.5077
22.024576630, 96.390, 2387.0, 48.8569
22.077097761, 96.390, 2348.0, 48.4562
22.129618891, 96.390, 2384.0, 48.8262
22.182140022, 96.390, 2312.0, 48.0833
22.234661153, 96.390, 2502.0, 50.0200
22.287182283, 96.390, 2381.0, 48.7955
22.339703414, 96.390, 2322.0, 48.1871
22.392224545, 96.390, 2347.0, 48.4458
22.444745675, 96.390, 2393.0, 48.9183
22.497266806, 96.390, 2351.0, 48.4871
22.549787937, 96.390, 2280.0, 47.7493
22.602309068, 96.390, 2284.0, 47.7912
22.654830198, 96.390, 2387.0, 48.8569
22.707351329, 96.390, 2343.0, 48.4045
22.759872460, 96.390, 2278.0, 47.7284
22.812393590, 96.390, 2301.0, 47.9687
22.864914721, 96.390, 2375.0, 48.7340
22.917435852, 96.390, 2314.0, 48.1041
22.969956983, 96.390, 2354.0, 48.5180
23.022478113, 96.390, 2377.0, 48.7545
23.074999244, 96.390, 2283.0, 47.7807
23.127520375, 96.390, 2332.0, 48.2908
23.180041505, 96.390, 2287.0, 47.8226
23.232562636, 96.390, 2316.0, 48.1248
23.285083767, 96.390, 2389.0, 48.8774
23.337604898, 96.390, 2221.0, 47.1275
23.390126028, 96.390, 2302.0, 47.9792
23.442647159, 96.390, 2241.0, 47.3392
23.495168290, 96.390, 2278.0, 47.7284
23.547689420, 96.390, 2338.0, 48.3529
23.600210551, 96.390, 2296.0, 47.9166
23.652731682, 96.390, 2203.0, 46.9361
23.705252813, 96.390, 2270.0, 47.6445
23.757773943, 96.390, 2291.0, 47.8644
23.810295074, 96.390, 2205.0, 46.9574
23.862816205, 96.390, 2231.0, 47.2335
23.915337335, 96.390, 2156.0, 46.4327
23.967858466, 96.390, 2227.0, 47.1911
24.020379597, 96.390, 2242.0, 47.3498
24.072900727, 96.390, 2211.0, 47.0213
24.125421858, 96.390, 2248.0, 47.4131
24.177942989, 96.390, 2273.0, 47.6760
24.230464120, 96.390, 2269.0, 47.6340
24.282985250, 96.390, 2260.0, 47.5395
24.335506381, 96.390, 2150.0, 46.3681
24.388027512, 96.390, 2126.0, 46.1086
24.440548642, 96.390, 2186.0, 46.7547
24.493069773, 96.390, 2158.0, 46.4543
24.545590904, 96.390, 2127.0, 46.1194
24.598112035, 96.390, 2088.0, 45.6946
24.650633165, 96.390, 2109.0, 45.9239
24.703154296, 96.390, 2064.0, 45.4313
24.755675427, 96.390, 2207.0, 46.9787
24.808196557, 96.390, 2052.0, 45.2990
24.860717688, 96.390, 2129.0, 46.1411
24.913238819, 96.390, 2102.0, 45.8476
24.965759950, 96.390, 2005.0, 44.7772
25.018281080, 96.390, 2123.0, 46.0760
25.070802211, 96.390, 2071.0, 45.5082
25.123323342, 96.390, 2041.0, 45.1774
25.175844472, 96.390, 2040.0, 45.1664
25.228365603, 96.390, 2029.0, 45.0444
25.280886734, 96.390, 1995.0, 44.6654
25.333407864, 96.390, 1982.0, 44.5197
25.385928995, 96.390, 2005.0, 44.7772
25.438450126, 96.390, 2009.0, 44.8219
25.490971257, 96.390, 2016.0, 44.8999
25.543492387, 96.390, 2014.0, 44.8776
25.596013518, 96.390, 1992.0, 44.6318
25.648534649, 96.390, 2017.0, 44.9110
25.701055779, 96.390, 2005.0, 44.7772
25.753576910, 96.390, 2038.0, 45.1442
25.806098041, 96.390, 2018.0, 44.9222
25.858619172, 96.390, 1998.0, 44.6990
25.911140302, 96.390, 1915.0, 43.7607
25.963661433, 96.390, 1976.0, 44.4522
26.016182564, 96.390, 1926.0, 43.8862
26.068703694, 96.390, 1983.0, 44.5309
26.121224825, 96.390, 1926.0, 43.8862
26.173745956, 96.390, 1886.0, 43.4281
26.226267087, 96.390, 1893.0, 43.5086
26.278788217, 96.390, 1977.0, 44.4635
26.331309348, 96.390, 1921.0, 43.8292
26.383830479, 96.390, 1920.0, 43.8178
26.436351609, 96.390, 1933.0, 43.9659
26.488872740, 96.390, 1887.0, 43.4396
26.541393871, 96.390, 1864.0, 43.1741
26.593915002, 96.390, 1894.0, 43.5201
26.646436132, 96.390, 1865.0, 43.1856
26.698957263, 96.390, 1908.0, 43.6807
26.751478394, 96.390, 1894.0, 43.5201
26.803999524, 96.390, 1821.0, 42.6732
26.856520655, 96.390, 1906.0, 43.6578
26.909041786, 96.390, 1919.0, 43.8064
26.961562916, 96.390, 1872.0, 43.2666
27.014084047, 96.390, 1925.0, 43.8748
27.066605178, 96.390, 1730.0, 41.5933
27.119126309, 96.390, 1830.0, 42.7785
27.171647439, 96.390, 1779.0, 42.1782
27.224168570, 96.390, 1818.0, 42.6380
27.276689701, 96.390, 1741.0, 41.7253
27.329210831, 96.390, 1840.0, 42.8952
27.381731962, 96.390, 1814.0, 42.5911
27.434253093, 96.390, 1809.0, 42.5323
27.486774224, 96.390, 1797.0, 42.3910
27.539295354, 96.390, 1811.0, 42.5558
27.591816485, 96.390, 1748.0, 41.8091
27.644337616, 96.390, 1858.0, 43.1045
27.696858746, 96.390, 1776.0, 42.1426
27.749379877, 96.390, 1811.0, 42.5558
27.801901008, 96.390, 1879.0, 43.3474
27.854422139, 96.390, 1808.0, 42.5206
27.906943269, 96.390, 1775.0, 42.1307
27.959464400, 96.390, 1708.0, 41.3280
28.011985531, 96.390, 1739.0, 41.7013
28.064506661, 96.390, 1682.0, 41.0122
28.117027792, 96.390, 1752.0, 41.8569
28.169548923, 96.390, 1708.0, 41.3280
28.222070054, 96.390, 1662.0, 40.7676
28.274591184, 96.390, 1795.0, 42.3674
28.327112315, 96.390, 1738.0, 41.6893
28.379633446, 96.390, 1782.0, 42.2137
28.432154576, 96.390, 1734.0, 41.6413
28.484675707, 96.390, 1764.0, 42.0000
28.537196838, 96.390, 1685.0, 41.0488
28.589717968, 96.390, 1758.0, 41.9285
28.642239099, 96.390, 1789.0, 42.2966
28.694760230, 96.390, 1679.0, 40.9756
28.747281361, 96.390, 1709.0, 41.3401
28.799802491, 96.390, 1726.0, 41.5452
28.852323622, 96.390, 1637.0, 40.4599
28.904844753, 96.390, 1721.0, 41.4849
28.957365883, 96.390, 1686.0, 41.0609
29.009887014, 96.390, 1693.0, 41.1461
29.062408145, 96.390, 1661.0, 40.7554
29.114929276, 96.390, 1704.0, 41.2795
29.167450406, 96.390, 1643.0, 40.5339
29.219971537, 96.390, 1722.0, 41.4970
29.272492668, 96.390, 1677.0, 40.9512
29.325013798, 96.390, 1649.0, 40.6079
29.377534929, 96.390, 1696.0, 41.1825
29.430056060, 96.390, 1634.0, 40.4228
29.482577191, 96.390, 1654.0, 40.6694
29.535098321, 96.390, 1619.0, 40.2368
29.587619452, 96.390, 1603.0, 40.0375
29.640140583, 96.390, 1627.0, 40.3361
29.692661713, 96.390, 1642.0, 40.5216
29.745182844, 96.390, 1610.0, 40.1248
29.797703975, 96.390, 1614.0, 40.1746
29.850225105, 96.390, 1628.0, 40.3485
29.902746236, 96.390, 1586.0, 39.8246
29.955267367, 96.390, 1561.0, 39.5095
30.007788498, 96.390, 1593.0, 39.9124
30.060309628, 96.390, 1596.0, 39.9500
30.112830759, 96.390, 1560.0, 39.4968
30.165351890, 96.390, 1656.0, 40.6940
30.217873020, 96.390, 1626.0, 40.3237
30.270394151, 96.390, 1623.0, 40.2865
30.322915282, 96.390, 1597.0, 39.9625
30.375436413, 96.390, 1636.0, 40.4475
30.427957543, 96.390, 1582.0, 39.7744
30.480478674, 96.390, 1612.0, 40.1497
30.532999805, 96.390, 1589.0, 39.8623
30.585520935, 96.390, 1555.0, 39.4335
30.638042066, 96.390, 1580.0, 39.7492
30.690563197, 96.390, 1545.0, 39.3065
30.743084328, 96.390, 1528.0, 39.0896
30.795605458, 96.390, 1540.0, 39.2428
30.848126589, 96.390, 1597.0, 39.9625
30.900647720, 96.390, 1596.0, 39.9500
30.953168850, 96.390, 1501.0, 38.7427
31.005689981, 96.390, 1555.0, 39.4335
31.058211112, 96.390, 1537.0, 39.2046
31.110732243, 96.390, 1522.0, 39.0128
31.163253373, 96.390, 1507.0, 38.8201
31.215774504, 96.390, 1495.0, 38.6652
31.268295635, 96.390, 1518.0, 38.9615
31.320816765, 96.390, 1505.0, 38.7943
31.373337896, 96.390, 1531.0, 39.1280
31.425859027, 96.390, 1524.0, 39.0384
31.478380157, 96.390, 1547.0, 39.3319
31.530901288, 96.390, 1570.0, 39.6232
31.583422419, 96.390, 1572.0, 39.6485
31.635943550, 96.390, 1476.0, 38.4187
31.688464680, 96.390, 1546.0, 39.3192
31.740985811, 96.390, 1601.0, 40.0125
31.793506942, 96.390, 1432.0, 37.8418
31.846028072, 96.390, 1482.0, 38.4968
31.898549203, 96.390, 1534.0, 39.1663
31.951070334, 96.390, 1492.0, 38.6264
32.003591465, 96.390, 1536.0, 39.1918
32.056112595, 96.390, 1524.0, 39.0384
32.108633726, 96.390, 1498.0, 38.7040
32.161154857, 96.390, 1440.0, 37.9473
32.213675987, 96.390, 1497.0, 38.6911
32.266197118, 96.390, 1485.0, 38.5357
32.318718249, 96.390, 1388.0, 37.2559
32.371239380, 96.390, 1475.0, 38.4057
32.423760510, 96.390, 1479.0, 38.4578
32.476281641, 96.390, 1478.0, 38.4448
32.528802772, 96.390, 1442.0, 37.9737
32.581323902, 96.390, 1446.0, 38.0263
32.633845033, 96.390, 1413.0, 37.5899
32.686366164, 96.390, 1479.0, 38.4578
32.738887295, 96.390, 1426.0, 37.7624
32.791408425, 96.390, 1453.0, 38.1182
32.843929556, 96.390, 1464.0, 38.2623
32.896450687, 96.390, 1457.0, 38.1707
32.948971817, 96.390, 1446.0, 38.0263
33.001492948, 96.390, 1425.0, 37.7492
33.054014079, 96.390, 1476.0, 38.4187
33.106535209, 96.390, 1409.0, 37.5366
33.159056340, 96.390, 1396.0, 37.3631
33.211577471, 96.390, 1434.0, 37.8682
33.264098602, 96.390, 1429.0, 37.8021
33.316619732, 96.390, 1385.0, 37.2156
33.369140863, 96.390, 1449.0, 38.0657
33.421661994, 96.390, 1418.0, 37.6563
33.474183124, 96.390, 1389.0, 37.2693
33.526704255, 96.390, 1345.0, 36.6742
33.579225386, 96.390, 1424.0, 37.7359
33.631746517, 96.390, 1416.0, 37.6298
33.684267647, 96.390, 1394.0, 37.3363
33.736788778, 96.390, 1391.0, 37.2961
33.789309909, 96.390, 1356.0, 36.8239
33.841831039, 96.390, 1440.0, 37.9473
33.894352170, 96.390, 1374.0, 37.0675
33.946873301, 96.390, 1413.0, 37.5899
33.999394432, 96.390, 1396.0, 37.3631
34.051915562, 96.390, 1356.0, 36.8239
34.104436693, 96.390, 1466.0, 38.2884
34.156957824, 96.390, 1324.0, 36.3868
34.209478954, 96.390, 1417.0, 37.6431
34.262000085, 96.390, 1358.0, 36.8511
34.314521216, 96.390, 1322.0, 36.3593
34.367042346, 96.390, 1381.0, 37.1618
34.419563477, 96.390, 1378.0, 37.1214
34.472084608, 96.390, 1434.0, 37.8682
34.524605739, 96.390, 1292.0, 35.9444
34.577126869, 96.390, 1362.0, 36.9053
34.629648000, 96.390, 1339.0, 36.5923
34.682169131, 96.390, 1329.0, 36.4555
34.734690261, 96.390, 1336.0, 36.5513
34.787211392, 96.390, 1298.0, 36.0278
34.839732523, 96.390, 1282.0, 35.8050
34.892253654, 96.390, 1412.0, 37.5766
34.944774784, 96.390, 1362.0, 36.9053
34.997295915, 96.390, 1349.0, 36.7287
35.049817046, 96.390, 1286.0, 35.8608
35.102338176, 96.390, 1360.0, 36.8782
35.154859307, 96.390, 1267.0, 35.5949
35.207380438, 96.390, 1249.0, 35.3412
35.259901569, 96.390, 1363.0, 36.9188
35.312422699, 96.390, 1302.0, 36.0832
35.364943830, 96.390, 1348.0, 36.7151
35.417464961, 96.390, 1319.0, 36.3180
35.469986091, 96.390, 1259.0, 35.4824
35.522507222, 96.390, 1346.0, 36.6879
35.575028353, 96.390, 1325.0, 36.4005
35.627549484, 96.390, 1356.0, 36.8239
35.680070614, 96.390, 1319.0, 36.3180
35.732591745, 96.390, 1314.0, 36.2491
35.785112876, 96.390, 1300.0, 36.0555
35.837634006, 96.390, 1321.0, 36.3456
35.890155137, 96.390, 1276.0, 35.7211
35.942676268, 96.390, 1294.0, 35.9722
35.995197398, 96.390, 1280.0, 35.7771
36.047718529, 96.390, 1301.0, 36.0694
36.100239660, 96.390, 1300.0, 36.0555
36.152760791, 96.390, 1322.0, 36.3593
36.205281921, 96.390, 1335.0, 36.5377
36.257803052, 96.390, 1333.0, 36.5103
36.310324183, 96.390, 1266.0, 35.5809
36.362845313, 96.390, 1302.0, 36.0832
36.415366444, 96.390, 1284.0, 35.8329
36.467887575, 96.390, 1284.0, 35.8329
36.520408706, 96.390, 1308.0, 36.1663
36.572929836, 96.390, 1289.0, 35.9026
36.625450967, 96.390, 1341.0, 36.6197
36.677972098, 96.390, 1346.0, 36.6879
36.730493228, 96.390, 1304.0, 36.1109
36.783014359, 96.390, 1369.0, 37.0000
36.835535490, 96.390, 1339.0, 36.5923
36.888056621, 96.390, 1361.0, 36.8917
36.940577751, 96.390, 1320.0, 36.3318
36.993098882, 96.390, 1340.0, 36.6060
37.045620013, 96.390, 1333.0, 36.5103
37.098141143, 96.390, 1285.0, 35.8469
37.150662274, 96.390, 1328.0, 36.4417
37.203183405, 96.390, 1272.0, 35.6651
37.255704535, 96.390, 1255.0, 35.4260
37.308225666, 96.390, 1246.0, 35.2987
37.360746797, 96.390, 1236.0, 35.1568
37.413267928, 96.390, 1204.0, 34.6987
37.465789058, 96.390, 1215.0, 34.8569
37.518310189, 96.390, 1241.0, 35.2278
37.570831320, 96.390, 1205.0, 34.7131
37.623352450, 96.390, 1221.0, 34.9428
37.675873581, 96.390, 1247.0, 35.3129
37.728394712, 96.390, 1216.0, 34.8712
37.780915843, 96.390, 1222.0, 34.9571
37.833436973, 96.390, 1203.0, 34.6843
37.885958104, 96.390, 1241.0, 35.2278
37.938479235, 96.390, 1191.0, 34.5109
37.991000365, 96.390, 1197.0, 34.5977
38.043521496, 96.390, 1188.0, 34.4674
38.096042627, 96.390, 1226.0, 35.0143
38.148563758, 96.390, 1157.0, 34.0147
38.201084888, 96.390, 1217.0, 34.8855
38.253606019, 96.390, 1205.0, 34.7131
38.306127150, 96.390, 1183.0, 34.3948
38.358648280, 96.390, 1171.0, 34.2199
38.411169411, 96.390, 1180.0, 34.3511
38.463690542, 96.390, 1092.0, 33.0454
38.516211673, 96.390, 1145.0, 33.8378
38.568732803, 96.390, 1155.0, 33.9853
38.621253934, 96.390, 1191.0, 34.5109
38.673775065, 96.390, 1151.0, 33.9264
38.726296195, 96.390, 1137.0, 33.7194
38.778817326, 96.390, 1065.0, 32.6343
38.831338457, 96.390, 1144.0, 33.8231
38.883859587, 96.390, 1107.0, 33.2716
38.936380718, 96.390, 1109.0, 33.3017
38.988901849, 96.390, 1185.0, 34.4238
39.041422980, 96.390, 1193.0, 34.5398
39.093944110, 96.390, 1098.0, 33.1361
39.146465241, 96.390, 1160.0, 34.0588
39.198986372, 96.390, 1156.0, 34.0000
39.251507502, 96.390, 1128.0, 33.5857
39.304028633, 96.390, 1154.0, 33.9706
39.356549764, 96.390, 1176.0, 34.2929
39.409070895, 96.390, 1156.0, 34.0000
39.461592025, 96.390, 1123.0, 33.5112
39.514113156, 96.390, 1142.0, 33.7935
39.566634287, 96.390, 1121.0, 33.4813
39.619155417, 96.390, 1057.0, 32.5115
39.671676548, 96.390, 1193.0, 34.5398
39.724197679, 96.390, 1063.0, 32.6037
39.776718810, 96.390, 1104.0, 33.2265
39.829239940, 96.390, 1090.0, 33.0151
39.881761071, 96.390, 1103.0, 33.2114
39.934282202, 96.390, 1109.0, 33.3017
39.986803332, 96.390, 1124.0, 33.5261
40.039324463, 96.390, 1104.0, 33.2265
40.091845594, 96.390, 1102.0, 33.1964
40.144366725, 96.390, 1131.0, 33.6303
40.196887855, 96.390, 1110.0, 33.3167
40.249408986, 96.390, 1105.0, 33.2415
40.301930117, 96.390, 1147.0, 33.8674
40.354451247, 96.390, 1143.0, 33.8083
40.406972378, 96.390, 1122.0, 33.4963
40.459493509, 96.390, 1064.0, 32.6190
40.512014639, 96.390, 1034.0, 32.1559
40.564535770, 96.390, 1136.0, 33.7046
40.617056901, 96.390, 1056.0, 32.4962
40.669578032, 96.390, 1101.0, 33.1813
40.722099162, 96.390, 1090.0, 33.0151
40.774620293, 96.390, 1099.0, 33.1512
40.827141424, 96.390, 1115.0, 33.3916
40.879662554, 96.390, 1097.0, 33.1210
40.932183685, 96.390, 1116.0, 33.4066
40.984704816, 96.390, 1064.0, 32.6190
41.037225947, 96.390, 1094.0, 33.0757
41.089747077, 96.390, 1059.0, 32.5423
41.142268208, 96.390, 1131.0, 33.6303
41.194789339, 96.390, 1075.0, 32.7872
41.247310469, 96.390, 1110.0, 33.3167
41.299831600, 96.390, 1100.0, 33.1662
41.352352731, 96.390, 1060.0, 32.5576
41.404873862, 96.390, 1102.0, 33.1964
41.457394992, 96.390, 1118.0, 33.4365
41.509916123, 96.390, 1058.0, 32.5269
41.562437254, 96.390, 1113.0, 33.3617
41.614958384, 96.390, 1094.0, 33.0757
41.667479515, 96.390, 1145.0, 33.8378
41.720000646, 96.390, 1077.0, 32.8177
41.772521776, 96.390, 1205.0, 34.7131
41.825042907, 96.390, 1090.0, 33.0151
41.877564038, 96.390, 1141.0, 33.7787
41.930085169, 96.390, 1118.0, 33.4365
41.982606299, 96.390, 1126.0, 33.5559
42.035127430, 96.390, 1147.0, 33.8674
42.087648561, 96.390, 1189.0, 34.4819
42.140169691, 96.390, 1200.0, 34.6410
42.192690822, 96.390, 1155.0, 33.9853
42.245211953, 96.390, 1194.0, 34.5543
42.297733084, 96.390, 1267.0, 35.5949
42.350254214, 96.390, 1185.0, 34.4238
42.402775345, 96.390, 1226.0, 35.0143
42.455296476, 96.390, 1327.0, 36.4280
42.507817606, 96.390, 1314.0, 36.2491
42.560338737, 96.390, 1339.0, 36.5923
42.612859868, 96.390, 1415.0, 37.6165
42.665380999, 96.390, 1417.0, 37.6431
42.717902129, 96.390, 1473.0, 38.3797
42.770423260, 96.390, 1588.0, 39.8497
42.822944391, 96.390, 1597.0, 39.9625
42.875465521, 96.390, 1727.0, 41.5572
42.927986652, 96.390, 1603.0, 40.0375
42.980507783, 96.390, 1695.0, 41.1704
43.033028914, 96.390, 1633.0, 40.4104
43.085550044, 96.390, 1620.0, 40.2492
43.138071175, 96.390, 1529.0, 39.1024
43.190592306, 96.390, 1477.0, 38.4318
43.243113436, 96.390, 1396.0, 37.3631
43.295634567, 96.390, 1434.0, 37.8682
43.348155698, 96.390, 1293.0, 35.9583
43.400676828, 96.390, 1324.0, 36.3868
43.453197959, 96.390, 1254.0, 35.4119
43.505719090, 96.390, 1298.0, 36.0278
43.558240221, 96.390, 1212.0, 34.8138
43.610761351, 96.390, 1194.0, 34.5543
43.663282482, 96.390, 1139.0, 33.7491
43.715803613, 96.390, 1154.0, 33.9706
43.768324743, 96.390, 1169.0, 34.1906
43.820845874, 96.390, 1133.0, 33.6601
43.873367005, 96.390, 1123.0, 33.5112
43.925888136, 96.390, 1076.0, 32.8024
43.978409266, 96.390, 1018.0, 31.9061
44.030930397, 96.390, 999.0, 31.6070
44.083451528, 96.390, 1078.0, 32.8329
44.135972658, 96.390, 1034.0, 32.1559
44.188493789, 96.390, 1014.0, 31.8434
44.241014920, 96.390, 1021.0, 31.9531
44.293536051, 96.390, 1044.0, 32.3110
44.346057181, 96.390, 1065.0, 32.6343
44.398578312, 96.390, 1002.0, 31.6544
44.451099443, 96.390, 1051.0, 32.4191
44.503620573, 96.390, 963.0, 31.0322
44.556141704, 96.390, 983.0, 31.3528
44.608662835, 96.390, 972.0, 31.1769
44.661183966, 96.390, 992.0, 31.4960
44.713705096, 96.390, 999.0, 31.6070
44.766226227, 96.390, 954.0, 30.8869
44.818747358, 96.390, 1014.0, 31.8434
44.871268488, 96.390, 930.0, 30.4959
44.923789619, 96.390, 950.0, 30.8221
44.976310750, 96.390, 956.0, 30.9192
45.028831880, 96.390, 1008.0, 31.7490
45.081353011, 96.390, 962.0, 31.0161
45.133874142, 96.390, 988.0, 31.4325
45.186395273, 96.390, 940.0, 30.6594
45.238916403, 96.390, 979.0, 31.2890
45.291437534, 96.390, 960.0, 30.9839
45.343958665, 96.390, 1002.0, 31.6544
45.396479795, 96.390, 874.0, 29.5635
45.449000926, 96.390, 929.0, 30.4795
45.501522057, 96.390, 916.0, 30.2655
45.554043188, 96.390, 882.0, 29.6985
45.606564318, 96.390, 907.0, 30.1164
45.659085449, 96.390, 909.0, 30.1496
45.711606580, 96.390, 894.0, 29.8998
45.764127710, 96.390, 877.0, 29.6142
45.816648841, 96.390, 951.0, 30.8383
45.869169972, 96.390, 835.0, 28.8964
45.921691103, 96.390, 840.0, 28.9828
45.974212233, 96.390, 827.0, 28.7576
46.026733364, 96.390, 870.0, 29.4958
46.079254495, 96.390, 861.0, 29.3428
46.131775625, 96.390, 922.0, 30.3645
46.184296756, 96.390, 863.0, 29.3769
46.236817887, 96.390, 867.0, 29.4449
46.289339017, 96.390, 879.0, 29.6479
46.341860148, 96.390, 836.0, 28.9137
46.394381279, 96.390, 855.0, 29.2404
46.446902410, 96.390, 816.0, 28.5657
46.499423540, 96.390, 822.0, 28.6705
46.551944671, 96.390, 836.0, 28.9137
46.604465802, 96.390, 881.0, 29.6816
46.656986932, 96.390, 825.0, 28.7228
46.709508063, 96.390, 829.0, 28.7924
46.762029194, 96.390, 816.0, 28.5657
46.814550325, 96.390, 880.0, 29.6648
46.867071455, 96.390, 798.0, 28.2489
46.919592586, 96.390, 843.0, 29.0345
46.972113717, 96.390, 881.0, 29.6816
47.024634847, 96.390, 791.0, 28.1247
47.077155978, 96.390, 868.0, 29.4618
47.129677109, 96.390, 806.0, 28.3901
47.182198240, 96.390, 788.0, 28.0713
47.234719370, 96.390, 839.0, 28.9655
47.287240501, 96.390, 814.0, 28.5307
47.339761632, 96.390, 791.0, 28.1247
47.392282762, 96.390, 839.0, 28.9655
47.444803893, 96.390, 825.0, 28.7228
47.497325024, 96.390, 811.0, 28.4781
47.549846155, 96.390, 851.0, 29.1719
47.602367285, 96.390, 845.0, 29.0689
47.654888416, 96.390, 824.0, 28.7054
47.707409547, 96.390, 791.0, 28.1247
47.759930677, 96.390, 806.0, 28.3901
47.812451808, 96.390, 765.0, 27.6586
47.864972939, 96.390, 748.0, 27.3496
47.917494069, 96.390, 798.0, 28.2489
47.970015200, 96.390, 791.0, 28.1247
48.022536331, 96.390, 796.0, 28.2135
48.075057462, 96.390, 733.0, 27.0740
48.127578592, 96.390, 788.0, 28.0713
48.180099723, 96.390, 789.0, 28.0891
48.232620854, 96.390, 781.0, 27.9464
48.285141984, 96.390, 749.0, 27.3679
48.337663115, 96.390, 770.0, 27.7489
48.390184246, 96.390, 756.0, 27.4955
48.442705377, 96.390, 803.0, 28.3373
48.495226507, 96.390, 784.0, 28.0000
48.547747638, 96.390, 735.0, 27.1109
48.600268769, 96.390, 826.0, 28.7402
48.652789899, 96.390, 774.0, 27.8209
48.705311030, 96.390, 711.0, 26.6646
48.757832161, 96.390, 823.0, 28.6880
48.810353292, 96.390, 753.0, 27.4408
48.862874422, 96.390, 762.0, 27.6043
48.915395553, 96.390, 737.0, 27.1477
48.967916684, 96.390, 725.0, 26.9258
49.020437814, 96.390, 761.0, 27.5862
49.072958945, 96.390, 770.0, 27.7489
49.125480076, 96.390, 746.0, 27.3130
49.178001207, 96.390, 778.0, 27.8927
49.230522337, 96.390, 756.0, 27.4955
49.283043468, 96.390, 772.0, 27.7849
49.335564599, 96.390, 760.0, 27.5681
49.388085729, 96.390, 745.0, 27.2947
49.440606860, 96.390, 722.0, 26.8701
49.493127991, 96.390, 752.0, 27.4226
49.545649121, 96.390, 743.0, 27.2580
49.598170252, 96.390, 733.0, 27.0740
49.650691383, 96.390, 732.0, 27.0555
49.703212514, 96.390, 750.0, 27.3861
49.755733644, 96.390, 758.0, 27.5318
49.808254775, 96.390, 740.0, 27.2029
49.860775906, 96.390, 746.0, 27.3130
49.913297036, 96.390, 727.0, 26.9629
49.965818167, 96.390, 776.0, 27.8568
50.018339298, 96.390, 756.0, 27.4955
50.070860429, 96.390, 727.0, 26.9629
50.123381559, 96.390, 691.0, 26.2869
50.175902690, 96.390, 678.0, 26.0384
50.228423821, 96.390, 731.0, 27.0370
50.280944951, 96.390, 765.0, 27.6586
50.333466082, 96.390, 733.0, 27.0740
50.385987213, 96.390, 782.0, 27.9643
50.438508344, 96.390, 670.0, 25.8844
50.491029474, 96.390, 704.0, 26.5330
50.543550605, 96.390, 764.0, 27.6405
50.596071736, 96.390, 666.0, 25.8070
50.648592866, 96.390, 762.0, 27.6043
50.701113997, 96.390, 725.0, 26.9258
50.753635128, 96.390, 718.0, 26.7955
50.806156258, 96.390, 708.0, 26.6083
50.858677389, 96.390, 692.0, 26.3059
50.911198520, 96.390, 706.0, 26.5707
50.963719651, 96.390, 678.0, 26.0384
51.016240781, 96.390, 704.0, 26.5330
51.068761912, 96.390, 710.0, 26.6458
51.121283043, 96.390, 693.0, 26.3249
51.173804173, 96.390, 729.0, 27.0000
51.226325304, 96.390, 688.0, 26.2298
51.278846435, 96.390, 742.0, 27.2397
51.331367566, 96.390, 716.0, 26.7582
51.383888696, 96.390, 690.0, 26.2679
51.436409827, 96.390, 747.0, 27.3313
51.488930958, 96.390, 741.0, 27.2213
51.541452088, 96.390, 686.0, 26.1916
51.593973219, 96.390, 730.0, 27.0185
51.646494350, 96.390, 685.0, 26.1725
51.699015481, 96.390, 698.0, 26.4197
51.751536611, 96.390, 737.0, 27.1477
51.804057742, 96.390, 749.0, 27.3679
51.856578873, 96.390, 707.0, 26.5895
51.909100003, 96.390, 680.0, 26.0768
51.961621134, 96.390, 709.0, 26.6271
52.014142265, 96.390, 673.0, 25.9422
52.066663396, 96.390, 708.0, 26.6083
52.119184526, 96.390, 710.0, 26.6458
52.171705657, 96.390, 718.0, 26.7955
52.224226788, 96.390, 683.0, 26.1343
52.276747918, 96.390, 697.0, 26.4008
52.329269049, 96.390, 722.0, 26.8701
52.381790180, 96.390, 738.0, 27.1662
52.434311310, 96.390, 665.0, 25.7876
52.486832441, 96.390, 667.0, 25.8263
52.539353572, 96.390, 705.0, 26.5518
52.591874703, 96.390, 673.0, 25.9422
52.644395833, 96.390, 657.0, 25.6320
52.696916964, 96.390, 679.0, 26.0576
52.749438095, 96.390, 644.0, 25.3772
52.801959225, 96.390, 709.0, 26.6271
52.854480356, 96.390, 708.0, 26.6083
52.907001487, 96.390, 694.0, 26.3439
52.959522618, 96.390, 684.0, 26.1534
53.012043748, 96.390, 651.0, 25.5147
53.064564879, 96.390, 696.0, 26.3818
53.117086010, 96.390, 680.0, 26.0768
53.169607140, 96.390, 670.0, 25.8844
53.222128271, 96.390, 698.0, 26.4197
53.274649402, 96.390, 678.0, 26.0384
53.327170533, 96.390, 679.0, 26.0576
53.379691663, 96.390, 668.0, 25.8457
53.432212794, 96.390, 686.0, 26.1916
53.484733925, 96.390, 685.0, 26.1725
53.537255055, 96.390, 622.0, 24.9399
53.589776186, 96.390, 686.0, 26.1916
53.642297317, 96.390, 619.0, 24.8797
53.694818448, 96.390, 705.0, 26.5518
53.747339578, 96.390, 679.0, 26.0576
53.799860709, 96.390, 622.0, 24.9399
53.852381840, 96.390, 672.0, 25.9230
53.904902970, 96.390, 641.0, 25.3180
53.957424101, 96.390, 654.0, 25.5734
54.009945232, 96.390, 678.0, 26.0384
54.062466362, 96.390, 669.0, 25.8650
54.114987493, 96.390, 687.0, 26.2107
54.167508624, 96.390, 648.0, 25.4558
54.220029755, 96.390, 658.0, 25.6515
54.272550885, 96.390, 647.0, 25.4362
54.325072016, 96.390, 641.0, 25.3180
54.377593147, 96.390, 701.0, 26.4764
54.430114277, 96.390, 623.0, 24.9600
54.482635408, 96.390, 637.0, 25.2389
54.535156539, 96.390, 674.0, 25.9615
54.587677670, 96.390, 642.0, 25.3377
54.640198800, 96.390, 685.0, 26.1725
54.692719931, 96.390, 656.0, 25.6125
54.745241062, 96.390, 683.0, 26.1343
54.797762192, 96.390, 602.0, 24.5357
54.850283323, 96.390, 668.0, 25.8457
54.902804454, 96.390, 616.0, 24.8193
54.955325585, 96.390, 657.0, 25.6320
55.007846715, 96.390, 667.0, 25.8263
55.060367846, 96.390, 695.0, 26.3629
55.112888977, 96.390, 675.0, 25.9808
55.165410107, 96.390, 634.0, 25.1794
55.217931238, 96.390, 675.0, 25.9808
55.270452369, 96.390, 643.0, 25.3574
55.322973499, 96.390, 658.0, 25.6515
55.375494630, 96.390, 692.0, 26.3059
55.428015761, 96.390, 650.0, 25.4951
55.480536892, 96.390, 711.0, 26.6646
55.533058022, 96.390, 659.0, 25.6710
55.585579153, 96.390, 651.0, 25.5147
55.638100284, 96.390, 681.0, 26.0960
55.690621414, 96.390, 678.0, 26.0384
55.743142545, 96.390, 676.0, 26.0000
55.795663676, 96.390, 696.0, 26.3818
55.848184807, 96.390, 693.0, 26.3249
55.900705937, 96.390, 679.0, 26.0576
55.953227068, 96.390, 717.0, 26.7769
56.005748199, 96.390, 657.0, 25.6320
56.058269329, 96.390, 612.0, 24.7386
56.110790460, 96.390, 691.0, 26.2869
56.163311591, 96.390, 660.0, 25.6905
56.215832722, 96.390, 677.0, 26.0192
56.268353852, 96.390, 678.0, 26.0384
56.320874983, 96.390, 670.0, 25.8844
56.373396114, 96.390, 727.0, 26.9629
56.425917244, 96.390, 685.0, 26.1725
56.478438375, 96.390, 656.0, 25.6125
56.530959506, 96.390, 688.0, 26.2298
56.583480637, 96.390, 684.0, 26.1534
56.636001767, 96.390, 637.0, 25.2389
56.688522898, 96.390, 688.0, 26.2298
56.741044029, 96.390, 661.0, 25.7099
56.793565159, 96.390, 680.0, 26.0768
56.846086290, 96.390, 660.0, 25.6905
56.898607421, 96.390, 661.0, 25.7099
56.951128551, 96.390, 649.0, 25.4755
57.003649682, 96.390, 668.0, 25.8457
57.056170813, 96.390, 680.0, 26.0768
57.108691944, 96.390, 655.0, 25.5930
57.161213074, 96.390, 679.0, 26.0576
57.213734205, 96.390, 674.0, 25.9615
57.266255336, 96.390, 704.0, 26.5330
57.318776466, 96.390, 662.0, 25.7294
57.371297597, 96.390, 639.0, 25.2784
57.423818728, 96.390, 666.0, 25.8070
57.476339859, 96.390, 658.0, 25.6515
57.528860989, 96.390, 665.0, 25.7876
57.581382120, 96.390, 658.0, 25.6515
57.633903251, 96.390, 704.0, 26.5330
57.686424381, 96.390, 623.0, 24.9600
57.738945512, 96.390, 674.0, 25.9615
57.791466643, 96.390, 654.0, 25.5734
57.843987774, 96.390, 702.0, 26.4953
57.896508904, 96.390, 661.0, 25.7099
57.949030035, 96.390, 686.0, 26.1916
58.001551166, 96.390, 725.0, 26.9258
58.054072296, 96.390, 692.0, 26.3059
58.106593427, 96.390, 675.0, 25.9808
58.159114558, 96.390, 690.0, 26.2679
58.211635689, 96.390, 689.0, 26.2488
58.264156819, 96.390, 674.0, 25.9615
58.316677950, 96.390, 669.0, 25.8650
58.369199081, 96.390, 699.0, 26.4386
58.421720211, 96.390, 669.0, 25.8650
58.474241342, 96.390, 711.0, 26.6646
58.526762473, 96.390, 706.0, 26.5707
58.579283603, 96.390, 696.0, 26.3818
58.631804734, 96.390, 674.0, 25.9615
58.684325865, 96.390, 747.0, 27.3313
58.736846996, 96.390, 733.0, 27.0740
58.789368126, 96.390, 659.0, 25.6710
58.841889257, 96.390, 724.0, 26.9072
58.894410388, 96.390, 719.0, 26.8142
58.946931518, 96.390, 683.0, 26.1343
58.999452649, 96.390, 703.0, 26.5141
59.051973780, 96.390, 688.0, 26.2298
59.104494911, 96.390, 719.0, 26.8142
59.157016041, 96.390, 704.0, 26.5330
59.209537172, 96.390, 726.0, 26.9444
59.262058303, 96.390, 752.0, 27.4226
59.314579433, 96.390, 695.0, 26.3629
59.367100564, 96.390, 694.0, 26.3439
59.419621695, 96.390, 703.0, 26.5141
59.472142826, 96.390, 717.0, 26.7769
59.524663956, 96.390, 738.0, 27.1662
59.577185087, 96.390, 717.0, 26.7769
59.629706218, 96.390, 771.0, 27.7669
59.682227348, 96.390, 729.0, 27.0000
59.734748479, 96.390, 731.0, 27.0370
59.787269610, 96.390, 683.0, 26.1343
59.839790740, 96.390, 753.0, 27.4408
59.892311871, 96.390, 704.0, 26.5330
59.944833002, 96.390, 710.0, 26.6458
59.997354133, 96.390, 723.0, 26.8887
60.049875263, 96.390, 762.0, 27.6043
60.102396394, 96.390, 733.0, 27.0740
60.154917525, 96.390, 766.0, 27.6767
60.207438655, 96.390, 748.0, 27.3496
60.259959786, 96.390, 709.0, 26.6271
60.312480917, 96.390, 764.0, 27.6405
60.365002048, 96.390, 749.0, 27.3679
60.417523178, 96.390, 761.0, 27.5862
60.470044309, 96.390, 721.0, 26.8514
60.522565440, 96.390, 753.0, 27.4408
60.575086570, 96.390, 769.0, 27.7308
60.627607701, 96.390, 731.0, 27.0370
60.680128832, 96.390, 758.0, 27.5318
60.732649963, 96.390, 766.0, 27.6767
60.785171093, 96.390, 781.0, 27.9464
60.837692224, 96.390, 756.0, 27.4955
60.890213355, 96.390, 803.0, 28.3373
60.942734485, 96.390, 793.0, 28.1603
60.995255616, 96.390, 825.0, 28.7228
61.047776747, 96.390, 838.0, 28.9482
61.100297878, 96.390, 803.0, 28.3373
61.152819008, 96.390, 794.0, 28.1780
61.205340139, 96.390, 814.0, 28.5307
61.257861270, 96.390, 805.0, 28.3725
61.310382400, 96.390, 828.0, 28.7750
61.362903531, 96.390, 813.0, 28.5132
61.415424662, 96.390, 824.0, 28.7054
61.467945792, 96.390, 812.0, 28.4956
61.520466923, 96.390, 830.0, 28.8097
61.572988054, 96.390, 831.0, 28.8271
61.625509185, 96.390, 863.0, 29.3769
61.678030315, 96.390, 854.0, 29.2233
61.730551446, 96.390, 876.0, 29.5973
61.783072577, 96.390, 877.0, 29.6142
61.835593707, 96.390, 920.0, 30.3315
61.888114838, 96.390, 904.0, 30.0666
61.940635969, 96.390, 910.0, 30.1662
61.993157100, 96.390, 937.0, 30.6105
62.045678230, 96.390, 942.0, 30.6920
62.098199361, 96.390, 951.0, 30.8383
62.150720492, 96.390, 969.0, 31.1288
62.203241622, 96.390, 1028.0, 32.0624
62.255762753, 96.390, 1081.0, 32.8786
62.308283884, 96.390, 1061.0, 32.5730
62.360805015, 96.390, 1079.0, 32.8481
62.413326145, 96.390, 1059.0, 32.5423
62.465847276, 96.390, 996.0, 31.5595
62.518368407, 96.390, 1029.0, 32.0780
62.570889537, 96.390, 1023.0, 31.9844
62.623410668, 96.390, 991.0, 31.4802
62.675931799, 96.390, 948.0, 30.7896
62.728452930, 96.390, 957.0, 30.9354
62.780974060, 96.390, 893.0, 29.8831
62.833495191, 96.390, 893.0, 29.8831
62.886016322, 96.390, 909.0, 30.1496
62.938537452, 96.390, 923.0, 30.3809
62.991058583, 96.390, 946.0, 30.7571
63.043579714, 96.390, 930.0, 30.4959
63.096100844, 96.390, 888.0, 29.7993
63.148621975, 96.390, 909.0, 30.1496
63.201143106, 96.390, 901.0, 30.0167
63.253664237, 96.390, 837.0, 28.9310
63.306185367, 96.390, 837.0, 28.9310
63.358706498, 96.390, 871.0, 29.5127
63.411227629, 96.390, 891.0, 29.8496
63.463748759, 96.390, 878.0, 29.6311
63.516269890, 96.390, 847.0, 29.1033
63.568791021, 96.390, 836.0, 28.9137
63.621312152, 96.390, 863.0, 29.3769
63.673833282, 96.390, 847.0, 29.1033
63.726354413, 96.390, 850.0, 29.1548
63.778875544, 96.390, 849.0, 29.1376
63.831396674, 96.390, 858.0, 29.2916
63.883917805, 96.390, 860.0, 29.3258
63.936438936, 96.390, 897.0, 29.9500
63.988960067, 96.390, 829.0, 28.7924
64.041481197, 96.390, 854.0, 29.2233
64.094002328, 96.390, 885.0, 29.7489
64.146523459, 96.390, 885.0, 29.7489
64.199044589, 96.390, 879.0, 29.6479
64.251565720, 96.390, 877.0, 29.6142
64.304086851, 96.390, 850.0, 29.1548
64.356607981, 96.390, 871.0, 29.5127
64.409129112, 96.390, 874.0, 29.5635
64.461650243, 96.390, 889.0, 29.8161
64.514171374, 96.390, 822.0, 28.6705
64.566692504, 96.390, 873.0, 29.5466
64.619213635, 96.390, 851.0, 29.1719
64.671734766, 96.390, 834.0, 28.8791
64.724255896, 96.390, 878.0, 29.6311
64.776777027, 96.390, 908.0, 30.1330
64.829298158, 96.390, 867.0, 29.4449
64.881819289, 96.390, 866.0, 29.4279
64.934340419, 96.390, 827.0, 28.7576
64.986861550, 96.390, 899.0, 29.9833