File: Files_organized_for_plots/PC/XRD_PC_PaxialPC22nov2021.csv
[Measurement conditions]
Sample identification,MNASPH_PaxialPC22nov2021
Comment - 1,"Configuration=Stage for Flat Samples/Holders, Owner=User-1, Creation date=7/1/2020 9:53:24 AM"
Comment - 2,"Goniometer=Theta/Theta; Minimum step size 2Theta:0.0001; Minimum step size Omega:0.0001"
Comment - 3,"Sample stage=Stage for flat samples/holders"
Comment - 4,"Diffractometer system=EMPYREAN"
Comment - 5,"Measurement program=C:\Users\ibo5034\OneDrive - The Pennsylvania State University\NEUP - Reed, Titus's files\XRD\Cement\Zerobackground scan.xrdmp, Identifier={98A3B11C-88F9-4AA6-982C-73314A311EF5}"
Anode material,Cu
K-Alpha1 wavelength,1.5405980
K-Alpha2 wavelength,1.5444260
Ratio K-Alpha2/K-Alpha1,0.500
Divergence slit,Fixed,0.25
Monochromator used,NO
Generator voltage, 45
Tube current, 40
File date and time,15/Dec/2021 11:23
Unit cell,
h k l, 0 0 0
Scan axis,Gonio
Scan range,4.994599997,64.999991833
Scan step size,0.0262606
No. of points, 2285
Scan type,CONTINUOUS
Time per step,96.390
[Scan points]
Angle, TimePerStep, Intensity, ESD
5.007730280, 96.390, 4054.0, 63.6710
5.060251411, 96.390, 4127.0, 64.2417
5.112772541, 96.390, 3868.0, 62.1932
5.165293672, 96.390, 4000.0, 63.2456
5.217814803, 96.390, 3974.0, 63.0397
5.270335934, 96.390, 3775.0, 61.4410
5.322857064, 96.390, 3710.0, 60.9098
5.375378195, 96.390, 3650.0, 60.4152
5.427899326, 96.390, 3759.0, 61.3107
5.480420456, 96.390, 3679.0, 60.6548
5.532941587, 96.390, 3639.0, 60.3241
5.585462718, 96.390, 3657.0, 60.4731
5.637983849, 96.390, 3597.0, 59.9750
5.690504979, 96.390, 3589.0, 59.9083
5.743026110, 96.390, 3407.0, 58.3695
5.795547241, 96.390, 3577.0, 59.8080
5.848068371, 96.390, 3508.0, 59.2284
5.900589502, 96.390, 3519.0, 59.3212
5.953110633, 96.390, 3354.0, 57.9137
6.005631763, 96.390, 3460.0, 58.8218
6.058152894, 96.390, 3439.0, 58.6430
6.110674025, 96.390, 3494.0, 59.1101
6.163195156, 96.390, 3401.0, 58.3181
6.215716286, 96.390, 3436.0, 58.6174
6.268237417, 96.390, 3361.0, 57.9741
6.320758548, 96.390, 3395.0, 58.2666
6.373279678, 96.390, 3330.0, 57.7062
6.425800809, 96.390, 3450.0, 58.7367
6.478321940, 96.390, 3329.0, 57.6975
6.530843071, 96.390, 3280.0, 57.2713
6.583364201, 96.390, 3347.0, 57.8533
6.635885332, 96.390, 3235.0, 56.8771
6.688406463, 96.390, 3308.0, 57.5152
6.740927593, 96.390, 3227.0, 56.8067
6.793448724, 96.390, 3222.0, 56.7627
6.845969855, 96.390, 3209.0, 56.6480
6.898490986, 96.390, 3202.0, 56.5862
6.951012116, 96.390, 3186.0, 56.4447
7.003533247, 96.390, 3127.0, 55.9196
7.056054378, 96.390, 3133.0, 55.9732
7.108575508, 96.390, 3121.0, 55.8659
7.161096639, 96.390, 3151.0, 56.1338
7.213617770, 96.390, 3257.0, 57.0701
7.266138900, 96.390, 3133.0, 55.9732
7.318660031, 96.390, 3109.0, 55.7584
7.371181162, 96.390, 3040.0, 55.1362
7.423702293, 96.390, 3097.0, 55.6507
7.476223423, 96.390, 3115.0, 55.8122
7.528744554, 96.390, 3016.0, 54.9181
7.581265685, 96.390, 3019.0, 54.9454
7.633786815, 96.390, 2997.0, 54.7449
7.686307946, 96.390, 2997.0, 54.7449
7.738829077, 96.390, 3140.0, 56.0357
7.791350208, 96.390, 3057.0, 55.2901
7.843871338, 96.390, 2980.0, 54.5894
7.896392469, 96.390, 3031.0, 55.0545
7.948913600, 96.390, 3096.0, 55.6417
8.001434730, 96.390, 2957.0, 54.3783
8.053955861, 96.390, 3056.0, 55.2811
8.106476992, 96.390, 2941.0, 54.2310
8.158998123, 96.390, 2927.0, 54.1018
8.211519253, 96.390, 2979.0, 54.5802
8.264040384, 96.390, 2973.0, 54.5252
8.316561515, 96.390, 3026.0, 55.0091
8.369082645, 96.390, 2997.0, 54.7449
8.421603776, 96.390, 2963.0, 54.4334
8.474124907, 96.390, 2910.0, 53.9444
8.526646038, 96.390, 2846.0, 53.3479
8.579167168, 96.390, 2829.0, 53.1883
8.631688299, 96.390, 2868.0, 53.5537
8.684209430, 96.390, 2924.0, 54.0740
8.736730560, 96.390, 2854.0, 53.4228
8.789251691, 96.390, 2823.0, 53.1319
8.841772822, 96.390, 2766.0, 52.5928
8.894293952, 96.390, 2809.0, 53.0000
8.946815083, 96.390, 2933.0, 54.1572
8.999336214, 96.390, 2904.0, 53.8888
9.051857345, 96.390, 2831.0, 53.2071
9.104378475, 96.390, 2763.0, 52.5642
9.156899606, 96.390, 2740.0, 52.3450
9.209420737, 96.390, 2706.0, 52.0192
9.261941867, 96.390, 2789.0, 52.8110
9.314462998, 96.390, 2661.0, 51.5849
9.366984129, 96.390, 2788.0, 52.8015
9.419505260, 96.390, 2830.0, 53.1977
9.472026390, 96.390, 2690.0, 51.8652
9.524547521, 96.390, 2744.0, 52.3832
9.577068652, 96.390, 2772.0, 52.6498
9.629589782, 96.390, 2676.0, 51.7301
9.682110913, 96.390, 2679.0, 51.7591
9.734632044, 96.390, 2676.0, 51.7301
9.787153175, 96.390, 2736.0, 52.3068
9.839674305, 96.390, 2697.0, 51.9326
9.892195436, 96.390, 2773.0, 52.6593
9.944716567, 96.390, 2699.0, 51.9519
9.997237697, 96.390, 2714.0, 52.0961
10.049758828, 96.390, 2638.0, 51.3615
10.102279959, 96.390, 2699.0, 51.9519
10.154801090, 96.390, 2618.0, 51.1664
10.207322220, 96.390, 2721.0, 52.1632
10.259843351, 96.390, 2644.0, 51.4198
10.312364482, 96.390, 2537.0, 50.3686
10.364885612, 96.390, 2612.0, 51.1077
10.417406743, 96.390, 2663.0, 51.6043
10.469927874, 96.390, 2591.0, 50.9019
10.522449004, 96.390, 2503.0, 50.0300
10.574970135, 96.390, 2564.0, 50.6360
10.627491266, 96.390, 2692.0, 51.8845
10.680012397, 96.390, 2480.0, 49.7996
10.732533527, 96.390, 2668.0, 51.6527
10.785054658, 96.390, 2647.0, 51.4490
10.837575789, 96.390, 2462.0, 49.6185
10.890096919, 96.390, 2535.0, 50.3488
10.942618050, 96.390, 2536.0, 50.3587
10.995139181, 96.390, 2500.0, 50.0000
11.047660312, 96.390, 2481.0, 49.8096
11.100181442, 96.390, 2568.0, 50.6754
11.152702573, 96.390, 2518.0, 50.1797
11.205223704, 96.390, 2453.0, 49.5278
11.257744834, 96.390, 2551.0, 50.5074
11.310265965, 96.390, 2520.0, 50.1996
11.362787096, 96.390, 2399.0, 48.9796
11.415308227, 96.390, 2584.0, 50.8331
11.467829357, 96.390, 2484.0, 49.8397
11.520350488, 96.390, 2567.0, 50.6656
11.572871619, 96.390, 2429.0, 49.2849
11.625392749, 96.390, 2514.0, 50.1398
11.677913880, 96.390, 2452.0, 49.5177
11.730435011, 96.390, 2474.0, 49.7393
11.782956141, 96.390, 2434.0, 49.3356
11.835477272, 96.390, 2389.0, 48.8774
11.887998403, 96.390, 2415.0, 49.1426
11.940519534, 96.390, 2399.0, 48.9796
11.993040664, 96.390, 2395.0, 48.9387
12.045561795, 96.390, 2392.0, 48.9081
12.098082926, 96.390, 2413.0, 49.1223
12.150604056, 96.390, 2440.0, 49.3964
12.203125187, 96.390, 2462.0, 49.6185
12.255646318, 96.390, 2437.0, 49.3660
12.308167449, 96.390, 2340.0, 48.3735
12.360688579, 96.390, 2363.0, 48.6107
12.413209710, 96.390, 2448.0, 49.4773
12.465730841, 96.390, 2407.0, 49.0612
12.518251971, 96.390, 2350.0, 48.4768
12.570773102, 96.390, 2402.0, 49.0102
12.623294233, 96.390, 2479.0, 49.7896
12.675815364, 96.390, 2406.0, 49.0510
12.728336494, 96.390, 2388.0, 48.8672
12.780857625, 96.390, 2312.0, 48.0833
12.833378756, 96.390, 2404.0, 49.0306
12.885899886, 96.390, 2305.0, 48.0104
12.938421017, 96.390, 2254.0, 47.4763
12.990942148, 96.390, 2315.0, 48.1144
13.043463279, 96.390, 2299.0, 47.9479
13.095984409, 96.390, 2345.0, 48.4252
13.148505540, 96.390, 2331.0, 48.2804
13.201026671, 96.390, 2203.0, 46.9361
13.253547801, 96.390, 2390.0, 48.8876
13.306068932, 96.390, 2254.0, 47.4763
13.358590063, 96.390, 2233.0, 47.2546
13.411111193, 96.390, 2392.0, 48.9081
13.463632324, 96.390, 2366.0, 48.6415
13.516153455, 96.390, 2339.0, 48.3632
13.568674586, 96.390, 2224.0, 47.1593
13.621195716, 96.390, 2282.0, 47.7703
13.673716847, 96.390, 2333.0, 48.3011
13.726237978, 96.390, 2347.0, 48.4458
13.778759108, 96.390, 2247.0, 47.4025
13.831280239, 96.390, 2223.0, 47.1487
13.883801370, 96.390, 2277.0, 47.7179
13.936322501, 96.390, 2176.0, 46.6476
13.988843631, 96.390, 2262.0, 47.5605
14.041364762, 96.390, 2238.0, 47.3075
14.093885893, 96.390, 2214.0, 47.0532
14.146407023, 96.390, 2259.0, 47.5289
14.198928154, 96.390, 2306.0, 48.0208
14.251449285, 96.390, 2206.0, 46.9681
14.303970416, 96.390, 2255.0, 47.4868
14.356491546, 96.390, 2235.0, 47.2758
14.409012677, 96.390, 2240.0, 47.3286
14.461533808, 96.390, 2195.0, 46.8508
14.514054938, 96.390, 2322.0, 48.1871
14.566576069, 96.390, 2248.0, 47.4131
14.619097200, 96.390, 2282.0, 47.7703
14.671618331, 96.390, 2248.0, 47.4131
14.724139461, 96.390, 2288.0, 47.8330
14.776660592, 96.390, 2290.0, 47.8539
14.829181723, 96.390, 2279.0, 47.7389
14.881702853, 96.390, 2208.0, 46.9894
14.934223984, 96.390, 2237.0, 47.2969
14.986745115, 96.390, 2272.0, 47.6655
15.039266245, 96.390, 2265.0, 47.5920
15.091787376, 96.390, 2248.0, 47.4131
15.144308507, 96.390, 2324.0, 48.2079
15.196829638, 96.390, 2248.0, 47.4131
15.249350768, 96.390, 2277.0, 47.7179
15.301871899, 96.390, 2241.0, 47.3392
15.354393030, 96.390, 2296.0, 47.9166
15.406914160, 96.390, 2314.0, 48.1041
15.459435291, 96.390, 2363.0, 48.6107
15.511956422, 96.390, 2391.0, 48.8979
15.564477553, 96.390, 2292.0, 47.8748
15.616998683, 96.390, 2311.0, 48.0729
15.669519814, 96.390, 2322.0, 48.1871
15.722040945, 96.390, 2299.0, 47.9479
15.774562075, 96.390, 2424.0, 49.2341
15.827083206, 96.390, 2309.0, 48.0521
15.879604337, 96.390, 2337.0, 48.3425
15.932125468, 96.390, 2383.0, 48.8160
15.984646598, 96.390, 2413.0, 49.1223
16.037167729, 96.390, 2274.0, 47.6865
16.089688860, 96.390, 2394.0, 48.9285
16.142209990, 96.390, 2294.0, 47.8957
16.194731121, 96.390, 2401.0, 49.0000
16.247252252, 96.390, 2383.0, 48.8160
16.299773382, 96.390, 2421.0, 49.2037
16.352294513, 96.390, 2451.0, 49.5076
16.404815644, 96.390, 2452.0, 49.5177
16.457336775, 96.390, 2435.0, 49.3457
16.509857905, 96.390, 2404.0, 49.0306
16.562379036, 96.390, 2358.0, 48.5592
16.614900167, 96.390, 2478.0, 49.7795
16.667421297, 96.390, 2461.0, 49.6085
16.719942428, 96.390, 2454.0, 49.5379
16.772463559, 96.390, 2428.0, 49.2747
16.824984690, 96.390, 2602.0, 51.0098
16.877505820, 96.390, 2475.0, 49.7494
16.930026951, 96.390, 2522.0, 50.2195
16.982548082, 96.390, 2494.0, 49.9400
17.035069212, 96.390, 2566.0, 50.6557
17.087590343, 96.390, 2549.0, 50.4876
17.140111474, 96.390, 2517.0, 50.1697
17.192632605, 96.390, 2655.0, 51.5267
17.245153735, 96.390, 2638.0, 51.3615
17.297674866, 96.390, 2651.0, 51.4879
17.350195997, 96.390, 2622.0, 51.2055
17.402717127, 96.390, 2709.0, 52.0481
17.455238258, 96.390, 2701.0, 51.9711
17.507759389, 96.390, 2637.0, 51.3517
17.560280520, 96.390, 2700.0, 51.9615
17.612801650, 96.390, 2700.0, 51.9615
17.665322781, 96.390, 2756.0, 52.4976
17.717843912, 96.390, 2796.0, 52.8772
17.770365042, 96.390, 2874.0, 53.6097
17.822886173, 96.390, 2729.0, 52.2398
17.875407304, 96.390, 2713.0, 52.0865
17.927928434, 96.390, 2714.0, 52.0961
17.980449565, 96.390, 2790.0, 52.8205
18.032970696, 96.390, 2844.0, 53.3292
18.085491827, 96.390, 2829.0, 53.1883
18.138012957, 96.390, 2866.0, 53.5350
18.190534088, 96.390, 2905.0, 53.8981
18.243055219, 96.390, 2956.0, 54.3691
18.295576349, 96.390, 3031.0, 55.0545
18.348097480, 96.390, 3018.0, 54.9363
18.400618611, 96.390, 3006.0, 54.8270
18.453139742, 96.390, 2907.0, 53.9166
18.505660872, 96.390, 3024.0, 54.9909
18.558182003, 96.390, 3132.0, 55.9643
18.610703134, 96.390, 3106.0, 55.7315
18.663224264, 96.390, 3068.0, 55.3895
18.715745395, 96.390, 3126.0, 55.9106
18.768266526, 96.390, 3211.0, 56.6657
18.820787657, 96.390, 3234.0, 56.8683
18.873308787, 96.390, 3084.0, 55.5338
18.925829918, 96.390, 3256.0, 57.0614
18.978351049, 96.390, 3230.0, 56.8331
19.030872179, 96.390, 3211.0, 56.6657
19.083393310, 96.390, 3302.0, 57.4630
19.135914441, 96.390, 3251.0, 57.0175
19.188435572, 96.390, 3315.0, 57.5760
19.240956702, 96.390, 3340.0, 57.7927
19.293477833, 96.390, 3368.0, 58.0345
19.345998964, 96.390, 3439.0, 58.6430
19.398520094, 96.390, 3431.0, 58.5747
19.451041225, 96.390, 3434.0, 58.6003
19.503562356, 96.390, 3522.0, 59.3464
19.556083486, 96.390, 3513.0, 59.2706
19.608604617, 96.390, 3552.0, 59.5987
19.661125748, 96.390, 3632.0, 60.2661
19.713646879, 96.390, 3626.0, 60.2163
19.766168009, 96.390, 3679.0, 60.6548
19.818689140, 96.390, 3718.0, 60.9754
19.871210271, 96.390, 3771.0, 61.4085
19.923731401, 96.390, 3707.0, 60.8851
19.976252532, 96.390, 3927.0, 62.6658
20.028773663, 96.390, 3959.0, 62.9206
20.081294794, 96.390, 4208.0, 64.8691
20.133815924, 96.390, 4227.0, 65.0154
20.186337055, 96.390, 4348.0, 65.9394
20.238858186, 96.390, 4453.0, 66.7308
20.291379316, 96.390, 4522.0, 67.2458
20.343900447, 96.390, 4547.0, 67.4314
20.396421578, 96.390, 4535.0, 67.3424
20.448942709, 96.390, 4655.0, 68.2276
20.501463839, 96.390, 4580.0, 67.6757
20.553984970, 96.390, 4619.0, 67.9632
20.606506101, 96.390, 4456.0, 66.7533
20.659027231, 96.390, 4600.0, 67.8233
20.711548362, 96.390, 4528.0, 67.2904
20.764069493, 96.390, 4371.0, 66.1135
20.816590623, 96.390, 4577.0, 67.6535
20.869111754, 96.390, 4436.0, 66.6033
20.921632885, 96.390, 4480.0, 66.9328
20.974154016, 96.390, 4446.0, 66.6783
21.026675146, 96.390, 4467.0, 66.8356
21.079196277, 96.390, 4524.0, 67.2607
21.131717408, 96.390, 4626.0, 68.0147
21.184238538, 96.390, 4741.0, 68.8549
21.236759669, 96.390, 4697.0, 68.5347
21.289280800, 96.390, 4915.0, 70.1071
21.341801931, 96.390, 5081.0, 71.2811
21.394323061, 96.390, 5271.0, 72.6017
21.446844192, 96.390, 5054.0, 71.0915
21.499365323, 96.390, 5234.0, 72.3464
21.551886453, 96.390, 5076.0, 71.2461
21.604407584, 96.390, 4888.0, 69.9142
21.656928715, 96.390, 4736.0, 68.8186
21.709449846, 96.390, 4692.0, 68.4982
21.761970976, 96.390, 4761.0, 69.0000
21.814492107, 96.390, 4541.0, 67.3869
21.867013238, 96.390, 4527.0, 67.2830
21.919534368, 96.390, 4530.0, 67.3053
21.972055499, 96.390, 4485.0, 66.9701
22.024576630, 96.390, 4492.0, 67.0224
22.077097761, 96.390, 4627.0, 68.0221
22.129618891, 96.390, 4442.0, 66.6483
22.182140022, 96.390, 4468.0, 66.8431
22.234661153, 96.390, 4411.0, 66.4154
22.287182283, 96.390, 4533.0, 67.3276
22.339703414, 96.390, 4473.0, 66.8805
22.392224545, 96.390, 4514.0, 67.1863
22.444745675, 96.390, 4515.0, 67.1937
22.497266806, 96.390, 4428.0, 66.5432
22.549787937, 96.390, 4461.0, 66.7907
22.602309068, 96.390, 4451.0, 66.7158
22.654830198, 96.390, 4444.0, 66.6633
22.707351329, 96.390, 4460.0, 66.7832
22.759872460, 96.390, 4417.0, 66.4605
22.812393590, 96.390, 4410.0, 66.4078
22.864914721, 96.390, 4326.0, 65.7723
22.917435852, 96.390, 4335.0, 65.8407
22.969956983, 96.390, 4429.0, 66.5507
23.022478113, 96.390, 4263.0, 65.2917
23.074999244, 96.390, 4338.0, 65.8635
23.127520375, 96.390, 4330.0, 65.8027
23.180041505, 96.390, 4192.0, 64.7457
23.232562636, 96.390, 4194.0, 64.7611
23.285083767, 96.390, 4246.0, 65.1613
23.337604898, 96.390, 4120.0, 64.1872
23.390126028, 96.390, 3976.0, 63.0555
23.442647159, 96.390, 4031.0, 63.4902
23.495168290, 96.390, 4008.0, 63.3088
23.547689420, 96.390, 4075.0, 63.8357
23.600210551, 96.390, 3924.0, 62.6418
23.652731682, 96.390, 3916.0, 62.5780
23.705252813, 96.390, 3934.0, 62.7216
23.757773943, 96.390, 3851.0, 62.0564
23.810295074, 96.390, 3786.0, 61.5305
23.862816205, 96.390, 3825.0, 61.8466
23.915337335, 96.390, 3874.0, 62.2415
23.967858466, 96.390, 3634.0, 60.2827
24.020379597, 96.390, 3714.0, 60.9426
24.072900727, 96.390, 3778.0, 61.4654
24.125421858, 96.390, 3658.0, 60.4814
24.177942989, 96.390, 3653.0, 60.4401
24.230464120, 96.390, 3670.0, 60.5805
24.282985250, 96.390, 3657.0, 60.4731
24.335506381, 96.390, 3684.0, 60.6960
24.388027512, 96.390, 3582.0, 59.8498
24.440548642, 96.390, 3543.0, 59.5231
24.493069773, 96.390, 3601.0, 60.0083
24.545590904, 96.390, 3584.0, 59.8665
24.598112035, 96.390, 3516.0, 59.2959
24.650633165, 96.390, 3521.0, 59.3380
24.703154296, 96.390, 3497.0, 59.1354
24.755675427, 96.390, 3537.0, 59.4727
24.808196557, 96.390, 3477.0, 58.9661
24.860717688, 96.390, 3382.0, 58.1550
24.913238819, 96.390, 3499.0, 59.1523
24.965759950, 96.390, 3377.0, 58.1120
25.018281080, 96.390, 3408.0, 58.3781
25.070802211, 96.390, 3258.0, 57.0789
25.123323342, 96.390, 3269.0, 57.1752
25.175844472, 96.390, 3409.0, 58.3866
25.228365603, 96.390, 3451.0, 58.7452
25.280886734, 96.390, 3196.0, 56.5332
25.333407864, 96.390, 3188.0, 56.4624
25.385928995, 96.390, 3158.0, 56.1961
25.438450126, 96.390, 3215.0, 56.7010
25.490971257, 96.390, 3244.0, 56.9561
25.543492387, 96.390, 3163.0, 56.2406
25.596013518, 96.390, 3184.0, 56.4269
25.648534649, 96.390, 3114.0, 55.8032
25.701055779, 96.390, 3166.0, 56.2672
25.753576910, 96.390, 3194.0, 56.5155
25.806098041, 96.390, 2985.0, 54.6352
25.858619172, 96.390, 3052.0, 55.2449
25.911140302, 96.390, 3093.0, 55.6147
25.963661433, 96.390, 3055.0, 55.2721
26.016182564, 96.390, 3052.0, 55.2449
26.068703694, 96.390, 3036.0, 55.0999
26.121224825, 96.390, 2967.0, 54.4702
26.173745956, 96.390, 2945.0, 54.2679
26.226267087, 96.390, 2901.0, 53.8609
26.278788217, 96.390, 2982.0, 54.6077
26.331309348, 96.390, 2857.0, 53.4509
26.383830479, 96.390, 2854.0, 53.4228
26.436351609, 96.390, 2881.0, 53.6749
26.488872740, 96.390, 2806.0, 52.9717
26.541393871, 96.390, 2855.0, 53.4322
26.593915002, 96.390, 2928.0, 54.1110
26.646436132, 96.390, 2769.0, 52.6213
26.698957263, 96.390, 2810.0, 53.0094
26.751478394, 96.390, 2817.0, 53.0754
26.803999524, 96.390, 2762.0, 52.5547
26.856520655, 96.390, 2804.0, 52.9528
26.909041786, 96.390, 2796.0, 52.8772
26.961562916, 96.390, 2735.0, 52.2972
27.014084047, 96.390, 2729.0, 52.2398
27.066605178, 96.390, 2758.0, 52.5167
27.119126309, 96.390, 2702.0, 51.9808
27.171647439, 96.390, 2579.0, 50.7839
27.224168570, 96.390, 2691.0, 51.8748
27.276689701, 96.390, 2708.0, 52.0384
27.329210831, 96.390, 2664.0, 51.6140
27.381731962, 96.390, 2576.0, 50.7543
27.434253093, 96.390, 2658.0, 51.5558
27.486774224, 96.390, 2528.0, 50.2792
27.539295354, 96.390, 2589.0, 50.8822
27.591816485, 96.390, 2601.0, 51.0000
27.644337616, 96.390, 2577.0, 50.7642
27.696858746, 96.390, 2602.0, 51.0098
27.749379877, 96.390, 2452.0, 49.5177
27.801901008, 96.390, 2450.0, 49.4975
27.854422139, 96.390, 2462.0, 49.6185
27.906943269, 96.390, 2473.0, 49.7293
27.959464400, 96.390, 2491.0, 49.9099
28.011985531, 96.390, 2466.0, 49.6588
28.064506661, 96.390, 2464.0, 49.6387
28.117027792, 96.390, 2564.0, 50.6360
28.169548923, 96.390, 2447.0, 49.4672
28.222070054, 96.390, 2348.0, 48.4562
28.274591184, 96.390, 2444.0, 49.4368
28.327112315, 96.390, 2405.0, 49.0408
28.379633446, 96.390, 2425.0, 49.2443
28.432154576, 96.390, 2338.0, 48.3529
28.484675707, 96.390, 2439.0, 49.3862
28.537196838, 96.390, 2413.0, 49.1223
28.589717968, 96.390, 2394.0, 48.9285
28.642239099, 96.390, 2302.0, 47.9792
28.694760230, 96.390, 2342.0, 48.3942
28.747281361, 96.390, 2252.0, 47.4552
28.799802491, 96.390, 2315.0, 48.1144
28.852323622, 96.390, 2308.0, 48.0416
28.904844753, 96.390, 2308.0, 48.0416
28.957365883, 96.390, 2284.0, 47.7912
29.009887014, 96.390, 2313.0, 48.0937
29.062408145, 96.390, 2221.0, 47.1275
29.114929276, 96.390, 2280.0, 47.7493
29.167450406, 96.390, 2256.0, 47.4974
29.219971537, 96.390, 2164.0, 46.5188
29.272492668, 96.390, 2172.0, 46.6047
29.325013798, 96.390, 2162.0, 46.4973
29.377534929, 96.390, 2108.0, 45.9130
29.430056060, 96.390, 2158.0, 46.4543
29.482577191, 96.390, 2126.0, 46.1086
29.535098321, 96.390, 2158.0, 46.4543
29.587619452, 96.390, 2141.0, 46.2709
29.640140583, 96.390, 2176.0, 46.6476
29.692661713, 96.390, 2135.0, 46.2061
29.745182844, 96.390, 2183.0, 46.7226
29.797703975, 96.390, 2145.0, 46.3141
29.850225105, 96.390, 2071.0, 45.5082
29.902746236, 96.390, 2032.0, 45.0777
29.955267367, 96.390, 2039.0, 45.1553
30.007788498, 96.390, 2003.0, 44.7549
30.060309628, 96.390, 2023.0, 44.9778
30.112830759, 96.390, 2086.0, 45.6727
30.165351890, 96.390, 2073.0, 45.5302
30.217873020, 96.390, 1921.0, 43.8292
30.270394151, 96.390, 2013.0, 44.8665
30.322915282, 96.390, 1948.0, 44.1362
30.375436413, 96.390, 1981.0, 44.5084
30.427957543, 96.390, 1957.0, 44.2380
30.480478674, 96.390, 1888.0, 43.4511
30.532999805, 96.390, 1885.0, 43.4166
30.585520935, 96.390, 2018.0, 44.9222
30.638042066, 96.390, 1955.0, 44.2154
30.690563197, 96.390, 1968.0, 44.3621
30.743084328, 96.390, 1942.0, 44.0681
30.795605458, 96.390, 1937.0, 44.0114
30.848126589, 96.390, 1957.0, 44.2380
30.900647720, 96.390, 1963.0, 44.3058
30.953168850, 96.390, 1868.0, 43.2204
31.005689981, 96.390, 1927.0, 43.8976
31.058211112, 96.390, 1856.0, 43.0813
31.110732243, 96.390, 1858.0, 43.1045
31.163253373, 96.390, 1916.0, 43.7721
31.215774504, 96.390, 1836.0, 42.8486
31.268295635, 96.390, 1737.0, 41.6773
31.320816765, 96.390, 1770.0, 42.0714
31.373337896, 96.390, 1860.0, 43.1277
31.425859027, 96.390, 1837.0, 42.8602
31.478380157, 96.390, 1802.0, 42.4500
31.530901288, 96.390, 1725.0, 41.5331
31.583422419, 96.390, 1781.0, 42.2019
31.635943550, 96.390, 1792.0, 42.3320
31.688464680, 96.390, 1788.0, 42.2847
31.740985811, 96.390, 1728.0, 41.5692
31.793506942, 96.390, 1785.0, 42.2493
31.846028072, 96.390, 1709.0, 41.3401
31.898549203, 96.390, 1799.0, 42.4146
31.951070334, 96.390, 1724.0, 41.5211
32.003591465, 96.390, 1708.0, 41.3280
32.056112595, 96.390, 1745.0, 41.7732
32.108633726, 96.390, 1763.0, 41.9881
32.161154857, 96.390, 1751.0, 41.8450
32.213675987, 96.390, 1582.0, 39.7744
32.266197118, 96.390, 1655.0, 40.6817
32.318718249, 96.390, 1651.0, 40.6325
32.371239380, 96.390, 1618.0, 40.2244
32.423760510, 96.390, 1644.0, 40.5463
32.476281641, 96.390, 1677.0, 40.9512
32.528802772, 96.390, 1632.0, 40.3980
32.581323902, 96.390, 1676.0, 40.9390
32.633845033, 96.390, 1615.0, 40.1871
32.686366164, 96.390, 1591.0, 39.8873
32.738887295, 96.390, 1583.0, 39.7869
32.791408425, 96.390, 1649.0, 40.6079
32.843929556, 96.390, 1628.0, 40.3485
32.896450687, 96.390, 1594.0, 39.9249
32.948971817, 96.390, 1616.0, 40.1995
33.001492948, 96.390, 1566.0, 39.5727
33.054014079, 96.390, 1509.0, 38.8458
33.106535209, 96.390, 1605.0, 40.0625
33.159056340, 96.390, 1537.0, 39.2046
33.211577471, 96.390, 1561.0, 39.5095
33.264098602, 96.390, 1605.0, 40.0625
33.316619732, 96.390, 1585.0, 39.8121
33.369140863, 96.390, 1530.0, 39.1152
33.421661994, 96.390, 1493.0, 38.6394
33.474183124, 96.390, 1508.0, 38.8330
33.526704255, 96.390, 1560.0, 39.4968
33.579225386, 96.390, 1545.0, 39.3065
33.631746517, 96.390, 1487.0, 38.5616
33.684267647, 96.390, 1512.0, 38.8844
33.736788778, 96.390, 1526.0, 39.0640
33.789309909, 96.390, 1478.0, 38.4448
33.841831039, 96.390, 1544.0, 39.2938
33.894352170, 96.390, 1435.0, 37.8814
33.946873301, 96.390, 1479.0, 38.4578
33.999394432, 96.390, 1461.0, 38.2230
34.051915562, 96.390, 1477.0, 38.4318
34.104436693, 96.390, 1495.0, 38.6652
34.156957824, 96.390, 1471.0, 38.3536
34.209478954, 96.390, 1452.0, 38.1051
34.262000085, 96.390, 1531.0, 39.1280
34.314521216, 96.390, 1478.0, 38.4448
34.367042346, 96.390, 1497.0, 38.6911
34.419563477, 96.390, 1407.0, 37.5100
34.472084608, 96.390, 1389.0, 37.2693
34.524605739, 96.390, 1476.0, 38.4187
34.577126869, 96.390, 1439.0, 37.9342
34.629648000, 96.390, 1430.0, 37.8153
34.682169131, 96.390, 1432.0, 37.8418
34.734690261, 96.390, 1317.0, 36.2905
34.787211392, 96.390, 1387.0, 37.2424
34.839732523, 96.390, 1370.0, 37.0135
34.892253654, 96.390, 1488.0, 38.5746
34.944774784, 96.390, 1425.0, 37.7492
34.997295915, 96.390, 1399.0, 37.4032
35.049817046, 96.390, 1437.0, 37.9078
35.102338176, 96.390, 1495.0, 38.6652
35.154859307, 96.390, 1429.0, 37.8021
35.207380438, 96.390, 1459.0, 38.1969
35.259901569, 96.390, 1499.0, 38.7169
35.312422699, 96.390, 1549.0, 39.3573
35.364943830, 96.390, 1568.0, 39.5980
35.417464961, 96.390, 1506.0, 38.8072
35.469986091, 96.390, 1514.0, 38.9102
35.522507222, 96.390, 1537.0, 39.2046
35.575028353, 96.390, 1499.0, 38.7169
35.627549484, 96.390, 1462.0, 38.2361
35.680070614, 96.390, 1454.0, 38.1314
35.732591745, 96.390, 1403.0, 37.4566
35.785112876, 96.390, 1445.0, 38.0132
35.837634006, 96.390, 1378.0, 37.1214
35.890155137, 96.390, 1361.0, 36.8917
35.942676268, 96.390, 1332.0, 36.4966
35.995197398, 96.390, 1375.0, 37.0810
36.047718529, 96.390, 1310.0, 36.1939
36.100239660, 96.390, 1304.0, 36.1109
36.152760791, 96.390, 1365.0, 36.9459
36.205281921, 96.390, 1291.0, 35.9305
36.257803052, 96.390, 1317.0, 36.2905
36.310324183, 96.390, 1327.0, 36.4280
36.362845313, 96.390, 1312.0, 36.2215
36.415366444, 96.390, 1277.0, 35.7351
36.467887575, 96.390, 1318.0, 36.3043
36.520408706, 96.390, 1280.0, 35.7771
36.572929836, 96.390, 1209.0, 34.7707
36.625450967, 96.390, 1249.0, 35.3412
36.677972098, 96.390, 1165.0, 34.1321
36.730493228, 96.390, 1293.0, 35.9583
36.783014359, 96.390, 1297.0, 36.0139
36.835535490, 96.390, 1236.0, 35.1568
36.888056621, 96.390, 1248.0, 35.3270
36.940577751, 96.390, 1234.0, 35.1283
36.993098882, 96.390, 1111.0, 33.3317
37.045620013, 96.390, 1247.0, 35.3129
37.098141143, 96.390, 1135.0, 33.6898
37.150662274, 96.390, 1206.0, 34.7275
37.203183405, 96.390, 1221.0, 34.9428
37.255704535, 96.390, 1166.0, 34.1467
37.308225666, 96.390, 1150.0, 33.9116
37.360746797, 96.390, 1192.0, 34.5254
37.413267928, 96.390, 1218.0, 34.8999
37.465789058, 96.390, 1122.0, 33.4963
37.518310189, 96.390, 1108.0, 33.2866
37.570831320, 96.390, 1152.0, 33.9411
37.623352450, 96.390, 1173.0, 34.2491
37.675873581, 96.390, 1136.0, 33.7046
37.728394712, 96.390, 1137.0, 33.7194
37.780915843, 96.390, 1144.0, 33.8231
37.833436973, 96.390, 1060.0, 32.5576
37.885958104, 96.390, 1100.0, 33.1662
37.938479235, 96.390, 1157.0, 34.0147
37.991000365, 96.390, 1132.0, 33.6452
38.043521496, 96.390, 1067.0, 32.6650
38.096042627, 96.390, 1157.0, 34.0147
38.148563758, 96.390, 1143.0, 33.8083
38.201084888, 96.390, 1113.0, 33.3617
38.253606019, 96.390, 1061.0, 32.5730
38.306127150, 96.390, 1089.0, 33.0000
38.358648280, 96.390, 1068.0, 32.6803
38.411169411, 96.390, 1090.0, 33.0151
38.463690542, 96.390, 1038.0, 32.2180
38.516211673, 96.390, 1120.0, 33.4664
38.568732803, 96.390, 1050.0, 32.4037
38.621253934, 96.390, 1130.0, 33.6155
38.673775065, 96.390, 1069.0, 32.6956
38.726296195, 96.390, 1061.0, 32.5730
38.778817326, 96.390, 1041.0, 32.2645
38.831338457, 96.390, 1030.0, 32.0936
38.883859587, 96.390, 1015.0, 31.8591
38.936380718, 96.390, 1031.0, 32.1092
38.988901849, 96.390, 1032.0, 32.1248
39.041422980, 96.390, 1085.0, 32.9393
39.093944110, 96.390, 1051.0, 32.4191
39.146465241, 96.390, 1030.0, 32.0936
39.198986372, 96.390, 1014.0, 31.8434
39.251507502, 96.390, 1074.0, 32.7719
39.304028633, 96.390, 1009.0, 31.7648
39.356549764, 96.390, 988.0, 31.4325
39.409070895, 96.390, 986.0, 31.4006
39.461592025, 96.390, 974.0, 31.2090
39.514113156, 96.390, 1062.0, 32.5883
39.566634287, 96.390, 988.0, 31.4325
39.619155417, 96.390, 971.0, 31.1609
39.671676548, 96.390, 1001.0, 31.6386
39.724197679, 96.390, 923.0, 30.3809
39.776718810, 96.390, 1003.0, 31.6702
39.829239940, 96.390, 966.0, 31.0805
39.881761071, 96.390, 998.0, 31.5911
39.934282202, 96.390, 1005.0, 31.7017
39.986803332, 96.390, 960.0, 30.9839
40.039324463, 96.390, 965.0, 31.0644
40.091845594, 96.390, 972.0, 31.1769
40.144366725, 96.390, 1021.0, 31.9531
40.196887855, 96.390, 993.0, 31.5119
40.249408986, 96.390, 1014.0, 31.8434
40.301930117, 96.390, 926.0, 30.4302
40.354451247, 96.390, 932.0, 30.5287
40.406972378, 96.390, 966.0, 31.0805
40.459493509, 96.390, 938.0, 30.6268
40.512014639, 96.390, 971.0, 31.1609
40.564535770, 96.390, 999.0, 31.6070
40.617056901, 96.390, 956.0, 30.9192
40.669578032, 96.390, 902.0, 30.0333
40.722099162, 96.390, 978.0, 31.2730
40.774620293, 96.390, 977.0, 31.2570
40.827141424, 96.390, 1036.0, 32.1870
40.879662554, 96.390, 958.0, 30.9516
40.932183685, 96.390, 1007.0, 31.7333
40.984704816, 96.390, 951.0, 30.8383
41.037225947, 96.390, 980.0, 31.3050
41.089747077, 96.390, 941.0, 30.6757
41.142268208, 96.390, 1011.0, 31.7962
41.194789339, 96.390, 960.0, 30.9839
41.247310469, 96.390, 987.0, 31.4166
41.299831600, 96.390, 921.0, 30.3480
41.352352731, 96.390, 950.0, 30.8221
41.404873862, 96.390, 973.0, 31.1929
41.457394992, 96.390, 993.0, 31.5119
41.509916123, 96.390, 989.0, 31.4484
41.562437254, 96.390, 892.0, 29.8664
41.614958384, 96.390, 911.0, 30.1828
41.667479515, 96.390, 979.0, 31.2890
41.720000646, 96.390, 966.0, 31.0805
41.772521776, 96.390, 963.0, 31.0322
41.825042907, 96.390, 970.0, 31.1448
41.877564038, 96.390, 970.0, 31.1448
41.930085169, 96.390, 940.0, 30.6594
41.982606299, 96.390, 1004.0, 31.6860
42.035127430, 96.390, 941.0, 30.6757
42.087648561, 96.390, 964.0, 31.0483
42.140169691, 96.390, 918.0, 30.2985
42.192690822, 96.390, 1026.0, 32.0312
42.245211953, 96.390, 950.0, 30.8221
42.297733084, 96.390, 967.0, 31.0966
42.350254214, 96.390, 930.0, 30.4959
42.402775345, 96.390, 934.0, 30.5614
42.455296476, 96.390, 989.0, 31.4484
42.507817606, 96.390, 891.0, 29.8496
42.560338737, 96.390, 967.0, 31.0966
42.612859868, 96.390, 913.0, 30.2159
42.665380999, 96.390, 993.0, 31.5119
42.717902129, 96.390, 1003.0, 31.6702
42.770423260, 96.390, 986.0, 31.4006
42.822944391, 96.390, 940.0, 30.6594
42.875465521, 96.390, 983.0, 31.3528
42.927986652, 96.390, 1004.0, 31.6860
42.980507783, 96.390, 936.0, 30.5941
43.033028914, 96.390, 983.0, 31.3528
43.085550044, 96.390, 979.0, 31.2890
43.138071175, 96.390, 956.0, 30.9192
43.190592306, 96.390, 954.0, 30.8869
43.243113436, 96.390, 950.0, 30.8221
43.295634567, 96.390, 907.0, 30.1164
43.348155698, 96.390, 951.0, 30.8383
43.400676828, 96.390, 932.0, 30.5287
43.453197959, 96.390, 894.0, 29.8998
43.505719090, 96.390, 995.0, 31.5436
43.558240221, 96.390, 985.0, 31.3847
43.610761351, 96.390, 992.0, 31.4960
43.663282482, 96.390, 929.0, 30.4795
43.715803613, 96.390, 949.0, 30.8058
43.768324743, 96.390, 979.0, 31.2890
43.820845874, 96.390, 962.0, 31.0161
43.873367005, 96.390, 967.0, 31.0966
43.925888136, 96.390, 987.0, 31.4166
43.978409266, 96.390, 909.0, 30.1496
44.030930397, 96.390, 934.0, 30.5614
44.083451528, 96.390, 924.0, 30.3974
44.135972658, 96.390, 929.0, 30.4795
44.188493789, 96.390, 957.0, 30.9354
44.241014920, 96.390, 989.0, 31.4484
44.293536051, 96.390, 897.0, 29.9500
44.346057181, 96.390, 900.0, 30.0000
44.398578312, 96.390, 939.0, 30.6431
44.451099443, 96.390, 944.0, 30.7246
44.503620573, 96.390, 917.0, 30.2820
44.556141704, 96.390, 942.0, 30.6920
44.608662835, 96.390, 959.0, 30.9677
44.661183966, 96.390, 902.0, 30.0333
44.713705096, 96.390, 958.0, 30.9516
44.766226227, 96.390, 908.0, 30.1330
44.818747358, 96.390, 924.0, 30.3974
44.871268488, 96.390, 863.0, 29.3769
44.923789619, 96.390, 973.0, 31.1929
44.976310750, 96.390, 895.0, 29.9166
45.028831880, 96.390, 893.0, 29.8831
45.081353011, 96.390, 945.0, 30.7409
45.133874142, 96.390, 946.0, 30.7571
45.186395273, 96.390, 921.0, 30.3480
45.238916403, 96.390, 904.0, 30.0666
45.291437534, 96.390, 914.0, 30.2324
45.343958665, 96.390, 905.0, 30.0832
45.396479795, 96.390, 892.0, 29.8664
45.449000926, 96.390, 925.0, 30.4138
45.501522057, 96.390, 892.0, 29.8664
45.554043188, 96.390, 917.0, 30.2820
45.606564318, 96.390, 872.0, 29.5296
45.659085449, 96.390, 878.0, 29.6311
45.711606580, 96.390, 913.0, 30.2159
45.764127710, 96.390, 922.0, 30.3645
45.816648841, 96.390, 899.0, 29.9833
45.869169972, 96.390, 918.0, 30.2985
45.921691103, 96.390, 925.0, 30.4138
45.974212233, 96.390, 939.0, 30.6431
46.026733364, 96.390, 895.0, 29.9166
46.079254495, 96.390, 840.0, 28.9828
46.131775625, 96.390, 845.0, 29.0689
46.184296756, 96.390, 885.0, 29.7489
46.236817887, 96.390, 867.0, 29.4449
46.289339017, 96.390, 885.0, 29.7489
46.341860148, 96.390, 887.0, 29.7825
46.394381279, 96.390, 925.0, 30.4138
46.446902410, 96.390, 879.0, 29.6479
46.499423540, 96.390, 871.0, 29.5127
46.551944671, 96.390, 899.0, 29.9833
46.604465802, 96.390, 883.0, 29.7153
46.656986932, 96.390, 897.0, 29.9500
46.709508063, 96.390, 915.0, 30.2490
46.762029194, 96.390, 828.0, 28.7750
46.814550325, 96.390, 869.0, 29.4788
46.867071455, 96.390, 866.0, 29.4279
46.919592586, 96.390, 867.0, 29.4449
46.972113717, 96.390, 892.0, 29.8664
47.024634847, 96.390, 892.0, 29.8664
47.077155978, 96.390, 892.0, 29.8664
47.129677109, 96.390, 941.0, 30.6757
47.182198240, 96.390, 874.0, 29.5635
47.234719370, 96.390, 890.0, 29.8329
47.287240501, 96.390, 871.0, 29.5127
47.339761632, 96.390, 901.0, 30.0167
47.392282762, 96.390, 877.0, 29.6142
47.444803893, 96.390, 934.0, 30.5614
47.497325024, 96.390, 855.0, 29.2404
47.549846155, 96.390, 899.0, 29.9833
47.602367285, 96.390, 872.0, 29.5296
47.654888416, 96.390, 884.0, 29.7321
47.707409547, 96.390, 886.0, 29.7658
47.759930677, 96.390, 790.0, 28.1069
47.812451808, 96.390, 856.0, 29.2575
47.864972939, 96.390, 880.0, 29.6648
47.917494069, 96.390, 854.0, 29.2233
47.970015200, 96.390, 878.0, 29.6311
48.022536331, 96.390, 907.0, 30.1164
48.075057462, 96.390, 903.0, 30.0500
48.127578592, 96.390, 840.0, 28.9828
48.180099723, 96.390, 855.0, 29.2404
48.232620854, 96.390, 856.0, 29.2575
48.285141984, 96.390, 874.0, 29.5635
48.337663115, 96.390, 889.0, 29.8161
48.390184246, 96.390, 830.0, 28.8097
48.442705377, 96.390, 858.0, 29.2916
48.495226507, 96.390, 844.0, 29.0517
48.547747638, 96.390, 820.0, 28.6356
48.600268769, 96.390, 830.0, 28.8097
48.652789899, 96.390, 882.0, 29.6985
48.705311030, 96.390, 890.0, 29.8329
48.757832161, 96.390, 859.0, 29.3087
48.810353292, 96.390, 862.0, 29.3598
48.862874422, 96.390, 823.0, 28.6880
48.915395553, 96.390, 874.0, 29.5635
48.967916684, 96.390, 832.0, 28.8444
49.020437814, 96.390, 876.0, 29.5973
49.072958945, 96.390, 869.0, 29.4788
49.125480076, 96.390, 848.0, 29.1204
49.178001207, 96.390, 820.0, 28.6356
49.230522337, 96.390, 832.0, 28.8444
49.283043468, 96.390, 823.0, 28.6880
49.335564599, 96.390, 875.0, 29.5804
49.388085729, 96.390, 848.0, 29.1204
49.440606860, 96.390, 803.0, 28.3373
49.493127991, 96.390, 793.0, 28.1603
49.545649121, 96.390, 808.0, 28.4253
49.598170252, 96.390, 818.0, 28.6007
49.650691383, 96.390, 809.0, 28.4429
49.703212514, 96.390, 859.0, 29.3087
49.755733644, 96.390, 814.0, 28.5307
49.808254775, 96.390, 852.0, 29.1890
49.860775906, 96.390, 825.0, 28.7228
49.913297036, 96.390, 811.0, 28.4781
49.965818167, 96.390, 850.0, 29.1548
50.018339298, 96.390, 876.0, 29.5973
50.070860429, 96.390, 781.0, 27.9464
50.123381559, 96.390, 891.0, 29.8496
50.175902690, 96.390, 864.0, 29.3939
50.228423821, 96.390, 822.0, 28.6705
50.280944951, 96.390, 875.0, 29.5804
50.333466082, 96.390, 836.0, 28.9137
50.385987213, 96.390, 880.0, 29.6648
50.438508344, 96.390, 805.0, 28.3725
50.491029474, 96.390, 848.0, 29.1204
50.543550605, 96.390, 822.0, 28.6705
50.596071736, 96.390, 812.0, 28.4956
50.648592866, 96.390, 872.0, 29.5296
50.701113997, 96.390, 827.0, 28.7576
50.753635128, 96.390, 858.0, 29.2916
50.806156258, 96.390, 808.0, 28.4253
50.858677389, 96.390, 824.0, 28.7054
50.911198520, 96.390, 809.0, 28.4429
50.963719651, 96.390, 880.0, 29.6648
51.016240781, 96.390, 791.0, 28.1247
51.068761912, 96.390, 868.0, 29.4618
51.121283043, 96.390, 824.0, 28.7054
51.173804173, 96.390, 788.0, 28.0713
51.226325304, 96.390, 815.0, 28.5482
51.278846435, 96.390, 781.0, 27.9464
51.331367566, 96.390, 827.0, 28.7576
51.383888696, 96.390, 860.0, 29.3258
51.436409827, 96.390, 766.0, 27.6767
51.488930958, 96.390, 777.0, 27.8747
51.541452088, 96.390, 778.0, 27.8927
51.593973219, 96.390, 747.0, 27.3313
51.646494350, 96.390, 831.0, 28.8271
51.699015481, 96.390, 837.0, 28.9310
51.751536611, 96.390, 791.0, 28.1247
51.804057742, 96.390, 846.0, 29.0861
51.856578873, 96.390, 784.0, 28.0000
51.909100003, 96.390, 809.0, 28.4429
51.961621134, 96.390, 808.0, 28.4253
52.014142265, 96.390, 749.0, 27.3679
52.066663396, 96.390, 764.0, 27.6405
52.119184526, 96.390, 785.0, 28.0179
52.171705657, 96.390, 745.0, 27.2947
52.224226788, 96.390, 860.0, 29.3258
52.276747918, 96.390, 802.0, 28.3196
52.329269049, 96.390, 779.0, 27.9106
52.381790180, 96.390, 774.0, 27.8209
52.434311310, 96.390, 817.0, 28.5832
52.486832441, 96.390, 835.0, 28.8964
52.539353572, 96.390, 805.0, 28.3725
52.591874703, 96.390, 788.0, 28.0713
52.644395833, 96.390, 833.0, 28.8617
52.696916964, 96.390, 791.0, 28.1247
52.749438095, 96.390, 782.0, 27.9643
52.801959225, 96.390, 801.0, 28.3019
52.854480356, 96.390, 796.0, 28.2135
52.907001487, 96.390, 797.0, 28.2312
52.959522618, 96.390, 819.0, 28.6182
53.012043748, 96.390, 801.0, 28.3019
53.064564879, 96.390, 802.0, 28.3196
53.117086010, 96.390, 773.0, 27.8029
53.169607140, 96.390, 853.0, 29.2062
53.222128271, 96.390, 773.0, 27.8029
53.274649402, 96.390, 803.0, 28.3373
53.327170533, 96.390, 789.0, 28.0891
53.379691663, 96.390, 812.0, 28.4956
53.432212794, 96.390, 823.0, 28.6880
53.484733925, 96.390, 789.0, 28.0891
53.537255055, 96.390, 774.0, 27.8209
53.589776186, 96.390, 771.0, 27.7669
53.642297317, 96.390, 811.0, 28.4781
53.694818448, 96.390, 855.0, 29.2404
53.747339578, 96.390, 875.0, 29.5804
53.799860709, 96.390, 827.0, 28.7576
53.852381840, 96.390, 773.0, 27.8029
53.904902970, 96.390, 789.0, 28.0891
53.957424101, 96.390, 810.0, 28.4605
54.009945232, 96.390, 832.0, 28.8444
54.062466362, 96.390, 799.0, 28.2666
54.114987493, 96.390, 817.0, 28.5832
54.167508624, 96.390, 798.0, 28.2489
54.220029755, 96.390, 708.0, 26.6083
54.272550885, 96.390, 831.0, 28.8271
54.325072016, 96.390, 789.0, 28.0891
54.377593147, 96.390, 796.0, 28.2135
54.430114277, 96.390, 837.0, 28.9310
54.482635408, 96.390, 806.0, 28.3901
54.535156539, 96.390, 761.0, 27.5862
54.587677670, 96.390, 797.0, 28.2312
54.640198800, 96.390, 783.0, 27.9821
54.692719931, 96.390, 827.0, 28.7576
54.745241062, 96.390, 816.0, 28.5657
54.797762192, 96.390, 777.0, 27.8747
54.850283323, 96.390, 824.0, 28.7054
54.902804454, 96.390, 818.0, 28.6007
54.955325585, 96.390, 800.0, 28.2843
55.007846715, 96.390, 821.0, 28.6531
55.060367846, 96.390, 776.0, 27.8568
55.112888977, 96.390, 755.0, 27.4773
55.165410107, 96.390, 824.0, 28.7054
55.217931238, 96.390, 798.0, 28.2489
55.270452369, 96.390, 815.0, 28.5482
55.322973499, 96.390, 808.0, 28.4253
55.375494630, 96.390, 791.0, 28.1247
55.428015761, 96.390, 838.0, 28.9482
55.480536892, 96.390, 847.0, 29.1033
55.533058022, 96.390, 839.0, 28.9655
55.585579153, 96.390, 859.0, 29.3087
55.638100284, 96.390, 802.0, 28.3196
55.690621414, 96.390, 770.0, 27.7489
55.743142545, 96.390, 797.0, 28.2312
55.795663676, 96.390, 846.0, 29.0861
55.848184807, 96.390, 797.0, 28.2312
55.900705937, 96.390, 797.0, 28.2312
55.953227068, 96.390, 810.0, 28.4605
56.005748199, 96.390, 768.0, 27.7128
56.058269329, 96.390, 853.0, 29.2062
56.110790460, 96.390, 797.0, 28.2312
56.163311591, 96.390, 781.0, 27.9464
56.215832722, 96.390, 775.0, 27.8388
56.268353852, 96.390, 789.0, 28.0891
56.320874983, 96.390, 837.0, 28.9310
56.373396114, 96.390, 837.0, 28.9310
56.425917244, 96.390, 811.0, 28.4781
56.478438375, 96.390, 795.0, 28.1957
56.530959506, 96.390, 783.0, 27.9821
56.583480637, 96.390, 782.0, 27.9643
56.636001767, 96.390, 768.0, 27.7128
56.688522898, 96.390, 769.0, 27.7308
56.741044029, 96.390, 848.0, 29.1204
56.793565159, 96.390, 781.0, 27.9464
56.846086290, 96.390, 785.0, 28.0179
56.898607421, 96.390, 825.0, 28.7228
56.951128551, 96.390, 809.0, 28.4429
57.003649682, 96.390, 816.0, 28.5657
57.056170813, 96.390, 791.0, 28.1247
57.108691944, 96.390, 801.0, 28.3019
57.161213074, 96.390, 780.0, 27.9285
57.213734205, 96.390, 827.0, 28.7576
57.266255336, 96.390, 755.0, 27.4773
57.318776466, 96.390, 835.0, 28.8964
57.371297597, 96.390, 796.0, 28.2135
57.423818728, 96.390, 753.0, 27.4408
57.476339859, 96.390, 772.0, 27.7849
57.528860989, 96.390, 821.0, 28.6531
57.581382120, 96.390, 780.0, 27.9285
57.633903251, 96.390, 764.0, 27.6405
57.686424381, 96.390, 784.0, 28.0000
57.738945512, 96.390, 794.0, 28.1780
57.791466643, 96.390, 767.0, 27.6948
57.843987774, 96.390, 790.0, 28.1069
57.896508904, 96.390, 826.0, 28.7402
57.949030035, 96.390, 788.0, 28.0713
58.001551166, 96.390, 775.0, 27.8388
58.054072296, 96.390, 782.0, 27.9643
58.106593427, 96.390, 771.0, 27.7669
58.159114558, 96.390, 769.0, 27.7308
58.211635689, 96.390, 832.0, 28.8444
58.264156819, 96.390, 826.0, 28.7402
58.316677950, 96.390, 785.0, 28.0179
58.369199081, 96.390, 865.0, 29.4109
58.421720211, 96.390, 803.0, 28.3373
58.474241342, 96.390, 753.0, 27.4408
58.526762473, 96.390, 809.0, 28.4429
58.579283603, 96.390, 765.0, 27.6586
58.631804734, 96.390, 802.0, 28.3196
58.684325865, 96.390, 799.0, 28.2666
58.736846996, 96.390, 803.0, 28.3373
58.789368126, 96.390, 837.0, 28.9310
58.841889257, 96.390, 799.0, 28.2666
58.894410388, 96.390, 767.0, 27.6948
58.946931518, 96.390, 783.0, 27.9821
58.999452649, 96.390, 744.0, 27.2764
59.051973780, 96.390, 807.0, 28.4077
59.104494911, 96.390, 764.0, 27.6405
59.157016041, 96.390, 807.0, 28.4077
59.209537172, 96.390, 814.0, 28.5307
59.262058303, 96.390, 849.0, 29.1376
59.314579433, 96.390, 788.0, 28.0713
59.367100564, 96.390, 724.0, 26.9072
59.419621695, 96.390, 816.0, 28.5657
59.472142826, 96.390, 794.0, 28.1780
59.524663956, 96.390, 799.0, 28.2666
59.577185087, 96.390, 836.0, 28.9137
59.629706218, 96.390, 812.0, 28.4956
59.682227348, 96.390, 804.0, 28.3549
59.734748479, 96.390, 852.0, 29.1890
59.787269610, 96.390, 748.0, 27.3496
59.839790740, 96.390, 816.0, 28.5657
59.892311871, 96.390, 795.0, 28.1957
59.944833002, 96.390, 784.0, 28.0000
59.997354133, 96.390, 793.0, 28.1603
60.049875263, 96.390, 804.0, 28.3549
60.102396394, 96.390, 752.0, 27.4226
60.154917525, 96.390, 760.0, 27.5681
60.207438655, 96.390, 787.0, 28.0535
60.259959786, 96.390, 832.0, 28.8444
60.312480917, 96.390, 788.0, 28.0713
60.365002048, 96.390, 803.0, 28.3373
60.417523178, 96.390, 844.0, 29.0517
60.470044309, 96.390, 758.0, 27.5318
60.522565440, 96.390, 802.0, 28.3196
60.575086570, 96.390, 775.0, 27.8388
60.627607701, 96.390, 846.0, 29.0861
60.680128832, 96.390, 801.0, 28.3019
60.732649963, 96.390, 804.0, 28.3549
60.785171093, 96.390, 788.0, 28.0713
60.837692224, 96.390, 786.0, 28.0357
60.890213355, 96.390, 783.0, 27.9821
60.942734485, 96.390, 796.0, 28.2135
60.995255616, 96.390, 803.0, 28.3373
61.047776747, 96.390, 835.0, 28.8964
61.100297878, 96.390, 821.0, 28.6531
61.152819008, 96.390, 780.0, 27.9285
61.205340139, 96.390, 869.0, 29.4788
61.257861270, 96.390, 843.0, 29.0345
61.310382400, 96.390, 804.0, 28.3549
61.362903531, 96.390, 782.0, 27.9643
61.415424662, 96.390, 821.0, 28.6531
61.467945792, 96.390, 813.0, 28.5132
61.520466923, 96.390, 737.0, 27.1477
61.572988054, 96.390, 819.0, 28.6182
61.625509185, 96.390, 842.0, 29.0172
61.678030315, 96.390, 840.0, 28.9828
61.730551446, 96.390, 792.0, 28.1425
61.783072577, 96.390, 808.0, 28.4253
61.835593707, 96.390, 762.0, 27.6043
61.888114838, 96.390, 780.0, 27.9285
61.940635969, 96.390, 757.0, 27.5136
61.993157100, 96.390, 749.0, 27.3679
62.045678230, 96.390, 801.0, 28.3019
62.098199361, 96.390, 798.0, 28.2489
62.150720492, 96.390, 815.0, 28.5482
62.203241622, 96.390, 759.0, 27.5500
62.255762753, 96.390, 794.0, 28.1780
62.308283884, 96.390, 858.0, 29.2916
62.360805015, 96.390, 750.0, 27.3861
62.413326145, 96.390, 772.0, 27.7849
62.465847276, 96.390, 779.0, 27.9106
62.518368407, 96.390, 843.0, 29.0345
62.570889537, 96.390, 815.0, 28.5482
62.623410668, 96.390, 839.0, 28.9655
62.675931799, 96.390, 780.0, 27.9285
62.728452930, 96.390, 811.0, 28.4781
62.780974060, 96.390, 815.0, 28.5482
62.833495191, 96.390, 765.0, 27.6586
62.886016322, 96.390, 828.0, 28.7750
62.938537452, 96.390, 783.0, 27.9821
62.991058583, 96.390, 821.0, 28.6531
63.043579714, 96.390, 807.0, 28.4077
63.096100844, 96.390, 812.0, 28.4956
63.148621975, 96.390, 825.0, 28.7228
63.201143106, 96.390, 784.0, 28.0000
63.253664237, 96.390, 783.0, 27.9821
63.306185367, 96.390, 827.0, 28.7576
63.358706498, 96.390, 798.0, 28.2489
63.411227629, 96.390, 786.0, 28.0357
63.463748759, 96.390, 836.0, 28.9137
63.516269890, 96.390, 870.0, 29.4958
63.568791021, 96.390, 809.0, 28.4429
63.621312152, 96.390, 779.0, 27.9106
63.673833282, 96.390, 798.0, 28.2489
63.726354413, 96.390, 782.0, 27.9643
63.778875544, 96.390, 800.0, 28.2843
63.831396674, 96.390, 787.0, 28.0535
63.883917805, 96.390, 811.0, 28.4781
63.936438936, 96.390, 816.0, 28.5657
63.988960067, 96.390, 791.0, 28.1247
64.041481197, 96.390, 780.0, 27.9285
64.094002328, 96.390, 815.0, 28.5482
64.146523459, 96.390, 804.0, 28.3549
64.199044589, 96.390, 827.0, 28.7576
64.251565720, 96.390, 781.0, 27.9464
64.304086851, 96.390, 802.0, 28.3196
64.356607981, 96.390, 815.0, 28.5482
64.409129112, 96.390, 801.0, 28.3019
64.461650243, 96.390, 821.0, 28.6531
64.514171374, 96.390, 752.0, 27.4226
64.566692504, 96.390, 784.0, 28.0000
64.619213635, 96.390, 786.0, 28.0357
64.671734766, 96.390, 809.0, 28.4429
64.724255896, 96.390, 759.0, 27.5500
64.776777027, 96.390, 800.0, 28.2843
64.829298158, 96.390, 763.0, 27.6225
64.881819289, 96.390, 786.0, 28.0357
64.934340419, 96.390, 757.0, 27.5136
64.986861550, 96.390, 742.0, 27.2397