File: Files_organized_for_plots/PC/XRD_PC_AlaxialPC01nov2021.csv
[Measurement conditions]
Sample identification,MNASPH_AlaxialPC01nov2021
Comment - 1,"Configuration=Stage for Flat Samples/Holders, Owner=User-1, Creation date=7/1/2020 9:53:24 AM"
Comment - 2,"Goniometer=Theta/Theta; Minimum step size 2Theta:0.0001; Minimum step size Omega:0.0001"
Comment - 3,"Sample stage=Stage for flat samples/holders"
Comment - 4,"Diffractometer system=EMPYREAN"
Comment - 5,"Measurement program=C:\Users\ibo5034\OneDrive - The Pennsylvania State University\NEUP - Reed, Titus's files\XRD\Cement\Zerobackground scan.xrdmp, Identifier={98A3B11C-88F9-4AA6-982C-73314A311EF5}"
Anode material,Cu
K-Alpha1 wavelength,1.5405980
K-Alpha2 wavelength,1.5444260
Ratio K-Alpha2/K-Alpha1,0.500
Divergence slit,Fixed,0.25
Monochromator used,NO
Generator voltage, 45
Tube current, 40
File date and time,15/Dec/2021 11:43
Unit cell,
h k l, 0 0 0
Scan axis,Gonio
Scan range,4.994599997,64.999991833
Scan step size,0.0262606
No. of points, 2285
Scan type,CONTINUOUS
Time per step,96.390
[Scan points]
Angle, TimePerStep, Intensity, ESD
5.007730280, 96.390, 4877.0, 69.8355
5.060251411, 96.390, 4832.0, 69.5126
5.112772541, 96.390, 4682.0, 68.4251
5.165293672, 96.390, 4696.0, 68.5274
5.217814803, 96.390, 4588.0, 67.7348
5.270335934, 96.390, 4524.0, 67.2607
5.322857064, 96.390, 4535.0, 67.3424
5.375378195, 96.390, 4410.0, 66.4078
5.427899326, 96.390, 4346.0, 65.9242
5.480420456, 96.390, 4425.0, 66.5207
5.532941587, 96.390, 4121.0, 64.1950
5.585462718, 96.390, 4198.0, 64.7920
5.637983849, 96.390, 4171.0, 64.5833
5.690504979, 96.390, 4132.0, 64.2806
5.743026110, 96.390, 4073.0, 63.8201
5.795547241, 96.390, 4097.0, 64.0078
5.848068371, 96.390, 4002.0, 63.2614
5.900589502, 96.390, 3882.0, 62.3057
5.953110633, 96.390, 3916.0, 62.5780
6.005631763, 96.390, 3931.0, 62.6977
6.058152894, 96.390, 3817.0, 61.7819
6.110674025, 96.390, 3815.0, 61.7657
6.163195156, 96.390, 3748.0, 61.2209
6.215716286, 96.390, 3702.0, 60.8441
6.268237417, 96.390, 3726.0, 61.0410
6.320758548, 96.390, 3773.0, 61.4248
6.373279678, 96.390, 3726.0, 61.0410
6.425800809, 96.390, 3727.0, 61.0492
6.478321940, 96.390, 3623.0, 60.1914
6.530843071, 96.390, 3497.0, 59.1354
6.583364201, 96.390, 3697.0, 60.8030
6.635885332, 96.390, 3521.0, 59.3380
6.688406463, 96.390, 3651.0, 60.4235
6.740927593, 96.390, 3546.0, 59.5483
6.793448724, 96.390, 3598.0, 59.9833
6.845969855, 96.390, 3572.0, 59.7662
6.898490986, 96.390, 3528.0, 59.3970
6.951012116, 96.390, 3510.0, 59.2453
7.003533247, 96.390, 3485.0, 59.0339
7.056054378, 96.390, 3396.0, 58.2752
7.108575508, 96.390, 3400.0, 58.3095
7.161096639, 96.390, 3435.0, 58.6089
7.213617770, 96.390, 3485.0, 59.0339
7.266138900, 96.390, 3441.0, 58.6600
7.318660031, 96.390, 3284.0, 57.3062
7.371181162, 96.390, 3246.0, 56.9737
7.423702293, 96.390, 3374.0, 58.0861
7.476223423, 96.390, 3253.0, 57.0351
7.528744554, 96.390, 3297.0, 57.4195
7.581265685, 96.390, 3301.0, 57.4543
7.633786815, 96.390, 3296.0, 57.4108
7.686307946, 96.390, 3281.0, 57.2800
7.738829077, 96.390, 3313.0, 57.5587
7.791350208, 96.390, 3279.0, 57.2626
7.843871338, 96.390, 3327.0, 57.6802
7.896392469, 96.390, 3164.0, 56.2494
7.948913600, 96.390, 3292.0, 57.3760
8.001434730, 96.390, 3244.0, 56.9561
8.053955861, 96.390, 3127.0, 55.9196
8.106476992, 96.390, 3164.0, 56.2494
8.158998123, 96.390, 3151.0, 56.1338
8.211519253, 96.390, 3146.0, 56.0892
8.264040384, 96.390, 3177.0, 56.3649
8.316561515, 96.390, 3068.0, 55.3895
8.369082645, 96.390, 3166.0, 56.2672
8.421603776, 96.390, 3117.0, 55.8301
8.474124907, 96.390, 2994.0, 54.7175
8.526646038, 96.390, 3002.0, 54.7905
8.579167168, 96.390, 3053.0, 55.2540
8.631688299, 96.390, 3068.0, 55.3895
8.684209430, 96.390, 3033.0, 55.0727
8.736730560, 96.390, 3024.0, 54.9909
8.789251691, 96.390, 2970.0, 54.4977
8.841772822, 96.390, 3068.0, 55.3895
8.894293952, 96.390, 2992.0, 54.6992
8.946815083, 96.390, 3032.0, 55.0636
8.999336214, 96.390, 2928.0, 54.1110
9.051857345, 96.390, 2916.0, 54.0000
9.104378475, 96.390, 3044.0, 55.1725
9.156899606, 96.390, 2961.0, 54.4151
9.209420737, 96.390, 2943.0, 54.2494
9.261941867, 96.390, 2929.0, 54.1202
9.314462998, 96.390, 2844.0, 53.3292
9.366984129, 96.390, 2895.0, 53.8052
9.419505260, 96.390, 2990.0, 54.6809
9.472026390, 96.390, 2938.0, 54.2033
9.524547521, 96.390, 2899.0, 53.8424
9.577068652, 96.390, 2785.0, 52.7731
9.629589782, 96.390, 2914.0, 53.9815
9.682110913, 96.390, 2837.0, 53.2635
9.734632044, 96.390, 2774.0, 52.6688
9.787153175, 96.390, 2759.0, 52.5262
9.839674305, 96.390, 2807.0, 52.9811
9.892195436, 96.390, 2692.0, 51.8845
9.944716567, 96.390, 2792.0, 52.8394
9.997237697, 96.390, 2809.0, 53.0000
10.049758828, 96.390, 2772.0, 52.6498
10.102279959, 96.390, 2725.0, 52.2015
10.154801090, 96.390, 2758.0, 52.5167
10.207322220, 96.390, 2843.0, 53.3198
10.259843351, 96.390, 2814.0, 53.0471
10.312364482, 96.390, 2749.0, 52.4309
10.364885612, 96.390, 2707.0, 52.0288
10.417406743, 96.390, 2738.0, 52.3259
10.469927874, 96.390, 2637.0, 51.3517
10.522449004, 96.390, 2624.0, 51.2250
10.574970135, 96.390, 2642.0, 51.4004
10.627491266, 96.390, 2613.0, 51.1175
10.680012397, 96.390, 2694.0, 51.9038
10.732533527, 96.390, 2606.0, 51.0490
10.785054658, 96.390, 2678.0, 51.7494
10.837575789, 96.390, 2637.0, 51.3517
10.890096919, 96.390, 2603.0, 51.0196
10.942618050, 96.390, 2627.0, 51.2543
10.995139181, 96.390, 2630.0, 51.2835
11.047660312, 96.390, 2567.0, 50.6656
11.100181442, 96.390, 2700.0, 51.9615
11.152702573, 96.390, 2604.0, 51.0294
11.205223704, 96.390, 2487.0, 49.8698
11.257744834, 96.390, 2637.0, 51.3517
11.310265965, 96.390, 2615.0, 51.1371
11.362787096, 96.390, 2505.0, 50.0500
11.415308227, 96.390, 2600.0, 50.9902
11.467829357, 96.390, 2570.0, 50.6952
11.520350488, 96.390, 2615.0, 51.1371
11.572871619, 96.390, 2472.0, 49.7192
11.625392749, 96.390, 2457.0, 49.5681
11.677913880, 96.390, 2499.0, 49.9900
11.730435011, 96.390, 2477.0, 49.7695
11.782956141, 96.390, 2429.0, 49.2849
11.835477272, 96.390, 2464.0, 49.6387
11.887998403, 96.390, 2421.0, 49.2037
11.940519534, 96.390, 2440.0, 49.3964
11.993040664, 96.390, 2503.0, 50.0300
12.045561795, 96.390, 2477.0, 49.7695
12.098082926, 96.390, 2489.0, 49.8899
12.150604056, 96.390, 2451.0, 49.5076
12.203125187, 96.390, 2455.0, 49.5480
12.255646318, 96.390, 2395.0, 48.9387
12.308167449, 96.390, 2360.0, 48.5798
12.360688579, 96.390, 2442.0, 49.4166
12.413209710, 96.390, 2414.0, 49.1325
12.465730841, 96.390, 2413.0, 49.1223
12.518251971, 96.390, 2436.0, 49.3559
12.570773102, 96.390, 2401.0, 49.0000
12.623294233, 96.390, 2362.0, 48.6004
12.675815364, 96.390, 2421.0, 49.2037
12.728336494, 96.390, 2365.0, 48.6313
12.780857625, 96.390, 2457.0, 49.5681
12.833378756, 96.390, 2392.0, 48.9081
12.885899886, 96.390, 2376.0, 48.7442
12.938421017, 96.390, 2297.0, 47.9270
12.990942148, 96.390, 2403.0, 49.0204
13.043463279, 96.390, 2417.0, 49.1630
13.095984409, 96.390, 2336.0, 48.3322
13.148505540, 96.390, 2248.0, 47.4131
13.201026671, 96.390, 2313.0, 48.0937
13.253547801, 96.390, 2283.0, 47.7807
13.306068932, 96.390, 2261.0, 47.5500
13.358590063, 96.390, 2307.0, 48.0312
13.411111193, 96.390, 2329.0, 48.2597
13.463632324, 96.390, 2369.0, 48.6724
13.516153455, 96.390, 2294.0, 47.8957
13.568674586, 96.390, 2272.0, 47.6655
13.621195716, 96.390, 2315.0, 48.1144
13.673716847, 96.390, 2383.0, 48.8160
13.726237978, 96.390, 2208.0, 46.9894
13.778759108, 96.390, 2257.0, 47.5079
13.831280239, 96.390, 2175.0, 46.6369
13.883801370, 96.390, 2231.0, 47.2335
13.936322501, 96.390, 2236.0, 47.2864
13.988843631, 96.390, 2266.0, 47.6025
14.041364762, 96.390, 2252.0, 47.4552
14.093885893, 96.390, 2242.0, 47.3498
14.146407023, 96.390, 2217.0, 47.0850
14.198928154, 96.390, 2210.0, 47.0106
14.251449285, 96.390, 2232.0, 47.2440
14.303970416, 96.390, 2181.0, 46.7012
14.356491546, 96.390, 2265.0, 47.5920
14.409012677, 96.390, 2139.0, 46.2493
14.461533808, 96.390, 2224.0, 47.1593
14.514054938, 96.390, 2203.0, 46.9361
14.566576069, 96.390, 2149.0, 46.3573
14.619097200, 96.390, 2212.0, 47.0319
14.671618331, 96.390, 2180.0, 46.6905
14.724139461, 96.390, 2170.0, 46.5833
14.776660592, 96.390, 2102.0, 45.8476
14.829181723, 96.390, 2175.0, 46.6369
14.881702853, 96.390, 2207.0, 46.9787
14.934223984, 96.390, 2253.0, 47.4658
14.986745115, 96.390, 2251.0, 47.4447
15.039266245, 96.390, 2211.0, 47.0213
15.091787376, 96.390, 2161.0, 46.4866
15.144308507, 96.390, 2253.0, 47.4658
15.196829638, 96.390, 2165.0, 46.5296
15.249350768, 96.390, 2106.0, 45.8912
15.301871899, 96.390, 2248.0, 47.4131
15.354393030, 96.390, 2162.0, 46.4973
15.406914160, 96.390, 2113.0, 45.9674
15.459435291, 96.390, 2293.0, 47.8853
15.511956422, 96.390, 2245.0, 47.3814
15.564477553, 96.390, 2137.0, 46.2277
15.616998683, 96.390, 2141.0, 46.2709
15.669519814, 96.390, 2197.0, 46.8722
15.722040945, 96.390, 2245.0, 47.3814
15.774562075, 96.390, 2164.0, 46.5188
15.827083206, 96.390, 2203.0, 46.9361
15.879604337, 96.390, 2223.0, 47.1487
15.932125468, 96.390, 2085.0, 45.6618
15.984646598, 96.390, 2200.0, 46.9042
16.037167729, 96.390, 2228.0, 47.2017
16.089688860, 96.390, 2193.0, 46.8295
16.142209990, 96.390, 2239.0, 47.3181
16.194731121, 96.390, 2079.0, 45.5961
16.247252252, 96.390, 2201.0, 46.9148
16.299773382, 96.390, 2235.0, 47.2758
16.352294513, 96.390, 2175.0, 46.6369
16.404815644, 96.390, 2239.0, 47.3181
16.457336775, 96.390, 2132.0, 46.1736
16.509857905, 96.390, 2159.0, 46.4650
16.562379036, 96.390, 2151.0, 46.3789
16.614900167, 96.390, 2260.0, 47.5395
16.667421297, 96.390, 2327.0, 48.2390
16.719942428, 96.390, 2162.0, 46.4973
16.772463559, 96.390, 2186.0, 46.7547
16.824984690, 96.390, 2194.0, 46.8402
16.877505820, 96.390, 2268.0, 47.6235
16.930026951, 96.390, 2258.0, 47.5184
16.982548082, 96.390, 2182.0, 46.7119
17.035069212, 96.390, 2232.0, 47.2440
17.087590343, 96.390, 2251.0, 47.4447
17.140111474, 96.390, 2289.0, 47.8435
17.192632605, 96.390, 2140.0, 46.2601
17.245153735, 96.390, 2271.0, 47.6550
17.297674866, 96.390, 2305.0, 48.0104
17.350195997, 96.390, 2289.0, 47.8435
17.402717127, 96.390, 2200.0, 46.9042
17.455238258, 96.390, 2289.0, 47.8435
17.507759389, 96.390, 2312.0, 48.0833
17.560280520, 96.390, 2241.0, 47.3392
17.612801650, 96.390, 2319.0, 48.1560
17.665322781, 96.390, 2270.0, 47.6445
17.717843912, 96.390, 2357.0, 48.5489
17.770365042, 96.390, 2226.0, 47.1805
17.822886173, 96.390, 2388.0, 48.8672
17.875407304, 96.390, 2370.0, 48.6826
17.927928434, 96.390, 2305.0, 48.0104
17.980449565, 96.390, 2302.0, 47.9792
18.032970696, 96.390, 2417.0, 49.1630
18.085491827, 96.390, 2308.0, 48.0416
18.138012957, 96.390, 2329.0, 48.2597
18.190534088, 96.390, 2444.0, 49.4368
18.243055219, 96.390, 2412.0, 49.1121
18.295576349, 96.390, 2396.0, 48.9490
18.348097480, 96.390, 2341.0, 48.3839
18.400618611, 96.390, 2403.0, 49.0204
18.453139742, 96.390, 2415.0, 49.1426
18.505660872, 96.390, 2456.0, 49.5580
18.558182003, 96.390, 2465.0, 49.6488
18.610703134, 96.390, 2463.0, 49.6286
18.663224264, 96.390, 2390.0, 48.8876
18.715745395, 96.390, 2517.0, 50.1697
18.768266526, 96.390, 2455.0, 49.5480
18.820787657, 96.390, 2539.0, 50.3885
18.873308787, 96.390, 2510.0, 50.0999
18.925829918, 96.390, 2539.0, 50.3885
18.978351049, 96.390, 2458.0, 49.5782
19.030872179, 96.390, 2499.0, 49.9900
19.083393310, 96.390, 2556.0, 50.5569
19.135914441, 96.390, 2602.0, 51.0098
19.188435572, 96.390, 2577.0, 50.7642
19.240956702, 96.390, 2520.0, 50.1996
19.293477833, 96.390, 2629.0, 51.2738
19.345998964, 96.390, 2635.0, 51.3323
19.398520094, 96.390, 2675.0, 51.7204
19.451041225, 96.390, 2561.0, 50.6063
19.503562356, 96.390, 2727.0, 52.2207
19.556083486, 96.390, 2668.0, 51.6527
19.608604617, 96.390, 2697.0, 51.9326
19.661125748, 96.390, 2632.0, 51.3030
19.713646879, 96.390, 2754.0, 52.4786
19.766168009, 96.390, 2733.0, 52.2781
19.818689140, 96.390, 2839.0, 53.2823
19.871210271, 96.390, 2744.0, 52.3832
19.923731401, 96.390, 2783.0, 52.7541
19.976252532, 96.390, 2803.0, 52.9434
20.028773663, 96.390, 2788.0, 52.8015
20.081294794, 96.390, 2809.0, 53.0000
20.133815924, 96.390, 2821.0, 53.1131
20.186337055, 96.390, 2866.0, 53.5350
20.238858186, 96.390, 2846.0, 53.3479
20.291379316, 96.390, 2910.0, 53.9444
20.343900447, 96.390, 2878.0, 53.6470
20.396421578, 96.390, 2919.0, 54.0278
20.448942709, 96.390, 2889.0, 53.7494
20.501463839, 96.390, 3017.0, 54.9272
20.553984970, 96.390, 2994.0, 54.7175
20.606506101, 96.390, 2994.0, 54.7175
20.659027231, 96.390, 2946.0, 54.2771
20.711548362, 96.390, 2946.0, 54.2771
20.764069493, 96.390, 3022.0, 54.9727
20.816590623, 96.390, 3021.0, 54.9636
20.869111754, 96.390, 2916.0, 54.0000
20.921632885, 96.390, 3091.0, 55.5968
20.974154016, 96.390, 3035.0, 55.0908
21.026675146, 96.390, 3043.0, 55.1634
21.079196277, 96.390, 3061.0, 55.3263
21.131717408, 96.390, 3034.0, 55.0818
21.184238538, 96.390, 3144.0, 56.0714
21.236759669, 96.390, 3133.0, 55.9732
21.289280800, 96.390, 3168.0, 56.2850
21.341801931, 96.390, 3215.0, 56.7010
21.394323061, 96.390, 3114.0, 55.8032
21.446844192, 96.390, 3097.0, 55.6507
21.499365323, 96.390, 3223.0, 56.7715
21.551886453, 96.390, 3169.0, 56.2939
21.604407584, 96.390, 3143.0, 56.0625
21.656928715, 96.390, 3182.0, 56.4092
21.709449846, 96.390, 3311.0, 57.5413
21.761970976, 96.390, 3351.0, 57.8878
21.814492107, 96.390, 3258.0, 57.0789
21.867013238, 96.390, 3268.0, 57.1664
21.919534368, 96.390, 3229.0, 56.8243
21.972055499, 96.390, 3352.0, 57.8965
22.024576630, 96.390, 3150.0, 56.1249
22.077097761, 96.390, 3219.0, 56.7362
22.129618891, 96.390, 3234.0, 56.8683
22.182140022, 96.390, 3321.0, 57.6281
22.234661153, 96.390, 3282.0, 57.2887
22.287182283, 96.390, 3426.0, 58.5320
22.339703414, 96.390, 3295.0, 57.4021
22.392224545, 96.390, 3308.0, 57.5152
22.444745675, 96.390, 3389.0, 58.2151
22.497266806, 96.390, 3310.0, 57.5326
22.549787937, 96.390, 3333.0, 57.7321
22.602309068, 96.390, 3318.0, 57.6021
22.654830198, 96.390, 3378.0, 58.1206
22.707351329, 96.390, 3265.0, 57.1402
22.759872460, 96.390, 3293.0, 57.3847
22.812393590, 96.390, 3226.0, 56.7979
22.864914721, 96.390, 3291.0, 57.3672
22.917435852, 96.390, 3393.0, 58.2495
22.969956983, 96.390, 3342.0, 57.8100
23.022478113, 96.390, 3264.0, 57.1314
23.074999244, 96.390, 3282.0, 57.2887
23.127520375, 96.390, 3371.0, 58.0603
23.180041505, 96.390, 3351.0, 57.8878
23.232562636, 96.390, 3327.0, 57.6802
23.285083767, 96.390, 3391.0, 58.2323
23.337604898, 96.390, 3367.0, 58.0259
23.390126028, 96.390, 3353.0, 57.9051
23.442647159, 96.390, 3234.0, 56.8683
23.495168290, 96.390, 3266.0, 57.1489
23.547689420, 96.390, 3318.0, 57.6021
23.600210551, 96.390, 3304.0, 57.4804
23.652731682, 96.390, 3244.0, 56.9561
23.705252813, 96.390, 3278.0, 57.2538
23.757773943, 96.390, 3276.0, 57.2364
23.810295074, 96.390, 3351.0, 57.8878
23.862816205, 96.390, 3235.0, 56.8771
23.915337335, 96.390, 3337.0, 57.7668
23.967858466, 96.390, 3240.0, 56.9210
24.020379597, 96.390, 3320.0, 57.6194
24.072900727, 96.390, 3309.0, 57.5239
24.125421858, 96.390, 3167.0, 56.2761
24.177942989, 96.390, 3229.0, 56.8243
24.230464120, 96.390, 3283.0, 57.2975
24.282985250, 96.390, 3163.0, 56.2406
24.335506381, 96.390, 3176.0, 56.3560
24.388027512, 96.390, 3192.0, 56.4978
24.440548642, 96.390, 3282.0, 57.2887
24.493069773, 96.390, 3137.0, 56.0089
24.545590904, 96.390, 3099.0, 55.6687
24.598112035, 96.390, 3143.0, 56.0625
24.650633165, 96.390, 3080.0, 55.4977
24.703154296, 96.390, 3119.0, 55.8480
24.755675427, 96.390, 3183.0, 56.4181
24.808196557, 96.390, 3138.0, 56.0179
24.860717688, 96.390, 3159.0, 56.2050
24.913238819, 96.390, 3109.0, 55.7584
24.965759950, 96.390, 3206.0, 56.6216
25.018281080, 96.390, 3097.0, 55.6507
25.070802211, 96.390, 3130.0, 55.9464
25.123323342, 96.390, 3166.0, 56.2672
25.175844472, 96.390, 3074.0, 55.4437
25.228365603, 96.390, 3067.0, 55.3805
25.280886734, 96.390, 3052.0, 55.2449
25.333407864, 96.390, 3094.0, 55.6237
25.385928995, 96.390, 3018.0, 54.9363
25.438450126, 96.390, 3056.0, 55.2811
25.490971257, 96.390, 3049.0, 55.2178
25.543492387, 96.390, 3018.0, 54.9363
25.596013518, 96.390, 3027.0, 55.0182
25.648534649, 96.390, 2954.0, 54.3507
25.701055779, 96.390, 3084.0, 55.5338
25.753576910, 96.390, 2875.0, 53.6190
25.806098041, 96.390, 3039.0, 55.1271
25.858619172, 96.390, 2957.0, 54.3783
25.911140302, 96.390, 2849.0, 53.3760
25.963661433, 96.390, 2941.0, 54.2310
26.016182564, 96.390, 2908.0, 53.9259
26.068703694, 96.390, 3057.0, 55.2901
26.121224825, 96.390, 2920.0, 54.0370
26.173745956, 96.390, 2877.0, 53.6377
26.226267087, 96.390, 2943.0, 54.2494
26.278788217, 96.390, 2835.0, 53.2447
26.331309348, 96.390, 2827.0, 53.1695
26.383830479, 96.390, 2796.0, 52.8772
26.436351609, 96.390, 2845.0, 53.3385
26.488872740, 96.390, 2842.0, 53.3104
26.541393871, 96.390, 2933.0, 54.1572
26.593915002, 96.390, 2875.0, 53.6190
26.646436132, 96.390, 2808.0, 52.9906
26.698957263, 96.390, 2850.0, 53.3854
26.751478394, 96.390, 2774.0, 52.6688
26.803999524, 96.390, 2763.0, 52.5642
26.856520655, 96.390, 2777.0, 52.6972
26.909041786, 96.390, 2735.0, 52.2972
26.961562916, 96.390, 2788.0, 52.8015
27.014084047, 96.390, 2780.0, 52.7257
27.066605178, 96.390, 2755.0, 52.4881
27.119126309, 96.390, 2702.0, 51.9808
27.171647439, 96.390, 2673.0, 51.7011
27.224168570, 96.390, 2688.0, 51.8459
27.276689701, 96.390, 2791.0, 52.8299
27.329210831, 96.390, 2655.0, 51.5267
27.381731962, 96.390, 2623.0, 51.2152
27.434253093, 96.390, 2642.0, 51.4004
27.486774224, 96.390, 2724.0, 52.1920
27.539295354, 96.390, 2589.0, 50.8822
27.591816485, 96.390, 2684.0, 51.8073
27.644337616, 96.390, 2695.0, 51.9134
27.696858746, 96.390, 2600.0, 50.9902
27.749379877, 96.390, 2548.0, 50.4777
27.801901008, 96.390, 2629.0, 51.2738
27.854422139, 96.390, 2600.0, 50.9902
27.906943269, 96.390, 2564.0, 50.6360
27.959464400, 96.390, 2507.0, 50.0700
28.011985531, 96.390, 2617.0, 51.1566
28.064506661, 96.390, 2527.0, 50.2693
28.117027792, 96.390, 2582.0, 50.8134
28.169548923, 96.390, 2490.0, 49.8999
28.222070054, 96.390, 2583.0, 50.8232
28.274591184, 96.390, 2518.0, 50.1797
28.327112315, 96.390, 2382.0, 48.8057
28.379633446, 96.390, 2555.0, 50.5470
28.432154576, 96.390, 2533.0, 50.3289
28.484675707, 96.390, 2543.0, 50.4282
28.537196838, 96.390, 2423.0, 49.2240
28.589717968, 96.390, 2426.0, 49.2544
28.642239099, 96.390, 2405.0, 49.0408
28.694760230, 96.390, 2422.0, 49.2138
28.747281361, 96.390, 2353.0, 48.5077
28.799802491, 96.390, 2447.0, 49.4672
28.852323622, 96.390, 2393.0, 48.9183
28.904844753, 96.390, 2353.0, 48.5077
28.957365883, 96.390, 2378.0, 48.7647
29.009887014, 96.390, 2370.0, 48.6826
29.062408145, 96.390, 2302.0, 47.9792
29.114929276, 96.390, 2410.0, 49.0918
29.167450406, 96.390, 2381.0, 48.7955
29.219971537, 96.390, 2311.0, 48.0729
29.272492668, 96.390, 2424.0, 49.2341
29.325013798, 96.390, 2350.0, 48.4768
29.377534929, 96.390, 2329.0, 48.2597
29.430056060, 96.390, 2345.0, 48.4252
29.482577191, 96.390, 2276.0, 47.7074
29.535098321, 96.390, 2266.0, 47.6025
29.587619452, 96.390, 2336.0, 48.3322
29.640140583, 96.390, 2268.0, 47.6235
29.692661713, 96.390, 2220.0, 47.1169
29.745182844, 96.390, 2323.0, 48.1975
29.797703975, 96.390, 2217.0, 47.0850
29.850225105, 96.390, 2210.0, 47.0106
29.902746236, 96.390, 2201.0, 46.9148
29.955267367, 96.390, 2123.0, 46.0760
30.007788498, 96.390, 2258.0, 47.5184
30.060309628, 96.390, 2243.0, 47.3603
30.112830759, 96.390, 2161.0, 46.4866
30.165351890, 96.390, 2173.0, 46.6154
30.217873020, 96.390, 2205.0, 46.9574
30.270394151, 96.390, 2152.0, 46.3897
30.322915282, 96.390, 2057.0, 45.3542
30.375436413, 96.390, 2088.0, 45.6946
30.427957543, 96.390, 2166.0, 46.5403
30.480478674, 96.390, 2096.0, 45.7821
30.532999805, 96.390, 2120.0, 46.0435
30.585520935, 96.390, 2005.0, 44.7772
30.638042066, 96.390, 2111.0, 45.9456
30.690563197, 96.390, 2127.0, 46.1194
30.743084328, 96.390, 2029.0, 45.0444
30.795605458, 96.390, 2057.0, 45.3542
30.848126589, 96.390, 2035.0, 45.1110
30.900647720, 96.390, 2052.0, 45.2990
30.953168850, 96.390, 2112.0, 45.9565
31.005689981, 96.390, 2021.0, 44.9555
31.058211112, 96.390, 2071.0, 45.5082
31.110732243, 96.390, 2052.0, 45.2990
31.163253373, 96.390, 1989.0, 44.5982
31.215774504, 96.390, 2025.0, 45.0000
31.268295635, 96.390, 1982.0, 44.5197
31.320816765, 96.390, 1917.0, 43.7836
31.373337896, 96.390, 1906.0, 43.6578
31.425859027, 96.390, 1970.0, 44.3847
31.478380157, 96.390, 2001.0, 44.7325
31.530901288, 96.390, 1926.0, 43.8862
31.583422419, 96.390, 1947.0, 44.1248
31.635943550, 96.390, 1943.0, 44.0795
31.688464680, 96.390, 1974.0, 44.4297
31.740985811, 96.390, 2005.0, 44.7772
31.793506942, 96.390, 2006.0, 44.7884
31.846028072, 96.390, 1881.0, 43.3705
31.898549203, 96.390, 1900.0, 43.5890
31.951070334, 96.390, 1922.0, 43.8406
32.003591465, 96.390, 1974.0, 44.4297
32.056112595, 96.390, 1898.0, 43.5660
32.108633726, 96.390, 1873.0, 43.2782
32.161154857, 96.390, 1862.0, 43.1509
32.213675987, 96.390, 1948.0, 44.1362
32.266197118, 96.390, 1821.0, 42.6732
32.318718249, 96.390, 1851.0, 43.0232
32.371239380, 96.390, 1850.0, 43.0116
32.423760510, 96.390, 1930.0, 43.9318
32.476281641, 96.390, 1841.0, 42.9069
32.528802772, 96.390, 1808.0, 42.5206
32.581323902, 96.390, 1874.0, 43.2897
32.633845033, 96.390, 1847.0, 42.9767
32.686366164, 96.390, 1848.0, 42.9884
32.738887295, 96.390, 1840.0, 42.8952
32.791408425, 96.390, 1785.0, 42.2493
32.843929556, 96.390, 1861.0, 43.1393
32.896450687, 96.390, 1808.0, 42.5206
32.948971817, 96.390, 1788.0, 42.2847
33.001492948, 96.390, 1734.0, 41.6413
33.054014079, 96.390, 1824.0, 42.7083
33.106535209, 96.390, 1795.0, 42.3674
33.159056340, 96.390, 1810.0, 42.5441
33.211577471, 96.390, 1733.0, 41.6293
33.264098602, 96.390, 1679.0, 40.9756
33.316619732, 96.390, 1793.0, 42.3438
33.369140863, 96.390, 1730.0, 41.5933
33.421661994, 96.390, 1643.0, 40.5339
33.474183124, 96.390, 1726.0, 41.5452
33.526704255, 96.390, 1726.0, 41.5452
33.579225386, 96.390, 1671.0, 40.8779
33.631746517, 96.390, 1683.0, 41.0244
33.684267647, 96.390, 1711.0, 41.3642
33.736788778, 96.390, 1638.0, 40.4722
33.789309909, 96.390, 1595.0, 39.9375
33.841831039, 96.390, 1710.0, 41.3521
33.894352170, 96.390, 1606.0, 40.0749
33.946873301, 96.390, 1668.0, 40.8412
33.999394432, 96.390, 1557.0, 39.4588
34.051915562, 96.390, 1621.0, 40.2616
34.104436693, 96.390, 1644.0, 40.5463
34.156957824, 96.390, 1626.0, 40.3237
34.209478954, 96.390, 1619.0, 40.2368
34.262000085, 96.390, 1639.0, 40.4846
34.314521216, 96.390, 1616.0, 40.1995
34.367042346, 96.390, 1618.0, 40.2244
34.419563477, 96.390, 1612.0, 40.1497
34.472084608, 96.390, 1658.0, 40.7185
34.524605739, 96.390, 1618.0, 40.2244
34.577126869, 96.390, 1549.0, 39.3573
34.629648000, 96.390, 1604.0, 40.0500
34.682169131, 96.390, 1597.0, 39.9625
34.734690261, 96.390, 1523.0, 39.0256
34.787211392, 96.390, 1589.0, 39.8623
34.839732523, 96.390, 1524.0, 39.0384
34.892253654, 96.390, 1579.0, 39.7366
34.944774784, 96.390, 1582.0, 39.7744
34.997295915, 96.390, 1560.0, 39.4968
35.049817046, 96.390, 1494.0, 38.6523
35.102338176, 96.390, 1574.0, 39.6737
35.154859307, 96.390, 1600.0, 40.0000
35.207380438, 96.390, 1436.0, 37.8946
35.259901569, 96.390, 1468.0, 38.3145
35.312422699, 96.390, 1498.0, 38.7040
35.364943830, 96.390, 1500.0, 38.7298
35.417464961, 96.390, 1479.0, 38.4578
35.469986091, 96.390, 1457.0, 38.1707
35.522507222, 96.390, 1542.0, 39.2683
35.575028353, 96.390, 1437.0, 37.9078
35.627549484, 96.390, 1383.0, 37.1887
35.680070614, 96.390, 1492.0, 38.6264
35.732591745, 96.390, 1462.0, 38.2361
35.785112876, 96.390, 1427.0, 37.7757
35.837634006, 96.390, 1359.0, 36.8646
35.890155137, 96.390, 1404.0, 37.4700
35.942676268, 96.390, 1480.0, 38.4708
35.995197398, 96.390, 1441.0, 37.9605
36.047718529, 96.390, 1350.0, 36.7423
36.100239660, 96.390, 1491.0, 38.6135
36.152760791, 96.390, 1454.0, 38.1314
36.205281921, 96.390, 1481.0, 38.4838
36.257803052, 96.390, 1320.0, 36.3318
36.310324183, 96.390, 1396.0, 37.3631
36.362845313, 96.390, 1376.0, 37.0945
36.415366444, 96.390, 1403.0, 37.4566
36.467887575, 96.390, 1445.0, 38.0132
36.520408706, 96.390, 1446.0, 38.0263
36.572929836, 96.390, 1270.0, 35.6371
36.625450967, 96.390, 1294.0, 35.9722
36.677972098, 96.390, 1353.0, 36.7831
36.730493228, 96.390, 1333.0, 36.5103
36.783014359, 96.390, 1328.0, 36.4417
36.835535490, 96.390, 1339.0, 36.5923
36.888056621, 96.390, 1341.0, 36.6197
36.940577751, 96.390, 1369.0, 37.0000
36.993098882, 96.390, 1364.0, 36.9324
37.045620013, 96.390, 1330.0, 36.4692
37.098141143, 96.390, 1299.0, 36.0416
37.150662274, 96.390, 1325.0, 36.4005
37.203183405, 96.390, 1324.0, 36.3868
37.255704535, 96.390, 1290.0, 35.9166
37.308225666, 96.390, 1387.0, 37.2424
37.360746797, 96.390, 1269.0, 35.6230
37.413267928, 96.390, 1261.0, 35.5106
37.465789058, 96.390, 1287.0, 35.8748
37.518310189, 96.390, 1330.0, 36.4692
37.570831320, 96.390, 1293.0, 35.9583
37.623352450, 96.390, 1223.0, 34.9714
37.675873581, 96.390, 1280.0, 35.7771
37.728394712, 96.390, 1271.0, 35.6511
37.780915843, 96.390, 1274.0, 35.6931
37.833436973, 96.390, 1284.0, 35.8329
37.885958104, 96.390, 1207.0, 34.7419
37.938479235, 96.390, 1252.0, 35.3836
37.991000365, 96.390, 1266.0, 35.5809
38.043521496, 96.390, 1268.0, 35.6090
38.096042627, 96.390, 1247.0, 35.3129
38.148563758, 96.390, 1222.0, 34.9571
38.201084888, 96.390, 1238.0, 35.1852
38.253606019, 96.390, 1266.0, 35.5809
38.306127150, 96.390, 1242.0, 35.2420
38.358648280, 96.390, 1179.0, 34.3366
38.411169411, 96.390, 1208.0, 34.7563
38.463690542, 96.390, 1281.0, 35.7911
38.516211673, 96.390, 1253.0, 35.3977
38.568732803, 96.390, 1154.0, 33.9706
38.621253934, 96.390, 1236.0, 35.1568
38.673775065, 96.390, 1210.0, 34.7851
38.726296195, 96.390, 1209.0, 34.7707
38.778817326, 96.390, 1185.0, 34.4238
38.831338457, 96.390, 1221.0, 34.9428
38.883859587, 96.390, 1161.0, 34.0735
38.936380718, 96.390, 1217.0, 34.8855
38.988901849, 96.390, 1248.0, 35.3270
39.041422980, 96.390, 1166.0, 34.1467
39.093944110, 96.390, 1167.0, 34.1614
39.146465241, 96.390, 1214.0, 34.8425
39.198986372, 96.390, 1168.0, 34.1760
39.251507502, 96.390, 1155.0, 33.9853
39.304028633, 96.390, 1178.0, 34.3220
39.356549764, 96.390, 1142.0, 33.7935
39.409070895, 96.390, 1177.0, 34.3074
39.461592025, 96.390, 1171.0, 34.2199
39.514113156, 96.390, 1239.0, 35.1994
39.566634287, 96.390, 1157.0, 34.0147
39.619155417, 96.390, 1208.0, 34.7563
39.671676548, 96.390, 1189.0, 34.4819
39.724197679, 96.390, 1201.0, 34.6554
39.776718810, 96.390, 1203.0, 34.6843
39.829239940, 96.390, 1181.0, 34.3657
39.881761071, 96.390, 1156.0, 34.0000
39.934282202, 96.390, 1171.0, 34.2199
39.986803332, 96.390, 1172.0, 34.2345
40.039324463, 96.390, 1174.0, 34.2637
40.091845594, 96.390, 1191.0, 34.5109
40.144366725, 96.390, 1187.0, 34.4529
40.196887855, 96.390, 1105.0, 33.2415
40.249408986, 96.390, 1194.0, 34.5543
40.301930117, 96.390, 1239.0, 35.1994
40.354451247, 96.390, 1154.0, 33.9706
40.406972378, 96.390, 1222.0, 34.9571
40.459493509, 96.390, 1148.0, 33.8821
40.512014639, 96.390, 1186.0, 34.4384
40.564535770, 96.390, 1098.0, 33.1361
40.617056901, 96.390, 1091.0, 33.0303
40.669578032, 96.390, 1104.0, 33.2265
40.722099162, 96.390, 1137.0, 33.7194
40.774620293, 96.390, 1093.0, 33.0606
40.827141424, 96.390, 1129.0, 33.6006
40.879662554, 96.390, 1225.0, 35.0000
40.932183685, 96.390, 1143.0, 33.8083
40.984704816, 96.390, 1100.0, 33.1662
41.037225947, 96.390, 1137.0, 33.7194
41.089747077, 96.390, 1078.0, 32.8329
41.142268208, 96.390, 1190.0, 34.4964
41.194789339, 96.390, 1165.0, 34.1321
41.247310469, 96.390, 1131.0, 33.6303
41.299831600, 96.390, 1083.0, 32.9090
41.352352731, 96.390, 1139.0, 33.7491
41.404873862, 96.390, 1091.0, 33.0303
41.457394992, 96.390, 1065.0, 32.6343
41.509916123, 96.390, 1070.0, 32.7109
41.562437254, 96.390, 1101.0, 33.1813
41.614958384, 96.390, 1124.0, 33.5261
41.667479515, 96.390, 1102.0, 33.1964
41.720000646, 96.390, 1148.0, 33.8821
41.772521776, 96.390, 1139.0, 33.7491
41.825042907, 96.390, 1069.0, 32.6956
41.877564038, 96.390, 1139.0, 33.7491
41.930085169, 96.390, 1083.0, 32.9090
41.982606299, 96.390, 1069.0, 32.6956
42.035127430, 96.390, 1150.0, 33.9116
42.087648561, 96.390, 1083.0, 32.9090
42.140169691, 96.390, 1081.0, 32.8786
42.192690822, 96.390, 1145.0, 33.8378
42.245211953, 96.390, 1066.0, 32.6497
42.297733084, 96.390, 1127.0, 33.5708
42.350254214, 96.390, 1033.0, 32.1403
42.402775345, 96.390, 1109.0, 33.3017
42.455296476, 96.390, 1096.0, 33.1059
42.507817606, 96.390, 1061.0, 32.5730
42.560338737, 96.390, 1046.0, 32.3419
42.612859868, 96.390, 1147.0, 33.8674
42.665380999, 96.390, 1119.0, 33.4515
42.717902129, 96.390, 1080.0, 32.8634
42.770423260, 96.390, 1106.0, 33.2566
42.822944391, 96.390, 1043.0, 32.2955
42.875465521, 96.390, 1083.0, 32.9090
42.927986652, 96.390, 1031.0, 32.1092
42.980507783, 96.390, 1072.0, 32.7414
43.033028914, 96.390, 1118.0, 33.4365
43.085550044, 96.390, 1094.0, 33.0757
43.138071175, 96.390, 1024.0, 32.0000
43.190592306, 96.390, 1027.0, 32.0468
43.243113436, 96.390, 1061.0, 32.5730
43.295634567, 96.390, 1085.0, 32.9393
43.348155698, 96.390, 1050.0, 32.4037
43.400676828, 96.390, 1066.0, 32.6497
43.453197959, 96.390, 1107.0, 33.2716
43.505719090, 96.390, 1099.0, 33.1512
43.558240221, 96.390, 1146.0, 33.8526
43.610761351, 96.390, 1031.0, 32.1092
43.663282482, 96.390, 1075.0, 32.7872
43.715803613, 96.390, 1034.0, 32.1559
43.768324743, 96.390, 1079.0, 32.8481
43.820845874, 96.390, 1103.0, 33.2114
43.873367005, 96.390, 1055.0, 32.4808
43.925888136, 96.390, 1059.0, 32.5423
43.978409266, 96.390, 998.0, 31.5911
44.030930397, 96.390, 1078.0, 32.8329
44.083451528, 96.390, 1050.0, 32.4037
44.135972658, 96.390, 1040.0, 32.2490
44.188493789, 96.390, 978.0, 31.2730
44.241014920, 96.390, 1014.0, 31.8434
44.293536051, 96.390, 1073.0, 32.7567
44.346057181, 96.390, 996.0, 31.5595
44.398578312, 96.390, 1012.0, 31.8119
44.451099443, 96.390, 1031.0, 32.1092
44.503620573, 96.390, 1022.0, 31.9687
44.556141704, 96.390, 1021.0, 31.9531
44.608662835, 96.390, 1085.0, 32.9393
44.661183966, 96.390, 1035.0, 32.1714
44.713705096, 96.390, 1033.0, 32.1403
44.766226227, 96.390, 1015.0, 31.8591
44.818747358, 96.390, 997.0, 31.5753
44.871268488, 96.390, 993.0, 31.5119
44.923789619, 96.390, 1056.0, 32.4962
44.976310750, 96.390, 1001.0, 31.6386
45.028831880, 96.390, 988.0, 31.4325
45.081353011, 96.390, 1029.0, 32.0780
45.133874142, 96.390, 992.0, 31.4960
45.186395273, 96.390, 1017.0, 31.8904
45.238916403, 96.390, 1017.0, 31.8904
45.291437534, 96.390, 1020.0, 31.9374
45.343958665, 96.390, 1040.0, 32.2490
45.396479795, 96.390, 979.0, 31.2890
45.449000926, 96.390, 990.0, 31.4643
45.501522057, 96.390, 1020.0, 31.9374
45.554043188, 96.390, 990.0, 31.4643
45.606564318, 96.390, 1040.0, 32.2490
45.659085449, 96.390, 978.0, 31.2730
45.711606580, 96.390, 994.0, 31.5278
45.764127710, 96.390, 1061.0, 32.5730
45.816648841, 96.390, 1083.0, 32.9090
45.869169972, 96.390, 953.0, 30.8707
45.921691103, 96.390, 976.0, 31.2410
45.974212233, 96.390, 895.0, 29.9166
46.026733364, 96.390, 998.0, 31.5911
46.079254495, 96.390, 1002.0, 31.6544
46.131775625, 96.390, 995.0, 31.5436
46.184296756, 96.390, 969.0, 31.1288
46.236817887, 96.390, 986.0, 31.4006
46.289339017, 96.390, 971.0, 31.1609
46.341860148, 96.390, 970.0, 31.1448
46.394381279, 96.390, 964.0, 31.0483
46.446902410, 96.390, 972.0, 31.1769
46.499423540, 96.390, 945.0, 30.7409
46.551944671, 96.390, 946.0, 30.7571
46.604465802, 96.390, 986.0, 31.4006
46.656986932, 96.390, 948.0, 30.7896
46.709508063, 96.390, 955.0, 30.9031
46.762029194, 96.390, 934.0, 30.5614
46.814550325, 96.390, 1001.0, 31.6386
46.867071455, 96.390, 979.0, 31.2890
46.919592586, 96.390, 986.0, 31.4006
46.972113717, 96.390, 951.0, 30.8383
47.024634847, 96.390, 1031.0, 32.1092
47.077155978, 96.390, 981.0, 31.3209
47.129677109, 96.390, 964.0, 31.0483
47.182198240, 96.390, 936.0, 30.5941
47.234719370, 96.390, 994.0, 31.5278
47.287240501, 96.390, 936.0, 30.5941
47.339761632, 96.390, 967.0, 31.0966
47.392282762, 96.390, 930.0, 30.4959
47.444803893, 96.390, 990.0, 31.4643
47.497325024, 96.390, 900.0, 30.0000
47.549846155, 96.390, 929.0, 30.4795
47.602367285, 96.390, 924.0, 30.3974
47.654888416, 96.390, 962.0, 31.0161
47.707409547, 96.390, 961.0, 31.0000
47.759930677, 96.390, 964.0, 31.0483
47.812451808, 96.390, 958.0, 30.9516
47.864972939, 96.390, 979.0, 31.2890
47.917494069, 96.390, 975.0, 31.2250
47.970015200, 96.390, 904.0, 30.0666
48.022536331, 96.390, 917.0, 30.2820
48.075057462, 96.390, 973.0, 31.1929
48.127578592, 96.390, 912.0, 30.1993
48.180099723, 96.390, 951.0, 30.8383
48.232620854, 96.390, 917.0, 30.2820
48.285141984, 96.390, 958.0, 30.9516
48.337663115, 96.390, 957.0, 30.9354
48.390184246, 96.390, 894.0, 29.8998
48.442705377, 96.390, 876.0, 29.5973
48.495226507, 96.390, 831.0, 28.8271
48.547747638, 96.390, 966.0, 31.0805
48.600268769, 96.390, 958.0, 30.9516
48.652789899, 96.390, 910.0, 30.1662
48.705311030, 96.390, 902.0, 30.0333
48.757832161, 96.390, 958.0, 30.9516
48.810353292, 96.390, 957.0, 30.9354
48.862874422, 96.390, 929.0, 30.4795
48.915395553, 96.390, 886.0, 29.7658
48.967916684, 96.390, 922.0, 30.3645
49.020437814, 96.390, 896.0, 29.9333
49.072958945, 96.390, 898.0, 29.9666
49.125480076, 96.390, 944.0, 30.7246
49.178001207, 96.390, 882.0, 29.6985
49.230522337, 96.390, 850.0, 29.1548
49.283043468, 96.390, 851.0, 29.1719
49.335564599, 96.390, 900.0, 30.0000
49.388085729, 96.390, 932.0, 30.5287
49.440606860, 96.390, 935.0, 30.5778
49.493127991, 96.390, 918.0, 30.2985
49.545649121, 96.390, 962.0, 31.0161
49.598170252, 96.390, 886.0, 29.7658
49.650691383, 96.390, 895.0, 29.9166
49.703212514, 96.390, 884.0, 29.7321
49.755733644, 96.390, 935.0, 30.5778
49.808254775, 96.390, 876.0, 29.5973
49.860775906, 96.390, 892.0, 29.8664
49.913297036, 96.390, 947.0, 30.7734
49.965818167, 96.390, 853.0, 29.2062
50.018339298, 96.390, 894.0, 29.8998
50.070860429, 96.390, 911.0, 30.1828
50.123381559, 96.390, 924.0, 30.3974
50.175902690, 96.390, 894.0, 29.8998
50.228423821, 96.390, 926.0, 30.4302
50.280944951, 96.390, 897.0, 29.9500
50.333466082, 96.390, 896.0, 29.9333
50.385987213, 96.390, 912.0, 30.1993
50.438508344, 96.390, 880.0, 29.6648
50.491029474, 96.390, 869.0, 29.4788
50.543550605, 96.390, 892.0, 29.8664
50.596071736, 96.390, 882.0, 29.6985
50.648592866, 96.390, 869.0, 29.4788
50.701113997, 96.390, 869.0, 29.4788
50.753635128, 96.390, 933.0, 30.5450
50.806156258, 96.390, 937.0, 30.6105
50.858677389, 96.390, 860.0, 29.3258
50.911198520, 96.390, 895.0, 29.9166
50.963719651, 96.390, 951.0, 30.8383
51.016240781, 96.390, 929.0, 30.4795
51.068761912, 96.390, 887.0, 29.7825
51.121283043, 96.390, 840.0, 28.9828
51.173804173, 96.390, 899.0, 29.9833
51.226325304, 96.390, 878.0, 29.6311
51.278846435, 96.390, 862.0, 29.3598
51.331367566, 96.390, 824.0, 28.7054
51.383888696, 96.390, 900.0, 30.0000
51.436409827, 96.390, 844.0, 29.0517
51.488930958, 96.390, 892.0, 29.8664
51.541452088, 96.390, 876.0, 29.5973
51.593973219, 96.390, 915.0, 30.2490
51.646494350, 96.390, 880.0, 29.6648
51.699015481, 96.390, 916.0, 30.2655
51.751536611, 96.390, 924.0, 30.3974
51.804057742, 96.390, 849.0, 29.1376
51.856578873, 96.390, 855.0, 29.2404
51.909100003, 96.390, 914.0, 30.2324
51.961621134, 96.390, 882.0, 29.6985
52.014142265, 96.390, 886.0, 29.7658
52.066663396, 96.390, 925.0, 30.4138
52.119184526, 96.390, 917.0, 30.2820
52.171705657, 96.390, 925.0, 30.4138
52.224226788, 96.390, 845.0, 29.0689
52.276747918, 96.390, 897.0, 29.9500
52.329269049, 96.390, 876.0, 29.5973
52.381790180, 96.390, 870.0, 29.4958
52.434311310, 96.390, 900.0, 30.0000
52.486832441, 96.390, 872.0, 29.5296
52.539353572, 96.390, 844.0, 29.0517
52.591874703, 96.390, 847.0, 29.1033
52.644395833, 96.390, 860.0, 29.3258
52.696916964, 96.390, 848.0, 29.1204
52.749438095, 96.390, 906.0, 30.0998
52.801959225, 96.390, 851.0, 29.1719
52.854480356, 96.390, 892.0, 29.8664
52.907001487, 96.390, 875.0, 29.5804
52.959522618, 96.390, 837.0, 28.9310
53.012043748, 96.390, 861.0, 29.3428
53.064564879, 96.390, 838.0, 28.9482
53.117086010, 96.390, 846.0, 29.0861
53.169607140, 96.390, 908.0, 30.1330
53.222128271, 96.390, 835.0, 28.8964
53.274649402, 96.390, 937.0, 30.6105
53.327170533, 96.390, 849.0, 29.1376
53.379691663, 96.390, 843.0, 29.0345
53.432212794, 96.390, 882.0, 29.6985
53.484733925, 96.390, 835.0, 28.8964
53.537255055, 96.390, 829.0, 28.7924
53.589776186, 96.390, 858.0, 29.2916
53.642297317, 96.390, 824.0, 28.7054
53.694818448, 96.390, 860.0, 29.3258
53.747339578, 96.390, 929.0, 30.4795
53.799860709, 96.390, 929.0, 30.4795
53.852381840, 96.390, 830.0, 28.8097
53.904902970, 96.390, 858.0, 29.2916
53.957424101, 96.390, 842.0, 29.0172
54.009945232, 96.390, 864.0, 29.3939
54.062466362, 96.390, 861.0, 29.3428
54.114987493, 96.390, 872.0, 29.5296
54.167508624, 96.390, 830.0, 28.8097
54.220029755, 96.390, 810.0, 28.4605
54.272550885, 96.390, 874.0, 29.5635
54.325072016, 96.390, 833.0, 28.8617
54.377593147, 96.390, 900.0, 30.0000
54.430114277, 96.390, 876.0, 29.5973
54.482635408, 96.390, 844.0, 29.0517
54.535156539, 96.390, 825.0, 28.7228
54.587677670, 96.390, 874.0, 29.5635
54.640198800, 96.390, 860.0, 29.3258
54.692719931, 96.390, 831.0, 28.8271
54.745241062, 96.390, 862.0, 29.3598
54.797762192, 96.390, 875.0, 29.5804
54.850283323, 96.390, 878.0, 29.6311
54.902804454, 96.390, 825.0, 28.7228
54.955325585, 96.390, 862.0, 29.3598
55.007846715, 96.390, 891.0, 29.8496
55.060367846, 96.390, 826.0, 28.7402
55.112888977, 96.390, 861.0, 29.3428
55.165410107, 96.390, 822.0, 28.6705
55.217931238, 96.390, 901.0, 30.0167
55.270452369, 96.390, 902.0, 30.0333
55.322973499, 96.390, 870.0, 29.4958
55.375494630, 96.390, 887.0, 29.7825
55.428015761, 96.390, 844.0, 29.0517
55.480536892, 96.390, 821.0, 28.6531
55.533058022, 96.390, 886.0, 29.7658
55.585579153, 96.390, 827.0, 28.7576
55.638100284, 96.390, 909.0, 30.1496
55.690621414, 96.390, 880.0, 29.6648
55.743142545, 96.390, 841.0, 29.0000
55.795663676, 96.390, 859.0, 29.3087
55.848184807, 96.390, 849.0, 29.1376
55.900705937, 96.390, 903.0, 30.0500
55.953227068, 96.390, 887.0, 29.7825
56.005748199, 96.390, 794.0, 28.1780
56.058269329, 96.390, 920.0, 30.3315
56.110790460, 96.390, 846.0, 29.0861
56.163311591, 96.390, 872.0, 29.5296
56.215832722, 96.390, 836.0, 28.9137
56.268353852, 96.390, 902.0, 30.0333
56.320874983, 96.390, 866.0, 29.4279
56.373396114, 96.390, 851.0, 29.1719
56.425917244, 96.390, 811.0, 28.4781
56.478438375, 96.390, 858.0, 29.2916
56.530959506, 96.390, 869.0, 29.4788
56.583480637, 96.390, 852.0, 29.1890
56.636001767, 96.390, 845.0, 29.0689
56.688522898, 96.390, 886.0, 29.7658
56.741044029, 96.390, 943.0, 30.7083
56.793565159, 96.390, 894.0, 29.8998
56.846086290, 96.390, 894.0, 29.8998
56.898607421, 96.390, 856.0, 29.2575
56.951128551, 96.390, 898.0, 29.9666
57.003649682, 96.390, 868.0, 29.4618
57.056170813, 96.390, 887.0, 29.7825
57.108691944, 96.390, 822.0, 28.6705
57.161213074, 96.390, 856.0, 29.2575
57.213734205, 96.390, 869.0, 29.4788
57.266255336, 96.390, 900.0, 30.0000
57.318776466, 96.390, 903.0, 30.0500
57.371297597, 96.390, 889.0, 29.8161
57.423818728, 96.390, 899.0, 29.9833
57.476339859, 96.390, 853.0, 29.2062
57.528860989, 96.390, 886.0, 29.7658
57.581382120, 96.390, 830.0, 28.8097
57.633903251, 96.390, 862.0, 29.3598
57.686424381, 96.390, 885.0, 29.7489
57.738945512, 96.390, 873.0, 29.5466
57.791466643, 96.390, 864.0, 29.3939
57.843987774, 96.390, 837.0, 28.9310
57.896508904, 96.390, 899.0, 29.9833
57.949030035, 96.390, 877.0, 29.6142
58.001551166, 96.390, 889.0, 29.8161
58.054072296, 96.390, 928.0, 30.4631
58.106593427, 96.390, 909.0, 30.1496
58.159114558, 96.390, 858.0, 29.2916
58.211635689, 96.390, 876.0, 29.5973
58.264156819, 96.390, 855.0, 29.2404
58.316677950, 96.390, 875.0, 29.5804
58.369199081, 96.390, 909.0, 30.1496
58.421720211, 96.390, 886.0, 29.7658
58.474241342, 96.390, 867.0, 29.4449
58.526762473, 96.390, 878.0, 29.6311
58.579283603, 96.390, 879.0, 29.6479
58.631804734, 96.390, 871.0, 29.5127
58.684325865, 96.390, 878.0, 29.6311
58.736846996, 96.390, 856.0, 29.2575
58.789368126, 96.390, 877.0, 29.6142
58.841889257, 96.390, 911.0, 30.1828
58.894410388, 96.390, 856.0, 29.2575
58.946931518, 96.390, 889.0, 29.8161
58.999452649, 96.390, 875.0, 29.5804
59.051973780, 96.390, 885.0, 29.7489
59.104494911, 96.390, 882.0, 29.6985
59.157016041, 96.390, 840.0, 28.9828
59.209537172, 96.390, 819.0, 28.6182
59.262058303, 96.390, 877.0, 29.6142
59.314579433, 96.390, 848.0, 29.1204
59.367100564, 96.390, 852.0, 29.1890
59.419621695, 96.390, 899.0, 29.9833
59.472142826, 96.390, 868.0, 29.4618
59.524663956, 96.390, 830.0, 28.8097
59.577185087, 96.390, 924.0, 30.3974
59.629706218, 96.390, 943.0, 30.7083
59.682227348, 96.390, 865.0, 29.4109
59.734748479, 96.390, 858.0, 29.2916
59.787269610, 96.390, 855.0, 29.2404
59.839790740, 96.390, 855.0, 29.2404
59.892311871, 96.390, 900.0, 30.0000
59.944833002, 96.390, 854.0, 29.2233
59.997354133, 96.390, 865.0, 29.4109
60.049875263, 96.390, 856.0, 29.2575
60.102396394, 96.390, 915.0, 30.2490
60.154917525, 96.390, 871.0, 29.5127
60.207438655, 96.390, 876.0, 29.5973
60.259959786, 96.390, 913.0, 30.2159
60.312480917, 96.390, 873.0, 29.5466
60.365002048, 96.390, 877.0, 29.6142
60.417523178, 96.390, 850.0, 29.1548
60.470044309, 96.390, 892.0, 29.8664
60.522565440, 96.390, 896.0, 29.9333
60.575086570, 96.390, 896.0, 29.9333
60.627607701, 96.390, 912.0, 30.1993
60.680128832, 96.390, 915.0, 30.2490
60.732649963, 96.390, 876.0, 29.5973
60.785171093, 96.390, 876.0, 29.5973
60.837692224, 96.390, 911.0, 30.1828
60.890213355, 96.390, 839.0, 28.9655
60.942734485, 96.390, 846.0, 29.0861
60.995255616, 96.390, 951.0, 30.8383
61.047776747, 96.390, 868.0, 29.4618
61.100297878, 96.390, 918.0, 30.2985
61.152819008, 96.390, 907.0, 30.1164
61.205340139, 96.390, 891.0, 29.8496
61.257861270, 96.390, 864.0, 29.3939
61.310382400, 96.390, 951.0, 30.8383
61.362903531, 96.390, 888.0, 29.7993
61.415424662, 96.390, 881.0, 29.6816
61.467945792, 96.390, 870.0, 29.4958
61.520466923, 96.390, 871.0, 29.5127
61.572988054, 96.390, 901.0, 30.0167
61.625509185, 96.390, 869.0, 29.4788
61.678030315, 96.390, 881.0, 29.6816
61.730551446, 96.390, 925.0, 30.4138
61.783072577, 96.390, 912.0, 30.1993
61.835593707, 96.390, 882.0, 29.6985
61.888114838, 96.390, 841.0, 29.0000
61.940635969, 96.390, 900.0, 30.0000
61.993157100, 96.390, 918.0, 30.2985
62.045678230, 96.390, 897.0, 29.9500
62.098199361, 96.390, 877.0, 29.6142
62.150720492, 96.390, 882.0, 29.6985
62.203241622, 96.390, 864.0, 29.3939
62.255762753, 96.390, 895.0, 29.9166
62.308283884, 96.390, 873.0, 29.5466
62.360805015, 96.390, 885.0, 29.7489
62.413326145, 96.390, 847.0, 29.1033
62.465847276, 96.390, 880.0, 29.6648
62.518368407, 96.390, 962.0, 31.0161
62.570889537, 96.390, 875.0, 29.5804
62.623410668, 96.390, 913.0, 30.2159
62.675931799, 96.390, 872.0, 29.5296
62.728452930, 96.390, 897.0, 29.9500
62.780974060, 96.390, 889.0, 29.8161
62.833495191, 96.390, 908.0, 30.1330
62.886016322, 96.390, 836.0, 28.9137
62.938537452, 96.390, 917.0, 30.2820
62.991058583, 96.390, 861.0, 29.3428
63.043579714, 96.390, 860.0, 29.3258
63.096100844, 96.390, 879.0, 29.6479
63.148621975, 96.390, 895.0, 29.9166
63.201143106, 96.390, 861.0, 29.3428
63.253664237, 96.390, 883.0, 29.7153
63.306185367, 96.390, 926.0, 30.4302
63.358706498, 96.390, 849.0, 29.1376
63.411227629, 96.390, 840.0, 28.9828
63.463748759, 96.390, 856.0, 29.2575
63.516269890, 96.390, 905.0, 30.0832
63.568791021, 96.390, 887.0, 29.7825
63.621312152, 96.390, 866.0, 29.4279
63.673833282, 96.390, 927.0, 30.4467
63.726354413, 96.390, 874.0, 29.5635
63.778875544, 96.390, 850.0, 29.1548
63.831396674, 96.390, 919.0, 30.3150
63.883917805, 96.390, 837.0, 28.9310
63.936438936, 96.390, 876.0, 29.5973
63.988960067, 96.390, 872.0, 29.5296
64.041481197, 96.390, 858.0, 29.2916
64.094002328, 96.390, 816.0, 28.5657
64.146523459, 96.390, 888.0, 29.7993
64.199044589, 96.390, 878.0, 29.6311
64.251565720, 96.390, 866.0, 29.4279
64.304086851, 96.390, 869.0, 29.4788
64.356607981, 96.390, 862.0, 29.3598
64.409129112, 96.390, 882.0, 29.6985
64.461650243, 96.390, 885.0, 29.7489
64.514171374, 96.390, 888.0, 29.7993
64.566692504, 96.390, 884.0, 29.7321
64.619213635, 96.390, 898.0, 29.9666
64.671734766, 96.390, 925.0, 30.4138
64.724255896, 96.390, 865.0, 29.4109
64.776777027, 96.390, 836.0, 28.9137
64.829298158, 96.390, 821.0, 28.6531
64.881819289, 96.390, 840.0, 28.9828
64.934340419, 96.390, 814.0, 28.5307
64.986861550, 96.390, 847.0, 29.1033