File: Files_organized_for_plots/PC/XRD_PC_MgAxialPrecursor24Jan22_B2_1.csv
[Measurement conditions]
Sample identification,XRD_MgAxialPrecursor24Jan22_B2_1
Comment - 1,"Configuration=Stage for Flat Samples/Holders, Owner=User-1, Creation date=7/1/2020 9:53:24 AM"
Comment - 2,"Goniometer=Theta/Theta; Minimum step size 2Theta:0.0001; Minimum step size Omega:0.0001"
Comment - 3,"Sample stage=Stage for flat samples/holders"
Comment - 4,"Diffractometer system=EMPYREAN"
Comment - 5,"Measurement program=C:\Users\ibo5034\OneDrive - The Pennsylvania State University\NEUP - Reed, Titus's files\XRD\Cement\Zerobackground scan.xrdmp, Identifier={98A3B11C-88F9-4AA6-982C-73314A311EF5}"
Anode material,Cu
K-Alpha1 wavelength,1.5405980
K-Alpha2 wavelength,1.5444260
Ratio K-Alpha2/K-Alpha1,0.500
Divergence slit,Fixed,0.25
Monochromator used,NO
Generator voltage, 45
Tube current, 40
File date and time,10/Mar/2022 13:35
Unit cell,
h k l, 0 0 0
Scan axis,Gonio
Scan range,4.994599997,64.999991833
Scan step size,0.0262606
No. of points, 2285
Scan type,CONTINUOUS
Time per step,96.390
[Scan points]
Angle, TimePerStep, Intensity, ESD
5.007730280, 96.390, 4642.0, 68.1322
5.060251411, 96.390, 4653.0, 68.2129
5.112772541, 96.390, 4441.0, 66.6408
5.165293672, 96.390, 4433.0, 66.5808
5.217814803, 96.390, 4353.0, 65.9773
5.270335934, 96.390, 4146.0, 64.3894
5.322857064, 96.390, 4300.0, 65.5744
5.375378195, 96.390, 4193.0, 64.7534
5.427899326, 96.390, 3975.0, 63.0476
5.480420456, 96.390, 3979.0, 63.0793
5.532941587, 96.390, 3940.0, 62.7694
5.585462718, 96.390, 3867.0, 62.1852
5.637983849, 96.390, 3909.0, 62.5220
5.690504979, 96.390, 3858.0, 62.1128
5.743026110, 96.390, 3831.0, 61.8951
5.795547241, 96.390, 3912.0, 62.5460
5.848068371, 96.390, 3711.0, 60.9180
5.900589502, 96.390, 3773.0, 61.4248
5.953110633, 96.390, 3788.0, 61.5467
6.005631763, 96.390, 3610.0, 60.0833
6.058152894, 96.390, 3511.0, 59.2537
6.110674025, 96.390, 3696.0, 60.7947
6.163195156, 96.390, 3450.0, 58.7367
6.215716286, 96.390, 3571.0, 59.7578
6.268237417, 96.390, 3543.0, 59.5231
6.320758548, 96.390, 3558.0, 59.6490
6.373279678, 96.390, 3470.0, 58.9067
6.425800809, 96.390, 3379.0, 58.1292
6.478321940, 96.390, 3347.0, 57.8533
6.530843071, 96.390, 3339.0, 57.7841
6.583364201, 96.390, 3409.0, 58.3866
6.635885332, 96.390, 3291.0, 57.3672
6.688406463, 96.390, 3274.0, 57.2189
6.740927593, 96.390, 3412.0, 58.4123
6.793448724, 96.390, 3317.0, 57.5934
6.845969855, 96.390, 3204.0, 56.6039
6.898490986, 96.390, 3210.0, 56.6569
6.951012116, 96.390, 3185.0, 56.4358
7.003533247, 96.390, 3135.0, 55.9911
7.056054378, 96.390, 3304.0, 57.4804
7.108575508, 96.390, 3242.0, 56.9386
7.161096639, 96.390, 3121.0, 55.8659
7.213617770, 96.390, 3070.0, 55.4076
7.266138900, 96.390, 3191.0, 56.4889
7.318660031, 96.390, 3208.0, 56.6392
7.371181162, 96.390, 3099.0, 55.6687
7.423702293, 96.390, 3089.0, 55.5788
7.476223423, 96.390, 3046.0, 55.1906
7.528744554, 96.390, 3066.0, 55.3715
7.581265685, 96.390, 3075.0, 55.4527
7.633786815, 96.390, 3072.0, 55.4256
7.686307946, 96.390, 3059.0, 55.3082
7.738829077, 96.390, 2978.0, 54.5711
7.791350208, 96.390, 3013.0, 54.8908
7.843871338, 96.390, 2973.0, 54.5252
7.896392469, 96.390, 2884.0, 53.7029
7.948913600, 96.390, 2976.0, 54.5527
8.001434730, 96.390, 2850.0, 53.3854
8.053955861, 96.390, 2929.0, 54.1202
8.106476992, 96.390, 2905.0, 53.8981
8.158998123, 96.390, 2936.0, 54.1849
8.211519253, 96.390, 2884.0, 53.7029
8.264040384, 96.390, 2873.0, 53.6004
8.316561515, 96.390, 2803.0, 52.9434
8.369082645, 96.390, 2900.0, 53.8516
8.421603776, 96.390, 2862.0, 53.4977
8.474124907, 96.390, 2859.0, 53.4696
8.526646038, 96.390, 2763.0, 52.5642
8.579167168, 96.390, 2809.0, 53.0000
8.631688299, 96.390, 2862.0, 53.4977
8.684209430, 96.390, 2815.0, 53.0566
8.736730560, 96.390, 2809.0, 53.0000
8.789251691, 96.390, 2702.0, 51.9808
8.841772822, 96.390, 2846.0, 53.3479
8.894293952, 96.390, 2728.0, 52.2303
8.946815083, 96.390, 2719.0, 52.1440
8.999336214, 96.390, 2738.0, 52.3259
9.051857345, 96.390, 2702.0, 51.9808
9.104378475, 96.390, 2759.0, 52.5262
9.156899606, 96.390, 2697.0, 51.9326
9.209420737, 96.390, 2789.0, 52.8110
9.261941867, 96.390, 2728.0, 52.2303
9.314462998, 96.390, 2698.0, 51.9423
9.366984129, 96.390, 2708.0, 52.0384
9.419505260, 96.390, 2649.0, 51.4684
9.472026390, 96.390, 2641.0, 51.3907
9.524547521, 96.390, 2671.0, 51.6817
9.577068652, 96.390, 2635.0, 51.3323
9.629589782, 96.390, 2599.0, 50.9804
9.682110913, 96.390, 2651.0, 51.4879
9.734632044, 96.390, 2635.0, 51.3323
9.787153175, 96.390, 2577.0, 50.7642
9.839674305, 96.390, 2486.0, 49.8598
9.892195436, 96.390, 2531.0, 50.3090
9.944716567, 96.390, 2545.0, 50.4480
9.997237697, 96.390, 2590.0, 50.8920
10.049758828, 96.390, 2538.0, 50.3786
10.102279959, 96.390, 2524.0, 50.2394
10.154801090, 96.390, 2503.0, 50.0300
10.207322220, 96.390, 2558.0, 50.5767
10.259843351, 96.390, 2492.0, 49.9199
10.312364482, 96.390, 2524.0, 50.2394
10.364885612, 96.390, 2425.0, 49.2443
10.417406743, 96.390, 2545.0, 50.4480
10.469927874, 96.390, 2463.0, 49.6286
10.522449004, 96.390, 2479.0, 49.7896
10.574970135, 96.390, 2407.0, 49.0612
10.627491266, 96.390, 2501.0, 50.0100
10.680012397, 96.390, 2398.0, 48.9694
10.732533527, 96.390, 2391.0, 48.8979
10.785054658, 96.390, 2386.0, 48.8467
10.837575789, 96.390, 2355.0, 48.5283
10.890096919, 96.390, 2431.0, 49.3052
10.942618050, 96.390, 2327.0, 48.2390
10.995139181, 96.390, 2389.0, 48.8774
11.047660312, 96.390, 2317.0, 48.1352
11.100181442, 96.390, 2398.0, 48.9694
11.152702573, 96.390, 2390.0, 48.8876
11.205223704, 96.390, 2393.0, 48.9183
11.257744834, 96.390, 2395.0, 48.9387
11.310265965, 96.390, 2305.0, 48.0104
11.362787096, 96.390, 2299.0, 47.9479
11.415308227, 96.390, 2299.0, 47.9479
11.467829357, 96.390, 2355.0, 48.5283
11.520350488, 96.390, 2277.0, 47.7179
11.572871619, 96.390, 2306.0, 48.0208
11.625392749, 96.390, 2322.0, 48.1871
11.677913880, 96.390, 2359.0, 48.5695
11.730435011, 96.390, 2324.0, 48.2079
11.782956141, 96.390, 2214.0, 47.0532
11.835477272, 96.390, 2311.0, 48.0729
11.887998403, 96.390, 2251.0, 47.4447
11.940519534, 96.390, 2250.0, 47.4342
11.993040664, 96.390, 2216.0, 47.0744
12.045561795, 96.390, 2251.0, 47.4447
12.098082926, 96.390, 2174.0, 46.6262
12.150604056, 96.390, 2227.0, 47.1911
12.203125187, 96.390, 2246.0, 47.3920
12.255646318, 96.390, 2219.0, 47.1063
12.308167449, 96.390, 2195.0, 46.8508
12.360688579, 96.390, 2179.0, 46.6798
12.413209710, 96.390, 2201.0, 46.9148
12.465730841, 96.390, 2131.0, 46.1628
12.518251971, 96.390, 2162.0, 46.4973
12.570773102, 96.390, 2194.0, 46.8402
12.623294233, 96.390, 2211.0, 47.0213
12.675815364, 96.390, 2170.0, 46.5833
12.728336494, 96.390, 2183.0, 46.7226
12.780857625, 96.390, 2086.0, 45.6727
12.833378756, 96.390, 2117.0, 46.0109
12.885899886, 96.390, 2064.0, 45.4313
12.938421017, 96.390, 2093.0, 45.7493
12.990942148, 96.390, 2110.0, 45.9347
13.043463279, 96.390, 2035.0, 45.1110
13.095984409, 96.390, 2140.0, 46.2601
13.148505540, 96.390, 2098.0, 45.8039
13.201026671, 96.390, 2056.0, 45.3431
13.253547801, 96.390, 2134.0, 46.1952
13.306068932, 96.390, 2095.0, 45.7712
13.358590063, 96.390, 2001.0, 44.7325
13.411111193, 96.390, 2016.0, 44.8999
13.463632324, 96.390, 2025.0, 45.0000
13.516153455, 96.390, 2000.0, 44.7214
13.568674586, 96.390, 2034.0, 45.0999
13.621195716, 96.390, 2069.0, 45.4863
13.673716847, 96.390, 2067.0, 45.4643
13.726237978, 96.390, 2111.0, 45.9456
13.778759108, 96.390, 2041.0, 45.1774
13.831280239, 96.390, 1955.0, 44.2154
13.883801370, 96.390, 1888.0, 43.4511
13.936322501, 96.390, 2014.0, 44.8776
13.988843631, 96.390, 2074.0, 45.5412
14.041364762, 96.390, 2080.0, 45.6070
14.093885893, 96.390, 1970.0, 44.3847
14.146407023, 96.390, 2041.0, 45.1774
14.198928154, 96.390, 2030.0, 45.0555
14.251449285, 96.390, 1940.0, 44.0454
14.303970416, 96.390, 1996.0, 44.6766
14.356491546, 96.390, 1994.0, 44.6542
14.409012677, 96.390, 1976.0, 44.4522
14.461533808, 96.390, 1955.0, 44.2154
14.514054938, 96.390, 2050.0, 45.2769
14.566576069, 96.390, 2113.0, 45.9674
14.619097200, 96.390, 2048.0, 45.2548
14.671618331, 96.390, 1936.0, 44.0000
14.724139461, 96.390, 1861.0, 43.1393
14.776660592, 96.390, 1989.0, 44.5982
14.829181723, 96.390, 2011.0, 44.8442
14.881702853, 96.390, 1943.0, 44.0795
14.934223984, 96.390, 1925.0, 43.8748
14.986745115, 96.390, 1961.0, 44.2832
15.039266245, 96.390, 1946.0, 44.1135
15.091787376, 96.390, 1973.0, 44.4185
15.144308507, 96.390, 2058.0, 45.3652
15.196829638, 96.390, 1972.0, 44.4072
15.249350768, 96.390, 1962.0, 44.2945
15.301871899, 96.390, 1962.0, 44.2945
15.354393030, 96.390, 1884.0, 43.4051
15.406914160, 96.390, 1875.0, 43.3013
15.459435291, 96.390, 1889.0, 43.4626
15.511956422, 96.390, 1928.0, 43.9090
15.564477553, 96.390, 1950.0, 44.1588
15.616998683, 96.390, 1969.0, 44.3734
15.669519814, 96.390, 1983.0, 44.5309
15.722040945, 96.390, 1925.0, 43.8748
15.774562075, 96.390, 1889.0, 43.4626
15.827083206, 96.390, 1907.0, 43.6692
15.879604337, 96.390, 1960.0, 44.2719
15.932125468, 96.390, 2045.0, 45.2217
15.984646598, 96.390, 1984.0, 44.5421
16.037167729, 96.390, 1949.0, 44.1475
16.089688860, 96.390, 1865.0, 43.1856
16.142209990, 96.390, 1979.0, 44.4860
16.194731121, 96.390, 1892.0, 43.4971
16.247252252, 96.390, 1883.0, 43.3935
16.299773382, 96.390, 2014.0, 44.8776
16.352294513, 96.390, 1869.0, 43.2319
16.404815644, 96.390, 2016.0, 44.8999
16.457336775, 96.390, 1929.0, 43.9204
16.509857905, 96.390, 2014.0, 44.8776
16.562379036, 96.390, 1932.0, 43.9545
16.614900167, 96.390, 1886.0, 43.4281
16.667421297, 96.390, 1985.0, 44.5533
16.719942428, 96.390, 1905.0, 43.6463
16.772463559, 96.390, 1946.0, 44.1135
16.824984690, 96.390, 2049.0, 45.2659
16.877505820, 96.390, 2022.0, 44.9667
16.930026951, 96.390, 1970.0, 44.3847
16.982548082, 96.390, 2013.0, 44.8665
17.035069212, 96.390, 1978.0, 44.4747
17.087590343, 96.390, 1961.0, 44.2832
17.140111474, 96.390, 2069.0, 45.4863
17.192632605, 96.390, 1966.0, 44.3396
17.245153735, 96.390, 1941.0, 44.0568
17.297674866, 96.390, 2013.0, 44.8665
17.350195997, 96.390, 1990.0, 44.6094
17.402717127, 96.390, 2027.0, 45.0222
17.455238258, 96.390, 1956.0, 44.2267
17.507759389, 96.390, 1930.0, 43.9318
17.560280520, 96.390, 1991.0, 44.6206
17.612801650, 96.390, 1989.0, 44.5982
17.665322781, 96.390, 1941.0, 44.0568
17.717843912, 96.390, 2031.0, 45.0666
17.770365042, 96.390, 1978.0, 44.4747
17.822886173, 96.390, 2100.0, 45.8258
17.875407304, 96.390, 2040.0, 45.1664
17.927928434, 96.390, 2043.0, 45.1996
17.980449565, 96.390, 2065.0, 45.4423
18.032970696, 96.390, 2128.0, 46.1303
18.085491827, 96.390, 2040.0, 45.1664
18.138012957, 96.390, 2082.0, 45.6289
18.190534088, 96.390, 2015.0, 44.8888
18.243055219, 96.390, 2075.0, 45.5522
18.295576349, 96.390, 2185.0, 46.7440
18.348097480, 96.390, 2049.0, 45.2659
18.400618611, 96.390, 2128.0, 46.1303
18.453139742, 96.390, 2148.0, 46.3465
18.505660872, 96.390, 2114.0, 45.9783
18.558182003, 96.390, 2107.0, 45.9021
18.610703134, 96.390, 2118.0, 46.0217
18.663224264, 96.390, 2088.0, 45.6946
18.715745395, 96.390, 2134.0, 46.1952
18.768266526, 96.390, 2157.0, 46.4435
18.820787657, 96.390, 2245.0, 47.3814
18.873308787, 96.390, 2170.0, 46.5833
18.925829918, 96.390, 2213.0, 47.0425
18.978351049, 96.390, 2183.0, 46.7226
19.030872179, 96.390, 2299.0, 47.9479
19.083393310, 96.390, 2219.0, 47.1063
19.135914441, 96.390, 2297.0, 47.9270
19.188435572, 96.390, 2316.0, 48.1248
19.240956702, 96.390, 2291.0, 47.8644
19.293477833, 96.390, 2265.0, 47.5920
19.345998964, 96.390, 2240.0, 47.3286
19.398520094, 96.390, 2360.0, 48.5798
19.451041225, 96.390, 2335.0, 48.3218
19.503562356, 96.390, 2252.0, 47.4552
19.556083486, 96.390, 2387.0, 48.8569
19.608604617, 96.390, 2352.0, 48.4974
19.661125748, 96.390, 2374.0, 48.7237
19.713646879, 96.390, 2360.0, 48.5798
19.766168009, 96.390, 2361.0, 48.5901
19.818689140, 96.390, 2350.0, 48.4768
19.871210271, 96.390, 2489.0, 49.8899
19.923731401, 96.390, 2402.0, 49.0102
19.976252532, 96.390, 2461.0, 49.6085
20.028773663, 96.390, 2457.0, 49.5681
20.081294794, 96.390, 2423.0, 49.2240
20.133815924, 96.390, 2568.0, 50.6754
20.186337055, 96.390, 2425.0, 49.2443
20.238858186, 96.390, 2505.0, 50.0500
20.291379316, 96.390, 2477.0, 49.7695
20.343900447, 96.390, 2498.0, 49.9800
20.396421578, 96.390, 2486.0, 49.8598
20.448942709, 96.390, 2584.0, 50.8331
20.501463839, 96.390, 2543.0, 50.4282
20.553984970, 96.390, 2635.0, 51.3323
20.606506101, 96.390, 2588.0, 50.8724
20.659027231, 96.390, 2620.0, 51.1859
20.711548362, 96.390, 2623.0, 51.2152
20.764069493, 96.390, 2621.0, 51.1957
20.816590623, 96.390, 2549.0, 50.4876
20.869111754, 96.390, 2593.0, 50.9215
20.921632885, 96.390, 2661.0, 51.5849
20.974154016, 96.390, 2633.0, 51.3128
21.026675146, 96.390, 2734.0, 52.2877
21.079196277, 96.390, 2660.0, 51.5752
21.131717408, 96.390, 2737.0, 52.3163
21.184238538, 96.390, 2699.0, 51.9519
21.236759669, 96.390, 2772.0, 52.6498
21.289280800, 96.390, 2681.0, 51.7784
21.341801931, 96.390, 2831.0, 53.2071
21.394323061, 96.390, 2735.0, 52.2972
21.446844192, 96.390, 2811.0, 53.0189
21.499365323, 96.390, 2844.0, 53.3292
21.551886453, 96.390, 2921.0, 54.0463
21.604407584, 96.390, 2736.0, 52.3068
21.656928715, 96.390, 2866.0, 53.5350
21.709449846, 96.390, 2921.0, 54.0463
21.761970976, 96.390, 2884.0, 53.7029
21.814492107, 96.390, 2887.0, 53.7308
21.867013238, 96.390, 2782.0, 52.7447
21.919534368, 96.390, 2853.0, 53.4135
21.972055499, 96.390, 2815.0, 53.0566
22.024576630, 96.390, 2843.0, 53.3198
22.077097761, 96.390, 2927.0, 54.1018
22.129618891, 96.390, 2889.0, 53.7494
22.182140022, 96.390, 2869.0, 53.5630
22.234661153, 96.390, 2846.0, 53.3479
22.287182283, 96.390, 2863.0, 53.5070
22.339703414, 96.390, 2874.0, 53.6097
22.392224545, 96.390, 2912.0, 53.9630
22.444745675, 96.390, 2827.0, 53.1695
22.497266806, 96.390, 2907.0, 53.9166
22.549787937, 96.390, 2938.0, 54.2033
22.602309068, 96.390, 2898.0, 53.8331
22.654830198, 96.390, 3023.0, 54.9818
22.707351329, 96.390, 2874.0, 53.6097
22.759872460, 96.390, 2922.0, 54.0555
22.812393590, 96.390, 2969.0, 54.4885
22.864914721, 96.390, 2955.0, 54.3599
22.917435852, 96.390, 2889.0, 53.7494
22.969956983, 96.390, 2976.0, 54.5527
23.022478113, 96.390, 2945.0, 54.2679
23.074999244, 96.390, 2956.0, 54.3691
23.127520375, 96.390, 2905.0, 53.8981
23.180041505, 96.390, 2959.0, 54.3967
23.232562636, 96.390, 3050.0, 55.2268
23.285083767, 96.390, 2925.0, 54.0833
23.337604898, 96.390, 2965.0, 54.4518
23.390126028, 96.390, 3015.0, 54.9090
23.442647159, 96.390, 2884.0, 53.7029
23.495168290, 96.390, 2880.0, 53.6656
23.547689420, 96.390, 3063.0, 55.3444
23.600210551, 96.390, 2904.0, 53.8888
23.652731682, 96.390, 2921.0, 54.0463
23.705252813, 96.390, 3125.0, 55.9017
23.757773943, 96.390, 2929.0, 54.1202
23.810295074, 96.390, 2974.0, 54.5344
23.862816205, 96.390, 2933.0, 54.1572
23.915337335, 96.390, 3035.0, 55.0908
23.967858466, 96.390, 2899.0, 53.8424
24.020379597, 96.390, 2940.0, 54.2218
24.072900727, 96.390, 3002.0, 54.7905
24.125421858, 96.390, 2979.0, 54.5802
24.177942989, 96.390, 2956.0, 54.3691
24.230464120, 96.390, 2872.0, 53.5910
24.282985250, 96.390, 3019.0, 54.9454
24.335506381, 96.390, 2848.0, 53.3667
24.388027512, 96.390, 2921.0, 54.0463
24.440548642, 96.390, 3037.0, 55.1090
24.493069773, 96.390, 3023.0, 54.9818
24.545590904, 96.390, 2957.0, 54.3783
24.598112035, 96.390, 2837.0, 53.2635
24.650633165, 96.390, 2855.0, 53.4322
24.703154296, 96.390, 2846.0, 53.3479
24.755675427, 96.390, 2892.0, 53.7773
24.808196557, 96.390, 2878.0, 53.6470
24.860717688, 96.390, 2884.0, 53.7029
24.913238819, 96.390, 2747.0, 52.4118
24.965759950, 96.390, 2919.0, 54.0278
25.018281080, 96.390, 2821.0, 53.1131
25.070802211, 96.390, 2918.0, 54.0185
25.123323342, 96.390, 2933.0, 54.1572
25.175844472, 96.390, 2817.0, 53.0754
25.228365603, 96.390, 2767.0, 52.6023
25.280886734, 96.390, 2857.0, 53.4509
25.333407864, 96.390, 2904.0, 53.8888
25.385928995, 96.390, 2797.0, 52.8867
25.438450126, 96.390, 2870.0, 53.5724
25.490971257, 96.390, 2850.0, 53.3854
25.543492387, 96.390, 2820.0, 53.1037
25.596013518, 96.390, 2849.0, 53.3760
25.648534649, 96.390, 2815.0, 53.0566
25.701055779, 96.390, 2861.0, 53.4883
25.753576910, 96.390, 2785.0, 52.7731
25.806098041, 96.390, 2865.0, 53.5257
25.858619172, 96.390, 2724.0, 52.1920
25.911140302, 96.390, 2789.0, 52.8110
25.963661433, 96.390, 2729.0, 52.2398
26.016182564, 96.390, 2758.0, 52.5167
26.068703694, 96.390, 2806.0, 52.9717
26.121224825, 96.390, 2666.0, 51.6333
26.173745956, 96.390, 2795.0, 52.8678
26.226267087, 96.390, 2790.0, 52.8205
26.278788217, 96.390, 2774.0, 52.6688
26.331309348, 96.390, 2829.0, 53.1883
26.383830479, 96.390, 2715.0, 52.1057
26.436351609, 96.390, 2652.0, 51.4976
26.488872740, 96.390, 2822.0, 53.1225
26.541393871, 96.390, 2766.0, 52.5928
26.593915002, 96.390, 2756.0, 52.4976
26.646436132, 96.390, 2715.0, 52.1057
26.698957263, 96.390, 2709.0, 52.0481
26.751478394, 96.390, 2750.0, 52.4404
26.803999524, 96.390, 2719.0, 52.1440
26.856520655, 96.390, 2811.0, 53.0189
26.909041786, 96.390, 2713.0, 52.0865
26.961562916, 96.390, 2576.0, 50.7543
27.014084047, 96.390, 2682.0, 51.7880
27.066605178, 96.390, 2607.0, 51.0588
27.119126309, 96.390, 2533.0, 50.3289
27.171647439, 96.390, 2702.0, 51.9808
27.224168570, 96.390, 2738.0, 52.3259
27.276689701, 96.390, 2669.0, 51.6624
27.329210831, 96.390, 2694.0, 51.9038
27.381731962, 96.390, 2621.0, 51.1957
27.434253093, 96.390, 2585.0, 50.8429
27.486774224, 96.390, 2601.0, 51.0000
27.539295354, 96.390, 2579.0, 50.7839
27.591816485, 96.390, 2643.0, 51.4101
27.644337616, 96.390, 2586.0, 50.8527
27.696858746, 96.390, 2515.0, 50.1498
27.749379877, 96.390, 2569.0, 50.6853
27.801901008, 96.390, 2548.0, 50.4777
27.854422139, 96.390, 2624.0, 51.2250
27.906943269, 96.390, 2500.0, 50.0000
27.959464400, 96.390, 2578.0, 50.7740
28.011985531, 96.390, 2568.0, 50.6754
28.064506661, 96.390, 2590.0, 50.8920
28.117027792, 96.390, 2483.0, 49.8297
28.169548923, 96.390, 2520.0, 50.1996
28.222070054, 96.390, 2437.0, 49.3660
28.274591184, 96.390, 2426.0, 49.2544
28.327112315, 96.390, 2577.0, 50.7642
28.379633446, 96.390, 2524.0, 50.2394
28.432154576, 96.390, 2558.0, 50.5767
28.484675707, 96.390, 2475.0, 49.7494
28.537196838, 96.390, 2454.0, 49.5379
28.589717968, 96.390, 2531.0, 50.3090
28.642239099, 96.390, 2439.0, 49.3862
28.694760230, 96.390, 2449.0, 49.4874
28.747281361, 96.390, 2562.0, 50.6162
28.799802491, 96.390, 2436.0, 49.3559
28.852323622, 96.390, 2403.0, 49.0204
28.904844753, 96.390, 2513.0, 50.1298
28.957365883, 96.390, 2379.0, 48.7750
29.009887014, 96.390, 2573.0, 50.7247
29.062408145, 96.390, 2426.0, 49.2544
29.114929276, 96.390, 2444.0, 49.4368
29.167450406, 96.390, 2502.0, 50.0200
29.219971537, 96.390, 2453.0, 49.5278
29.272492668, 96.390, 2430.0, 49.2950
29.325013798, 96.390, 2389.0, 48.8774
29.377534929, 96.390, 2380.0, 48.7852
29.430056060, 96.390, 2329.0, 48.2597
29.482577191, 96.390, 2314.0, 48.1041
29.535098321, 96.390, 2395.0, 48.9387
29.587619452, 96.390, 2368.0, 48.6621
29.640140583, 96.390, 2268.0, 47.6235
29.692661713, 96.390, 2346.0, 48.4355
29.745182844, 96.390, 2346.0, 48.4355
29.797703975, 96.390, 2370.0, 48.6826
29.850225105, 96.390, 2294.0, 47.8957
29.902746236, 96.390, 2254.0, 47.4763
29.955267367, 96.390, 2322.0, 48.1871
30.007788498, 96.390, 2291.0, 47.8644
30.060309628, 96.390, 2367.0, 48.6518
30.112830759, 96.390, 2299.0, 47.9479
30.165351890, 96.390, 2361.0, 48.5901
30.217873020, 96.390, 2264.0, 47.5815
30.270394151, 96.390, 2284.0, 47.7912
30.322915282, 96.390, 2304.0, 48.0000
30.375436413, 96.390, 2227.0, 47.1911
30.427957543, 96.390, 2377.0, 48.7545
30.480478674, 96.390, 2218.0, 47.0956
30.532999805, 96.390, 2280.0, 47.7493
30.585520935, 96.390, 2273.0, 47.6760
30.638042066, 96.390, 2170.0, 46.5833
30.690563197, 96.390, 2259.0, 47.5289
30.743084328, 96.390, 2119.0, 46.0326
30.795605458, 96.390, 2244.0, 47.3709
30.848126589, 96.390, 2200.0, 46.9042
30.900647720, 96.390, 2222.0, 47.1381
30.953168850, 96.390, 2199.0, 46.8935
31.005689981, 96.390, 2162.0, 46.4973
31.058211112, 96.390, 2146.0, 46.3249
31.110732243, 96.390, 2081.0, 45.6180
31.163253373, 96.390, 2062.0, 45.4093
31.215774504, 96.390, 2081.0, 45.6180
31.268295635, 96.390, 2092.0, 45.7384
31.320816765, 96.390, 2083.0, 45.6399
31.373337896, 96.390, 2143.0, 46.2925
31.425859027, 96.390, 2140.0, 46.2601
31.478380157, 96.390, 2041.0, 45.1774
31.530901288, 96.390, 1998.0, 44.6990
31.583422419, 96.390, 2035.0, 45.1110
31.635943550, 96.390, 2045.0, 45.2217
31.688464680, 96.390, 2085.0, 45.6618
31.740985811, 96.390, 2122.0, 46.0652
31.793506942, 96.390, 2093.0, 45.7493
31.846028072, 96.390, 2054.0, 45.3211
31.898549203, 96.390, 1956.0, 44.2267
31.951070334, 96.390, 1949.0, 44.1475
32.003591465, 96.390, 2047.0, 45.2438
32.056112595, 96.390, 1971.0, 44.3959
32.108633726, 96.390, 2013.0, 44.8665
32.161154857, 96.390, 2014.0, 44.8776
32.213675987, 96.390, 1948.0, 44.1362
32.266197118, 96.390, 2045.0, 45.2217
32.318718249, 96.390, 1982.0, 44.5197
32.371239380, 96.390, 1976.0, 44.4522
32.423760510, 96.390, 1949.0, 44.1475
32.476281641, 96.390, 1948.0, 44.1362
32.528802772, 96.390, 1925.0, 43.8748
32.581323902, 96.390, 1998.0, 44.6990
32.633845033, 96.390, 1870.0, 43.2435
32.686366164, 96.390, 1861.0, 43.1393
32.738887295, 96.390, 1906.0, 43.6578
32.791408425, 96.390, 1943.0, 44.0795
32.843929556, 96.390, 1877.0, 43.3244
32.896450687, 96.390, 1886.0, 43.4281
32.948971817, 96.390, 1805.0, 42.4853
33.001492948, 96.390, 1861.0, 43.1393
33.054014079, 96.390, 1824.0, 42.7083
33.106535209, 96.390, 1805.0, 42.4853
33.159056340, 96.390, 1860.0, 43.1277
33.211577471, 96.390, 1822.0, 42.6849
33.264098602, 96.390, 1781.0, 42.2019
33.316619732, 96.390, 1807.0, 42.5088
33.369140863, 96.390, 1778.0, 42.1663
33.421661994, 96.390, 1761.0, 41.9643
33.474183124, 96.390, 1780.0, 42.1900
33.526704255, 96.390, 1764.0, 42.0000
33.579225386, 96.390, 1809.0, 42.5323
33.631746517, 96.390, 1811.0, 42.5558
33.684267647, 96.390, 1795.0, 42.3674
33.736788778, 96.390, 1775.0, 42.1307
33.789309909, 96.390, 1731.0, 41.6053
33.841831039, 96.390, 1718.0, 41.4488
33.894352170, 96.390, 1729.0, 41.5812
33.946873301, 96.390, 1744.0, 41.7612
33.999394432, 96.390, 1731.0, 41.6053
34.051915562, 96.390, 1683.0, 41.0244
34.104436693, 96.390, 1686.0, 41.0609
34.156957824, 96.390, 1734.0, 41.6413
34.209478954, 96.390, 1679.0, 40.9756
34.262000085, 96.390, 1730.0, 41.5933
34.314521216, 96.390, 1654.0, 40.6694
34.367042346, 96.390, 1678.0, 40.9634
34.419563477, 96.390, 1680.0, 40.9878
34.472084608, 96.390, 1708.0, 41.3280
34.524605739, 96.390, 1675.0, 40.9268
34.577126869, 96.390, 1577.0, 39.7115
34.629648000, 96.390, 1631.0, 40.3856
34.682169131, 96.390, 1685.0, 41.0488
34.734690261, 96.390, 1660.0, 40.7431
34.787211392, 96.390, 1605.0, 40.0625
34.839732523, 96.390, 1545.0, 39.3065
34.892253654, 96.390, 1563.0, 39.5348
34.944774784, 96.390, 1614.0, 40.1746
34.997295915, 96.390, 1524.0, 39.0384
35.049817046, 96.390, 1575.0, 39.6863
35.102338176, 96.390, 1551.0, 39.3827
35.154859307, 96.390, 1544.0, 39.2938
35.207380438, 96.390, 1550.0, 39.3700
35.259901569, 96.390, 1594.0, 39.9249
35.312422699, 96.390, 1574.0, 39.6737
35.364943830, 96.390, 1498.0, 38.7040
35.417464961, 96.390, 1541.0, 39.2556
35.469986091, 96.390, 1505.0, 38.7943
35.522507222, 96.390, 1512.0, 38.8844
35.575028353, 96.390, 1537.0, 39.2046
35.627549484, 96.390, 1523.0, 39.0256
35.680070614, 96.390, 1464.0, 38.2623
35.732591745, 96.390, 1493.0, 38.6394
35.785112876, 96.390, 1513.0, 38.8973
35.837634006, 96.390, 1522.0, 39.0128
35.890155137, 96.390, 1433.0, 37.8550
35.942676268, 96.390, 1477.0, 38.4318
35.995197398, 96.390, 1603.0, 40.0375
36.047718529, 96.390, 1525.0, 39.0512
36.100239660, 96.390, 1421.0, 37.6962
36.152760791, 96.390, 1458.0, 38.1838
36.205281921, 96.390, 1421.0, 37.6962
36.257803052, 96.390, 1454.0, 38.1314
36.310324183, 96.390, 1423.0, 37.7227
36.362845313, 96.390, 1347.0, 36.7015
36.415366444, 96.390, 1352.0, 36.7696
36.467887575, 96.390, 1375.0, 37.0810
36.520408706, 96.390, 1378.0, 37.1214
36.572929836, 96.390, 1407.0, 37.5100
36.625450967, 96.390, 1324.0, 36.3868
36.677972098, 96.390, 1444.0, 38.0000
36.730493228, 96.390, 1352.0, 36.7696
36.783014359, 96.390, 1307.0, 36.1525
36.835535490, 96.390, 1351.0, 36.7560
36.888056621, 96.390, 1319.0, 36.3180
36.940577751, 96.390, 1386.0, 37.2290
36.993098882, 96.390, 1390.0, 37.2827
37.045620013, 96.390, 1335.0, 36.5377
37.098141143, 96.390, 1319.0, 36.3180
37.150662274, 96.390, 1287.0, 35.8748
37.203183405, 96.390, 1376.0, 37.0945
37.255704535, 96.390, 1273.0, 35.6791
37.308225666, 96.390, 1345.0, 36.6742
37.360746797, 96.390, 1235.0, 35.1426
37.413267928, 96.390, 1314.0, 36.2491
37.465789058, 96.390, 1303.0, 36.0971
37.518310189, 96.390, 1318.0, 36.3043
37.570831320, 96.390, 1309.0, 36.1801
37.623352450, 96.390, 1297.0, 36.0139
37.675873581, 96.390, 1272.0, 35.6651
37.728394712, 96.390, 1199.0, 34.6266
37.780915843, 96.390, 1219.0, 34.9142
37.833436973, 96.390, 1267.0, 35.5949
37.885958104, 96.390, 1228.0, 35.0428
37.938479235, 96.390, 1270.0, 35.6371
37.991000365, 96.390, 1201.0, 34.6554
38.043521496, 96.390, 1215.0, 34.8569
38.096042627, 96.390, 1328.0, 36.4417
38.148563758, 96.390, 1229.0, 35.0571
38.201084888, 96.390, 1263.0, 35.5387
38.253606019, 96.390, 1239.0, 35.1994
38.306127150, 96.390, 1203.0, 34.6843
38.358648280, 96.390, 1235.0, 35.1426
38.411169411, 96.390, 1181.0, 34.3657
38.463690542, 96.390, 1185.0, 34.4238
38.516211673, 96.390, 1284.0, 35.8329
38.568732803, 96.390, 1242.0, 35.2420
38.621253934, 96.390, 1227.0, 35.0286
38.673775065, 96.390, 1214.0, 34.8425
38.726296195, 96.390, 1239.0, 35.1994
38.778817326, 96.390, 1179.0, 34.3366
38.831338457, 96.390, 1240.0, 35.2136
38.883859587, 96.390, 1165.0, 34.1321
38.936380718, 96.390, 1240.0, 35.2136
38.988901849, 96.390, 1223.0, 34.9714
39.041422980, 96.390, 1169.0, 34.1906
39.093944110, 96.390, 1228.0, 35.0428
39.146465241, 96.390, 1192.0, 34.5254
39.198986372, 96.390, 1186.0, 34.4384
39.251507502, 96.390, 1162.0, 34.0881
39.304028633, 96.390, 1140.0, 33.7639
39.356549764, 96.390, 1204.0, 34.6987
39.409070895, 96.390, 1206.0, 34.7275
39.461592025, 96.390, 1235.0, 35.1426
39.514113156, 96.390, 1150.0, 33.9116
39.566634287, 96.390, 1219.0, 34.9142
39.619155417, 96.390, 1136.0, 33.7046
39.671676548, 96.390, 1188.0, 34.4674
39.724197679, 96.390, 1217.0, 34.8855
39.776718810, 96.390, 1185.0, 34.4238
39.829239940, 96.390, 1182.0, 34.3802
39.881761071, 96.390, 1193.0, 34.5398
39.934282202, 96.390, 1242.0, 35.2420
39.986803332, 96.390, 1183.0, 34.3948
40.039324463, 96.390, 1160.0, 34.0588
40.091845594, 96.390, 1179.0, 34.3366
40.144366725, 96.390, 1191.0, 34.5109
40.196887855, 96.390, 1194.0, 34.5543
40.249408986, 96.390, 1195.0, 34.5688
40.301930117, 96.390, 1122.0, 33.4963
40.354451247, 96.390, 1201.0, 34.6554
40.406972378, 96.390, 1155.0, 33.9853
40.459493509, 96.390, 1210.0, 34.7851
40.512014639, 96.390, 1153.0, 33.9559
40.564535770, 96.390, 1185.0, 34.4238
40.617056901, 96.390, 1127.0, 33.5708
40.669578032, 96.390, 1129.0, 33.6006
40.722099162, 96.390, 1134.0, 33.6749
40.774620293, 96.390, 1141.0, 33.7787
40.827141424, 96.390, 1167.0, 34.1614
40.879662554, 96.390, 1145.0, 33.8378
40.932183685, 96.390, 1160.0, 34.0588
40.984704816, 96.390, 1162.0, 34.0881
41.037225947, 96.390, 1204.0, 34.6987
41.089747077, 96.390, 1157.0, 34.0147
41.142268208, 96.390, 1094.0, 33.0757
41.194789339, 96.390, 1141.0, 33.7787
41.247310469, 96.390, 1115.0, 33.3916
41.299831600, 96.390, 1123.0, 33.5112
41.352352731, 96.390, 1133.0, 33.6601
41.404873862, 96.390, 1052.0, 32.4345
41.457394992, 96.390, 1117.0, 33.4215
41.509916123, 96.390, 1112.0, 33.3467
41.562437254, 96.390, 1168.0, 34.1760
41.614958384, 96.390, 1142.0, 33.7935
41.667479515, 96.390, 1129.0, 33.6006
41.720000646, 96.390, 1143.0, 33.8083
41.772521776, 96.390, 1101.0, 33.1813
41.825042907, 96.390, 1125.0, 33.5410
41.877564038, 96.390, 1103.0, 33.2114
41.930085169, 96.390, 1111.0, 33.3317
41.982606299, 96.390, 1193.0, 34.5398
42.035127430, 96.390, 1084.0, 32.9242
42.087648561, 96.390, 1149.0, 33.8969
42.140169691, 96.390, 1162.0, 34.0881
42.192690822, 96.390, 1053.0, 32.4500
42.245211953, 96.390, 1133.0, 33.6601
42.297733084, 96.390, 1099.0, 33.1512
42.350254214, 96.390, 1136.0, 33.7046
42.402775345, 96.390, 1126.0, 33.5559
42.455296476, 96.390, 1147.0, 33.8674
42.507817606, 96.390, 1195.0, 34.5688
42.560338737, 96.390, 1135.0, 33.6898
42.612859868, 96.390, 1164.0, 34.1174
42.665380999, 96.390, 1134.0, 33.6749
42.717902129, 96.390, 1195.0, 34.5688
42.770423260, 96.390, 1194.0, 34.5543
42.822944391, 96.390, 1185.0, 34.4238
42.875465521, 96.390, 1127.0, 33.5708
42.927986652, 96.390, 1258.0, 35.4683
42.980507783, 96.390, 1176.0, 34.2929
43.033028914, 96.390, 1100.0, 33.1662
43.085550044, 96.390, 1177.0, 34.3074
43.138071175, 96.390, 1132.0, 33.6452
43.190592306, 96.390, 1128.0, 33.5857
43.243113436, 96.390, 1129.0, 33.6006
43.295634567, 96.390, 1111.0, 33.3317
43.348155698, 96.390, 1098.0, 33.1361
43.400676828, 96.390, 1122.0, 33.4963
43.453197959, 96.390, 1139.0, 33.7491
43.505719090, 96.390, 1046.0, 32.3419
43.558240221, 96.390, 1072.0, 32.7414
43.610761351, 96.390, 1045.0, 32.3265
43.663282482, 96.390, 1084.0, 32.9242
43.715803613, 96.390, 1023.0, 31.9844
43.768324743, 96.390, 1101.0, 33.1813
43.820845874, 96.390, 1077.0, 32.8177
43.873367005, 96.390, 1033.0, 32.1403
43.925888136, 96.390, 1046.0, 32.3419
43.978409266, 96.390, 1120.0, 33.4664
44.030930397, 96.390, 1064.0, 32.6190
44.083451528, 96.390, 1132.0, 33.6452
44.135972658, 96.390, 1080.0, 32.8634
44.188493789, 96.390, 1136.0, 33.7046
44.241014920, 96.390, 1025.0, 32.0156
44.293536051, 96.390, 1031.0, 32.1092
44.346057181, 96.390, 1059.0, 32.5423
44.398578312, 96.390, 1021.0, 31.9531
44.451099443, 96.390, 1058.0, 32.5269
44.503620573, 96.390, 1048.0, 32.3728
44.556141704, 96.390, 1026.0, 32.0312
44.608662835, 96.390, 992.0, 31.4960
44.661183966, 96.390, 1075.0, 32.7872
44.713705096, 96.390, 1029.0, 32.0780
44.766226227, 96.390, 1028.0, 32.0624
44.818747358, 96.390, 1075.0, 32.7872
44.871268488, 96.390, 1092.0, 33.0454
44.923789619, 96.390, 1012.0, 31.8119
44.976310750, 96.390, 1067.0, 32.6650
45.028831880, 96.390, 1084.0, 32.9242
45.081353011, 96.390, 1030.0, 32.0936
45.133874142, 96.390, 1031.0, 32.1092
45.186395273, 96.390, 1071.0, 32.7261
45.238916403, 96.390, 1043.0, 32.2955
45.291437534, 96.390, 1007.0, 31.7333
45.343958665, 96.390, 973.0, 31.1929
45.396479795, 96.390, 1028.0, 32.0624
45.449000926, 96.390, 1077.0, 32.8177
45.501522057, 96.390, 966.0, 31.0805
45.554043188, 96.390, 1042.0, 32.2800
45.606564318, 96.390, 1013.0, 31.8277
45.659085449, 96.390, 1005.0, 31.7017
45.711606580, 96.390, 1038.0, 32.2180
45.764127710, 96.390, 1049.0, 32.3883
45.816648841, 96.390, 980.0, 31.3050
45.869169972, 96.390, 1003.0, 31.6702
45.921691103, 96.390, 1041.0, 32.2645
45.974212233, 96.390, 990.0, 31.4643
46.026733364, 96.390, 986.0, 31.4006
46.079254495, 96.390, 1025.0, 32.0156
46.131775625, 96.390, 957.0, 30.9354
46.184296756, 96.390, 987.0, 31.4166
46.236817887, 96.390, 1004.0, 31.6860
46.289339017, 96.390, 1001.0, 31.6386
46.341860148, 96.390, 979.0, 31.2890
46.394381279, 96.390, 983.0, 31.3528
46.446902410, 96.390, 960.0, 30.9839
46.499423540, 96.390, 979.0, 31.2890
46.551944671, 96.390, 967.0, 31.0966
46.604465802, 96.390, 989.0, 31.4484
46.656986932, 96.390, 990.0, 31.4643
46.709508063, 96.390, 973.0, 31.1929
46.762029194, 96.390, 999.0, 31.6070
46.814550325, 96.390, 1031.0, 32.1092
46.867071455, 96.390, 946.0, 30.7571
46.919592586, 96.390, 995.0, 31.5436
46.972113717, 96.390, 1001.0, 31.6386
47.024634847, 96.390, 978.0, 31.2730
47.077155978, 96.390, 1018.0, 31.9061
47.129677109, 96.390, 981.0, 31.3209
47.182198240, 96.390, 962.0, 31.0161
47.234719370, 96.390, 966.0, 31.0805
47.287240501, 96.390, 1035.0, 32.1714
47.339761632, 96.390, 1051.0, 32.4191
47.392282762, 96.390, 939.0, 30.6431
47.444803893, 96.390, 981.0, 31.3209
47.497325024, 96.390, 959.0, 30.9677
47.549846155, 96.390, 1002.0, 31.6544
47.602367285, 96.390, 1043.0, 32.2955
47.654888416, 96.390, 1022.0, 31.9687
47.707409547, 96.390, 941.0, 30.6757
47.759930677, 96.390, 1032.0, 32.1248
47.812451808, 96.390, 999.0, 31.6070
47.864972939, 96.390, 996.0, 31.5595
47.917494069, 96.390, 977.0, 31.2570
47.970015200, 96.390, 993.0, 31.5119
48.022536331, 96.390, 907.0, 30.1164
48.075057462, 96.390, 905.0, 30.0832
48.127578592, 96.390, 949.0, 30.8058
48.180099723, 96.390, 1035.0, 32.1714
48.232620854, 96.390, 982.0, 31.3369
48.285141984, 96.390, 986.0, 31.4006
48.337663115, 96.390, 975.0, 31.2250
48.390184246, 96.390, 945.0, 30.7409
48.442705377, 96.390, 959.0, 30.9677
48.495226507, 96.390, 950.0, 30.8221
48.547747638, 96.390, 918.0, 30.2985
48.600268769, 96.390, 951.0, 30.8383
48.652789899, 96.390, 924.0, 30.3974
48.705311030, 96.390, 1050.0, 32.4037
48.757832161, 96.390, 953.0, 30.8707
48.810353292, 96.390, 916.0, 30.2655
48.862874422, 96.390, 947.0, 30.7734
48.915395553, 96.390, 944.0, 30.7246
48.967916684, 96.390, 950.0, 30.8221
49.020437814, 96.390, 928.0, 30.4631
49.072958945, 96.390, 988.0, 31.4325
49.125480076, 96.390, 935.0, 30.5778
49.178001207, 96.390, 921.0, 30.3480
49.230522337, 96.390, 931.0, 30.5123
49.283043468, 96.390, 986.0, 31.4006
49.335564599, 96.390, 929.0, 30.4795
49.388085729, 96.390, 934.0, 30.5614
49.440606860, 96.390, 944.0, 30.7246
49.493127991, 96.390, 944.0, 30.7246
49.545649121, 96.390, 958.0, 30.9516
49.598170252, 96.390, 940.0, 30.6594
49.650691383, 96.390, 950.0, 30.8221
49.703212514, 96.390, 926.0, 30.4302
49.755733644, 96.390, 957.0, 30.9354
49.808254775, 96.390, 892.0, 29.8664
49.860775906, 96.390, 935.0, 30.5778
49.913297036, 96.390, 978.0, 31.2730
49.965818167, 96.390, 963.0, 31.0322
50.018339298, 96.390, 959.0, 30.9677
50.070860429, 96.390, 909.0, 30.1496
50.123381559, 96.390, 1030.0, 32.0936
50.175902690, 96.390, 932.0, 30.5287
50.228423821, 96.390, 995.0, 31.5436
50.280944951, 96.390, 946.0, 30.7571
50.333466082, 96.390, 1025.0, 32.0156
50.385987213, 96.390, 922.0, 30.3645
50.438508344, 96.390, 932.0, 30.5287
50.491029474, 96.390, 890.0, 29.8329
50.543550605, 96.390, 952.0, 30.8545
50.596071736, 96.390, 928.0, 30.4631
50.648592866, 96.390, 900.0, 30.0000
50.701113997, 96.390, 927.0, 30.4467
50.753635128, 96.390, 1005.0, 31.7017
50.806156258, 96.390, 920.0, 30.3315
50.858677389, 96.390, 928.0, 30.4631
50.911198520, 96.390, 933.0, 30.5450
50.963719651, 96.390, 914.0, 30.2324
51.016240781, 96.390, 964.0, 31.0483
51.068761912, 96.390, 950.0, 30.8221
51.121283043, 96.390, 962.0, 31.0161
51.173804173, 96.390, 899.0, 29.9833
51.226325304, 96.390, 912.0, 30.1993
51.278846435, 96.390, 897.0, 29.9500
51.331367566, 96.390, 886.0, 29.7658
51.383888696, 96.390, 953.0, 30.8707
51.436409827, 96.390, 998.0, 31.5911
51.488930958, 96.390, 921.0, 30.3480
51.541452088, 96.390, 945.0, 30.7409
51.593973219, 96.390, 937.0, 30.6105
51.646494350, 96.390, 938.0, 30.6268
51.699015481, 96.390, 903.0, 30.0500
51.751536611, 96.390, 906.0, 30.0998
51.804057742, 96.390, 882.0, 29.6985
51.856578873, 96.390, 940.0, 30.6594
51.909100003, 96.390, 990.0, 31.4643
51.961621134, 96.390, 938.0, 30.6268
52.014142265, 96.390, 876.0, 29.5973
52.066663396, 96.390, 883.0, 29.7153
52.119184526, 96.390, 893.0, 29.8831
52.171705657, 96.390, 884.0, 29.7321
52.224226788, 96.390, 958.0, 30.9516
52.276747918, 96.390, 981.0, 31.3209
52.329269049, 96.390, 883.0, 29.7153
52.381790180, 96.390, 978.0, 31.2730
52.434311310, 96.390, 948.0, 30.7896
52.486832441, 96.390, 958.0, 30.9516
52.539353572, 96.390, 904.0, 30.0666
52.591874703, 96.390, 909.0, 30.1496
52.644395833, 96.390, 901.0, 30.0167
52.696916964, 96.390, 886.0, 29.7658
52.749438095, 96.390, 955.0, 30.9031
52.801959225, 96.390, 930.0, 30.4959
52.854480356, 96.390, 946.0, 30.7571
52.907001487, 96.390, 944.0, 30.7246
52.959522618, 96.390, 900.0, 30.0000
53.012043748, 96.390, 892.0, 29.8664
53.064564879, 96.390, 921.0, 30.3480
53.117086010, 96.390, 934.0, 30.5614
53.169607140, 96.390, 905.0, 30.0832
53.222128271, 96.390, 911.0, 30.1828
53.274649402, 96.390, 935.0, 30.5778
53.327170533, 96.390, 952.0, 30.8545
53.379691663, 96.390, 973.0, 31.1929
53.432212794, 96.390, 951.0, 30.8383
53.484733925, 96.390, 912.0, 30.1993
53.537255055, 96.390, 930.0, 30.4959
53.589776186, 96.390, 898.0, 29.9666
53.642297317, 96.390, 958.0, 30.9516
53.694818448, 96.390, 940.0, 30.6594
53.747339578, 96.390, 919.0, 30.3150
53.799860709, 96.390, 943.0, 30.7083
53.852381840, 96.390, 924.0, 30.3974
53.904902970, 96.390, 920.0, 30.3315
53.957424101, 96.390, 950.0, 30.8221
54.009945232, 96.390, 884.0, 29.7321
54.062466362, 96.390, 946.0, 30.7571
54.114987493, 96.390, 952.0, 30.8545
54.167508624, 96.390, 1001.0, 31.6386
54.220029755, 96.390, 919.0, 30.3150
54.272550885, 96.390, 894.0, 29.8998
54.325072016, 96.390, 878.0, 29.6311
54.377593147, 96.390, 963.0, 31.0322
54.430114277, 96.390, 918.0, 30.2985
54.482635408, 96.390, 944.0, 30.7246
54.535156539, 96.390, 866.0, 29.4279
54.587677670, 96.390, 936.0, 30.5941
54.640198800, 96.390, 938.0, 30.6268
54.692719931, 96.390, 902.0, 30.0333
54.745241062, 96.390, 925.0, 30.4138
54.797762192, 96.390, 955.0, 30.9031
54.850283323, 96.390, 880.0, 29.6648
54.902804454, 96.390, 927.0, 30.4467
54.955325585, 96.390, 892.0, 29.8664
55.007846715, 96.390, 925.0, 30.4138
55.060367846, 96.390, 924.0, 30.3974
55.112888977, 96.390, 957.0, 30.9354
55.165410107, 96.390, 941.0, 30.6757
55.217931238, 96.390, 905.0, 30.0832
55.270452369, 96.390, 848.0, 29.1204
55.322973499, 96.390, 911.0, 30.1828
55.375494630, 96.390, 910.0, 30.1662
55.428015761, 96.390, 921.0, 30.3480
55.480536892, 96.390, 855.0, 29.2404
55.533058022, 96.390, 891.0, 29.8496
55.585579153, 96.390, 970.0, 31.1448
55.638100284, 96.390, 952.0, 30.8545
55.690621414, 96.390, 918.0, 30.2985
55.743142545, 96.390, 909.0, 30.1496
55.795663676, 96.390, 926.0, 30.4302
55.848184807, 96.390, 959.0, 30.9677
55.900705937, 96.390, 945.0, 30.7409
55.953227068, 96.390, 907.0, 30.1164
56.005748199, 96.390, 915.0, 30.2490
56.058269329, 96.390, 966.0, 31.0805
56.110790460, 96.390, 922.0, 30.3645
56.163311591, 96.390, 983.0, 31.3528
56.215832722, 96.390, 912.0, 30.1993
56.268353852, 96.390, 925.0, 30.4138
56.320874983, 96.390, 902.0, 30.0333
56.373396114, 96.390, 936.0, 30.5941
56.425917244, 96.390, 909.0, 30.1496
56.478438375, 96.390, 943.0, 30.7083
56.530959506, 96.390, 984.0, 31.3688
56.583480637, 96.390, 915.0, 30.2490
56.636001767, 96.390, 953.0, 30.8707
56.688522898, 96.390, 933.0, 30.5450
56.741044029, 96.390, 915.0, 30.2490
56.793565159, 96.390, 917.0, 30.2820
56.846086290, 96.390, 941.0, 30.6757
56.898607421, 96.390, 891.0, 29.8496
56.951128551, 96.390, 890.0, 29.8329
57.003649682, 96.390, 894.0, 29.8998
57.056170813, 96.390, 901.0, 30.0167
57.108691944, 96.390, 937.0, 30.6105
57.161213074, 96.390, 930.0, 30.4959
57.213734205, 96.390, 976.0, 31.2410
57.266255336, 96.390, 927.0, 30.4467
57.318776466, 96.390, 902.0, 30.0333
57.371297597, 96.390, 936.0, 30.5941
57.423818728, 96.390, 1006.0, 31.7175
57.476339859, 96.390, 953.0, 30.8707
57.528860989, 96.390, 915.0, 30.2490
57.581382120, 96.390, 918.0, 30.2985
57.633903251, 96.390, 899.0, 29.9833
57.686424381, 96.390, 880.0, 29.6648
57.738945512, 96.390, 909.0, 30.1496
57.791466643, 96.390, 899.0, 29.9833
57.843987774, 96.390, 959.0, 30.9677
57.896508904, 96.390, 913.0, 30.2159
57.949030035, 96.390, 915.0, 30.2490
58.001551166, 96.390, 972.0, 31.1769
58.054072296, 96.390, 960.0, 30.9839
58.106593427, 96.390, 848.0, 29.1204
58.159114558, 96.390, 907.0, 30.1164
58.211635689, 96.390, 913.0, 30.2159
58.264156819, 96.390, 976.0, 31.2410
58.316677950, 96.390, 942.0, 30.6920
58.369199081, 96.390, 969.0, 31.1288
58.421720211, 96.390, 976.0, 31.2410
58.474241342, 96.390, 948.0, 30.7896
58.526762473, 96.390, 941.0, 30.6757
58.579283603, 96.390, 914.0, 30.2324
58.631804734, 96.390, 872.0, 29.5296
58.684325865, 96.390, 1009.0, 31.7648
58.736846996, 96.390, 902.0, 30.0333
58.789368126, 96.390, 918.0, 30.2985
58.841889257, 96.390, 922.0, 30.3645
58.894410388, 96.390, 885.0, 29.7489
58.946931518, 96.390, 899.0, 29.9833
58.999452649, 96.390, 887.0, 29.7825
59.051973780, 96.390, 871.0, 29.5127
59.104494911, 96.390, 945.0, 30.7409
59.157016041, 96.390, 927.0, 30.4467
59.209537172, 96.390, 957.0, 30.9354
59.262058303, 96.390, 886.0, 29.7658
59.314579433, 96.390, 895.0, 29.9166
59.367100564, 96.390, 927.0, 30.4467
59.419621695, 96.390, 871.0, 29.5127
59.472142826, 96.390, 957.0, 30.9354
59.524663956, 96.390, 939.0, 30.6431
59.577185087, 96.390, 862.0, 29.3598
59.629706218, 96.390, 966.0, 31.0805
59.682227348, 96.390, 917.0, 30.2820
59.734748479, 96.390, 956.0, 30.9192
59.787269610, 96.390, 895.0, 29.9166
59.839790740, 96.390, 902.0, 30.0333
59.892311871, 96.390, 914.0, 30.2324
59.944833002, 96.390, 920.0, 30.3315
59.997354133, 96.390, 974.0, 31.2090
60.049875263, 96.390, 922.0, 30.3645
60.102396394, 96.390, 925.0, 30.4138
60.154917525, 96.390, 890.0, 29.8329
60.207438655, 96.390, 911.0, 30.1828
60.259959786, 96.390, 954.0, 30.8869
60.312480917, 96.390, 904.0, 30.0666
60.365002048, 96.390, 960.0, 30.9839
60.417523178, 96.390, 978.0, 31.2730
60.470044309, 96.390, 903.0, 30.0500
60.522565440, 96.390, 939.0, 30.6431
60.575086570, 96.390, 917.0, 30.2820
60.627607701, 96.390, 944.0, 30.7246
60.680128832, 96.390, 961.0, 31.0000
60.732649963, 96.390, 891.0, 29.8496
60.785171093, 96.390, 887.0, 29.7825
60.837692224, 96.390, 997.0, 31.5753
60.890213355, 96.390, 919.0, 30.3150
60.942734485, 96.390, 902.0, 30.0333
60.995255616, 96.390, 929.0, 30.4795
61.047776747, 96.390, 914.0, 30.2324
61.100297878, 96.390, 938.0, 30.6268
61.152819008, 96.390, 961.0, 31.0000
61.205340139, 96.390, 912.0, 30.1993
61.257861270, 96.390, 914.0, 30.2324
61.310382400, 96.390, 924.0, 30.3974
61.362903531, 96.390, 931.0, 30.5123
61.415424662, 96.390, 907.0, 30.1164
61.467945792, 96.390, 928.0, 30.4631
61.520466923, 96.390, 955.0, 30.9031
61.572988054, 96.390, 868.0, 29.4618
61.625509185, 96.390, 920.0, 30.3315
61.678030315, 96.390, 978.0, 31.2730
61.730551446, 96.390, 935.0, 30.5778
61.783072577, 96.390, 902.0, 30.0333
61.835593707, 96.390, 912.0, 30.1993
61.888114838, 96.390, 917.0, 30.2820
61.940635969, 96.390, 914.0, 30.2324
61.993157100, 96.390, 957.0, 30.9354
62.045678230, 96.390, 916.0, 30.2655
62.098199361, 96.390, 944.0, 30.7246
62.150720492, 96.390, 920.0, 30.3315
62.203241622, 96.390, 930.0, 30.4959
62.255762753, 96.390, 992.0, 31.4960
62.308283884, 96.390, 931.0, 30.5123
62.360805015, 96.390, 895.0, 29.9166
62.413326145, 96.390, 1005.0, 31.7017
62.465847276, 96.390, 935.0, 30.5778
62.518368407, 96.390, 942.0, 30.6920
62.570889537, 96.390, 930.0, 30.4959
62.623410668, 96.390, 956.0, 30.9192
62.675931799, 96.390, 987.0, 31.4166
62.728452930, 96.390, 905.0, 30.0832
62.780974060, 96.390, 914.0, 30.2324
62.833495191, 96.390, 858.0, 29.2916
62.886016322, 96.390, 877.0, 29.6142
62.938537452, 96.390, 945.0, 30.7409
62.991058583, 96.390, 896.0, 29.9333
63.043579714, 96.390, 918.0, 30.2985
63.096100844, 96.390, 949.0, 30.8058
63.148621975, 96.390, 925.0, 30.4138
63.201143106, 96.390, 934.0, 30.5614
63.253664237, 96.390, 904.0, 30.0666
63.306185367, 96.390, 923.0, 30.3809
63.358706498, 96.390, 929.0, 30.4795
63.411227629, 96.390, 956.0, 30.9192
63.463748759, 96.390, 874.0, 29.5635
63.516269890, 96.390, 874.0, 29.5635
63.568791021, 96.390, 848.0, 29.1204
63.621312152, 96.390, 933.0, 30.5450
63.673833282, 96.390, 961.0, 31.0000
63.726354413, 96.390, 859.0, 29.3087
63.778875544, 96.390, 905.0, 30.0832
63.831396674, 96.390, 894.0, 29.8998
63.883917805, 96.390, 928.0, 30.4631
63.936438936, 96.390, 915.0, 30.2490
63.988960067, 96.390, 890.0, 29.8329
64.041481197, 96.390, 859.0, 29.3087
64.094002328, 96.390, 900.0, 30.0000
64.146523459, 96.390, 865.0, 29.4109
64.199044589, 96.390, 910.0, 30.1662
64.251565720, 96.390, 903.0, 30.0500
64.304086851, 96.390, 871.0, 29.5127
64.356607981, 96.390, 894.0, 29.8998
64.409129112, 96.390, 903.0, 30.0500
64.461650243, 96.390, 863.0, 29.3769
64.514171374, 96.390, 891.0, 29.8496
64.566692504, 96.390, 840.0, 28.9828
64.619213635, 96.390, 917.0, 30.2820
64.671734766, 96.390, 869.0, 29.4788
64.724255896, 96.390, 880.0, 29.6648
64.776777027, 96.390, 881.0, 29.6816
64.829298158, 96.390, 930.0, 30.4959
64.881819289, 96.390, 902.0, 30.0333
64.934340419, 96.390, 875.0, 29.5804
64.986861550, 96.390, 894.0, 29.8998