File: Files_organized_for_plots/PC/XRD_PC_AlcornerPC27oct21.csv
[Measurement conditions]
Sample identification,MNASPH_ALcornerPC27oct21
Comment - 1,"Configuration=Stage for Flat Samples/Holders, Owner=User-1, Creation date=7/1/2020 9:53:24 AM"
Comment - 2,"Goniometer=Theta/Theta; Minimum step size 2Theta:0.0001; Minimum step size Omega:0.0001"
Comment - 3,"Sample stage=Stage for flat samples/holders"
Comment - 4,"Diffractometer system=EMPYREAN"
Comment - 5,"Measurement program=C:\Users\ibo5034\OneDrive - The Pennsylvania State University\NEUP\Zerobackground scan.xrdmp, Identifier={98A3B11C-88F9-4AA6-982C-73314A311EF5}"
Anode material,Cu
K-Alpha1 wavelength,1.5405980
K-Alpha2 wavelength,1.5444260
Ratio K-Alpha2/K-Alpha1,0.500
Divergence slit,Fixed,0.25
Monochromator used,NO
Generator voltage, 45
Tube current, 40
File date and time,03/Dec/2021 10:17
Unit cell,
h k l, 0 0 0
Scan axis,Gonio
Scan range,4.994599997,64.999991833
Scan step size,0.0262606
No. of points, 2285
Scan type,CONTINUOUS
Time per step,96.390
[Scan points]
Angle, TimePerStep, Intensity, ESD
5.007730280, 96.390, 5442.0, 73.7699
5.060251411, 96.390, 5265.0, 72.5603
5.112772541, 96.390, 5174.0, 71.9305
5.165293672, 96.390, 5165.0, 71.8679
5.217814803, 96.390, 5083.0, 71.2952
5.270335934, 96.390, 4951.0, 70.3633
5.322857064, 96.390, 4842.0, 69.5845
5.375378195, 96.390, 4679.0, 68.4032
5.427899326, 96.390, 4638.0, 68.1029
5.480420456, 96.390, 4701.0, 68.5638
5.532941587, 96.390, 4576.0, 67.6461
5.585462718, 96.390, 4622.0, 67.9853
5.637983849, 96.390, 4418.0, 66.4680
5.690504979, 96.390, 4432.0, 66.5733
5.743026110, 96.390, 4428.0, 66.5432
5.795547241, 96.390, 4383.0, 66.2042
5.848068371, 96.390, 4297.0, 65.5515
5.900589502, 96.390, 4207.0, 64.8614
5.953110633, 96.390, 4234.0, 65.0692
6.005631763, 96.390, 4130.0, 64.2651
6.058152894, 96.390, 4161.0, 64.5058
6.110674025, 96.390, 4053.0, 63.6632
6.163195156, 96.390, 4074.0, 63.8279
6.215716286, 96.390, 3942.0, 62.7853
6.268237417, 96.390, 3957.0, 62.9047
6.320758548, 96.390, 4000.0, 63.2456
6.373279678, 96.390, 3926.0, 62.6578
6.425800809, 96.390, 3942.0, 62.7853
6.478321940, 96.390, 3765.0, 61.3596
6.530843071, 96.390, 3864.0, 62.1611
6.583364201, 96.390, 3821.0, 61.8142
6.635885332, 96.390, 3769.0, 61.3922
6.688406463, 96.390, 3723.0, 61.0164
6.740927593, 96.390, 3705.0, 60.8687
6.793448724, 96.390, 3724.0, 61.0246
6.845969855, 96.390, 3704.0, 60.8605
6.898490986, 96.390, 3716.0, 60.9590
6.951012116, 96.390, 3639.0, 60.3241
7.003533247, 96.390, 3559.0, 59.6574
7.056054378, 96.390, 3496.0, 59.1270
7.108575508, 96.390, 3532.0, 59.4306
7.161096639, 96.390, 3519.0, 59.3212
7.213617770, 96.390, 3625.0, 60.2080
7.266138900, 96.390, 3368.0, 58.0345
7.318660031, 96.390, 3601.0, 60.0083
7.371181162, 96.390, 3448.0, 58.7197
7.423702293, 96.390, 3524.0, 59.3633
7.476223423, 96.390, 3408.0, 58.3781
7.528744554, 96.390, 3330.0, 57.7062
7.581265685, 96.390, 3402.0, 58.3267
7.633786815, 96.390, 3432.0, 58.5833
7.686307946, 96.390, 3430.0, 58.5662
7.738829077, 96.390, 3365.0, 58.0086
7.791350208, 96.390, 3450.0, 58.7367
7.843871338, 96.390, 3351.0, 57.8878
7.896392469, 96.390, 3356.0, 57.9310
7.948913600, 96.390, 3314.0, 57.5674
8.001434730, 96.390, 3346.0, 57.8446
8.053955861, 96.390, 3308.0, 57.5152
8.106476992, 96.390, 3369.0, 58.0431
8.158998123, 96.390, 3348.0, 57.8619
8.211519253, 96.390, 3304.0, 57.4804
8.264040384, 96.390, 3268.0, 57.1664
8.316561515, 96.390, 3260.0, 57.0964
8.369082645, 96.390, 3235.0, 56.8771
8.421603776, 96.390, 3216.0, 56.7098
8.474124907, 96.390, 3181.0, 56.4004
8.526646038, 96.390, 3155.0, 56.1694
8.579167168, 96.390, 3096.0, 55.6417
8.631688299, 96.390, 3234.0, 56.8683
8.684209430, 96.390, 3138.0, 56.0179
8.736730560, 96.390, 3040.0, 55.1362
8.789251691, 96.390, 3067.0, 55.3805
8.841772822, 96.390, 3209.0, 56.6480
8.894293952, 96.390, 3108.0, 55.7494
8.946815083, 96.390, 3067.0, 55.3805
8.999336214, 96.390, 3026.0, 55.0091
9.051857345, 96.390, 3033.0, 55.0727
9.104378475, 96.390, 3048.0, 55.2087
9.156899606, 96.390, 3055.0, 55.2721
9.209420737, 96.390, 2987.0, 54.6535
9.261941867, 96.390, 2958.0, 54.3875
9.314462998, 96.390, 2958.0, 54.3875
9.366984129, 96.390, 2989.0, 54.6717
9.419505260, 96.390, 3036.0, 55.0999
9.472026390, 96.390, 2990.0, 54.6809
9.524547521, 96.390, 2951.0, 54.3231
9.577068652, 96.390, 2946.0, 54.2771
9.629589782, 96.390, 2892.0, 53.7773
9.682110913, 96.390, 2861.0, 53.4883
9.734632044, 96.390, 2877.0, 53.6377
9.787153175, 96.390, 2893.0, 53.7866
9.839674305, 96.390, 2841.0, 53.3010
9.892195436, 96.390, 2926.0, 54.0925
9.944716567, 96.390, 2955.0, 54.3599
9.997237697, 96.390, 2839.0, 53.2823
10.049758828, 96.390, 2834.0, 53.2353
10.102279959, 96.390, 2925.0, 54.0833
10.154801090, 96.390, 2878.0, 53.6470
10.207322220, 96.390, 2789.0, 52.8110
10.259843351, 96.390, 2832.0, 53.2165
10.312364482, 96.390, 2863.0, 53.5070
10.364885612, 96.390, 2748.0, 52.4214
10.417406743, 96.390, 2809.0, 53.0000
10.469927874, 96.390, 2815.0, 53.0566
10.522449004, 96.390, 2723.0, 52.1824
10.574970135, 96.390, 2713.0, 52.0865
10.627491266, 96.390, 2762.0, 52.5547
10.680012397, 96.390, 2784.0, 52.7636
10.732533527, 96.390, 2794.0, 52.8583
10.785054658, 96.390, 2739.0, 52.3355
10.837575789, 96.390, 2714.0, 52.0961
10.890096919, 96.390, 2728.0, 52.2303
10.942618050, 96.390, 2732.0, 52.2685
10.995139181, 96.390, 2677.0, 51.7397
11.047660312, 96.390, 2744.0, 52.3832
11.100181442, 96.390, 2650.0, 51.4782
11.152702573, 96.390, 2777.0, 52.6972
11.205223704, 96.390, 2708.0, 52.0384
11.257744834, 96.390, 2696.0, 51.9230
11.310265965, 96.390, 2626.0, 51.2445
11.362787096, 96.390, 2671.0, 51.6817
11.415308227, 96.390, 2605.0, 51.0392
11.467829357, 96.390, 2557.0, 50.5668
11.520350488, 96.390, 2613.0, 51.1175
11.572871619, 96.390, 2540.0, 50.3984
11.625392749, 96.390, 2639.0, 51.3712
11.677913880, 96.390, 2542.0, 50.4183
11.730435011, 96.390, 2631.0, 51.2933
11.782956141, 96.390, 2493.0, 49.9300
11.835477272, 96.390, 2621.0, 51.1957
11.887998403, 96.390, 2617.0, 51.1566
11.940519534, 96.390, 2565.0, 50.6458
11.993040664, 96.390, 2539.0, 50.3885
12.045561795, 96.390, 2511.0, 50.1099
12.098082926, 96.390, 2564.0, 50.6360
12.150604056, 96.390, 2605.0, 51.0392
12.203125187, 96.390, 2606.0, 51.0490
12.255646318, 96.390, 2484.0, 49.8397
12.308167449, 96.390, 2456.0, 49.5580
12.360688579, 96.390, 2538.0, 50.3786
12.413209710, 96.390, 2509.0, 50.0899
12.465730841, 96.390, 2537.0, 50.3686
12.518251971, 96.390, 2508.0, 50.0799
12.570773102, 96.390, 2394.0, 48.9285
12.623294233, 96.390, 2542.0, 50.4183
12.675815364, 96.390, 2483.0, 49.8297
12.728336494, 96.390, 2495.0, 49.9500
12.780857625, 96.390, 2531.0, 50.3090
12.833378756, 96.390, 2440.0, 49.3964
12.885899886, 96.390, 2402.0, 49.0102
12.938421017, 96.390, 2414.0, 49.1325
12.990942148, 96.390, 2470.0, 49.6991
13.043463279, 96.390, 2433.0, 49.3254
13.095984409, 96.390, 2478.0, 49.7795
13.148505540, 96.390, 2511.0, 50.1099
13.201026671, 96.390, 2414.0, 49.1325
13.253547801, 96.390, 2417.0, 49.1630
13.306068932, 96.390, 2292.0, 47.8748
13.358590063, 96.390, 2392.0, 48.9081
13.411111193, 96.390, 2509.0, 50.0899
13.463632324, 96.390, 2476.0, 49.7594
13.516153455, 96.390, 2337.0, 48.3425
13.568674586, 96.390, 2401.0, 49.0000
13.621195716, 96.390, 2330.0, 48.2701
13.673716847, 96.390, 2399.0, 48.9796
13.726237978, 96.390, 2325.0, 48.2183
13.778759108, 96.390, 2414.0, 49.1325
13.831280239, 96.390, 2393.0, 48.9183
13.883801370, 96.390, 2360.0, 48.5798
13.936322501, 96.390, 2358.0, 48.5592
13.988843631, 96.390, 2381.0, 48.7955
14.041364762, 96.390, 2378.0, 48.7647
14.093885893, 96.390, 2455.0, 49.5480
14.146407023, 96.390, 2399.0, 48.9796
14.198928154, 96.390, 2332.0, 48.2908
14.251449285, 96.390, 2345.0, 48.4252
14.303970416, 96.390, 2292.0, 47.8748
14.356491546, 96.390, 2312.0, 48.0833
14.409012677, 96.390, 2390.0, 48.8876
14.461533808, 96.390, 2355.0, 48.5283
14.514054938, 96.390, 2275.0, 47.6970
14.566576069, 96.390, 2374.0, 48.7237
14.619097200, 96.390, 2343.0, 48.4045
14.671618331, 96.390, 2280.0, 47.7493
14.724139461, 96.390, 2251.0, 47.4447
14.776660592, 96.390, 2338.0, 48.3529
14.829181723, 96.390, 2259.0, 47.5289
14.881702853, 96.390, 2265.0, 47.5920
14.934223984, 96.390, 2250.0, 47.4342
14.986745115, 96.390, 2231.0, 47.2335
15.039266245, 96.390, 2308.0, 48.0416
15.091787376, 96.390, 2278.0, 47.7284
15.144308507, 96.390, 2197.0, 46.8722
15.196829638, 96.390, 2288.0, 47.8330
15.249350768, 96.390, 2314.0, 48.1041
15.301871899, 96.390, 2227.0, 47.1911
15.354393030, 96.390, 2200.0, 46.9042
15.406914160, 96.390, 2181.0, 46.7012
15.459435291, 96.390, 2331.0, 48.2804
15.511956422, 96.390, 2309.0, 48.0521
15.564477553, 96.390, 2347.0, 48.4458
15.616998683, 96.390, 2304.0, 48.0000
15.669519814, 96.390, 2277.0, 47.7179
15.722040945, 96.390, 2298.0, 47.9375
15.774562075, 96.390, 2246.0, 47.3920
15.827083206, 96.390, 2260.0, 47.5395
15.879604337, 96.390, 2273.0, 47.6760
15.932125468, 96.390, 2216.0, 47.0744
15.984646598, 96.390, 2240.0, 47.3286
16.037167729, 96.390, 2311.0, 48.0729
16.089688860, 96.390, 2235.0, 47.2758
16.142209990, 96.390, 2312.0, 48.0833
16.194731121, 96.390, 2264.0, 47.5815
16.247252252, 96.390, 2332.0, 48.2908
16.299773382, 96.390, 2263.0, 47.5710
16.352294513, 96.390, 2272.0, 47.6655
16.404815644, 96.390, 2393.0, 48.9183
16.457336775, 96.390, 2290.0, 47.8539
16.509857905, 96.390, 2256.0, 47.4974
16.562379036, 96.390, 2252.0, 47.4552
16.614900167, 96.390, 2268.0, 47.6235
16.667421297, 96.390, 2433.0, 49.3254
16.719942428, 96.390, 2276.0, 47.7074
16.772463559, 96.390, 2213.0, 47.0425
16.824984690, 96.390, 2329.0, 48.2597
16.877505820, 96.390, 2343.0, 48.4045
16.930026951, 96.390, 2296.0, 47.9166
16.982548082, 96.390, 2372.0, 48.7032
17.035069212, 96.390, 2260.0, 47.5395
17.087590343, 96.390, 2303.0, 47.9896
17.140111474, 96.390, 2323.0, 48.1975
17.192632605, 96.390, 2327.0, 48.2390
17.245153735, 96.390, 2352.0, 48.4974
17.297674866, 96.390, 2313.0, 48.0937
17.350195997, 96.390, 2333.0, 48.3011
17.402717127, 96.390, 2290.0, 47.8539
17.455238258, 96.390, 2365.0, 48.6313
17.507759389, 96.390, 2356.0, 48.5386
17.560280520, 96.390, 2327.0, 48.2390
17.612801650, 96.390, 2434.0, 49.3356
17.665322781, 96.390, 2294.0, 47.8957
17.717843912, 96.390, 2409.0, 49.0816
17.770365042, 96.390, 2437.0, 49.3660
17.822886173, 96.390, 2448.0, 49.4773
17.875407304, 96.390, 2419.0, 49.1833
17.927928434, 96.390, 2431.0, 49.3052
17.980449565, 96.390, 2443.0, 49.4267
18.032970696, 96.390, 2385.0, 48.8365
18.085491827, 96.390, 2503.0, 50.0300
18.138012957, 96.390, 2425.0, 49.2443
18.190534088, 96.390, 2424.0, 49.2341
18.243055219, 96.390, 2399.0, 48.9796
18.295576349, 96.390, 2489.0, 49.8899
18.348097480, 96.390, 2482.0, 49.8197
18.400618611, 96.390, 2534.0, 50.3389
18.453139742, 96.390, 2546.0, 50.4579
18.505660872, 96.390, 2536.0, 50.3587
18.558182003, 96.390, 2478.0, 49.7795
18.610703134, 96.390, 2422.0, 49.2138
18.663224264, 96.390, 2543.0, 50.4282
18.715745395, 96.390, 2525.0, 50.2494
18.768266526, 96.390, 2587.0, 50.8626
18.820787657, 96.390, 2643.0, 51.4101
18.873308787, 96.390, 2497.0, 49.9700
18.925829918, 96.390, 2550.0, 50.4975
18.978351049, 96.390, 2526.0, 50.2593
19.030872179, 96.390, 2603.0, 51.0196
19.083393310, 96.390, 2553.0, 50.5272
19.135914441, 96.390, 2629.0, 51.2738
19.188435572, 96.390, 2589.0, 50.8822
19.240956702, 96.390, 2664.0, 51.6140
19.293477833, 96.390, 2607.0, 51.0588
19.345998964, 96.390, 2639.0, 51.3712
19.398520094, 96.390, 2709.0, 52.0481
19.451041225, 96.390, 2658.0, 51.5558
19.503562356, 96.390, 2714.0, 52.0961
19.556083486, 96.390, 2764.0, 52.5738
19.608604617, 96.390, 2602.0, 51.0098
19.661125748, 96.390, 2664.0, 51.6140
19.713646879, 96.390, 2779.0, 52.7162
19.766168009, 96.390, 2824.0, 53.1413
19.818689140, 96.390, 2681.0, 51.7784
19.871210271, 96.390, 2718.0, 52.1344
19.923731401, 96.390, 2717.0, 52.1249
19.976252532, 96.390, 2772.0, 52.6498
20.028773663, 96.390, 2820.0, 53.1037
20.081294794, 96.390, 2854.0, 53.4228
20.133815924, 96.390, 2731.0, 52.2590
20.186337055, 96.390, 2716.0, 52.1153
20.238858186, 96.390, 2848.0, 53.3667
20.291379316, 96.390, 2834.0, 53.2353
20.343900447, 96.390, 2916.0, 54.0000
20.396421578, 96.390, 2872.0, 53.5910
20.448942709, 96.390, 2983.0, 54.6168
20.501463839, 96.390, 2784.0, 52.7636
20.553984970, 96.390, 2897.0, 53.8238
20.606506101, 96.390, 2906.0, 53.9073
20.659027231, 96.390, 2928.0, 54.1110
20.711548362, 96.390, 2977.0, 54.5619
20.764069493, 96.390, 2803.0, 52.9434
20.816590623, 96.390, 2784.0, 52.7636
20.869111754, 96.390, 2978.0, 54.5711
20.921632885, 96.390, 2978.0, 54.5711
20.974154016, 96.390, 2910.0, 53.9444
21.026675146, 96.390, 3028.0, 55.0273
21.079196277, 96.390, 3088.0, 55.5698
21.131717408, 96.390, 2895.0, 53.8052
21.184238538, 96.390, 2987.0, 54.6535
21.236759669, 96.390, 3045.0, 55.1815
21.289280800, 96.390, 2968.0, 54.4794
21.341801931, 96.390, 3060.0, 55.3173
21.394323061, 96.390, 2994.0, 54.7175
21.446844192, 96.390, 2992.0, 54.6992
21.499365323, 96.390, 3010.0, 54.8635
21.551886453, 96.390, 3013.0, 54.8908
21.604407584, 96.390, 3048.0, 55.2087
21.656928715, 96.390, 2966.0, 54.4610
21.709449846, 96.390, 3075.0, 55.4527
21.761970976, 96.390, 3021.0, 54.9636
21.814492107, 96.390, 3146.0, 56.0892
21.867013238, 96.390, 3068.0, 55.3895
21.919534368, 96.390, 3136.0, 56.0000
21.972055499, 96.390, 3173.0, 56.3294
22.024576630, 96.390, 3278.0, 57.2538
22.077097761, 96.390, 3094.0, 55.6237
22.129618891, 96.390, 3210.0, 56.6569
22.182140022, 96.390, 3141.0, 56.0446
22.234661153, 96.390, 3183.0, 56.4181
22.287182283, 96.390, 3128.0, 55.9285
22.339703414, 96.390, 3269.0, 57.1752
22.392224545, 96.390, 3224.0, 56.7803
22.444745675, 96.390, 3199.0, 56.5597
22.497266806, 96.390, 3034.0, 55.0818
22.549787937, 96.390, 3243.0, 56.9473
22.602309068, 96.390, 3200.0, 56.5685
22.654830198, 96.390, 3187.0, 56.4535
22.707351329, 96.390, 3211.0, 56.6657
22.759872460, 96.390, 3167.0, 56.2761
22.812393590, 96.390, 3160.0, 56.2139
22.864914721, 96.390, 3187.0, 56.4535
22.917435852, 96.390, 3180.0, 56.3915
22.969956983, 96.390, 3117.0, 55.8301
23.022478113, 96.390, 3130.0, 55.9464
23.074999244, 96.390, 3138.0, 56.0179
23.127520375, 96.390, 3118.0, 55.8391
23.180041505, 96.390, 3069.0, 55.3986
23.232562636, 96.390, 3021.0, 54.9636
23.285083767, 96.390, 3137.0, 56.0089
23.337604898, 96.390, 3198.0, 56.5509
23.390126028, 96.390, 3155.0, 56.1694
23.442647159, 96.390, 3080.0, 55.4977
23.495168290, 96.390, 3107.0, 55.7405
23.547689420, 96.390, 3094.0, 55.6237
23.600210551, 96.390, 3055.0, 55.2721
23.652731682, 96.390, 3108.0, 55.7494
23.705252813, 96.390, 3108.0, 55.7494
23.757773943, 96.390, 3107.0, 55.7405
23.810295074, 96.390, 3103.0, 55.7046
23.862816205, 96.390, 3102.0, 55.6956
23.915337335, 96.390, 3116.0, 55.8211
23.967858466, 96.390, 3075.0, 55.4527
24.020379597, 96.390, 3081.0, 55.5068
24.072900727, 96.390, 3066.0, 55.3715
24.125421858, 96.390, 3026.0, 55.0091
24.177942989, 96.390, 3048.0, 55.2087
24.230464120, 96.390, 3142.0, 56.0535
24.282985250, 96.390, 2990.0, 54.6809
24.335506381, 96.390, 3034.0, 55.0818
24.388027512, 96.390, 3047.0, 55.1996
24.440548642, 96.390, 3089.0, 55.5788
24.493069773, 96.390, 2983.0, 54.6168
24.545590904, 96.390, 2954.0, 54.3507
24.598112035, 96.390, 3025.0, 55.0000
24.650633165, 96.390, 3039.0, 55.1271
24.703154296, 96.390, 3049.0, 55.2178
24.755675427, 96.390, 2865.0, 53.5257
24.808196557, 96.390, 3106.0, 55.7315
24.860717688, 96.390, 2900.0, 53.8516
24.913238819, 96.390, 2937.0, 54.1941
24.965759950, 96.390, 2930.0, 54.1295
25.018281080, 96.390, 2936.0, 54.1849
25.070802211, 96.390, 2958.0, 54.3875
25.123323342, 96.390, 2954.0, 54.3507
25.175844472, 96.390, 2879.0, 53.6563
25.228365603, 96.390, 2966.0, 54.4610
25.280886734, 96.390, 2856.0, 53.4416
25.333407864, 96.390, 3082.0, 55.5158
25.385928995, 96.390, 2909.0, 53.9351
25.438450126, 96.390, 2878.0, 53.6470
25.490971257, 96.390, 2756.0, 52.4976
25.543492387, 96.390, 2854.0, 53.4228
25.596013518, 96.390, 2907.0, 53.9166
25.648534649, 96.390, 2878.0, 53.6470
25.701055779, 96.390, 2860.0, 53.4790
25.753576910, 96.390, 2915.0, 53.9907
25.806098041, 96.390, 2762.0, 52.5547
25.858619172, 96.390, 2828.0, 53.1789
25.911140302, 96.390, 2837.0, 53.2635
25.963661433, 96.390, 2790.0, 52.8205
26.016182564, 96.390, 2706.0, 52.0192
26.068703694, 96.390, 2754.0, 52.4786
26.121224825, 96.390, 2739.0, 52.3355
26.173745956, 96.390, 2722.0, 52.1728
26.226267087, 96.390, 2757.0, 52.5071
26.278788217, 96.390, 2724.0, 52.1920
26.331309348, 96.390, 2764.0, 52.5738
26.383830479, 96.390, 2752.0, 52.4595
26.436351609, 96.390, 2713.0, 52.0865
26.488872740, 96.390, 2666.0, 51.6333
26.541393871, 96.390, 2713.0, 52.0865
26.593915002, 96.390, 2759.0, 52.5262
26.646436132, 96.390, 2727.0, 52.2207
26.698957263, 96.390, 2706.0, 52.0192
26.751478394, 96.390, 2748.0, 52.4214
26.803999524, 96.390, 2663.0, 51.6043
26.856520655, 96.390, 2643.0, 51.4101
26.909041786, 96.390, 2654.0, 51.5170
26.961562916, 96.390, 2719.0, 52.1440
27.014084047, 96.390, 2714.0, 52.0961
27.066605178, 96.390, 2642.0, 51.4004
27.119126309, 96.390, 2669.0, 51.6624
27.171647439, 96.390, 2649.0, 51.4684
27.224168570, 96.390, 2618.0, 51.1664
27.276689701, 96.390, 2699.0, 51.9519
27.329210831, 96.390, 2621.0, 51.1957
27.381731962, 96.390, 2599.0, 50.9804
27.434253093, 96.390, 2670.0, 51.6720
27.486774224, 96.390, 2636.0, 51.3420
27.539295354, 96.390, 2561.0, 50.6063
27.591816485, 96.390, 2608.0, 51.0686
27.644337616, 96.390, 2538.0, 50.3786
27.696858746, 96.390, 2539.0, 50.3885
27.749379877, 96.390, 2553.0, 50.5272
27.801901008, 96.390, 2525.0, 50.2494
27.854422139, 96.390, 2455.0, 49.5480
27.906943269, 96.390, 2568.0, 50.6754
27.959464400, 96.390, 2607.0, 51.0588
28.011985531, 96.390, 2486.0, 49.8598
28.064506661, 96.390, 2434.0, 49.3356
28.117027792, 96.390, 2503.0, 50.0300
28.169548923, 96.390, 2435.0, 49.3457
28.222070054, 96.390, 2453.0, 49.5278
28.274591184, 96.390, 2393.0, 48.9183
28.327112315, 96.390, 2461.0, 49.6085
28.379633446, 96.390, 2390.0, 48.8876
28.432154576, 96.390, 2430.0, 49.2950
28.484675707, 96.390, 2468.0, 49.6790
28.537196838, 96.390, 2535.0, 50.3488
28.589717968, 96.390, 2441.0, 49.4065
28.642239099, 96.390, 2365.0, 48.6313
28.694760230, 96.390, 2367.0, 48.6518
28.747281361, 96.390, 2399.0, 48.9796
28.799802491, 96.390, 2313.0, 48.0937
28.852323622, 96.390, 2489.0, 49.8899
28.904844753, 96.390, 2377.0, 48.7545
28.957365883, 96.390, 2336.0, 48.3322
29.009887014, 96.390, 2335.0, 48.3218
29.062408145, 96.390, 2387.0, 48.8569
29.114929276, 96.390, 2400.0, 48.9898
29.167450406, 96.390, 2327.0, 48.2390
29.219971537, 96.390, 2386.0, 48.8467
29.272492668, 96.390, 2222.0, 47.1381
29.325013798, 96.390, 2322.0, 48.1871
29.377534929, 96.390, 2316.0, 48.1248
29.430056060, 96.390, 2238.0, 47.3075
29.482577191, 96.390, 2260.0, 47.5395
29.535098321, 96.390, 2378.0, 48.7647
29.587619452, 96.390, 2309.0, 48.0521
29.640140583, 96.390, 2316.0, 48.1248
29.692661713, 96.390, 2249.0, 47.4236
29.745182844, 96.390, 2210.0, 47.0106
29.797703975, 96.390, 2218.0, 47.0956
29.850225105, 96.390, 2296.0, 47.9166
29.902746236, 96.390, 2227.0, 47.1911
29.955267367, 96.390, 2199.0, 46.8935
30.007788498, 96.390, 2120.0, 46.0435
30.060309628, 96.390, 2188.0, 46.7761
30.112830759, 96.390, 2228.0, 47.2017
30.165351890, 96.390, 2200.0, 46.9042
30.217873020, 96.390, 2259.0, 47.5289
30.270394151, 96.390, 2148.0, 46.3465
30.322915282, 96.390, 2145.0, 46.3141
30.375436413, 96.390, 2152.0, 46.3897
30.427957543, 96.390, 2270.0, 47.6445
30.480478674, 96.390, 2127.0, 46.1194
30.532999805, 96.390, 2108.0, 45.9130
30.585520935, 96.390, 2140.0, 46.2601
30.638042066, 96.390, 2123.0, 46.0760
30.690563197, 96.390, 2184.0, 46.7333
30.743084328, 96.390, 2025.0, 45.0000
30.795605458, 96.390, 2145.0, 46.3141
30.848126589, 96.390, 2055.0, 45.3321
30.900647720, 96.390, 2169.0, 46.5725
30.953168850, 96.390, 2142.0, 46.2817
31.005689981, 96.390, 2120.0, 46.0435
31.058211112, 96.390, 2124.0, 46.0869
31.110732243, 96.390, 2049.0, 45.2659
31.163253373, 96.390, 2070.0, 45.4973
31.215774504, 96.390, 2123.0, 46.0760
31.268295635, 96.390, 2086.0, 45.6727
31.320816765, 96.390, 2105.0, 45.8803
31.373337896, 96.390, 2169.0, 46.5725
31.425859027, 96.390, 2033.0, 45.0888
31.478380157, 96.390, 2010.0, 44.8330
31.530901288, 96.390, 2025.0, 45.0000
31.583422419, 96.390, 2008.0, 44.8107
31.635943550, 96.390, 2051.0, 45.2880
31.688464680, 96.390, 1983.0, 44.5309
31.740985811, 96.390, 2004.0, 44.7661
31.793506942, 96.390, 1998.0, 44.6990
31.846028072, 96.390, 1907.0, 43.6692
31.898549203, 96.390, 1901.0, 43.6005
31.951070334, 96.390, 1874.0, 43.2897
32.003591465, 96.390, 1942.0, 44.0681
32.056112595, 96.390, 1955.0, 44.2154
32.108633726, 96.390, 1961.0, 44.2832
32.161154857, 96.390, 1992.0, 44.6318
32.213675987, 96.390, 1917.0, 43.7836
32.266197118, 96.390, 1978.0, 44.4747
32.318718249, 96.390, 1934.0, 43.9773
32.371239380, 96.390, 1979.0, 44.4860
32.423760510, 96.390, 1916.0, 43.7721
32.476281641, 96.390, 1954.0, 44.2041
32.528802772, 96.390, 1884.0, 43.4051
32.581323902, 96.390, 1863.0, 43.1625
32.633845033, 96.390, 1878.0, 43.3359
32.686366164, 96.390, 1876.0, 43.3128
32.738887295, 96.390, 1898.0, 43.5660
32.791408425, 96.390, 1890.0, 43.4741
32.843929556, 96.390, 1897.0, 43.5546
32.896450687, 96.390, 1867.0, 43.2088
32.948971817, 96.390, 1913.0, 43.7379
33.001492948, 96.390, 1925.0, 43.8748
33.054014079, 96.390, 1915.0, 43.7607
33.106535209, 96.390, 1872.0, 43.2666
33.159056340, 96.390, 1917.0, 43.7836
33.211577471, 96.390, 1883.0, 43.3935
33.264098602, 96.390, 1941.0, 44.0568
33.316619732, 96.390, 1924.0, 43.8634
33.369140863, 96.390, 1736.0, 41.6653
33.421661994, 96.390, 1854.0, 43.0581
33.474183124, 96.390, 1783.0, 42.2256
33.526704255, 96.390, 1771.0, 42.0833
33.579225386, 96.390, 1875.0, 43.3013
33.631746517, 96.390, 1895.0, 43.5316
33.684267647, 96.390, 1753.0, 41.8688
33.736788778, 96.390, 1696.0, 41.1825
33.789309909, 96.390, 1803.0, 42.4617
33.841831039, 96.390, 1720.0, 41.4729
33.894352170, 96.390, 1798.0, 42.4028
33.946873301, 96.390, 1792.0, 42.3320
33.999394432, 96.390, 1770.0, 42.0714
34.051915562, 96.390, 1763.0, 41.9881
34.104436693, 96.390, 1722.0, 41.4970
34.156957824, 96.390, 1721.0, 41.4849
34.209478954, 96.390, 1753.0, 41.8688
34.262000085, 96.390, 1735.0, 41.6533
34.314521216, 96.390, 1798.0, 42.4028
34.367042346, 96.390, 1728.0, 41.5692
34.419563477, 96.390, 1688.0, 41.0853
34.472084608, 96.390, 1687.0, 41.0731
34.524605739, 96.390, 1646.0, 40.5709
34.577126869, 96.390, 1672.0, 40.8901
34.629648000, 96.390, 1772.0, 42.0951
34.682169131, 96.390, 1759.0, 41.9404
34.734690261, 96.390, 1696.0, 41.1825
34.787211392, 96.390, 1662.0, 40.7676
34.839732523, 96.390, 1725.0, 41.5331
34.892253654, 96.390, 1693.0, 41.1461
34.944774784, 96.390, 1689.0, 41.0974
34.997295915, 96.390, 1604.0, 40.0500
35.049817046, 96.390, 1644.0, 40.5463
35.102338176, 96.390, 1654.0, 40.6694
35.154859307, 96.390, 1637.0, 40.4599
35.207380438, 96.390, 1591.0, 39.8873
35.259901569, 96.390, 1621.0, 40.2616
35.312422699, 96.390, 1569.0, 39.6106
35.364943830, 96.390, 1619.0, 40.2368
35.417464961, 96.390, 1631.0, 40.3856
35.469986091, 96.390, 1597.0, 39.9625
35.522507222, 96.390, 1676.0, 40.9390
35.575028353, 96.390, 1705.0, 41.2916
35.627549484, 96.390, 1591.0, 39.8873
35.680070614, 96.390, 1586.0, 39.8246
35.732591745, 96.390, 1556.0, 39.4462
35.785112876, 96.390, 1574.0, 39.6737
35.837634006, 96.390, 1555.0, 39.4335
35.890155137, 96.390, 1482.0, 38.4968
35.942676268, 96.390, 1578.0, 39.7240
35.995197398, 96.390, 1551.0, 39.3827
36.047718529, 96.390, 1489.0, 38.5876
36.100239660, 96.390, 1535.0, 39.1791
36.152760791, 96.390, 1588.0, 39.8497
36.205281921, 96.390, 1546.0, 39.3192
36.257803052, 96.390, 1489.0, 38.5876
36.310324183, 96.390, 1491.0, 38.6135
36.362845313, 96.390, 1528.0, 39.0896
36.415366444, 96.390, 1549.0, 39.3573
36.467887575, 96.390, 1496.0, 38.6782
36.520408706, 96.390, 1556.0, 39.4462
36.572929836, 96.390, 1500.0, 38.7298
36.625450967, 96.390, 1398.0, 37.3898
36.677972098, 96.390, 1416.0, 37.6298
36.730493228, 96.390, 1454.0, 38.1314
36.783014359, 96.390, 1556.0, 39.4462
36.835535490, 96.390, 1491.0, 38.6135
36.888056621, 96.390, 1453.0, 38.1182
36.940577751, 96.390, 1525.0, 39.0512
36.993098882, 96.390, 1513.0, 38.8973
37.045620013, 96.390, 1503.0, 38.7685
37.098141143, 96.390, 1506.0, 38.8072
37.150662274, 96.390, 1427.0, 37.7757
37.203183405, 96.390, 1441.0, 37.9605
37.255704535, 96.390, 1484.0, 38.5227
37.308225666, 96.390, 1518.0, 38.9615
37.360746797, 96.390, 1401.0, 37.4299
37.413267928, 96.390, 1415.0, 37.6165
37.465789058, 96.390, 1385.0, 37.2156
37.518310189, 96.390, 1398.0, 37.3898
37.570831320, 96.390, 1451.0, 38.0920
37.623352450, 96.390, 1391.0, 37.2961
37.675873581, 96.390, 1373.0, 37.0540
37.728394712, 96.390, 1376.0, 37.0945
37.780915843, 96.390, 1413.0, 37.5899
37.833436973, 96.390, 1461.0, 38.2230
37.885958104, 96.390, 1382.0, 37.1753
37.938479235, 96.390, 1451.0, 38.0920
37.991000365, 96.390, 1393.0, 37.3229
38.043521496, 96.390, 1418.0, 37.6563
38.096042627, 96.390, 1389.0, 37.2693
38.148563758, 96.390, 1378.0, 37.1214
38.201084888, 96.390, 1302.0, 36.0832
38.253606019, 96.390, 1357.0, 36.8375
38.306127150, 96.390, 1355.0, 36.8103
38.358648280, 96.390, 1303.0, 36.0971
38.411169411, 96.390, 1331.0, 36.4829
38.463690542, 96.390, 1331.0, 36.4829
38.516211673, 96.390, 1433.0, 37.8550
38.568732803, 96.390, 1357.0, 36.8375
38.621253934, 96.390, 1426.0, 37.7624
38.673775065, 96.390, 1360.0, 36.8782
38.726296195, 96.390, 1329.0, 36.4555
38.778817326, 96.390, 1400.0, 37.4166
38.831338457, 96.390, 1248.0, 35.3270
38.883859587, 96.390, 1386.0, 37.2290
38.936380718, 96.390, 1294.0, 35.9722
38.988901849, 96.390, 1359.0, 36.8646
39.041422980, 96.390, 1314.0, 36.2491
39.093944110, 96.390, 1268.0, 35.6090
39.146465241, 96.390, 1298.0, 36.0278
39.198986372, 96.390, 1344.0, 36.6606
39.251507502, 96.390, 1340.0, 36.6060
39.304028633, 96.390, 1242.0, 35.2420
39.356549764, 96.390, 1354.0, 36.7967
39.409070895, 96.390, 1310.0, 36.1939
39.461592025, 96.390, 1270.0, 35.6371
39.514113156, 96.390, 1321.0, 36.3456
39.566634287, 96.390, 1280.0, 35.7771
39.619155417, 96.390, 1233.0, 35.1141
39.671676548, 96.390, 1296.0, 36.0000
39.724197679, 96.390, 1339.0, 36.5923
39.776718810, 96.390, 1304.0, 36.1109
39.829239940, 96.390, 1302.0, 36.0832
39.881761071, 96.390, 1270.0, 35.6371
39.934282202, 96.390, 1319.0, 36.3180
39.986803332, 96.390, 1378.0, 37.1214
40.039324463, 96.390, 1253.0, 35.3977
40.091845594, 96.390, 1363.0, 36.9188
40.144366725, 96.390, 1272.0, 35.6651
40.196887855, 96.390, 1340.0, 36.6060
40.249408986, 96.390, 1327.0, 36.4280
40.301930117, 96.390, 1312.0, 36.2215
40.354451247, 96.390, 1288.0, 35.8887
40.406972378, 96.390, 1300.0, 36.0555
40.459493509, 96.390, 1310.0, 36.1939
40.512014639, 96.390, 1317.0, 36.2905
40.564535770, 96.390, 1325.0, 36.4005
40.617056901, 96.390, 1252.0, 35.3836
40.669578032, 96.390, 1320.0, 36.3318
40.722099162, 96.390, 1280.0, 35.7771
40.774620293, 96.390, 1211.0, 34.7994
40.827141424, 96.390, 1295.0, 35.9861
40.879662554, 96.390, 1307.0, 36.1525
40.932183685, 96.390, 1331.0, 36.4829
40.984704816, 96.390, 1304.0, 36.1109
41.037225947, 96.390, 1278.0, 35.7491
41.089747077, 96.390, 1292.0, 35.9444
41.142268208, 96.390, 1254.0, 35.4119
41.194789339, 96.390, 1246.0, 35.2987
41.247310469, 96.390, 1265.0, 35.5668
41.299831600, 96.390, 1228.0, 35.0428
41.352352731, 96.390, 1284.0, 35.8329
41.404873862, 96.390, 1273.0, 35.6791
41.457394992, 96.390, 1223.0, 34.9714
41.509916123, 96.390, 1272.0, 35.6651
41.562437254, 96.390, 1229.0, 35.0571
41.614958384, 96.390, 1309.0, 36.1801
41.667479515, 96.390, 1293.0, 35.9583
41.720000646, 96.390, 1326.0, 36.4143
41.772521776, 96.390, 1207.0, 34.7419
41.825042907, 96.390, 1235.0, 35.1426
41.877564038, 96.390, 1293.0, 35.9583
41.930085169, 96.390, 1240.0, 35.2136
41.982606299, 96.390, 1254.0, 35.4119
42.035127430, 96.390, 1289.0, 35.9026
42.087648561, 96.390, 1246.0, 35.2987
42.140169691, 96.390, 1287.0, 35.8748
42.192690822, 96.390, 1193.0, 34.5398
42.245211953, 96.390, 1263.0, 35.5387
42.297733084, 96.390, 1247.0, 35.3129
42.350254214, 96.390, 1251.0, 35.3695
42.402775345, 96.390, 1210.0, 34.7851
42.455296476, 96.390, 1189.0, 34.4819
42.507817606, 96.390, 1222.0, 34.9571
42.560338737, 96.390, 1187.0, 34.4529
42.612859868, 96.390, 1182.0, 34.3802
42.665380999, 96.390, 1162.0, 34.0881
42.717902129, 96.390, 1248.0, 35.3270
42.770423260, 96.390, 1193.0, 34.5398
42.822944391, 96.390, 1260.0, 35.4965
42.875465521, 96.390, 1138.0, 33.7343
42.927986652, 96.390, 1233.0, 35.1141
42.980507783, 96.390, 1243.0, 35.2562
43.033028914, 96.390, 1213.0, 34.8281
43.085550044, 96.390, 1199.0, 34.6266
43.138071175, 96.390, 1178.0, 34.3220
43.190592306, 96.390, 1199.0, 34.6266
43.243113436, 96.390, 1176.0, 34.2929
43.295634567, 96.390, 1265.0, 35.5668
43.348155698, 96.390, 1207.0, 34.7419
43.400676828, 96.390, 1163.0, 34.1028
43.453197959, 96.390, 1203.0, 34.6843
43.505719090, 96.390, 1179.0, 34.3366
43.558240221, 96.390, 1251.0, 35.3695
43.610761351, 96.390, 1170.0, 34.2053
43.663282482, 96.390, 1243.0, 35.2562
43.715803613, 96.390, 1154.0, 33.9706
43.768324743, 96.390, 1181.0, 34.3657
43.820845874, 96.390, 1132.0, 33.6452
43.873367005, 96.390, 1202.0, 34.6699
43.925888136, 96.390, 1186.0, 34.4384
43.978409266, 96.390, 1161.0, 34.0735
44.030930397, 96.390, 1140.0, 33.7639
44.083451528, 96.390, 1136.0, 33.7046
44.135972658, 96.390, 1132.0, 33.6452
44.188493789, 96.390, 1114.0, 33.3766
44.241014920, 96.390, 1141.0, 33.7787
44.293536051, 96.390, 1178.0, 34.3220
44.346057181, 96.390, 1156.0, 34.0000
44.398578312, 96.390, 1116.0, 33.4066
44.451099443, 96.390, 1189.0, 34.4819
44.503620573, 96.390, 1109.0, 33.3017
44.556141704, 96.390, 1158.0, 34.0294
44.608662835, 96.390, 1132.0, 33.6452
44.661183966, 96.390, 1158.0, 34.0294
44.713705096, 96.390, 1112.0, 33.3467
44.766226227, 96.390, 1143.0, 33.8083
44.818747358, 96.390, 1139.0, 33.7491
44.871268488, 96.390, 1129.0, 33.6006
44.923789619, 96.390, 1116.0, 33.4066
44.976310750, 96.390, 1127.0, 33.5708
45.028831880, 96.390, 1161.0, 34.0735
45.081353011, 96.390, 1086.0, 32.9545
45.133874142, 96.390, 1120.0, 33.4664
45.186395273, 96.390, 1155.0, 33.9853
45.238916403, 96.390, 1098.0, 33.1361
45.291437534, 96.390, 1123.0, 33.5112
45.343958665, 96.390, 1120.0, 33.4664
45.396479795, 96.390, 1095.0, 33.0908
45.449000926, 96.390, 1122.0, 33.4963
45.501522057, 96.390, 1074.0, 32.7719
45.554043188, 96.390, 1065.0, 32.6343
45.606564318, 96.390, 1150.0, 33.9116
45.659085449, 96.390, 1087.0, 32.9697
45.711606580, 96.390, 1086.0, 32.9545
45.764127710, 96.390, 1114.0, 33.3766
45.816648841, 96.390, 1077.0, 32.8177
45.869169972, 96.390, 1066.0, 32.6497
45.921691103, 96.390, 1156.0, 34.0000
45.974212233, 96.390, 1116.0, 33.4066
46.026733364, 96.390, 1125.0, 33.5410
46.079254495, 96.390, 1143.0, 33.8083
46.131775625, 96.390, 1110.0, 33.3167
46.184296756, 96.390, 1093.0, 33.0606
46.236817887, 96.390, 1098.0, 33.1361
46.289339017, 96.390, 1049.0, 32.3883
46.341860148, 96.390, 1114.0, 33.3766
46.394381279, 96.390, 1078.0, 32.8329
46.446902410, 96.390, 1004.0, 31.6860
46.499423540, 96.390, 1057.0, 32.5115
46.551944671, 96.390, 1071.0, 32.7261
46.604465802, 96.390, 1053.0, 32.4500
46.656986932, 96.390, 1047.0, 32.3574
46.709508063, 96.390, 1012.0, 31.8119
46.762029194, 96.390, 1058.0, 32.5269
46.814550325, 96.390, 1031.0, 32.1092
46.867071455, 96.390, 1016.0, 31.8748
46.919592586, 96.390, 1014.0, 31.8434
46.972113717, 96.390, 1079.0, 32.8481
47.024634847, 96.390, 1070.0, 32.7109
47.077155978, 96.390, 1072.0, 32.7414
47.129677109, 96.390, 1038.0, 32.2180
47.182198240, 96.390, 1015.0, 31.8591
47.234719370, 96.390, 1005.0, 31.7017
47.287240501, 96.390, 1034.0, 32.1559
47.339761632, 96.390, 1046.0, 32.3419
47.392282762, 96.390, 954.0, 30.8869
47.444803893, 96.390, 1095.0, 33.0908
47.497325024, 96.390, 1039.0, 32.2335
47.549846155, 96.390, 1070.0, 32.7109
47.602367285, 96.390, 1052.0, 32.4345
47.654888416, 96.390, 970.0, 31.1448
47.707409547, 96.390, 1048.0, 32.3728
47.759930677, 96.390, 962.0, 31.0161
47.812451808, 96.390, 952.0, 30.8545
47.864972939, 96.390, 1013.0, 31.8277
47.917494069, 96.390, 965.0, 31.0644
47.970015200, 96.390, 981.0, 31.3209
48.022536331, 96.390, 1068.0, 32.6803
48.075057462, 96.390, 1024.0, 32.0000
48.127578592, 96.390, 1031.0, 32.1092
48.180099723, 96.390, 1021.0, 31.9531
48.232620854, 96.390, 1018.0, 31.9061
48.285141984, 96.390, 1043.0, 32.2955
48.337663115, 96.390, 1018.0, 31.9061
48.390184246, 96.390, 966.0, 31.0805
48.442705377, 96.390, 1022.0, 31.9687
48.495226507, 96.390, 951.0, 30.8383
48.547747638, 96.390, 1073.0, 32.7567
48.600268769, 96.390, 1032.0, 32.1248
48.652789899, 96.390, 1008.0, 31.7490
48.705311030, 96.390, 1038.0, 32.2180
48.757832161, 96.390, 1038.0, 32.2180
48.810353292, 96.390, 1023.0, 31.9844
48.862874422, 96.390, 973.0, 31.1929
48.915395553, 96.390, 992.0, 31.4960
48.967916684, 96.390, 1014.0, 31.8434
49.020437814, 96.390, 1021.0, 31.9531
49.072958945, 96.390, 997.0, 31.5753
49.125480076, 96.390, 975.0, 31.2250
49.178001207, 96.390, 980.0, 31.3050
49.230522337, 96.390, 997.0, 31.5753
49.283043468, 96.390, 993.0, 31.5119
49.335564599, 96.390, 1002.0, 31.6544
49.388085729, 96.390, 989.0, 31.4484
49.440606860, 96.390, 1036.0, 32.1870
49.493127991, 96.390, 945.0, 30.7409
49.545649121, 96.390, 1029.0, 32.0780
49.598170252, 96.390, 1031.0, 32.1092
49.650691383, 96.390, 988.0, 31.4325
49.703212514, 96.390, 992.0, 31.4960
49.755733644, 96.390, 982.0, 31.3369
49.808254775, 96.390, 974.0, 31.2090
49.860775906, 96.390, 941.0, 30.6757
49.913297036, 96.390, 1020.0, 31.9374
49.965818167, 96.390, 923.0, 30.3809
50.018339298, 96.390, 1021.0, 31.9531
50.070860429, 96.390, 1011.0, 31.7962
50.123381559, 96.390, 985.0, 31.3847
50.175902690, 96.390, 967.0, 31.0966
50.228423821, 96.390, 991.0, 31.4802
50.280944951, 96.390, 967.0, 31.0966
50.333466082, 96.390, 1013.0, 31.8277
50.385987213, 96.390, 967.0, 31.0966
50.438508344, 96.390, 948.0, 30.7896
50.491029474, 96.390, 888.0, 29.7993
50.543550605, 96.390, 945.0, 30.7409
50.596071736, 96.390, 948.0, 30.7896
50.648592866, 96.390, 999.0, 31.6070
50.701113997, 96.390, 935.0, 30.5778
50.753635128, 96.390, 952.0, 30.8545
50.806156258, 96.390, 975.0, 31.2250
50.858677389, 96.390, 1017.0, 31.8904
50.911198520, 96.390, 971.0, 31.1609
50.963719651, 96.390, 920.0, 30.3315
51.016240781, 96.390, 991.0, 31.4802
51.068761912, 96.390, 935.0, 30.5778
51.121283043, 96.390, 988.0, 31.4325
51.173804173, 96.390, 966.0, 31.0805
51.226325304, 96.390, 1018.0, 31.9061
51.278846435, 96.390, 971.0, 31.1609
51.331367566, 96.390, 957.0, 30.9354
51.383888696, 96.390, 948.0, 30.7896
51.436409827, 96.390, 949.0, 30.8058
51.488930958, 96.390, 953.0, 30.8707
51.541452088, 96.390, 956.0, 30.9192
51.593973219, 96.390, 933.0, 30.5450
51.646494350, 96.390, 955.0, 30.9031
51.699015481, 96.390, 928.0, 30.4631
51.751536611, 96.390, 918.0, 30.2985
51.804057742, 96.390, 990.0, 31.4643
51.856578873, 96.390, 974.0, 31.2090
51.909100003, 96.390, 947.0, 30.7734
51.961621134, 96.390, 949.0, 30.8058
52.014142265, 96.390, 973.0, 31.1929
52.066663396, 96.390, 965.0, 31.0644
52.119184526, 96.390, 930.0, 30.4959
52.171705657, 96.390, 928.0, 30.4631
52.224226788, 96.390, 912.0, 30.1993
52.276747918, 96.390, 993.0, 31.5119
52.329269049, 96.390, 944.0, 30.7246
52.381790180, 96.390, 957.0, 30.9354
52.434311310, 96.390, 984.0, 31.3688
52.486832441, 96.390, 934.0, 30.5614
52.539353572, 96.390, 930.0, 30.4959
52.591874703, 96.390, 944.0, 30.7246
52.644395833, 96.390, 1011.0, 31.7962
52.696916964, 96.390, 1003.0, 31.6702
52.749438095, 96.390, 939.0, 30.6431
52.801959225, 96.390, 1006.0, 31.7175
52.854480356, 96.390, 985.0, 31.3847
52.907001487, 96.390, 943.0, 30.7083
52.959522618, 96.390, 970.0, 31.1448
53.012043748, 96.390, 936.0, 30.5941
53.064564879, 96.390, 947.0, 30.7734
53.117086010, 96.390, 893.0, 29.8831
53.169607140, 96.390, 938.0, 30.6268
53.222128271, 96.390, 961.0, 31.0000
53.274649402, 96.390, 957.0, 30.9354
53.327170533, 96.390, 950.0, 30.8221
53.379691663, 96.390, 923.0, 30.3809
53.432212794, 96.390, 941.0, 30.6757
53.484733925, 96.390, 957.0, 30.9354
53.537255055, 96.390, 943.0, 30.7083
53.589776186, 96.390, 943.0, 30.7083
53.642297317, 96.390, 907.0, 30.1164
53.694818448, 96.390, 961.0, 31.0000
53.747339578, 96.390, 978.0, 31.2730
53.799860709, 96.390, 964.0, 31.0483
53.852381840, 96.390, 971.0, 31.1609
53.904902970, 96.390, 922.0, 30.3645
53.957424101, 96.390, 940.0, 30.6594
54.009945232, 96.390, 937.0, 30.6105
54.062466362, 96.390, 962.0, 31.0161
54.114987493, 96.390, 951.0, 30.8383
54.167508624, 96.390, 980.0, 31.3050
54.220029755, 96.390, 968.0, 31.1127
54.272550885, 96.390, 923.0, 30.3809
54.325072016, 96.390, 891.0, 29.8496
54.377593147, 96.390, 997.0, 31.5753
54.430114277, 96.390, 884.0, 29.7321
54.482635408, 96.390, 953.0, 30.8707
54.535156539, 96.390, 962.0, 31.0161
54.587677670, 96.390, 948.0, 30.7896
54.640198800, 96.390, 943.0, 30.7083
54.692719931, 96.390, 945.0, 30.7409
54.745241062, 96.390, 903.0, 30.0500
54.797762192, 96.390, 951.0, 30.8383
54.850283323, 96.390, 976.0, 31.2410
54.902804454, 96.390, 937.0, 30.6105
54.955325585, 96.390, 1022.0, 31.9687
55.007846715, 96.390, 999.0, 31.6070
55.060367846, 96.390, 897.0, 29.9500
55.112888977, 96.390, 933.0, 30.5450
55.165410107, 96.390, 933.0, 30.5450
55.217931238, 96.390, 964.0, 31.0483
55.270452369, 96.390, 958.0, 30.9516
55.322973499, 96.390, 959.0, 30.9677
55.375494630, 96.390, 988.0, 31.4325
55.428015761, 96.390, 948.0, 30.7896
55.480536892, 96.390, 998.0, 31.5911
55.533058022, 96.390, 982.0, 31.3369
55.585579153, 96.390, 941.0, 30.6757
55.638100284, 96.390, 1009.0, 31.7648
55.690621414, 96.390, 959.0, 30.9677
55.743142545, 96.390, 898.0, 29.9666
55.795663676, 96.390, 960.0, 30.9839
55.848184807, 96.390, 956.0, 30.9192
55.900705937, 96.390, 907.0, 30.1164
55.953227068, 96.390, 935.0, 30.5778
56.005748199, 96.390, 981.0, 31.3209
56.058269329, 96.390, 1023.0, 31.9844
56.110790460, 96.390, 934.0, 30.5614
56.163311591, 96.390, 919.0, 30.3150
56.215832722, 96.390, 997.0, 31.5753
56.268353852, 96.390, 989.0, 31.4484
56.320874983, 96.390, 963.0, 31.0322
56.373396114, 96.390, 997.0, 31.5753
56.425917244, 96.390, 978.0, 31.2730
56.478438375, 96.390, 968.0, 31.1127
56.530959506, 96.390, 940.0, 30.6594
56.583480637, 96.390, 908.0, 30.1330
56.636001767, 96.390, 980.0, 31.3050
56.688522898, 96.390, 934.0, 30.5614
56.741044029, 96.390, 965.0, 31.0644
56.793565159, 96.390, 956.0, 30.9192
56.846086290, 96.390, 997.0, 31.5753
56.898607421, 96.390, 923.0, 30.3809
56.951128551, 96.390, 977.0, 31.2570
57.003649682, 96.390, 963.0, 31.0322
57.056170813, 96.390, 958.0, 30.9516
57.108691944, 96.390, 956.0, 30.9192
57.161213074, 96.390, 927.0, 30.4467
57.213734205, 96.390, 916.0, 30.2655
57.266255336, 96.390, 941.0, 30.6757
57.318776466, 96.390, 963.0, 31.0322
57.371297597, 96.390, 945.0, 30.7409
57.423818728, 96.390, 971.0, 31.1609
57.476339859, 96.390, 999.0, 31.6070
57.528860989, 96.390, 1036.0, 32.1870
57.581382120, 96.390, 932.0, 30.5287
57.633903251, 96.390, 937.0, 30.6105
57.686424381, 96.390, 1001.0, 31.6386
57.738945512, 96.390, 986.0, 31.4006
57.791466643, 96.390, 928.0, 30.4631
57.843987774, 96.390, 998.0, 31.5911
57.896508904, 96.390, 1010.0, 31.7805
57.949030035, 96.390, 951.0, 30.8383
58.001551166, 96.390, 1027.0, 32.0468
58.054072296, 96.390, 927.0, 30.4467
58.106593427, 96.390, 984.0, 31.3688
58.159114558, 96.390, 956.0, 30.9192
58.211635689, 96.390, 933.0, 30.5450
58.264156819, 96.390, 967.0, 31.0966
58.316677950, 96.390, 1008.0, 31.7490
58.369199081, 96.390, 910.0, 30.1662
58.421720211, 96.390, 981.0, 31.3209
58.474241342, 96.390, 967.0, 31.0966
58.526762473, 96.390, 1096.0, 33.1059
58.579283603, 96.390, 1007.0, 31.7333
58.631804734, 96.390, 1048.0, 32.3728
58.684325865, 96.390, 989.0, 31.4484
58.736846996, 96.390, 992.0, 31.4960
58.789368126, 96.390, 1033.0, 32.1403
58.841889257, 96.390, 993.0, 31.5119
58.894410388, 96.390, 1058.0, 32.5269
58.946931518, 96.390, 984.0, 31.3688
58.999452649, 96.390, 938.0, 30.6268
59.051973780, 96.390, 947.0, 30.7734
59.104494911, 96.390, 971.0, 31.1609
59.157016041, 96.390, 961.0, 31.0000
59.209537172, 96.390, 982.0, 31.3369
59.262058303, 96.390, 1000.0, 31.6228
59.314579433, 96.390, 1010.0, 31.7805
59.367100564, 96.390, 965.0, 31.0644
59.419621695, 96.390, 1005.0, 31.7017
59.472142826, 96.390, 966.0, 31.0805
59.524663956, 96.390, 966.0, 31.0805
59.577185087, 96.390, 1016.0, 31.8748
59.629706218, 96.390, 1017.0, 31.8904
59.682227348, 96.390, 943.0, 30.7083
59.734748479, 96.390, 1030.0, 32.0936
59.787269610, 96.390, 978.0, 31.2730
59.839790740, 96.390, 1063.0, 32.6037
59.892311871, 96.390, 992.0, 31.4960
59.944833002, 96.390, 959.0, 30.9677
59.997354133, 96.390, 1005.0, 31.7017
60.049875263, 96.390, 970.0, 31.1448
60.102396394, 96.390, 1000.0, 31.6228
60.154917525, 96.390, 1018.0, 31.9061
60.207438655, 96.390, 1052.0, 32.4345
60.259959786, 96.390, 999.0, 31.6070
60.312480917, 96.390, 1041.0, 32.2645
60.365002048, 96.390, 987.0, 31.4166
60.417523178, 96.390, 999.0, 31.6070
60.470044309, 96.390, 986.0, 31.4006
60.522565440, 96.390, 983.0, 31.3528
60.575086570, 96.390, 1006.0, 31.7175
60.627607701, 96.390, 1023.0, 31.9844
60.680128832, 96.390, 1083.0, 32.9090
60.732649963, 96.390, 994.0, 31.5278
60.785171093, 96.390, 981.0, 31.3209
60.837692224, 96.390, 1001.0, 31.6386
60.890213355, 96.390, 938.0, 30.6268
60.942734485, 96.390, 963.0, 31.0322
60.995255616, 96.390, 1039.0, 32.2335
61.047776747, 96.390, 1017.0, 31.8904
61.100297878, 96.390, 1004.0, 31.6860
61.152819008, 96.390, 979.0, 31.2890
61.205340139, 96.390, 1033.0, 32.1403
61.257861270, 96.390, 977.0, 31.2570
61.310382400, 96.390, 1030.0, 32.0936
61.362903531, 96.390, 1046.0, 32.3419
61.415424662, 96.390, 981.0, 31.3209
61.467945792, 96.390, 993.0, 31.5119
61.520466923, 96.390, 952.0, 30.8545
61.572988054, 96.390, 1076.0, 32.8024
61.625509185, 96.390, 1037.0, 32.2025
61.678030315, 96.390, 982.0, 31.3369
61.730551446, 96.390, 1026.0, 32.0312
61.783072577, 96.390, 980.0, 31.3050
61.835593707, 96.390, 1040.0, 32.2490
61.888114838, 96.390, 988.0, 31.4325
61.940635969, 96.390, 1062.0, 32.5883
61.993157100, 96.390, 993.0, 31.5119
62.045678230, 96.390, 1003.0, 31.6702
62.098199361, 96.390, 987.0, 31.4166
62.150720492, 96.390, 1048.0, 32.3728
62.203241622, 96.390, 1047.0, 32.3574
62.255762753, 96.390, 999.0, 31.6070
62.308283884, 96.390, 1025.0, 32.0156
62.360805015, 96.390, 1037.0, 32.2025
62.413326145, 96.390, 1016.0, 31.8748
62.465847276, 96.390, 957.0, 30.9354
62.518368407, 96.390, 994.0, 31.5278
62.570889537, 96.390, 1071.0, 32.7261
62.623410668, 96.390, 1092.0, 33.0454
62.675931799, 96.390, 983.0, 31.3528
62.728452930, 96.390, 1006.0, 31.7175
62.780974060, 96.390, 1036.0, 32.1870
62.833495191, 96.390, 970.0, 31.1448
62.886016322, 96.390, 961.0, 31.0000
62.938537452, 96.390, 1042.0, 32.2800
62.991058583, 96.390, 1009.0, 31.7648
63.043579714, 96.390, 1023.0, 31.9844
63.096100844, 96.390, 1036.0, 32.1870
63.148621975, 96.390, 1031.0, 32.1092
63.201143106, 96.390, 986.0, 31.4006
63.253664237, 96.390, 1017.0, 31.8904
63.306185367, 96.390, 1037.0, 32.2025
63.358706498, 96.390, 984.0, 31.3688
63.411227629, 96.390, 1009.0, 31.7648
63.463748759, 96.390, 1078.0, 32.8329
63.516269890, 96.390, 1034.0, 32.1559
63.568791021, 96.390, 1000.0, 31.6228
63.621312152, 96.390, 1004.0, 31.6860
63.673833282, 96.390, 1065.0, 32.6343
63.726354413, 96.390, 1030.0, 32.0936
63.778875544, 96.390, 1022.0, 31.9687
63.831396674, 96.390, 1007.0, 31.7333
63.883917805, 96.390, 1012.0, 31.8119
63.936438936, 96.390, 1047.0, 32.3574
63.988960067, 96.390, 1011.0, 31.7962
64.041481197, 96.390, 949.0, 30.8058
64.094002328, 96.390, 975.0, 31.2250
64.146523459, 96.390, 940.0, 30.6594
64.199044589, 96.390, 1007.0, 31.7333
64.251565720, 96.390, 1040.0, 32.2490
64.304086851, 96.390, 1061.0, 32.5730
64.356607981, 96.390, 1073.0, 32.7567
64.409129112, 96.390, 1008.0, 31.7490
64.461650243, 96.390, 976.0, 31.2410
64.514171374, 96.390, 1024.0, 32.0000
64.566692504, 96.390, 1050.0, 32.4037
64.619213635, 96.390, 998.0, 31.5911
64.671734766, 96.390, 953.0, 30.8707
64.724255896, 96.390, 1042.0, 32.2800
64.776777027, 96.390, 1006.0, 31.7175
64.829298158, 96.390, 1001.0, 31.6386
64.881819289, 96.390, 1000.0, 31.6228
64.934340419, 96.390, 1018.0, 31.9061
64.986861550, 96.390, 1003.0, 31.6702