File: Files_organized_for_plots/Spin_V_0_background/Centroid08Dec21_Act12Feb23_B1_0714M_NaOH_LS0173_Num150.csv
[Measurement conditions]
Sample identification,Centroid08Dec21_Act12Feb23_B1_0714M_NaOH_LS0173_Num150
Comment - 1,"Configuration=Stage for Flat Samples/Holders, Owner=nmw10, Creation date=9/21/2022 10:06:30 AM"
Comment - 2,"Goniometer=Theta/Theta; Minimum step size 2Theta:0.0001; Minimum step size Omega:0.0001"
Comment - 3,"Sample stage=Stage for flat samples/holders"
Comment - 4,"Diffractometer system=EMPYREAN"
Comment - 5,"Measurement program=X:\XRD\Cement\Zerobackground scan.xrdmp, Created identifier={98A3B11C-88F9-4AA6-982C-73314A311EF5}, Created by=Titus Reed, Id=tmr79, Creation date=10/26/2021 3:01:47 PM"
Anode material,Cu
K-Alpha1 wavelength,1.5405980
K-Alpha2 wavelength,1.5444260
Ratio K-Alpha2/K-Alpha1,0.500
Divergence slit,Fixed,0.25
Monochromator used,NO
Generator voltage, 45
Tube current, 40
File date and time,15/Mar/2023 18:04
Unit cell,
h k l, 0 0 0
Scan axis,Gonio
Scan range,4.994599997,64.999991833
Scan step size,0.0262606
No. of points, 2285
Scan type,CONTINUOUS
Time per step,96.390
[Scan points]
Angle, TimePerStep, Intensity, ESD
5.007730280, 96.390, 4020.0, 63.4035
5.060251411, 96.390, 3985.0, 63.1269
5.112772541, 96.390, 4144.0, 64.3739
5.165293672, 96.390, 4106.0, 64.0781
5.217814803, 96.390, 4026.0, 63.4508
5.270335934, 96.390, 3946.0, 62.8172
5.322857064, 96.390, 4064.0, 63.7495
5.375378195, 96.390, 3979.0, 63.0793
5.427899326, 96.390, 3875.0, 62.2495
5.480420456, 96.390, 3819.0, 61.7981
5.532941587, 96.390, 3800.0, 61.6441
5.585462718, 96.390, 3645.0, 60.3738
5.637983849, 96.390, 3701.0, 60.8358
5.690504979, 96.390, 3775.0, 61.4410
5.743026110, 96.390, 3693.0, 60.7701
5.795547241, 96.390, 3679.0, 60.6548
5.848068371, 96.390, 3705.0, 60.8687
5.900589502, 96.390, 3511.0, 59.2537
5.953110633, 96.390, 3715.0, 60.9508
6.005631763, 96.390, 3585.0, 59.8749
6.058152894, 96.390, 3626.0, 60.2163
6.110674025, 96.390, 3672.0, 60.5970
6.163195156, 96.390, 3517.0, 59.3043
6.215716286, 96.390, 3589.0, 59.9083
6.268237417, 96.390, 3551.0, 59.5903
6.320758548, 96.390, 3580.0, 59.8331
6.373279678, 96.390, 3668.0, 60.5640
6.425800809, 96.390, 3503.0, 59.1861
6.478321940, 96.390, 3580.0, 59.8331
6.530843071, 96.390, 3469.0, 58.8982
6.583364201, 96.390, 3527.0, 59.3886
6.635885332, 96.390, 3633.0, 60.2744
6.688406463, 96.390, 3676.0, 60.6300
6.740927593, 96.390, 3600.0, 60.0000
6.793448724, 96.390, 3485.0, 59.0339
6.845969855, 96.390, 3578.0, 59.8164
6.898490986, 96.390, 3490.0, 59.0762
6.951012116, 96.390, 3464.0, 58.8558
7.003533247, 96.390, 3589.0, 59.9083
7.056054378, 96.390, 3490.0, 59.0762
7.108575508, 96.390, 3474.0, 58.9406
7.161096639, 96.390, 3653.0, 60.4401
7.213617770, 96.390, 3513.0, 59.2706
7.266138900, 96.390, 3544.0, 59.5315
7.318660031, 96.390, 3518.0, 59.3127
7.371181162, 96.390, 3536.0, 59.4643
7.423702293, 96.390, 3424.0, 58.5150
7.476223423, 96.390, 3574.0, 59.7829
7.528744554, 96.390, 3624.0, 60.1997
7.581265685, 96.390, 3615.0, 60.1249
7.633786815, 96.390, 3521.0, 59.3380
7.686307946, 96.390, 3528.0, 59.3970
7.738829077, 96.390, 3543.0, 59.5231
7.791350208, 96.390, 3573.0, 59.7746
7.843871338, 96.390, 3523.0, 59.3549
7.896392469, 96.390, 3456.0, 58.7878
7.948913600, 96.390, 3704.0, 60.8605
8.001434730, 96.390, 3576.0, 59.7997
8.053955861, 96.390, 3647.0, 60.3904
8.106476992, 96.390, 3692.0, 60.7618
8.158998123, 96.390, 3570.0, 59.7495
8.211519253, 96.390, 3650.0, 60.4152
8.264040384, 96.390, 3498.0, 59.1439
8.316561515, 96.390, 3554.0, 59.6154
8.369082645, 96.390, 3468.0, 58.8897
8.421603776, 96.390, 3577.0, 59.8080
8.474124907, 96.390, 3559.0, 59.6574
8.526646038, 96.390, 3574.0, 59.7829
8.579167168, 96.390, 3499.0, 59.1523
8.631688299, 96.390, 3643.0, 60.3573
8.684209430, 96.390, 3767.0, 61.3759
8.736730560, 96.390, 3632.0, 60.2661
8.789251691, 96.390, 3637.0, 60.3075
8.841772822, 96.390, 3441.0, 58.6600
8.894293952, 96.390, 3492.0, 59.0931
8.946815083, 96.390, 3485.0, 59.0339
8.999336214, 96.390, 3601.0, 60.0083
9.051857345, 96.390, 3500.0, 59.1608
9.104378475, 96.390, 3558.0, 59.6490
9.156899606, 96.390, 3503.0, 59.1861
9.209420737, 96.390, 3497.0, 59.1354
9.261941867, 96.390, 3531.0, 59.4222
9.314462998, 96.390, 3500.0, 59.1608
9.366984129, 96.390, 3514.0, 59.2790
9.419505260, 96.390, 3448.0, 58.7197
9.472026390, 96.390, 3442.0, 58.6686
9.524547521, 96.390, 3389.0, 58.2151
9.577068652, 96.390, 3532.0, 59.4306
9.629589782, 96.390, 3460.0, 58.8218
9.682110913, 96.390, 3523.0, 59.3549
9.734632044, 96.390, 3414.0, 58.4294
9.787153175, 96.390, 3472.0, 58.9237
9.839674305, 96.390, 3497.0, 59.1354
9.892195436, 96.390, 3581.0, 59.8415
9.944716567, 96.390, 3423.0, 58.5064
9.997237697, 96.390, 3483.0, 59.0169
10.049758828, 96.390, 3590.0, 59.9166
10.102279959, 96.390, 3590.0, 59.9166
10.154801090, 96.390, 3495.0, 59.1185
10.207322220, 96.390, 3317.0, 57.5934
10.259843351, 96.390, 3379.0, 58.1292
10.312364482, 96.390, 3518.0, 59.3127
10.364885612, 96.390, 4091.0, 63.9609
10.417406743, 96.390, 4255.0, 65.2304
10.469927874, 96.390, 3778.0, 61.4654
10.522449004, 96.390, 3511.0, 59.2537
10.574970135, 96.390, 3279.0, 57.2626
10.627491266, 96.390, 3389.0, 58.2151
10.680012397, 96.390, 3374.0, 58.0861
10.732533527, 96.390, 3340.0, 57.7927
10.785054658, 96.390, 3342.0, 57.8100
10.837575789, 96.390, 3333.0, 57.7321
10.890096919, 96.390, 3312.0, 57.5500
10.942618050, 96.390, 3569.0, 59.7411
10.995139181, 96.390, 4129.0, 64.2573
11.047660312, 96.390, 3557.0, 59.6406
11.100181442, 96.390, 3300.0, 57.4456
11.152702573, 96.390, 3188.0, 56.4624
11.205223704, 96.390, 3186.0, 56.4447
11.257744834, 96.390, 3146.0, 56.0892
11.310265965, 96.390, 3170.0, 56.3028
11.362787096, 96.390, 3229.0, 56.8243
11.415308227, 96.390, 3158.0, 56.1961
11.467829357, 96.390, 3169.0, 56.2939
11.520350488, 96.390, 3091.0, 55.5968
11.572871619, 96.390, 3006.0, 54.8270
11.625392749, 96.390, 3056.0, 55.2811
11.677913880, 96.390, 3074.0, 55.4437
11.730435011, 96.390, 3149.0, 56.1160
11.782956141, 96.390, 3112.0, 55.7853
11.835477272, 96.390, 3178.0, 56.3738
11.887998403, 96.390, 3059.0, 55.3082
11.940519534, 96.390, 2904.0, 53.8888
11.993040664, 96.390, 3028.0, 55.0273
12.045561795, 96.390, 3036.0, 55.0999
12.098082926, 96.390, 2883.0, 53.6936
12.150604056, 96.390, 2884.0, 53.7029
12.203125187, 96.390, 2868.0, 53.5537
12.255646318, 96.390, 2892.0, 53.7773
12.308167449, 96.390, 2885.0, 53.7122
12.360688579, 96.390, 2857.0, 53.4509
12.413209710, 96.390, 2895.0, 53.8052
12.465730841, 96.390, 2843.0, 53.3198
12.518251971, 96.390, 2810.0, 53.0094
12.570773102, 96.390, 2856.0, 53.4416
12.623294233, 96.390, 2815.0, 53.0566
12.675815364, 96.390, 2744.0, 52.3832
12.728336494, 96.390, 2670.0, 51.6720
12.780857625, 96.390, 2795.0, 52.8678
12.833378756, 96.390, 2738.0, 52.3259
12.885899886, 96.390, 2735.0, 52.2972
12.938421017, 96.390, 2747.0, 52.4118
12.990942148, 96.390, 2673.0, 51.7011
13.043463279, 96.390, 2673.0, 51.7011
13.095984409, 96.390, 2642.0, 51.4004
13.148505540, 96.390, 2703.0, 51.9904
13.201026671, 96.390, 2565.0, 50.6458
13.253547801, 96.390, 2543.0, 50.4282
13.306068932, 96.390, 2613.0, 51.1175
13.358590063, 96.390, 2633.0, 51.3128
13.411111193, 96.390, 2579.0, 50.7839
13.463632324, 96.390, 2570.0, 50.6952
13.516153455, 96.390, 2596.0, 50.9510
13.568674586, 96.390, 2684.0, 51.8073
13.621195716, 96.390, 2633.0, 51.3128
13.673716847, 96.390, 2742.0, 52.3641
13.726237978, 96.390, 3076.0, 55.4617
13.778759108, 96.390, 4085.0, 63.9140
13.831280239, 96.390, 3251.0, 57.0175
13.883801370, 96.390, 2497.0, 49.9700
13.936322501, 96.390, 2473.0, 49.7293
13.988843631, 96.390, 2518.0, 50.1797
14.041364762, 96.390, 2587.0, 50.8626
14.093885893, 96.390, 2577.0, 50.7642
14.146407023, 96.390, 2885.0, 53.7122
14.198928154, 96.390, 5462.0, 73.9053
14.251449285, 96.390, 8773.0, 93.6643
14.303970416, 96.390, 5340.0, 73.0753
14.356491546, 96.390, 2626.0, 51.2445
14.409012677, 96.390, 2624.0, 51.2250
14.461533808, 96.390, 2668.0, 51.6527
14.514054938, 96.390, 2852.0, 53.4041
14.566576069, 96.390, 2616.0, 51.1468
14.619097200, 96.390, 2269.0, 47.6340
14.671618331, 96.390, 2352.0, 48.4974
14.724139461, 96.390, 2315.0, 48.1144
14.776660592, 96.390, 2363.0, 48.6107
14.829181723, 96.390, 2390.0, 48.8876
14.881702853, 96.390, 2202.0, 46.9255
14.934223984, 96.390, 2353.0, 48.5077
14.986745115, 96.390, 2336.0, 48.3322
15.039266245, 96.390, 2338.0, 48.3529
15.091787376, 96.390, 2337.0, 48.3425
15.144308507, 96.390, 2486.0, 49.8598
15.196829638, 96.390, 2484.0, 49.8397
15.249350768, 96.390, 2497.0, 49.9700
15.301871899, 96.390, 2339.0, 48.3632
15.354393030, 96.390, 2241.0, 47.3392
15.406914160, 96.390, 2281.0, 47.7598
15.459435291, 96.390, 2274.0, 47.6865
15.511956422, 96.390, 2295.0, 47.9062
15.564477553, 96.390, 2320.0, 48.1664
15.616998683, 96.390, 2300.0, 47.9583
15.669519814, 96.390, 2272.0, 47.6655
15.722040945, 96.390, 2321.0, 48.1768
15.774562075, 96.390, 2308.0, 48.0416
15.827083206, 96.390, 2308.0, 48.0416
15.879604337, 96.390, 2238.0, 47.3075
15.932125468, 96.390, 2320.0, 48.1664
15.984646598, 96.390, 2221.0, 47.1275
16.037167729, 96.390, 2320.0, 48.1664
16.089688860, 96.390, 2170.0, 46.5833
16.142209990, 96.390, 2205.0, 46.9574
16.194731121, 96.390, 2356.0, 48.5386
16.247252252, 96.390, 2359.0, 48.5695
16.299773382, 96.390, 2535.0, 50.3488
16.352294513, 96.390, 2391.0, 48.8979
16.404815644, 96.390, 2195.0, 46.8508
16.457336775, 96.390, 2197.0, 46.8722
16.509857905, 96.390, 2113.0, 45.9674
16.562379036, 96.390, 2182.0, 46.7119
16.614900167, 96.390, 2163.0, 46.5081
16.667421297, 96.390, 2177.0, 46.6583
16.719942428, 96.390, 2225.0, 47.1699
16.772463559, 96.390, 2143.0, 46.2925
16.824984690, 96.390, 2197.0, 46.8722
16.877505820, 96.390, 2450.0, 49.4975
16.930026951, 96.390, 2550.0, 50.4975
16.982548082, 96.390, 2279.0, 47.7389
17.035069212, 96.390, 2136.0, 46.2169
17.087590343, 96.390, 2191.0, 46.8081
17.140111474, 96.390, 2159.0, 46.4650
17.192632605, 96.390, 2169.0, 46.5725
17.245153735, 96.390, 2148.0, 46.3465
17.297674866, 96.390, 2193.0, 46.8295
17.350195997, 96.390, 2460.0, 49.5984
17.402717127, 96.390, 2444.0, 49.4368
17.455238258, 96.390, 2219.0, 47.1063
17.507759389, 96.390, 2104.0, 45.8694
17.560280520, 96.390, 2240.0, 47.3286
17.612801650, 96.390, 2189.0, 46.7868
17.665322781, 96.390, 2184.0, 46.7333
17.717843912, 96.390, 2195.0, 46.8508
17.770365042, 96.390, 2123.0, 46.0760
17.822886173, 96.390, 2184.0, 46.7333
17.875407304, 96.390, 2115.0, 45.9891
17.927928434, 96.390, 2191.0, 46.8081
17.980449565, 96.390, 2128.0, 46.1303
18.032970696, 96.390, 2223.0, 47.1487
18.085491827, 96.390, 2422.0, 49.2138
18.138012957, 96.390, 2344.0, 48.4149
18.190534088, 96.390, 2599.0, 50.9804
18.243055219, 96.390, 2764.0, 52.5738
18.295576349, 96.390, 2952.0, 54.3323
18.348097480, 96.390, 2752.0, 52.4595
18.400618611, 96.390, 2937.0, 54.1941
18.453139742, 96.390, 2960.0, 54.4059
18.505660872, 96.390, 2331.0, 48.2804
18.558182003, 96.390, 2213.0, 47.0425
18.610703134, 96.390, 2179.0, 46.6798
18.663224264, 96.390, 2200.0, 46.9042
18.715745395, 96.390, 2269.0, 47.6340
18.768266526, 96.390, 2312.0, 48.0833
18.820787657, 96.390, 2492.0, 49.9199
18.873308787, 96.390, 2606.0, 51.0490
18.925829918, 96.390, 2842.0, 53.3104
18.978351049, 96.390, 2876.0, 53.6284
19.030872179, 96.390, 2612.0, 51.1077
19.083393310, 96.390, 2393.0, 48.9183
19.135914441, 96.390, 2310.0, 48.0625
19.188435572, 96.390, 2273.0, 47.6760
19.240956702, 96.390, 2284.0, 47.7912
19.293477833, 96.390, 2376.0, 48.7442
19.345998964, 96.390, 2341.0, 48.3839
19.398520094, 96.390, 2415.0, 49.1426
19.451041225, 96.390, 2743.0, 52.3737
19.503562356, 96.390, 2676.0, 51.7301
19.556083486, 96.390, 2389.0, 48.8774
19.608604617, 96.390, 2366.0, 48.6415
19.661125748, 96.390, 2528.0, 50.2792
19.713646879, 96.390, 2868.0, 53.5537
19.766168009, 96.390, 3359.0, 57.9569
19.818689140, 96.390, 2754.0, 52.4786
19.871210271, 96.390, 2420.0, 49.1935
19.923731401, 96.390, 2343.0, 48.4045
19.976252532, 96.390, 2310.0, 48.0625
20.028773663, 96.390, 2328.0, 48.2494
20.081294794, 96.390, 2392.0, 48.9081
20.133815924, 96.390, 2424.0, 49.2341
20.186337055, 96.390, 2505.0, 50.0500
20.238858186, 96.390, 2481.0, 49.8096
20.291379316, 96.390, 2552.0, 50.5173
20.343900447, 96.390, 2862.0, 53.4977
20.396421578, 96.390, 3584.0, 59.8665
20.448942709, 96.390, 3115.0, 55.8122
20.501463839, 96.390, 2794.0, 52.8583
20.553984970, 96.390, 3042.0, 55.1543
20.606506101, 96.390, 3359.0, 57.9569
20.659027231, 96.390, 2910.0, 53.9444
20.711548362, 96.390, 2574.0, 50.7346
20.764069493, 96.390, 2634.0, 51.3225
20.816590623, 96.390, 2470.0, 49.6991
20.869111754, 96.390, 2525.0, 50.2494
20.921632885, 96.390, 2632.0, 51.3030
20.974154016, 96.390, 2847.0, 53.3573
21.026675146, 96.390, 2608.0, 51.0686
21.079196277, 96.390, 2458.0, 49.5782
21.131717408, 96.390, 2507.0, 50.0700
21.184238538, 96.390, 2499.0, 49.9900
21.236759669, 96.390, 2534.0, 50.3389
21.289280800, 96.390, 2613.0, 51.1175
21.341801931, 96.390, 2480.0, 49.7996
21.394323061, 96.390, 2474.0, 49.7393
21.446844192, 96.390, 2419.0, 49.1833
21.499365323, 96.390, 2410.0, 49.0918
21.551886453, 96.390, 2549.0, 50.4876
21.604407584, 96.390, 2700.0, 51.9615
21.656928715, 96.390, 2849.0, 53.3760
21.709449846, 96.390, 3406.0, 58.3609
21.761970976, 96.390, 2927.0, 54.1018
21.814492107, 96.390, 2462.0, 49.6185
21.867013238, 96.390, 2427.0, 49.2646
21.919534368, 96.390, 2514.0, 50.1398
21.972055499, 96.390, 2461.0, 49.6085
22.024576630, 96.390, 2403.0, 49.0204
22.077097761, 96.390, 2478.0, 49.7795
22.129618891, 96.390, 2511.0, 50.1099
22.182140022, 96.390, 2512.0, 50.1199
22.234661153, 96.390, 2530.0, 50.2991
22.287182283, 96.390, 2504.0, 50.0400
22.339703414, 96.390, 2504.0, 50.0400
22.392224545, 96.390, 2587.0, 50.8626
22.444745675, 96.390, 2502.0, 50.0200
22.497266806, 96.390, 2537.0, 50.3686
22.549787937, 96.390, 2684.0, 51.8073
22.602309068, 96.390, 2655.0, 51.5267
22.654830198, 96.390, 2410.0, 49.0918
22.707351329, 96.390, 2560.0, 50.5964
22.759872460, 96.390, 2712.0, 52.0769
22.812393590, 96.390, 2781.0, 52.7352
22.864914721, 96.390, 2773.0, 52.6593
22.917435852, 96.390, 2621.0, 51.1957
22.969956983, 96.390, 2592.0, 50.9117
23.022478113, 96.390, 2718.0, 52.1344
23.074999244, 96.390, 2759.0, 52.5262
23.127520375, 96.390, 2996.0, 54.7357
23.180041505, 96.390, 2950.0, 54.3139
23.232562636, 96.390, 2841.0, 53.3010
23.285083767, 96.390, 2716.0, 52.1153
23.337604898, 96.390, 2696.0, 51.9230
23.390126028, 96.390, 2844.0, 53.3292
23.442647159, 96.390, 3028.0, 55.0273
23.495168290, 96.390, 3955.0, 62.8888
23.547689420, 96.390, 3557.0, 59.6406
23.600210551, 96.390, 2798.0, 52.8961
23.652731682, 96.390, 2491.0, 49.9099
23.705252813, 96.390, 2396.0, 48.9490
23.757773943, 96.390, 2427.0, 49.2646
23.810295074, 96.390, 2396.0, 48.9490
23.862816205, 96.390, 2417.0, 49.1630
23.915337335, 96.390, 2397.0, 48.9592
23.967858466, 96.390, 2391.0, 48.8979
24.020379597, 96.390, 2329.0, 48.2597
24.072900727, 96.390, 2624.0, 51.2250
24.125421858, 96.390, 2541.0, 50.4083
24.177942989, 96.390, 2885.0, 53.7122
24.230464120, 96.390, 3073.0, 55.4346
24.282985250, 96.390, 2809.0, 53.0000
24.335506381, 96.390, 2543.0, 50.4282
24.388027512, 96.390, 2399.0, 48.9796
24.440548642, 96.390, 2461.0, 49.6085
24.493069773, 96.390, 2713.0, 52.0865
24.545590904, 96.390, 3900.0, 62.4500
24.598112035, 96.390, 3233.0, 56.8595
24.650633165, 96.390, 2187.0, 46.7654
24.703154296, 96.390, 2125.0, 46.0977
24.755675427, 96.390, 2191.0, 46.8081
24.808196557, 96.390, 2183.0, 46.7226
24.860717688, 96.390, 2103.0, 45.8585
24.913238819, 96.390, 2185.0, 46.7440
24.965759950, 96.390, 2119.0, 46.0326
25.018281080, 96.390, 2170.0, 46.5833
25.070802211, 96.390, 2054.0, 45.3211
25.123323342, 96.390, 1988.0, 44.5870
25.175844472, 96.390, 2038.0, 45.1442
25.228365603, 96.390, 2012.0, 44.8553
25.280886734, 96.390, 2069.0, 45.4863
25.333407864, 96.390, 2332.0, 48.2908
25.385928995, 96.390, 2536.0, 50.3587
25.438450126, 96.390, 2267.0, 47.6130
25.490971257, 96.390, 2077.0, 45.5741
25.543492387, 96.390, 2030.0, 45.0555
25.596013518, 96.390, 1938.0, 44.0227
25.648534649, 96.390, 1988.0, 44.5870
25.701055779, 96.390, 2045.0, 45.2217
25.753576910, 96.390, 1995.0, 44.6654
25.806098041, 96.390, 2041.0, 45.1774
25.858619172, 96.390, 2107.0, 45.9021
25.911140302, 96.390, 2172.0, 46.6047
25.963661433, 96.390, 1896.0, 43.5431
26.016182564, 96.390, 1931.0, 43.9431
26.068703694, 96.390, 1844.0, 42.9418
26.121224825, 96.390, 1939.0, 44.0341
26.173745956, 96.390, 1866.0, 43.1972
26.226267087, 96.390, 1897.0, 43.5546
26.278788217, 96.390, 1944.0, 44.0908
26.331309348, 96.390, 1884.0, 43.4051
26.383830479, 96.390, 1774.0, 42.1189
26.436351609, 96.390, 1808.0, 42.5206
26.488872740, 96.390, 1751.0, 41.8450
26.541393871, 96.390, 1893.0, 43.5086
26.593915002, 96.390, 1922.0, 43.8406
26.646436132, 96.390, 2297.0, 47.9270
26.698957263, 96.390, 2165.0, 46.5296
26.751478394, 96.390, 2099.0, 45.8148
26.803999524, 96.390, 2089.0, 45.7056
26.856520655, 96.390, 1985.0, 44.5533
26.909041786, 96.390, 2331.0, 48.2804
26.961562916, 96.390, 2360.0, 48.5798
27.014084047, 96.390, 2387.0, 48.8569
27.066605178, 96.390, 2172.0, 46.6047
27.119126309, 96.390, 2237.0, 47.2969
27.171647439, 96.390, 2429.0, 49.2849
27.224168570, 96.390, 2225.0, 47.1699
27.276689701, 96.390, 2206.0, 46.9681
27.329210831, 96.390, 2085.0, 45.6618
27.381731962, 96.390, 1893.0, 43.5086
27.434253093, 96.390, 1850.0, 43.0116
27.486774224, 96.390, 1823.0, 42.6966
27.539295354, 96.390, 1842.0, 42.9185
27.591816485, 96.390, 1915.0, 43.7607
27.644337616, 96.390, 2089.0, 45.7056
27.696858746, 96.390, 2012.0, 44.8553
27.749379877, 96.390, 2040.0, 45.1664
27.801901008, 96.390, 1863.0, 43.1625
27.854422139, 96.390, 1785.0, 42.2493
27.906943269, 96.390, 1785.0, 42.2493
27.959464400, 96.390, 1706.0, 41.3038
28.011985531, 96.390, 1721.0, 41.4849
28.064506661, 96.390, 1779.0, 42.1782
28.117027792, 96.390, 1899.0, 43.5775
28.169548923, 96.390, 1987.0, 44.5758
28.222070054, 96.390, 2124.0, 46.0869
28.274591184, 96.390, 2072.0, 45.5192
28.327112315, 96.390, 2122.0, 46.0652
28.379633446, 96.390, 1847.0, 42.9767
28.432154576, 96.390, 1755.0, 41.8927
28.484675707, 96.390, 2114.0, 45.9783
28.537196838, 96.390, 1977.0, 44.4635
28.589717968, 96.390, 1905.0, 43.6463
28.642239099, 96.390, 1808.0, 42.5206
28.694760230, 96.390, 1739.0, 41.7013
28.747281361, 96.390, 1803.0, 42.4617
28.799802491, 96.390, 1810.0, 42.5441
28.852323622, 96.390, 1814.0, 42.5911
28.904844753, 96.390, 1966.0, 44.3396
28.957365883, 96.390, 1849.0, 43.0000
29.009887014, 96.390, 1899.0, 43.5775
29.062408145, 96.390, 1853.0, 43.0465
29.114929276, 96.390, 1934.0, 43.9773
29.167450406, 96.390, 1906.0, 43.6578
29.219971537, 96.390, 2089.0, 45.7056
29.272492668, 96.390, 2299.0, 47.9479
29.325013798, 96.390, 2101.0, 45.8367
29.377534929, 96.390, 2115.0, 45.9891
29.430056060, 96.390, 2145.0, 46.3141
29.482577191, 96.390, 2116.0, 46.0000
29.535098321, 96.390, 2053.0, 45.3100
29.587619452, 96.390, 2047.0, 45.2438
29.640140583, 96.390, 2024.0, 44.9889
29.692661713, 96.390, 1972.0, 44.4072
29.745182844, 96.390, 1856.0, 43.0813
29.797703975, 96.390, 1829.0, 42.7668
29.850225105, 96.390, 1813.0, 42.5793
29.902746236, 96.390, 1820.0, 42.6615
29.955267367, 96.390, 1722.0, 41.4970
30.007788498, 96.390, 1773.0, 42.1070
30.060309628, 96.390, 1829.0, 42.7668
30.112830759, 96.390, 1725.0, 41.5331
30.165351890, 96.390, 1727.0, 41.5572
30.217873020, 96.390, 1647.0, 40.5832
30.270394151, 96.390, 1714.0, 41.4005
30.322915282, 96.390, 1783.0, 42.2256
30.375436413, 96.390, 1768.0, 42.0476
30.427957543, 96.390, 1941.0, 44.0568
30.480478674, 96.390, 2143.0, 46.2925
30.532999805, 96.390, 2151.0, 46.3789
30.585520935, 96.390, 2281.0, 47.7598
30.638042066, 96.390, 2888.0, 53.7401
30.690563197, 96.390, 4605.0, 67.8602
30.743084328, 96.390, 3131.0, 55.9553
30.795605458, 96.390, 3064.0, 55.3534
30.848126589, 96.390, 2120.0, 46.0435
30.900647720, 96.390, 2069.0, 45.4863
30.953168850, 96.390, 1902.0, 43.6119
31.005689981, 96.390, 1932.0, 43.9545
31.058211112, 96.390, 1969.0, 44.3734
31.110732243, 96.390, 1861.0, 43.1393
31.163253373, 96.390, 1970.0, 44.3847
31.215774504, 96.390, 2001.0, 44.7325
31.268295635, 96.390, 2158.0, 46.4543
31.320816765, 96.390, 2225.0, 47.1699
31.373337896, 96.390, 2239.0, 47.3181
31.425859027, 96.390, 2171.0, 46.5940
31.478380157, 96.390, 2007.0, 44.7996
31.530901288, 96.390, 1955.0, 44.2154
31.583422419, 96.390, 2464.0, 49.6387
31.635943550, 96.390, 3322.0, 57.6368
31.688464680, 96.390, 4012.0, 63.3404
31.740985811, 96.390, 3738.0, 61.1392
31.793506942, 96.390, 3757.0, 61.2944
31.846028072, 96.390, 2148.0, 46.3465
31.898549203, 96.390, 2438.0, 49.3761
31.951070334, 96.390, 2204.0, 46.9468
32.003591465, 96.390, 2253.0, 47.4658
32.056112595, 96.390, 2000.0, 44.7214
32.108633726, 96.390, 1812.0, 42.5676
32.161154857, 96.390, 1946.0, 44.1135
32.213675987, 96.390, 1990.0, 44.6094
32.266197118, 96.390, 2010.0, 44.8330
32.318718249, 96.390, 1895.0, 43.5316
32.371239380, 96.390, 1886.0, 43.4281
32.423760510, 96.390, 1877.0, 43.3244
32.476281641, 96.390, 1725.0, 41.5331
32.528802772, 96.390, 1765.0, 42.0119
32.581323902, 96.390, 1752.0, 41.8569
32.633845033, 96.390, 2192.0, 46.8188
32.686366164, 96.390, 2370.0, 48.6826
32.738887295, 96.390, 2245.0, 47.3814
32.791408425, 96.390, 1934.0, 43.9773
32.843929556, 96.390, 1927.0, 43.8976
32.896450687, 96.390, 2177.0, 46.6583
32.948971817, 96.390, 2203.0, 46.9361
33.001492948, 96.390, 2302.0, 47.9792
33.054014079, 96.390, 2202.0, 46.9255
33.106535209, 96.390, 2186.0, 46.7547
33.159056340, 96.390, 2070.0, 45.4973
33.211577471, 96.390, 2068.0, 45.4753
33.264098602, 96.390, 1994.0, 44.6542
33.316619732, 96.390, 2117.0, 46.0109
33.369140863, 96.390, 2759.0, 52.5262
33.421661994, 96.390, 4640.0, 68.1175
33.474183124, 96.390, 6279.0, 79.2401
33.526704255, 96.390, 4466.0, 66.8281
33.579225386, 96.390, 2620.0, 51.1859
33.631746517, 96.390, 1937.0, 44.0114
33.684267647, 96.390, 1834.0, 42.8252
33.736788778, 96.390, 1848.0, 42.9884
33.789309909, 96.390, 1957.0, 44.2380
33.841831039, 96.390, 2014.0, 44.8776
33.894352170, 96.390, 2201.0, 46.9148
33.946873301, 96.390, 2133.0, 46.1844
33.999394432, 96.390, 2114.0, 45.9783
34.051915562, 96.390, 2163.0, 46.5081
34.104436693, 96.390, 2033.0, 45.0888
34.156957824, 96.390, 2077.0, 45.5741
34.209478954, 96.390, 2346.0, 48.4355
34.262000085, 96.390, 2396.0, 48.9490
34.314521216, 96.390, 2847.0, 53.3573
34.367042346, 96.390, 2495.0, 49.9500
34.419563477, 96.390, 2527.0, 50.2693
34.472084608, 96.390, 2411.0, 49.1019
34.524605739, 96.390, 2592.0, 50.9117
34.577126869, 96.390, 2670.0, 51.6720
34.629648000, 96.390, 2636.0, 51.3420
34.682169131, 96.390, 2644.0, 51.4198
34.734690261, 96.390, 2644.0, 51.4198
34.787211392, 96.390, 2314.0, 48.1041
34.839732523, 96.390, 2406.0, 49.0510
34.892253654, 96.390, 2341.0, 48.3839
34.944774784, 96.390, 2732.0, 52.2685
34.997295915, 96.390, 2977.0, 54.5619
35.049817046, 96.390, 2688.0, 51.8459
35.102338176, 96.390, 2583.0, 50.8232
35.154859307, 96.390, 2641.0, 51.3907
35.207380438, 96.390, 3001.0, 54.7814
35.259901569, 96.390, 2516.0, 50.1597
35.312422699, 96.390, 2372.0, 48.7032
35.364943830, 96.390, 2084.0, 45.6508
35.417464961, 96.390, 2024.0, 44.9889
35.469986091, 96.390, 1991.0, 44.6206
35.522507222, 96.390, 2038.0, 45.1442
35.575028353, 96.390, 2080.0, 45.6070
35.627549484, 96.390, 2090.0, 45.7165
35.680070614, 96.390, 2041.0, 45.1774
35.732591745, 96.390, 2048.0, 45.2548
35.785112876, 96.390, 1977.0, 44.4635
35.837634006, 96.390, 2130.0, 46.1519
35.890155137, 96.390, 2201.0, 46.9148
35.942676268, 96.390, 2283.0, 47.7807
35.995197398, 96.390, 2205.0, 46.9574
36.047718529, 96.390, 2134.0, 46.1952
36.100239660, 96.390, 2013.0, 44.8665
36.152760791, 96.390, 2035.0, 45.1110
36.205281921, 96.390, 2066.0, 45.4533
36.257803052, 96.390, 2040.0, 45.1664
36.310324183, 96.390, 2018.0, 44.9222
36.362845313, 96.390, 1942.0, 44.0681
36.415366444, 96.390, 1851.0, 43.0232
36.467887575, 96.390, 1846.0, 42.9651
36.520408706, 96.390, 1580.0, 39.7492
36.572929836, 96.390, 1663.0, 40.7799
36.625450967, 96.390, 1744.0, 41.7612
36.677972098, 96.390, 1893.0, 43.5086
36.730493228, 96.390, 1708.0, 41.3280
36.783014359, 96.390, 1636.0, 40.4475
36.835535490, 96.390, 1573.0, 39.6611
36.888056621, 96.390, 1568.0, 39.5980
36.940577751, 96.390, 1509.0, 38.8458
36.993098882, 96.390, 1589.0, 39.8623
37.045620013, 96.390, 1540.0, 39.2428
37.098141143, 96.390, 1600.0, 40.0000
37.150662274, 96.390, 1590.0, 39.8748
37.203183405, 96.390, 1622.0, 40.2741
37.255704535, 96.390, 1489.0, 38.5876
37.308225666, 96.390, 1556.0, 39.4462
37.360746797, 96.390, 1609.0, 40.1123
37.413267928, 96.390, 1655.0, 40.6817
37.465789058, 96.390, 1691.0, 41.1218
37.518310189, 96.390, 1598.0, 39.9750
37.570831320, 96.390, 1655.0, 40.6817
37.623352450, 96.390, 1572.0, 39.6485
37.675873581, 96.390, 1566.0, 39.5727
37.728394712, 96.390, 1693.0, 41.1461
37.780915843, 96.390, 1825.0, 42.7200
37.833436973, 96.390, 2148.0, 46.3465
37.885958104, 96.390, 2086.0, 45.6727
37.938479235, 96.390, 1817.0, 42.6263
37.991000365, 96.390, 1790.0, 42.3084
38.043521496, 96.390, 1549.0, 39.3573
38.096042627, 96.390, 1638.0, 40.4722
38.148563758, 96.390, 2288.0, 47.8330
38.201084888, 96.390, 1825.0, 42.7200
38.253606019, 96.390, 2104.0, 45.8694
38.306127150, 96.390, 1880.0, 43.3590
38.358648280, 96.390, 1577.0, 39.7115
38.411169411, 96.390, 1670.0, 40.8656
38.463690542, 96.390, 1518.0, 38.9615
38.516211673, 96.390, 1554.0, 39.4208
38.568732803, 96.390, 1503.0, 38.7685
38.621253934, 96.390, 1530.0, 39.1152
38.673775065, 96.390, 1549.0, 39.3573
38.726296195, 96.390, 1498.0, 38.7040
38.778817326, 96.390, 1466.0, 38.2884
38.831338457, 96.390, 1424.0, 37.7359
38.883859587, 96.390, 1452.0, 38.1051
38.936380718, 96.390, 1514.0, 38.9102
38.988901849, 96.390, 1481.0, 38.4838
39.041422980, 96.390, 1487.0, 38.5616
39.093944110, 96.390, 1444.0, 38.0000
39.146465241, 96.390, 1544.0, 39.2938
39.198986372, 96.390, 1751.0, 41.8450
39.251507502, 96.390, 1834.0, 42.8252
39.304028633, 96.390, 1567.0, 39.5854
39.356549764, 96.390, 1533.0, 39.1535
39.409070895, 96.390, 1390.0, 37.2827
39.461592025, 96.390, 1338.0, 36.5787
39.514113156, 96.390, 1457.0, 38.1707
39.566634287, 96.390, 1486.0, 38.5487
39.619155417, 96.390, 1531.0, 39.1280
39.671676548, 96.390, 1693.0, 41.1461
39.724197679, 96.390, 1786.0, 42.2611
39.776718810, 96.390, 2823.0, 53.1319
39.829239940, 96.390, 1742.0, 41.7373
39.881761071, 96.390, 2032.0, 45.0777
39.934282202, 96.390, 1540.0, 39.2428
39.986803332, 96.390, 1446.0, 38.0263
40.039324463, 96.390, 1493.0, 38.6394
40.091845594, 96.390, 1606.0, 40.0749
40.144366725, 96.390, 1573.0, 39.6611
40.196887855, 96.390, 1529.0, 39.1024
40.249408986, 96.390, 1468.0, 38.3145
40.301930117, 96.390, 1450.0, 38.0789
40.354451247, 96.390, 1423.0, 37.7227
40.406972378, 96.390, 1330.0, 36.4692
40.459493509, 96.390, 1324.0, 36.3868
40.512014639, 96.390, 1282.0, 35.8050
40.564535770, 96.390, 1387.0, 37.2424
40.617056901, 96.390, 1309.0, 36.1801
40.669578032, 96.390, 1351.0, 36.7560
40.722099162, 96.390, 1308.0, 36.1663
40.774620293, 96.390, 1201.0, 34.6554
40.827141424, 96.390, 1278.0, 35.7491
40.879662554, 96.390, 1228.0, 35.0428
40.932183685, 96.390, 1315.0, 36.2629
40.984704816, 96.390, 1275.0, 35.7071
41.037225947, 96.390, 1238.0, 35.1852
41.089747077, 96.390, 1290.0, 35.9166
41.142268208, 96.390, 1227.0, 35.0286
41.194789339, 96.390, 1320.0, 36.3318
41.247310469, 96.390, 1248.0, 35.3270
41.299831600, 96.390, 1386.0, 37.2290
41.352352731, 96.390, 1316.0, 36.2767
41.404873862, 96.390, 1359.0, 36.8646
41.457394992, 96.390, 1294.0, 35.9722
41.509916123, 96.390, 1312.0, 36.2215
41.562437254, 96.390, 1229.0, 35.0571
41.614958384, 96.390, 1286.0, 35.8608
41.667479515, 96.390, 1269.0, 35.6230
41.720000646, 96.390, 1214.0, 34.8425
41.772521776, 96.390, 1162.0, 34.0881
41.825042907, 96.390, 1202.0, 34.6699
41.877564038, 96.390, 1103.0, 33.2114
41.930085169, 96.390, 1236.0, 35.1568
41.982606299, 96.390, 1205.0, 34.7131
42.035127430, 96.390, 1278.0, 35.7491
42.087648561, 96.390, 1432.0, 37.8418
42.140169691, 96.390, 1601.0, 40.0125
42.192690822, 96.390, 1425.0, 37.7492
42.245211953, 96.390, 1486.0, 38.5487
42.297733084, 96.390, 1428.0, 37.7889
42.350254214, 96.390, 1252.0, 35.3836
42.402775345, 96.390, 1281.0, 35.7911
42.455296476, 96.390, 1175.0, 34.2783
42.507817606, 96.390, 1119.0, 33.4515
42.560338737, 96.390, 1228.0, 35.0428
42.612859868, 96.390, 1223.0, 34.9714
42.665380999, 96.390, 1308.0, 36.1663
42.717902129, 96.390, 1312.0, 36.2215
42.770423260, 96.390, 1228.0, 35.0428
42.822944391, 96.390, 1161.0, 34.0735
42.875465521, 96.390, 1080.0, 32.8634
42.927986652, 96.390, 1101.0, 33.1813
42.980507783, 96.390, 1086.0, 32.9545
43.033028914, 96.390, 1109.0, 33.3017
43.085550044, 96.390, 1128.0, 33.5857
43.138071175, 96.390, 1149.0, 33.8969
43.190592306, 96.390, 1131.0, 33.6303
43.243113436, 96.390, 1160.0, 34.0588
43.295634567, 96.390, 1124.0, 33.5261
43.348155698, 96.390, 1123.0, 33.5112
43.400676828, 96.390, 1105.0, 33.2415
43.453197959, 96.390, 1053.0, 32.4500
43.505719090, 96.390, 1124.0, 33.5261
43.558240221, 96.390, 1075.0, 32.7872
43.610761351, 96.390, 1181.0, 34.3657
43.663282482, 96.390, 1060.0, 32.5576
43.715803613, 96.390, 1117.0, 33.4215
43.768324743, 96.390, 1190.0, 34.4964
43.820845874, 96.390, 1186.0, 34.4384
43.873367005, 96.390, 1129.0, 33.6006
43.925888136, 96.390, 1185.0, 34.4238
43.978409266, 96.390, 1113.0, 33.3617
44.030930397, 96.390, 1143.0, 33.8083
44.083451528, 96.390, 1200.0, 34.6410
44.135972658, 96.390, 1161.0, 34.0735
44.188493789, 96.390, 1539.0, 39.2301
44.241014920, 96.390, 3621.0, 60.1747
44.293536051, 96.390, 1653.0, 40.6571
44.346057181, 96.390, 2314.0, 48.1041
44.398578312, 96.390, 1550.0, 39.3700
44.451099443, 96.390, 1165.0, 34.1321
44.503620573, 96.390, 1189.0, 34.4819
44.556141704, 96.390, 1250.0, 35.3553
44.608662835, 96.390, 1163.0, 34.1028
44.661183966, 96.390, 1251.0, 35.3695
44.713705096, 96.390, 1312.0, 36.2215
44.766226227, 96.390, 1253.0, 35.3977
44.818747358, 96.390, 1290.0, 35.9166
44.871268488, 96.390, 1245.0, 35.2846
44.923789619, 96.390, 1256.0, 35.4401
44.976310750, 96.390, 1275.0, 35.7071
45.028831880, 96.390, 1207.0, 34.7419
45.081353011, 96.390, 1399.0, 37.4032
45.133874142, 96.390, 1841.0, 42.9069
45.186395273, 96.390, 1389.0, 37.2693
45.238916403, 96.390, 1458.0, 38.1838
45.291437534, 96.390, 1277.0, 35.7351
45.343958665, 96.390, 1189.0, 34.4819
45.396479795, 96.390, 1209.0, 34.7707
45.449000926, 96.390, 1190.0, 34.4964
45.501522057, 96.390, 1238.0, 35.1852
45.554043188, 96.390, 1238.0, 35.1852
45.606564318, 96.390, 1362.0, 36.9053
45.659085449, 96.390, 1324.0, 36.3868
45.711606580, 96.390, 1460.0, 38.2099
45.764127710, 96.390, 1256.0, 35.4401
45.816648841, 96.390, 1272.0, 35.6651
45.869169972, 96.390, 1261.0, 35.5106
45.921691103, 96.390, 1180.0, 34.3511
45.974212233, 96.390, 1208.0, 34.7563
46.026733364, 96.390, 1219.0, 34.9142
46.079254495, 96.390, 1385.0, 37.2156
46.131775625, 96.390, 1430.0, 37.8153
46.184296756, 96.390, 1532.0, 39.1408
46.236817887, 96.390, 1694.0, 41.1582
46.289339017, 96.390, 2091.0, 45.7275
46.341860148, 96.390, 1604.0, 40.0500
46.394381279, 96.390, 1958.0, 44.2493
46.446902410, 96.390, 1809.0, 42.5323
46.499423540, 96.390, 1522.0, 39.0128
46.551944671, 96.390, 1542.0, 39.2683
46.604465802, 96.390, 1475.0, 38.4057
46.656986932, 96.390, 1469.0, 38.3275
46.709508063, 96.390, 1503.0, 38.7685
46.762029194, 96.390, 1319.0, 36.3180
46.814550325, 96.390, 1271.0, 35.6511
46.867071455, 96.390, 1187.0, 34.4529
46.919592586, 96.390, 1200.0, 34.6410
46.972113717, 96.390, 1207.0, 34.7419
47.024634847, 96.390, 1140.0, 33.7639
47.077155978, 96.390, 1185.0, 34.4238
47.129677109, 96.390, 1190.0, 34.4964
47.182198240, 96.390, 1332.0, 36.4966
47.234719370, 96.390, 1212.0, 34.8138
47.287240501, 96.390, 1237.0, 35.1710
47.339761632, 96.390, 1277.0, 35.7351
47.392282762, 96.390, 1144.0, 33.8231
47.444803893, 96.390, 1169.0, 34.1906
47.497325024, 96.390, 1171.0, 34.2199
47.549846155, 96.390, 1169.0, 34.1906
47.602367285, 96.390, 1163.0, 34.1028
47.654888416, 96.390, 1151.0, 33.9264
47.707409547, 96.390, 1155.0, 33.9853
47.759930677, 96.390, 1143.0, 33.8083
47.812451808, 96.390, 1171.0, 34.2199
47.864972939, 96.390, 1174.0, 34.2637
47.917494069, 96.390, 1159.0, 34.0441
47.970015200, 96.390, 1182.0, 34.3802
48.022536331, 96.390, 1115.0, 33.3916
48.075057462, 96.390, 1225.0, 35.0000
48.127578592, 96.390, 1168.0, 34.1760
48.180099723, 96.390, 1150.0, 33.9116
48.232620854, 96.390, 1134.0, 33.6749
48.285141984, 96.390, 1039.0, 32.2335
48.337663115, 96.390, 1182.0, 34.3802
48.390184246, 96.390, 1203.0, 34.6843
48.442705377, 96.390, 1226.0, 35.0143
48.495226507, 96.390, 1216.0, 34.8712
48.547747638, 96.390, 1255.0, 35.4260
48.600268769, 96.390, 1204.0, 34.6987
48.652789899, 96.390, 1159.0, 34.0441
48.705311030, 96.390, 1134.0, 33.6749
48.757832161, 96.390, 1048.0, 32.3728
48.810353292, 96.390, 1083.0, 32.9090
48.862874422, 96.390, 1095.0, 33.0908
48.915395553, 96.390, 1060.0, 32.5576
48.967916684, 96.390, 1109.0, 33.3017
49.020437814, 96.390, 1103.0, 33.2114
49.072958945, 96.390, 1118.0, 33.4365
49.125480076, 96.390, 1201.0, 34.6554
49.178001207, 96.390, 1087.0, 32.9697
49.230522337, 96.390, 1163.0, 34.1028
49.283043468, 96.390, 1036.0, 32.1870
49.335564599, 96.390, 1121.0, 33.4813
49.388085729, 96.390, 1139.0, 33.7491
49.440606860, 96.390, 1087.0, 32.9697
49.493127991, 96.390, 1059.0, 32.5423
49.545649121, 96.390, 1114.0, 33.3766
49.598170252, 96.390, 1115.0, 33.3916
49.650691383, 96.390, 1601.0, 40.0125
49.703212514, 96.390, 1605.0, 40.0625
49.755733644, 96.390, 1303.0, 36.0971
49.808254775, 96.390, 1481.0, 38.4838
49.860775906, 96.390, 1039.0, 32.2335
49.913297036, 96.390, 1057.0, 32.5115
49.965818167, 96.390, 1001.0, 31.6386
50.018339298, 96.390, 942.0, 30.6920
50.070860429, 96.390, 940.0, 30.6594
50.123381559, 96.390, 969.0, 31.1288
50.175902690, 96.390, 998.0, 31.5911
50.228423821, 96.390, 962.0, 31.0161
50.280944951, 96.390, 1005.0, 31.7017
50.333466082, 96.390, 928.0, 30.4631
50.385987213, 96.390, 1045.0, 32.3265
50.438508344, 96.390, 978.0, 31.2730
50.491029474, 96.390, 982.0, 31.3369
50.543550605, 96.390, 1002.0, 31.6544
50.596071736, 96.390, 1025.0, 32.0156
50.648592866, 96.390, 975.0, 31.2250
50.701113997, 96.390, 1038.0, 32.2180
50.753635128, 96.390, 963.0, 31.0322
50.806156258, 96.390, 1010.0, 31.7805
50.858677389, 96.390, 990.0, 31.4643
50.911198520, 96.390, 949.0, 30.8058
50.963719651, 96.390, 1153.0, 33.9559
51.016240781, 96.390, 1795.0, 42.3674
51.068761912, 96.390, 1273.0, 35.6791
51.121283043, 96.390, 1095.0, 33.0908
51.173804173, 96.390, 1442.0, 37.9737
51.226325304, 96.390, 1027.0, 32.0468
51.278846435, 96.390, 969.0, 31.1288
51.331367566, 96.390, 995.0, 31.5436
51.383888696, 96.390, 1152.0, 33.9411
51.436409827, 96.390, 1051.0, 32.4191
51.488930958, 96.390, 979.0, 31.2890
51.541452088, 96.390, 1062.0, 32.5883
51.593973219, 96.390, 879.0, 29.6479
51.646494350, 96.390, 877.0, 29.6142
51.699015481, 96.390, 911.0, 30.1828
51.751536611, 96.390, 893.0, 29.8831
51.804057742, 96.390, 925.0, 30.4138
51.856578873, 96.390, 861.0, 29.3428
51.909100003, 96.390, 1006.0, 31.7175
51.961621134, 96.390, 970.0, 31.1448
52.014142265, 96.390, 930.0, 30.4959
52.066663396, 96.390, 911.0, 30.1828
52.119184526, 96.390, 932.0, 30.5287
52.171705657, 96.390, 967.0, 31.0966
52.224226788, 96.390, 891.0, 29.8496
52.276747918, 96.390, 994.0, 31.5278
52.329269049, 96.390, 1009.0, 31.7648
52.381790180, 96.390, 1216.0, 34.8712
52.434311310, 96.390, 982.0, 31.3369
52.486832441, 96.390, 1012.0, 31.8119
52.539353572, 96.390, 1080.0, 32.8634
52.591874703, 96.390, 958.0, 30.9516
52.644395833, 96.390, 992.0, 31.4960
52.696916964, 96.390, 1048.0, 32.3728
52.749438095, 96.390, 978.0, 31.2730
52.801959225, 96.390, 884.0, 29.7321
52.854480356, 96.390, 1076.0, 32.8024
52.907001487, 96.390, 1087.0, 32.9697
52.959522618, 96.390, 956.0, 30.9192
53.012043748, 96.390, 980.0, 31.3050
53.064564879, 96.390, 982.0, 31.3369
53.117086010, 96.390, 1114.0, 33.3766
53.169607140, 96.390, 967.0, 31.0966
53.222128271, 96.390, 913.0, 30.2159
53.274649402, 96.390, 938.0, 30.6268
53.327170533, 96.390, 949.0, 30.8058
53.379691663, 96.390, 885.0, 29.7489
53.432212794, 96.390, 823.0, 28.6880
53.484733925, 96.390, 909.0, 30.1496
53.537255055, 96.390, 878.0, 29.6311
53.589776186, 96.390, 836.0, 28.9137
53.642297317, 96.390, 888.0, 29.7993
53.694818448, 96.390, 848.0, 29.1204
53.747339578, 96.390, 870.0, 29.4958
53.799860709, 96.390, 943.0, 30.7083
53.852381840, 96.390, 988.0, 31.4325
53.904902970, 96.390, 989.0, 31.4484
53.957424101, 96.390, 981.0, 31.3209
54.009945232, 96.390, 927.0, 30.4467
54.062466362, 96.390, 986.0, 31.4006
54.114987493, 96.390, 976.0, 31.2410
54.167508624, 96.390, 858.0, 29.2916
54.220029755, 96.390, 916.0, 30.2655
54.272550885, 96.390, 877.0, 29.6142
54.325072016, 96.390, 921.0, 30.3480
54.377593147, 96.390, 904.0, 30.0666
54.430114277, 96.390, 909.0, 30.1496
54.482635408, 96.390, 812.0, 28.4956
54.535156539, 96.390, 928.0, 30.4631
54.587677670, 96.390, 881.0, 29.6816
54.640198800, 96.390, 879.0, 29.6479
54.692719931, 96.390, 855.0, 29.2404
54.745241062, 96.390, 862.0, 29.3598
54.797762192, 96.390, 849.0, 29.1376
54.850283323, 96.390, 878.0, 29.6311
54.902804454, 96.390, 997.0, 31.5753
54.955325585, 96.390, 920.0, 30.3315
55.007846715, 96.390, 873.0, 29.5466
55.060367846, 96.390, 1053.0, 32.4500
55.112888977, 96.390, 952.0, 30.8545
55.165410107, 96.390, 889.0, 29.8161
55.217931238, 96.390, 914.0, 30.2324
55.270452369, 96.390, 870.0, 29.4958
55.322973499, 96.390, 758.0, 27.5318
55.375494630, 96.390, 860.0, 29.3258
55.428015761, 96.390, 801.0, 28.3019
55.480536892, 96.390, 844.0, 29.0517
55.533058022, 96.390, 788.0, 28.0713
55.585579153, 96.390, 805.0, 28.3725
55.638100284, 96.390, 824.0, 28.7054
55.690621414, 96.390, 742.0, 27.2397
55.743142545, 96.390, 845.0, 29.0689
55.795663676, 96.390, 850.0, 29.1548
55.848184807, 96.390, 808.0, 28.4253
55.900705937, 96.390, 825.0, 28.7228
55.953227068, 96.390, 824.0, 28.7054
56.005748199, 96.390, 796.0, 28.2135
56.058269329, 96.390, 814.0, 28.5307
56.110790460, 96.390, 851.0, 29.1719
56.163311591, 96.390, 829.0, 28.7924
56.215832722, 96.390, 855.0, 29.2404
56.268353852, 96.390, 816.0, 28.5657
56.320874983, 96.390, 861.0, 29.3428
56.373396114, 96.390, 825.0, 28.7228
56.425917244, 96.390, 827.0, 28.7576
56.478438375, 96.390, 827.0, 28.7576
56.530959506, 96.390, 888.0, 29.7993
56.583480637, 96.390, 779.0, 27.9106
56.636001767, 96.390, 813.0, 28.5132
56.688522898, 96.390, 790.0, 28.1069
56.741044029, 96.390, 728.0, 26.9815
56.793565159, 96.390, 733.0, 27.0740
56.846086290, 96.390, 801.0, 28.3019
56.898607421, 96.390, 767.0, 27.6948
56.951128551, 96.390, 804.0, 28.3549
57.003649682, 96.390, 765.0, 27.6586
57.056170813, 96.390, 760.0, 27.5681
57.108691944, 96.390, 736.0, 27.1293
57.161213074, 96.390, 829.0, 28.7924
57.213734205, 96.390, 798.0, 28.2489
57.266255336, 96.390, 829.0, 28.7924
57.318776466, 96.390, 891.0, 29.8496
57.371297597, 96.390, 916.0, 30.2655
57.423818728, 96.390, 874.0, 29.5635
57.476339859, 96.390, 1044.0, 32.3110
57.528860989, 96.390, 893.0, 29.8831
57.581382120, 96.390, 908.0, 30.1330
57.633903251, 96.390, 1084.0, 32.9242
57.686424381, 96.390, 1027.0, 32.0468
57.738945512, 96.390, 951.0, 30.8383
57.791466643, 96.390, 855.0, 29.2404
57.843987774, 96.390, 1019.0, 31.9218
57.896508904, 96.390, 920.0, 30.3315
57.949030035, 96.390, 836.0, 28.9137
58.001551166, 96.390, 894.0, 29.8998
58.054072296, 96.390, 792.0, 28.1425
58.106593427, 96.390, 777.0, 27.8747
58.159114558, 96.390, 883.0, 29.7153
58.211635689, 96.390, 736.0, 27.1293
58.264156819, 96.390, 819.0, 28.6182
58.316677950, 96.390, 859.0, 29.3087
58.369199081, 96.390, 750.0, 27.3861
58.421720211, 96.390, 787.0, 28.0535
58.474241342, 96.390, 771.0, 27.7669
58.526762473, 96.390, 743.0, 27.2580
58.579283603, 96.390, 792.0, 28.1425
58.631804734, 96.390, 725.0, 26.9258
58.684325865, 96.390, 735.0, 27.1109
58.736846996, 96.390, 734.0, 27.0924
58.789368126, 96.390, 727.0, 26.9629
58.841889257, 96.390, 746.0, 27.3130
58.894410388, 96.390, 700.0, 26.4575
58.946931518, 96.390, 765.0, 27.6586
58.999452649, 96.390, 708.0, 26.6083
59.051973780, 96.390, 720.0, 26.8328
59.104494911, 96.390, 784.0, 28.0000
59.157016041, 96.390, 721.0, 26.8514
59.209537172, 96.390, 836.0, 28.9137
59.262058303, 96.390, 832.0, 28.8444
59.314579433, 96.390, 865.0, 29.4109
59.367100564, 96.390, 847.0, 29.1033
59.419621695, 96.390, 802.0, 28.3196
59.472142826, 96.390, 851.0, 29.1719
59.524663956, 96.390, 758.0, 27.5318
59.577185087, 96.390, 776.0, 27.8568
59.629706218, 96.390, 750.0, 27.3861
59.682227348, 96.390, 810.0, 28.4605
59.734748479, 96.390, 776.0, 27.8568
59.787269610, 96.390, 861.0, 29.3428
59.839790740, 96.390, 775.0, 27.8388
59.892311871, 96.390, 818.0, 28.6007
59.944833002, 96.390, 792.0, 28.1425
59.997354133, 96.390, 779.0, 27.9106
60.049875263, 96.390, 780.0, 27.9285
60.102396394, 96.390, 859.0, 29.3087
60.154917525, 96.390, 861.0, 29.3428
60.207438655, 96.390, 819.0, 28.6182
60.259959786, 96.390, 880.0, 29.6648
60.312480917, 96.390, 911.0, 30.1828
60.365002048, 96.390, 894.0, 29.8998
60.417523178, 96.390, 950.0, 30.8221
60.470044309, 96.390, 964.0, 31.0483
60.522565440, 96.390, 994.0, 31.5278
60.575086570, 96.390, 976.0, 31.2410
60.627607701, 96.390, 1022.0, 31.9687
60.680128832, 96.390, 1036.0, 32.1870
60.732649963, 96.390, 1072.0, 32.7414
60.785171093, 96.390, 1064.0, 32.6190
60.837692224, 96.390, 1098.0, 33.1361
60.890213355, 96.390, 1093.0, 33.0606
60.942734485, 96.390, 1118.0, 33.4365
60.995255616, 96.390, 1177.0, 34.3074
61.047776747, 96.390, 1239.0, 35.1994
61.100297878, 96.390, 1244.0, 35.2704
61.152819008, 96.390, 1299.0, 36.0416
61.205340139, 96.390, 1265.0, 35.5668
61.257861270, 96.390, 1193.0, 34.5398
61.310382400, 96.390, 1207.0, 34.7419
61.362903531, 96.390, 1174.0, 34.2637
61.415424662, 96.390, 1184.0, 34.4093
61.467945792, 96.390, 1103.0, 33.2114
61.520466923, 96.390, 1161.0, 34.0735
61.572988054, 96.390, 1102.0, 33.1964
61.625509185, 96.390, 1048.0, 32.3728
61.678030315, 96.390, 1032.0, 32.1248
61.730551446, 96.390, 1053.0, 32.4500
61.783072577, 96.390, 1067.0, 32.6650
61.835593707, 96.390, 1017.0, 31.8904
61.888114838, 96.390, 1105.0, 33.2415
61.940635969, 96.390, 1050.0, 32.4037
61.993157100, 96.390, 1057.0, 32.5115
62.045678230, 96.390, 1031.0, 32.1092
62.098199361, 96.390, 1044.0, 32.3110
62.150720492, 96.390, 1023.0, 31.9844
62.203241622, 96.390, 948.0, 30.7896
62.255762753, 96.390, 965.0, 31.0644
62.308283884, 96.390, 966.0, 31.0805
62.360805015, 96.390, 988.0, 31.4325
62.413326145, 96.390, 988.0, 31.4325
62.465847276, 96.390, 985.0, 31.3847
62.518368407, 96.390, 934.0, 30.5614
62.570889537, 96.390, 930.0, 30.4959
62.623410668, 96.390, 972.0, 31.1769
62.675931799, 96.390, 900.0, 30.0000
62.728452930, 96.390, 915.0, 30.2490
62.780974060, 96.390, 881.0, 29.6816
62.833495191, 96.390, 843.0, 29.0345
62.886016322, 96.390, 844.0, 29.0517
62.938537452, 96.390, 835.0, 28.8964
62.991058583, 96.390, 774.0, 27.8209
63.043579714, 96.390, 793.0, 28.1603
63.096100844, 96.390, 764.0, 27.6405
63.148621975, 96.390, 785.0, 28.0179
63.201143106, 96.390, 771.0, 27.7669
63.253664237, 96.390, 754.0, 27.4591
63.306185367, 96.390, 795.0, 28.1957
63.358706498, 96.390, 788.0, 28.0713
63.411227629, 96.390, 787.0, 28.0535
63.463748759, 96.390, 755.0, 27.4773
63.516269890, 96.390, 758.0, 27.5318
63.568791021, 96.390, 797.0, 28.2312
63.621312152, 96.390, 752.0, 27.4226
63.673833282, 96.390, 719.0, 26.8142
63.726354413, 96.390, 771.0, 27.7669
63.778875544, 96.390, 719.0, 26.8142
63.831396674, 96.390, 744.0, 27.2764
63.883917805, 96.390, 791.0, 28.1247
63.936438936, 96.390, 860.0, 29.3258
63.988960067, 96.390, 839.0, 28.9655
64.041481197, 96.390, 825.0, 28.7228
64.094002328, 96.390, 878.0, 29.6311
64.146523459, 96.390, 818.0, 28.6007
64.199044589, 96.390, 784.0, 28.0000
64.251565720, 96.390, 757.0, 27.5136
64.304086851, 96.390, 705.0, 26.5518
64.356607981, 96.390, 672.0, 25.9230
64.409129112, 96.390, 654.0, 25.5734
64.461650243, 96.390, 700.0, 26.4575
64.514171374, 96.390, 642.0, 25.3377
64.566692504, 96.390, 731.0, 27.0370
64.619213635, 96.390, 759.0, 27.5500
64.671734766, 96.390, 693.0, 26.3249
64.724255896, 96.390, 652.0, 25.5343
64.776777027, 96.390, 718.0, 26.7955
64.829298158, 96.390, 685.0, 26.1725
64.881819289, 96.390, 718.0, 26.7955
64.934340419, 96.390, 772.0, 27.7849
64.986861550, 96.390, 700.0, 26.4575