File: Files_organized_for_plots/Spin_V_0_background/Spinner_MgAxial24Jan22_Act12Feb23_B1_0714M_NaOH_LS0173_Num154.csv
[Measurement conditions],,,
Sample identification,MgAxial24Jan22_Act12Feb23_B1_0714M_NaOH_LS0173_Num154,,
Comment - 1,"Configuration=Reflection-Transmission Spinner 3.0, Owner=nmw10, Creation date=9/26/2022 3:05:51 PM",,
Comment - 2,Goniometer=Theta/Theta; Minimum step size 2Theta:0.0001; Minimum step size Omega:0.0001,,
Comment - 3,Sample stage=Reflection-transmission spinner 3.0; Minimum step size Phi:0.1,,
Comment - 4,Diffractometer system=EMPYREAN,,
Comment - 5,"Measurement program=X:\XRD\Cement\Spinner_for_cement.xrdmp, Created identifier={6DF360EA-8E6E-4CFC-907C-F1BFECF51AA2}, Created by=Titus Reed, Id=tmr79, Creation date=2/15/2023 11:27:56 AM",,
Anode material,Cu,,
K-Alpha1 wavelength,1.540598,,
K-Alpha2 wavelength,1.544426,,
Ratio K-Alpha2/K-Alpha1,0.5,,
Divergence slit,Fixed,0.125,
Monochromator used,NO,,
Generator voltage,45,,
Tube current,40,,
File date and time,3/15/2023 22:19,,
Unit cell,,,
h k l, 0 0 0,,
Scan axis,Gonio,,
Scan range,4.994599997,64.99999183,
Scan step size,0.0262606,,
No. of points,2285,,
Scan type,CONTINUOUS,,
Phi,225.8,,
Time per step,96.39,,
Angle, TimePerStep, Intensity, ESD
5.00773028,96.39,1431,37.8286
5.060251411,96.39,1419,37.6696
5.112772541,96.39,1349,36.7287
5.165293672,96.39,1284,35.8329
5.217814803,96.39,1268,35.609
5.270335934,96.39,1270,35.6371
5.322857064,96.39,1274,35.6931
5.375378195,96.39,1314,36.2491
5.427899326,96.39,1253,35.3977
5.480420456,96.39,1171,34.2199
5.532941587,96.39,1201,34.6554
5.585462718,96.39,1231,35.0856
5.637983849,96.39,1176,34.2929
5.690504979,96.39,1193,34.5398
5.74302611,96.39,1219,34.9142
5.795547241,96.39,1166,34.1467
5.848068371,96.39,1199,34.6266
5.900589502,96.39,1162,34.0881
5.953110633,96.39,1252,35.3836
6.005631763,96.39,1203,34.6843
6.058152894,96.39,1105,33.2415
6.110674025,96.39,1133,33.6601
6.163195156,96.39,1164,34.1174
6.215716286,96.39,1165,34.1321
6.268237417,96.39,1118,33.4365
6.320758548,96.39,1059,32.5423
6.373279678,96.39,1102,33.1964
6.425800809,96.39,1106,33.2566
6.47832194,96.39,1030,32.0936
6.530843071,96.39,1056,32.4962
6.583364201,96.39,1079,32.8481
6.635885332,96.39,1099,33.1512
6.688406463,96.39,1054,32.4654
6.740927593,96.39,1090,33.0151
6.793448724,96.39,1064,32.619
6.845969855,96.39,980,31.305
6.898490986,96.39,1100,33.1662
6.951012116,96.39,1053,32.45
7.003533247,96.39,1077,32.8177
7.056054378,96.39,1079,32.8481
7.108575508,96.39,1091,33.0303
7.161096639,96.39,1018,31.9061
7.21361777,96.39,994,31.5278
7.2661389,96.39,996,31.5595
7.318660031,96.39,984,31.3688
7.371181162,96.39,1047,32.3574
7.423702293,96.39,1016,31.8748
7.476223423,96.39,999,31.607
7.528744554,96.39,948,30.7896
7.581265685,96.39,939,30.6431
7.633786815,96.39,990,31.4643
7.686307946,96.39,948,30.7896
7.738829077,96.39,1032,32.1248
7.791350208,96.39,954,30.8869
7.843871338,96.39,969,31.1288
7.896392469,96.39,1065,32.6343
7.9489136,96.39,998,31.5911
8.00143473,96.39,1027,32.0468
8.053955861,96.39,1075,32.7872
8.106476992,96.39,1070,32.7109
8.158998123,96.39,1102,33.1964
8.211519253,96.39,1041,32.2645
8.264040384,96.39,962,31.0161
8.316561515,96.39,1018,31.9061
8.369082645,96.39,1051,32.4191
8.421603776,96.39,978,31.273
8.474124907,96.39,980,31.305
8.526646038,96.39,1000,31.6228
8.579167168,96.39,941,30.6757
8.631688299,96.39,968,31.1127
8.68420943,96.39,986,31.4006
8.73673056,96.39,998,31.5911
8.789251691,96.39,999,31.607
8.841772822,96.39,1015,31.8591
8.894293952,96.39,974,31.209
8.946815083,96.39,972,31.1769
8.999336214,96.39,913,30.2159
9.051857345,96.39,1013,31.8277
9.104378475,96.39,994,31.5278
9.156899606,96.39,980,31.305
9.209420737,96.39,1030,32.0936
9.261941867,96.39,1020,31.9374
9.314462998,96.39,994,31.5278
9.366984129,96.39,971,31.1609
9.41950526,96.39,991,31.4802
9.47202639,96.39,1108,33.2866
9.524547521,96.39,1126,33.5559
9.577068652,96.39,1066,32.6497
9.629589782,96.39,1020,31.9374
9.682110913,96.39,1055,32.4808
9.734632044,96.39,1049,32.3883
9.787153175,96.39,1077,32.8177
9.839674305,96.39,1090,33.0151
9.892195436,96.39,1107,33.2716
9.944716567,96.39,1073,32.7567
9.997237697,96.39,1132,33.6452
10.04975883,96.39,1108,33.2866
10.10227996,96.39,1090,33.0151
10.15480109,96.39,1098,33.1361
10.20732222,96.39,1153,33.9559
10.25984335,96.39,1138,33.7343
10.31236448,96.39,1161,34.0735
10.36488561,96.39,1171,34.2199
10.41740674,96.39,1193,34.5398
10.46992787,96.39,1158,34.0294
10.522449,96.39,1169,34.1906
10.57497014,96.39,1174,34.2637
10.62749127,96.39,1269,35.623
10.6800124,96.39,1266,35.5809
10.73253353,96.39,1206,34.7275
10.78505466,96.39,1251,35.3695
10.83757579,96.39,1289,35.9026
10.89009692,96.39,1288,35.8887
10.94261805,96.39,1240,35.2136
10.99513918,96.39,1342,36.6333
11.04766031,96.39,1254,35.4119
11.10018144,96.39,1274,35.6931
11.15270257,96.39,1289,35.9026
11.2052237,96.39,1278,35.7491
11.25774483,96.39,1220,34.9285
11.31026597,96.39,1259,35.4824
11.3627871,96.39,1222,34.9571
11.41530823,96.39,1249,35.3412
11.46782936,96.39,1232,35.0999
11.52035049,96.39,1186,34.4384
11.57287162,96.39,1257,35.4542
11.62539275,96.39,1212,34.8138
11.67791388,96.39,1100,33.1662
11.73043501,96.39,1132,33.6452
11.78295614,96.39,1154,33.9706
11.83547727,96.39,1170,34.2053
11.8879984,96.39,1169,34.1906
11.94051953,96.39,1143,33.8083
11.99304066,96.39,1036,32.187
12.0455618,96.39,1076,32.8024
12.09808293,96.39,1100,33.1662
12.15060406,96.39,1017,31.8904
12.20312519,96.39,1062,32.5883
12.25564632,96.39,989,31.4484
12.30816745,96.39,1017,31.8904
12.36068858,96.39,945,30.7409
12.41320971,96.39,1022,31.9687
12.46573084,96.39,950,30.8221
12.51825197,96.39,958,30.9516
12.5707731,96.39,920,30.3315
12.62329423,96.39,903,30.05
12.67581536,96.39,911,30.1828
12.72833649,96.39,920,30.3315
12.78085763,96.39,882,29.6985
12.83337876,96.39,898,29.9666
12.88589989,96.39,882,29.6985
12.93842102,96.39,842,29.0172
12.99094215,96.39,818,28.6007
13.04346328,96.39,805,28.3725
13.09598441,96.39,783,27.9821
13.14850554,96.39,803,28.3373
13.20102667,96.39,796,28.2135
13.2535478,96.39,745,27.2947
13.30606893,96.39,801,28.3019
13.35859006,96.39,774,27.8209
13.41111119,96.39,783,27.9821
13.46363232,96.39,755,27.4773
13.51615346,96.39,776,27.8568
13.56867459,96.39,708,26.6083
13.62119572,96.39,763,27.6225
13.67371685,96.39,708,26.6083
13.72623798,96.39,701,26.4764
13.77875911,96.39,780,27.9285
13.83128024,96.39,724,26.9072
13.88380137,96.39,746,27.313
13.9363225,96.39,704,26.533
13.98884363,96.39,656,25.6125
14.04136476,96.39,673,25.9422
14.09388589,96.39,689,26.2488
14.14640702,96.39,715,26.7395
14.19892815,96.39,669,25.865
14.25144929,96.39,727,26.9629
14.30397042,96.39,763,27.6225
14.35649155,96.39,696,26.3818
14.40901268,96.39,673,25.9422
14.46153381,96.39,794,28.178
14.51405494,96.39,949,30.8058
14.56657607,96.39,916,30.2655
14.6190972,96.39,735,27.1109
14.67161833,96.39,618,24.8596
14.72413946,96.39,610,24.6982
14.77666059,96.39,611,24.7184
14.82918172,96.39,603,24.5561
14.88170285,96.39,592,24.3311
14.93422398,96.39,631,25.1197
14.98674512,96.39,613,24.7588
15.03926625,96.39,598,24.454
15.09178738,96.39,696,26.3818
15.14430851,96.39,684,26.1534
15.19682964,96.39,813,28.5132
15.24935077,96.39,741,27.2213
15.3018719,96.39,697,26.4008
15.35439303,96.39,665,25.7876
15.40691416,96.39,623,24.96
15.45943529,96.39,631,25.1197
15.51195642,96.39,619,24.8797
15.56447755,96.39,613,24.7588
15.61699868,96.39,609,24.6779
15.66951981,96.39,602,24.5357
15.72204095,96.39,697,26.4008
15.77456208,96.39,538,23.1948
15.82708321,96.39,605,24.5967
15.87960434,96.39,625,25
15.93212547,96.39,571,23.8956
15.9846466,96.39,569,23.8537
16.03716773,96.39,607,24.6374
16.08968886,96.39,579,24.0624
16.14220999,96.39,585,24.1868
16.19473112,96.39,635,25.1992
16.24725225,96.39,636,25.219
16.29977338,96.39,754,27.4591
16.35229451,96.39,816,28.5657
16.40481564,96.39,592,24.3311
16.45733678,96.39,587,24.2281
16.50985791,96.39,603,24.5561
16.56237904,96.39,599,24.4745
16.61490017,96.39,520,22.8035
16.6674213,96.39,551,23.4734
16.71994243,96.39,523,22.8692
16.77246356,96.39,588,24.2487
16.82498469,96.39,625,25
16.87750582,96.39,601,24.5153
16.93002695,96.39,579,24.0624
16.98254808,96.39,547,23.388
17.03506921,96.39,468,21.6333
17.08759034,96.39,575,23.9792
17.14011147,96.39,499,22.3383
17.19263261,96.39,557,23.6008
17.24515374,96.39,510,22.5832
17.29767487,96.39,522,22.8473
17.350196,96.39,561,23.6854
17.40271713,96.39,610,24.6982
17.45523826,96.39,534,23.1084
17.50775939,96.39,525,22.9129
17.56028052,96.39,515,22.6936
17.61280165,96.39,547,23.388
17.66532278,96.39,517,22.7376
17.71784391,96.39,572,23.9165
17.77036504,96.39,526,22.9347
17.82288617,96.39,526,22.9347
17.8754073,96.39,561,23.6854
17.92792843,96.39,512,22.6274
17.98044957,96.39,543,23.3024
18.0329707,96.39,556,23.5797
18.08549183,96.39,539,23.2164
18.13801296,96.39,531,23.0434
18.19053409,96.39,546,23.3666
18.24305522,96.39,561,23.6854
18.29557635,96.39,602,24.5357
18.34809748,96.39,586,24.2074
18.40061861,96.39,551,23.4734
18.45313974,96.39,556,23.5797
18.50566087,96.39,526,22.9347
18.558182,96.39,571,23.8956
18.61070313,96.39,528,22.9783
18.66322426,96.39,575,23.9792
18.7157454,96.39,590,24.2899
18.76826653,96.39,602,24.5357
18.82078766,96.39,695,26.3629
18.87330879,96.39,820,28.6356
18.92582992,96.39,786,28.0357
18.97835105,96.39,855,29.2404
19.03087218,96.39,728,26.9815
19.08339331,96.39,645,25.3969
19.13591444,96.39,664,25.7682
19.18843557,96.39,572,23.9165
19.2409567,96.39,574,23.9583
19.29347783,96.39,610,24.6982
19.34599896,96.39,592,24.3311
19.39852009,96.39,598,24.454
19.45104123,96.39,615,24.7992
19.50356236,96.39,623,24.96
19.55608349,96.39,560,23.6643
19.60860462,96.39,547,23.388
19.66112575,96.39,545,23.3452
19.71364688,96.39,568,23.8328
19.76616801,96.39,636,25.219
19.81868914,96.39,595,24.3926
19.87121027,96.39,633,25.1595
19.9237314,96.39,576,24
19.97625253,96.39,563,23.7276
20.02877366,96.39,604,24.5764
20.08129479,96.39,577,24.0208
20.13381592,96.39,597,24.4336
20.18633706,96.39,585,24.1868
20.23885819,96.39,625,25
20.29137932,96.39,640,25.2982
20.34390045,96.39,599,24.4745
20.39642158,96.39,671,25.9037
20.44894271,96.39,731,27.037
20.50146384,96.39,723,26.8887
20.55398497,96.39,695,26.3629
20.6065061,96.39,720,26.8328
20.65902723,96.39,746,27.313
20.71154836,96.39,793,28.1603
20.76406949,96.39,699,26.4386
20.81659062,96.39,706,26.5707
20.86911175,96.39,660,25.6905
20.92163289,96.39,638,25.2587
20.97415402,96.39,614,24.779
21.02667515,96.39,633,25.1595
21.07919628,96.39,625,25
21.13171741,96.39,611,24.7184
21.18423854,96.39,685,26.1725
21.23675967,96.39,656,25.6125
21.2892808,96.39,772,27.7849
21.34180193,96.39,800,28.2843
21.39432306,96.39,655,25.593
21.44684419,96.39,654,25.5734
21.49936532,96.39,659,25.671
21.55188645,96.39,808,28.4253
21.60440758,96.39,800,28.2843
21.65692872,96.39,833,28.8617
21.70944985,96.39,789,28.0891
21.76197098,96.39,667,25.8263
21.81449211,96.39,663,25.7488
21.86701324,96.39,660,25.6905
21.91953437,96.39,671,25.9037
21.9720555,96.39,666,25.807
22.02457663,96.39,704,26.533
22.07709776,96.39,634,25.1794
22.12961889,96.39,746,27.313
22.18214002,96.39,749,27.3679
22.23466115,96.39,734,27.0924
22.28718228,96.39,788,28.0713
22.33970341,96.39,751,27.4044
22.39222455,96.39,774,27.8209
22.44474568,96.39,796,28.2135
22.49726681,96.39,771,27.7669
22.54978794,96.39,824,28.7054
22.60230907,96.39,816,28.5657
22.6548302,96.39,817,28.5832
22.70735133,96.39,797,28.2312
22.75987246,96.39,855,29.2404
22.81239359,96.39,901,30.0167
22.86491472,96.39,967,31.0966
22.91743585,96.39,944,30.7246
22.96995698,96.39,845,29.0689
23.02247811,96.39,843,29.0345
23.07499924,96.39,900,30
23.12752038,96.39,956,30.9192
23.18004151,96.39,1039,32.2335
23.23256264,96.39,1007,31.7333
23.28508377,96.39,867,29.4449
23.3376049,96.39,881,29.6816
23.39012603,96.39,867,29.4449
23.44264716,96.39,809,28.4429
23.49516829,96.39,779,27.9106
23.54768942,96.39,756,27.4955
23.60021055,96.39,810,28.4605
23.65273168,96.39,738,27.1662
23.70525281,96.39,695,26.3629
23.75777394,96.39,672,25.923
23.81029507,96.39,697,26.4008
23.86281621,96.39,648,25.4558
23.91533734,96.39,689,26.2488
23.96785847,96.39,652,25.5343
24.0203796,96.39,651,25.5147
24.07290073,96.39,617,24.8395
24.12542186,96.39,642,25.3377
24.17794299,96.39,645,25.3969
24.23046412,96.39,645,25.3969
24.28298525,96.39,614,24.779
24.33550638,96.39,624,24.98
24.38802751,96.39,612,24.7386
24.44054864,96.39,591,24.3105
24.49306977,96.39,607,24.6374
24.5455909,96.39,603,24.5561
24.59811204,96.39,616,24.8193
24.65063317,96.39,550,23.4521
24.7031543,96.39,588,24.2487
24.75567543,96.39,555,23.5584
24.80819656,96.39,550,23.4521
24.86071769,96.39,580,24.0832
24.91323882,96.39,552,23.4947
24.96575995,96.39,502,22.4054
25.01828108,96.39,550,23.4521
25.07080221,96.39,510,22.5832
25.12332334,96.39,537,23.1733
25.17584447,96.39,565,23.7697
25.2283656,96.39,496,22.2711
25.28088673,96.39,502,22.4054
25.33340786,96.39,501,22.383
25.385929,96.39,529,23
25.43845013,96.39,542,23.2809
25.49097126,96.39,519,22.7816
25.54349239,96.39,492,22.1811
25.59601352,96.39,483,21.9773
25.64853465,96.39,517,22.7376
25.70105578,96.39,534,23.1084
25.75357691,96.39,471,21.7025
25.80609804,96.39,557,23.6008
25.85861917,96.39,572,23.9165
25.9111403,96.39,504,22.4499
25.96366143,96.39,582,24.1247
26.01618256,96.39,541,23.2594
26.06870369,96.39,560,23.6643
26.12122483,96.39,499,22.3383
26.17374596,96.39,544,23.3238
26.22626709,96.39,508,22.5389
26.27878822,96.39,503,22.4277
26.33130935,96.39,509,22.561
26.38383048,96.39,487,22.0681
26.43635161,96.39,553,23.516
26.48887274,96.39,508,22.5389
26.54139387,96.39,550,23.4521
26.593915,96.39,569,23.8537
26.64643613,96.39,554,23.5372
26.69895726,96.39,602,24.5357
26.75147839,96.39,696,26.3818
26.80399952,96.39,749,27.3679
26.85652066,96.39,752,27.4226
26.90904179,96.39,709,26.6271
26.96156292,96.39,622,24.9399
27.01408405,96.39,762,27.6043
27.06660518,96.39,758,27.5318
27.11912631,96.39,842,29.0172
27.17164744,96.39,856,29.2575
27.22416857,96.39,846,29.0861
27.2766897,96.39,748,27.3496
27.32921083,96.39,590,24.2899
27.38173196,96.39,615,24.7992
27.43425309,96.39,592,24.3311
27.48677422,96.39,571,23.8956
27.53929535,96.39,554,23.5372
27.59181649,96.39,509,22.561
27.64433762,96.39,513,22.6495
27.69685875,96.39,578,24.0416
27.74937988,96.39,522,22.8473
27.80190101,96.39,502,22.4054
27.85442214,96.39,481,21.9317
27.90694327,96.39,509,22.561
27.9594644,96.39,514,22.6716
28.01198553,96.39,518,22.7596
28.06450666,96.39,544,23.3238
28.11702779,96.39,517,22.7376
28.16954892,96.39,493,22.2036
28.22207005,96.39,487,22.0681
28.27459118,96.39,552,23.4947
28.32711232,96.39,631,25.1197
28.37963345,96.39,572,23.9165
28.43215458,96.39,564,23.7487
28.48467571,96.39,622,24.9399
28.53719684,96.39,561,23.6854
28.58971797,96.39,575,23.9792
28.6422391,96.39,495,22.2486
28.69476023,96.39,524,22.891
28.74728136,96.39,507,22.5167
28.79980249,96.39,523,22.8692
28.85232362,96.39,585,24.1868
28.90484475,96.39,597,24.4336
28.95736588,96.39,529,23
29.00988701,96.39,578,24.0416
29.06240815,96.39,595,24.3926
29.11492928,96.39,603,24.5561
29.16745041,96.39,671,25.9037
29.21997154,96.39,720,26.8328
29.27249267,96.39,819,28.6182
29.3250138,96.39,880,29.6648
29.37753493,96.39,781,27.9464
29.43005606,96.39,782,27.9643
29.48257719,96.39,800,28.2843
29.53509832,96.39,729,27
29.58761945,96.39,651,25.5147
29.64014058,96.39,638,25.2587
29.69266171,96.39,587,24.2281
29.74518284,96.39,628,25.0599
29.79770398,96.39,552,23.4947
29.85022511,96.39,551,23.4734
29.90274624,96.39,569,23.8537
29.95526737,96.39,504,22.4499
30.0077885,96.39,620,24.8998
30.06030963,96.39,546,23.3666
30.11283076,96.39,520,22.8035
30.16535189,96.39,556,23.5797
30.21787302,96.39,510,22.5832
30.27039415,96.39,531,23.0434
30.32291528,96.39,479,21.8861
30.37543641,96.39,516,22.7156
30.42795754,96.39,518,22.7596
30.48047867,96.39,594,24.3721
30.53299981,96.39,544,23.3238
30.58552094,96.39,577,24.0208
30.63804207,96.39,601,24.5153
30.6905632,96.39,589,24.2693
30.74308433,96.39,638,25.2587
30.79560546,96.39,610,24.6982
30.84812659,96.39,591,24.3105
30.90064772,96.39,569,23.8537
30.95316885,96.39,564,23.7487
31.00568998,96.39,580,24.0832
31.05821111,96.39,540,23.2379
31.11073224,96.39,602,24.5357
31.16325337,96.39,601,24.5153
31.2157745,96.39,701,26.4764
31.26829564,96.39,704,26.533
31.32081677,96.39,840,28.9828
31.3733379,96.39,776,27.8568
31.42585903,96.39,733,27.074
31.47838016,96.39,638,25.2587
31.53090129,96.39,591,24.3105
31.58342242,96.39,545,23.3452
31.63594355,96.39,561,23.6854
31.68846468,96.39,637,25.2389
31.74098581,96.39,526,22.9347
31.79350694,96.39,571,23.8956
31.84602807,96.39,610,24.6982
31.8985492,96.39,676,26
31.95107033,96.39,628,25.0599
32.00359147,96.39,665,25.7876
32.0561126,96.39,708,26.6083
32.10863373,96.39,687,26.2107
32.16115486,96.39,654,25.5734
32.21367599,96.39,736,27.1293
32.26619712,96.39,768,27.7128
32.31871825,96.39,803,28.3373
32.37123938,96.39,691,26.2869
32.42376051,96.39,629,25.0799
32.47628164,96.39,555,23.5584
32.52880277,96.39,531,23.0434
32.5813239,96.39,577,24.0208
32.63384503,96.39,578,24.0416
32.68636616,96.39,569,23.8537
32.7388873,96.39,618,24.8596
32.79140843,96.39,609,24.6779
32.84392956,96.39,631,25.1197
32.89645069,96.39,601,24.5153
32.94897182,96.39,608,24.6577
33.00149295,96.39,605,24.5967
33.05401408,96.39,622,24.9399
33.10653521,96.39,615,24.7992
33.15905634,96.39,643,25.3574
33.21157747,96.39,614,24.779
33.2640986,96.39,628,25.0599
33.31661973,96.39,590,24.2899
33.36914086,96.39,647,25.4362
33.42166199,96.39,676,26
33.47418312,96.39,724,26.9072
33.52670426,96.39,662,25.7294
33.57922539,96.39,637,25.2389
33.63174652,96.39,662,25.7294
33.68426765,96.39,650,25.4951
33.73678878,96.39,661,25.7099
33.78930991,96.39,650,25.4951
33.84183104,96.39,662,25.7294
33.89435217,96.39,750,27.3861
33.9468733,96.39,736,27.1293
33.99939443,96.39,731,27.037
34.05191556,96.39,748,27.3496
34.10443669,96.39,821,28.6531
34.15695782,96.39,839,28.9655
34.20947895,96.39,867,29.4449
34.26200009,96.39,897,29.95
34.31452122,96.39,853,29.2062
34.36704235,96.39,874,29.5635
34.41956348,96.39,919,30.315
34.47208461,96.39,989,31.4484
34.52460574,96.39,1032,32.1248
34.57712687,96.39,1111,33.3317
34.629648,96.39,1126,33.5559
34.68216913,96.39,938,30.6268
34.73469026,96.39,880,29.6648
34.78721139,96.39,840,28.9828
34.83973252,96.39,791,28.1247
34.89225365,96.39,855,29.2404
34.94477478,96.39,809,28.4429
34.99729592,96.39,785,28.0179
35.04981705,96.39,842,29.0172
35.10233818,96.39,789,28.0891
35.15485931,96.39,814,28.5307
35.20738044,96.39,786,28.0357
35.25990157,96.39,800,28.2843
35.3124227,96.39,722,26.8701
35.36494383,96.39,714,26.7208
35.41746496,96.39,648,25.4558
35.46998609,96.39,620,24.8998
35.52250722,96.39,689,26.2488
35.57502835,96.39,642,25.3377
35.62754948,96.39,677,26.0192
35.68007061,96.39,649,25.4755
35.73259175,96.39,671,25.9037
35.78511288,96.39,680,26.0768
35.83763401,96.39,692,26.3059
35.89015514,96.39,723,26.8887
35.94267627,96.39,817,28.5832
35.9951974,96.39,712,26.6833
36.04771853,96.39,796,28.2135
36.10023966,96.39,749,27.3679
36.15276079,96.39,820,28.6356
36.20528192,96.39,940,30.6594
36.25780305,96.39,736,27.1293
36.31032418,96.39,769,27.7308
36.36284531,96.39,645,25.3969
36.41536644,96.39,548,23.4094
36.46788758,96.39,527,22.9565
36.52040871,96.39,543,23.3024
36.57292984,96.39,557,23.6008
36.62545097,96.39,609,24.6779
36.6779721,96.39,530,23.0217
36.73049323,96.39,513,22.6495
36.78301436,96.39,486,22.0454
36.83553549,96.39,494,22.2261
36.88805662,96.39,508,22.5389
36.94057775,96.39,508,22.5389
36.99309888,96.39,548,23.4094
37.04562001,96.39,484,22
37.09814114,96.39,543,23.3024
37.15066227,96.39,540,23.2379
37.20318341,96.39,508,22.5389
37.25570454,96.39,565,23.7697
37.30822567,96.39,560,23.6643
37.3607468,96.39,570,23.8747
37.41326793,96.39,549,23.4307
37.46578906,96.39,600,24.4949
37.51831019,96.39,582,24.1247
37.57083132,96.39,615,24.7992
37.62335245,96.39,597,24.4336
37.67587358,96.39,619,24.8797
37.72839471,96.39,566,23.7908
37.78091584,96.39,648,25.4558
37.83343697,96.39,684,26.1534
37.8859581,96.39,661,25.7099
37.93847924,96.39,676,26
37.99100037,96.39,640,25.2982
38.0435215,96.39,600,24.4949
38.09604263,96.39,570,23.8747
38.14856376,96.39,541,23.2594
38.20108489,96.39,608,24.6577
38.25360602,96.39,562,23.7065
38.30612715,96.39,576,24
38.35864828,96.39,491,22.1585
38.41116941,96.39,522,22.8473
38.46369054,96.39,502,22.4054
38.51621167,96.39,505,22.4722
38.5687328,96.39,539,23.2164
38.62125393,96.39,543,23.3024
38.67377507,96.39,498,22.3159
38.7262962,96.39,480,21.9089
38.77881733,96.39,504,22.4499
38.83133846,96.39,501,22.383
38.88385959,96.39,463,21.5174
38.93638072,96.39,534,23.1084
38.98890185,96.39,487,22.0681
39.04142298,96.39,508,22.5389
39.09394411,96.39,522,22.8473
39.14646524,96.39,557,23.6008
39.19898637,96.39,550,23.4521
39.2515075,96.39,495,22.2486
39.30402863,96.39,553,23.516
39.35654976,96.39,484,22
39.4090709,96.39,491,22.1585
39.46159203,96.39,483,21.9773
39.51411316,96.39,508,22.5389
39.56663429,96.39,463,21.5174
39.61915542,96.39,496,22.2711
39.67167655,96.39,496,22.2711
39.72419768,96.39,469,21.6564
39.77671881,96.39,511,22.6053
39.82923994,96.39,568,23.8328
39.88176107,96.39,499,22.3383
39.9342822,96.39,462,21.4942
39.98680333,96.39,498,22.3159
40.03932446,96.39,497,22.2935
40.09184559,96.39,456,21.3542
40.14436673,96.39,453,21.2838
40.19688786,96.39,454,21.3073
40.24940899,96.39,460,21.4476
40.30193012,96.39,434,20.8327
40.35445125,96.39,451,21.2368
40.40697238,96.39,431,20.7605
40.45949351,96.39,436,20.8806
40.51201464,96.39,414,20.347
40.56453577,96.39,440,20.9762
40.6170569,96.39,461,21.4709
40.66957803,96.39,463,21.5174
40.72209916,96.39,452,21.2603
40.77462029,96.39,459,21.4243
40.82714142,96.39,388,19.6977
40.87966255,96.39,412,20.2978
40.93218369,96.39,407,20.1742
40.98470482,96.39,416,20.3961
41.03722595,96.39,380,19.4936
41.08974708,96.39,407,20.1742
41.14226821,96.39,442,21.0238
41.19478934,96.39,410,20.2485
41.24731047,96.39,433,20.8087
41.2998316,96.39,379,19.4679
41.35235273,96.39,400,20
41.40487386,96.39,379,19.4679
41.45739499,96.39,373,19.3132
41.50991612,96.39,386,19.6469
41.56243725,96.39,398,19.9499
41.61495838,96.39,419,20.4695
41.66747952,96.39,399,19.975
41.72000065,96.39,386,19.6469
41.77252178,96.39,417,20.4206
41.82504291,96.39,392,19.799
41.87756404,96.39,381,19.5192
41.93008517,96.39,385,19.6214
41.9826063,96.39,399,19.975
42.03512743,96.39,450,21.2132
42.08764856,96.39,452,21.2603
42.14016969,96.39,521,22.8254
42.19269082,96.39,573,23.9374
42.24521195,96.39,527,22.9565
42.29773308,96.39,464,21.5407
42.35025421,96.39,405,20.1246
42.40277535,96.39,424,20.5913
42.45529648,96.39,353,18.7883
42.50781761,96.39,380,19.4936
42.56033874,96.39,346,18.6011
42.61285987,96.39,382,19.5448
42.665381,96.39,348,18.6548
42.71790213,96.39,414,20.347
42.77042326,96.39,369,19.2094
42.82294439,96.39,365,19.105
42.87546552,96.39,350,18.7083
42.92798665,96.39,343,18.5203
42.98050778,96.39,343,18.5203
43.03302891,96.39,381,19.5192
43.08555004,96.39,334,18.2757
43.13807118,96.39,365,19.105
43.19059231,96.39,321,17.9165
43.24311344,96.39,405,20.1246
43.29563457,96.39,353,18.7883
43.3481557,96.39,333,18.2483
43.40067683,96.39,351,18.735
43.45319796,96.39,368,19.1833
43.50571909,96.39,354,18.8149
43.55824022,96.39,346,18.6011
43.61076135,96.39,344,18.5472
43.66328248,96.39,348,18.6548
43.71580361,96.39,341,18.4662
43.76832474,96.39,377,19.4165
43.82084587,96.39,353,18.7883
43.87336701,96.39,418,20.445
43.92588814,96.39,412,20.2978
43.97840927,96.39,381,19.5192
44.0309304,96.39,372,19.2873
44.08345153,96.39,382,19.5448
44.13597266,96.39,350,18.7083
44.18849379,96.39,353,18.7883
44.24101492,96.39,376,19.3907
44.29353605,96.39,401,20.025
44.34605718,96.39,375,19.3649
44.39857831,96.39,342,18.4932
44.45109944,96.39,368,19.1833
44.50362057,96.39,372,19.2873
44.5561417,96.39,376,19.3907
44.60866284,96.39,372,19.2873
44.66118397,96.39,371,19.2614
44.7137051,96.39,381,19.5192
44.76622623,96.39,387,19.6723
44.81874736,96.39,397,19.9249
44.87126849,96.39,407,20.1742
44.92378962,96.39,418,20.445
44.97631075,96.39,430,20.7364
45.02883188,96.39,384,19.5959
45.08135301,96.39,398,19.9499
45.13387414,96.39,438,20.9284
45.18639527,96.39,435,20.8567
45.2389164,96.39,377,19.4165
45.29143753,96.39,413,20.3224
45.34395867,96.39,397,19.9249
45.3964798,96.39,412,20.2978
45.44900093,96.39,341,18.4662
45.50152206,96.39,380,19.4936
45.55404319,96.39,379,19.4679
45.60656432,96.39,409,20.2237
45.65908545,96.39,386,19.6469
45.71160658,96.39,410,20.2485
45.76412771,96.39,407,20.1742
45.81664884,96.39,392,19.799
45.86916997,96.39,378,19.4422
45.9216911,96.39,414,20.347
45.97421223,96.39,421,20.5183
46.02673336,96.39,394,19.8494
46.0792545,96.39,417,20.4206
46.13177563,96.39,459,21.4243
46.18429676,96.39,478,21.8632
46.23681789,96.39,517,22.7376
46.28933902,96.39,471,21.7025
46.34186015,96.39,460,21.4476
46.39438128,96.39,447,21.1424
46.44690241,96.39,405,20.1246
46.49942354,96.39,402,20.0499
46.55194467,96.39,398,19.9499
46.6044658,96.39,375,19.3649
46.65698693,96.39,424,20.5913
46.70950806,96.39,402,20.0499
46.76202919,96.39,408,20.199
46.81455033,96.39,396,19.8997
46.86707146,96.39,395,19.8746
46.91959259,96.39,351,18.735
46.97211372,96.39,348,18.6548
47.02463485,96.39,390,19.7484
47.07715598,96.39,390,19.7484
47.12967711,96.39,403,20.0749
47.18219824,96.39,355,18.8414
47.23471937,96.39,372,19.2873
47.2872405,96.39,355,18.8414
47.33976163,96.39,399,19.975
47.39228276,96.39,384,19.5959
47.44480389,96.39,393,19.8242
47.49732502,96.39,404,20.0998
47.54984616,96.39,376,19.3907
47.60236729,96.39,403,20.0749
47.65488842,96.39,424,20.5913
47.70740955,96.39,387,19.6723
47.75993068,96.39,436,20.8806
47.81245181,96.39,403,20.0749
47.86497294,96.39,379,19.4679
47.91749407,96.39,428,20.6882
47.9700152,96.39,356,18.868
48.02253633,96.39,332,18.2209
48.07505746,96.39,419,20.4695
48.12757859,96.39,369,19.2094
48.18009972,96.39,386,19.6469
48.23262085,96.39,364,19.0788
48.28514198,96.39,415,20.3715
48.33766312,96.39,418,20.445
48.39018425,96.39,413,20.3224
48.44270538,96.39,424,20.5913
48.49522651,96.39,404,20.0998
48.54774764,96.39,398,19.9499
48.60026877,96.39,359,18.9473
48.6527899,96.39,353,18.7883
48.70531103,96.39,344,18.5472
48.75783216,96.39,370,19.2354
48.81035329,96.39,365,19.105
48.86287442,96.39,359,18.9473
48.91539555,96.39,371,19.2614
48.96791668,96.39,354,18.8149
49.02043781,96.39,350,18.7083
49.07295895,96.39,350,18.7083
49.12548008,96.39,370,19.2354
49.17800121,96.39,390,19.7484
49.23052234,96.39,324,18
49.28304347,96.39,353,18.7883
49.3355646,96.39,338,18.3848
49.38808573,96.39,354,18.8149
49.44060686,96.39,336,18.3303
49.49312799,96.39,353,18.7883
49.54564912,96.39,320,17.8885
49.59817025,96.39,340,18.4391
49.65069138,96.39,322,17.9444
49.70321251,96.39,324,18
49.75573364,96.39,309,17.5784
49.80825478,96.39,354,18.8149
49.86077591,96.39,312,17.6635
49.91329704,96.39,312,17.6635
49.96581817,96.39,307,17.5214
50.0183393,96.39,309,17.5784
50.07086043,96.39,283,16.8226
50.12338156,96.39,301,17.3494
50.17590269,96.39,302,17.3781
50.22842382,96.39,337,18.3576
50.28094495,96.39,324,18
50.33346608,96.39,337,18.3576
50.38598721,96.39,326,18.0555
50.43850834,96.39,383,19.5704
50.49102947,96.39,380,19.4936
50.54355061,96.39,370,19.2354
50.59607174,96.39,323,17.9722
50.64859287,96.39,342,18.4932
50.701114,96.39,319,17.8606
50.75363513,96.39,340,18.4391
50.80615626,96.39,325,18.0278
50.85867739,96.39,310,17.6068
50.91119852,96.39,296,17.2047
50.96371965,96.39,334,18.2757
51.01624078,96.39,360,18.9737
51.06876191,96.39,394,19.8494
51.12128304,96.39,317,17.8045
51.17380417,96.39,345,18.5742
51.2263253,96.39,305,17.4642
51.27884644,96.39,373,19.3132
51.33136757,96.39,264,16.2481
51.3838887,96.39,308,17.5499
51.43640983,96.39,305,17.4642
51.48893096,96.39,297,17.2337
51.54145209,96.39,288,16.9706
51.59397322,96.39,303,17.4069
51.64649435,96.39,283,16.8226
51.69901548,96.39,327,18.0831
51.75153661,96.39,332,18.2209
51.80405774,96.39,295,17.1756
51.85657887,96.39,290,17.0294
51.9091,96.39,292,17.088
51.96162113,96.39,299,17.2916
52.01414227,96.39,294,17.1464
52.0666634,96.39,270,16.4317
52.11918453,96.39,264,16.2481
52.17170566,96.39,293,17.1172
52.22422679,96.39,293,17.1172
52.27674792,96.39,333,18.2483
52.32926905,96.39,281,16.7631
52.38179018,96.39,299,17.2916
52.43431131,96.39,287,16.9411
52.48683244,96.39,322,17.9444
52.53935357,96.39,291,17.0587
52.5918747,96.39,277,16.6433
52.64439583,96.39,275,16.5831
52.69691696,96.39,280,16.7332
52.7494381,96.39,268,16.3707
52.80195923,96.39,276,16.6132
52.85448036,96.39,304,17.4356
52.90700149,96.39,297,17.2337
52.95952262,96.39,293,17.1172
53.01204375,96.39,278,16.6733
53.06456488,96.39,288,16.9706
53.11708601,96.39,269,16.4012
53.16960714,96.39,293,17.1172
53.22212827,96.39,280,16.7332
53.2746494,96.39,300,17.3205
53.32717053,96.39,314,17.72
53.37969166,96.39,314,17.72
53.43221279,96.39,283,16.8226
53.48473393,96.39,263,16.2173
53.53725506,96.39,259,16.0935
53.58977619,96.39,321,17.9165
53.64229732,96.39,263,16.2173
53.69481845,96.39,270,16.4317
53.74733958,96.39,290,17.0294
53.79986071,96.39,294,17.1464
53.85238184,96.39,326,18.0555
53.90490297,96.39,306,17.4929
53.9574241,96.39,348,18.6548
54.00994523,96.39,310,17.6068
54.06246636,96.39,324,18
54.11498749,96.39,316,17.7764
54.16750862,96.39,297,17.2337
54.22002976,96.39,318,17.8326
54.27255089,96.39,288,16.9706
54.32507202,96.39,259,16.0935
54.37759315,96.39,295,17.1756
54.43011428,96.39,287,16.9411
54.48263541,96.39,330,18.1659
54.53515654,96.39,281,16.7631
54.58767767,96.39,284,16.8523
54.6401988,96.39,302,17.3781
54.69271993,96.39,241,15.5242
54.74524106,96.39,298,17.2627
54.79776219,96.39,272,16.4924
54.85028332,96.39,270,16.4317
54.90280445,96.39,276,16.6132
54.95532559,96.39,231,15.1987
55.00784672,96.39,257,16.0312
55.06036785,96.39,264,16.2481
55.11288898,96.39,266,16.3095
55.16541011,96.39,248,15.748
55.21793124,96.39,252,15.8745
55.27045237,96.39,257,16.0312
55.3229735,96.39,260,16.1245
55.37549463,96.39,275,16.5831
55.42801576,96.39,224,14.9666
55.48053689,96.39,288,16.9706
55.53305802,96.39,285,16.8819
55.58557915,96.39,259,16.0935
55.63810028,96.39,248,15.748
55.69062141,96.39,252,15.8745
55.74314255,96.39,277,16.6433
55.79566368,96.39,278,16.6733
55.84818481,96.39,252,15.8745
55.90070594,96.39,287,16.9411
55.95322707,96.39,297,17.2337
56.0057482,96.39,281,16.7631
56.05826933,96.39,289,17
56.11079046,96.39,277,16.6433
56.16331159,96.39,302,17.3781
56.21583272,96.39,280,16.7332
56.26835385,96.39,307,17.5214
56.32087498,96.39,285,16.8819
56.37339611,96.39,294,17.1464
56.42591724,96.39,294,17.1464
56.47843838,96.39,285,16.8819
56.53095951,96.39,285,16.8819
56.58348064,96.39,249,15.7797
56.63600177,96.39,286,16.9115
56.6885229,96.39,257,16.0312
56.74104403,96.39,251,15.843
56.79356516,96.39,256,16
56.84608629,96.39,236,15.3623
56.89860742,96.39,275,16.5831
56.95112855,96.39,239,15.4596
57.00364968,96.39,249,15.7797
57.05617081,96.39,286,16.9115
57.10869194,96.39,275,16.5831
57.16121307,96.39,274,16.5529
57.21373421,96.39,267,16.3401
57.26625534,96.39,290,17.0294
57.31877647,96.39,272,16.4924
57.3712976,96.39,271,16.4621
57.42381873,96.39,260,16.1245
57.47633986,96.39,257,16.0312
57.52886099,96.39,256,16
57.58138212,96.39,266,16.3095
57.63390325,96.39,272,16.4924
57.68642438,96.39,268,16.3707
57.73894551,96.39,265,16.2788
57.79146664,96.39,277,16.6433
57.84398777,96.39,263,16.2173
57.8965089,96.39,282,16.7929
57.94903004,96.39,282,16.7929
58.00155117,96.39,264,16.2481
58.0540723,96.39,265,16.2788
58.10659343,96.39,248,15.748
58.15911456,96.39,258,16.0624
58.21163569,96.39,252,15.8745
58.26415682,96.39,229,15.1327
58.31667795,96.39,247,15.7162
58.36919908,96.39,269,16.4012
58.42172021,96.39,234,15.2971
58.47424134,96.39,258,16.0624
58.52676247,96.39,237,15.3948
58.5792836,96.39,282,16.7929
58.63180473,96.39,257,16.0312
58.68432587,96.39,255,15.9687
58.736847,96.39,252,15.8745
58.78936813,96.39,259,16.0935
58.84188926,96.39,236,15.3623
58.89441039,96.39,267,16.3401
58.94693152,96.39,247,15.7162
58.99945265,96.39,259,16.0935
59.05197378,96.39,234,15.2971
59.10449491,96.39,262,16.1864
59.15701604,96.39,273,16.5227
59.20953717,96.39,246,15.6844
59.2620583,96.39,276,16.6132
59.31457943,96.39,248,15.748
59.36710056,96.39,297,17.2337
59.4196217,96.39,266,16.3095
59.47214283,96.39,268,16.3707
59.52466396,96.39,295,17.1756
59.57718509,96.39,274,16.5529
59.62970622,96.39,298,17.2627
59.68222735,96.39,303,17.4069
59.73474848,96.39,314,17.72
59.78726961,96.39,319,17.8606
59.83979074,96.39,280,16.7332
59.89231187,96.39,290,17.0294
59.944833,96.39,295,17.1756
59.99735413,96.39,336,18.3303
60.04987526,96.39,321,17.9165
60.10239639,96.39,324,18
60.15491753,96.39,330,18.1659
60.20743866,96.39,392,19.799
60.25995979,96.39,381,19.5192
60.31248092,96.39,433,20.8087
60.36500205,96.39,405,20.1246
60.41752318,96.39,398,19.9499
60.47004431,96.39,419,20.4695
60.52256544,96.39,440,20.9762
60.57508657,96.39,402,20.0499
60.6276077,96.39,463,21.5174
60.68012883,96.39,454,21.3073
60.73264996,96.39,467,21.6102
60.78517109,96.39,468,21.6333
60.83769222,96.39,490,22.1359
60.89021336,96.39,431,20.7605
60.94273449,96.39,454,21.3073
60.99525562,96.39,479,21.8861
61.04777675,96.39,405,20.1246
61.10029788,96.39,439,20.9523
61.15281901,96.39,438,20.9284
61.20534014,96.39,434,20.8327
61.25786127,96.39,419,20.4695
61.3103824,96.39,380,19.4936
61.36290353,96.39,409,20.2237
61.41542466,96.39,384,19.5959
61.46794579,96.39,358,18.9209
61.52046692,96.39,390,19.7484
61.57298805,96.39,380,19.4936
61.62550919,96.39,381,19.5192
61.67803032,96.39,378,19.4422
61.73055145,96.39,407,20.1742
61.78307258,96.39,392,19.799
61.83559371,96.39,355,18.8414
61.88811484,96.39,360,18.9737
61.94063597,96.39,369,19.2094
61.9931571,96.39,375,19.3649
62.04567823,96.39,332,18.2209
62.09819936,96.39,351,18.735
62.15072049,96.39,338,18.3848
62.20324162,96.39,371,19.2614
62.25576275,96.39,321,17.9165
62.30828388,96.39,294,17.1464
62.36080502,96.39,329,18.1384
62.41332615,96.39,336,18.3303
62.46584728,96.39,262,16.1864
62.51836841,96.39,278,16.6733
62.57088954,96.39,302,17.3781
62.62341067,96.39,265,16.2788
62.6759318,96.39,293,17.1172
62.72845293,96.39,266,16.3095
62.78097406,96.39,253,15.906
62.83349519,96.39,248,15.748
62.88601632,96.39,262,16.1864
62.93853745,96.39,270,16.4317
62.99105858,96.39,233,15.2643
63.04357971,96.39,210,14.4914
63.09610084,96.39,245,15.6525
63.14862198,96.39,203,14.2478
63.20114311,96.39,227,15.0665
63.25366424,96.39,213,14.5945
63.30618537,96.39,210,14.4914
63.3587065,96.39,232,15.2315
63.41122763,96.39,207,14.3875
63.46374876,96.39,230,15.1658
63.51626989,96.39,231,15.1987
63.56879102,96.39,212,14.5602
63.62131215,96.39,230,15.1658
63.67383328,96.39,202,14.2127
63.72635441,96.39,232,15.2315
63.77887554,96.39,204,14.2829
63.83139667,96.39,220,14.8324
63.88391781,96.39,207,14.3875
63.93643894,96.39,218,14.7648
63.98896007,96.39,221,14.8661
64.0414812,96.39,228,15.0997
64.09400233,96.39,220,14.8324
64.14652346,96.39,198,14.0712
64.19904459,96.39,240,15.4919
64.25156572,96.39,240,15.4919
64.30408685,96.39,233,15.2643
64.35660798,96.39,221,14.8661
64.40912911,96.39,229,15.1327
64.46165024,96.39,194,13.9284
64.51417137,96.39,206,14.3527
64.5666925,96.39,199,14.1067
64.61921364,96.39,186,13.6382
64.67173477,96.39,190,13.784
64.7242559,96.39,209,14.4568
64.77677703,96.39,205,14.3178
64.82929816,96.39,181,13.4536
64.88181929,96.39,206,14.3527
64.93434042,96.39,220,14.8324
64.98686155,96.39,197,14.0357