File: Files_organized_for_plots/Spin_V_0_background/Spinner_Centroid08Dec21_Act13Feb23_B1_0714M_NaOH_LS0173_Num160.csv
[Measurement conditions],,,
Sample identification,Centroid08Dec21_Act13Feb23_B1_0714M_NaOH_LS0173_Num160,,
Comment - 1,"Configuration=Reflection-Transmission Spinner 3.0, Owner=nmw10, Creation date=9/26/2022 3:05:51 PM",,
Comment - 2,Goniometer=Theta/Theta; Minimum step size 2Theta:0.0001; Minimum step size Omega:0.0001,,
Comment - 3,Sample stage=Reflection-transmission spinner 3.0; Minimum step size Phi:0.1,,
Comment - 4,Diffractometer system=EMPYREAN,,
Comment - 5,"Measurement program=X:\XRD\Cement\Spinner_for_cement.xrdmp, Created identifier={6DF360EA-8E6E-4CFC-907C-F1BFECF51AA2}, Created by=Titus Reed, Id=tmr79, Creation date=2/15/2023 11:27:56 AM",,
Anode material,Cu,,
K-Alpha1 wavelength,1.540598,,
K-Alpha2 wavelength,1.544426,,
Ratio K-Alpha2/K-Alpha1,0.5,,
Divergence slit,Fixed,0.125,
Monochromator used,NO,,
Generator voltage,45,,
Tube current,40,,
File date and time,3/15/2023 21:59,,
Unit cell,,,
h k l, 0 0 0,,
Scan axis,Gonio,,
Scan range,4.994599997,64.99999183,
Scan step size,0.0262606,,
No. of points,2285,,
Scan type,CONTINUOUS,,
Phi,160.5,,
Time per step,96.39,,
Angle, TimePerStep, Intensity, ESD
5.00773028,96.39,1345,36.6742
5.060251411,96.39,1301,36.0694
5.112772541,96.39,1265,35.5668
5.165293672,96.39,1251,35.3695
5.217814803,96.39,1267,35.5949
5.270335934,96.39,1202,34.6699
5.322857064,96.39,1242,35.242
5.375378195,96.39,1189,34.4819
5.427899326,96.39,1141,33.7787
5.480420456,96.39,1183,34.3948
5.532941587,96.39,1156,34
5.585462718,96.39,1145,33.8378
5.637983849,96.39,1194,34.5543
5.690504979,96.39,1186,34.4384
5.74302611,96.39,1152,33.9411
5.795547241,96.39,1186,34.4384
5.848068371,96.39,1131,33.6303
5.900589502,96.39,1184,34.4093
5.953110633,96.39,1222,34.9571
6.005631763,96.39,1105,33.2415
6.058152894,96.39,1104,33.2265
6.110674025,96.39,1125,33.541
6.163195156,96.39,1116,33.4066
6.215716286,96.39,1107,33.2716
6.268237417,96.39,1096,33.1059
6.320758548,96.39,1152,33.9411
6.373279678,96.39,1107,33.2716
6.425800809,96.39,1111,33.3317
6.47832194,96.39,1073,32.7567
6.530843071,96.39,1017,31.8904
6.583364201,96.39,1096,33.1059
6.635885332,96.39,1067,32.665
6.688406463,96.39,1041,32.2645
6.740927593,96.39,1094,33.0757
6.793448724,96.39,1066,32.6497
6.845969855,96.39,1058,32.5269
6.898490986,96.39,1053,32.45
6.951012116,96.39,1071,32.7261
7.003533247,96.39,1057,32.5115
7.056054378,96.39,1032,32.1248
7.108575508,96.39,1087,32.9697
7.161096639,96.39,1070,32.7109
7.21361777,96.39,1047,32.3574
7.2661389,96.39,1036,32.187
7.318660031,96.39,1052,32.4345
7.371181162,96.39,1021,31.9531
7.423702293,96.39,1082,32.8938
7.476223423,96.39,1056,32.4962
7.528744554,96.39,989,31.4484
7.581265685,96.39,1037,32.2025
7.633786815,96.39,1035,32.1714
7.686307946,96.39,1073,32.7567
7.738829077,96.39,995,31.5436
7.791350208,96.39,1083,32.909
7.843871338,96.39,970,31.1448
7.896392469,96.39,1076,32.8024
7.9489136,96.39,1024,32
8.00143473,96.39,995,31.5436
8.053955861,96.39,999,31.607
8.106476992,96.39,989,31.4484
8.158998123,96.39,1074,32.7719
8.211519253,96.39,1000,31.6228
8.264040384,96.39,963,31.0322
8.316561515,96.39,1032,32.1248
8.369082645,96.39,1070,32.7109
8.421603776,96.39,1037,32.2025
8.474124907,96.39,1036,32.187
8.526646038,96.39,1001,31.6386
8.579167168,96.39,1057,32.5115
8.631688299,96.39,1038,32.218
8.68420943,96.39,1039,32.2335
8.73673056,96.39,1033,32.1403
8.789251691,96.39,997,31.5753
8.841772822,96.39,1016,31.8748
8.894293952,96.39,1045,32.3265
8.946815083,96.39,947,30.7734
8.999336214,96.39,997,31.5753
9.051857345,96.39,1026,32.0312
9.104378475,96.39,1020,31.9374
9.156899606,96.39,1046,32.3419
9.209420737,96.39,1000,31.6228
9.261941867,96.39,969,31.1288
9.314462998,96.39,940,30.6594
9.366984129,96.39,990,31.4643
9.41950526,96.39,1016,31.8748
9.47202639,96.39,980,31.305
9.524547521,96.39,1042,32.28
9.577068652,96.39,1019,31.9218
9.629589782,96.39,1017,31.8904
9.682110913,96.39,957,30.9354
9.734632044,96.39,989,31.4484
9.787153175,96.39,998,31.5911
9.839674305,96.39,976,31.241
9.892195436,96.39,1001,31.6386
9.944716567,96.39,980,31.305
9.997237697,96.39,965,31.0644
10.04975883,96.39,990,31.4643
10.10227996,96.39,936,30.5941
10.15480109,96.39,968,31.1127
10.20732222,96.39,1013,31.8277
10.25984335,96.39,1014,31.8434
10.31236448,96.39,1061,32.573
10.36488561,96.39,982,31.3369
10.41740674,96.39,1013,31.8277
10.46992787,96.39,977,31.257
10.522449,96.39,1045,32.3265
10.57497014,96.39,986,31.4006
10.62749127,96.39,958,30.9516
10.6800124,96.39,974,31.209
10.73253353,96.39,930,30.4959
10.78505466,96.39,1012,31.8119
10.83757579,96.39,982,31.3369
10.89009692,96.39,947,30.7734
10.94261805,96.39,978,31.273
10.99513918,96.39,1027,32.0468
11.04766031,96.39,1018,31.9061
11.10018144,96.39,949,30.8058
11.15270257,96.39,963,31.0322
11.2052237,96.39,910,30.1662
11.25774483,96.39,970,31.1448
11.31026597,96.39,980,31.305
11.3627871,96.39,889,29.8161
11.41530823,96.39,928,30.4631
11.46782936,96.39,922,30.3645
11.52035049,96.39,870,29.4958
11.57287162,96.39,867,29.4449
11.62539275,96.39,884,29.7321
11.67791388,96.39,952,30.8545
11.73043501,96.39,884,29.7321
11.78295614,96.39,916,30.2655
11.83547727,96.39,877,29.6142
11.8879984,96.39,924,30.3974
11.94051953,96.39,854,29.2233
11.99304066,96.39,927,30.4467
12.0455618,96.39,878,29.6311
12.09808293,96.39,898,29.9666
12.15060406,96.39,858,29.2916
12.20312519,96.39,850,29.1548
12.25564632,96.39,830,28.8097
12.30816745,96.39,853,29.2062
12.36068858,96.39,806,28.3901
12.41320971,96.39,826,28.7402
12.46573084,96.39,926,30.4302
12.51825197,96.39,883,29.7153
12.5707731,96.39,805,28.3725
12.62329423,96.39,821,28.6531
12.67581536,96.39,822,28.6705
12.72833649,96.39,773,27.8029
12.78085763,96.39,791,28.1247
12.83337876,96.39,792,28.1425
12.88589989,96.39,861,29.3428
12.93842102,96.39,774,27.8209
12.99094215,96.39,764,27.6405
13.04346328,96.39,779,27.9106
13.09598441,96.39,776,27.8568
13.14850554,96.39,781,27.9464
13.20102667,96.39,794,28.178
13.2535478,96.39,783,27.9821
13.30606893,96.39,804,28.3549
13.35859006,96.39,720,26.8328
13.41111119,96.39,790,28.1069
13.46363232,96.39,847,29.1033
13.51615346,96.39,893,29.8831
13.56867459,96.39,753,27.4408
13.62119572,96.39,765,27.6586
13.67371685,96.39,795,28.1957
13.72623798,96.39,799,28.2666
13.77875911,96.39,865,29.4109
13.83128024,96.39,882,29.6985
13.88380137,96.39,804,28.3549
13.9363225,96.39,802,28.3196
13.98884363,96.39,736,27.1293
14.04136476,96.39,783,27.9821
14.09388589,96.39,731,27.037
14.14640702,96.39,796,28.2135
14.19892815,96.39,846,29.0861
14.25144929,96.39,1000,31.6228
14.30397042,96.39,908,30.133
14.35649155,96.39,749,27.3679
14.40901268,96.39,756,27.4955
14.46153381,96.39,680,26.0768
14.51405494,96.39,717,26.7769
14.56657607,96.39,712,26.6833
14.6190972,96.39,716,26.7582
14.67161833,96.39,714,26.7208
14.72413946,96.39,687,26.2107
14.77666059,96.39,703,26.5141
14.82918172,96.39,706,26.5707
14.88170285,96.39,657,25.632
14.93422398,96.39,674,25.9615
14.98674512,96.39,694,26.3439
15.03926625,96.39,675,25.9808
15.09178738,96.39,760,27.5681
15.14430851,96.39,764,27.6405
15.19682964,96.39,795,28.1957
15.24935077,96.39,830,28.8097
15.3018719,96.39,835,28.8964
15.35439303,96.39,685,26.1725
15.40691416,96.39,716,26.7582
15.45943529,96.39,629,25.0799
15.51195642,96.39,654,25.5734
15.56447755,96.39,690,26.2679
15.61699868,96.39,645,25.3969
15.66951981,96.39,671,25.9037
15.72204095,96.39,642,25.3377
15.77456208,96.39,616,24.8193
15.82708321,96.39,640,25.2982
15.87960434,96.39,607,24.6374
15.93212547,96.39,625,25
15.9846466,96.39,682,26.1151
16.03716773,96.39,660,25.6905
16.08968886,96.39,613,24.7588
16.14220999,96.39,641,25.318
16.19473112,96.39,637,25.2389
16.24725225,96.39,643,25.3574
16.29977338,96.39,646,25.4165
16.35229451,96.39,676,26
16.40481564,96.39,648,25.4558
16.45733678,96.39,666,25.807
16.50985791,96.39,694,26.3439
16.56237904,96.39,664,25.7682
16.61490017,96.39,615,24.7992
16.6674213,96.39,648,25.4558
16.71994243,96.39,636,25.219
16.77246356,96.39,630,25.0998
16.82498469,96.39,644,25.3772
16.87750582,96.39,655,25.593
16.93002695,96.39,743,27.258
16.98254808,96.39,640,25.2982
17.03506921,96.39,658,25.6515
17.08759034,96.39,599,24.4745
17.14011147,96.39,582,24.1247
17.19263261,96.39,637,25.2389
17.24515374,96.39,647,25.4362
17.29767487,96.39,670,25.8844
17.350196,96.39,694,26.3439
17.40271713,96.39,701,26.4764
17.45523826,96.39,662,25.7294
17.50775939,96.39,574,23.9583
17.56028052,96.39,616,24.8193
17.61280165,96.39,601,24.5153
17.66532278,96.39,630,25.0998
17.71784391,96.39,626,25.02
17.77036504,96.39,651,25.5147
17.82288617,96.39,647,25.4362
17.8754073,96.39,602,24.5357
17.92792843,96.39,636,25.219
17.98044957,96.39,628,25.0599
18.0329707,96.39,635,25.1992
18.08549183,96.39,662,25.7294
18.13801296,96.39,659,25.671
18.19053409,96.39,692,26.3059
18.24305522,96.39,668,25.8457
18.29557635,96.39,794,28.178
18.34809748,96.39,765,27.6586
18.40061861,96.39,729,27
18.45313974,96.39,688,26.2298
18.50566087,96.39,678,26.0384
18.558182,96.39,693,26.3249
18.61070313,96.39,659,25.671
18.66322426,96.39,655,25.593
18.7157454,96.39,650,25.4951
18.76826653,96.39,689,26.2488
18.82078766,96.39,688,26.2298
18.87330879,96.39,669,25.865
18.92582992,96.39,690,26.2679
18.97835105,96.39,674,25.9615
19.03087218,96.39,695,26.3629
19.08339331,96.39,725,26.9258
19.13591444,96.39,676,26
19.18843557,96.39,681,26.096
19.2409567,96.39,640,25.2982
19.29347783,96.39,658,25.6515
19.34599896,96.39,727,26.9629
19.39852009,96.39,828,28.775
19.45104123,96.39,816,28.5657
19.50356236,96.39,800,28.2843
19.55608349,96.39,700,26.4575
19.60860462,96.39,698,26.4197
19.66112575,96.39,784,28
19.71364688,96.39,820,28.6356
19.76616801,96.39,934,30.5614
19.81868914,96.39,926,30.4302
19.87121027,96.39,895,29.9166
19.9237314,96.39,1029,32.078
19.97625253,96.39,1141,33.7787
20.02877366,96.39,934,30.5614
20.08129479,96.39,769,27.7308
20.13381592,96.39,786,28.0357
20.18633706,96.39,771,27.7669
20.23885819,96.39,771,27.7669
20.29137932,96.39,798,28.2489
20.34390045,96.39,910,30.1662
20.39642158,96.39,1006,31.7175
20.44894271,96.39,1021,31.9531
20.50146384,96.39,951,30.8383
20.55398497,96.39,1047,32.3574
20.6065061,96.39,1193,34.5398
20.65902723,96.39,1597,39.9625
20.71154836,96.39,1827,42.7434
20.76406949,96.39,1367,36.973
20.81659062,96.39,891,29.8496
20.86911175,96.39,794,28.178
20.92163289,96.39,769,27.7308
20.97415402,96.39,816,28.5657
21.02667515,96.39,714,26.7208
21.07919628,96.39,746,27.313
21.13171741,96.39,755,27.4773
21.18423854,96.39,770,27.7489
21.23675967,96.39,759,27.55
21.2892808,96.39,767,27.6948
21.34180193,96.39,690,26.2679
21.39432306,96.39,670,25.8844
21.44684419,96.39,665,25.7876
21.49936532,96.39,731,27.037
21.55188645,96.39,710,26.6458
21.60440758,96.39,757,27.5136
21.65692872,96.39,758,27.5318
21.70944985,96.39,761,27.5862
21.76197098,96.39,759,27.55
21.81449211,96.39,809,28.4429
21.86701324,96.39,734,27.0924
21.91953437,96.39,740,27.2029
21.9720555,96.39,706,26.5707
22.02457663,96.39,761,27.5862
22.07709776,96.39,789,28.0891
22.12961889,96.39,763,27.6225
22.18214002,96.39,769,27.7308
22.23466115,96.39,697,26.4008
22.28718228,96.39,683,26.1343
22.33970341,96.39,684,26.1534
22.39222455,96.39,730,27.0185
22.44474568,96.39,751,27.4044
22.49726681,96.39,735,27.1109
22.54978794,96.39,744,27.2764
22.60230907,96.39,803,28.3373
22.6548302,96.39,760,27.5681
22.70735133,96.39,672,25.923
22.75987246,96.39,720,26.8328
22.81239359,96.39,784,28
22.86491472,96.39,762,27.6043
22.91743585,96.39,764,27.6405
22.96995698,96.39,740,27.2029
23.02247811,96.39,734,27.0924
23.07499924,96.39,773,27.8029
23.12752038,96.39,738,27.1662
23.18004151,96.39,798,28.2489
23.23256264,96.39,766,27.6767
23.28508377,96.39,733,27.074
23.3376049,96.39,738,27.1662
23.39012603,96.39,753,27.4408
23.44264716,96.39,752,27.4226
23.49516829,96.39,812,28.4956
23.54768942,96.39,839,28.9655
23.60021055,96.39,748,27.3496
23.65273168,96.39,712,26.6833
23.70525281,96.39,751,27.4044
23.75777394,96.39,749,27.3679
23.81029507,96.39,739,27.1846
23.86281621,96.39,726,26.9444
23.91533734,96.39,725,26.9258
23.96785847,96.39,724,26.9072
24.0203796,96.39,757,27.5136
24.07290073,96.39,810,28.4605
24.12542186,96.39,773,27.8029
24.17794299,96.39,870,29.4958
24.23046412,96.39,866,29.4279
24.28298525,96.39,752,27.4226
24.33550638,96.39,771,27.7669
24.38802751,96.39,699,26.4386
24.44054864,96.39,663,25.7488
24.49306977,96.39,629,25.0799
24.5455909,96.39,748,27.3496
24.59811204,96.39,743,27.258
24.65063317,96.39,654,25.5734
24.7031543,96.39,643,25.3574
24.75567543,96.39,617,24.8395
24.80819656,96.39,630,25.0998
24.86071769,96.39,643,25.3574
24.91323882,96.39,707,26.5895
24.96575995,96.39,626,25.02
25.01828108,96.39,627,25.04
25.07080221,96.39,631,25.1197
25.12332334,96.39,592,24.3311
25.17584447,96.39,599,24.4745
25.2283656,96.39,571,23.8956
25.28088673,96.39,643,25.3574
25.33340786,96.39,741,27.2213
25.385929,96.39,774,27.8209
25.43845013,96.39,892,29.8664
25.49097126,96.39,733,27.074
25.54349239,96.39,621,24.9199
25.59601352,96.39,615,24.7992
25.64853465,96.39,571,23.8956
25.70105578,96.39,610,24.6982
25.75357691,96.39,601,24.5153
25.80609804,96.39,582,24.1247
25.85861917,96.39,658,25.6515
25.9111403,96.39,577,24.0208
25.96366143,96.39,598,24.454
26.01618256,96.39,597,24.4336
26.06870369,96.39,565,23.7697
26.12122483,96.39,546,23.3666
26.17374596,96.39,499,22.3383
26.22626709,96.39,564,23.7487
26.27878822,96.39,548,23.4094
26.33130935,96.39,547,23.388
26.38383048,96.39,539,23.2164
26.43635161,96.39,580,24.0832
26.48887274,96.39,513,22.6495
26.54139387,96.39,566,23.7908
26.593915,96.39,526,22.9347
26.64643613,96.39,546,23.3666
26.69895726,96.39,573,23.9374
26.75147839,96.39,595,24.3926
26.80399952,96.39,532,23.0651
26.85652066,96.39,518,22.7596
26.90904179,96.39,523,22.8692
26.96156292,96.39,553,23.516
27.01408405,96.39,587,24.2281
27.06660518,96.39,585,24.1868
27.11912631,96.39,712,26.6833
27.17164744,96.39,794,28.178
27.22416857,96.39,732,27.0555
27.2766897,96.39,624,24.98
27.32921083,96.39,653,25.5539
27.38173196,96.39,573,23.9374
27.43425309,96.39,540,23.2379
27.48677422,96.39,532,23.0651
27.53929535,96.39,547,23.388
27.59181649,96.39,575,23.9792
27.64433762,96.39,520,22.8035
27.69685875,96.39,551,23.4734
27.74937988,96.39,497,22.2935
27.80190101,96.39,532,23.0651
27.85442214,96.39,531,23.0434
27.90694327,96.39,530,23.0217
27.9594644,96.39,515,22.6936
28.01198553,96.39,582,24.1247
28.06450666,96.39,567,23.8118
28.11702779,96.39,558,23.622
28.16954892,96.39,573,23.9374
28.22207005,96.39,570,23.8747
28.27459118,96.39,582,24.1247
28.32711232,96.39,591,24.3105
28.37963345,96.39,572,23.9165
28.43215458,96.39,567,23.8118
28.48467571,96.39,560,23.6643
28.53719684,96.39,528,22.9783
28.58971797,96.39,544,23.3238
28.6422391,96.39,555,23.5584
28.69476023,96.39,575,23.9792
28.74728136,96.39,621,24.9199
28.79980249,96.39,563,23.7276
28.85232362,96.39,564,23.7487
28.90484475,96.39,547,23.388
28.95736588,96.39,511,22.6053
29.00988701,96.39,554,23.5372
29.06240815,96.39,600,24.4949
29.11492928,96.39,644,25.3772
29.16745041,96.39,564,23.7487
29.21997154,96.39,566,23.7908
29.27249267,96.39,505,22.4722
29.3250138,96.39,576,24
29.37753493,96.39,528,22.9783
29.43005606,96.39,557,23.6008
29.48257719,96.39,545,23.3452
29.53509832,96.39,538,23.1948
29.58761945,96.39,530,23.0217
29.64014058,96.39,550,23.4521
29.69266171,96.39,506,22.4944
29.74518284,96.39,526,22.9347
29.79770398,96.39,541,23.2594
29.85022511,96.39,525,22.9129
29.90274624,96.39,543,23.3024
29.95526737,96.39,538,23.1948
30.0077885,96.39,562,23.7065
30.06030963,96.39,517,22.7376
30.11283076,96.39,543,23.3024
30.16535189,96.39,550,23.4521
30.21787302,96.39,521,22.8254
30.27039415,96.39,557,23.6008
30.32291528,96.39,567,23.8118
30.37543641,96.39,523,22.8692
30.42795754,96.39,518,22.7596
30.48047867,96.39,625,25
30.53299981,96.39,603,24.5561
30.58552094,96.39,612,24.7386
30.63804207,96.39,652,25.5343
30.6905632,96.39,765,27.6586
30.74308433,96.39,808,28.4253
30.79560546,96.39,750,27.3861
30.84812659,96.39,637,25.2389
30.90064772,96.39,628,25.0599
30.95316885,96.39,553,23.516
31.00568998,96.39,551,23.4734
31.05821111,96.39,565,23.7697
31.11073224,96.39,592,24.3311
31.16325337,96.39,689,26.2488
31.2157745,96.39,776,27.8568
31.26829564,96.39,763,27.6225
31.32081677,96.39,667,25.8263
31.3733379,96.39,610,24.6982
31.42585903,96.39,616,24.8193
31.47838016,96.39,677,26.0192
31.53090129,96.39,702,26.4953
31.58342242,96.39,713,26.7021
31.63594355,96.39,630,25.0998
31.68846468,96.39,759,27.55
31.74098581,96.39,717,26.7769
31.79350694,96.39,670,25.8844
31.84602807,96.39,622,24.9399
31.8985492,96.39,644,25.3772
31.95107033,96.39,798,28.2489
32.00359147,96.39,1150,33.9116
32.0561126,96.39,1382,37.1753
32.10863373,96.39,1150,33.9116
32.16115486,96.39,894,29.8998
32.21367599,96.39,615,24.7992
32.26619712,96.39,561,23.6854
32.31871825,96.39,545,23.3452
32.37123938,96.39,583,24.1454
32.42376051,96.39,562,23.7065
32.47628164,96.39,495,22.2486
32.52880277,96.39,512,22.6274
32.5813239,96.39,546,23.3666
32.63384503,96.39,579,24.0624
32.68636616,96.39,634,25.1794
32.7388873,96.39,533,23.0868
32.79140843,96.39,495,22.2486
32.84392956,96.39,525,22.9129
32.89645069,96.39,563,23.7276
32.94897182,96.39,594,24.3721
33.00149295,96.39,615,24.7992
33.05401408,96.39,655,25.593
33.10653521,96.39,648,25.4558
33.15905634,96.39,646,25.4165
33.21157747,96.39,667,25.8263
33.2640986,96.39,669,25.865
33.31661973,96.39,602,24.5357
33.36914086,96.39,734,27.0924
33.42166199,96.39,809,28.4429
33.47418312,96.39,779,27.9106
33.52670426,96.39,692,26.3059
33.57922539,96.39,647,25.4362
33.63174652,96.39,571,23.8956
33.68426765,96.39,593,24.3516
33.73678878,96.39,609,24.6779
33.78930991,96.39,590,24.2899
33.84183104,96.39,681,26.096
33.89435217,96.39,894,29.8998
33.9468733,96.39,989,31.4484
33.99939443,96.39,875,29.5804
34.05191556,96.39,875,29.5804
34.10443669,96.39,724,26.9072
34.15695782,96.39,713,26.7021
34.20947895,96.39,739,27.1846
34.26200009,96.39,741,27.2213
34.31452122,96.39,722,26.8701
34.36704235,96.39,784,28
34.41956348,96.39,756,27.4955
34.47208461,96.39,780,27.9285
34.52460574,96.39,795,28.1957
34.57712687,96.39,746,27.313
34.629648,96.39,755,27.4773
34.68216913,96.39,760,27.5681
34.73469026,96.39,768,27.7128
34.78721139,96.39,788,28.0713
34.83973252,96.39,833,28.8617
34.89225365,96.39,982,31.3369
34.94477478,96.39,1032,32.1248
34.99729592,96.39,942,30.692
35.04981705,96.39,891,29.8496
35.10233818,96.39,748,27.3496
35.15485931,96.39,716,26.7582
35.20738044,96.39,726,26.9444
35.25990157,96.39,718,26.7955
35.3124227,96.39,641,25.318
35.36494383,96.39,632,25.1396
35.41746496,96.39,572,23.9165
35.46998609,96.39,581,24.1039
35.52250722,96.39,569,23.8537
35.57502835,96.39,602,24.5357
35.62754948,96.39,662,25.7294
35.68007061,96.39,607,24.6374
35.73259175,96.39,630,25.0998
35.78511288,96.39,617,24.8395
35.83763401,96.39,572,23.9165
35.89015514,96.39,592,24.3311
35.94267627,96.39,596,24.4131
35.9951974,96.39,581,24.1039
36.04771853,96.39,620,24.8998
36.10023966,96.39,540,23.2379
36.15276079,96.39,513,22.6495
36.20528192,96.39,516,22.7156
36.25780305,96.39,531,23.0434
36.31032418,96.39,547,23.388
36.36284531,96.39,592,24.3311
36.41536644,96.39,543,23.3024
36.46788758,96.39,540,23.2379
36.52040871,96.39,558,23.622
36.57292984,96.39,529,23
36.62545097,96.39,527,22.9565
36.6779721,96.39,484,22
36.73049323,96.39,503,22.4277
36.78301436,96.39,497,22.2935
36.83553549,96.39,430,20.7364
36.88805662,96.39,513,22.6495
36.94057775,96.39,479,21.8861
36.99309888,96.39,472,21.7256
37.04562001,96.39,486,22.0454
37.09814114,96.39,465,21.5639
37.15066227,96.39,479,21.8861
37.20318341,96.39,481,21.9317
37.25570454,96.39,514,22.6716
37.30822567,96.39,477,21.8403
37.3607468,96.39,453,21.2838
37.41326793,96.39,458,21.4009
37.46578906,96.39,456,21.3542
37.51831019,96.39,465,21.5639
37.57083132,96.39,454,21.3073
37.62335245,96.39,506,22.4944
37.67587358,96.39,544,23.3238
37.72839471,96.39,617,24.8395
37.78091584,96.39,570,23.8747
37.83343697,96.39,557,23.6008
37.8859581,96.39,566,23.7908
37.93847924,96.39,483,21.9773
37.99100037,96.39,521,22.8254
38.0435215,96.39,474,21.7715
38.09604263,96.39,478,21.8632
38.14856376,96.39,528,22.9783
38.20108489,96.39,536,23.1517
38.25360602,96.39,546,23.3666
38.30612715,96.39,518,22.7596
38.35864828,96.39,473,21.7486
38.41116941,96.39,565,23.7697
38.46369054,96.39,475,21.7945
38.51621167,96.39,474,21.7715
38.5687328,96.39,459,21.4243
38.62125393,96.39,468,21.6333
38.67377507,96.39,482,21.9545
38.7262962,96.39,510,22.5832
38.77881733,96.39,498,22.3159
38.83133846,96.39,478,21.8632
38.88385959,96.39,437,20.9045
38.93638072,96.39,493,22.2036
38.98890185,96.39,419,20.4695
39.04142298,96.39,445,21.095
39.09394411,96.39,444,21.0713
39.14646524,96.39,452,21.2603
39.19898637,96.39,484,22
39.2515075,96.39,504,22.4499
39.30402863,96.39,472,21.7256
39.35654976,96.39,465,21.5639
39.4090709,96.39,614,24.779
39.46159203,96.39,564,23.7487
39.51411316,96.39,475,21.7945
39.56663429,96.39,426,20.6398
39.61915542,96.39,477,21.8403
39.67167655,96.39,444,21.0713
39.72419768,96.39,426,20.6398
39.77671881,96.39,436,20.8806
39.82923994,96.39,450,21.2132
39.88176107,96.39,431,20.7605
39.9342822,96.39,415,20.3715
39.98680333,96.39,429,20.7123
40.03932446,96.39,436,20.8806
40.09184559,96.39,469,21.6564
40.14436673,96.39,439,20.9523
40.19688786,96.39,447,21.1424
40.24940899,96.39,450,21.2132
40.30193012,96.39,394,19.8494
40.35445125,96.39,400,20
40.40697238,96.39,389,19.7231
40.45949351,96.39,391,19.7737
40.51201464,96.39,407,20.1742
40.56453577,96.39,433,20.8087
40.6170569,96.39,482,21.9545
40.66957803,96.39,423,20.567
40.72209916,96.39,390,19.7484
40.77462029,96.39,377,19.4165
40.82714142,96.39,376,19.3907
40.87966255,96.39,338,18.3848
40.93218369,96.39,369,19.2094
40.98470482,96.39,379,19.4679
41.03722595,96.39,387,19.6723
41.08974708,96.39,349,18.6815
41.14226821,96.39,410,20.2485
41.19478934,96.39,369,19.2094
41.24731047,96.39,392,19.799
41.2998316,96.39,426,20.6398
41.35235273,96.39,542,23.2809
41.40487386,96.39,499,22.3383
41.45739499,96.39,424,20.5913
41.50991612,96.39,400,20
41.56243725,96.39,374,19.3391
41.61495838,96.39,350,18.7083
41.66747952,96.39,376,19.3907
41.72000065,96.39,331,18.1934
41.77252178,96.39,367,19.1572
41.82504291,96.39,348,18.6548
41.87756404,96.39,348,18.6548
41.93008517,96.39,332,18.2209
41.9826063,96.39,358,18.9209
42.03512743,96.39,369,19.2094
42.08764856,96.39,392,19.799
42.14016969,96.39,423,20.567
42.19269082,96.39,441,21
42.24521195,96.39,408,20.199
42.29773308,96.39,389,19.7231
42.35025421,96.39,414,20.347
42.40277535,96.39,357,18.8944
42.45529648,96.39,319,17.8606
42.50781761,96.39,371,19.2614
42.56033874,96.39,380,19.4936
42.61285987,96.39,377,19.4165
42.665381,96.39,389,19.7231
42.71790213,96.39,358,18.9209
42.77042326,96.39,341,18.4662
42.82294439,96.39,342,18.4932
42.87546552,96.39,364,19.0788
42.92798665,96.39,394,19.8494
42.98050778,96.39,350,18.7083
43.03302891,96.39,354,18.8149
43.08555004,96.39,357,18.8944
43.13807118,96.39,334,18.2757
43.19059231,96.39,351,18.735
43.24311344,96.39,360,18.9737
43.29563457,96.39,320,17.8885
43.3481557,96.39,361,19
43.40067683,96.39,326,18.0555
43.45319796,96.39,339,18.412
43.50571909,96.39,338,18.3848
43.55824022,96.39,332,18.2209
43.61076135,96.39,376,19.3907
43.66328248,96.39,395,19.8746
43.71580361,96.39,458,21.4009
43.76832474,96.39,450,21.2132
43.82084587,96.39,425,20.6155
43.87336701,96.39,404,20.0998
43.92588814,96.39,367,19.1572
43.97840927,96.39,341,18.4662
44.0309304,96.39,410,20.2485
44.08345153,96.39,337,18.3576
44.13597266,96.39,337,18.3576
44.18849379,96.39,320,17.8885
44.24101492,96.39,405,20.1246
44.29353605,96.39,409,20.2237
44.34605718,96.39,399,19.975
44.39857831,96.39,393,19.8242
44.45109944,96.39,387,19.6723
44.50362057,96.39,404,20.0998
44.5561417,96.39,344,18.5472
44.60866284,96.39,351,18.735
44.66118397,96.39,378,19.4422
44.7137051,96.39,370,19.2354
44.76622623,96.39,358,18.9209
44.81874736,96.39,379,19.4679
44.87126849,96.39,415,20.3715
44.92378962,96.39,359,18.9473
44.97631075,96.39,414,20.347
45.02883188,96.39,384,19.5959
45.08135301,96.39,473,21.7486
45.13387414,96.39,420,20.4939
45.18639527,96.39,454,21.3073
45.2389164,96.39,443,21.0476
45.29143753,96.39,418,20.445
45.34395867,96.39,430,20.7364
45.3964798,96.39,446,21.1187
45.44900093,96.39,483,21.9773
45.50152206,96.39,438,20.9284
45.55404319,96.39,371,19.2614
45.60656432,96.39,430,20.7364
45.65908545,96.39,410,20.2485
45.71160658,96.39,406,20.1494
45.76412771,96.39,384,19.5959
45.81664884,96.39,373,19.3132
45.86916997,96.39,401,20.025
45.9216911,96.39,354,18.8149
45.97421223,96.39,379,19.4679
46.02673336,96.39,400,20
46.0792545,96.39,395,19.8746
46.13177563,96.39,424,20.5913
46.18429676,96.39,520,22.8035
46.23681789,96.39,473,21.7486
46.28933902,96.39,482,21.9545
46.34186015,96.39,422,20.5426
46.39438128,96.39,450,21.2132
46.44690241,96.39,437,20.9045
46.49942354,96.39,423,20.567
46.55194467,96.39,393,19.8242
46.6044658,96.39,377,19.4165
46.65698693,96.39,417,20.4206
46.70950806,96.39,439,20.9523
46.76202919,96.39,413,20.3224
46.81455033,96.39,421,20.5183
46.86707146,96.39,404,20.0998
46.91959259,96.39,408,20.199
46.97211372,96.39,461,21.4709
47.02463485,96.39,413,20.3224
47.07715598,96.39,397,19.9249
47.12967711,96.39,374,19.3391
47.18219824,96.39,393,19.8242
47.23471937,96.39,344,18.5472
47.2872405,96.39,325,18.0278
47.33976163,96.39,381,19.5192
47.39228276,96.39,322,17.9444
47.44480389,96.39,353,18.7883
47.49732502,96.39,373,19.3132
47.54984616,96.39,349,18.6815
47.60236729,96.39,328,18.1108
47.65488842,96.39,347,18.6279
47.70740955,96.39,306,17.4929
47.75993068,96.39,357,18.8944
47.81245181,96.39,361,19
47.86497294,96.39,342,18.4932
47.91749407,96.39,338,18.3848
47.9700152,96.39,341,18.4662
48.02253633,96.39,380,19.4936
48.07505746,96.39,412,20.2978
48.12757859,96.39,387,19.6723
48.18009972,96.39,369,19.2094
48.23262085,96.39,374,19.3391
48.28514198,96.39,370,19.2354
48.33766312,96.39,336,18.3303
48.39018425,96.39,352,18.7617
48.44270538,96.39,406,20.1494
48.49522651,96.39,417,20.4206
48.54774764,96.39,351,18.735
48.60026877,96.39,337,18.3576
48.6527899,96.39,347,18.6279
48.70531103,96.39,347,18.6279
48.75783216,96.39,340,18.4391
48.81035329,96.39,313,17.6918
48.86287442,96.39,327,18.0831
48.91539555,96.39,337,18.3576
48.96791668,96.39,329,18.1384
49.02043781,96.39,366,19.1311
49.07295895,96.39,348,18.6548
49.12548008,96.39,310,17.6068
49.17800121,96.39,347,18.6279
49.23052234,96.39,307,17.5214
49.28304347,96.39,333,18.2483
49.3355646,96.39,335,18.303
49.38808573,96.39,349,18.6815
49.44060686,96.39,363,19.0526
49.49312799,96.39,314,17.72
49.54564912,96.39,338,18.3848
49.59817025,96.39,297,17.2337
49.65069138,96.39,393,19.8242
49.70321251,96.39,317,17.8045
49.75573364,96.39,348,18.6548
49.80825478,96.39,355,18.8414
49.86077591,96.39,333,18.2483
49.91329704,96.39,303,17.4069
49.96581817,96.39,306,17.4929
50.0183393,96.39,271,16.4621
50.07086043,96.39,295,17.1756
50.12338156,96.39,300,17.3205
50.17590269,96.39,310,17.6068
50.22842382,96.39,355,18.8414
50.28094495,96.39,361,19
50.33346608,96.39,348,18.6548
50.38598721,96.39,330,18.1659
50.43850834,96.39,277,16.6433
50.49102947,96.39,288,16.9706
50.54355061,96.39,272,16.4924
50.59607174,96.39,271,16.4621
50.64859287,96.39,285,16.8819
50.701114,96.39,300,17.3205
50.75363513,96.39,296,17.2047
50.80615626,96.39,314,17.72
50.85867739,96.39,306,17.4929
50.91119852,96.39,272,16.4924
50.96371965,96.39,315,17.7482
51.01624078,96.39,299,17.2916
51.06876191,96.39,305,17.4642
51.12128304,96.39,307,17.5214
51.17380417,96.39,317,17.8045
51.2263253,96.39,324,18
51.27884644,96.39,306,17.4929
51.33136757,96.39,301,17.3494
51.3838887,96.39,288,16.9706
51.43640983,96.39,283,16.8226
51.48893096,96.39,252,15.8745
51.54145209,96.39,259,16.0935
51.59397322,96.39,300,17.3205
51.64649435,96.39,320,17.8885
51.69901548,96.39,281,16.7631
51.75153661,96.39,288,16.9706
51.80405774,96.39,310,17.6068
51.85657887,96.39,275,16.5831
51.9091,96.39,322,17.9444
51.96162113,96.39,301,17.3494
52.01414227,96.39,280,16.7332
52.0666634,96.39,295,17.1756
52.11918453,96.39,306,17.4929
52.17170566,96.39,312,17.6635
52.22422679,96.39,335,18.303
52.27674792,96.39,340,18.4391
52.32926905,96.39,322,17.9444
52.38179018,96.39,319,17.8606
52.43431131,96.39,346,18.6011
52.48683244,96.39,282,16.7929
52.53935357,96.39,294,17.1464
52.5918747,96.39,278,16.6733
52.64439583,96.39,282,16.7929
52.69691696,96.39,342,18.4932
52.7494381,96.39,326,18.0555
52.80195923,96.39,263,16.2173
52.85448036,96.39,282,16.7929
52.90700149,96.39,285,16.8819
52.95952262,96.39,271,16.4621
53.01204375,96.39,288,16.9706
53.06456488,96.39,284,16.8523
53.11708601,96.39,315,17.7482
53.16960714,96.39,340,18.4391
53.22212827,96.39,313,17.6918
53.2746494,96.39,282,16.7929
53.32717053,96.39,299,17.2916
53.37969166,96.39,337,18.3576
53.43221279,96.39,284,16.8523
53.48473393,96.39,251,15.843
53.53725506,96.39,306,17.4929
53.58977619,96.39,283,16.8226
53.64229732,96.39,250,15.8114
53.69481845,96.39,239,15.4596
53.74733958,96.39,249,15.7797
53.79986071,96.39,251,15.843
53.85238184,96.39,251,15.843
53.90490297,96.39,266,16.3095
53.9574241,96.39,287,16.9411
54.00994523,96.39,253,15.906
54.06246636,96.39,289,17
54.11498749,96.39,350,18.7083
54.16750862,96.39,304,17.4356
54.22002976,96.39,282,16.7929
54.27255089,96.39,298,17.2627
54.32507202,96.39,296,17.2047
54.37759315,96.39,286,16.9115
54.43011428,96.39,290,17.0294
54.48263541,96.39,260,16.1245
54.53515654,96.39,273,16.5227
54.58767767,96.39,278,16.6733
54.6401988,96.39,262,16.1864
54.69271993,96.39,260,16.1245
54.74524106,96.39,251,15.843
54.79776219,96.39,254,15.9374
54.85028332,96.39,264,16.2481
54.90280445,96.39,269,16.4012
54.95532559,96.39,231,15.1987
55.00784672,96.39,273,16.5227
55.06036785,96.39,263,16.2173
55.11288898,96.39,263,16.2173
55.16541011,96.39,242,15.5563
55.21793124,96.39,255,15.9687
55.27045237,96.39,242,15.5563
55.3229735,96.39,227,15.0665
55.37549463,96.39,226,15.0333
55.42801576,96.39,232,15.2315
55.48053689,96.39,239,15.4596
55.53305802,96.39,304,17.4356
55.58557915,96.39,244,15.6205
55.63810028,96.39,264,16.2481
55.69062141,96.39,264,16.2481
55.74314255,96.39,248,15.748
55.79566368,96.39,255,15.9687
55.84818481,96.39,249,15.7797
55.90070594,96.39,231,15.1987
55.95322707,96.39,229,15.1327
56.0057482,96.39,241,15.5242
56.05826933,96.39,234,15.2971
56.11079046,96.39,237,15.3948
56.16331159,96.39,249,15.7797
56.21583272,96.39,234,15.2971
56.26835385,96.39,244,15.6205
56.32087498,96.39,253,15.906
56.37339611,96.39,249,15.7797
56.42591724,96.39,242,15.5563
56.47843838,96.39,237,15.3948
56.53095951,96.39,241,15.5242
56.58348064,96.39,236,15.3623
56.63600177,96.39,243,15.5885
56.6885229,96.39,234,15.2971
56.74104403,96.39,230,15.1658
56.79356516,96.39,231,15.1987
56.84608629,96.39,236,15.3623
56.89860742,96.39,247,15.7162
56.95112855,96.39,236,15.3623
57.00364968,96.39,235,15.3297
57.05617081,96.39,242,15.5563
57.10869194,96.39,222,14.8997
57.16121307,96.39,229,15.1327
57.21373421,96.39,239,15.4596
57.26625534,96.39,246,15.6844
57.31877647,96.39,248,15.748
57.3712976,96.39,260,16.1245
57.42381873,96.39,227,15.0665
57.47633986,96.39,294,17.1464
57.52886099,96.39,254,15.9374
57.58138212,96.39,242,15.5563
57.63390325,96.39,252,15.8745
57.68642438,96.39,204,14.2829
57.73894551,96.39,246,15.6844
57.79146664,96.39,235,15.3297
57.84398777,96.39,234,15.2971
57.8965089,96.39,233,15.2643
57.94903004,96.39,264,16.2481
58.00155117,96.39,258,16.0624
58.0540723,96.39,267,16.3401
58.10659343,96.39,253,15.906
58.15911456,96.39,301,17.3494
58.21163569,96.39,247,15.7162
58.26415682,96.39,257,16.0312
58.31667795,96.39,221,14.8661
58.36919908,96.39,260,16.1245
58.42172021,96.39,235,15.3297
58.47424134,96.39,211,14.5258
58.52676247,96.39,245,15.6525
58.5792836,96.39,242,15.5563
58.63180473,96.39,221,14.8661
58.68432587,96.39,254,15.9374
58.736847,96.39,252,15.8745
58.78936813,96.39,210,14.4914
58.84188926,96.39,240,15.4919
58.89441039,96.39,229,15.1327
58.94693152,96.39,239,15.4596
58.99945265,96.39,213,14.5945
59.05197378,96.39,212,14.5602
59.10449491,96.39,219,14.7986
59.15701604,96.39,221,14.8661
59.20953717,96.39,236,15.3623
59.2620583,96.39,228,15.0997
59.31457943,96.39,262,16.1864
59.36710056,96.39,258,16.0624
59.4196217,96.39,248,15.748
59.47214283,96.39,223,14.9332
59.52466396,96.39,240,15.4919
59.57718509,96.39,260,16.1245
59.62970622,96.39,256,16
59.68222735,96.39,268,16.3707
59.73474848,96.39,245,15.6525
59.78726961,96.39,275,16.5831
59.83979074,96.39,237,15.3948
59.89231187,96.39,246,15.6844
59.944833,96.39,294,17.1464
59.99735413,96.39,268,16.3707
60.04987526,96.39,291,17.0587
60.10239639,96.39,253,15.906
60.15491753,96.39,290,17.0294
60.20743866,96.39,251,15.843
60.25995979,96.39,268,16.3707
60.31248092,96.39,309,17.5784
60.36500205,96.39,272,16.4924
60.41752318,96.39,292,17.088
60.47004431,96.39,306,17.4929
60.52256544,96.39,321,17.9165
60.57508657,96.39,317,17.8045
60.6276077,96.39,376,19.3907
60.68012883,96.39,315,17.7482
60.73264996,96.39,375,19.3649
60.78517109,96.39,358,18.9209
60.83769222,96.39,353,18.7883
60.89021336,96.39,345,18.5742
60.94273449,96.39,336,18.3303
60.99525562,96.39,377,19.4165
61.04777675,96.39,361,19
61.10029788,96.39,374,19.3391
61.15281901,96.39,365,19.105
61.20534014,96.39,391,19.7737
61.25786127,96.39,372,19.2873
61.3103824,96.39,379,19.4679
61.36290353,96.39,386,19.6469
61.41542466,96.39,366,19.1311
61.46794579,96.39,380,19.4936
61.52046692,96.39,370,19.2354
61.57298805,96.39,338,18.3848
61.62550919,96.39,371,19.2614
61.67803032,96.39,368,19.1833
61.73055145,96.39,329,18.1384
61.78307258,96.39,323,17.9722
61.83559371,96.39,346,18.6011
61.88811484,96.39,358,18.9209
61.94063597,96.39,338,18.3848
61.9931571,96.39,307,17.5214
62.04567823,96.39,340,18.4391
62.09819936,96.39,330,18.1659
62.15072049,96.39,340,18.4391
62.20324162,96.39,312,17.6635
62.25576275,96.39,262,16.1864
62.30828388,96.39,283,16.8226
62.36080502,96.39,291,17.0587
62.41332615,96.39,319,17.8606
62.46584728,96.39,274,16.5529
62.51836841,96.39,261,16.1555
62.57088954,96.39,280,16.7332
62.62341067,96.39,323,17.9722
62.6759318,96.39,273,16.5227
62.72845293,96.39,282,16.7929
62.78097406,96.39,276,16.6132
62.83349519,96.39,306,17.4929
62.88601632,96.39,260,16.1245
62.93853745,96.39,259,16.0935
62.99105858,96.39,259,16.0935
63.04357971,96.39,261,16.1555
63.09610084,96.39,236,15.3623
63.14862198,96.39,229,15.1327
63.20114311,96.39,229,15.1327
63.25366424,96.39,234,15.2971
63.30618537,96.39,220,14.8324
63.3587065,96.39,263,16.2173
63.41122763,96.39,222,14.8997
63.46374876,96.39,231,15.1987
63.51626989,96.39,245,15.6525
63.56879102,96.39,232,15.2315
63.62131215,96.39,232,15.2315
63.67383328,96.39,213,14.5945
63.72635441,96.39,238,15.4272
63.77887554,96.39,250,15.8114
63.83139667,96.39,263,16.2173
63.88391781,96.39,248,15.748
63.93643894,96.39,219,14.7986
63.98896007,96.39,220,14.8324
64.0414812,96.39,232,15.2315
64.09400233,96.39,254,15.9374
64.14652346,96.39,237,15.3948
64.19904459,96.39,233,15.2643
64.25156572,96.39,256,16
64.30408685,96.39,199,14.1067
64.35660798,96.39,222,14.8997
64.40912911,96.39,195,13.9642
64.46165024,96.39,226,15.0333
64.51417137,96.39,199,14.1067
64.5666925,96.39,237,15.3948
64.61921364,96.39,206,14.3527
64.67173477,96.39,221,14.8661
64.7242559,96.39,212,14.5602
64.77677703,96.39,192,13.8564
64.82929816,96.39,192,13.8564
64.88181929,96.39,228,15.0997
64.93434042,96.39,199,14.1067
64.98686155,96.39,230,15.1658