File: Files_organized_for_plots/Quant/B_XRD_155QuantSpiner_Al-Corner.csv
[Measurement conditions],,,
Sample identification,AlCorner31Jan22_Act12Feb23_B1_0833M_NaOH_LS0153,,
Comment - 1,"Configuration=Reflection-Transmission Spinner 3.0, Owner=arr19, Creation date=3/22/2023 1:21:48 PM",,
Comment - 2,Goniometer=Theta/Theta; Minimum step size 2Theta:0.0001; Minimum step size Omega:0.0001,,
Comment - 3,Sample stage=Reflection-transmission spinner 3.0; Minimum step size Phi:0.1,,
Comment - 5,"Measurement program=X:\XRD\Cement\Spinner_for_cement.xrdmp, Created identifier={6DF360EA-8E6E-4CFC-907C-F1BFECF51AA2}, Created by=Titus Reed, Id=tmr79, Creation date=2/15/2023 11:27:56 AM",,
Anode material,Cu,,
K-Alpha1 wavelength,1.540598,,
K-Alpha2 wavelength,1.544426,,
Ratio K-Alpha2/K-Alpha1,0.5,,
Divergence slit,Fixed,0.125,
Monochromator used,NO,,
Generator voltage,45,,
Tube current,40,,
File date and time,3/22/2023 14:37,,
Unit cell,,,
h k l, 0 0 0,,
Scan axis,Gonio,,
Scan range,4.994599997,64.99999183,
Scan step size,0.0262606,,
No. of points,2285,,
Scan type,CONTINUOUS,,
Phi,263.4,,
Time per step,96.39,,
[Scan points],,,
Angle, TimePerStep, Intensity, ESD
5.00773028,96.39,1166,34.1467
5.060251411,96.39,1169,34.1906
5.112772541,96.39,1137,33.7194
5.165293672,96.39,1093,33.0606
5.217814803,96.39,1120,33.4664
5.270335934,96.39,1064,32.619
5.322857064,96.39,1069,32.6956
5.375378195,96.39,1053,32.45
5.427899326,96.39,999,31.607
5.480420456,96.39,1047,32.3574
5.532941587,96.39,1052,32.4345
5.585462718,96.39,1000,31.6228
5.637983849,96.39,1054,32.4654
5.690504979,96.39,998,31.5911
5.74302611,96.39,1052,32.4345
5.795547241,96.39,1038,32.218
5.848068371,96.39,1010,31.7805
5.900589502,96.39,994,31.5278
5.953110633,96.39,968,31.1127
6.005631763,96.39,1002,31.6544
6.058152894,96.39,948,30.7896
6.110674025,96.39,1037,32.2025
6.163195156,96.39,1002,31.6544
6.215716286,96.39,952,30.8545
6.268237417,96.39,1009,31.7648
6.320758548,96.39,980,31.305
6.373279678,96.39,1140,33.7639
6.425800809,96.39,986,31.4006
6.47832194,96.39,997,31.5753
6.530843071,96.39,1032,32.1248
6.583364201,96.39,1001,31.6386
6.635885332,96.39,1040,32.249
6.688406463,96.39,998,31.5911
6.740927593,96.39,1007,31.7333
6.793448724,96.39,1086,32.9545
6.845969855,96.39,1187,34.4529
6.898490986,96.39,1287,35.8748
6.951012116,96.39,1388,37.2559
7.003533247,96.39,1611,40.1373
7.056054378,96.39,2062,45.4093
7.108575508,96.39,2597,50.9608
7.161096639,96.39,3462,58.8388
7.21361777,96.39,3038,55.1181
7.2661389,96.39,1527,39.0768
7.318660031,96.39,1224,34.9857
7.371181162,96.39,1044,32.311
7.423702293,96.39,965,31.0644
7.476223423,96.39,928,30.4631
7.528744554,96.39,875,29.5804
7.581265685,96.39,834,28.8791
7.633786815,96.39,808,28.4253
7.686307946,96.39,820,28.6356
7.738829077,96.39,837,28.931
7.791350208,96.39,860,29.3258
7.843871338,96.39,807,28.4077
7.896392469,96.39,856,29.2575
7.9489136,96.39,861,29.3428
8.00143473,96.39,806,28.3901
8.053955861,96.39,787,28.0535
8.106476992,96.39,812,28.4956
8.158998123,96.39,797,28.2312
8.211519253,96.39,815,28.5482
8.264040384,96.39,793,28.1603
8.316561515,96.39,814,28.5307
8.369082645,96.39,757,27.5136
8.421603776,96.39,777,27.8747
8.474124907,96.39,867,29.4449
8.526646038,96.39,783,27.9821
8.579167168,96.39,785,28.0179
8.631688299,96.39,743,27.258
8.68420943,96.39,797,28.2312
8.73673056,96.39,746,27.313
8.789251691,96.39,800,28.2843
8.841772822,96.39,805,28.3725
8.894293952,96.39,783,27.9821
8.946815083,96.39,784,28
8.999336214,96.39,717,26.7769
9.051857345,96.39,714,26.7208
9.104378475,96.39,723,26.8887
9.156899606,96.39,757,27.5136
9.209420737,96.39,800,28.2843
9.261941867,96.39,759,27.55
9.314462998,96.39,781,27.9464
9.366984129,96.39,768,27.7128
9.41950526,96.39,781,27.9464
9.47202639,96.39,711,26.6646
9.524547521,96.39,727,26.9629
9.577068652,96.39,763,27.6225
9.629589782,96.39,771,27.7669
9.682110913,96.39,737,27.1477
9.734632044,96.39,757,27.5136
9.787153175,96.39,829,28.7924
9.839674305,96.39,854,29.2233
9.892195436,96.39,924,30.3974
9.944716567,96.39,1027,32.0468
9.997237697,96.39,1105,33.2415
10.04975883,96.39,1358,36.8511
10.10227996,96.39,1693,41.1461
10.15480109,96.39,2334,48.3115
10.20732222,96.39,1813,42.5793
10.25984335,96.39,1054,32.4654
10.31236448,96.39,859,29.3087
10.36488561,96.39,833,28.8617
10.41740674,96.39,786,28.0357
10.46992787,96.39,770,27.7489
10.522449,96.39,735,27.1109
10.57497014,96.39,782,27.9643
10.62749127,96.39,790,28.1069
10.6800124,96.39,777,27.8747
10.73253353,96.39,803,28.3373
10.78505466,96.39,813,28.5132
10.83757579,96.39,784,28
10.89009692,96.39,881,29.6816
10.94261805,96.39,809,28.4429
10.99513918,96.39,823,28.688
11.04766031,96.39,856,29.2575
11.10018144,96.39,886,29.7658
11.15270257,96.39,921,30.348
11.2052237,96.39,952,30.8545
11.25774483,96.39,1016,31.8748
11.31026597,96.39,989,31.4484
11.3627871,96.39,1130,33.6155
11.41530823,96.39,1296,36
11.46782936,96.39,1293,35.9583
11.52035049,96.39,1424,37.7359
11.57287162,96.39,1434,37.8682
11.62539275,96.39,1443,37.9868
11.67791388,96.39,1495,38.6652
11.73043501,96.39,1405,37.4833
11.78295614,96.39,1290,35.9166
11.83547727,96.39,1215,34.8569
11.8879984,96.39,1122,33.4963
11.94051953,96.39,1059,32.5423
11.99304066,96.39,952,30.8545
12.0455618,96.39,911,30.1828
12.09808293,96.39,866,29.4279
12.15060406,96.39,875,29.5804
12.20312519,96.39,858,29.2916
12.25564632,96.39,862,29.3598
12.30816745,96.39,1040,32.249
12.36068858,96.39,1114,33.3766
12.41320971,96.39,1498,38.704
12.46573084,96.39,1686,41.0609
12.51825197,96.39,1206,34.7275
12.5707731,96.39,839,28.9655
12.62329423,96.39,720,26.8328
12.67581536,96.39,735,27.1109
12.72833649,96.39,646,25.4165
12.78085763,96.39,607,24.6374
12.83337876,96.39,625,25
12.88589989,96.39,638,25.2587
12.93842102,96.39,605,24.5967
12.99094215,96.39,613,24.7588
13.04346328,96.39,618,24.8596
13.09598441,96.39,607,24.6374
13.14850554,96.39,575,23.9792
13.20102667,96.39,570,23.8747
13.2535478,96.39,552,23.4947
13.30606893,96.39,622,24.9399
13.35859006,96.39,532,23.0651
13.41111119,96.39,528,22.9783
13.46363232,96.39,551,23.4734
13.51615346,96.39,549,23.4307
13.56867459,96.39,572,23.9165
13.62119572,96.39,529,23
13.67371685,96.39,569,23.8537
13.72623798,96.39,549,23.4307
13.77875911,96.39,532,23.0651
13.83128024,96.39,570,23.8747
13.88380137,96.39,476,21.8174
13.9363225,96.39,511,22.6053
13.98884363,96.39,537,23.1733
14.04136476,96.39,559,23.6432
14.09388589,96.39,493,22.2036
14.14640702,96.39,555,23.5584
14.19892815,96.39,461,21.4709
14.25144929,96.39,488,22.0907
14.30397042,96.39,464,21.5407
14.35649155,96.39,531,23.0434
14.40901268,96.39,506,22.4944
14.46153381,96.39,501,22.383
14.51405494,96.39,527,22.9565
14.56657607,96.39,534,23.1084
14.6190972,96.39,505,22.4722
14.67161833,96.39,500,22.3607
14.72413946,96.39,490,22.1359
14.77666059,96.39,497,22.2935
14.82918172,96.39,492,22.1811
14.88170285,96.39,481,21.9317
14.93422398,96.39,481,21.9317
14.98674512,96.39,509,22.561
15.03926625,96.39,500,22.3607
15.09178738,96.39,441,21
15.14430851,96.39,502,22.4054
15.19682964,96.39,459,21.4243
15.24935077,96.39,479,21.8861
15.3018719,96.39,464,21.5407
15.35439303,96.39,471,21.7025
15.40691416,96.39,507,22.5167
15.45943529,96.39,450,21.2132
15.51195642,96.39,438,20.9284
15.56447755,96.39,497,22.2935
15.61699868,96.39,484,22
15.66951981,96.39,458,21.4009
15.72204095,96.39,499,22.3383
15.77456208,96.39,463,21.5174
15.82708321,96.39,516,22.7156
15.87960434,96.39,525,22.9129
15.93212547,96.39,568,23.8328
15.9846466,96.39,701,26.4764
16.03716773,96.39,876,29.5973
16.08968886,96.39,1082,32.8938
16.14220999,96.39,988,31.4325
16.19473112,96.39,714,26.7208
16.24725225,96.39,561,23.6854
16.29977338,96.39,535,23.1301
16.35229451,96.39,467,21.6102
16.40481564,96.39,455,21.3307
16.45733678,96.39,504,22.4499
16.50985791,96.39,468,21.6333
16.56237904,96.39,415,20.3715
16.61490017,96.39,463,21.5174
16.6674213,96.39,433,20.8087
16.71994243,96.39,448,21.166
16.77246356,96.39,452,21.2603
16.82498469,96.39,425,20.6155
16.87750582,96.39,447,21.1424
16.93002695,96.39,452,21.2603
16.98254808,96.39,417,20.4206
17.03506921,96.39,438,20.9284
17.08759034,96.39,398,19.9499
17.14011147,96.39,432,20.7846
17.19263261,96.39,393,19.8242
17.24515374,96.39,447,21.1424
17.29767487,96.39,393,19.8242
17.350196,96.39,403,20.0749
17.40271713,96.39,438,20.9284
17.45523826,96.39,425,20.6155
17.50775939,96.39,439,20.9523
17.56028052,96.39,461,21.4709
17.61280165,96.39,409,20.2237
17.66532278,96.39,503,22.4277
17.71784391,96.39,472,21.7256
17.77036504,96.39,454,21.3073
17.82288617,96.39,441,21
17.8754073,96.39,485,22.0227
17.92792843,96.39,471,21.7025
17.98044957,96.39,442,21.0238
18.0329707,96.39,535,23.1301
18.08549183,96.39,513,22.6495
18.13801296,96.39,628,25.0599
18.19053409,96.39,686,26.1916
18.24305522,96.39,763,27.6225
18.29557635,96.39,801,28.3019
18.34809748,96.39,990,31.4643
18.40061861,96.39,1115,33.3916
18.45313974,96.39,1311,36.2077
18.50566087,96.39,1385,37.2156
18.558182,96.39,1558,39.4715
18.61070313,96.39,1622,40.2741
18.66322426,96.39,1792,42.332
18.7157454,96.39,1917,43.7836
18.76826653,96.39,1620,40.2492
18.82078766,96.39,1289,35.9026
18.87330879,96.39,940,30.6594
18.92582992,96.39,639,25.2784
18.97835105,96.39,544,23.3238
19.03087218,96.39,514,22.6716
19.08339331,96.39,471,21.7025
19.13591444,96.39,472,21.7256
19.18843557,96.39,448,21.166
19.2409567,96.39,398,19.9499
19.29347783,96.39,451,21.2368
19.34599896,96.39,469,21.6564
19.39852009,96.39,467,21.6102
19.45104123,96.39,412,20.2978
19.50356236,96.39,406,20.1494
19.55608349,96.39,462,21.4942
19.60860462,96.39,406,20.1494
19.66112575,96.39,434,20.8327
19.71364688,96.39,441,21
19.76616801,96.39,418,20.445
19.81868914,96.39,443,21.0476
19.87121027,96.39,487,22.0681
19.9237314,96.39,465,21.5639
19.97625253,96.39,545,23.3452
20.02877366,96.39,599,24.4745
20.08129479,96.39,692,26.3059
20.13381592,96.39,860,29.3258
20.18633706,96.39,1187,34.4529
20.23885819,96.39,1543,39.281
20.29137932,96.39,1881,43.3705
20.34390045,96.39,1826,42.7317
20.39642158,96.39,1677,40.9512
20.44894271,96.39,1478,38.4448
20.50146384,96.39,1206,34.7275
20.55398497,96.39,1051,32.4191
20.6065061,96.39,890,29.8329
20.65902723,96.39,827,28.7576
20.71154836,96.39,833,28.8617
20.76406949,96.39,781,27.9464
20.81659062,96.39,758,27.5318
20.86911175,96.39,691,26.2869
20.92163289,96.39,608,24.6577
20.97415402,96.39,566,23.7908
21.02667515,96.39,550,23.4521
21.07919628,96.39,511,22.6053
21.13171741,96.39,546,23.3666
21.18423854,96.39,448,21.166
21.23675967,96.39,478,21.8632
21.2892808,96.39,483,21.9773
21.34180193,96.39,512,22.6274
21.39432306,96.39,515,22.6936
21.44684419,96.39,546,23.3666
21.49936532,96.39,629,25.0799
21.55188645,96.39,685,26.1725
21.60440758,96.39,940,30.6594
21.65692872,96.39,1261,35.5106
21.70944985,96.39,1098,33.1361
21.76197098,96.39,774,27.8209
21.81449211,96.39,557,23.6008
21.86701324,96.39,436,20.8806
21.91953437,96.39,438,20.9284
21.9720555,96.39,415,20.3715
22.02457663,96.39,388,19.6977
22.07709776,96.39,398,19.9499
22.12961889,96.39,405,20.1246
22.18214002,96.39,407,20.1742
22.23466115,96.39,353,18.7883
22.28718228,96.39,407,20.1742
22.33970341,96.39,435,20.8567
22.39222455,96.39,414,20.347
22.44474568,96.39,386,19.6469
22.49726681,96.39,393,19.8242
22.54978794,96.39,420,20.4939
22.60230907,96.39,419,20.4695
22.6548302,96.39,403,20.0749
22.70735133,96.39,402,20.0499
22.75987246,96.39,455,21.3307
22.81239359,96.39,517,22.7376
22.86491472,96.39,525,22.9129
22.91743585,96.39,517,22.7376
22.96995698,96.39,489,22.1133
23.02247811,96.39,468,21.6333
23.07499924,96.39,512,22.6274
23.12752038,96.39,584,24.1661
23.18004151,96.39,552,23.4947
23.23256264,96.39,607,24.6374
23.28508377,96.39,643,25.3574
23.3376049,96.39,696,26.3818
23.39012603,96.39,706,26.5707
23.44264716,96.39,737,27.1477
23.49516829,96.39,746,27.313
23.54768942,96.39,695,26.3629
23.60021055,96.39,738,27.1662
23.65273168,96.39,672,25.923
23.70525281,96.39,672,25.923
23.75777394,96.39,705,26.5518
23.81029507,96.39,768,27.7128
23.86281621,96.39,909,30.1496
23.91533734,96.39,1319,36.318
23.96785847,96.39,1696,41.1825
24.0203796,96.39,1687,41.0731
24.07290073,96.39,1224,34.9857
24.12542186,96.39,774,27.8209
24.17794299,96.39,537,23.1733
24.23046412,96.39,511,22.6053
24.28298525,96.39,419,20.4695
24.33550638,96.39,406,20.1494
24.38802751,96.39,366,19.1311
24.44054864,96.39,366,19.1311
24.49306977,96.39,359,18.9473
24.5455909,96.39,335,18.303
24.59811204,96.39,355,18.8414
24.65063317,96.39,340,18.4391
24.7031543,96.39,419,20.4695
24.75567543,96.39,372,19.2873
24.80819656,96.39,353,18.7883
24.86071769,96.39,369,19.2094
24.91323882,96.39,325,18.0278
24.96575995,96.39,373,19.3132
25.01828108,96.39,345,18.5742
25.07080221,96.39,352,18.7617
25.12332334,96.39,350,18.7083
25.17584447,96.39,356,18.868
25.2283656,96.39,362,19.0263
25.28088673,96.39,359,18.9473
25.33340786,96.39,416,20.3961
25.385929,96.39,464,21.5407
25.43845013,96.39,627,25.04
25.49097126,96.39,956,30.9192
25.54349239,96.39,1435,37.8814
25.59601352,96.39,1309,36.1801
25.64853465,96.39,785,28.0179
25.70105578,96.39,440,20.9762
25.75357691,96.39,358,18.9209
25.80609804,96.39,358,18.9209
25.85861917,96.39,425,20.6155
25.9111403,96.39,391,19.7737
25.96366143,96.39,461,21.4709
26.01618256,96.39,482,21.9545
26.06870369,96.39,621,24.9199
26.12122483,96.39,750,27.3861
26.17374596,96.39,650,25.4951
26.22626709,96.39,499,22.3383
26.27878822,96.39,404,20.0998
26.33130935,96.39,382,19.5448
26.38383048,96.39,330,18.1659
26.43635161,96.39,379,19.4679
26.48887274,96.39,384,19.5959
26.54139387,96.39,402,20.0499
26.593915,96.39,403,20.0749
26.64643613,96.39,437,20.9045
26.69895726,96.39,417,20.4206
26.75147839,96.39,434,20.8327
26.80399952,96.39,457,21.3776
26.85652066,96.39,449,21.1896
26.90904179,96.39,549,23.4307
26.96156292,96.39,674,25.9615
27.01408405,96.39,915,30.249
27.06660518,96.39,1219,34.9142
27.11912631,96.39,1589,39.8623
27.17164744,96.39,1363,36.9188
27.22416857,96.39,916,30.2655
27.2766897,96.39,600,24.4949
27.32921083,96.39,582,24.1247
27.38173196,96.39,469,21.6564
27.43425309,96.39,454,21.3073
27.48677422,96.39,489,22.1133
27.53929535,96.39,479,21.8861
27.59181649,96.39,507,22.5167
27.64433762,96.39,546,23.3666
27.69685875,96.39,584,24.1661
27.74937988,96.39,569,23.8537
27.80190101,96.39,599,24.4745
27.85442214,96.39,578,24.0416
27.90694327,96.39,546,23.3666
27.9594644,96.39,467,21.6102
28.01198553,96.39,463,21.5174
28.06450666,96.39,416,20.3961
28.11702779,96.39,403,20.0749
28.16954892,96.39,390,19.7484
28.22207005,96.39,351,18.735
28.27459118,96.39,344,18.5472
28.32711232,96.39,354,18.8149
28.37963345,96.39,361,19
28.43215458,96.39,361,19
28.48467571,96.39,333,18.2483
28.53719684,96.39,340,18.4391
28.58971797,96.39,341,18.4662
28.6422391,96.39,369,19.2094
28.69476023,96.39,334,18.2757
28.74728136,96.39,369,19.2094
28.79980249,96.39,371,19.2614
28.85232362,96.39,345,18.5742
28.90484475,96.39,344,18.5472
28.95736588,96.39,353,18.7883
29.00988701,96.39,338,18.3848
29.06240815,96.39,373,19.3132
29.11492928,96.39,391,19.7737
29.16745041,96.39,350,18.7083
29.21997154,96.39,359,18.9473
29.27249267,96.39,378,19.4422
29.3250138,96.39,328,18.1108
29.37753493,96.39,315,17.7482
29.43005606,96.39,341,18.4662
29.48257719,96.39,358,18.9209
29.53509832,96.39,385,19.6214
29.58761945,96.39,403,20.0749
29.64014058,96.39,423,20.567
29.69266171,96.39,533,23.0868
29.74518284,96.39,621,24.9199
29.79770398,96.39,791,28.1247
29.85022511,96.39,1062,32.5883
29.90274624,96.39,1535,39.1791
29.95526737,96.39,1759,41.9404
30.0077885,96.39,1506,38.8072
30.06030963,96.39,1034,32.1559
30.11283076,96.39,692,26.3059
30.16535189,96.39,541,23.2594
30.21787302,96.39,444,21.0713
30.27039415,96.39,386,19.6469
30.32291528,96.39,384,19.5959
30.37543641,96.39,426,20.6398
30.42795754,96.39,384,19.5959
30.48047867,96.39,329,18.1384
30.53299981,96.39,331,18.1934
30.58552094,96.39,371,19.2614
30.63804207,96.39,386,19.6469
30.6905632,96.39,423,20.567
30.74308433,96.39,450,21.2132
30.79560546,96.39,515,22.6936
30.84812659,96.39,506,22.4944
30.90064772,96.39,454,21.3073
30.95316885,96.39,403,20.0749
31.00568998,96.39,377,19.4165
31.05821111,96.39,341,18.4662
31.11073224,96.39,343,18.5203
31.16325337,96.39,353,18.7883
31.2157745,96.39,316,17.7764
31.26829564,96.39,338,18.3848
31.32081677,96.39,349,18.6815
31.3733379,96.39,325,18.0278
31.42585903,96.39,349,18.6815
31.47838016,96.39,303,17.4069
31.53090129,96.39,342,18.4932
31.58342242,96.39,358,18.9209
31.63594355,96.39,351,18.735
31.68846468,96.39,313,17.6918
31.74098581,96.39,307,17.5214
31.79350694,96.39,321,17.9165
31.84602807,96.39,337,18.3576
31.8985492,96.39,330,18.1659
31.95107033,96.39,349,18.6815
32.00359147,96.39,341,18.4662
32.0561126,96.39,331,18.1934
32.10863373,96.39,324,18
32.16115486,96.39,381,19.5192
32.21367599,96.39,409,20.2237
32.26619712,96.39,442,21.0238
32.31871825,96.39,434,20.8327
32.37123938,96.39,440,20.9762
32.42376051,96.39,480,21.9089
32.47628164,96.39,555,23.5584
32.52880277,96.39,613,24.7588
32.5813239,96.39,597,24.4336
32.63384503,96.39,516,22.7156
32.68636616,96.39,417,20.4206
32.7388873,96.39,354,18.8149
32.79140843,96.39,359,18.9473
32.84392956,96.39,375,19.3649
32.89645069,96.39,392,19.799
32.94897182,96.39,355,18.8414
33.00149295,96.39,389,19.7231
33.05401408,96.39,381,19.5192
33.10653521,96.39,427,20.664
33.15905634,96.39,433,20.8087
33.21157747,96.39,408,20.199
33.2640986,96.39,438,20.9284
33.31661973,96.39,520,22.8035
33.36914086,96.39,517,22.7376
33.42166199,96.39,554,23.5372
33.47418312,96.39,529,23
33.52670426,96.39,494,22.2261
33.57922539,96.39,490,22.1359
33.63174652,96.39,493,22.2036
33.68426765,96.39,526,22.9347
33.73678878,96.39,582,24.1247
33.78930991,96.39,610,24.6982
33.84183104,96.39,693,26.3249
33.89435217,96.39,719,26.8142
33.9468733,96.39,773,27.8029
33.99939443,96.39,920,30.3315
34.05191556,96.39,1023,31.9844
34.10443669,96.39,1348,36.7151
34.15695782,96.39,1502,38.7556
34.20947895,96.39,1666,40.8167
34.26200009,96.39,1375,37.081
34.31452122,96.39,1166,34.1467
34.36704235,96.39,921,30.348
34.41956348,96.39,860,29.3258
34.47208461,96.39,788,28.0713
34.52460574,96.39,764,27.6405
34.57712687,96.39,717,26.7769
34.629648,96.39,648,25.4558
34.68216913,96.39,705,26.5518
34.73469026,96.39,668,25.8457
34.78721139,96.39,713,26.7021
34.83973252,96.39,748,27.3496
34.89225365,96.39,810,28.4605
34.94477478,96.39,904,30.0666
34.99729592,96.39,1024,32
35.04981705,96.39,1332,36.4966
35.10233818,96.39,2017,44.911
35.15485931,96.39,1949,44.1475
35.20738044,96.39,1425,37.7492
35.25990157,96.39,862,29.3598
35.3124227,96.39,578,24.0416
35.36494383,96.39,506,22.4944
35.41746496,96.39,441,21
35.46998609,96.39,462,21.4942
35.52250722,96.39,439,20.9523
35.57502835,96.39,421,20.5183
35.62754948,96.39,407,20.1742
35.68007061,96.39,442,21.0238
35.73259175,96.39,456,21.3542
35.78511288,96.39,483,21.9773
35.83763401,96.39,452,21.2603
35.89015514,96.39,440,20.9762
35.94267627,96.39,407,20.1742
35.9951974,96.39,405,20.1246
36.04771853,96.39,425,20.6155
36.10023966,96.39,407,20.1742
36.15276079,96.39,405,20.1246
36.20528192,96.39,369,19.2094
36.25780305,96.39,408,20.199
36.31032418,96.39,375,19.3649
36.36284531,96.39,404,20.0998
36.41536644,96.39,446,21.1187
36.46788758,96.39,445,21.095
36.52040871,96.39,498,22.3159
36.57292984,96.39,435,20.8567
36.62545097,96.39,378,19.4422
36.6779721,96.39,403,20.0749
36.73049323,96.39,334,18.2757
36.78301436,96.39,365,19.105
36.83553549,96.39,329,18.1384
36.88805662,96.39,355,18.8414
36.94057775,96.39,336,18.3303
36.99309888,96.39,314,17.72
37.04562001,96.39,332,18.2209
37.09814114,96.39,338,18.3848
37.15066227,96.39,333,18.2483
37.20318341,96.39,361,19
37.25570454,96.39,368,19.1833
37.30822567,96.39,388,19.6977
37.3607468,96.39,390,19.7484
37.41326793,96.39,446,21.1187
37.46578906,96.39,418,20.445
37.51831019,96.39,447,21.1424
37.57083132,96.39,508,22.5389
37.62335245,96.39,601,24.5153
37.67587358,96.39,725,26.9258
37.72839471,96.39,1047,32.3574
37.78091584,96.39,1040,32.249
37.83343697,96.39,860,29.3258
37.8859581,96.39,726,26.9444
37.93847924,96.39,543,23.3024
37.99100037,96.39,558,23.622
38.0435215,96.39,511,22.6053
38.09604263,96.39,477,21.8403
38.14856376,96.39,474,21.7715
38.20108489,96.39,368,19.1833
38.25360602,96.39,423,20.567
38.30612715,96.39,360,18.9737
38.35864828,96.39,353,18.7883
38.41116941,96.39,366,19.1311
38.46369054,96.39,365,19.105
38.51621167,96.39,347,18.6279
38.5687328,96.39,425,20.6155
38.62125393,96.39,373,19.3132
38.67377507,96.39,367,19.1572
38.7262962,96.39,384,19.5959
38.77881733,96.39,375,19.3649
38.83133846,96.39,359,18.9473
38.88385959,96.39,340,18.4391
38.93638072,96.39,379,19.4679
38.98890185,96.39,359,18.9473
39.04142298,96.39,371,19.2614
39.09394411,96.39,441,21
39.14646524,96.39,413,20.3224
39.19898637,96.39,433,20.8087
39.2515075,96.39,464,21.5407
39.30402863,96.39,444,21.0713
39.35654976,96.39,504,22.4499
39.4090709,96.39,527,22.9565
39.46159203,96.39,539,23.2164
39.51411316,96.39,567,23.8118
39.56663429,96.39,522,22.8473
39.61915542,96.39,545,23.3452
39.67167655,96.39,482,21.9545
39.72419768,96.39,470,21.6795
39.77671881,96.39,476,21.8174
39.82923994,96.39,450,21.2132
39.88176107,96.39,494,22.2261
39.9342822,96.39,445,21.095
39.98680333,96.39,474,21.7715
40.03932446,96.39,469,21.6564
40.09184559,96.39,525,22.9129
40.14436673,96.39,602,24.5357
40.19688786,96.39,675,25.9808
40.24940899,96.39,690,26.2679
40.30193012,96.39,711,26.6646
40.35445125,96.39,826,28.7402
40.40697238,96.39,938,30.6268
40.45949351,96.39,952,30.8545
40.51201464,96.39,1001,31.6386
40.56453577,96.39,997,31.5753
40.6170569,96.39,942,30.692
40.66957803,96.39,829,28.7924
40.72209916,96.39,728,26.9815
40.77462029,96.39,588,24.2487
40.82714142,96.39,544,23.3238
40.87966255,96.39,487,22.0681
40.93218369,96.39,436,20.8806
40.98470482,96.39,448,21.166
41.03722595,96.39,436,20.8806
41.08974708,96.39,410,20.2485
41.14226821,96.39,420,20.4939
41.19478934,96.39,423,20.567
41.24731047,96.39,420,20.4939
41.2998316,96.39,380,19.4936
41.35235273,96.39,429,20.7123
41.40487386,96.39,436,20.8806
41.45739499,96.39,492,22.1811
41.50991612,96.39,521,22.8254
41.56243725,96.39,473,21.7486
41.61495838,96.39,519,22.7816
41.66747952,96.39,434,20.8327
41.72000065,96.39,406,20.1494
41.77252178,96.39,369,19.2094
41.82504291,96.39,360,18.9737
41.87756404,96.39,399,19.975
41.93008517,96.39,343,18.5203
41.9826063,96.39,359,18.9473
42.03512743,96.39,383,19.5704
42.08764856,96.39,317,17.8045
42.14016969,96.39,404,20.0998
42.19269082,96.39,392,19.799
42.24521195,96.39,417,20.4206
42.29773308,96.39,384,19.5959
42.35025421,96.39,337,18.3576
42.40277535,96.39,323,17.9722
42.45529648,96.39,299,17.2916
42.50781761,96.39,287,16.9411
42.56033874,96.39,300,17.3205
42.61285987,96.39,309,17.5784
42.665381,96.39,338,18.3848
42.71790213,96.39,316,17.7764
42.77042326,96.39,329,18.1384
42.82294439,96.39,335,18.303
42.87546552,96.39,361,19
42.92798665,96.39,352,18.7617
42.98050778,96.39,367,19.1572
43.03302891,96.39,363,19.0526
43.08555004,96.39,403,20.0749
43.13807118,96.39,469,21.6564
43.19059231,96.39,645,25.3969
43.24311344,96.39,1022,31.9687
43.29563457,96.39,1638,40.4722
43.3481557,96.39,1844,42.9418
43.40067683,96.39,1146,33.8526
43.45319796,96.39,1094,33.0757
43.50571909,96.39,600,24.4949
43.55824022,96.39,395,19.8746
43.61076135,96.39,374,19.3391
43.66328248,96.39,352,18.7617
43.71580361,96.39,345,18.5742
43.76832474,96.39,326,18.0555
43.82084587,96.39,283,16.8226
43.87336701,96.39,316,17.7764
43.92588814,96.39,276,16.6132
43.97840927,96.39,326,18.0555
44.0309304,96.39,325,18.0278
44.08345153,96.39,375,19.3649
44.13597266,96.39,448,21.166
44.18849379,96.39,427,20.664
44.24101492,96.39,382,19.5448
44.29353605,96.39,369,19.2094
44.34605718,96.39,346,18.6011
44.39857831,96.39,323,17.9722
44.45109944,96.39,297,17.2337
44.50362057,96.39,295,17.1756
44.5561417,96.39,281,16.7631
44.60866284,96.39,262,16.1864
44.66118397,96.39,247,15.7162
44.7137051,96.39,265,16.2788
44.76622623,96.39,259,16.0935
44.81874736,96.39,306,17.4929
44.87126849,96.39,277,16.6433
44.92378962,96.39,280,16.7332
44.97631075,96.39,281,16.7631
45.02883188,96.39,286,16.9115
45.08135301,96.39,293,17.1172
45.13387414,96.39,262,16.1864
45.18639527,96.39,271,16.4621
45.2389164,96.39,296,17.2047
45.29143753,96.39,256,16
45.34395867,96.39,309,17.5784
45.3964798,96.39,289,17
45.44900093,96.39,297,17.2337
45.50152206,96.39,279,16.7033
45.55404319,96.39,309,17.5784
45.60656432,96.39,322,17.9444
45.65908545,96.39,299,17.2916
45.71160658,96.39,302,17.3781
45.76412771,96.39,293,17.1172
45.81664884,96.39,297,17.2337
45.86916997,96.39,275,16.5831
45.9216911,96.39,262,16.1864
45.97421223,96.39,321,17.9165
46.02673336,96.39,318,17.8326
46.0792545,96.39,297,17.2337
46.13177563,96.39,334,18.2757
46.18429676,96.39,324,18
46.23681789,96.39,322,17.9444
46.28933902,96.39,313,17.6918
46.34186015,96.39,334,18.2757
46.39438128,96.39,320,17.8885
46.44690241,96.39,325,18.0278
46.49942354,96.39,360,18.9737
46.55194467,96.39,324,18
46.6044658,96.39,357,18.8944
46.65698693,96.39,346,18.6011
46.70950806,96.39,316,17.7764
46.76202919,96.39,372,19.2873
46.81455033,96.39,387,19.6723
46.86707146,96.39,360,18.9737
46.91959259,96.39,371,19.2614
46.97211372,96.39,378,19.4422
47.02463485,96.39,374,19.3391
47.07715598,96.39,404,20.0998
47.12967711,96.39,449,21.1896
47.18219824,96.39,453,21.2838
47.23471937,96.39,410,20.2485
47.2872405,96.39,457,21.3776
47.33976163,96.39,449,21.1896
47.39228276,96.39,390,19.7484
47.44480389,96.39,350,18.7083
47.49732502,96.39,340,18.4391
47.54984616,96.39,296,17.2047
47.60236729,96.39,348,18.6548
47.65488842,96.39,280,16.7332
47.70740955,96.39,271,16.4621
47.75993068,96.39,321,17.9165
47.81245181,96.39,332,18.2209
47.86497294,96.39,350,18.7083
47.91749407,96.39,331,18.1934
47.9700152,96.39,343,18.5203
48.02253633,96.39,335,18.303
48.07505746,96.39,327,18.0831
48.12757859,96.39,312,17.6635
48.18009972,96.39,296,17.2047
48.23262085,96.39,321,17.9165
48.28514198,96.39,264,16.2481
48.33766312,96.39,241,15.5242
48.39018425,96.39,297,17.2337
48.44270538,96.39,289,17
48.49522651,96.39,266,16.3095
48.54774764,96.39,304,17.4356
48.60026877,96.39,256,16
48.6527899,96.39,271,16.4621
48.70531103,96.39,241,15.5242
48.75783216,96.39,267,16.3401
48.81035329,96.39,287,16.9411
48.86287442,96.39,249,15.7797
48.91539555,96.39,288,16.9706
48.96791668,96.39,300,17.3205
49.02043781,96.39,300,17.3205
49.07295895,96.39,329,18.1384
49.12548008,96.39,282,16.7929
49.17800121,96.39,261,16.1555
49.23052234,96.39,317,17.8045
49.28304347,96.39,265,16.2788
49.3355646,96.39,275,16.5831
49.38808573,96.39,252,15.8745
49.44060686,96.39,244,15.6205
49.49312799,96.39,276,16.6132
49.54564912,96.39,286,16.9115
49.59817025,96.39,289,17
49.65069138,96.39,274,16.5529
49.70321251,96.39,290,17.0294
49.75573364,96.39,309,17.5784
49.80825478,96.39,266,16.3095
49.86077591,96.39,282,16.7929
49.91329704,96.39,280,16.7332
49.96581817,96.39,224,14.9666
50.0183393,96.39,223,14.9332
50.07086043,96.39,208,14.4222
50.12338156,96.39,290,17.0294
50.17590269,96.39,229,15.1327
50.22842382,96.39,234,15.2971
50.28094495,96.39,223,14.9332
50.33346608,96.39,238,15.4272
50.38598721,96.39,276,16.6132
50.43850834,96.39,242,15.5563
50.49102947,96.39,242,15.5563
50.54355061,96.39,240,15.4919
50.59607174,96.39,246,15.6844
50.64859287,96.39,239,15.4596
50.701114,96.39,199,14.1067
50.75363513,96.39,221,14.8661
50.80615626,96.39,223,14.9332
50.85867739,96.39,215,14.6629
50.91119852,96.39,249,15.7797
50.96371965,96.39,227,15.0665
51.01624078,96.39,228,15.0997
51.06876191,96.39,253,15.906
51.12128304,96.39,240,15.4919
51.17380417,96.39,225,15
51.2263253,96.39,232,15.2315
51.27884644,96.39,207,14.3875
51.33136757,96.39,236,15.3623
51.3838887,96.39,193,13.8924
51.43640983,96.39,246,15.6844
51.48893096,96.39,230,15.1658
51.54145209,96.39,263,16.2173
51.59397322,96.39,254,15.9374
51.64649435,96.39,247,15.7162
51.69901548,96.39,255,15.9687
51.75153661,96.39,245,15.6525
51.80405774,96.39,245,15.6525
51.85657887,96.39,256,16
51.9091,96.39,237,15.3948
51.96162113,96.39,251,15.843
52.01414227,96.39,306,17.4929
52.0666634,96.39,296,17.2047
52.11918453,96.39,315,17.7482
52.17170566,96.39,310,17.6068
52.22422679,96.39,334,18.2757
52.27674792,96.39,337,18.3576
52.32926905,96.39,387,19.6723
52.38179018,96.39,532,23.0651
52.43431131,96.39,642,25.3377
52.48683244,96.39,1036,32.187
52.53935357,96.39,1121,33.4813
52.5918747,96.39,897,29.95
52.64439583,96.39,890,29.8329
52.69691696,96.39,762,27.6043
52.7494381,96.39,573,23.9374
52.80195923,96.39,468,21.6333
52.85448036,96.39,457,21.3776
52.90700149,96.39,434,20.8327
52.95952262,96.39,461,21.4709
53.01204375,96.39,479,21.8861
53.06456488,96.39,547,23.388
53.11708601,96.39,579,24.0624
53.16960714,96.39,512,22.6274
53.22212827,96.39,454,21.3073
53.2746494,96.39,422,20.5426
53.32717053,96.39,375,19.3649
53.37969166,96.39,351,18.735
53.43221279,96.39,332,18.2209
53.48473393,96.39,313,17.6918
53.53725506,96.39,307,17.5214
53.58977619,96.39,278,16.6733
53.64229732,96.39,254,15.9374
53.69481845,96.39,262,16.1864
53.74733958,96.39,286,16.9115
53.79986071,96.39,276,16.6132
53.85238184,96.39,256,16
53.90490297,96.39,241,15.5242
53.9574241,96.39,253,15.906
54.00994523,96.39,258,16.0624
54.06246636,96.39,267,16.3401
54.11498749,96.39,274,16.5529
54.16750862,96.39,297,17.2337
54.22002976,96.39,324,18
54.27255089,96.39,352,18.7617
54.32507202,96.39,340,18.4391
54.37759315,96.39,317,17.8045
54.43011428,96.39,271,16.4621
54.48263541,96.39,260,16.1245
54.53515654,96.39,256,16
54.58767767,96.39,269,16.4012
54.6401988,96.39,235,15.3297
54.69271993,96.39,251,15.843
54.74524106,96.39,245,15.6525
54.79776219,96.39,231,15.1987
54.85028332,96.39,224,14.9666
54.90280445,96.39,245,15.6525
54.95532559,96.39,233,15.2643
55.00784672,96.39,206,14.3527
55.06036785,96.39,214,14.6287
55.11288898,96.39,213,14.5945
55.16541011,96.39,209,14.4568
55.21793124,96.39,199,14.1067
55.27045237,96.39,204,14.2829
55.3229735,96.39,229,15.1327
55.37549463,96.39,221,14.8661
55.42801576,96.39,207,14.3875
55.48053689,96.39,206,14.3527
55.53305802,96.39,217,14.7309
55.58557915,96.39,207,14.3875
55.63810028,96.39,232,15.2315
55.69062141,96.39,213,14.5945
55.74314255,96.39,204,14.2829
55.79566368,96.39,232,15.2315
55.84818481,96.39,235,15.3297
55.90070594,96.39,216,14.6969
55.95322707,96.39,213,14.5945
56.0057482,96.39,201,14.1774
56.05826933,96.39,210,14.4914
56.11079046,96.39,209,14.4568
56.16331159,96.39,238,15.4272
56.21583272,96.39,213,14.5945
56.26835385,96.39,225,15
56.32087498,96.39,222,14.8997
56.37339611,96.39,248,15.748
56.42591724,96.39,278,16.6733
56.47843838,96.39,278,16.6733
56.53095951,96.39,252,15.8745
56.58348064,96.39,303,17.4069
56.63600177,96.39,245,15.6525
56.6885229,96.39,226,15.0333
56.74104403,96.39,226,15.0333
56.79356516,96.39,238,15.4272
56.84608629,96.39,243,15.5885
56.89860742,96.39,243,15.5885
56.95112855,96.39,232,15.2315
57.00364968,96.39,259,16.0935
57.05617081,96.39,283,16.8226
57.10869194,96.39,281,16.7631
57.16121307,96.39,339,18.412
57.21373421,96.39,363,19.0526
57.26625534,96.39,428,20.6882
57.31877647,96.39,572,23.9165
57.3712976,96.39,866,29.4279
57.42381873,96.39,1221,34.9428
57.47633986,96.39,1655,40.6817
57.52886099,96.39,1039,32.2335
57.58138212,96.39,940,30.6594
57.63390325,96.39,924,30.3974
57.68642438,96.39,576,24
57.73894551,96.39,354,18.8149
57.79146664,96.39,295,17.1756
57.84398777,96.39,241,15.5242
57.8965089,96.39,241,15.5242
57.94903004,96.39,249,15.7797
58.00155117,96.39,217,14.7309
58.0540723,96.39,207,14.3875
58.10659343,96.39,207,14.3875
58.15911456,96.39,208,14.4222
58.21163569,96.39,215,14.6629
58.26415682,96.39,209,14.4568
58.31667795,96.39,225,15
58.36919908,96.39,236,15.3623
58.42172021,96.39,237,15.3948
58.47424134,96.39,262,16.1864
58.52676247,96.39,277,16.6433
58.5792836,96.39,280,16.7332
58.63180473,96.39,323,17.9722
58.68432587,96.39,269,16.4012
58.736847,96.39,275,16.5831
58.78936813,96.39,247,15.7162
58.84188926,96.39,258,16.0624
58.89441039,96.39,237,15.3948
58.94693152,96.39,229,15.1327
58.99945265,96.39,205,14.3178
59.05197378,96.39,225,15
59.10449491,96.39,229,15.1327
59.15701604,96.39,233,15.2643
59.20953717,96.39,207,14.3875
59.2620583,96.39,256,16
59.31457943,96.39,235,15.3297
59.36710056,96.39,255,15.9687
59.4196217,96.39,243,15.5885
59.47214283,96.39,222,14.8997
59.52466396,96.39,192,13.8564
59.57718509,96.39,234,15.2971
59.62970622,96.39,228,15.0997
59.68222735,96.39,228,15.0997
59.73474848,96.39,257,16.0312
59.78726961,96.39,209,14.4568
59.83979074,96.39,196,14
59.89231187,96.39,211,14.5258
59.944833,96.39,235,15.3297
59.99735413,96.39,223,14.9332
60.04987526,96.39,200,14.1421
60.10239639,96.39,207,14.3875
60.15491753,96.39,215,14.6629
60.20743866,96.39,206,14.3527
60.25995979,96.39,204,14.2829
60.31248092,96.39,242,15.5563
60.36500205,96.39,229,15.1327
60.41752318,96.39,256,16
60.47004431,96.39,240,15.4919
60.52256544,96.39,240,15.4919
60.57508657,96.39,283,16.8226
60.6276077,96.39,301,17.3494
60.68012883,96.39,340,18.4391
60.73264996,96.39,325,18.0278
60.78517109,96.39,399,19.975
60.83769222,96.39,367,19.1572
60.89021336,96.39,381,19.5192
60.94273449,96.39,427,20.664
60.99525562,96.39,343,18.5203
61.04777675,96.39,350,18.7083
61.10029788,96.39,303,17.4069
61.15281901,96.39,314,17.72
61.20534014,96.39,346,18.6011
61.25786127,96.39,355,18.8414
61.3103824,96.39,316,17.7764
61.36290353,96.39,282,16.7929
61.41542466,96.39,277,16.6433
61.46794579,96.39,256,16
61.52046692,96.39,252,15.8745
61.57298805,96.39,217,14.7309
61.62550919,96.39,197,14.0357
61.67803032,96.39,265,16.2788
61.73055145,96.39,230,15.1658
61.78307258,96.39,259,16.0935
61.83559371,96.39,277,16.6433
61.88811484,96.39,246,15.6844
61.94063597,96.39,251,15.843
61.9931571,96.39,285,16.8819
62.04567823,96.39,285,16.8819
62.09819936,96.39,342,18.4932
62.15072049,96.39,323,17.9722
62.20324162,96.39,339,18.412
62.25576275,96.39,361,19
62.30828388,96.39,350,18.7083
62.36080502,96.39,275,16.5831
62.41332615,96.39,291,17.0587
62.46584728,96.39,243,15.5885
62.51836841,96.39,265,16.2788
62.57088954,96.39,242,15.5563
62.62341067,96.39,220,14.8324
62.6759318,96.39,247,15.7162
62.72845293,96.39,215,14.6629
62.78097406,96.39,263,16.2173
62.83349519,96.39,225,15
62.88601632,96.39,248,15.748
62.93853745,96.39,225,15
62.99105858,96.39,197,14.0357
63.04357971,96.39,188,13.7113
63.09610084,96.39,202,14.2127
63.14862198,96.39,241,15.5242
63.20114311,96.39,190,13.784
63.25366424,96.39,190,13.784
63.30618537,96.39,181,13.4536
63.3587065,96.39,226,15.0333
63.41122763,96.39,209,14.4568
63.46374876,96.39,212,14.5602
63.51626989,96.39,232,15.2315
63.56879102,96.39,274,16.5529
63.62131215,96.39,261,16.1555
63.67383328,96.39,258,16.0624
63.72635441,96.39,330,18.1659
63.77887554,96.39,321,17.9165
63.83139667,96.39,320,17.8885
63.88391781,96.39,319,17.8606
63.93643894,96.39,276,16.6132
63.98896007,96.39,294,17.1464
64.0414812,96.39,248,15.748
64.09400233,96.39,249,15.7797
64.14652346,96.39,235,15.3297
64.19904459,96.39,303,17.4069
64.25156572,96.39,248,15.748
64.30408685,96.39,305,17.4642
64.35660798,96.39,287,16.9411
64.40912911,96.39,262,16.1864
64.46165024,96.39,254,15.9374
64.51417137,96.39,248,15.748
64.5666925,96.39,235,15.3297
64.61921364,96.39,208,14.4222
64.67173477,96.39,213,14.5945
64.7242559,96.39,177,13.3041
64.77677703,96.39,208,14.4222
64.82929816,96.39,190,13.784
64.88181929,96.39,193,13.8924
64.93434042,96.39,174,13.1909
64.98686155,96.39,194,13.9284