File: Files_organized_for_plots/Quant/C_XRD_150Pure_Spiner_Centroid.csv
[Measurement conditions],,,
Sample identification,Centroid08Dec21_Act12Feb23_B1_0714M_NaOH_LS0173,,
Comment - 1,"Configuration=Reflection-Transmission Spinner 3.0, Owner=arr19, Creation date=3/22/2023 1:21:48 PM",,
Comment - 2,Goniometer=Theta/Theta; Minimum step size 2Theta:0.0001; Minimum step size Omega:0.0001,,
Comment - 3,Sample stage=Reflection-transmission spinner 3.0; Minimum step size Phi:0.1,,
Comment - 4,Diffractometer system=EMPYREAN,,
Comment - 5,"Measurement program=X:\XRD\Cement\Spinner_for_cement.xrdmp, Created identifier={6DF360EA-8E6E-4CFC-907C-F1BFECF51AA2}, Created by=Titus Reed, Id=tmr79, Creation date=2/15/2023 11:27:56 AM",,
Anode material,Cu,,
K-Alpha1 wavelength,1.540598,,
K-Alpha2 wavelength,1.544426,,
Ratio K-Alpha2/K-Alpha1,0.5,,
Divergence slit,Fixed,0.125,
Monochromator used,NO,,
Generator voltage,45,,
Tube current,40,,
File date and time,3/22/2023 14:15,,
Unit cell,,,
h k l, 0 0 0,,
Scan axis,Gonio,,
Scan range,4.994599997,64.99999183,
Scan step size,0.0262606,,
No. of points,2285,,
Scan type,CONTINUOUS,,
Phi,32.2,,
Time per step,96.39,,
Angle, TimePerStep, Intensity, ESD
5.00773028,96.39,1313,36.2353
5.060251411,96.39,1291,35.9305
5.112772541,96.39,1272,35.6651
5.165293672,96.39,1212,34.8138
5.217814803,96.39,1240,35.2136
5.270335934,96.39,1266,35.5809
5.322857064,96.39,1185,34.4238
5.375378195,96.39,1188,34.4674
5.427899326,96.39,1202,34.6699
5.480420456,96.39,1204,34.6987
5.532941587,96.39,1153,33.9559
5.585462718,96.39,1162,34.0881
5.637983849,96.39,1185,34.4238
5.690504979,96.39,1186,34.4384
5.74302611,96.39,1185,34.4238
5.795547241,96.39,1156,34
5.848068371,96.39,1122,33.4963
5.900589502,96.39,1139,33.7491
5.953110633,96.39,1204,34.6987
6.005631763,96.39,1098,33.1361
6.058152894,96.39,1112,33.3467
6.110674025,96.39,1134,33.6749
6.163195156,96.39,1114,33.3766
6.215716286,96.39,1093,33.0606
6.268237417,96.39,1157,34.0147
6.320758548,96.39,1136,33.7046
6.373279678,96.39,1095,33.0908
6.425800809,96.39,1149,33.8969
6.47832194,96.39,1130,33.6155
6.530843071,96.39,1063,32.6037
6.583364201,96.39,1176,34.2929
6.635885332,96.39,1090,33.0151
6.688406463,96.39,1080,32.8634
6.740927593,96.39,1045,32.3265
6.793448724,96.39,1056,32.4962
6.845969855,96.39,1035,32.1714
6.898490986,96.39,1063,32.6037
6.951012116,96.39,1052,32.4345
7.003533247,96.39,1033,32.1403
7.056054378,96.39,1072,32.7414
7.108575508,96.39,1089,33
7.161096639,96.39,1072,32.7414
7.21361777,96.39,1069,32.6956
7.2661389,96.39,1002,31.6544
7.318660031,96.39,1073,32.7567
7.371181162,96.39,1052,32.4345
7.423702293,96.39,1044,32.311
7.476223423,96.39,1072,32.7414
7.528744554,96.39,1045,32.3265
7.581265685,96.39,1074,32.7719
7.633786815,96.39,1005,31.7017
7.686307946,96.39,1037,32.2025
7.738829077,96.39,1019,31.9218
7.791350208,96.39,1088,32.9848
7.843871338,96.39,1093,33.0606
7.896392469,96.39,1063,32.6037
7.9489136,96.39,1048,32.3728
8.00143473,96.39,1047,32.3574
8.053955861,96.39,1123,33.5112
8.106476992,96.39,1157,34.0147
8.158998123,96.39,1218,34.8999
8.211519253,96.39,1114,33.3766
8.264040384,96.39,1062,32.5883
8.316561515,96.39,1047,32.3574
8.369082645,96.39,1004,31.686
8.421603776,96.39,1034,32.1559
8.474124907,96.39,1119,33.4515
8.526646038,96.39,1045,32.3265
8.579167168,96.39,1049,32.3883
8.631688299,96.39,1043,32.2955
8.68420943,96.39,1084,32.9242
8.73673056,96.39,1075,32.7872
8.789251691,96.39,1019,31.9218
8.841772822,96.39,1059,32.5423
8.894293952,96.39,1057,32.5115
8.946815083,96.39,1038,32.218
8.999336214,96.39,1062,32.5883
9.051857345,96.39,1102,33.1964
9.104378475,96.39,1006,31.7175
9.156899606,96.39,1025,32.0156
9.209420737,96.39,1065,32.6343
9.261941867,96.39,1082,32.8938
9.314462998,96.39,1046,32.3419
9.366984129,96.39,1054,32.4654
9.41950526,96.39,1002,31.6544
9.47202639,96.39,996,31.5595
9.524547521,96.39,1066,32.6497
9.577068652,96.39,1012,31.8119
9.629589782,96.39,996,31.5595
9.682110913,96.39,1045,32.3265
9.734632044,96.39,1018,31.9061
9.787153175,96.39,1110,33.3167
9.839674305,96.39,1076,32.8024
9.892195436,96.39,1026,32.0312
9.944716567,96.39,999,31.607
9.997237697,96.39,1019,31.9218
10.04975883,96.39,1019,31.9218
10.10227996,96.39,1018,31.9061
10.15480109,96.39,991,31.4802
10.20732222,96.39,1001,31.6386
10.25984335,96.39,1069,32.6956
10.31236448,96.39,1003,31.6702
10.36488561,96.39,1043,32.2955
10.41740674,96.39,1070,32.7109
10.46992787,96.39,1160,34.0588
10.522449,96.39,1007,31.7333
10.57497014,96.39,1041,32.2645
10.62749127,96.39,1000,31.6228
10.6800124,96.39,1004,31.686
10.73253353,96.39,987,31.4166
10.78505466,96.39,1032,32.1248
10.83757579,96.39,954,30.8869
10.89009692,96.39,962,31.0161
10.94261805,96.39,977,31.257
10.99513918,96.39,980,31.305
11.04766031,96.39,940,30.6594
11.10018144,96.39,955,30.9031
11.15270257,96.39,1012,31.8119
11.2052237,96.39,917,30.282
11.25774483,96.39,986,31.4006
11.31026597,96.39,944,30.7246
11.3627871,96.39,951,30.8383
11.41530823,96.39,958,30.9516
11.46782936,96.39,984,31.3688
11.52035049,96.39,953,30.8707
11.57287162,96.39,891,29.8496
11.62539275,96.39,907,30.1164
11.67791388,96.39,899,29.9833
11.73043501,96.39,875,29.5804
11.78295614,96.39,938,30.6268
11.83547727,96.39,855,29.2404
11.8879984,96.39,888,29.7993
11.94051953,96.39,834,28.8791
11.99304066,96.39,886,29.7658
12.0455618,96.39,852,29.189
12.09808293,96.39,893,29.8831
12.15060406,96.39,921,30.348
12.20312519,96.39,888,29.7993
12.25564632,96.39,885,29.7489
12.30816745,96.39,819,28.6182
12.36068858,96.39,892,29.8664
12.41320971,96.39,921,30.348
12.46573084,96.39,853,29.2062
12.51825197,96.39,820,28.6356
12.5707731,96.39,828,28.775
12.62329423,96.39,813,28.5132
12.67581536,96.39,820,28.6356
12.72833649,96.39,810,28.4605
12.78085763,96.39,837,28.931
12.83337876,96.39,827,28.7576
12.88589989,96.39,827,28.7576
12.93842102,96.39,707,26.5895
12.99094215,96.39,812,28.4956
13.04346328,96.39,766,27.6767
13.09598441,96.39,795,28.1957
13.14850554,96.39,786,28.0357
13.20102667,96.39,764,27.6405
13.2535478,96.39,765,27.6586
13.30606893,96.39,748,27.3496
13.35859006,96.39,743,27.258
13.41111119,96.39,718,26.7955
13.46363232,96.39,790,28.1069
13.51615346,96.39,773,27.8029
13.56867459,96.39,754,27.4591
13.62119572,96.39,757,27.5136
13.67371685,96.39,746,27.313
13.72623798,96.39,762,27.6043
13.77875911,96.39,869,29.4788
13.83128024,96.39,836,28.9137
13.88380137,96.39,783,27.9821
13.9363225,96.39,703,26.5141
13.98884363,96.39,712,26.6833
14.04136476,96.39,712,26.6833
14.09388589,96.39,726,26.9444
14.14640702,96.39,725,26.9258
14.19892815,96.39,889,29.8161
14.25144929,96.39,968,31.1127
14.30397042,96.39,1057,32.5115
14.35649155,96.39,742,27.2397
14.40901268,96.39,767,27.6948
14.46153381,96.39,841,29
14.51405494,96.39,1121,33.4813
14.56657607,96.39,1059,32.5423
14.6190972,96.39,712,26.6833
14.67161833,96.39,701,26.4764
14.72413946,96.39,650,25.4951
14.77666059,96.39,708,26.6083
14.82918172,96.39,671,25.9037
14.88170285,96.39,694,26.3439
14.93422398,96.39,671,25.9037
14.98674512,96.39,679,26.0576
15.03926625,96.39,652,25.5343
15.09178738,96.39,688,26.2298
15.14430851,96.39,784,28
15.19682964,96.39,856,29.2575
15.24935077,96.39,828,28.775
15.3018719,96.39,777,27.8747
15.35439303,96.39,688,26.2298
15.40691416,96.39,637,25.2389
15.45943529,96.39,653,25.5539
15.51195642,96.39,696,26.3818
15.56447755,96.39,610,24.6982
15.61699868,96.39,624,24.98
15.66951981,96.39,643,25.3574
15.72204095,96.39,735,27.1109
15.77456208,96.39,646,25.4165
15.82708321,96.39,642,25.3377
15.87960434,96.39,592,24.3311
15.93212547,96.39,674,25.9615
15.9846466,96.39,621,24.9199
16.03716773,96.39,630,25.0998
16.08968886,96.39,692,26.3059
16.14220999,96.39,643,25.3574
16.19473112,96.39,704,26.533
16.24725225,96.39,726,26.9444
16.29977338,96.39,833,28.8617
16.35229451,96.39,883,29.7153
16.40481564,96.39,715,26.7395
16.45733678,96.39,606,24.6171
16.50985791,96.39,609,24.6779
16.56237904,96.39,657,25.632
16.61490017,96.39,620,24.8998
16.6674213,96.39,662,25.7294
16.71994243,96.39,616,24.8193
16.77246356,96.39,618,24.8596
16.82498469,96.39,665,25.7876
16.87750582,96.39,617,24.8395
16.93002695,96.39,682,26.1151
16.98254808,96.39,607,24.6374
17.03506921,96.39,616,24.8193
17.08759034,96.39,586,24.2074
17.14011147,96.39,637,25.2389
17.19263261,96.39,614,24.779
17.24515374,96.39,601,24.5153
17.29767487,96.39,669,25.865
17.350196,96.39,633,25.1595
17.40271713,96.39,635,25.1992
17.45523826,96.39,644,25.3772
17.50775939,96.39,638,25.2587
17.56028052,96.39,621,24.9199
17.61280165,96.39,626,25.02
17.66532278,96.39,610,24.6982
17.71784391,96.39,614,24.779
17.77036504,96.39,624,24.98
17.82288617,96.39,629,25.0799
17.8754073,96.39,590,24.2899
17.92792843,96.39,634,25.1794
17.98044957,96.39,648,25.4558
18.0329707,96.39,639,25.2784
18.08549183,96.39,634,25.1794
18.13801296,96.39,649,25.4755
18.19053409,96.39,638,25.2587
18.24305522,96.39,690,26.2679
18.29557635,96.39,717,26.7769
18.34809748,96.39,694,26.3439
18.40061861,96.39,623,24.96
18.45313974,96.39,674,25.9615
18.50566087,96.39,626,25.02
18.558182,96.39,619,24.8797
18.61070313,96.39,606,24.6171
18.66322426,96.39,665,25.7876
18.7157454,96.39,696,26.3818
18.76826653,96.39,735,27.1109
18.82078766,96.39,827,28.7576
18.87330879,96.39,978,31.273
18.92582992,96.39,992,31.496
18.97835105,96.39,1116,33.4066
19.03087218,96.39,922,30.3645
19.08339331,96.39,814,28.5307
19.13591444,96.39,743,27.258
19.18843557,96.39,688,26.2298
19.2409567,96.39,697,26.4008
19.29347783,96.39,723,26.8887
19.34599896,96.39,738,27.1662
19.39852009,96.39,696,26.3818
19.45104123,96.39,704,26.533
19.50356236,96.39,712,26.6833
19.55608349,96.39,678,26.0384
19.60860462,96.39,655,25.593
19.66112575,96.39,680,26.0768
19.71364688,96.39,690,26.2679
19.76616801,96.39,773,27.8029
19.81868914,96.39,772,27.7849
19.87121027,96.39,660,25.6905
19.9237314,96.39,727,26.9629
19.97625253,96.39,707,26.5895
20.02877366,96.39,724,26.9072
20.08129479,96.39,656,25.6125
20.13381592,96.39,683,26.1343
20.18633706,96.39,703,26.5141
20.23885819,96.39,735,27.1109
20.29137932,96.39,688,26.2298
20.34390045,96.39,731,27.037
20.39642158,96.39,821,28.6531
20.44894271,96.39,784,28
20.50146384,96.39,695,26.3629
20.55398497,96.39,758,27.5318
20.6065061,96.39,802,28.3196
20.65902723,96.39,825,28.7228
20.71154836,96.39,870,29.4958
20.76406949,96.39,827,28.7576
20.81659062,96.39,759,27.55
20.86911175,96.39,694,26.3439
20.92163289,96.39,767,27.6948
20.97415402,96.39,738,27.1662
21.02667515,96.39,821,28.6531
21.07919628,96.39,671,25.9037
21.13171741,96.39,704,26.533
21.18423854,96.39,771,27.7669
21.23675967,96.39,751,27.4044
21.2892808,96.39,858,29.2916
21.34180193,96.39,848,29.1204
21.39432306,96.39,770,27.7489
21.44684419,96.39,707,26.5895
21.49936532,96.39,726,26.9444
21.55188645,96.39,887,29.7825
21.60440758,96.39,984,31.3688
21.65692872,96.39,928,30.4631
21.70944985,96.39,865,29.4109
21.76197098,96.39,733,27.074
21.81449211,96.39,681,26.096
21.86701324,96.39,735,27.1109
21.91953437,96.39,738,27.1662
21.9720555,96.39,734,27.0924
22.02457663,96.39,696,26.3818
22.07709776,96.39,751,27.4044
22.12961889,96.39,811,28.4781
22.18214002,96.39,735,27.1109
22.23466115,96.39,699,26.4386
22.28718228,96.39,802,28.3196
22.33970341,96.39,787,28.0535
22.39222455,96.39,786,28.0357
22.44474568,96.39,784,28
22.49726681,96.39,787,28.0535
22.54978794,96.39,801,28.3019
22.60230907,96.39,841,29
22.6548302,96.39,789,28.0891
22.70735133,96.39,803,28.3373
22.75987246,96.39,844,29.0517
22.81239359,96.39,951,30.8383
22.86491472,96.39,976,31.241
22.91743585,96.39,888,29.7993
22.96995698,96.39,932,30.5287
23.02247811,96.39,956,30.9192
23.07499924,96.39,939,30.6431
23.12752038,96.39,952,30.8545
23.18004151,96.39,1075,32.7872
23.23256264,96.39,1002,31.6544
23.28508377,96.39,882,29.6985
23.3376049,96.39,915,30.249
23.39012603,96.39,959,30.9677
23.44264716,96.39,908,30.133
23.49516829,96.39,895,29.9166
23.54768942,96.39,915,30.249
23.60021055,96.39,828,28.775
23.65273168,96.39,771,27.7669
23.70525281,96.39,737,27.1477
23.75777394,96.39,774,27.8209
23.81029507,96.39,716,26.7582
23.86281621,96.39,697,26.4008
23.91533734,96.39,684,26.1534
23.96785847,96.39,690,26.2679
24.0203796,96.39,731,27.037
24.07290073,96.39,691,26.2869
24.12542186,96.39,713,26.7021
24.17794299,96.39,695,26.3629
24.23046412,96.39,788,28.0713
24.28298525,96.39,755,27.4773
24.33550638,96.39,673,25.9422
24.38802751,96.39,717,26.7769
24.44054864,96.39,653,25.5539
24.49306977,96.39,709,26.6271
24.5455909,96.39,777,27.8747
24.59811204,96.39,742,27.2397
24.65063317,96.39,621,24.9199
24.7031543,96.39,692,26.3059
24.75567543,96.39,712,26.6833
24.80819656,96.39,627,25.04
24.86071769,96.39,620,24.8998
24.91323882,96.39,688,26.2298
24.96575995,96.39,662,25.7294
25.01828108,96.39,590,24.2899
25.07080221,96.39,603,24.5561
25.12332334,96.39,562,23.7065
25.17584447,96.39,624,24.98
25.2283656,96.39,572,23.9165
25.28088673,96.39,561,23.6854
25.33340786,96.39,599,24.4745
25.385929,96.39,599,24.4745
25.43845013,96.39,619,24.8797
25.49097126,96.39,609,24.6779
25.54349239,96.39,555,23.5584
25.59601352,96.39,583,24.1454
25.64853465,96.39,567,23.8118
25.70105578,96.39,585,24.1868
25.75357691,96.39,582,24.1247
25.80609804,96.39,563,23.7276
25.85861917,96.39,594,24.3721
25.9111403,96.39,577,24.0208
25.96366143,96.39,542,23.2809
26.01618256,96.39,605,24.5967
26.06870369,96.39,573,23.9374
26.12122483,96.39,545,23.3452
26.17374596,96.39,539,23.2164
26.22626709,96.39,527,22.9565
26.27878822,96.39,526,22.9347
26.33130935,96.39,509,22.561
26.38383048,96.39,550,23.4521
26.43635161,96.39,496,22.2711
26.48887274,96.39,588,24.2487
26.54139387,96.39,517,22.7376
26.593915,96.39,550,23.4521
26.64643613,96.39,588,24.2487
26.69895726,96.39,646,25.4165
26.75147839,96.39,796,28.2135
26.80399952,96.39,849,29.1376
26.85652066,96.39,772,27.7849
26.90904179,96.39,709,26.6271
26.96156292,96.39,739,27.1846
27.01408405,96.39,804,28.3549
27.06660518,96.39,852,29.189
27.11912631,96.39,884,29.7321
27.17164744,96.39,1001,31.6386
27.22416857,96.39,1001,31.6386
27.2766897,96.39,777,27.8747
27.32921083,96.39,635,25.1992
27.38173196,96.39,591,24.3105
27.43425309,96.39,563,23.7276
27.48677422,96.39,510,22.5832
27.53929535,96.39,518,22.7596
27.59181649,96.39,583,24.1454
27.64433762,96.39,539,23.2164
27.69685875,96.39,542,23.2809
27.74937988,96.39,549,23.4307
27.80190101,96.39,561,23.6854
27.85442214,96.39,492,22.1811
27.90694327,96.39,503,22.4277
27.9594644,96.39,517,22.7376
28.01198553,96.39,526,22.9347
28.06450666,96.39,507,22.5167
28.11702779,96.39,535,23.1301
28.16954892,96.39,521,22.8254
28.22207005,96.39,565,23.7697
28.27459118,96.39,527,22.9565
28.32711232,96.39,538,23.1948
28.37963345,96.39,589,24.2693
28.43215458,96.39,566,23.7908
28.48467571,96.39,564,23.7487
28.53719684,96.39,552,23.4947
28.58971797,96.39,587,24.2281
28.6422391,96.39,551,23.4734
28.69476023,96.39,526,22.9347
28.74728136,96.39,489,22.1133
28.79980249,96.39,531,23.0434
28.85232362,96.39,586,24.2074
28.90484475,96.39,549,23.4307
28.95736588,96.39,614,24.779
29.00988701,96.39,571,23.8956
29.06240815,96.39,585,24.1868
29.11492928,96.39,655,25.593
29.16745041,96.39,718,26.7955
29.21997154,96.39,716,26.7582
29.27249267,96.39,882,29.6985
29.3250138,96.39,981,31.3209
29.37753493,96.39,820,28.6356
29.43005606,96.39,794,28.178
29.48257719,96.39,821,28.6531
29.53509832,96.39,808,28.4253
29.58761945,96.39,725,26.9258
29.64014058,96.39,707,26.5895
29.69266171,96.39,618,24.8596
29.74518284,96.39,616,24.8193
29.79770398,96.39,554,23.5372
29.85022511,96.39,581,24.1039
29.90274624,96.39,534,23.1084
29.95526737,96.39,554,23.5372
30.0077885,96.39,552,23.4947
30.06030963,96.39,526,22.9347
30.11283076,96.39,540,23.2379
30.16535189,96.39,534,23.1084
30.21787302,96.39,530,23.0217
30.27039415,96.39,525,22.9129
30.32291528,96.39,535,23.1301
30.37543641,96.39,545,23.3452
30.42795754,96.39,561,23.6854
30.48047867,96.39,596,24.4131
30.53299981,96.39,583,24.1454
30.58552094,96.39,595,24.3926
30.63804207,96.39,631,25.1197
30.6905632,96.39,708,26.6083
30.74308433,96.39,646,25.4165
30.79560546,96.39,701,26.4764
30.84812659,96.39,676,26
30.90064772,96.39,599,24.4745
30.95316885,96.39,613,24.7588
31.00568998,96.39,549,23.4307
31.05821111,96.39,542,23.2809
31.11073224,96.39,621,24.9199
31.16325337,96.39,622,24.9399
31.2157745,96.39,724,26.9072
31.26829564,96.39,865,29.4109
31.32081677,96.39,910,30.1662
31.3733379,96.39,903,30.05
31.42585903,96.39,778,27.8927
31.47838016,96.39,670,25.8844
31.53090129,96.39,608,24.6577
31.58342242,96.39,610,24.6982
31.63594355,96.39,614,24.779
31.68846468,96.39,971,31.1609
31.74098581,96.39,1260,35.4965
31.79350694,96.39,783,27.9821
31.84602807,96.39,722,26.8701
31.8985492,96.39,640,25.2982
31.95107033,96.39,699,26.4386
32.00359147,96.39,698,26.4197
32.0561126,96.39,637,25.2389
32.10863373,96.39,708,26.6083
32.16115486,96.39,630,25.0998
32.21367599,96.39,695,26.3629
32.26619712,96.39,870,29.4958
32.31871825,96.39,728,26.9815
32.37123938,96.39,651,25.5147
32.42376051,96.39,581,24.1039
32.47628164,96.39,506,22.4944
32.52880277,96.39,508,22.5389
32.5813239,96.39,565,23.7697
32.63384503,96.39,582,24.1247
32.68636616,96.39,595,24.3926
32.7388873,96.39,604,24.5764
32.79140843,96.39,564,23.7487
32.84392956,96.39,590,24.2899
32.89645069,96.39,599,24.4745
32.94897182,96.39,615,24.7992
33.00149295,96.39,645,25.3969
33.05401408,96.39,649,25.4755
33.10653521,96.39,644,25.3772
33.15905634,96.39,612,24.7386
33.21157747,96.39,588,24.2487
33.2640986,96.39,620,24.8998
33.31661973,96.39,606,24.6171
33.36914086,96.39,550,23.4521
33.42166199,96.39,588,24.2487
33.47418312,96.39,593,24.3516
33.52670426,96.39,541,23.2594
33.57922539,96.39,554,23.5372
33.63174652,96.39,592,24.3311
33.68426765,96.39,544,23.3238
33.73678878,96.39,525,22.9129
33.78930991,96.39,570,23.8747
33.84183104,96.39,546,23.3666
33.89435217,96.39,602,24.5357
33.9468733,96.39,559,23.6432
33.99939443,96.39,553,23.516
34.05191556,96.39,523,22.8692
34.10443669,96.39,564,23.7487
34.15695782,96.39,561,23.6854
34.20947895,96.39,617,24.8395
34.26200009,96.39,601,24.5153
34.31452122,96.39,666,25.807
34.36704235,96.39,665,25.7876
34.41956348,96.39,701,26.4764
34.47208461,96.39,786,28.0357
34.52460574,96.39,957,30.9354
34.57712687,96.39,1054,32.4654
34.629648,96.39,993,31.5119
34.68216913,96.39,914,30.2324
34.73469026,96.39,715,26.7395
34.78721139,96.39,697,26.4008
34.83973252,96.39,695,26.3629
34.89225365,96.39,719,26.8142
34.94477478,96.39,740,27.2029
34.99729592,96.39,733,27.074
35.04981705,96.39,754,27.4591
35.10233818,96.39,679,26.0576
35.15485931,96.39,704,26.533
35.20738044,96.39,809,28.4429
35.25990157,96.39,742,27.2397
35.3124227,96.39,651,25.5147
35.36494383,96.39,621,24.9199
35.41746496,96.39,600,24.4949
35.46998609,96.39,567,23.8118
35.52250722,96.39,590,24.2899
35.57502835,96.39,583,24.1454
35.62754948,96.39,588,24.2487
35.68007061,96.39,633,25.1595
35.73259175,96.39,600,24.4949
35.78511288,96.39,572,23.9165
35.83763401,96.39,648,25.4558
35.89015514,96.39,687,26.2107
35.94267627,96.39,888,29.7993
35.9951974,96.39,826,28.7402
36.04771853,96.39,800,28.2843
36.10023966,96.39,780,27.9285
36.15276079,96.39,778,27.8927
36.20528192,96.39,919,30.315
36.25780305,96.39,814,28.5307
36.31032418,96.39,745,27.2947
36.36284531,96.39,665,25.7876
36.41536644,96.39,604,24.5764
36.46788758,96.39,512,22.6274
36.52040871,96.39,521,22.8254
36.57292984,96.39,511,22.6053
36.62545097,96.39,493,22.2036
36.6779721,96.39,473,21.7486
36.73049323,96.39,510,22.5832
36.78301436,96.39,474,21.7715
36.83553549,96.39,461,21.4709
36.88805662,96.39,446,21.1187
36.94057775,96.39,496,22.2711
36.99309888,96.39,503,22.4277
37.04562001,96.39,503,22.4277
37.09814114,96.39,490,22.1359
37.15066227,96.39,525,22.9129
37.20318341,96.39,537,23.1733
37.25570454,96.39,575,23.9792
37.30822567,96.39,471,21.7025
37.3607468,96.39,522,22.8473
37.41326793,96.39,534,23.1084
37.46578906,96.39,598,24.454
37.51831019,96.39,551,23.4734
37.57083132,96.39,578,24.0416
37.62335245,96.39,521,22.8254
37.67587358,96.39,540,23.2379
37.72839471,96.39,484,22
37.78091584,96.39,563,23.7276
37.83343697,96.39,606,24.6171
37.8859581,96.39,668,25.8457
37.93847924,96.39,626,25.02
37.99100037,96.39,637,25.2389
38.0435215,96.39,507,22.5167
38.09604263,96.39,533,23.0868
38.14856376,96.39,572,23.9165
38.20108489,96.39,557,23.6008
38.25360602,96.39,540,23.2379
38.30612715,96.39,491,22.1585
38.35864828,96.39,540,23.2379
38.41116941,96.39,453,21.2838
38.46369054,96.39,443,21.0476
38.51621167,96.39,466,21.587
38.5687328,96.39,457,21.3776
38.62125393,96.39,431,20.7605
38.67377507,96.39,469,21.6564
38.7262962,96.39,462,21.4942
38.77881733,96.39,467,21.6102
38.83133846,96.39,487,22.0681
38.88385959,96.39,424,20.5913
38.93638072,96.39,425,20.6155
38.98890185,96.39,411,20.2731
39.04142298,96.39,453,21.2838
39.09394411,96.39,428,20.6882
39.14646524,96.39,461,21.4709
39.19898637,96.39,461,21.4709
39.2515075,96.39,448,21.166
39.30402863,96.39,452,21.2603
39.35654976,96.39,446,21.1187
39.4090709,96.39,417,20.4206
39.46159203,96.39,438,20.9284
39.51411316,96.39,435,20.8567
39.56663429,96.39,436,20.8806
39.61915542,96.39,440,20.9762
39.67167655,96.39,449,21.1896
39.72419768,96.39,459,21.4243
39.77671881,96.39,442,21.0238
39.82923994,96.39,514,22.6716
39.88176107,96.39,434,20.8327
39.9342822,96.39,451,21.2368
39.98680333,96.39,435,20.8567
40.03932446,96.39,407,20.1742
40.09184559,96.39,393,19.8242
40.14436673,96.39,430,20.7364
40.19688786,96.39,382,19.5448
40.24940899,96.39,385,19.6214
40.30193012,96.39,405,20.1246
40.35445125,96.39,357,18.8944
40.40697238,96.39,383,19.5704
40.45949351,96.39,376,19.3907
40.51201464,96.39,432,20.7846
40.56453577,96.39,390,19.7484
40.6170569,96.39,404,20.0998
40.66957803,96.39,442,21.0238
40.72209916,96.39,429,20.7123
40.77462029,96.39,353,18.7883
40.82714142,96.39,375,19.3649
40.87966255,96.39,378,19.4422
40.93218369,96.39,405,20.1246
40.98470482,96.39,357,18.8944
41.03722595,96.39,349,18.6815
41.08974708,96.39,355,18.8414
41.14226821,96.39,375,19.3649
41.19478934,96.39,372,19.2873
41.24731047,96.39,356,18.868
41.2998316,96.39,379,19.4679
41.35235273,96.39,395,19.8746
41.40487386,96.39,349,18.6815
41.45739499,96.39,346,18.6011
41.50991612,96.39,314,17.72
41.56243725,96.39,397,19.9249
41.61495838,96.39,360,18.9737
41.66747952,96.39,347,18.6279
41.72000065,96.39,390,19.7484
41.77252178,96.39,425,20.6155
41.82504291,96.39,371,19.2614
41.87756404,96.39,372,19.2873
41.93008517,96.39,355,18.8414
41.9826063,96.39,396,19.8997
42.03512743,96.39,390,19.7484
42.08764856,96.39,448,21.166
42.14016969,96.39,552,23.4947
42.19269082,96.39,481,21.9317
42.24521195,96.39,504,22.4499
42.29773308,96.39,420,20.4939
42.35025421,96.39,412,20.2978
42.40277535,96.39,322,17.9444
42.45529648,96.39,368,19.1833
42.50781761,96.39,339,18.412
42.56033874,96.39,323,17.9722
42.61285987,96.39,358,18.9209
42.665381,96.39,398,19.9499
42.71790213,96.39,417,20.4206
42.77042326,96.39,444,21.0713
42.82294439,96.39,360,18.9737
42.87546552,96.39,419,20.4695
42.92798665,96.39,322,17.9444
42.98050778,96.39,305,17.4642
43.03302891,96.39,402,20.0499
43.08555004,96.39,360,18.9737
43.13807118,96.39,375,19.3649
43.19059231,96.39,327,18.0831
43.24311344,96.39,339,18.412
43.29563457,96.39,359,18.9473
43.3481557,96.39,306,17.4929
43.40067683,96.39,343,18.5203
43.45319796,96.39,339,18.412
43.50571909,96.39,367,19.1572
43.55824022,96.39,294,17.1464
43.61076135,96.39,338,18.3848
43.66328248,96.39,358,18.9209
43.71580361,96.39,344,18.5472
43.76832474,96.39,350,18.7083
43.82084587,96.39,357,18.8944
43.87336701,96.39,319,17.8606
43.92588814,96.39,383,19.5704
43.97840927,96.39,339,18.412
44.0309304,96.39,349,18.6815
44.08345153,96.39,360,18.9737
44.13597266,96.39,330,18.1659
44.18849379,96.39,413,20.3224
44.24101492,96.39,405,20.1246
44.29353605,96.39,374,19.3391
44.34605718,96.39,406,20.1494
44.39857831,96.39,384,19.5959
44.45109944,96.39,393,19.8242
44.50362057,96.39,376,19.3907
44.5561417,96.39,359,18.9473
44.60866284,96.39,373,19.3132
44.66118397,96.39,368,19.1833
44.7137051,96.39,409,20.2237
44.76622623,96.39,417,20.4206
44.81874736,96.39,393,19.8242
44.87126849,96.39,412,20.2978
44.92378962,96.39,375,19.3649
44.97631075,96.39,390,19.7484
45.02883188,96.39,375,19.3649
45.08135301,96.39,354,18.8149
45.13387414,96.39,393,19.8242
45.18639527,96.39,361,19
45.2389164,96.39,350,18.7083
45.29143753,96.39,373,19.3132
45.34395867,96.39,352,18.7617
45.3964798,96.39,372,19.2873
45.44900093,96.39,367,19.1572
45.50152206,96.39,338,18.3848
45.55404319,96.39,383,19.5704
45.60656432,96.39,364,19.0788
45.65908545,96.39,374,19.3391
45.71160658,96.39,424,20.5913
45.76412771,96.39,326,18.0555
45.81664884,96.39,374,19.3391
45.86916997,96.39,383,19.5704
45.9216911,96.39,370,19.2354
45.97421223,96.39,354,18.8149
46.02673336,96.39,360,18.9737
46.0792545,96.39,429,20.7123
46.13177563,96.39,460,21.4476
46.18429676,96.39,488,22.0907
46.23681789,96.39,522,22.8473
46.28933902,96.39,617,24.8395
46.34186015,96.39,489,22.1133
46.39438128,96.39,506,22.4944
46.44690241,96.39,425,20.6155
46.49942354,96.39,454,21.3073
46.55194467,96.39,415,20.3715
46.6044658,96.39,383,19.5704
46.65698693,96.39,387,19.6723
46.70950806,96.39,398,19.9499
46.76202919,96.39,334,18.2757
46.81455033,96.39,382,19.5448
46.86707146,96.39,415,20.3715
46.91959259,96.39,356,18.868
46.97211372,96.39,357,18.8944
47.02463485,96.39,363,19.0526
47.07715598,96.39,343,18.5203
47.12967711,96.39,375,19.3649
47.18219824,96.39,322,17.9444
47.23471937,96.39,366,19.1311
47.2872405,96.39,381,19.5192
47.33976163,96.39,389,19.7231
47.39228276,96.39,371,19.2614
47.44480389,96.39,403,20.0749
47.49732502,96.39,410,20.2485
47.54984616,96.39,392,19.799
47.60236729,96.39,401,20.025
47.65488842,96.39,390,19.7484
47.70740955,96.39,390,19.7484
47.75993068,96.39,410,20.2485
47.81245181,96.39,382,19.5448
47.86497294,96.39,358,18.9209
47.91749407,96.39,384,19.5959
47.9700152,96.39,365,19.105
48.02253633,96.39,332,18.2209
48.07505746,96.39,315,17.7482
48.12757859,96.39,356,18.868
48.18009972,96.39,389,19.7231
48.23262085,96.39,363,19.0526
48.28514198,96.39,361,19
48.33766312,96.39,356,18.868
48.39018425,96.39,402,20.0499
48.44270538,96.39,404,20.0998
48.49522651,96.39,413,20.3224
48.54774764,96.39,430,20.7364
48.60026877,96.39,390,19.7484
48.6527899,96.39,341,18.4662
48.70531103,96.39,342,18.4932
48.75783216,96.39,293,17.1172
48.81035329,96.39,324,18
48.86287442,96.39,310,17.6068
48.91539555,96.39,307,17.5214
48.96791668,96.39,303,17.4069
49.02043781,96.39,317,17.8045
49.07295895,96.39,372,19.2873
49.12548008,96.39,343,18.5203
49.17800121,96.39,356,18.868
49.23052234,96.39,326,18.0555
49.28304347,96.39,337,18.3576
49.3355646,96.39,315,17.7482
49.38808573,96.39,356,18.868
49.44060686,96.39,337,18.3576
49.49312799,96.39,303,17.4069
49.54564912,96.39,331,18.1934
49.59817025,96.39,333,18.2483
49.65069138,96.39,373,19.3132
49.70321251,96.39,354,18.8149
49.75573364,96.39,368,19.1833
49.80825478,96.39,331,18.1934
49.86077591,96.39,359,18.9473
49.91329704,96.39,351,18.735
49.96581817,96.39,311,17.6352
50.0183393,96.39,290,17.0294
50.07086043,96.39,331,18.1934
50.12338156,96.39,315,17.7482
50.17590269,96.39,290,17.0294
50.22842382,96.39,312,17.6635
50.28094495,96.39,298,17.2627
50.33346608,96.39,299,17.2916
50.38598721,96.39,340,18.4391
50.43850834,96.39,373,19.3132
50.49102947,96.39,414,20.347
50.54355061,96.39,384,19.5959
50.59607174,96.39,356,18.868
50.64859287,96.39,310,17.6068
50.701114,96.39,333,18.2483
50.75363513,96.39,348,18.6548
50.80615626,96.39,321,17.9165
50.85867739,96.39,357,18.8944
50.91119852,96.39,314,17.72
50.96371965,96.39,316,17.7764
51.01624078,96.39,376,19.3907
51.06876191,96.39,319,17.8606
51.12128304,96.39,322,17.9444
51.17380417,96.39,360,18.9737
51.2263253,96.39,323,17.9722
51.27884644,96.39,314,17.72
51.33136757,96.39,272,16.4924
51.3838887,96.39,308,17.5499
51.43640983,96.39,262,16.1864
51.48893096,96.39,301,17.3494
51.54145209,96.39,280,16.7332
51.59397322,96.39,293,17.1172
51.64649435,96.39,294,17.1464
51.69901548,96.39,318,17.8326
51.75153661,96.39,295,17.1756
51.80405774,96.39,302,17.3781
51.85657887,96.39,303,17.4069
51.9091,96.39,322,17.9444
51.96162113,96.39,266,16.3095
52.01414227,96.39,305,17.4642
52.0666634,96.39,283,16.8226
52.11918453,96.39,276,16.6132
52.17170566,96.39,280,16.7332
52.22422679,96.39,308,17.5499
52.27674792,96.39,297,17.2337
52.32926905,96.39,277,16.6433
52.38179018,96.39,288,16.9706
52.43431131,96.39,289,17
52.48683244,96.39,285,16.8819
52.53935357,96.39,290,17.0294
52.5918747,96.39,292,17.088
52.64439583,96.39,289,17
52.69691696,96.39,277,16.6433
52.7494381,96.39,301,17.3494
52.80195923,96.39,270,16.4317
52.85448036,96.39,288,16.9706
52.90700149,96.39,302,17.3781
52.95952262,96.39,305,17.4642
53.01204375,96.39,251,15.843
53.06456488,96.39,289,17
53.11708601,96.39,250,15.8114
53.16960714,96.39,305,17.4642
53.22212827,96.39,289,17
53.2746494,96.39,281,16.7631
53.32717053,96.39,262,16.1864
53.37969166,96.39,302,17.3781
53.43221279,96.39,277,16.6433
53.48473393,96.39,260,16.1245
53.53725506,96.39,281,16.7631
53.58977619,96.39,271,16.4621
53.64229732,96.39,274,16.5529
53.69481845,96.39,265,16.2788
53.74733958,96.39,274,16.5529
53.79986071,96.39,295,17.1756
53.85238184,96.39,337,18.3576
53.90490297,96.39,318,17.8326
53.9574241,96.39,368,19.1833
54.00994523,96.39,320,17.8885
54.06246636,96.39,300,17.3205
54.11498749,96.39,294,17.1464
54.16750862,96.39,323,17.9722
54.22002976,96.39,335,18.303
54.27255089,96.39,313,17.6918
54.32507202,96.39,305,17.4642
54.37759315,96.39,335,18.303
54.43011428,96.39,292,17.088
54.48263541,96.39,274,16.5529
54.53515654,96.39,270,16.4317
54.58767767,96.39,273,16.5227
54.6401988,96.39,255,15.9687
54.69271993,96.39,235,15.3297
54.74524106,96.39,299,17.2916
54.79776219,96.39,258,16.0624
54.85028332,96.39,240,15.4919
54.90280445,96.39,243,15.5885
54.95532559,96.39,268,16.3707
55.00784672,96.39,272,16.4924
55.06036785,96.39,240,15.4919
55.11288898,96.39,282,16.7929
55.16541011,96.39,229,15.1327
55.21793124,96.39,239,15.4596
55.27045237,96.39,260,16.1245
55.3229735,96.39,269,16.4012
55.37549463,96.39,246,15.6844
55.42801576,96.39,294,17.1464
55.48053689,96.39,267,16.3401
55.53305802,96.39,262,16.1864
55.58557915,96.39,222,14.8997
55.63810028,96.39,265,16.2788
55.69062141,96.39,240,15.4919
55.74314255,96.39,236,15.3623
55.79566368,96.39,264,16.2481
55.84818481,96.39,258,16.0624
55.90070594,96.39,243,15.5885
55.95322707,96.39,255,15.9687
56.0057482,96.39,284,16.8523
56.05826933,96.39,292,17.088
56.11079046,96.39,253,15.906
56.16331159,96.39,271,16.4621
56.21583272,96.39,277,16.6433
56.26835385,96.39,295,17.1756
56.32087498,96.39,264,16.2481
56.37339611,96.39,248,15.748
56.42591724,96.39,255,15.9687
56.47843838,96.39,278,16.6733
56.53095951,96.39,271,16.4621
56.58348064,96.39,255,15.9687
56.63600177,96.39,251,15.843
56.6885229,96.39,242,15.5563
56.74104403,96.39,236,15.3623
56.79356516,96.39,237,15.3948
56.84608629,96.39,231,15.1987
56.89860742,96.39,238,15.4272
56.95112855,96.39,251,15.843
57.00364968,96.39,241,15.5242
57.05617081,96.39,253,15.906
57.10869194,96.39,251,15.843
57.16121307,96.39,289,17
57.21373421,96.39,269,16.4012
57.26625534,96.39,257,16.0312
57.31877647,96.39,269,16.4012
57.3712976,96.39,251,15.843
57.42381873,96.39,232,15.2315
57.47633986,96.39,256,16
57.52886099,96.39,252,15.8745
57.58138212,96.39,267,16.3401
57.63390325,96.39,284,16.8523
57.68642438,96.39,257,16.0312
57.73894551,96.39,281,16.7631
57.79146664,96.39,270,16.4317
57.84398777,96.39,271,16.4621
57.8965089,96.39,291,17.0587
57.94903004,96.39,260,16.1245
58.00155117,96.39,263,16.2173
58.0540723,96.39,286,16.9115
58.10659343,96.39,248,15.748
58.15911456,96.39,250,15.8114
58.21163569,96.39,262,16.1864
58.26415682,96.39,243,15.5885
58.31667795,96.39,254,15.9374
58.36919908,96.39,233,15.2643
58.42172021,96.39,255,15.9687
58.47424134,96.39,255,15.9687
58.52676247,96.39,230,15.1658
58.5792836,96.39,222,14.8997
58.63180473,96.39,253,15.906
58.68432587,96.39,234,15.2971
58.736847,96.39,235,15.3297
58.78936813,96.39,220,14.8324
58.84188926,96.39,252,15.8745
58.89441039,96.39,224,14.9666
58.94693152,96.39,242,15.5563
58.99945265,96.39,254,15.9374
59.05197378,96.39,243,15.5885
59.10449491,96.39,241,15.5242
59.15701604,96.39,277,16.6433
59.20953717,96.39,251,15.843
59.2620583,96.39,217,14.7309
59.31457943,96.39,250,15.8114
59.36710056,96.39,244,15.6205
59.4196217,96.39,247,15.7162
59.47214283,96.39,207,14.3875
59.52466396,96.39,242,15.5563
59.57718509,96.39,251,15.843
59.62970622,96.39,224,14.9666
59.68222735,96.39,236,15.3623
59.73474848,96.39,236,15.3623
59.78726961,96.39,230,15.1658
59.83979074,96.39,241,15.5242
59.89231187,96.39,269,16.4012
59.944833,96.39,255,15.9687
59.99735413,96.39,261,16.1555
60.04987526,96.39,288,16.9706
60.10239639,96.39,250,15.8114
60.15491753,96.39,272,16.4924
60.20743866,96.39,267,16.3401
60.25995979,96.39,263,16.2173
60.31248092,96.39,292,17.088
60.36500205,96.39,272,16.4924
60.41752318,96.39,296,17.2047
60.47004431,96.39,287,16.9411
60.52256544,96.39,293,17.1172
60.57508657,96.39,342,18.4932
60.6276077,96.39,318,17.8326
60.68012883,96.39,368,19.1833
60.73264996,96.39,345,18.5742
60.78517109,96.39,337,18.3576
60.83769222,96.39,366,19.1311
60.89021336,96.39,383,19.5704
60.94273449,96.39,367,19.1572
60.99525562,96.39,359,18.9473
61.04777675,96.39,392,19.799
61.10029788,96.39,387,19.6723
61.15281901,96.39,400,20
61.20534014,96.39,359,18.9473
61.25786127,96.39,360,18.9737
61.3103824,96.39,394,19.8494
61.36290353,96.39,375,19.3649
61.41542466,96.39,375,19.3649
61.46794579,96.39,384,19.5959
61.52046692,96.39,374,19.3391
61.57298805,96.39,394,19.8494
61.62550919,96.39,364,19.0788
61.67803032,96.39,351,18.735
61.73055145,96.39,343,18.5203
61.78307258,96.39,351,18.735
61.83559371,96.39,337,18.3576
61.88811484,96.39,314,17.72
61.94063597,96.39,298,17.2627
61.9931571,96.39,331,18.1934
62.04567823,96.39,333,18.2483
62.09819936,96.39,342,18.4932
62.15072049,96.39,324,18
62.20324162,96.39,309,17.5784
62.25576275,96.39,353,18.7883
62.30828388,96.39,317,17.8045
62.36080502,96.39,309,17.5784
62.41332615,96.39,260,16.1245
62.46584728,96.39,306,17.4929
62.51836841,96.39,313,17.6918
62.57088954,96.39,318,17.8326
62.62341067,96.39,282,16.7929
62.6759318,96.39,303,17.4069
62.72845293,96.39,269,16.4012
62.78097406,96.39,264,16.2481
62.83349519,96.39,294,17.1464
62.88601632,96.39,263,16.2173
62.93853745,96.39,259,16.0935
62.99105858,96.39,243,15.5885
63.04357971,96.39,226,15.0333
63.09610084,96.39,287,16.9411
63.14862198,96.39,225,15
63.20114311,96.39,236,15.3623
63.25366424,96.39,256,16
63.30618537,96.39,243,15.5885
63.3587065,96.39,262,16.1864
63.41122763,96.39,247,15.7162
63.46374876,96.39,228,15.0997
63.51626989,96.39,232,15.2315
63.56879102,96.39,220,14.8324
63.62131215,96.39,247,15.7162
63.67383328,96.39,240,15.4919
63.72635441,96.39,241,15.5242
63.77887554,96.39,242,15.5563
63.83139667,96.39,252,15.8745
63.88391781,96.39,235,15.3297
63.93643894,96.39,232,15.2315
63.98896007,96.39,208,14.4222
64.0414812,96.39,227,15.0665
64.09400233,96.39,222,14.8997
64.14652346,96.39,229,15.1327
64.19904459,96.39,214,14.6287
64.25156572,96.39,231,15.1987
64.30408685,96.39,227,15.0665
64.35660798,96.39,225,15
64.40912911,96.39,204,14.2829
64.46165024,96.39,210,14.4914
64.51417137,96.39,192,13.8564
64.5666925,96.39,203,14.2478
64.61921364,96.39,226,15.0333
64.67173477,96.39,236,15.3623
64.7242559,96.39,202,14.2127
64.77677703,96.39,218,14.7648
64.82929816,96.39,196,14
64.88181929,96.39,198,14.0712
64.93434042,96.39,215,14.6629
64.98686155,96.39,185,13.6015