File: Files_organized_for_plots/Quant/F_XRD_153QuantSpiner_Mg-Corner.csv
[Measurement conditions],,,
Sample identification,153_MgCorner11May22_Act12Feb23_B1_0714M_NaOH_LS0173,,
Comment - 1,"Configuration=Reflection-Transmission Spinner 3.0, Owner=arr19, Creation date=3/22/2023 1:21:48 PM",,
Comment - 2,Goniometer=Theta/Theta; Minimum step size 2Theta:0.0001; Minimum step size Omega:0.0001,,
Comment - 3,Sample stage=Reflection-transmission spinner 3.0; Minimum step size Phi:0.1,,
Comment - 4,Diffractometer system=EMPYREAN,,
Comment - 5,"Measurement program=X:\XRD\Cement\Spinner_for_cement.xrdmp, Created identifier={6DF360EA-8E6E-4CFC-907C-F1BFECF51AA2}, Created by=Titus Reed, Id=tmr79, Creation date=2/15/2023 11:27:56 AM",,
Anode material,Cu,,
K-Alpha1 wavelength,1.540598,,
K-Alpha2 wavelength,1.544426,,
Ratio K-Alpha2/K-Alpha1,0.5,,
Divergence slit,Fixed,0.125,
Monochromator used,NO,,
Generator voltage,45,,
Tube current,40,,
File date and time,3/22/2023 13:54,,
Unit cell,,,
h k l, 0 0 0,,
Scan axis,Gonio,,
Scan range,4.994599997,64.99999183,
Scan step size,0.0262606,,
No. of points,2285,,
Scan type,CONTINUOUS,,
Phi,43.1,,
Time per step,96.39,,
Angle, TimePerStep, Intensity, ESD
5.00773028,96.39,1597,39.9625
5.060251411,96.39,1593,39.9124
5.112772541,96.39,1590,39.8748
5.165293672,96.39,1558,39.4715
5.217814803,96.39,1528,39.0896
5.270335934,96.39,1575,39.6863
5.322857064,96.39,1512,38.8844
5.375378195,96.39,1566,39.5727
5.427899326,96.39,1390,37.2827
5.480420456,96.39,1457,38.1707
5.532941587,96.39,1497,38.6911
5.585462718,96.39,1502,38.7556
5.637983849,96.39,1487,38.5616
5.690504979,96.39,1459,38.1969
5.74302611,96.39,1452,38.1051
5.795547241,96.39,1465,38.2753
5.848068371,96.39,1417,37.6431
5.900589502,96.39,1344,36.6606
5.953110633,96.39,1378,37.1214
6.005631763,96.39,1380,37.1484
6.058152894,96.39,1335,36.5377
6.110674025,96.39,1447,38.0395
6.163195156,96.39,1408,37.5233
6.215716286,96.39,1355,36.8103
6.268237417,96.39,1343,36.647
6.320758548,96.39,1318,36.3043
6.373279678,96.39,1390,37.2827
6.425800809,96.39,1319,36.318
6.47832194,96.39,1286,35.8608
6.530843071,96.39,1284,35.8329
6.583364201,96.39,1274,35.6931
6.635885332,96.39,1309,36.1801
6.688406463,96.39,1310,36.1939
6.740927593,96.39,1306,36.1386
6.793448724,96.39,1244,35.2704
6.845969855,96.39,1225,35
6.898490986,96.39,1308,36.1663
6.951012116,96.39,1201,34.6554
7.003533247,96.39,1216,34.8712
7.056054378,96.39,1330,36.4692
7.108575508,96.39,1221,34.9428
7.161096639,96.39,1205,34.7131
7.21361777,96.39,1233,35.1141
7.2661389,96.39,1244,35.2704
7.318660031,96.39,1247,35.3129
7.371181162,96.39,1243,35.2562
7.423702293,96.39,1241,35.2278
7.476223423,96.39,1224,34.9857
7.528744554,96.39,1116,33.4066
7.581265685,96.39,1191,34.5109
7.633786815,96.39,1205,34.7131
7.686307946,96.39,1143,33.8083
7.738829077,96.39,1151,33.9264
7.791350208,96.39,1219,34.9142
7.843871338,96.39,1124,33.5261
7.896392469,96.39,1208,34.7563
7.9489136,96.39,1188,34.4674
8.00143473,96.39,1169,34.1906
8.053955861,96.39,1143,33.8083
8.106476992,96.39,1138,33.7343
8.158998123,96.39,1146,33.8526
8.211519253,96.39,1095,33.0908
8.264040384,96.39,1089,33
8.316561515,96.39,1093,33.0606
8.369082645,96.39,1062,32.5883
8.421603776,96.39,1095,33.0908
8.474124907,96.39,1083,32.909
8.526646038,96.39,1075,32.7872
8.579167168,96.39,1099,33.1512
8.631688299,96.39,1051,32.4191
8.68420943,96.39,1052,32.4345
8.73673056,96.39,998,31.5911
8.789251691,96.39,1152,33.9411
8.841772822,96.39,997,31.5753
8.894293952,96.39,1028,32.0624
8.946815083,96.39,1069,32.6956
8.999336214,96.39,1010,31.7805
9.051857345,96.39,1047,32.3574
9.104378475,96.39,1084,32.9242
9.156899606,96.39,1020,31.9374
9.209420737,96.39,1056,32.4962
9.261941867,96.39,1064,32.619
9.314462998,96.39,1046,32.3419
9.366984129,96.39,1098,33.1361
9.41950526,96.39,1046,32.3419
9.47202639,96.39,1048,32.3728
9.524547521,96.39,1007,31.7333
9.577068652,96.39,1016,31.8748
9.629589782,96.39,1005,31.7017
9.682110913,96.39,1046,32.3419
9.734632044,96.39,1056,32.4962
9.787153175,96.39,1053,32.45
9.839674305,96.39,1102,33.1964
9.892195436,96.39,1079,32.8481
9.944716567,96.39,1083,32.909
9.997237697,96.39,1075,32.7872
10.04975883,96.39,1143,33.8083
10.10227996,96.39,1190,34.4964
10.15480109,96.39,1116,33.4066
10.20732222,96.39,1234,35.1283
10.25984335,96.39,1204,34.6987
10.31236448,96.39,1164,34.1174
10.36488561,96.39,1132,33.6452
10.41740674,96.39,1176,34.2929
10.46992787,96.39,1197,34.5977
10.522449,96.39,1208,34.7563
10.57497014,96.39,1264,35.5528
10.62749127,96.39,1329,36.4555
10.6800124,96.39,1397,37.3765
10.73253353,96.39,1259,35.4824
10.78505466,96.39,1407,37.51
10.83757579,96.39,1379,37.1349
10.89009692,96.39,1348,36.7151
10.94261805,96.39,1374,37.0675
10.99513918,96.39,1524,39.0384
11.04766031,96.39,1481,38.4838
11.10018144,96.39,1548,39.3446
11.15270257,96.39,1590,39.8748
11.2052237,96.39,1654,40.6694
11.25774483,96.39,1832,42.8019
11.31026597,96.39,1864,43.1741
11.3627871,96.39,2268,47.6235
11.41530823,96.39,2371,48.6929
11.46782936,96.39,2448,49.4773
11.52035049,96.39,1844,42.9418
11.57287162,96.39,1494,38.6523
11.62539275,96.39,1401,37.4299
11.67791388,96.39,1237,35.171
11.73043501,96.39,1203,34.6843
11.78295614,96.39,1250,35.3553
11.83547727,96.39,1134,33.6749
11.8879984,96.39,1095,33.0908
11.94051953,96.39,1017,31.8904
11.99304066,96.39,992,31.496
12.0455618,96.39,1057,32.5115
12.09808293,96.39,1040,32.249
12.15060406,96.39,997,31.5753
12.20312519,96.39,968,31.1127
12.25564632,96.39,924,30.3974
12.30816745,96.39,899,29.9833
12.36068858,96.39,904,30.0666
12.41320971,96.39,887,29.7825
12.46573084,96.39,855,29.2404
12.51825197,96.39,812,28.4956
12.5707731,96.39,859,29.3087
12.62329423,96.39,785,28.0179
12.67581536,96.39,810,28.4605
12.72833649,96.39,757,27.5136
12.78085763,96.39,776,27.8568
12.83337876,96.39,762,27.6043
12.88589989,96.39,741,27.2213
12.93842102,96.39,730,27.0185
12.99094215,96.39,750,27.3861
13.04346328,96.39,721,26.8514
13.09598441,96.39,725,26.9258
13.14850554,96.39,736,27.1293
13.20102667,96.39,713,26.7021
13.2535478,96.39,697,26.4008
13.30606893,96.39,692,26.3059
13.35859006,96.39,652,25.5343
13.41111119,96.39,659,25.671
13.46363232,96.39,715,26.7395
13.51615346,96.39,706,26.5707
13.56867459,96.39,706,26.5707
13.62119572,96.39,607,24.6374
13.67371685,96.39,693,26.3249
13.72623798,96.39,591,24.3105
13.77875911,96.39,672,25.923
13.83128024,96.39,620,24.8998
13.88380137,96.39,682,26.1151
13.9363225,96.39,606,24.6171
13.98884363,96.39,612,24.7386
14.04136476,96.39,604,24.5764
14.09388589,96.39,605,24.5967
14.14640702,96.39,630,25.0998
14.19892815,96.39,613,24.7588
14.25144929,96.39,569,23.8537
14.30397042,96.39,583,24.1454
14.35649155,96.39,621,24.9199
14.40901268,96.39,609,24.6779
14.46153381,96.39,611,24.7184
14.51405494,96.39,591,24.3105
14.56657607,96.39,668,25.8457
14.6190972,96.39,571,23.8956
14.67161833,96.39,619,24.8797
14.72413946,96.39,547,23.388
14.77666059,96.39,562,23.7065
14.82918172,96.39,571,23.8956
14.88170285,96.39,589,24.2693
14.93422398,96.39,630,25.0998
14.98674512,96.39,550,23.4521
15.03926625,96.39,584,24.1661
15.09178738,96.39,537,23.1733
15.14430851,96.39,572,23.9165
15.19682964,96.39,596,24.4131
15.24935077,96.39,571,23.8956
15.3018719,96.39,586,24.2074
15.35439303,96.39,511,22.6053
15.40691416,96.39,576,24
15.45943529,96.39,558,23.622
15.51195642,96.39,548,23.4094
15.56447755,96.39,552,23.4947
15.61699868,96.39,537,23.1733
15.66951981,96.39,566,23.7908
15.72204095,96.39,523,22.8692
15.77456208,96.39,520,22.8035
15.82708321,96.39,546,23.3666
15.87960434,96.39,522,22.8473
15.93212547,96.39,529,23
15.9846466,96.39,533,23.0868
16.03716773,96.39,525,22.9129
16.08968886,96.39,552,23.4947
16.14220999,96.39,498,22.3159
16.19473112,96.39,480,21.9089
16.24725225,96.39,535,23.1301
16.29977338,96.39,610,24.6982
16.35229451,96.39,528,22.9783
16.40481564,96.39,529,23
16.45733678,96.39,560,23.6643
16.50985791,96.39,577,24.0208
16.56237904,96.39,571,23.8956
16.61490017,96.39,541,23.2594
16.6674213,96.39,483,21.9773
16.71994243,96.39,507,22.5167
16.77246356,96.39,497,22.2935
16.82498469,96.39,535,23.1301
16.87750582,96.39,497,22.2935
16.93002695,96.39,508,22.5389
16.98254808,96.39,496,22.2711
17.03506921,96.39,465,21.5639
17.08759034,96.39,492,22.1811
17.14011147,96.39,477,21.8403
17.19263261,96.39,546,23.3666
17.24515374,96.39,475,21.7945
17.29767487,96.39,461,21.4709
17.350196,96.39,454,21.3073
17.40271713,96.39,480,21.9089
17.45523826,96.39,508,22.5389
17.50775939,96.39,494,22.2261
17.56028052,96.39,474,21.7715
17.61280165,96.39,495,22.2486
17.66532278,96.39,489,22.1133
17.71784391,96.39,500,22.3607
17.77036504,96.39,502,22.4054
17.82288617,96.39,466,21.587
17.8754073,96.39,470,21.6795
17.92792843,96.39,477,21.8403
17.98044957,96.39,506,22.4944
18.0329707,96.39,443,21.0476
18.08549183,96.39,464,21.5407
18.13801296,96.39,418,20.445
18.19053409,96.39,476,21.8174
18.24305522,96.39,470,21.6795
18.29557635,96.39,497,22.2935
18.34809748,96.39,484,22
18.40061861,96.39,471,21.7025
18.45313974,96.39,492,22.1811
18.50566087,96.39,510,22.5832
18.558182,96.39,482,21.9545
18.61070313,96.39,485,22.0227
18.66322426,96.39,488,22.0907
18.7157454,96.39,540,23.2379
18.76826653,96.39,537,23.1733
18.82078766,96.39,558,23.622
18.87330879,96.39,574,23.9583
18.92582992,96.39,498,22.3159
18.97835105,96.39,540,23.2379
19.03087218,96.39,518,22.7596
19.08339331,96.39,497,22.2935
19.13591444,96.39,516,22.7156
19.18843557,96.39,453,21.2838
19.2409567,96.39,525,22.9129
19.29347783,96.39,480,21.9089
19.34599896,96.39,504,22.4499
19.39852009,96.39,479,21.8861
19.45104123,96.39,534,23.1084
19.50356236,96.39,511,22.6053
19.55608349,96.39,497,22.2935
19.60860462,96.39,464,21.5407
19.66112575,96.39,482,21.9545
19.71364688,96.39,514,22.6716
19.76616801,96.39,553,23.516
19.81868914,96.39,539,23.2164
19.87121027,96.39,504,22.4499
19.9237314,96.39,518,22.7596
19.97625253,96.39,505,22.4722
20.02877366,96.39,539,23.2164
20.08129479,96.39,526,22.9347
20.13381592,96.39,477,21.8403
20.18633706,96.39,537,23.1733
20.23885819,96.39,566,23.7908
20.29137932,96.39,588,24.2487
20.34390045,96.39,604,24.5764
20.39642158,96.39,656,25.6125
20.44894271,96.39,672,25.923
20.50146384,96.39,761,27.5862
20.55398497,96.39,771,27.7669
20.6065061,96.39,892,29.8664
20.65902723,96.39,950,30.8221
20.71154836,96.39,906,30.0998
20.76406949,96.39,856,29.2575
20.81659062,96.39,874,29.5635
20.86911175,96.39,835,28.8964
20.92163289,96.39,752,27.4226
20.97415402,96.39,634,25.1794
21.02667515,96.39,601,24.5153
21.07919628,96.39,609,24.6779
21.13171741,96.39,594,24.3721
21.18423854,96.39,591,24.3105
21.23675967,96.39,645,25.3969
21.2892808,96.39,631,25.1197
21.34180193,96.39,661,25.7099
21.39432306,96.39,613,24.7588
21.44684419,96.39,628,25.0599
21.49936532,96.39,619,24.8797
21.55188645,96.39,603,24.5561
21.60440758,96.39,648,25.4558
21.65692872,96.39,626,25.02
21.70944985,96.39,642,25.3377
21.76197098,96.39,629,25.0799
21.81449211,96.39,624,24.98
21.86701324,96.39,643,25.3574
21.91953437,96.39,687,26.2107
21.9720555,96.39,683,26.1343
22.02457663,96.39,692,26.3059
22.07709776,96.39,706,26.5707
22.12961889,96.39,659,25.671
22.18214002,96.39,705,26.5518
22.23466115,96.39,723,26.8887
22.28718228,96.39,691,26.2869
22.33970341,96.39,690,26.2679
22.39222455,96.39,753,27.4408
22.44474568,96.39,754,27.4591
22.49726681,96.39,756,27.4955
22.54978794,96.39,779,27.9106
22.60230907,96.39,732,27.0555
22.6548302,96.39,740,27.2029
22.70735133,96.39,772,27.7849
22.75987246,96.39,839,28.9655
22.81239359,96.39,904,30.0666
22.86491472,96.39,945,30.7409
22.91743585,96.39,941,30.6757
22.96995698,96.39,1020,31.9374
23.02247811,96.39,1033,32.1403
23.07499924,96.39,964,31.0483
23.12752038,96.39,831,28.8271
23.18004151,96.39,750,27.3861
23.23256264,96.39,679,26.0576
23.28508377,96.39,662,25.7294
23.3376049,96.39,610,24.6982
23.39012603,96.39,709,26.6271
23.44264716,96.39,647,25.4362
23.49516829,96.39,567,23.8118
23.54768942,96.39,573,23.9374
23.60021055,96.39,637,25.2389
23.65273168,96.39,604,24.5764
23.70525281,96.39,594,24.3721
23.75777394,96.39,623,24.96
23.81029507,96.39,602,24.5357
23.86281621,96.39,610,24.6982
23.91533734,96.39,622,24.9399
23.96785847,96.39,641,25.318
24.0203796,96.39,618,24.8596
24.07290073,96.39,555,23.5584
24.12542186,96.39,549,23.4307
24.17794299,96.39,543,23.3024
24.23046412,96.39,505,22.4722
24.28298525,96.39,495,22.2486
24.33550638,96.39,492,22.1811
24.38802751,96.39,450,21.2132
24.44054864,96.39,471,21.7025
24.49306977,96.39,467,21.6102
24.5455909,96.39,517,22.7376
24.59811204,96.39,424,20.5913
24.65063317,96.39,465,21.5639
24.7031543,96.39,494,22.2261
24.75567543,96.39,449,21.1896
24.80819656,96.39,479,21.8861
24.86071769,96.39,414,20.347
24.91323882,96.39,435,20.8567
24.96575995,96.39,422,20.5426
25.01828108,96.39,420,20.4939
25.07080221,96.39,434,20.8327
25.12332334,96.39,417,20.4206
25.17584447,96.39,401,20.025
25.2283656,96.39,398,19.9499
25.28088673,96.39,441,21
25.33340786,96.39,457,21.3776
25.385929,96.39,568,23.8328
25.43845013,96.39,729,27
25.49097126,96.39,1127,33.5708
25.54349239,96.39,1539,39.2301
25.59601352,96.39,1225,35
25.64853465,96.39,727,26.9629
25.70105578,96.39,481,21.9317
25.75357691,96.39,424,20.5913
25.80609804,96.39,457,21.3776
25.85861917,96.39,448,21.166
25.9111403,96.39,427,20.664
25.96366143,96.39,404,20.0998
26.01618256,96.39,440,20.9762
26.06870369,96.39,417,20.4206
26.12122483,96.39,388,19.6977
26.17374596,96.39,390,19.7484
26.22626709,96.39,441,21
26.27878822,96.39,409,20.2237
26.33130935,96.39,438,20.9284
26.38383048,96.39,411,20.2731
26.43635161,96.39,415,20.3715
26.48887274,96.39,450,21.2132
26.54139387,96.39,454,21.3073
26.593915,96.39,543,23.3024
26.64643613,96.39,489,22.1133
26.69895726,96.39,484,22
26.75147839,96.39,406,20.1494
26.80399952,96.39,409,20.2237
26.85652066,96.39,411,20.2731
26.90904179,96.39,454,21.3073
26.96156292,96.39,394,19.8494
27.01408405,96.39,395,19.8746
27.06660518,96.39,447,21.1424
27.11912631,96.39,469,21.6564
27.17164744,96.39,440,20.9762
27.22416857,96.39,420,20.4939
27.2766897,96.39,397,19.9249
27.32921083,96.39,394,19.8494
27.38173196,96.39,420,20.4939
27.43425309,96.39,369,19.2094
27.48677422,96.39,400,20
27.53929535,96.39,414,20.347
27.59181649,96.39,376,19.3907
27.64433762,96.39,408,20.199
27.69685875,96.39,399,19.975
27.74937988,96.39,412,20.2978
27.80190101,96.39,342,18.4932
27.85442214,96.39,386,19.6469
27.90694327,96.39,403,20.0749
27.9594644,96.39,381,19.5192
28.01198553,96.39,370,19.2354
28.06450666,96.39,373,19.3132
28.11702779,96.39,364,19.0788
28.16954892,96.39,397,19.9249
28.22207005,96.39,377,19.4165
28.27459118,96.39,421,20.5183
28.32711232,96.39,399,19.975
28.37963345,96.39,393,19.8242
28.43215458,96.39,407,20.1742
28.48467571,96.39,415,20.3715
28.53719684,96.39,421,20.5183
28.58971797,96.39,390,19.7484
28.6422391,96.39,413,20.3224
28.69476023,96.39,406,20.1494
28.74728136,96.39,369,19.2094
28.79980249,96.39,352,18.7617
28.85232362,96.39,365,19.105
28.90484475,96.39,384,19.5959
28.95736588,96.39,373,19.3132
29.00988701,96.39,382,19.5448
29.06240815,96.39,389,19.7231
29.11492928,96.39,367,19.1572
29.16745041,96.39,401,20.025
29.21997154,96.39,391,19.7737
29.27249267,96.39,434,20.8327
29.3250138,96.39,427,20.664
29.37753493,96.39,414,20.347
29.43005606,96.39,382,19.5448
29.48257719,96.39,437,20.9045
29.53509832,96.39,378,19.4422
29.58761945,96.39,424,20.5913
29.64014058,96.39,383,19.5704
29.69266171,96.39,460,21.4476
29.74518284,96.39,415,20.3715
29.79770398,96.39,401,20.025
29.85022511,96.39,404,20.0998
29.90274624,96.39,409,20.2237
29.95526737,96.39,455,21.3307
30.0077885,96.39,442,21.0238
30.06030963,96.39,504,22.4499
30.11283076,96.39,434,20.8327
30.16535189,96.39,396,19.8997
30.21787302,96.39,401,20.025
30.27039415,96.39,381,19.5192
30.32291528,96.39,370,19.2354
30.37543641,96.39,388,19.6977
30.42795754,96.39,349,18.6815
30.48047867,96.39,376,19.3907
30.53299981,96.39,394,19.8494
30.58552094,96.39,385,19.6214
30.63804207,96.39,386,19.6469
30.6905632,96.39,387,19.6723
30.74308433,96.39,391,19.7737
30.79560546,96.39,406,20.1494
30.84812659,96.39,357,18.8944
30.90064772,96.39,369,19.2094
30.95316885,96.39,361,19
31.00568998,96.39,376,19.3907
31.05821111,96.39,308,17.5499
31.11073224,96.39,374,19.3391
31.16325337,96.39,346,18.6011
31.2157745,96.39,423,20.567
31.26829564,96.39,394,19.8494
31.32081677,96.39,426,20.6398
31.3733379,96.39,399,19.975
31.42585903,96.39,367,19.1572
31.47838016,96.39,360,18.9737
31.53090129,96.39,407,20.1742
31.58342242,96.39,421,20.5183
31.63594355,96.39,388,19.6977
31.68846468,96.39,372,19.2873
31.74098581,96.39,408,20.199
31.79350694,96.39,383,19.5704
31.84602807,96.39,393,19.8242
31.8985492,96.39,386,19.6469
31.95107033,96.39,367,19.1572
32.00359147,96.39,381,19.5192
32.0561126,96.39,394,19.8494
32.10863373,96.39,457,21.3776
32.16115486,96.39,456,21.3542
32.21367599,96.39,527,22.9565
32.26619712,96.39,525,22.9129
32.31871825,96.39,463,21.5174
32.37123938,96.39,472,21.7256
32.42376051,96.39,453,21.2838
32.47628164,96.39,414,20.347
32.52880277,96.39,450,21.2132
32.5813239,96.39,439,20.9523
32.63384503,96.39,393,19.8242
32.68636616,96.39,415,20.3715
32.7388873,96.39,379,19.4679
32.79140843,96.39,390,19.7484
32.84392956,96.39,388,19.6977
32.89645069,96.39,423,20.567
32.94897182,96.39,447,21.1424
33.00149295,96.39,440,20.9762
33.05401408,96.39,435,20.8567
33.10653521,96.39,415,20.3715
33.15905634,96.39,460,21.4476
33.21157747,96.39,504,22.4499
33.2640986,96.39,515,22.6936
33.31661973,96.39,584,24.1661
33.36914086,96.39,544,23.3238
33.42166199,96.39,567,23.8118
33.47418312,96.39,635,25.1992
33.52670426,96.39,630,25.0998
33.57922539,96.39,633,25.1595
33.63174652,96.39,665,25.7876
33.68426765,96.39,636,25.219
33.73678878,96.39,711,26.6646
33.78930991,96.39,763,27.6225
33.84183104,96.39,839,28.9655
33.89435217,96.39,922,30.3645
33.9468733,96.39,943,30.7083
33.99939443,96.39,1124,33.5261
34.05191556,96.39,1207,34.7419
34.10443669,96.39,1362,36.9053
34.15695782,96.39,1361,36.8917
34.20947895,96.39,1213,34.8281
34.26200009,96.39,1170,34.2053
34.31452122,96.39,1131,33.6303
34.36704235,96.39,1141,33.7787
34.41956348,96.39,1048,32.3728
34.47208461,96.39,1013,31.8277
34.52460574,96.39,997,31.5753
34.57712687,96.39,1000,31.6228
34.629648,96.39,969,31.1288
34.68216913,96.39,1056,32.4962
34.73469026,96.39,991,31.4802
34.78721139,96.39,960,30.9839
34.83973252,96.39,904,30.0666
34.89225365,96.39,886,29.7658
34.94477478,96.39,962,31.0161
34.99729592,96.39,1170,34.2053
35.04981705,96.39,1575,39.6863
35.10233818,96.39,2301,47.9687
35.15485931,96.39,2046,45.2327
35.20738044,96.39,1541,39.2556
35.25990157,96.39,1048,32.3728
35.3124227,96.39,815,28.5482
35.36494383,96.39,741,27.2213
35.41746496,96.39,706,26.5707
35.46998609,96.39,687,26.2107
35.52250722,96.39,648,25.4558
35.57502835,96.39,671,25.9037
35.62754948,96.39,574,23.9583
35.68007061,96.39,585,24.1868
35.73259175,96.39,631,25.1197
35.78511288,96.39,615,24.7992
35.83763401,96.39,625,25
35.89015514,96.39,626,25.02
35.94267627,96.39,634,25.1794
35.9951974,96.39,584,24.1661
36.04771853,96.39,653,25.5539
36.10023966,96.39,641,25.318
36.15276079,96.39,609,24.6779
36.20528192,96.39,625,25
36.25780305,96.39,645,25.3969
36.31032418,96.39,600,24.4949
36.36284531,96.39,617,24.8395
36.41536644,96.39,596,24.4131
36.46788758,96.39,595,24.3926
36.52040871,96.39,559,23.6432
36.57292984,96.39,629,25.0799
36.62545097,96.39,568,23.8328
36.6779721,96.39,538,23.1948
36.73049323,96.39,574,23.9583
36.78301436,96.39,572,23.9165
36.83553549,96.39,487,22.0681
36.88805662,96.39,567,23.8118
36.94057775,96.39,538,23.1948
36.99309888,96.39,535,23.1301
37.04562001,96.39,532,23.0651
37.09814114,96.39,598,24.454
37.15066227,96.39,587,24.2281
37.20318341,96.39,565,23.7697
37.25570454,96.39,563,23.7276
37.30822567,96.39,642,25.3377
37.3607468,96.39,564,23.7487
37.41326793,96.39,576,24
37.46578906,96.39,610,24.6982
37.51831019,96.39,618,24.8596
37.57083132,96.39,698,26.4197
37.62335245,96.39,771,27.7669
37.67587358,96.39,922,30.3645
37.72839471,96.39,1261,35.5106
37.78091584,96.39,1182,34.3802
37.83343697,96.39,1048,32.3728
37.8859581,96.39,915,30.249
37.93847924,96.39,776,27.8568
37.99100037,96.39,718,26.7955
38.0435215,96.39,601,24.5153
38.09604263,96.39,597,24.4336
38.14856376,96.39,605,24.5967
38.20108489,96.39,595,24.3926
38.25360602,96.39,576,24
38.30612715,96.39,558,23.622
38.35864828,96.39,521,22.8254
38.41116941,96.39,558,23.622
38.46369054,96.39,513,22.6495
38.51621167,96.39,612,24.7386
38.5687328,96.39,517,22.7376
38.62125393,96.39,543,23.3024
38.67377507,96.39,553,23.516
38.7262962,96.39,515,22.6936
38.77881733,96.39,533,23.0868
38.83133846,96.39,544,23.3238
38.88385959,96.39,563,23.7276
38.93638072,96.39,550,23.4521
38.98890185,96.39,625,25
39.04142298,96.39,603,24.5561
39.09394411,96.39,617,24.8395
39.14646524,96.39,616,24.8193
39.19898637,96.39,630,25.0998
39.2515075,96.39,586,24.2074
39.30402863,96.39,571,23.8956
39.35654976,96.39,491,22.1585
39.4090709,96.39,485,22.0227
39.46159203,96.39,487,22.0681
39.51411316,96.39,481,21.9317
39.56663429,96.39,533,23.0868
39.61915542,96.39,449,21.1896
39.67167655,96.39,450,21.2132
39.72419768,96.39,500,22.3607
39.77671881,96.39,453,21.2838
39.82923994,96.39,438,20.9284
39.88176107,96.39,448,21.166
39.9342822,96.39,434,20.8327
39.98680333,96.39,440,20.9762
40.03932446,96.39,449,21.1896
40.09184559,96.39,438,20.9284
40.14436673,96.39,437,20.9045
40.19688786,96.39,456,21.3542
40.24940899,96.39,439,20.9523
40.30193012,96.39,455,21.3307
40.35445125,96.39,433,20.8087
40.40697238,96.39,402,20.0499
40.45949351,96.39,411,20.2731
40.51201464,96.39,390,19.7484
40.56453577,96.39,383,19.5704
40.6170569,96.39,407,20.1742
40.66957803,96.39,396,19.8997
40.72209916,96.39,398,19.9499
40.77462029,96.39,405,20.1246
40.82714142,96.39,413,20.3224
40.87966255,96.39,411,20.2731
40.93218369,96.39,410,20.2485
40.98470482,96.39,433,20.8087
41.03722595,96.39,434,20.8327
41.08974708,96.39,376,19.3907
41.14226821,96.39,414,20.347
41.19478934,96.39,453,21.2838
41.24731047,96.39,447,21.1424
41.2998316,96.39,421,20.5183
41.35235273,96.39,421,20.5183
41.40487386,96.39,440,20.9762
41.45739499,96.39,498,22.3159
41.50991612,96.39,446,21.1187
41.56243725,96.39,439,20.9523
41.61495838,96.39,401,20.025
41.66747952,96.39,376,19.3907
41.72000065,96.39,402,20.0499
41.77252178,96.39,359,18.9473
41.82504291,96.39,403,20.0749
41.87756404,96.39,378,19.4422
41.93008517,96.39,382,19.5448
41.9826063,96.39,387,19.6723
42.03512743,96.39,386,19.6469
42.08764856,96.39,445,21.095
42.14016969,96.39,391,19.7737
42.19269082,96.39,384,19.5959
42.24521195,96.39,417,20.4206
42.29773308,96.39,386,19.6469
42.35025421,96.39,400,20
42.40277535,96.39,388,19.6977
42.45529648,96.39,373,19.3132
42.50781761,96.39,363,19.0526
42.56033874,96.39,343,18.5203
42.61285987,96.39,387,19.6723
42.665381,96.39,365,19.105
42.71790213,96.39,377,19.4165
42.77042326,96.39,388,19.6977
42.82294439,96.39,369,19.2094
42.87546552,96.39,364,19.0788
42.92798665,96.39,356,18.868
42.98050778,96.39,377,19.4165
43.03302891,96.39,447,21.1424
43.08555004,96.39,480,21.9089
43.13807118,96.39,638,25.2587
43.19059231,96.39,829,28.7924
43.24311344,96.39,1183,34.3948
43.29563457,96.39,1849,43
43.3481557,96.39,1744,41.7612
43.40067683,96.39,1201,34.6554
43.45319796,96.39,1084,32.9242
43.50571909,96.39,588,24.2487
43.55824022,96.39,437,20.9045
43.61076135,96.39,396,19.8997
43.66328248,96.39,371,19.2614
43.71580361,96.39,375,19.3649
43.76832474,96.39,385,19.6214
43.82084587,96.39,378,19.4422
43.87336701,96.39,348,18.6548
43.92588814,96.39,371,19.2614
43.97840927,96.39,334,18.2757
44.0309304,96.39,323,17.9722
44.08345153,96.39,351,18.735
44.13597266,96.39,304,17.4356
44.18849379,96.39,350,18.7083
44.24101492,96.39,349,18.6815
44.29353605,96.39,305,17.4642
44.34605718,96.39,344,18.5472
44.39857831,96.39,354,18.8149
44.45109944,96.39,400,20
44.50362057,96.39,386,19.6469
44.5561417,96.39,382,19.5448
44.60866284,96.39,343,18.5203
44.66118397,96.39,350,18.7083
44.7137051,96.39,350,18.7083
44.76622623,96.39,374,19.3391
44.81874736,96.39,307,17.5214
44.87126849,96.39,335,18.303
44.92378962,96.39,386,19.6469
44.97631075,96.39,366,19.1311
45.02883188,96.39,389,19.7231
45.08135301,96.39,361,19
45.13387414,96.39,354,18.8149
45.18639527,96.39,334,18.2757
45.2389164,96.39,341,18.4662
45.29143753,96.39,380,19.4936
45.34395867,96.39,331,18.1934
45.3964798,96.39,339,18.412
45.44900093,96.39,388,19.6977
45.50152206,96.39,342,18.4932
45.55404319,96.39,341,18.4662
45.60656432,96.39,324,18
45.65908545,96.39,361,19
45.71160658,96.39,376,19.3907
45.76412771,96.39,328,18.1108
45.81664884,96.39,333,18.2483
45.86916997,96.39,352,18.7617
45.9216911,96.39,342,18.4932
45.97421223,96.39,348,18.6548
46.02673336,96.39,382,19.5448
46.0792545,96.39,408,20.199
46.13177563,96.39,411,20.2731
46.18429676,96.39,445,21.095
46.23681789,96.39,447,21.1424
46.28933902,96.39,448,21.166
46.34186015,96.39,458,21.4009
46.39438128,96.39,464,21.5407
46.44690241,96.39,446,21.1187
46.49942354,96.39,424,20.5913
46.55194467,96.39,423,20.567
46.6044658,96.39,420,20.4939
46.65698693,96.39,377,19.4165
46.70950806,96.39,359,18.9473
46.76202919,96.39,353,18.7883
46.81455033,96.39,363,19.0526
46.86707146,96.39,336,18.3303
46.91959259,96.39,327,18.0831
46.97211372,96.39,356,18.868
47.02463485,96.39,360,18.9737
47.07715598,96.39,312,17.6635
47.12967711,96.39,325,18.0278
47.18219824,96.39,331,18.1934
47.23471937,96.39,304,17.4356
47.2872405,96.39,305,17.4642
47.33976163,96.39,331,18.1934
47.39228276,96.39,304,17.4356
47.44480389,96.39,307,17.5214
47.49732502,96.39,289,17
47.54984616,96.39,307,17.5214
47.60236729,96.39,316,17.7764
47.65488842,96.39,338,18.3848
47.70740955,96.39,318,17.8326
47.75993068,96.39,334,18.2757
47.81245181,96.39,317,17.8045
47.86497294,96.39,323,17.9722
47.91749407,96.39,296,17.2047
47.9700152,96.39,312,17.6635
48.02253633,96.39,301,17.3494
48.07505746,96.39,322,17.9444
48.12757859,96.39,319,17.8606
48.18009972,96.39,359,18.9473
48.23262085,96.39,330,18.1659
48.28514198,96.39,282,16.7929
48.33766312,96.39,302,17.3781
48.39018425,96.39,331,18.1934
48.44270538,96.39,377,19.4165
48.49522651,96.39,338,18.3848
48.54774764,96.39,322,17.9444
48.60026877,96.39,306,17.4929
48.6527899,96.39,305,17.4642
48.70531103,96.39,315,17.7482
48.75783216,96.39,317,17.8045
48.81035329,96.39,315,17.7482
48.86287442,96.39,337,18.3576
48.91539555,96.39,343,18.5203
48.96791668,96.39,356,18.868
49.02043781,96.39,357,18.8944
49.07295895,96.39,339,18.412
49.12548008,96.39,353,18.7883
49.17800121,96.39,332,18.2209
49.23052234,96.39,335,18.303
49.28304347,96.39,354,18.8149
49.3355646,96.39,314,17.72
49.38808573,96.39,342,18.4932
49.44060686,96.39,337,18.3576
49.49312799,96.39,267,16.3401
49.54564912,96.39,294,17.1464
49.59817025,96.39,300,17.3205
49.65069138,96.39,282,16.7929
49.70321251,96.39,290,17.0294
49.75573364,96.39,277,16.6433
49.80825478,96.39,271,16.4621
49.86077591,96.39,296,17.2047
49.91329704,96.39,278,16.6733
49.96581817,96.39,237,15.3948
50.0183393,96.39,247,15.7162
50.07086043,96.39,279,16.7033
50.12338156,96.39,319,17.8606
50.17590269,96.39,296,17.2047
50.22842382,96.39,252,15.8745
50.28094495,96.39,267,16.3401
50.33346608,96.39,253,15.906
50.38598721,96.39,251,15.843
50.43850834,96.39,263,16.2173
50.49102947,96.39,268,16.3707
50.54355061,96.39,275,16.5831
50.59607174,96.39,285,16.8819
50.64859287,96.39,265,16.2788
50.701114,96.39,248,15.748
50.75363513,96.39,272,16.4924
50.80615626,96.39,241,15.5242
50.85867739,96.39,257,16.0312
50.91119852,96.39,275,16.5831
50.96371965,96.39,297,17.2337
51.01624078,96.39,274,16.5529
51.06876191,96.39,255,15.9687
51.12128304,96.39,287,16.9411
51.17380417,96.39,251,15.843
51.2263253,96.39,271,16.4621
51.27884644,96.39,263,16.2173
51.33136757,96.39,278,16.6733
51.3838887,96.39,296,17.2047
51.43640983,96.39,245,15.6525
51.48893096,96.39,238,15.4272
51.54145209,96.39,248,15.748
51.59397322,96.39,274,16.5529
51.64649435,96.39,243,15.5885
51.69901548,96.39,227,15.0665
51.75153661,96.39,236,15.3623
51.80405774,96.39,222,14.8997
51.85657887,96.39,254,15.9374
51.9091,96.39,247,15.7162
51.96162113,96.39,265,16.2788
52.01414227,96.39,271,16.4621
52.0666634,96.39,278,16.6733
52.11918453,96.39,252,15.8745
52.17170566,96.39,314,17.72
52.22422679,96.39,279,16.7033
52.27674792,96.39,294,17.1464
52.32926905,96.39,359,18.9473
52.38179018,96.39,513,22.6495
52.43431131,96.39,639,25.2784
52.48683244,96.39,876,29.5973
52.53935357,96.39,889,29.8161
52.5918747,96.39,577,24.0208
52.64439583,96.39,586,24.2074
52.69691696,96.39,432,20.7846
52.7494381,96.39,313,17.6918
52.80195923,96.39,307,17.5214
52.85448036,96.39,265,16.2788
52.90700149,96.39,245,15.6525
52.95952262,96.39,235,15.3297
53.01204375,96.39,242,15.5563
53.06456488,96.39,253,15.906
53.11708601,96.39,253,15.906
53.16960714,96.39,255,15.9687
53.22212827,96.39,270,16.4317
53.2746494,96.39,253,15.906
53.32717053,96.39,267,16.3401
53.37969166,96.39,258,16.0624
53.43221279,96.39,259,16.0935
53.48473393,96.39,249,15.7797
53.53725506,96.39,265,16.2788
53.58977619,96.39,267,16.3401
53.64229732,96.39,268,16.3707
53.69481845,96.39,241,15.5242
53.74733958,96.39,247,15.7162
53.79986071,96.39,275,16.5831
53.85238184,96.39,234,15.2971
53.90490297,96.39,246,15.6844
53.9574241,96.39,246,15.6844
54.00994523,96.39,207,14.3875
54.06246636,96.39,247,15.7162
54.11498749,96.39,218,14.7648
54.16750862,96.39,257,16.0312
54.22002976,96.39,228,15.0997
54.27255089,96.39,237,15.3948
54.32507202,96.39,242,15.5563
54.37759315,96.39,266,16.3095
54.43011428,96.39,259,16.0935
54.48263541,96.39,273,16.5227
54.53515654,96.39,267,16.3401
54.58767767,96.39,249,15.7797
54.6401988,96.39,230,15.1658
54.69271993,96.39,266,16.3095
54.74524106,96.39,222,14.8997
54.79776219,96.39,250,15.8114
54.85028332,96.39,257,16.0312
54.90280445,96.39,230,15.1658
54.95532559,96.39,251,15.843
55.00784672,96.39,253,15.906
55.06036785,96.39,237,15.3948
55.11288898,96.39,264,16.2481
55.16541011,96.39,212,14.5602
55.21793124,96.39,251,15.843
55.27045237,96.39,231,15.1987
55.3229735,96.39,250,15.8114
55.37549463,96.39,252,15.8745
55.42801576,96.39,262,16.1864
55.48053689,96.39,244,15.6205
55.53305802,96.39,224,14.9666
55.58557915,96.39,274,16.5529
55.63810028,96.39,224,14.9666
55.69062141,96.39,237,15.3948
55.74314255,96.39,264,16.2481
55.79566368,96.39,255,15.9687
55.84818481,96.39,296,17.2047
55.90070594,96.39,236,15.3623
55.95322707,96.39,228,15.0997
56.0057482,96.39,238,15.4272
56.05826933,96.39,231,15.1987
56.11079046,96.39,242,15.5563
56.16331159,96.39,235,15.3297
56.21583272,96.39,223,14.9332
56.26835385,96.39,235,15.3297
56.32087498,96.39,241,15.5242
56.37339611,96.39,213,14.5945
56.42591724,96.39,229,15.1327
56.47843838,96.39,235,15.3297
56.53095951,96.39,249,15.7797
56.58348064,96.39,215,14.6629
56.63600177,96.39,262,16.1864
56.6885229,96.39,246,15.6844
56.74104403,96.39,251,15.843
56.79356516,96.39,236,15.3623
56.84608629,96.39,251,15.843
56.89860742,96.39,257,16.0312
56.95112855,96.39,237,15.3948
57.00364968,96.39,287,16.9411
57.05617081,96.39,277,16.6433
57.10869194,96.39,298,17.2627
57.16121307,96.39,307,17.5214
57.21373421,96.39,346,18.6011
57.26625534,96.39,459,21.4243
57.31877647,96.39,619,24.8797
57.3712976,96.39,837,28.931
57.42381873,96.39,1322,36.3593
57.47633986,96.39,1399,37.4032
57.52886099,96.39,934,30.5614
57.58138212,96.39,813,28.5132
57.63390325,96.39,830,28.8097
57.68642438,96.39,439,20.9523
57.73894551,96.39,322,17.9444
57.79146664,96.39,279,16.7033
57.84398777,96.39,245,15.6525
57.8965089,96.39,303,17.4069
57.94903004,96.39,235,15.3297
58.00155117,96.39,239,15.4596
58.0540723,96.39,238,15.4272
58.10659343,96.39,253,15.906
58.15911456,96.39,243,15.5885
58.21163569,96.39,218,14.7648
58.26415682,96.39,262,16.1864
58.31667795,96.39,268,16.3707
58.36919908,96.39,281,16.7631
58.42172021,96.39,241,15.5242
58.47424134,96.39,231,15.1987
58.52676247,96.39,238,15.4272
58.5792836,96.39,264,16.2481
58.63180473,96.39,260,16.1245
58.68432587,96.39,260,16.1245
58.736847,96.39,251,15.843
58.78936813,96.39,265,16.2788
58.84188926,96.39,254,15.9374
58.89441039,96.39,279,16.7033
58.94693152,96.39,258,16.0624
58.99945265,96.39,282,16.7929
59.05197378,96.39,289,17
59.10449491,96.39,280,16.7332
59.15701604,96.39,341,18.4662
59.20953717,96.39,341,18.4662
59.2620583,96.39,322,17.9444
59.31457943,96.39,332,18.2209
59.36710056,96.39,334,18.2757
59.4196217,96.39,338,18.3848
59.47214283,96.39,377,19.4165
59.52466396,96.39,368,19.1833
59.57718509,96.39,402,20.0499
59.62970622,96.39,456,21.3542
59.68222735,96.39,448,21.166
59.73474848,96.39,414,20.347
59.78726961,96.39,451,21.2368
59.83979074,96.39,431,20.7605
59.89231187,96.39,471,21.7025
59.944833,96.39,493,22.2036
59.99735413,96.39,490,22.1359
60.04987526,96.39,466,21.587
60.10239639,96.39,486,22.0454
60.15491753,96.39,553,23.516
60.20743866,96.39,530,23.0217
60.25995979,96.39,525,22.9129
60.31248092,96.39,550,23.4521
60.36500205,96.39,579,24.0624
60.41752318,96.39,528,22.9783
60.47004431,96.39,566,23.7908
60.52256544,96.39,539,23.2164
60.57508657,96.39,600,24.4949
60.6276077,96.39,537,23.1733
60.68012883,96.39,511,22.6053
60.73264996,96.39,460,21.4476
60.78517109,96.39,466,21.587
60.83769222,96.39,466,21.587
60.89021336,96.39,490,22.1359
60.94273449,96.39,462,21.4942
60.99525562,96.39,465,21.5639
61.04777675,96.39,506,22.4944
61.10029788,96.39,505,22.4722
61.15281901,96.39,483,21.9773
61.20534014,96.39,511,22.6053
61.25786127,96.39,500,22.3607
61.3103824,96.39,503,22.4277
61.36290353,96.39,479,21.8861
61.41542466,96.39,437,20.9045
61.46794579,96.39,434,20.8327
61.52046692,96.39,358,18.9209
61.57298805,96.39,397,19.9249
61.62550919,96.39,374,19.3391
61.67803032,96.39,428,20.6882
61.73055145,96.39,354,18.8149
61.78307258,96.39,394,19.8494
61.83559371,96.39,350,18.7083
61.88811484,96.39,376,19.3907
61.94063597,96.39,359,18.9473
61.9931571,96.39,297,17.2337
62.04567823,96.39,307,17.5214
62.09819936,96.39,259,16.0935
62.15072049,96.39,296,17.2047
62.20324162,96.39,288,16.9706
62.25576275,96.39,262,16.1864
62.30828388,96.39,246,15.6844
62.36080502,96.39,242,15.5563
62.41332615,96.39,255,15.9687
62.46584728,96.39,265,16.2788
62.51836841,96.39,284,16.8523
62.57088954,96.39,236,15.3623
62.62341067,96.39,219,14.7986
62.6759318,96.39,260,16.1245
62.72845293,96.39,246,15.6844
62.78097406,96.39,264,16.2481
62.83349519,96.39,259,16.0935
62.88601632,96.39,205,14.3178
62.93853745,96.39,232,15.2315
62.99105858,96.39,225,15
63.04357971,96.39,204,14.2829
63.09610084,96.39,226,15.0333
63.14862198,96.39,218,14.7648
63.20114311,96.39,223,14.9332
63.25366424,96.39,193,13.8924
63.30618537,96.39,185,13.6015
63.3587065,96.39,187,13.6748
63.41122763,96.39,211,14.5258
63.46374876,96.39,196,14
63.51626989,96.39,201,14.1774
63.56879102,96.39,237,15.3948
63.62131215,96.39,179,13.3791
63.67383328,96.39,193,13.8924
63.72635441,96.39,194,13.9284
63.77887554,96.39,185,13.6015
63.83139667,96.39,219,14.7986
63.88391781,96.39,187,13.6748
63.93643894,96.39,195,13.9642
63.98896007,96.39,197,14.0357
64.0414812,96.39,190,13.784
64.09400233,96.39,210,14.4914
64.14652346,96.39,207,14.3875
64.19904459,96.39,190,13.784
64.25156572,96.39,190,13.784
64.30408685,96.39,203,14.2478
64.35660798,96.39,198,14.0712
64.40912911,96.39,179,13.3791
64.46165024,96.39,192,13.8564
64.51417137,96.39,198,14.0712
64.5666925,96.39,182,13.4907
64.61921364,96.39,195,13.9642
64.67173477,96.39,180,13.4164
64.7242559,96.39,211,14.5258
64.77677703,96.39,177,13.3041
64.82929816,96.39,189,13.7477
64.88181929,96.39,185,13.6015
64.93434042,96.39,185,13.6015
64.98686155,96.39,198,14.0712